11/18/2012 09:18:44;0002;PBS_Server;Svr;Log;Log opened
11/18/2012 09:18:44;0006;PBS_Server;Svr;PBS_Server;Server tyrone-cluster started, initialization type = 1
11/18/2012 09:18:44;0002;PBS_Server;Svr;Act;Account file /var/spool/torque/server_priv/accounting/20121118 opened
11/18/2012 09:18:44;0040;PBS_Server;Req;setup_nodes;setup_nodes()
11/18/2012 09:18:44;0086;PBS_Server;Svr;PBS_Server;Recovered queue qp32
11/18/2012 09:18:44;0086;PBS_Server;Svr;PBS_Server;Recovered queue qp256
11/18/2012 09:18:44;0086;PBS_Server;Svr;PBS_Server;Recovered queue idqueue
11/18/2012 09:18:44;0086;PBS_Server;Svr;PBS_Server;Recovered queue qp128
11/18/2012 09:18:44;0086;PBS_Server;Svr;PBS_Server;Recovered queue qp64
11/18/2012 09:18:44;0086;PBS_Server;Svr;PBS_Server;Recovered queue batch
11/18/2012 09:18:44;0002;PBS_Server;Svr;PBS_Server;Expected 6, recovered 6 queues
11/18/2012 09:18:44;0100;PBS_Server;Job;13582.tyrone-cluster;enqueuing into qp32, state 4 hop 1
11/18/2012 09:18:44;0086;PBS_Server;Job;13582.tyrone-cluster;Requeueing job, substate: 42 Requeued in queue: qp32
11/18/2012 09:18:44;0100;PBS_Server;Job;13588.tyrone-cluster;enqueuing into qp32, state 1 hop 1
11/18/2012 09:18:44;0086;PBS_Server;Job;13588.tyrone-cluster;Requeueing job, substate: 10 Requeued in queue: qp32
11/18/2012 09:18:44;0100;PBS_Server;Job;13520.tyrone-cluster;enqueuing into qp64, state 4 hop 1
11/18/2012 09:18:44;0086;PBS_Server;Job;13520.tyrone-cluster;Requeueing job, substate: 42 Requeued in queue: qp64
11/18/2012 09:18:44;0100;PBS_Server;Job;13573.tyrone-cluster;enqueuing into qp64, state 1 hop 1
11/18/2012 09:18:44;0086;PBS_Server;Job;13573.tyrone-cluster;Requeueing job, substate: 10 Requeued in queue: qp64
11/18/2012 09:18:44;0100;PBS_Server;Job;13603.tyrone-cluster;enqueuing into qp64, state 4 hop 1
11/18/2012 09:18:44;0086;PBS_Server;Job;13603.tyrone-cluster;Requeueing job, substate: 42 Requeued in queue: qp64
11/18/2012 09:18:44;0100;PBS_Server;Job;13640.tyrone-cluster;enqueuing into qp32, state 4 hop 1
11/18/2012 09:18:44;0086;PBS_Server;Job;13640.tyrone-cluster;Requeueing job, substate: 42 Requeued in queue: qp32
11/18/2012 09:18:44;0100;PBS_Server;Job;13697.tyrone-cluster;enqueuing into batch, state 1 hop 1
11/18/2012 09:18:44;0086;PBS_Server;Job;13697.tyrone-cluster;Requeueing job, substate: 10 Requeued in queue: batch
11/18/2012 09:18:44;0100;PBS_Server;Job;13598.tyrone-cluster;enqueuing into qp32, state 4 hop 1
11/18/2012 09:18:44;0086;PBS_Server;Job;13598.tyrone-cluster;Requeueing job, substate: 42 Requeued in queue: qp32
11/18/2012 09:18:44;0100;PBS_Server;Job;13773.tyrone-cluster;enqueuing into qp32, state 4 hop 1
11/18/2012 09:18:44;0086;PBS_Server;Job;13773.tyrone-cluster;Requeueing job, substate: 42 Requeued in queue: qp32
11/18/2012 09:18:44;0100;PBS_Server;Job;13774.tyrone-cluster;enqueuing into qp32, state 1 hop 1
11/18/2012 09:18:44;0086;PBS_Server;Job;13774.tyrone-cluster;Requeueing job, substate: 10 Requeued in queue: qp32
11/18/2012 09:18:44;0100;PBS_Server;Job;13599.tyrone-cluster;enqueuing into qp32, state 1 hop 1
11/18/2012 09:18:44;0086;PBS_Server;Job;13599.tyrone-cluster;Requeueing job, substate: 10 Requeued in queue: qp32
11/18/2012 09:18:44;0100;PBS_Server;Job;13794.tyrone-cluster;enqueuing into qp32, state 1 hop 1
11/18/2012 09:18:44;0086;PBS_Server;Job;13794.tyrone-cluster;Requeueing job, substate: 10 Requeued in queue: qp32
11/18/2012 09:18:44;0100;PBS_Server;Job;13796.tyrone-cluster;enqueuing into qp64, state 4 hop 1
11/18/2012 09:18:44;0086;PBS_Server;Job;13796.tyrone-cluster;Requeueing job, substate: 42 Requeued in queue: qp64
11/18/2012 09:18:44;0100;PBS_Server;Job;13799.tyrone-cluster;enqueuing into qp32, state 1 hop 1
11/18/2012 09:18:44;0086;PBS_Server;Job;13799.tyrone-cluster;Requeueing job, substate: 10 Requeued in queue: qp32
11/18/2012 09:18:44;0100;PBS_Server;Job;13808.tyrone-cluster;enqueuing into qp32, state 1 hop 1
11/18/2012 09:18:44;0086;PBS_Server;Job;13808.tyrone-cluster;Requeueing job, substate: 10 Requeued in queue: qp32
11/18/2012 09:18:44;0100;PBS_Server;Job;13592.tyrone-cluster;enqueuing into qp32, state 1 hop 1
11/18/2012 09:18:44;0086;PBS_Server;Job;13592.tyrone-cluster;Requeueing job, substate: 10 Requeued in queue: qp32
11/18/2012 09:18:44;0100;PBS_Server;Job;13810.tyrone-cluster;enqueuing into qp32, state 1 hop 1
11/18/2012 09:18:44;0086;PBS_Server;Job;13810.tyrone-cluster;Requeueing job, substate: 10 Requeued in queue: qp32
11/18/2012 09:18:44;0100;PBS_Server;Job;13837.tyrone-cluster;enqueuing into qp64, state 4 hop 1
11/18/2012 09:18:44;0086;PBS_Server;Job;13837.tyrone-cluster;Requeueing job, substate: 42 Requeued in queue: qp64
11/18/2012 09:18:44;0100;PBS_Server;Job;13899.tyrone-cluster;enqueuing into qp64, state 1 hop 1
11/18/2012 09:18:44;0086;PBS_Server;Job;13899.tyrone-cluster;Requeueing job, substate: 10 Requeued in queue: qp64
11/18/2012 09:18:44;0100;PBS_Server;Job;13594.tyrone-cluster;enqueuing into qp32, state 1 hop 1
11/18/2012 09:18:44;0086;PBS_Server;Job;13594.tyrone-cluster;Requeueing job, substate: 10 Requeued in queue: qp32
11/18/2012 09:18:44;0100;PBS_Server;Job;13936.tyrone-cluster;enqueuing into qp64, state 1 hop 1
11/18/2012 09:18:44;0086;PBS_Server;Job;13936.tyrone-cluster;Requeueing job, substate: 10 Requeued in queue: qp64
11/18/2012 09:18:44;0100;PBS_Server;Job;13981.tyrone-cluster;enqueuing into qp32, state 1 hop 1
11/18/2012 09:18:44;0086;PBS_Server;Job;13981.tyrone-cluster;Requeueing job, substate: 10 Requeued in queue: qp32
11/18/2012 09:18:44;0100;PBS_Server;Job;13984.tyrone-cluster;enqueuing into qp32, state 1 hop 1
11/18/2012 09:18:44;0086;PBS_Server;Job;13984.tyrone-cluster;Requeueing job, substate: 10 Requeued in queue: qp32
11/18/2012 09:18:44;0100;PBS_Server;Job;13985.tyrone-cluster;enqueuing into qp32, state 1 hop 1
11/18/2012 09:18:44;0086;PBS_Server;Job;13985.tyrone-cluster;Requeueing job, substate: 10 Requeued in queue: qp32
11/18/2012 09:18:44;0100;PBS_Server;Job;13986.tyrone-cluster;enqueuing into qp64, state 1 hop 1
11/18/2012 09:18:44;0086;PBS_Server;Job;13986.tyrone-cluster;Requeueing job, substate: 10 Requeued in queue: qp64
11/18/2012 09:18:44;0100;PBS_Server;Job;13987.tyrone-cluster;enqueuing into batch, state 1 hop 1
11/18/2012 09:18:44;0086;PBS_Server;Job;13987.tyrone-cluster;Requeueing job, substate: 10 Requeued in queue: batch
11/18/2012 09:18:44;0100;PBS_Server;Job;13992.tyrone-cluster;enqueuing into qp32, state 1 hop 1
11/18/2012 09:18:44;0086;PBS_Server;Job;13992.tyrone-cluster;Requeueing job, substate: 10 Requeued in queue: qp32
11/18/2012 09:18:44;0100;PBS_Server;Job;13993.tyrone-cluster;enqueuing into qp32, state 1 hop 1
11/18/2012 09:18:44;0086;PBS_Server;Job;13993.tyrone-cluster;Requeueing job, substate: 10 Requeued in queue: qp32
11/18/2012 09:18:44;0100;PBS_Server;Job;13994.tyrone-cluster;enqueuing into batch, state 1 hop 1
11/18/2012 09:18:44;0086;PBS_Server;Job;13994.tyrone-cluster;Requeueing job, substate: 10 Requeued in queue: batch
11/18/2012 09:18:44;0100;PBS_Server;Job;13995.tyrone-cluster;enqueuing into batch, state 1 hop 1
11/18/2012 09:18:44;0086;PBS_Server;Job;13995.tyrone-cluster;Requeueing job, substate: 10 Requeued in queue: batch
11/18/2012 09:18:44;0100;PBS_Server;Job;13695.tyrone-cluster;enqueuing into qp32, state 1 hop 1
11/18/2012 09:18:44;0086;PBS_Server;Job;13695.tyrone-cluster;Requeueing job, substate: 10 Requeued in queue: qp32
11/18/2012 09:18:44;0100;PBS_Server;Job;13996.tyrone-cluster;enqueuing into idqueue, state 4 hop 1
11/18/2012 09:18:44;0086;PBS_Server;Job;13996.tyrone-cluster;Requeueing job, substate: 42 Requeued in queue: idqueue
11/18/2012 09:18:44;0100;PBS_Server;Job;13998.tyrone-cluster;enqueuing into idqueue, state 4 hop 1
11/18/2012 09:18:44;0086;PBS_Server;Job;13998.tyrone-cluster;Requeueing job, substate: 42 Requeued in queue: idqueue
11/18/2012 09:18:44;0100;PBS_Server;Job;14000.tyrone-cluster;enqueuing into idqueue, state 1 hop 1
11/18/2012 09:18:44;0086;PBS_Server;Job;14000.tyrone-cluster;Requeueing job, substate: 10 Requeued in queue: idqueue
11/18/2012 09:18:44;0100;PBS_Server;Job;13696.tyrone-cluster;enqueuing into qp32, state 1 hop 1
11/18/2012 09:18:44;0086;PBS_Server;Job;13696.tyrone-cluster;Requeueing job, substate: 10 Requeued in queue: qp32
11/18/2012 09:18:44;0100;PBS_Server;Job;14001.tyrone-cluster;enqueuing into idqueue, state 1 hop 1
11/18/2012 09:18:44;0086;PBS_Server;Job;14001.tyrone-cluster;Requeueing job, substate: 10 Requeued in queue: idqueue
11/18/2012 09:18:44;0100;PBS_Server;Job;14010.tyrone-cluster;enqueuing into qp32, state 1 hop 1
11/18/2012 09:18:44;0086;PBS_Server;Job;14010.tyrone-cluster;Requeueing job, substate: 10 Requeued in queue: qp32
11/18/2012 09:18:44;0002;PBS_Server;Svr;PBS_Server;Expected 37, recovered 37 jobs
11/18/2012 09:18:44;0006;PBS_Server;Svr;PBS_Server;Using ports Server:15001  Scheduler:15004  MOM:15002 (server: 'tyrone-cluster')
11/18/2012 09:18:44;0002;PBS_Server;Svr;daemonize_server;INFO:      parent is exiting
11/18/2012 09:18:44;0002;PBS_Server;Svr;daemonize_server;INFO:      parent is exiting
11/18/2012 09:18:44;0002;PBS_Server;Svr;daemonize_server;INFO:      child process in background
11/18/2012 09:18:44;0002;PBS_Server;Svr;PBS_Server;Server Ready, pid = 3891, loglevel=0
11/18/2012 09:18:44;0040;PBS_Server;Svr;tyrone-cluster;Scheduler was sent the command scheduler_first
11/18/2012 09:18:47;0040;PBS_Server;Svr;tyrone-cluster;Scheduler was sent the command new
11/18/2012 09:18:47;0008;PBS_Server;Job;13996.tyrone-cluster;Job Modified at request of Scheduler@tyrone-cluster
11/18/2012 09:18:47;0008;PBS_Server;Job;14000.tyrone-cluster;Job Modified at request of Scheduler@tyrone-cluster
11/18/2012 09:18:47;0008;PBS_Server;Job;14001.tyrone-cluster;Job Modified at request of Scheduler@tyrone-cluster
11/18/2012 09:18:48;0040;PBS_Server;Svr;tyrone-cluster;Scheduler was sent the command new
11/18/2012 09:18:48;0008;PBS_Server;Job;13998.tyrone-cluster;Job Modified at request of Scheduler@tyrone-cluster
11/18/2012 09:18:49;0002;PBS_Server;Svr;PBS_Server;Torque Server Version = 3.0.5, loglevel = 0
11/18/2012 09:18:56;000d;PBS_Server;Job;13582.tyrone-cluster;Not sending email: User does not want mail of this type.
11/18/2012 09:18:56;0010;PBS_Server;Job;13582.tyrone-cluster;Exit_status=28 resources_used.cput=06:00:04 resources_used.mem=3170772kb resources_used.vmem=3609260kb resources_used.walltime=16:04:24
11/18/2012 09:18:56;0008;PBS_Server;Job;NULL;on_job_exit valid pjob: 0x131e480 (substate=50)
11/18/2012 09:18:56;0008;PBS_Server;Job;NULL;on_job_exit valid pjob: 0x131e480 (substate=51)
11/18/2012 09:18:56;0008;PBS_Server;Job;NULL;on_job_exit valid pjob: 0x131e480 (substate=51)
11/18/2012 09:18:56;0008;PBS_Server;Job;NULL;on_job_exit valid pjob: 0x131e480 (substate=53)
11/18/2012 09:18:56;0100;PBS_Server;Job;13582.tyrone-cluster;dequeuing from qp32, state COMPLETE
11/18/2012 09:18:56;0040;PBS_Server;Svr;tyrone-cluster;Scheduler was sent the command term
11/18/2012 09:18:56;0008;PBS_Server;Job;13588.tyrone-cluster;Job Modified at request of Scheduler@tyrone-cluster
11/18/2012 09:18:56;0008;PBS_Server;Job;13588.tyrone-cluster;Job Run at request of Scheduler@tyrone-cluster
11/18/2012 09:18:57;0008;PBS_Server;Job;13996.tyrone-cluster;Job Modified at request of Scheduler@tyrone-cluster
11/18/2012 09:18:57;000d;PBS_Server;Job;13588.tyrone-cluster;Not sending email: User does not want mail of this type.
11/18/2012 09:18:57;0008;PBS_Server;Job;13996.tyrone-cluster;Job Run at request of Scheduler@tyrone-cluster
11/18/2012 09:18:57;0008;PBS_Server;Job;13998.tyrone-cluster;Job Modified at request of Scheduler@tyrone-cluster
11/18/2012 09:18:57;0008;PBS_Server;Job;13998.tyrone-cluster;Job Run at request of Scheduler@tyrone-cluster
11/18/2012 09:18:57;000d;PBS_Server;Job;13996.tyrone-cluster;Not sending email: User does not want mail of this type.
11/18/2012 09:18:57;000d;PBS_Server;Job;13640.tyrone-cluster;Not sending email: User does not want mail of this type.
11/18/2012 09:18:57;0010;PBS_Server;Job;13640.tyrone-cluster;Exit_status=0 resources_used.cput=472:05:00 resources_used.mem=1228072kb resources_used.vmem=5048996kb resources_used.walltime=25:29:56
11/18/2012 09:18:57;0008;PBS_Server;Job;NULL;on_job_exit valid pjob: 0x12f9680 (substate=50)
11/18/2012 09:18:57;0008;PBS_Server;Job;NULL;on_job_exit valid pjob: 0x12f9680 (substate=51)
11/18/2012 09:18:57;000d;PBS_Server;Job;13773.tyrone-cluster;Not sending email: User does not want mail of this type.
11/18/2012 09:18:57;0010;PBS_Server;Job;13773.tyrone-cluster;Exit_status=1 resources_used.cput=108:25:06 resources_used.mem=5248664kb resources_used.vmem=20778356kb resources_used.walltime=11:40:52
11/18/2012 09:18:57;0008;PBS_Server;Job;NULL;on_job_exit valid pjob: 0x1307b70 (substate=50)
11/18/2012 09:18:57;0008;PBS_Server;Job;NULL;on_job_exit valid pjob: 0x1307b70 (substate=51)
11/18/2012 09:18:57;000d;PBS_Server;Job;13598.tyrone-cluster;Not sending email: User does not want mail of this type.
11/18/2012 09:18:57;0010;PBS_Server;Job;13598.tyrone-cluster;Exit_status=0 resources_used.cput=141:30:09 resources_used.mem=5377256kb resources_used.vmem=10302236kb resources_used.walltime=14:24:19
11/18/2012 09:18:57;0008;PBS_Server;Job;NULL;on_job_exit valid pjob: 0x1337ab0 (substate=50)
11/18/2012 09:18:57;0008;PBS_Server;Job;NULL;on_job_exit valid pjob: 0x1337ab0 (substate=51)
11/18/2012 09:18:57;0008;PBS_Server;Job;14000.tyrone-cluster;Job Modified at request of Scheduler@tyrone-cluster
11/18/2012 09:18:57;0008;PBS_Server;Job;14001.tyrone-cluster;Job Modified at request of Scheduler@tyrone-cluster
11/18/2012 09:18:57;000d;PBS_Server;Job;13998.tyrone-cluster;Not sending email: User does not want mail of this type.
11/18/2012 09:18:58;0008;PBS_Server;Job;NULL;on_job_exit valid pjob: 0x1307b70 (substate=51)
11/18/2012 09:18:58;0008;PBS_Server;Job;NULL;on_job_exit valid pjob: 0x1307b70 (substate=53)
11/18/2012 09:18:58;0100;PBS_Server;Job;13773.tyrone-cluster;dequeuing from qp32, state COMPLETE
11/18/2012 09:18:58;0040;PBS_Server;Svr;tyrone-cluster;Scheduler was sent the command term
11/18/2012 09:18:59;0008;PBS_Server;Job;13774.tyrone-cluster;Job Modified at request of Scheduler@tyrone-cluster
11/18/2012 09:18:59;0008;PBS_Server;Job;13774.tyrone-cluster;Job Run at request of Scheduler@tyrone-cluster
11/18/2012 09:18:59;0008;PBS_Server;Job;13599.tyrone-cluster;Job Modified at request of Scheduler@tyrone-cluster
11/18/2012 09:18:59;000d;PBS_Server;Job;13774.tyrone-cluster;Not sending email: User does not want mail of this type.
11/18/2012 09:18:59;0008;PBS_Server;Job;13599.tyrone-cluster;Job Run at request of Scheduler@tyrone-cluster
11/18/2012 09:19:00;0008;PBS_Server;Job;13794.tyrone-cluster;Job Modified at request of Scheduler@tyrone-cluster
11/18/2012 09:19:00;000d;PBS_Server;Job;13599.tyrone-cluster;Not sending email: User does not want mail of this type.
11/18/2012 09:19:00;0008;PBS_Server;Job;13794.tyrone-cluster;Job Run at request of Scheduler@tyrone-cluster
11/18/2012 09:19:00;000d;PBS_Server;Job;13794.tyrone-cluster;Not sending email: User does not want mail of this type.
11/18/2012 09:19:06;0008;PBS_Server;Job;NULL;on_job_exit valid pjob: 0x1337ab0 (substate=51)
11/18/2012 09:19:06;0008;PBS_Server;Job;NULL;on_job_exit valid pjob: 0x1337ab0 (substate=53)
11/18/2012 09:19:06;0100;PBS_Server;Job;13598.tyrone-cluster;dequeuing from qp32, state COMPLETE
11/18/2012 09:19:06;0040;PBS_Server;Svr;tyrone-cluster;Scheduler was sent the command term
11/18/2012 09:19:08;0008;PBS_Server;Job;NULL;on_job_exit valid pjob: 0x12f9680 (substate=51)
11/18/2012 09:19:08;000d;PBS_Server;Job;13640.tyrone-cluster;Post job file processing error; job 13640.tyrone-cluster on host tyrone-node2/31+tyrone-node2/30+tyrone-node2/29+tyrone-node2/28+tyrone-node2/27+tyrone-node2/26+tyrone-node2/25+tyrone-node2/24+tyrone-node2/23+tyrone-node2/22+tyrone-node2/21+tyrone-node2/20+tyrone-node2/19+tyrone-node2/18+tyrone-node2/17+tyrone-node2/16+tyrone-node2/15+tyrone-node2/14+tyrone-node2/13+tyrone-node2/12+tyrone-node2/11+tyrone-node2/10+tyrone-node2/9+tyrone-node2/8+tyrone-node2/7+tyrone-node2/6+tyrone-node2/5+tyrone-node2/4+tyrone-node2/3+tyrone-node2/2+tyrone-node2/1+tyrone-node2/0
11/18/2012 09:19:08;0008;PBS_Server;Job;NULL;on_job_exit valid pjob: 0x12f9680 (substate=53)
11/18/2012 09:19:08;0100;PBS_Server;Job;13640.tyrone-cluster;dequeuing from qp32, state COMPLETE
11/18/2012 09:19:08;0040;PBS_Server;Svr;tyrone-cluster;Scheduler was sent the command term
11/18/2012 09:19:17;0100;PBS_Server;Job;13994.tyrone-cluster;dequeuing from batch, state QUEUED
11/18/2012 09:19:17;0100;PBS_Server;Job;13994.tyrone-cluster;enqueuing into qp32, state 1 hop 1
11/18/2012 09:19:28;0040;PBS_Server;Svr;tyrone-cluster;Scheduler was sent the command new
11/18/2012 09:19:29;0008;PBS_Server;Job;13994.tyrone-cluster;Job Modified at request of Scheduler@tyrone-cluster
11/18/2012 09:19:48;0040;PBS_Server;Svr;tyrone-cluster;Scheduler was sent the command new
11/18/2012 09:20:18;0040;PBS_Server;Svr;tyrone-cluster;Scheduler was sent the command new
11/18/2012 09:20:18;000d;PBS_Server;Job;13794.tyrone-cluster;Not sending email: User does not want mail of this type.
11/18/2012 09:20:18;0010;PBS_Server;Job;13794.tyrone-cluster;Exit_status=0 resources_used.cput=00:00:04 resources_used.mem=3948kb resources_used.vmem=332632kb resources_used.walltime=00:01:18
11/18/2012 09:20:18;0008;PBS_Server;Job;NULL;on_job_exit valid pjob: 0x1347ad0 (substate=50)
11/18/2012 09:20:18;0008;PBS_Server;Job;NULL;on_job_exit valid pjob: 0x1347ad0 (substate=51)
11/18/2012 09:20:26;0008;PBS_Server;Job;NULL;on_job_exit valid pjob: 0x1347ad0 (substate=51)
11/18/2012 09:20:26;000d;PBS_Server;Job;13794.tyrone-cluster;Post job file processing error; job 13794.tyrone-cluster on host tyrone-node7/31+tyrone-node7/30+tyrone-node7/29+tyrone-node7/28+tyrone-node7/27+tyrone-node7/26+tyrone-node7/25+tyrone-node7/24+tyrone-node7/23+tyrone-node7/22+tyrone-node7/21+tyrone-node7/20+tyrone-node7/19+tyrone-node7/18+tyrone-node7/17+tyrone-node7/16+tyrone-node7/15+tyrone-node7/14+tyrone-node7/13+tyrone-node7/12+tyrone-node7/11+tyrone-node7/10+tyrone-node7/9+tyrone-node7/8+tyrone-node7/7+tyrone-node7/6+tyrone-node7/5+tyrone-node7/4+tyrone-node7/3+tyrone-node7/2+tyrone-node7/1+tyrone-node7/0
11/18/2012 09:20:26;0008;PBS_Server;Job;NULL;on_job_exit valid pjob: 0x1347ad0 (substate=53)
11/18/2012 09:20:26;0100;PBS_Server;Job;13794.tyrone-cluster;dequeuing from qp32, state COMPLETE
11/18/2012 09:20:26;0040;PBS_Server;Svr;tyrone-cluster;Scheduler was sent the command term
11/18/2012 09:20:27;0008;PBS_Server;Job;13799.tyrone-cluster;Job Modified at request of Scheduler@tyrone-cluster
11/18/2012 09:20:27;0008;PBS_Server;Job;13799.tyrone-cluster;Job Run at request of Scheduler@tyrone-cluster
11/18/2012 09:20:27;0040;PBS_Server;Svr;tyrone-cluster;Scheduler was sent the command recyc
11/18/2012 09:20:27;000d;PBS_Server;Job;13799.tyrone-cluster;Not sending email: User does not want mail of this type.
11/18/2012 09:20:50;0040;PBS_Server;Svr;tyrone-cluster;Scheduler was sent the command new
11/18/2012 09:21:22;0040;PBS_Server;Svr;tyrone-cluster;Scheduler was sent the command new
11/18/2012 09:21:53;0040;PBS_Server;Svr;tyrone-cluster;Scheduler was sent the command new
11/18/2012 09:22:30;0040;PBS_Server;Svr;tyrone-cluster;Scheduler was sent the command new
11/18/2012 09:23:05;0040;PBS_Server;Svr;tyrone-cluster;Scheduler was sent the command new
11/18/2012 09:23:37;0040;PBS_Server;Svr;tyrone-cluster;Scheduler was sent the command new
11/18/2012 09:23:49;0002;PBS_Server;Svr;PBS_Server;Torque Server Version = 3.0.5, loglevel = 0
11/18/2012 09:24:07;0040;PBS_Server;Svr;tyrone-cluster;Scheduler was sent the command new
11/18/2012 09:24:45;0040;PBS_Server;Svr;tyrone-cluster;Scheduler was sent the command new
11/18/2012 09:25:20;0040;PBS_Server;Svr;tyrone-cluster;Scheduler was sent the command new
11/18/2012 09:25:52;0040;PBS_Server;Svr;tyrone-cluster;Scheduler was sent the command new
11/18/2012 09:26:22;0040;PBS_Server;Svr;tyrone-cluster;Scheduler was sent the command new
11/18/2012 09:27:00;0040;PBS_Server;Svr;tyrone-cluster;Scheduler was sent the command new
11/18/2012 09:27:35;0040;PBS_Server;Svr;tyrone-cluster;Scheduler was sent the command new
11/18/2012 09:28:07;0040;PBS_Server;Svr;tyrone-cluster;Scheduler was sent the command new
11/18/2012 09:28:37;0040;PBS_Server;Svr;tyrone-cluster;Scheduler was sent the command new
11/18/2012 09:28:49;0002;PBS_Server;Svr;PBS_Server;Torque Server Version = 3.0.5, loglevel = 0
11/18/2012 09:29:15;0040;PBS_Server;Svr;tyrone-cluster;Scheduler was sent the command new
11/18/2012 09:29:50;0040;PBS_Server;Svr;tyrone-cluster;Scheduler was sent the command new
11/18/2012 09:30:22;0040;PBS_Server;Svr;tyrone-cluster;Scheduler was sent the command new
11/18/2012 09:30:53;0040;PBS_Server;Svr;tyrone-cluster;Scheduler was sent the command new
11/18/2012 09:31:30;0040;PBS_Server;Svr;tyrone-cluster;Scheduler was sent the command new
11/18/2012 09:32:05;0040;PBS_Server;Svr;tyrone-cluster;Scheduler was sent the command new
11/18/2012 09:32:37;0040;PBS_Server;Svr;tyrone-cluster;Scheduler was sent the command new
11/18/2012 09:33:07;0040;PBS_Server;Svr;tyrone-cluster;Scheduler was sent the command new
11/18/2012 09:33:45;0040;PBS_Server;Svr;tyrone-cluster;Scheduler was sent the command new
11/18/2012 09:33:49;0002;PBS_Server;Svr;PBS_Server;Torque Server Version = 3.0.5, loglevel = 0
11/18/2012 09:34:20;0040;PBS_Server;Svr;tyrone-cluster;Scheduler was sent the command new
11/18/2012 09:34:24;0100;PBS_Server;Job;14037.tyrone-cluster;enqueuing into batch, state 1 hop 1
11/18/2012 09:34:24;0100;PBS_Server;Job;14037.tyrone-cluster;dequeuing from batch, state QUEUED
11/18/2012 09:34:24;0100;PBS_Server;Job;14037.tyrone-cluster;enqueuing into qp64, state 1 hop 1
11/18/2012 09:34:24;0008;PBS_Server;Job;14037.tyrone-cluster;Job Queued at request of asealama@tyrone-node9, owner = asealama@tyrone-node9, job name = jobname, queue = qp64
11/18/2012 09:34:24;0040;PBS_Server;Svr;tyrone-cluster;Scheduler was sent the command new
11/18/2012 09:34:24;0008;PBS_Server;Job;14037.tyrone-cluster;Job Modified at request of Scheduler@tyrone-cluster
11/18/2012 09:34:52;0040;PBS_Server;Svr;tyrone-cluster;Scheduler was sent the command new
11/18/2012 09:35:22;0040;PBS_Server;Svr;tyrone-cluster;Scheduler was sent the command new
11/18/2012 09:36:00;0040;PBS_Server;Svr;tyrone-cluster;Scheduler was sent the command new
11/18/2012 09:36:35;0040;PBS_Server;Svr;tyrone-cluster;Scheduler was sent the command new
11/18/2012 09:37:07;0040;PBS_Server;Svr;tyrone-cluster;Scheduler was sent the command new
11/18/2012 09:37:37;0040;PBS_Server;Svr;tyrone-cluster;Scheduler was sent the command new
11/18/2012 09:38:15;0040;PBS_Server;Svr;tyrone-cluster;Scheduler was sent the command new
11/18/2012 09:38:49;0002;PBS_Server;Svr;PBS_Server;Torque Server Version = 3.0.5, loglevel = 0
11/18/2012 09:38:49;0040;PBS_Server;Svr;tyrone-cluster;Scheduler was sent the command new
11/18/2012 09:39:16;0040;PBS_Server;Svr;tyrone-cluster;Scheduler was sent the command new
11/18/2012 09:39:46;0040;PBS_Server;Svr;tyrone-cluster;Scheduler was sent the command new
11/18/2012 09:40:20;0040;PBS_Server;Svr;tyrone-cluster;Scheduler was sent the command new
11/18/2012 09:40:52;0040;PBS_Server;Svr;tyrone-cluster;Scheduler was sent the command new
11/18/2012 09:41:22;0040;PBS_Server;Svr;tyrone-cluster;Scheduler was sent the command new
11/18/2012 09:41:28;0100;PBS_Server;Job;14038.tyrone-cluster;enqueuing into batch, state 1 hop 1
11/18/2012 09:41:28;0100;PBS_Server;Job;14038.tyrone-cluster;dequeuing from batch, state QUEUED
11/18/2012 09:41:28;0100;PBS_Server;Job;14038.tyrone-cluster;enqueuing into qp32, state 1 hop 1
11/18/2012 09:41:28;0008;PBS_Server;Job;14038.tyrone-cluster;Job Queued at request of asealama@tyrone-cluster, owner = asealama@tyrone-cluster, job name = jobname, queue = qp32
11/18/2012 09:41:28;0040;PBS_Server;Svr;tyrone-cluster;Scheduler was sent the command new
11/18/2012 09:41:28;0008;PBS_Server;Job;14038.tyrone-cluster;Job Modified at request of Scheduler@tyrone-cluster
11/18/2012 09:42:00;0040;PBS_Server;Svr;tyrone-cluster;Scheduler was sent the command new
11/18/2012 09:42:35;0040;PBS_Server;Svr;tyrone-cluster;Scheduler was sent the command new
11/18/2012 09:43:07;0040;PBS_Server;Svr;tyrone-cluster;Scheduler was sent the command new
11/18/2012 09:43:37;0040;PBS_Server;Svr;tyrone-cluster;Scheduler was sent the command new
11/18/2012 09:43:49;0002;PBS_Server;Svr;PBS_Server;Torque Server Version = 3.0.5, loglevel = 0
11/18/2012 09:44:15;0040;PBS_Server;Svr;tyrone-cluster;Scheduler was sent the command new
11/18/2012 09:44:50;0040;PBS_Server;Svr;tyrone-cluster;Scheduler was sent the command new
11/18/2012 09:45:22;0040;PBS_Server;Svr;tyrone-cluster;Scheduler was sent the command new
11/18/2012 09:45:52;0040;PBS_Server;Svr;tyrone-cluster;Scheduler was sent the command new
11/18/2012 09:46:30;0040;PBS_Server;Svr;tyrone-cluster;Scheduler was sent the command new
11/18/2012 09:47:05;0040;PBS_Server;Svr;tyrone-cluster;Scheduler was sent the command new
11/18/2012 09:47:37;0040;PBS_Server;Svr;tyrone-cluster;Scheduler was sent the command new
11/18/2012 09:48:08;0040;PBS_Server;Svr;tyrone-cluster;Scheduler was sent the command new
11/18/2012 09:48:45;0040;PBS_Server;Svr;tyrone-cluster;Scheduler was sent the command new
11/18/2012 09:48:49;0002;PBS_Server;Svr;PBS_Server;Torque Server Version = 3.0.5, loglevel = 0
11/18/2012 09:49:20;0040;PBS_Server;Svr;tyrone-cluster;Scheduler was sent the command new
11/18/2012 09:49:52;0040;PBS_Server;Svr;tyrone-cluster;Scheduler was sent the command new
11/18/2012 09:50:25;0040;PBS_Server;Svr;tyrone-cluster;Scheduler was sent the command new
11/18/2012 09:51:00;0040;PBS_Server;Svr;tyrone-cluster;Scheduler was sent the command new
11/18/2012 09:51:35;0040;PBS_Server;Svr;tyrone-cluster;Scheduler was sent the command new
11/18/2012 09:52:07;0040;PBS_Server;Svr;tyrone-cluster;Scheduler was sent the command new
11/18/2012 09:52:38;0040;PBS_Server;Svr;tyrone-cluster;Scheduler was sent the command new
11/18/2012 09:53:15;0040;PBS_Server;Svr;tyrone-cluster;Scheduler was sent the command new
11/18/2012 09:53:49;0002;PBS_Server;Svr;PBS_Server;Torque Server Version = 3.0.5, loglevel = 0
11/18/2012 09:53:49;0040;PBS_Server;Svr;tyrone-cluster;Scheduler was sent the command new
11/18/2012 09:54:16;0040;PBS_Server;Svr;tyrone-cluster;Scheduler was sent the command new
11/18/2012 09:54:46;0040;PBS_Server;Svr;tyrone-cluster;Scheduler was sent the command new
11/18/2012 09:55:20;0040;PBS_Server;Svr;tyrone-cluster;Scheduler was sent the command new
11/18/2012 09:55:52;0040;PBS_Server;Svr;tyrone-cluster;Scheduler was sent the command new
11/18/2012 09:56:25;0040;PBS_Server;Svr;tyrone-cluster;Scheduler was sent the command new
11/18/2012 09:57:00;0040;PBS_Server;Svr;tyrone-cluster;Scheduler was sent the command new
11/18/2012 09:57:35;0040;PBS_Server;Svr;tyrone-cluster;Scheduler was sent the command new
11/18/2012 09:58:07;0040;PBS_Server;Svr;tyrone-cluster;Scheduler was sent the command new
11/18/2012 09:58:38;0040;PBS_Server;Svr;tyrone-cluster;Scheduler was sent the command new
11/18/2012 09:58:49;0002;PBS_Server;Svr;PBS_Server;Torque Server Version = 3.0.5, loglevel = 0
11/18/2012 09:59:15;0040;PBS_Server;Svr;tyrone-cluster;Scheduler was sent the command new
11/18/2012 09:59:50;0040;PBS_Server;Svr;tyrone-cluster;Scheduler was sent the command new
11/18/2012 10:00:22;0040;PBS_Server;Svr;tyrone-cluster;Scheduler was sent the command new
11/18/2012 10:00:52;0040;PBS_Server;Svr;tyrone-cluster;Scheduler was sent the command new
11/18/2012 10:01:30;0040;PBS_Server;Svr;tyrone-cluster;Scheduler was sent the command new
11/18/2012 10:02:05;0040;PBS_Server;Svr;tyrone-cluster;Scheduler was sent the command new
11/18/2012 10:02:37;0040;PBS_Server;Svr;tyrone-cluster;Scheduler was sent the command new
11/18/2012 10:03:08;0040;PBS_Server;Svr;tyrone-cluster;Scheduler was sent the command new
11/18/2012 10:03:45;0040;PBS_Server;Svr;tyrone-cluster;Scheduler was sent the command new
11/18/2012 10:03:49;0002;PBS_Server;Svr;PBS_Server;Torque Server Version = 3.0.5, loglevel = 0
11/18/2012 10:04:20;0040;PBS_Server;Svr;tyrone-cluster;Scheduler was sent the command new
11/18/2012 10:04:52;0040;PBS_Server;Svr;tyrone-cluster;Scheduler was sent the command new
11/18/2012 10:05:22;0040;PBS_Server;Svr;tyrone-cluster;Scheduler was sent the command new
11/18/2012 10:06:00;0040;PBS_Server;Svr;tyrone-cluster;Scheduler was sent the command new
11/18/2012 10:06:35;0040;PBS_Server;Svr;tyrone-cluster;Scheduler was sent the command new
11/18/2012 10:07:07;0040;PBS_Server;Svr;tyrone-cluster;Scheduler was sent the command new
11/18/2012 10:07:40;0040;PBS_Server;Svr;tyrone-cluster;Scheduler was sent the command new
11/18/2012 10:08:15;0040;PBS_Server;Svr;tyrone-cluster;Scheduler was sent the command new
11/18/2012 10:08:49;0002;PBS_Server;Svr;PBS_Server;Torque Server Version = 3.0.5, loglevel = 0
11/18/2012 10:08:49;0040;PBS_Server;Svr;tyrone-cluster;Scheduler was sent the command new
11/18/2012 10:09:16;0040;PBS_Server;Svr;tyrone-cluster;Scheduler was sent the command new
11/18/2012 10:09:46;0040;PBS_Server;Svr;tyrone-cluster;Scheduler was sent the command new
11/18/2012 10:10:20;0040;PBS_Server;Svr;tyrone-cluster;Scheduler was sent the command new
11/18/2012 10:10:53;0040;PBS_Server;Svr;tyrone-cluster;Scheduler was sent the command new
11/18/2012 10:11:26;0040;PBS_Server;Svr;tyrone-cluster;Scheduler was sent the command new
11/18/2012 10:12:00;0040;PBS_Server;Svr;tyrone-cluster;Scheduler was sent the command new
11/18/2012 10:12:35;0040;PBS_Server;Svr;tyrone-cluster;Scheduler was sent the command new
11/18/2012 10:13:07;0040;PBS_Server;Svr;tyrone-cluster;Scheduler was sent the command new
11/18/2012 10:13:40;0040;PBS_Server;Svr;tyrone-cluster;Scheduler was sent the command new
11/18/2012 10:13:49;0002;PBS_Server;Svr;PBS_Server;Torque Server Version = 3.0.5, loglevel = 0
11/18/2012 10:14:14;0040;PBS_Server;Svr;tyrone-cluster;Scheduler was sent the command new
11/18/2012 10:14:14;0100;PBS_Server;Job;14039.tyrone-cluster;enqueuing into batch, state 1 hop 1
11/18/2012 10:14:14;0100;PBS_Server;Job;14039.tyrone-cluster;dequeuing from batch, state QUEUED
11/18/2012 10:14:14;0100;PBS_Server;Job;14039.tyrone-cluster;enqueuing into qp64, state 1 hop 1
11/18/2012 10:14:14;0008;PBS_Server;Job;14039.tyrone-cluster;Job Queued at request of ipckousi@tyrone-cluster, owner = ipckousi@tyrone-cluster, job name = n10, queue = qp64
11/18/2012 10:14:14;0008;PBS_Server;Job;14039.tyrone-cluster;Job Modified at request of Scheduler@tyrone-cluster
11/18/2012 10:14:50;0040;PBS_Server;Svr;tyrone-cluster;Scheduler was sent the command new
11/18/2012 10:15:22;0040;PBS_Server;Svr;tyrone-cluster;Scheduler was sent the command new
11/18/2012 10:15:55;0040;PBS_Server;Svr;tyrone-cluster;Scheduler was sent the command new
11/18/2012 10:16:30;0040;PBS_Server;Svr;tyrone-cluster;Scheduler was sent the command new
11/18/2012 10:17:05;0040;PBS_Server;Svr;tyrone-cluster;Scheduler was sent the command new
11/18/2012 10:17:37;0040;PBS_Server;Svr;tyrone-cluster;Scheduler was sent the command new
11/18/2012 10:18:08;0040;PBS_Server;Svr;tyrone-cluster;Scheduler was sent the command new
11/18/2012 10:18:45;0040;PBS_Server;Svr;tyrone-cluster;Scheduler was sent the command new
11/18/2012 10:18:49;0002;PBS_Server;Svr;PBS_Server;Torque Server Version = 3.0.5, loglevel = 0
11/18/2012 10:19:20;0040;PBS_Server;Svr;tyrone-cluster;Scheduler was sent the command new
11/18/2012 10:19:41;0100;PBS_Server;Job;14040.tyrone-cluster;enqueuing into batch, state 1 hop 1
11/18/2012 10:19:41;0100;PBS_Server;Job;14040.tyrone-cluster;dequeuing from batch, state QUEUED
11/18/2012 10:19:41;0100;PBS_Server;Job;14040.tyrone-cluster;enqueuing into qp64, state 1 hop 1
11/18/2012 10:19:41;0008;PBS_Server;Job;14040.tyrone-cluster;Job Queued at request of ciesita@tyrone-cluster, owner = ciesita@tyrone-cluster, job name = a=125, queue = qp64
11/18/2012 10:19:41;0040;PBS_Server;Svr;tyrone-cluster;Scheduler was sent the command new
11/18/2012 10:19:41;0008;PBS_Server;Job;14040.tyrone-cluster;Job Modified at request of Scheduler@tyrone-cluster
11/18/2012 10:19:52;0040;PBS_Server;Svr;tyrone-cluster;Scheduler was sent the command new
11/18/2012 10:20:25;0040;PBS_Server;Svr;tyrone-cluster;Scheduler was sent the command new
11/18/2012 10:21:00;0040;PBS_Server;Svr;tyrone-cluster;Scheduler was sent the command new
11/18/2012 10:21:35;0040;PBS_Server;Svr;tyrone-cluster;Scheduler was sent the command new
11/18/2012 10:22:07;0040;PBS_Server;Svr;tyrone-cluster;Scheduler was sent the command new
11/18/2012 10:22:37;0040;PBS_Server;Svr;tyrone-cluster;Scheduler was sent the command new
11/18/2012 10:23:15;0040;PBS_Server;Svr;tyrone-cluster;Scheduler was sent the command new
11/18/2012 10:23:49;0002;PBS_Server;Svr;PBS_Server;Torque Server Version = 3.0.5, loglevel = 0
11/18/2012 10:23:49;0040;PBS_Server;Svr;tyrone-cluster;Scheduler was sent the command new
11/18/2012 10:24:16;0040;PBS_Server;Svr;tyrone-cluster;Scheduler was sent the command new
11/18/2012 10:24:46;0040;PBS_Server;Svr;tyrone-cluster;Scheduler was sent the command new
11/18/2012 10:25:20;0040;PBS_Server;Svr;tyrone-cluster;Scheduler was sent the command new
11/18/2012 10:25:53;0040;PBS_Server;Svr;tyrone-cluster;Scheduler was sent the command new
11/18/2012 10:26:25;0040;PBS_Server;Svr;tyrone-cluster;Scheduler was sent the command new
11/18/2012 10:27:00;0040;PBS_Server;Svr;tyrone-cluster;Scheduler was sent the command new
11/18/2012 10:27:35;0040;PBS_Server;Svr;tyrone-cluster;Scheduler was sent the command new
11/18/2012 10:28:07;0040;PBS_Server;Svr;tyrone-cluster;Scheduler was sent the command new
11/18/2012 10:28:40;0040;PBS_Server;Svr;tyrone-cluster;Scheduler was sent the command new
11/18/2012 10:28:49;0002;PBS_Server;Svr;PBS_Server;Torque Server Version = 3.0.5, loglevel = 0
11/18/2012 10:29:15;0040;PBS_Server;Svr;tyrone-cluster;Scheduler was sent the command new
11/18/2012 10:29:50;0040;PBS_Server;Svr;tyrone-cluster;Scheduler was sent the command new
11/18/2012 10:30:22;0040;PBS_Server;Svr;tyrone-cluster;Scheduler was sent the command new
11/18/2012 10:30:55;0040;PBS_Server;Svr;tyrone-cluster;Scheduler was sent the command new
11/18/2012 10:31:30;0040;PBS_Server;Svr;tyrone-cluster;Scheduler was sent the command new
11/18/2012 10:32:05;0040;PBS_Server;Svr;tyrone-cluster;Scheduler was sent the command new
11/18/2012 10:32:37;0040;PBS_Server;Svr;tyrone-cluster;Scheduler was sent the command new
11/18/2012 10:33:07;0040;PBS_Server;Svr;tyrone-cluster;Scheduler was sent the command new
11/18/2012 10:33:45;0040;PBS_Server;Svr;tyrone-cluster;Scheduler was sent the command new
11/18/2012 10:33:49;0002;PBS_Server;Svr;PBS_Server;Torque Server Version = 3.0.5, loglevel = 0
11/18/2012 10:34:20;0040;PBS_Server;Svr;tyrone-cluster;Scheduler was sent the command new
11/18/2012 10:34:52;0040;PBS_Server;Svr;tyrone-cluster;Scheduler was sent the command new
11/18/2012 10:35:25;0040;PBS_Server;Svr;tyrone-cluster;Scheduler was sent the command new
11/18/2012 10:36:00;0040;PBS_Server;Svr;tyrone-cluster;Scheduler was sent the command new
11/18/2012 10:36:35;0040;PBS_Server;Svr;tyrone-cluster;Scheduler was sent the command new
11/18/2012 10:37:07;0040;PBS_Server;Svr;tyrone-cluster;Scheduler was sent the command new
11/18/2012 10:37:38;0040;PBS_Server;Svr;tyrone-cluster;Scheduler was sent the command new
11/18/2012 10:38:15;0040;PBS_Server;Svr;tyrone-cluster;Scheduler was sent the command new
11/18/2012 10:38:49;0002;PBS_Server;Svr;PBS_Server;Torque Server Version = 3.0.5, loglevel = 0
11/18/2012 10:38:49;0040;PBS_Server;Svr;tyrone-cluster;Scheduler was sent the command new
11/18/2012 10:39:16;0040;PBS_Server;Svr;tyrone-cluster;Scheduler was sent the command new
11/18/2012 10:39:46;0040;PBS_Server;Svr;tyrone-cluster;Scheduler was sent the command new
11/18/2012 10:40:20;0040;PBS_Server;Svr;tyrone-cluster;Scheduler was sent the command new
11/18/2012 10:40:52;0040;PBS_Server;Svr;tyrone-cluster;Scheduler was sent the command new
11/18/2012 10:41:25;0040;PBS_Server;Svr;tyrone-cluster;Scheduler was sent the command new
11/18/2012 10:42:00;0040;PBS_Server;Svr;tyrone-cluster;Scheduler was sent the command new
11/18/2012 10:42:35;0040;PBS_Server;Svr;tyrone-cluster;Scheduler was sent the command new
11/18/2012 10:43:07;0040;PBS_Server;Svr;tyrone-cluster;Scheduler was sent the command new
11/18/2012 10:43:39;0040;PBS_Server;Svr;tyrone-cluster;Scheduler was sent the command new
11/18/2012 10:43:49;0002;PBS_Server;Svr;PBS_Server;Torque Server Version = 3.0.5, loglevel = 0
11/18/2012 10:44:15;0040;PBS_Server;Svr;tyrone-cluster;Scheduler was sent the command new
11/18/2012 10:44:50;0040;PBS_Server;Svr;tyrone-cluster;Scheduler was sent the command new
11/18/2012 10:45:08;000d;PBS_Server;Job;13603.tyrone-cluster;Not sending email: User does not want mail of this type.
11/18/2012 10:45:08;0010;PBS_Server;Job;13603.tyrone-cluster;Exit_status=143 resources_used.cput=1532:15:13 resources_used.mem=3335708kb resources_used.vmem=10557120kb resources_used.walltime=24:00:48
11/18/2012 10:45:08;0008;PBS_Server;Job;NULL;on_job_exit valid pjob: 0x12ff8a0 (substate=50)
11/18/2012 10:45:08;0008;PBS_Server;Job;NULL;on_job_exit valid pjob: 0x12ff8a0 (substate=51)
11/18/2012 10:45:08;0008;PBS_Server;Job;NULL;on_job_exit valid pjob: 0x12ff8a0 (substate=51)
11/18/2012 10:45:08;0008;PBS_Server;Job;NULL;on_job_exit valid pjob: 0x12ff8a0 (substate=53)
11/18/2012 10:45:08;0100;PBS_Server;Job;13603.tyrone-cluster;dequeuing from qp64, state COMPLETE
11/18/2012 10:45:08;0040;PBS_Server;Svr;tyrone-cluster;Scheduler was sent the command term
11/18/2012 10:45:08;0008;PBS_Server;Job;13573.tyrone-cluster;Job Modified at request of Scheduler@tyrone-cluster
11/18/2012 10:45:08;0008;PBS_Server;Job;13899.tyrone-cluster;Job Modified at request of Scheduler@tyrone-cluster
11/18/2012 10:45:08;0008;PBS_Server;Job;13899.tyrone-cluster;Job Run at request of Scheduler@tyrone-cluster
11/18/2012 10:45:08;0040;PBS_Server;Svr;tyrone-cluster;Scheduler was sent the command recyc
11/18/2012 10:45:08;000d;PBS_Server;Job;13899.tyrone-cluster;Not sending email: User does not want mail of this type.
11/18/2012 10:45:15;000d;PBS_Server;Job;13899.tyrone-cluster;Not sending email: User does not want mail of this type.
11/18/2012 10:45:15;0010;PBS_Server;Job;13899.tyrone-cluster;Exit_status=0 resources_used.cput=00:00:01 resources_used.mem=0kb resources_used.vmem=0kb resources_used.walltime=00:00:07
11/18/2012 10:45:15;0008;PBS_Server;Job;NULL;on_job_exit valid pjob: 0x1324780 (substate=50)
11/18/2012 10:45:15;0008;PBS_Server;Job;NULL;on_job_exit valid pjob: 0x1324780 (substate=51)
11/18/2012 10:45:15;0008;PBS_Server;Job;NULL;on_job_exit valid pjob: 0x1324780 (substate=51)
11/18/2012 10:45:15;0008;PBS_Server;Job;NULL;on_job_exit valid pjob: 0x1324780 (substate=53)
11/18/2012 10:45:15;0100;PBS_Server;Job;13899.tyrone-cluster;dequeuing from qp64, state COMPLETE
11/18/2012 10:45:15;0040;PBS_Server;Svr;tyrone-cluster;Scheduler was sent the command term
11/18/2012 10:45:16;0008;PBS_Server;Job;13936.tyrone-cluster;Job Modified at request of Scheduler@tyrone-cluster
11/18/2012 10:45:16;0008;PBS_Server;Job;13936.tyrone-cluster;Job Run at request of Scheduler@tyrone-cluster
11/18/2012 10:45:16;0040;PBS_Server;Svr;tyrone-cluster;Scheduler was sent the command recyc
11/18/2012 10:45:16;000d;PBS_Server;Job;13936.tyrone-cluster;Not sending email: User does not want mail of this type.
11/18/2012 10:45:22;0040;PBS_Server;Svr;tyrone-cluster;Scheduler was sent the command new
11/18/2012 10:45:23;0008;PBS_Server;Job;13573.tyrone-cluster;Job Modified at request of Scheduler@tyrone-cluster
11/18/2012 10:45:53;0040;PBS_Server;Svr;tyrone-cluster;Scheduler was sent the command new
11/18/2012 10:46:30;0040;PBS_Server;Svr;tyrone-cluster;Scheduler was sent the command new
11/18/2012 10:47:05;0040;PBS_Server;Svr;tyrone-cluster;Scheduler was sent the command new
11/18/2012 10:47:37;0040;PBS_Server;Svr;tyrone-cluster;Scheduler was sent the command new
11/18/2012 10:48:10;0040;PBS_Server;Svr;tyrone-cluster;Scheduler was sent the command new
11/18/2012 10:48:11;000d;PBS_Server;Job;13796.tyrone-cluster;Not sending email: User does not want mail of this type.
11/18/2012 10:48:11;0010;PBS_Server;Job;13796.tyrone-cluster;Exit_status=143 resources_used.cput=1536:25:28 resources_used.mem=101969032kb resources_used.vmem=139279044kb resources_used.walltime=24:00:45
11/18/2012 10:48:11;0008;PBS_Server;Job;NULL;on_job_exit valid pjob: 0x12f3ed0 (substate=50)
11/18/2012 10:48:11;0008;PBS_Server;Job;NULL;on_job_exit valid pjob: 0x12f3ed0 (substate=51)
11/18/2012 10:48:11;0008;PBS_Server;Job;NULL;on_job_exit valid pjob: 0x12f3ed0 (substate=51)
11/18/2012 10:48:11;0008;PBS_Server;Job;NULL;on_job_exit valid pjob: 0x12f3ed0 (substate=53)
11/18/2012 10:48:11;0100;PBS_Server;Job;13796.tyrone-cluster;dequeuing from qp64, state COMPLETE
11/18/2012 10:48:11;0040;PBS_Server;Svr;tyrone-cluster;Scheduler was sent the command term
11/18/2012 10:48:11;0008;PBS_Server;Job;13573.tyrone-cluster;Job Modified at request of Scheduler@tyrone-cluster
11/18/2012 10:48:11;0008;PBS_Server;Job;13986.tyrone-cluster;Job Modified at request of Scheduler@tyrone-cluster
11/18/2012 10:48:11;0008;PBS_Server;Job;13986.tyrone-cluster;Job Run at request of Scheduler@tyrone-cluster
11/18/2012 10:48:11;0040;PBS_Server;Svr;tyrone-cluster;Scheduler was sent the command recyc
11/18/2012 10:48:11;000d;PBS_Server;Job;13986.tyrone-cluster;Not sending email: User does not want mail of this type.
11/18/2012 10:48:45;0040;PBS_Server;Svr;tyrone-cluster;Scheduler was sent the command new
11/18/2012 10:48:45;0008;PBS_Server;Job;13573.tyrone-cluster;Job Modified at request of Scheduler@tyrone-cluster
11/18/2012 10:48:49;0002;PBS_Server;Svr;PBS_Server;Torque Server Version = 3.0.5, loglevel = 0
11/18/2012 10:49:20;0040;PBS_Server;Svr;tyrone-cluster;Scheduler was sent the command new
11/18/2012 10:49:52;0040;PBS_Server;Svr;tyrone-cluster;Scheduler was sent the command new
11/18/2012 10:50:25;0040;PBS_Server;Svr;tyrone-cluster;Scheduler was sent the command new
11/18/2012 10:50:52;0040;PBS_Server;Svr;tyrone-cluster;Scheduler was sent the command new
11/18/2012 10:51:22;0040;PBS_Server;Svr;tyrone-cluster;Scheduler was sent the command new
11/18/2012 10:51:55;0040;PBS_Server;Svr;tyrone-cluster;Scheduler was sent the command new
11/18/2012 10:52:30;0040;PBS_Server;Svr;tyrone-cluster;Scheduler was sent the command new
11/18/2012 10:53:05;0040;PBS_Server;Svr;tyrone-cluster;Scheduler was sent the command new
11/18/2012 10:53:37;0040;PBS_Server;Svr;tyrone-cluster;Scheduler was sent the command new
11/18/2012 10:53:49;0002;PBS_Server;Svr;PBS_Server;Torque Server Version = 3.0.5, loglevel = 0
11/18/2012 10:54:10;0040;PBS_Server;Svr;tyrone-cluster;Scheduler was sent the command new
11/18/2012 10:54:45;0040;PBS_Server;Svr;tyrone-cluster;Scheduler was sent the command new
11/18/2012 10:55:20;0040;PBS_Server;Svr;tyrone-cluster;Scheduler was sent the command new
11/18/2012 10:55:52;0040;PBS_Server;Svr;tyrone-cluster;Scheduler was sent the command new
11/18/2012 10:56:24;0040;PBS_Server;Svr;tyrone-cluster;Scheduler was sent the command new
11/18/2012 10:57:00;0040;PBS_Server;Svr;tyrone-cluster;Scheduler was sent the command new
11/18/2012 10:57:35;0040;PBS_Server;Svr;tyrone-cluster;Scheduler was sent the command new
11/18/2012 10:58:07;0040;PBS_Server;Svr;tyrone-cluster;Scheduler was sent the command new
11/18/2012 10:58:40;0040;PBS_Server;Svr;tyrone-cluster;Scheduler was sent the command new
11/18/2012 10:58:49;0002;PBS_Server;Svr;PBS_Server;Torque Server Version = 3.0.5, loglevel = 0
11/18/2012 10:58:56;0100;PBS_Server;Job;14041.tyrone-cluster;enqueuing into batch, state 1 hop 1
11/18/2012 10:58:56;0008;PBS_Server;Job;14041.tyrone-cluster;Job Queued at request of ciesita@tyrone-cluster, owner = ciesita@tyrone-cluster, job name = R=10, queue = batch
11/18/2012 10:58:56;0040;PBS_Server;Svr;tyrone-cluster;Scheduler was sent the command new
11/18/2012 10:58:56;0008;PBS_Server;Job;14041.tyrone-cluster;Job Modified at request of Scheduler@tyrone-cluster
11/18/2012 10:59:15;0040;PBS_Server;Svr;tyrone-cluster;Scheduler was sent the command new
11/18/2012 10:59:26;0040;PBS_Server;Svr;tyrone-cluster;Scheduler was sent the command new
11/18/2012 10:59:50;0040;PBS_Server;Svr;tyrone-cluster;Scheduler was sent the command new
11/18/2012 11:00:00;0040;PBS_Server;Svr;tyrone-cluster;Scheduler was sent the command new
11/18/2012 11:00:22;0040;PBS_Server;Svr;tyrone-cluster;Scheduler was sent the command new
11/18/2012 11:00:35;0040;PBS_Server;Svr;tyrone-cluster;Scheduler was sent the command new
11/18/2012 11:00:55;0040;PBS_Server;Svr;tyrone-cluster;Scheduler was sent the command new
11/18/2012 11:01:07;0040;PBS_Server;Svr;tyrone-cluster;Scheduler was sent the command new
11/18/2012 11:01:30;0040;PBS_Server;Svr;tyrone-cluster;Scheduler was sent the command new
11/18/2012 11:01:39;0040;PBS_Server;Svr;tyrone-cluster;Scheduler was sent the command new
11/18/2012 11:02:05;0040;PBS_Server;Svr;tyrone-cluster;Scheduler was sent the command new
11/18/2012 11:02:15;0040;PBS_Server;Svr;tyrone-cluster;Scheduler was sent the command new
11/18/2012 11:02:37;0040;PBS_Server;Svr;tyrone-cluster;Scheduler was sent the command new
11/18/2012 11:02:50;0040;PBS_Server;Svr;tyrone-cluster;Scheduler was sent the command new
11/18/2012 11:03:10;0040;PBS_Server;Svr;tyrone-cluster;Scheduler was sent the command new
11/18/2012 11:03:20;0040;PBS_Server;Svr;tyrone-cluster;Scheduler was sent the command new
11/18/2012 11:03:45;0040;PBS_Server;Svr;tyrone-cluster;Scheduler was sent the command new
11/18/2012 11:03:49;0002;PBS_Server;Svr;PBS_Server;Torque Server Version = 3.0.5, loglevel = 0
11/18/2012 11:03:50;0040;PBS_Server;Svr;tyrone-cluster;Scheduler was sent the command new
11/18/2012 11:04:20;0040;PBS_Server;Svr;tyrone-cluster;Scheduler was sent the command new
11/18/2012 11:04:52;0040;PBS_Server;Svr;tyrone-cluster;Scheduler was sent the command new
11/18/2012 11:05:03;0100;PBS_Server;Job;14042.tyrone-cluster;enqueuing into batch, state 1 hop 1
11/18/2012 11:05:03;0100;PBS_Server;Job;14042.tyrone-cluster;dequeuing from batch, state QUEUED
11/18/2012 11:05:03;0100;PBS_Server;Job;14042.tyrone-cluster;enqueuing into idqueue, state 1 hop 1
11/18/2012 11:05:03;0008;PBS_Server;Job;14042.tyrone-cluster;Job Queued at request of secbadar@tyrone-cluster, owner = secbadar@tyrone-cluster, job name = myjob, queue = idqueue
11/18/2012 11:05:03;0040;PBS_Server;Svr;tyrone-cluster;Scheduler was sent the command new
11/18/2012 11:05:03;0008;PBS_Server;Job;14042.tyrone-cluster;Job Modified at request of Scheduler@tyrone-cluster
11/18/2012 11:05:03;0008;PBS_Server;Job;14042.tyrone-cluster;Job Run at request of Scheduler@tyrone-cluster
11/18/2012 11:05:03;0040;PBS_Server;Svr;tyrone-cluster;Scheduler was sent the command recyc
11/18/2012 11:05:03;000d;PBS_Server;Job;14042.tyrone-cluster;Not sending email: User does not want mail of this type.
11/18/2012 11:05:25;0040;PBS_Server;Svr;tyrone-cluster;Scheduler was sent the command new
11/18/2012 11:05:57;0040;PBS_Server;Svr;tyrone-cluster;Scheduler was sent the command new
11/18/2012 11:06:15;0100;PBS_Server;Job;14043.tyrone-cluster;enqueuing into batch, state 1 hop 1
11/18/2012 11:06:15;0008;PBS_Server;Job;14043.tyrone-cluster;Job Queued at request of ciesita@tyrone-cluster, owner = ciesita@tyrone-cluster, job name = R=20, queue = batch
11/18/2012 11:06:15;0040;PBS_Server;Svr;tyrone-cluster;Scheduler was sent the command new
11/18/2012 11:06:15;0008;PBS_Server;Job;14043.tyrone-cluster;Job Modified at request of Scheduler@tyrone-cluster
11/18/2012 11:06:28;0040;PBS_Server;Svr;tyrone-cluster;Scheduler was sent the command new
11/18/2012 11:06:46;0040;PBS_Server;Svr;tyrone-cluster;Scheduler was sent the command new
11/18/2012 11:06:58;0040;PBS_Server;Svr;tyrone-cluster;Scheduler was sent the command new
11/18/2012 11:07:20;0040;PBS_Server;Svr;tyrone-cluster;Scheduler was sent the command new
11/18/2012 11:07:30;0040;PBS_Server;Svr;tyrone-cluster;Scheduler was sent the command new
11/18/2012 11:07:35;000d;PBS_Server;Job;14042.tyrone-cluster;Not sending email: User does not want mail of this type.
11/18/2012 11:07:35;0010;PBS_Server;Job;14042.tyrone-cluster;Exit_status=0 resources_used.cput=00:10:11 resources_used.mem=445448kb resources_used.vmem=1171044kb resources_used.walltime=00:02:32
11/18/2012 11:07:35;0008;PBS_Server;Job;NULL;on_job_exit valid pjob: 0x12fc270 (substate=50)
11/18/2012 11:07:35;0008;PBS_Server;Job;NULL;on_job_exit valid pjob: 0x12fc270 (substate=51)
11/18/2012 11:07:35;0008;PBS_Server;Job;NULL;on_job_exit valid pjob: 0x12fc270 (substate=51)
11/18/2012 11:07:35;0008;PBS_Server;Job;NULL;on_job_exit valid pjob: 0x12fc270 (substate=53)
11/18/2012 11:07:35;0100;PBS_Server;Job;14042.tyrone-cluster;dequeuing from idqueue, state COMPLETE
11/18/2012 11:07:35;0040;PBS_Server;Svr;tyrone-cluster;Scheduler was sent the command term
11/18/2012 11:07:52;0040;PBS_Server;Svr;tyrone-cluster;Scheduler was sent the command new
11/18/2012 11:08:05;0040;PBS_Server;Svr;tyrone-cluster;Scheduler was sent the command new
11/18/2012 11:08:25;0040;PBS_Server;Svr;tyrone-cluster;Scheduler was sent the command new
11/18/2012 11:08:37;0040;PBS_Server;Svr;tyrone-cluster;Scheduler was sent the command new
11/18/2012 11:08:49;0002;PBS_Server;Svr;PBS_Server;Torque Server Version = 3.0.5, loglevel = 0
11/18/2012 11:09:00;0040;PBS_Server;Svr;tyrone-cluster;Scheduler was sent the command new
11/18/2012 11:09:10;0040;PBS_Server;Svr;tyrone-cluster;Scheduler was sent the command new
11/18/2012 11:09:35;0040;PBS_Server;Svr;tyrone-cluster;Scheduler was sent the command new
11/18/2012 11:09:45;0040;PBS_Server;Svr;tyrone-cluster;Scheduler was sent the command new
11/18/2012 11:10:07;0040;PBS_Server;Svr;tyrone-cluster;Scheduler was sent the command new
11/18/2012 11:10:20;0040;PBS_Server;Svr;tyrone-cluster;Scheduler was sent the command new
11/18/2012 11:10:40;0040;PBS_Server;Svr;tyrone-cluster;Scheduler was sent the command new
11/18/2012 11:10:52;0040;PBS_Server;Svr;tyrone-cluster;Scheduler was sent the command new
11/18/2012 11:11:15;0040;PBS_Server;Svr;tyrone-cluster;Scheduler was sent the command new
11/18/2012 11:11:23;0040;PBS_Server;Svr;tyrone-cluster;Scheduler was sent the command new
11/18/2012 11:11:50;0040;PBS_Server;Svr;tyrone-cluster;Scheduler was sent the command new
11/18/2012 11:12:00;0040;PBS_Server;Svr;tyrone-cluster;Scheduler was sent the command new
11/18/2012 11:12:22;0040;PBS_Server;Svr;tyrone-cluster;Scheduler was sent the command new
11/18/2012 11:12:35;0040;PBS_Server;Svr;tyrone-cluster;Scheduler was sent the command new
11/18/2012 11:12:55;0040;PBS_Server;Svr;tyrone-cluster;Scheduler was sent the command new
11/18/2012 11:13:07;0040;PBS_Server;Svr;tyrone-cluster;Scheduler was sent the command new
11/18/2012 11:13:24;0040;PBS_Server;Svr;tyrone-cluster;Scheduler was sent the command new
11/18/2012 11:13:24;0100;PBS_Server;Job;14044.tyrone-cluster;enqueuing into batch, state 1 hop 1
11/18/2012 11:13:24;0100;PBS_Server;Job;14044.tyrone-cluster;dequeuing from batch, state QUEUED
11/18/2012 11:13:24;0100;PBS_Server;Job;14044.tyrone-cluster;enqueuing into idqueue, state 1 hop 1
11/18/2012 11:13:24;0008;PBS_Server;Job;14044.tyrone-cluster;Job Queued at request of secbadar@tyrone-cluster, owner = secbadar@tyrone-cluster, job name = myjob, queue = idqueue
11/18/2012 11:13:24;0008;PBS_Server;Job;14044.tyrone-cluster;Job Modified at request of Scheduler@tyrone-cluster
11/18/2012 11:13:24;0008;PBS_Server;Job;14044.tyrone-cluster;Job Run at request of Scheduler@tyrone-cluster
11/18/2012 11:13:24;0040;PBS_Server;Svr;tyrone-cluster;Scheduler was sent the command recyc
11/18/2012 11:13:24;000d;PBS_Server;Job;14044.tyrone-cluster;Not sending email: User does not want mail of this type.
11/18/2012 11:13:40;0040;PBS_Server;Svr;tyrone-cluster;Scheduler was sent the command new
11/18/2012 11:13:49;0002;PBS_Server;Svr;PBS_Server;Torque Server Version = 3.0.5, loglevel = 0
11/18/2012 11:13:58;0040;PBS_Server;Svr;tyrone-cluster;Scheduler was sent the command new
11/18/2012 11:14:15;0040;PBS_Server;Svr;tyrone-cluster;Scheduler was sent the command new
11/18/2012 11:14:31;0040;PBS_Server;Svr;tyrone-cluster;Scheduler was sent the command new
11/18/2012 11:14:50;0040;PBS_Server;Svr;tyrone-cluster;Scheduler was sent the command new
11/18/2012 11:15:00;0040;PBS_Server;Svr;tyrone-cluster;Scheduler was sent the command new
11/18/2012 11:15:22;0040;PBS_Server;Svr;tyrone-cluster;Scheduler was sent the command new
11/18/2012 11:15:35;0040;PBS_Server;Svr;tyrone-cluster;Scheduler was sent the command new
11/18/2012 11:15:55;0040;PBS_Server;Svr;tyrone-cluster;Scheduler was sent the command new
11/18/2012 11:16:07;0040;PBS_Server;Svr;tyrone-cluster;Scheduler was sent the command new
11/18/2012 11:16:30;0040;PBS_Server;Svr;tyrone-cluster;Scheduler was sent the command new
11/18/2012 11:16:40;0040;PBS_Server;Svr;tyrone-cluster;Scheduler was sent the command new
11/18/2012 11:17:05;0040;PBS_Server;Svr;tyrone-cluster;Scheduler was sent the command new
11/18/2012 11:17:15;0040;PBS_Server;Svr;tyrone-cluster;Scheduler was sent the command new
11/18/2012 11:17:37;0040;PBS_Server;Svr;tyrone-cluster;Scheduler was sent the command new
11/18/2012 11:17:50;0040;PBS_Server;Svr;tyrone-cluster;Scheduler was sent the command new
11/18/2012 11:18:09;0040;PBS_Server;Svr;tyrone-cluster;Scheduler was sent the command new
11/18/2012 11:18:22;0040;PBS_Server;Svr;tyrone-cluster;Scheduler was sent the command new
11/18/2012 11:18:45;0040;PBS_Server;Svr;tyrone-cluster;Scheduler was sent the command new
11/18/2012 11:18:49;0002;PBS_Server;Svr;PBS_Server;Torque Server Version = 3.0.5, loglevel = 0
11/18/2012 11:18:54;0040;PBS_Server;Svr;tyrone-cluster;Scheduler was sent the command new
11/18/2012 11:19:15;0040;PBS_Server;Svr;tyrone-cluster;Scheduler was sent the command new
11/18/2012 11:19:22;0040;PBS_Server;Svr;tyrone-cluster;Scheduler was sent the command new
11/18/2012 11:19:46;0040;PBS_Server;Svr;tyrone-cluster;Scheduler was sent the command new
11/18/2012 11:19:46;000d;PBS_Server;Job;13996.tyrone-cluster;Not sending email: User does not want mail of this type.
11/18/2012 11:19:46;0010;PBS_Server;Job;13996.tyrone-cluster;Exit_status=143 resources_used.cput=31:43:22 resources_used.mem=15971444kb resources_used.vmem=20780396kb resources_used.walltime=02:00:49
11/18/2012 11:19:46;0008;PBS_Server;Job;NULL;on_job_exit valid pjob: 0x13032d0 (substate=50)
11/18/2012 11:19:46;0008;PBS_Server;Job;NULL;on_job_exit valid pjob: 0x13032d0 (substate=51)
11/18/2012 11:19:46;000d;PBS_Server;Job;13998.tyrone-cluster;Not sending email: User does not want mail of this type.
11/18/2012 11:19:46;0010;PBS_Server;Job;13998.tyrone-cluster;Exit_status=143 resources_used.cput=31:57:51 resources_used.mem=15982004kb resources_used.vmem=20780392kb resources_used.walltime=02:00:49
11/18/2012 11:19:46;0008;PBS_Server;Job;NULL;on_job_exit valid pjob: 0x13416a0 (substate=50)
11/18/2012 11:19:46;0008;PBS_Server;Job;NULL;on_job_exit valid pjob: 0x13416a0 (substate=51)
11/18/2012 11:19:46;0008;PBS_Server;Job;14000.tyrone-cluster;Job Modified at request of Scheduler@tyrone-cluster
11/18/2012 11:19:46;0008;PBS_Server;Job;14000.tyrone-cluster;Job Run at request of Scheduler@tyrone-cluster
11/18/2012 11:19:46;0008;PBS_Server;Job;NULL;on_job_exit valid pjob: 0x13416a0 (substate=51)
11/18/2012 11:19:46;0008;PBS_Server;Job;NULL;on_job_exit valid pjob: 0x13032d0 (substate=51)
11/18/2012 11:19:46;0008;PBS_Server;Job;NULL;on_job_exit valid pjob: 0x13416a0 (substate=53)
11/18/2012 11:19:46;0100;PBS_Server;Job;13998.tyrone-cluster;dequeuing from idqueue, state COMPLETE
11/18/2012 11:19:46;0008;PBS_Server;Job;NULL;on_job_exit valid pjob: 0x13032d0 (substate=53)
11/18/2012 11:19:46;0100;PBS_Server;Job;13996.tyrone-cluster;dequeuing from idqueue, state COMPLETE
11/18/2012 11:19:47;0008;PBS_Server;Job;14001.tyrone-cluster;Job Modified at request of Scheduler@tyrone-cluster
11/18/2012 11:19:47;000d;PBS_Server;Job;14000.tyrone-cluster;Not sending email: User does not want mail of this type.
11/18/2012 11:19:47;0008;PBS_Server;Job;14001.tyrone-cluster;Job Run at request of Scheduler@tyrone-cluster
11/18/2012 11:19:48;000d;PBS_Server;Job;14001.tyrone-cluster;Not sending email: User does not want mail of this type.
11/18/2012 11:19:52;0040;PBS_Server;Svr;tyrone-cluster;Scheduler was sent the command new
11/18/2012 11:20:08;000d;PBS_Server;Job;14044.tyrone-cluster;Not sending email: User does not want mail of this type.
11/18/2012 11:20:08;0010;PBS_Server;Job;14044.tyrone-cluster;Exit_status=0 resources_used.cput=00:24:48 resources_used.mem=445204kb resources_used.vmem=1170900kb resources_used.walltime=00:06:31
11/18/2012 11:20:08;0008;PBS_Server;Job;NULL;on_job_exit valid pjob: 0x12fc270 (substate=50)
11/18/2012 11:20:08;0008;PBS_Server;Job;NULL;on_job_exit valid pjob: 0x12fc270 (substate=51)
11/18/2012 11:20:08;0100;PBS_Server;Job;14045.tyrone-cluster;enqueuing into batch, state 1 hop 1
11/18/2012 11:20:08;0100;PBS_Server;Job;14045.tyrone-cluster;dequeuing from batch, state QUEUED
11/18/2012 11:20:08;0100;PBS_Server;Job;14045.tyrone-cluster;enqueuing into idqueue, state 1 hop 1
11/18/2012 11:20:08;0008;PBS_Server;Job;14045.tyrone-cluster;Job Queued at request of secbadar@tyrone-cluster, owner = secbadar@tyrone-cluster, job name = myjob, queue = idqueue
11/18/2012 11:20:08;0040;PBS_Server;Svr;tyrone-cluster;Scheduler was sent the command new
11/18/2012 11:20:08;0008;PBS_Server;Job;14045.tyrone-cluster;Job Modified at request of Scheduler@tyrone-cluster
11/18/2012 11:20:08;0008;PBS_Server;Job;14045.tyrone-cluster;Job Run at request of Scheduler@tyrone-cluster
11/18/2012 11:20:08;0040;PBS_Server;Svr;tyrone-cluster;Scheduler was sent the command recyc
11/18/2012 11:20:08;000d;PBS_Server;Job;14045.tyrone-cluster;Not sending email: User does not want mail of this type.
11/18/2012 11:20:09;0008;PBS_Server;Job;NULL;on_job_exit valid pjob: 0x12fc270 (substate=51)
11/18/2012 11:20:09;0008;PBS_Server;Job;NULL;on_job_exit valid pjob: 0x12fc270 (substate=53)
11/18/2012 11:20:09;0100;PBS_Server;Job;14044.tyrone-cluster;dequeuing from idqueue, state COMPLETE
11/18/2012 11:20:09;0040;PBS_Server;Svr;tyrone-cluster;Scheduler was sent the command term
11/18/2012 11:20:16;0040;PBS_Server;Svr;tyrone-cluster;Scheduler was sent the command new
11/18/2012 11:20:23;0040;PBS_Server;Svr;tyrone-cluster;Scheduler was sent the command new
11/18/2012 11:20:50;0040;PBS_Server;Svr;tyrone-cluster;Scheduler was sent the command new
11/18/2012 11:21:00;0040;PBS_Server;Svr;tyrone-cluster;Scheduler was sent the command new
11/18/2012 11:21:22;0040;PBS_Server;Svr;tyrone-cluster;Scheduler was sent the command new
11/18/2012 11:21:35;0040;PBS_Server;Svr;tyrone-cluster;Scheduler was sent the command new
11/18/2012 11:21:54;0040;PBS_Server;Svr;tyrone-cluster;Scheduler was sent the command new
11/18/2012 11:22:07;0040;PBS_Server;Svr;tyrone-cluster;Scheduler was sent the command new
11/18/2012 11:22:19;000d;PBS_Server;Job;14045.tyrone-cluster;Not sending email: User does not want mail of this type.
11/18/2012 11:22:19;0010;PBS_Server;Job;14045.tyrone-cluster;Exit_status=0 resources_used.cput=00:04:46 resources_used.mem=424176kb resources_used.vmem=882672kb resources_used.walltime=00:02:11
11/18/2012 11:22:19;0008;PBS_Server;Job;NULL;on_job_exit valid pjob: 0x13416a0 (substate=50)
11/18/2012 11:22:19;0008;PBS_Server;Job;NULL;on_job_exit valid pjob: 0x13416a0 (substate=51)
11/18/2012 11:22:19;0008;PBS_Server;Job;NULL;on_job_exit valid pjob: 0x13416a0 (substate=51)
11/18/2012 11:22:19;0008;PBS_Server;Job;NULL;on_job_exit valid pjob: 0x13416a0 (substate=53)
11/18/2012 11:22:19;0100;PBS_Server;Job;14045.tyrone-cluster;dequeuing from idqueue, state COMPLETE
11/18/2012 11:22:19;0040;PBS_Server;Svr;tyrone-cluster;Scheduler was sent the command term
11/18/2012 11:22:30;0040;PBS_Server;Svr;tyrone-cluster;Scheduler was sent the command new
11/18/2012 11:22:39;0040;PBS_Server;Svr;tyrone-cluster;Scheduler was sent the command new
11/18/2012 11:23:05;0040;PBS_Server;Svr;tyrone-cluster;Scheduler was sent the command new
11/18/2012 11:23:15;0040;PBS_Server;Svr;tyrone-cluster;Scheduler was sent the command new
11/18/2012 11:23:19;0100;PBS_Server;Job;14046.tyrone-cluster;enqueuing into batch, state 1 hop 1
11/18/2012 11:23:19;0100;PBS_Server;Job;14046.tyrone-cluster;dequeuing from batch, state QUEUED
11/18/2012 11:23:19;0100;PBS_Server;Job;14046.tyrone-cluster;enqueuing into idqueue, state 1 hop 1
11/18/2012 11:23:19;0008;PBS_Server;Job;14046.tyrone-cluster;Job Queued at request of secbadar@tyrone-cluster, owner = secbadar@tyrone-cluster, job name = myjob, queue = idqueue
11/18/2012 11:23:19;0040;PBS_Server;Svr;tyrone-cluster;Scheduler was sent the command new
11/18/2012 11:23:19;0008;PBS_Server;Job;14046.tyrone-cluster;Job Modified at request of Scheduler@tyrone-cluster
11/18/2012 11:23:19;0008;PBS_Server;Job;14046.tyrone-cluster;Job Run at request of Scheduler@tyrone-cluster
11/18/2012 11:23:19;0040;PBS_Server;Svr;tyrone-cluster;Scheduler was sent the command recyc
11/18/2012 11:23:19;000d;PBS_Server;Job;14046.tyrone-cluster;Not sending email: User does not want mail of this type.
11/18/2012 11:23:37;0040;PBS_Server;Svr;tyrone-cluster;Scheduler was sent the command new
11/18/2012 11:23:49;0002;PBS_Server;Svr;PBS_Server;Torque Server Version = 3.0.5, loglevel = 0
11/18/2012 11:23:49;0040;PBS_Server;Svr;tyrone-cluster;Scheduler was sent the command new
11/18/2012 11:24:09;0040;PBS_Server;Svr;tyrone-cluster;Scheduler was sent the command new
11/18/2012 11:24:16;0040;PBS_Server;Svr;tyrone-cluster;Scheduler was sent the command new
11/18/2012 11:24:45;0040;PBS_Server;Svr;tyrone-cluster;Scheduler was sent the command new
11/18/2012 11:24:46;0040;PBS_Server;Svr;tyrone-cluster;Scheduler was sent the command new
11/18/2012 11:25:15;0040;PBS_Server;Svr;tyrone-cluster;Scheduler was sent the command new
11/18/2012 11:25:20;0040;PBS_Server;Svr;tyrone-cluster;Scheduler was sent the command new
11/18/2012 11:25:46;0040;PBS_Server;Svr;tyrone-cluster;Scheduler was sent the command new
11/18/2012 11:25:52;0040;PBS_Server;Svr;tyrone-cluster;Scheduler was sent the command new
11/18/2012 11:26:16;0040;PBS_Server;Svr;tyrone-cluster;Scheduler was sent the command new
11/18/2012 11:26:23;0040;PBS_Server;Svr;tyrone-cluster;Scheduler was sent the command new
11/18/2012 11:26:50;0040;PBS_Server;Svr;tyrone-cluster;Scheduler was sent the command new
11/18/2012 11:27:00;0040;PBS_Server;Svr;tyrone-cluster;Scheduler was sent the command new
11/18/2012 11:27:15;0100;PBS_Server;Job;14047.tyrone-cluster;enqueuing into batch, state 1 hop 1
11/18/2012 11:27:15;0100;PBS_Server;Job;14047.tyrone-cluster;dequeuing from batch, state QUEUED
11/18/2012 11:27:15;0100;PBS_Server;Job;14047.tyrone-cluster;enqueuing into idqueue, state 1 hop 1
11/18/2012 11:27:15;0008;PBS_Server;Job;14047.tyrone-cluster;Job Queued at request of secbadar@tyrone-cluster, owner = secbadar@tyrone-cluster, job name = myjob, queue = idqueue
11/18/2012 11:27:15;0040;PBS_Server;Svr;tyrone-cluster;Scheduler was sent the command new
11/18/2012 11:27:15;0008;PBS_Server;Job;14047.tyrone-cluster;Job Modified at request of Scheduler@tyrone-cluster
11/18/2012 11:27:15;0008;PBS_Server;Job;14047.tyrone-cluster;Job Run at request of Scheduler@tyrone-cluster
11/18/2012 11:27:16;0040;PBS_Server;Svr;tyrone-cluster;Scheduler was sent the command recyc
11/18/2012 11:27:16;000d;PBS_Server;Job;14047.tyrone-cluster;Not sending email: User does not want mail of this type.
11/18/2012 11:27:22;0040;PBS_Server;Svr;tyrone-cluster;Scheduler was sent the command new
11/18/2012 11:27:35;0040;PBS_Server;Svr;tyrone-cluster;Scheduler was sent the command new
11/18/2012 11:27:54;0040;PBS_Server;Svr;tyrone-cluster;Scheduler was sent the command new
11/18/2012 11:28:07;0040;PBS_Server;Svr;tyrone-cluster;Scheduler was sent the command new
11/18/2012 11:28:30;0040;PBS_Server;Svr;tyrone-cluster;Scheduler was sent the command new
11/18/2012 11:28:37;0040;PBS_Server;Svr;tyrone-cluster;Scheduler was sent the command new
11/18/2012 11:28:49;0002;PBS_Server;Svr;PBS_Server;Torque Server Version = 3.0.5, loglevel = 0
11/18/2012 11:29:05;0040;PBS_Server;Svr;tyrone-cluster;Scheduler was sent the command new
11/18/2012 11:29:09;0040;PBS_Server;Svr;tyrone-cluster;Scheduler was sent the command new
11/18/2012 11:29:37;0040;PBS_Server;Svr;tyrone-cluster;Scheduler was sent the command new
11/18/2012 11:29:43;0040;PBS_Server;Svr;tyrone-cluster;Scheduler was sent the command new
11/18/2012 11:30:09;0040;PBS_Server;Svr;tyrone-cluster;Scheduler was sent the command new
11/18/2012 11:30:13;0040;PBS_Server;Svr;tyrone-cluster;Scheduler was sent the command new
11/18/2012 11:30:41;0040;PBS_Server;Svr;tyrone-cluster;Scheduler was sent the command new
11/18/2012 11:30:42;000d;PBS_Server;Job;14046.tyrone-cluster;Not sending email: User does not want mail of this type.
11/18/2012 11:30:42;0010;PBS_Server;Job;14046.tyrone-cluster;Exit_status=0 resources_used.cput=00:03:46 resources_used.mem=409604kb resources_used.vmem=732320kb resources_used.walltime=00:07:22
11/18/2012 11:30:42;0008;PBS_Server;Job;NULL;on_job_exit valid pjob: 0x13416a0 (substate=50)
11/18/2012 11:30:42;0008;PBS_Server;Job;NULL;on_job_exit valid pjob: 0x13416a0 (substate=51)
11/18/2012 11:30:42;0008;PBS_Server;Job;NULL;on_job_exit valid pjob: 0x13416a0 (substate=51)
11/18/2012 11:30:42;0008;PBS_Server;Job;NULL;on_job_exit valid pjob: 0x13416a0 (substate=53)
11/18/2012 11:30:42;0100;PBS_Server;Job;14046.tyrone-cluster;dequeuing from idqueue, state COMPLETE
11/18/2012 11:30:42;0040;PBS_Server;Svr;tyrone-cluster;Scheduler was sent the command term
11/18/2012 11:30:45;0040;PBS_Server;Svr;tyrone-cluster;Scheduler was sent the command new
11/18/2012 11:31:13;0040;PBS_Server;Svr;tyrone-cluster;Scheduler was sent the command new
11/18/2012 11:31:20;0040;PBS_Server;Svr;tyrone-cluster;Scheduler was sent the command new
11/18/2012 11:31:22;000d;PBS_Server;Job;14047.tyrone-cluster;Not sending email: User does not want mail of this type.
11/18/2012 11:31:22;0010;PBS_Server;Job;14047.tyrone-cluster;Exit_status=0 resources_used.cput=00:15:03 resources_used.mem=445216kb resources_used.vmem=1170900kb resources_used.walltime=00:04:06
11/18/2012 11:31:22;0008;PBS_Server;Job;NULL;on_job_exit valid pjob: 0x12fc270 (substate=50)
11/18/2012 11:31:22;0008;PBS_Server;Job;NULL;on_job_exit valid pjob: 0x12fc270 (substate=51)
11/18/2012 11:31:22;0008;PBS_Server;Job;NULL;on_job_exit valid pjob: 0x12fc270 (substate=51)
11/18/2012 11:31:22;0008;PBS_Server;Job;NULL;on_job_exit valid pjob: 0x12fc270 (substate=53)
11/18/2012 11:31:22;0100;PBS_Server;Job;14047.tyrone-cluster;dequeuing from idqueue, state COMPLETE
11/18/2012 11:31:22;0040;PBS_Server;Svr;tyrone-cluster;Scheduler was sent the command term
11/18/2012 11:31:43;0040;PBS_Server;Svr;tyrone-cluster;Scheduler was sent the command new
11/18/2012 11:31:46;0040;PBS_Server;Svr;tyrone-cluster;Scheduler was sent the command new
11/18/2012 11:32:15;0040;PBS_Server;Svr;tyrone-cluster;Scheduler was sent the command new
11/18/2012 11:32:16;0040;PBS_Server;Svr;tyrone-cluster;Scheduler was sent the command new
11/18/2012 11:32:50;0040;PBS_Server;Svr;tyrone-cluster;Scheduler was sent the command new
11/18/2012 11:33:22;0040;PBS_Server;Svr;tyrone-cluster;Scheduler was sent the command new
11/18/2012 11:33:49;0002;PBS_Server;Svr;PBS_Server;Torque Server Version = 3.0.5, loglevel = 0
11/18/2012 11:33:54;0040;PBS_Server;Svr;tyrone-cluster;Scheduler was sent the command new
11/18/2012 11:34:30;0040;PBS_Server;Svr;tyrone-cluster;Scheduler was sent the command new
11/18/2012 11:34:35;000d;PBS_Server;Job;13520.tyrone-cluster;Not sending email: User does not want mail of this type.
11/18/2012 11:34:35;0010;PBS_Server;Job;13520.tyrone-cluster;Exit_status=0 resources_used.cput=108:58:25 resources_used.mem=12703216kb resources_used.vmem=28160500kb resources_used.walltime=16:39:25
11/18/2012 11:34:35;0008;PBS_Server;Job;NULL;on_job_exit valid pjob: 0x132ff00 (substate=50)
11/18/2012 11:34:35;0008;PBS_Server;Job;NULL;on_job_exit valid pjob: 0x132ff00 (substate=51)
11/18/2012 11:34:35;0008;PBS_Server;Job;NULL;on_job_exit valid pjob: 0x132ff00 (substate=51)
11/18/2012 11:34:35;0008;PBS_Server;Job;NULL;on_job_exit valid pjob: 0x132ff00 (substate=53)
11/18/2012 11:34:35;0100;PBS_Server;Job;13520.tyrone-cluster;dequeuing from qp64, state COMPLETE
11/18/2012 11:34:35;0040;PBS_Server;Svr;tyrone-cluster;Scheduler was sent the command term
11/18/2012 11:34:35;0008;PBS_Server;Job;13573.tyrone-cluster;Job Modified at request of Scheduler@tyrone-cluster
11/18/2012 11:34:35;0008;PBS_Server;Job;13573.tyrone-cluster;Job Run at request of Scheduler@tyrone-cluster
11/18/2012 11:34:35;0040;PBS_Server;Svr;tyrone-cluster;Scheduler was sent the command recyc
11/18/2012 11:34:35;000d;PBS_Server;Job;13573.tyrone-cluster;Not sending email: User does not want mail of this type.
11/18/2012 11:35:05;0100;PBS_Server;Job;14041.tyrone-cluster;dequeuing from batch, state QUEUED
11/18/2012 11:35:05;0100;PBS_Server;Job;14041.tyrone-cluster;enqueuing into qp64, state 1 hop 1
11/18/2012 11:35:05;0040;PBS_Server;Svr;tyrone-cluster;Scheduler was sent the command new
11/18/2012 11:35:05;0008;PBS_Server;Job;14041.tyrone-cluster;Job Modified at request of Scheduler@tyrone-cluster
11/18/2012 11:35:37;0040;PBS_Server;Svr;tyrone-cluster;Scheduler was sent the command new
11/18/2012 11:36:09;0040;PBS_Server;Svr;tyrone-cluster;Scheduler was sent the command new
11/18/2012 11:36:45;0040;PBS_Server;Svr;tyrone-cluster;Scheduler was sent the command new
11/18/2012 11:37:20;0040;PBS_Server;Svr;tyrone-cluster;Scheduler was sent the command new
11/18/2012 11:37:52;0040;PBS_Server;Svr;tyrone-cluster;Scheduler was sent the command new
11/18/2012 11:38:24;0040;PBS_Server;Svr;tyrone-cluster;Scheduler was sent the command new
11/18/2012 11:38:49;0002;PBS_Server;Svr;PBS_Server;Torque Server Version = 3.0.5, loglevel = 0
11/18/2012 11:39:00;0040;PBS_Server;Svr;tyrone-cluster;Scheduler was sent the command new
11/18/2012 11:39:35;0040;PBS_Server;Svr;tyrone-cluster;Scheduler was sent the command new
11/18/2012 11:39:56;0100;PBS_Server;Job;14048.tyrone-cluster;enqueuing into batch, state 1 hop 1
11/18/2012 11:39:56;0100;PBS_Server;Job;14048.tyrone-cluster;dequeuing from batch, state QUEUED
11/18/2012 11:39:56;0100;PBS_Server;Job;14048.tyrone-cluster;enqueuing into idqueue, state 1 hop 1
11/18/2012 11:39:56;0008;PBS_Server;Job;14048.tyrone-cluster;Job Queued at request of secbadar@tyrone-cluster, owner = secbadar@tyrone-cluster, job name = myjob, queue = idqueue
11/18/2012 11:39:56;0040;PBS_Server;Svr;tyrone-cluster;Scheduler was sent the command new
11/18/2012 11:39:56;0008;PBS_Server;Job;14048.tyrone-cluster;Job Modified at request of Scheduler@tyrone-cluster
11/18/2012 11:39:56;0008;PBS_Server;Job;14048.tyrone-cluster;Job Run at request of Scheduler@tyrone-cluster
11/18/2012 11:39:56;0040;PBS_Server;Svr;tyrone-cluster;Scheduler was sent the command recyc
11/18/2012 11:39:56;000d;PBS_Server;Job;14048.tyrone-cluster;Not sending email: User does not want mail of this type.
11/18/2012 11:40:06;0040;PBS_Server;Svr;tyrone-cluster;Scheduler was sent the command new
11/18/2012 11:40:37;0040;PBS_Server;Svr;tyrone-cluster;Scheduler was sent the command new
11/18/2012 11:41:06;0040;PBS_Server;Svr;tyrone-cluster;Scheduler was sent the command new
11/18/2012 11:41:38;0040;PBS_Server;Svr;tyrone-cluster;Scheduler was sent the command new
11/18/2012 11:42:10;0040;PBS_Server;Svr;tyrone-cluster;Scheduler was sent the command new
11/18/2012 11:42:46;0040;PBS_Server;Svr;tyrone-cluster;Scheduler was sent the command new
11/18/2012 11:43:21;0040;PBS_Server;Svr;tyrone-cluster;Scheduler was sent the command new
11/18/2012 11:43:49;0002;PBS_Server;Svr;PBS_Server;Torque Server Version = 3.0.5, loglevel = 0
11/18/2012 11:43:53;0040;PBS_Server;Svr;tyrone-cluster;Scheduler was sent the command new
11/18/2012 11:44:03;000d;PBS_Server;Job;14048.tyrone-cluster;Not sending email: User does not want mail of this type.
11/18/2012 11:44:03;0010;PBS_Server;Job;14048.tyrone-cluster;Exit_status=0 resources_used.cput=00:14:42 resources_used.mem=445184kb resources_used.vmem=1170900kb resources_used.walltime=00:04:07
11/18/2012 11:44:03;0008;PBS_Server;Job;NULL;on_job_exit valid pjob: 0x13416a0 (substate=50)
11/18/2012 11:44:03;0008;PBS_Server;Job;NULL;on_job_exit valid pjob: 0x13416a0 (substate=51)
11/18/2012 11:44:03;0008;PBS_Server;Job;NULL;on_job_exit valid pjob: 0x13416a0 (substate=51)
11/18/2012 11:44:03;0008;PBS_Server;Job;NULL;on_job_exit valid pjob: 0x13416a0 (substate=53)
11/18/2012 11:44:03;0100;PBS_Server;Job;14048.tyrone-cluster;dequeuing from idqueue, state COMPLETE
11/18/2012 11:44:03;0040;PBS_Server;Svr;tyrone-cluster;Scheduler was sent the command term
11/18/2012 11:44:07;0100;PBS_Server;Job;14049.tyrone-cluster;enqueuing into batch, state 1 hop 1
11/18/2012 11:44:07;0100;PBS_Server;Job;14049.tyrone-cluster;dequeuing from batch, state QUEUED
11/18/2012 11:44:07;0100;PBS_Server;Job;14049.tyrone-cluster;enqueuing into idqueue, state 1 hop 1
11/18/2012 11:44:07;0008;PBS_Server;Job;14049.tyrone-cluster;Job Queued at request of secbadar@tyrone-cluster, owner = secbadar@tyrone-cluster, job name = myjob, queue = idqueue
11/18/2012 11:44:07;0040;PBS_Server;Svr;tyrone-cluster;Scheduler was sent the command new
11/18/2012 11:44:07;0008;PBS_Server;Job;14049.tyrone-cluster;Job Modified at request of Scheduler@tyrone-cluster
11/18/2012 11:44:07;0008;PBS_Server;Job;14049.tyrone-cluster;Job Run at request of Scheduler@tyrone-cluster
11/18/2012 11:44:08;0040;PBS_Server;Svr;tyrone-cluster;Scheduler was sent the command recyc
11/18/2012 11:44:08;000d;PBS_Server;Job;14049.tyrone-cluster;Not sending email: User does not want mail of this type.
11/18/2012 11:44:25;0040;PBS_Server;Svr;tyrone-cluster;Scheduler was sent the command new
11/18/2012 11:44:53;0100;PBS_Server;Job;14050.tyrone-cluster;enqueuing into batch, state 1 hop 1
11/18/2012 11:44:53;0100;PBS_Server;Job;14050.tyrone-cluster;dequeuing from batch, state QUEUED
11/18/2012 11:44:53;0100;PBS_Server;Job;14050.tyrone-cluster;enqueuing into idqueue, state 1 hop 1
11/18/2012 11:44:53;0008;PBS_Server;Job;14050.tyrone-cluster;Job Queued at request of secbadar@tyrone-cluster, owner = secbadar@tyrone-cluster, job name = myjob, queue = idqueue
11/18/2012 11:44:53;0040;PBS_Server;Svr;tyrone-cluster;Scheduler was sent the command new
11/18/2012 11:44:53;0008;PBS_Server;Job;14050.tyrone-cluster;Job Modified at request of Scheduler@tyrone-cluster
11/18/2012 11:44:53;0008;PBS_Server;Job;14050.tyrone-cluster;Job Run at request of Scheduler@tyrone-cluster
11/18/2012 11:44:53;0040;PBS_Server;Svr;tyrone-cluster;Scheduler was sent the command recyc
11/18/2012 11:44:53;000d;PBS_Server;Job;14050.tyrone-cluster;Not sending email: User does not want mail of this type.
11/18/2012 11:45:01;0040;PBS_Server;Svr;tyrone-cluster;Scheduler was sent the command new
11/18/2012 11:45:36;0040;PBS_Server;Svr;tyrone-cluster;Scheduler was sent the command new
11/18/2012 11:46:08;0040;PBS_Server;Svr;tyrone-cluster;Scheduler was sent the command new
11/18/2012 11:46:39;0040;PBS_Server;Svr;tyrone-cluster;Scheduler was sent the command new
11/18/2012 11:46:39;0100;PBS_Server;Job;14051.tyrone-cluster;enqueuing into batch, state 1 hop 1
11/18/2012 11:46:39;0100;PBS_Server;Job;14051.tyrone-cluster;dequeuing from batch, state QUEUED
11/18/2012 11:46:39;0100;PBS_Server;Job;14051.tyrone-cluster;enqueuing into idqueue, state 1 hop 1
11/18/2012 11:46:39;0008;PBS_Server;Job;14051.tyrone-cluster;Job Queued at request of secbadar@tyrone-cluster, owner = secbadar@tyrone-cluster, job name = myjob, queue = idqueue
11/18/2012 11:46:39;0008;PBS_Server;Job;14051.tyrone-cluster;Job Modified at request of Scheduler@tyrone-cluster
11/18/2012 11:47:16;0040;PBS_Server;Svr;tyrone-cluster;Scheduler was sent the command new
11/18/2012 11:47:22;000d;PBS_Server;Job;14050.tyrone-cluster;Not sending email: User does not want mail of this type.
11/18/2012 11:47:22;0010;PBS_Server;Job;14050.tyrone-cluster;Exit_status=0 resources_used.cput=00:04:30 resources_used.mem=424160kb resources_used.vmem=882672kb resources_used.walltime=00:02:29
11/18/2012 11:47:22;0008;PBS_Server;Job;NULL;on_job_exit valid pjob: 0x12fc270 (substate=50)
11/18/2012 11:47:22;0008;PBS_Server;Job;NULL;on_job_exit valid pjob: 0x12fc270 (substate=51)
11/18/2012 11:47:22;0008;PBS_Server;Job;NULL;on_job_exit valid pjob: 0x12fc270 (substate=51)
11/18/2012 11:47:22;0008;PBS_Server;Job;NULL;on_job_exit valid pjob: 0x12fc270 (substate=53)
11/18/2012 11:47:22;0100;PBS_Server;Job;14050.tyrone-cluster;dequeuing from idqueue, state COMPLETE
11/18/2012 11:47:22;0040;PBS_Server;Svr;tyrone-cluster;Scheduler was sent the command term
11/18/2012 11:47:22;0008;PBS_Server;Job;14051.tyrone-cluster;Job Modified at request of Scheduler@tyrone-cluster
11/18/2012 11:47:22;0008;PBS_Server;Job;14051.tyrone-cluster;Job Run at request of Scheduler@tyrone-cluster
11/18/2012 11:47:22;0040;PBS_Server;Svr;tyrone-cluster;Scheduler was sent the command recyc
11/18/2012 11:47:22;000d;PBS_Server;Job;14051.tyrone-cluster;Not sending email: User does not want mail of this type.
11/18/2012 11:47:51;0040;PBS_Server;Svr;tyrone-cluster;Scheduler was sent the command new
11/18/2012 11:48:23;0040;PBS_Server;Svr;tyrone-cluster;Scheduler was sent the command new
11/18/2012 11:48:49;0002;PBS_Server;Svr;PBS_Server;Torque Server Version = 3.0.5, loglevel = 0
11/18/2012 11:48:55;0040;PBS_Server;Svr;tyrone-cluster;Scheduler was sent the command new
11/18/2012 11:49:31;0040;PBS_Server;Svr;tyrone-cluster;Scheduler was sent the command new
11/18/2012 11:50:01;0040;PBS_Server;Svr;tyrone-cluster;Scheduler was sent the command new
11/18/2012 11:50:31;0040;PBS_Server;Svr;tyrone-cluster;Scheduler was sent the command new
11/18/2012 11:51:01;0040;PBS_Server;Svr;tyrone-cluster;Scheduler was sent the command new
11/18/2012 11:51:36;0040;PBS_Server;Svr;tyrone-cluster;Scheduler was sent the command new
11/18/2012 11:52:04;000d;PBS_Server;Job;14049.tyrone-cluster;Not sending email: User does not want mail of this type.
11/18/2012 11:52:04;0010;PBS_Server;Job;14049.tyrone-cluster;Exit_status=0 resources_used.cput=00:03:43 resources_used.mem=409608kb resources_used.vmem=732320kb resources_used.walltime=00:07:57
11/18/2012 11:52:04;0008;PBS_Server;Job;NULL;on_job_exit valid pjob: 0x13416a0 (substate=50)
11/18/2012 11:52:04;0008;PBS_Server;Job;NULL;on_job_exit valid pjob: 0x13416a0 (substate=51)
11/18/2012 11:52:05;0008;PBS_Server;Job;NULL;on_job_exit valid pjob: 0x13416a0 (substate=51)
11/18/2012 11:52:05;0008;PBS_Server;Job;NULL;on_job_exit valid pjob: 0x13416a0 (substate=53)
11/18/2012 11:52:05;0100;PBS_Server;Job;14049.tyrone-cluster;dequeuing from idqueue, state COMPLETE
11/18/2012 11:52:05;0040;PBS_Server;Svr;tyrone-cluster;Scheduler was sent the command term
11/18/2012 11:52:08;0040;PBS_Server;Svr;tyrone-cluster;Scheduler was sent the command new
11/18/2012 11:52:40;0040;PBS_Server;Svr;tyrone-cluster;Scheduler was sent the command new
11/18/2012 11:53:16;0040;PBS_Server;Svr;tyrone-cluster;Scheduler was sent the command new
11/18/2012 11:53:47;0040;PBS_Server;Svr;tyrone-cluster;Scheduler was sent the command new
11/18/2012 11:53:49;0002;PBS_Server;Svr;PBS_Server;Torque Server Version = 3.0.5, loglevel = 0
11/18/2012 11:54:17;0040;PBS_Server;Svr;tyrone-cluster;Scheduler was sent the command new
11/18/2012 11:54:47;0040;PBS_Server;Svr;tyrone-cluster;Scheduler was sent the command new
11/18/2012 11:55:21;0040;PBS_Server;Svr;tyrone-cluster;Scheduler was sent the command new
11/18/2012 11:55:53;0040;PBS_Server;Svr;tyrone-cluster;Scheduler was sent the command new
11/18/2012 11:56:25;0040;PBS_Server;Svr;tyrone-cluster;Scheduler was sent the command new
11/18/2012 11:57:01;0040;PBS_Server;Svr;tyrone-cluster;Scheduler was sent the command new
11/18/2012 11:57:36;0040;PBS_Server;Svr;tyrone-cluster;Scheduler was sent the command new
11/18/2012 11:57:48;0100;PBS_Server;Job;14052.tyrone-cluster;enqueuing into batch, state 1 hop 1
11/18/2012 11:57:48;0100;PBS_Server;Job;14052.tyrone-cluster;dequeuing from batch, state QUEUED
11/18/2012 11:57:48;0100;PBS_Server;Job;14052.tyrone-cluster;enqueuing into idqueue, state 1 hop 1
11/18/2012 11:57:48;0008;PBS_Server;Job;14052.tyrone-cluster;Job Queued at request of secbadar@tyrone-cluster, owner = secbadar@tyrone-cluster, job name = myjob, queue = idqueue
11/18/2012 11:57:48;0040;PBS_Server;Svr;tyrone-cluster;Scheduler was sent the command new
11/18/2012 11:57:48;0008;PBS_Server;Job;14052.tyrone-cluster;Job Modified at request of Scheduler@tyrone-cluster
11/18/2012 11:57:48;0008;PBS_Server;Job;14052.tyrone-cluster;Job Run at request of Scheduler@tyrone-cluster
11/18/2012 11:57:48;0040;PBS_Server;Svr;tyrone-cluster;Scheduler was sent the command recyc
11/18/2012 11:57:48;000d;PBS_Server;Job;14052.tyrone-cluster;Not sending email: User does not want mail of this type.
11/18/2012 11:58:08;0040;PBS_Server;Svr;tyrone-cluster;Scheduler was sent the command new
11/18/2012 11:58:40;0040;PBS_Server;Svr;tyrone-cluster;Scheduler was sent the command new
11/18/2012 11:58:49;0002;PBS_Server;Svr;PBS_Server;Torque Server Version = 3.0.5, loglevel = 0
11/18/2012 11:59:16;0040;PBS_Server;Svr;tyrone-cluster;Scheduler was sent the command new
11/18/2012 11:59:51;0040;PBS_Server;Svr;tyrone-cluster;Scheduler was sent the command new
11/18/2012 12:00:23;0040;PBS_Server;Svr;tyrone-cluster;Scheduler was sent the command new
11/18/2012 12:00:55;0040;PBS_Server;Svr;tyrone-cluster;Scheduler was sent the command new
11/18/2012 12:01:31;0040;PBS_Server;Svr;tyrone-cluster;Scheduler was sent the command new
11/18/2012 12:01:41;0008;PBS_Server;Job;13599.tyrone-cluster;Job deleted at request of csdsuben@tyrone-cluster
11/18/2012 12:01:41;0008;PBS_Server;Job;13599.tyrone-cluster;Job sent signal SIGTERM on delete
11/18/2012 12:01:42;0008;PBS_Server;Job;13599.tyrone-cluster;Job deleted at request of csdsuben@tyrone-cluster
11/18/2012 12:01:42;0008;PBS_Server;Job;13599.tyrone-cluster;Job sent signal SIGTERM on delete
11/18/2012 12:01:43;0008;PBS_Server;Job;13599.tyrone-cluster;Job sent signal SIGKILL on delete
11/18/2012 12:01:47;000d;PBS_Server;Job;13599.tyrone-cluster;Not sending email: User does not want mail of this type.
11/18/2012 12:01:47;0010;PBS_Server;Job;13599.tyrone-cluster;Exit_status=143 resources_used.cput=81:21:52 resources_used.mem=5378484kb resources_used.vmem=10303136kb resources_used.walltime=02:42:47
11/18/2012 12:01:47;0008;PBS_Server;Job;NULL;on_job_exit valid pjob: 0x12fe5e0 (substate=50)
11/18/2012 12:01:47;0008;PBS_Server;Job;NULL;on_job_exit valid pjob: 0x12fe5e0 (substate=51)
11/18/2012 12:01:52;0008;PBS_Server;Job;NULL;on_job_exit valid pjob: 0x12fe5e0 (substate=51)
11/18/2012 12:01:52;0008;PBS_Server;Job;NULL;on_job_exit valid pjob: 0x12fe5e0 (substate=53)
11/18/2012 12:01:52;0100;PBS_Server;Job;13599.tyrone-cluster;dequeuing from qp32, state COMPLETE
11/18/2012 12:01:52;0040;PBS_Server;Svr;tyrone-cluster;Scheduler was sent the command term
11/18/2012 12:01:52;0008;PBS_Server;Job;13808.tyrone-cluster;Job Modified at request of Scheduler@tyrone-cluster
11/18/2012 12:01:52;0008;PBS_Server;Job;13808.tyrone-cluster;Job Run at request of Scheduler@tyrone-cluster
11/18/2012 12:01:52;0040;PBS_Server;Svr;tyrone-cluster;Scheduler was sent the command recyc
11/18/2012 12:01:52;000d;PBS_Server;Job;13808.tyrone-cluster;Not sending email: User does not want mail of this type.
11/18/2012 12:02:06;0100;PBS_Server;Job;13995.tyrone-cluster;dequeuing from batch, state QUEUED
11/18/2012 12:02:06;0100;PBS_Server;Job;13995.tyrone-cluster;enqueuing into qp32, state 1 hop 1
11/18/2012 12:02:06;0040;PBS_Server;Svr;tyrone-cluster;Scheduler was sent the command new
11/18/2012 12:02:07;0008;PBS_Server;Job;13995.tyrone-cluster;Job Modified at request of Scheduler@tyrone-cluster
11/18/2012 12:02:38;0040;PBS_Server;Svr;tyrone-cluster;Scheduler was sent the command new
11/18/2012 12:03:10;0040;PBS_Server;Svr;tyrone-cluster;Scheduler was sent the command new
11/18/2012 12:03:45;0040;PBS_Server;Svr;tyrone-cluster;Scheduler was sent the command new
11/18/2012 12:03:49;0002;PBS_Server;Svr;PBS_Server;Torque Server Version = 3.0.5, loglevel = 0
11/18/2012 12:04:14;0040;PBS_Server;Svr;tyrone-cluster;Scheduler was sent the command new
11/18/2012 12:04:46;0040;PBS_Server;Svr;tyrone-cluster;Scheduler was sent the command new
11/18/2012 12:05:16;0040;PBS_Server;Svr;tyrone-cluster;Scheduler was sent the command new
11/18/2012 12:05:51;0040;PBS_Server;Svr;tyrone-cluster;Scheduler was sent the command new
11/18/2012 12:06:23;0040;PBS_Server;Svr;tyrone-cluster;Scheduler was sent the command new
11/18/2012 12:06:55;0040;PBS_Server;Svr;tyrone-cluster;Scheduler was sent the command new
11/18/2012 12:07:31;0040;PBS_Server;Svr;tyrone-cluster;Scheduler was sent the command new
11/18/2012 12:08:06;0040;PBS_Server;Svr;tyrone-cluster;Scheduler was sent the command new
11/18/2012 12:08:38;0040;PBS_Server;Svr;tyrone-cluster;Scheduler was sent the command new
11/18/2012 12:08:49;0002;PBS_Server;Svr;PBS_Server;Torque Server Version = 3.0.5, loglevel = 0
11/18/2012 12:09:04;0100;PBS_Server;Job;14053.tyrone-cluster;enqueuing into batch, state 1 hop 1
11/18/2012 12:09:04;0100;PBS_Server;Job;14053.tyrone-cluster;dequeuing from batch, state QUEUED
11/18/2012 12:09:04;0100;PBS_Server;Job;14053.tyrone-cluster;enqueuing into idqueue, state 1 hop 1
11/18/2012 12:09:04;0008;PBS_Server;Job;14053.tyrone-cluster;Job Queued at request of secbadar@tyrone-cluster, owner = secbadar@tyrone-cluster, job name = myjob, queue = idqueue
11/18/2012 12:09:04;0040;PBS_Server;Svr;tyrone-cluster;Scheduler was sent the command new
11/18/2012 12:09:04;0008;PBS_Server;Job;14053.tyrone-cluster;Job Modified at request of Scheduler@tyrone-cluster
11/18/2012 12:09:10;0040;PBS_Server;Svr;tyrone-cluster;Scheduler was sent the command new
11/18/2012 12:09:46;0040;PBS_Server;Svr;tyrone-cluster;Scheduler was sent the command new
11/18/2012 12:10:21;0040;PBS_Server;Svr;tyrone-cluster;Scheduler was sent the command new
11/18/2012 12:10:53;0040;PBS_Server;Svr;tyrone-cluster;Scheduler was sent the command new
11/18/2012 12:11:25;0040;PBS_Server;Svr;tyrone-cluster;Scheduler was sent the command new
11/18/2012 12:12:00;0040;PBS_Server;Svr;tyrone-cluster;Scheduler was sent the command new
11/18/2012 12:12:35;0040;PBS_Server;Svr;tyrone-cluster;Scheduler was sent the command new
11/18/2012 12:13:05;0040;PBS_Server;Svr;tyrone-cluster;Scheduler was sent the command new
11/18/2012 12:13:35;0040;PBS_Server;Svr;tyrone-cluster;Scheduler was sent the command new
11/18/2012 12:13:45;0008;PBS_Server;Job;14052.tyrone-cluster;Job deleted at request of secbadar@tyrone-cluster
11/18/2012 12:13:45;0008;PBS_Server;Job;14052.tyrone-cluster;Job sent signal SIGTERM on delete
11/18/2012 12:13:45;000d;PBS_Server;Job;14052.tyrone-cluster;Not sending email: User does not want mail of this type.
11/18/2012 12:13:45;0010;PBS_Server;Job;14052.tyrone-cluster;Exit_status=143 resources_used.cput=02:34:16 resources_used.mem=616996kb resources_used.vmem=6426148kb resources_used.walltime=00:15:57
11/18/2012 12:13:45;0008;PBS_Server;Job;NULL;on_job_exit valid pjob: 0x13416a0 (substate=50)
11/18/2012 12:13:45;0008;PBS_Server;Job;NULL;on_job_exit valid pjob: 0x13416a0 (substate=51)
11/18/2012 12:13:46;0008;PBS_Server;Job;NULL;on_job_exit valid pjob: 0x13416a0 (substate=51)
11/18/2012 12:13:46;0008;PBS_Server;Job;NULL;on_job_exit valid pjob: 0x13416a0 (substate=53)
11/18/2012 12:13:46;0100;PBS_Server;Job;14052.tyrone-cluster;dequeuing from idqueue, state COMPLETE
11/18/2012 12:13:46;0040;PBS_Server;Svr;tyrone-cluster;Scheduler was sent the command term
11/18/2012 12:13:46;0008;PBS_Server;Job;14053.tyrone-cluster;Job Modified at request of Scheduler@tyrone-cluster
11/18/2012 12:13:46;0008;PBS_Server;Job;14053.tyrone-cluster;Job Run at request of Scheduler@tyrone-cluster
11/18/2012 12:13:46;0040;PBS_Server;Svr;tyrone-cluster;Scheduler was sent the command recyc
11/18/2012 12:13:46;000d;PBS_Server;Job;14053.tyrone-cluster;Not sending email: User does not want mail of this type.
11/18/2012 12:13:49;0002;PBS_Server;Svr;PBS_Server;Torque Server Version = 3.0.5, loglevel = 0
11/18/2012 12:14:06;0040;PBS_Server;Svr;tyrone-cluster;Scheduler was sent the command new
11/18/2012 12:14:36;0040;PBS_Server;Svr;tyrone-cluster;Scheduler was sent the command new
11/18/2012 12:15:06;0040;PBS_Server;Svr;tyrone-cluster;Scheduler was sent the command new
11/18/2012 12:15:36;0040;PBS_Server;Svr;tyrone-cluster;Scheduler was sent the command new
11/18/2012 12:16:06;0040;PBS_Server;Svr;tyrone-cluster;Scheduler was sent the command new
11/18/2012 12:16:37;0040;PBS_Server;Svr;tyrone-cluster;Scheduler was sent the command new
11/18/2012 12:17:08;0040;PBS_Server;Svr;tyrone-cluster;Scheduler was sent the command new
11/18/2012 12:17:13;000d;PBS_Server;Job;14053.tyrone-cluster;Not sending email: User does not want mail of this type.
11/18/2012 12:17:13;0010;PBS_Server;Job;14053.tyrone-cluster;Exit_status=0 resources_used.cput=00:05:31 resources_used.mem=452076kb resources_used.vmem=910852kb resources_used.walltime=00:03:27
11/18/2012 12:17:13;0008;PBS_Server;Job;NULL;on_job_exit valid pjob: 0x12fe5e0 (substate=50)
11/18/2012 12:17:13;0008;PBS_Server;Job;NULL;on_job_exit valid pjob: 0x12fe5e0 (substate=51)
11/18/2012 12:17:13;0008;PBS_Server;Job;NULL;on_job_exit valid pjob: 0x12fe5e0 (substate=51)
11/18/2012 12:17:13;0008;PBS_Server;Job;NULL;on_job_exit valid pjob: 0x12fe5e0 (substate=53)
11/18/2012 12:17:13;0100;PBS_Server;Job;14053.tyrone-cluster;dequeuing from idqueue, state COMPLETE
11/18/2012 12:17:13;0040;PBS_Server;Svr;tyrone-cluster;Scheduler was sent the command term
11/18/2012 12:17:38;0040;PBS_Server;Svr;tyrone-cluster;Scheduler was sent the command new
11/18/2012 12:17:49;0100;PBS_Server;Job;14054.tyrone-cluster;enqueuing into batch, state 1 hop 1
11/18/2012 12:17:49;0100;PBS_Server;Job;14054.tyrone-cluster;dequeuing from batch, state QUEUED
11/18/2012 12:17:49;0100;PBS_Server;Job;14054.tyrone-cluster;enqueuing into qp32, state 1 hop 1
11/18/2012 12:17:49;0008;PBS_Server;Job;14054.tyrone-cluster;Job Queued at request of cheaslam@tyrone-cluster, owner = cheaslam@tyrone-cluster, job name = script_1000_RTSBI, queue = qp32
11/18/2012 12:17:49;0040;PBS_Server;Svr;tyrone-cluster;Scheduler was sent the command new
11/18/2012 12:17:49;0008;PBS_Server;Job;14054.tyrone-cluster;Job Modified at request of Scheduler@tyrone-cluster
11/18/2012 12:18:10;0040;PBS_Server;Svr;tyrone-cluster;Scheduler was sent the command new
11/18/2012 12:18:45;0040;PBS_Server;Svr;tyrone-cluster;Scheduler was sent the command new
11/18/2012 12:18:49;0002;PBS_Server;Svr;PBS_Server;Torque Server Version = 3.0.5, loglevel = 0
11/18/2012 12:19:14;0040;PBS_Server;Svr;tyrone-cluster;Scheduler was sent the command new
11/18/2012 12:19:46;0040;PBS_Server;Svr;tyrone-cluster;Scheduler was sent the command new
11/18/2012 12:20:16;0040;PBS_Server;Svr;tyrone-cluster;Scheduler was sent the command new
11/18/2012 12:20:51;0040;PBS_Server;Svr;tyrone-cluster;Scheduler was sent the command new
11/18/2012 12:21:23;0040;PBS_Server;Svr;tyrone-cluster;Scheduler was sent the command new
11/18/2012 12:21:41;0100;PBS_Server;Job;14055.tyrone-cluster;enqueuing into batch, state 1 hop 1
11/18/2012 12:21:41;0100;PBS_Server;Job;14055.tyrone-cluster;dequeuing from batch, state QUEUED
11/18/2012 12:21:41;0100;PBS_Server;Job;14055.tyrone-cluster;enqueuing into idqueue, state 1 hop 1
11/18/2012 12:21:41;0008;PBS_Server;Job;14055.tyrone-cluster;Job Queued at request of secbadar@tyrone-cluster, owner = secbadar@tyrone-cluster, job name = myjob, queue = idqueue
11/18/2012 12:21:41;0040;PBS_Server;Svr;tyrone-cluster;Scheduler was sent the command new
11/18/2012 12:21:41;0008;PBS_Server;Job;14055.tyrone-cluster;Job Modified at request of Scheduler@tyrone-cluster
11/18/2012 12:21:41;0008;PBS_Server;Job;14055.tyrone-cluster;Job Run at request of Scheduler@tyrone-cluster
11/18/2012 12:21:41;0040;PBS_Server;Svr;tyrone-cluster;Scheduler was sent the command recyc
11/18/2012 12:21:41;000d;PBS_Server;Job;14055.tyrone-cluster;Not sending email: User does not want mail of this type.
11/18/2012 12:21:55;0040;PBS_Server;Svr;tyrone-cluster;Scheduler was sent the command new
11/18/2012 12:22:31;0040;PBS_Server;Svr;tyrone-cluster;Scheduler was sent the command new
11/18/2012 12:22:33;000d;PBS_Server;Job;14051.tyrone-cluster;Not sending email: User does not want mail of this type.
11/18/2012 12:22:33;0010;PBS_Server;Job;14051.tyrone-cluster;Exit_status=0 resources_used.cput=02:38:41 resources_used.mem=468460kb resources_used.vmem=1582624kb resources_used.walltime=00:35:11
11/18/2012 12:22:33;0008;PBS_Server;Job;NULL;on_job_exit valid pjob: 0x132ff00 (substate=50)
11/18/2012 12:22:33;0008;PBS_Server;Job;NULL;on_job_exit valid pjob: 0x132ff00 (substate=51)
11/18/2012 12:22:33;0008;PBS_Server;Job;NULL;on_job_exit valid pjob: 0x132ff00 (substate=51)
11/18/2012 12:22:33;0008;PBS_Server;Job;NULL;on_job_exit valid pjob: 0x132ff00 (substate=53)
11/18/2012 12:22:33;0100;PBS_Server;Job;14051.tyrone-cluster;dequeuing from idqueue, state COMPLETE
11/18/2012 12:22:33;0040;PBS_Server;Svr;tyrone-cluster;Scheduler was sent the command term
11/18/2012 12:23:06;0040;PBS_Server;Svr;tyrone-cluster;Scheduler was sent the command new
11/18/2012 12:23:38;0040;PBS_Server;Svr;tyrone-cluster;Scheduler was sent the command new
11/18/2012 12:23:49;0002;PBS_Server;Svr;PBS_Server;Torque Server Version = 3.0.5, loglevel = 0
11/18/2012 12:24:10;0040;PBS_Server;Svr;tyrone-cluster;Scheduler was sent the command new
11/18/2012 12:24:38;000d;PBS_Server;Job;14055.tyrone-cluster;Not sending email: User does not want mail of this type.
11/18/2012 12:24:38;0010;PBS_Server;Job;14055.tyrone-cluster;Exit_status=0 resources_used.cput=00:10:33 resources_used.mem=509800kb resources_used.vmem=1235764kb resources_used.walltime=00:02:57
11/18/2012 12:24:38;0008;PBS_Server;Job;NULL;on_job_exit valid pjob: 0x13416a0 (substate=50)
11/18/2012 12:24:38;0008;PBS_Server;Job;NULL;on_job_exit valid pjob: 0x13416a0 (substate=51)
11/18/2012 12:24:38;0008;PBS_Server;Job;NULL;on_job_exit valid pjob: 0x13416a0 (substate=51)
11/18/2012 12:24:38;0008;PBS_Server;Job;NULL;on_job_exit valid pjob: 0x13416a0 (substate=53)
11/18/2012 12:24:38;0100;PBS_Server;Job;14055.tyrone-cluster;dequeuing from idqueue, state COMPLETE
11/18/2012 12:24:38;0040;PBS_Server;Svr;tyrone-cluster;Scheduler was sent the command term
11/18/2012 12:24:45;0040;PBS_Server;Svr;tyrone-cluster;Scheduler was sent the command new
11/18/2012 12:25:21;0040;PBS_Server;Svr;tyrone-cluster;Scheduler was sent the command new
11/18/2012 12:25:53;0040;PBS_Server;Svr;tyrone-cluster;Scheduler was sent the command new
11/18/2012 12:26:25;0040;PBS_Server;Svr;tyrone-cluster;Scheduler was sent the command new
11/18/2012 12:27:01;0040;PBS_Server;Svr;tyrone-cluster;Scheduler was sent the command new
11/18/2012 12:27:33;0040;PBS_Server;Svr;tyrone-cluster;Scheduler was sent the command new
11/18/2012 12:27:33;0100;PBS_Server;Job;14056.tyrone-cluster;enqueuing into batch, state 1 hop 1
11/18/2012 12:27:33;0100;PBS_Server;Job;14056.tyrone-cluster;dequeuing from batch, state QUEUED
11/18/2012 12:27:33;0100;PBS_Server;Job;14056.tyrone-cluster;enqueuing into idqueue, state 1 hop 1
11/18/2012 12:27:33;0008;PBS_Server;Job;14056.tyrone-cluster;Job Queued at request of secbadar@tyrone-cluster, owner = secbadar@tyrone-cluster, job name = myjob, queue = idqueue
11/18/2012 12:27:33;0008;PBS_Server;Job;14056.tyrone-cluster;Job Modified at request of Scheduler@tyrone-cluster
11/18/2012 12:27:33;0008;PBS_Server;Job;14056.tyrone-cluster;Job Run at request of Scheduler@tyrone-cluster
11/18/2012 12:27:33;0040;PBS_Server;Svr;tyrone-cluster;Scheduler was sent the command recyc
11/18/2012 12:27:33;000d;PBS_Server;Job;14056.tyrone-cluster;Not sending email: User does not want mail of this type.
11/18/2012 12:28:05;0040;PBS_Server;Svr;tyrone-cluster;Scheduler was sent the command new
11/18/2012 12:28:18;0100;PBS_Server;Job;14057.tyrone-cluster;enqueuing into batch, state 1 hop 1
11/18/2012 12:28:18;0100;PBS_Server;Job;14057.tyrone-cluster;dequeuing from batch, state QUEUED
11/18/2012 12:28:18;0100;PBS_Server;Job;14057.tyrone-cluster;enqueuing into idqueue, state 1 hop 1
11/18/2012 12:28:18;0008;PBS_Server;Job;14057.tyrone-cluster;Job Queued at request of secbadar@tyrone-cluster, owner = secbadar@tyrone-cluster, job name = myjob, queue = idqueue
11/18/2012 12:28:18;0040;PBS_Server;Svr;tyrone-cluster;Scheduler was sent the command new
11/18/2012 12:28:18;0008;PBS_Server;Job;14057.tyrone-cluster;Job Modified at request of Scheduler@tyrone-cluster
11/18/2012 12:28:18;0008;PBS_Server;Job;14057.tyrone-cluster;Job Run at request of Scheduler@tyrone-cluster
11/18/2012 12:28:19;0040;PBS_Server;Svr;tyrone-cluster;Scheduler was sent the command recyc
11/18/2012 12:28:19;000d;PBS_Server;Job;14057.tyrone-cluster;Not sending email: User does not want mail of this type.
11/18/2012 12:28:35;0040;PBS_Server;Svr;tyrone-cluster;Scheduler was sent the command new
11/18/2012 12:28:49;0002;PBS_Server;Svr;PBS_Server;Torque Server Version = 3.0.5, loglevel = 0
11/18/2012 12:29:06;0040;PBS_Server;Svr;tyrone-cluster;Scheduler was sent the command new
11/18/2012 12:29:38;0040;PBS_Server;Svr;tyrone-cluster;Scheduler was sent the command new
11/18/2012 12:30:10;0040;PBS_Server;Svr;tyrone-cluster;Scheduler was sent the command new
11/18/2012 12:30:42;0040;PBS_Server;Svr;tyrone-cluster;Scheduler was sent the command new
11/18/2012 12:30:42;000d;PBS_Server;Job;14056.tyrone-cluster;Not sending email: User does not want mail of this type.
11/18/2012 12:30:42;0010;PBS_Server;Job;14056.tyrone-cluster;Exit_status=0 resources_used.cput=00:06:02 resources_used.mem=452060kb resources_used.vmem=910852kb resources_used.walltime=00:03:09
11/18/2012 12:30:42;0008;PBS_Server;Job;NULL;on_job_exit valid pjob: 0x13416a0 (substate=50)
11/18/2012 12:30:42;0008;PBS_Server;Job;NULL;on_job_exit valid pjob: 0x13416a0 (substate=51)
11/18/2012 12:30:43;0008;PBS_Server;Job;NULL;on_job_exit valid pjob: 0x13416a0 (substate=51)
11/18/2012 12:30:43;0008;PBS_Server;Job;NULL;on_job_exit valid pjob: 0x13416a0 (substate=53)
11/18/2012 12:30:43;0100;PBS_Server;Job;14056.tyrone-cluster;dequeuing from idqueue, state COMPLETE
11/18/2012 12:30:43;0040;PBS_Server;Svr;tyrone-cluster;Scheduler was sent the command term
11/18/2012 12:31:14;0040;PBS_Server;Svr;tyrone-cluster;Scheduler was sent the command new
11/18/2012 12:31:47;0040;PBS_Server;Svr;tyrone-cluster;Scheduler was sent the command new
11/18/2012 12:32:16;0100;PBS_Server;Job;14058.tyrone-cluster;enqueuing into batch, state 1 hop 1
11/18/2012 12:32:16;0100;PBS_Server;Job;14058.tyrone-cluster;dequeuing from batch, state QUEUED
11/18/2012 12:32:16;0100;PBS_Server;Job;14058.tyrone-cluster;enqueuing into idqueue, state 1 hop 1
11/18/2012 12:32:16;0008;PBS_Server;Job;14058.tyrone-cluster;Job Queued at request of secbadar@tyrone-cluster, owner = secbadar@tyrone-cluster, job name = myjob, queue = idqueue
11/18/2012 12:32:16;0040;PBS_Server;Svr;tyrone-cluster;Scheduler was sent the command new
11/18/2012 12:32:16;0008;PBS_Server;Job;14058.tyrone-cluster;Job Modified at request of Scheduler@tyrone-cluster
11/18/2012 12:32:16;0008;PBS_Server;Job;14058.tyrone-cluster;Job Run at request of Scheduler@tyrone-cluster
11/18/2012 12:32:17;0040;PBS_Server;Svr;tyrone-cluster;Scheduler was sent the command recyc
11/18/2012 12:32:17;000d;PBS_Server;Job;14058.tyrone-cluster;Not sending email: User does not want mail of this type.
11/18/2012 12:32:51;0040;PBS_Server;Svr;tyrone-cluster;Scheduler was sent the command new
11/18/2012 12:33:23;0040;PBS_Server;Svr;tyrone-cluster;Scheduler was sent the command new
11/18/2012 12:33:49;0002;PBS_Server;Svr;PBS_Server;Torque Server Version = 3.0.5, loglevel = 0
11/18/2012 12:33:55;0040;PBS_Server;Svr;tyrone-cluster;Scheduler was sent the command new
11/18/2012 12:34:26;0040;PBS_Server;Svr;tyrone-cluster;Scheduler was sent the command new
11/18/2012 12:34:59;0040;PBS_Server;Svr;tyrone-cluster;Scheduler was sent the command new
11/18/2012 12:34:59;000d;PBS_Server;Job;14058.tyrone-cluster;Not sending email: User does not want mail of this type.
11/18/2012 12:34:59;0010;PBS_Server;Job;14058.tyrone-cluster;Exit_status=0 resources_used.cput=00:13:41 resources_used.mem=569784kb resources_used.vmem=1685156kb resources_used.walltime=00:02:43
11/18/2012 12:34:59;0008;PBS_Server;Job;NULL;on_job_exit valid pjob: 0x13416a0 (substate=50)
11/18/2012 12:34:59;0008;PBS_Server;Job;NULL;on_job_exit valid pjob: 0x13416a0 (substate=51)
11/18/2012 12:34:59;0008;PBS_Server;Job;NULL;on_job_exit valid pjob: 0x13416a0 (substate=51)
11/18/2012 12:34:59;0008;PBS_Server;Job;NULL;on_job_exit valid pjob: 0x13416a0 (substate=53)
11/18/2012 12:34:59;0100;PBS_Server;Job;14058.tyrone-cluster;dequeuing from idqueue, state COMPLETE
11/18/2012 12:34:59;0040;PBS_Server;Svr;tyrone-cluster;Scheduler was sent the command term
11/18/2012 12:35:03;0100;PBS_Server;Job;14059.tyrone-cluster;enqueuing into batch, state 1 hop 1
11/18/2012 12:35:03;0100;PBS_Server;Job;14059.tyrone-cluster;dequeuing from batch, state QUEUED
11/18/2012 12:35:03;0100;PBS_Server;Job;14059.tyrone-cluster;enqueuing into idqueue, state 1 hop 1
11/18/2012 12:35:03;0008;PBS_Server;Job;14059.tyrone-cluster;Job Queued at request of secbadar@tyrone-cluster, owner = secbadar@tyrone-cluster, job name = myjob, queue = idqueue
11/18/2012 12:35:03;0040;PBS_Server;Svr;tyrone-cluster;Scheduler was sent the command new
11/18/2012 12:35:03;0008;PBS_Server;Job;14059.tyrone-cluster;Job Modified at request of Scheduler@tyrone-cluster
11/18/2012 12:35:03;0008;PBS_Server;Job;14059.tyrone-cluster;Job Run at request of Scheduler@tyrone-cluster
11/18/2012 12:35:04;0040;PBS_Server;Svr;tyrone-cluster;Scheduler was sent the command recyc
11/18/2012 12:35:04;000d;PBS_Server;Job;14059.tyrone-cluster;Not sending email: User does not want mail of this type.
11/18/2012 12:35:32;0040;PBS_Server;Svr;tyrone-cluster;Scheduler was sent the command new
11/18/2012 12:36:02;0040;PBS_Server;Svr;tyrone-cluster;Scheduler was sent the command new
11/18/2012 12:36:32;0040;PBS_Server;Svr;tyrone-cluster;Scheduler was sent the command new
11/18/2012 12:36:32;000d;PBS_Server;Job;14057.tyrone-cluster;Not sending email: User does not want mail of this type.
11/18/2012 12:36:32;0010;PBS_Server;Job;14057.tyrone-cluster;Exit_status=0 resources_used.cput=00:03:44 resources_used.mem=409592kb resources_used.vmem=732320kb resources_used.walltime=00:08:14
11/18/2012 12:36:32;0008;PBS_Server;Job;NULL;on_job_exit valid pjob: 0x12fc270 (substate=50)
11/18/2012 12:36:32;0008;PBS_Server;Job;NULL;on_job_exit valid pjob: 0x12fc270 (substate=51)
11/18/2012 12:36:32;0008;PBS_Server;Job;NULL;on_job_exit valid pjob: 0x12fc270 (substate=51)
11/18/2012 12:36:32;0008;PBS_Server;Job;NULL;on_job_exit valid pjob: 0x12fc270 (substate=53)
11/18/2012 12:36:32;0100;PBS_Server;Job;14057.tyrone-cluster;dequeuing from idqueue, state COMPLETE
11/18/2012 12:36:32;0040;PBS_Server;Svr;tyrone-cluster;Scheduler was sent the command term
11/18/2012 12:37:02;0040;PBS_Server;Svr;tyrone-cluster;Scheduler was sent the command new
11/18/2012 12:37:32;0040;PBS_Server;Svr;tyrone-cluster;Scheduler was sent the command new
11/18/2012 12:37:54;000d;PBS_Server;Job;14059.tyrone-cluster;Not sending email: User does not want mail of this type.
11/18/2012 12:37:54;0010;PBS_Server;Job;14059.tyrone-cluster;Exit_status=0 resources_used.cput=00:09:46 resources_used.mem=509808kb resources_used.vmem=1235764kb resources_used.walltime=00:02:51
11/18/2012 12:37:54;0008;PBS_Server;Job;NULL;on_job_exit valid pjob: 0x13416a0 (substate=50)
11/18/2012 12:37:54;0008;PBS_Server;Job;NULL;on_job_exit valid pjob: 0x13416a0 (substate=51)
11/18/2012 12:37:54;0008;PBS_Server;Job;NULL;on_job_exit valid pjob: 0x13416a0 (substate=51)
11/18/2012 12:37:54;0008;PBS_Server;Job;NULL;on_job_exit valid pjob: 0x13416a0 (substate=53)
11/18/2012 12:37:54;0100;PBS_Server;Job;14059.tyrone-cluster;dequeuing from idqueue, state COMPLETE
11/18/2012 12:37:54;0040;PBS_Server;Svr;tyrone-cluster;Scheduler was sent the command term
11/18/2012 12:38:06;0040;PBS_Server;Svr;tyrone-cluster;Scheduler was sent the command new
11/18/2012 12:38:21;0100;PBS_Server;Job;14060.tyrone-cluster;enqueuing into batch, state 1 hop 1
11/18/2012 12:38:21;0100;PBS_Server;Job;14060.tyrone-cluster;dequeuing from batch, state QUEUED
11/18/2012 12:38:21;0100;PBS_Server;Job;14060.tyrone-cluster;enqueuing into idqueue, state 1 hop 1
11/18/2012 12:38:21;0008;PBS_Server;Job;14060.tyrone-cluster;Job Queued at request of secbadar@tyrone-cluster, owner = secbadar@tyrone-cluster, job name = myjob, queue = idqueue
11/18/2012 12:38:21;0040;PBS_Server;Svr;tyrone-cluster;Scheduler was sent the command new
11/18/2012 12:38:21;0008;PBS_Server;Job;14060.tyrone-cluster;Job Modified at request of Scheduler@tyrone-cluster
11/18/2012 12:38:21;0008;PBS_Server;Job;14060.tyrone-cluster;Job Run at request of Scheduler@tyrone-cluster
11/18/2012 12:38:21;0040;PBS_Server;Svr;tyrone-cluster;Scheduler was sent the command recyc
11/18/2012 12:38:21;000d;PBS_Server;Job;14060.tyrone-cluster;Not sending email: User does not want mail of this type.
11/18/2012 12:38:38;0040;PBS_Server;Svr;tyrone-cluster;Scheduler was sent the command new
11/18/2012 12:38:49;0002;PBS_Server;Svr;PBS_Server;Torque Server Version = 3.0.5, loglevel = 0
11/18/2012 12:39:10;0040;PBS_Server;Svr;tyrone-cluster;Scheduler was sent the command new
11/18/2012 12:39:46;0040;PBS_Server;Svr;tyrone-cluster;Scheduler was sent the command new
11/18/2012 12:40:20;0040;PBS_Server;Svr;tyrone-cluster;Scheduler was sent the command new
11/18/2012 12:40:50;0040;PBS_Server;Svr;tyrone-cluster;Scheduler was sent the command new
11/18/2012 12:41:15;000d;PBS_Server;Job;14060.tyrone-cluster;Not sending email: User does not want mail of this type.
11/18/2012 12:41:15;0010;PBS_Server;Job;14060.tyrone-cluster;Exit_status=0 resources_used.cput=00:14:04 resources_used.mem=569788kb resources_used.vmem=1685156kb resources_used.walltime=00:02:54
11/18/2012 12:41:15;0008;PBS_Server;Job;NULL;on_job_exit valid pjob: 0x13416a0 (substate=50)
11/18/2012 12:41:15;0008;PBS_Server;Job;NULL;on_job_exit valid pjob: 0x13416a0 (substate=51)
11/18/2012 12:41:16;0008;PBS_Server;Job;NULL;on_job_exit valid pjob: 0x13416a0 (substate=51)
11/18/2012 12:41:16;0008;PBS_Server;Job;NULL;on_job_exit valid pjob: 0x13416a0 (substate=53)
11/18/2012 12:41:16;0100;PBS_Server;Job;14060.tyrone-cluster;dequeuing from idqueue, state COMPLETE
11/18/2012 12:41:16;0040;PBS_Server;Svr;tyrone-cluster;Scheduler was sent the command term
11/18/2012 12:41:20;0040;PBS_Server;Svr;tyrone-cluster;Scheduler was sent the command new
11/18/2012 12:41:51;0040;PBS_Server;Svr;tyrone-cluster;Scheduler was sent the command new
11/18/2012 12:42:23;0040;PBS_Server;Svr;tyrone-cluster;Scheduler was sent the command new
11/18/2012 12:42:55;0040;PBS_Server;Svr;tyrone-cluster;Scheduler was sent the command new
11/18/2012 12:43:30;0040;PBS_Server;Svr;tyrone-cluster;Scheduler was sent the command new
11/18/2012 12:43:35;0100;PBS_Server;Job;14061.tyrone-cluster;enqueuing into batch, state 1 hop 1
11/18/2012 12:43:35;0100;PBS_Server;Job;14061.tyrone-cluster;dequeuing from batch, state QUEUED
11/18/2012 12:43:35;0100;PBS_Server;Job;14061.tyrone-cluster;enqueuing into idqueue, state 1 hop 1
11/18/2012 12:43:35;0008;PBS_Server;Job;14061.tyrone-cluster;Job Queued at request of seckriti@tyrone-cluster, owner = seckriti@tyrone-cluster, job name = myjob, queue = idqueue
11/18/2012 12:43:35;0040;PBS_Server;Svr;tyrone-cluster;Scheduler was sent the command new
11/18/2012 12:43:35;0008;PBS_Server;Job;14061.tyrone-cluster;Job Modified at request of Scheduler@tyrone-cluster
11/18/2012 12:43:35;0008;PBS_Server;Job;14061.tyrone-cluster;Job Run at request of Scheduler@tyrone-cluster
11/18/2012 12:43:35;0040;PBS_Server;Svr;tyrone-cluster;Scheduler was sent the command recyc
11/18/2012 12:43:35;000d;PBS_Server;Job;14061.tyrone-cluster;Not sending email: User does not want mail of this type.
11/18/2012 12:43:36;000d;PBS_Server;Job;14061.tyrone-cluster;Not sending email: User does not want mail of this type.
11/18/2012 12:43:36;0010;PBS_Server;Job;14061.tyrone-cluster;Exit_status=255 resources_used.cput=00:00:00 resources_used.mem=0kb resources_used.vmem=0kb resources_used.walltime=00:00:01
11/18/2012 12:43:36;0008;PBS_Server;Job;NULL;on_job_exit valid pjob: 0x13416a0 (substate=50)
11/18/2012 12:43:36;0008;PBS_Server;Job;NULL;on_job_exit valid pjob: 0x13416a0 (substate=51)
11/18/2012 12:43:36;0008;PBS_Server;Job;NULL;on_job_exit valid pjob: 0x13416a0 (substate=51)
11/18/2012 12:43:36;0008;PBS_Server;Job;NULL;on_job_exit valid pjob: 0x13416a0 (substate=53)
11/18/2012 12:43:36;0100;PBS_Server;Job;14061.tyrone-cluster;dequeuing from idqueue, state COMPLETE
11/18/2012 12:43:36;0040;PBS_Server;Svr;tyrone-cluster;Scheduler was sent the command term
11/18/2012 12:43:46;0100;PBS_Server;Job;14062.tyrone-cluster;enqueuing into batch, state 1 hop 1
11/18/2012 12:43:46;0100;PBS_Server;Job;14062.tyrone-cluster;dequeuing from batch, state QUEUED
11/18/2012 12:43:46;0100;PBS_Server;Job;14062.tyrone-cluster;enqueuing into idqueue, state 1 hop 1
11/18/2012 12:43:46;0008;PBS_Server;Job;14062.tyrone-cluster;Job Queued at request of seckriti@tyrone-cluster, owner = seckriti@tyrone-cluster, job name = myjob, queue = idqueue
11/18/2012 12:43:46;0040;PBS_Server;Svr;tyrone-cluster;Scheduler was sent the command new
11/18/2012 12:43:46;0008;PBS_Server;Job;14062.tyrone-cluster;Job Modified at request of Scheduler@tyrone-cluster
11/18/2012 12:43:46;0008;PBS_Server;Job;14062.tyrone-cluster;Job Run at request of Scheduler@tyrone-cluster
11/18/2012 12:43:46;0040;PBS_Server;Svr;tyrone-cluster;Scheduler was sent the command recyc
11/18/2012 12:43:46;000d;PBS_Server;Job;14062.tyrone-cluster;Not sending email: User does not want mail of this type.
11/18/2012 12:43:47;000d;PBS_Server;Job;14062.tyrone-cluster;Not sending email: User does not want mail of this type.
11/18/2012 12:43:47;0010;PBS_Server;Job;14062.tyrone-cluster;Exit_status=255 resources_used.cput=00:00:00 resources_used.mem=0kb resources_used.vmem=0kb resources_used.walltime=00:00:01
11/18/2012 12:43:47;0008;PBS_Server;Job;NULL;on_job_exit valid pjob: 0x13416a0 (substate=50)
11/18/2012 12:43:47;0008;PBS_Server;Job;NULL;on_job_exit valid pjob: 0x13416a0 (substate=51)
11/18/2012 12:43:47;0008;PBS_Server;Job;NULL;on_job_exit valid pjob: 0x13416a0 (substate=51)
11/18/2012 12:43:47;0008;PBS_Server;Job;NULL;on_job_exit valid pjob: 0x13416a0 (substate=53)
11/18/2012 12:43:47;0100;PBS_Server;Job;14062.tyrone-cluster;dequeuing from idqueue, state COMPLETE
11/18/2012 12:43:47;0040;PBS_Server;Svr;tyrone-cluster;Scheduler was sent the command term
11/18/2012 12:43:49;0002;PBS_Server;Svr;PBS_Server;Torque Server Version = 3.0.5, loglevel = 0
11/18/2012 12:44:06;0040;PBS_Server;Svr;tyrone-cluster;Scheduler was sent the command new
11/18/2012 12:44:17;0100;PBS_Server;Job;14063.tyrone-cluster;enqueuing into batch, state 1 hop 1
11/18/2012 12:44:17;0100;PBS_Server;Job;14063.tyrone-cluster;dequeuing from batch, state QUEUED
11/18/2012 12:44:17;0100;PBS_Server;Job;14063.tyrone-cluster;enqueuing into idqueue, state 1 hop 1
11/18/2012 12:44:17;0008;PBS_Server;Job;14063.tyrone-cluster;Job Queued at request of seckriti@tyrone-cluster, owner = seckriti@tyrone-cluster, job name = myjob, queue = idqueue
11/18/2012 12:44:17;0040;PBS_Server;Svr;tyrone-cluster;Scheduler was sent the command new
11/18/2012 12:44:17;0008;PBS_Server;Job;14063.tyrone-cluster;Job Modified at request of Scheduler@tyrone-cluster
11/18/2012 12:44:17;0008;PBS_Server;Job;14063.tyrone-cluster;Job Run at request of Scheduler@tyrone-cluster
11/18/2012 12:44:18;0040;PBS_Server;Svr;tyrone-cluster;Scheduler was sent the command recyc
11/18/2012 12:44:18;000d;PBS_Server;Job;14063.tyrone-cluster;Not sending email: User does not want mail of this type.
11/18/2012 12:44:18;000d;PBS_Server;Job;14063.tyrone-cluster;Not sending email: User does not want mail of this type.
11/18/2012 12:44:18;0010;PBS_Server;Job;14063.tyrone-cluster;Exit_status=255 resources_used.cput=00:00:00 resources_used.mem=0kb resources_used.vmem=0kb resources_used.walltime=00:00:01
11/18/2012 12:44:18;0008;PBS_Server;Job;NULL;on_job_exit valid pjob: 0x13416a0 (substate=50)
11/18/2012 12:44:18;0008;PBS_Server;Job;NULL;on_job_exit valid pjob: 0x13416a0 (substate=51)
11/18/2012 12:44:19;0008;PBS_Server;Job;NULL;on_job_exit valid pjob: 0x13416a0 (substate=51)
11/18/2012 12:44:19;0008;PBS_Server;Job;NULL;on_job_exit valid pjob: 0x13416a0 (substate=53)
11/18/2012 12:44:19;0100;PBS_Server;Job;14063.tyrone-cluster;dequeuing from idqueue, state COMPLETE
11/18/2012 12:44:19;0040;PBS_Server;Svr;tyrone-cluster;Scheduler was sent the command term
11/18/2012 12:44:38;0040;PBS_Server;Svr;tyrone-cluster;Scheduler was sent the command new
11/18/2012 12:45:10;0040;PBS_Server;Svr;tyrone-cluster;Scheduler was sent the command new
11/18/2012 12:45:45;0040;PBS_Server;Svr;tyrone-cluster;Scheduler was sent the command new
11/18/2012 12:46:12;0100;PBS_Server;Job;14064.tyrone-cluster;enqueuing into batch, state 1 hop 1
11/18/2012 12:46:12;0100;PBS_Server;Job;14064.tyrone-cluster;dequeuing from batch, state QUEUED
11/18/2012 12:46:12;0100;PBS_Server;Job;14064.tyrone-cluster;enqueuing into idqueue, state 1 hop 1
11/18/2012 12:46:12;0008;PBS_Server;Job;14064.tyrone-cluster;Job Queued at request of seckriti@tyrone-cluster, owner = seckriti@tyrone-cluster, job name = myjob, queue = idqueue
11/18/2012 12:46:12;0040;PBS_Server;Svr;tyrone-cluster;Scheduler was sent the command new
11/18/2012 12:46:12;0008;PBS_Server;Job;14064.tyrone-cluster;Job Modified at request of Scheduler@tyrone-cluster
11/18/2012 12:46:12;0008;PBS_Server;Job;14064.tyrone-cluster;Job Run at request of Scheduler@tyrone-cluster
11/18/2012 12:46:12;0040;PBS_Server;Svr;tyrone-cluster;Scheduler was sent the command recyc
11/18/2012 12:46:12;000d;PBS_Server;Job;14064.tyrone-cluster;Not sending email: User does not want mail of this type.
11/18/2012 12:46:13;000d;PBS_Server;Job;14064.tyrone-cluster;Not sending email: User does not want mail of this type.
11/18/2012 12:46:13;0010;PBS_Server;Job;14064.tyrone-cluster;Exit_status=255 resources_used.cput=00:00:00 resources_used.mem=0kb resources_used.vmem=0kb resources_used.walltime=00:00:01
11/18/2012 12:46:13;0008;PBS_Server;Job;NULL;on_job_exit valid pjob: 0x13416a0 (substate=50)
11/18/2012 12:46:13;0008;PBS_Server;Job;NULL;on_job_exit valid pjob: 0x13416a0 (substate=51)
11/18/2012 12:46:13;0008;PBS_Server;Job;NULL;on_job_exit valid pjob: 0x13416a0 (substate=51)
11/18/2012 12:46:13;0008;PBS_Server;Job;NULL;on_job_exit valid pjob: 0x13416a0 (substate=53)
11/18/2012 12:46:13;0100;PBS_Server;Job;14064.tyrone-cluster;dequeuing from idqueue, state COMPLETE
11/18/2012 12:46:13;0040;PBS_Server;Svr;tyrone-cluster;Scheduler was sent the command term
11/18/2012 12:46:21;0040;PBS_Server;Svr;tyrone-cluster;Scheduler was sent the command new
11/18/2012 12:46:53;0040;PBS_Server;Svr;tyrone-cluster;Scheduler was sent the command new
11/18/2012 12:47:25;0040;PBS_Server;Svr;tyrone-cluster;Scheduler was sent the command new
11/18/2012 12:48:00;0040;PBS_Server;Svr;tyrone-cluster;Scheduler was sent the command new
11/18/2012 12:48:03;0100;PBS_Server;Job;14065.tyrone-cluster;enqueuing into batch, state 1 hop 1
11/18/2012 12:48:03;0100;PBS_Server;Job;14065.tyrone-cluster;dequeuing from batch, state QUEUED
11/18/2012 12:48:03;0100;PBS_Server;Job;14065.tyrone-cluster;enqueuing into idqueue, state 1 hop 1
11/18/2012 12:48:03;0008;PBS_Server;Job;14065.tyrone-cluster;Job Queued at request of seckriti@tyrone-cluster, owner = seckriti@tyrone-cluster, job name = myjob, queue = idqueue
11/18/2012 12:48:03;0040;PBS_Server;Svr;tyrone-cluster;Scheduler was sent the command new
11/18/2012 12:48:03;0008;PBS_Server;Job;14065.tyrone-cluster;Job Modified at request of Scheduler@tyrone-cluster
11/18/2012 12:48:03;0008;PBS_Server;Job;14065.tyrone-cluster;Job Run at request of Scheduler@tyrone-cluster
11/18/2012 12:48:04;0040;PBS_Server;Svr;tyrone-cluster;Scheduler was sent the command recyc
11/18/2012 12:48:04;000d;PBS_Server;Job;14065.tyrone-cluster;Not sending email: User does not want mail of this type.
11/18/2012 12:48:04;000d;PBS_Server;Job;14065.tyrone-cluster;Not sending email: User does not want mail of this type.
11/18/2012 12:48:04;0010;PBS_Server;Job;14065.tyrone-cluster;Exit_status=255 resources_used.cput=00:00:00 resources_used.mem=0kb resources_used.vmem=0kb resources_used.walltime=00:00:01
11/18/2012 12:48:04;0008;PBS_Server;Job;NULL;on_job_exit valid pjob: 0x13416a0 (substate=50)
11/18/2012 12:48:04;0008;PBS_Server;Job;NULL;on_job_exit valid pjob: 0x13416a0 (substate=51)
11/18/2012 12:48:04;0008;PBS_Server;Job;NULL;on_job_exit valid pjob: 0x13416a0 (substate=51)
11/18/2012 12:48:04;0008;PBS_Server;Job;NULL;on_job_exit valid pjob: 0x13416a0 (substate=53)
11/18/2012 12:48:04;0100;PBS_Server;Job;14065.tyrone-cluster;dequeuing from idqueue, state COMPLETE
11/18/2012 12:48:04;0040;PBS_Server;Svr;tyrone-cluster;Scheduler was sent the command term
11/18/2012 12:48:36;0040;PBS_Server;Svr;tyrone-cluster;Scheduler was sent the command new
11/18/2012 12:48:49;0002;PBS_Server;Svr;PBS_Server;Torque Server Version = 3.0.5, loglevel = 0
11/18/2012 12:49:05;0100;PBS_Server;Job;14066.tyrone-cluster;enqueuing into batch, state 1 hop 1
11/18/2012 12:49:05;0100;PBS_Server;Job;14066.tyrone-cluster;dequeuing from batch, state QUEUED
11/18/2012 12:49:05;0100;PBS_Server;Job;14066.tyrone-cluster;enqueuing into idqueue, state 1 hop 1
11/18/2012 12:49:05;0008;PBS_Server;Job;14066.tyrone-cluster;Job Queued at request of seckriti@tyrone-cluster, owner = seckriti@tyrone-cluster, job name = myjob, queue = idqueue
11/18/2012 12:49:05;0040;PBS_Server;Svr;tyrone-cluster;Scheduler was sent the command new
11/18/2012 12:49:05;0008;PBS_Server;Job;14066.tyrone-cluster;Job Modified at request of Scheduler@tyrone-cluster
11/18/2012 12:49:05;0008;PBS_Server;Job;14066.tyrone-cluster;Job Run at request of Scheduler@tyrone-cluster
11/18/2012 12:49:05;0040;PBS_Server;Svr;tyrone-cluster;Scheduler was sent the command recyc
11/18/2012 12:49:05;000d;PBS_Server;Job;14066.tyrone-cluster;Not sending email: User does not want mail of this type.
11/18/2012 12:49:06;0040;PBS_Server;Svr;tyrone-cluster;Scheduler was sent the command new
11/18/2012 12:49:06;000d;PBS_Server;Job;14066.tyrone-cluster;Not sending email: User does not want mail of this type.
11/18/2012 12:49:06;0010;PBS_Server;Job;14066.tyrone-cluster;Exit_status=255 resources_used.cput=00:00:00 resources_used.mem=0kb resources_used.vmem=0kb resources_used.walltime=00:00:01
11/18/2012 12:49:06;0008;PBS_Server;Job;NULL;on_job_exit valid pjob: 0x13416a0 (substate=50)
11/18/2012 12:49:06;0008;PBS_Server;Job;NULL;on_job_exit valid pjob: 0x13416a0 (substate=51)
11/18/2012 12:49:07;0008;PBS_Server;Job;NULL;on_job_exit valid pjob: 0x13416a0 (substate=51)
11/18/2012 12:49:07;0008;PBS_Server;Job;NULL;on_job_exit valid pjob: 0x13416a0 (substate=53)
11/18/2012 12:49:07;0100;PBS_Server;Job;14066.tyrone-cluster;dequeuing from idqueue, state COMPLETE
11/18/2012 12:49:07;0040;PBS_Server;Svr;tyrone-cluster;Scheduler was sent the command term
11/18/2012 12:49:39;0040;PBS_Server;Svr;tyrone-cluster;Scheduler was sent the command new
11/18/2012 12:50:08;0040;PBS_Server;Svr;tyrone-cluster;Scheduler was sent the command new
11/18/2012 12:50:38;0040;PBS_Server;Svr;tyrone-cluster;Scheduler was sent the command new
11/18/2012 12:51:10;0040;PBS_Server;Svr;tyrone-cluster;Scheduler was sent the command new
11/18/2012 12:51:45;0040;PBS_Server;Svr;tyrone-cluster;Scheduler was sent the command new
11/18/2012 12:52:19;0040;PBS_Server;Svr;tyrone-cluster;Scheduler was sent the command new
11/18/2012 12:52:19;0100;PBS_Server;Job;14067.tyrone-cluster;enqueuing into batch, state 1 hop 1
11/18/2012 12:52:19;0100;PBS_Server;Job;14067.tyrone-cluster;dequeuing from batch, state QUEUED
11/18/2012 12:52:19;0100;PBS_Server;Job;14067.tyrone-cluster;enqueuing into idqueue, state 1 hop 1
11/18/2012 12:52:19;0008;PBS_Server;Job;14067.tyrone-cluster;Job Queued at request of seckriti@tyrone-cluster, owner = seckriti@tyrone-cluster, job name = myjob, queue = idqueue
11/18/2012 12:52:19;0008;PBS_Server;Job;14067.tyrone-cluster;Job Modified at request of Scheduler@tyrone-cluster
11/18/2012 12:52:19;0008;PBS_Server;Job;14067.tyrone-cluster;Job Run at request of Scheduler@tyrone-cluster
11/18/2012 12:52:20;0040;PBS_Server;Svr;tyrone-cluster;Scheduler was sent the command recyc
11/18/2012 12:52:20;000d;PBS_Server;Job;14067.tyrone-cluster;Not sending email: User does not want mail of this type.
11/18/2012 12:52:20;000d;PBS_Server;Job;14067.tyrone-cluster;Not sending email: User does not want mail of this type.
11/18/2012 12:52:20;0010;PBS_Server;Job;14067.tyrone-cluster;Exit_status=255 resources_used.cput=00:00:00 resources_used.mem=0kb resources_used.vmem=0kb resources_used.walltime=00:00:01
11/18/2012 12:52:20;0008;PBS_Server;Job;NULL;on_job_exit valid pjob: 0x13416a0 (substate=50)
11/18/2012 12:52:20;0008;PBS_Server;Job;NULL;on_job_exit valid pjob: 0x13416a0 (substate=51)
11/18/2012 12:52:20;0008;PBS_Server;Job;NULL;on_job_exit valid pjob: 0x13416a0 (substate=51)
11/18/2012 12:52:20;0008;PBS_Server;Job;NULL;on_job_exit valid pjob: 0x13416a0 (substate=53)
11/18/2012 12:52:20;0100;PBS_Server;Job;14067.tyrone-cluster;dequeuing from idqueue, state COMPLETE
11/18/2012 12:52:20;0040;PBS_Server;Svr;tyrone-cluster;Scheduler was sent the command term
11/18/2012 12:52:50;0040;PBS_Server;Svr;tyrone-cluster;Scheduler was sent the command new
11/18/2012 12:53:20;0040;PBS_Server;Svr;tyrone-cluster;Scheduler was sent the command new
11/18/2012 12:53:49;0002;PBS_Server;Svr;PBS_Server;Torque Server Version = 3.0.5, loglevel = 0
11/18/2012 12:53:51;0040;PBS_Server;Svr;tyrone-cluster;Scheduler was sent the command new
11/18/2012 12:54:04;0100;PBS_Server;Job;14068.tyrone-cluster;enqueuing into batch, state 1 hop 1
11/18/2012 12:54:04;0100;PBS_Server;Job;14068.tyrone-cluster;dequeuing from batch, state QUEUED
11/18/2012 12:54:04;0100;PBS_Server;Job;14068.tyrone-cluster;enqueuing into idqueue, state 1 hop 1
11/18/2012 12:54:04;0008;PBS_Server;Job;14068.tyrone-cluster;Job Queued at request of seckriti@tyrone-cluster, owner = seckriti@tyrone-cluster, job name = myjob, queue = idqueue
11/18/2012 12:54:04;0040;PBS_Server;Svr;tyrone-cluster;Scheduler was sent the command new
11/18/2012 12:54:04;0008;PBS_Server;Job;14068.tyrone-cluster;Job Modified at request of Scheduler@tyrone-cluster
11/18/2012 12:54:04;0008;PBS_Server;Job;14068.tyrone-cluster;Job Run at request of Scheduler@tyrone-cluster
11/18/2012 12:54:04;0040;PBS_Server;Svr;tyrone-cluster;Scheduler was sent the command recyc
11/18/2012 12:54:04;000d;PBS_Server;Job;14068.tyrone-cluster;Not sending email: User does not want mail of this type.
11/18/2012 12:54:07;000d;PBS_Server;Job;14068.tyrone-cluster;Not sending email: User does not want mail of this type.
11/18/2012 12:54:07;0010;PBS_Server;Job;14068.tyrone-cluster;Exit_status=0 resources_used.cput=00:00:04 resources_used.mem=24324kb resources_used.vmem=483088kb resources_used.walltime=00:00:03
11/18/2012 12:54:07;0008;PBS_Server;Job;NULL;on_job_exit valid pjob: 0x12fc270 (substate=50)
11/18/2012 12:54:07;0008;PBS_Server;Job;NULL;on_job_exit valid pjob: 0x12fc270 (substate=51)
11/18/2012 12:54:07;0008;PBS_Server;Job;NULL;on_job_exit valid pjob: 0x12fc270 (substate=51)
11/18/2012 12:54:07;0008;PBS_Server;Job;NULL;on_job_exit valid pjob: 0x12fc270 (substate=53)
11/18/2012 12:54:07;0100;PBS_Server;Job;14068.tyrone-cluster;dequeuing from idqueue, state COMPLETE
11/18/2012 12:54:07;0040;PBS_Server;Svr;tyrone-cluster;Scheduler was sent the command term
11/18/2012 12:54:23;0040;PBS_Server;Svr;tyrone-cluster;Scheduler was sent the command new
11/18/2012 12:54:55;0040;PBS_Server;Svr;tyrone-cluster;Scheduler was sent the command new
11/18/2012 12:55:16;0100;PBS_Server;Job;14069.tyrone-cluster;enqueuing into batch, state 1 hop 1
11/18/2012 12:55:16;0100;PBS_Server;Job;14069.tyrone-cluster;dequeuing from batch, state QUEUED
11/18/2012 12:55:16;0100;PBS_Server;Job;14069.tyrone-cluster;enqueuing into idqueue, state 1 hop 1
11/18/2012 12:55:16;0008;PBS_Server;Job;14069.tyrone-cluster;Job Queued at request of seckriti@tyrone-cluster, owner = seckriti@tyrone-cluster, job name = myjob, queue = idqueue
11/18/2012 12:55:16;0040;PBS_Server;Svr;tyrone-cluster;Scheduler was sent the command new
11/18/2012 12:55:16;0008;PBS_Server;Job;14069.tyrone-cluster;Job Modified at request of Scheduler@tyrone-cluster
11/18/2012 12:55:16;0008;PBS_Server;Job;14069.tyrone-cluster;Job Run at request of Scheduler@tyrone-cluster
11/18/2012 12:55:16;0040;PBS_Server;Svr;tyrone-cluster;Scheduler was sent the command recyc
11/18/2012 12:55:16;000d;PBS_Server;Job;14069.tyrone-cluster;Not sending email: User does not want mail of this type.
11/18/2012 12:55:20;000d;PBS_Server;Job;14069.tyrone-cluster;Not sending email: User does not want mail of this type.
11/18/2012 12:55:20;0010;PBS_Server;Job;14069.tyrone-cluster;Exit_status=0 resources_used.cput=00:00:05 resources_used.mem=0kb resources_used.vmem=0kb resources_used.walltime=00:00:04
11/18/2012 12:55:20;0008;PBS_Server;Job;NULL;on_job_exit valid pjob: 0x13416a0 (substate=50)
11/18/2012 12:55:20;0008;PBS_Server;Job;NULL;on_job_exit valid pjob: 0x13416a0 (substate=51)
11/18/2012 12:55:20;0008;PBS_Server;Job;NULL;on_job_exit valid pjob: 0x13416a0 (substate=51)
11/18/2012 12:55:20;0008;PBS_Server;Job;NULL;on_job_exit valid pjob: 0x13416a0 (substate=53)
11/18/2012 12:55:20;0100;PBS_Server;Job;14069.tyrone-cluster;dequeuing from idqueue, state COMPLETE
11/18/2012 12:55:20;0040;PBS_Server;Svr;tyrone-cluster;Scheduler was sent the command term
11/18/2012 12:55:30;0040;PBS_Server;Svr;tyrone-cluster;Scheduler was sent the command new
11/18/2012 12:56:06;0040;PBS_Server;Svr;tyrone-cluster;Scheduler was sent the command new
11/18/2012 12:56:09;0100;PBS_Server;Job;14070.tyrone-cluster;enqueuing into batch, state 1 hop 1
11/18/2012 12:56:09;0100;PBS_Server;Job;14070.tyrone-cluster;dequeuing from batch, state QUEUED
11/18/2012 12:56:09;0100;PBS_Server;Job;14070.tyrone-cluster;enqueuing into idqueue, state 1 hop 1
11/18/2012 12:56:09;0008;PBS_Server;Job;14070.tyrone-cluster;Job Queued at request of seckriti@tyrone-cluster, owner = seckriti@tyrone-cluster, job name = myjob, queue = idqueue
11/18/2012 12:56:09;0040;PBS_Server;Svr;tyrone-cluster;Scheduler was sent the command new
11/18/2012 12:56:09;0008;PBS_Server;Job;14070.tyrone-cluster;Job Modified at request of Scheduler@tyrone-cluster
11/18/2012 12:56:09;0008;PBS_Server;Job;14070.tyrone-cluster;Job Run at request of Scheduler@tyrone-cluster
11/18/2012 12:56:09;0040;PBS_Server;Svr;tyrone-cluster;Scheduler was sent the command recyc
11/18/2012 12:56:09;000d;PBS_Server;Job;14070.tyrone-cluster;Not sending email: User does not want mail of this type.
11/18/2012 12:56:12;000d;PBS_Server;Job;14070.tyrone-cluster;Not sending email: User does not want mail of this type.
11/18/2012 12:56:12;0010;PBS_Server;Job;14070.tyrone-cluster;Exit_status=0 resources_used.cput=00:00:03 resources_used.mem=0kb resources_used.vmem=0kb resources_used.walltime=00:00:03
11/18/2012 12:56:12;0008;PBS_Server;Job;NULL;on_job_exit valid pjob: 0x13416a0 (substate=50)
11/18/2012 12:56:12;0008;PBS_Server;Job;NULL;on_job_exit valid pjob: 0x13416a0 (substate=51)
11/18/2012 12:56:12;0008;PBS_Server;Job;NULL;on_job_exit valid pjob: 0x13416a0 (substate=51)
11/18/2012 12:56:12;0008;PBS_Server;Job;NULL;on_job_exit valid pjob: 0x13416a0 (substate=53)
11/18/2012 12:56:12;0100;PBS_Server;Job;14070.tyrone-cluster;dequeuing from idqueue, state COMPLETE
11/18/2012 12:56:12;0040;PBS_Server;Svr;tyrone-cluster;Scheduler was sent the command term
11/18/2012 12:56:38;0040;PBS_Server;Svr;tyrone-cluster;Scheduler was sent the command new
11/18/2012 12:57:10;0040;PBS_Server;Svr;tyrone-cluster;Scheduler was sent the command new
11/18/2012 12:57:45;0040;PBS_Server;Svr;tyrone-cluster;Scheduler was sent the command new
11/18/2012 12:57:57;0100;PBS_Server;Job;14071.tyrone-cluster;enqueuing into batch, state 1 hop 1
11/18/2012 12:57:57;0100;PBS_Server;Job;14071.tyrone-cluster;dequeuing from batch, state QUEUED
11/18/2012 12:57:57;0100;PBS_Server;Job;14071.tyrone-cluster;enqueuing into idqueue, state 1 hop 1
11/18/2012 12:57:57;0008;PBS_Server;Job;14071.tyrone-cluster;Job Queued at request of seckriti@tyrone-cluster, owner = seckriti@tyrone-cluster, job name = myjob, queue = idqueue
11/18/2012 12:57:57;0040;PBS_Server;Svr;tyrone-cluster;Scheduler was sent the command new
11/18/2012 12:57:58;0008;PBS_Server;Job;14071.tyrone-cluster;Job Modified at request of Scheduler@tyrone-cluster
11/18/2012 12:57:58;0008;PBS_Server;Job;14071.tyrone-cluster;Job Run at request of Scheduler@tyrone-cluster
11/18/2012 12:57:58;0040;PBS_Server;Svr;tyrone-cluster;Scheduler was sent the command recyc
11/18/2012 12:57:58;000d;PBS_Server;Job;14071.tyrone-cluster;Not sending email: User does not want mail of this type.
11/18/2012 12:58:00;000d;PBS_Server;Job;14071.tyrone-cluster;Not sending email: User does not want mail of this type.
11/18/2012 12:58:00;0010;PBS_Server;Job;14071.tyrone-cluster;Exit_status=0 resources_used.cput=00:00:03 resources_used.mem=0kb resources_used.vmem=0kb resources_used.walltime=00:00:02
11/18/2012 12:58:00;0008;PBS_Server;Job;NULL;on_job_exit valid pjob: 0x13416a0 (substate=50)
11/18/2012 12:58:00;0008;PBS_Server;Job;NULL;on_job_exit valid pjob: 0x13416a0 (substate=51)
11/18/2012 12:58:01;0008;PBS_Server;Job;NULL;on_job_exit valid pjob: 0x13416a0 (substate=51)
11/18/2012 12:58:01;0008;PBS_Server;Job;NULL;on_job_exit valid pjob: 0x13416a0 (substate=53)
11/18/2012 12:58:01;0100;PBS_Server;Job;14071.tyrone-cluster;dequeuing from idqueue, state COMPLETE
11/18/2012 12:58:01;0040;PBS_Server;Svr;tyrone-cluster;Scheduler was sent the command term
11/18/2012 12:58:21;0040;PBS_Server;Svr;tyrone-cluster;Scheduler was sent the command new
11/18/2012 12:58:49;0002;PBS_Server;Svr;PBS_Server;Torque Server Version = 3.0.5, loglevel = 0
11/18/2012 12:58:53;0040;PBS_Server;Svr;tyrone-cluster;Scheduler was sent the command new
11/18/2012 12:59:25;0040;PBS_Server;Svr;tyrone-cluster;Scheduler was sent the command new
11/18/2012 13:00:00;0040;PBS_Server;Svr;tyrone-cluster;Scheduler was sent the command new
11/18/2012 13:00:00;0100;PBS_Server;Job;14072.tyrone-cluster;enqueuing into batch, state 1 hop 1
11/18/2012 13:00:00;0100;PBS_Server;Job;14072.tyrone-cluster;dequeuing from batch, state QUEUED
11/18/2012 13:00:00;0100;PBS_Server;Job;14072.tyrone-cluster;enqueuing into idqueue, state 1 hop 1
11/18/2012 13:00:00;0008;PBS_Server;Job;14072.tyrone-cluster;Job Queued at request of seckriti@tyrone-cluster, owner = seckriti@tyrone-cluster, job name = myjob, queue = idqueue
11/18/2012 13:00:00;0008;PBS_Server;Job;14072.tyrone-cluster;Job Modified at request of Scheduler@tyrone-cluster
11/18/2012 13:00:00;0008;PBS_Server;Job;14072.tyrone-cluster;Job Run at request of Scheduler@tyrone-cluster
11/18/2012 13:00:00;0040;PBS_Server;Svr;tyrone-cluster;Scheduler was sent the command recyc
11/18/2012 13:00:00;000d;PBS_Server;Job;14072.tyrone-cluster;Not sending email: User does not want mail of this type.
11/18/2012 13:00:03;000d;PBS_Server;Job;14072.tyrone-cluster;Not sending email: User does not want mail of this type.
11/18/2012 13:00:03;0010;PBS_Server;Job;14072.tyrone-cluster;Exit_status=0 resources_used.cput=00:00:03 resources_used.mem=0kb resources_used.vmem=0kb resources_used.walltime=00:00:02
11/18/2012 13:00:03;0008;PBS_Server;Job;NULL;on_job_exit valid pjob: 0x13416a0 (substate=50)
11/18/2012 13:00:03;0008;PBS_Server;Job;NULL;on_job_exit valid pjob: 0x13416a0 (substate=51)
11/18/2012 13:00:03;0008;PBS_Server;Job;NULL;on_job_exit valid pjob: 0x13416a0 (substate=51)
11/18/2012 13:00:03;0008;PBS_Server;Job;NULL;on_job_exit valid pjob: 0x13416a0 (substate=53)
11/18/2012 13:00:03;0100;PBS_Server;Job;14072.tyrone-cluster;dequeuing from idqueue, state COMPLETE
11/18/2012 13:00:03;0040;PBS_Server;Svr;tyrone-cluster;Scheduler was sent the command term
11/18/2012 13:00:31;0040;PBS_Server;Svr;tyrone-cluster;Scheduler was sent the command new
11/18/2012 13:00:31;0100;PBS_Server;Job;14073.tyrone-cluster;enqueuing into batch, state 1 hop 1
11/18/2012 13:00:31;0100;PBS_Server;Job;14073.tyrone-cluster;dequeuing from batch, state QUEUED
11/18/2012 13:00:31;0100;PBS_Server;Job;14073.tyrone-cluster;enqueuing into idqueue, state 1 hop 1
11/18/2012 13:00:31;0008;PBS_Server;Job;14073.tyrone-cluster;Job Queued at request of seckriti@tyrone-cluster, owner = seckriti@tyrone-cluster, job name = myjob, queue = idqueue
11/18/2012 13:00:31;0008;PBS_Server;Job;14073.tyrone-cluster;Job Modified at request of Scheduler@tyrone-cluster
11/18/2012 13:00:31;0008;PBS_Server;Job;14073.tyrone-cluster;Job Run at request of Scheduler@tyrone-cluster
11/18/2012 13:00:32;0040;PBS_Server;Svr;tyrone-cluster;Scheduler was sent the command recyc
11/18/2012 13:00:32;000d;PBS_Server;Job;14073.tyrone-cluster;Not sending email: User does not want mail of this type.
11/18/2012 13:01:01;0040;PBS_Server;Svr;tyrone-cluster;Scheduler was sent the command new
11/18/2012 13:01:31;0040;PBS_Server;Svr;tyrone-cluster;Scheduler was sent the command new
11/18/2012 13:02:06;0040;PBS_Server;Svr;tyrone-cluster;Scheduler was sent the command new
11/18/2012 13:02:38;0040;PBS_Server;Svr;tyrone-cluster;Scheduler was sent the command new
11/18/2012 13:03:10;0040;PBS_Server;Svr;tyrone-cluster;Scheduler was sent the command new
11/18/2012 13:03:45;0040;PBS_Server;Svr;tyrone-cluster;Scheduler was sent the command new
11/18/2012 13:03:49;0002;PBS_Server;Svr;PBS_Server;Torque Server Version = 3.0.5, loglevel = 0
11/18/2012 13:04:14;0040;PBS_Server;Svr;tyrone-cluster;Scheduler was sent the command new
11/18/2012 13:04:23;0100;PBS_Server;Job;14074.tyrone-cluster;enqueuing into batch, state 1 hop 1
11/18/2012 13:04:23;0100;PBS_Server;Job;14074.tyrone-cluster;dequeuing from batch, state QUEUED
11/18/2012 13:04:23;0100;PBS_Server;Job;14074.tyrone-cluster;enqueuing into idqueue, state 1 hop 1
11/18/2012 13:04:23;0008;PBS_Server;Job;14074.tyrone-cluster;Job Queued at request of seckriti@tyrone-cluster, owner = seckriti@tyrone-cluster, job name = myjob, queue = idqueue
11/18/2012 13:04:23;0040;PBS_Server;Svr;tyrone-cluster;Scheduler was sent the command new
11/18/2012 13:04:23;0008;PBS_Server;Job;14074.tyrone-cluster;Job Modified at request of Scheduler@tyrone-cluster
11/18/2012 13:04:23;0008;PBS_Server;Job;14074.tyrone-cluster;Job Run at request of Scheduler@tyrone-cluster
11/18/2012 13:04:23;0040;PBS_Server;Svr;tyrone-cluster;Scheduler was sent the command recyc
11/18/2012 13:04:23;000d;PBS_Server;Job;14074.tyrone-cluster;Not sending email: User does not want mail of this type.
11/18/2012 13:04:26;000d;PBS_Server;Job;14074.tyrone-cluster;Not sending email: User does not want mail of this type.
11/18/2012 13:04:26;0010;PBS_Server;Job;14074.tyrone-cluster;Exit_status=0 resources_used.cput=00:00:02 resources_used.mem=0kb resources_used.vmem=0kb resources_used.walltime=00:00:03
11/18/2012 13:04:26;0008;PBS_Server;Job;NULL;on_job_exit valid pjob: 0x132ff00 (substate=50)
11/18/2012 13:04:26;0008;PBS_Server;Job;NULL;on_job_exit valid pjob: 0x132ff00 (substate=51)
11/18/2012 13:04:26;0008;PBS_Server;Job;NULL;on_job_exit valid pjob: 0x132ff00 (substate=51)
11/18/2012 13:04:26;0008;PBS_Server;Job;NULL;on_job_exit valid pjob: 0x132ff00 (substate=53)
11/18/2012 13:04:26;0100;PBS_Server;Job;14074.tyrone-cluster;dequeuing from idqueue, state COMPLETE
11/18/2012 13:04:26;0040;PBS_Server;Svr;tyrone-cluster;Scheduler was sent the command term
11/18/2012 13:04:46;0040;PBS_Server;Svr;tyrone-cluster;Scheduler was sent the command new
11/18/2012 13:05:16;0040;PBS_Server;Svr;tyrone-cluster;Scheduler was sent the command new
11/18/2012 13:05:16;0100;PBS_Server;Job;14075.tyrone-cluster;enqueuing into batch, state 1 hop 1
11/18/2012 13:05:16;0100;PBS_Server;Job;14075.tyrone-cluster;dequeuing from batch, state QUEUED
11/18/2012 13:05:16;0100;PBS_Server;Job;14075.tyrone-cluster;enqueuing into idqueue, state 1 hop 1
11/18/2012 13:05:16;0008;PBS_Server;Job;14075.tyrone-cluster;Job Queued at request of seckriti@tyrone-cluster, owner = seckriti@tyrone-cluster, job name = myjob, queue = idqueue
11/18/2012 13:05:16;0008;PBS_Server;Job;14075.tyrone-cluster;Job Modified at request of Scheduler@tyrone-cluster
11/18/2012 13:05:16;0008;PBS_Server;Job;14075.tyrone-cluster;Job Run at request of Scheduler@tyrone-cluster
11/18/2012 13:05:16;0040;PBS_Server;Svr;tyrone-cluster;Scheduler was sent the command recyc
11/18/2012 13:05:16;000d;PBS_Server;Job;14075.tyrone-cluster;Not sending email: User does not want mail of this type.
11/18/2012 13:05:51;0040;PBS_Server;Svr;tyrone-cluster;Scheduler was sent the command new
11/18/2012 13:06:23;0040;PBS_Server;Svr;tyrone-cluster;Scheduler was sent the command new
11/18/2012 13:06:55;0040;PBS_Server;Svr;tyrone-cluster;Scheduler was sent the command new
11/18/2012 13:07:02;0100;PBS_Server;Job;14076.tyrone-cluster;enqueuing into batch, state 1 hop 1
11/18/2012 13:07:02;0100;PBS_Server;Job;14076.tyrone-cluster;dequeuing from batch, state QUEUED
11/18/2012 13:07:02;0100;PBS_Server;Job;14076.tyrone-cluster;enqueuing into idqueue, state 1 hop 1
11/18/2012 13:07:02;0008;PBS_Server;Job;14076.tyrone-cluster;Job Queued at request of secpka@tyrone-cluster, owner = secpka@tyrone-cluster, job name = myjob, queue = idqueue
11/18/2012 13:07:02;0040;PBS_Server;Svr;tyrone-cluster;Scheduler was sent the command new
11/18/2012 13:07:02;0008;PBS_Server;Job;14076.tyrone-cluster;Job Modified at request of Scheduler@tyrone-cluster
11/18/2012 13:07:24;0040;PBS_Server;Svr;tyrone-cluster;Scheduler was sent the command new
11/18/2012 13:07:59;0040;PBS_Server;Svr;tyrone-cluster;Scheduler was sent the command new
11/18/2012 13:08:31;0040;PBS_Server;Svr;tyrone-cluster;Scheduler was sent the command new
11/18/2012 13:08:49;0002;PBS_Server;Svr;PBS_Server;Torque Server Version = 3.0.5, loglevel = 0
11/18/2012 13:09:01;0040;PBS_Server;Svr;tyrone-cluster;Scheduler was sent the command new
11/18/2012 13:09:36;0040;PBS_Server;Svr;tyrone-cluster;Scheduler was sent the command new
11/18/2012 13:10:08;0040;PBS_Server;Svr;tyrone-cluster;Scheduler was sent the command new
11/18/2012 13:10:40;0040;PBS_Server;Svr;tyrone-cluster;Scheduler was sent the command new
11/18/2012 13:11:15;0040;PBS_Server;Svr;tyrone-cluster;Scheduler was sent the command new
11/18/2012 13:11:44;0040;PBS_Server;Svr;tyrone-cluster;Scheduler was sent the command new
11/18/2012 13:12:16;0040;PBS_Server;Svr;tyrone-cluster;Scheduler was sent the command new
11/18/2012 13:12:46;0040;PBS_Server;Svr;tyrone-cluster;Scheduler was sent the command new
11/18/2012 13:13:21;0040;PBS_Server;Svr;tyrone-cluster;Scheduler was sent the command new
11/18/2012 13:13:49;0002;PBS_Server;Svr;PBS_Server;Torque Server Version = 3.0.5, loglevel = 0
11/18/2012 13:13:53;0040;PBS_Server;Svr;tyrone-cluster;Scheduler was sent the command new
11/18/2012 13:14:25;0040;PBS_Server;Svr;tyrone-cluster;Scheduler was sent the command new
11/18/2012 13:15:00;0040;PBS_Server;Svr;tyrone-cluster;Scheduler was sent the command new
11/18/2012 13:15:36;0040;PBS_Server;Svr;tyrone-cluster;Scheduler was sent the command new
11/18/2012 13:16:08;0040;PBS_Server;Svr;tyrone-cluster;Scheduler was sent the command new
11/18/2012 13:16:40;0040;PBS_Server;Svr;tyrone-cluster;Scheduler was sent the command new
11/18/2012 13:17:15;0040;PBS_Server;Svr;tyrone-cluster;Scheduler was sent the command new
11/18/2012 13:17:51;0040;PBS_Server;Svr;tyrone-cluster;Scheduler was sent the command new
11/18/2012 13:18:23;0040;PBS_Server;Svr;tyrone-cluster;Scheduler was sent the command new
11/18/2012 13:18:49;0002;PBS_Server;Svr;PBS_Server;Torque Server Version = 3.0.5, loglevel = 0
11/18/2012 13:18:54;0040;PBS_Server;Svr;tyrone-cluster;Scheduler was sent the command new
11/18/2012 13:19:23;0040;PBS_Server;Svr;tyrone-cluster;Scheduler was sent the command new
11/18/2012 13:19:53;0040;PBS_Server;Svr;tyrone-cluster;Scheduler was sent the command new
11/18/2012 13:20:25;0040;PBS_Server;Svr;tyrone-cluster;Scheduler was sent the command new
11/18/2012 13:20:30;000d;PBS_Server;Job;14000.tyrone-cluster;Not sending email: User does not want mail of this type.
11/18/2012 13:20:30;0010;PBS_Server;Job;14000.tyrone-cluster;Exit_status=143 resources_used.cput=27:51:50 resources_used.mem=16002740kb resources_used.vmem=20780396kb resources_used.walltime=02:00:44
11/18/2012 13:20:30;0008;PBS_Server;Job;NULL;on_job_exit valid pjob: 0x1317ed0 (substate=50)
11/18/2012 13:20:30;0008;PBS_Server;Job;NULL;on_job_exit valid pjob: 0x1317ed0 (substate=51)
11/18/2012 13:20:30;000d;PBS_Server;Job;14001.tyrone-cluster;Not sending email: User does not want mail of this type.
11/18/2012 13:20:30;0010;PBS_Server;Job;14001.tyrone-cluster;Exit_status=143 resources_used.cput=28:09:26 resources_used.mem=15959336kb resources_used.vmem=20780740kb resources_used.walltime=02:00:42
11/18/2012 13:20:30;0008;PBS_Server;Job;NULL;on_job_exit valid pjob: 0x131f740 (substate=50)
11/18/2012 13:20:30;0008;PBS_Server;Job;NULL;on_job_exit valid pjob: 0x131f740 (substate=51)
11/18/2012 13:20:30;0008;PBS_Server;Job;NULL;on_job_exit valid pjob: 0x131f740 (substate=51)
11/18/2012 13:20:30;0008;PBS_Server;Job;NULL;on_job_exit valid pjob: 0x131f740 (substate=53)
11/18/2012 13:20:30;0100;PBS_Server;Job;14001.tyrone-cluster;dequeuing from idqueue, state COMPLETE
11/18/2012 13:20:30;0040;PBS_Server;Svr;tyrone-cluster;Scheduler was sent the command term
11/18/2012 13:20:30;0008;PBS_Server;Job;NULL;on_job_exit valid pjob: 0x1317ed0 (substate=51)
11/18/2012 13:20:30;0008;PBS_Server;Job;NULL;on_job_exit valid pjob: 0x1317ed0 (substate=53)
11/18/2012 13:20:30;0100;PBS_Server;Job;14000.tyrone-cluster;dequeuing from idqueue, state COMPLETE
11/18/2012 13:20:30;0008;PBS_Server;Job;14076.tyrone-cluster;Job Modified at request of Scheduler@tyrone-cluster
11/18/2012 13:20:30;0008;PBS_Server;Job;14076.tyrone-cluster;Job Run at request of Scheduler@tyrone-cluster
11/18/2012 13:20:31;000d;PBS_Server;Job;14076.tyrone-cluster;Not sending email: User does not want mail of this type.
11/18/2012 13:20:31;0040;PBS_Server;Svr;tyrone-cluster;Scheduler was sent the command recyc
11/18/2012 13:20:32;000d;PBS_Server;Job;14076.tyrone-cluster;Not sending email: User does not want mail of this type.
11/18/2012 13:20:32;0010;PBS_Server;Job;14076.tyrone-cluster;Exit_status=0 resources_used.cput=00:00:00 resources_used.mem=0kb resources_used.vmem=0kb resources_used.walltime=00:00:02
11/18/2012 13:20:32;0008;PBS_Server;Job;NULL;on_job_exit valid pjob: 0x1304bf0 (substate=50)
11/18/2012 13:20:32;0008;PBS_Server;Job;NULL;on_job_exit valid pjob: 0x1304bf0 (substate=51)
11/18/2012 13:20:32;0008;PBS_Server;Job;NULL;on_job_exit valid pjob: 0x1304bf0 (substate=51)
11/18/2012 13:20:32;0008;PBS_Server;Job;NULL;on_job_exit valid pjob: 0x1304bf0 (substate=53)
11/18/2012 13:20:32;0100;PBS_Server;Job;14076.tyrone-cluster;dequeuing from idqueue, state COMPLETE
11/18/2012 13:20:32;0040;PBS_Server;Svr;tyrone-cluster;Scheduler was sent the command term
11/18/2012 13:21:00;0040;PBS_Server;Svr;tyrone-cluster;Scheduler was sent the command new
11/18/2012 13:21:36;0040;PBS_Server;Svr;tyrone-cluster;Scheduler was sent the command new
11/18/2012 13:22:08;0040;PBS_Server;Svr;tyrone-cluster;Scheduler was sent the command new
11/18/2012 13:22:40;0040;PBS_Server;Svr;tyrone-cluster;Scheduler was sent the command new
11/18/2012 13:23:08;0040;PBS_Server;Svr;tyrone-cluster;Scheduler was sent the command new
11/18/2012 13:23:38;0040;PBS_Server;Svr;tyrone-cluster;Scheduler was sent the command new
11/18/2012 13:23:49;0002;PBS_Server;Svr;PBS_Server;Torque Server Version = 3.0.5, loglevel = 0
11/18/2012 13:24:11;0040;PBS_Server;Svr;tyrone-cluster;Scheduler was sent the command new
11/18/2012 13:24:46;0040;PBS_Server;Svr;tyrone-cluster;Scheduler was sent the command new
11/18/2012 13:25:21;0040;PBS_Server;Svr;tyrone-cluster;Scheduler was sent the command new
11/18/2012 13:25:53;0040;PBS_Server;Svr;tyrone-cluster;Scheduler was sent the command new
11/18/2012 13:26:25;0040;PBS_Server;Svr;tyrone-cluster;Scheduler was sent the command new
11/18/2012 13:27:00;0040;PBS_Server;Svr;tyrone-cluster;Scheduler was sent the command new
11/18/2012 13:27:36;0040;PBS_Server;Svr;tyrone-cluster;Scheduler was sent the command new
11/18/2012 13:28:08;0040;PBS_Server;Svr;tyrone-cluster;Scheduler was sent the command new
11/18/2012 13:28:40;0040;PBS_Server;Svr;tyrone-cluster;Scheduler was sent the command new
11/18/2012 13:28:49;0002;PBS_Server;Svr;PBS_Server;Torque Server Version = 3.0.5, loglevel = 0
11/18/2012 13:29:15;0040;PBS_Server;Svr;tyrone-cluster;Scheduler was sent the command new
11/18/2012 13:29:44;0040;PBS_Server;Svr;tyrone-cluster;Scheduler was sent the command new
11/18/2012 13:30:10;0008;PBS_Server;Job;13986.tyrone-cluster;Job deleted at request of asealama@tyrone-node9
11/18/2012 13:30:10;0008;PBS_Server;Job;13986.tyrone-cluster;Job sent signal SIGTERM on delete
11/18/2012 13:30:10;000d;PBS_Server;Job;13986.tyrone-cluster;Not sending email: User does not want mail of this type.
11/18/2012 13:30:10;0010;PBS_Server;Job;13986.tyrone-cluster;Exit_status=143 resources_used.cput=86:20:42 resources_used.mem=1796736kb resources_used.vmem=6625356kb resources_used.walltime=02:42:03
11/18/2012 13:30:10;0008;PBS_Server;Job;NULL;on_job_exit valid pjob: 0x12f5dd0 (substate=50)
11/18/2012 13:30:10;0008;PBS_Server;Job;NULL;on_job_exit valid pjob: 0x12f5dd0 (substate=51)
11/18/2012 13:30:10;0008;PBS_Server;Job;NULL;on_job_exit valid pjob: 0x12f5dd0 (substate=51)
11/18/2012 13:30:10;0008;PBS_Server;Job;NULL;on_job_exit valid pjob: 0x12f5dd0 (substate=53)
11/18/2012 13:30:10;0100;PBS_Server;Job;13986.tyrone-cluster;dequeuing from qp64, state COMPLETE
11/18/2012 13:30:10;0040;PBS_Server;Svr;tyrone-cluster;Scheduler was sent the command term
11/18/2012 13:30:10;0008;PBS_Server;Job;14037.tyrone-cluster;Job Modified at request of Scheduler@tyrone-cluster
11/18/2012 13:30:10;0008;PBS_Server;Job;14037.tyrone-cluster;Job Run at request of Scheduler@tyrone-cluster
11/18/2012 13:30:11;0040;PBS_Server;Svr;tyrone-cluster;Scheduler was sent the command recyc
11/18/2012 13:30:11;000d;PBS_Server;Job;14037.tyrone-cluster;Not sending email: User does not want mail of this type.
11/18/2012 13:30:16;0040;PBS_Server;Svr;tyrone-cluster;Scheduler was sent the command new
11/18/2012 13:30:46;0040;PBS_Server;Svr;tyrone-cluster;Scheduler was sent the command new
11/18/2012 13:31:19;0040;PBS_Server;Svr;tyrone-cluster;Scheduler was sent the command new
11/18/2012 13:31:50;0040;PBS_Server;Svr;tyrone-cluster;Scheduler was sent the command new
11/18/2012 13:32:20;0040;PBS_Server;Svr;tyrone-cluster;Scheduler was sent the command new
11/18/2012 13:32:51;0040;PBS_Server;Svr;tyrone-cluster;Scheduler was sent the command new
11/18/2012 13:33:23;0040;PBS_Server;Svr;tyrone-cluster;Scheduler was sent the command new
11/18/2012 13:33:49;0002;PBS_Server;Svr;PBS_Server;Torque Server Version = 3.0.5, loglevel = 0
11/18/2012 13:33:55;0040;PBS_Server;Svr;tyrone-cluster;Scheduler was sent the command new
11/18/2012 13:34:30;0040;PBS_Server;Svr;tyrone-cluster;Scheduler was sent the command new
11/18/2012 13:35:04;0040;PBS_Server;Svr;tyrone-cluster;Scheduler was sent the command new
11/18/2012 13:35:35;0040;PBS_Server;Svr;tyrone-cluster;Scheduler was sent the command new
11/18/2012 13:36:05;0040;PBS_Server;Svr;tyrone-cluster;Scheduler was sent the command new
11/18/2012 13:36:36;0040;PBS_Server;Svr;tyrone-cluster;Scheduler was sent the command new
11/18/2012 13:37:08;0040;PBS_Server;Svr;tyrone-cluster;Scheduler was sent the command new
11/18/2012 13:37:40;0040;PBS_Server;Svr;tyrone-cluster;Scheduler was sent the command new
11/18/2012 13:38:08;0040;PBS_Server;Svr;tyrone-cluster;Scheduler was sent the command new
11/18/2012 13:38:38;0040;PBS_Server;Svr;tyrone-cluster;Scheduler was sent the command new
11/18/2012 13:38:49;0002;PBS_Server;Svr;PBS_Server;Torque Server Version = 3.0.5, loglevel = 0
11/18/2012 13:39:10;0040;PBS_Server;Svr;tyrone-cluster;Scheduler was sent the command new
11/18/2012 13:39:45;0040;PBS_Server;Svr;tyrone-cluster;Scheduler was sent the command new
11/18/2012 13:40:19;0040;PBS_Server;Svr;tyrone-cluster;Scheduler was sent the command new
11/18/2012 13:40:50;0040;PBS_Server;Svr;tyrone-cluster;Scheduler was sent the command new
11/18/2012 13:41:20;0040;PBS_Server;Svr;tyrone-cluster;Scheduler was sent the command new
11/18/2012 13:41:51;0040;PBS_Server;Svr;tyrone-cluster;Scheduler was sent the command new
11/18/2012 13:42:23;0040;PBS_Server;Svr;tyrone-cluster;Scheduler was sent the command new
11/18/2012 13:42:55;0040;PBS_Server;Svr;tyrone-cluster;Scheduler was sent the command new
11/18/2012 13:43:23;0040;PBS_Server;Svr;tyrone-cluster;Scheduler was sent the command new
11/18/2012 13:43:49;0002;PBS_Server;Svr;PBS_Server;Torque Server Version = 3.0.5, loglevel = 0
11/18/2012 13:43:53;0040;PBS_Server;Svr;tyrone-cluster;Scheduler was sent the command new
11/18/2012 13:44:25;0040;PBS_Server;Svr;tyrone-cluster;Scheduler was sent the command new
11/18/2012 13:44:53;0040;PBS_Server;Svr;tyrone-cluster;Scheduler was sent the command new
11/18/2012 13:45:23;0040;PBS_Server;Svr;tyrone-cluster;Scheduler was sent the command new
11/18/2012 13:45:55;0040;PBS_Server;Svr;tyrone-cluster;Scheduler was sent the command new
11/18/2012 13:46:30;0040;PBS_Server;Svr;tyrone-cluster;Scheduler was sent the command new
11/18/2012 13:47:04;0040;PBS_Server;Svr;tyrone-cluster;Scheduler was sent the command new
11/18/2012 13:47:25;0100;PBS_Server;Job;14077.tyrone-cluster;enqueuing into batch, state 1 hop 1
11/18/2012 13:47:25;0100;PBS_Server;Job;14077.tyrone-cluster;dequeuing from batch, state QUEUED
11/18/2012 13:47:25;0100;PBS_Server;Job;14077.tyrone-cluster;enqueuing into idqueue, state 1 hop 1
11/18/2012 13:47:25;0008;PBS_Server;Job;14077.tyrone-cluster;Job Queued at request of secgeet@tyrone-cluster, owner = secgeet@tyrone-cluster, job name = myjob, queue = idqueue
11/18/2012 13:47:25;0040;PBS_Server;Svr;tyrone-cluster;Scheduler was sent the command new
11/18/2012 13:47:25;0008;PBS_Server;Job;14077.tyrone-cluster;Job Modified at request of Scheduler@tyrone-cluster
11/18/2012 13:47:25;0008;PBS_Server;Job;14077.tyrone-cluster;Job Run at request of Scheduler@tyrone-cluster
11/18/2012 13:47:25;0040;PBS_Server;Svr;tyrone-cluster;Scheduler was sent the command recyc
11/18/2012 13:47:25;000d;PBS_Server;Job;14077.tyrone-cluster;Not sending email: User does not want mail of this type.
11/18/2012 13:47:35;0040;PBS_Server;Svr;tyrone-cluster;Scheduler was sent the command new
11/18/2012 13:48:05;0040;PBS_Server;Svr;tyrone-cluster;Scheduler was sent the command new
11/18/2012 13:48:36;0040;PBS_Server;Svr;tyrone-cluster;Scheduler was sent the command new
11/18/2012 13:48:38;000d;PBS_Server;Job;14077.tyrone-cluster;Not sending email: User does not want mail of this type.
11/18/2012 13:48:38;0010;PBS_Server;Job;14077.tyrone-cluster;Exit_status=0 resources_used.cput=00:09:38 resources_used.mem=484288kb resources_used.vmem=4371548kb resources_used.walltime=00:01:13
11/18/2012 13:48:38;0008;PBS_Server;Job;NULL;on_job_exit valid pjob: 0x131f740 (substate=50)
11/18/2012 13:48:38;0008;PBS_Server;Job;NULL;on_job_exit valid pjob: 0x131f740 (substate=51)
11/18/2012 13:48:38;0008;PBS_Server;Job;NULL;on_job_exit valid pjob: 0x131f740 (substate=51)
11/18/2012 13:48:38;0008;PBS_Server;Job;NULL;on_job_exit valid pjob: 0x131f740 (substate=53)
11/18/2012 13:48:38;0100;PBS_Server;Job;14077.tyrone-cluster;dequeuing from idqueue, state COMPLETE
11/18/2012 13:48:38;0040;PBS_Server;Svr;tyrone-cluster;Scheduler was sent the command term
11/18/2012 13:48:49;0002;PBS_Server;Svr;PBS_Server;Torque Server Version = 3.0.5, loglevel = 0
11/18/2012 13:49:08;0040;PBS_Server;Svr;tyrone-cluster;Scheduler was sent the command new
11/18/2012 13:49:40;0040;PBS_Server;Svr;tyrone-cluster;Scheduler was sent the command new
11/18/2012 13:50:12;0040;PBS_Server;Svr;tyrone-cluster;Scheduler was sent the command new
11/18/2012 13:50:12;0100;PBS_Server;Job;14078.tyrone-cluster;enqueuing into batch, state 1 hop 1
11/18/2012 13:50:12;0100;PBS_Server;Job;14078.tyrone-cluster;dequeuing from batch, state QUEUED
11/18/2012 13:50:12;0100;PBS_Server;Job;14078.tyrone-cluster;enqueuing into idqueue, state 1 hop 1
11/18/2012 13:50:12;0008;PBS_Server;Job;14078.tyrone-cluster;Job Queued at request of secgeet@tyrone-cluster, owner = secgeet@tyrone-cluster, job name = myjob, queue = idqueue
11/18/2012 13:50:12;0008;PBS_Server;Job;14078.tyrone-cluster;Job Modified at request of Scheduler@tyrone-cluster
11/18/2012 13:50:12;0008;PBS_Server;Job;14078.tyrone-cluster;Job Run at request of Scheduler@tyrone-cluster
11/18/2012 13:50:12;0040;PBS_Server;Svr;tyrone-cluster;Scheduler was sent the command recyc
11/18/2012 13:50:12;000d;PBS_Server;Job;14078.tyrone-cluster;Not sending email: User does not want mail of this type.
11/18/2012 13:50:48;0040;PBS_Server;Svr;tyrone-cluster;Scheduler was sent the command new
11/18/2012 13:50:48;0100;PBS_Server;Job;14079.tyrone-cluster;enqueuing into batch, state 1 hop 1
11/18/2012 13:50:48;0100;PBS_Server;Job;14079.tyrone-cluster;dequeuing from batch, state QUEUED
11/18/2012 13:50:48;0100;PBS_Server;Job;14079.tyrone-cluster;enqueuing into idqueue, state 1 hop 1
11/18/2012 13:50:48;0008;PBS_Server;Job;14079.tyrone-cluster;Job Queued at request of secgeet@tyrone-cluster, owner = secgeet@tyrone-cluster, job name = myjob, queue = idqueue
11/18/2012 13:50:48;0008;PBS_Server;Job;14079.tyrone-cluster;Job Modified at request of Scheduler@tyrone-cluster
11/18/2012 13:50:48;0008;PBS_Server;Job;14079.tyrone-cluster;Job Run at request of Scheduler@tyrone-cluster
11/18/2012 13:50:49;000d;PBS_Server;Job;14079.tyrone-cluster;Not sending email: User does not want mail of this type.
11/18/2012 13:50:49;0040;PBS_Server;Svr;tyrone-cluster;Scheduler was sent the command recyc
11/18/2012 13:50:51;0100;PBS_Server;Job;14080.tyrone-cluster;enqueuing into batch, state 1 hop 1
11/18/2012 13:50:51;0100;PBS_Server;Job;14080.tyrone-cluster;dequeuing from batch, state QUEUED
11/18/2012 13:50:51;0100;PBS_Server;Job;14080.tyrone-cluster;enqueuing into idqueue, state 1 hop 1
11/18/2012 13:50:51;0008;PBS_Server;Job;14080.tyrone-cluster;Job Queued at request of secgeet@tyrone-cluster, owner = secgeet@tyrone-cluster, job name = myjob, queue = idqueue
11/18/2012 13:50:51;0040;PBS_Server;Svr;tyrone-cluster;Scheduler was sent the command new
11/18/2012 13:50:51;0008;PBS_Server;Job;14080.tyrone-cluster;Job Modified at request of Scheduler@tyrone-cluster
11/18/2012 13:50:52;0100;PBS_Server;Job;14081.tyrone-cluster;enqueuing into batch, state 1 hop 1
11/18/2012 13:50:52;0100;PBS_Server;Job;14081.tyrone-cluster;dequeuing from batch, state QUEUED
11/18/2012 13:50:52;0100;PBS_Server;Job;14081.tyrone-cluster;enqueuing into idqueue, state 1 hop 1
11/18/2012 13:50:52;0008;PBS_Server;Job;14081.tyrone-cluster;Job Queued at request of secgeet@tyrone-cluster, owner = secgeet@tyrone-cluster, job name = myjob, queue = idqueue
11/18/2012 13:50:52;0040;PBS_Server;Svr;tyrone-cluster;Scheduler was sent the command new
11/18/2012 13:50:52;0008;PBS_Server;Job;14081.tyrone-cluster;Job Modified at request of Scheduler@tyrone-cluster
11/18/2012 13:50:53;0100;PBS_Server;Job;14082.tyrone-cluster;enqueuing into batch, state 1 hop 1
11/18/2012 13:50:53;0100;PBS_Server;Job;14082.tyrone-cluster;dequeuing from batch, state QUEUED
11/18/2012 13:50:53;0100;PBS_Server;Job;14082.tyrone-cluster;enqueuing into idqueue, state 1 hop 1
11/18/2012 13:50:53;0008;PBS_Server;Job;14082.tyrone-cluster;Job Queued at request of secgeet@tyrone-cluster, owner = secgeet@tyrone-cluster, job name = myjob, queue = idqueue
11/18/2012 13:50:53;0040;PBS_Server;Svr;tyrone-cluster;Scheduler was sent the command new
11/18/2012 13:50:53;0008;PBS_Server;Job;14082.tyrone-cluster;Job Modified at request of Scheduler@tyrone-cluster
11/18/2012 13:51:20;0040;PBS_Server;Svr;tyrone-cluster;Scheduler was sent the command new
11/18/2012 13:51:50;0040;PBS_Server;Svr;tyrone-cluster;Scheduler was sent the command new
11/18/2012 13:52:21;0040;PBS_Server;Svr;tyrone-cluster;Scheduler was sent the command new
11/18/2012 13:52:53;0040;PBS_Server;Svr;tyrone-cluster;Scheduler was sent the command new
11/18/2012 13:53:25;0040;PBS_Server;Svr;tyrone-cluster;Scheduler was sent the command new
11/18/2012 13:53:49;0002;PBS_Server;Svr;PBS_Server;Torque Server Version = 3.0.5, loglevel = 0
11/18/2012 13:54:00;0040;PBS_Server;Svr;tyrone-cluster;Scheduler was sent the command new
11/18/2012 13:54:30;0040;PBS_Server;Svr;tyrone-cluster;Scheduler was sent the command new
11/18/2012 13:55:01;0040;PBS_Server;Svr;tyrone-cluster;Scheduler was sent the command new
11/18/2012 13:55:31;0040;PBS_Server;Svr;tyrone-cluster;Scheduler was sent the command new
11/18/2012 13:56:04;0040;PBS_Server;Svr;tyrone-cluster;Scheduler was sent the command new
11/18/2012 13:56:35;0040;PBS_Server;Svr;tyrone-cluster;Scheduler was sent the command new
11/18/2012 13:57:00;000d;PBS_Server;Job;14078.tyrone-cluster;Not sending email: User does not want mail of this type.
11/18/2012 13:57:00;0010;PBS_Server;Job;14078.tyrone-cluster;Exit_status=0 resources_used.cput=01:05:40 resources_used.mem=628092kb resources_used.vmem=6388536kb resources_used.walltime=00:06:48
11/18/2012 13:57:00;0008;PBS_Server;Job;NULL;on_job_exit valid pjob: 0x131f740 (substate=50)
11/18/2012 13:57:00;0008;PBS_Server;Job;NULL;on_job_exit valid pjob: 0x131f740 (substate=51)
11/18/2012 13:57:00;0008;PBS_Server;Job;NULL;on_job_exit valid pjob: 0x131f740 (substate=51)
11/18/2012 13:57:00;0008;PBS_Server;Job;NULL;on_job_exit valid pjob: 0x131f740 (substate=53)
11/18/2012 13:57:00;0100;PBS_Server;Job;14078.tyrone-cluster;dequeuing from idqueue, state COMPLETE
11/18/2012 13:57:00;0040;PBS_Server;Svr;tyrone-cluster;Scheduler was sent the command term
11/18/2012 13:57:01;0008;PBS_Server;Job;14080.tyrone-cluster;Job Modified at request of Scheduler@tyrone-cluster
11/18/2012 13:57:01;0008;PBS_Server;Job;14080.tyrone-cluster;Job Run at request of Scheduler@tyrone-cluster
11/18/2012 13:57:01;0040;PBS_Server;Svr;tyrone-cluster;Scheduler was sent the command recyc
11/18/2012 13:57:01;000d;PBS_Server;Job;14080.tyrone-cluster;Not sending email: User does not want mail of this type.
11/18/2012 13:57:05;0040;PBS_Server;Svr;tyrone-cluster;Scheduler was sent the command new
11/18/2012 13:57:34;000d;PBS_Server;Job;14079.tyrone-cluster;Not sending email: User does not want mail of this type.
11/18/2012 13:57:34;0010;PBS_Server;Job;14079.tyrone-cluster;Exit_status=0 resources_used.cput=01:05:01 resources_used.mem=628108kb resources_used.vmem=6388536kb resources_used.walltime=00:06:46
11/18/2012 13:57:34;0008;PBS_Server;Job;NULL;on_job_exit valid pjob: 0x1317ed0 (substate=50)
11/18/2012 13:57:34;0008;PBS_Server;Job;NULL;on_job_exit valid pjob: 0x1317ed0 (substate=51)
11/18/2012 13:57:34;0008;PBS_Server;Job;NULL;on_job_exit valid pjob: 0x1317ed0 (substate=51)
11/18/2012 13:57:34;0008;PBS_Server;Job;NULL;on_job_exit valid pjob: 0x1317ed0 (substate=53)
11/18/2012 13:57:34;0100;PBS_Server;Job;14079.tyrone-cluster;dequeuing from idqueue, state COMPLETE
11/18/2012 13:57:34;0040;PBS_Server;Svr;tyrone-cluster;Scheduler was sent the command term
11/18/2012 13:57:34;0008;PBS_Server;Job;14081.tyrone-cluster;Job Modified at request of Scheduler@tyrone-cluster
11/18/2012 13:57:34;0008;PBS_Server;Job;14081.tyrone-cluster;Job Run at request of Scheduler@tyrone-cluster
11/18/2012 13:57:34;0040;PBS_Server;Svr;tyrone-cluster;Scheduler was sent the command recyc
11/18/2012 13:57:34;000d;PBS_Server;Job;14081.tyrone-cluster;Not sending email: User does not want mail of this type.
11/18/2012 13:57:36;0040;PBS_Server;Svr;tyrone-cluster;Scheduler was sent the command new
11/18/2012 13:58:08;0040;PBS_Server;Svr;tyrone-cluster;Scheduler was sent the command new
11/18/2012 13:58:40;0040;PBS_Server;Svr;tyrone-cluster;Scheduler was sent the command new
11/18/2012 13:58:49;0002;PBS_Server;Svr;PBS_Server;Torque Server Version = 3.0.5, loglevel = 0
11/18/2012 13:59:08;0040;PBS_Server;Svr;tyrone-cluster;Scheduler was sent the command new
11/18/2012 13:59:38;0040;PBS_Server;Svr;tyrone-cluster;Scheduler was sent the command new
11/18/2012 14:00:10;0040;PBS_Server;Svr;tyrone-cluster;Scheduler was sent the command new
11/18/2012 14:00:38;0040;PBS_Server;Svr;tyrone-cluster;Scheduler was sent the command new
11/18/2012 14:01:08;0040;PBS_Server;Svr;tyrone-cluster;Scheduler was sent the command new
11/18/2012 14:01:40;0040;PBS_Server;Svr;tyrone-cluster;Scheduler was sent the command new
11/18/2012 14:02:08;0040;PBS_Server;Svr;tyrone-cluster;Scheduler was sent the command new
11/18/2012 14:02:30;0100;PBS_Server;Job;14083.tyrone-cluster;enqueuing into batch, state 1 hop 1
11/18/2012 14:02:30;0100;PBS_Server;Job;14083.tyrone-cluster;dequeuing from batch, state QUEUED
11/18/2012 14:02:30;0100;PBS_Server;Job;14083.tyrone-cluster;enqueuing into qp32, state 1 hop 1
11/18/2012 14:02:30;0008;PBS_Server;Job;14083.tyrone-cluster;Job Queued at request of mrcpndey@tyrone-cluster, owner = mrcpndey@tyrone-cluster, job name = 1_disp, queue = qp32
11/18/2012 14:02:30;0040;PBS_Server;Svr;tyrone-cluster;Scheduler was sent the command new
11/18/2012 14:02:30;0008;PBS_Server;Job;14083.tyrone-cluster;Job Modified at request of Scheduler@tyrone-cluster
11/18/2012 14:02:38;0040;PBS_Server;Svr;tyrone-cluster;Scheduler was sent the command new
11/18/2012 14:03:02;0100;PBS_Server;Job;14084.tyrone-cluster;enqueuing into batch, state 1 hop 1
11/18/2012 14:03:02;0100;PBS_Server;Job;14084.tyrone-cluster;dequeuing from batch, state QUEUED
11/18/2012 14:03:02;0100;PBS_Server;Job;14084.tyrone-cluster;enqueuing into qp32, state 1 hop 1
11/18/2012 14:03:02;0008;PBS_Server;Job;14084.tyrone-cluster;Job Queued at request of mrcpndey@tyrone-cluster, owner = mrcpndey@tyrone-cluster, job name = 2_disp, queue = qp32
11/18/2012 14:03:02;0040;PBS_Server;Svr;tyrone-cluster;Scheduler was sent the command new
11/18/2012 14:03:02;0008;PBS_Server;Job;14084.tyrone-cluster;Job Modified at request of Scheduler@tyrone-cluster
11/18/2012 14:03:10;0040;PBS_Server;Svr;tyrone-cluster;Scheduler was sent the command new
11/18/2012 14:03:44;0040;PBS_Server;Svr;tyrone-cluster;Scheduler was sent the command new
11/18/2012 14:03:46;000d;PBS_Server;Job;14080.tyrone-cluster;Not sending email: User does not want mail of this type.
11/18/2012 14:03:46;0010;PBS_Server;Job;14080.tyrone-cluster;Exit_status=0 resources_used.cput=01:04:59 resources_used.mem=881844kb resources_used.vmem=6388536kb resources_used.walltime=00:06:45
11/18/2012 14:03:46;0008;PBS_Server;Job;NULL;on_job_exit valid pjob: 0x12f5dd0 (substate=50)
11/18/2012 14:03:46;0008;PBS_Server;Job;NULL;on_job_exit valid pjob: 0x12f5dd0 (substate=51)
11/18/2012 14:03:46;0008;PBS_Server;Job;NULL;on_job_exit valid pjob: 0x12f5dd0 (substate=51)
11/18/2012 14:03:46;0008;PBS_Server;Job;NULL;on_job_exit valid pjob: 0x12f5dd0 (substate=53)
11/18/2012 14:03:46;0100;PBS_Server;Job;14080.tyrone-cluster;dequeuing from idqueue, state COMPLETE
11/18/2012 14:03:46;0040;PBS_Server;Svr;tyrone-cluster;Scheduler was sent the command term
11/18/2012 14:03:46;0008;PBS_Server;Job;14082.tyrone-cluster;Job Modified at request of Scheduler@tyrone-cluster
11/18/2012 14:03:46;0008;PBS_Server;Job;14082.tyrone-cluster;Job Run at request of Scheduler@tyrone-cluster
11/18/2012 14:03:46;0040;PBS_Server;Svr;tyrone-cluster;Scheduler was sent the command recyc
11/18/2012 14:03:46;000d;PBS_Server;Job;14082.tyrone-cluster;Not sending email: User does not want mail of this type.
11/18/2012 14:03:49;0002;PBS_Server;Svr;PBS_Server;Torque Server Version = 3.0.5, loglevel = 0
11/18/2012 14:04:17;0040;PBS_Server;Svr;tyrone-cluster;Scheduler was sent the command new
11/18/2012 14:04:25;000d;PBS_Server;Job;14081.tyrone-cluster;Not sending email: User does not want mail of this type.
11/18/2012 14:04:25;0010;PBS_Server;Job;14081.tyrone-cluster;Exit_status=0 resources_used.cput=01:05:54 resources_used.mem=628116kb resources_used.vmem=6388536kb resources_used.walltime=00:06:51
11/18/2012 14:04:25;0008;PBS_Server;Job;NULL;on_job_exit valid pjob: 0x13de8b0 (substate=50)
11/18/2012 14:04:25;0008;PBS_Server;Job;NULL;on_job_exit valid pjob: 0x13de8b0 (substate=51)
11/18/2012 14:04:25;0008;PBS_Server;Job;NULL;on_job_exit valid pjob: 0x13de8b0 (substate=51)
11/18/2012 14:04:25;0008;PBS_Server;Job;NULL;on_job_exit valid pjob: 0x13de8b0 (substate=53)
11/18/2012 14:04:25;0100;PBS_Server;Job;14081.tyrone-cluster;dequeuing from idqueue, state COMPLETE
11/18/2012 14:04:25;0040;PBS_Server;Svr;tyrone-cluster;Scheduler was sent the command term
11/18/2012 14:04:47;0040;PBS_Server;Svr;tyrone-cluster;Scheduler was sent the command new
11/18/2012 14:05:17;0040;PBS_Server;Svr;tyrone-cluster;Scheduler was sent the command new
11/18/2012 14:05:49;0040;PBS_Server;Svr;tyrone-cluster;Scheduler was sent the command new
11/18/2012 14:06:20;0040;PBS_Server;Svr;tyrone-cluster;Scheduler was sent the command new
11/18/2012 14:06:50;0040;PBS_Server;Svr;tyrone-cluster;Scheduler was sent the command new
11/18/2012 14:07:21;0040;PBS_Server;Svr;tyrone-cluster;Scheduler was sent the command new
11/18/2012 14:07:53;0040;PBS_Server;Svr;tyrone-cluster;Scheduler was sent the command new
11/18/2012 14:08:25;0040;PBS_Server;Svr;tyrone-cluster;Scheduler was sent the command new
11/18/2012 14:08:49;0002;PBS_Server;Svr;PBS_Server;Torque Server Version = 3.0.5, loglevel = 0
11/18/2012 14:08:53;0040;PBS_Server;Svr;tyrone-cluster;Scheduler was sent the command new
11/18/2012 14:09:23;0040;PBS_Server;Svr;tyrone-cluster;Scheduler was sent the command new
11/18/2012 14:09:55;0040;PBS_Server;Svr;tyrone-cluster;Scheduler was sent the command new
11/18/2012 14:09:57;0100;PBS_Server;Job;14085.tyrone-cluster;enqueuing into batch, state 1 hop 1
11/18/2012 14:09:57;0100;PBS_Server;Job;14085.tyrone-cluster;dequeuing from batch, state QUEUED
11/18/2012 14:09:57;0100;PBS_Server;Job;14085.tyrone-cluster;enqueuing into idqueue, state 1 hop 1
11/18/2012 14:09:57;0008;PBS_Server;Job;14085.tyrone-cluster;Job Queued at request of secvkm@tyrone-cluster, owner = secvkm@tyrone-cluster, job name = myjob, queue = idqueue
11/18/2012 14:09:57;0040;PBS_Server;Svr;tyrone-cluster;Scheduler was sent the command new
11/18/2012 14:09:57;0008;PBS_Server;Job;14085.tyrone-cluster;Job Modified at request of Scheduler@tyrone-cluster
11/18/2012 14:09:57;0008;PBS_Server;Job;14085.tyrone-cluster;Job Run at request of Scheduler@tyrone-cluster
11/18/2012 14:09:57;0040;PBS_Server;Svr;tyrone-cluster;Scheduler was sent the command recyc
11/18/2012 14:09:57;000d;PBS_Server;Job;14085.tyrone-cluster;Not sending email: User does not want mail of this type.
11/18/2012 14:10:30;0040;PBS_Server;Svr;tyrone-cluster;Scheduler was sent the command new
11/18/2012 14:10:30;000d;PBS_Server;Job;14082.tyrone-cluster;Not sending email: User does not want mail of this type.
11/18/2012 14:10:30;0010;PBS_Server;Job;14082.tyrone-cluster;Exit_status=0 resources_used.cput=01:04:48 resources_used.mem=945284kb resources_used.vmem=6388536kb resources_used.walltime=00:06:44
11/18/2012 14:10:30;0008;PBS_Server;Job;NULL;on_job_exit valid pjob: 0x1304bf0 (substate=50)
11/18/2012 14:10:30;0008;PBS_Server;Job;NULL;on_job_exit valid pjob: 0x1304bf0 (substate=51)
11/18/2012 14:10:30;0008;PBS_Server;Job;NULL;on_job_exit valid pjob: 0x1304bf0 (substate=51)
11/18/2012 14:10:30;0008;PBS_Server;Job;NULL;on_job_exit valid pjob: 0x1304bf0 (substate=53)
11/18/2012 14:10:30;0100;PBS_Server;Job;14082.tyrone-cluster;dequeuing from idqueue, state COMPLETE
11/18/2012 14:10:54;000d;PBS_Server;Job;14085.tyrone-cluster;Not sending email: User does not want mail of this type.
11/18/2012 14:10:54;0010;PBS_Server;Job;14085.tyrone-cluster;Exit_status=0 resources_used.cput=00:03:45 resources_used.mem=884756kb resources_used.vmem=3683048kb resources_used.walltime=00:00:57
11/18/2012 14:10:54;0008;PBS_Server;Job;NULL;on_job_exit valid pjob: 0x131f740 (substate=50)
11/18/2012 14:10:54;0008;PBS_Server;Job;NULL;on_job_exit valid pjob: 0x131f740 (substate=51)
11/18/2012 14:10:54;0008;PBS_Server;Job;NULL;on_job_exit valid pjob: 0x131f740 (substate=51)
11/18/2012 14:10:54;0008;PBS_Server;Job;NULL;on_job_exit valid pjob: 0x131f740 (substate=53)
11/18/2012 14:10:54;0100;PBS_Server;Job;14085.tyrone-cluster;dequeuing from idqueue, state COMPLETE
11/18/2012 14:10:54;0040;PBS_Server;Svr;tyrone-cluster;Scheduler was sent the command term
11/18/2012 14:11:04;0040;PBS_Server;Svr;tyrone-cluster;Scheduler was sent the command new
11/18/2012 14:11:35;0040;PBS_Server;Svr;tyrone-cluster;Scheduler was sent the command new
11/18/2012 14:12:05;0040;PBS_Server;Svr;tyrone-cluster;Scheduler was sent the command new
11/18/2012 14:12:36;0040;PBS_Server;Svr;tyrone-cluster;Scheduler was sent the command new
11/18/2012 14:13:08;0040;PBS_Server;Svr;tyrone-cluster;Scheduler was sent the command new
11/18/2012 14:13:40;0040;PBS_Server;Svr;tyrone-cluster;Scheduler was sent the command new
11/18/2012 14:13:49;0002;PBS_Server;Svr;PBS_Server;Torque Server Version = 3.0.5, loglevel = 0
11/18/2012 14:14:15;0040;PBS_Server;Svr;tyrone-cluster;Scheduler was sent the command new
11/18/2012 14:14:49;0040;PBS_Server;Svr;tyrone-cluster;Scheduler was sent the command new
11/18/2012 14:15:20;0040;PBS_Server;Svr;tyrone-cluster;Scheduler was sent the command new
11/18/2012 14:15:35;0100;PBS_Server;Job;14086.tyrone-cluster;enqueuing into batch, state 1 hop 1
11/18/2012 14:15:35;0100;PBS_Server;Job;14086.tyrone-cluster;dequeuing from batch, state QUEUED
11/18/2012 14:15:35;0100;PBS_Server;Job;14086.tyrone-cluster;enqueuing into idqueue, state 1 hop 1
11/18/2012 14:15:35;0008;PBS_Server;Job;14086.tyrone-cluster;Job Queued at request of ipcvrk@tyrone-cluster, owner = ipcvrk@tyrone-cluster, job name = pq.cmd, queue = idqueue
11/18/2012 14:15:35;0040;PBS_Server;Svr;tyrone-cluster;Scheduler was sent the command new
11/18/2012 14:15:35;0008;PBS_Server;Job;14086.tyrone-cluster;Job Modified at request of Scheduler@tyrone-cluster
11/18/2012 14:15:35;0008;PBS_Server;Job;14086.tyrone-cluster;Job Run at request of Scheduler@tyrone-cluster
11/18/2012 14:15:36;000d;PBS_Server;Job;14086.tyrone-cluster;Not sending email: User does not want mail of this type.
11/18/2012 14:15:36;0040;PBS_Server;Svr;tyrone-cluster;Scheduler was sent the command recyc
11/18/2012 14:15:50;0040;PBS_Server;Svr;tyrone-cluster;Scheduler was sent the command new
11/18/2012 14:15:53;0100;PBS_Server;Job;14087.tyrone-cluster;enqueuing into batch, state 1 hop 1
11/18/2012 14:15:53;0100;PBS_Server;Job;14087.tyrone-cluster;dequeuing from batch, state QUEUED
11/18/2012 14:15:53;0100;PBS_Server;Job;14087.tyrone-cluster;enqueuing into idqueue, state 1 hop 1
11/18/2012 14:15:53;0008;PBS_Server;Job;14087.tyrone-cluster;Job Queued at request of secbadar@tyrone-cluster, owner = secbadar@tyrone-cluster, job name = myjob, queue = idqueue
11/18/2012 14:15:53;0040;PBS_Server;Svr;tyrone-cluster;Scheduler was sent the command new
11/18/2012 14:15:53;0008;PBS_Server;Job;14087.tyrone-cluster;Job Modified at request of Scheduler@tyrone-cluster
11/18/2012 14:15:53;0008;PBS_Server;Job;14087.tyrone-cluster;Job Run at request of Scheduler@tyrone-cluster
11/18/2012 14:15:53;0040;PBS_Server;Svr;tyrone-cluster;Scheduler was sent the command recyc
11/18/2012 14:15:53;000d;PBS_Server;Job;14087.tyrone-cluster;Not sending email: User does not want mail of this type.
11/18/2012 14:16:13;0100;PBS_Server;Job;14088.tyrone-cluster;enqueuing into batch, state 1 hop 1
11/18/2012 14:16:13;0100;PBS_Server;Job;14088.tyrone-cluster;dequeuing from batch, state QUEUED
11/18/2012 14:16:13;0100;PBS_Server;Job;14088.tyrone-cluster;enqueuing into qp32, state 1 hop 1
11/18/2012 14:16:13;0008;PBS_Server;Job;14088.tyrone-cluster;Job Queued at request of ipcvrk@tyrone-cluster, owner = ipcvrk@tyrone-cluster, job name = pq1.cmd, queue = qp32
11/18/2012 14:16:13;0040;PBS_Server;Svr;tyrone-cluster;Scheduler was sent the command new
11/18/2012 14:16:13;0008;PBS_Server;Job;14088.tyrone-cluster;Job Modified at request of Scheduler@tyrone-cluster
11/18/2012 14:16:21;0040;PBS_Server;Svr;tyrone-cluster;Scheduler was sent the command new
11/18/2012 14:16:41;0100;PBS_Server;Job;14089.tyrone-cluster;enqueuing into batch, state 1 hop 1
11/18/2012 14:16:41;0100;PBS_Server;Job;14089.tyrone-cluster;dequeuing from batch, state QUEUED
11/18/2012 14:16:41;0100;PBS_Server;Job;14089.tyrone-cluster;enqueuing into qp32, state 1 hop 1
11/18/2012 14:16:41;0008;PBS_Server;Job;14089.tyrone-cluster;Job Queued at request of ipcvrk@tyrone-cluster, owner = ipcvrk@tyrone-cluster, job name = pq2.cmd, queue = qp32
11/18/2012 14:16:41;0040;PBS_Server;Svr;tyrone-cluster;Scheduler was sent the command new
11/18/2012 14:16:41;0008;PBS_Server;Job;14089.tyrone-cluster;Job Modified at request of Scheduler@tyrone-cluster
11/18/2012 14:16:52;0040;PBS_Server;Svr;tyrone-cluster;Scheduler was sent the command new
11/18/2012 14:17:24;0040;PBS_Server;Svr;tyrone-cluster;Scheduler was sent the command new
11/18/2012 14:17:32;0100;PBS_Server;Job;14090.tyrone-cluster;enqueuing into batch, state 1 hop 1
11/18/2012 14:17:32;0100;PBS_Server;Job;14090.tyrone-cluster;dequeuing from batch, state QUEUED
11/18/2012 14:17:32;0100;PBS_Server;Job;14090.tyrone-cluster;enqueuing into qp64, state 1 hop 1
11/18/2012 14:17:32;0008;PBS_Server;Job;14090.tyrone-cluster;Job Queued at request of ipcvrk@tyrone-cluster, owner = ipcvrk@tyrone-cluster, job name = pq3.cmd, queue = qp64
11/18/2012 14:17:32;0040;PBS_Server;Svr;tyrone-cluster;Scheduler was sent the command new
11/18/2012 14:17:32;0008;PBS_Server;Job;14090.tyrone-cluster;Job Modified at request of Scheduler@tyrone-cluster
11/18/2012 14:17:53;0040;PBS_Server;Svr;tyrone-cluster;Scheduler was sent the command new
11/18/2012 14:18:23;0040;PBS_Server;Svr;tyrone-cluster;Scheduler was sent the command new
11/18/2012 14:18:49;0002;PBS_Server;Svr;PBS_Server;Torque Server Version = 3.0.5, loglevel = 0
11/18/2012 14:18:54;0040;PBS_Server;Svr;tyrone-cluster;Scheduler was sent the command new
11/18/2012 14:19:23;0040;PBS_Server;Svr;tyrone-cluster;Scheduler was sent the command new
11/18/2012 14:19:34;000d;PBS_Server;Job;14087.tyrone-cluster;Not sending email: User does not want mail of this type.
11/18/2012 14:19:34;0010;PBS_Server;Job;14087.tyrone-cluster;Exit_status=0 resources_used.cput=00:16:21 resources_used.mem=509432kb resources_used.vmem=1235396kb resources_used.walltime=00:03:41
11/18/2012 14:19:34;0008;PBS_Server;Job;NULL;on_job_exit valid pjob: 0x131f740 (substate=50)
11/18/2012 14:19:34;0008;PBS_Server;Job;NULL;on_job_exit valid pjob: 0x131f740 (substate=51)
11/18/2012 14:19:34;0008;PBS_Server;Job;NULL;on_job_exit valid pjob: 0x131f740 (substate=51)
11/18/2012 14:19:34;0008;PBS_Server;Job;NULL;on_job_exit valid pjob: 0x131f740 (substate=53)
11/18/2012 14:19:34;0100;PBS_Server;Job;14087.tyrone-cluster;dequeuing from idqueue, state COMPLETE
11/18/2012 14:19:34;0040;PBS_Server;Svr;tyrone-cluster;Scheduler was sent the command term
11/18/2012 14:19:53;0040;PBS_Server;Svr;tyrone-cluster;Scheduler was sent the command new
11/18/2012 14:19:59;000d;PBS_Server;Job;13799.tyrone-cluster;Not sending email: User does not want mail of this type.
11/18/2012 14:19:59;0010;PBS_Server;Job;13799.tyrone-cluster;Exit_status=0 resources_used.cput=159:30:39 resources_used.mem=661416kb resources_used.vmem=7125784kb resources_used.walltime=04:59:36
11/18/2012 14:19:59;0008;PBS_Server;Job;NULL;on_job_exit valid pjob: 0x12f83c0 (substate=50)
11/18/2012 14:19:59;0008;PBS_Server;Job;NULL;on_job_exit valid pjob: 0x12f83c0 (substate=51)
11/18/2012 14:20:01;0008;PBS_Server;Job;NULL;on_job_exit valid pjob: 0x12f83c0 (substate=51)
11/18/2012 14:20:01;0008;PBS_Server;Job;NULL;on_job_exit valid pjob: 0x12f83c0 (substate=53)
11/18/2012 14:20:01;0100;PBS_Server;Job;13799.tyrone-cluster;dequeuing from qp32, state COMPLETE
11/18/2012 14:20:01;0040;PBS_Server;Svr;tyrone-cluster;Scheduler was sent the command term
11/18/2012 14:20:01;0008;PBS_Server;Job;13592.tyrone-cluster;Job Modified at request of Scheduler@tyrone-cluster
11/18/2012 14:20:01;0008;PBS_Server;Job;13592.tyrone-cluster;Job Run at request of Scheduler@tyrone-cluster
11/18/2012 14:20:01;0040;PBS_Server;Svr;tyrone-cluster;Scheduler was sent the command recyc
11/18/2012 14:20:01;000d;PBS_Server;Job;13592.tyrone-cluster;Not sending email: User does not want mail of this type.
11/18/2012 14:20:24;0040;PBS_Server;Svr;tyrone-cluster;Scheduler was sent the command new
11/18/2012 14:20:53;0040;PBS_Server;Svr;tyrone-cluster;Scheduler was sent the command new
11/18/2012 14:21:34;0040;PBS_Server;Svr;tyrone-cluster;Scheduler was sent the command new
11/18/2012 14:22:05;0040;PBS_Server;Svr;tyrone-cluster;Scheduler was sent the command new
11/18/2012 14:22:16;0100;PBS_Server;Job;14091.tyrone-cluster;enqueuing into batch, state 1 hop 1
11/18/2012 14:22:16;0100;PBS_Server;Job;14091.tyrone-cluster;dequeuing from batch, state QUEUED
11/18/2012 14:22:16;0100;PBS_Server;Job;14091.tyrone-cluster;enqueuing into idqueue, state 1 hop 1
11/18/2012 14:22:16;0008;PBS_Server;Job;14091.tyrone-cluster;Job Queued at request of secvkm@tyrone-cluster, owner = secvkm@tyrone-cluster, job name = myjob, queue = idqueue
11/18/2012 14:22:16;0040;PBS_Server;Svr;tyrone-cluster;Scheduler was sent the command new
11/18/2012 14:22:16;0008;PBS_Server;Job;14091.tyrone-cluster;Job Modified at request of Scheduler@tyrone-cluster
11/18/2012 14:22:16;0008;PBS_Server;Job;14091.tyrone-cluster;Job Run at request of Scheduler@tyrone-cluster
11/18/2012 14:22:17;0040;PBS_Server;Svr;tyrone-cluster;Scheduler was sent the command recyc
11/18/2012 14:22:17;000d;PBS_Server;Job;14091.tyrone-cluster;Not sending email: User does not want mail of this type.
11/18/2012 14:22:35;0040;PBS_Server;Svr;tyrone-cluster;Scheduler was sent the command new
11/18/2012 14:23:06;0040;PBS_Server;Svr;tyrone-cluster;Scheduler was sent the command new
11/18/2012 14:23:49;0002;PBS_Server;Svr;PBS_Server;Torque Server Version = 3.0.5, loglevel = 0
11/18/2012 14:23:49;0040;PBS_Server;Svr;tyrone-cluster;Scheduler was sent the command new
11/18/2012 14:24:16;0040;PBS_Server;Svr;tyrone-cluster;Scheduler was sent the command new
11/18/2012 14:24:47;0040;PBS_Server;Svr;tyrone-cluster;Scheduler was sent the command new
11/18/2012 14:25:19;0040;PBS_Server;Svr;tyrone-cluster;Scheduler was sent the command new
11/18/2012 14:25:50;0040;PBS_Server;Svr;tyrone-cluster;Scheduler was sent the command new
11/18/2012 14:26:20;0040;PBS_Server;Svr;tyrone-cluster;Scheduler was sent the command new
11/18/2012 14:26:21;000d;PBS_Server;Job;14091.tyrone-cluster;Not sending email: User does not want mail of this type.
11/18/2012 14:26:21;0010;PBS_Server;Job;14091.tyrone-cluster;Exit_status=0 resources_used.cput=00:03:32 resources_used.mem=809880kb resources_used.vmem=1132460kb resources_used.walltime=00:04:05
11/18/2012 14:26:21;0008;PBS_Server;Job;NULL;on_job_exit valid pjob: 0x12f83c0 (substate=50)
11/18/2012 14:26:21;0008;PBS_Server;Job;NULL;on_job_exit valid pjob: 0x12f83c0 (substate=51)
11/18/2012 14:26:22;0008;PBS_Server;Job;NULL;on_job_exit valid pjob: 0x12f83c0 (substate=51)
11/18/2012 14:26:22;0008;PBS_Server;Job;NULL;on_job_exit valid pjob: 0x12f83c0 (substate=53)
11/18/2012 14:26:22;0100;PBS_Server;Job;14091.tyrone-cluster;dequeuing from idqueue, state COMPLETE
11/18/2012 14:26:22;0040;PBS_Server;Svr;tyrone-cluster;Scheduler was sent the command term
11/18/2012 14:26:51;0040;PBS_Server;Svr;tyrone-cluster;Scheduler was sent the command new
11/18/2012 14:27:34;0040;PBS_Server;Svr;tyrone-cluster;Scheduler was sent the command new
11/18/2012 14:28:05;0040;PBS_Server;Svr;tyrone-cluster;Scheduler was sent the command new
11/18/2012 14:28:35;0040;PBS_Server;Svr;tyrone-cluster;Scheduler was sent the command new
11/18/2012 14:28:49;0002;PBS_Server;Svr;PBS_Server;Torque Server Version = 3.0.5, loglevel = 0
11/18/2012 14:28:54;0100;PBS_Server;Job;14092.tyrone-cluster;enqueuing into batch, state 1 hop 1
11/18/2012 14:28:54;0100;PBS_Server;Job;14092.tyrone-cluster;dequeuing from batch, state QUEUED
11/18/2012 14:28:54;0100;PBS_Server;Job;14092.tyrone-cluster;enqueuing into idqueue, state 1 hop 1
11/18/2012 14:28:54;0008;PBS_Server;Job;14092.tyrone-cluster;Job Queued at request of ipcvrk@tyrone-cluster, owner = ipcvrk@tyrone-cluster, job name = pqtrip.cmd, queue = idqueue
11/18/2012 14:28:54;0040;PBS_Server;Svr;tyrone-cluster;Scheduler was sent the command new
11/18/2012 14:28:54;0008;PBS_Server;Job;14092.tyrone-cluster;Job Modified at request of Scheduler@tyrone-cluster
11/18/2012 14:28:54;0008;PBS_Server;Job;14092.tyrone-cluster;Job Run at request of Scheduler@tyrone-cluster
11/18/2012 14:28:54;0040;PBS_Server;Svr;tyrone-cluster;Scheduler was sent the command recyc
11/18/2012 14:28:54;000d;PBS_Server;Job;14092.tyrone-cluster;Not sending email: User does not want mail of this type.
11/18/2012 14:29:06;0040;PBS_Server;Svr;tyrone-cluster;Scheduler was sent the command new
11/18/2012 14:29:13;0100;PBS_Server;Job;14093.tyrone-cluster;enqueuing into batch, state 1 hop 1
11/18/2012 14:29:13;0100;PBS_Server;Job;14093.tyrone-cluster;dequeuing from batch, state QUEUED
11/18/2012 14:29:13;0100;PBS_Server;Job;14093.tyrone-cluster;enqueuing into idqueue, state 1 hop 1
11/18/2012 14:29:13;0008;PBS_Server;Job;14093.tyrone-cluster;Job Queued at request of ipcvrk@tyrone-cluster, owner = ipcvrk@tyrone-cluster, job name = pq.cmd, queue = idqueue
11/18/2012 14:29:13;0040;PBS_Server;Svr;tyrone-cluster;Scheduler was sent the command new
11/18/2012 14:29:13;0008;PBS_Server;Job;14093.tyrone-cluster;Job Modified at request of Scheduler@tyrone-cluster
11/18/2012 14:29:18;0008;PBS_Server;Job;14092.tyrone-cluster;Job deleted at request of ipcvrk@tyrone-cluster
11/18/2012 14:29:18;0008;PBS_Server;Job;14092.tyrone-cluster;Job sent signal SIGTERM on delete
11/18/2012 14:29:20;0008;PBS_Server;Job;14092.tyrone-cluster;Job sent signal SIGKILL on delete
11/18/2012 14:29:24;000d;PBS_Server;Job;14092.tyrone-cluster;Not sending email: User does not want mail of this type.
11/18/2012 14:29:24;0010;PBS_Server;Job;14092.tyrone-cluster;Exit_status=143 resources_used.cput=00:04:15 resources_used.mem=134464kb resources_used.vmem=18510584kb resources_used.walltime=00:00:30
11/18/2012 14:29:24;0008;PBS_Server;Job;NULL;on_job_exit valid pjob: 0x131f740 (substate=50)
11/18/2012 14:29:24;0008;PBS_Server;Job;NULL;on_job_exit valid pjob: 0x131f740 (substate=51)
11/18/2012 14:29:24;0008;PBS_Server;Job;NULL;on_job_exit valid pjob: 0x131f740 (substate=51)
11/18/2012 14:29:24;0008;PBS_Server;Job;NULL;on_job_exit valid pjob: 0x131f740 (substate=53)
11/18/2012 14:29:24;0100;PBS_Server;Job;14092.tyrone-cluster;dequeuing from idqueue, state COMPLETE
11/18/2012 14:29:24;0040;PBS_Server;Svr;tyrone-cluster;Scheduler was sent the command term
11/18/2012 14:29:24;0008;PBS_Server;Job;14093.tyrone-cluster;Job Modified at request of Scheduler@tyrone-cluster
11/18/2012 14:29:24;0008;PBS_Server;Job;14093.tyrone-cluster;Job Run at request of Scheduler@tyrone-cluster
11/18/2012 14:29:24;0040;PBS_Server;Svr;tyrone-cluster;Scheduler was sent the command recyc
11/18/2012 14:29:24;000d;PBS_Server;Job;14093.tyrone-cluster;Not sending email: User does not want mail of this type.
11/18/2012 14:29:32;0008;PBS_Server;Job;14093.tyrone-cluster;Job deleted at request of ipcvrk@tyrone-cluster
11/18/2012 14:29:32;0008;PBS_Server;Job;14093.tyrone-cluster;Job sent signal SIGTERM on delete
11/18/2012 14:29:33;0008;PBS_Server;Job;14093.tyrone-cluster;Job deleted at request of ipcvrk@tyrone-cluster
11/18/2012 14:29:33;0008;PBS_Server;Job;14093.tyrone-cluster;Job sent signal SIGTERM on delete
11/18/2012 14:29:34;0008;PBS_Server;Job;14093.tyrone-cluster;Job sent signal SIGKILL on delete
11/18/2012 14:29:38;0040;PBS_Server;Svr;tyrone-cluster;Scheduler was sent the command new
11/18/2012 14:29:38;0008;PBS_Server;Job;14093.tyrone-cluster;Job deleted at request of ipcvrk@tyrone-cluster
11/18/2012 14:29:38;0008;PBS_Server;Job;14093.tyrone-cluster;Job sent signal SIGTERM on delete
11/18/2012 14:29:38;000d;PBS_Server;Job;14093.tyrone-cluster;Not sending email: User does not want mail of this type.
11/18/2012 14:29:38;0010;PBS_Server;Job;14093.tyrone-cluster;Exit_status=143 resources_used.cput=00:01:04 resources_used.mem=375356kb resources_used.vmem=20542096kb resources_used.walltime=00:00:14
11/18/2012 14:29:38;0008;PBS_Server;Job;NULL;on_job_exit valid pjob: 0x13f2680 (substate=50)
11/18/2012 14:29:38;0008;PBS_Server;Job;NULL;on_job_exit valid pjob: 0x13f2680 (substate=51)
11/18/2012 14:29:38;0008;PBS_Server;Job;NULL;on_job_exit valid pjob: 0x13f2680 (substate=51)
11/18/2012 14:29:38;0008;PBS_Server;Job;NULL;on_job_exit valid pjob: 0x13f2680 (substate=53)
11/18/2012 14:29:38;0100;PBS_Server;Job;14093.tyrone-cluster;dequeuing from idqueue, state COMPLETE
11/18/2012 14:29:48;0100;PBS_Server;Job;14094.tyrone-cluster;enqueuing into batch, state 1 hop 1
11/18/2012 14:29:48;0100;PBS_Server;Job;14094.tyrone-cluster;dequeuing from batch, state QUEUED
11/18/2012 14:29:48;0100;PBS_Server;Job;14094.tyrone-cluster;enqueuing into idqueue, state 1 hop 1
11/18/2012 14:29:48;0008;PBS_Server;Job;14094.tyrone-cluster;Job Queued at request of ipcvrk@tyrone-cluster, owner = ipcvrk@tyrone-cluster, job name = pqtrip.cmd, queue = idqueue
11/18/2012 14:29:48;0040;PBS_Server;Svr;tyrone-cluster;Scheduler was sent the command new
11/18/2012 14:29:48;0008;PBS_Server;Job;14094.tyrone-cluster;Job Modified at request of Scheduler@tyrone-cluster
11/18/2012 14:29:48;0008;PBS_Server;Job;14094.tyrone-cluster;Job Run at request of Scheduler@tyrone-cluster
11/18/2012 14:29:48;0040;PBS_Server;Svr;tyrone-cluster;Scheduler was sent the command recyc
11/18/2012 14:29:48;000d;PBS_Server;Job;14094.tyrone-cluster;Not sending email: User does not want mail of this type.
11/18/2012 14:30:09;0040;PBS_Server;Svr;tyrone-cluster;Scheduler was sent the command new
11/18/2012 14:30:38;0040;PBS_Server;Svr;tyrone-cluster;Scheduler was sent the command new
11/18/2012 14:31:16;0040;PBS_Server;Svr;tyrone-cluster;Scheduler was sent the command new
11/18/2012 14:31:16;000d;PBS_Server;Job;13592.tyrone-cluster;Not sending email: User does not want mail of this type.
11/18/2012 14:31:16;0010;PBS_Server;Job;13592.tyrone-cluster;Exit_status=0 resources_used.cput=02:49:31 resources_used.mem=663352kb resources_used.vmem=4914968kb resources_used.walltime=00:11:15
11/18/2012 14:31:16;0008;PBS_Server;Job;NULL;on_job_exit valid pjob: 0x1342960 (substate=50)
11/18/2012 14:31:16;0008;PBS_Server;Job;NULL;on_job_exit valid pjob: 0x1342960 (substate=51)
11/18/2012 14:31:16;0008;PBS_Server;Job;13810.tyrone-cluster;Job Modified at request of Scheduler@tyrone-cluster
11/18/2012 14:31:16;0008;PBS_Server;Job;13594.tyrone-cluster;Job Modified at request of Scheduler@tyrone-cluster
11/18/2012 14:31:16;0008;PBS_Server;Job;13981.tyrone-cluster;Job Modified at request of Scheduler@tyrone-cluster
11/18/2012 14:31:16;0008;PBS_Server;Job;13981.tyrone-cluster;Job Run at request of Scheduler@tyrone-cluster
11/18/2012 14:31:16;0040;PBS_Server;Svr;tyrone-cluster;Scheduler was sent the command recyc
11/18/2012 14:31:16;000d;PBS_Server;Job;13981.tyrone-cluster;Not sending email: User does not want mail of this type.
11/18/2012 14:31:24;0008;PBS_Server;Job;NULL;on_job_exit valid pjob: 0x1342960 (substate=51)
11/18/2012 14:31:24;000d;PBS_Server;Job;13592.tyrone-cluster;Post job file processing error; job 13592.tyrone-cluster on host tyrone-node2/31+tyrone-node2/30+tyrone-node2/29+tyrone-node2/28+tyrone-node2/27+tyrone-node2/26+tyrone-node2/25+tyrone-node2/24+tyrone-node2/23+tyrone-node2/22+tyrone-node2/21+tyrone-node2/20+tyrone-node2/19+tyrone-node2/18+tyrone-node2/17+tyrone-node2/16+tyrone-node2/15+tyrone-node2/14+tyrone-node2/13+tyrone-node2/12+tyrone-node2/11+tyrone-node2/10+tyrone-node2/9+tyrone-node2/8+tyrone-node2/7+tyrone-node2/6+tyrone-node2/5+tyrone-node2/4+tyrone-node2/3+tyrone-node2/2+tyrone-node2/1+tyrone-node2/0
11/18/2012 14:31:24;0008;PBS_Server;Job;NULL;on_job_exit valid pjob: 0x1342960 (substate=53)
11/18/2012 14:31:24;0100;PBS_Server;Job;13592.tyrone-cluster;dequeuing from qp32, state COMPLETE
11/18/2012 14:31:24;0040;PBS_Server;Svr;tyrone-cluster;Scheduler was sent the command term
11/18/2012 14:31:24;0008;PBS_Server;Job;13810.tyrone-cluster;Job Modified at request of Scheduler@tyrone-cluster
11/18/2012 14:31:24;0008;PBS_Server;Job;13594.tyrone-cluster;Job Modified at request of Scheduler@tyrone-cluster
11/18/2012 14:31:46;0100;PBS_Server;Job;13697.tyrone-cluster;dequeuing from batch, state QUEUED
11/18/2012 14:31:46;0100;PBS_Server;Job;13697.tyrone-cluster;enqueuing into qp32, state 1 hop 1
11/18/2012 14:31:46;0040;PBS_Server;Svr;tyrone-cluster;Scheduler was sent the command new
11/18/2012 14:31:47;0008;PBS_Server;Job;13697.tyrone-cluster;Job Modified at request of Scheduler@tyrone-cluster
11/18/2012 14:32:16;0040;PBS_Server;Svr;tyrone-cluster;Scheduler was sent the command new
11/18/2012 14:32:49;0040;PBS_Server;Svr;tyrone-cluster;Scheduler was sent the command new
11/18/2012 14:33:04;0100;PBS_Server;Job;14095.tyrone-cluster;enqueuing into batch, state 1 hop 1
11/18/2012 14:33:04;0100;PBS_Server;Job;14095.tyrone-cluster;dequeuing from batch, state QUEUED
11/18/2012 14:33:04;0100;PBS_Server;Job;14095.tyrone-cluster;enqueuing into idqueue, state 1 hop 1
11/18/2012 14:33:04;0008;PBS_Server;Job;14095.tyrone-cluster;Job Queued at request of secbadar@tyrone-cluster, owner = secbadar@tyrone-cluster, job name = myjob, queue = idqueue
11/18/2012 14:33:04;0040;PBS_Server;Svr;tyrone-cluster;Scheduler was sent the command new
11/18/2012 14:33:04;0008;PBS_Server;Job;14095.tyrone-cluster;Job Modified at request of Scheduler@tyrone-cluster
11/18/2012 14:33:08;0100;PBS_Server;Job;14096.tyrone-cluster;enqueuing into batch, state 1 hop 1
11/18/2012 14:33:08;0100;PBS_Server;Job;14096.tyrone-cluster;dequeuing from batch, state QUEUED
11/18/2012 14:33:08;0100;PBS_Server;Job;14096.tyrone-cluster;enqueuing into idqueue, state 1 hop 1
11/18/2012 14:33:08;0008;PBS_Server;Job;14096.tyrone-cluster;Job Queued at request of secbadar@tyrone-cluster, owner = secbadar@tyrone-cluster, job name = myjob, queue = idqueue
11/18/2012 14:33:08;0040;PBS_Server;Svr;tyrone-cluster;Scheduler was sent the command new
11/18/2012 14:33:08;0008;PBS_Server;Job;14096.tyrone-cluster;Job Modified at request of Scheduler@tyrone-cluster
11/18/2012 14:33:19;0040;PBS_Server;Svr;tyrone-cluster;Scheduler was sent the command new
11/18/2012 14:33:49;0002;PBS_Server;Svr;PBS_Server;Torque Server Version = 3.0.5, loglevel = 0
11/18/2012 14:33:50;0040;PBS_Server;Svr;tyrone-cluster;Scheduler was sent the command new
11/18/2012 14:34:19;0040;PBS_Server;Svr;tyrone-cluster;Scheduler was sent the command new
11/18/2012 14:34:49;0040;PBS_Server;Svr;tyrone-cluster;Scheduler was sent the command new
11/18/2012 14:35:19;0040;PBS_Server;Svr;tyrone-cluster;Scheduler was sent the command new
11/18/2012 14:35:49;0040;PBS_Server;Svr;tyrone-cluster;Scheduler was sent the command new
11/18/2012 14:36:19;0040;PBS_Server;Svr;tyrone-cluster;Scheduler was sent the command new
11/18/2012 14:36:49;0040;PBS_Server;Svr;tyrone-cluster;Scheduler was sent the command new
11/18/2012 14:37:19;0040;PBS_Server;Svr;tyrone-cluster;Scheduler was sent the command new
11/18/2012 14:37:49;0040;PBS_Server;Svr;tyrone-cluster;Scheduler was sent the command new
11/18/2012 14:38:19;0040;PBS_Server;Svr;tyrone-cluster;Scheduler was sent the command new
11/18/2012 14:38:49;0002;PBS_Server;Svr;PBS_Server;Torque Server Version = 3.0.5, loglevel = 0
11/18/2012 14:38:49;0040;PBS_Server;Svr;tyrone-cluster;Scheduler was sent the command new
11/18/2012 14:39:19;0040;PBS_Server;Svr;tyrone-cluster;Scheduler was sent the command new
11/18/2012 14:39:50;0040;PBS_Server;Svr;tyrone-cluster;Scheduler was sent the command new
11/18/2012 14:40:21;0040;PBS_Server;Svr;tyrone-cluster;Scheduler was sent the command new
11/18/2012 14:41:04;0040;PBS_Server;Svr;tyrone-cluster;Scheduler was sent the command new
11/18/2012 14:41:34;0040;PBS_Server;Svr;tyrone-cluster;Scheduler was sent the command new
11/18/2012 14:42:04;0040;PBS_Server;Svr;tyrone-cluster;Scheduler was sent the command new
11/18/2012 14:42:34;0040;PBS_Server;Svr;tyrone-cluster;Scheduler was sent the command new
11/18/2012 14:43:04;0040;PBS_Server;Svr;tyrone-cluster;Scheduler was sent the command new
11/18/2012 14:43:34;0040;PBS_Server;Svr;tyrone-cluster;Scheduler was sent the command new
11/18/2012 14:43:49;0002;PBS_Server;Svr;PBS_Server;Torque Server Version = 3.0.5, loglevel = 0
11/18/2012 14:44:04;0040;PBS_Server;Svr;tyrone-cluster;Scheduler was sent the command new
11/18/2012 14:44:34;0040;PBS_Server;Svr;tyrone-cluster;Scheduler was sent the command new
11/18/2012 14:45:05;0040;PBS_Server;Svr;tyrone-cluster;Scheduler was sent the command new
11/18/2012 14:45:34;0040;PBS_Server;Svr;tyrone-cluster;Scheduler was sent the command new
11/18/2012 14:46:04;0040;PBS_Server;Svr;tyrone-cluster;Scheduler was sent the command new
11/18/2012 14:46:35;0040;PBS_Server;Svr;tyrone-cluster;Scheduler was sent the command new
11/18/2012 14:47:04;0040;PBS_Server;Svr;tyrone-cluster;Scheduler was sent the command new
11/18/2012 14:47:34;0040;PBS_Server;Svr;tyrone-cluster;Scheduler was sent the command new
11/18/2012 14:48:05;0040;PBS_Server;Svr;tyrone-cluster;Scheduler was sent the command new
11/18/2012 14:48:34;0040;PBS_Server;Svr;tyrone-cluster;Scheduler was sent the command new
11/18/2012 14:48:49;0002;PBS_Server;Svr;PBS_Server;Torque Server Version = 3.0.5, loglevel = 0
11/18/2012 14:49:04;0040;PBS_Server;Svr;tyrone-cluster;Scheduler was sent the command new
11/18/2012 14:49:34;0040;PBS_Server;Svr;tyrone-cluster;Scheduler was sent the command new
11/18/2012 14:50:04;0040;PBS_Server;Svr;tyrone-cluster;Scheduler was sent the command new
11/18/2012 14:50:34;0040;PBS_Server;Svr;tyrone-cluster;Scheduler was sent the command new
11/18/2012 14:51:04;0040;PBS_Server;Svr;tyrone-cluster;Scheduler was sent the command new
11/18/2012 14:51:34;0040;PBS_Server;Svr;tyrone-cluster;Scheduler was sent the command new
11/18/2012 14:52:04;0040;PBS_Server;Svr;tyrone-cluster;Scheduler was sent the command new
11/18/2012 14:52:34;0040;PBS_Server;Svr;tyrone-cluster;Scheduler was sent the command new
11/18/2012 14:53:04;0040;PBS_Server;Svr;tyrone-cluster;Scheduler was sent the command new
11/18/2012 14:53:34;0040;PBS_Server;Svr;tyrone-cluster;Scheduler was sent the command new
11/18/2012 14:53:49;0002;PBS_Server;Svr;PBS_Server;Torque Server Version = 3.0.5, loglevel = 0
11/18/2012 14:54:05;0040;PBS_Server;Svr;tyrone-cluster;Scheduler was sent the command new
11/18/2012 14:54:36;0040;PBS_Server;Svr;tyrone-cluster;Scheduler was sent the command new
11/18/2012 14:55:19;0040;PBS_Server;Svr;tyrone-cluster;Scheduler was sent the command new
11/18/2012 14:55:49;0040;PBS_Server;Svr;tyrone-cluster;Scheduler was sent the command new
11/18/2012 14:56:19;0040;PBS_Server;Svr;tyrone-cluster;Scheduler was sent the command new
11/18/2012 14:56:28;0100;PBS_Server;Job;14097.tyrone-cluster;enqueuing into batch, state 1 hop 1
11/18/2012 14:56:28;0100;PBS_Server;Job;14097.tyrone-cluster;dequeuing from batch, state QUEUED
11/18/2012 14:56:28;0100;PBS_Server;Job;14097.tyrone-cluster;enqueuing into idqueue, state 1 hop 1
11/18/2012 14:56:28;0008;PBS_Server;Job;14097.tyrone-cluster;Job Queued at request of secadach@tyrone-cluster, owner = secadach@tyrone-cluster, job name = myjob, queue = idqueue
11/18/2012 14:56:28;0040;PBS_Server;Svr;tyrone-cluster;Scheduler was sent the command new
11/18/2012 14:56:28;0008;PBS_Server;Job;14097.tyrone-cluster;Job Modified at request of Scheduler@tyrone-cluster
11/18/2012 14:56:49;0040;PBS_Server;Svr;tyrone-cluster;Scheduler was sent the command new
11/18/2012 14:57:19;0040;PBS_Server;Svr;tyrone-cluster;Scheduler was sent the command new
11/18/2012 14:57:49;0040;PBS_Server;Svr;tyrone-cluster;Scheduler was sent the command new
11/18/2012 14:58:19;0040;PBS_Server;Svr;tyrone-cluster;Scheduler was sent the command new
11/18/2012 14:58:49;0002;PBS_Server;Svr;PBS_Server;Torque Server Version = 3.0.5, loglevel = 0
11/18/2012 14:58:49;0040;PBS_Server;Svr;tyrone-cluster;Scheduler was sent the command new
11/18/2012 14:59:19;0040;PBS_Server;Svr;tyrone-cluster;Scheduler was sent the command new
11/18/2012 14:59:44;0008;PBS_Server;Job;14097.tyrone-cluster;Job deleted at request of secadach@tyrone-cluster
11/18/2012 14:59:44;0008;PBS_Server;Job;NULL;on_job_exit valid pjob: 0x1342960 (substate=59)
11/18/2012 14:59:44;0100;PBS_Server;Job;14097.tyrone-cluster;dequeuing from idqueue, state COMPLETE
11/18/2012 14:59:44;0040;PBS_Server;Svr;tyrone-cluster;Scheduler was sent the command term
11/18/2012 14:59:49;0040;PBS_Server;Svr;tyrone-cluster;Scheduler was sent the command new
11/18/2012 15:00:19;0040;PBS_Server;Svr;tyrone-cluster;Scheduler was sent the command new
11/18/2012 15:00:50;0040;PBS_Server;Svr;tyrone-cluster;Scheduler was sent the command new
11/18/2012 15:00:54;000d;PBS_Server;Job;14073.tyrone-cluster;Not sending email: User does not want mail of this type.
11/18/2012 15:00:54;0010;PBS_Server;Job;14073.tyrone-cluster;Exit_status=143 resources_used.cput=06:04:26 resources_used.mem=424804kb resources_used.vmem=883672kb resources_used.walltime=02:00:23
11/18/2012 15:00:54;0008;PBS_Server;Job;NULL;on_job_exit valid pjob: 0x13416a0 (substate=50)
11/18/2012 15:00:54;0008;PBS_Server;Job;NULL;on_job_exit valid pjob: 0x13416a0 (substate=51)
11/18/2012 15:00:54;0008;PBS_Server;Job;NULL;on_job_exit valid pjob: 0x13416a0 (substate=51)
11/18/2012 15:00:54;0008;PBS_Server;Job;NULL;on_job_exit valid pjob: 0x13416a0 (substate=53)
11/18/2012 15:00:54;0100;PBS_Server;Job;14073.tyrone-cluster;dequeuing from idqueue, state COMPLETE
11/18/2012 15:00:54;0040;PBS_Server;Svr;tyrone-cluster;Scheduler was sent the command term
11/18/2012 15:00:54;0008;PBS_Server;Job;14095.tyrone-cluster;Job Modified at request of Scheduler@tyrone-cluster
11/18/2012 15:00:54;0008;PBS_Server;Job;14095.tyrone-cluster;Job Run at request of Scheduler@tyrone-cluster
11/18/2012 15:00:55;000d;PBS_Server;Job;14095.tyrone-cluster;Not sending email: User does not want mail of this type.
11/18/2012 15:00:55;0040;PBS_Server;Svr;tyrone-cluster;Scheduler was sent the command recyc
11/18/2012 15:01:19;0040;PBS_Server;Svr;tyrone-cluster;Scheduler was sent the command new
11/18/2012 15:01:49;0040;PBS_Server;Svr;tyrone-cluster;Scheduler was sent the command new
11/18/2012 15:01:55;0100;PBS_Server;Job;14098.tyrone-cluster;enqueuing into batch, state 1 hop 1
11/18/2012 15:01:55;0100;PBS_Server;Job;14098.tyrone-cluster;dequeuing from batch, state QUEUED
11/18/2012 15:01:55;0100;PBS_Server;Job;14098.tyrone-cluster;enqueuing into idqueue, state 1 hop 1
11/18/2012 15:01:55;0008;PBS_Server;Job;14098.tyrone-cluster;Job Queued at request of secadach@tyrone-cluster, owner = secadach@tyrone-cluster, job name = myjob, queue = idqueue
11/18/2012 15:01:55;0040;PBS_Server;Svr;tyrone-cluster;Scheduler was sent the command new
11/18/2012 15:01:55;0008;PBS_Server;Job;14098.tyrone-cluster;Job Modified at request of Scheduler@tyrone-cluster
11/18/2012 15:02:19;0040;PBS_Server;Svr;tyrone-cluster;Scheduler was sent the command new
11/18/2012 15:02:32;000d;PBS_Server;Job;13837.tyrone-cluster;Not sending email: User does not want mail of this type.
11/18/2012 15:02:32;0010;PBS_Server;Job;13837.tyrone-cluster;Exit_status=143 resources_used.cput=1459:09:53 resources_used.mem=2955416kb resources_used.vmem=10548932kb resources_used.walltime=24:00:24
11/18/2012 15:02:32;0008;PBS_Server;Job;NULL;on_job_exit valid pjob: 0x134e980 (substate=50)
11/18/2012 15:02:32;0008;PBS_Server;Job;NULL;on_job_exit valid pjob: 0x134e980 (substate=51)
11/18/2012 15:02:32;0008;PBS_Server;Job;NULL;on_job_exit valid pjob: 0x134e980 (substate=51)
11/18/2012 15:02:32;0008;PBS_Server;Job;NULL;on_job_exit valid pjob: 0x134e980 (substate=53)
11/18/2012 15:02:32;0100;PBS_Server;Job;13837.tyrone-cluster;dequeuing from qp64, state COMPLETE
11/18/2012 15:02:32;0040;PBS_Server;Svr;tyrone-cluster;Scheduler was sent the command term
11/18/2012 15:02:32;0008;PBS_Server;Job;14039.tyrone-cluster;Job Modified at request of Scheduler@tyrone-cluster
11/18/2012 15:02:32;0008;PBS_Server;Job;14039.tyrone-cluster;Job Run at request of Scheduler@tyrone-cluster
11/18/2012 15:02:33;0040;PBS_Server;Svr;tyrone-cluster;Scheduler was sent the command recyc
11/18/2012 15:02:33;000d;PBS_Server;Job;14039.tyrone-cluster;Not sending email: User does not want mail of this type.
11/18/2012 15:02:49;0040;PBS_Server;Svr;tyrone-cluster;Scheduler was sent the command new
11/18/2012 15:03:19;0040;PBS_Server;Svr;tyrone-cluster;Scheduler was sent the command new
11/18/2012 15:03:49;0002;PBS_Server;Svr;PBS_Server;Torque Server Version = 3.0.5, loglevel = 0
11/18/2012 15:03:49;0040;PBS_Server;Svr;tyrone-cluster;Scheduler was sent the command new
11/18/2012 15:04:19;0040;PBS_Server;Svr;tyrone-cluster;Scheduler was sent the command new
11/18/2012 15:04:49;0040;PBS_Server;Svr;tyrone-cluster;Scheduler was sent the command new
11/18/2012 15:05:19;0040;PBS_Server;Svr;tyrone-cluster;Scheduler was sent the command new
11/18/2012 15:05:25;000d;PBS_Server;Job;14075.tyrone-cluster;Not sending email: User does not want mail of this type.
11/18/2012 15:05:25;0010;PBS_Server;Job;14075.tyrone-cluster;Exit_status=143 resources_used.cput=06:00:52 resources_used.mem=63884kb resources_used.vmem=522760kb resources_used.walltime=02:00:08
11/18/2012 15:05:25;0008;PBS_Server;Job;NULL;on_job_exit valid pjob: 0x132ff00 (substate=50)
11/18/2012 15:05:25;0008;PBS_Server;Job;NULL;on_job_exit valid pjob: 0x132ff00 (substate=51)
11/18/2012 15:05:25;0008;PBS_Server;Job;NULL;on_job_exit valid pjob: 0x132ff00 (substate=51)
11/18/2012 15:05:25;0008;PBS_Server;Job;NULL;on_job_exit valid pjob: 0x132ff00 (substate=53)
11/18/2012 15:05:25;0100;PBS_Server;Job;14075.tyrone-cluster;dequeuing from idqueue, state COMPLETE
11/18/2012 15:05:25;0040;PBS_Server;Svr;tyrone-cluster;Scheduler was sent the command term
11/18/2012 15:05:25;0008;PBS_Server;Job;14096.tyrone-cluster;Job Modified at request of Scheduler@tyrone-cluster
11/18/2012 15:05:25;0008;PBS_Server;Job;14096.tyrone-cluster;Job Run at request of Scheduler@tyrone-cluster
11/18/2012 15:05:25;000d;PBS_Server;Job;14096.tyrone-cluster;Not sending email: User does not want mail of this type.
11/18/2012 15:05:25;0040;PBS_Server;Svr;tyrone-cluster;Scheduler was sent the command recyc
11/18/2012 15:05:49;0040;PBS_Server;Svr;tyrone-cluster;Scheduler was sent the command new
11/18/2012 15:06:19;0040;PBS_Server;Svr;tyrone-cluster;Scheduler was sent the command new
11/18/2012 15:06:49;0040;PBS_Server;Svr;tyrone-cluster;Scheduler was sent the command new
11/18/2012 15:07:19;0040;PBS_Server;Svr;tyrone-cluster;Scheduler was sent the command new
11/18/2012 15:07:49;0040;PBS_Server;Svr;tyrone-cluster;Scheduler was sent the command new
11/18/2012 15:08:19;0040;PBS_Server;Svr;tyrone-cluster;Scheduler was sent the command new
11/18/2012 15:08:49;0002;PBS_Server;Svr;PBS_Server;Torque Server Version = 3.0.5, loglevel = 0
11/18/2012 15:08:49;0040;PBS_Server;Svr;tyrone-cluster;Scheduler was sent the command new
11/18/2012 15:09:19;0040;PBS_Server;Svr;tyrone-cluster;Scheduler was sent the command new
11/18/2012 15:09:49;0040;PBS_Server;Svr;tyrone-cluster;Scheduler was sent the command new
11/18/2012 15:10:19;0040;PBS_Server;Svr;tyrone-cluster;Scheduler was sent the command new
11/18/2012 15:10:49;0040;PBS_Server;Svr;tyrone-cluster;Scheduler was sent the command new
11/18/2012 15:10:53;0008;PBS_Server;Job;14095.tyrone-cluster;Job deleted at request of secbadar@tyrone-cluster
11/18/2012 15:10:53;0008;PBS_Server;Job;14095.tyrone-cluster;Job sent signal SIGTERM on delete
11/18/2012 15:10:54;000d;PBS_Server;Job;14095.tyrone-cluster;Not sending email: User does not want mail of this type.
11/18/2012 15:10:54;0010;PBS_Server;Job;14095.tyrone-cluster;Exit_status=143 resources_used.cput=00:29:32 resources_used.mem=569528kb resources_used.vmem=1684888kb resources_used.walltime=00:10:00
11/18/2012 15:10:54;0008;PBS_Server;Job;NULL;on_job_exit valid pjob: 0x131f740 (substate=50)
11/18/2012 15:10:54;0008;PBS_Server;Job;NULL;on_job_exit valid pjob: 0x131f740 (substate=51)
11/18/2012 15:10:55;0008;PBS_Server;Job;NULL;on_job_exit valid pjob: 0x131f740 (substate=51)
11/18/2012 15:10:55;0008;PBS_Server;Job;NULL;on_job_exit valid pjob: 0x131f740 (substate=53)
11/18/2012 15:10:55;0100;PBS_Server;Job;14095.tyrone-cluster;dequeuing from idqueue, state COMPLETE
11/18/2012 15:10:55;0040;PBS_Server;Svr;tyrone-cluster;Scheduler was sent the command term
11/18/2012 15:10:55;0008;PBS_Server;Job;14098.tyrone-cluster;Job Modified at request of Scheduler@tyrone-cluster
11/18/2012 15:10:55;0008;PBS_Server;Job;14098.tyrone-cluster;Job Run at request of Scheduler@tyrone-cluster
11/18/2012 15:10:55;0040;PBS_Server;Svr;tyrone-cluster;Scheduler was sent the command recyc
11/18/2012 15:10:55;000d;PBS_Server;Job;14098.tyrone-cluster;Not sending email: User does not want mail of this type.
11/18/2012 15:10:57;000d;PBS_Server;Job;14098.tyrone-cluster;Not sending email: User does not want mail of this type.
11/18/2012 15:10:57;0010;PBS_Server;Job;14098.tyrone-cluster;Exit_status=0 resources_used.cput=00:00:02 resources_used.mem=0kb resources_used.vmem=0kb resources_used.walltime=00:00:02
11/18/2012 15:10:57;0008;PBS_Server;Job;NULL;on_job_exit valid pjob: 0x13416a0 (substate=50)
11/18/2012 15:10:57;0008;PBS_Server;Job;NULL;on_job_exit valid pjob: 0x13416a0 (substate=51)
11/18/2012 15:10:57;0008;PBS_Server;Job;NULL;on_job_exit valid pjob: 0x13416a0 (substate=51)
11/18/2012 15:10:57;0008;PBS_Server;Job;NULL;on_job_exit valid pjob: 0x13416a0 (substate=53)
11/18/2012 15:10:57;0100;PBS_Server;Job;14098.tyrone-cluster;dequeuing from idqueue, state COMPLETE
11/18/2012 15:10:57;0040;PBS_Server;Svr;tyrone-cluster;Scheduler was sent the command term
11/18/2012 15:11:20;0040;PBS_Server;Svr;tyrone-cluster;Scheduler was sent the command new
11/18/2012 15:11:49;0040;PBS_Server;Svr;tyrone-cluster;Scheduler was sent the command new
11/18/2012 15:11:54;0100;PBS_Server;Job;14099.tyrone-cluster;enqueuing into batch, state 1 hop 1
11/18/2012 15:11:54;0100;PBS_Server;Job;14099.tyrone-cluster;dequeuing from batch, state QUEUED
11/18/2012 15:11:54;0100;PBS_Server;Job;14099.tyrone-cluster;enqueuing into idqueue, state 1 hop 1
11/18/2012 15:11:54;0008;PBS_Server;Job;14099.tyrone-cluster;Job Queued at request of seckriti@tyrone-cluster, owner = seckriti@tyrone-cluster, job name = myjob, queue = idqueue
11/18/2012 15:11:54;0040;PBS_Server;Svr;tyrone-cluster;Scheduler was sent the command new
11/18/2012 15:11:54;0008;PBS_Server;Job;14099.tyrone-cluster;Job Modified at request of Scheduler@tyrone-cluster
11/18/2012 15:11:54;0008;PBS_Server;Job;14099.tyrone-cluster;Job Run at request of Scheduler@tyrone-cluster
11/18/2012 15:11:54;0040;PBS_Server;Svr;tyrone-cluster;Scheduler was sent the command recyc
11/18/2012 15:11:54;000d;PBS_Server;Job;14099.tyrone-cluster;Not sending email: User does not want mail of this type.
11/18/2012 15:11:59;000d;PBS_Server;Job;14099.tyrone-cluster;Not sending email: User does not want mail of this type.
11/18/2012 15:11:59;0010;PBS_Server;Job;14099.tyrone-cluster;Exit_status=0 resources_used.cput=00:00:10 resources_used.mem=0kb resources_used.vmem=0kb resources_used.walltime=00:00:05
11/18/2012 15:11:59;0008;PBS_Server;Job;NULL;on_job_exit valid pjob: 0x131f740 (substate=50)
11/18/2012 15:11:59;0008;PBS_Server;Job;NULL;on_job_exit valid pjob: 0x131f740 (substate=51)
11/18/2012 15:12:00;0008;PBS_Server;Job;NULL;on_job_exit valid pjob: 0x131f740 (substate=51)
11/18/2012 15:12:00;0008;PBS_Server;Job;NULL;on_job_exit valid pjob: 0x131f740 (substate=53)
11/18/2012 15:12:00;0100;PBS_Server;Job;14099.tyrone-cluster;dequeuing from idqueue, state COMPLETE
11/18/2012 15:12:00;0040;PBS_Server;Svr;tyrone-cluster;Scheduler was sent the command term
11/18/2012 15:12:19;0040;PBS_Server;Svr;tyrone-cluster;Scheduler was sent the command new
11/18/2012 15:12:49;0040;PBS_Server;Svr;tyrone-cluster;Scheduler was sent the command new
11/18/2012 15:13:19;0040;PBS_Server;Svr;tyrone-cluster;Scheduler was sent the command new
11/18/2012 15:13:22;0100;PBS_Server;Job;14100.tyrone-cluster;enqueuing into batch, state 1 hop 1
11/18/2012 15:13:22;0100;PBS_Server;Job;14100.tyrone-cluster;dequeuing from batch, state QUEUED
11/18/2012 15:13:22;0100;PBS_Server;Job;14100.tyrone-cluster;enqueuing into idqueue, state 1 hop 1
11/18/2012 15:13:22;0008;PBS_Server;Job;14100.tyrone-cluster;Job Queued at request of secgeet@tyrone-cluster, owner = secgeet@tyrone-cluster, job name = myjob, queue = idqueue
11/18/2012 15:13:22;0040;PBS_Server;Svr;tyrone-cluster;Scheduler was sent the command new
11/18/2012 15:13:22;0008;PBS_Server;Job;14100.tyrone-cluster;Job Modified at request of Scheduler@tyrone-cluster
11/18/2012 15:13:22;0008;PBS_Server;Job;14100.tyrone-cluster;Job Run at request of Scheduler@tyrone-cluster
11/18/2012 15:13:22;0040;PBS_Server;Svr;tyrone-cluster;Scheduler was sent the command recyc
11/18/2012 15:13:22;000d;PBS_Server;Job;14100.tyrone-cluster;Not sending email: User does not want mail of this type.
11/18/2012 15:13:22;0100;PBS_Server;Job;14101.tyrone-cluster;enqueuing into batch, state 1 hop 1
11/18/2012 15:13:22;0100;PBS_Server;Job;14101.tyrone-cluster;dequeuing from batch, state QUEUED
11/18/2012 15:13:22;0100;PBS_Server;Job;14101.tyrone-cluster;enqueuing into idqueue, state 1 hop 1
11/18/2012 15:13:22;0008;PBS_Server;Job;14101.tyrone-cluster;Job Queued at request of secgeet@tyrone-cluster, owner = secgeet@tyrone-cluster, job name = myjob, queue = idqueue
11/18/2012 15:13:22;0040;PBS_Server;Svr;tyrone-cluster;Scheduler was sent the command new
11/18/2012 15:13:23;0008;PBS_Server;Job;14101.tyrone-cluster;Job Modified at request of Scheduler@tyrone-cluster
11/18/2012 15:13:23;0100;PBS_Server;Job;14102.tyrone-cluster;enqueuing into batch, state 1 hop 1
11/18/2012 15:13:23;0100;PBS_Server;Job;14102.tyrone-cluster;dequeuing from batch, state QUEUED
11/18/2012 15:13:23;0100;PBS_Server;Job;14102.tyrone-cluster;enqueuing into idqueue, state 1 hop 1
11/18/2012 15:13:23;0008;PBS_Server;Job;14102.tyrone-cluster;Job Queued at request of secgeet@tyrone-cluster, owner = secgeet@tyrone-cluster, job name = myjob, queue = idqueue
11/18/2012 15:13:23;0040;PBS_Server;Svr;tyrone-cluster;Scheduler was sent the command new
11/18/2012 15:13:23;0008;PBS_Server;Job;14102.tyrone-cluster;Job Modified at request of Scheduler@tyrone-cluster
11/18/2012 15:13:24;0100;PBS_Server;Job;14103.tyrone-cluster;enqueuing into batch, state 1 hop 1
11/18/2012 15:13:24;0100;PBS_Server;Job;14103.tyrone-cluster;dequeuing from batch, state QUEUED
11/18/2012 15:13:24;0100;PBS_Server;Job;14103.tyrone-cluster;enqueuing into idqueue, state 1 hop 1
11/18/2012 15:13:24;0008;PBS_Server;Job;14103.tyrone-cluster;Job Queued at request of secgeet@tyrone-cluster, owner = secgeet@tyrone-cluster, job name = myjob, queue = idqueue
11/18/2012 15:13:24;0040;PBS_Server;Svr;tyrone-cluster;Scheduler was sent the command new
11/18/2012 15:13:25;0008;PBS_Server;Job;14103.tyrone-cluster;Job Modified at request of Scheduler@tyrone-cluster
11/18/2012 15:13:25;0100;PBS_Server;Job;14104.tyrone-cluster;enqueuing into batch, state 1 hop 1
11/18/2012 15:13:25;0100;PBS_Server;Job;14104.tyrone-cluster;dequeuing from batch, state QUEUED
11/18/2012 15:13:25;0100;PBS_Server;Job;14104.tyrone-cluster;enqueuing into idqueue, state 1 hop 1
11/18/2012 15:13:25;0008;PBS_Server;Job;14104.tyrone-cluster;Job Queued at request of secgeet@tyrone-cluster, owner = secgeet@tyrone-cluster, job name = myjob, queue = idqueue
11/18/2012 15:13:25;0040;PBS_Server;Svr;tyrone-cluster;Scheduler was sent the command new
11/18/2012 15:13:25;0008;PBS_Server;Job;14104.tyrone-cluster;Job Modified at request of Scheduler@tyrone-cluster
11/18/2012 15:13:49;0002;PBS_Server;Svr;PBS_Server;Torque Server Version = 3.0.5, loglevel = 0
11/18/2012 15:13:49;0040;PBS_Server;Svr;tyrone-cluster;Scheduler was sent the command new
11/18/2012 15:14:19;0040;PBS_Server;Svr;tyrone-cluster;Scheduler was sent the command new
11/18/2012 15:14:49;0040;PBS_Server;Svr;tyrone-cluster;Scheduler was sent the command new
11/18/2012 15:15:06;0100;PBS_Server;Job;14105.tyrone-cluster;enqueuing into batch, state 1 hop 1
11/18/2012 15:15:06;0100;PBS_Server;Job;14105.tyrone-cluster;dequeuing from batch, state QUEUED
11/18/2012 15:15:06;0100;PBS_Server;Job;14105.tyrone-cluster;enqueuing into idqueue, state 1 hop 1
11/18/2012 15:15:06;0008;PBS_Server;Job;14105.tyrone-cluster;Job Queued at request of secvkm@tyrone-cluster, owner = secvkm@tyrone-cluster, job name = myjob, queue = idqueue
11/18/2012 15:15:06;0040;PBS_Server;Svr;tyrone-cluster;Scheduler was sent the command new
11/18/2012 15:15:06;0008;PBS_Server;Job;14105.tyrone-cluster;Job Modified at request of Scheduler@tyrone-cluster
11/18/2012 15:15:19;0040;PBS_Server;Svr;tyrone-cluster;Scheduler was sent the command new
11/18/2012 15:15:49;0040;PBS_Server;Svr;tyrone-cluster;Scheduler was sent the command new
11/18/2012 15:15:57;0100;PBS_Server;Job;14106.tyrone-cluster;enqueuing into batch, state 1 hop 1
11/18/2012 15:15:57;0100;PBS_Server;Job;14106.tyrone-cluster;dequeuing from batch, state QUEUED
11/18/2012 15:15:57;0100;PBS_Server;Job;14106.tyrone-cluster;enqueuing into idqueue, state 1 hop 1
11/18/2012 15:15:57;0008;PBS_Server;Job;14106.tyrone-cluster;Job Queued at request of secbadar@tyrone-cluster, owner = secbadar@tyrone-cluster, job name = myjob, queue = idqueue
11/18/2012 15:15:57;0040;PBS_Server;Svr;tyrone-cluster;Scheduler was sent the command new
11/18/2012 15:15:57;0008;PBS_Server;Job;14106.tyrone-cluster;Job Modified at request of Scheduler@tyrone-cluster
11/18/2012 15:16:19;0040;PBS_Server;Svr;tyrone-cluster;Scheduler was sent the command new
11/18/2012 15:16:49;0040;PBS_Server;Svr;tyrone-cluster;Scheduler was sent the command new
11/18/2012 15:17:19;0040;PBS_Server;Svr;tyrone-cluster;Scheduler was sent the command new
11/18/2012 15:17:49;0040;PBS_Server;Svr;tyrone-cluster;Scheduler was sent the command new
11/18/2012 15:18:19;0040;PBS_Server;Svr;tyrone-cluster;Scheduler was sent the command new
11/18/2012 15:18:40;0100;PBS_Server;Job;14107.tyrone-cluster;enqueuing into batch, state 1 hop 1
11/18/2012 15:18:40;0100;PBS_Server;Job;14107.tyrone-cluster;dequeuing from batch, state QUEUED
11/18/2012 15:18:40;0100;PBS_Server;Job;14107.tyrone-cluster;enqueuing into idqueue, state 1 hop 1
11/18/2012 15:18:40;0008;PBS_Server;Job;14107.tyrone-cluster;Job Queued at request of secadach@tyrone-cluster, owner = secadach@tyrone-cluster, job name = myjob, queue = idqueue
11/18/2012 15:18:40;0040;PBS_Server;Svr;tyrone-cluster;Scheduler was sent the command new
11/18/2012 15:18:40;0008;PBS_Server;Job;14107.tyrone-cluster;Job Modified at request of Scheduler@tyrone-cluster
11/18/2012 15:18:49;0002;PBS_Server;Svr;PBS_Server;Torque Server Version = 3.0.5, loglevel = 0
11/18/2012 15:18:49;0040;PBS_Server;Svr;tyrone-cluster;Scheduler was sent the command new
11/18/2012 15:19:07;0100;PBS_Server;Job;14108.tyrone-cluster;enqueuing into batch, state 1 hop 1
11/18/2012 15:19:07;0100;PBS_Server;Job;14108.tyrone-cluster;dequeuing from batch, state QUEUED
11/18/2012 15:19:07;0100;PBS_Server;Job;14108.tyrone-cluster;enqueuing into idqueue, state 1 hop 1
11/18/2012 15:19:07;0008;PBS_Server;Job;14108.tyrone-cluster;Job Queued at request of secadach@tyrone-cluster, owner = secadach@tyrone-cluster, job name = myjob, queue = idqueue
11/18/2012 15:19:07;0040;PBS_Server;Svr;tyrone-cluster;Scheduler was sent the command new
11/18/2012 15:19:07;0008;PBS_Server;Job;14108.tyrone-cluster;Job Modified at request of Scheduler@tyrone-cluster
11/18/2012 15:19:19;0040;PBS_Server;Svr;tyrone-cluster;Scheduler was sent the command new
11/18/2012 15:19:49;0040;PBS_Server;Svr;tyrone-cluster;Scheduler was sent the command new
11/18/2012 15:20:19;0040;PBS_Server;Svr;tyrone-cluster;Scheduler was sent the command new
11/18/2012 15:20:49;0040;PBS_Server;Svr;tyrone-cluster;Scheduler was sent the command new
11/18/2012 15:21:19;0040;PBS_Server;Svr;tyrone-cluster;Scheduler was sent the command new
11/18/2012 15:21:19;000d;PBS_Server;Job;14096.tyrone-cluster;Not sending email: User does not want mail of this type.
11/18/2012 15:21:19;0010;PBS_Server;Job;14096.tyrone-cluster;Exit_status=0 resources_used.cput=00:33:40 resources_used.mem=569884kb resources_used.vmem=1685256kb resources_used.walltime=00:15:54
11/18/2012 15:21:19;0008;PBS_Server;Job;NULL;on_job_exit valid pjob: 0x13f2680 (substate=50)
11/18/2012 15:21:19;0008;PBS_Server;Job;NULL;on_job_exit valid pjob: 0x13f2680 (substate=51)
11/18/2012 15:21:20;0008;PBS_Server;Job;NULL;on_job_exit valid pjob: 0x13f2680 (substate=51)
11/18/2012 15:21:20;0008;PBS_Server;Job;NULL;on_job_exit valid pjob: 0x13f2680 (substate=53)
11/18/2012 15:21:20;0100;PBS_Server;Job;14096.tyrone-cluster;dequeuing from idqueue, state COMPLETE
11/18/2012 15:21:20;0040;PBS_Server;Svr;tyrone-cluster;Scheduler was sent the command term
11/18/2012 15:21:20;0008;PBS_Server;Job;14101.tyrone-cluster;Job Modified at request of Scheduler@tyrone-cluster
11/18/2012 15:21:20;0008;PBS_Server;Job;14101.tyrone-cluster;Job Run at request of Scheduler@tyrone-cluster
11/18/2012 15:21:20;0008;PBS_Server;Job;14102.tyrone-cluster;Job Modified at request of Scheduler@tyrone-cluster
11/18/2012 15:21:20;0008;PBS_Server;Job;14103.tyrone-cluster;Job Modified at request of Scheduler@tyrone-cluster
11/18/2012 15:21:20;0008;PBS_Server;Job;14104.tyrone-cluster;Job Modified at request of Scheduler@tyrone-cluster
11/18/2012 15:21:20;000d;PBS_Server;Job;14101.tyrone-cluster;Not sending email: User does not want mail of this type.
11/18/2012 15:21:20;0040;PBS_Server;Svr;tyrone-cluster;Scheduler was sent the command recyc
11/18/2012 15:21:49;0040;PBS_Server;Svr;tyrone-cluster;Scheduler was sent the command new
11/18/2012 15:22:19;0040;PBS_Server;Svr;tyrone-cluster;Scheduler was sent the command new
11/18/2012 15:22:49;0040;PBS_Server;Svr;tyrone-cluster;Scheduler was sent the command new
11/18/2012 15:23:19;0040;PBS_Server;Svr;tyrone-cluster;Scheduler was sent the command new
11/18/2012 15:23:49;0002;PBS_Server;Svr;PBS_Server;Torque Server Version = 3.0.5, loglevel = 0
11/18/2012 15:23:49;0040;PBS_Server;Svr;tyrone-cluster;Scheduler was sent the command new
11/18/2012 15:24:19;0040;PBS_Server;Svr;tyrone-cluster;Scheduler was sent the command new
11/18/2012 15:24:49;0040;PBS_Server;Svr;tyrone-cluster;Scheduler was sent the command new
11/18/2012 15:25:19;0040;PBS_Server;Svr;tyrone-cluster;Scheduler was sent the command new
11/18/2012 15:25:49;0040;PBS_Server;Svr;tyrone-cluster;Scheduler was sent the command new
11/18/2012 15:26:19;0040;PBS_Server;Svr;tyrone-cluster;Scheduler was sent the command new
11/18/2012 15:26:49;0040;PBS_Server;Svr;tyrone-cluster;Scheduler was sent the command new
11/18/2012 15:27:19;0040;PBS_Server;Svr;tyrone-cluster;Scheduler was sent the command new
11/18/2012 15:27:49;0040;PBS_Server;Svr;tyrone-cluster;Scheduler was sent the command new
11/18/2012 15:28:19;0040;PBS_Server;Svr;tyrone-cluster;Scheduler was sent the command new
11/18/2012 15:28:49;0002;PBS_Server;Svr;PBS_Server;Torque Server Version = 3.0.5, loglevel = 0
11/18/2012 15:28:49;0040;PBS_Server;Svr;tyrone-cluster;Scheduler was sent the command new
11/18/2012 15:29:19;0040;PBS_Server;Svr;tyrone-cluster;Scheduler was sent the command new
11/18/2012 15:29:49;0040;PBS_Server;Svr;tyrone-cluster;Scheduler was sent the command new
11/18/2012 15:30:19;0040;PBS_Server;Svr;tyrone-cluster;Scheduler was sent the command new
11/18/2012 15:30:49;0040;PBS_Server;Svr;tyrone-cluster;Scheduler was sent the command new
11/18/2012 15:31:19;0040;PBS_Server;Svr;tyrone-cluster;Scheduler was sent the command new
11/18/2012 15:31:49;0040;PBS_Server;Svr;tyrone-cluster;Scheduler was sent the command new
11/18/2012 15:32:19;0040;PBS_Server;Svr;tyrone-cluster;Scheduler was sent the command new
11/18/2012 15:32:49;0040;PBS_Server;Svr;tyrone-cluster;Scheduler was sent the command new
11/18/2012 15:33:19;0040;PBS_Server;Svr;tyrone-cluster;Scheduler was sent the command new
11/18/2012 15:33:49;0002;PBS_Server;Svr;PBS_Server;Torque Server Version = 3.0.5, loglevel = 0
11/18/2012 15:33:49;0040;PBS_Server;Svr;tyrone-cluster;Scheduler was sent the command new
11/18/2012 15:34:19;0040;PBS_Server;Svr;tyrone-cluster;Scheduler was sent the command new
11/18/2012 15:34:49;0040;PBS_Server;Svr;tyrone-cluster;Scheduler was sent the command new
11/18/2012 15:35:19;0040;PBS_Server;Svr;tyrone-cluster;Scheduler was sent the command new
11/18/2012 15:35:49;0040;PBS_Server;Svr;tyrone-cluster;Scheduler was sent the command new
11/18/2012 15:36:19;0040;PBS_Server;Svr;tyrone-cluster;Scheduler was sent the command new
11/18/2012 15:36:49;0040;PBS_Server;Svr;tyrone-cluster;Scheduler was sent the command new
11/18/2012 15:37:19;0040;PBS_Server;Svr;tyrone-cluster;Scheduler was sent the command new
11/18/2012 15:37:49;0040;PBS_Server;Svr;tyrone-cluster;Scheduler was sent the command new
11/18/2012 15:38:19;0040;PBS_Server;Svr;tyrone-cluster;Scheduler was sent the command new
11/18/2012 15:38:49;0002;PBS_Server;Svr;PBS_Server;Torque Server Version = 3.0.5, loglevel = 0
11/18/2012 15:38:49;0040;PBS_Server;Svr;tyrone-cluster;Scheduler was sent the command new
11/18/2012 15:39:19;0040;PBS_Server;Svr;tyrone-cluster;Scheduler was sent the command new
11/18/2012 15:39:49;0040;PBS_Server;Svr;tyrone-cluster;Scheduler was sent the command new
11/18/2012 15:40:19;0040;PBS_Server;Svr;tyrone-cluster;Scheduler was sent the command new
11/18/2012 15:40:49;0040;PBS_Server;Svr;tyrone-cluster;Scheduler was sent the command new
11/18/2012 15:41:19;0040;PBS_Server;Svr;tyrone-cluster;Scheduler was sent the command new
11/18/2012 15:41:37;0008;PBS_Server;Job;14107.tyrone-cluster;Job deleted at request of secadach@tyrone-cluster
11/18/2012 15:41:37;0008;PBS_Server;Job;NULL;on_job_exit valid pjob: 0x13fedb0 (substate=59)
11/18/2012 15:41:37;0100;PBS_Server;Job;14107.tyrone-cluster;dequeuing from idqueue, state COMPLETE
11/18/2012 15:41:37;0040;PBS_Server;Svr;tyrone-cluster;Scheduler was sent the command term
11/18/2012 15:41:40;0008;PBS_Server;Job;14108.tyrone-cluster;Job deleted at request of secadach@tyrone-cluster
11/18/2012 15:41:40;0008;PBS_Server;Job;NULL;on_job_exit valid pjob: 0x1400070 (substate=59)
11/18/2012 15:41:40;0100;PBS_Server;Job;14108.tyrone-cluster;dequeuing from idqueue, state COMPLETE
11/18/2012 15:41:40;0040;PBS_Server;Svr;tyrone-cluster;Scheduler was sent the command term
11/18/2012 15:41:49;0040;PBS_Server;Svr;tyrone-cluster;Scheduler was sent the command new
11/18/2012 15:42:13;0100;PBS_Server;Job;14109.tyrone-cluster;enqueuing into batch, state 1 hop 1
11/18/2012 15:42:13;0100;PBS_Server;Job;14109.tyrone-cluster;dequeuing from batch, state QUEUED
11/18/2012 15:42:13;0100;PBS_Server;Job;14109.tyrone-cluster;enqueuing into idqueue, state 1 hop 1
11/18/2012 15:42:13;0008;PBS_Server;Job;14109.tyrone-cluster;Job Queued at request of secadach@tyrone-cluster, owner = secadach@tyrone-cluster, job name = myjob, queue = idqueue
11/18/2012 15:42:13;0040;PBS_Server;Svr;tyrone-cluster;Scheduler was sent the command new
11/18/2012 15:42:14;0008;PBS_Server;Job;14109.tyrone-cluster;Job Modified at request of Scheduler@tyrone-cluster
11/18/2012 15:42:18;0100;PBS_Server;Job;14110.tyrone-cluster;enqueuing into batch, state 1 hop 1
11/18/2012 15:42:18;0100;PBS_Server;Job;14110.tyrone-cluster;dequeuing from batch, state QUEUED
11/18/2012 15:42:18;0100;PBS_Server;Job;14110.tyrone-cluster;enqueuing into idqueue, state 1 hop 1
11/18/2012 15:42:18;0008;PBS_Server;Job;14110.tyrone-cluster;Job Queued at request of secadach@tyrone-cluster, owner = secadach@tyrone-cluster, job name = myjob, queue = idqueue
11/18/2012 15:42:18;0040;PBS_Server;Svr;tyrone-cluster;Scheduler was sent the command new
11/18/2012 15:42:19;0008;PBS_Server;Job;14110.tyrone-cluster;Job Modified at request of Scheduler@tyrone-cluster
11/18/2012 15:42:20;0100;PBS_Server;Job;14111.tyrone-cluster;enqueuing into batch, state 1 hop 1
11/18/2012 15:42:20;0100;PBS_Server;Job;14111.tyrone-cluster;dequeuing from batch, state QUEUED
11/18/2012 15:42:20;0100;PBS_Server;Job;14111.tyrone-cluster;enqueuing into idqueue, state 1 hop 1
11/18/2012 15:42:20;0008;PBS_Server;Job;14111.tyrone-cluster;Job Queued at request of secadach@tyrone-cluster, owner = secadach@tyrone-cluster, job name = myjob, queue = idqueue
11/18/2012 15:42:20;0040;PBS_Server;Svr;tyrone-cluster;Scheduler was sent the command new
11/18/2012 15:42:20;0008;PBS_Server;Job;14111.tyrone-cluster;Job Modified at request of Scheduler@tyrone-cluster
11/18/2012 15:42:23;0100;PBS_Server;Job;14112.tyrone-cluster;enqueuing into batch, state 1 hop 1
11/18/2012 15:42:23;0100;PBS_Server;Job;14112.tyrone-cluster;dequeuing from batch, state QUEUED
11/18/2012 15:42:23;0100;PBS_Server;Job;14112.tyrone-cluster;enqueuing into idqueue, state 1 hop 1
11/18/2012 15:42:23;0008;PBS_Server;Job;14112.tyrone-cluster;Job Queued at request of secadach@tyrone-cluster, owner = secadach@tyrone-cluster, job name = myjob, queue = idqueue
11/18/2012 15:42:23;0040;PBS_Server;Svr;tyrone-cluster;Scheduler was sent the command new
11/18/2012 15:42:23;0008;PBS_Server;Job;14112.tyrone-cluster;Job Modified at request of Scheduler@tyrone-cluster
11/18/2012 15:42:24;0100;PBS_Server;Job;14113.tyrone-cluster;enqueuing into batch, state 1 hop 1
11/18/2012 15:42:24;0100;PBS_Server;Job;14113.tyrone-cluster;dequeuing from batch, state QUEUED
11/18/2012 15:42:24;0100;PBS_Server;Job;14113.tyrone-cluster;enqueuing into idqueue, state 1 hop 1
11/18/2012 15:42:24;0008;PBS_Server;Job;14113.tyrone-cluster;Job Queued at request of secadach@tyrone-cluster, owner = secadach@tyrone-cluster, job name = myjob, queue = idqueue
11/18/2012 15:42:24;0040;PBS_Server;Svr;tyrone-cluster;Scheduler was sent the command new
11/18/2012 15:42:24;0008;PBS_Server;Job;14113.tyrone-cluster;Job Modified at request of Scheduler@tyrone-cluster
11/18/2012 15:42:49;0040;PBS_Server;Svr;tyrone-cluster;Scheduler was sent the command new
11/18/2012 15:43:19;0040;PBS_Server;Svr;tyrone-cluster;Scheduler was sent the command new
11/18/2012 15:43:49;0002;PBS_Server;Svr;PBS_Server;Torque Server Version = 3.0.5, loglevel = 0
11/18/2012 15:43:49;0008;PBS_Server;Job;14104.tyrone-cluster;Job deleted at request of secgeet@tyrone-cluster
11/18/2012 15:43:49;0008;PBS_Server;Job;NULL;on_job_exit valid pjob: 0x1342960 (substate=59)
11/18/2012 15:43:49;0100;PBS_Server;Job;14104.tyrone-cluster;dequeuing from idqueue, state COMPLETE
11/18/2012 15:43:49;0040;PBS_Server;Svr;tyrone-cluster;Scheduler was sent the command term
11/18/2012 15:43:58;0008;PBS_Server;Job;14103.tyrone-cluster;Job deleted at request of secgeet@tyrone-cluster
11/18/2012 15:43:58;0008;PBS_Server;Job;NULL;on_job_exit valid pjob: 0x13416a0 (substate=59)
11/18/2012 15:43:58;0100;PBS_Server;Job;14103.tyrone-cluster;dequeuing from idqueue, state COMPLETE
11/18/2012 15:43:58;0040;PBS_Server;Svr;tyrone-cluster;Scheduler was sent the command term
11/18/2012 15:44:19;0040;PBS_Server;Svr;tyrone-cluster;Scheduler was sent the command new
11/18/2012 15:44:49;0040;PBS_Server;Svr;tyrone-cluster;Scheduler was sent the command new
11/18/2012 15:45:19;0040;PBS_Server;Svr;tyrone-cluster;Scheduler was sent the command new
11/18/2012 15:45:49;0040;PBS_Server;Svr;tyrone-cluster;Scheduler was sent the command new
11/18/2012 15:46:19;0040;PBS_Server;Svr;tyrone-cluster;Scheduler was sent the command new
11/18/2012 15:46:49;0040;PBS_Server;Svr;tyrone-cluster;Scheduler was sent the command new
11/18/2012 15:47:19;0040;PBS_Server;Svr;tyrone-cluster;Scheduler was sent the command new
11/18/2012 15:47:49;0040;PBS_Server;Svr;tyrone-cluster;Scheduler was sent the command new
11/18/2012 15:48:19;0040;PBS_Server;Svr;tyrone-cluster;Scheduler was sent the command new
11/18/2012 15:48:49;0002;PBS_Server;Svr;PBS_Server;Torque Server Version = 3.0.5, loglevel = 0
11/18/2012 15:48:49;0040;PBS_Server;Svr;tyrone-cluster;Scheduler was sent the command new
11/18/2012 15:49:19;0040;PBS_Server;Svr;tyrone-cluster;Scheduler was sent the command new
11/18/2012 15:49:49;0040;PBS_Server;Svr;tyrone-cluster;Scheduler was sent the command new
11/18/2012 15:50:19;0040;PBS_Server;Svr;tyrone-cluster;Scheduler was sent the command new
11/18/2012 15:50:49;0040;PBS_Server;Svr;tyrone-cluster;Scheduler was sent the command new
11/18/2012 15:51:19;0040;PBS_Server;Svr;tyrone-cluster;Scheduler was sent the command new
11/18/2012 15:51:50;0040;PBS_Server;Svr;tyrone-cluster;Scheduler was sent the command new
11/18/2012 15:52:19;0040;PBS_Server;Svr;tyrone-cluster;Scheduler was sent the command new
11/18/2012 15:52:49;0040;PBS_Server;Svr;tyrone-cluster;Scheduler was sent the command new
11/18/2012 15:53:20;0040;PBS_Server;Svr;tyrone-cluster;Scheduler was sent the command new
11/18/2012 15:53:49;0002;PBS_Server;Svr;PBS_Server;Torque Server Version = 3.0.5, loglevel = 0
11/18/2012 15:53:51;0040;PBS_Server;Svr;tyrone-cluster;Scheduler was sent the command new
11/18/2012 15:54:26;0040;PBS_Server;Svr;tyrone-cluster;Scheduler was sent the command new
11/18/2012 15:54:56;0040;PBS_Server;Svr;tyrone-cluster;Scheduler was sent the command new
11/18/2012 15:55:27;0040;PBS_Server;Svr;tyrone-cluster;Scheduler was sent the command new
11/18/2012 15:55:58;0040;PBS_Server;Svr;tyrone-cluster;Scheduler was sent the command new
11/18/2012 15:56:28;0040;PBS_Server;Svr;tyrone-cluster;Scheduler was sent the command new
11/18/2012 15:56:58;0040;PBS_Server;Svr;tyrone-cluster;Scheduler was sent the command new
11/18/2012 15:57:28;0040;PBS_Server;Svr;tyrone-cluster;Scheduler was sent the command new
11/18/2012 15:57:58;0040;PBS_Server;Svr;tyrone-cluster;Scheduler was sent the command new
11/18/2012 15:58:29;0040;PBS_Server;Svr;tyrone-cluster;Scheduler was sent the command new
11/18/2012 15:58:49;0002;PBS_Server;Svr;PBS_Server;Torque Server Version = 3.0.5, loglevel = 0
11/18/2012 15:58:58;0040;PBS_Server;Svr;tyrone-cluster;Scheduler was sent the command new
11/18/2012 15:59:28;0040;PBS_Server;Svr;tyrone-cluster;Scheduler was sent the command new
11/18/2012 15:59:59;0040;PBS_Server;Svr;tyrone-cluster;Scheduler was sent the command new
11/18/2012 16:00:26;0008;PBS_Server;Job;14102.tyrone-cluster;Job deleted at request of secgeet@tyrone-cluster
11/18/2012 16:00:26;0008;PBS_Server;Job;NULL;on_job_exit valid pjob: 0x132ff00 (substate=59)
11/18/2012 16:00:26;0100;PBS_Server;Job;14102.tyrone-cluster;dequeuing from idqueue, state COMPLETE
11/18/2012 16:00:26;0040;PBS_Server;Svr;tyrone-cluster;Scheduler was sent the command term
11/18/2012 16:00:28;0040;PBS_Server;Svr;tyrone-cluster;Scheduler was sent the command new
11/18/2012 16:00:58;0040;PBS_Server;Svr;tyrone-cluster;Scheduler was sent the command new
11/18/2012 16:01:29;0040;PBS_Server;Svr;tyrone-cluster;Scheduler was sent the command new
11/18/2012 16:01:58;0040;PBS_Server;Svr;tyrone-cluster;Scheduler was sent the command new
11/18/2012 16:02:28;0040;PBS_Server;Svr;tyrone-cluster;Scheduler was sent the command new
11/18/2012 16:02:58;0040;PBS_Server;Svr;tyrone-cluster;Scheduler was sent the command new
11/18/2012 16:03:28;0040;PBS_Server;Svr;tyrone-cluster;Scheduler was sent the command new
11/18/2012 16:03:49;0002;PBS_Server;Svr;PBS_Server;Torque Server Version = 3.0.5, loglevel = 0
11/18/2012 16:03:58;0040;PBS_Server;Svr;tyrone-cluster;Scheduler was sent the command new
11/18/2012 16:04:28;0040;PBS_Server;Svr;tyrone-cluster;Scheduler was sent the command new
11/18/2012 16:04:58;0040;PBS_Server;Svr;tyrone-cluster;Scheduler was sent the command new
11/18/2012 16:05:28;0040;PBS_Server;Svr;tyrone-cluster;Scheduler was sent the command new
11/18/2012 16:05:58;0040;PBS_Server;Svr;tyrone-cluster;Scheduler was sent the command new
11/18/2012 16:06:28;0040;PBS_Server;Svr;tyrone-cluster;Scheduler was sent the command new
11/18/2012 16:06:58;0040;PBS_Server;Svr;tyrone-cluster;Scheduler was sent the command new
11/18/2012 16:07:29;0040;PBS_Server;Svr;tyrone-cluster;Scheduler was sent the command new
11/18/2012 16:07:58;0040;PBS_Server;Svr;tyrone-cluster;Scheduler was sent the command new
11/18/2012 16:08:28;0040;PBS_Server;Svr;tyrone-cluster;Scheduler was sent the command new
11/18/2012 16:08:49;0002;PBS_Server;Svr;PBS_Server;Torque Server Version = 3.0.5, loglevel = 0
11/18/2012 16:08:54;0008;PBS_Server;Job;14101.tyrone-cluster;Job deleted at request of secgeet@tyrone-cluster
11/18/2012 16:08:54;0008;PBS_Server;Job;14101.tyrone-cluster;Job sent signal SIGTERM on delete
11/18/2012 16:08:54;000d;PBS_Server;Job;14101.tyrone-cluster;Not sending email: User does not want mail of this type.
11/18/2012 16:08:54;0010;PBS_Server;Job;14101.tyrone-cluster;Exit_status=143 resources_used.cput=02:16:26 resources_used.mem=598912kb resources_used.vmem=6388168kb resources_used.walltime=00:47:34
11/18/2012 16:08:54;0008;PBS_Server;Job;NULL;on_job_exit valid pjob: 0x134e980 (substate=50)
11/18/2012 16:08:54;0008;PBS_Server;Job;NULL;on_job_exit valid pjob: 0x134e980 (substate=51)
11/18/2012 16:08:54;0008;PBS_Server;Job;NULL;on_job_exit valid pjob: 0x134e980 (substate=51)
11/18/2012 16:08:54;0008;PBS_Server;Job;NULL;on_job_exit valid pjob: 0x134e980 (substate=53)
11/18/2012 16:08:54;0100;PBS_Server;Job;14101.tyrone-cluster;dequeuing from idqueue, state COMPLETE
11/18/2012 16:08:54;0040;PBS_Server;Svr;tyrone-cluster;Scheduler was sent the command term
11/18/2012 16:08:54;0008;PBS_Server;Job;14105.tyrone-cluster;Job Modified at request of Scheduler@tyrone-cluster
11/18/2012 16:08:54;0008;PBS_Server;Job;14105.tyrone-cluster;Job Run at request of Scheduler@tyrone-cluster
11/18/2012 16:08:54;000d;PBS_Server;Job;14105.tyrone-cluster;Not sending email: User does not want mail of this type.
11/18/2012 16:08:54;0040;PBS_Server;Svr;tyrone-cluster;Scheduler was sent the command recyc
11/18/2012 16:08:58;0040;PBS_Server;Svr;tyrone-cluster;Scheduler was sent the command new
11/18/2012 16:09:34;0040;PBS_Server;Svr;tyrone-cluster;Scheduler was sent the command new
11/18/2012 16:10:04;0040;PBS_Server;Svr;tyrone-cluster;Scheduler was sent the command new
11/18/2012 16:10:35;0040;PBS_Server;Svr;tyrone-cluster;Scheduler was sent the command new
11/18/2012 16:11:06;0040;PBS_Server;Svr;tyrone-cluster;Scheduler was sent the command new
11/18/2012 16:11:41;0040;PBS_Server;Svr;tyrone-cluster;Scheduler was sent the command new
11/18/2012 16:12:11;0040;PBS_Server;Svr;tyrone-cluster;Scheduler was sent the command new
11/18/2012 16:12:23;000d;PBS_Server;Job;14105.tyrone-cluster;Not sending email: User does not want mail of this type.
11/18/2012 16:12:23;0010;PBS_Server;Job;14105.tyrone-cluster;Exit_status=0 resources_used.cput=00:05:33 resources_used.mem=2075824kb resources_used.vmem=3682792kb resources_used.walltime=00:03:29
11/18/2012 16:12:23;0008;PBS_Server;Job;NULL;on_job_exit valid pjob: 0x13fc830 (substate=50)
11/18/2012 16:12:23;0008;PBS_Server;Job;NULL;on_job_exit valid pjob: 0x13fc830 (substate=51)
11/18/2012 16:12:23;0008;PBS_Server;Job;NULL;on_job_exit valid pjob: 0x13fc830 (substate=51)
11/18/2012 16:12:23;0008;PBS_Server;Job;NULL;on_job_exit valid pjob: 0x13fc830 (substate=53)
11/18/2012 16:12:23;0100;PBS_Server;Job;14105.tyrone-cluster;dequeuing from idqueue, state COMPLETE
11/18/2012 16:12:23;0040;PBS_Server;Svr;tyrone-cluster;Scheduler was sent the command term
11/18/2012 16:12:23;0008;PBS_Server;Job;14106.tyrone-cluster;Job Modified at request of Scheduler@tyrone-cluster
11/18/2012 16:12:23;0008;PBS_Server;Job;14106.tyrone-cluster;Job Run at request of Scheduler@tyrone-cluster
11/18/2012 16:12:23;000d;PBS_Server;Job;14106.tyrone-cluster;Not sending email: User does not want mail of this type.
11/18/2012 16:12:23;0040;PBS_Server;Svr;tyrone-cluster;Scheduler was sent the command recyc
11/18/2012 16:12:42;0040;PBS_Server;Svr;tyrone-cluster;Scheduler was sent the command new
11/18/2012 16:13:19;0040;PBS_Server;Svr;tyrone-cluster;Scheduler was sent the command new
11/18/2012 16:13:49;0002;PBS_Server;Svr;PBS_Server;Torque Server Version = 3.0.5, loglevel = 0
11/18/2012 16:13:49;0040;PBS_Server;Svr;tyrone-cluster;Scheduler was sent the command new
11/18/2012 16:14:20;0040;PBS_Server;Svr;tyrone-cluster;Scheduler was sent the command new
11/18/2012 16:14:51;0040;PBS_Server;Svr;tyrone-cluster;Scheduler was sent the command new
11/18/2012 16:15:26;0040;PBS_Server;Svr;tyrone-cluster;Scheduler was sent the command new
11/18/2012 16:15:56;0040;PBS_Server;Svr;tyrone-cluster;Scheduler was sent the command new
11/18/2012 16:15:58;0100;PBS_Server;Job;14114.tyrone-cluster;enqueuing into batch, state 1 hop 1
11/18/2012 16:15:58;0100;PBS_Server;Job;14114.tyrone-cluster;dequeuing from batch, state QUEUED
11/18/2012 16:15:58;0100;PBS_Server;Job;14114.tyrone-cluster;enqueuing into idqueue, state 1 hop 1
11/18/2012 16:15:58;0008;PBS_Server;Job;14114.tyrone-cluster;Job Queued at request of seckriti@tyrone-cluster, owner = seckriti@tyrone-cluster, job name = myjob, queue = idqueue
11/18/2012 16:16:00;0008;PBS_Server;Job;14114.tyrone-cluster;Job Modified at request of Scheduler@tyrone-cluster
11/18/2012 16:16:00;000d;PBS_Server;Job;14086.tyrone-cluster;Not sending email: User does not want mail of this type.
11/18/2012 16:16:00;0010;PBS_Server;Job;14086.tyrone-cluster;Exit_status=143 resources_used.cput=29:07:02 resources_used.mem=15856764kb resources_used.vmem=20780392kb resources_used.walltime=02:00:25
11/18/2012 16:16:00;0008;PBS_Server;Job;NULL;on_job_exit valid pjob: 0x12f5dd0 (substate=50)
11/18/2012 16:16:00;0008;PBS_Server;Job;NULL;on_job_exit valid pjob: 0x12f5dd0 (substate=51)
11/18/2012 16:16:00;0008;PBS_Server;Job;NULL;on_job_exit valid pjob: 0x12f5dd0 (substate=51)
11/18/2012 16:16:00;0008;PBS_Server;Job;NULL;on_job_exit valid pjob: 0x12f5dd0 (substate=53)
11/18/2012 16:16:00;0100;PBS_Server;Job;14086.tyrone-cluster;dequeuing from idqueue, state COMPLETE
11/18/2012 16:16:00;0040;PBS_Server;Svr;tyrone-cluster;Scheduler was sent the command term
11/18/2012 16:16:00;0008;PBS_Server;Job;14109.tyrone-cluster;Job Modified at request of Scheduler@tyrone-cluster
11/18/2012 16:16:00;0008;PBS_Server;Job;14109.tyrone-cluster;Job Run at request of Scheduler@tyrone-cluster
11/18/2012 16:16:00;000d;PBS_Server;Job;14109.tyrone-cluster;Not sending email: User does not want mail of this type.
11/18/2012 16:16:00;0040;PBS_Server;Svr;tyrone-cluster;Scheduler was sent the command recyc
11/18/2012 16:16:28;0040;PBS_Server;Svr;tyrone-cluster;Scheduler was sent the command new
11/18/2012 16:16:59;0040;PBS_Server;Svr;tyrone-cluster;Scheduler was sent the command new
11/18/2012 16:17:31;0040;PBS_Server;Svr;tyrone-cluster;Scheduler was sent the command new
11/18/2012 16:18:02;0040;PBS_Server;Svr;tyrone-cluster;Scheduler was sent the command new
11/18/2012 16:18:37;0040;PBS_Server;Svr;tyrone-cluster;Scheduler was sent the command new
11/18/2012 16:18:49;0002;PBS_Server;Svr;PBS_Server;Torque Server Version = 3.0.5, loglevel = 0
11/18/2012 16:19:07;0040;PBS_Server;Svr;tyrone-cluster;Scheduler was sent the command new
11/18/2012 16:19:38;0040;PBS_Server;Svr;tyrone-cluster;Scheduler was sent the command new
11/18/2012 16:20:08;0040;PBS_Server;Svr;tyrone-cluster;Scheduler was sent the command new
11/18/2012 16:20:38;0040;PBS_Server;Svr;tyrone-cluster;Scheduler was sent the command new
11/18/2012 16:20:52;0080;PBS_Server;Req;req_reject;Reject reply code=15007(Unauthorized Request ), aux=0, type=Manager, from seckriti@tyrone-cluster
11/18/2012 16:21:08;0040;PBS_Server;Svr;tyrone-cluster;Scheduler was sent the command new
11/18/2012 16:21:39;0040;PBS_Server;Svr;tyrone-cluster;Scheduler was sent the command new
11/18/2012 16:22:14;0040;PBS_Server;Svr;tyrone-cluster;Scheduler was sent the command new
11/18/2012 16:22:46;0040;PBS_Server;Svr;tyrone-cluster;Scheduler was sent the command new
11/18/2012 16:23:02;0100;PBS_Server;Job;14115.tyrone-cluster;enqueuing into batch, state 1 hop 1
11/18/2012 16:23:02;0100;PBS_Server;Job;14115.tyrone-cluster;dequeuing from batch, state QUEUED
11/18/2012 16:23:02;0100;PBS_Server;Job;14115.tyrone-cluster;enqueuing into idqueue, state 1 hop 1
11/18/2012 16:23:02;0008;PBS_Server;Job;14115.tyrone-cluster;Job Queued at request of seckriti@tyrone-cluster, owner = seckriti@tyrone-cluster, job name = myjob, queue = idqueue
11/18/2012 16:23:02;0040;PBS_Server;Svr;tyrone-cluster;Scheduler was sent the command new
11/18/2012 16:23:02;0008;PBS_Server;Job;14115.tyrone-cluster;Job Modified at request of Scheduler@tyrone-cluster
11/18/2012 16:23:06;0100;PBS_Server;Job;14116.tyrone-cluster;enqueuing into batch, state 1 hop 1
11/18/2012 16:23:06;0100;PBS_Server;Job;14116.tyrone-cluster;dequeuing from batch, state QUEUED
11/18/2012 16:23:06;0100;PBS_Server;Job;14116.tyrone-cluster;enqueuing into idqueue, state 1 hop 1
11/18/2012 16:23:06;0008;PBS_Server;Job;14116.tyrone-cluster;Job Queued at request of seckriti@tyrone-cluster, owner = seckriti@tyrone-cluster, job name = myjob, queue = idqueue
11/18/2012 16:23:06;0040;PBS_Server;Svr;tyrone-cluster;Scheduler was sent the command new
11/18/2012 16:23:06;0008;PBS_Server;Job;14116.tyrone-cluster;Job Modified at request of Scheduler@tyrone-cluster
11/18/2012 16:23:10;0100;PBS_Server;Job;14117.tyrone-cluster;enqueuing into batch, state 1 hop 1
11/18/2012 16:23:10;0100;PBS_Server;Job;14117.tyrone-cluster;dequeuing from batch, state QUEUED
11/18/2012 16:23:10;0100;PBS_Server;Job;14117.tyrone-cluster;enqueuing into idqueue, state 1 hop 1
11/18/2012 16:23:10;0008;PBS_Server;Job;14117.tyrone-cluster;Job Queued at request of seckriti@tyrone-cluster, owner = seckriti@tyrone-cluster, job name = myjob, queue = idqueue
11/18/2012 16:23:10;0040;PBS_Server;Svr;tyrone-cluster;Scheduler was sent the command new
11/18/2012 16:23:10;0008;PBS_Server;Job;14117.tyrone-cluster;Job Modified at request of Scheduler@tyrone-cluster
11/18/2012 16:23:15;0040;PBS_Server;Svr;tyrone-cluster;Scheduler was sent the command new
11/18/2012 16:23:44;0040;PBS_Server;Svr;tyrone-cluster;Scheduler was sent the command new
11/18/2012 16:23:49;0002;PBS_Server;Svr;PBS_Server;Torque Server Version = 3.0.5, loglevel = 0
11/18/2012 16:24:16;0040;PBS_Server;Svr;tyrone-cluster;Scheduler was sent the command new
11/18/2012 16:24:45;0040;PBS_Server;Svr;tyrone-cluster;Scheduler was sent the command new
11/18/2012 16:25:14;0040;PBS_Server;Svr;tyrone-cluster;Scheduler was sent the command new
11/18/2012 16:25:31;0100;PBS_Server;Job;14118.tyrone-cluster;enqueuing into batch, state 1 hop 1
11/18/2012 16:25:31;0100;PBS_Server;Job;14118.tyrone-cluster;dequeuing from batch, state QUEUED
11/18/2012 16:25:31;0100;PBS_Server;Job;14118.tyrone-cluster;enqueuing into idqueue, state 1 hop 1
11/18/2012 16:25:31;0008;PBS_Server;Job;14118.tyrone-cluster;Job Queued at request of secvkm@tyrone-cluster, owner = secvkm@tyrone-cluster, job name = myjob, queue = idqueue
11/18/2012 16:25:31;0040;PBS_Server;Svr;tyrone-cluster;Scheduler was sent the command new
11/18/2012 16:25:31;0008;PBS_Server;Job;14118.tyrone-cluster;Job Modified at request of Scheduler@tyrone-cluster
11/18/2012 16:25:46;0040;PBS_Server;Svr;tyrone-cluster;Scheduler was sent the command new
11/18/2012 16:26:08;0100;PBS_Server;Job;14119.tyrone-cluster;enqueuing into batch, state 1 hop 1
11/18/2012 16:26:08;0100;PBS_Server;Job;14119.tyrone-cluster;dequeuing from batch, state QUEUED
11/18/2012 16:26:08;0100;PBS_Server;Job;14119.tyrone-cluster;enqueuing into idqueue, state 1 hop 1
11/18/2012 16:26:08;0008;PBS_Server;Job;14119.tyrone-cluster;Job Queued at request of secvkm@tyrone-cluster, owner = secvkm@tyrone-cluster, job name = myjob, queue = idqueue
11/18/2012 16:26:08;0040;PBS_Server;Svr;tyrone-cluster;Scheduler was sent the command new
11/18/2012 16:26:08;0008;PBS_Server;Job;14119.tyrone-cluster;Job Modified at request of Scheduler@tyrone-cluster
11/18/2012 16:26:11;0100;PBS_Server;Job;14120.tyrone-cluster;enqueuing into batch, state 1 hop 1
11/18/2012 16:26:11;0100;PBS_Server;Job;14120.tyrone-cluster;dequeuing from batch, state QUEUED
11/18/2012 16:26:11;0100;PBS_Server;Job;14120.tyrone-cluster;enqueuing into idqueue, state 1 hop 1
11/18/2012 16:26:11;0008;PBS_Server;Job;14120.tyrone-cluster;Job Queued at request of secvkm@tyrone-cluster, owner = secvkm@tyrone-cluster, job name = myjob, queue = idqueue
11/18/2012 16:26:11;0040;PBS_Server;Svr;tyrone-cluster;Scheduler was sent the command new
11/18/2012 16:26:11;0008;PBS_Server;Job;14120.tyrone-cluster;Job Modified at request of Scheduler@tyrone-cluster
11/18/2012 16:26:12;0100;PBS_Server;Job;14121.tyrone-cluster;enqueuing into batch, state 1 hop 1
11/18/2012 16:26:12;0100;PBS_Server;Job;14121.tyrone-cluster;dequeuing from batch, state QUEUED
11/18/2012 16:26:12;0100;PBS_Server;Job;14121.tyrone-cluster;enqueuing into idqueue, state 1 hop 1
11/18/2012 16:26:12;0008;PBS_Server;Job;14121.tyrone-cluster;Job Queued at request of secvkm@tyrone-cluster, owner = secvkm@tyrone-cluster, job name = myjob, queue = idqueue
11/18/2012 16:26:12;0040;PBS_Server;Svr;tyrone-cluster;Scheduler was sent the command new
11/18/2012 16:26:12;0008;PBS_Server;Job;14121.tyrone-cluster;Job Modified at request of Scheduler@tyrone-cluster
11/18/2012 16:26:13;0100;PBS_Server;Job;14122.tyrone-cluster;enqueuing into batch, state 1 hop 1
11/18/2012 16:26:13;0100;PBS_Server;Job;14122.tyrone-cluster;dequeuing from batch, state QUEUED
11/18/2012 16:26:13;0100;PBS_Server;Job;14122.tyrone-cluster;enqueuing into idqueue, state 1 hop 1
11/18/2012 16:26:13;0008;PBS_Server;Job;14122.tyrone-cluster;Job Queued at request of secvkm@tyrone-cluster, owner = secvkm@tyrone-cluster, job name = myjob, queue = idqueue
11/18/2012 16:26:13;0040;PBS_Server;Svr;tyrone-cluster;Scheduler was sent the command new
11/18/2012 16:26:13;0008;PBS_Server;Job;14122.tyrone-cluster;Job Modified at request of Scheduler@tyrone-cluster
11/18/2012 16:26:17;0040;PBS_Server;Svr;tyrone-cluster;Scheduler was sent the command new
11/18/2012 16:26:39;000d;PBS_Server;Job;14106.tyrone-cluster;Not sending email: User does not want mail of this type.
11/18/2012 16:26:39;0010;PBS_Server;Job;14106.tyrone-cluster;Exit_status=0 resources_used.cput=00:32:55 resources_used.mem=569892kb resources_used.vmem=1685256kb resources_used.walltime=00:14:16
11/18/2012 16:26:39;0008;PBS_Server;Job;NULL;on_job_exit valid pjob: 0x13fdaf0 (substate=50)
11/18/2012 16:26:39;0008;PBS_Server;Job;NULL;on_job_exit valid pjob: 0x13fdaf0 (substate=51)
11/18/2012 16:26:40;0008;PBS_Server;Job;NULL;on_job_exit valid pjob: 0x13fdaf0 (substate=51)
11/18/2012 16:26:40;0008;PBS_Server;Job;NULL;on_job_exit valid pjob: 0x13fdaf0 (substate=53)
11/18/2012 16:26:40;0100;PBS_Server;Job;14106.tyrone-cluster;dequeuing from idqueue, state COMPLETE
11/18/2012 16:26:40;0040;PBS_Server;Svr;tyrone-cluster;Scheduler was sent the command term
11/18/2012 16:26:40;0008;PBS_Server;Job;14110.tyrone-cluster;Job Modified at request of Scheduler@tyrone-cluster
11/18/2012 16:26:40;0008;PBS_Server;Job;14110.tyrone-cluster;Job Run at request of Scheduler@tyrone-cluster
11/18/2012 16:26:40;0008;PBS_Server;Job;14111.tyrone-cluster;Job Modified at request of Scheduler@tyrone-cluster
11/18/2012 16:26:40;0008;PBS_Server;Job;14112.tyrone-cluster;Job Modified at request of Scheduler@tyrone-cluster
11/18/2012 16:26:40;0008;PBS_Server;Job;14113.tyrone-cluster;Job Modified at request of Scheduler@tyrone-cluster
11/18/2012 16:26:40;000d;PBS_Server;Job;14110.tyrone-cluster;Not sending email: User does not want mail of this type.
11/18/2012 16:26:40;0040;PBS_Server;Svr;tyrone-cluster;Scheduler was sent the command recyc
11/18/2012 16:26:47;0040;PBS_Server;Svr;tyrone-cluster;Scheduler was sent the command new
11/18/2012 16:27:20;0040;PBS_Server;Svr;tyrone-cluster;Scheduler was sent the command new
11/18/2012 16:27:52;0040;PBS_Server;Svr;tyrone-cluster;Scheduler was sent the command new
11/18/2012 16:28:22;0040;PBS_Server;Svr;tyrone-cluster;Scheduler was sent the command new
11/18/2012 16:28:49;0002;PBS_Server;Svr;PBS_Server;Torque Server Version = 3.0.5, loglevel = 0
11/18/2012 16:28:52;0040;PBS_Server;Svr;tyrone-cluster;Scheduler was sent the command new
11/18/2012 16:29:23;0040;PBS_Server;Svr;tyrone-cluster;Scheduler was sent the command new
11/18/2012 16:29:54;0040;PBS_Server;Svr;tyrone-cluster;Scheduler was sent the command new
11/18/2012 16:30:14;000d;PBS_Server;Job;14094.tyrone-cluster;Not sending email: User does not want mail of this type.
11/18/2012 16:30:14;0010;PBS_Server;Job;14094.tyrone-cluster;Exit_status=143 resources_used.cput=27:21:59 resources_used.mem=15451216kb resources_used.vmem=20774340kb resources_used.walltime=02:00:26
11/18/2012 16:30:14;0008;PBS_Server;Job;NULL;on_job_exit valid pjob: 0x12f83c0 (substate=50)
11/18/2012 16:30:14;0008;PBS_Server;Job;NULL;on_job_exit valid pjob: 0x12f83c0 (substate=51)
11/18/2012 16:30:15;0008;PBS_Server;Job;NULL;on_job_exit valid pjob: 0x12f83c0 (substate=51)
11/18/2012 16:30:15;0008;PBS_Server;Job;NULL;on_job_exit valid pjob: 0x12f83c0 (substate=53)
11/18/2012 16:30:15;0100;PBS_Server;Job;14094.tyrone-cluster;dequeuing from idqueue, state COMPLETE
11/18/2012 16:30:15;0040;PBS_Server;Svr;tyrone-cluster;Scheduler was sent the command term
11/18/2012 16:30:15;0008;PBS_Server;Job;14114.tyrone-cluster;Job Modified at request of Scheduler@tyrone-cluster
11/18/2012 16:30:15;0008;PBS_Server;Job;14114.tyrone-cluster;Job Run at request of Scheduler@tyrone-cluster
11/18/2012 16:30:15;000d;PBS_Server;Job;14114.tyrone-cluster;Not sending email: User does not want mail of this type.
11/18/2012 16:30:15;0040;PBS_Server;Svr;tyrone-cluster;Scheduler was sent the command recyc
11/18/2012 16:30:37;0040;PBS_Server;Svr;tyrone-cluster;Scheduler was sent the command new
11/18/2012 16:30:43;0100;PBS_Server;Job;14123.tyrone-cluster;enqueuing into batch, state 1 hop 1
11/18/2012 16:30:43;0100;PBS_Server;Job;14123.tyrone-cluster;dequeuing from batch, state QUEUED
11/18/2012 16:30:43;0100;PBS_Server;Job;14123.tyrone-cluster;enqueuing into idqueue, state 1 hop 1
11/18/2012 16:30:43;0008;PBS_Server;Job;14123.tyrone-cluster;Job Queued at request of secjagvi@tyrone-cluster, owner = secjagvi@tyrone-cluster, job name = myjob, queue = idqueue
11/18/2012 16:30:43;000d;PBS_Server;Job;14114.tyrone-cluster;Not sending email: User does not want mail of this type.
11/18/2012 16:30:43;0010;PBS_Server;Job;14114.tyrone-cluster;Exit_status=0 resources_used.cput=00:00:53 resources_used.mem=0kb resources_used.vmem=0kb resources_used.walltime=00:00:28
11/18/2012 16:30:43;0008;PBS_Server;Job;NULL;on_job_exit valid pjob: 0x134e980 (substate=50)
11/18/2012 16:30:43;0008;PBS_Server;Job;NULL;on_job_exit valid pjob: 0x134e980 (substate=51)
11/18/2012 16:30:43;0008;PBS_Server;Job;14123.tyrone-cluster;Job Modified at request of Scheduler@tyrone-cluster
11/18/2012 16:30:43;000d;PBS_Server;Job;14100.tyrone-cluster;Not sending email: User does not want mail of this type.
11/18/2012 16:30:43;0010;PBS_Server;Job;14100.tyrone-cluster;Exit_status=0 resources_used.cput=05:44:10 resources_used.mem=715932kb resources_used.vmem=8546024kb resources_used.walltime=01:17:21
11/18/2012 16:30:43;0008;PBS_Server;Job;NULL;on_job_exit valid pjob: 0x131f740 (substate=50)
11/18/2012 16:30:43;0008;PBS_Server;Job;NULL;on_job_exit valid pjob: 0x131f740 (substate=51)
11/18/2012 16:30:44;0008;PBS_Server;Job;NULL;on_job_exit valid pjob: 0x134e980 (substate=51)
11/18/2012 16:30:44;0008;PBS_Server;Job;NULL;on_job_exit valid pjob: 0x134e980 (substate=53)
11/18/2012 16:30:44;0100;PBS_Server;Job;14114.tyrone-cluster;dequeuing from idqueue, state COMPLETE
11/18/2012 16:30:44;0040;PBS_Server;Svr;tyrone-cluster;Scheduler was sent the command term
11/18/2012 16:30:44;0008;PBS_Server;Job;NULL;on_job_exit valid pjob: 0x131f740 (substate=51)
11/18/2012 16:30:44;0008;PBS_Server;Job;NULL;on_job_exit valid pjob: 0x131f740 (substate=53)
11/18/2012 16:30:44;0100;PBS_Server;Job;14100.tyrone-cluster;dequeuing from idqueue, state COMPLETE
11/18/2012 16:30:44;0008;PBS_Server;Job;14115.tyrone-cluster;Job Modified at request of Scheduler@tyrone-cluster
11/18/2012 16:30:44;0008;PBS_Server;Job;14115.tyrone-cluster;Job Run at request of Scheduler@tyrone-cluster
11/18/2012 16:30:44;0008;PBS_Server;Job;14116.tyrone-cluster;Job Modified at request of Scheduler@tyrone-cluster
11/18/2012 16:30:44;0008;PBS_Server;Job;14116.tyrone-cluster;Job Run at request of Scheduler@tyrone-cluster
11/18/2012 16:30:44;000d;PBS_Server;Job;14115.tyrone-cluster;Not sending email: User does not want mail of this type.
11/18/2012 16:30:45;0008;PBS_Server;Job;14117.tyrone-cluster;Job Modified at request of Scheduler@tyrone-cluster
11/18/2012 16:30:45;000d;PBS_Server;Job;14116.tyrone-cluster;Not sending email: User does not want mail of this type.
11/18/2012 16:30:45;000d;PBS_Server;Job;14116.tyrone-cluster;Not sending email: User does not want mail of this type.
11/18/2012 16:30:45;0010;PBS_Server;Job;14116.tyrone-cluster;Exit_status=0 resources_used.cput=00:00:01 resources_used.mem=0kb resources_used.vmem=0kb resources_used.walltime=00:00:01
11/18/2012 16:30:45;0008;PBS_Server;Job;NULL;on_job_exit valid pjob: 0x12f5dd0 (substate=50)
11/18/2012 16:30:45;0008;PBS_Server;Job;NULL;on_job_exit valid pjob: 0x12f5dd0 (substate=51)
11/18/2012 16:30:45;0008;PBS_Server;Job;NULL;on_job_exit valid pjob: 0x12f5dd0 (substate=51)
11/18/2012 16:30:45;0008;PBS_Server;Job;NULL;on_job_exit valid pjob: 0x12f5dd0 (substate=53)
11/18/2012 16:30:45;0100;PBS_Server;Job;14116.tyrone-cluster;dequeuing from idqueue, state COMPLETE
11/18/2012 16:30:45;0040;PBS_Server;Svr;tyrone-cluster;Scheduler was sent the command term
11/18/2012 16:30:46;000d;PBS_Server;Job;14115.tyrone-cluster;Not sending email: User does not want mail of this type.
11/18/2012 16:30:46;0010;PBS_Server;Job;14115.tyrone-cluster;Exit_status=0 resources_used.cput=00:00:01 resources_used.mem=25212kb resources_used.vmem=483832kb resources_used.walltime=00:00:02
11/18/2012 16:30:46;0008;PBS_Server;Job;NULL;on_job_exit valid pjob: 0x132ff00 (substate=50)
11/18/2012 16:30:46;0008;PBS_Server;Job;NULL;on_job_exit valid pjob: 0x132ff00 (substate=51)
11/18/2012 16:30:46;0008;PBS_Server;Job;NULL;on_job_exit valid pjob: 0x132ff00 (substate=51)
11/18/2012 16:30:46;0008;PBS_Server;Job;NULL;on_job_exit valid pjob: 0x132ff00 (substate=53)
11/18/2012 16:30:46;0100;PBS_Server;Job;14115.tyrone-cluster;dequeuing from idqueue, state COMPLETE
11/18/2012 16:30:46;0008;PBS_Server;Job;14117.tyrone-cluster;Job Modified at request of Scheduler@tyrone-cluster
11/18/2012 16:30:46;0008;PBS_Server;Job;14117.tyrone-cluster;Job Run at request of Scheduler@tyrone-cluster
11/18/2012 16:30:46;0008;PBS_Server;Job;14118.tyrone-cluster;Job Modified at request of Scheduler@tyrone-cluster
11/18/2012 16:30:46;000d;PBS_Server;Job;14117.tyrone-cluster;Not sending email: User does not want mail of this type.
11/18/2012 16:30:46;0008;PBS_Server;Job;14118.tyrone-cluster;Job Run at request of Scheduler@tyrone-cluster
11/18/2012 16:30:46;000d;PBS_Server;Job;14118.tyrone-cluster;Not sending email: User does not want mail of this type.
11/18/2012 16:30:47;000d;PBS_Server;Job;14117.tyrone-cluster;Not sending email: User does not want mail of this type.
11/18/2012 16:30:47;0010;PBS_Server;Job;14117.tyrone-cluster;Exit_status=0 resources_used.cput=00:00:02 resources_used.mem=0kb resources_used.vmem=0kb resources_used.walltime=00:00:01
11/18/2012 16:30:47;0008;PBS_Server;Job;NULL;on_job_exit valid pjob: 0x13e5610 (substate=50)
11/18/2012 16:30:47;0008;PBS_Server;Job;NULL;on_job_exit valid pjob: 0x13e5610 (substate=51)
11/18/2012 16:30:47;0008;PBS_Server;Job;NULL;on_job_exit valid pjob: 0x13e5610 (substate=51)
11/18/2012 16:30:47;0008;PBS_Server;Job;NULL;on_job_exit valid pjob: 0x13e5610 (substate=53)
11/18/2012 16:30:47;0100;PBS_Server;Job;14117.tyrone-cluster;dequeuing from idqueue, state COMPLETE
11/18/2012 16:30:47;0040;PBS_Server;Svr;tyrone-cluster;Scheduler was sent the command term
11/18/2012 16:30:47;0008;PBS_Server;Job;14119.tyrone-cluster;Job Modified at request of Scheduler@tyrone-cluster
11/18/2012 16:30:47;0008;PBS_Server;Job;14119.tyrone-cluster;Job Run at request of Scheduler@tyrone-cluster
11/18/2012 16:30:47;0008;PBS_Server;Job;14120.tyrone-cluster;Job Modified at request of Scheduler@tyrone-cluster
11/18/2012 16:30:47;0008;PBS_Server;Job;14121.tyrone-cluster;Job Modified at request of Scheduler@tyrone-cluster
11/18/2012 16:30:47;000d;PBS_Server;Job;14119.tyrone-cluster;Not sending email: User does not want mail of this type.
11/18/2012 16:30:47;0008;PBS_Server;Job;14122.tyrone-cluster;Job Modified at request of Scheduler@tyrone-cluster
11/18/2012 16:30:47;0040;PBS_Server;Svr;tyrone-cluster;Scheduler was sent the command recyc
11/18/2012 16:31:01;0040;PBS_Server;Svr;tyrone-cluster;Scheduler was sent the command new
11/18/2012 16:31:30;0040;PBS_Server;Svr;tyrone-cluster;Scheduler was sent the command new
11/18/2012 16:32:07;0040;PBS_Server;Svr;tyrone-cluster;Scheduler was sent the command new
11/18/2012 16:32:37;0040;PBS_Server;Svr;tyrone-cluster;Scheduler was sent the command new
11/18/2012 16:33:08;0040;PBS_Server;Svr;tyrone-cluster;Scheduler was sent the command new
11/18/2012 16:33:37;0040;PBS_Server;Svr;tyrone-cluster;Scheduler was sent the command new
11/18/2012 16:33:49;0002;PBS_Server;Svr;PBS_Server;Torque Server Version = 3.0.5, loglevel = 0
11/18/2012 16:33:59;000d;PBS_Server;Job;13774.tyrone-cluster;Not sending email: User does not want mail of this type.
11/18/2012 16:33:59;0010;PBS_Server;Job;13774.tyrone-cluster;Exit_status=0 resources_used.cput=224:40:49 resources_used.mem=5752476kb resources_used.vmem=20778488kb resources_used.walltime=07:15:00
11/18/2012 16:33:59;0008;PBS_Server;Job;NULL;on_job_exit valid pjob: 0x1314c50 (substate=50)
11/18/2012 16:33:59;0008;PBS_Server;Job;NULL;on_job_exit valid pjob: 0x1314c50 (substate=51)
11/18/2012 16:33:59;0008;PBS_Server;Job;NULL;on_job_exit valid pjob: 0x1314c50 (substate=51)
11/18/2012 16:33:59;0008;PBS_Server;Job;NULL;on_job_exit valid pjob: 0x1314c50 (substate=53)
11/18/2012 16:33:59;0100;PBS_Server;Job;13774.tyrone-cluster;dequeuing from qp32, state COMPLETE
11/18/2012 16:33:59;0040;PBS_Server;Svr;tyrone-cluster;Scheduler was sent the command term
11/18/2012 16:33:59;0008;PBS_Server;Job;13810.tyrone-cluster;Job Modified at request of Scheduler@tyrone-cluster
11/18/2012 16:33:59;0008;PBS_Server;Job;13594.tyrone-cluster;Job Modified at request of Scheduler@tyrone-cluster
11/18/2012 16:33:59;0008;PBS_Server;Job;13984.tyrone-cluster;Job Modified at request of Scheduler@tyrone-cluster
11/18/2012 16:33:59;0008;PBS_Server;Job;13985.tyrone-cluster;Job Modified at request of Scheduler@tyrone-cluster
11/18/2012 16:33:59;0008;PBS_Server;Job;13992.tyrone-cluster;Job Modified at request of Scheduler@tyrone-cluster
11/18/2012 16:33:59;0008;PBS_Server;Job;13992.tyrone-cluster;Job Run at request of Scheduler@tyrone-cluster
11/18/2012 16:33:59;0040;PBS_Server;Svr;tyrone-cluster;Scheduler was sent the command recyc
11/18/2012 16:33:59;000d;PBS_Server;Job;13992.tyrone-cluster;Not sending email: User does not want mail of this type.
11/18/2012 16:34:07;0040;PBS_Server;Svr;tyrone-cluster;Scheduler was sent the command new
11/18/2012 16:34:07;0008;PBS_Server;Job;13810.tyrone-cluster;Job Modified at request of Scheduler@tyrone-cluster
11/18/2012 16:34:07;0008;PBS_Server;Job;13594.tyrone-cluster;Job Modified at request of Scheduler@tyrone-cluster
11/18/2012 16:34:07;0008;PBS_Server;Job;13984.tyrone-cluster;Job Modified at request of Scheduler@tyrone-cluster
11/18/2012 16:34:07;0008;PBS_Server;Job;13985.tyrone-cluster;Job Modified at request of Scheduler@tyrone-cluster
11/18/2012 16:34:12;0100;PBS_Server;Job;14124.tyrone-cluster;enqueuing into batch, state 1 hop 1
11/18/2012 16:34:12;0100;PBS_Server;Job;14124.tyrone-cluster;dequeuing from batch, state QUEUED
11/18/2012 16:34:12;0100;PBS_Server;Job;14124.tyrone-cluster;enqueuing into idqueue, state 1 hop 1
11/18/2012 16:34:12;0008;PBS_Server;Job;14124.tyrone-cluster;Job Queued at request of seckriti@tyrone-cluster, owner = seckriti@tyrone-cluster, job name = myjob, queue = idqueue
11/18/2012 16:34:12;0040;PBS_Server;Svr;tyrone-cluster;Scheduler was sent the command new
11/18/2012 16:34:12;0008;PBS_Server;Job;14124.tyrone-cluster;Job Modified at request of Scheduler@tyrone-cluster
11/18/2012 16:34:18;0100;PBS_Server;Job;14125.tyrone-cluster;enqueuing into batch, state 1 hop 1
11/18/2012 16:34:18;0100;PBS_Server;Job;14125.tyrone-cluster;dequeuing from batch, state QUEUED
11/18/2012 16:34:18;0100;PBS_Server;Job;14125.tyrone-cluster;enqueuing into idqueue, state 1 hop 1
11/18/2012 16:34:18;0008;PBS_Server;Job;14125.tyrone-cluster;Job Queued at request of seckriti@tyrone-cluster, owner = seckriti@tyrone-cluster, job name = myjob, queue = idqueue
11/18/2012 16:34:18;0040;PBS_Server;Svr;tyrone-cluster;Scheduler was sent the command new
11/18/2012 16:34:18;0008;PBS_Server;Job;14125.tyrone-cluster;Job Modified at request of Scheduler@tyrone-cluster
11/18/2012 16:34:23;0100;PBS_Server;Job;14126.tyrone-cluster;enqueuing into batch, state 1 hop 1
11/18/2012 16:34:23;0100;PBS_Server;Job;14126.tyrone-cluster;dequeuing from batch, state QUEUED
11/18/2012 16:34:23;0100;PBS_Server;Job;14126.tyrone-cluster;enqueuing into idqueue, state 1 hop 1
11/18/2012 16:34:23;0008;PBS_Server;Job;14126.tyrone-cluster;Job Queued at request of seckriti@tyrone-cluster, owner = seckriti@tyrone-cluster, job name = myjob, queue = idqueue
11/18/2012 16:34:23;0040;PBS_Server;Svr;tyrone-cluster;Scheduler was sent the command new
11/18/2012 16:34:23;0008;PBS_Server;Job;14126.tyrone-cluster;Job Modified at request of Scheduler@tyrone-cluster
11/18/2012 16:34:26;0100;PBS_Server;Job;14127.tyrone-cluster;enqueuing into batch, state 1 hop 1
11/18/2012 16:34:26;0100;PBS_Server;Job;14127.tyrone-cluster;dequeuing from batch, state QUEUED
11/18/2012 16:34:26;0100;PBS_Server;Job;14127.tyrone-cluster;enqueuing into idqueue, state 1 hop 1
11/18/2012 16:34:26;0008;PBS_Server;Job;14127.tyrone-cluster;Job Queued at request of seckriti@tyrone-cluster, owner = seckriti@tyrone-cluster, job name = myjob, queue = idqueue
11/18/2012 16:34:26;0040;PBS_Server;Svr;tyrone-cluster;Scheduler was sent the command new
11/18/2012 16:34:26;0008;PBS_Server;Job;14127.tyrone-cluster;Job Modified at request of Scheduler@tyrone-cluster
11/18/2012 16:34:38;0040;PBS_Server;Svr;tyrone-cluster;Scheduler was sent the command new
11/18/2012 16:35:09;0040;PBS_Server;Svr;tyrone-cluster;Scheduler was sent the command new
11/18/2012 16:35:11;000d;PBS_Server;Job;14109.tyrone-cluster;Not sending email: User does not want mail of this type.
11/18/2012 16:35:11;0010;PBS_Server;Job;14109.tyrone-cluster;Exit_status=0 resources_used.cput=01:32:56 resources_used.mem=468484kb resources_used.vmem=1582624kb resources_used.walltime=00:19:11
11/18/2012 16:35:11;0008;PBS_Server;Job;NULL;on_job_exit valid pjob: 0x13f2680 (substate=50)
11/18/2012 16:35:11;0008;PBS_Server;Job;NULL;on_job_exit valid pjob: 0x13f2680 (substate=51)
11/18/2012 16:35:11;0008;PBS_Server;Job;NULL;on_job_exit valid pjob: 0x13f2680 (substate=51)
11/18/2012 16:35:11;0008;PBS_Server;Job;NULL;on_job_exit valid pjob: 0x13f2680 (substate=53)
11/18/2012 16:35:11;0100;PBS_Server;Job;14109.tyrone-cluster;dequeuing from idqueue, state COMPLETE
11/18/2012 16:35:11;0040;PBS_Server;Svr;tyrone-cluster;Scheduler was sent the command term
11/18/2012 16:35:11;0008;PBS_Server;Job;14111.tyrone-cluster;Job Modified at request of Scheduler@tyrone-cluster
11/18/2012 16:35:11;0008;PBS_Server;Job;14111.tyrone-cluster;Job Run at request of Scheduler@tyrone-cluster
11/18/2012 16:35:12;000d;PBS_Server;Job;14111.tyrone-cluster;Not sending email: User does not want mail of this type.
11/18/2012 16:35:12;0040;PBS_Server;Svr;tyrone-cluster;Scheduler was sent the command recyc
11/18/2012 16:35:43;0040;PBS_Server;Svr;tyrone-cluster;Scheduler was sent the command new
11/18/2012 16:35:43;000d;PBS_Server;Job;14110.tyrone-cluster;Not sending email: User does not want mail of this type.
11/18/2012 16:35:43;0010;PBS_Server;Job;14110.tyrone-cluster;Exit_status=0 resources_used.cput=00:36:11 resources_used.mem=468492kb resources_used.vmem=1582624kb resources_used.walltime=00:09:03
11/18/2012 16:35:43;0008;PBS_Server;Job;NULL;on_job_exit valid pjob: 0x13fedb0 (substate=50)
11/18/2012 16:35:43;0008;PBS_Server;Job;NULL;on_job_exit valid pjob: 0x13fedb0 (substate=51)
11/18/2012 16:35:43;0008;PBS_Server;Job;NULL;on_job_exit valid pjob: 0x13fedb0 (substate=51)
11/18/2012 16:35:43;0008;PBS_Server;Job;NULL;on_job_exit valid pjob: 0x13fedb0 (substate=53)
11/18/2012 16:35:43;0100;PBS_Server;Job;14110.tyrone-cluster;dequeuing from idqueue, state COMPLETE
11/18/2012 16:35:43;0040;PBS_Server;Svr;tyrone-cluster;Scheduler was sent the command term
11/18/2012 16:35:43;0008;PBS_Server;Job;14112.tyrone-cluster;Job Modified at request of Scheduler@tyrone-cluster
11/18/2012 16:35:43;0008;PBS_Server;Job;14112.tyrone-cluster;Job Run at request of Scheduler@tyrone-cluster
11/18/2012 16:35:44;000d;PBS_Server;Job;14112.tyrone-cluster;Not sending email: User does not want mail of this type.
11/18/2012 16:35:44;0040;PBS_Server;Svr;tyrone-cluster;Scheduler was sent the command recyc
11/18/2012 16:36:15;0040;PBS_Server;Svr;tyrone-cluster;Scheduler was sent the command new
11/18/2012 16:36:45;0040;PBS_Server;Svr;tyrone-cluster;Scheduler was sent the command new
11/18/2012 16:37:21;0040;PBS_Server;Svr;tyrone-cluster;Scheduler was sent the command new
11/18/2012 16:37:52;0040;PBS_Server;Svr;tyrone-cluster;Scheduler was sent the command new
11/18/2012 16:38:06;0100;PBS_Server;Job;14128.tyrone-cluster;enqueuing into batch, state 1 hop 1
11/18/2012 16:38:06;0100;PBS_Server;Job;14128.tyrone-cluster;dequeuing from batch, state QUEUED
11/18/2012 16:38:06;0100;PBS_Server;Job;14128.tyrone-cluster;enqueuing into idqueue, state 1 hop 1
11/18/2012 16:38:06;0008;PBS_Server;Job;14128.tyrone-cluster;Job Queued at request of secjagvi@tyrone-cluster, owner = secjagvi@tyrone-cluster, job name = myjob, queue = idqueue
11/18/2012 16:38:06;0040;PBS_Server;Svr;tyrone-cluster;Scheduler was sent the command new
11/18/2012 16:38:06;0008;PBS_Server;Job;14128.tyrone-cluster;Job Modified at request of Scheduler@tyrone-cluster
11/18/2012 16:38:23;0040;PBS_Server;Svr;tyrone-cluster;Scheduler was sent the command new
11/18/2012 16:38:49;0002;PBS_Server;Svr;PBS_Server;Torque Server Version = 3.0.5, loglevel = 0
11/18/2012 16:38:54;0040;PBS_Server;Svr;tyrone-cluster;Scheduler was sent the command new
11/18/2012 16:39:37;0040;PBS_Server;Svr;tyrone-cluster;Scheduler was sent the command new
11/18/2012 16:39:40;0100;PBS_Server;Job;14129.tyrone-cluster;enqueuing into batch, state 1 hop 1
11/18/2012 16:39:40;0100;PBS_Server;Job;14129.tyrone-cluster;dequeuing from batch, state QUEUED
11/18/2012 16:39:40;0100;PBS_Server;Job;14129.tyrone-cluster;enqueuing into idqueue, state 1 hop 1
11/18/2012 16:39:40;0008;PBS_Server;Job;14129.tyrone-cluster;Job Queued at request of secjagvi@tyrone-cluster, owner = secjagvi@tyrone-cluster, job name = myjob, queue = idqueue
11/18/2012 16:39:40;0040;PBS_Server;Svr;tyrone-cluster;Scheduler was sent the command new
11/18/2012 16:39:41;0008;PBS_Server;Job;14129.tyrone-cluster;Job Modified at request of Scheduler@tyrone-cluster
11/18/2012 16:39:53;000d;PBS_Server;Job;14118.tyrone-cluster;Not sending email: User does not want mail of this type.
11/18/2012 16:39:53;0010;PBS_Server;Job;14118.tyrone-cluster;Exit_status=0 resources_used.cput=00:48:13 resources_used.mem=5422580kb resources_used.vmem=10784592kb resources_used.walltime=00:09:07
11/18/2012 16:39:53;0008;PBS_Server;Job;NULL;on_job_exit valid pjob: 0x13416a0 (substate=50)
11/18/2012 16:39:53;0008;PBS_Server;Job;NULL;on_job_exit valid pjob: 0x13416a0 (substate=51)
11/18/2012 16:39:53;0008;PBS_Server;Job;NULL;on_job_exit valid pjob: 0x13416a0 (substate=51)
11/18/2012 16:39:53;0008;PBS_Server;Job;NULL;on_job_exit valid pjob: 0x13416a0 (substate=53)
11/18/2012 16:39:53;0100;PBS_Server;Job;14118.tyrone-cluster;dequeuing from idqueue, state COMPLETE
11/18/2012 16:39:53;0040;PBS_Server;Svr;tyrone-cluster;Scheduler was sent the command term
11/18/2012 16:39:53;0008;PBS_Server;Job;14120.tyrone-cluster;Job Modified at request of Scheduler@tyrone-cluster
11/18/2012 16:39:53;0008;PBS_Server;Job;14120.tyrone-cluster;Job Run at request of Scheduler@tyrone-cluster
11/18/2012 16:39:53;000d;PBS_Server;Job;14120.tyrone-cluster;Not sending email: User does not want mail of this type.
11/18/2012 16:39:53;0040;PBS_Server;Svr;tyrone-cluster;Scheduler was sent the command recyc
11/18/2012 16:39:57;000d;PBS_Server;Job;14119.tyrone-cluster;Not sending email: User does not want mail of this type.
11/18/2012 16:39:57;0010;PBS_Server;Job;14119.tyrone-cluster;Exit_status=0 resources_used.cput=00:48:59 resources_used.mem=5422584kb resources_used.vmem=10784592kb resources_used.walltime=00:09:10
11/18/2012 16:39:57;0008;PBS_Server;Job;NULL;on_job_exit valid pjob: 0x1342960 (substate=50)
11/18/2012 16:39:57;0008;PBS_Server;Job;NULL;on_job_exit valid pjob: 0x1342960 (substate=51)
11/18/2012 16:39:57;0008;PBS_Server;Job;NULL;on_job_exit valid pjob: 0x1342960 (substate=51)
11/18/2012 16:39:57;0008;PBS_Server;Job;NULL;on_job_exit valid pjob: 0x1342960 (substate=53)
11/18/2012 16:39:57;0100;PBS_Server;Job;14119.tyrone-cluster;dequeuing from idqueue, state COMPLETE
11/18/2012 16:39:57;0040;PBS_Server;Svr;tyrone-cluster;Scheduler was sent the command term
11/18/2012 16:39:57;0008;PBS_Server;Job;14121.tyrone-cluster;Job Modified at request of Scheduler@tyrone-cluster
11/18/2012 16:39:57;0008;PBS_Server;Job;14121.tyrone-cluster;Job Run at request of Scheduler@tyrone-cluster
11/18/2012 16:39:57;000d;PBS_Server;Job;14121.tyrone-cluster;Not sending email: User does not want mail of this type.
11/18/2012 16:39:57;0040;PBS_Server;Svr;tyrone-cluster;Scheduler was sent the command recyc
11/18/2012 16:40:07;0040;PBS_Server;Svr;tyrone-cluster;Scheduler was sent the command new
11/18/2012 16:40:37;0040;PBS_Server;Svr;tyrone-cluster;Scheduler was sent the command new
11/18/2012 16:40:51;0100;PBS_Server;Job;14130.tyrone-cluster;enqueuing into batch, state 1 hop 1
11/18/2012 16:40:51;0100;PBS_Server;Job;14130.tyrone-cluster;dequeuing from batch, state QUEUED
11/18/2012 16:40:51;0100;PBS_Server;Job;14130.tyrone-cluster;enqueuing into idqueue, state 1 hop 1
11/18/2012 16:40:51;0008;PBS_Server;Job;14130.tyrone-cluster;Job Queued at request of seckriti@tyrone-cluster, owner = seckriti@tyrone-cluster, job name = myjob, queue = idqueue
11/18/2012 16:40:51;0040;PBS_Server;Svr;tyrone-cluster;Scheduler was sent the command new
11/18/2012 16:40:51;0008;PBS_Server;Job;14130.tyrone-cluster;Job Modified at request of Scheduler@tyrone-cluster
11/18/2012 16:40:55;0100;PBS_Server;Job;14131.tyrone-cluster;enqueuing into batch, state 1 hop 1
11/18/2012 16:40:55;0100;PBS_Server;Job;14131.tyrone-cluster;dequeuing from batch, state QUEUED
11/18/2012 16:40:55;0100;PBS_Server;Job;14131.tyrone-cluster;enqueuing into idqueue, state 1 hop 1
11/18/2012 16:40:55;0008;PBS_Server;Job;14131.tyrone-cluster;Job Queued at request of seckriti@tyrone-cluster, owner = seckriti@tyrone-cluster, job name = myjob, queue = idqueue
11/18/2012 16:40:55;0040;PBS_Server;Svr;tyrone-cluster;Scheduler was sent the command new
11/18/2012 16:40:55;0008;PBS_Server;Job;14131.tyrone-cluster;Job Modified at request of Scheduler@tyrone-cluster
11/18/2012 16:40:59;0100;PBS_Server;Job;14132.tyrone-cluster;enqueuing into batch, state 1 hop 1
11/18/2012 16:40:59;0100;PBS_Server;Job;14132.tyrone-cluster;dequeuing from batch, state QUEUED
11/18/2012 16:40:59;0100;PBS_Server;Job;14132.tyrone-cluster;enqueuing into idqueue, state 1 hop 1
11/18/2012 16:40:59;0008;PBS_Server;Job;14132.tyrone-cluster;Job Queued at request of seckriti@tyrone-cluster, owner = seckriti@tyrone-cluster, job name = myjob, queue = idqueue
11/18/2012 16:40:59;0040;PBS_Server;Svr;tyrone-cluster;Scheduler was sent the command new
11/18/2012 16:40:59;0008;PBS_Server;Job;14132.tyrone-cluster;Job Modified at request of Scheduler@tyrone-cluster
11/18/2012 16:41:07;0040;PBS_Server;Svr;tyrone-cluster;Scheduler was sent the command new
11/18/2012 16:41:37;0040;PBS_Server;Svr;tyrone-cluster;Scheduler was sent the command new
11/18/2012 16:42:08;0040;PBS_Server;Svr;tyrone-cluster;Scheduler was sent the command new
11/18/2012 16:42:37;0040;PBS_Server;Svr;tyrone-cluster;Scheduler was sent the command new
11/18/2012 16:43:07;0040;PBS_Server;Svr;tyrone-cluster;Scheduler was sent the command new
11/18/2012 16:43:38;0040;PBS_Server;Svr;tyrone-cluster;Scheduler was sent the command new
11/18/2012 16:43:49;0002;PBS_Server;Svr;PBS_Server;Torque Server Version = 3.0.5, loglevel = 0
11/18/2012 16:44:09;0040;PBS_Server;Svr;tyrone-cluster;Scheduler was sent the command new
11/18/2012 16:44:36;000d;PBS_Server;Job;14120.tyrone-cluster;Not sending email: User does not want mail of this type.
11/18/2012 16:44:36;0010;PBS_Server;Job;14120.tyrone-cluster;Exit_status=0 resources_used.cput=00:13:29 resources_used.mem=5422584kb resources_used.vmem=10784592kb resources_used.walltime=00:04:43
11/18/2012 16:44:36;0008;PBS_Server;Job;NULL;on_job_exit valid pjob: 0x140a620 (substate=50)
11/18/2012 16:44:36;0008;PBS_Server;Job;NULL;on_job_exit valid pjob: 0x140a620 (substate=51)
11/18/2012 16:44:37;0008;PBS_Server;Job;NULL;on_job_exit valid pjob: 0x140a620 (substate=51)
11/18/2012 16:44:37;0008;PBS_Server;Job;NULL;on_job_exit valid pjob: 0x140a620 (substate=53)
11/18/2012 16:44:37;0100;PBS_Server;Job;14120.tyrone-cluster;dequeuing from idqueue, state COMPLETE
11/18/2012 16:44:37;0040;PBS_Server;Svr;tyrone-cluster;Scheduler was sent the command term
11/18/2012 16:44:37;0008;PBS_Server;Job;14122.tyrone-cluster;Job Modified at request of Scheduler@tyrone-cluster
11/18/2012 16:44:37;0008;PBS_Server;Job;14122.tyrone-cluster;Job Run at request of Scheduler@tyrone-cluster
11/18/2012 16:44:37;000d;PBS_Server;Job;14122.tyrone-cluster;Not sending email: User does not want mail of this type.
11/18/2012 16:44:37;0040;PBS_Server;Svr;tyrone-cluster;Scheduler was sent the command recyc
11/18/2012 16:44:41;0040;PBS_Server;Svr;tyrone-cluster;Scheduler was sent the command new
11/18/2012 16:44:44;000d;PBS_Server;Job;14121.tyrone-cluster;Not sending email: User does not want mail of this type.
11/18/2012 16:44:44;0010;PBS_Server;Job;14121.tyrone-cluster;Exit_status=0 resources_used.cput=00:13:35 resources_used.mem=5422584kb resources_used.vmem=10784592kb resources_used.walltime=00:04:47
11/18/2012 16:44:44;0008;PBS_Server;Job;NULL;on_job_exit valid pjob: 0x1405ac0 (substate=50)
11/18/2012 16:44:44;0008;PBS_Server;Job;NULL;on_job_exit valid pjob: 0x1405ac0 (substate=51)
11/18/2012 16:44:44;0008;PBS_Server;Job;NULL;on_job_exit valid pjob: 0x1405ac0 (substate=51)
11/18/2012 16:44:44;0008;PBS_Server;Job;NULL;on_job_exit valid pjob: 0x1405ac0 (substate=53)
11/18/2012 16:44:44;0100;PBS_Server;Job;14121.tyrone-cluster;dequeuing from idqueue, state COMPLETE
11/18/2012 16:44:44;0040;PBS_Server;Svr;tyrone-cluster;Scheduler was sent the command term
11/18/2012 16:44:44;0008;PBS_Server;Job;14123.tyrone-cluster;Job Modified at request of Scheduler@tyrone-cluster
11/18/2012 16:44:44;0008;PBS_Server;Job;14123.tyrone-cluster;Job Run at request of Scheduler@tyrone-cluster
11/18/2012 16:44:44;000d;PBS_Server;Job;14123.tyrone-cluster;Not sending email: User does not want mail of this type.
11/18/2012 16:44:44;0040;PBS_Server;Svr;tyrone-cluster;Scheduler was sent the command recyc
11/18/2012 16:44:45;000d;PBS_Server;Job;14123.tyrone-cluster;Not sending email: User does not want mail of this type.
11/18/2012 16:44:45;0010;PBS_Server;Job;14123.tyrone-cluster;Exit_status=255 resources_used.cput=00:00:00 resources_used.mem=0kb resources_used.vmem=0kb resources_used.walltime=00:00:01
11/18/2012 16:44:45;0008;PBS_Server;Job;NULL;on_job_exit valid pjob: 0x12f83c0 (substate=50)
11/18/2012 16:44:45;0008;PBS_Server;Job;NULL;on_job_exit valid pjob: 0x12f83c0 (substate=51)
11/18/2012 16:44:45;0008;PBS_Server;Job;NULL;on_job_exit valid pjob: 0x12f83c0 (substate=51)
11/18/2012 16:44:45;0008;PBS_Server;Job;NULL;on_job_exit valid pjob: 0x12f83c0 (substate=53)
11/18/2012 16:44:45;0100;PBS_Server;Job;14123.tyrone-cluster;dequeuing from idqueue, state COMPLETE
11/18/2012 16:44:45;0040;PBS_Server;Svr;tyrone-cluster;Scheduler was sent the command term
11/18/2012 16:44:45;0008;PBS_Server;Job;14124.tyrone-cluster;Job Modified at request of Scheduler@tyrone-cluster
11/18/2012 16:44:45;0008;PBS_Server;Job;14124.tyrone-cluster;Job Run at request of Scheduler@tyrone-cluster
11/18/2012 16:44:45;000d;PBS_Server;Job;14124.tyrone-cluster;Not sending email: User does not want mail of this type.
11/18/2012 16:44:45;0040;PBS_Server;Svr;tyrone-cluster;Scheduler was sent the command recyc
11/18/2012 16:44:46;000d;PBS_Server;Job;14124.tyrone-cluster;Not sending email: User does not want mail of this type.
11/18/2012 16:44:46;0010;PBS_Server;Job;14124.tyrone-cluster;Exit_status=0 resources_used.cput=00:00:03 resources_used.mem=0kb resources_used.vmem=0kb resources_used.walltime=00:00:01
11/18/2012 16:44:46;0008;PBS_Server;Job;NULL;on_job_exit valid pjob: 0x131f740 (substate=50)
11/18/2012 16:44:46;0008;PBS_Server;Job;NULL;on_job_exit valid pjob: 0x131f740 (substate=51)
11/18/2012 16:44:47;0008;PBS_Server;Job;NULL;on_job_exit valid pjob: 0x131f740 (substate=51)
11/18/2012 16:44:47;0008;PBS_Server;Job;NULL;on_job_exit valid pjob: 0x131f740 (substate=53)
11/18/2012 16:44:47;0100;PBS_Server;Job;14124.tyrone-cluster;dequeuing from idqueue, state COMPLETE
11/18/2012 16:44:47;0040;PBS_Server;Svr;tyrone-cluster;Scheduler was sent the command term
11/18/2012 16:44:47;0008;PBS_Server;Job;14125.tyrone-cluster;Job Modified at request of Scheduler@tyrone-cluster
11/18/2012 16:44:47;0008;PBS_Server;Job;14125.tyrone-cluster;Job Run at request of Scheduler@tyrone-cluster
11/18/2012 16:44:47;000d;PBS_Server;Job;14125.tyrone-cluster;Not sending email: User does not want mail of this type.
11/18/2012 16:44:47;0040;PBS_Server;Svr;tyrone-cluster;Scheduler was sent the command recyc
11/18/2012 16:44:49;000d;PBS_Server;Job;14111.tyrone-cluster;Not sending email: User does not want mail of this type.
11/18/2012 16:44:49;0010;PBS_Server;Job;14111.tyrone-cluster;Exit_status=0 resources_used.cput=00:50:31 resources_used.mem=468480kb resources_used.vmem=1582624kb resources_used.walltime=00:09:38
11/18/2012 16:44:49;0008;PBS_Server;Job;NULL;on_job_exit valid pjob: 0x1400070 (substate=50)
11/18/2012 16:44:49;0008;PBS_Server;Job;NULL;on_job_exit valid pjob: 0x1400070 (substate=51)
11/18/2012 16:44:49;0008;PBS_Server;Job;NULL;on_job_exit valid pjob: 0x1400070 (substate=51)
11/18/2012 16:44:49;0008;PBS_Server;Job;NULL;on_job_exit valid pjob: 0x1400070 (substate=53)
11/18/2012 16:44:49;0100;PBS_Server;Job;14111.tyrone-cluster;dequeuing from idqueue, state COMPLETE
11/18/2012 16:44:49;0040;PBS_Server;Svr;tyrone-cluster;Scheduler was sent the command term
11/18/2012 16:44:50;000d;PBS_Server;Job;14125.tyrone-cluster;Not sending email: User does not want mail of this type.
11/18/2012 16:44:50;0010;PBS_Server;Job;14125.tyrone-cluster;Exit_status=0 resources_used.cput=00:00:08 resources_used.mem=34240kb resources_used.vmem=492816kb resources_used.walltime=00:00:03
11/18/2012 16:44:50;0008;PBS_Server;Job;NULL;on_job_exit valid pjob: 0x134e980 (substate=50)
11/18/2012 16:44:50;0008;PBS_Server;Job;NULL;on_job_exit valid pjob: 0x134e980 (substate=51)
11/18/2012 16:44:50;0008;PBS_Server;Job;14113.tyrone-cluster;Job Modified at request of Scheduler@tyrone-cluster
11/18/2012 16:44:50;0008;PBS_Server;Job;14113.tyrone-cluster;Job Run at request of Scheduler@tyrone-cluster
11/18/2012 16:44:50;0008;PBS_Server;Job;NULL;on_job_exit valid pjob: 0x134e980 (substate=51)
11/18/2012 16:44:50;0008;PBS_Server;Job;NULL;on_job_exit valid pjob: 0x134e980 (substate=53)
11/18/2012 16:44:50;0100;PBS_Server;Job;14125.tyrone-cluster;dequeuing from idqueue, state COMPLETE
11/18/2012 16:44:50;0008;PBS_Server;Job;14126.tyrone-cluster;Job Modified at request of Scheduler@tyrone-cluster
11/18/2012 16:44:50;0008;PBS_Server;Job;14126.tyrone-cluster;Job Run at request of Scheduler@tyrone-cluster
11/18/2012 16:44:50;000d;PBS_Server;Job;14113.tyrone-cluster;Not sending email: User does not want mail of this type.
11/18/2012 16:44:50;000d;PBS_Server;Job;14126.tyrone-cluster;Not sending email: User does not want mail of this type.
11/18/2012 16:44:52;000d;PBS_Server;Job;14126.tyrone-cluster;Not sending email: User does not want mail of this type.
11/18/2012 16:44:52;0010;PBS_Server;Job;14126.tyrone-cluster;Exit_status=0 resources_used.cput=00:00:15 resources_used.mem=0kb resources_used.vmem=0kb resources_used.walltime=00:00:02
11/18/2012 16:44:52;0008;PBS_Server;Job;NULL;on_job_exit valid pjob: 0x132ff00 (substate=50)
11/18/2012 16:44:52;0008;PBS_Server;Job;NULL;on_job_exit valid pjob: 0x132ff00 (substate=51)
11/18/2012 16:44:52;0008;PBS_Server;Job;NULL;on_job_exit valid pjob: 0x132ff00 (substate=51)
11/18/2012 16:44:52;0008;PBS_Server;Job;NULL;on_job_exit valid pjob: 0x132ff00 (substate=53)
11/18/2012 16:44:52;0100;PBS_Server;Job;14126.tyrone-cluster;dequeuing from idqueue, state COMPLETE
11/18/2012 16:44:52;0040;PBS_Server;Svr;tyrone-cluster;Scheduler was sent the command term
11/18/2012 16:44:53;0008;PBS_Server;Job;14127.tyrone-cluster;Job Modified at request of Scheduler@tyrone-cluster
11/18/2012 16:44:53;0008;PBS_Server;Job;14127.tyrone-cluster;Job Run at request of Scheduler@tyrone-cluster
11/18/2012 16:44:53;000d;PBS_Server;Job;14127.tyrone-cluster;Not sending email: User does not want mail of this type.
11/18/2012 16:44:53;0040;PBS_Server;Svr;tyrone-cluster;Scheduler was sent the command recyc
11/18/2012 16:44:56;000d;PBS_Server;Job;14127.tyrone-cluster;Not sending email: User does not want mail of this type.
11/18/2012 16:44:56;0010;PBS_Server;Job;14127.tyrone-cluster;Exit_status=0 resources_used.cput=00:00:27 resources_used.mem=0kb resources_used.vmem=0kb resources_used.walltime=00:00:03
11/18/2012 16:44:56;0008;PBS_Server;Job;NULL;on_job_exit valid pjob: 0x12f5dd0 (substate=50)
11/18/2012 16:44:56;0008;PBS_Server;Job;NULL;on_job_exit valid pjob: 0x12f5dd0 (substate=51)
11/18/2012 16:44:56;0008;PBS_Server;Job;NULL;on_job_exit valid pjob: 0x12f5dd0 (substate=51)
11/18/2012 16:44:56;0008;PBS_Server;Job;NULL;on_job_exit valid pjob: 0x12f5dd0 (substate=53)
11/18/2012 16:44:56;0100;PBS_Server;Job;14127.tyrone-cluster;dequeuing from idqueue, state COMPLETE
11/18/2012 16:44:56;0040;PBS_Server;Svr;tyrone-cluster;Scheduler was sent the command term
11/18/2012 16:44:56;0008;PBS_Server;Job;14128.tyrone-cluster;Job Modified at request of Scheduler@tyrone-cluster
11/18/2012 16:44:56;0008;PBS_Server;Job;14128.tyrone-cluster;Job Run at request of Scheduler@tyrone-cluster
11/18/2012 16:44:56;000d;PBS_Server;Job;14128.tyrone-cluster;Not sending email: User does not want mail of this type.
11/18/2012 16:44:56;0040;PBS_Server;Svr;tyrone-cluster;Scheduler was sent the command recyc
11/18/2012 16:44:57;000d;PBS_Server;Job;14128.tyrone-cluster;Not sending email: User does not want mail of this type.
11/18/2012 16:44:57;0010;PBS_Server;Job;14128.tyrone-cluster;Exit_status=255 resources_used.cput=00:00:00 resources_used.mem=0kb resources_used.vmem=0kb resources_used.walltime=00:00:01
11/18/2012 16:44:57;0008;PBS_Server;Job;NULL;on_job_exit valid pjob: 0x13f2680 (substate=50)
11/18/2012 16:44:57;0008;PBS_Server;Job;NULL;on_job_exit valid pjob: 0x13f2680 (substate=51)
11/18/2012 16:44:57;0008;PBS_Server;Job;NULL;on_job_exit valid pjob: 0x13f2680 (substate=51)
11/18/2012 16:44:57;0008;PBS_Server;Job;NULL;on_job_exit valid pjob: 0x13f2680 (substate=53)
11/18/2012 16:44:57;0100;PBS_Server;Job;14128.tyrone-cluster;dequeuing from idqueue, state COMPLETE
11/18/2012 16:44:57;0040;PBS_Server;Svr;tyrone-cluster;Scheduler was sent the command term
11/18/2012 16:44:57;0008;PBS_Server;Job;14129.tyrone-cluster;Job Modified at request of Scheduler@tyrone-cluster
11/18/2012 16:44:57;0008;PBS_Server;Job;14129.tyrone-cluster;Job Run at request of Scheduler@tyrone-cluster
11/18/2012 16:44:57;000d;PBS_Server;Job;14129.tyrone-cluster;Not sending email: User does not want mail of this type.
11/18/2012 16:44:57;0040;PBS_Server;Svr;tyrone-cluster;Scheduler was sent the command recyc
11/18/2012 16:44:58;000d;PBS_Server;Job;14129.tyrone-cluster;Not sending email: User does not want mail of this type.
11/18/2012 16:44:58;0010;PBS_Server;Job;14129.tyrone-cluster;Exit_status=255 resources_used.cput=00:00:00 resources_used.mem=0kb resources_used.vmem=0kb resources_used.walltime=00:00:01
11/18/2012 16:44:58;0008;PBS_Server;Job;NULL;on_job_exit valid pjob: 0x13e5610 (substate=50)
11/18/2012 16:44:58;0008;PBS_Server;Job;NULL;on_job_exit valid pjob: 0x13e5610 (substate=51)
11/18/2012 16:44:58;0008;PBS_Server;Job;NULL;on_job_exit valid pjob: 0x13e5610 (substate=51)
11/18/2012 16:44:58;0008;PBS_Server;Job;NULL;on_job_exit valid pjob: 0x13e5610 (substate=53)
11/18/2012 16:44:58;0100;PBS_Server;Job;14129.tyrone-cluster;dequeuing from idqueue, state COMPLETE
11/18/2012 16:44:58;0040;PBS_Server;Svr;tyrone-cluster;Scheduler was sent the command term
11/18/2012 16:44:58;0008;PBS_Server;Job;14130.tyrone-cluster;Job Modified at request of Scheduler@tyrone-cluster
11/18/2012 16:44:58;0008;PBS_Server;Job;14130.tyrone-cluster;Job Run at request of Scheduler@tyrone-cluster
11/18/2012 16:44:58;0040;PBS_Server;Svr;tyrone-cluster;Scheduler was sent the command recyc
11/18/2012 16:44:58;000d;PBS_Server;Job;14130.tyrone-cluster;Not sending email: User does not want mail of this type.
11/18/2012 16:45:02;000d;PBS_Server;Job;14112.tyrone-cluster;Not sending email: User does not want mail of this type.
11/18/2012 16:45:02;0010;PBS_Server;Job;14112.tyrone-cluster;Exit_status=0 resources_used.cput=00:46:17 resources_used.mem=468512kb resources_used.vmem=1582624kb resources_used.walltime=00:09:18
11/18/2012 16:45:02;0008;PBS_Server;Job;NULL;on_job_exit valid pjob: 0x1401330 (substate=50)
11/18/2012 16:45:02;0008;PBS_Server;Job;NULL;on_job_exit valid pjob: 0x1401330 (substate=51)
11/18/2012 16:45:02;0008;PBS_Server;Job;NULL;on_job_exit valid pjob: 0x1401330 (substate=51)
11/18/2012 16:45:02;0008;PBS_Server;Job;NULL;on_job_exit valid pjob: 0x1401330 (substate=53)
11/18/2012 16:45:02;0100;PBS_Server;Job;14112.tyrone-cluster;dequeuing from idqueue, state COMPLETE
11/18/2012 16:45:02;0040;PBS_Server;Svr;tyrone-cluster;Scheduler was sent the command term
11/18/2012 16:45:02;0008;PBS_Server;Job;14131.tyrone-cluster;Job Modified at request of Scheduler@tyrone-cluster
11/18/2012 16:45:02;0008;PBS_Server;Job;14131.tyrone-cluster;Job Run at request of Scheduler@tyrone-cluster
11/18/2012 16:45:02;0008;PBS_Server;Job;14132.tyrone-cluster;Job Modified at request of Scheduler@tyrone-cluster
11/18/2012 16:45:02;0040;PBS_Server;Svr;tyrone-cluster;Scheduler was sent the command recyc
11/18/2012 16:45:02;000d;PBS_Server;Job;14131.tyrone-cluster;Not sending email: User does not want mail of this type.
11/18/2012 16:45:11;0040;PBS_Server;Svr;tyrone-cluster;Scheduler was sent the command new
11/18/2012 16:45:28;000d;PBS_Server;Job;14130.tyrone-cluster;Not sending email: User does not want mail of this type.
11/18/2012 16:45:28;0010;PBS_Server;Job;14130.tyrone-cluster;Exit_status=0 resources_used.cput=00:01:57 resources_used.mem=84516kb resources_used.vmem=543040kb resources_used.walltime=00:00:30
11/18/2012 16:45:28;0008;PBS_Server;Job;NULL;on_job_exit valid pjob: 0x1314c50 (substate=50)
11/18/2012 16:45:28;0008;PBS_Server;Job;NULL;on_job_exit valid pjob: 0x1314c50 (substate=51)
11/18/2012 16:45:28;0008;PBS_Server;Job;NULL;on_job_exit valid pjob: 0x1314c50 (substate=51)
11/18/2012 16:45:28;0008;PBS_Server;Job;NULL;on_job_exit valid pjob: 0x1314c50 (substate=53)
11/18/2012 16:45:28;0100;PBS_Server;Job;14130.tyrone-cluster;dequeuing from idqueue, state COMPLETE
11/18/2012 16:45:28;0040;PBS_Server;Svr;tyrone-cluster;Scheduler was sent the command term
11/18/2012 16:45:29;0008;PBS_Server;Job;14132.tyrone-cluster;Job Modified at request of Scheduler@tyrone-cluster
11/18/2012 16:45:29;0008;PBS_Server;Job;14132.tyrone-cluster;Job Run at request of Scheduler@tyrone-cluster
11/18/2012 16:45:29;0040;PBS_Server;Svr;tyrone-cluster;Scheduler was sent the command recyc
11/18/2012 16:45:29;000d;PBS_Server;Job;14132.tyrone-cluster;Not sending email: User does not want mail of this type.
11/18/2012 16:45:37;000d;PBS_Server;Job;14131.tyrone-cluster;Not sending email: User does not want mail of this type.
11/18/2012 16:45:37;0010;PBS_Server;Job;14131.tyrone-cluster;Exit_status=0 resources_used.cput=00:04:16 resources_used.mem=143156kb resources_used.vmem=868864kb resources_used.walltime=00:00:35
11/18/2012 16:45:37;0008;PBS_Server;Job;NULL;on_job_exit valid pjob: 0x1408040 (substate=50)
11/18/2012 16:45:37;0008;PBS_Server;Job;NULL;on_job_exit valid pjob: 0x1408040 (substate=51)
11/18/2012 16:45:38;0008;PBS_Server;Job;NULL;on_job_exit valid pjob: 0x1408040 (substate=51)
11/18/2012 16:45:38;0008;PBS_Server;Job;NULL;on_job_exit valid pjob: 0x1408040 (substate=53)
11/18/2012 16:45:38;0100;PBS_Server;Job;14131.tyrone-cluster;dequeuing from idqueue, state COMPLETE
11/18/2012 16:45:38;0040;PBS_Server;Svr;tyrone-cluster;Scheduler was sent the command term
11/18/2012 16:45:41;0040;PBS_Server;Svr;tyrone-cluster;Scheduler was sent the command new
11/18/2012 16:46:00;000d;PBS_Server;Job;14132.tyrone-cluster;Not sending email: User does not want mail of this type.
11/18/2012 16:46:00;0010;PBS_Server;Job;14132.tyrone-cluster;Exit_status=0 resources_used.cput=00:06:02 resources_used.mem=202732kb resources_used.vmem=1317932kb resources_used.walltime=00:00:31
11/18/2012 16:46:00;0008;PBS_Server;Job;NULL;on_job_exit valid pjob: 0x1409300 (substate=50)
11/18/2012 16:46:00;0008;PBS_Server;Job;NULL;on_job_exit valid pjob: 0x1409300 (substate=51)
11/18/2012 16:46:00;0008;PBS_Server;Job;NULL;on_job_exit valid pjob: 0x1409300 (substate=51)
11/18/2012 16:46:00;0008;PBS_Server;Job;NULL;on_job_exit valid pjob: 0x1409300 (substate=53)
11/18/2012 16:46:00;0100;PBS_Server;Job;14132.tyrone-cluster;dequeuing from idqueue, state COMPLETE
11/18/2012 16:46:00;0040;PBS_Server;Svr;tyrone-cluster;Scheduler was sent the command term
11/18/2012 16:46:13;0040;PBS_Server;Svr;tyrone-cluster;Scheduler was sent the command new
11/18/2012 16:46:46;0040;PBS_Server;Svr;tyrone-cluster;Scheduler was sent the command new
11/18/2012 16:47:15;0040;PBS_Server;Svr;tyrone-cluster;Scheduler was sent the command new
11/18/2012 16:47:52;0040;PBS_Server;Svr;tyrone-cluster;Scheduler was sent the command new
11/18/2012 16:48:22;0040;PBS_Server;Svr;tyrone-cluster;Scheduler was sent the command new
11/18/2012 16:48:49;0002;PBS_Server;Svr;PBS_Server;Torque Server Version = 3.0.5, loglevel = 0
11/18/2012 16:48:53;0040;PBS_Server;Svr;tyrone-cluster;Scheduler was sent the command new
11/18/2012 16:49:20;000d;PBS_Server;Job;14122.tyrone-cluster;Not sending email: User does not want mail of this type.
11/18/2012 16:49:20;0010;PBS_Server;Job;14122.tyrone-cluster;Exit_status=0 resources_used.cput=00:13:32 resources_used.mem=3748292kb resources_used.vmem=7170860kb resources_used.walltime=00:04:43
11/18/2012 16:49:20;0008;PBS_Server;Job;NULL;on_job_exit valid pjob: 0x1406d80 (substate=50)
11/18/2012 16:49:20;0008;PBS_Server;Job;NULL;on_job_exit valid pjob: 0x1406d80 (substate=51)
11/18/2012 16:49:20;0008;PBS_Server;Job;NULL;on_job_exit valid pjob: 0x1406d80 (substate=51)
11/18/2012 16:49:20;0008;PBS_Server;Job;NULL;on_job_exit valid pjob: 0x1406d80 (substate=53)
11/18/2012 16:49:20;0100;PBS_Server;Job;14122.tyrone-cluster;dequeuing from idqueue, state COMPLETE
11/18/2012 16:49:20;0040;PBS_Server;Svr;tyrone-cluster;Scheduler was sent the command term
11/18/2012 16:49:22;0040;PBS_Server;Svr;tyrone-cluster;Scheduler was sent the command new
11/18/2012 16:49:52;0040;PBS_Server;Svr;tyrone-cluster;Scheduler was sent the command new
11/18/2012 16:50:03;000d;PBS_Server;Job;14113.tyrone-cluster;Not sending email: User does not want mail of this type.
11/18/2012 16:50:03;0010;PBS_Server;Job;14113.tyrone-cluster;Exit_status=0 resources_used.cput=00:14:47 resources_used.mem=468476kb resources_used.vmem=1582624kb resources_used.walltime=00:05:13
11/18/2012 16:50:03;0008;PBS_Server;Job;NULL;on_job_exit valid pjob: 0x14025f0 (substate=50)
11/18/2012 16:50:03;0008;PBS_Server;Job;NULL;on_job_exit valid pjob: 0x14025f0 (substate=51)
11/18/2012 16:50:04;0008;PBS_Server;Job;NULL;on_job_exit valid pjob: 0x14025f0 (substate=51)
11/18/2012 16:50:04;0008;PBS_Server;Job;NULL;on_job_exit valid pjob: 0x14025f0 (substate=53)
11/18/2012 16:50:04;0100;PBS_Server;Job;14113.tyrone-cluster;dequeuing from idqueue, state COMPLETE
11/18/2012 16:50:04;0040;PBS_Server;Svr;tyrone-cluster;Scheduler was sent the command term
11/18/2012 16:50:17;0100;PBS_Server;Job;14133.tyrone-cluster;enqueuing into batch, state 1 hop 1
11/18/2012 16:50:17;0100;PBS_Server;Job;14133.tyrone-cluster;dequeuing from batch, state QUEUED
11/18/2012 16:50:17;0100;PBS_Server;Job;14133.tyrone-cluster;enqueuing into idqueue, state 1 hop 1
11/18/2012 16:50:17;0008;PBS_Server;Job;14133.tyrone-cluster;Job Queued at request of seckriti@tyrone-cluster, owner = seckriti@tyrone-cluster, job name = myjob, queue = idqueue
11/18/2012 16:50:17;0040;PBS_Server;Svr;tyrone-cluster;Scheduler was sent the command new
11/18/2012 16:50:17;0008;PBS_Server;Job;14133.tyrone-cluster;Job Modified at request of Scheduler@tyrone-cluster
11/18/2012 16:50:17;0008;PBS_Server;Job;14133.tyrone-cluster;Job Run at request of Scheduler@tyrone-cluster
11/18/2012 16:50:17;0040;PBS_Server;Svr;tyrone-cluster;Scheduler was sent the command recyc
11/18/2012 16:50:17;000d;PBS_Server;Job;14133.tyrone-cluster;Not sending email: User does not want mail of this type.
11/18/2012 16:50:23;0040;PBS_Server;Svr;tyrone-cluster;Scheduler was sent the command new
11/18/2012 16:50:23;0100;PBS_Server;Job;14134.tyrone-cluster;enqueuing into batch, state 1 hop 1
11/18/2012 16:50:23;0100;PBS_Server;Job;14134.tyrone-cluster;dequeuing from batch, state QUEUED
11/18/2012 16:50:23;0100;PBS_Server;Job;14134.tyrone-cluster;enqueuing into idqueue, state 1 hop 1
11/18/2012 16:50:23;0008;PBS_Server;Job;14134.tyrone-cluster;Job Queued at request of seckriti@tyrone-cluster, owner = seckriti@tyrone-cluster, job name = myjob, queue = idqueue
11/18/2012 16:50:23;0008;PBS_Server;Job;14134.tyrone-cluster;Job Modified at request of Scheduler@tyrone-cluster
11/18/2012 16:50:23;0008;PBS_Server;Job;14134.tyrone-cluster;Job Run at request of Scheduler@tyrone-cluster
11/18/2012 16:50:23;0040;PBS_Server;Svr;tyrone-cluster;Scheduler was sent the command recyc
11/18/2012 16:50:23;000d;PBS_Server;Job;14134.tyrone-cluster;Not sending email: User does not want mail of this type.
11/18/2012 16:50:26;0100;PBS_Server;Job;14135.tyrone-cluster;enqueuing into batch, state 1 hop 1
11/18/2012 16:50:26;0100;PBS_Server;Job;14135.tyrone-cluster;dequeuing from batch, state QUEUED
11/18/2012 16:50:26;0100;PBS_Server;Job;14135.tyrone-cluster;enqueuing into idqueue, state 1 hop 1
11/18/2012 16:50:26;0008;PBS_Server;Job;14135.tyrone-cluster;Job Queued at request of seckriti@tyrone-cluster, owner = seckriti@tyrone-cluster, job name = myjob, queue = idqueue
11/18/2012 16:50:26;0040;PBS_Server;Svr;tyrone-cluster;Scheduler was sent the command new
11/18/2012 16:50:26;0008;PBS_Server;Job;14135.tyrone-cluster;Job Modified at request of Scheduler@tyrone-cluster
11/18/2012 16:50:47;0100;PBS_Server;Job;14136.tyrone-cluster;enqueuing into batch, state 1 hop 1
11/18/2012 16:50:47;0100;PBS_Server;Job;14136.tyrone-cluster;dequeuing from batch, state QUEUED
11/18/2012 16:50:47;0100;PBS_Server;Job;14136.tyrone-cluster;enqueuing into idqueue, state 1 hop 1
11/18/2012 16:50:47;0008;PBS_Server;Job;14136.tyrone-cluster;Job Queued at request of secvkm@tyrone-cluster, owner = secvkm@tyrone-cluster, job name = myjob, queue = idqueue
11/18/2012 16:50:47;0040;PBS_Server;Svr;tyrone-cluster;Scheduler was sent the command new
11/18/2012 16:50:47;0008;PBS_Server;Job;14136.tyrone-cluster;Job Modified at request of Scheduler@tyrone-cluster
11/18/2012 16:50:47;0008;PBS_Server;Job;14136.tyrone-cluster;Job Run at request of Scheduler@tyrone-cluster
11/18/2012 16:50:47;0040;PBS_Server;Svr;tyrone-cluster;Scheduler was sent the command recyc
11/18/2012 16:50:47;000d;PBS_Server;Job;14136.tyrone-cluster;Not sending email: User does not want mail of this type.
11/18/2012 16:50:48;0100;PBS_Server;Job;14137.tyrone-cluster;enqueuing into batch, state 1 hop 1
11/18/2012 16:50:48;0100;PBS_Server;Job;14137.tyrone-cluster;dequeuing from batch, state QUEUED
11/18/2012 16:50:48;0100;PBS_Server;Job;14137.tyrone-cluster;enqueuing into idqueue, state 1 hop 1
11/18/2012 16:50:48;0008;PBS_Server;Job;14137.tyrone-cluster;Job Queued at request of secvkm@tyrone-cluster, owner = secvkm@tyrone-cluster, job name = myjob, queue = idqueue
11/18/2012 16:50:48;0040;PBS_Server;Svr;tyrone-cluster;Scheduler was sent the command new
11/18/2012 16:50:48;0008;PBS_Server;Job;14137.tyrone-cluster;Job Modified at request of Scheduler@tyrone-cluster
11/18/2012 16:50:48;0008;PBS_Server;Job;14137.tyrone-cluster;Job Run at request of Scheduler@tyrone-cluster
11/18/2012 16:50:48;0040;PBS_Server;Svr;tyrone-cluster;Scheduler was sent the command recyc
11/18/2012 16:50:48;000d;PBS_Server;Job;14137.tyrone-cluster;Not sending email: User does not want mail of this type.
11/18/2012 16:50:52;0040;PBS_Server;Svr;tyrone-cluster;Scheduler was sent the command new
11/18/2012 16:51:10;0100;PBS_Server;Job;14138.tyrone-cluster;enqueuing into batch, state 1 hop 1
11/18/2012 16:51:11;0100;PBS_Server;Job;14138.tyrone-cluster;dequeuing from batch, state QUEUED
11/18/2012 16:51:11;0100;PBS_Server;Job;14138.tyrone-cluster;enqueuing into idqueue, state 1 hop 1
11/18/2012 16:51:11;0008;PBS_Server;Job;14138.tyrone-cluster;Job Queued at request of secjagvi@tyrone-cluster, owner = secjagvi@tyrone-cluster, job name = myjob, queue = idqueue
11/18/2012 16:51:11;0040;PBS_Server;Svr;tyrone-cluster;Scheduler was sent the command new
11/18/2012 16:51:11;0008;PBS_Server;Job;14138.tyrone-cluster;Job Modified at request of Scheduler@tyrone-cluster
11/18/2012 16:51:22;0040;PBS_Server;Svr;tyrone-cluster;Scheduler was sent the command new
11/18/2012 16:51:33;000d;PBS_Server;Job;14134.tyrone-cluster;Not sending email: User does not want mail of this type.
11/18/2012 16:51:33;0010;PBS_Server;Job;14134.tyrone-cluster;Exit_status=0 resources_used.cput=00:09:14 resources_used.mem=503372kb resources_used.vmem=1229088kb resources_used.walltime=00:01:10
11/18/2012 16:51:33;0008;PBS_Server;Job;NULL;on_job_exit valid pjob: 0x131f740 (substate=50)
11/18/2012 16:51:33;0008;PBS_Server;Job;NULL;on_job_exit valid pjob: 0x131f740 (substate=51)
11/18/2012 16:51:33;0008;PBS_Server;Job;NULL;on_job_exit valid pjob: 0x131f740 (substate=51)
11/18/2012 16:51:33;0008;PBS_Server;Job;NULL;on_job_exit valid pjob: 0x131f740 (substate=53)
11/18/2012 16:51:33;0100;PBS_Server;Job;14134.tyrone-cluster;dequeuing from idqueue, state COMPLETE
11/18/2012 16:51:33;0040;PBS_Server;Svr;tyrone-cluster;Scheduler was sent the command term
11/18/2012 16:51:33;0008;PBS_Server;Job;14135.tyrone-cluster;Job Modified at request of Scheduler@tyrone-cluster
11/18/2012 16:51:33;0008;PBS_Server;Job;14135.tyrone-cluster;Job Run at request of Scheduler@tyrone-cluster
11/18/2012 16:51:34;0040;PBS_Server;Svr;tyrone-cluster;Scheduler was sent the command recyc
11/18/2012 16:51:34;000d;PBS_Server;Job;14135.tyrone-cluster;Not sending email: User does not want mail of this type.
11/18/2012 16:51:53;0040;PBS_Server;Svr;tyrone-cluster;Scheduler was sent the command new
11/18/2012 16:51:58;000d;PBS_Server;Job;14133.tyrone-cluster;Not sending email: User does not want mail of this type.
11/18/2012 16:51:58;0010;PBS_Server;Job;14133.tyrone-cluster;Exit_status=0 resources_used.cput=00:06:38 resources_used.mem=445836kb resources_used.vmem=904364kb resources_used.walltime=00:01:41
11/18/2012 16:51:58;0008;PBS_Server;Job;NULL;on_job_exit valid pjob: 0x12f83c0 (substate=50)
11/18/2012 16:51:58;0008;PBS_Server;Job;NULL;on_job_exit valid pjob: 0x12f83c0 (substate=51)
11/18/2012 16:51:58;0008;PBS_Server;Job;NULL;on_job_exit valid pjob: 0x12f83c0 (substate=51)
11/18/2012 16:51:58;0008;PBS_Server;Job;NULL;on_job_exit valid pjob: 0x12f83c0 (substate=53)
11/18/2012 16:51:58;0100;PBS_Server;Job;14133.tyrone-cluster;dequeuing from idqueue, state COMPLETE
11/18/2012 16:51:58;0040;PBS_Server;Svr;tyrone-cluster;Scheduler was sent the command term
11/18/2012 16:51:58;0008;PBS_Server;Job;14138.tyrone-cluster;Job Modified at request of Scheduler@tyrone-cluster
11/18/2012 16:51:58;0008;PBS_Server;Job;14138.tyrone-cluster;Job Run at request of Scheduler@tyrone-cluster
11/18/2012 16:51:58;0040;PBS_Server;Svr;tyrone-cluster;Scheduler was sent the command recyc
11/18/2012 16:51:58;000d;PBS_Server;Job;14138.tyrone-cluster;Not sending email: User does not want mail of this type.
11/18/2012 16:52:01;000d;PBS_Server;Job;14138.tyrone-cluster;Not sending email: User does not want mail of this type.
11/18/2012 16:52:01;0010;PBS_Server;Job;14138.tyrone-cluster;Exit_status=255 resources_used.cput=00:00:00 resources_used.mem=0kb resources_used.vmem=0kb resources_used.walltime=00:00:03
11/18/2012 16:52:01;0008;PBS_Server;Job;NULL;on_job_exit valid pjob: 0x1314c50 (substate=50)
11/18/2012 16:52:01;0008;PBS_Server;Job;NULL;on_job_exit valid pjob: 0x1314c50 (substate=51)
11/18/2012 16:52:01;0008;PBS_Server;Job;NULL;on_job_exit valid pjob: 0x1314c50 (substate=51)
11/18/2012 16:52:01;0008;PBS_Server;Job;NULL;on_job_exit valid pjob: 0x1314c50 (substate=53)
11/18/2012 16:52:01;0100;PBS_Server;Job;14138.tyrone-cluster;dequeuing from idqueue, state COMPLETE
11/18/2012 16:52:01;0040;PBS_Server;Svr;tyrone-cluster;Scheduler was sent the command term
11/18/2012 16:52:22;0040;PBS_Server;Svr;tyrone-cluster;Scheduler was sent the command new
11/18/2012 16:52:30;000d;PBS_Server;Job;14135.tyrone-cluster;Not sending email: User does not want mail of this type.
11/18/2012 16:52:30;0010;PBS_Server;Job;14135.tyrone-cluster;Exit_status=0 resources_used.cput=00:11:14 resources_used.mem=560700kb resources_used.vmem=1675924kb resources_used.walltime=00:00:57
11/18/2012 16:52:30;0008;PBS_Server;Job;NULL;on_job_exit valid pjob: 0x134e980 (substate=50)
11/18/2012 16:52:30;0008;PBS_Server;Job;NULL;on_job_exit valid pjob: 0x134e980 (substate=51)
11/18/2012 16:52:31;0008;PBS_Server;Job;NULL;on_job_exit valid pjob: 0x134e980 (substate=51)
11/18/2012 16:52:31;0008;PBS_Server;Job;NULL;on_job_exit valid pjob: 0x134e980 (substate=53)
11/18/2012 16:52:31;0100;PBS_Server;Job;14135.tyrone-cluster;dequeuing from idqueue, state COMPLETE
11/18/2012 16:52:31;0040;PBS_Server;Svr;tyrone-cluster;Scheduler was sent the command term
11/18/2012 16:52:52;0040;PBS_Server;Svr;tyrone-cluster;Scheduler was sent the command new
11/18/2012 16:53:23;0040;PBS_Server;Svr;tyrone-cluster;Scheduler was sent the command new
11/18/2012 16:53:49;0002;PBS_Server;Svr;PBS_Server;Torque Server Version = 3.0.5, loglevel = 0
11/18/2012 16:53:54;0040;PBS_Server;Svr;tyrone-cluster;Scheduler was sent the command new
11/18/2012 16:54:37;0040;PBS_Server;Svr;tyrone-cluster;Scheduler was sent the command new
11/18/2012 16:54:39;0100;PBS_Server;Job;14139.tyrone-cluster;enqueuing into batch, state 1 hop 1
11/18/2012 16:54:39;0100;PBS_Server;Job;14139.tyrone-cluster;dequeuing from batch, state QUEUED
11/18/2012 16:54:39;0100;PBS_Server;Job;14139.tyrone-cluster;enqueuing into idqueue, state 1 hop 1
11/18/2012 16:54:39;0008;PBS_Server;Job;14139.tyrone-cluster;Job Queued at request of secvkm@tyrone-cluster, owner = secvkm@tyrone-cluster, job name = myjob, queue = idqueue
11/18/2012 16:54:39;0040;PBS_Server;Svr;tyrone-cluster;Scheduler was sent the command new
11/18/2012 16:54:39;0008;PBS_Server;Job;14139.tyrone-cluster;Job Modified at request of Scheduler@tyrone-cluster
11/18/2012 16:54:54;0100;PBS_Server;Job;14140.tyrone-cluster;enqueuing into batch, state 1 hop 1
11/18/2012 16:54:54;0100;PBS_Server;Job;14140.tyrone-cluster;dequeuing from batch, state QUEUED
11/18/2012 16:54:54;0100;PBS_Server;Job;14140.tyrone-cluster;enqueuing into idqueue, state 1 hop 1
11/18/2012 16:54:54;0008;PBS_Server;Job;14140.tyrone-cluster;Job Queued at request of secadach@tyrone-cluster, owner = secadach@tyrone-cluster, job name = myjob, queue = idqueue
11/18/2012 16:54:54;0040;PBS_Server;Svr;tyrone-cluster;Scheduler was sent the command new
11/18/2012 16:54:54;0008;PBS_Server;Job;14140.tyrone-cluster;Job Modified at request of Scheduler@tyrone-cluster
11/18/2012 16:54:54;0008;PBS_Server;Job;14140.tyrone-cluster;Job Run at request of Scheduler@tyrone-cluster
11/18/2012 16:54:54;0040;PBS_Server;Svr;tyrone-cluster;Scheduler was sent the command recyc
11/18/2012 16:54:54;000d;PBS_Server;Job;14140.tyrone-cluster;Not sending email: User does not want mail of this type.
11/18/2012 16:55:07;0040;PBS_Server;Svr;tyrone-cluster;Scheduler was sent the command new
11/18/2012 16:55:24;0100;PBS_Server;Job;14141.tyrone-cluster;enqueuing into batch, state 1 hop 1
11/18/2012 16:55:25;0100;PBS_Server;Job;14141.tyrone-cluster;dequeuing from batch, state QUEUED
11/18/2012 16:55:25;0100;PBS_Server;Job;14141.tyrone-cluster;enqueuing into idqueue, state 1 hop 1
11/18/2012 16:55:25;0008;PBS_Server;Job;14141.tyrone-cluster;Job Queued at request of secadach@tyrone-cluster, owner = secadach@tyrone-cluster, job name = myjob, queue = idqueue
11/18/2012 16:55:25;0040;PBS_Server;Svr;tyrone-cluster;Scheduler was sent the command new
11/18/2012 16:55:25;0008;PBS_Server;Job;14141.tyrone-cluster;Job Modified at request of Scheduler@tyrone-cluster
11/18/2012 16:55:25;0008;PBS_Server;Job;14141.tyrone-cluster;Job Run at request of Scheduler@tyrone-cluster
11/18/2012 16:55:25;0040;PBS_Server;Svr;tyrone-cluster;Scheduler was sent the command recyc
11/18/2012 16:55:25;000d;PBS_Server;Job;14141.tyrone-cluster;Not sending email: User does not want mail of this type.
11/18/2012 16:55:26;0100;PBS_Server;Job;14142.tyrone-cluster;enqueuing into batch, state 1 hop 1
11/18/2012 16:55:26;0100;PBS_Server;Job;14142.tyrone-cluster;dequeuing from batch, state QUEUED
11/18/2012 16:55:26;0100;PBS_Server;Job;14142.tyrone-cluster;enqueuing into idqueue, state 1 hop 1
11/18/2012 16:55:26;0008;PBS_Server;Job;14142.tyrone-cluster;Job Queued at request of seckriti@tyrone-cluster, owner = seckriti@tyrone-cluster, job name = myjob, queue = idqueue
11/18/2012 16:55:26;0040;PBS_Server;Svr;tyrone-cluster;Scheduler was sent the command new
11/18/2012 16:55:27;0008;PBS_Server;Job;14142.tyrone-cluster;Job Modified at request of Scheduler@tyrone-cluster
11/18/2012 16:55:29;0100;PBS_Server;Job;14143.tyrone-cluster;enqueuing into batch, state 1 hop 1
11/18/2012 16:55:29;0100;PBS_Server;Job;14143.tyrone-cluster;dequeuing from batch, state QUEUED
11/18/2012 16:55:29;0100;PBS_Server;Job;14143.tyrone-cluster;enqueuing into idqueue, state 1 hop 1
11/18/2012 16:55:29;0008;PBS_Server;Job;14143.tyrone-cluster;Job Queued at request of secadach@tyrone-cluster, owner = secadach@tyrone-cluster, job name = myjob, queue = idqueue
11/18/2012 16:55:29;0040;PBS_Server;Svr;tyrone-cluster;Scheduler was sent the command new
11/18/2012 16:55:29;0008;PBS_Server;Job;14143.tyrone-cluster;Job Modified at request of Scheduler@tyrone-cluster
11/18/2012 16:55:30;0100;PBS_Server;Job;14144.tyrone-cluster;enqueuing into batch, state 1 hop 1
11/18/2012 16:55:30;0100;PBS_Server;Job;14144.tyrone-cluster;dequeuing from batch, state QUEUED
11/18/2012 16:55:30;0100;PBS_Server;Job;14144.tyrone-cluster;enqueuing into idqueue, state 1 hop 1
11/18/2012 16:55:30;0008;PBS_Server;Job;14144.tyrone-cluster;Job Queued at request of seckriti@tyrone-cluster, owner = seckriti@tyrone-cluster, job name = myjob, queue = idqueue
11/18/2012 16:55:30;0040;PBS_Server;Svr;tyrone-cluster;Scheduler was sent the command new
11/18/2012 16:55:30;0008;PBS_Server;Job;14144.tyrone-cluster;Job Modified at request of Scheduler@tyrone-cluster
11/18/2012 16:55:30;0100;PBS_Server;Job;14145.tyrone-cluster;enqueuing into batch, state 1 hop 1
11/18/2012 16:55:30;0100;PBS_Server;Job;14145.tyrone-cluster;dequeuing from batch, state QUEUED
11/18/2012 16:55:30;0100;PBS_Server;Job;14145.tyrone-cluster;enqueuing into idqueue, state 1 hop 1
11/18/2012 16:55:30;0008;PBS_Server;Job;14145.tyrone-cluster;Job Queued at request of secadach@tyrone-cluster, owner = secadach@tyrone-cluster, job name = myjob, queue = idqueue
11/18/2012 16:55:30;0040;PBS_Server;Svr;tyrone-cluster;Scheduler was sent the command new
11/18/2012 16:55:30;0008;PBS_Server;Job;14145.tyrone-cluster;Job Modified at request of Scheduler@tyrone-cluster
11/18/2012 16:55:32;0100;PBS_Server;Job;14146.tyrone-cluster;enqueuing into batch, state 1 hop 1
11/18/2012 16:55:32;0100;PBS_Server;Job;14146.tyrone-cluster;dequeuing from batch, state QUEUED
11/18/2012 16:55:32;0100;PBS_Server;Job;14146.tyrone-cluster;enqueuing into idqueue, state 1 hop 1
11/18/2012 16:55:32;0008;PBS_Server;Job;14146.tyrone-cluster;Job Queued at request of seckriti@tyrone-cluster, owner = seckriti@tyrone-cluster, job name = myjob, queue = idqueue
11/18/2012 16:55:32;0040;PBS_Server;Svr;tyrone-cluster;Scheduler was sent the command new
11/18/2012 16:55:32;0008;PBS_Server;Job;14146.tyrone-cluster;Job Modified at request of Scheduler@tyrone-cluster
11/18/2012 16:55:33;0100;PBS_Server;Job;14147.tyrone-cluster;enqueuing into batch, state 1 hop 1
11/18/2012 16:55:33;0100;PBS_Server;Job;14147.tyrone-cluster;dequeuing from batch, state QUEUED
11/18/2012 16:55:33;0100;PBS_Server;Job;14147.tyrone-cluster;enqueuing into idqueue, state 1 hop 1
11/18/2012 16:55:33;0008;PBS_Server;Job;14147.tyrone-cluster;Job Queued at request of secadach@tyrone-cluster, owner = secadach@tyrone-cluster, job name = myjob, queue = idqueue
11/18/2012 16:55:33;0040;PBS_Server;Svr;tyrone-cluster;Scheduler was sent the command new
11/18/2012 16:55:34;0008;PBS_Server;Job;14147.tyrone-cluster;Job Modified at request of Scheduler@tyrone-cluster
11/18/2012 16:55:37;0040;PBS_Server;Svr;tyrone-cluster;Scheduler was sent the command new
11/18/2012 16:56:07;0040;PBS_Server;Svr;tyrone-cluster;Scheduler was sent the command new
11/18/2012 16:56:26;0100;PBS_Server;Job;14148.tyrone-cluster;enqueuing into batch, state 1 hop 1
11/18/2012 16:56:26;0100;PBS_Server;Job;14148.tyrone-cluster;dequeuing from batch, state QUEUED
11/18/2012 16:56:26;0100;PBS_Server;Job;14148.tyrone-cluster;enqueuing into idqueue, state 1 hop 1
11/18/2012 16:56:26;0008;PBS_Server;Job;14148.tyrone-cluster;Job Queued at request of secjagvi@tyrone-cluster, owner = secjagvi@tyrone-cluster, job name = myjob, queue = idqueue
11/18/2012 16:56:26;0040;PBS_Server;Svr;tyrone-cluster;Scheduler was sent the command new
11/18/2012 16:56:27;0008;PBS_Server;Job;14148.tyrone-cluster;Job Modified at request of Scheduler@tyrone-cluster
11/18/2012 16:56:37;0040;PBS_Server;Svr;tyrone-cluster;Scheduler was sent the command new
11/18/2012 16:56:48;000d;PBS_Server;Job;14136.tyrone-cluster;Not sending email: User does not want mail of this type.
11/18/2012 16:56:48;0010;PBS_Server;Job;14136.tyrone-cluster;Exit_status=0 resources_used.cput=00:24:59 resources_used.mem=5422576kb resources_used.vmem=10784592kb resources_used.walltime=00:06:01
11/18/2012 16:56:48;0008;PBS_Server;Job;NULL;on_job_exit valid pjob: 0x13f2680 (substate=50)
11/18/2012 16:56:48;0008;PBS_Server;Job;NULL;on_job_exit valid pjob: 0x13f2680 (substate=51)
11/18/2012 16:56:48;0008;PBS_Server;Job;NULL;on_job_exit valid pjob: 0x13f2680 (substate=51)
11/18/2012 16:56:48;0008;PBS_Server;Job;NULL;on_job_exit valid pjob: 0x13f2680 (substate=53)
11/18/2012 16:56:48;0100;PBS_Server;Job;14136.tyrone-cluster;dequeuing from idqueue, state COMPLETE
11/18/2012 16:56:48;0040;PBS_Server;Svr;tyrone-cluster;Scheduler was sent the command term
11/18/2012 16:56:49;0008;PBS_Server;Job;14139.tyrone-cluster;Job Modified at request of Scheduler@tyrone-cluster
11/18/2012 16:56:49;0008;PBS_Server;Job;14139.tyrone-cluster;Job Run at request of Scheduler@tyrone-cluster
11/18/2012 16:56:49;0040;PBS_Server;Svr;tyrone-cluster;Scheduler was sent the command recyc
11/18/2012 16:56:49;000d;PBS_Server;Job;14139.tyrone-cluster;Not sending email: User does not want mail of this type.
11/18/2012 16:56:56;000d;PBS_Server;Job;14137.tyrone-cluster;Not sending email: User does not want mail of this type.
11/18/2012 16:56:56;0010;PBS_Server;Job;14137.tyrone-cluster;Exit_status=0 resources_used.cput=00:25:56 resources_used.mem=5422576kb resources_used.vmem=10784592kb resources_used.walltime=00:06:08
11/18/2012 16:56:56;0008;PBS_Server;Job;NULL;on_job_exit valid pjob: 0x12f5dd0 (substate=50)
11/18/2012 16:56:56;0008;PBS_Server;Job;NULL;on_job_exit valid pjob: 0x12f5dd0 (substate=51)
11/18/2012 16:56:56;0008;PBS_Server;Job;NULL;on_job_exit valid pjob: 0x12f5dd0 (substate=51)
11/18/2012 16:56:56;0008;PBS_Server;Job;NULL;on_job_exit valid pjob: 0x12f5dd0 (substate=53)
11/18/2012 16:56:56;0100;PBS_Server;Job;14137.tyrone-cluster;dequeuing from idqueue, state COMPLETE
11/18/2012 16:56:56;0040;PBS_Server;Svr;tyrone-cluster;Scheduler was sent the command term
11/18/2012 16:56:56;0008;PBS_Server;Job;14142.tyrone-cluster;Job Modified at request of Scheduler@tyrone-cluster
11/18/2012 16:56:56;0008;PBS_Server;Job;14142.tyrone-cluster;Job Run at request of Scheduler@tyrone-cluster
11/18/2012 16:56:56;0040;PBS_Server;Svr;tyrone-cluster;Scheduler was sent the command recyc
11/18/2012 16:56:56;000d;PBS_Server;Job;14142.tyrone-cluster;Not sending email: User does not want mail of this type.
11/18/2012 16:57:08;0040;PBS_Server;Svr;tyrone-cluster;Scheduler was sent the command new
11/18/2012 16:57:37;0040;PBS_Server;Svr;tyrone-cluster;Scheduler was sent the command new
11/18/2012 16:58:07;0040;PBS_Server;Svr;tyrone-cluster;Scheduler was sent the command new
11/18/2012 16:58:10;0100;PBS_Server;Job;14149.tyrone-cluster;enqueuing into batch, state 1 hop 1
11/18/2012 16:58:10;0100;PBS_Server;Job;14149.tyrone-cluster;dequeuing from batch, state QUEUED
11/18/2012 16:58:10;0100;PBS_Server;Job;14149.tyrone-cluster;enqueuing into idqueue, state 1 hop 1
11/18/2012 16:58:10;0008;PBS_Server;Job;14149.tyrone-cluster;Job Queued at request of seckriti@tyrone-cluster, owner = seckriti@tyrone-cluster, job name = myjob, queue = idqueue
11/18/2012 16:58:10;0040;PBS_Server;Svr;tyrone-cluster;Scheduler was sent the command new
11/18/2012 16:58:10;0008;PBS_Server;Job;14149.tyrone-cluster;Job Modified at request of Scheduler@tyrone-cluster
11/18/2012 16:58:15;0100;PBS_Server;Job;14150.tyrone-cluster;enqueuing into batch, state 1 hop 1
11/18/2012 16:58:15;0100;PBS_Server;Job;14150.tyrone-cluster;dequeuing from batch, state QUEUED
11/18/2012 16:58:15;0100;PBS_Server;Job;14150.tyrone-cluster;enqueuing into idqueue, state 1 hop 1
11/18/2012 16:58:15;0008;PBS_Server;Job;14150.tyrone-cluster;Job Queued at request of seckriti@tyrone-cluster, owner = seckriti@tyrone-cluster, job name = myjob, queue = idqueue
11/18/2012 16:58:15;0040;PBS_Server;Svr;tyrone-cluster;Scheduler was sent the command new
11/18/2012 16:58:15;0008;PBS_Server;Job;14150.tyrone-cluster;Job Modified at request of Scheduler@tyrone-cluster
11/18/2012 16:58:17;0100;PBS_Server;Job;14151.tyrone-cluster;enqueuing into batch, state 1 hop 1
11/18/2012 16:58:17;0100;PBS_Server;Job;14151.tyrone-cluster;dequeuing from batch, state QUEUED
11/18/2012 16:58:17;0100;PBS_Server;Job;14151.tyrone-cluster;enqueuing into idqueue, state 1 hop 1
11/18/2012 16:58:17;0008;PBS_Server;Job;14151.tyrone-cluster;Job Queued at request of seckriti@tyrone-cluster, owner = seckriti@tyrone-cluster, job name = myjob, queue = idqueue
11/18/2012 16:58:17;0040;PBS_Server;Svr;tyrone-cluster;Scheduler was sent the command new
11/18/2012 16:58:17;0008;PBS_Server;Job;14151.tyrone-cluster;Job Modified at request of Scheduler@tyrone-cluster
11/18/2012 16:58:30;0100;PBS_Server;Job;14152.tyrone-cluster;enqueuing into batch, state 1 hop 1
11/18/2012 16:58:30;0100;PBS_Server;Job;14152.tyrone-cluster;dequeuing from batch, state QUEUED
11/18/2012 16:58:30;0100;PBS_Server;Job;14152.tyrone-cluster;enqueuing into idqueue, state 1 hop 1
11/18/2012 16:58:30;0008;PBS_Server;Job;14152.tyrone-cluster;Job Queued at request of secbadar@tyrone-cluster, owner = secbadar@tyrone-cluster, job name = myjob, queue = idqueue
11/18/2012 16:58:30;0040;PBS_Server;Svr;tyrone-cluster;Scheduler was sent the command new
11/18/2012 16:58:31;0008;PBS_Server;Job;14152.tyrone-cluster;Job Modified at request of Scheduler@tyrone-cluster
11/18/2012 16:58:37;0040;PBS_Server;Svr;tyrone-cluster;Scheduler was sent the command new
11/18/2012 16:58:37;000d;PBS_Server;Job;14142.tyrone-cluster;Not sending email: User does not want mail of this type.
11/18/2012 16:58:37;0010;PBS_Server;Job;14142.tyrone-cluster;Exit_status=0 resources_used.cput=00:06:38 resources_used.mem=441428kb resources_used.vmem=899968kb resources_used.walltime=00:01:41
11/18/2012 16:58:37;0008;PBS_Server;Job;NULL;on_job_exit valid pjob: 0x1314c50 (substate=50)
11/18/2012 16:58:37;0008;PBS_Server;Job;NULL;on_job_exit valid pjob: 0x1314c50 (substate=51)
11/18/2012 16:58:37;0008;PBS_Server;Job;NULL;on_job_exit valid pjob: 0x1314c50 (substate=51)
11/18/2012 16:58:37;0008;PBS_Server;Job;NULL;on_job_exit valid pjob: 0x1314c50 (substate=53)
11/18/2012 16:58:37;0100;PBS_Server;Job;14142.tyrone-cluster;dequeuing from idqueue, state COMPLETE
11/18/2012 16:58:37;0008;PBS_Server;Job;14144.tyrone-cluster;Job Modified at request of Scheduler@tyrone-cluster
11/18/2012 16:58:37;0008;PBS_Server;Job;14144.tyrone-cluster;Job Run at request of Scheduler@tyrone-cluster
11/18/2012 16:58:37;000d;PBS_Server;Job;14144.tyrone-cluster;Not sending email: User does not want mail of this type.
11/18/2012 16:58:37;0040;PBS_Server;Svr;tyrone-cluster;Scheduler was sent the command recyc
11/18/2012 16:58:49;0002;PBS_Server;Svr;PBS_Server;Torque Server Version = 3.0.5, loglevel = 0
11/18/2012 16:58:50;0100;PBS_Server;Job;14153.tyrone-cluster;enqueuing into batch, state 1 hop 1
11/18/2012 16:58:50;0100;PBS_Server;Job;14153.tyrone-cluster;dequeuing from batch, state QUEUED
11/18/2012 16:58:50;0100;PBS_Server;Job;14153.tyrone-cluster;enqueuing into idqueue, state 1 hop 1
11/18/2012 16:58:50;0008;PBS_Server;Job;14153.tyrone-cluster;Job Queued at request of secvkm@tyrone-cluster, owner = secvkm@tyrone-cluster, job name = myjob, queue = idqueue
11/18/2012 16:58:50;0040;PBS_Server;Svr;tyrone-cluster;Scheduler was sent the command new
11/18/2012 16:58:50;0008;PBS_Server;Job;14153.tyrone-cluster;Job Modified at request of Scheduler@tyrone-cluster
11/18/2012 16:58:51;0100;PBS_Server;Job;14154.tyrone-cluster;enqueuing into batch, state 1 hop 1
11/18/2012 16:58:51;0100;PBS_Server;Job;14154.tyrone-cluster;dequeuing from batch, state QUEUED
11/18/2012 16:58:51;0100;PBS_Server;Job;14154.tyrone-cluster;enqueuing into idqueue, state 1 hop 1
11/18/2012 16:58:51;0008;PBS_Server;Job;14154.tyrone-cluster;Job Queued at request of secvkm@tyrone-cluster, owner = secvkm@tyrone-cluster, job name = myjob, queue = idqueue
11/18/2012 16:58:51;0040;PBS_Server;Svr;tyrone-cluster;Scheduler was sent the command new
11/18/2012 16:58:51;0008;PBS_Server;Job;14154.tyrone-cluster;Job Modified at request of Scheduler@tyrone-cluster
11/18/2012 16:59:07;0040;PBS_Server;Svr;tyrone-cluster;Scheduler was sent the command new
11/18/2012 16:59:37;0040;PBS_Server;Svr;tyrone-cluster;Scheduler was sent the command new
11/18/2012 16:59:50;000d;PBS_Server;Job;14144.tyrone-cluster;Not sending email: User does not want mail of this type.
11/18/2012 16:59:50;0010;PBS_Server;Job;14144.tyrone-cluster;Exit_status=0 resources_used.cput=00:09:35 resources_used.mem=505204kb resources_used.vmem=1230920kb resources_used.walltime=00:01:13
11/18/2012 16:59:50;0008;PBS_Server;Job;NULL;on_job_exit valid pjob: 0x12fb1f0 (substate=50)
11/18/2012 16:59:50;0008;PBS_Server;Job;NULL;on_job_exit valid pjob: 0x12fb1f0 (substate=51)
11/18/2012 16:59:50;0008;PBS_Server;Job;NULL;on_job_exit valid pjob: 0x12fb1f0 (substate=51)
11/18/2012 16:59:50;0008;PBS_Server;Job;NULL;on_job_exit valid pjob: 0x12fb1f0 (substate=53)
11/18/2012 16:59:50;0100;PBS_Server;Job;14144.tyrone-cluster;dequeuing from idqueue, state COMPLETE
11/18/2012 16:59:50;0040;PBS_Server;Svr;tyrone-cluster;Scheduler was sent the command term
11/18/2012 16:59:50;0008;PBS_Server;Job;14146.tyrone-cluster;Job Modified at request of Scheduler@tyrone-cluster
11/18/2012 16:59:50;0008;PBS_Server;Job;14146.tyrone-cluster;Job Run at request of Scheduler@tyrone-cluster
11/18/2012 16:59:50;000d;PBS_Server;Job;14146.tyrone-cluster;Not sending email: User does not want mail of this type.
11/18/2012 16:59:50;0040;PBS_Server;Svr;tyrone-cluster;Scheduler was sent the command recyc
11/18/2012 17:00:08;0040;PBS_Server;Svr;tyrone-cluster;Scheduler was sent the command new
11/18/2012 17:00:39;0040;PBS_Server;Svr;tyrone-cluster;Scheduler was sent the command new
11/18/2012 17:00:43;000d;PBS_Server;Job;14146.tyrone-cluster;Not sending email: User does not want mail of this type.
11/18/2012 17:00:43;0010;PBS_Server;Job;14146.tyrone-cluster;Exit_status=0 resources_used.cput=00:10:29 resources_used.mem=562908kb resources_used.vmem=1678124kb resources_used.walltime=00:00:53
11/18/2012 17:00:43;0008;PBS_Server;Job;NULL;on_job_exit valid pjob: 0x1342960 (substate=50)
11/18/2012 17:00:43;0008;PBS_Server;Job;NULL;on_job_exit valid pjob: 0x1342960 (substate=51)
11/18/2012 17:00:43;0008;PBS_Server;Job;NULL;on_job_exit valid pjob: 0x1342960 (substate=51)
11/18/2012 17:00:43;0008;PBS_Server;Job;NULL;on_job_exit valid pjob: 0x1342960 (substate=53)
11/18/2012 17:00:43;0100;PBS_Server;Job;14146.tyrone-cluster;dequeuing from idqueue, state COMPLETE
11/18/2012 17:00:43;0040;PBS_Server;Svr;tyrone-cluster;Scheduler was sent the command term
11/18/2012 17:00:43;0008;PBS_Server;Job;14148.tyrone-cluster;Job Modified at request of Scheduler@tyrone-cluster
11/18/2012 17:00:43;0008;PBS_Server;Job;14148.tyrone-cluster;Job Run at request of Scheduler@tyrone-cluster
11/18/2012 17:00:43;000d;PBS_Server;Job;14148.tyrone-cluster;Not sending email: User does not want mail of this type.
11/18/2012 17:00:43;0040;PBS_Server;Svr;tyrone-cluster;Scheduler was sent the command recyc
11/18/2012 17:00:44;000d;PBS_Server;Job;14148.tyrone-cluster;Not sending email: User does not want mail of this type.
11/18/2012 17:00:44;0010;PBS_Server;Job;14148.tyrone-cluster;Exit_status=255 resources_used.cput=00:00:00 resources_used.mem=0kb resources_used.vmem=0kb resources_used.walltime=00:00:01
11/18/2012 17:00:44;0008;PBS_Server;Job;NULL;on_job_exit valid pjob: 0x13fd950 (substate=50)
11/18/2012 17:00:44;0008;PBS_Server;Job;NULL;on_job_exit valid pjob: 0x13fd950 (substate=51)
11/18/2012 17:00:44;0008;PBS_Server;Job;NULL;on_job_exit valid pjob: 0x13fd950 (substate=51)
11/18/2012 17:00:44;0008;PBS_Server;Job;NULL;on_job_exit valid pjob: 0x13fd950 (substate=53)
11/18/2012 17:00:44;0100;PBS_Server;Job;14148.tyrone-cluster;dequeuing from idqueue, state COMPLETE
11/18/2012 17:00:44;0040;PBS_Server;Svr;tyrone-cluster;Scheduler was sent the command term
11/18/2012 17:00:44;0008;PBS_Server;Job;14149.tyrone-cluster;Job Modified at request of Scheduler@tyrone-cluster
11/18/2012 17:00:44;0008;PBS_Server;Job;14149.tyrone-cluster;Job Run at request of Scheduler@tyrone-cluster
11/18/2012 17:00:44;000d;PBS_Server;Job;14149.tyrone-cluster;Not sending email: User does not want mail of this type.
11/18/2012 17:00:44;0040;PBS_Server;Svr;tyrone-cluster;Scheduler was sent the command recyc
11/18/2012 17:01:10;0040;PBS_Server;Svr;tyrone-cluster;Scheduler was sent the command new
11/18/2012 17:01:10;000d;PBS_Server;Job;14140.tyrone-cluster;Not sending email: User does not want mail of this type.
11/18/2012 17:01:10;0010;PBS_Server;Job;14140.tyrone-cluster;Exit_status=0 resources_used.cput=00:19:59 resources_used.mem=445172kb resources_used.vmem=1170900kb resources_used.walltime=00:06:16
11/18/2012 17:01:10;0008;PBS_Server;Job;NULL;on_job_exit valid pjob: 0x131f740 (substate=50)
11/18/2012 17:01:10;0008;PBS_Server;Job;NULL;on_job_exit valid pjob: 0x131f740 (substate=51)
11/18/2012 17:01:10;0008;PBS_Server;Job;14143.tyrone-cluster;Job Modified at request of Scheduler@tyrone-cluster
11/18/2012 17:01:10;0008;PBS_Server;Job;14145.tyrone-cluster;Job Modified at request of Scheduler@tyrone-cluster
11/18/2012 17:01:10;0008;PBS_Server;Job;14147.tyrone-cluster;Job Modified at request of Scheduler@tyrone-cluster
11/18/2012 17:01:10;0008;PBS_Server;Job;NULL;on_job_exit valid pjob: 0x131f740 (substate=51)
11/18/2012 17:01:10;0008;PBS_Server;Job;NULL;on_job_exit valid pjob: 0x131f740 (substate=53)
11/18/2012 17:01:10;0100;PBS_Server;Job;14140.tyrone-cluster;dequeuing from idqueue, state COMPLETE
11/18/2012 17:01:10;0040;PBS_Server;Svr;tyrone-cluster;Scheduler was sent the command term
11/18/2012 17:01:10;0008;PBS_Server;Job;14143.tyrone-cluster;Job Modified at request of Scheduler@tyrone-cluster
11/18/2012 17:01:10;0008;PBS_Server;Job;14143.tyrone-cluster;Job Run at request of Scheduler@tyrone-cluster
11/18/2012 17:01:10;0008;PBS_Server;Job;14145.tyrone-cluster;Job Modified at request of Scheduler@tyrone-cluster
11/18/2012 17:01:10;0008;PBS_Server;Job;14147.tyrone-cluster;Job Modified at request of Scheduler@tyrone-cluster
11/18/2012 17:01:10;000d;PBS_Server;Job;14143.tyrone-cluster;Not sending email: User does not want mail of this type.
11/18/2012 17:01:10;0040;PBS_Server;Svr;tyrone-cluster;Scheduler was sent the command recyc
11/18/2012 17:01:24;0100;PBS_Server;Job;14155.tyrone-cluster;enqueuing into batch, state 1 hop 1
11/18/2012 17:01:24;0100;PBS_Server;Job;14155.tyrone-cluster;dequeuing from batch, state QUEUED
11/18/2012 17:01:24;0100;PBS_Server;Job;14155.tyrone-cluster;enqueuing into idqueue, state 1 hop 1
11/18/2012 17:01:24;0008;PBS_Server;Job;14155.tyrone-cluster;Job Queued at request of secjagvi@tyrone-cluster, owner = secjagvi@tyrone-cluster, job name = myjob, queue = idqueue
11/18/2012 17:01:24;0040;PBS_Server;Svr;tyrone-cluster;Scheduler was sent the command new
11/18/2012 17:01:25;0008;PBS_Server;Job;14155.tyrone-cluster;Job Modified at request of Scheduler@tyrone-cluster
11/18/2012 17:01:35;000d;PBS_Server;Job;14139.tyrone-cluster;Not sending email: User does not want mail of this type.
11/18/2012 17:01:35;0010;PBS_Server;Job;14139.tyrone-cluster;Exit_status=0 resources_used.cput=00:13:35 resources_used.mem=3748296kb resources_used.vmem=7170860kb resources_used.walltime=00:04:46
11/18/2012 17:01:35;0008;PBS_Server;Job;NULL;on_job_exit valid pjob: 0x12f83c0 (substate=50)
11/18/2012 17:01:35;0008;PBS_Server;Job;NULL;on_job_exit valid pjob: 0x12f83c0 (substate=51)
11/18/2012 17:01:35;0008;PBS_Server;Job;NULL;on_job_exit valid pjob: 0x12f83c0 (substate=51)
11/18/2012 17:01:35;0008;PBS_Server;Job;NULL;on_job_exit valid pjob: 0x12f83c0 (substate=53)
11/18/2012 17:01:35;0100;PBS_Server;Job;14139.tyrone-cluster;dequeuing from idqueue, state COMPLETE
11/18/2012 17:01:35;0040;PBS_Server;Svr;tyrone-cluster;Scheduler was sent the command term
11/18/2012 17:01:35;0008;PBS_Server;Job;14150.tyrone-cluster;Job Modified at request of Scheduler@tyrone-cluster
11/18/2012 17:01:35;0008;PBS_Server;Job;14150.tyrone-cluster;Job Run at request of Scheduler@tyrone-cluster
11/18/2012 17:01:36;0008;PBS_Server;Job;14151.tyrone-cluster;Job Modified at request of Scheduler@tyrone-cluster
11/18/2012 17:01:36;000d;PBS_Server;Job;14150.tyrone-cluster;Not sending email: User does not want mail of this type.
11/18/2012 17:01:36;0040;PBS_Server;Svr;tyrone-cluster;Scheduler was sent the command recyc
11/18/2012 17:01:40;0040;PBS_Server;Svr;tyrone-cluster;Scheduler was sent the command new
11/18/2012 17:01:59;000d;PBS_Server;Job;14141.tyrone-cluster;Not sending email: User does not want mail of this type.
11/18/2012 17:01:59;0010;PBS_Server;Job;14141.tyrone-cluster;Exit_status=0 resources_used.cput=00:25:40 resources_used.mem=468456kb resources_used.vmem=1582624kb resources_used.walltime=00:06:34
11/18/2012 17:01:59;0008;PBS_Server;Job;NULL;on_job_exit valid pjob: 0x134e980 (substate=50)
11/18/2012 17:01:59;0008;PBS_Server;Job;NULL;on_job_exit valid pjob: 0x134e980 (substate=51)
11/18/2012 17:01:59;0008;PBS_Server;Job;NULL;on_job_exit valid pjob: 0x134e980 (substate=51)
11/18/2012 17:01:59;0008;PBS_Server;Job;NULL;on_job_exit valid pjob: 0x134e980 (substate=53)
11/18/2012 17:01:59;0100;PBS_Server;Job;14141.tyrone-cluster;dequeuing from idqueue, state COMPLETE
11/18/2012 17:01:59;0040;PBS_Server;Svr;tyrone-cluster;Scheduler was sent the command term
11/18/2012 17:01:59;0008;PBS_Server;Job;14145.tyrone-cluster;Job Modified at request of Scheduler@tyrone-cluster
11/18/2012 17:01:59;0008;PBS_Server;Job;14145.tyrone-cluster;Job Run at request of Scheduler@tyrone-cluster
11/18/2012 17:01:59;000d;PBS_Server;Job;14145.tyrone-cluster;Not sending email: User does not want mail of this type.
11/18/2012 17:01:59;0040;PBS_Server;Svr;tyrone-cluster;Scheduler was sent the command recyc
11/18/2012 17:02:11;0040;PBS_Server;Svr;tyrone-cluster;Scheduler was sent the command new
11/18/2012 17:02:26;000d;PBS_Server;Job;14149.tyrone-cluster;Not sending email: User does not want mail of this type.
11/18/2012 17:02:26;0010;PBS_Server;Job;14149.tyrone-cluster;Exit_status=0 resources_used.cput=00:06:44 resources_used.mem=446196kb resources_used.vmem=904728kb resources_used.walltime=00:01:42
11/18/2012 17:02:26;0008;PBS_Server;Job;NULL;on_job_exit valid pjob: 0x12f5dd0 (substate=50)
11/18/2012 17:02:26;0008;PBS_Server;Job;NULL;on_job_exit valid pjob: 0x12f5dd0 (substate=51)
11/18/2012 17:02:26;0008;PBS_Server;Job;NULL;on_job_exit valid pjob: 0x12f5dd0 (substate=51)
11/18/2012 17:02:26;0008;PBS_Server;Job;NULL;on_job_exit valid pjob: 0x12f5dd0 (substate=53)
11/18/2012 17:02:26;0100;PBS_Server;Job;14149.tyrone-cluster;dequeuing from idqueue, state COMPLETE
11/18/2012 17:02:26;0040;PBS_Server;Svr;tyrone-cluster;Scheduler was sent the command term
11/18/2012 17:02:26;0008;PBS_Server;Job;14151.tyrone-cluster;Job Modified at request of Scheduler@tyrone-cluster
11/18/2012 17:02:26;0008;PBS_Server;Job;14151.tyrone-cluster;Job Run at request of Scheduler@tyrone-cluster
11/18/2012 17:02:27;000d;PBS_Server;Job;14151.tyrone-cluster;Not sending email: User does not want mail of this type.
11/18/2012 17:02:27;0040;PBS_Server;Svr;tyrone-cluster;Scheduler was sent the command recyc
11/18/2012 17:02:44;0040;PBS_Server;Svr;tyrone-cluster;Scheduler was sent the command new
11/18/2012 17:02:46;000d;PBS_Server;Job;14150.tyrone-cluster;Not sending email: User does not want mail of this type.
11/18/2012 17:02:46;0010;PBS_Server;Job;14150.tyrone-cluster;Exit_status=0 resources_used.cput=00:09:18 resources_used.mem=503384kb resources_used.vmem=1229088kb resources_used.walltime=00:01:11
11/18/2012 17:02:46;0008;PBS_Server;Job;NULL;on_job_exit valid pjob: 0x13e5a30 (substate=50)
11/18/2012 17:02:46;0008;PBS_Server;Job;NULL;on_job_exit valid pjob: 0x13e5a30 (substate=51)
11/18/2012 17:02:46;0008;PBS_Server;Job;NULL;on_job_exit valid pjob: 0x13e5a30 (substate=51)
11/18/2012 17:02:46;0008;PBS_Server;Job;NULL;on_job_exit valid pjob: 0x13e5a30 (substate=53)
11/18/2012 17:02:46;0100;PBS_Server;Job;14150.tyrone-cluster;dequeuing from idqueue, state COMPLETE
11/18/2012 17:02:46;0040;PBS_Server;Svr;tyrone-cluster;Scheduler was sent the command term
11/18/2012 17:02:46;0008;PBS_Server;Job;14152.tyrone-cluster;Job Modified at request of Scheduler@tyrone-cluster
11/18/2012 17:02:46;0008;PBS_Server;Job;14152.tyrone-cluster;Job Run at request of Scheduler@tyrone-cluster
11/18/2012 17:02:47;000d;PBS_Server;Job;14152.tyrone-cluster;Not sending email: User does not want mail of this type.
11/18/2012 17:02:47;0040;PBS_Server;Svr;tyrone-cluster;Scheduler was sent the command recyc
11/18/2012 17:03:15;0040;PBS_Server;Svr;tyrone-cluster;Scheduler was sent the command new
11/18/2012 17:03:24;000d;PBS_Server;Job;14151.tyrone-cluster;Not sending email: User does not want mail of this type.
11/18/2012 17:03:24;0010;PBS_Server;Job;14151.tyrone-cluster;Exit_status=0 resources_used.cput=00:11:26 resources_used.mem=564736kb resources_used.vmem=1679904kb resources_used.walltime=00:00:58
11/18/2012 17:03:24;0008;PBS_Server;Job;NULL;on_job_exit valid pjob: 0x13fec10 (substate=50)
11/18/2012 17:03:24;0008;PBS_Server;Job;NULL;on_job_exit valid pjob: 0x13fec10 (substate=51)
11/18/2012 17:03:25;0008;PBS_Server;Job;NULL;on_job_exit valid pjob: 0x13fec10 (substate=51)
11/18/2012 17:03:25;0008;PBS_Server;Job;NULL;on_job_exit valid pjob: 0x13fec10 (substate=53)
11/18/2012 17:03:25;0100;PBS_Server;Job;14151.tyrone-cluster;dequeuing from idqueue, state COMPLETE
11/18/2012 17:03:25;0040;PBS_Server;Svr;tyrone-cluster;Scheduler was sent the command term
11/18/2012 17:03:25;0008;PBS_Server;Job;14153.tyrone-cluster;Job Modified at request of Scheduler@tyrone-cluster
11/18/2012 17:03:25;0008;PBS_Server;Job;14153.tyrone-cluster;Job Run at request of Scheduler@tyrone-cluster
11/18/2012 17:03:25;0040;PBS_Server;Svr;tyrone-cluster;Scheduler was sent the command recyc
11/18/2012 17:03:25;000d;PBS_Server;Job;14153.tyrone-cluster;Not sending email: User does not want mail of this type.
11/18/2012 17:03:44;0040;PBS_Server;Svr;tyrone-cluster;Scheduler was sent the command new
11/18/2012 17:03:49;0002;PBS_Server;Svr;PBS_Server;Torque Server Version = 3.0.5, loglevel = 0
11/18/2012 17:04:14;0040;PBS_Server;Svr;tyrone-cluster;Scheduler was sent the command new
11/18/2012 17:04:52;0040;PBS_Server;Svr;tyrone-cluster;Scheduler was sent the command new
11/18/2012 17:05:18;0040;PBS_Server;Svr;tyrone-cluster;Scheduler was sent the command new
11/18/2012 17:05:52;0040;PBS_Server;Svr;tyrone-cluster;Scheduler was sent the command new
11/18/2012 17:06:22;0040;PBS_Server;Svr;tyrone-cluster;Scheduler was sent the command new
11/18/2012 17:06:22;000d;PBS_Server;Job;14143.tyrone-cluster;Not sending email: User does not want mail of this type.
11/18/2012 17:06:22;0010;PBS_Server;Job;14143.tyrone-cluster;Exit_status=0 resources_used.cput=00:14:41 resources_used.mem=445204kb resources_used.vmem=1170900kb resources_used.walltime=00:05:12
11/18/2012 17:06:22;0008;PBS_Server;Job;NULL;on_job_exit valid pjob: 0x132ff00 (substate=50)
11/18/2012 17:06:22;0008;PBS_Server;Job;NULL;on_job_exit valid pjob: 0x132ff00 (substate=51)
11/18/2012 17:06:22;0008;PBS_Server;Job;14147.tyrone-cluster;Job Modified at request of Scheduler@tyrone-cluster
11/18/2012 17:06:22;0008;PBS_Server;Job;NULL;on_job_exit valid pjob: 0x132ff00 (substate=51)
11/18/2012 17:06:22;0008;PBS_Server;Job;NULL;on_job_exit valid pjob: 0x132ff00 (substate=53)
11/18/2012 17:06:22;0100;PBS_Server;Job;14143.tyrone-cluster;dequeuing from idqueue, state COMPLETE
11/18/2012 17:06:22;0040;PBS_Server;Svr;tyrone-cluster;Scheduler was sent the command term
11/18/2012 17:06:22;0008;PBS_Server;Job;14147.tyrone-cluster;Job Modified at request of Scheduler@tyrone-cluster
11/18/2012 17:06:22;0008;PBS_Server;Job;14147.tyrone-cluster;Job Run at request of Scheduler@tyrone-cluster
11/18/2012 17:06:23;000d;PBS_Server;Job;14147.tyrone-cluster;Not sending email: User does not want mail of this type.
11/18/2012 17:06:23;0040;PBS_Server;Svr;tyrone-cluster;Scheduler was sent the command recyc
11/18/2012 17:06:53;0040;PBS_Server;Svr;tyrone-cluster;Scheduler was sent the command new
11/18/2012 17:07:12;000d;PBS_Server;Job;14145.tyrone-cluster;Not sending email: User does not want mail of this type.
11/18/2012 17:07:12;0010;PBS_Server;Job;14145.tyrone-cluster;Exit_status=0 resources_used.cput=00:14:46 resources_used.mem=445196kb resources_used.vmem=1170900kb resources_used.walltime=00:05:13
11/18/2012 17:07:12;0008;PBS_Server;Job;NULL;on_job_exit valid pjob: 0x13416a0 (substate=50)
11/18/2012 17:07:12;0008;PBS_Server;Job;NULL;on_job_exit valid pjob: 0x13416a0 (substate=51)
11/18/2012 17:07:12;0008;PBS_Server;Job;NULL;on_job_exit valid pjob: 0x13416a0 (substate=51)
11/18/2012 17:07:12;0008;PBS_Server;Job;NULL;on_job_exit valid pjob: 0x13416a0 (substate=53)
11/18/2012 17:07:12;0100;PBS_Server;Job;14145.tyrone-cluster;dequeuing from idqueue, state COMPLETE
11/18/2012 17:07:12;0040;PBS_Server;Svr;tyrone-cluster;Scheduler was sent the command term
11/18/2012 17:07:12;0008;PBS_Server;Job;14154.tyrone-cluster;Job Modified at request of Scheduler@tyrone-cluster
11/18/2012 17:07:12;0008;PBS_Server;Job;14154.tyrone-cluster;Job Run at request of Scheduler@tyrone-cluster
11/18/2012 17:07:13;0040;PBS_Server;Svr;tyrone-cluster;Scheduler was sent the command recyc
11/18/2012 17:07:13;000d;PBS_Server;Job;14154.tyrone-cluster;Not sending email: User does not want mail of this type.
11/18/2012 17:07:22;0040;PBS_Server;Svr;tyrone-cluster;Scheduler was sent the command new
11/18/2012 17:07:52;0040;PBS_Server;Svr;tyrone-cluster;Scheduler was sent the command new
11/18/2012 17:08:10;000d;PBS_Server;Job;14153.tyrone-cluster;Not sending email: User does not want mail of this type.
11/18/2012 17:08:10;0010;PBS_Server;Job;14153.tyrone-cluster;Exit_status=0 resources_used.cput=00:13:33 resources_used.mem=3748284kb resources_used.vmem=7170860kb resources_used.walltime=00:04:45
11/18/2012 17:08:10;0008;PBS_Server;Job;NULL;on_job_exit valid pjob: 0x1401190 (substate=50)
11/18/2012 17:08:10;0008;PBS_Server;Job;NULL;on_job_exit valid pjob: 0x1401190 (substate=51)
11/18/2012 17:08:10;0008;PBS_Server;Job;NULL;on_job_exit valid pjob: 0x1401190 (substate=51)
11/18/2012 17:08:10;0008;PBS_Server;Job;NULL;on_job_exit valid pjob: 0x1401190 (substate=53)
11/18/2012 17:08:10;0100;PBS_Server;Job;14153.tyrone-cluster;dequeuing from idqueue, state COMPLETE
11/18/2012 17:08:10;0040;PBS_Server;Svr;tyrone-cluster;Scheduler was sent the command term
11/18/2012 17:08:10;0008;PBS_Server;Job;14155.tyrone-cluster;Job Modified at request of Scheduler@tyrone-cluster
11/18/2012 17:08:10;0008;PBS_Server;Job;14155.tyrone-cluster;Job Run at request of Scheduler@tyrone-cluster
11/18/2012 17:08:10;0040;PBS_Server;Svr;tyrone-cluster;Scheduler was sent the command recyc
11/18/2012 17:08:10;000d;PBS_Server;Job;14155.tyrone-cluster;Not sending email: User does not want mail of this type.
11/18/2012 17:08:10;000d;PBS_Server;Job;14155.tyrone-cluster;Not sending email: User does not want mail of this type.
11/18/2012 17:08:10;0010;PBS_Server;Job;14155.tyrone-cluster;Exit_status=255 resources_used.cput=00:00:00 resources_used.mem=0kb resources_used.vmem=0kb resources_used.walltime=00:00:00
11/18/2012 17:08:10;0008;PBS_Server;Job;NULL;on_job_exit valid pjob: 0x13fd950 (substate=50)
11/18/2012 17:08:10;0008;PBS_Server;Job;NULL;on_job_exit valid pjob: 0x13fd950 (substate=51)
11/18/2012 17:08:11;0008;PBS_Server;Job;NULL;on_job_exit valid pjob: 0x13fd950 (substate=51)
11/18/2012 17:08:11;0008;PBS_Server;Job;NULL;on_job_exit valid pjob: 0x13fd950 (substate=53)
11/18/2012 17:08:11;0100;PBS_Server;Job;14155.tyrone-cluster;dequeuing from idqueue, state COMPLETE
11/18/2012 17:08:11;0040;PBS_Server;Svr;tyrone-cluster;Scheduler was sent the command term
11/18/2012 17:08:23;0040;PBS_Server;Svr;tyrone-cluster;Scheduler was sent the command new
11/18/2012 17:08:35;0100;PBS_Server;Job;14156.tyrone-cluster;enqueuing into batch, state 1 hop 1
11/18/2012 17:08:35;0100;PBS_Server;Job;14156.tyrone-cluster;dequeuing from batch, state QUEUED
11/18/2012 17:08:35;0100;PBS_Server;Job;14156.tyrone-cluster;enqueuing into idqueue, state 1 hop 1
11/18/2012 17:08:35;0008;PBS_Server;Job;14156.tyrone-cluster;Job Queued at request of secjagvi@tyrone-cluster, owner = secjagvi@tyrone-cluster, job name = myjob, queue = idqueue
11/18/2012 17:08:35;0040;PBS_Server;Svr;tyrone-cluster;Scheduler was sent the command new
11/18/2012 17:08:35;0008;PBS_Server;Job;14156.tyrone-cluster;Job Modified at request of Scheduler@tyrone-cluster
11/18/2012 17:08:35;0008;PBS_Server;Job;14156.tyrone-cluster;Job Run at request of Scheduler@tyrone-cluster
11/18/2012 17:08:35;0040;PBS_Server;Svr;tyrone-cluster;Scheduler was sent the command recyc
11/18/2012 17:08:35;000d;PBS_Server;Job;14156.tyrone-cluster;Not sending email: User does not want mail of this type.
11/18/2012 17:08:36;000d;PBS_Server;Job;14156.tyrone-cluster;Not sending email: User does not want mail of this type.
11/18/2012 17:08:36;0010;PBS_Server;Job;14156.tyrone-cluster;Exit_status=255 resources_used.cput=00:00:00 resources_used.mem=0kb resources_used.vmem=0kb resources_used.walltime=00:00:01
11/18/2012 17:08:36;0008;PBS_Server;Job;NULL;on_job_exit valid pjob: 0x1401190 (substate=50)
11/18/2012 17:08:36;0008;PBS_Server;Job;NULL;on_job_exit valid pjob: 0x1401190 (substate=51)
11/18/2012 17:08:36;0008;PBS_Server;Job;NULL;on_job_exit valid pjob: 0x1401190 (substate=51)
11/18/2012 17:08:36;0008;PBS_Server;Job;NULL;on_job_exit valid pjob: 0x1401190 (substate=53)
11/18/2012 17:08:36;0100;PBS_Server;Job;14156.tyrone-cluster;dequeuing from idqueue, state COMPLETE
11/18/2012 17:08:36;0040;PBS_Server;Svr;tyrone-cluster;Scheduler was sent the command term
11/18/2012 17:08:49;0002;PBS_Server;Svr;PBS_Server;Torque Server Version = 3.0.5, loglevel = 0
11/18/2012 17:08:54;0040;PBS_Server;Svr;tyrone-cluster;Scheduler was sent the command new
11/18/2012 17:09:27;0040;PBS_Server;Svr;tyrone-cluster;Scheduler was sent the command new
11/18/2012 17:09:27;000d;PBS_Server;Job;14152.tyrone-cluster;Not sending email: User does not want mail of this type.
11/18/2012 17:09:27;0010;PBS_Server;Job;14152.tyrone-cluster;Exit_status=0 resources_used.cput=00:26:46 resources_used.mem=567340kb resources_used.vmem=1682692kb resources_used.walltime=00:06:40
11/18/2012 17:09:27;0008;PBS_Server;Job;NULL;on_job_exit valid pjob: 0x13ffed0 (substate=50)
11/18/2012 17:09:27;0008;PBS_Server;Job;NULL;on_job_exit valid pjob: 0x13ffed0 (substate=51)
11/18/2012 17:09:27;0008;PBS_Server;Job;NULL;on_job_exit valid pjob: 0x13ffed0 (substate=51)
11/18/2012 17:09:27;0008;PBS_Server;Job;NULL;on_job_exit valid pjob: 0x13ffed0 (substate=53)
11/18/2012 17:09:27;0100;PBS_Server;Job;14152.tyrone-cluster;dequeuing from idqueue, state COMPLETE
11/18/2012 17:09:27;0040;PBS_Server;Svr;tyrone-cluster;Scheduler was sent the command term
11/18/2012 17:10:01;0040;PBS_Server;Svr;tyrone-cluster;Scheduler was sent the command new
11/18/2012 17:10:30;0040;PBS_Server;Svr;tyrone-cluster;Scheduler was sent the command new
11/18/2012 17:10:30;0100;PBS_Server;Job;14157.tyrone-cluster;enqueuing into batch, state 1 hop 1
11/18/2012 17:10:30;0100;PBS_Server;Job;14157.tyrone-cluster;dequeuing from batch, state QUEUED
11/18/2012 17:10:30;0100;PBS_Server;Job;14157.tyrone-cluster;enqueuing into idqueue, state 1 hop 1
11/18/2012 17:10:30;0008;PBS_Server;Job;14157.tyrone-cluster;Job Queued at request of secjagvi@tyrone-cluster, owner = secjagvi@tyrone-cluster, job name = myjob, queue = idqueue
11/18/2012 17:10:30;0040;PBS_Server;Svr;tyrone-cluster;Scheduler was sent the command new
11/18/2012 17:10:30;0008;PBS_Server;Job;14157.tyrone-cluster;Job Modified at request of Scheduler@tyrone-cluster
11/18/2012 17:10:30;0008;PBS_Server;Job;14157.tyrone-cluster;Job Run at request of Scheduler@tyrone-cluster
11/18/2012 17:10:31;0040;PBS_Server;Svr;tyrone-cluster;Scheduler was sent the command recyc
11/18/2012 17:10:31;000d;PBS_Server;Job;14157.tyrone-cluster;Not sending email: User does not want mail of this type.
11/18/2012 17:10:31;000d;PBS_Server;Job;14157.tyrone-cluster;Not sending email: User does not want mail of this type.
11/18/2012 17:10:31;0010;PBS_Server;Job;14157.tyrone-cluster;Exit_status=255 resources_used.cput=00:00:00 resources_used.mem=0kb resources_used.vmem=0kb resources_used.walltime=00:00:01
11/18/2012 17:10:31;0008;PBS_Server;Job;NULL;on_job_exit valid pjob: 0x12f5dd0 (substate=50)
11/18/2012 17:10:31;0008;PBS_Server;Job;NULL;on_job_exit valid pjob: 0x12f5dd0 (substate=51)
11/18/2012 17:10:31;0008;PBS_Server;Job;NULL;on_job_exit valid pjob: 0x12f5dd0 (substate=51)
11/18/2012 17:10:31;0008;PBS_Server;Job;NULL;on_job_exit valid pjob: 0x12f5dd0 (substate=53)
11/18/2012 17:10:31;0100;PBS_Server;Job;14157.tyrone-cluster;dequeuing from idqueue, state COMPLETE
11/18/2012 17:10:31;0040;PBS_Server;Svr;tyrone-cluster;Scheduler was sent the command term
11/18/2012 17:11:03;0040;PBS_Server;Svr;tyrone-cluster;Scheduler was sent the command new
11/18/2012 17:11:37;0040;PBS_Server;Svr;tyrone-cluster;Scheduler was sent the command new
11/18/2012 17:11:37;000d;PBS_Server;Job;14147.tyrone-cluster;Not sending email: User does not want mail of this type.
11/18/2012 17:11:37;0010;PBS_Server;Job;14147.tyrone-cluster;Exit_status=0 resources_used.cput=00:14:43 resources_used.mem=445192kb resources_used.vmem=1170900kb resources_used.walltime=00:05:15
11/18/2012 17:11:37;0008;PBS_Server;Job;NULL;on_job_exit valid pjob: 0x13fad70 (substate=50)
11/18/2012 17:11:37;0008;PBS_Server;Job;NULL;on_job_exit valid pjob: 0x13fad70 (substate=51)
11/18/2012 17:11:37;0008;PBS_Server;Job;NULL;on_job_exit valid pjob: 0x13fad70 (substate=51)
11/18/2012 17:11:37;0008;PBS_Server;Job;NULL;on_job_exit valid pjob: 0x13fad70 (substate=53)
11/18/2012 17:11:37;0100;PBS_Server;Job;14147.tyrone-cluster;dequeuing from idqueue, state COMPLETE
11/18/2012 17:11:37;0040;PBS_Server;Svr;tyrone-cluster;Scheduler was sent the command term
11/18/2012 17:11:55;000d;PBS_Server;Job;14154.tyrone-cluster;Not sending email: User does not want mail of this type.
11/18/2012 17:11:55;0010;PBS_Server;Job;14154.tyrone-cluster;Exit_status=0 resources_used.cput=00:13:33 resources_used.mem=5422328kb resources_used.vmem=10784592kb resources_used.walltime=00:04:43
11/18/2012 17:11:55;0008;PBS_Server;Job;NULL;on_job_exit valid pjob: 0x1402450 (substate=50)
11/18/2012 17:11:55;0008;PBS_Server;Job;NULL;on_job_exit valid pjob: 0x1402450 (substate=51)
11/18/2012 17:11:55;0008;PBS_Server;Job;NULL;on_job_exit valid pjob: 0x1402450 (substate=51)
11/18/2012 17:11:55;0008;PBS_Server;Job;NULL;on_job_exit valid pjob: 0x1402450 (substate=53)
11/18/2012 17:11:55;0100;PBS_Server;Job;14154.tyrone-cluster;dequeuing from idqueue, state COMPLETE
11/18/2012 17:11:55;0040;PBS_Server;Svr;tyrone-cluster;Scheduler was sent the command term
11/18/2012 17:12:08;0040;PBS_Server;Svr;tyrone-cluster;Scheduler was sent the command new
11/18/2012 17:12:37;0040;PBS_Server;Svr;tyrone-cluster;Scheduler was sent the command new
11/18/2012 17:13:07;0040;PBS_Server;Svr;tyrone-cluster;Scheduler was sent the command new
11/18/2012 17:13:38;0040;PBS_Server;Svr;tyrone-cluster;Scheduler was sent the command new
11/18/2012 17:13:49;0002;PBS_Server;Svr;PBS_Server;Torque Server Version = 3.0.5, loglevel = 0
11/18/2012 17:14:07;0040;PBS_Server;Svr;tyrone-cluster;Scheduler was sent the command new
11/18/2012 17:14:23;0100;PBS_Server;Job;14158.tyrone-cluster;enqueuing into batch, state 1 hop 1
11/18/2012 17:14:23;0100;PBS_Server;Job;14158.tyrone-cluster;dequeuing from batch, state QUEUED
11/18/2012 17:14:23;0100;PBS_Server;Job;14158.tyrone-cluster;enqueuing into idqueue, state 1 hop 1
11/18/2012 17:14:23;0008;PBS_Server;Job;14158.tyrone-cluster;Job Queued at request of secjagvi@tyrone-cluster, owner = secjagvi@tyrone-cluster, job name = myjob, queue = idqueue
11/18/2012 17:14:23;0040;PBS_Server;Svr;tyrone-cluster;Scheduler was sent the command new
11/18/2012 17:14:23;0008;PBS_Server;Job;14158.tyrone-cluster;Job Modified at request of Scheduler@tyrone-cluster
11/18/2012 17:14:23;0008;PBS_Server;Job;14158.tyrone-cluster;Job Run at request of Scheduler@tyrone-cluster
11/18/2012 17:14:23;0040;PBS_Server;Svr;tyrone-cluster;Scheduler was sent the command recyc
11/18/2012 17:14:23;000d;PBS_Server;Job;14158.tyrone-cluster;Not sending email: User does not want mail of this type.
11/18/2012 17:14:24;000d;PBS_Server;Job;14158.tyrone-cluster;Not sending email: User does not want mail of this type.
11/18/2012 17:14:24;0010;PBS_Server;Job;14158.tyrone-cluster;Exit_status=255 resources_used.cput=00:00:00 resources_used.mem=0kb resources_used.vmem=0kb resources_used.walltime=00:00:01
11/18/2012 17:14:24;0008;PBS_Server;Job;NULL;on_job_exit valid pjob: 0x134e980 (substate=50)
11/18/2012 17:14:24;0008;PBS_Server;Job;NULL;on_job_exit valid pjob: 0x134e980 (substate=51)
11/18/2012 17:14:24;0008;PBS_Server;Job;NULL;on_job_exit valid pjob: 0x134e980 (substate=51)
11/18/2012 17:14:24;0008;PBS_Server;Job;NULL;on_job_exit valid pjob: 0x134e980 (substate=53)
11/18/2012 17:14:24;0100;PBS_Server;Job;14158.tyrone-cluster;dequeuing from idqueue, state COMPLETE
11/18/2012 17:14:24;0040;PBS_Server;Svr;tyrone-cluster;Scheduler was sent the command term
11/18/2012 17:14:37;0040;PBS_Server;Svr;tyrone-cluster;Scheduler was sent the command new
11/18/2012 17:15:07;0040;PBS_Server;Svr;tyrone-cluster;Scheduler was sent the command new
11/18/2012 17:15:37;0040;PBS_Server;Svr;tyrone-cluster;Scheduler was sent the command new
11/18/2012 17:16:07;0040;PBS_Server;Svr;tyrone-cluster;Scheduler was sent the command new
11/18/2012 17:16:38;0040;PBS_Server;Svr;tyrone-cluster;Scheduler was sent the command new
11/18/2012 17:17:07;0040;PBS_Server;Svr;tyrone-cluster;Scheduler was sent the command new
11/18/2012 17:17:37;0040;PBS_Server;Svr;tyrone-cluster;Scheduler was sent the command new
11/18/2012 17:18:08;0040;PBS_Server;Svr;tyrone-cluster;Scheduler was sent the command new
11/18/2012 17:18:31;0100;PBS_Server;Job;14159.tyrone-cluster;enqueuing into batch, state 1 hop 1
11/18/2012 17:18:31;0100;PBS_Server;Job;14159.tyrone-cluster;dequeuing from batch, state QUEUED
11/18/2012 17:18:31;0100;PBS_Server;Job;14159.tyrone-cluster;enqueuing into idqueue, state 1 hop 1
11/18/2012 17:18:31;0008;PBS_Server;Job;14159.tyrone-cluster;Job Queued at request of secpka@tyrone-cluster, owner = secpka@tyrone-cluster, job name = myjob, queue = idqueue
11/18/2012 17:18:31;0040;PBS_Server;Svr;tyrone-cluster;Scheduler was sent the command new
11/18/2012 17:18:31;0008;PBS_Server;Job;14159.tyrone-cluster;Job Modified at request of Scheduler@tyrone-cluster
11/18/2012 17:18:31;0008;PBS_Server;Job;14159.tyrone-cluster;Job Run at request of Scheduler@tyrone-cluster
11/18/2012 17:18:31;0040;PBS_Server;Svr;tyrone-cluster;Scheduler was sent the command recyc
11/18/2012 17:18:31;000d;PBS_Server;Job;14159.tyrone-cluster;Not sending email: User does not want mail of this type.
11/18/2012 17:18:32;000d;PBS_Server;Job;14159.tyrone-cluster;Not sending email: User does not want mail of this type.
11/18/2012 17:18:32;0010;PBS_Server;Job;14159.tyrone-cluster;Exit_status=139 resources_used.cput=00:00:00 resources_used.mem=0kb resources_used.vmem=0kb resources_used.walltime=00:00:01
11/18/2012 17:18:32;0008;PBS_Server;Job;NULL;on_job_exit valid pjob: 0x134e980 (substate=50)
11/18/2012 17:18:32;0008;PBS_Server;Job;NULL;on_job_exit valid pjob: 0x134e980 (substate=51)
11/18/2012 17:18:32;0008;PBS_Server;Job;NULL;on_job_exit valid pjob: 0x134e980 (substate=51)
11/18/2012 17:18:32;0008;PBS_Server;Job;NULL;on_job_exit valid pjob: 0x134e980 (substate=53)
11/18/2012 17:18:32;0100;PBS_Server;Job;14159.tyrone-cluster;dequeuing from idqueue, state COMPLETE
11/18/2012 17:18:32;0040;PBS_Server;Svr;tyrone-cluster;Scheduler was sent the command term
11/18/2012 17:18:37;0040;PBS_Server;Svr;tyrone-cluster;Scheduler was sent the command new
11/18/2012 17:18:49;0002;PBS_Server;Svr;PBS_Server;Torque Server Version = 3.0.5, loglevel = 0
11/18/2012 17:19:07;0040;PBS_Server;Svr;tyrone-cluster;Scheduler was sent the command new
11/18/2012 17:19:38;0040;PBS_Server;Svr;tyrone-cluster;Scheduler was sent the command new
11/18/2012 17:20:09;0040;PBS_Server;Svr;tyrone-cluster;Scheduler was sent the command new
11/18/2012 17:20:52;0040;PBS_Server;Svr;tyrone-cluster;Scheduler was sent the command new
11/18/2012 17:21:22;0040;PBS_Server;Svr;tyrone-cluster;Scheduler was sent the command new
11/18/2012 17:21:53;0040;PBS_Server;Svr;tyrone-cluster;Scheduler was sent the command new
11/18/2012 17:22:22;0040;PBS_Server;Svr;tyrone-cluster;Scheduler was sent the command new
11/18/2012 17:22:31;0100;PBS_Server;Job;14160.tyrone-cluster;enqueuing into batch, state 1 hop 1
11/18/2012 17:22:31;0100;PBS_Server;Job;14160.tyrone-cluster;dequeuing from batch, state QUEUED
11/18/2012 17:22:31;0100;PBS_Server;Job;14160.tyrone-cluster;enqueuing into idqueue, state 1 hop 1
11/18/2012 17:22:31;0008;PBS_Server;Job;14160.tyrone-cluster;Job Queued at request of secpka@tyrone-cluster, owner = secpka@tyrone-cluster, job name = myjob, queue = idqueue
11/18/2012 17:22:31;0040;PBS_Server;Svr;tyrone-cluster;Scheduler was sent the command new
11/18/2012 17:22:31;0008;PBS_Server;Job;14160.tyrone-cluster;Job Modified at request of Scheduler@tyrone-cluster
11/18/2012 17:22:31;0008;PBS_Server;Job;14160.tyrone-cluster;Job Run at request of Scheduler@tyrone-cluster
11/18/2012 17:22:31;0040;PBS_Server;Svr;tyrone-cluster;Scheduler was sent the command recyc
11/18/2012 17:22:31;000d;PBS_Server;Job;14160.tyrone-cluster;Not sending email: User does not want mail of this type.
11/18/2012 17:22:32;000d;PBS_Server;Job;14160.tyrone-cluster;Not sending email: User does not want mail of this type.
11/18/2012 17:22:32;0010;PBS_Server;Job;14160.tyrone-cluster;Exit_status=139 resources_used.cput=00:00:00 resources_used.mem=0kb resources_used.vmem=0kb resources_used.walltime=00:00:01
11/18/2012 17:22:32;0008;PBS_Server;Job;NULL;on_job_exit valid pjob: 0x131f740 (substate=50)
11/18/2012 17:22:32;0008;PBS_Server;Job;NULL;on_job_exit valid pjob: 0x131f740 (substate=51)
11/18/2012 17:22:32;0008;PBS_Server;Job;NULL;on_job_exit valid pjob: 0x131f740 (substate=51)
11/18/2012 17:22:32;0008;PBS_Server;Job;NULL;on_job_exit valid pjob: 0x131f740 (substate=53)
11/18/2012 17:22:32;0100;PBS_Server;Job;14160.tyrone-cluster;dequeuing from idqueue, state COMPLETE
11/18/2012 17:22:32;0040;PBS_Server;Svr;tyrone-cluster;Scheduler was sent the command term
11/18/2012 17:22:52;0040;PBS_Server;Svr;tyrone-cluster;Scheduler was sent the command new
11/18/2012 17:23:22;0040;PBS_Server;Svr;tyrone-cluster;Scheduler was sent the command new
11/18/2012 17:23:49;0002;PBS_Server;Svr;PBS_Server;Torque Server Version = 3.0.5, loglevel = 0
11/18/2012 17:23:51;0100;PBS_Server;Job;14161.tyrone-cluster;enqueuing into batch, state 1 hop 1
11/18/2012 17:23:51;0100;PBS_Server;Job;14161.tyrone-cluster;dequeuing from batch, state QUEUED
11/18/2012 17:23:51;0100;PBS_Server;Job;14161.tyrone-cluster;enqueuing into idqueue, state 1 hop 1
11/18/2012 17:23:51;0008;PBS_Server;Job;14161.tyrone-cluster;Job Queued at request of seckriti@tyrone-cluster, owner = seckriti@tyrone-cluster, job name = myjob, queue = idqueue
11/18/2012 17:23:51;0040;PBS_Server;Svr;tyrone-cluster;Scheduler was sent the command new
11/18/2012 17:23:51;0008;PBS_Server;Job;14161.tyrone-cluster;Job Modified at request of Scheduler@tyrone-cluster
11/18/2012 17:23:51;0008;PBS_Server;Job;14161.tyrone-cluster;Job Run at request of Scheduler@tyrone-cluster
11/18/2012 17:23:51;0040;PBS_Server;Svr;tyrone-cluster;Scheduler was sent the command recyc
11/18/2012 17:23:51;000d;PBS_Server;Job;14161.tyrone-cluster;Not sending email: User does not want mail of this type.
11/18/2012 17:23:52;0040;PBS_Server;Svr;tyrone-cluster;Scheduler was sent the command new
11/18/2012 17:23:53;0100;PBS_Server;Job;14162.tyrone-cluster;enqueuing into batch, state 1 hop 1
11/18/2012 17:23:53;0100;PBS_Server;Job;14162.tyrone-cluster;dequeuing from batch, state QUEUED
11/18/2012 17:23:53;0100;PBS_Server;Job;14162.tyrone-cluster;enqueuing into idqueue, state 1 hop 1
11/18/2012 17:23:53;0008;PBS_Server;Job;14162.tyrone-cluster;Job Queued at request of seckriti@tyrone-cluster, owner = seckriti@tyrone-cluster, job name = myjob, queue = idqueue
11/18/2012 17:23:53;0040;PBS_Server;Svr;tyrone-cluster;Scheduler was sent the command new
11/18/2012 17:23:54;0008;PBS_Server;Job;14162.tyrone-cluster;Job Modified at request of Scheduler@tyrone-cluster
11/18/2012 17:23:54;0008;PBS_Server;Job;14162.tyrone-cluster;Job Run at request of Scheduler@tyrone-cluster
11/18/2012 17:23:54;0040;PBS_Server;Svr;tyrone-cluster;Scheduler was sent the command recyc
11/18/2012 17:23:54;000d;PBS_Server;Job;14162.tyrone-cluster;Not sending email: User does not want mail of this type.
11/18/2012 17:23:56;0100;PBS_Server;Job;14163.tyrone-cluster;enqueuing into batch, state 1 hop 1
11/18/2012 17:23:56;0100;PBS_Server;Job;14163.tyrone-cluster;dequeuing from batch, state QUEUED
11/18/2012 17:23:56;0100;PBS_Server;Job;14163.tyrone-cluster;enqueuing into idqueue, state 1 hop 1
11/18/2012 17:23:56;0008;PBS_Server;Job;14163.tyrone-cluster;Job Queued at request of seckriti@tyrone-cluster, owner = seckriti@tyrone-cluster, job name = myjob, queue = idqueue
11/18/2012 17:23:56;0040;PBS_Server;Svr;tyrone-cluster;Scheduler was sent the command new
11/18/2012 17:23:56;0008;PBS_Server;Job;14163.tyrone-cluster;Job Modified at request of Scheduler@tyrone-cluster
11/18/2012 17:24:22;0040;PBS_Server;Svr;tyrone-cluster;Scheduler was sent the command new
11/18/2012 17:24:52;0040;PBS_Server;Svr;tyrone-cluster;Scheduler was sent the command new
11/18/2012 17:25:22;0040;PBS_Server;Svr;tyrone-cluster;Scheduler was sent the command new
11/18/2012 17:25:52;0040;PBS_Server;Svr;tyrone-cluster;Scheduler was sent the command new
11/18/2012 17:26:22;0040;PBS_Server;Svr;tyrone-cluster;Scheduler was sent the command new
11/18/2012 17:26:52;0040;PBS_Server;Svr;tyrone-cluster;Scheduler was sent the command new
11/18/2012 17:27:09;0100;PBS_Server;Job;14164.tyrone-cluster;enqueuing into batch, state 1 hop 1
11/18/2012 17:27:09;0100;PBS_Server;Job;14164.tyrone-cluster;dequeuing from batch, state QUEUED
11/18/2012 17:27:09;0100;PBS_Server;Job;14164.tyrone-cluster;enqueuing into idqueue, state 1 hop 1
11/18/2012 17:27:09;0008;PBS_Server;Job;14164.tyrone-cluster;Job Queued at request of secpka@tyrone-cluster, owner = secpka@tyrone-cluster, job name = myjob, queue = idqueue
11/18/2012 17:27:09;0040;PBS_Server;Svr;tyrone-cluster;Scheduler was sent the command new
11/18/2012 17:27:09;0008;PBS_Server;Job;14164.tyrone-cluster;Job Modified at request of Scheduler@tyrone-cluster
11/18/2012 17:27:09;0008;PBS_Server;Job;14164.tyrone-cluster;Job Run at request of Scheduler@tyrone-cluster
11/18/2012 17:27:10;0040;PBS_Server;Svr;tyrone-cluster;Scheduler was sent the command recyc
11/18/2012 17:27:10;000d;PBS_Server;Job;14164.tyrone-cluster;Not sending email: User does not want mail of this type.
11/18/2012 17:27:10;000d;PBS_Server;Job;14164.tyrone-cluster;Not sending email: User does not want mail of this type.
11/18/2012 17:27:10;0010;PBS_Server;Job;14164.tyrone-cluster;Exit_status=139 resources_used.cput=00:00:00 resources_used.mem=0kb resources_used.vmem=0kb resources_used.walltime=00:00:01
11/18/2012 17:27:10;0008;PBS_Server;Job;NULL;on_job_exit valid pjob: 0x134e980 (substate=50)
11/18/2012 17:27:10;0008;PBS_Server;Job;NULL;on_job_exit valid pjob: 0x134e980 (substate=51)
11/18/2012 17:27:10;0008;PBS_Server;Job;NULL;on_job_exit valid pjob: 0x134e980 (substate=51)
11/18/2012 17:27:10;0008;PBS_Server;Job;NULL;on_job_exit valid pjob: 0x134e980 (substate=53)
11/18/2012 17:27:10;0100;PBS_Server;Job;14164.tyrone-cluster;dequeuing from idqueue, state COMPLETE
11/18/2012 17:27:10;0040;PBS_Server;Svr;tyrone-cluster;Scheduler was sent the command term
11/18/2012 17:27:22;0040;PBS_Server;Svr;tyrone-cluster;Scheduler was sent the command new
11/18/2012 17:27:52;0040;PBS_Server;Svr;tyrone-cluster;Scheduler was sent the command new
11/18/2012 17:28:22;0040;PBS_Server;Svr;tyrone-cluster;Scheduler was sent the command new
11/18/2012 17:28:30;0100;PBS_Server;Job;14165.tyrone-cluster;enqueuing into batch, state 1 hop 1
11/18/2012 17:28:30;0100;PBS_Server;Job;14165.tyrone-cluster;dequeuing from batch, state QUEUED
11/18/2012 17:28:30;0100;PBS_Server;Job;14165.tyrone-cluster;enqueuing into idqueue, state 1 hop 1
11/18/2012 17:28:30;0008;PBS_Server;Job;14165.tyrone-cluster;Job Queued at request of secpka@tyrone-cluster, owner = secpka@tyrone-cluster, job name = myjob, queue = idqueue
11/18/2012 17:28:30;0040;PBS_Server;Svr;tyrone-cluster;Scheduler was sent the command new
11/18/2012 17:28:30;0008;PBS_Server;Job;14165.tyrone-cluster;Job Modified at request of Scheduler@tyrone-cluster
11/18/2012 17:28:30;0008;PBS_Server;Job;14165.tyrone-cluster;Job Run at request of Scheduler@tyrone-cluster
11/18/2012 17:28:31;0040;PBS_Server;Svr;tyrone-cluster;Scheduler was sent the command recyc
11/18/2012 17:28:31;000d;PBS_Server;Job;14165.tyrone-cluster;Not sending email: User does not want mail of this type.
11/18/2012 17:28:31;000d;PBS_Server;Job;14165.tyrone-cluster;Not sending email: User does not want mail of this type.
11/18/2012 17:28:31;0010;PBS_Server;Job;14165.tyrone-cluster;Exit_status=139 resources_used.cput=00:00:00 resources_used.mem=0kb resources_used.vmem=0kb resources_used.walltime=00:00:01
11/18/2012 17:28:31;0008;PBS_Server;Job;NULL;on_job_exit valid pjob: 0x134e980 (substate=50)
11/18/2012 17:28:31;0008;PBS_Server;Job;NULL;on_job_exit valid pjob: 0x134e980 (substate=51)
11/18/2012 17:28:31;0008;PBS_Server;Job;NULL;on_job_exit valid pjob: 0x134e980 (substate=51)
11/18/2012 17:28:31;0008;PBS_Server;Job;NULL;on_job_exit valid pjob: 0x134e980 (substate=53)
11/18/2012 17:28:31;0100;PBS_Server;Job;14165.tyrone-cluster;dequeuing from idqueue, state COMPLETE
11/18/2012 17:28:31;0040;PBS_Server;Svr;tyrone-cluster;Scheduler was sent the command term
11/18/2012 17:28:49;0002;PBS_Server;Svr;PBS_Server;Torque Server Version = 3.0.5, loglevel = 0
11/18/2012 17:28:52;0040;PBS_Server;Svr;tyrone-cluster;Scheduler was sent the command new
11/18/2012 17:29:22;0040;PBS_Server;Svr;tyrone-cluster;Scheduler was sent the command new
11/18/2012 17:29:52;0040;PBS_Server;Svr;tyrone-cluster;Scheduler was sent the command new
11/18/2012 17:30:17;0100;PBS_Server;Job;14166.tyrone-cluster;enqueuing into batch, state 1 hop 1
11/18/2012 17:30:17;0100;PBS_Server;Job;14166.tyrone-cluster;dequeuing from batch, state QUEUED
11/18/2012 17:30:17;0100;PBS_Server;Job;14166.tyrone-cluster;enqueuing into idqueue, state 1 hop 1
11/18/2012 17:30:17;0008;PBS_Server;Job;14166.tyrone-cluster;Job Queued at request of secpka@tyrone-cluster, owner = secpka@tyrone-cluster, job name = myjob, queue = idqueue
11/18/2012 17:30:17;0040;PBS_Server;Svr;tyrone-cluster;Scheduler was sent the command new
11/18/2012 17:30:17;0008;PBS_Server;Job;14166.tyrone-cluster;Job Modified at request of Scheduler@tyrone-cluster
11/18/2012 17:30:17;0008;PBS_Server;Job;14166.tyrone-cluster;Job Run at request of Scheduler@tyrone-cluster
11/18/2012 17:30:17;0040;PBS_Server;Svr;tyrone-cluster;Scheduler was sent the command recyc
11/18/2012 17:30:17;000d;PBS_Server;Job;14166.tyrone-cluster;Not sending email: User does not want mail of this type.
11/18/2012 17:30:18;000d;PBS_Server;Job;14166.tyrone-cluster;Not sending email: User does not want mail of this type.
11/18/2012 17:30:18;0010;PBS_Server;Job;14166.tyrone-cluster;Exit_status=0 resources_used.cput=00:00:07 resources_used.mem=0kb resources_used.vmem=0kb resources_used.walltime=00:00:01
11/18/2012 17:30:18;0008;PBS_Server;Job;NULL;on_job_exit valid pjob: 0x134e980 (substate=50)
11/18/2012 17:30:18;0008;PBS_Server;Job;NULL;on_job_exit valid pjob: 0x134e980 (substate=51)
11/18/2012 17:30:19;0008;PBS_Server;Job;NULL;on_job_exit valid pjob: 0x134e980 (substate=51)
11/18/2012 17:30:19;0008;PBS_Server;Job;NULL;on_job_exit valid pjob: 0x134e980 (substate=53)
11/18/2012 17:30:19;0100;PBS_Server;Job;14166.tyrone-cluster;dequeuing from idqueue, state COMPLETE
11/18/2012 17:30:19;0040;PBS_Server;Svr;tyrone-cluster;Scheduler was sent the command term
11/18/2012 17:30:22;0040;PBS_Server;Svr;tyrone-cluster;Scheduler was sent the command new
11/18/2012 17:30:53;0040;PBS_Server;Svr;tyrone-cluster;Scheduler was sent the command new
11/18/2012 17:31:22;0040;PBS_Server;Svr;tyrone-cluster;Scheduler was sent the command new
11/18/2012 17:31:52;0040;PBS_Server;Svr;tyrone-cluster;Scheduler was sent the command new
11/18/2012 17:32:00;0100;PBS_Server;Job;14167.tyrone-cluster;enqueuing into batch, state 1 hop 1
11/18/2012 17:32:00;0100;PBS_Server;Job;14167.tyrone-cluster;dequeuing from batch, state QUEUED
11/18/2012 17:32:00;0100;PBS_Server;Job;14167.tyrone-cluster;enqueuing into idqueue, state 1 hop 1
11/18/2012 17:32:00;0008;PBS_Server;Job;14167.tyrone-cluster;Job Queued at request of secvkm@tyrone-cluster, owner = secvkm@tyrone-cluster, job name = myjob, queue = idqueue
11/18/2012 17:32:00;0040;PBS_Server;Svr;tyrone-cluster;Scheduler was sent the command new
11/18/2012 17:32:00;0008;PBS_Server;Job;14167.tyrone-cluster;Job Modified at request of Scheduler@tyrone-cluster
11/18/2012 17:32:00;0008;PBS_Server;Job;14167.tyrone-cluster;Job Run at request of Scheduler@tyrone-cluster
11/18/2012 17:32:00;0040;PBS_Server;Svr;tyrone-cluster;Scheduler was sent the command recyc
11/18/2012 17:32:00;000d;PBS_Server;Job;14167.tyrone-cluster;Not sending email: User does not want mail of this type.
11/18/2012 17:32:01;0100;PBS_Server;Job;14168.tyrone-cluster;enqueuing into batch, state 1 hop 1
11/18/2012 17:32:01;0100;PBS_Server;Job;14168.tyrone-cluster;dequeuing from batch, state QUEUED
11/18/2012 17:32:01;0100;PBS_Server;Job;14168.tyrone-cluster;enqueuing into idqueue, state 1 hop 1
11/18/2012 17:32:01;0008;PBS_Server;Job;14168.tyrone-cluster;Job Queued at request of secvkm@tyrone-cluster, owner = secvkm@tyrone-cluster, job name = myjob, queue = idqueue
11/18/2012 17:32:01;0040;PBS_Server;Svr;tyrone-cluster;Scheduler was sent the command new
11/18/2012 17:32:01;0008;PBS_Server;Job;14168.tyrone-cluster;Job Modified at request of Scheduler@tyrone-cluster
11/18/2012 17:32:01;0008;PBS_Server;Job;14168.tyrone-cluster;Job Run at request of Scheduler@tyrone-cluster
11/18/2012 17:32:01;0040;PBS_Server;Svr;tyrone-cluster;Scheduler was sent the command recyc
11/18/2012 17:32:01;000d;PBS_Server;Job;14168.tyrone-cluster;Not sending email: User does not want mail of this type.
11/18/2012 17:32:02;0100;PBS_Server;Job;14169.tyrone-cluster;enqueuing into batch, state 1 hop 1
11/18/2012 17:32:02;0100;PBS_Server;Job;14169.tyrone-cluster;dequeuing from batch, state QUEUED
11/18/2012 17:32:02;0100;PBS_Server;Job;14169.tyrone-cluster;enqueuing into idqueue, state 1 hop 1
11/18/2012 17:32:02;0008;PBS_Server;Job;14169.tyrone-cluster;Job Queued at request of secvkm@tyrone-cluster, owner = secvkm@tyrone-cluster, job name = myjob, queue = idqueue
11/18/2012 17:32:02;0040;PBS_Server;Svr;tyrone-cluster;Scheduler was sent the command new
11/18/2012 17:32:02;0008;PBS_Server;Job;14169.tyrone-cluster;Job Modified at request of Scheduler@tyrone-cluster
11/18/2012 17:32:03;0100;PBS_Server;Job;14170.tyrone-cluster;enqueuing into batch, state 1 hop 1
11/18/2012 17:32:03;0100;PBS_Server;Job;14170.tyrone-cluster;dequeuing from batch, state QUEUED
11/18/2012 17:32:03;0100;PBS_Server;Job;14170.tyrone-cluster;enqueuing into idqueue, state 1 hop 1
11/18/2012 17:32:03;0008;PBS_Server;Job;14170.tyrone-cluster;Job Queued at request of secvkm@tyrone-cluster, owner = secvkm@tyrone-cluster, job name = myjob, queue = idqueue
11/18/2012 17:32:03;0040;PBS_Server;Svr;tyrone-cluster;Scheduler was sent the command new
11/18/2012 17:32:03;0008;PBS_Server;Job;14170.tyrone-cluster;Job Modified at request of Scheduler@tyrone-cluster
11/18/2012 17:32:03;0100;PBS_Server;Job;14171.tyrone-cluster;enqueuing into batch, state 1 hop 1
11/18/2012 17:32:03;0100;PBS_Server;Job;14171.tyrone-cluster;dequeuing from batch, state QUEUED
11/18/2012 17:32:03;0100;PBS_Server;Job;14171.tyrone-cluster;enqueuing into idqueue, state 1 hop 1
11/18/2012 17:32:03;0008;PBS_Server;Job;14171.tyrone-cluster;Job Queued at request of secvkm@tyrone-cluster, owner = secvkm@tyrone-cluster, job name = myjob, queue = idqueue
11/18/2012 17:32:03;0040;PBS_Server;Svr;tyrone-cluster;Scheduler was sent the command new
11/18/2012 17:32:03;0008;PBS_Server;Job;14171.tyrone-cluster;Job Modified at request of Scheduler@tyrone-cluster
11/18/2012 17:32:22;0040;PBS_Server;Svr;tyrone-cluster;Scheduler was sent the command new
11/18/2012 17:32:52;0040;PBS_Server;Svr;tyrone-cluster;Scheduler was sent the command new
11/18/2012 17:32:58;0100;PBS_Server;Job;14172.tyrone-cluster;enqueuing into batch, state 1 hop 1
11/18/2012 17:32:58;0100;PBS_Server;Job;14172.tyrone-cluster;dequeuing from batch, state QUEUED
11/18/2012 17:32:58;0100;PBS_Server;Job;14172.tyrone-cluster;enqueuing into idqueue, state 1 hop 1
11/18/2012 17:32:58;0008;PBS_Server;Job;14172.tyrone-cluster;Job Queued at request of secbadar@tyrone-cluster, owner = secbadar@tyrone-cluster, job name = myjob, queue = idqueue
11/18/2012 17:32:58;0040;PBS_Server;Svr;tyrone-cluster;Scheduler was sent the command new
11/18/2012 17:32:58;0008;PBS_Server;Job;14172.tyrone-cluster;Job Modified at request of Scheduler@tyrone-cluster
11/18/2012 17:33:22;0040;PBS_Server;Svr;tyrone-cluster;Scheduler was sent the command new
11/18/2012 17:33:49;0002;PBS_Server;Svr;PBS_Server;Torque Server Version = 3.0.5, loglevel = 0
11/18/2012 17:33:52;0040;PBS_Server;Svr;tyrone-cluster;Scheduler was sent the command new
11/18/2012 17:34:22;0040;PBS_Server;Svr;tyrone-cluster;Scheduler was sent the command new
11/18/2012 17:34:52;0040;PBS_Server;Svr;tyrone-cluster;Scheduler was sent the command new
11/18/2012 17:34:58;0100;PBS_Server;Job;14173.tyrone-cluster;enqueuing into batch, state 1 hop 1
11/18/2012 17:34:58;0100;PBS_Server;Job;14173.tyrone-cluster;dequeuing from batch, state QUEUED
11/18/2012 17:34:58;0100;PBS_Server;Job;14173.tyrone-cluster;enqueuing into idqueue, state 1 hop 1
11/18/2012 17:34:58;0008;PBS_Server;Job;14173.tyrone-cluster;Job Queued at request of secjagvi@tyrone-cluster, owner = secjagvi@tyrone-cluster, job name = myjob, queue = idqueue
11/18/2012 17:34:58;0040;PBS_Server;Svr;tyrone-cluster;Scheduler was sent the command new
11/18/2012 17:34:58;0008;PBS_Server;Job;14173.tyrone-cluster;Job Modified at request of Scheduler@tyrone-cluster
11/18/2012 17:35:00;0100;PBS_Server;Job;14174.tyrone-cluster;enqueuing into batch, state 1 hop 1
11/18/2012 17:35:00;0100;PBS_Server;Job;14174.tyrone-cluster;dequeuing from batch, state QUEUED
11/18/2012 17:35:00;0100;PBS_Server;Job;14174.tyrone-cluster;enqueuing into idqueue, state 1 hop 1
11/18/2012 17:35:00;0008;PBS_Server;Job;14174.tyrone-cluster;Job Queued at request of secbadar@tyrone-cluster, owner = secbadar@tyrone-cluster, job name = myjob, queue = idqueue
11/18/2012 17:35:00;0040;PBS_Server;Svr;tyrone-cluster;Scheduler was sent the command new
11/18/2012 17:35:00;0008;PBS_Server;Job;14174.tyrone-cluster;Job Modified at request of Scheduler@tyrone-cluster
11/18/2012 17:35:23;0040;PBS_Server;Svr;tyrone-cluster;Scheduler was sent the command new
11/18/2012 17:35:52;0040;PBS_Server;Svr;tyrone-cluster;Scheduler was sent the command new
11/18/2012 17:36:22;0040;PBS_Server;Svr;tyrone-cluster;Scheduler was sent the command new
11/18/2012 17:36:52;0040;PBS_Server;Svr;tyrone-cluster;Scheduler was sent the command new
11/18/2012 17:37:06;000d;PBS_Server;Job;14168.tyrone-cluster;Not sending email: User does not want mail of this type.
11/18/2012 17:37:06;0010;PBS_Server;Job;14168.tyrone-cluster;Exit_status=0 resources_used.cput=00:17:14 resources_used.mem=5422668kb resources_used.vmem=10784592kb resources_used.walltime=00:05:05
11/18/2012 17:37:06;0008;PBS_Server;Job;NULL;on_job_exit valid pjob: 0x13f2680 (substate=50)
11/18/2012 17:37:06;0008;PBS_Server;Job;NULL;on_job_exit valid pjob: 0x13f2680 (substate=51)
11/18/2012 17:37:06;0008;PBS_Server;Job;NULL;on_job_exit valid pjob: 0x13f2680 (substate=51)
11/18/2012 17:37:06;0008;PBS_Server;Job;NULL;on_job_exit valid pjob: 0x13f2680 (substate=53)
11/18/2012 17:37:06;0100;PBS_Server;Job;14168.tyrone-cluster;dequeuing from idqueue, state COMPLETE
11/18/2012 17:37:06;0040;PBS_Server;Svr;tyrone-cluster;Scheduler was sent the command term
11/18/2012 17:37:06;0008;PBS_Server;Job;14169.tyrone-cluster;Job Modified at request of Scheduler@tyrone-cluster
11/18/2012 17:37:06;0008;PBS_Server;Job;14169.tyrone-cluster;Job Run at request of Scheduler@tyrone-cluster
11/18/2012 17:37:06;000d;PBS_Server;Job;14169.tyrone-cluster;Not sending email: User does not want mail of this type.
11/18/2012 17:37:06;0040;PBS_Server;Svr;tyrone-cluster;Scheduler was sent the command recyc
11/18/2012 17:37:13;000d;PBS_Server;Job;14167.tyrone-cluster;Not sending email: User does not want mail of this type.
11/18/2012 17:37:13;0010;PBS_Server;Job;14167.tyrone-cluster;Exit_status=0 resources_used.cput=00:18:28 resources_used.mem=5422668kb resources_used.vmem=10784592kb resources_used.walltime=00:05:13
11/18/2012 17:37:13;0008;PBS_Server;Job;NULL;on_job_exit valid pjob: 0x134e980 (substate=50)
11/18/2012 17:37:13;0008;PBS_Server;Job;NULL;on_job_exit valid pjob: 0x134e980 (substate=51)
11/18/2012 17:37:13;0008;PBS_Server;Job;NULL;on_job_exit valid pjob: 0x134e980 (substate=51)
11/18/2012 17:37:13;0008;PBS_Server;Job;NULL;on_job_exit valid pjob: 0x134e980 (substate=53)
11/18/2012 17:37:13;0100;PBS_Server;Job;14167.tyrone-cluster;dequeuing from idqueue, state COMPLETE
11/18/2012 17:37:13;0040;PBS_Server;Svr;tyrone-cluster;Scheduler was sent the command term
11/18/2012 17:37:14;0008;PBS_Server;Job;14170.tyrone-cluster;Job Modified at request of Scheduler@tyrone-cluster
11/18/2012 17:37:14;0008;PBS_Server;Job;14170.tyrone-cluster;Job Run at request of Scheduler@tyrone-cluster
11/18/2012 17:37:14;000d;PBS_Server;Job;14170.tyrone-cluster;Not sending email: User does not want mail of this type.
11/18/2012 17:37:14;0040;PBS_Server;Svr;tyrone-cluster;Scheduler was sent the command recyc
11/18/2012 17:37:22;0040;PBS_Server;Svr;tyrone-cluster;Scheduler was sent the command new
11/18/2012 17:37:52;0040;PBS_Server;Svr;tyrone-cluster;Scheduler was sent the command new
11/18/2012 17:38:22;0040;PBS_Server;Svr;tyrone-cluster;Scheduler was sent the command new
11/18/2012 17:38:49;0002;PBS_Server;Svr;PBS_Server;Torque Server Version = 3.0.5, loglevel = 0
11/18/2012 17:38:52;0040;PBS_Server;Svr;tyrone-cluster;Scheduler was sent the command new
11/18/2012 17:39:22;0040;PBS_Server;Svr;tyrone-cluster;Scheduler was sent the command new
11/18/2012 17:39:53;0040;PBS_Server;Svr;tyrone-cluster;Scheduler was sent the command new
11/18/2012 17:40:22;0040;PBS_Server;Svr;tyrone-cluster;Scheduler was sent the command new
11/18/2012 17:40:52;0040;PBS_Server;Svr;tyrone-cluster;Scheduler was sent the command new
11/18/2012 17:41:22;0040;PBS_Server;Svr;tyrone-cluster;Scheduler was sent the command new
11/18/2012 17:41:52;0040;PBS_Server;Svr;tyrone-cluster;Scheduler was sent the command new
11/18/2012 17:42:00;000d;PBS_Server;Job;14169.tyrone-cluster;Not sending email: User does not want mail of this type.
11/18/2012 17:42:00;0010;PBS_Server;Job;14169.tyrone-cluster;Exit_status=0 resources_used.cput=00:15:06 resources_used.mem=3748368kb resources_used.vmem=7170860kb resources_used.walltime=00:04:54
11/18/2012 17:42:00;0008;PBS_Server;Job;NULL;on_job_exit valid pjob: 0x1314c50 (substate=50)
11/18/2012 17:42:00;0008;PBS_Server;Job;NULL;on_job_exit valid pjob: 0x1314c50 (substate=51)
11/18/2012 17:42:01;0008;PBS_Server;Job;NULL;on_job_exit valid pjob: 0x1314c50 (substate=51)
11/18/2012 17:42:01;0008;PBS_Server;Job;NULL;on_job_exit valid pjob: 0x1314c50 (substate=53)
11/18/2012 17:42:01;0100;PBS_Server;Job;14169.tyrone-cluster;dequeuing from idqueue, state COMPLETE
11/18/2012 17:42:01;0040;PBS_Server;Svr;tyrone-cluster;Scheduler was sent the command term
11/18/2012 17:42:01;0008;PBS_Server;Job;14171.tyrone-cluster;Job Modified at request of Scheduler@tyrone-cluster
11/18/2012 17:42:01;0008;PBS_Server;Job;14171.tyrone-cluster;Job Run at request of Scheduler@tyrone-cluster
11/18/2012 17:42:01;0040;PBS_Server;Svr;tyrone-cluster;Scheduler was sent the command recyc
11/18/2012 17:42:01;000d;PBS_Server;Job;14171.tyrone-cluster;Not sending email: User does not want mail of this type.
11/18/2012 17:42:08;000d;PBS_Server;Job;14170.tyrone-cluster;Not sending email: User does not want mail of this type.
11/18/2012 17:42:08;0010;PBS_Server;Job;14170.tyrone-cluster;Exit_status=0 resources_used.cput=00:15:12 resources_used.mem=5422684kb resources_used.vmem=10784592kb resources_used.walltime=00:04:54
11/18/2012 17:42:08;0008;PBS_Server;Job;NULL;on_job_exit valid pjob: 0x132ff00 (substate=50)
11/18/2012 17:42:08;0008;PBS_Server;Job;NULL;on_job_exit valid pjob: 0x132ff00 (substate=51)
11/18/2012 17:42:08;0008;PBS_Server;Job;NULL;on_job_exit valid pjob: 0x132ff00 (substate=51)
11/18/2012 17:42:08;0008;PBS_Server;Job;NULL;on_job_exit valid pjob: 0x132ff00 (substate=53)
11/18/2012 17:42:08;0100;PBS_Server;Job;14170.tyrone-cluster;dequeuing from idqueue, state COMPLETE
11/18/2012 17:42:08;0040;PBS_Server;Svr;tyrone-cluster;Scheduler was sent the command term
11/18/2012 17:42:08;0008;PBS_Server;Job;14172.tyrone-cluster;Job Modified at request of Scheduler@tyrone-cluster
11/18/2012 17:42:08;0008;PBS_Server;Job;14172.tyrone-cluster;Job Run at request of Scheduler@tyrone-cluster
11/18/2012 17:42:09;0040;PBS_Server;Svr;tyrone-cluster;Scheduler was sent the command recyc
11/18/2012 17:42:09;000d;PBS_Server;Job;14172.tyrone-cluster;Not sending email: User does not want mail of this type.
11/18/2012 17:42:22;0040;PBS_Server;Svr;tyrone-cluster;Scheduler was sent the command new
11/18/2012 17:42:53;0040;PBS_Server;Svr;tyrone-cluster;Scheduler was sent the command new
11/18/2012 17:43:23;0040;PBS_Server;Svr;tyrone-cluster;Scheduler was sent the command new
11/18/2012 17:43:49;0002;PBS_Server;Svr;PBS_Server;Torque Server Version = 3.0.5, loglevel = 0
11/18/2012 17:43:53;0040;PBS_Server;Svr;tyrone-cluster;Scheduler was sent the command new
11/18/2012 17:44:23;0040;PBS_Server;Svr;tyrone-cluster;Scheduler was sent the command new
11/18/2012 17:44:53;0040;PBS_Server;Svr;tyrone-cluster;Scheduler was sent the command new
11/18/2012 17:45:23;0040;PBS_Server;Svr;tyrone-cluster;Scheduler was sent the command new
11/18/2012 17:45:53;0040;PBS_Server;Svr;tyrone-cluster;Scheduler was sent the command new
11/18/2012 17:46:23;0040;PBS_Server;Svr;tyrone-cluster;Scheduler was sent the command new
11/18/2012 17:46:53;0040;PBS_Server;Svr;tyrone-cluster;Scheduler was sent the command new
11/18/2012 17:47:06;000d;PBS_Server;Job;14171.tyrone-cluster;Not sending email: User does not want mail of this type.
11/18/2012 17:47:06;0010;PBS_Server;Job;14171.tyrone-cluster;Exit_status=0 resources_used.cput=00:16:55 resources_used.mem=5422680kb resources_used.vmem=10784592kb resources_used.walltime=00:05:05
11/18/2012 17:47:06;0008;PBS_Server;Job;NULL;on_job_exit valid pjob: 0x12fb1f0 (substate=50)
11/18/2012 17:47:06;0008;PBS_Server;Job;NULL;on_job_exit valid pjob: 0x12fb1f0 (substate=51)
11/18/2012 17:47:06;0008;PBS_Server;Job;NULL;on_job_exit valid pjob: 0x12fb1f0 (substate=51)
11/18/2012 17:47:06;0008;PBS_Server;Job;NULL;on_job_exit valid pjob: 0x12fb1f0 (substate=53)
11/18/2012 17:47:06;0100;PBS_Server;Job;14171.tyrone-cluster;dequeuing from idqueue, state COMPLETE
11/18/2012 17:47:06;0040;PBS_Server;Svr;tyrone-cluster;Scheduler was sent the command term
11/18/2012 17:47:06;0008;PBS_Server;Job;14173.tyrone-cluster;Job Modified at request of Scheduler@tyrone-cluster
11/18/2012 17:47:06;0008;PBS_Server;Job;14173.tyrone-cluster;Job Run at request of Scheduler@tyrone-cluster
11/18/2012 17:47:07;000d;PBS_Server;Job;14173.tyrone-cluster;Not sending email: User does not want mail of this type.
11/18/2012 17:47:07;0040;PBS_Server;Svr;tyrone-cluster;Scheduler was sent the command recyc
11/18/2012 17:47:23;0040;PBS_Server;Svr;tyrone-cluster;Scheduler was sent the command new
11/18/2012 17:47:53;0040;PBS_Server;Svr;tyrone-cluster;Scheduler was sent the command new
11/18/2012 17:48:23;0040;PBS_Server;Svr;tyrone-cluster;Scheduler was sent the command new
11/18/2012 17:48:49;0002;PBS_Server;Svr;PBS_Server;Torque Server Version = 3.0.5, loglevel = 0
11/18/2012 17:48:53;0040;PBS_Server;Svr;tyrone-cluster;Scheduler was sent the command new
11/18/2012 17:49:23;0040;PBS_Server;Svr;tyrone-cluster;Scheduler was sent the command new
11/18/2012 17:49:53;0040;PBS_Server;Svr;tyrone-cluster;Scheduler was sent the command new
11/18/2012 17:50:23;0040;PBS_Server;Svr;tyrone-cluster;Scheduler was sent the command new
11/18/2012 17:50:53;0040;PBS_Server;Svr;tyrone-cluster;Scheduler was sent the command new
11/18/2012 17:51:23;0040;PBS_Server;Svr;tyrone-cluster;Scheduler was sent the command new
11/18/2012 17:51:53;0040;PBS_Server;Svr;tyrone-cluster;Scheduler was sent the command new
11/18/2012 17:52:21;0008;PBS_Server;Job;14172.tyrone-cluster;Job deleted at request of secbadar@tyrone-cluster
11/18/2012 17:52:21;0008;PBS_Server;Job;14172.tyrone-cluster;Job sent signal SIGTERM on delete
11/18/2012 17:52:21;000d;PBS_Server;Job;14172.tyrone-cluster;Not sending email: User does not want mail of this type.
11/18/2012 17:52:21;0010;PBS_Server;Job;14172.tyrone-cluster;Exit_status=143 resources_used.cput=01:36:46 resources_used.mem=573084kb resources_used.vmem=1686744kb resources_used.walltime=00:10:13
11/18/2012 17:52:21;0008;PBS_Server;Job;NULL;on_job_exit valid pjob: 0x13fad70 (substate=50)
11/18/2012 17:52:21;0008;PBS_Server;Job;NULL;on_job_exit valid pjob: 0x13fad70 (substate=51)
11/18/2012 17:52:21;0008;PBS_Server;Job;NULL;on_job_exit valid pjob: 0x13fad70 (substate=51)
11/18/2012 17:52:21;0008;PBS_Server;Job;NULL;on_job_exit valid pjob: 0x13fad70 (substate=53)
11/18/2012 17:52:21;0100;PBS_Server;Job;14172.tyrone-cluster;dequeuing from idqueue, state COMPLETE
11/18/2012 17:52:21;0040;PBS_Server;Svr;tyrone-cluster;Scheduler was sent the command term
11/18/2012 17:52:21;0008;PBS_Server;Job;14174.tyrone-cluster;Job Modified at request of Scheduler@tyrone-cluster
11/18/2012 17:52:21;0008;PBS_Server;Job;14174.tyrone-cluster;Job Run at request of Scheduler@tyrone-cluster
11/18/2012 17:52:22;000d;PBS_Server;Job;14174.tyrone-cluster;Not sending email: User does not want mail of this type.
11/18/2012 17:52:22;0040;PBS_Server;Svr;tyrone-cluster;Scheduler was sent the command recyc
11/18/2012 17:52:24;0040;PBS_Server;Svr;tyrone-cluster;Scheduler was sent the command new
11/18/2012 17:52:27;000d;PBS_Server;Job;14173.tyrone-cluster;Not sending email: User does not want mail of this type.
11/18/2012 17:52:27;0010;PBS_Server;Job;14173.tyrone-cluster;Exit_status=0 resources_used.cput=00:16:03 resources_used.mem=468700kb resources_used.vmem=1582780kb resources_used.walltime=00:05:21
11/18/2012 17:52:27;0008;PBS_Server;Job;NULL;on_job_exit valid pjob: 0x13fc030 (substate=50)
11/18/2012 17:52:27;0008;PBS_Server;Job;NULL;on_job_exit valid pjob: 0x13fc030 (substate=51)
11/18/2012 17:52:28;0008;PBS_Server;Job;NULL;on_job_exit valid pjob: 0x13fc030 (substate=51)
11/18/2012 17:52:28;0008;PBS_Server;Job;NULL;on_job_exit valid pjob: 0x13fc030 (substate=53)
11/18/2012 17:52:28;0100;PBS_Server;Job;14173.tyrone-cluster;dequeuing from idqueue, state COMPLETE
11/18/2012 17:52:28;0040;PBS_Server;Svr;tyrone-cluster;Scheduler was sent the command term
11/18/2012 17:53:07;0040;PBS_Server;Svr;tyrone-cluster;Scheduler was sent the command new
11/18/2012 17:53:37;0040;PBS_Server;Svr;tyrone-cluster;Scheduler was sent the command new
11/18/2012 17:53:49;0002;PBS_Server;Svr;PBS_Server;Torque Server Version = 3.0.5, loglevel = 0
11/18/2012 17:54:08;0040;PBS_Server;Svr;tyrone-cluster;Scheduler was sent the command new
11/18/2012 17:54:37;0040;PBS_Server;Svr;tyrone-cluster;Scheduler was sent the command new
11/18/2012 17:55:07;0040;PBS_Server;Svr;tyrone-cluster;Scheduler was sent the command new
11/18/2012 17:55:37;0040;PBS_Server;Svr;tyrone-cluster;Scheduler was sent the command new
11/18/2012 17:56:07;0040;PBS_Server;Svr;tyrone-cluster;Scheduler was sent the command new
11/18/2012 17:56:37;0040;PBS_Server;Svr;tyrone-cluster;Scheduler was sent the command new
11/18/2012 17:57:07;0040;PBS_Server;Svr;tyrone-cluster;Scheduler was sent the command new
11/18/2012 17:57:37;0040;PBS_Server;Svr;tyrone-cluster;Scheduler was sent the command new
11/18/2012 17:58:07;0040;PBS_Server;Svr;tyrone-cluster;Scheduler was sent the command new
11/18/2012 17:58:38;0040;PBS_Server;Svr;tyrone-cluster;Scheduler was sent the command new
11/18/2012 17:58:49;0002;PBS_Server;Svr;PBS_Server;Torque Server Version = 3.0.5, loglevel = 0
11/18/2012 17:59:07;0040;PBS_Server;Svr;tyrone-cluster;Scheduler was sent the command new
11/18/2012 17:59:37;0040;PBS_Server;Svr;tyrone-cluster;Scheduler was sent the command new
11/18/2012 18:00:07;0040;PBS_Server;Svr;tyrone-cluster;Scheduler was sent the command new
11/18/2012 18:00:37;0040;PBS_Server;Svr;tyrone-cluster;Scheduler was sent the command new
11/18/2012 18:01:07;0040;PBS_Server;Svr;tyrone-cluster;Scheduler was sent the command new
11/18/2012 18:01:37;0040;PBS_Server;Svr;tyrone-cluster;Scheduler was sent the command new
11/18/2012 18:02:07;0040;PBS_Server;Svr;tyrone-cluster;Scheduler was sent the command new
11/18/2012 18:02:37;0040;PBS_Server;Svr;tyrone-cluster;Scheduler was sent the command new
11/18/2012 18:03:07;0040;PBS_Server;Svr;tyrone-cluster;Scheduler was sent the command new
11/18/2012 18:03:37;0040;PBS_Server;Svr;tyrone-cluster;Scheduler was sent the command new
11/18/2012 18:03:49;0002;PBS_Server;Svr;PBS_Server;Torque Server Version = 3.0.5, loglevel = 0
11/18/2012 18:04:07;0040;PBS_Server;Svr;tyrone-cluster;Scheduler was sent the command new
11/18/2012 18:04:38;0040;PBS_Server;Svr;tyrone-cluster;Scheduler was sent the command new
11/18/2012 18:05:07;0040;PBS_Server;Svr;tyrone-cluster;Scheduler was sent the command new
11/18/2012 18:05:08;0100;PBS_Server;Job;14175.tyrone-cluster;enqueuing into batch, state 1 hop 1
11/18/2012 18:05:08;0100;PBS_Server;Job;14175.tyrone-cluster;dequeuing from batch, state QUEUED
11/18/2012 18:05:08;0100;PBS_Server;Job;14175.tyrone-cluster;enqueuing into idqueue, state 1 hop 1
11/18/2012 18:05:08;0008;PBS_Server;Job;14175.tyrone-cluster;Job Queued at request of secvkm@tyrone-cluster, owner = secvkm@tyrone-cluster, job name = myjob, queue = idqueue
11/18/2012 18:05:08;0040;PBS_Server;Svr;tyrone-cluster;Scheduler was sent the command new
11/18/2012 18:05:08;0008;PBS_Server;Job;14175.tyrone-cluster;Job Modified at request of Scheduler@tyrone-cluster
11/18/2012 18:05:08;0008;PBS_Server;Job;14175.tyrone-cluster;Job Run at request of Scheduler@tyrone-cluster
11/18/2012 18:05:08;0040;PBS_Server;Svr;tyrone-cluster;Scheduler was sent the command recyc
11/18/2012 18:05:08;000d;PBS_Server;Job;14175.tyrone-cluster;Not sending email: User does not want mail of this type.
11/18/2012 18:05:09;0100;PBS_Server;Job;14176.tyrone-cluster;enqueuing into batch, state 1 hop 1
11/18/2012 18:05:09;0100;PBS_Server;Job;14176.tyrone-cluster;dequeuing from batch, state QUEUED
11/18/2012 18:05:09;0100;PBS_Server;Job;14176.tyrone-cluster;enqueuing into idqueue, state 1 hop 1
11/18/2012 18:05:09;0008;PBS_Server;Job;14176.tyrone-cluster;Job Queued at request of secvkm@tyrone-cluster, owner = secvkm@tyrone-cluster, job name = myjob, queue = idqueue
11/18/2012 18:05:09;0040;PBS_Server;Svr;tyrone-cluster;Scheduler was sent the command new
11/18/2012 18:05:09;0008;PBS_Server;Job;14176.tyrone-cluster;Job Modified at request of Scheduler@tyrone-cluster
11/18/2012 18:05:10;0100;PBS_Server;Job;14177.tyrone-cluster;enqueuing into batch, state 1 hop 1
11/18/2012 18:05:10;0100;PBS_Server;Job;14177.tyrone-cluster;dequeuing from batch, state QUEUED
11/18/2012 18:05:10;0100;PBS_Server;Job;14177.tyrone-cluster;enqueuing into idqueue, state 1 hop 1
11/18/2012 18:05:10;0008;PBS_Server;Job;14177.tyrone-cluster;Job Queued at request of secvkm@tyrone-cluster, owner = secvkm@tyrone-cluster, job name = myjob, queue = idqueue
11/18/2012 18:05:10;0040;PBS_Server;Svr;tyrone-cluster;Scheduler was sent the command new
11/18/2012 18:05:10;0008;PBS_Server;Job;14177.tyrone-cluster;Job Modified at request of Scheduler@tyrone-cluster
11/18/2012 18:05:10;0100;PBS_Server;Job;14178.tyrone-cluster;enqueuing into batch, state 1 hop 1
11/18/2012 18:05:10;0100;PBS_Server;Job;14178.tyrone-cluster;dequeuing from batch, state QUEUED
11/18/2012 18:05:10;0100;PBS_Server;Job;14178.tyrone-cluster;enqueuing into idqueue, state 1 hop 1
11/18/2012 18:05:10;0008;PBS_Server;Job;14178.tyrone-cluster;Job Queued at request of secvkm@tyrone-cluster, owner = secvkm@tyrone-cluster, job name = myjob, queue = idqueue
11/18/2012 18:05:10;0040;PBS_Server;Svr;tyrone-cluster;Scheduler was sent the command new
11/18/2012 18:05:10;0008;PBS_Server;Job;14178.tyrone-cluster;Job Modified at request of Scheduler@tyrone-cluster
11/18/2012 18:05:10;0100;PBS_Server;Job;14179.tyrone-cluster;enqueuing into batch, state 1 hop 1
11/18/2012 18:05:10;0100;PBS_Server;Job;14179.tyrone-cluster;dequeuing from batch, state QUEUED
11/18/2012 18:05:10;0100;PBS_Server;Job;14179.tyrone-cluster;enqueuing into idqueue, state 1 hop 1
11/18/2012 18:05:10;0008;PBS_Server;Job;14179.tyrone-cluster;Job Queued at request of secvkm@tyrone-cluster, owner = secvkm@tyrone-cluster, job name = myjob, queue = idqueue
11/18/2012 18:05:10;0040;PBS_Server;Svr;tyrone-cluster;Scheduler was sent the command new
11/18/2012 18:05:11;0100;PBS_Server;Job;14180.tyrone-cluster;enqueuing into batch, state 1 hop 1
11/18/2012 18:05:11;0100;PBS_Server;Job;14180.tyrone-cluster;dequeuing from batch, state QUEUED
11/18/2012 18:05:11;0100;PBS_Server;Job;14180.tyrone-cluster;enqueuing into idqueue, state 1 hop 1
11/18/2012 18:05:11;0008;PBS_Server;Job;14180.tyrone-cluster;Job Queued at request of secjagvi@tyrone-cluster, owner = secjagvi@tyrone-cluster, job name = myjob, queue = idqueue
11/18/2012 18:05:11;0008;PBS_Server;Job;14179.tyrone-cluster;Job Modified at request of Scheduler@tyrone-cluster
11/18/2012 18:05:11;0008;PBS_Server;Job;14180.tyrone-cluster;Job Modified at request of Scheduler@tyrone-cluster
11/18/2012 18:05:20;000d;PBS_Server;Job;14175.tyrone-cluster;Not sending email: User does not want mail of this type.
11/18/2012 18:05:20;0010;PBS_Server;Job;14175.tyrone-cluster;Exit_status=0 resources_used.cput=00:00:45 resources_used.mem=0kb resources_used.vmem=0kb resources_used.walltime=00:00:12
11/18/2012 18:05:20;0008;PBS_Server;Job;NULL;on_job_exit valid pjob: 0x134e980 (substate=50)
11/18/2012 18:05:20;0008;PBS_Server;Job;NULL;on_job_exit valid pjob: 0x134e980 (substate=51)
11/18/2012 18:05:20;0008;PBS_Server;Job;NULL;on_job_exit valid pjob: 0x134e980 (substate=51)
11/18/2012 18:05:20;0008;PBS_Server;Job;NULL;on_job_exit valid pjob: 0x134e980 (substate=53)
11/18/2012 18:05:20;0100;PBS_Server;Job;14175.tyrone-cluster;dequeuing from idqueue, state COMPLETE
11/18/2012 18:05:20;0040;PBS_Server;Svr;tyrone-cluster;Scheduler was sent the command term
11/18/2012 18:05:20;0008;PBS_Server;Job;14176.tyrone-cluster;Job Modified at request of Scheduler@tyrone-cluster
11/18/2012 18:05:20;0008;PBS_Server;Job;14176.tyrone-cluster;Job Run at request of Scheduler@tyrone-cluster
11/18/2012 18:05:20;000d;PBS_Server;Job;14176.tyrone-cluster;Not sending email: User does not want mail of this type.
11/18/2012 18:05:20;0040;PBS_Server;Svr;tyrone-cluster;Scheduler was sent the command recyc
11/18/2012 18:05:31;000d;PBS_Server;Job;14176.tyrone-cluster;Not sending email: User does not want mail of this type.
11/18/2012 18:05:31;0010;PBS_Server;Job;14176.tyrone-cluster;Exit_status=0 resources_used.cput=00:00:43 resources_used.mem=809896kb resources_used.vmem=1132396kb resources_used.walltime=00:00:11
11/18/2012 18:05:31;0008;PBS_Server;Job;NULL;on_job_exit valid pjob: 0x13f2680 (substate=50)
11/18/2012 18:05:31;0008;PBS_Server;Job;NULL;on_job_exit valid pjob: 0x13f2680 (substate=51)
11/18/2012 18:05:31;0008;PBS_Server;Job;NULL;on_job_exit valid pjob: 0x13f2680 (substate=51)
11/18/2012 18:05:31;0008;PBS_Server;Job;NULL;on_job_exit valid pjob: 0x13f2680 (substate=53)
11/18/2012 18:05:31;0100;PBS_Server;Job;14176.tyrone-cluster;dequeuing from idqueue, state COMPLETE
11/18/2012 18:05:31;0040;PBS_Server;Svr;tyrone-cluster;Scheduler was sent the command term
11/18/2012 18:05:31;0008;PBS_Server;Job;14177.tyrone-cluster;Job Modified at request of Scheduler@tyrone-cluster
11/18/2012 18:05:31;0008;PBS_Server;Job;14177.tyrone-cluster;Job Run at request of Scheduler@tyrone-cluster
11/18/2012 18:05:31;000d;PBS_Server;Job;14177.tyrone-cluster;Not sending email: User does not want mail of this type.
11/18/2012 18:05:31;0040;PBS_Server;Svr;tyrone-cluster;Scheduler was sent the command recyc
11/18/2012 18:05:37;0040;PBS_Server;Svr;tyrone-cluster;Scheduler was sent the command new
11/18/2012 18:05:42;000d;PBS_Server;Job;14177.tyrone-cluster;Not sending email: User does not want mail of this type.
11/18/2012 18:05:42;0010;PBS_Server;Job;14177.tyrone-cluster;Exit_status=0 resources_used.cput=00:00:42 resources_used.mem=0kb resources_used.vmem=0kb resources_used.walltime=00:00:11
11/18/2012 18:05:42;0008;PBS_Server;Job;NULL;on_job_exit valid pjob: 0x1314c50 (substate=50)
11/18/2012 18:05:42;0008;PBS_Server;Job;NULL;on_job_exit valid pjob: 0x1314c50 (substate=51)
11/18/2012 18:05:42;0008;PBS_Server;Job;NULL;on_job_exit valid pjob: 0x1314c50 (substate=51)
11/18/2012 18:05:42;0008;PBS_Server;Job;NULL;on_job_exit valid pjob: 0x1314c50 (substate=53)
11/18/2012 18:05:42;0100;PBS_Server;Job;14177.tyrone-cluster;dequeuing from idqueue, state COMPLETE
11/18/2012 18:05:42;0040;PBS_Server;Svr;tyrone-cluster;Scheduler was sent the command term
11/18/2012 18:05:43;0008;PBS_Server;Job;14178.tyrone-cluster;Job Modified at request of Scheduler@tyrone-cluster
11/18/2012 18:05:43;0008;PBS_Server;Job;14178.tyrone-cluster;Job Run at request of Scheduler@tyrone-cluster
11/18/2012 18:05:43;0040;PBS_Server;Svr;tyrone-cluster;Scheduler was sent the command recyc
11/18/2012 18:05:43;000d;PBS_Server;Job;14178.tyrone-cluster;Not sending email: User does not want mail of this type.
11/18/2012 18:05:54;000d;PBS_Server;Job;14178.tyrone-cluster;Not sending email: User does not want mail of this type.
11/18/2012 18:05:54;0010;PBS_Server;Job;14178.tyrone-cluster;Exit_status=0 resources_used.cput=00:00:42 resources_used.mem=0kb resources_used.vmem=0kb resources_used.walltime=00:00:11
11/18/2012 18:05:54;0008;PBS_Server;Job;NULL;on_job_exit valid pjob: 0x132ff00 (substate=50)
11/18/2012 18:05:54;0008;PBS_Server;Job;NULL;on_job_exit valid pjob: 0x132ff00 (substate=51)
11/18/2012 18:05:54;0008;PBS_Server;Job;NULL;on_job_exit valid pjob: 0x132ff00 (substate=51)
11/18/2012 18:05:54;0008;PBS_Server;Job;NULL;on_job_exit valid pjob: 0x132ff00 (substate=53)
11/18/2012 18:05:54;0100;PBS_Server;Job;14178.tyrone-cluster;dequeuing from idqueue, state COMPLETE
11/18/2012 18:05:54;0040;PBS_Server;Svr;tyrone-cluster;Scheduler was sent the command term
11/18/2012 18:05:54;0008;PBS_Server;Job;14179.tyrone-cluster;Job Modified at request of Scheduler@tyrone-cluster
11/18/2012 18:05:54;0008;PBS_Server;Job;14179.tyrone-cluster;Job Run at request of Scheduler@tyrone-cluster
11/18/2012 18:05:54;0040;PBS_Server;Svr;tyrone-cluster;Scheduler was sent the command recyc
11/18/2012 18:05:54;000d;PBS_Server;Job;14179.tyrone-cluster;Not sending email: User does not want mail of this type.
11/18/2012 18:06:05;000d;PBS_Server;Job;14179.tyrone-cluster;Not sending email: User does not want mail of this type.
11/18/2012 18:06:05;0010;PBS_Server;Job;14179.tyrone-cluster;Exit_status=0 resources_used.cput=00:00:43 resources_used.mem=0kb resources_used.vmem=0kb resources_used.walltime=00:00:11
11/18/2012 18:06:05;0008;PBS_Server;Job;NULL;on_job_exit valid pjob: 0x12fb1f0 (substate=50)
11/18/2012 18:06:05;0008;PBS_Server;Job;NULL;on_job_exit valid pjob: 0x12fb1f0 (substate=51)
11/18/2012 18:06:05;0008;PBS_Server;Job;NULL;on_job_exit valid pjob: 0x12fb1f0 (substate=51)
11/18/2012 18:06:05;0008;PBS_Server;Job;NULL;on_job_exit valid pjob: 0x12fb1f0 (substate=53)
11/18/2012 18:06:05;0100;PBS_Server;Job;14179.tyrone-cluster;dequeuing from idqueue, state COMPLETE
11/18/2012 18:06:05;0040;PBS_Server;Svr;tyrone-cluster;Scheduler was sent the command term
11/18/2012 18:06:05;0008;PBS_Server;Job;14180.tyrone-cluster;Job Modified at request of Scheduler@tyrone-cluster
11/18/2012 18:06:05;0008;PBS_Server;Job;14180.tyrone-cluster;Job Run at request of Scheduler@tyrone-cluster
11/18/2012 18:06:06;0040;PBS_Server;Svr;tyrone-cluster;Scheduler was sent the command recyc
11/18/2012 18:06:06;000d;PBS_Server;Job;14180.tyrone-cluster;Not sending email: User does not want mail of this type.
11/18/2012 18:06:08;0040;PBS_Server;Svr;tyrone-cluster;Scheduler was sent the command new
11/18/2012 18:06:29;0100;PBS_Server;Job;14181.tyrone-cluster;enqueuing into batch, state 1 hop 1
11/18/2012 18:06:29;0100;PBS_Server;Job;14181.tyrone-cluster;dequeuing from batch, state QUEUED
11/18/2012 18:06:29;0100;PBS_Server;Job;14181.tyrone-cluster;enqueuing into idqueue, state 1 hop 1
11/18/2012 18:06:29;0008;PBS_Server;Job;14181.tyrone-cluster;Job Queued at request of secjagvi@tyrone-cluster, owner = secjagvi@tyrone-cluster, job name = myjob, queue = idqueue
11/18/2012 18:06:29;0040;PBS_Server;Svr;tyrone-cluster;Scheduler was sent the command new
11/18/2012 18:06:29;0008;PBS_Server;Job;14181.tyrone-cluster;Job Modified at request of Scheduler@tyrone-cluster
11/18/2012 18:06:39;0040;PBS_Server;Svr;tyrone-cluster;Scheduler was sent the command new
11/18/2012 18:07:22;0040;PBS_Server;Svr;tyrone-cluster;Scheduler was sent the command new
11/18/2012 18:07:30;0100;PBS_Server;Job;14182.tyrone-cluster;enqueuing into batch, state 1 hop 1
11/18/2012 18:07:30;0100;PBS_Server;Job;14182.tyrone-cluster;dequeuing from batch, state QUEUED
11/18/2012 18:07:30;0100;PBS_Server;Job;14182.tyrone-cluster;enqueuing into idqueue, state 1 hop 1
11/18/2012 18:07:30;0008;PBS_Server;Job;14182.tyrone-cluster;Job Queued at request of secbadar@tyrone-cluster, owner = secbadar@tyrone-cluster, job name = myjob, queue = idqueue
11/18/2012 18:07:30;0040;PBS_Server;Svr;tyrone-cluster;Scheduler was sent the command new
11/18/2012 18:07:30;0008;PBS_Server;Job;14182.tyrone-cluster;Job Modified at request of Scheduler@tyrone-cluster
11/18/2012 18:07:52;0040;PBS_Server;Svr;tyrone-cluster;Scheduler was sent the command new
11/18/2012 18:08:23;0040;PBS_Server;Svr;tyrone-cluster;Scheduler was sent the command new
11/18/2012 18:08:49;0002;PBS_Server;Svr;PBS_Server;Torque Server Version = 3.0.5, loglevel = 0
11/18/2012 18:08:52;0040;PBS_Server;Svr;tyrone-cluster;Scheduler was sent the command new
11/18/2012 18:08:55;0100;PBS_Server;Job;14183.tyrone-cluster;enqueuing into batch, state 1 hop 1
11/18/2012 18:08:55;0100;PBS_Server;Job;14183.tyrone-cluster;dequeuing from batch, state QUEUED
11/18/2012 18:08:55;0100;PBS_Server;Job;14183.tyrone-cluster;enqueuing into idqueue, state 1 hop 1
11/18/2012 18:08:55;0008;PBS_Server;Job;14183.tyrone-cluster;Job Queued at request of secjagvi@tyrone-cluster, owner = secjagvi@tyrone-cluster, job name = myjob, queue = idqueue
11/18/2012 18:08:55;0040;PBS_Server;Svr;tyrone-cluster;Scheduler was sent the command new
11/18/2012 18:08:55;0008;PBS_Server;Job;14183.tyrone-cluster;Job Modified at request of Scheduler@tyrone-cluster
11/18/2012 18:09:22;0040;PBS_Server;Svr;tyrone-cluster;Scheduler was sent the command new
