12/24/2012 00:03:22;0002;PBS_Server;Svr;Log;Log opened
12/24/2012 00:03:22;0002;PBS_Server;Svr;PBS_Server;Torque Server Version = 3.0.5, loglevel = 0
12/24/2012 00:04:32;0100;PBS_Server;Job;17510.tyrone-cluster;enqueuing into batch, state 1 hop 1
12/24/2012 00:04:32;0002;PBS_Server;Svr;Act;Account file /var/spool/torque/server_priv/accounting/20121224 opened
12/24/2012 00:04:32;0100;PBS_Server;Job;17510.tyrone-cluster;dequeuing from batch, state QUEUED
12/24/2012 00:04:32;0100;PBS_Server;Job;17510.tyrone-cluster;enqueuing into qp32, state 1 hop 1
12/24/2012 00:04:32;0008;PBS_Server;Job;17510.tyrone-cluster;Job Queued at request of csdsuben@tyrone-cluster, owner = csdsuben@tyrone-cluster, job name = zr-cum-sime3, queue = qp32
12/24/2012 00:04:32;0040;PBS_Server;Svr;tyrone-cluster;Scheduler was sent the command new
12/24/2012 00:04:32;0008;PBS_Server;Job;17480.tyrone-cluster;Job Modified at request of Scheduler@tyrone-cluster
12/24/2012 00:04:32;0008;PBS_Server;Job;17423.tyrone-cluster;Job Modified at request of Scheduler@tyrone-cluster
12/24/2012 00:04:32;0008;PBS_Server;Job;17486.tyrone-cluster;Job Modified at request of Scheduler@tyrone-cluster
12/24/2012 00:04:32;0008;PBS_Server;Job;17487.tyrone-cluster;Job Modified at request of Scheduler@tyrone-cluster
12/24/2012 00:04:32;0008;PBS_Server;Job;17510.tyrone-cluster;Job Modified at request of Scheduler@tyrone-cluster
12/24/2012 00:08:22;0002;PBS_Server;Svr;PBS_Server;Torque Server Version = 3.0.5, loglevel = 0
12/24/2012 00:09:47;0100;PBS_Server;Job;17511.tyrone-cluster;enqueuing into batch, state 1 hop 1
12/24/2012 00:09:47;0100;PBS_Server;Job;17511.tyrone-cluster;dequeuing from batch, state QUEUED
12/24/2012 00:09:47;0100;PBS_Server;Job;17511.tyrone-cluster;enqueuing into qp32, state 1 hop 1
12/24/2012 00:09:47;0008;PBS_Server;Job;17511.tyrone-cluster;Job Queued at request of mrcatanu@tyrone-cluster, owner = mrcatanu@tyrone-cluster, job name = SCFHSE, queue = qp32
12/24/2012 00:09:47;0040;PBS_Server;Svr;tyrone-cluster;Scheduler was sent the command new
12/24/2012 00:09:47;0008;PBS_Server;Job;17511.tyrone-cluster;Job Modified at request of Scheduler@tyrone-cluster
12/24/2012 00:10:52;0008;PBS_Server;Job;17511.tyrone-cluster;Job deleted at request of mrcatanu@tyrone-cluster
12/24/2012 00:10:52;0008;PBS_Server;Job;NULL;on_job_exit valid pjob: 0x1b53a10 (substate=59)
12/24/2012 00:10:52;0100;PBS_Server;Job;17511.tyrone-cluster;dequeuing from qp32, state COMPLETE
12/24/2012 00:10:52;0040;PBS_Server;Svr;tyrone-cluster;Scheduler was sent the command term
12/24/2012 00:11:10;0100;PBS_Server;Job;17512.tyrone-cluster;enqueuing into batch, state 1 hop 1
12/24/2012 00:11:10;0100;PBS_Server;Job;17512.tyrone-cluster;dequeuing from batch, state QUEUED
12/24/2012 00:11:10;0100;PBS_Server;Job;17512.tyrone-cluster;enqueuing into qp128, state 1 hop 1
12/24/2012 00:11:10;0008;PBS_Server;Job;17512.tyrone-cluster;Job Queued at request of mrcatanu@tyrone-cluster, owner = mrcatanu@tyrone-cluster, job name = SCFHSE, queue = qp128
12/24/2012 00:11:10;0040;PBS_Server;Svr;tyrone-cluster;Scheduler was sent the command new
12/24/2012 00:11:10;0008;PBS_Server;Job;17512.tyrone-cluster;Job Modified at request of Scheduler@tyrone-cluster
12/24/2012 00:11:10;0008;PBS_Server;Job;17512.tyrone-cluster;Job Run at request of Scheduler@tyrone-cluster
12/24/2012 00:11:10;0040;PBS_Server;Svr;tyrone-cluster;Scheduler was sent the command recyc
12/24/2012 00:11:55;000d;PBS_Server;Job;17512.tyrone-cluster;Not sending email: User does not want mail of this type.
12/24/2012 00:13:22;0002;PBS_Server;Svr;PBS_Server;Torque Server Version = 3.0.5, loglevel = 0
12/24/2012 00:18:22;0002;PBS_Server;Svr;PBS_Server;Torque Server Version = 3.0.5, loglevel = 0
12/24/2012 00:21:05;000d;PBS_Server;Job;17509.tyrone-cluster;Not sending email: User does not want mail of this type.
12/24/2012 00:21:05;0010;PBS_Server;Job;17509.tyrone-cluster;Exit_status=0 resources_used.cput=25:53:37 resources_used.mem=8504944kb resources_used.vmem=14758512kb resources_used.walltime=00:25:10
12/24/2012 00:21:05;0008;PBS_Server;Job;NULL;on_job_exit valid pjob: 0x1cd0760 (substate=50)
12/24/2012 00:21:05;0008;PBS_Server;Job;NULL;on_job_exit valid pjob: 0x1cd0760 (substate=51)
12/24/2012 00:21:08;0008;PBS_Server;Job;NULL;on_job_exit valid pjob: 0x1cd0760 (substate=51)
12/24/2012 00:21:08;0008;PBS_Server;Job;NULL;on_job_exit valid pjob: 0x1cd0760 (substate=53)
12/24/2012 00:21:08;0100;PBS_Server;Job;17509.tyrone-cluster;dequeuing from qp64, state COMPLETE
12/24/2012 00:21:08;0040;PBS_Server;Svr;tyrone-cluster;Scheduler was sent the command term
12/24/2012 00:21:08;0008;PBS_Server;Job;17480.tyrone-cluster;Job Modified at request of Scheduler@tyrone-cluster
12/24/2012 00:21:08;0008;PBS_Server;Job;17423.tyrone-cluster;Job Modified at request of Scheduler@tyrone-cluster
12/24/2012 00:21:08;0008;PBS_Server;Job;17486.tyrone-cluster;Job Modified at request of Scheduler@tyrone-cluster
12/24/2012 00:21:08;0008;PBS_Server;Job;17487.tyrone-cluster;Job Modified at request of Scheduler@tyrone-cluster
12/24/2012 00:23:22;0002;PBS_Server;Svr;PBS_Server;Torque Server Version = 3.0.5, loglevel = 0
12/24/2012 00:28:22;0002;PBS_Server;Svr;PBS_Server;Torque Server Version = 3.0.5, loglevel = 0
12/24/2012 00:31:08;0040;PBS_Server;Svr;tyrone-cluster;Scheduler was sent the command time
12/24/2012 00:33:22;0002;PBS_Server;Svr;PBS_Server;Torque Server Version = 3.0.5, loglevel = 0
12/24/2012 00:38:22;0002;PBS_Server;Svr;PBS_Server;Torque Server Version = 3.0.5, loglevel = 0
12/24/2012 00:41:08;0040;PBS_Server;Svr;tyrone-cluster;Scheduler was sent the command time
12/24/2012 00:43:22;0002;PBS_Server;Svr;PBS_Server;Torque Server Version = 3.0.5, loglevel = 0
12/24/2012 00:48:22;0002;PBS_Server;Svr;PBS_Server;Torque Server Version = 3.0.5, loglevel = 0
12/24/2012 00:51:08;0040;PBS_Server;Svr;tyrone-cluster;Scheduler was sent the command time
12/24/2012 00:53:22;0002;PBS_Server;Svr;PBS_Server;Torque Server Version = 3.0.5, loglevel = 0
12/24/2012 00:58:22;0002;PBS_Server;Svr;PBS_Server;Torque Server Version = 3.0.5, loglevel = 0
12/24/2012 01:01:08;0040;PBS_Server;Svr;tyrone-cluster;Scheduler was sent the command time
12/24/2012 01:03:22;0002;PBS_Server;Svr;PBS_Server;Torque Server Version = 3.0.5, loglevel = 0
12/24/2012 01:08:22;0002;PBS_Server;Svr;PBS_Server;Torque Server Version = 3.0.5, loglevel = 0
12/24/2012 01:10:57;0100;PBS_Server;Job;17513.tyrone-cluster;enqueuing into batch, state 1 hop 1
12/24/2012 01:10:57;0100;PBS_Server;Job;17513.tyrone-cluster;dequeuing from batch, state QUEUED
12/24/2012 01:10:57;0100;PBS_Server;Job;17513.tyrone-cluster;enqueuing into qp32, state 1 hop 1
12/24/2012 01:10:57;0008;PBS_Server;Job;17513.tyrone-cluster;Job Queued at request of csddibye@tyrone-cluster, owner = csddibye@tyrone-cluster, job name = SM1_MS-GB_M06_HB, queue = qp32
12/24/2012 01:10:57;0040;PBS_Server;Svr;tyrone-cluster;Scheduler was sent the command new
12/24/2012 01:10:57;0008;PBS_Server;Job;17513.tyrone-cluster;Job Modified at request of Scheduler@tyrone-cluster
12/24/2012 01:13:22;0002;PBS_Server;Svr;PBS_Server;Torque Server Version = 3.0.5, loglevel = 0
12/24/2012 01:14:00;0100;PBS_Server;Job;17514.tyrone-cluster;enqueuing into batch, state 1 hop 1
12/24/2012 01:14:00;0100;PBS_Server;Job;17514.tyrone-cluster;dequeuing from batch, state QUEUED
12/24/2012 01:14:00;0100;PBS_Server;Job;17514.tyrone-cluster;enqueuing into qp64, state 1 hop 1
12/24/2012 01:14:00;0008;PBS_Server;Job;17514.tyrone-cluster;Job Queued at request of csddibye@tyrone-cluster, owner = csddibye@tyrone-cluster, job name = SM2_MS-GB_M06_HB, queue = qp64
12/24/2012 01:14:00;0040;PBS_Server;Svr;tyrone-cluster;Scheduler was sent the command new
12/24/2012 01:14:00;0008;PBS_Server;Job;17514.tyrone-cluster;Job Modified at request of Scheduler@tyrone-cluster
12/24/2012 01:18:22;0002;PBS_Server;Svr;PBS_Server;Torque Server Version = 3.0.5, loglevel = 0
12/24/2012 01:23:22;0002;PBS_Server;Svr;PBS_Server;Torque Server Version = 3.0.5, loglevel = 0
12/24/2012 01:24:00;0040;PBS_Server;Svr;tyrone-cluster;Scheduler was sent the command time
12/24/2012 01:28:22;0002;PBS_Server;Svr;PBS_Server;Torque Server Version = 3.0.5, loglevel = 0
12/24/2012 01:33:22;0002;PBS_Server;Svr;PBS_Server;Torque Server Version = 3.0.5, loglevel = 0
12/24/2012 01:34:00;0040;PBS_Server;Svr;tyrone-cluster;Scheduler was sent the command time
12/24/2012 01:37:14;0100;PBS_Server;Job;17515.tyrone-cluster;enqueuing into batch, state 1 hop 1
12/24/2012 01:37:14;0100;PBS_Server;Job;17515.tyrone-cluster;dequeuing from batch, state QUEUED
12/24/2012 01:37:14;0100;PBS_Server;Job;17515.tyrone-cluster;enqueuing into qp64, state 1 hop 1
12/24/2012 01:37:14;0008;PBS_Server;Job;17515.tyrone-cluster;Job Queued at request of csddibye@tyrone-cluster, owner = csddibye@tyrone-cluster, job name = TS_GB3-GB4_M06_BS_HB_freq, queue = qp64
12/24/2012 01:37:14;0040;PBS_Server;Svr;tyrone-cluster;Scheduler was sent the command new
12/24/2012 01:37:14;0008;PBS_Server;Job;17515.tyrone-cluster;Job Modified at request of Scheduler@tyrone-cluster
12/24/2012 01:38:22;0002;PBS_Server;Svr;PBS_Server;Torque Server Version = 3.0.5, loglevel = 0
12/24/2012 01:43:22;0002;PBS_Server;Svr;PBS_Server;Torque Server Version = 3.0.5, loglevel = 0
12/24/2012 01:47:14;0040;PBS_Server;Svr;tyrone-cluster;Scheduler was sent the command time
12/24/2012 01:48:22;0002;PBS_Server;Svr;PBS_Server;Torque Server Version = 3.0.5, loglevel = 0
12/24/2012 01:53:22;0002;PBS_Server;Svr;PBS_Server;Torque Server Version = 3.0.5, loglevel = 0
12/24/2012 01:57:14;0040;PBS_Server;Svr;tyrone-cluster;Scheduler was sent the command time
12/24/2012 01:58:22;0002;PBS_Server;Svr;PBS_Server;Torque Server Version = 3.0.5, loglevel = 0
12/24/2012 02:03:22;0002;PBS_Server;Svr;PBS_Server;Torque Server Version = 3.0.5, loglevel = 0
12/24/2012 02:07:14;0040;PBS_Server;Svr;tyrone-cluster;Scheduler was sent the command time
12/24/2012 02:08:22;0002;PBS_Server;Svr;PBS_Server;Torque Server Version = 3.0.5, loglevel = 0
12/24/2012 02:13:22;0002;PBS_Server;Svr;PBS_Server;Torque Server Version = 3.0.5, loglevel = 0
12/24/2012 02:17:14;0040;PBS_Server;Svr;tyrone-cluster;Scheduler was sent the command time
12/24/2012 02:18:22;0002;PBS_Server;Svr;PBS_Server;Torque Server Version = 3.0.5, loglevel = 0
12/24/2012 02:23:22;0002;PBS_Server;Svr;PBS_Server;Torque Server Version = 3.0.5, loglevel = 0
12/24/2012 02:27:14;0040;PBS_Server;Svr;tyrone-cluster;Scheduler was sent the command time
12/24/2012 02:28:22;0002;PBS_Server;Svr;PBS_Server;Torque Server Version = 3.0.5, loglevel = 0
12/24/2012 02:33:22;0002;PBS_Server;Svr;PBS_Server;Torque Server Version = 3.0.5, loglevel = 0
12/24/2012 02:37:14;0040;PBS_Server;Svr;tyrone-cluster;Scheduler was sent the command time
12/24/2012 02:38:22;0002;PBS_Server;Svr;PBS_Server;Torque Server Version = 3.0.5, loglevel = 0
12/24/2012 02:43:22;0002;PBS_Server;Svr;PBS_Server;Torque Server Version = 3.0.5, loglevel = 0
12/24/2012 02:47:14;0040;PBS_Server;Svr;tyrone-cluster;Scheduler was sent the command time
12/24/2012 02:48:22;0002;PBS_Server;Svr;PBS_Server;Torque Server Version = 3.0.5, loglevel = 0
12/24/2012 02:53:22;0002;PBS_Server;Svr;PBS_Server;Torque Server Version = 3.0.5, loglevel = 0
12/24/2012 02:57:14;0040;PBS_Server;Svr;tyrone-cluster;Scheduler was sent the command time
12/24/2012 02:58:22;0002;PBS_Server;Svr;PBS_Server;Torque Server Version = 3.0.5, loglevel = 0
12/24/2012 03:03:22;0002;PBS_Server;Svr;PBS_Server;Torque Server Version = 3.0.5, loglevel = 0
12/24/2012 03:07:14;0040;PBS_Server;Svr;tyrone-cluster;Scheduler was sent the command time
12/24/2012 03:08:22;0002;PBS_Server;Svr;PBS_Server;Torque Server Version = 3.0.5, loglevel = 0
12/24/2012 03:13:22;0002;PBS_Server;Svr;PBS_Server;Torque Server Version = 3.0.5, loglevel = 0
12/24/2012 03:17:14;0040;PBS_Server;Svr;tyrone-cluster;Scheduler was sent the command time
12/24/2012 03:18:22;0002;PBS_Server;Svr;PBS_Server;Torque Server Version = 3.0.5, loglevel = 0
12/24/2012 03:23:22;0002;PBS_Server;Svr;PBS_Server;Torque Server Version = 3.0.5, loglevel = 0
12/24/2012 03:27:14;0040;PBS_Server;Svr;tyrone-cluster;Scheduler was sent the command time
12/24/2012 03:28:22;0002;PBS_Server;Svr;PBS_Server;Torque Server Version = 3.0.5, loglevel = 0
12/24/2012 03:33:22;0002;PBS_Server;Svr;PBS_Server;Torque Server Version = 3.0.5, loglevel = 0
12/24/2012 03:37:14;0040;PBS_Server;Svr;tyrone-cluster;Scheduler was sent the command time
12/24/2012 03:38:22;0002;PBS_Server;Svr;PBS_Server;Torque Server Version = 3.0.5, loglevel = 0
12/24/2012 03:43:22;0002;PBS_Server;Svr;PBS_Server;Torque Server Version = 3.0.5, loglevel = 0
12/24/2012 03:47:14;0040;PBS_Server;Svr;tyrone-cluster;Scheduler was sent the command time
12/24/2012 03:48:22;0002;PBS_Server;Svr;PBS_Server;Torque Server Version = 3.0.5, loglevel = 0
12/24/2012 03:53:22;0002;PBS_Server;Svr;PBS_Server;Torque Server Version = 3.0.5, loglevel = 0
12/24/2012 03:57:14;0040;PBS_Server;Svr;tyrone-cluster;Scheduler was sent the command time
12/24/2012 03:58:22;0002;PBS_Server;Svr;PBS_Server;Torque Server Version = 3.0.5, loglevel = 0
12/24/2012 04:03:22;0002;PBS_Server;Svr;PBS_Server;Torque Server Version = 3.0.5, loglevel = 0
12/24/2012 04:07:14;0040;PBS_Server;Svr;tyrone-cluster;Scheduler was sent the command time
12/24/2012 04:08:22;0002;PBS_Server;Svr;PBS_Server;Torque Server Version = 3.0.5, loglevel = 0
12/24/2012 04:12:51;000d;PBS_Server;Job;17484.tyrone-cluster;Not sending email: User does not want mail of this type.
12/24/2012 04:12:51;0010;PBS_Server;Job;17484.tyrone-cluster;Exit_status=0 resources_used.cput=100:07:19 resources_used.mem=15017924kb resources_used.vmem=22752932kb resources_used.walltime=16:31:07
12/24/2012 04:12:51;0008;PBS_Server;Job;NULL;on_job_exit valid pjob: 0x1c25c20 (substate=50)
12/24/2012 04:12:51;0008;PBS_Server;Job;NULL;on_job_exit valid pjob: 0x1c25c20 (substate=51)
12/24/2012 04:12:51;0008;PBS_Server;Job;NULL;on_job_exit valid pjob: 0x1c25c20 (substate=51)
12/24/2012 04:12:51;0008;PBS_Server;Job;NULL;on_job_exit valid pjob: 0x1c25c20 (substate=53)
12/24/2012 04:12:51;0100;PBS_Server;Job;17484.tyrone-cluster;dequeuing from qp32, state COMPLETE
12/24/2012 04:12:51;0040;PBS_Server;Svr;tyrone-cluster;Scheduler was sent the command term
12/24/2012 04:12:51;0008;PBS_Server;Job;17485.tyrone-cluster;Job Modified at request of Scheduler@tyrone-cluster
12/24/2012 04:12:51;0008;PBS_Server;Job;17485.tyrone-cluster;Job Run at request of Scheduler@tyrone-cluster
12/24/2012 04:12:51;0040;PBS_Server;Svr;tyrone-cluster;Scheduler was sent the command recyc
12/24/2012 04:12:51;000d;PBS_Server;Job;17485.tyrone-cluster;Not sending email: User does not want mail of this type.
12/24/2012 04:12:53;000d;PBS_Server;Job;17485.tyrone-cluster;Not sending email: User does not want mail of this type.
12/24/2012 04:12:53;0010;PBS_Server;Job;17485.tyrone-cluster;Exit_status=0 resources_used.cput=00:00:00 resources_used.mem=0kb resources_used.vmem=0kb resources_used.walltime=00:00:02
12/24/2012 04:12:53;0008;PBS_Server;Job;NULL;on_job_exit valid pjob: 0x1b92e60 (substate=50)
12/24/2012 04:12:53;0008;PBS_Server;Job;NULL;on_job_exit valid pjob: 0x1b92e60 (substate=51)
12/24/2012 04:12:53;0008;PBS_Server;Job;NULL;on_job_exit valid pjob: 0x1b92e60 (substate=51)
12/24/2012 04:12:53;0008;PBS_Server;Job;NULL;on_job_exit valid pjob: 0x1b92e60 (substate=53)
12/24/2012 04:12:53;0100;PBS_Server;Job;17485.tyrone-cluster;dequeuing from qp32, state COMPLETE
12/24/2012 04:12:53;0040;PBS_Server;Svr;tyrone-cluster;Scheduler was sent the command term
12/24/2012 04:12:53;0008;PBS_Server;Job;17508.tyrone-cluster;Job Modified at request of Scheduler@tyrone-cluster
12/24/2012 04:12:53;0008;PBS_Server;Job;17510.tyrone-cluster;Job Modified at request of Scheduler@tyrone-cluster
12/24/2012 04:12:53;0008;PBS_Server;Job;17510.tyrone-cluster;Job Run at request of Scheduler@tyrone-cluster
12/24/2012 04:12:53;0040;PBS_Server;Svr;tyrone-cluster;Scheduler was sent the command recyc
12/24/2012 04:12:53;000d;PBS_Server;Job;17510.tyrone-cluster;Not sending email: User does not want mail of this type.
12/24/2012 04:13:22;0002;PBS_Server;Svr;PBS_Server;Torque Server Version = 3.0.5, loglevel = 0
12/24/2012 04:18:22;0002;PBS_Server;Svr;PBS_Server;Torque Server Version = 3.0.5, loglevel = 0
12/24/2012 04:22:53;0040;PBS_Server;Svr;tyrone-cluster;Scheduler was sent the command time
12/24/2012 04:22:53;0008;PBS_Server;Job;17508.tyrone-cluster;Job Modified at request of Scheduler@tyrone-cluster
12/24/2012 04:23:22;0002;PBS_Server;Svr;PBS_Server;Torque Server Version = 3.0.5, loglevel = 0
12/24/2012 04:28:22;0002;PBS_Server;Svr;PBS_Server;Torque Server Version = 3.0.5, loglevel = 0
12/24/2012 04:32:53;0040;PBS_Server;Svr;tyrone-cluster;Scheduler was sent the command time
12/24/2012 04:33:22;0002;PBS_Server;Svr;PBS_Server;Torque Server Version = 3.0.5, loglevel = 0
12/24/2012 04:38:22;0002;PBS_Server;Svr;PBS_Server;Torque Server Version = 3.0.5, loglevel = 0
12/24/2012 04:42:53;0040;PBS_Server;Svr;tyrone-cluster;Scheduler was sent the command time
12/24/2012 04:43:22;0002;PBS_Server;Svr;PBS_Server;Torque Server Version = 3.0.5, loglevel = 0
12/24/2012 04:45:29;000d;PBS_Server;Job;17502.tyrone-cluster;Not sending email: User does not want mail of this type.
12/24/2012 04:45:29;0010;PBS_Server;Job;17502.tyrone-cluster;Exit_status=0 resources_used.cput=454:47:34 resources_used.mem=4459052kb resources_used.vmem=10691872kb resources_used.walltime=07:13:08
12/24/2012 04:45:29;0008;PBS_Server;Job;NULL;on_job_exit valid pjob: 0x1b476f0 (substate=50)
12/24/2012 04:45:29;0008;PBS_Server;Job;NULL;on_job_exit valid pjob: 0x1b476f0 (substate=51)
12/24/2012 04:45:32;0008;PBS_Server;Job;NULL;on_job_exit valid pjob: 0x1b476f0 (substate=51)
12/24/2012 04:45:32;0008;PBS_Server;Job;NULL;on_job_exit valid pjob: 0x1b476f0 (substate=53)
12/24/2012 04:45:32;0100;PBS_Server;Job;17502.tyrone-cluster;dequeuing from qp64, state COMPLETE
12/24/2012 04:45:32;0040;PBS_Server;Svr;tyrone-cluster;Scheduler was sent the command term
12/24/2012 04:45:32;0008;PBS_Server;Job;17514.tyrone-cluster;Job Modified at request of Scheduler@tyrone-cluster
12/24/2012 04:45:32;0008;PBS_Server;Job;17514.tyrone-cluster;Job Run at request of Scheduler@tyrone-cluster
12/24/2012 04:45:32;0040;PBS_Server;Svr;tyrone-cluster;Scheduler was sent the command recyc
12/24/2012 04:45:32;000d;PBS_Server;Job;17514.tyrone-cluster;Not sending email: User does not want mail of this type.
12/24/2012 04:48:22;0002;PBS_Server;Svr;PBS_Server;Torque Server Version = 3.0.5, loglevel = 0
12/24/2012 04:53:22;0002;PBS_Server;Svr;PBS_Server;Torque Server Version = 3.0.5, loglevel = 0
12/24/2012 04:55:32;0040;PBS_Server;Svr;tyrone-cluster;Scheduler was sent the command time
12/24/2012 04:58:22;0002;PBS_Server;Svr;PBS_Server;Torque Server Version = 3.0.5, loglevel = 0
12/24/2012 05:03:22;0002;PBS_Server;Svr;PBS_Server;Torque Server Version = 3.0.5, loglevel = 0
12/24/2012 05:05:23;000d;PBS_Server;Job;17493.tyrone-cluster;Not sending email: User does not want mail of this type.
12/24/2012 05:05:23;0010;PBS_Server;Job;17493.tyrone-cluster;Exit_status=0 resources_used.cput=341:20:11 resources_used.mem=5710356kb resources_used.vmem=9524520kb resources_used.walltime=10:49:50
12/24/2012 05:05:23;0008;PBS_Server;Job;NULL;on_job_exit valid pjob: 0x1b95a50 (substate=50)
12/24/2012 05:05:23;0008;PBS_Server;Job;NULL;on_job_exit valid pjob: 0x1b95a50 (substate=51)
12/24/2012 05:05:25;0008;PBS_Server;Job;NULL;on_job_exit valid pjob: 0x1b95a50 (substate=51)
12/24/2012 05:05:25;0008;PBS_Server;Job;NULL;on_job_exit valid pjob: 0x1b95a50 (substate=53)
12/24/2012 05:05:25;0100;PBS_Server;Job;17493.tyrone-cluster;dequeuing from qp32, state COMPLETE
12/24/2012 05:05:25;0040;PBS_Server;Svr;tyrone-cluster;Scheduler was sent the command term
12/24/2012 05:05:25;0008;PBS_Server;Job;17508.tyrone-cluster;Job Modified at request of Scheduler@tyrone-cluster
12/24/2012 05:05:25;0008;PBS_Server;Job;17513.tyrone-cluster;Job Modified at request of Scheduler@tyrone-cluster
12/24/2012 05:05:25;0008;PBS_Server;Job;17513.tyrone-cluster;Job Run at request of Scheduler@tyrone-cluster
12/24/2012 05:05:26;0040;PBS_Server;Svr;tyrone-cluster;Scheduler was sent the command recyc
12/24/2012 05:05:26;000d;PBS_Server;Job;17513.tyrone-cluster;Not sending email: User does not want mail of this type.
12/24/2012 05:06:36;000d;PBS_Server;Job;17504.tyrone-cluster;Not sending email: User does not want mail of this type.
12/24/2012 05:06:36;0010;PBS_Server;Job;17504.tyrone-cluster;Exit_status=0 resources_used.cput=215:18:40 resources_used.mem=6179332kb resources_used.vmem=14086488kb resources_used.walltime=06:43:52
12/24/2012 05:06:36;0008;PBS_Server;Job;NULL;on_job_exit valid pjob: 0x1b7af20 (substate=50)
12/24/2012 05:06:36;0008;PBS_Server;Job;NULL;on_job_exit valid pjob: 0x1b7af20 (substate=51)
12/24/2012 05:06:37;0008;PBS_Server;Job;NULL;on_job_exit valid pjob: 0x1b7af20 (substate=51)
12/24/2012 05:06:37;0008;PBS_Server;Job;NULL;on_job_exit valid pjob: 0x1b7af20 (substate=53)
12/24/2012 05:06:37;0100;PBS_Server;Job;17504.tyrone-cluster;dequeuing from qp32, state COMPLETE
12/24/2012 05:06:37;0040;PBS_Server;Svr;tyrone-cluster;Scheduler was sent the command term
12/24/2012 05:06:37;0008;PBS_Server;Job;17508.tyrone-cluster;Job Modified at request of Scheduler@tyrone-cluster
12/24/2012 05:06:37;0008;PBS_Server;Job;17508.tyrone-cluster;Job Run at request of Scheduler@tyrone-cluster
12/24/2012 05:06:37;0040;PBS_Server;Svr;tyrone-cluster;Scheduler was sent the command recyc
12/24/2012 05:06:37;000d;PBS_Server;Job;17508.tyrone-cluster;Not sending email: User does not want mail of this type.
12/24/2012 05:08:22;0002;PBS_Server;Svr;PBS_Server;Torque Server Version = 3.0.5, loglevel = 0
12/24/2012 05:13:22;0002;PBS_Server;Svr;PBS_Server;Torque Server Version = 3.0.5, loglevel = 0
12/24/2012 05:16:37;0040;PBS_Server;Svr;tyrone-cluster;Scheduler was sent the command time
12/24/2012 05:18:22;0002;PBS_Server;Svr;PBS_Server;Torque Server Version = 3.0.5, loglevel = 0
12/24/2012 05:23:22;0002;PBS_Server;Svr;PBS_Server;Torque Server Version = 3.0.5, loglevel = 0
12/24/2012 05:26:37;0040;PBS_Server;Svr;tyrone-cluster;Scheduler was sent the command time
12/24/2012 05:28:23;0002;PBS_Server;Svr;PBS_Server;Torque Server Version = 3.0.5, loglevel = 0
12/24/2012 05:33:23;0002;PBS_Server;Svr;PBS_Server;Torque Server Version = 3.0.5, loglevel = 0
12/24/2012 05:36:37;0040;PBS_Server;Svr;tyrone-cluster;Scheduler was sent the command time
12/24/2012 05:38:23;0002;PBS_Server;Svr;PBS_Server;Torque Server Version = 3.0.5, loglevel = 0
12/24/2012 05:43:23;0002;PBS_Server;Svr;PBS_Server;Torque Server Version = 3.0.5, loglevel = 0
12/24/2012 05:46:37;0040;PBS_Server;Svr;tyrone-cluster;Scheduler was sent the command time
12/24/2012 05:48:23;0002;PBS_Server;Svr;PBS_Server;Torque Server Version = 3.0.5, loglevel = 0
12/24/2012 05:53:23;0002;PBS_Server;Svr;PBS_Server;Torque Server Version = 3.0.5, loglevel = 0
12/24/2012 05:56:37;0040;PBS_Server;Svr;tyrone-cluster;Scheduler was sent the command time
12/24/2012 05:58:23;0002;PBS_Server;Svr;PBS_Server;Torque Server Version = 3.0.5, loglevel = 0
12/24/2012 06:03:23;0002;PBS_Server;Svr;PBS_Server;Torque Server Version = 3.0.5, loglevel = 0
12/24/2012 06:06:37;0040;PBS_Server;Svr;tyrone-cluster;Scheduler was sent the command time
12/24/2012 06:08:23;0002;PBS_Server;Svr;PBS_Server;Torque Server Version = 3.0.5, loglevel = 0
12/24/2012 06:13:23;0002;PBS_Server;Svr;PBS_Server;Torque Server Version = 3.0.5, loglevel = 0
12/24/2012 06:16:37;0040;PBS_Server;Svr;tyrone-cluster;Scheduler was sent the command time
12/24/2012 06:18:23;0002;PBS_Server;Svr;PBS_Server;Torque Server Version = 3.0.5, loglevel = 0
12/24/2012 06:23:23;0002;PBS_Server;Svr;PBS_Server;Torque Server Version = 3.0.5, loglevel = 0
12/24/2012 06:26:37;0040;PBS_Server;Svr;tyrone-cluster;Scheduler was sent the command time
12/24/2012 06:28:23;0002;PBS_Server;Svr;PBS_Server;Torque Server Version = 3.0.5, loglevel = 0
12/24/2012 06:33:23;0002;PBS_Server;Svr;PBS_Server;Torque Server Version = 3.0.5, loglevel = 0
12/24/2012 06:36:37;0040;PBS_Server;Svr;tyrone-cluster;Scheduler was sent the command time
12/24/2012 06:38:23;0002;PBS_Server;Svr;PBS_Server;Torque Server Version = 3.0.5, loglevel = 0
12/24/2012 06:43:23;0002;PBS_Server;Svr;PBS_Server;Torque Server Version = 3.0.5, loglevel = 0
12/24/2012 06:46:37;0040;PBS_Server;Svr;tyrone-cluster;Scheduler was sent the command time
12/24/2012 06:48:23;0002;PBS_Server;Svr;PBS_Server;Torque Server Version = 3.0.5, loglevel = 0
12/24/2012 06:51:48;000d;PBS_Server;Job;17510.tyrone-cluster;Not sending email: User does not want mail of this type.
12/24/2012 06:51:48;0010;PBS_Server;Job;17510.tyrone-cluster;Exit_status=0 resources_used.cput=82:04:55 resources_used.mem=8474148kb resources_used.vmem=12397068kb resources_used.walltime=02:38:57
12/24/2012 06:51:48;0008;PBS_Server;Job;NULL;on_job_exit valid pjob: 0x1c33cc0 (substate=50)
12/24/2012 06:51:48;0008;PBS_Server;Job;NULL;on_job_exit valid pjob: 0x1c33cc0 (substate=51)
12/24/2012 06:51:51;0008;PBS_Server;Job;NULL;on_job_exit valid pjob: 0x1c33cc0 (substate=51)
12/24/2012 06:51:51;0008;PBS_Server;Job;NULL;on_job_exit valid pjob: 0x1c33cc0 (substate=53)
12/24/2012 06:51:51;0100;PBS_Server;Job;17510.tyrone-cluster;dequeuing from qp32, state COMPLETE
12/24/2012 06:51:51;0040;PBS_Server;Svr;tyrone-cluster;Scheduler was sent the command term
12/24/2012 06:53:23;0002;PBS_Server;Svr;PBS_Server;Torque Server Version = 3.0.5, loglevel = 0
12/24/2012 06:58:23;0002;PBS_Server;Svr;PBS_Server;Torque Server Version = 3.0.5, loglevel = 0
12/24/2012 07:01:51;0040;PBS_Server;Svr;tyrone-cluster;Scheduler was sent the command time
12/24/2012 07:03:23;0002;PBS_Server;Svr;PBS_Server;Torque Server Version = 3.0.5, loglevel = 0
12/24/2012 07:08:23;0002;PBS_Server;Svr;PBS_Server;Torque Server Version = 3.0.5, loglevel = 0
12/24/2012 07:11:51;0040;PBS_Server;Svr;tyrone-cluster;Scheduler was sent the command time
12/24/2012 07:13:23;0002;PBS_Server;Svr;PBS_Server;Torque Server Version = 3.0.5, loglevel = 0
12/24/2012 07:18:23;0002;PBS_Server;Svr;PBS_Server;Torque Server Version = 3.0.5, loglevel = 0
12/24/2012 07:21:51;0040;PBS_Server;Svr;tyrone-cluster;Scheduler was sent the command time
12/24/2012 07:23:23;0002;PBS_Server;Svr;PBS_Server;Torque Server Version = 3.0.5, loglevel = 0
12/24/2012 07:23:39;000d;PBS_Server;Job;17452.tyrone-cluster;Not sending email: User does not want mail of this type.
12/24/2012 07:23:39;0010;PBS_Server;Job;17452.tyrone-cluster;Exit_status=0 resources_used.cput=1458:00:20 resources_used.mem=14876004kb resources_used.vmem=23176772kb resources_used.walltime=23:19:14
12/24/2012 07:23:39;0008;PBS_Server;Job;NULL;on_job_exit valid pjob: 0x1ccf4a0 (substate=50)
12/24/2012 07:23:39;0008;PBS_Server;Job;NULL;on_job_exit valid pjob: 0x1ccf4a0 (substate=51)
12/24/2012 07:23:39;0008;PBS_Server;Job;NULL;on_job_exit valid pjob: 0x1ccf4a0 (substate=51)
12/24/2012 07:23:39;0008;PBS_Server;Job;NULL;on_job_exit valid pjob: 0x1ccf4a0 (substate=53)
12/24/2012 07:23:39;0100;PBS_Server;Job;17452.tyrone-cluster;dequeuing from qp64, state COMPLETE
12/24/2012 07:23:39;0040;PBS_Server;Svr;tyrone-cluster;Scheduler was sent the command term
12/24/2012 07:23:39;0008;PBS_Server;Job;17480.tyrone-cluster;Job Modified at request of Scheduler@tyrone-cluster
12/24/2012 07:23:39;0008;PBS_Server;Job;17480.tyrone-cluster;Job Run at request of Scheduler@tyrone-cluster
12/24/2012 07:23:39;0040;PBS_Server;Svr;tyrone-cluster;Scheduler was sent the command recyc
12/24/2012 07:23:39;000d;PBS_Server;Job;17480.tyrone-cluster;Not sending email: User does not want mail of this type.
12/24/2012 07:28:23;0002;PBS_Server;Svr;PBS_Server;Torque Server Version = 3.0.5, loglevel = 0
12/24/2012 07:33:23;0002;PBS_Server;Svr;PBS_Server;Torque Server Version = 3.0.5, loglevel = 0
12/24/2012 07:33:39;0040;PBS_Server;Svr;tyrone-cluster;Scheduler was sent the command time
12/24/2012 07:38:23;0002;PBS_Server;Svr;PBS_Server;Torque Server Version = 3.0.5, loglevel = 0
12/24/2012 07:43:23;0002;PBS_Server;Svr;PBS_Server;Torque Server Version = 3.0.5, loglevel = 0
12/24/2012 07:43:39;0040;PBS_Server;Svr;tyrone-cluster;Scheduler was sent the command time
12/24/2012 07:48:23;0002;PBS_Server;Svr;PBS_Server;Torque Server Version = 3.0.5, loglevel = 0
12/24/2012 07:53:23;0002;PBS_Server;Svr;PBS_Server;Torque Server Version = 3.0.5, loglevel = 0
12/24/2012 07:53:39;0040;PBS_Server;Svr;tyrone-cluster;Scheduler was sent the command time
12/24/2012 07:58:23;0002;PBS_Server;Svr;PBS_Server;Torque Server Version = 3.0.5, loglevel = 0
12/24/2012 08:03:23;0002;PBS_Server;Svr;PBS_Server;Torque Server Version = 3.0.5, loglevel = 0
12/24/2012 08:03:39;0040;PBS_Server;Svr;tyrone-cluster;Scheduler was sent the command time
12/24/2012 08:08:23;0002;PBS_Server;Svr;PBS_Server;Torque Server Version = 3.0.5, loglevel = 0
12/24/2012 08:13:23;0002;PBS_Server;Svr;PBS_Server;Torque Server Version = 3.0.5, loglevel = 0
12/24/2012 08:13:39;0040;PBS_Server;Svr;tyrone-cluster;Scheduler was sent the command time
12/24/2012 08:18:22;000d;PBS_Server;Job;17408.tyrone-cluster;Not sending email: User does not want mail of this type.
12/24/2012 08:18:22;0010;PBS_Server;Job;17408.tyrone-cluster;Exit_status=0 resources_used.cput=196:19:52 resources_used.mem=15127532kb resources_used.vmem=29148964kb resources_used.walltime=18:06:20
12/24/2012 08:18:22;0008;PBS_Server;Job;NULL;on_job_exit valid pjob: 0x1cda860 (substate=50)
12/24/2012 08:18:22;0008;PBS_Server;Job;NULL;on_job_exit valid pjob: 0x1cda860 (substate=51)
12/24/2012 08:18:22;0008;PBS_Server;Job;NULL;on_job_exit valid pjob: 0x1cda860 (substate=51)
12/24/2012 08:18:22;0008;PBS_Server;Job;NULL;on_job_exit valid pjob: 0x1cda860 (substate=53)
12/24/2012 08:18:22;0100;PBS_Server;Job;17408.tyrone-cluster;dequeuing from qp64, state COMPLETE
12/24/2012 08:18:22;0040;PBS_Server;Svr;tyrone-cluster;Scheduler was sent the command term
12/24/2012 08:18:22;0008;PBS_Server;Job;17423.tyrone-cluster;Job Modified at request of Scheduler@tyrone-cluster
12/24/2012 08:18:22;0008;PBS_Server;Job;17423.tyrone-cluster;Job Run at request of Scheduler@tyrone-cluster
12/24/2012 08:18:22;0040;PBS_Server;Svr;tyrone-cluster;Scheduler was sent the command recyc
12/24/2012 08:18:22;000d;PBS_Server;Job;17423.tyrone-cluster;Not sending email: User does not want mail of this type.
12/24/2012 08:18:23;0002;PBS_Server;Svr;PBS_Server;Torque Server Version = 3.0.5, loglevel = 0
12/24/2012 08:23:23;0002;PBS_Server;Svr;PBS_Server;Torque Server Version = 3.0.5, loglevel = 0
12/24/2012 08:28:22;0040;PBS_Server;Svr;tyrone-cluster;Scheduler was sent the command time
12/24/2012 08:28:23;0002;PBS_Server;Svr;PBS_Server;Torque Server Version = 3.0.5, loglevel = 0
12/24/2012 08:33:23;0002;PBS_Server;Svr;PBS_Server;Torque Server Version = 3.0.5, loglevel = 0
12/24/2012 08:38:22;0040;PBS_Server;Svr;tyrone-cluster;Scheduler was sent the command time
12/24/2012 08:38:23;0002;PBS_Server;Svr;PBS_Server;Torque Server Version = 3.0.5, loglevel = 0
12/24/2012 08:43:23;0002;PBS_Server;Svr;PBS_Server;Torque Server Version = 3.0.5, loglevel = 0
12/24/2012 08:48:22;0040;PBS_Server;Svr;tyrone-cluster;Scheduler was sent the command time
12/24/2012 08:48:23;0002;PBS_Server;Svr;PBS_Server;Torque Server Version = 3.0.5, loglevel = 0
12/24/2012 08:53:23;0002;PBS_Server;Svr;PBS_Server;Torque Server Version = 3.0.5, loglevel = 0
12/24/2012 08:58:22;0040;PBS_Server;Svr;tyrone-cluster;Scheduler was sent the command time
12/24/2012 08:58:23;0002;PBS_Server;Svr;PBS_Server;Torque Server Version = 3.0.5, loglevel = 0
12/24/2012 09:03:06;000d;PBS_Server;Job;17514.tyrone-cluster;Not sending email: User does not want mail of this type.
12/24/2012 09:03:06;0010;PBS_Server;Job;17514.tyrone-cluster;Exit_status=0 resources_used.cput=266:40:31 resources_used.mem=5799192kb resources_used.vmem=11048192kb resources_used.walltime=04:17:36
12/24/2012 09:03:06;0008;PBS_Server;Job;NULL;on_job_exit valid pjob: 0x1b53a10 (substate=50)
12/24/2012 09:03:06;0008;PBS_Server;Job;NULL;on_job_exit valid pjob: 0x1b53a10 (substate=51)
12/24/2012 09:03:09;0008;PBS_Server;Job;NULL;on_job_exit valid pjob: 0x1b53a10 (substate=51)
12/24/2012 09:03:09;0008;PBS_Server;Job;NULL;on_job_exit valid pjob: 0x1b53a10 (substate=53)
12/24/2012 09:03:09;0100;PBS_Server;Job;17514.tyrone-cluster;dequeuing from qp64, state COMPLETE
12/24/2012 09:03:09;0040;PBS_Server;Svr;tyrone-cluster;Scheduler was sent the command term
12/24/2012 09:03:09;0008;PBS_Server;Job;17515.tyrone-cluster;Job Modified at request of Scheduler@tyrone-cluster
12/24/2012 09:03:09;0008;PBS_Server;Job;17515.tyrone-cluster;Job Run at request of Scheduler@tyrone-cluster
12/24/2012 09:03:09;0040;PBS_Server;Svr;tyrone-cluster;Scheduler was sent the command recyc
12/24/2012 09:03:09;000d;PBS_Server;Job;17515.tyrone-cluster;Not sending email: User does not want mail of this type.
12/24/2012 09:03:23;0002;PBS_Server;Svr;PBS_Server;Torque Server Version = 3.0.5, loglevel = 0
12/24/2012 09:08:23;0002;PBS_Server;Svr;PBS_Server;Torque Server Version = 3.0.5, loglevel = 0
12/24/2012 09:13:09;0040;PBS_Server;Svr;tyrone-cluster;Scheduler was sent the command time
12/24/2012 09:13:20;0100;PBS_Server;Job;17516.tyrone-cluster;enqueuing into batch, state 1 hop 1
12/24/2012 09:13:20;0100;PBS_Server;Job;17516.tyrone-cluster;dequeuing from batch, state QUEUED
12/24/2012 09:13:20;0100;PBS_Server;Job;17516.tyrone-cluster;enqueuing into idqueue, state 1 hop 1
12/24/2012 09:13:20;0008;PBS_Server;Job;17516.tyrone-cluster;Job Queued at request of metposhi@tyrone-cluster, owner = metposhi@tyrone-cluster, job name = poshit1, queue = idqueue
12/24/2012 09:13:20;0040;PBS_Server;Svr;tyrone-cluster;Scheduler was sent the command new
12/24/2012 09:13:20;0008;PBS_Server;Job;17516.tyrone-cluster;Job Modified at request of Scheduler@tyrone-cluster
12/24/2012 09:13:20;0008;PBS_Server;Job;17516.tyrone-cluster;Job Run at request of Scheduler@tyrone-cluster
12/24/2012 09:13:20;0040;PBS_Server;Svr;tyrone-cluster;Scheduler was sent the command recyc
12/24/2012 09:13:20;000d;PBS_Server;Job;17516.tyrone-cluster;Not sending email: User does not want mail of this type.
12/24/2012 09:13:23;0002;PBS_Server;Svr;PBS_Server;Torque Server Version = 3.0.5, loglevel = 0
12/24/2012 09:18:23;0002;PBS_Server;Svr;PBS_Server;Torque Server Version = 3.0.5, loglevel = 0
12/24/2012 09:21:20;000d;PBS_Server;Job;17516.tyrone-cluster;Not sending email: User does not want mail of this type.
12/24/2012 09:21:20;0010;PBS_Server;Job;17516.tyrone-cluster;Exit_status=0 resources_used.cput=04:11:34 resources_used.mem=1458032kb resources_used.vmem=9872384kb resources_used.walltime=00:08:00
12/24/2012 09:21:20;0008;PBS_Server;Job;NULL;on_job_exit valid pjob: 0x1c25c20 (substate=50)
12/24/2012 09:21:20;0008;PBS_Server;Job;NULL;on_job_exit valid pjob: 0x1c25c20 (substate=51)
12/24/2012 09:21:20;0008;PBS_Server;Job;NULL;on_job_exit valid pjob: 0x1c25c20 (substate=51)
12/24/2012 09:21:20;0008;PBS_Server;Job;NULL;on_job_exit valid pjob: 0x1c25c20 (substate=53)
12/24/2012 09:21:20;0100;PBS_Server;Job;17516.tyrone-cluster;dequeuing from idqueue, state COMPLETE
12/24/2012 09:21:20;0040;PBS_Server;Svr;tyrone-cluster;Scheduler was sent the command term
12/24/2012 09:23:23;0002;PBS_Server;Svr;PBS_Server;Torque Server Version = 3.0.5, loglevel = 0
12/24/2012 09:27:47;0100;PBS_Server;Job;17517.tyrone-cluster;enqueuing into batch, state 1 hop 1
12/24/2012 09:27:47;0100;PBS_Server;Job;17517.tyrone-cluster;dequeuing from batch, state QUEUED
12/24/2012 09:27:47;0100;PBS_Server;Job;17517.tyrone-cluster;enqueuing into idqueue, state 1 hop 1
12/24/2012 09:27:47;0008;PBS_Server;Job;17517.tyrone-cluster;Job Queued at request of metposhi@tyrone-cluster, owner = metposhi@tyrone-cluster, job name = poshit1, queue = idqueue
12/24/2012 09:27:47;0040;PBS_Server;Svr;tyrone-cluster;Scheduler was sent the command new
12/24/2012 09:27:47;0008;PBS_Server;Job;17517.tyrone-cluster;Job Modified at request of Scheduler@tyrone-cluster
12/24/2012 09:27:47;0008;PBS_Server;Job;17517.tyrone-cluster;Job Run at request of Scheduler@tyrone-cluster
12/24/2012 09:27:47;0040;PBS_Server;Svr;tyrone-cluster;Scheduler was sent the command recyc
12/24/2012 09:27:47;000d;PBS_Server;Job;17517.tyrone-cluster;Not sending email: User does not want mail of this type.
12/24/2012 09:28:23;0002;PBS_Server;Svr;PBS_Server;Torque Server Version = 3.0.5, loglevel = 0
12/24/2012 09:33:23;0002;PBS_Server;Svr;PBS_Server;Torque Server Version = 3.0.5, loglevel = 0
12/24/2012 09:37:47;0040;PBS_Server;Svr;tyrone-cluster;Scheduler was sent the command time
12/24/2012 09:38:23;0002;PBS_Server;Svr;PBS_Server;Torque Server Version = 3.0.5, loglevel = 0
12/24/2012 09:43:23;0002;PBS_Server;Svr;PBS_Server;Torque Server Version = 3.0.5, loglevel = 0
12/24/2012 09:44:11;000d;PBS_Server;Job;17517.tyrone-cluster;Not sending email: User does not want mail of this type.
12/24/2012 09:44:11;0010;PBS_Server;Job;17517.tyrone-cluster;Exit_status=0 resources_used.cput=08:30:50 resources_used.mem=1489288kb resources_used.vmem=9881912kb resources_used.walltime=00:16:24
12/24/2012 09:44:11;0008;PBS_Server;Job;NULL;on_job_exit valid pjob: 0x1c25c20 (substate=50)
12/24/2012 09:44:11;0008;PBS_Server;Job;NULL;on_job_exit valid pjob: 0x1c25c20 (substate=51)
12/24/2012 09:44:11;0008;PBS_Server;Job;NULL;on_job_exit valid pjob: 0x1c25c20 (substate=51)
12/24/2012 09:44:11;0008;PBS_Server;Job;NULL;on_job_exit valid pjob: 0x1c25c20 (substate=53)
12/24/2012 09:44:11;0100;PBS_Server;Job;17517.tyrone-cluster;dequeuing from idqueue, state COMPLETE
12/24/2012 09:44:11;0040;PBS_Server;Svr;tyrone-cluster;Scheduler was sent the command term
12/24/2012 09:48:23;0002;PBS_Server;Svr;PBS_Server;Torque Server Version = 3.0.5, loglevel = 0
12/24/2012 09:51:30;0001;PBS_Server;Svr;PBS_Server;LOG_DEBUG::check_host, gethostbyaddr failed for host 10.16.4.22: h_error is 1
12/24/2012 09:52:56;0100;PBS_Server;Job;17518.tyrone-cluster;enqueuing into batch, state 1 hop 1
12/24/2012 09:52:56;0100;PBS_Server;Job;17518.tyrone-cluster;dequeuing from batch, state QUEUED
12/24/2012 09:52:56;0100;PBS_Server;Job;17518.tyrone-cluster;enqueuing into qp32, state 1 hop 1
12/24/2012 09:52:56;0008;PBS_Server;Job;17518.tyrone-cluster;Job Queued at request of ciesita@tyrone-cluster, owner = ciesita@tyrone-cluster, job name = R=200, queue = qp32
12/24/2012 09:52:56;0040;PBS_Server;Svr;tyrone-cluster;Scheduler was sent the command new
12/24/2012 09:52:56;0008;PBS_Server;Job;17518.tyrone-cluster;Job Modified at request of Scheduler@tyrone-cluster
12/24/2012 09:52:56;0008;PBS_Server;Job;17518.tyrone-cluster;Job Run at request of Scheduler@tyrone-cluster
12/24/2012 09:52:56;0040;PBS_Server;Svr;tyrone-cluster;Scheduler was sent the command recyc
12/24/2012 09:52:56;000d;PBS_Server;Job;17518.tyrone-cluster;Not sending email: User does not want mail of this type.
12/24/2012 09:53:23;0002;PBS_Server;Svr;PBS_Server;Torque Server Version = 3.0.5, loglevel = 0
12/24/2012 09:58:23;0002;PBS_Server;Svr;PBS_Server;Torque Server Version = 3.0.5, loglevel = 0
12/24/2012 09:58:56;0100;PBS_Server;Job;17519.tyrone-cluster;enqueuing into batch, state 1 hop 1
12/24/2012 09:58:56;0100;PBS_Server;Job;17519.tyrone-cluster;dequeuing from batch, state QUEUED
12/24/2012 09:58:56;0100;PBS_Server;Job;17519.tyrone-cluster;enqueuing into qp32, state 1 hop 1
12/24/2012 09:58:56;0008;PBS_Server;Job;17519.tyrone-cluster;Job Queued at request of ciesita@tyrone-cluster, owner = ciesita@tyrone-cluster, job name = R=100, queue = qp32
12/24/2012 09:58:56;0040;PBS_Server;Svr;tyrone-cluster;Scheduler was sent the command new
12/24/2012 09:58:56;0008;PBS_Server;Job;17519.tyrone-cluster;Job Modified at request of Scheduler@tyrone-cluster
12/24/2012 10:01:00;000d;PBS_Server;Job;17513.tyrone-cluster;Not sending email: User does not want mail of this type.
12/24/2012 10:01:00;0010;PBS_Server;Job;17513.tyrone-cluster;Exit_status=0 resources_used.cput=153:24:59 resources_used.mem=4396992kb resources_used.vmem=8212980kb resources_used.walltime=04:55:35
12/24/2012 10:01:00;0008;PBS_Server;Job;NULL;on_job_exit valid pjob: 0x1cd0760 (substate=50)
12/24/2012 10:01:00;0008;PBS_Server;Job;NULL;on_job_exit valid pjob: 0x1cd0760 (substate=51)
12/24/2012 10:01:02;0008;PBS_Server;Job;NULL;on_job_exit valid pjob: 0x1cd0760 (substate=51)
12/24/2012 10:01:02;0008;PBS_Server;Job;NULL;on_job_exit valid pjob: 0x1cd0760 (substate=53)
12/24/2012 10:01:02;0100;PBS_Server;Job;17513.tyrone-cluster;dequeuing from qp32, state COMPLETE
12/24/2012 10:01:02;0040;PBS_Server;Svr;tyrone-cluster;Scheduler was sent the command term
12/24/2012 10:01:02;0008;PBS_Server;Job;17519.tyrone-cluster;Job Modified at request of Scheduler@tyrone-cluster
12/24/2012 10:01:06;0100;PBS_Server;Job;17520.tyrone-cluster;enqueuing into batch, state 1 hop 1
12/24/2012 10:01:06;0100;PBS_Server;Job;17520.tyrone-cluster;dequeuing from batch, state QUEUED
12/24/2012 10:01:06;0100;PBS_Server;Job;17520.tyrone-cluster;enqueuing into qp64, state 1 hop 1
12/24/2012 10:01:06;0008;PBS_Server;Job;17520.tyrone-cluster;Job Queued at request of ciesita@tyrone-cluster, owner = ciesita@tyrone-cluster, job name = R=20, queue = qp64
12/24/2012 10:01:06;0040;PBS_Server;Svr;tyrone-cluster;Scheduler was sent the command new
12/24/2012 10:01:07;0008;PBS_Server;Job;17520.tyrone-cluster;Job Modified at request of Scheduler@tyrone-cluster
12/24/2012 10:02:08;0100;PBS_Server;Job;17521.tyrone-cluster;enqueuing into batch, state 1 hop 1
12/24/2012 10:02:08;0100;PBS_Server;Job;17521.tyrone-cluster;dequeuing from batch, state QUEUED
12/24/2012 10:02:08;0100;PBS_Server;Job;17521.tyrone-cluster;enqueuing into qp32, state 1 hop 1
12/24/2012 10:02:08;0008;PBS_Server;Job;17521.tyrone-cluster;Job Queued at request of mrcatanu@tyrone-cluster, owner = mrcatanu@tyrone-cluster, job name = SCFH, queue = qp32
12/24/2012 10:02:08;0040;PBS_Server;Svr;tyrone-cluster;Scheduler was sent the command new
12/24/2012 10:02:08;0008;PBS_Server;Job;17521.tyrone-cluster;Job Modified at request of Scheduler@tyrone-cluster
12/24/2012 10:03:23;0002;PBS_Server;Svr;PBS_Server;Torque Server Version = 3.0.5, loglevel = 0
12/24/2012 10:08:23;0002;PBS_Server;Svr;PBS_Server;Torque Server Version = 3.0.5, loglevel = 0
12/24/2012 10:09:45;0100;PBS_Server;Job;17522.tyrone-cluster;enqueuing into batch, state 1 hop 1
12/24/2012 10:09:45;0100;PBS_Server;Job;17522.tyrone-cluster;dequeuing from batch, state QUEUED
12/24/2012 10:09:45;0100;PBS_Server;Job;17522.tyrone-cluster;enqueuing into qp32, state 1 hop 1
12/24/2012 10:09:45;0008;PBS_Server;Job;17522.tyrone-cluster;Job Queued at request of ciesita@tyrone-cluster, owner = ciesita@tyrone-cluster, job name = a=10, queue = qp32
12/24/2012 10:09:45;0040;PBS_Server;Svr;tyrone-cluster;Scheduler was sent the command new
12/24/2012 10:09:45;0008;PBS_Server;Job;17522.tyrone-cluster;Job Modified at request of Scheduler@tyrone-cluster
12/24/2012 10:10:07;0100;PBS_Server;Job;17523.tyrone-cluster;enqueuing into batch, state 1 hop 1
12/24/2012 10:10:07;0100;PBS_Server;Job;17523.tyrone-cluster;dequeuing from batch, state QUEUED
12/24/2012 10:10:07;0100;PBS_Server;Job;17523.tyrone-cluster;enqueuing into qp32, state 1 hop 1
12/24/2012 10:10:07;0008;PBS_Server;Job;17523.tyrone-cluster;Job Queued at request of ipcmthen@tyrone-cluster, owner = ipcmthen@tyrone-cluster, job name = tyrn1, queue = qp32
12/24/2012 10:10:07;0040;PBS_Server;Svr;tyrone-cluster;Scheduler was sent the command new
12/24/2012 10:10:07;0008;PBS_Server;Job;17523.tyrone-cluster;Job Modified at request of Scheduler@tyrone-cluster
12/24/2012 10:10:07;0008;PBS_Server;Job;17523.tyrone-cluster;Job Run at request of Scheduler@tyrone-cluster
12/24/2012 10:10:07;0040;PBS_Server;Svr;tyrone-cluster;Scheduler was sent the command recyc
12/24/2012 10:10:07;000d;PBS_Server;Job;17523.tyrone-cluster;Not sending email: User does not want mail of this type.
12/24/2012 10:12:46;0100;PBS_Server;Job;17524.tyrone-cluster;enqueuing into batch, state 1 hop 1
12/24/2012 10:12:46;0008;PBS_Server;Job;17524.tyrone-cluster;Job Queued at request of ciesita@tyrone-cluster, owner = ciesita@tyrone-cluster, job name = a=50, queue = batch
12/24/2012 10:12:46;0040;PBS_Server;Svr;tyrone-cluster;Scheduler was sent the command new
12/24/2012 10:12:46;0008;PBS_Server;Job;17524.tyrone-cluster;Job Modified at request of Scheduler@tyrone-cluster
12/24/2012 10:12:46;0008;PBS_Server;Job;17519.tyrone-cluster;Job Modified at request of Scheduler@tyrone-cluster
12/24/2012 10:12:46;0008;PBS_Server;Job;17521.tyrone-cluster;Job Modified at request of Scheduler@tyrone-cluster
12/24/2012 10:12:46;0008;PBS_Server;Job;17522.tyrone-cluster;Job Modified at request of Scheduler@tyrone-cluster
12/24/2012 10:13:18;0040;PBS_Server;Svr;tyrone-cluster;Scheduler was sent the command new
12/24/2012 10:13:23;0002;PBS_Server;Svr;PBS_Server;Torque Server Version = 3.0.5, loglevel = 0
12/24/2012 10:13:49;0040;PBS_Server;Svr;tyrone-cluster;Scheduler was sent the command new
12/24/2012 10:14:23;0040;PBS_Server;Svr;tyrone-cluster;Scheduler was sent the command new
12/24/2012 10:14:54;0040;PBS_Server;Svr;tyrone-cluster;Scheduler was sent the command new
12/24/2012 10:15:26;0040;PBS_Server;Svr;tyrone-cluster;Scheduler was sent the command new
12/24/2012 10:15:56;0040;PBS_Server;Svr;tyrone-cluster;Scheduler was sent the command new
12/24/2012 10:16:27;0040;PBS_Server;Svr;tyrone-cluster;Scheduler was sent the command new
12/24/2012 10:16:56;0040;PBS_Server;Svr;tyrone-cluster;Scheduler was sent the command new
12/24/2012 10:17:27;0040;PBS_Server;Svr;tyrone-cluster;Scheduler was sent the command new
12/24/2012 10:17:57;0040;PBS_Server;Svr;tyrone-cluster;Scheduler was sent the command new
12/24/2012 10:17:57;0100;PBS_Server;Job;17525.tyrone-cluster;enqueuing into batch, state 1 hop 1
12/24/2012 10:17:57;0008;PBS_Server;Job;17525.tyrone-cluster;Job Queued at request of ciesita@tyrone-cluster, owner = ciesita@tyrone-cluster, job name = a=100, queue = batch
12/24/2012 10:17:57;0008;PBS_Server;Job;17525.tyrone-cluster;Job Modified at request of Scheduler@tyrone-cluster
12/24/2012 10:18:23;0002;PBS_Server;Svr;PBS_Server;Torque Server Version = 3.0.5, loglevel = 0
12/24/2012 10:18:26;0040;PBS_Server;Svr;tyrone-cluster;Scheduler was sent the command new
12/24/2012 10:18:30;0040;PBS_Server;Svr;tyrone-cluster;Scheduler was sent the command new
12/24/2012 10:18:56;0040;PBS_Server;Svr;tyrone-cluster;Scheduler was sent the command new
12/24/2012 10:19:00;0040;PBS_Server;Svr;tyrone-cluster;Scheduler was sent the command new
12/24/2012 10:19:27;0040;PBS_Server;Svr;tyrone-cluster;Scheduler was sent the command new
12/24/2012 10:19:56;0040;PBS_Server;Svr;tyrone-cluster;Scheduler was sent the command new
12/24/2012 10:20:02;0040;PBS_Server;Svr;tyrone-cluster;Scheduler was sent the command new
12/24/2012 10:20:26;0040;PBS_Server;Svr;tyrone-cluster;Scheduler was sent the command new
12/24/2012 10:20:30;0040;PBS_Server;Svr;tyrone-cluster;Scheduler was sent the command new
12/24/2012 10:20:57;0040;PBS_Server;Svr;tyrone-cluster;Scheduler was sent the command new
12/24/2012 10:21:03;0040;PBS_Server;Svr;tyrone-cluster;Scheduler was sent the command new
12/24/2012 10:21:26;0040;PBS_Server;Svr;tyrone-cluster;Scheduler was sent the command new
12/24/2012 10:21:33;0040;PBS_Server;Svr;tyrone-cluster;Scheduler was sent the command new
12/24/2012 10:21:56;0040;PBS_Server;Svr;tyrone-cluster;Scheduler was sent the command new
12/24/2012 10:22:04;0040;PBS_Server;Svr;tyrone-cluster;Scheduler was sent the command new
12/24/2012 10:22:27;0040;PBS_Server;Svr;tyrone-cluster;Scheduler was sent the command new
12/24/2012 10:22:33;0040;PBS_Server;Svr;tyrone-cluster;Scheduler was sent the command new
12/24/2012 10:22:56;0040;PBS_Server;Svr;tyrone-cluster;Scheduler was sent the command new
12/24/2012 10:23:03;0040;PBS_Server;Svr;tyrone-cluster;Scheduler was sent the command new
12/24/2012 10:23:23;0002;PBS_Server;Svr;PBS_Server;Torque Server Version = 3.0.5, loglevel = 0
12/24/2012 10:23:29;0040;PBS_Server;Svr;tyrone-cluster;Scheduler was sent the command new
12/24/2012 10:23:34;0040;PBS_Server;Svr;tyrone-cluster;Scheduler was sent the command new
12/24/2012 10:23:57;0040;PBS_Server;Svr;tyrone-cluster;Scheduler was sent the command new
12/24/2012 10:24:03;0040;PBS_Server;Svr;tyrone-cluster;Scheduler was sent the command new
12/24/2012 10:24:26;0040;PBS_Server;Svr;tyrone-cluster;Scheduler was sent the command new
12/24/2012 10:24:33;0040;PBS_Server;Svr;tyrone-cluster;Scheduler was sent the command new
12/24/2012 10:24:56;0040;PBS_Server;Svr;tyrone-cluster;Scheduler was sent the command new
12/24/2012 10:25:02;0040;PBS_Server;Svr;tyrone-cluster;Scheduler was sent the command new
12/24/2012 10:25:27;0040;PBS_Server;Svr;tyrone-cluster;Scheduler was sent the command new
12/24/2012 10:25:33;0040;PBS_Server;Svr;tyrone-cluster;Scheduler was sent the command new
12/24/2012 10:25:56;0040;PBS_Server;Svr;tyrone-cluster;Scheduler was sent the command new
12/24/2012 10:26:03;0040;PBS_Server;Svr;tyrone-cluster;Scheduler was sent the command new
12/24/2012 10:26:27;0040;PBS_Server;Svr;tyrone-cluster;Scheduler was sent the command new
12/24/2012 10:26:34;0040;PBS_Server;Svr;tyrone-cluster;Scheduler was sent the command new
12/24/2012 10:26:57;0040;PBS_Server;Svr;tyrone-cluster;Scheduler was sent the command new
12/24/2012 10:27:08;0040;PBS_Server;Svr;tyrone-cluster;Scheduler was sent the command new
12/24/2012 10:27:26;0040;PBS_Server;Svr;tyrone-cluster;Scheduler was sent the command new
12/24/2012 10:27:38;0040;PBS_Server;Svr;tyrone-cluster;Scheduler was sent the command new
12/24/2012 10:27:56;0040;PBS_Server;Svr;tyrone-cluster;Scheduler was sent the command new
12/24/2012 10:28:11;0040;PBS_Server;Svr;tyrone-cluster;Scheduler was sent the command new
12/24/2012 10:28:23;0002;PBS_Server;Svr;PBS_Server;Torque Server Version = 3.0.5, loglevel = 0
12/24/2012 10:28:27;0040;PBS_Server;Svr;tyrone-cluster;Scheduler was sent the command new
12/24/2012 10:28:42;0040;PBS_Server;Svr;tyrone-cluster;Scheduler was sent the command new
12/24/2012 10:28:56;0040;PBS_Server;Svr;tyrone-cluster;Scheduler was sent the command new
12/24/2012 10:29:12;0040;PBS_Server;Svr;tyrone-cluster;Scheduler was sent the command new
12/24/2012 10:29:26;0040;PBS_Server;Svr;tyrone-cluster;Scheduler was sent the command new
12/24/2012 10:29:41;0040;PBS_Server;Svr;tyrone-cluster;Scheduler was sent the command new
12/24/2012 10:29:57;0040;PBS_Server;Svr;tyrone-cluster;Scheduler was sent the command new
12/24/2012 10:30:14;0040;PBS_Server;Svr;tyrone-cluster;Scheduler was sent the command new
12/24/2012 10:30:26;0040;PBS_Server;Svr;tyrone-cluster;Scheduler was sent the command new
12/24/2012 10:30:42;0040;PBS_Server;Svr;tyrone-cluster;Scheduler was sent the command new
12/24/2012 10:30:56;0040;PBS_Server;Svr;tyrone-cluster;Scheduler was sent the command new
12/24/2012 10:31:15;0040;PBS_Server;Svr;tyrone-cluster;Scheduler was sent the command new
12/24/2012 10:31:27;0040;PBS_Server;Svr;tyrone-cluster;Scheduler was sent the command new
12/24/2012 10:31:45;0040;PBS_Server;Svr;tyrone-cluster;Scheduler was sent the command new
12/24/2012 10:31:56;0040;PBS_Server;Svr;tyrone-cluster;Scheduler was sent the command new
12/24/2012 10:31:57;0100;PBS_Server;Job;17526.tyrone-cluster;enqueuing into batch, state 1 hop 1
12/24/2012 10:31:57;0100;PBS_Server;Job;17526.tyrone-cluster;dequeuing from batch, state QUEUED
12/24/2012 10:31:57;0100;PBS_Server;Job;17526.tyrone-cluster;enqueuing into idqueue, state 1 hop 1
12/24/2012 10:31:57;0008;PBS_Server;Job;17526.tyrone-cluster;Job Queued at request of metposhi@tyrone-cluster, owner = metposhi@tyrone-cluster, job name = poshit1, queue = idqueue
12/24/2012 10:31:57;0040;PBS_Server;Svr;tyrone-cluster;Scheduler was sent the command new
12/24/2012 10:31:57;0008;PBS_Server;Job;17526.tyrone-cluster;Job Modified at request of Scheduler@tyrone-cluster
12/24/2012 10:31:57;0008;PBS_Server;Job;17526.tyrone-cluster;Job Run at request of Scheduler@tyrone-cluster
12/24/2012 10:31:58;0040;PBS_Server;Svr;tyrone-cluster;Scheduler was sent the command recyc
12/24/2012 10:31:58;000d;PBS_Server;Job;17526.tyrone-cluster;Not sending email: User does not want mail of this type.
12/24/2012 10:31:59;000d;PBS_Server;Job;17526.tyrone-cluster;Not sending email: User does not want mail of this type.
12/24/2012 10:31:59;0010;PBS_Server;Job;17526.tyrone-cluster;Exit_status=0 resources_used.cput=00:00:32 resources_used.mem=0kb resources_used.vmem=0kb resources_used.walltime=00:00:02
12/24/2012 10:31:59;0008;PBS_Server;Job;NULL;on_job_exit valid pjob: 0x1d2d0d0 (substate=50)
12/24/2012 10:31:59;0008;PBS_Server;Job;NULL;on_job_exit valid pjob: 0x1d2d0d0 (substate=51)
12/24/2012 10:31:59;0008;PBS_Server;Job;NULL;on_job_exit valid pjob: 0x1d2d0d0 (substate=51)
12/24/2012 10:31:59;0008;PBS_Server;Job;NULL;on_job_exit valid pjob: 0x1d2d0d0 (substate=53)
12/24/2012 10:31:59;0100;PBS_Server;Job;17526.tyrone-cluster;dequeuing from idqueue, state COMPLETE
12/24/2012 10:31:59;0040;PBS_Server;Svr;tyrone-cluster;Scheduler was sent the command term
12/24/2012 10:32:12;0040;PBS_Server;Svr;tyrone-cluster;Scheduler was sent the command new
12/24/2012 10:32:26;0040;PBS_Server;Svr;tyrone-cluster;Scheduler was sent the command new
12/24/2012 10:32:35;0100;PBS_Server;Job;17527.tyrone-cluster;enqueuing into batch, state 1 hop 1
12/24/2012 10:32:35;0100;PBS_Server;Job;17527.tyrone-cluster;dequeuing from batch, state QUEUED
12/24/2012 10:32:35;0100;PBS_Server;Job;17527.tyrone-cluster;enqueuing into idqueue, state 1 hop 1
12/24/2012 10:32:35;0008;PBS_Server;Job;17527.tyrone-cluster;Job Queued at request of metposhi@tyrone-cluster, owner = metposhi@tyrone-cluster, job name = poshit1, queue = idqueue
12/24/2012 10:32:35;0040;PBS_Server;Svr;tyrone-cluster;Scheduler was sent the command new
12/24/2012 10:32:35;0008;PBS_Server;Job;17527.tyrone-cluster;Job Modified at request of Scheduler@tyrone-cluster
12/24/2012 10:32:35;0008;PBS_Server;Job;17527.tyrone-cluster;Job Run at request of Scheduler@tyrone-cluster
12/24/2012 10:32:35;0040;PBS_Server;Svr;tyrone-cluster;Scheduler was sent the command recyc
12/24/2012 10:32:35;000d;PBS_Server;Job;17527.tyrone-cluster;Not sending email: User does not want mail of this type.
12/24/2012 10:32:38;000d;PBS_Server;Job;17527.tyrone-cluster;Not sending email: User does not want mail of this type.
12/24/2012 10:32:38;0010;PBS_Server;Job;17527.tyrone-cluster;Exit_status=0 resources_used.cput=00:00:36 resources_used.mem=0kb resources_used.vmem=0kb resources_used.walltime=00:00:03
12/24/2012 10:32:38;0008;PBS_Server;Job;NULL;on_job_exit valid pjob: 0x1d2d0d0 (substate=50)
12/24/2012 10:32:38;0008;PBS_Server;Job;NULL;on_job_exit valid pjob: 0x1d2d0d0 (substate=51)
12/24/2012 10:32:38;0008;PBS_Server;Job;NULL;on_job_exit valid pjob: 0x1d2d0d0 (substate=51)
12/24/2012 10:32:38;0008;PBS_Server;Job;NULL;on_job_exit valid pjob: 0x1d2d0d0 (substate=53)
12/24/2012 10:32:38;0100;PBS_Server;Job;17527.tyrone-cluster;dequeuing from idqueue, state COMPLETE
12/24/2012 10:32:38;0040;PBS_Server;Svr;tyrone-cluster;Scheduler was sent the command term
12/24/2012 10:32:43;0040;PBS_Server;Svr;tyrone-cluster;Scheduler was sent the command new
12/24/2012 10:32:57;0040;PBS_Server;Svr;tyrone-cluster;Scheduler was sent the command new
12/24/2012 10:33:15;0040;PBS_Server;Svr;tyrone-cluster;Scheduler was sent the command new
12/24/2012 10:33:23;0002;PBS_Server;Svr;PBS_Server;Torque Server Version = 3.0.5, loglevel = 0
12/24/2012 10:33:26;0040;PBS_Server;Svr;tyrone-cluster;Scheduler was sent the command new
12/24/2012 10:33:48;0040;PBS_Server;Svr;tyrone-cluster;Scheduler was sent the command new
12/24/2012 10:33:59;0040;PBS_Server;Svr;tyrone-cluster;Scheduler was sent the command new
12/24/2012 10:34:10;0100;PBS_Server;Job;17528.tyrone-cluster;enqueuing into batch, state 1 hop 1
12/24/2012 10:34:10;0100;PBS_Server;Job;17528.tyrone-cluster;dequeuing from batch, state QUEUED
12/24/2012 10:34:10;0100;PBS_Server;Job;17528.tyrone-cluster;enqueuing into idqueue, state 1 hop 1
12/24/2012 10:34:10;0008;PBS_Server;Job;17528.tyrone-cluster;Job Queued at request of metposhi@tyrone-cluster, owner = metposhi@tyrone-cluster, job name = poshit1, queue = idqueue
12/24/2012 10:34:10;0040;PBS_Server;Svr;tyrone-cluster;Scheduler was sent the command new
12/24/2012 10:34:10;0008;PBS_Server;Job;17528.tyrone-cluster;Job Modified at request of Scheduler@tyrone-cluster
12/24/2012 10:34:10;0008;PBS_Server;Job;17528.tyrone-cluster;Job Run at request of Scheduler@tyrone-cluster
12/24/2012 10:34:10;0040;PBS_Server;Svr;tyrone-cluster;Scheduler was sent the command recyc
12/24/2012 10:34:10;000d;PBS_Server;Job;17528.tyrone-cluster;Not sending email: User does not want mail of this type.
12/24/2012 10:34:13;000d;PBS_Server;Job;17528.tyrone-cluster;Not sending email: User does not want mail of this type.
12/24/2012 10:34:13;0010;PBS_Server;Job;17528.tyrone-cluster;Exit_status=0 resources_used.cput=00:01:13 resources_used.mem=0kb resources_used.vmem=0kb resources_used.walltime=00:00:03
12/24/2012 10:34:13;0008;PBS_Server;Job;NULL;on_job_exit valid pjob: 0x1d2d0d0 (substate=50)
12/24/2012 10:34:13;0008;PBS_Server;Job;NULL;on_job_exit valid pjob: 0x1d2d0d0 (substate=51)
12/24/2012 10:34:13;0008;PBS_Server;Job;NULL;on_job_exit valid pjob: 0x1d2d0d0 (substate=51)
12/24/2012 10:34:13;0008;PBS_Server;Job;NULL;on_job_exit valid pjob: 0x1d2d0d0 (substate=53)
12/24/2012 10:34:13;0100;PBS_Server;Job;17528.tyrone-cluster;dequeuing from idqueue, state COMPLETE
12/24/2012 10:34:13;0040;PBS_Server;Svr;tyrone-cluster;Scheduler was sent the command term
12/24/2012 10:34:18;0040;PBS_Server;Svr;tyrone-cluster;Scheduler was sent the command new
12/24/2012 10:34:27;0040;PBS_Server;Svr;tyrone-cluster;Scheduler was sent the command new
12/24/2012 10:34:49;0040;PBS_Server;Svr;tyrone-cluster;Scheduler was sent the command new
12/24/2012 10:34:52;0100;PBS_Server;Job;17529.tyrone-cluster;enqueuing into batch, state 1 hop 1
12/24/2012 10:34:52;0100;PBS_Server;Job;17529.tyrone-cluster;dequeuing from batch, state QUEUED
12/24/2012 10:34:52;0100;PBS_Server;Job;17529.tyrone-cluster;enqueuing into idqueue, state 1 hop 1
12/24/2012 10:34:52;0008;PBS_Server;Job;17529.tyrone-cluster;Job Queued at request of metposhi@tyrone-cluster, owner = metposhi@tyrone-cluster, job name = poshit1, queue = idqueue
12/24/2012 10:34:52;0040;PBS_Server;Svr;tyrone-cluster;Scheduler was sent the command new
12/24/2012 10:34:52;0008;PBS_Server;Job;17529.tyrone-cluster;Job Modified at request of Scheduler@tyrone-cluster
12/24/2012 10:34:52;0008;PBS_Server;Job;17529.tyrone-cluster;Job Run at request of Scheduler@tyrone-cluster
12/24/2012 10:34:52;0040;PBS_Server;Svr;tyrone-cluster;Scheduler was sent the command recyc
12/24/2012 10:34:52;000d;PBS_Server;Job;17529.tyrone-cluster;Not sending email: User does not want mail of this type.
12/24/2012 10:34:55;000d;PBS_Server;Job;17529.tyrone-cluster;Not sending email: User does not want mail of this type.
12/24/2012 10:34:55;0010;PBS_Server;Job;17529.tyrone-cluster;Exit_status=0 resources_used.cput=00:00:40 resources_used.mem=0kb resources_used.vmem=0kb resources_used.walltime=00:00:03
12/24/2012 10:34:55;0008;PBS_Server;Job;NULL;on_job_exit valid pjob: 0x1d2d0d0 (substate=50)
12/24/2012 10:34:55;0008;PBS_Server;Job;NULL;on_job_exit valid pjob: 0x1d2d0d0 (substate=51)
12/24/2012 10:34:55;0008;PBS_Server;Job;NULL;on_job_exit valid pjob: 0x1d2d0d0 (substate=51)
12/24/2012 10:34:55;0008;PBS_Server;Job;NULL;on_job_exit valid pjob: 0x1d2d0d0 (substate=53)
12/24/2012 10:34:55;0100;PBS_Server;Job;17529.tyrone-cluster;dequeuing from idqueue, state COMPLETE
12/24/2012 10:34:55;0040;PBS_Server;Svr;tyrone-cluster;Scheduler was sent the command term
12/24/2012 10:35:00;0040;PBS_Server;Svr;tyrone-cluster;Scheduler was sent the command new
12/24/2012 10:35:23;0040;PBS_Server;Svr;tyrone-cluster;Scheduler was sent the command new
12/24/2012 10:35:28;0040;PBS_Server;Svr;tyrone-cluster;Scheduler was sent the command new
12/24/2012 10:35:28;0100;PBS_Server;Job;17530.tyrone-cluster;enqueuing into batch, state 1 hop 1
12/24/2012 10:35:28;0100;PBS_Server;Job;17530.tyrone-cluster;dequeuing from batch, state QUEUED
12/24/2012 10:35:28;0100;PBS_Server;Job;17530.tyrone-cluster;enqueuing into idqueue, state 1 hop 1
12/24/2012 10:35:28;0008;PBS_Server;Job;17530.tyrone-cluster;Job Queued at request of metposhi@tyrone-cluster, owner = metposhi@tyrone-cluster, job name = poshit1, queue = idqueue
12/24/2012 10:35:28;0008;PBS_Server;Job;17530.tyrone-cluster;Job Modified at request of Scheduler@tyrone-cluster
12/24/2012 10:35:28;0008;PBS_Server;Job;17530.tyrone-cluster;Job Run at request of Scheduler@tyrone-cluster
12/24/2012 10:35:28;0040;PBS_Server;Svr;tyrone-cluster;Scheduler was sent the command recyc
12/24/2012 10:35:28;000d;PBS_Server;Job;17530.tyrone-cluster;Not sending email: User does not want mail of this type.
12/24/2012 10:35:54;0040;PBS_Server;Svr;tyrone-cluster;Scheduler was sent the command new
12/24/2012 10:36:03;0040;PBS_Server;Svr;tyrone-cluster;Scheduler was sent the command new
12/24/2012 10:36:26;0040;PBS_Server;Svr;tyrone-cluster;Scheduler was sent the command new
12/24/2012 10:36:31;0040;PBS_Server;Svr;tyrone-cluster;Scheduler was sent the command new
12/24/2012 10:36:55;0040;PBS_Server;Svr;tyrone-cluster;Scheduler was sent the command new
12/24/2012 10:37:01;0040;PBS_Server;Svr;tyrone-cluster;Scheduler was sent the command new
12/24/2012 10:37:27;0040;PBS_Server;Svr;tyrone-cluster;Scheduler was sent the command new
12/24/2012 10:37:33;0040;PBS_Server;Svr;tyrone-cluster;Scheduler was sent the command new
12/24/2012 10:37:56;0040;PBS_Server;Svr;tyrone-cluster;Scheduler was sent the command new
12/24/2012 10:38:01;0040;PBS_Server;Svr;tyrone-cluster;Scheduler was sent the command new
12/24/2012 10:38:23;0002;PBS_Server;Svr;PBS_Server;Torque Server Version = 3.0.5, loglevel = 0
12/24/2012 10:38:26;0040;PBS_Server;Svr;tyrone-cluster;Scheduler was sent the command new
12/24/2012 10:38:31;0040;PBS_Server;Svr;tyrone-cluster;Scheduler was sent the command new
12/24/2012 10:38:57;0040;PBS_Server;Svr;tyrone-cluster;Scheduler was sent the command new
12/24/2012 10:39:03;0040;PBS_Server;Svr;tyrone-cluster;Scheduler was sent the command new
12/24/2012 10:39:26;0040;PBS_Server;Svr;tyrone-cluster;Scheduler was sent the command new
12/24/2012 10:39:33;0040;PBS_Server;Svr;tyrone-cluster;Scheduler was sent the command new
12/24/2012 10:39:56;0040;PBS_Server;Svr;tyrone-cluster;Scheduler was sent the command new
12/24/2012 10:40:04;0040;PBS_Server;Svr;tyrone-cluster;Scheduler was sent the command new
12/24/2012 10:40:27;0040;PBS_Server;Svr;tyrone-cluster;Scheduler was sent the command new
12/24/2012 10:40:38;0040;PBS_Server;Svr;tyrone-cluster;Scheduler was sent the command new
12/24/2012 10:40:56;0040;PBS_Server;Svr;tyrone-cluster;Scheduler was sent the command new
12/24/2012 10:41:09;0040;PBS_Server;Svr;tyrone-cluster;Scheduler was sent the command new
12/24/2012 10:41:26;0040;PBS_Server;Svr;tyrone-cluster;Scheduler was sent the command new
12/24/2012 10:41:41;0040;PBS_Server;Svr;tyrone-cluster;Scheduler was sent the command new
12/24/2012 10:41:57;0040;PBS_Server;Svr;tyrone-cluster;Scheduler was sent the command new
12/24/2012 10:42:11;0040;PBS_Server;Svr;tyrone-cluster;Scheduler was sent the command new
12/24/2012 10:42:26;0040;PBS_Server;Svr;tyrone-cluster;Scheduler was sent the command new
12/24/2012 10:42:42;0040;PBS_Server;Svr;tyrone-cluster;Scheduler was sent the command new
12/24/2012 10:42:59;0040;PBS_Server;Svr;tyrone-cluster;Scheduler was sent the command new
12/24/2012 10:43:11;0040;PBS_Server;Svr;tyrone-cluster;Scheduler was sent the command new
12/24/2012 10:43:23;0002;PBS_Server;Svr;PBS_Server;Torque Server Version = 3.0.5, loglevel = 0
12/24/2012 10:43:27;0040;PBS_Server;Svr;tyrone-cluster;Scheduler was sent the command new
12/24/2012 10:43:44;0040;PBS_Server;Svr;tyrone-cluster;Scheduler was sent the command new
12/24/2012 10:43:56;0040;PBS_Server;Svr;tyrone-cluster;Scheduler was sent the command new
12/24/2012 10:44:12;0040;PBS_Server;Svr;tyrone-cluster;Scheduler was sent the command new
12/24/2012 10:44:26;0040;PBS_Server;Svr;tyrone-cluster;Scheduler was sent the command new
12/24/2012 10:44:42;0040;PBS_Server;Svr;tyrone-cluster;Scheduler was sent the command new
12/24/2012 10:44:57;0040;PBS_Server;Svr;tyrone-cluster;Scheduler was sent the command new
12/24/2012 10:45:15;0040;PBS_Server;Svr;tyrone-cluster;Scheduler was sent the command new
12/24/2012 10:45:26;0040;PBS_Server;Svr;tyrone-cluster;Scheduler was sent the command new
12/24/2012 10:45:42;0040;PBS_Server;Svr;tyrone-cluster;Scheduler was sent the command new
12/24/2012 10:45:56;0040;PBS_Server;Svr;tyrone-cluster;Scheduler was sent the command new
12/24/2012 10:46:14;0040;PBS_Server;Svr;tyrone-cluster;Scheduler was sent the command new
12/24/2012 10:46:27;0040;PBS_Server;Svr;tyrone-cluster;Scheduler was sent the command new
12/24/2012 10:46:44;0040;PBS_Server;Svr;tyrone-cluster;Scheduler was sent the command new
12/24/2012 10:46:57;0040;PBS_Server;Svr;tyrone-cluster;Scheduler was sent the command new
12/24/2012 10:47:12;0040;PBS_Server;Svr;tyrone-cluster;Scheduler was sent the command new
12/24/2012 10:47:27;0040;PBS_Server;Svr;tyrone-cluster;Scheduler was sent the command new
12/24/2012 10:47:42;0040;PBS_Server;Svr;tyrone-cluster;Scheduler was sent the command new
12/24/2012 10:47:57;0040;PBS_Server;Svr;tyrone-cluster;Scheduler was sent the command new
12/24/2012 10:48:15;0040;PBS_Server;Svr;tyrone-cluster;Scheduler was sent the command new
12/24/2012 10:48:23;0002;PBS_Server;Svr;PBS_Server;Torque Server Version = 3.0.5, loglevel = 0
12/24/2012 10:48:27;0040;PBS_Server;Svr;tyrone-cluster;Scheduler was sent the command new
12/24/2012 10:48:48;0040;PBS_Server;Svr;tyrone-cluster;Scheduler was sent the command new
12/24/2012 10:48:59;0040;PBS_Server;Svr;tyrone-cluster;Scheduler was sent the command new
12/24/2012 10:49:16;0040;PBS_Server;Svr;tyrone-cluster;Scheduler was sent the command new
12/24/2012 10:49:27;0040;PBS_Server;Svr;tyrone-cluster;Scheduler was sent the command new
12/24/2012 10:49:49;0040;PBS_Server;Svr;tyrone-cluster;Scheduler was sent the command new
12/24/2012 10:49:57;0040;PBS_Server;Svr;tyrone-cluster;Scheduler was sent the command new
12/24/2012 10:50:18;0040;PBS_Server;Svr;tyrone-cluster;Scheduler was sent the command new
12/24/2012 10:50:26;0040;PBS_Server;Svr;tyrone-cluster;Scheduler was sent the command new
12/24/2012 10:50:48;0040;PBS_Server;Svr;tyrone-cluster;Scheduler was sent the command new
12/24/2012 10:50:57;0040;PBS_Server;Svr;tyrone-cluster;Scheduler was sent the command new
12/24/2012 10:51:17;000d;PBS_Server;Job;17508.tyrone-cluster;Not sending email: User does not want mail of this type.
12/24/2012 10:51:17;0010;PBS_Server;Job;17508.tyrone-cluster;Exit_status=0 resources_used.cput=183:44:20 resources_used.mem=5683244kb resources_used.vmem=13590536kb resources_used.walltime=05:44:40
12/24/2012 10:51:17;0008;PBS_Server;Job;NULL;on_job_exit valid pjob: 0x1bb3c90 (substate=50)
12/24/2012 10:51:17;0008;PBS_Server;Job;NULL;on_job_exit valid pjob: 0x1bb3c90 (substate=51)
12/24/2012 10:51:18;0008;PBS_Server;Job;NULL;on_job_exit valid pjob: 0x1bb3c90 (substate=51)
12/24/2012 10:51:18;0008;PBS_Server;Job;NULL;on_job_exit valid pjob: 0x1bb3c90 (substate=53)
12/24/2012 10:51:18;0100;PBS_Server;Job;17508.tyrone-cluster;dequeuing from qp32, state COMPLETE
12/24/2012 10:51:18;0040;PBS_Server;Svr;tyrone-cluster;Scheduler was sent the command term
12/24/2012 10:51:18;0008;PBS_Server;Job;17519.tyrone-cluster;Job Modified at request of Scheduler@tyrone-cluster
12/24/2012 10:51:18;0008;PBS_Server;Job;17521.tyrone-cluster;Job Modified at request of Scheduler@tyrone-cluster
12/24/2012 10:51:18;0008;PBS_Server;Job;17521.tyrone-cluster;Job Run at request of Scheduler@tyrone-cluster
12/24/2012 10:51:18;0040;PBS_Server;Svr;tyrone-cluster;Scheduler was sent the command recyc
12/24/2012 10:51:18;000d;PBS_Server;Job;17521.tyrone-cluster;Not sending email: User does not want mail of this type.
12/24/2012 10:51:26;0040;PBS_Server;Svr;tyrone-cluster;Scheduler was sent the command new
12/24/2012 10:51:26;0008;PBS_Server;Job;17519.tyrone-cluster;Job Modified at request of Scheduler@tyrone-cluster
12/24/2012 10:51:48;0040;PBS_Server;Svr;tyrone-cluster;Scheduler was sent the command new
12/24/2012 10:51:56;0040;PBS_Server;Svr;tyrone-cluster;Scheduler was sent the command new
12/24/2012 10:52:18;0040;PBS_Server;Svr;tyrone-cluster;Scheduler was sent the command new
12/24/2012 10:52:27;0040;PBS_Server;Svr;tyrone-cluster;Scheduler was sent the command new
12/24/2012 10:52:49;0040;PBS_Server;Svr;tyrone-cluster;Scheduler was sent the command new
12/24/2012 10:52:57;0040;PBS_Server;Svr;tyrone-cluster;Scheduler was sent the command new
12/24/2012 10:53:23;0002;PBS_Server;Svr;PBS_Server;Torque Server Version = 3.0.5, loglevel = 0
12/24/2012 10:53:23;0040;PBS_Server;Svr;tyrone-cluster;Scheduler was sent the command new
12/24/2012 10:53:29;0040;PBS_Server;Svr;tyrone-cluster;Scheduler was sent the command new
12/24/2012 10:53:53;0040;PBS_Server;Svr;tyrone-cluster;Scheduler was sent the command new
12/24/2012 10:53:57;0040;PBS_Server;Svr;tyrone-cluster;Scheduler was sent the command new
12/24/2012 10:54:27;0040;PBS_Server;Svr;tyrone-cluster;Scheduler was sent the command new
12/24/2012 10:54:56;0040;PBS_Server;Svr;tyrone-cluster;Scheduler was sent the command new
12/24/2012 10:55:00;0040;PBS_Server;Svr;tyrone-cluster;Scheduler was sent the command new
12/24/2012 10:55:27;0040;PBS_Server;Svr;tyrone-cluster;Scheduler was sent the command new
12/24/2012 10:55:57;0040;PBS_Server;Svr;tyrone-cluster;Scheduler was sent the command new
12/24/2012 10:56:30;0040;PBS_Server;Svr;tyrone-cluster;Scheduler was sent the command new
12/24/2012 10:56:57;0040;PBS_Server;Svr;tyrone-cluster;Scheduler was sent the command new
12/24/2012 10:57:03;0040;PBS_Server;Svr;tyrone-cluster;Scheduler was sent the command new
12/24/2012 10:57:27;0040;PBS_Server;Svr;tyrone-cluster;Scheduler was sent the command new
12/24/2012 10:57:31;0040;PBS_Server;Svr;tyrone-cluster;Scheduler was sent the command new
12/24/2012 10:57:57;0040;PBS_Server;Svr;tyrone-cluster;Scheduler was sent the command new
12/24/2012 10:58:01;0040;PBS_Server;Svr;tyrone-cluster;Scheduler was sent the command new
12/24/2012 10:58:23;0002;PBS_Server;Svr;PBS_Server;Torque Server Version = 3.0.5, loglevel = 0
12/24/2012 10:58:27;0040;PBS_Server;Svr;tyrone-cluster;Scheduler was sent the command new
12/24/2012 10:58:33;0040;PBS_Server;Svr;tyrone-cluster;Scheduler was sent the command new
12/24/2012 10:58:56;0040;PBS_Server;Svr;tyrone-cluster;Scheduler was sent the command new
12/24/2012 10:59:01;0040;PBS_Server;Svr;tyrone-cluster;Scheduler was sent the command new
12/24/2012 10:59:26;0040;PBS_Server;Svr;tyrone-cluster;Scheduler was sent the command new
12/24/2012 10:59:31;0040;PBS_Server;Svr;tyrone-cluster;Scheduler was sent the command new
12/24/2012 10:59:57;0040;PBS_Server;Svr;tyrone-cluster;Scheduler was sent the command new
12/24/2012 11:00:03;0040;PBS_Server;Svr;tyrone-cluster;Scheduler was sent the command new
12/24/2012 11:00:27;0040;PBS_Server;Svr;tyrone-cluster;Scheduler was sent the command new
12/24/2012 11:00:31;0040;PBS_Server;Svr;tyrone-cluster;Scheduler was sent the command new
12/24/2012 11:00:50;0100;PBS_Server;Job;17531.tyrone-cluster;enqueuing into batch, state 1 hop 1
12/24/2012 11:00:50;0100;PBS_Server;Job;17531.tyrone-cluster;dequeuing from batch, state QUEUED
12/24/2012 11:00:50;0100;PBS_Server;Job;17531.tyrone-cluster;enqueuing into qp64, state 1 hop 1
12/24/2012 11:00:50;0008;PBS_Server;Job;17531.tyrone-cluster;Job Queued at request of ipcdskp@tyrone-cluster, owner = ipcdskp@tyrone-cluster, job name = n10, queue = qp64
12/24/2012 11:00:50;0040;PBS_Server;Svr;tyrone-cluster;Scheduler was sent the command new
12/24/2012 11:00:51;0008;PBS_Server;Job;17531.tyrone-cluster;Job Modified at request of Scheduler@tyrone-cluster
12/24/2012 11:00:51;0008;PBS_Server;Job;17531.tyrone-cluster;Job Run at request of Scheduler@tyrone-cluster
12/24/2012 11:00:51;0040;PBS_Server;Svr;tyrone-cluster;Scheduler was sent the command recyc
12/24/2012 11:00:51;000d;PBS_Server;Job;17531.tyrone-cluster;Not sending email: User does not want mail of this type.
12/24/2012 11:00:56;0040;PBS_Server;Svr;tyrone-cluster;Scheduler was sent the command new
12/24/2012 11:00:56;0008;PBS_Server;Job;17486.tyrone-cluster;Job Modified at request of Scheduler@tyrone-cluster
12/24/2012 11:00:56;0008;PBS_Server;Job;17487.tyrone-cluster;Job Modified at request of Scheduler@tyrone-cluster
12/24/2012 11:00:56;0008;PBS_Server;Job;17520.tyrone-cluster;Job Modified at request of Scheduler@tyrone-cluster
12/24/2012 11:01:01;0040;PBS_Server;Svr;tyrone-cluster;Scheduler was sent the command new
12/24/2012 11:01:27;0040;PBS_Server;Svr;tyrone-cluster;Scheduler was sent the command new
12/24/2012 11:01:33;0040;PBS_Server;Svr;tyrone-cluster;Scheduler was sent the command new
12/24/2012 11:01:57;0040;PBS_Server;Svr;tyrone-cluster;Scheduler was sent the command new
12/24/2012 11:02:01;0040;PBS_Server;Svr;tyrone-cluster;Scheduler was sent the command new
12/24/2012 11:02:29;0040;PBS_Server;Svr;tyrone-cluster;Scheduler was sent the command new
12/24/2012 11:02:34;0040;PBS_Server;Svr;tyrone-cluster;Scheduler was sent the command new
12/24/2012 11:02:57;0040;PBS_Server;Svr;tyrone-cluster;Scheduler was sent the command new
12/24/2012 11:03:03;0040;PBS_Server;Svr;tyrone-cluster;Scheduler was sent the command new
12/24/2012 11:03:23;0002;PBS_Server;Svr;PBS_Server;Torque Server Version = 3.0.5, loglevel = 0
12/24/2012 11:03:26;0040;PBS_Server;Svr;tyrone-cluster;Scheduler was sent the command new
12/24/2012 11:03:31;0040;PBS_Server;Svr;tyrone-cluster;Scheduler was sent the command new
12/24/2012 11:03:56;0040;PBS_Server;Svr;tyrone-cluster;Scheduler was sent the command new
12/24/2012 11:04:01;0040;PBS_Server;Svr;tyrone-cluster;Scheduler was sent the command new
12/24/2012 11:04:27;0040;PBS_Server;Svr;tyrone-cluster;Scheduler was sent the command new
12/24/2012 11:04:33;0040;PBS_Server;Svr;tyrone-cluster;Scheduler was sent the command new
12/24/2012 11:04:57;0040;PBS_Server;Svr;tyrone-cluster;Scheduler was sent the command new
12/24/2012 11:05:01;0040;PBS_Server;Svr;tyrone-cluster;Scheduler was sent the command new
12/24/2012 11:05:29;0040;PBS_Server;Svr;tyrone-cluster;Scheduler was sent the command new
12/24/2012 11:05:34;0040;PBS_Server;Svr;tyrone-cluster;Scheduler was sent the command new
12/24/2012 11:05:57;0040;PBS_Server;Svr;tyrone-cluster;Scheduler was sent the command new
12/24/2012 11:06:04;0040;PBS_Server;Svr;tyrone-cluster;Scheduler was sent the command new
12/24/2012 11:06:26;0040;PBS_Server;Svr;tyrone-cluster;Scheduler was sent the command new
12/24/2012 11:06:33;0040;PBS_Server;Svr;tyrone-cluster;Scheduler was sent the command new
12/24/2012 11:06:56;0040;PBS_Server;Svr;tyrone-cluster;Scheduler was sent the command new
12/24/2012 11:07:04;0040;PBS_Server;Svr;tyrone-cluster;Scheduler was sent the command new
12/24/2012 11:07:27;0040;PBS_Server;Svr;tyrone-cluster;Scheduler was sent the command new
12/24/2012 11:07:38;0040;PBS_Server;Svr;tyrone-cluster;Scheduler was sent the command new
12/24/2012 11:07:57;0040;PBS_Server;Svr;tyrone-cluster;Scheduler was sent the command new
12/24/2012 11:08:09;0040;PBS_Server;Svr;tyrone-cluster;Scheduler was sent the command new
12/24/2012 11:08:23;0002;PBS_Server;Svr;PBS_Server;Torque Server Version = 3.0.5, loglevel = 0
12/24/2012 11:08:26;0040;PBS_Server;Svr;tyrone-cluster;Scheduler was sent the command new
12/24/2012 11:08:41;0040;PBS_Server;Svr;tyrone-cluster;Scheduler was sent the command new
12/24/2012 11:08:57;0040;PBS_Server;Svr;tyrone-cluster;Scheduler was sent the command new
12/24/2012 11:09:09;0040;PBS_Server;Svr;tyrone-cluster;Scheduler was sent the command new
12/24/2012 11:09:27;0040;PBS_Server;Svr;tyrone-cluster;Scheduler was sent the command new
12/24/2012 11:09:39;0040;PBS_Server;Svr;tyrone-cluster;Scheduler was sent the command new
12/24/2012 11:09:59;0040;PBS_Server;Svr;tyrone-cluster;Scheduler was sent the command new
12/24/2012 11:10:11;0040;PBS_Server;Svr;tyrone-cluster;Scheduler was sent the command new
12/24/2012 11:10:27;0040;PBS_Server;Svr;tyrone-cluster;Scheduler was sent the command new
12/24/2012 11:10:40;0040;PBS_Server;Svr;tyrone-cluster;Scheduler was sent the command new
12/24/2012 11:10:40;0100;PBS_Server;Job;17532.tyrone-cluster;enqueuing into batch, state 1 hop 1
12/24/2012 11:10:40;0100;PBS_Server;Job;17532.tyrone-cluster;dequeuing from batch, state QUEUED
12/24/2012 11:10:40;0100;PBS_Server;Job;17532.tyrone-cluster;enqueuing into qp64, state 1 hop 1
12/24/2012 11:10:40;0008;PBS_Server;Job;17532.tyrone-cluster;Job Queued at request of csdpalvi@tyrone-cluster, owner = csdpalvi@tyrone-cluster, job name = n10, queue = qp64
12/24/2012 11:10:40;0008;PBS_Server;Job;17532.tyrone-cluster;Job Modified at request of Scheduler@tyrone-cluster
12/24/2012 11:10:57;0040;PBS_Server;Svr;tyrone-cluster;Scheduler was sent the command new
12/24/2012 11:11:12;0040;PBS_Server;Svr;tyrone-cluster;Scheduler was sent the command new
12/24/2012 11:11:29;0040;PBS_Server;Svr;tyrone-cluster;Scheduler was sent the command new
12/24/2012 11:11:42;0040;PBS_Server;Svr;tyrone-cluster;Scheduler was sent the command new
12/24/2012 11:11:57;0040;PBS_Server;Svr;tyrone-cluster;Scheduler was sent the command new
12/24/2012 11:12:11;0040;PBS_Server;Svr;tyrone-cluster;Scheduler was sent the command new
12/24/2012 11:12:26;0040;PBS_Server;Svr;tyrone-cluster;Scheduler was sent the command new
12/24/2012 11:12:42;0040;PBS_Server;Svr;tyrone-cluster;Scheduler was sent the command new
12/24/2012 11:13:00;0040;PBS_Server;Svr;tyrone-cluster;Scheduler was sent the command new
12/24/2012 11:13:12;0040;PBS_Server;Svr;tyrone-cluster;Scheduler was sent the command new
12/24/2012 11:13:23;0002;PBS_Server;Svr;PBS_Server;Torque Server Version = 3.0.5, loglevel = 0
12/24/2012 11:13:27;0040;PBS_Server;Svr;tyrone-cluster;Scheduler was sent the command new
12/24/2012 11:13:45;0040;PBS_Server;Svr;tyrone-cluster;Scheduler was sent the command new
12/24/2012 11:13:57;0040;PBS_Server;Svr;tyrone-cluster;Scheduler was sent the command new
12/24/2012 11:14:12;0040;PBS_Server;Svr;tyrone-cluster;Scheduler was sent the command new
12/24/2012 11:14:29;0040;PBS_Server;Svr;tyrone-cluster;Scheduler was sent the command new
12/24/2012 11:14:42;0040;PBS_Server;Svr;tyrone-cluster;Scheduler was sent the command new
12/24/2012 11:14:57;0040;PBS_Server;Svr;tyrone-cluster;Scheduler was sent the command new
12/24/2012 11:15:08;0100;PBS_Server;Job;17533.tyrone-cluster;enqueuing into batch, state 1 hop 1
12/24/2012 11:15:08;0100;PBS_Server;Job;17533.tyrone-cluster;dequeuing from batch, state QUEUED
12/24/2012 11:15:08;0100;PBS_Server;Job;17533.tyrone-cluster;enqueuing into qp64, state 1 hop 1
12/24/2012 11:15:08;0008;PBS_Server;Job;17533.tyrone-cluster;Job Queued at request of csdrjain@tyrone-cluster, owner = csdrjain@tyrone-cluster, job name = n10, queue = qp64
12/24/2012 11:15:08;0040;PBS_Server;Svr;tyrone-cluster;Scheduler was sent the command new
12/24/2012 11:15:08;0008;PBS_Server;Job;17533.tyrone-cluster;Job Modified at request of Scheduler@tyrone-cluster
12/24/2012 11:15:15;0040;PBS_Server;Svr;tyrone-cluster;Scheduler was sent the command new
12/24/2012 11:15:26;0040;PBS_Server;Svr;tyrone-cluster;Scheduler was sent the command new
12/24/2012 11:15:48;0040;PBS_Server;Svr;tyrone-cluster;Scheduler was sent the command new
12/24/2012 11:15:56;0040;PBS_Server;Svr;tyrone-cluster;Scheduler was sent the command new
12/24/2012 11:16:16;0040;PBS_Server;Svr;tyrone-cluster;Scheduler was sent the command new
12/24/2012 11:16:27;0040;PBS_Server;Svr;tyrone-cluster;Scheduler was sent the command new
12/24/2012 11:16:49;0040;PBS_Server;Svr;tyrone-cluster;Scheduler was sent the command new
12/24/2012 11:16:57;0040;PBS_Server;Svr;tyrone-cluster;Scheduler was sent the command new
12/24/2012 11:17:18;0040;PBS_Server;Svr;tyrone-cluster;Scheduler was sent the command new
12/24/2012 11:17:29;0040;PBS_Server;Svr;tyrone-cluster;Scheduler was sent the command new
12/24/2012 11:17:48;0040;PBS_Server;Svr;tyrone-cluster;Scheduler was sent the command new
12/24/2012 11:17:57;0040;PBS_Server;Svr;tyrone-cluster;Scheduler was sent the command new
12/24/2012 11:18:19;0040;PBS_Server;Svr;tyrone-cluster;Scheduler was sent the command new
12/24/2012 11:18:23;0002;PBS_Server;Svr;PBS_Server;Torque Server Version = 3.0.5, loglevel = 0
12/24/2012 11:18:26;0040;PBS_Server;Svr;tyrone-cluster;Scheduler was sent the command new
12/24/2012 11:18:53;0040;PBS_Server;Svr;tyrone-cluster;Scheduler was sent the command new
12/24/2012 11:19:00;0040;PBS_Server;Svr;tyrone-cluster;Scheduler was sent the command new
12/24/2012 11:19:24;0040;PBS_Server;Svr;tyrone-cluster;Scheduler was sent the command new
12/24/2012 11:19:27;0040;PBS_Server;Svr;tyrone-cluster;Scheduler was sent the command new
12/24/2012 11:19:56;0040;PBS_Server;Svr;tyrone-cluster;Scheduler was sent the command new
12/24/2012 11:20:26;0040;PBS_Server;Svr;tyrone-cluster;Scheduler was sent the command new
12/24/2012 11:20:49;0100;PBS_Server;Job;17534.tyrone-cluster;enqueuing into batch, state 1 hop 1
12/24/2012 11:20:49;0100;PBS_Server;Job;17534.tyrone-cluster;dequeuing from batch, state QUEUED
12/24/2012 11:20:49;0100;PBS_Server;Job;17534.tyrone-cluster;enqueuing into qp64, state 1 hop 1
12/24/2012 11:20:49;0008;PBS_Server;Job;17534.tyrone-cluster;Job Queued at request of ipckousi@tyrone-cluster, owner = ipckousi@tyrone-cluster, job name = n10, queue = qp64
12/24/2012 11:20:49;0040;PBS_Server;Svr;tyrone-cluster;Scheduler was sent the command new
12/24/2012 11:20:49;0008;PBS_Server;Job;17534.tyrone-cluster;Job Modified at request of Scheduler@tyrone-cluster
12/24/2012 11:20:57;0040;PBS_Server;Svr;tyrone-cluster;Scheduler was sent the command new
12/24/2012 11:21:27;0040;PBS_Server;Svr;tyrone-cluster;Scheduler was sent the command new
12/24/2012 11:21:59;0040;PBS_Server;Svr;tyrone-cluster;Scheduler was sent the command new
12/24/2012 11:22:27;0040;PBS_Server;Svr;tyrone-cluster;Scheduler was sent the command new
12/24/2012 11:22:58;0040;PBS_Server;Svr;tyrone-cluster;Scheduler was sent the command new
12/24/2012 11:23:23;0002;PBS_Server;Svr;PBS_Server;Torque Server Version = 3.0.5, loglevel = 0
12/24/2012 11:23:30;0040;PBS_Server;Svr;tyrone-cluster;Scheduler was sent the command new
12/24/2012 11:24:03;0040;PBS_Server;Svr;tyrone-cluster;Scheduler was sent the command new
12/24/2012 11:24:31;0040;PBS_Server;Svr;tyrone-cluster;Scheduler was sent the command new
12/24/2012 11:25:04;0040;PBS_Server;Svr;tyrone-cluster;Scheduler was sent the command new
12/24/2012 11:25:33;0040;PBS_Server;Svr;tyrone-cluster;Scheduler was sent the command new
12/24/2012 11:26:03;0040;PBS_Server;Svr;tyrone-cluster;Scheduler was sent the command new
12/24/2012 11:26:34;0040;PBS_Server;Svr;tyrone-cluster;Scheduler was sent the command new
12/24/2012 11:27:08;0040;PBS_Server;Svr;tyrone-cluster;Scheduler was sent the command new
12/24/2012 11:27:39;0040;PBS_Server;Svr;tyrone-cluster;Scheduler was sent the command new
12/24/2012 11:27:55;0100;PBS_Server;Job;17535.tyrone-cluster;enqueuing into batch, state 1 hop 1
12/24/2012 11:27:55;0100;PBS_Server;Job;17535.tyrone-cluster;dequeuing from batch, state QUEUED
12/24/2012 11:27:55;0100;PBS_Server;Job;17535.tyrone-cluster;enqueuing into qp64, state 1 hop 1
12/24/2012 11:27:55;0008;PBS_Server;Job;17535.tyrone-cluster;Job Queued at request of csddibye@tyrone-cluster, owner = csddibye@tyrone-cluster, job name = SM3_MS-GB_M06_HB, queue = qp64
12/24/2012 11:27:55;0040;PBS_Server;Svr;tyrone-cluster;Scheduler was sent the command new
12/24/2012 11:27:55;0008;PBS_Server;Job;17535.tyrone-cluster;Job Modified at request of Scheduler@tyrone-cluster
12/24/2012 11:28:11;0040;PBS_Server;Svr;tyrone-cluster;Scheduler was sent the command new
12/24/2012 11:28:23;0002;PBS_Server;Svr;PBS_Server;Torque Server Version = 3.0.5, loglevel = 0
12/24/2012 11:28:31;0008;PBS_Server;Job;17515.tyrone-cluster;Job deleted at request of csddibye@tyrone-cluster
12/24/2012 11:28:31;0008;PBS_Server;Job;17515.tyrone-cluster;Job sent signal SIGTERM on delete
12/24/2012 11:28:32;0008;PBS_Server;Job;17515.tyrone-cluster;Job deleted at request of csddibye@tyrone-cluster
12/24/2012 11:28:32;0008;PBS_Server;Job;17515.tyrone-cluster;Job sent signal SIGTERM on delete
12/24/2012 11:28:33;0008;PBS_Server;Job;17515.tyrone-cluster;Job sent signal SIGKILL on delete
12/24/2012 11:28:36;000d;PBS_Server;Job;17515.tyrone-cluster;Not sending email: User does not want mail of this type.
12/24/2012 11:28:36;0010;PBS_Server;Job;17515.tyrone-cluster;Exit_status=143 resources_used.cput=154:17:13 resources_used.mem=4337860kb resources_used.vmem=10571352kb resources_used.walltime=02:25:29
12/24/2012 11:28:36;0008;PBS_Server;Job;NULL;on_job_exit valid pjob: 0x1b6e960 (substate=50)
12/24/2012 11:28:36;0008;PBS_Server;Job;NULL;on_job_exit valid pjob: 0x1b6e960 (substate=51)
12/24/2012 11:28:40;0008;PBS_Server;Job;NULL;on_job_exit valid pjob: 0x1b6e960 (substate=51)
12/24/2012 11:28:40;0008;PBS_Server;Job;NULL;on_job_exit valid pjob: 0x1b6e960 (substate=53)
12/24/2012 11:28:40;0100;PBS_Server;Job;17515.tyrone-cluster;dequeuing from qp64, state COMPLETE
12/24/2012 11:28:40;0040;PBS_Server;Svr;tyrone-cluster;Scheduler was sent the command term
12/24/2012 11:28:40;0008;PBS_Server;Job;17486.tyrone-cluster;Job Modified at request of Scheduler@tyrone-cluster
12/24/2012 11:28:40;0008;PBS_Server;Job;17487.tyrone-cluster;Job Modified at request of Scheduler@tyrone-cluster
12/24/2012 11:28:40;0008;PBS_Server;Job;17520.tyrone-cluster;Job Modified at request of Scheduler@tyrone-cluster
12/24/2012 11:28:40;0008;PBS_Server;Job;17532.tyrone-cluster;Job Modified at request of Scheduler@tyrone-cluster
12/24/2012 11:28:40;0008;PBS_Server;Job;17532.tyrone-cluster;Job Run at request of Scheduler@tyrone-cluster
12/24/2012 11:28:41;0040;PBS_Server;Svr;tyrone-cluster;Scheduler was sent the command recyc
12/24/2012 11:28:41;000d;PBS_Server;Job;17532.tyrone-cluster;Not sending email: User does not want mail of this type.
12/24/2012 11:29:12;0040;PBS_Server;Svr;tyrone-cluster;Scheduler was sent the command new
12/24/2012 11:29:12;0008;PBS_Server;Job;17486.tyrone-cluster;Job Modified at request of Scheduler@tyrone-cluster
12/24/2012 11:29:12;0008;PBS_Server;Job;17487.tyrone-cluster;Job Modified at request of Scheduler@tyrone-cluster
12/24/2012 11:29:12;0008;PBS_Server;Job;17520.tyrone-cluster;Job Modified at request of Scheduler@tyrone-cluster
12/24/2012 11:29:42;0040;PBS_Server;Svr;tyrone-cluster;Scheduler was sent the command new
12/24/2012 11:30:11;0040;PBS_Server;Svr;tyrone-cluster;Scheduler was sent the command new
12/24/2012 11:30:42;0040;PBS_Server;Svr;tyrone-cluster;Scheduler was sent the command new
12/24/2012 11:31:12;0040;PBS_Server;Svr;tyrone-cluster;Scheduler was sent the command new
12/24/2012 11:31:44;0040;PBS_Server;Svr;tyrone-cluster;Scheduler was sent the command new
12/24/2012 11:32:12;0040;PBS_Server;Svr;tyrone-cluster;Scheduler was sent the command new
12/24/2012 11:32:42;0040;PBS_Server;Svr;tyrone-cluster;Scheduler was sent the command new
12/24/2012 11:33:11;0040;PBS_Server;Svr;tyrone-cluster;Scheduler was sent the command new
12/24/2012 11:33:23;0002;PBS_Server;Svr;PBS_Server;Torque Server Version = 3.0.5, loglevel = 0
12/24/2012 11:33:42;0040;PBS_Server;Svr;tyrone-cluster;Scheduler was sent the command new
12/24/2012 11:34:12;0040;PBS_Server;Svr;tyrone-cluster;Scheduler was sent the command new
12/24/2012 11:34:41;0040;PBS_Server;Svr;tyrone-cluster;Scheduler was sent the command new
12/24/2012 11:35:12;0040;PBS_Server;Svr;tyrone-cluster;Scheduler was sent the command new
12/24/2012 11:35:41;0040;PBS_Server;Svr;tyrone-cluster;Scheduler was sent the command new
12/24/2012 11:36:11;0040;PBS_Server;Svr;tyrone-cluster;Scheduler was sent the command new
12/24/2012 11:36:42;0040;PBS_Server;Svr;tyrone-cluster;Scheduler was sent the command new
12/24/2012 11:37:12;0040;PBS_Server;Svr;tyrone-cluster;Scheduler was sent the command new
12/24/2012 11:37:44;0040;PBS_Server;Svr;tyrone-cluster;Scheduler was sent the command new
12/24/2012 11:37:45;0100;PBS_Server;Job;17536.tyrone-cluster;enqueuing into batch, state 1 hop 1
12/24/2012 11:37:45;0100;PBS_Server;Job;17536.tyrone-cluster;dequeuing from batch, state QUEUED
12/24/2012 11:37:45;0100;PBS_Server;Job;17536.tyrone-cluster;enqueuing into qp32, state 1 hop 1
12/24/2012 11:37:45;0008;PBS_Server;Job;17536.tyrone-cluster;Job Queued at request of csddibye@tyrone-cluster, owner = csddibye@tyrone-cluster, job name = SM4_MS-GB_M06_HB, queue = qp32
12/24/2012 11:37:45;0040;PBS_Server;Svr;tyrone-cluster;Scheduler was sent the command new
12/24/2012 11:37:45;0008;PBS_Server;Job;17536.tyrone-cluster;Job Modified at request of Scheduler@tyrone-cluster
12/24/2012 11:38:12;0040;PBS_Server;Svr;tyrone-cluster;Scheduler was sent the command new
12/24/2012 11:38:23;0002;PBS_Server;Svr;PBS_Server;Torque Server Version = 3.0.5, loglevel = 0
12/24/2012 11:38:43;0040;PBS_Server;Svr;tyrone-cluster;Scheduler was sent the command new
12/24/2012 11:39:11;0040;PBS_Server;Svr;tyrone-cluster;Scheduler was sent the command new
12/24/2012 11:39:42;0040;PBS_Server;Svr;tyrone-cluster;Scheduler was sent the command new
12/24/2012 11:40:12;0040;PBS_Server;Svr;tyrone-cluster;Scheduler was sent the command new
12/24/2012 11:40:41;0040;PBS_Server;Svr;tyrone-cluster;Scheduler was sent the command new
12/24/2012 11:41:12;0040;PBS_Server;Svr;tyrone-cluster;Scheduler was sent the command new
12/24/2012 11:41:43;0040;PBS_Server;Svr;tyrone-cluster;Scheduler was sent the command new
12/24/2012 11:42:15;0040;PBS_Server;Svr;tyrone-cluster;Scheduler was sent the command new
12/24/2012 11:42:53;0040;PBS_Server;Svr;tyrone-cluster;Scheduler was sent the command new
12/24/2012 11:43:16;0040;PBS_Server;Svr;tyrone-cluster;Scheduler was sent the command new
12/24/2012 11:43:23;0002;PBS_Server;Svr;PBS_Server;Torque Server Version = 3.0.5, loglevel = 0
12/24/2012 11:43:49;0040;PBS_Server;Svr;tyrone-cluster;Scheduler was sent the command new
12/24/2012 11:44:23;0040;PBS_Server;Svr;tyrone-cluster;Scheduler was sent the command new
12/24/2012 11:44:54;0040;PBS_Server;Svr;tyrone-cluster;Scheduler was sent the command new
12/24/2012 11:45:25;0040;PBS_Server;Svr;tyrone-cluster;Scheduler was sent the command new
12/24/2012 11:45:56;0040;PBS_Server;Svr;tyrone-cluster;Scheduler was sent the command new
12/24/2012 11:46:27;0040;PBS_Server;Svr;tyrone-cluster;Scheduler was sent the command new
12/24/2012 11:46:57;0040;PBS_Server;Svr;tyrone-cluster;Scheduler was sent the command new
12/24/2012 11:47:26;0040;PBS_Server;Svr;tyrone-cluster;Scheduler was sent the command new
12/24/2012 11:47:57;0040;PBS_Server;Svr;tyrone-cluster;Scheduler was sent the command new
12/24/2012 11:48:00;0100;PBS_Server;Job;17537.tyrone-cluster;enqueuing into batch, state 1 hop 1
12/24/2012 11:48:00;0100;PBS_Server;Job;17537.tyrone-cluster;dequeuing from batch, state QUEUED
12/24/2012 11:48:00;0100;PBS_Server;Job;17537.tyrone-cluster;enqueuing into qp64, state 1 hop 1
12/24/2012 11:48:00;0008;PBS_Server;Job;17537.tyrone-cluster;Job Queued at request of esdraj@tyrone-cluster, owner = esdraj@tyrone-cluster, job name = dip45ns, queue = qp64
12/24/2012 11:48:00;0040;PBS_Server;Svr;tyrone-cluster;Scheduler was sent the command new
12/24/2012 11:48:00;0008;PBS_Server;Job;17537.tyrone-cluster;Job Modified at request of Scheduler@tyrone-cluster
12/24/2012 11:48:23;0002;PBS_Server;Svr;PBS_Server;Torque Server Version = 3.0.5, loglevel = 0
12/24/2012 11:48:28;0040;PBS_Server;Svr;tyrone-cluster;Scheduler was sent the command new
12/24/2012 11:48:43;0008;PBS_Server;Job;17537.tyrone-cluster;Job deleted at request of esdraj@tyrone-cluster
12/24/2012 11:48:43;0008;PBS_Server;Job;NULL;on_job_exit valid pjob: 0x1b588f0 (substate=59)
12/24/2012 11:48:43;0100;PBS_Server;Job;17537.tyrone-cluster;dequeuing from qp64, state COMPLETE
12/24/2012 11:48:43;0040;PBS_Server;Svr;tyrone-cluster;Scheduler was sent the command term
12/24/2012 11:49:00;0040;PBS_Server;Svr;tyrone-cluster;Scheduler was sent the command new
12/24/2012 11:49:38;0040;PBS_Server;Svr;tyrone-cluster;Scheduler was sent the command new
12/24/2012 11:49:47;0100;PBS_Server;Job;17538.tyrone-cluster;enqueuing into batch, state 1 hop 1
12/24/2012 11:49:47;0100;PBS_Server;Job;17538.tyrone-cluster;dequeuing from batch, state QUEUED
12/24/2012 11:49:47;0100;PBS_Server;Job;17538.tyrone-cluster;enqueuing into qp64, state 1 hop 1
12/24/2012 11:49:47;0008;PBS_Server;Job;17538.tyrone-cluster;Job Queued at request of esdraj@tyrone-cluster, owner = esdraj@tyrone-cluster, job name = dip45ns, queue = qp64
12/24/2012 11:49:47;0040;PBS_Server;Svr;tyrone-cluster;Scheduler was sent the command new
12/24/2012 11:49:47;0008;PBS_Server;Job;17538.tyrone-cluster;Job Modified at request of Scheduler@tyrone-cluster
12/24/2012 11:50:01;0040;PBS_Server;Svr;tyrone-cluster;Scheduler was sent the command new
12/24/2012 11:50:34;0040;PBS_Server;Svr;tyrone-cluster;Scheduler was sent the command new
12/24/2012 11:51:08;0040;PBS_Server;Svr;tyrone-cluster;Scheduler was sent the command new
12/24/2012 11:51:39;0040;PBS_Server;Svr;tyrone-cluster;Scheduler was sent the command new
12/24/2012 11:52:11;0040;PBS_Server;Svr;tyrone-cluster;Scheduler was sent the command new
12/24/2012 11:52:41;0040;PBS_Server;Svr;tyrone-cluster;Scheduler was sent the command new
12/24/2012 11:53:12;0040;PBS_Server;Svr;tyrone-cluster;Scheduler was sent the command new
12/24/2012 11:53:23;0002;PBS_Server;Svr;PBS_Server;Torque Server Version = 3.0.5, loglevel = 0
12/24/2012 11:53:43;0040;PBS_Server;Svr;tyrone-cluster;Scheduler was sent the command new
12/24/2012 11:54:11;0040;PBS_Server;Svr;tyrone-cluster;Scheduler was sent the command new
12/24/2012 11:54:42;0040;PBS_Server;Svr;tyrone-cluster;Scheduler was sent the command new
12/24/2012 11:55:12;0040;PBS_Server;Svr;tyrone-cluster;Scheduler was sent the command new
12/24/2012 11:55:44;0040;PBS_Server;Svr;tyrone-cluster;Scheduler was sent the command new
12/24/2012 11:56:12;0040;PBS_Server;Svr;tyrone-cluster;Scheduler was sent the command new
12/24/2012 11:56:44;0040;PBS_Server;Svr;tyrone-cluster;Scheduler was sent the command new
12/24/2012 11:57:15;0040;PBS_Server;Svr;tyrone-cluster;Scheduler was sent the command new
12/24/2012 11:57:53;0040;PBS_Server;Svr;tyrone-cluster;Scheduler was sent the command new
12/24/2012 11:58:16;0040;PBS_Server;Svr;tyrone-cluster;Scheduler was sent the command new
12/24/2012 11:58:23;0002;PBS_Server;Svr;PBS_Server;Torque Server Version = 3.0.5, loglevel = 0
12/24/2012 11:58:49;0040;PBS_Server;Svr;tyrone-cluster;Scheduler was sent the command new
12/24/2012 11:59:23;0040;PBS_Server;Svr;tyrone-cluster;Scheduler was sent the command new
12/24/2012 11:59:53;0040;PBS_Server;Svr;tyrone-cluster;Scheduler was sent the command new
12/24/2012 12:00:26;0040;PBS_Server;Svr;tyrone-cluster;Scheduler was sent the command new
12/24/2012 12:00:56;0040;PBS_Server;Svr;tyrone-cluster;Scheduler was sent the command new
12/24/2012 12:00:57;0100;PBS_Server;Job;17539.tyrone-cluster;enqueuing into batch, state 1 hop 1
12/24/2012 12:00:57;0100;PBS_Server;Job;17539.tyrone-cluster;dequeuing from batch, state QUEUED
12/24/2012 12:00:57;0100;PBS_Server;Job;17539.tyrone-cluster;enqueuing into qp32, state 1 hop 1
12/24/2012 12:00:57;0008;PBS_Server;Job;17539.tyrone-cluster;Job Queued at request of metposhi@tyrone-cluster, owner = metposhi@tyrone-cluster, job name = poshit1, queue = qp32
12/24/2012 12:00:57;0040;PBS_Server;Svr;tyrone-cluster;Scheduler was sent the command new
12/24/2012 12:00:57;0008;PBS_Server;Job;17539.tyrone-cluster;Job Modified at request of Scheduler@tyrone-cluster
12/24/2012 12:01:27;0040;PBS_Server;Svr;tyrone-cluster;Scheduler was sent the command new
12/24/2012 12:01:56;0040;PBS_Server;Svr;tyrone-cluster;Scheduler was sent the command new
12/24/2012 12:02:30;0040;PBS_Server;Svr;tyrone-cluster;Scheduler was sent the command new
12/24/2012 12:02:57;0040;PBS_Server;Svr;tyrone-cluster;Scheduler was sent the command new
12/24/2012 12:03:23;0002;PBS_Server;Svr;PBS_Server;Torque Server Version = 3.0.5, loglevel = 0
12/24/2012 12:03:28;0040;PBS_Server;Svr;tyrone-cluster;Scheduler was sent the command new
12/24/2012 12:04:00;0040;PBS_Server;Svr;tyrone-cluster;Scheduler was sent the command new
12/24/2012 12:04:38;0040;PBS_Server;Svr;tyrone-cluster;Scheduler was sent the command new
12/24/2012 12:05:01;0040;PBS_Server;Svr;tyrone-cluster;Scheduler was sent the command new
12/24/2012 12:05:34;0040;PBS_Server;Svr;tyrone-cluster;Scheduler was sent the command new
12/24/2012 12:06:08;0040;PBS_Server;Svr;tyrone-cluster;Scheduler was sent the command new
12/24/2012 12:06:39;0040;PBS_Server;Svr;tyrone-cluster;Scheduler was sent the command new
12/24/2012 12:07:11;0040;PBS_Server;Svr;tyrone-cluster;Scheduler was sent the command new
12/24/2012 12:07:41;0040;PBS_Server;Svr;tyrone-cluster;Scheduler was sent the command new
12/24/2012 12:08:12;0040;PBS_Server;Svr;tyrone-cluster;Scheduler was sent the command new
12/24/2012 12:08:23;0002;PBS_Server;Svr;PBS_Server;Torque Server Version = 3.0.5, loglevel = 0
12/24/2012 12:08:43;0040;PBS_Server;Svr;tyrone-cluster;Scheduler was sent the command new
12/24/2012 12:09:15;0040;PBS_Server;Svr;tyrone-cluster;Scheduler was sent the command new
12/24/2012 12:09:53;0040;PBS_Server;Svr;tyrone-cluster;Scheduler was sent the command new
12/24/2012 12:10:16;0040;PBS_Server;Svr;tyrone-cluster;Scheduler was sent the command new
12/24/2012 12:10:49;0040;PBS_Server;Svr;tyrone-cluster;Scheduler was sent the command new
12/24/2012 12:11:23;0040;PBS_Server;Svr;tyrone-cluster;Scheduler was sent the command new
12/24/2012 12:11:54;0040;PBS_Server;Svr;tyrone-cluster;Scheduler was sent the command new
12/24/2012 12:12:25;0040;PBS_Server;Svr;tyrone-cluster;Scheduler was sent the command new
12/24/2012 12:12:56;0040;PBS_Server;Svr;tyrone-cluster;Scheduler was sent the command new
12/24/2012 12:13:23;0002;PBS_Server;Svr;PBS_Server;Torque Server Version = 3.0.5, loglevel = 0
12/24/2012 12:13:27;0040;PBS_Server;Svr;tyrone-cluster;Scheduler was sent the command new
12/24/2012 12:13:58;0040;PBS_Server;Svr;tyrone-cluster;Scheduler was sent the command new
12/24/2012 12:14:30;0040;PBS_Server;Svr;tyrone-cluster;Scheduler was sent the command new
12/24/2012 12:15:08;0040;PBS_Server;Svr;tyrone-cluster;Scheduler was sent the command new
12/24/2012 12:15:31;0040;PBS_Server;Svr;tyrone-cluster;Scheduler was sent the command new
12/24/2012 12:16:04;0040;PBS_Server;Svr;tyrone-cluster;Scheduler was sent the command new
12/24/2012 12:16:38;0040;PBS_Server;Svr;tyrone-cluster;Scheduler was sent the command new
12/24/2012 12:17:09;0040;PBS_Server;Svr;tyrone-cluster;Scheduler was sent the command new
12/24/2012 12:17:41;0040;PBS_Server;Svr;tyrone-cluster;Scheduler was sent the command new
12/24/2012 12:17:42;0100;PBS_Server;Job;17540.tyrone-cluster;enqueuing into batch, state 1 hop 1
12/24/2012 12:17:42;0100;PBS_Server;Job;17540.tyrone-cluster;dequeuing from batch, state QUEUED
12/24/2012 12:17:42;0100;PBS_Server;Job;17540.tyrone-cluster;enqueuing into qp64, state 1 hop 1
12/24/2012 12:17:42;0008;PBS_Server;Job;17540.tyrone-cluster;Job Queued at request of mrcatanu@tyrone-cluster, owner = mrcatanu@tyrone-cluster, job name = relax2, queue = qp64
12/24/2012 12:17:42;0040;PBS_Server;Svr;tyrone-cluster;Scheduler was sent the command new
12/24/2012 12:17:43;0008;PBS_Server;Job;17540.tyrone-cluster;Job Modified at request of Scheduler@tyrone-cluster
12/24/2012 12:18:10;0040;PBS_Server;Svr;tyrone-cluster;Scheduler was sent the command new
12/24/2012 12:18:23;0002;PBS_Server;Svr;PBS_Server;Torque Server Version = 3.0.5, loglevel = 0
12/24/2012 12:18:42;0040;PBS_Server;Svr;tyrone-cluster;Scheduler was sent the command new
12/24/2012 12:19:12;0040;PBS_Server;Svr;tyrone-cluster;Scheduler was sent the command new
12/24/2012 12:19:43;0040;PBS_Server;Svr;tyrone-cluster;Scheduler was sent the command new
12/24/2012 12:19:43;0100;PBS_Server;Job;17541.tyrone-cluster;enqueuing into batch, state 1 hop 1
12/24/2012 12:19:43;0100;PBS_Server;Job;17541.tyrone-cluster;dequeuing from batch, state QUEUED
12/24/2012 12:19:43;0100;PBS_Server;Job;17541.tyrone-cluster;enqueuing into qp32, state 1 hop 1
12/24/2012 12:19:43;0008;PBS_Server;Job;17541.tyrone-cluster;Job Queued at request of metposhi@tyrone-cluster, owner = metposhi@tyrone-cluster, job name = poshit1, queue = qp32
12/24/2012 12:19:43;0008;PBS_Server;Job;17541.tyrone-cluster;Job Modified at request of Scheduler@tyrone-cluster
12/24/2012 12:20:23;0040;PBS_Server;Svr;tyrone-cluster;Scheduler was sent the command new
12/24/2012 12:20:46;0040;PBS_Server;Svr;tyrone-cluster;Scheduler was sent the command new
12/24/2012 12:21:19;0040;PBS_Server;Svr;tyrone-cluster;Scheduler was sent the command new
12/24/2012 12:21:53;0040;PBS_Server;Svr;tyrone-cluster;Scheduler was sent the command new
12/24/2012 12:22:23;0040;PBS_Server;Svr;tyrone-cluster;Scheduler was sent the command new
12/24/2012 12:22:24;0100;PBS_Server;Job;17542.tyrone-cluster;enqueuing into batch, state 1 hop 1
12/24/2012 12:22:24;0100;PBS_Server;Job;17542.tyrone-cluster;dequeuing from batch, state QUEUED
12/24/2012 12:22:24;0100;PBS_Server;Job;17542.tyrone-cluster;enqueuing into idqueue, state 1 hop 1
12/24/2012 12:22:24;0008;PBS_Server;Job;17542.tyrone-cluster;Job Queued at request of ipcdskp@tyrone-cluster, owner = ipcdskp@tyrone-cluster, job name = n10, queue = idqueue
12/24/2012 12:22:24;0040;PBS_Server;Svr;tyrone-cluster;Scheduler was sent the command new
12/24/2012 12:22:24;0008;PBS_Server;Job;17542.tyrone-cluster;Job Modified at request of Scheduler@tyrone-cluster
12/24/2012 12:22:24;0008;PBS_Server;Job;17542.tyrone-cluster;Job Run at request of Scheduler@tyrone-cluster
12/24/2012 12:22:25;0040;PBS_Server;Svr;tyrone-cluster;Scheduler was sent the command recyc
12/24/2012 12:22:25;000d;PBS_Server;Job;17542.tyrone-cluster;Not sending email: User does not want mail of this type.
12/24/2012 12:22:56;0040;PBS_Server;Svr;tyrone-cluster;Scheduler was sent the command new
12/24/2012 12:23:23;0002;PBS_Server;Svr;PBS_Server;Torque Server Version = 3.0.5, loglevel = 0
12/24/2012 12:23:25;0040;PBS_Server;Svr;tyrone-cluster;Scheduler was sent the command new
12/24/2012 12:23:57;0040;PBS_Server;Svr;tyrone-cluster;Scheduler was sent the command new
12/24/2012 12:24:28;0040;PBS_Server;Svr;tyrone-cluster;Scheduler was sent the command new
12/24/2012 12:25:00;0040;PBS_Server;Svr;tyrone-cluster;Scheduler was sent the command new
12/24/2012 12:25:38;0040;PBS_Server;Svr;tyrone-cluster;Scheduler was sent the command new
12/24/2012 12:26:01;0040;PBS_Server;Svr;tyrone-cluster;Scheduler was sent the command new
12/24/2012 12:26:34;0040;PBS_Server;Svr;tyrone-cluster;Scheduler was sent the command new
12/24/2012 12:27:08;0040;PBS_Server;Svr;tyrone-cluster;Scheduler was sent the command new
12/24/2012 12:27:38;0040;PBS_Server;Svr;tyrone-cluster;Scheduler was sent the command new
12/24/2012 12:28:10;0040;PBS_Server;Svr;tyrone-cluster;Scheduler was sent the command new
12/24/2012 12:28:23;0002;PBS_Server;Svr;PBS_Server;Torque Server Version = 3.0.5, loglevel = 0
12/24/2012 12:28:40;0040;PBS_Server;Svr;tyrone-cluster;Scheduler was sent the command new
12/24/2012 12:29:12;0040;PBS_Server;Svr;tyrone-cluster;Scheduler was sent the command new
12/24/2012 12:29:43;0040;PBS_Server;Svr;tyrone-cluster;Scheduler was sent the command new
12/24/2012 12:30:14;0040;PBS_Server;Svr;tyrone-cluster;Scheduler was sent the command new
12/24/2012 12:30:53;0040;PBS_Server;Svr;tyrone-cluster;Scheduler was sent the command new
12/24/2012 12:31:16;0040;PBS_Server;Svr;tyrone-cluster;Scheduler was sent the command new
12/24/2012 12:31:49;0040;PBS_Server;Svr;tyrone-cluster;Scheduler was sent the command new
12/24/2012 12:32:23;0040;PBS_Server;Svr;tyrone-cluster;Scheduler was sent the command new
12/24/2012 12:32:54;0040;PBS_Server;Svr;tyrone-cluster;Scheduler was sent the command new
12/24/2012 12:33:23;0002;PBS_Server;Svr;PBS_Server;Torque Server Version = 3.0.5, loglevel = 0
12/24/2012 12:33:25;0040;PBS_Server;Svr;tyrone-cluster;Scheduler was sent the command new
12/24/2012 12:33:53;0040;PBS_Server;Svr;tyrone-cluster;Scheduler was sent the command new
12/24/2012 12:34:24;0040;PBS_Server;Svr;tyrone-cluster;Scheduler was sent the command new
12/24/2012 12:34:55;0040;PBS_Server;Svr;tyrone-cluster;Scheduler was sent the command new
12/24/2012 12:35:25;0040;PBS_Server;Svr;tyrone-cluster;Scheduler was sent the command new
12/24/2012 12:35:56;0040;PBS_Server;Svr;tyrone-cluster;Scheduler was sent the command new
12/24/2012 12:35:56;000d;PBS_Server;Job;17530.tyrone-cluster;Not sending email: User does not want mail of this type.
12/24/2012 12:35:56;0010;PBS_Server;Job;17530.tyrone-cluster;Exit_status=143 resources_used.cput=58:39:24 resources_used.mem=3644832kb resources_used.vmem=12146724kb resources_used.walltime=02:00:28
12/24/2012 12:35:56;0008;PBS_Server;Job;NULL;on_job_exit valid pjob: 0x1d2d0d0 (substate=50)
12/24/2012 12:35:56;0008;PBS_Server;Job;NULL;on_job_exit valid pjob: 0x1d2d0d0 (substate=51)
12/24/2012 12:35:56;0008;PBS_Server;Job;NULL;on_job_exit valid pjob: 0x1d2d0d0 (substate=51)
12/24/2012 12:35:56;0008;PBS_Server;Job;NULL;on_job_exit valid pjob: 0x1d2d0d0 (substate=53)
12/24/2012 12:35:56;0100;PBS_Server;Job;17530.tyrone-cluster;dequeuing from idqueue, state COMPLETE
12/24/2012 12:36:28;0040;PBS_Server;Svr;tyrone-cluster;Scheduler was sent the command new
12/24/2012 12:36:59;0040;PBS_Server;Svr;tyrone-cluster;Scheduler was sent the command new
12/24/2012 12:37:38;0040;PBS_Server;Svr;tyrone-cluster;Scheduler was sent the command new
12/24/2012 12:38:03;0040;PBS_Server;Svr;tyrone-cluster;Scheduler was sent the command new
12/24/2012 12:38:23;0002;PBS_Server;Svr;PBS_Server;Torque Server Version = 3.0.5, loglevel = 0
12/24/2012 12:38:34;0040;PBS_Server;Svr;tyrone-cluster;Scheduler was sent the command new
12/24/2012 12:39:08;0040;PBS_Server;Svr;tyrone-cluster;Scheduler was sent the command new
12/24/2012 12:39:39;0040;PBS_Server;Svr;tyrone-cluster;Scheduler was sent the command new
12/24/2012 12:40:10;0040;PBS_Server;Svr;tyrone-cluster;Scheduler was sent the command new
12/24/2012 12:40:40;0040;PBS_Server;Svr;tyrone-cluster;Scheduler was sent the command new
12/24/2012 12:41:12;0040;PBS_Server;Svr;tyrone-cluster;Scheduler was sent the command new
12/24/2012 12:41:42;0040;PBS_Server;Svr;tyrone-cluster;Scheduler was sent the command new
12/24/2012 12:42:15;0040;PBS_Server;Svr;tyrone-cluster;Scheduler was sent the command new
12/24/2012 12:42:53;0040;PBS_Server;Svr;tyrone-cluster;Scheduler was sent the command new
12/24/2012 12:43:23;0002;PBS_Server;Svr;PBS_Server;Torque Server Version = 3.0.5, loglevel = 0
12/24/2012 12:43:24;0040;PBS_Server;Svr;tyrone-cluster;Scheduler was sent the command new
12/24/2012 12:43:55;0040;PBS_Server;Svr;tyrone-cluster;Scheduler was sent the command new
12/24/2012 12:44:17;0008;PBS_Server;Job;17538.tyrone-cluster;Job deleted at request of esdraj@tyrone-cluster
12/24/2012 12:44:17;0008;PBS_Server;Job;NULL;on_job_exit valid pjob: 0x1b588f0 (substate=59)
12/24/2012 12:44:17;0100;PBS_Server;Job;17538.tyrone-cluster;dequeuing from qp64, state COMPLETE
12/24/2012 12:44:17;0040;PBS_Server;Svr;tyrone-cluster;Scheduler was sent the command term
12/24/2012 12:44:25;0040;PBS_Server;Svr;tyrone-cluster;Scheduler was sent the command new
12/24/2012 12:44:27;0100;PBS_Server;Job;17543.tyrone-cluster;enqueuing into batch, state 1 hop 1
12/24/2012 12:44:27;0100;PBS_Server;Job;17543.tyrone-cluster;dequeuing from batch, state QUEUED
12/24/2012 12:44:27;0100;PBS_Server;Job;17543.tyrone-cluster;enqueuing into qp64, state 1 hop 1
12/24/2012 12:44:27;0008;PBS_Server;Job;17543.tyrone-cluster;Job Queued at request of esdraj@tyrone-cluster, owner = esdraj@tyrone-cluster, job name = dip45ns, queue = qp64
12/24/2012 12:44:27;0040;PBS_Server;Svr;tyrone-cluster;Scheduler was sent the command new
12/24/2012 12:44:28;0008;PBS_Server;Job;17543.tyrone-cluster;Job Modified at request of Scheduler@tyrone-cluster
12/24/2012 12:44:57;0040;PBS_Server;Svr;tyrone-cluster;Scheduler was sent the command new
12/24/2012 12:45:28;0040;PBS_Server;Svr;tyrone-cluster;Scheduler was sent the command new
12/24/2012 12:46:00;0040;PBS_Server;Svr;tyrone-cluster;Scheduler was sent the command new
12/24/2012 12:46:38;0040;PBS_Server;Svr;tyrone-cluster;Scheduler was sent the command new
12/24/2012 12:47:03;0040;PBS_Server;Svr;tyrone-cluster;Scheduler was sent the command new
12/24/2012 12:47:34;0040;PBS_Server;Svr;tyrone-cluster;Scheduler was sent the command new
12/24/2012 12:47:42;0100;PBS_Server;Job;17544.tyrone-cluster;enqueuing into batch, state 1 hop 1
12/24/2012 12:47:42;0100;PBS_Server;Job;17544.tyrone-cluster;dequeuing from batch, state QUEUED
12/24/2012 12:47:42;0100;PBS_Server;Job;17544.tyrone-cluster;enqueuing into idqueue, state 1 hop 1
12/24/2012 12:47:42;0008;PBS_Server;Job;17544.tyrone-cluster;Job Queued at request of metposhi@tyrone-cluster, owner = metposhi@tyrone-cluster, job name = poshit1, queue = idqueue
12/24/2012 12:47:42;0040;PBS_Server;Svr;tyrone-cluster;Scheduler was sent the command new
12/24/2012 12:47:42;0008;PBS_Server;Job;17544.tyrone-cluster;Job Modified at request of Scheduler@tyrone-cluster
12/24/2012 12:47:42;0008;PBS_Server;Job;17544.tyrone-cluster;Job Run at request of Scheduler@tyrone-cluster
12/24/2012 12:47:42;0040;PBS_Server;Svr;tyrone-cluster;Scheduler was sent the command recyc
12/24/2012 12:47:42;000d;PBS_Server;Job;17544.tyrone-cluster;Not sending email: User does not want mail of this type.
12/24/2012 12:48:08;0040;PBS_Server;Svr;tyrone-cluster;Scheduler was sent the command new
12/24/2012 12:48:23;0002;PBS_Server;Svr;PBS_Server;Torque Server Version = 3.0.5, loglevel = 0
12/24/2012 12:48:39;0040;PBS_Server;Svr;tyrone-cluster;Scheduler was sent the command new
12/24/2012 12:49:10;0040;PBS_Server;Svr;tyrone-cluster;Scheduler was sent the command new
12/24/2012 12:49:40;0040;PBS_Server;Svr;tyrone-cluster;Scheduler was sent the command new
12/24/2012 12:50:12;0040;PBS_Server;Svr;tyrone-cluster;Scheduler was sent the command new
12/24/2012 12:50:42;0040;PBS_Server;Svr;tyrone-cluster;Scheduler was sent the command new
12/24/2012 12:51:14;0040;PBS_Server;Svr;tyrone-cluster;Scheduler was sent the command new
12/24/2012 12:51:53;0040;PBS_Server;Svr;tyrone-cluster;Scheduler was sent the command new
12/24/2012 12:52:18;0040;PBS_Server;Svr;tyrone-cluster;Scheduler was sent the command new
12/24/2012 12:52:49;0040;PBS_Server;Svr;tyrone-cluster;Scheduler was sent the command new
12/24/2012 12:53:23;0002;PBS_Server;Svr;PBS_Server;Torque Server Version = 3.0.5, loglevel = 0
12/24/2012 12:53:23;0040;PBS_Server;Svr;tyrone-cluster;Scheduler was sent the command new
12/24/2012 12:53:54;0040;PBS_Server;Svr;tyrone-cluster;Scheduler was sent the command new
12/24/2012 12:54:25;0040;PBS_Server;Svr;tyrone-cluster;Scheduler was sent the command new
12/24/2012 12:54:55;0040;PBS_Server;Svr;tyrone-cluster;Scheduler was sent the command new
12/24/2012 12:55:27;0040;PBS_Server;Svr;tyrone-cluster;Scheduler was sent the command new
12/24/2012 12:55:58;0040;PBS_Server;Svr;tyrone-cluster;Scheduler was sent the command new
12/24/2012 12:56:29;0040;PBS_Server;Svr;tyrone-cluster;Scheduler was sent the command new
12/24/2012 12:57:08;0040;PBS_Server;Svr;tyrone-cluster;Scheduler was sent the command new
12/24/2012 12:57:33;0040;PBS_Server;Svr;tyrone-cluster;Scheduler was sent the command new
12/24/2012 12:58:04;0040;PBS_Server;Svr;tyrone-cluster;Scheduler was sent the command new
12/24/2012 12:58:23;0002;PBS_Server;Svr;PBS_Server;Torque Server Version = 3.0.5, loglevel = 0
12/24/2012 12:58:38;0040;PBS_Server;Svr;tyrone-cluster;Scheduler was sent the command new
12/24/2012 12:59:09;0040;PBS_Server;Svr;tyrone-cluster;Scheduler was sent the command new
12/24/2012 12:59:40;0040;PBS_Server;Svr;tyrone-cluster;Scheduler was sent the command new
12/24/2012 13:00:09;0040;PBS_Server;Svr;tyrone-cluster;Scheduler was sent the command new
12/24/2012 13:00:42;0040;PBS_Server;Svr;tyrone-cluster;Scheduler was sent the command new
12/24/2012 13:01:13;0040;PBS_Server;Svr;tyrone-cluster;Scheduler was sent the command new
12/24/2012 13:01:44;0040;PBS_Server;Svr;tyrone-cluster;Scheduler was sent the command new
12/24/2012 13:02:23;0040;PBS_Server;Svr;tyrone-cluster;Scheduler was sent the command new
12/24/2012 13:02:48;0040;PBS_Server;Svr;tyrone-cluster;Scheduler was sent the command new
12/24/2012 13:03:19;0040;PBS_Server;Svr;tyrone-cluster;Scheduler was sent the command new
12/24/2012 13:03:23;0002;PBS_Server;Svr;PBS_Server;Torque Server Version = 3.0.5, loglevel = 0
12/24/2012 13:03:53;0040;PBS_Server;Svr;tyrone-cluster;Scheduler was sent the command new
12/24/2012 13:04:24;0040;PBS_Server;Svr;tyrone-cluster;Scheduler was sent the command new
12/24/2012 13:04:55;0040;PBS_Server;Svr;tyrone-cluster;Scheduler was sent the command new
12/24/2012 13:05:24;0040;PBS_Server;Svr;tyrone-cluster;Scheduler was sent the command new
12/24/2012 13:05:57;0040;PBS_Server;Svr;tyrone-cluster;Scheduler was sent the command new
12/24/2012 13:06:27;0040;PBS_Server;Svr;tyrone-cluster;Scheduler was sent the command new
12/24/2012 13:06:59;0040;PBS_Server;Svr;tyrone-cluster;Scheduler was sent the command new
12/24/2012 13:07:38;0040;PBS_Server;Svr;tyrone-cluster;Scheduler was sent the command new
12/24/2012 13:08:03;0040;PBS_Server;Svr;tyrone-cluster;Scheduler was sent the command new
12/24/2012 13:08:23;0002;PBS_Server;Svr;PBS_Server;Torque Server Version = 3.0.5, loglevel = 0
12/24/2012 13:08:34;0040;PBS_Server;Svr;tyrone-cluster;Scheduler was sent the command new
12/24/2012 13:09:08;0040;PBS_Server;Svr;tyrone-cluster;Scheduler was sent the command new
12/24/2012 13:09:39;0040;PBS_Server;Svr;tyrone-cluster;Scheduler was sent the command new
12/24/2012 13:10:10;0040;PBS_Server;Svr;tyrone-cluster;Scheduler was sent the command new
12/24/2012 13:10:39;0040;PBS_Server;Svr;tyrone-cluster;Scheduler was sent the command new
12/24/2012 13:11:11;0040;PBS_Server;Svr;tyrone-cluster;Scheduler was sent the command new
12/24/2012 13:11:39;0040;PBS_Server;Svr;tyrone-cluster;Scheduler was sent the command new
12/24/2012 13:11:48;000d;PBS_Server;Job;17542.tyrone-cluster;Not sending email: User does not want mail of this type.
12/24/2012 13:11:48;0010;PBS_Server;Job;17542.tyrone-cluster;Exit_status=1 resources_used.cput=15:53:19 resources_used.mem=4350032kb resources_used.vmem=8189664kb resources_used.walltime=00:49:24
12/24/2012 13:11:48;0008;PBS_Server;Job;NULL;on_job_exit valid pjob: 0x1bb6ca0 (substate=50)
12/24/2012 13:11:48;0008;PBS_Server;Job;NULL;on_job_exit valid pjob: 0x1bb6ca0 (substate=51)
12/24/2012 13:11:48;0008;PBS_Server;Job;NULL;on_job_exit valid pjob: 0x1bb6ca0 (substate=51)
12/24/2012 13:11:48;0008;PBS_Server;Job;NULL;on_job_exit valid pjob: 0x1bb6ca0 (substate=53)
12/24/2012 13:11:48;0100;PBS_Server;Job;17542.tyrone-cluster;dequeuing from idqueue, state COMPLETE
12/24/2012 13:11:48;0040;PBS_Server;Svr;tyrone-cluster;Scheduler was sent the command term
12/24/2012 13:12:09;0040;PBS_Server;Svr;tyrone-cluster;Scheduler was sent the command new
12/24/2012 13:12:41;0040;PBS_Server;Svr;tyrone-cluster;Scheduler was sent the command new
12/24/2012 13:13:09;0040;PBS_Server;Svr;tyrone-cluster;Scheduler was sent the command new
12/24/2012 13:13:23;0002;PBS_Server;Svr;PBS_Server;Torque Server Version = 3.0.5, loglevel = 0
12/24/2012 13:13:40;0040;PBS_Server;Svr;tyrone-cluster;Scheduler was sent the command new
12/24/2012 13:14:09;0040;PBS_Server;Svr;tyrone-cluster;Scheduler was sent the command new
12/24/2012 13:14:40;0040;PBS_Server;Svr;tyrone-cluster;Scheduler was sent the command new
12/24/2012 13:15:14;0040;PBS_Server;Svr;tyrone-cluster;Scheduler was sent the command new
12/24/2012 13:15:42;0040;PBS_Server;Svr;tyrone-cluster;Scheduler was sent the command new
12/24/2012 13:16:12;0040;PBS_Server;Svr;tyrone-cluster;Scheduler was sent the command new
12/24/2012 13:16:44;0040;PBS_Server;Svr;tyrone-cluster;Scheduler was sent the command new
12/24/2012 13:17:23;0040;PBS_Server;Svr;tyrone-cluster;Scheduler was sent the command new
12/24/2012 13:17:53;0040;PBS_Server;Svr;tyrone-cluster;Scheduler was sent the command new
12/24/2012 13:18:23;0002;PBS_Server;Svr;PBS_Server;Torque Server Version = 3.0.5, loglevel = 0
12/24/2012 13:18:24;0040;PBS_Server;Svr;tyrone-cluster;Scheduler was sent the command new
12/24/2012 13:18:53;0040;PBS_Server;Svr;tyrone-cluster;Scheduler was sent the command new
12/24/2012 13:19:23;0040;PBS_Server;Svr;tyrone-cluster;Scheduler was sent the command new
12/24/2012 13:19:55;0040;PBS_Server;Svr;tyrone-cluster;Scheduler was sent the command new
12/24/2012 13:20:29;0040;PBS_Server;Svr;tyrone-cluster;Scheduler was sent the command new
12/24/2012 13:20:57;0040;PBS_Server;Svr;tyrone-cluster;Scheduler was sent the command new
12/24/2012 13:21:27;0040;PBS_Server;Svr;tyrone-cluster;Scheduler was sent the command new
12/24/2012 13:21:59;0040;PBS_Server;Svr;tyrone-cluster;Scheduler was sent the command new
12/24/2012 13:22:38;0040;PBS_Server;Svr;tyrone-cluster;Scheduler was sent the command new
12/24/2012 13:23:08;0040;PBS_Server;Svr;tyrone-cluster;Scheduler was sent the command new
12/24/2012 13:23:23;0002;PBS_Server;Svr;PBS_Server;Torque Server Version = 3.0.5, loglevel = 0
12/24/2012 13:23:39;0040;PBS_Server;Svr;tyrone-cluster;Scheduler was sent the command new
12/24/2012 13:24:09;0040;PBS_Server;Svr;tyrone-cluster;Scheduler was sent the command new
12/24/2012 13:24:42;0040;PBS_Server;Svr;tyrone-cluster;Scheduler was sent the command new
12/24/2012 13:25:13;0040;PBS_Server;Svr;tyrone-cluster;Scheduler was sent the command new
12/24/2012 13:25:44;0040;PBS_Server;Svr;tyrone-cluster;Scheduler was sent the command new
12/24/2012 13:26:23;0040;PBS_Server;Svr;tyrone-cluster;Scheduler was sent the command new
12/24/2012 13:26:54;0040;PBS_Server;Svr;tyrone-cluster;Scheduler was sent the command new
12/24/2012 13:27:25;0040;PBS_Server;Svr;tyrone-cluster;Scheduler was sent the command new
12/24/2012 13:27:54;0040;PBS_Server;Svr;tyrone-cluster;Scheduler was sent the command new
12/24/2012 13:28:23;0002;PBS_Server;Svr;PBS_Server;Torque Server Version = 3.0.5, loglevel = 0
12/24/2012 13:28:24;0040;PBS_Server;Svr;tyrone-cluster;Scheduler was sent the command new
12/24/2012 13:28:54;0040;PBS_Server;Svr;tyrone-cluster;Scheduler was sent the command new
12/24/2012 13:29:24;0040;PBS_Server;Svr;tyrone-cluster;Scheduler was sent the command new
12/24/2012 13:29:57;0040;PBS_Server;Svr;tyrone-cluster;Scheduler was sent the command new
12/24/2012 13:30:28;0040;PBS_Server;Svr;tyrone-cluster;Scheduler was sent the command new
12/24/2012 13:30:59;0040;PBS_Server;Svr;tyrone-cluster;Scheduler was sent the command new
12/24/2012 13:31:38;0040;PBS_Server;Svr;tyrone-cluster;Scheduler was sent the command new
12/24/2012 13:32:09;0040;PBS_Server;Svr;tyrone-cluster;Scheduler was sent the command new
12/24/2012 13:32:40;0040;PBS_Server;Svr;tyrone-cluster;Scheduler was sent the command new
12/24/2012 13:33:09;0040;PBS_Server;Svr;tyrone-cluster;Scheduler was sent the command new
12/24/2012 13:33:23;0002;PBS_Server;Svr;PBS_Server;Torque Server Version = 3.0.5, loglevel = 0
12/24/2012 13:33:39;0040;PBS_Server;Svr;tyrone-cluster;Scheduler was sent the command new
12/24/2012 13:34:10;0040;PBS_Server;Svr;tyrone-cluster;Scheduler was sent the command new
12/24/2012 13:34:39;0040;PBS_Server;Svr;tyrone-cluster;Scheduler was sent the command new
12/24/2012 13:35:11;0040;PBS_Server;Svr;tyrone-cluster;Scheduler was sent the command new
12/24/2012 13:35:39;0040;PBS_Server;Svr;tyrone-cluster;Scheduler was sent the command new
12/24/2012 13:36:09;0040;PBS_Server;Svr;tyrone-cluster;Scheduler was sent the command new
12/24/2012 13:36:39;0040;PBS_Server;Svr;tyrone-cluster;Scheduler was sent the command new
12/24/2012 13:37:10;0040;PBS_Server;Svr;tyrone-cluster;Scheduler was sent the command new
12/24/2012 13:37:44;0040;PBS_Server;Svr;tyrone-cluster;Scheduler was sent the command new
12/24/2012 13:38:12;0040;PBS_Server;Svr;tyrone-cluster;Scheduler was sent the command new
12/24/2012 13:38:23;0002;PBS_Server;Svr;PBS_Server;Torque Server Version = 3.0.5, loglevel = 0
12/24/2012 13:38:42;0040;PBS_Server;Svr;tyrone-cluster;Scheduler was sent the command new
12/24/2012 13:39:14;0040;PBS_Server;Svr;tyrone-cluster;Scheduler was sent the command new
12/24/2012 13:39:53;0040;PBS_Server;Svr;tyrone-cluster;Scheduler was sent the command new
12/24/2012 13:40:23;0040;PBS_Server;Svr;tyrone-cluster;Scheduler was sent the command new
12/24/2012 13:40:55;0040;PBS_Server;Svr;tyrone-cluster;Scheduler was sent the command new
12/24/2012 13:41:24;0040;PBS_Server;Svr;tyrone-cluster;Scheduler was sent the command new
12/24/2012 13:41:54;0040;PBS_Server;Svr;tyrone-cluster;Scheduler was sent the command new
12/24/2012 13:42:25;0040;PBS_Server;Svr;tyrone-cluster;Scheduler was sent the command new
12/24/2012 13:42:54;0040;PBS_Server;Svr;tyrone-cluster;Scheduler was sent the command new
12/24/2012 13:43:23;0002;PBS_Server;Svr;PBS_Server;Torque Server Version = 3.0.5, loglevel = 0
12/24/2012 13:43:24;0040;PBS_Server;Svr;tyrone-cluster;Scheduler was sent the command new
12/24/2012 13:43:55;0040;PBS_Server;Svr;tyrone-cluster;Scheduler was sent the command new
12/24/2012 13:44:24;0040;PBS_Server;Svr;tyrone-cluster;Scheduler was sent the command new
12/24/2012 13:44:54;0040;PBS_Server;Svr;tyrone-cluster;Scheduler was sent the command new
12/24/2012 13:45:24;0040;PBS_Server;Svr;tyrone-cluster;Scheduler was sent the command new
12/24/2012 13:45:54;0040;PBS_Server;Svr;tyrone-cluster;Scheduler was sent the command new
12/24/2012 13:46:27;0040;PBS_Server;Svr;tyrone-cluster;Scheduler was sent the command new
12/24/2012 13:46:57;0040;PBS_Server;Svr;tyrone-cluster;Scheduler was sent the command new
12/24/2012 13:47:29;0040;PBS_Server;Svr;tyrone-cluster;Scheduler was sent the command new
12/24/2012 13:48:08;0040;PBS_Server;Svr;tyrone-cluster;Scheduler was sent the command new
12/24/2012 13:48:23;0002;PBS_Server;Svr;PBS_Server;Torque Server Version = 3.0.5, loglevel = 0
12/24/2012 13:48:39;0040;PBS_Server;Svr;tyrone-cluster;Scheduler was sent the command new
12/24/2012 13:49:10;0040;PBS_Server;Svr;tyrone-cluster;Scheduler was sent the command new
12/24/2012 13:49:39;0040;PBS_Server;Svr;tyrone-cluster;Scheduler was sent the command new
12/24/2012 13:50:09;0040;PBS_Server;Svr;tyrone-cluster;Scheduler was sent the command new
12/24/2012 13:50:39;0040;PBS_Server;Svr;tyrone-cluster;Scheduler was sent the command new
12/24/2012 13:51:09;0040;PBS_Server;Svr;tyrone-cluster;Scheduler was sent the command new
12/24/2012 13:51:42;0040;PBS_Server;Svr;tyrone-cluster;Scheduler was sent the command new
12/24/2012 13:52:12;0040;PBS_Server;Svr;tyrone-cluster;Scheduler was sent the command new
12/24/2012 13:52:44;0040;PBS_Server;Svr;tyrone-cluster;Scheduler was sent the command new
12/24/2012 13:53:23;0002;PBS_Server;Svr;PBS_Server;Torque Server Version = 3.0.5, loglevel = 0
12/24/2012 13:53:23;0040;PBS_Server;Svr;tyrone-cluster;Scheduler was sent the command new
12/24/2012 13:53:54;0040;PBS_Server;Svr;tyrone-cluster;Scheduler was sent the command new
12/24/2012 13:54:25;0040;PBS_Server;Svr;tyrone-cluster;Scheduler was sent the command new
12/24/2012 13:54:54;0040;PBS_Server;Svr;tyrone-cluster;Scheduler was sent the command new
12/24/2012 13:55:24;0040;PBS_Server;Svr;tyrone-cluster;Scheduler was sent the command new
12/24/2012 13:55:55;0040;PBS_Server;Svr;tyrone-cluster;Scheduler was sent the command new
12/24/2012 13:56:24;0040;PBS_Server;Svr;tyrone-cluster;Scheduler was sent the command new
12/24/2012 13:56:54;0040;PBS_Server;Svr;tyrone-cluster;Scheduler was sent the command new
12/24/2012 13:57:24;0040;PBS_Server;Svr;tyrone-cluster;Scheduler was sent the command new
12/24/2012 13:57:54;0040;PBS_Server;Svr;tyrone-cluster;Scheduler was sent the command new
12/24/2012 13:58:23;0002;PBS_Server;Svr;PBS_Server;Torque Server Version = 3.0.5, loglevel = 0
12/24/2012 13:58:27;0040;PBS_Server;Svr;tyrone-cluster;Scheduler was sent the command new
12/24/2012 13:58:56;0040;PBS_Server;Svr;tyrone-cluster;Scheduler was sent the command new
12/24/2012 13:59:29;0040;PBS_Server;Svr;tyrone-cluster;Scheduler was sent the command new
12/24/2012 14:00:08;0040;PBS_Server;Svr;tyrone-cluster;Scheduler was sent the command new
12/24/2012 14:00:39;0040;PBS_Server;Svr;tyrone-cluster;Scheduler was sent the command new
12/24/2012 14:01:10;0040;PBS_Server;Svr;tyrone-cluster;Scheduler was sent the command new
12/24/2012 14:01:39;0040;PBS_Server;Svr;tyrone-cluster;Scheduler was sent the command new
12/24/2012 14:02:09;0040;PBS_Server;Svr;tyrone-cluster;Scheduler was sent the command new
12/24/2012 14:02:39;0040;PBS_Server;Svr;tyrone-cluster;Scheduler was sent the command new
12/24/2012 14:03:09;0040;PBS_Server;Svr;tyrone-cluster;Scheduler was sent the command new
12/24/2012 14:03:23;0002;PBS_Server;Svr;PBS_Server;Torque Server Version = 3.0.5, loglevel = 0
12/24/2012 14:03:41;0040;PBS_Server;Svr;tyrone-cluster;Scheduler was sent the command new
12/24/2012 14:04:09;0040;PBS_Server;Svr;tyrone-cluster;Scheduler was sent the command new
12/24/2012 14:04:39;0040;PBS_Server;Svr;tyrone-cluster;Scheduler was sent the command new
12/24/2012 14:05:09;0040;PBS_Server;Svr;tyrone-cluster;Scheduler was sent the command new
12/24/2012 14:05:40;0040;PBS_Server;Svr;tyrone-cluster;Scheduler was sent the command new
12/24/2012 14:06:09;0040;PBS_Server;Svr;tyrone-cluster;Scheduler was sent the command new
12/24/2012 14:06:16;0100;PBS_Server;Job;17545.tyrone-cluster;enqueuing into batch, state 1 hop 1
12/24/2012 14:06:16;0100;PBS_Server;Job;17545.tyrone-cluster;dequeuing from batch, state QUEUED
12/24/2012 14:06:16;0100;PBS_Server;Job;17545.tyrone-cluster;enqueuing into idqueue, state 1 hop 1
12/24/2012 14:06:16;0008;PBS_Server;Job;17545.tyrone-cluster;Job Queued at request of ipcdskp@tyrone-cluster, owner = ipcdskp@tyrone-cluster, job name = n10, queue = idqueue
12/24/2012 14:06:16;0040;PBS_Server;Svr;tyrone-cluster;Scheduler was sent the command new
12/24/2012 14:06:16;0008;PBS_Server;Job;17545.tyrone-cluster;Job Modified at request of Scheduler@tyrone-cluster
12/24/2012 14:06:16;0008;PBS_Server;Job;17545.tyrone-cluster;Job Run at request of Scheduler@tyrone-cluster
12/24/2012 14:06:17;0040;PBS_Server;Svr;tyrone-cluster;Scheduler was sent the command recyc
12/24/2012 14:06:17;000d;PBS_Server;Job;17545.tyrone-cluster;Not sending email: User does not want mail of this type.
12/24/2012 14:06:42;0040;PBS_Server;Svr;tyrone-cluster;Scheduler was sent the command new
12/24/2012 14:07:12;0040;PBS_Server;Svr;tyrone-cluster;Scheduler was sent the command new
12/24/2012 14:07:44;0040;PBS_Server;Svr;tyrone-cluster;Scheduler was sent the command new
12/24/2012 14:08:23;0002;PBS_Server;Svr;PBS_Server;Torque Server Version = 3.0.5, loglevel = 0
12/24/2012 14:08:23;0040;PBS_Server;Svr;tyrone-cluster;Scheduler was sent the command new
12/24/2012 14:08:54;0040;PBS_Server;Svr;tyrone-cluster;Scheduler was sent the command new
12/24/2012 14:09:24;0040;PBS_Server;Svr;tyrone-cluster;Scheduler was sent the command new
12/24/2012 14:09:54;0040;PBS_Server;Svr;tyrone-cluster;Scheduler was sent the command new
12/24/2012 14:10:27;0040;PBS_Server;Svr;tyrone-cluster;Scheduler was sent the command new
12/24/2012 14:10:57;0040;PBS_Server;Svr;tyrone-cluster;Scheduler was sent the command new
12/24/2012 14:11:29;0040;PBS_Server;Svr;tyrone-cluster;Scheduler was sent the command new
12/24/2012 14:12:08;0040;PBS_Server;Svr;tyrone-cluster;Scheduler was sent the command new
12/24/2012 14:12:39;0040;PBS_Server;Svr;tyrone-cluster;Scheduler was sent the command new
12/24/2012 14:13:09;0040;PBS_Server;Svr;tyrone-cluster;Scheduler was sent the command new
12/24/2012 14:13:23;0002;PBS_Server;Svr;PBS_Server;Torque Server Version = 3.0.5, loglevel = 0
12/24/2012 14:13:39;0040;PBS_Server;Svr;tyrone-cluster;Scheduler was sent the command new
12/24/2012 14:14:12;0040;PBS_Server;Svr;tyrone-cluster;Scheduler was sent the command new
12/24/2012 14:14:42;0040;PBS_Server;Svr;tyrone-cluster;Scheduler was sent the command new
12/24/2012 14:15:14;0040;PBS_Server;Svr;tyrone-cluster;Scheduler was sent the command new
12/24/2012 14:15:53;0040;PBS_Server;Svr;tyrone-cluster;Scheduler was sent the command new
12/24/2012 14:16:24;0040;PBS_Server;Svr;tyrone-cluster;Scheduler was sent the command new
12/24/2012 14:16:54;0040;PBS_Server;Svr;tyrone-cluster;Scheduler was sent the command new
12/24/2012 14:17:01;0008;PBS_Server;Job;17545.tyrone-cluster;Job deleted at request of ipcdskp@tyrone-cluster
12/24/2012 14:17:01;0008;PBS_Server;Job;17545.tyrone-cluster;Job sent signal SIGTERM on delete
12/24/2012 14:17:03;0008;PBS_Server;Job;17545.tyrone-cluster;Job sent signal SIGKILL on delete
12/24/2012 14:17:07;000d;PBS_Server;Job;17545.tyrone-cluster;Not sending email: User does not want mail of this type.
12/24/2012 14:17:07;0010;PBS_Server;Job;17545.tyrone-cluster;Exit_status=143 resources_used.cput=02:43:43 resources_used.mem=1099148kb resources_used.vmem=8189696kb resources_used.walltime=00:10:51
12/24/2012 14:17:07;0008;PBS_Server;Job;NULL;on_job_exit valid pjob: 0x1bb6ca0 (substate=50)
12/24/2012 14:17:07;0008;PBS_Server;Job;NULL;on_job_exit valid pjob: 0x1bb6ca0 (substate=51)
12/24/2012 14:17:07;0008;PBS_Server;Job;NULL;on_job_exit valid pjob: 0x1bb6ca0 (substate=51)
12/24/2012 14:17:07;0008;PBS_Server;Job;NULL;on_job_exit valid pjob: 0x1bb6ca0 (substate=53)
12/24/2012 14:17:07;0100;PBS_Server;Job;17545.tyrone-cluster;dequeuing from idqueue, state COMPLETE
12/24/2012 14:17:07;0040;PBS_Server;Svr;tyrone-cluster;Scheduler was sent the command term
12/24/2012 14:17:24;0040;PBS_Server;Svr;tyrone-cluster;Scheduler was sent the command new
12/24/2012 14:17:57;0040;PBS_Server;Svr;tyrone-cluster;Scheduler was sent the command new
12/24/2012 14:17:58;0100;PBS_Server;Job;17546.tyrone-cluster;enqueuing into batch, state 1 hop 1
12/24/2012 14:17:58;0100;PBS_Server;Job;17546.tyrone-cluster;dequeuing from batch, state QUEUED
12/24/2012 14:17:58;0100;PBS_Server;Job;17546.tyrone-cluster;enqueuing into idqueue, state 1 hop 1
12/24/2012 14:17:58;0008;PBS_Server;Job;17546.tyrone-cluster;Job Queued at request of ipcdskp@tyrone-cluster, owner = ipcdskp@tyrone-cluster, job name = n10, queue = idqueue
12/24/2012 14:17:58;0040;PBS_Server;Svr;tyrone-cluster;Scheduler was sent the command new
12/24/2012 14:17:58;0008;PBS_Server;Job;17546.tyrone-cluster;Job Modified at request of Scheduler@tyrone-cluster
12/24/2012 14:17:58;0008;PBS_Server;Job;17546.tyrone-cluster;Job Run at request of Scheduler@tyrone-cluster
12/24/2012 14:17:59;0040;PBS_Server;Svr;tyrone-cluster;Scheduler was sent the command recyc
12/24/2012 14:17:59;000d;PBS_Server;Job;17546.tyrone-cluster;Not sending email: User does not want mail of this type.
12/24/2012 14:18:22;0008;PBS_Server;Job;17546.tyrone-cluster;Job deleted at request of ipcdskp@tyrone-cluster
12/24/2012 14:18:22;0008;PBS_Server;Job;17546.tyrone-cluster;Job sent signal SIGTERM on delete
12/24/2012 14:18:23;0002;PBS_Server;Svr;PBS_Server;Torque Server Version = 3.0.5, loglevel = 0
12/24/2012 14:18:24;0008;PBS_Server;Job;17546.tyrone-cluster;Job sent signal SIGKILL on delete
12/24/2012 14:18:27;0040;PBS_Server;Svr;tyrone-cluster;Scheduler was sent the command new
12/24/2012 14:18:27;000d;PBS_Server;Job;17546.tyrone-cluster;Not sending email: User does not want mail of this type.
12/24/2012 14:18:27;0010;PBS_Server;Job;17546.tyrone-cluster;Exit_status=143 resources_used.cput=00:05:15 resources_used.mem=612828kb resources_used.vmem=7954756kb resources_used.walltime=00:00:29
12/24/2012 14:18:27;0008;PBS_Server;Job;NULL;on_job_exit valid pjob: 0x1bb6ca0 (substate=50)
12/24/2012 14:18:27;0008;PBS_Server;Job;NULL;on_job_exit valid pjob: 0x1bb6ca0 (substate=51)
12/24/2012 14:18:27;0008;PBS_Server;Job;NULL;on_job_exit valid pjob: 0x1bb6ca0 (substate=51)
12/24/2012 14:18:27;0008;PBS_Server;Job;NULL;on_job_exit valid pjob: 0x1bb6ca0 (substate=53)
12/24/2012 14:18:27;0100;PBS_Server;Job;17546.tyrone-cluster;dequeuing from idqueue, state COMPLETE
12/24/2012 14:18:27;0040;PBS_Server;Svr;tyrone-cluster;Scheduler was sent the command term
12/24/2012 14:18:58;0040;PBS_Server;Svr;tyrone-cluster;Scheduler was sent the command new
12/24/2012 14:19:38;0040;PBS_Server;Svr;tyrone-cluster;Scheduler was sent the command new
12/24/2012 14:19:43;0100;PBS_Server;Job;17547.tyrone-cluster;enqueuing into batch, state 1 hop 1
12/24/2012 14:19:43;0100;PBS_Server;Job;17547.tyrone-cluster;dequeuing from batch, state QUEUED
12/24/2012 14:19:43;0100;PBS_Server;Job;17547.tyrone-cluster;enqueuing into idqueue, state 1 hop 1
12/24/2012 14:19:43;0008;PBS_Server;Job;17547.tyrone-cluster;Job Queued at request of ipcdskp@tyrone-cluster, owner = ipcdskp@tyrone-cluster, job name = n10, queue = idqueue
12/24/2012 14:19:43;0040;PBS_Server;Svr;tyrone-cluster;Scheduler was sent the command new
12/24/2012 14:19:43;0008;PBS_Server;Job;17547.tyrone-cluster;Job Modified at request of Scheduler@tyrone-cluster
12/24/2012 14:19:43;0008;PBS_Server;Job;17547.tyrone-cluster;Job Run at request of Scheduler@tyrone-cluster
12/24/2012 14:19:43;0040;PBS_Server;Svr;tyrone-cluster;Scheduler was sent the command recyc
12/24/2012 14:19:43;000d;PBS_Server;Job;17547.tyrone-cluster;Not sending email: User does not want mail of this type.
12/24/2012 14:19:53;000d;PBS_Server;Job;17547.tyrone-cluster;Not sending email: User does not want mail of this type.
12/24/2012 14:19:53;0010;PBS_Server;Job;17547.tyrone-cluster;Exit_status=1 resources_used.cput=00:00:11 resources_used.mem=0kb resources_used.vmem=0kb resources_used.walltime=00:00:10
12/24/2012 14:19:53;0008;PBS_Server;Job;NULL;on_job_exit valid pjob: 0x1bb6ca0 (substate=50)
12/24/2012 14:19:53;0008;PBS_Server;Job;NULL;on_job_exit valid pjob: 0x1bb6ca0 (substate=51)
12/24/2012 14:19:53;0008;PBS_Server;Job;NULL;on_job_exit valid pjob: 0x1bb6ca0 (substate=51)
12/24/2012 14:19:53;0008;PBS_Server;Job;NULL;on_job_exit valid pjob: 0x1bb6ca0 (substate=53)
12/24/2012 14:19:53;0100;PBS_Server;Job;17547.tyrone-cluster;dequeuing from idqueue, state COMPLETE
12/24/2012 14:19:53;0040;PBS_Server;Svr;tyrone-cluster;Scheduler was sent the command term
12/24/2012 14:20:09;0040;PBS_Server;Svr;tyrone-cluster;Scheduler was sent the command new
12/24/2012 14:20:39;0040;PBS_Server;Svr;tyrone-cluster;Scheduler was sent the command new
12/24/2012 14:35:11;0004;PBS_Server;Svr;check_nodes;node tyrone-cluster not detected in 902 seconds, marking node down
12/24/2012 14:35:11;0004;PBS_Server;Svr;check_nodes;node tyrone-node1 not detected in 888 seconds, marking node down
12/24/2012 14:35:11;0004;PBS_Server;Svr;check_nodes;node tyrone-node2 not detected in 872 seconds, marking node down
12/24/2012 14:35:11;0004;PBS_Server;Svr;check_nodes;node tyrone-node3 not detected in 914 seconds, marking node down
12/24/2012 14:35:11;0004;PBS_Server;Svr;check_nodes;node tyrone-node4 not detected in 903 seconds, marking node down
12/24/2012 14:35:11;0004;PBS_Server;Svr;check_nodes;node tyrone-node5 not detected in 906 seconds, marking node down
12/24/2012 14:35:11;0004;PBS_Server;Svr;check_nodes;node tyrone-node6 not detected in 883 seconds, marking node down
12/24/2012 14:35:11;0004;PBS_Server;Svr;check_nodes;node tyrone-node7 not detected in 887 seconds, marking node down
12/24/2012 14:35:11;0004;PBS_Server;Svr;check_nodes;node tyrone-node8 not detected in 899 seconds, marking node down
12/24/2012 14:35:11;0004;PBS_Server;Svr;check_nodes;node tyrone-node9 not detected in 887 seconds, marking node down
12/24/2012 14:35:11;0004;PBS_Server;Svr;check_nodes;node tyrone-node10 not detected in 882 seconds, marking node down
12/24/2012 14:35:11;0004;PBS_Server;Svr;check_nodes;node tyrone-node11 not detected in 872 seconds, marking node down
12/24/2012 14:35:11;0004;PBS_Server;Svr;check_nodes;node tyrone-node12 not detected in 899 seconds, marking node down
12/24/2012 14:35:11;0004;PBS_Server;Svr;check_nodes;node tyrone-node13 not detected in 881 seconds, marking node down
12/24/2012 14:35:11;0004;PBS_Server;Svr;check_nodes;node tyrone-node14 not detected in 875 seconds, marking node down
12/24/2012 14:35:11;0004;PBS_Server;Svr;check_nodes;node tyrone-node15 not detected in 914 seconds, marking node down
12/24/2012 14:35:11;0004;PBS_Server;Svr;check_nodes;node tyrone-node16 not detected in 883 seconds, marking node down
12/24/2012 14:35:11;0002;PBS_Server;Svr;PBS_Server;Torque Server Version = 3.0.5, loglevel = 0
12/24/2012 14:35:11;0040;PBS_Server;Svr;tyrone-cluster;Scheduler was sent the command time
12/24/2012 14:35:30;0100;PBS_Server;Job;17548.tyrone-cluster;enqueuing into batch, state 1 hop 1
12/24/2012 14:35:30;0100;PBS_Server;Job;17548.tyrone-cluster;dequeuing from batch, state QUEUED
12/24/2012 14:35:30;0100;PBS_Server;Job;17548.tyrone-cluster;enqueuing into idqueue, state 1 hop 1
12/24/2012 14:35:30;0008;PBS_Server;Job;17548.tyrone-cluster;Job Queued at request of ipcdskp@tyrone-cluster, owner = ipcdskp@tyrone-cluster, job name = n10, queue = idqueue
12/24/2012 14:35:30;0040;PBS_Server;Svr;tyrone-cluster;Scheduler was sent the command new
12/24/2012 14:35:30;0008;PBS_Server;Job;17548.tyrone-cluster;Job Modified at request of Scheduler@tyrone-cluster
12/24/2012 14:35:30;0008;PBS_Server;Job;17548.tyrone-cluster;Job Run at request of Scheduler@tyrone-cluster
12/24/2012 14:35:30;0040;PBS_Server;Svr;tyrone-cluster;Scheduler was sent the command recyc
12/24/2012 14:35:30;000d;PBS_Server;Job;17548.tyrone-cluster;Not sending email: User does not want mail of this type.
12/24/2012 14:35:37;0001;PBS_Server;Svr;PBS_Server;LOG_ERROR::stream_eof, connection to tyrone-node1 is no longer valid, connection may have been closed remotely, remote service may be down, or message may be corrupt (End of File).  setting node state to down
12/24/2012 14:35:42;0040;PBS_Server;Svr;tyrone-cluster;Scheduler was sent the command new
12/24/2012 14:35:47;0001;PBS_Server;Svr;PBS_Server;LOG_ERROR::stream_eof, connection to tyrone-node2 is no longer valid, connection may have been closed remotely, remote service may be down, or message may be corrupt (End of File).  setting node state to down
12/24/2012 14:35:58;0001;PBS_Server;Svr;PBS_Server;LOG_ERROR::stream_eof, connection to tyrone-node3 is no longer valid, connection may have been closed remotely, remote service may be down, or message may be corrupt (End of File).  setting node state to down
12/24/2012 14:36:11;0001;PBS_Server;Svr;PBS_Server;LOG_ERROR::stream_eof, connection to tyrone-node4 is no longer valid, connection may have been closed remotely, remote service may be down, or message may be corrupt (End of File).  setting node state to down
12/24/2012 14:36:12;0040;PBS_Server;Svr;tyrone-cluster;Scheduler was sent the command new
12/24/2012 14:36:35;0001;PBS_Server;Svr;PBS_Server;LOG_ERROR::stream_eof, connection to tyrone-node5 is no longer valid, connection may have been closed remotely, remote service may be down, or message may be corrupt (End of File).  setting node state to down
12/24/2012 14:36:44;0040;PBS_Server;Svr;tyrone-cluster;Scheduler was sent the command new
12/24/2012 14:36:55;0001;PBS_Server;Svr;PBS_Server;LOG_ERROR::stream_eof, connection to tyrone-node6 is no longer valid, connection may have been closed remotely, remote service may be down, or message may be corrupt (End of File).  setting node state to down
12/24/2012 14:37:10;0001;PBS_Server;Svr;PBS_Server;LOG_ERROR::stream_eof, connection to tyrone-node7 is no longer valid, connection may have been closed remotely, remote service may be down, or message may be corrupt (End of File).  setting node state to down
12/24/2012 14:37:12;0040;PBS_Server;Svr;tyrone-cluster;Scheduler was sent the command new
12/24/2012 14:37:30;0001;PBS_Server;Svr;PBS_Server;LOG_ERROR::stream_eof, connection to tyrone-node8 is no longer valid, connection may have been closed remotely, remote service may be down, or message may be corrupt (End of File).  setting node state to down
12/24/2012 14:37:42;0040;PBS_Server;Svr;tyrone-cluster;Scheduler was sent the command new
12/24/2012 14:37:55;0001;PBS_Server;Svr;PBS_Server;LOG_ERROR::stream_eof, connection to tyrone-node9 is no longer valid, connection may have been closed remotely, remote service may be down, or message may be corrupt (End of File).  setting node state to down
12/24/2012 14:38:13;0040;PBS_Server;Svr;tyrone-cluster;Scheduler was sent the command new
12/24/2012 14:38:22;0001;PBS_Server;Svr;PBS_Server;LOG_ERROR::stream_eof, connection to tyrone-node10 is no longer valid, connection may have been closed remotely, remote service may be down, or message may be corrupt (End of File).  setting node state to down
12/24/2012 14:38:42;0040;PBS_Server;Svr;tyrone-cluster;Scheduler was sent the command new
12/24/2012 14:38:54;0001;PBS_Server;Svr;PBS_Server;LOG_ERROR::stream_eof, connection to tyrone-node11 is no longer valid, connection may have been closed remotely, remote service may be down, or message may be corrupt (End of File).  setting node state to down
12/24/2012 14:39:12;0040;PBS_Server;Svr;tyrone-cluster;Scheduler was sent the command new
12/24/2012 14:39:45;0040;PBS_Server;Svr;tyrone-cluster;Scheduler was sent the command new
12/24/2012 14:40:10;0001;PBS_Server;Svr;PBS_Server;LOG_ERROR::stream_eof, connection to tyrone-node13 is no longer valid, connection may have been closed remotely, remote service may be down, or message may be corrupt (End of File).  setting node state to down
12/24/2012 14:40:11;0002;PBS_Server;Svr;PBS_Server;Torque Server Version = 3.0.5, loglevel = 0
12/24/2012 14:40:21;0040;PBS_Server;Svr;tyrone-cluster;Scheduler was sent the command new
12/24/2012 14:40:30;0001;PBS_Server;Svr;PBS_Server;LOG_ERROR::stream_eof, connection to tyrone-node14 is no longer valid, connection may have been closed remotely, remote service may be down, or message may be corrupt (End of File).  setting node state to down
12/24/2012 14:40:43;0001;PBS_Server;Svr;PBS_Server;LOG_ERROR::stream_eof, connection to tyrone-node15 is no longer valid, connection may have been closed remotely, remote service may be down, or message may be corrupt (End of File).  setting node state to down
12/24/2012 14:40:52;0040;PBS_Server;Svr;tyrone-cluster;Scheduler was sent the command new
12/24/2012 14:40:56;0001;PBS_Server;Svr;PBS_Server;LOG_ERROR::stream_eof, connection to tyrone-node16 is no longer valid, connection may have been closed remotely, remote service may be down, or message may be corrupt (End of File).  setting node state to down
12/24/2012 14:41:26;0040;PBS_Server;Svr;tyrone-cluster;Scheduler was sent the command new
12/24/2012 14:41:56;0040;PBS_Server;Svr;tyrone-cluster;Scheduler was sent the command new
12/24/2012 14:42:28;0040;PBS_Server;Svr;tyrone-cluster;Scheduler was sent the command new
12/24/2012 14:42:56;0040;PBS_Server;Svr;tyrone-cluster;Scheduler was sent the command new
12/24/2012 14:43:26;0040;PBS_Server;Svr;tyrone-cluster;Scheduler was sent the command new
12/24/2012 14:43:58;0040;PBS_Server;Svr;tyrone-cluster;Scheduler was sent the command new
12/24/2012 14:44:26;0040;PBS_Server;Svr;tyrone-cluster;Scheduler was sent the command new
12/24/2012 14:44:56;0040;PBS_Server;Svr;tyrone-cluster;Scheduler was sent the command new
12/24/2012 14:45:11;0002;PBS_Server;Svr;PBS_Server;Torque Server Version = 3.0.5, loglevel = 0
12/24/2012 14:45:28;0040;PBS_Server;Svr;tyrone-cluster;Scheduler was sent the command new
12/24/2012 14:45:56;0040;PBS_Server;Svr;tyrone-cluster;Scheduler was sent the command new
12/24/2012 14:46:26;0040;PBS_Server;Svr;tyrone-cluster;Scheduler was sent the command new
12/24/2012 14:46:58;0040;PBS_Server;Svr;tyrone-cluster;Scheduler was sent the command new
12/24/2012 14:47:26;0040;PBS_Server;Svr;tyrone-cluster;Scheduler was sent the command new
12/24/2012 14:47:56;0040;PBS_Server;Svr;tyrone-cluster;Scheduler was sent the command new
12/24/2012 14:48:02;000d;PBS_Server;Job;17544.tyrone-cluster;Not sending email: User does not want mail of this type.
12/24/2012 14:48:02;0010;PBS_Server;Job;17544.tyrone-cluster;Exit_status=143 resources_used.cput=43:08:11 resources_used.mem=3649512kb resources_used.vmem=12147496kb resources_used.walltime=02:00:19
12/24/2012 14:48:02;0008;PBS_Server;Job;NULL;on_job_exit valid pjob: 0x1d2d0d0 (substate=50)
12/24/2012 14:48:02;0008;PBS_Server;Job;NULL;on_job_exit valid pjob: 0x1d2d0d0 (substate=51)
12/24/2012 14:48:02;0008;PBS_Server;Job;NULL;on_job_exit valid pjob: 0x1d2d0d0 (substate=51)
12/24/2012 14:48:02;0008;PBS_Server;Job;NULL;on_job_exit valid pjob: 0x1d2d0d0 (substate=53)
12/24/2012 14:48:02;0100;PBS_Server;Job;17544.tyrone-cluster;dequeuing from idqueue, state COMPLETE
12/24/2012 14:48:02;0040;PBS_Server;Svr;tyrone-cluster;Scheduler was sent the command term
12/24/2012 14:48:28;0040;PBS_Server;Svr;tyrone-cluster;Scheduler was sent the command new
12/24/2012 14:48:56;0040;PBS_Server;Svr;tyrone-cluster;Scheduler was sent the command new
12/24/2012 14:49:26;0040;PBS_Server;Svr;tyrone-cluster;Scheduler was sent the command new
12/24/2012 14:49:58;0040;PBS_Server;Svr;tyrone-cluster;Scheduler was sent the command new
12/24/2012 14:50:11;0002;PBS_Server;Svr;PBS_Server;Torque Server Version = 3.0.5, loglevel = 0
12/24/2012 14:50:26;0040;PBS_Server;Svr;tyrone-cluster;Scheduler was sent the command new
12/24/2012 14:50:56;0040;PBS_Server;Svr;tyrone-cluster;Scheduler was sent the command new
12/24/2012 14:51:28;0040;PBS_Server;Svr;tyrone-cluster;Scheduler was sent the command new
12/24/2012 14:51:56;0040;PBS_Server;Svr;tyrone-cluster;Scheduler was sent the command new
12/24/2012 14:52:27;0040;PBS_Server;Svr;tyrone-cluster;Scheduler was sent the command new
12/24/2012 14:52:58;0040;PBS_Server;Svr;tyrone-cluster;Scheduler was sent the command new
12/24/2012 14:53:27;0040;PBS_Server;Svr;tyrone-cluster;Scheduler was sent the command new
12/24/2012 14:54:00;0040;PBS_Server;Svr;tyrone-cluster;Scheduler was sent the command new
12/24/2012 14:54:35;0040;PBS_Server;Svr;tyrone-cluster;Scheduler was sent the command new
12/24/2012 14:55:01;0040;PBS_Server;Svr;tyrone-cluster;Scheduler was sent the command new
12/24/2012 14:55:11;0002;PBS_Server;Svr;PBS_Server;Torque Server Version = 3.0.5, loglevel = 0
12/24/2012 14:55:30;0040;PBS_Server;Svr;tyrone-cluster;Scheduler was sent the command new
12/24/2012 14:56:04;0040;PBS_Server;Svr;tyrone-cluster;Scheduler was sent the command new
12/24/2012 14:56:33;0040;PBS_Server;Svr;tyrone-cluster;Scheduler was sent the command new
12/24/2012 14:57:00;0040;PBS_Server;Svr;tyrone-cluster;Scheduler was sent the command new
12/24/2012 14:57:36;0040;PBS_Server;Svr;tyrone-cluster;Scheduler was sent the command new
12/24/2012 14:58:07;0040;PBS_Server;Svr;tyrone-cluster;Scheduler was sent the command new
12/24/2012 14:58:41;0040;PBS_Server;Svr;tyrone-cluster;Scheduler was sent the command new
12/24/2012 14:59:11;0040;PBS_Server;Svr;tyrone-cluster;Scheduler was sent the command new
12/24/2012 14:59:43;0040;PBS_Server;Svr;tyrone-cluster;Scheduler was sent the command new
12/24/2012 15:00:11;0002;PBS_Server;Svr;PBS_Server;Torque Server Version = 3.0.5, loglevel = 0
12/24/2012 15:00:11;0040;PBS_Server;Svr;tyrone-cluster;Scheduler was sent the command new
12/24/2012 15:00:41;0040;PBS_Server;Svr;tyrone-cluster;Scheduler was sent the command new
12/24/2012 15:01:12;0040;PBS_Server;Svr;tyrone-cluster;Scheduler was sent the command new
12/24/2012 15:01:41;0040;PBS_Server;Svr;tyrone-cluster;Scheduler was sent the command new
12/24/2012 15:02:11;0040;PBS_Server;Svr;tyrone-cluster;Scheduler was sent the command new
12/24/2012 15:02:21;0100;PBS_Server;Job;17549.tyrone-cluster;enqueuing into batch, state 1 hop 1
12/24/2012 15:02:21;0100;PBS_Server;Job;17549.tyrone-cluster;dequeuing from batch, state QUEUED
12/24/2012 15:02:21;0100;PBS_Server;Job;17549.tyrone-cluster;enqueuing into qp128, state 1 hop 1
12/24/2012 15:02:21;0008;PBS_Server;Job;17549.tyrone-cluster;Job Queued at request of nisaadi@tyrone-cluster, owner = nisaadi@tyrone-cluster, job name = 222, queue = qp128
12/24/2012 15:02:21;0040;PBS_Server;Svr;tyrone-cluster;Scheduler was sent the command new
12/24/2012 15:02:21;0008;PBS_Server;Job;17549.tyrone-cluster;Job Modified at request of Scheduler@tyrone-cluster
12/24/2012 15:02:33;0008;PBS_Server;Job;17549.tyrone-cluster;Job deleted at request of nisaadi@tyrone-cluster
12/24/2012 15:02:33;0008;PBS_Server;Job;NULL;on_job_exit valid pjob: 0x1d2d0d0 (substate=59)
12/24/2012 15:02:33;0100;PBS_Server;Job;17549.tyrone-cluster;dequeuing from qp128, state COMPLETE
12/24/2012 15:02:33;0040;PBS_Server;Svr;tyrone-cluster;Scheduler was sent the command term
12/24/2012 15:02:41;0040;PBS_Server;Svr;tyrone-cluster;Scheduler was sent the command new
12/24/2012 15:02:49;0100;PBS_Server;Job;17550.tyrone-cluster;enqueuing into batch, state 1 hop 1
12/24/2012 15:02:49;0100;PBS_Server;Job;17550.tyrone-cluster;dequeuing from batch, state QUEUED
12/24/2012 15:02:49;0100;PBS_Server;Job;17550.tyrone-cluster;enqueuing into qp32, state 1 hop 1
12/24/2012 15:02:49;0008;PBS_Server;Job;17550.tyrone-cluster;Job Queued at request of nisaadi@tyrone-cluster, owner = nisaadi@tyrone-cluster, job name = 222, queue = qp32
12/24/2012 15:02:49;0040;PBS_Server;Svr;tyrone-cluster;Scheduler was sent the command new
12/24/2012 15:02:49;0008;PBS_Server;Job;17550.tyrone-cluster;Job Modified at request of Scheduler@tyrone-cluster
12/24/2012 15:03:11;0040;PBS_Server;Svr;tyrone-cluster;Scheduler was sent the command new
12/24/2012 15:03:41;0040;PBS_Server;Svr;tyrone-cluster;Scheduler was sent the command new
12/24/2012 15:04:13;0040;PBS_Server;Svr;tyrone-cluster;Scheduler was sent the command new
12/24/2012 15:04:41;0040;PBS_Server;Svr;tyrone-cluster;Scheduler was sent the command new
12/24/2012 15:05:11;0002;PBS_Server;Svr;PBS_Server;Torque Server Version = 3.0.5, loglevel = 0
12/24/2012 15:05:12;0040;PBS_Server;Svr;tyrone-cluster;Scheduler was sent the command new
12/24/2012 15:05:42;0040;PBS_Server;Svr;tyrone-cluster;Scheduler was sent the command new
12/24/2012 15:06:11;0040;PBS_Server;Svr;tyrone-cluster;Scheduler was sent the command new
12/24/2012 15:06:41;0040;PBS_Server;Svr;tyrone-cluster;Scheduler was sent the command new
12/24/2012 15:07:13;0040;PBS_Server;Svr;tyrone-cluster;Scheduler was sent the command new
12/24/2012 15:07:41;0040;PBS_Server;Svr;tyrone-cluster;Scheduler was sent the command new
12/24/2012 15:08:11;0040;PBS_Server;Svr;tyrone-cluster;Scheduler was sent the command new
12/24/2012 15:08:43;0040;PBS_Server;Svr;tyrone-cluster;Scheduler was sent the command new
12/24/2012 15:09:11;0040;PBS_Server;Svr;tyrone-cluster;Scheduler was sent the command new
12/24/2012 15:09:42;0040;PBS_Server;Svr;tyrone-cluster;Scheduler was sent the command new
12/24/2012 15:10:11;0002;PBS_Server;Svr;PBS_Server;Torque Server Version = 3.0.5, loglevel = 0
12/24/2012 15:10:13;0040;PBS_Server;Svr;tyrone-cluster;Scheduler was sent the command new
12/24/2012 15:10:41;0040;PBS_Server;Svr;tyrone-cluster;Scheduler was sent the command new
12/24/2012 15:11:11;0040;PBS_Server;Svr;tyrone-cluster;Scheduler was sent the command new
12/24/2012 15:11:43;0040;PBS_Server;Svr;tyrone-cluster;Scheduler was sent the command new
12/24/2012 15:12:11;0040;PBS_Server;Svr;tyrone-cluster;Scheduler was sent the command new
12/24/2012 15:12:41;0040;PBS_Server;Svr;tyrone-cluster;Scheduler was sent the command new
12/24/2012 15:12:53;000d;PBS_Server;Job;17548.tyrone-cluster;Not sending email: User does not want mail of this type.
12/24/2012 15:12:53;0010;PBS_Server;Job;17548.tyrone-cluster;Exit_status=0 resources_used.cput=16:16:34 resources_used.mem=4705680kb resources_used.vmem=8543436kb resources_used.walltime=00:37:23
12/24/2012 15:12:53;0008;PBS_Server;Job;NULL;on_job_exit valid pjob: 0x1bb6ca0 (substate=50)
12/24/2012 15:12:53;0008;PBS_Server;Job;NULL;on_job_exit valid pjob: 0x1bb6ca0 (substate=51)
12/24/2012 15:12:53;0008;PBS_Server;Job;NULL;on_job_exit valid pjob: 0x1bb6ca0 (substate=51)
12/24/2012 15:12:53;0008;PBS_Server;Job;NULL;on_job_exit valid pjob: 0x1bb6ca0 (substate=53)
12/24/2012 15:12:53;0100;PBS_Server;Job;17548.tyrone-cluster;dequeuing from idqueue, state COMPLETE
12/24/2012 15:12:53;0040;PBS_Server;Svr;tyrone-cluster;Scheduler was sent the command term
12/24/2012 15:13:13;0040;PBS_Server;Svr;tyrone-cluster;Scheduler was sent the command new
12/24/2012 15:13:41;0040;PBS_Server;Svr;tyrone-cluster;Scheduler was sent the command new
12/24/2012 15:14:11;0040;PBS_Server;Svr;tyrone-cluster;Scheduler was sent the command new
12/24/2012 15:14:43;0040;PBS_Server;Svr;tyrone-cluster;Scheduler was sent the command new
12/24/2012 15:15:11;0002;PBS_Server;Svr;PBS_Server;Torque Server Version = 3.0.5, loglevel = 0
12/24/2012 15:15:11;0040;PBS_Server;Svr;tyrone-cluster;Scheduler was sent the command new
12/24/2012 15:15:42;0040;PBS_Server;Svr;tyrone-cluster;Scheduler was sent the command new
12/24/2012 15:16:12;0040;PBS_Server;Svr;tyrone-cluster;Scheduler was sent the command new
12/24/2012 15:16:41;0040;PBS_Server;Svr;tyrone-cluster;Scheduler was sent the command new
12/24/2012 15:17:11;0040;PBS_Server;Svr;tyrone-cluster;Scheduler was sent the command new
12/24/2012 15:17:43;0040;PBS_Server;Svr;tyrone-cluster;Scheduler was sent the command new
12/24/2012 15:18:11;0040;PBS_Server;Svr;tyrone-cluster;Scheduler was sent the command new
12/24/2012 15:18:41;0040;PBS_Server;Svr;tyrone-cluster;Scheduler was sent the command new
12/24/2012 15:19:12;0040;PBS_Server;Svr;tyrone-cluster;Scheduler was sent the command new
12/24/2012 15:19:41;0040;PBS_Server;Svr;tyrone-cluster;Scheduler was sent the command new
12/24/2012 15:20:11;0002;PBS_Server;Svr;PBS_Server;Torque Server Version = 3.0.5, loglevel = 0
12/24/2012 15:20:12;0040;PBS_Server;Svr;tyrone-cluster;Scheduler was sent the command new
12/24/2012 15:20:42;0040;PBS_Server;Svr;tyrone-cluster;Scheduler was sent the command new
12/24/2012 15:21:12;0040;PBS_Server;Svr;tyrone-cluster;Scheduler was sent the command new
12/24/2012 15:21:45;0040;PBS_Server;Svr;tyrone-cluster;Scheduler was sent the command new
12/24/2012 15:22:20;0040;PBS_Server;Svr;tyrone-cluster;Scheduler was sent the command new
12/24/2012 15:22:46;0040;PBS_Server;Svr;tyrone-cluster;Scheduler was sent the command new
12/24/2012 15:23:15;0040;PBS_Server;Svr;tyrone-cluster;Scheduler was sent the command new
12/24/2012 15:23:49;0040;PBS_Server;Svr;tyrone-cluster;Scheduler was sent the command new
12/24/2012 15:24:15;0040;PBS_Server;Svr;tyrone-cluster;Scheduler was sent the command new
12/24/2012 15:24:45;0040;PBS_Server;Svr;tyrone-cluster;Scheduler was sent the command new
12/24/2012 15:25:11;0002;PBS_Server;Svr;PBS_Server;Torque Server Version = 3.0.5, loglevel = 0
12/24/2012 15:25:21;0040;PBS_Server;Svr;tyrone-cluster;Scheduler was sent the command new
12/24/2012 15:25:52;0040;PBS_Server;Svr;tyrone-cluster;Scheduler was sent the command new
12/24/2012 15:26:25;0040;PBS_Server;Svr;tyrone-cluster;Scheduler was sent the command new
12/24/2012 15:26:56;0040;PBS_Server;Svr;tyrone-cluster;Scheduler was sent the command new
12/24/2012 15:27:28;0040;PBS_Server;Svr;tyrone-cluster;Scheduler was sent the command new
12/24/2012 15:27:56;0040;PBS_Server;Svr;tyrone-cluster;Scheduler was sent the command new
12/24/2012 15:28:26;0040;PBS_Server;Svr;tyrone-cluster;Scheduler was sent the command new
12/24/2012 15:28:57;0040;PBS_Server;Svr;tyrone-cluster;Scheduler was sent the command new
12/24/2012 15:29:26;0040;PBS_Server;Svr;tyrone-cluster;Scheduler was sent the command new
12/24/2012 15:29:57;0040;PBS_Server;Svr;tyrone-cluster;Scheduler was sent the command new
12/24/2012 15:30:11;0002;PBS_Server;Svr;PBS_Server;Torque Server Version = 3.0.5, loglevel = 0
12/24/2012 15:30:27;0040;PBS_Server;Svr;tyrone-cluster;Scheduler was sent the command new
12/24/2012 15:30:56;0040;PBS_Server;Svr;tyrone-cluster;Scheduler was sent the command new
12/24/2012 15:31:26;0040;PBS_Server;Svr;tyrone-cluster;Scheduler was sent the command new
12/24/2012 15:31:57;0040;PBS_Server;Svr;tyrone-cluster;Scheduler was sent the command new
12/24/2012 15:32:26;0040;PBS_Server;Svr;tyrone-cluster;Scheduler was sent the command new
12/24/2012 15:32:57;0040;PBS_Server;Svr;tyrone-cluster;Scheduler was sent the command new
12/24/2012 15:33:27;0040;PBS_Server;Svr;tyrone-cluster;Scheduler was sent the command new
12/24/2012 15:33:57;0040;PBS_Server;Svr;tyrone-cluster;Scheduler was sent the command new
12/24/2012 15:34:30;0040;PBS_Server;Svr;tyrone-cluster;Scheduler was sent the command new
12/24/2012 15:35:05;0040;PBS_Server;Svr;tyrone-cluster;Scheduler was sent the command new
12/24/2012 15:35:11;0002;PBS_Server;Svr;PBS_Server;Torque Server Version = 3.0.5, loglevel = 0
12/24/2012 15:35:31;0040;PBS_Server;Svr;tyrone-cluster;Scheduler was sent the command new
12/24/2012 15:36:00;0040;PBS_Server;Svr;tyrone-cluster;Scheduler was sent the command new
12/24/2012 15:36:34;0040;PBS_Server;Svr;tyrone-cluster;Scheduler was sent the command new
12/24/2012 15:37:00;0040;PBS_Server;Svr;tyrone-cluster;Scheduler was sent the command new
12/24/2012 15:37:30;0040;PBS_Server;Svr;tyrone-cluster;Scheduler was sent the command new
12/24/2012 15:38:06;0040;PBS_Server;Svr;tyrone-cluster;Scheduler was sent the command new
12/24/2012 15:38:37;0040;PBS_Server;Svr;tyrone-cluster;Scheduler was sent the command new
12/24/2012 15:39:09;0040;PBS_Server;Svr;tyrone-cluster;Scheduler was sent the command new
12/24/2012 15:39:41;0040;PBS_Server;Svr;tyrone-cluster;Scheduler was sent the command new
12/24/2012 15:40:11;0002;PBS_Server;Svr;PBS_Server;Torque Server Version = 3.0.5, loglevel = 0
12/24/2012 15:40:13;0040;PBS_Server;Svr;tyrone-cluster;Scheduler was sent the command new
12/24/2012 15:40:41;0040;PBS_Server;Svr;tyrone-cluster;Scheduler was sent the command new
12/24/2012 15:41:11;0040;PBS_Server;Svr;tyrone-cluster;Scheduler was sent the command new
12/24/2012 15:41:42;0040;PBS_Server;Svr;tyrone-cluster;Scheduler was sent the command new
12/24/2012 15:42:11;0040;PBS_Server;Svr;tyrone-cluster;Scheduler was sent the command new
12/24/2012 15:42:42;0040;PBS_Server;Svr;tyrone-cluster;Scheduler was sent the command new
12/24/2012 15:43:12;0040;PBS_Server;Svr;tyrone-cluster;Scheduler was sent the command new
12/24/2012 15:43:42;0040;PBS_Server;Svr;tyrone-cluster;Scheduler was sent the command new
12/24/2012 15:44:15;0040;PBS_Server;Svr;tyrone-cluster;Scheduler was sent the command new
12/24/2012 15:44:49;0040;PBS_Server;Svr;tyrone-cluster;Scheduler was sent the command new
12/24/2012 15:45:11;0002;PBS_Server;Svr;PBS_Server;Torque Server Version = 3.0.5, loglevel = 0
12/24/2012 15:45:15;0040;PBS_Server;Svr;tyrone-cluster;Scheduler was sent the command new
12/24/2012 15:45:45;0040;PBS_Server;Svr;tyrone-cluster;Scheduler was sent the command new
12/24/2012 15:46:21;0040;PBS_Server;Svr;tyrone-cluster;Scheduler was sent the command new
12/24/2012 15:46:52;0040;PBS_Server;Svr;tyrone-cluster;Scheduler was sent the command new
12/24/2012 15:47:24;0040;PBS_Server;Svr;tyrone-cluster;Scheduler was sent the command new
12/24/2012 15:47:56;0040;PBS_Server;Svr;tyrone-cluster;Scheduler was sent the command new
12/24/2012 15:48:27;0040;PBS_Server;Svr;tyrone-cluster;Scheduler was sent the command new
12/24/2012 15:48:56;0040;PBS_Server;Svr;tyrone-cluster;Scheduler was sent the command new
12/24/2012 15:49:26;0040;PBS_Server;Svr;tyrone-cluster;Scheduler was sent the command new
12/24/2012 15:49:57;0040;PBS_Server;Svr;tyrone-cluster;Scheduler was sent the command new
12/24/2012 15:50:11;0002;PBS_Server;Svr;PBS_Server;Torque Server Version = 3.0.5, loglevel = 0
12/24/2012 15:50:26;0040;PBS_Server;Svr;tyrone-cluster;Scheduler was sent the command new
12/24/2012 15:50:57;0040;PBS_Server;Svr;tyrone-cluster;Scheduler was sent the command new
12/24/2012 15:51:27;0040;PBS_Server;Svr;tyrone-cluster;Scheduler was sent the command new
12/24/2012 15:51:57;0040;PBS_Server;Svr;tyrone-cluster;Scheduler was sent the command new
12/24/2012 15:52:28;0040;PBS_Server;Svr;tyrone-cluster;Scheduler was sent the command new
12/24/2012 15:52:58;0040;PBS_Server;Svr;tyrone-cluster;Scheduler was sent the command new
12/24/2012 15:53:29;0040;PBS_Server;Svr;tyrone-cluster;Scheduler was sent the command new
12/24/2012 15:54:00;0040;PBS_Server;Svr;tyrone-cluster;Scheduler was sent the command new
12/24/2012 15:54:34;0040;PBS_Server;Svr;tyrone-cluster;Scheduler was sent the command new
12/24/2012 15:55:00;0040;PBS_Server;Svr;tyrone-cluster;Scheduler was sent the command new
12/24/2012 15:55:11;0002;PBS_Server;Svr;PBS_Server;Torque Server Version = 3.0.5, loglevel = 0
12/24/2012 15:55:30;0040;PBS_Server;Svr;tyrone-cluster;Scheduler was sent the command new
12/24/2012 15:56:06;0040;PBS_Server;Svr;tyrone-cluster;Scheduler was sent the command new
12/24/2012 15:56:37;0040;PBS_Server;Svr;tyrone-cluster;Scheduler was sent the command new
12/24/2012 15:57:09;0040;PBS_Server;Svr;tyrone-cluster;Scheduler was sent the command new
12/24/2012 15:57:36;0100;PBS_Server;Job;17551.tyrone-cluster;enqueuing into batch, state 1 hop 1
12/24/2012 15:57:36;0100;PBS_Server;Job;17551.tyrone-cluster;dequeuing from batch, state QUEUED
12/24/2012 15:57:36;0100;PBS_Server;Job;17551.tyrone-cluster;enqueuing into idqueue, state 1 hop 1
12/24/2012 15:57:36;0008;PBS_Server;Job;17551.tyrone-cluster;Job Queued at request of ipcvrk@tyrone-cluster, owner = ipcvrk@tyrone-cluster, job name = pq14.cmd, queue = idqueue
12/24/2012 15:57:36;0040;PBS_Server;Svr;tyrone-cluster;Scheduler was sent the command new
12/24/2012 15:57:36;0008;PBS_Server;Job;17551.tyrone-cluster;Job Modified at request of Scheduler@tyrone-cluster
12/24/2012 15:57:36;0008;PBS_Server;Job;17551.tyrone-cluster;Job Run at request of Scheduler@tyrone-cluster
12/24/2012 15:57:36;0040;PBS_Server;Svr;tyrone-cluster;Scheduler was sent the command recyc
12/24/2012 15:57:36;000d;PBS_Server;Job;17551.tyrone-cluster;Not sending email: User does not want mail of this type.
12/24/2012 15:57:41;0040;PBS_Server;Svr;tyrone-cluster;Scheduler was sent the command new
12/24/2012 15:58:12;0040;PBS_Server;Svr;tyrone-cluster;Scheduler was sent the command new
12/24/2012 15:58:41;0040;PBS_Server;Svr;tyrone-cluster;Scheduler was sent the command new
12/24/2012 15:59:12;0040;PBS_Server;Svr;tyrone-cluster;Scheduler was sent the command new
12/24/2012 15:59:42;0040;PBS_Server;Svr;tyrone-cluster;Scheduler was sent the command new
12/24/2012 16:00:11;0002;PBS_Server;Svr;PBS_Server;Torque Server Version = 3.0.5, loglevel = 0
12/24/2012 16:00:11;0040;PBS_Server;Svr;tyrone-cluster;Scheduler was sent the command new
12/24/2012 16:00:42;0040;PBS_Server;Svr;tyrone-cluster;Scheduler was sent the command new
12/24/2012 16:01:12;0040;PBS_Server;Svr;tyrone-cluster;Scheduler was sent the command new
12/24/2012 16:01:42;0040;PBS_Server;Svr;tyrone-cluster;Scheduler was sent the command new
12/24/2012 16:02:15;0040;PBS_Server;Svr;tyrone-cluster;Scheduler was sent the command new
12/24/2012 16:02:46;0040;PBS_Server;Svr;tyrone-cluster;Scheduler was sent the command new
12/24/2012 16:03:15;0040;PBS_Server;Svr;tyrone-cluster;Scheduler was sent the command new
12/24/2012 16:03:45;0040;PBS_Server;Svr;tyrone-cluster;Scheduler was sent the command new
12/24/2012 16:04:16;0040;PBS_Server;Svr;tyrone-cluster;Scheduler was sent the command new
12/24/2012 16:04:40;0100;PBS_Server;Job;17552.tyrone-cluster;enqueuing into batch, state 1 hop 1
12/24/2012 16:04:40;0100;PBS_Server;Job;17552.tyrone-cluster;dequeuing from batch, state QUEUED
12/24/2012 16:04:40;0100;PBS_Server;Job;17552.tyrone-cluster;enqueuing into qp64, state 1 hop 1
12/24/2012 16:04:40;0008;PBS_Server;Job;17552.tyrone-cluster;Job Queued at request of ipcvrk@tyrone-cluster, owner = ipcvrk@tyrone-cluster, job name = pq11.cmd, queue = qp64
12/24/2012 16:04:40;0040;PBS_Server;Svr;tyrone-cluster;Scheduler was sent the command new
12/24/2012 16:04:40;0008;PBS_Server;Job;17552.tyrone-cluster;Job Modified at request of Scheduler@tyrone-cluster
12/24/2012 16:04:48;0040;PBS_Server;Svr;tyrone-cluster;Scheduler was sent the command new
12/24/2012 16:05:05;0100;PBS_Server;Job;17553.tyrone-cluster;enqueuing into batch, state 1 hop 1
12/24/2012 16:05:05;0100;PBS_Server;Job;17553.tyrone-cluster;dequeuing from batch, state QUEUED
12/24/2012 16:05:05;0100;PBS_Server;Job;17553.tyrone-cluster;enqueuing into qp32, state 1 hop 1
12/24/2012 16:05:05;0008;PBS_Server;Job;17553.tyrone-cluster;Job Queued at request of ipcvrk@tyrone-cluster, owner = ipcvrk@tyrone-cluster, job name = pq12.cmd, queue = qp32
12/24/2012 16:05:05;0040;PBS_Server;Svr;tyrone-cluster;Scheduler was sent the command new
12/24/2012 16:05:05;0008;PBS_Server;Job;17553.tyrone-cluster;Job Modified at request of Scheduler@tyrone-cluster
12/24/2012 16:05:11;0002;PBS_Server;Svr;PBS_Server;Torque Server Version = 3.0.5, loglevel = 0
12/24/2012 16:05:24;0040;PBS_Server;Svr;tyrone-cluster;Scheduler was sent the command new
12/24/2012 16:05:51;0040;PBS_Server;Svr;tyrone-cluster;Scheduler was sent the command new
12/24/2012 16:06:18;0040;PBS_Server;Svr;tyrone-cluster;Scheduler was sent the command new
12/24/2012 16:06:55;0040;PBS_Server;Svr;tyrone-cluster;Scheduler was sent the command new
12/24/2012 16:07:21;0040;PBS_Server;Svr;tyrone-cluster;Scheduler was sent the command new
12/24/2012 16:07:52;0040;PBS_Server;Svr;tyrone-cluster;Scheduler was sent the command new
12/24/2012 16:08:25;0040;PBS_Server;Svr;tyrone-cluster;Scheduler was sent the command new
12/24/2012 16:08:56;0040;PBS_Server;Svr;tyrone-cluster;Scheduler was sent the command new
12/24/2012 16:09:27;0040;PBS_Server;Svr;tyrone-cluster;Scheduler was sent the command new
12/24/2012 16:09:56;0040;PBS_Server;Svr;tyrone-cluster;Scheduler was sent the command new
12/24/2012 16:10:11;0002;PBS_Server;Svr;PBS_Server;Torque Server Version = 3.0.5, loglevel = 0
12/24/2012 16:10:27;0040;PBS_Server;Svr;tyrone-cluster;Scheduler was sent the command new
12/24/2012 16:10:56;0040;PBS_Server;Svr;tyrone-cluster;Scheduler was sent the command new
12/24/2012 16:11:26;0040;PBS_Server;Svr;tyrone-cluster;Scheduler was sent the command new
12/24/2012 16:11:57;0040;PBS_Server;Svr;tyrone-cluster;Scheduler was sent the command new
12/24/2012 16:12:27;0040;PBS_Server;Svr;tyrone-cluster;Scheduler was sent the command new
12/24/2012 16:12:56;0040;PBS_Server;Svr;tyrone-cluster;Scheduler was sent the command new
12/24/2012 16:13:27;0040;PBS_Server;Svr;tyrone-cluster;Scheduler was sent the command new
12/24/2012 16:13:56;0040;PBS_Server;Svr;tyrone-cluster;Scheduler was sent the command new
12/24/2012 16:14:26;0040;PBS_Server;Svr;tyrone-cluster;Scheduler was sent the command new
12/24/2012 16:14:57;0040;PBS_Server;Svr;tyrone-cluster;Scheduler was sent the command new
12/24/2012 16:15:11;0002;PBS_Server;Svr;PBS_Server;Torque Server Version = 3.0.5, loglevel = 0
12/24/2012 16:15:27;0040;PBS_Server;Svr;tyrone-cluster;Scheduler was sent the command new
12/24/2012 16:15:57;0040;PBS_Server;Svr;tyrone-cluster;Scheduler was sent the command new
12/24/2012 16:16:28;0040;PBS_Server;Svr;tyrone-cluster;Scheduler was sent the command new
12/24/2012 16:16:57;0040;PBS_Server;Svr;tyrone-cluster;Scheduler was sent the command new
12/24/2012 16:17:27;0040;PBS_Server;Svr;tyrone-cluster;Scheduler was sent the command new
12/24/2012 16:17:58;0040;PBS_Server;Svr;tyrone-cluster;Scheduler was sent the command new
12/24/2012 16:18:27;0040;PBS_Server;Svr;tyrone-cluster;Scheduler was sent the command new
12/24/2012 16:18:57;0040;PBS_Server;Svr;tyrone-cluster;Scheduler was sent the command new
12/24/2012 16:19:29;0040;PBS_Server;Svr;tyrone-cluster;Scheduler was sent the command new
12/24/2012 16:19:57;0040;PBS_Server;Svr;tyrone-cluster;Scheduler was sent the command new
12/24/2012 16:20:11;0002;PBS_Server;Svr;PBS_Server;Torque Server Version = 3.0.5, loglevel = 0
12/24/2012 16:20:27;0040;PBS_Server;Svr;tyrone-cluster;Scheduler was sent the command new
12/24/2012 16:20:59;0040;PBS_Server;Svr;tyrone-cluster;Scheduler was sent the command new
12/24/2012 16:21:31;0040;PBS_Server;Svr;tyrone-cluster;Scheduler was sent the command new
12/24/2012 16:22:00;0040;PBS_Server;Svr;tyrone-cluster;Scheduler was sent the command new
12/24/2012 16:22:29;0040;PBS_Server;Svr;tyrone-cluster;Scheduler was sent the command new
12/24/2012 16:23:02;0040;PBS_Server;Svr;tyrone-cluster;Scheduler was sent the command new
12/24/2012 16:23:28;0040;PBS_Server;Svr;tyrone-cluster;Scheduler was sent the command new
12/24/2012 16:23:59;0040;PBS_Server;Svr;tyrone-cluster;Scheduler was sent the command new
12/24/2012 16:24:32;0040;PBS_Server;Svr;tyrone-cluster;Scheduler was sent the command new
12/24/2012 16:24:58;0040;PBS_Server;Svr;tyrone-cluster;Scheduler was sent the command new
12/24/2012 16:25:11;0002;PBS_Server;Svr;PBS_Server;Torque Server Version = 3.0.5, loglevel = 0
12/24/2012 16:25:29;0040;PBS_Server;Svr;tyrone-cluster;Scheduler was sent the command new
12/24/2012 16:26:02;0040;PBS_Server;Svr;tyrone-cluster;Scheduler was sent the command new
12/24/2012 16:26:28;0040;PBS_Server;Svr;tyrone-cluster;Scheduler was sent the command new
12/24/2012 16:27:00;0040;PBS_Server;Svr;tyrone-cluster;Scheduler was sent the command new
12/24/2012 16:27:32;0040;PBS_Server;Svr;tyrone-cluster;Scheduler was sent the command new
12/24/2012 16:27:58;0040;PBS_Server;Svr;tyrone-cluster;Scheduler was sent the command new
12/24/2012 16:28:29;0040;PBS_Server;Svr;tyrone-cluster;Scheduler was sent the command new
12/24/2012 16:29:02;0040;PBS_Server;Svr;tyrone-cluster;Scheduler was sent the command new
12/24/2012 16:29:28;0040;PBS_Server;Svr;tyrone-cluster;Scheduler was sent the command new
12/24/2012 16:30:00;0040;PBS_Server;Svr;tyrone-cluster;Scheduler was sent the command new
12/24/2012 16:30:11;0002;PBS_Server;Svr;PBS_Server;Torque Server Version = 3.0.5, loglevel = 0
12/24/2012 16:30:32;0040;PBS_Server;Svr;tyrone-cluster;Scheduler was sent the command new
12/24/2012 16:30:58;0040;PBS_Server;Svr;tyrone-cluster;Scheduler was sent the command new
12/24/2012 16:31:29;0040;PBS_Server;Svr;tyrone-cluster;Scheduler was sent the command new
12/24/2012 16:32:02;0040;PBS_Server;Svr;tyrone-cluster;Scheduler was sent the command new
12/24/2012 16:32:28;0040;PBS_Server;Svr;tyrone-cluster;Scheduler was sent the command new
12/24/2012 16:32:59;0040;PBS_Server;Svr;tyrone-cluster;Scheduler was sent the command new
12/24/2012 16:33:32;0040;PBS_Server;Svr;tyrone-cluster;Scheduler was sent the command new
12/24/2012 16:33:59;0040;PBS_Server;Svr;tyrone-cluster;Scheduler was sent the command new
12/24/2012 16:34:29;0040;PBS_Server;Svr;tyrone-cluster;Scheduler was sent the command new
12/24/2012 16:35:02;0040;PBS_Server;Svr;tyrone-cluster;Scheduler was sent the command new
12/24/2012 16:35:11;0002;PBS_Server;Svr;PBS_Server;Torque Server Version = 3.0.5, loglevel = 0
12/24/2012 16:35:28;0040;PBS_Server;Svr;tyrone-cluster;Scheduler was sent the command new
12/24/2012 16:35:59;0040;PBS_Server;Svr;tyrone-cluster;Scheduler was sent the command new
12/24/2012 16:36:05;0100;PBS_Server;Job;17554.tyrone-cluster;enqueuing into batch, state 1 hop 1
12/24/2012 16:36:05;0100;PBS_Server;Job;17554.tyrone-cluster;dequeuing from batch, state QUEUED
12/24/2012 16:36:05;0100;PBS_Server;Job;17554.tyrone-cluster;enqueuing into idqueue, state 1 hop 1
12/24/2012 16:36:05;0008;PBS_Server;Job;17554.tyrone-cluster;Job Queued at request of secgmk@tyrone-cluster, owner = secgmk@tyrone-cluster, job name = md1-1XK9, queue = idqueue
12/24/2012 16:36:05;0040;PBS_Server;Svr;tyrone-cluster;Scheduler was sent the command new
12/24/2012 16:36:06;0008;PBS_Server;Job;17554.tyrone-cluster;Job Modified at request of Scheduler@tyrone-cluster
12/24/2012 16:36:06;0008;PBS_Server;Job;17554.tyrone-cluster;Job Run at request of Scheduler@tyrone-cluster
12/24/2012 16:36:06;000d;PBS_Server;Job;17554.tyrone-cluster;Not sending email: User does not want mail of this type.
12/24/2012 16:36:06;0040;PBS_Server;Svr;tyrone-cluster;Scheduler was sent the command recyc
12/24/2012 16:36:32;0040;PBS_Server;Svr;tyrone-cluster;Scheduler was sent the command new
12/24/2012 16:36:58;0040;PBS_Server;Svr;tyrone-cluster;Scheduler was sent the command new
12/24/2012 16:37:28;0040;PBS_Server;Svr;tyrone-cluster;Scheduler was sent the command new
12/24/2012 16:38:02;0040;PBS_Server;Svr;tyrone-cluster;Scheduler was sent the command new
12/24/2012 16:38:28;0040;PBS_Server;Svr;tyrone-cluster;Scheduler was sent the command new
12/24/2012 16:38:59;0040;PBS_Server;Svr;tyrone-cluster;Scheduler was sent the command new
12/24/2012 16:39:32;0040;PBS_Server;Svr;tyrone-cluster;Scheduler was sent the command new
12/24/2012 16:39:58;0040;PBS_Server;Svr;tyrone-cluster;Scheduler was sent the command new
12/24/2012 16:40:11;0002;PBS_Server;Svr;PBS_Server;Torque Server Version = 3.0.5, loglevel = 0
12/24/2012 16:40:28;0040;PBS_Server;Svr;tyrone-cluster;Scheduler was sent the command new
12/24/2012 16:41:02;0040;PBS_Server;Svr;tyrone-cluster;Scheduler was sent the command new
12/24/2012 16:41:28;0040;PBS_Server;Svr;tyrone-cluster;Scheduler was sent the command new
12/24/2012 16:41:59;0040;PBS_Server;Svr;tyrone-cluster;Scheduler was sent the command new
12/24/2012 16:42:32;0040;PBS_Server;Svr;tyrone-cluster;Scheduler was sent the command new
12/24/2012 16:42:58;0040;PBS_Server;Svr;tyrone-cluster;Scheduler was sent the command new
12/24/2012 16:43:29;0040;PBS_Server;Svr;tyrone-cluster;Scheduler was sent the command new
12/24/2012 16:44:02;0040;PBS_Server;Svr;tyrone-cluster;Scheduler was sent the command new
12/24/2012 16:44:28;0040;PBS_Server;Svr;tyrone-cluster;Scheduler was sent the command new
12/24/2012 16:44:59;0040;PBS_Server;Svr;tyrone-cluster;Scheduler was sent the command new
12/24/2012 16:45:11;0002;PBS_Server;Svr;PBS_Server;Torque Server Version = 3.0.5, loglevel = 0
12/24/2012 16:45:32;0040;PBS_Server;Svr;tyrone-cluster;Scheduler was sent the command new
12/24/2012 16:45:58;0040;PBS_Server;Svr;tyrone-cluster;Scheduler was sent the command new
12/24/2012 16:46:28;0040;PBS_Server;Svr;tyrone-cluster;Scheduler was sent the command new
12/24/2012 16:47:02;0040;PBS_Server;Svr;tyrone-cluster;Scheduler was sent the command new
12/24/2012 16:47:34;0040;PBS_Server;Svr;tyrone-cluster;Scheduler was sent the command new
12/24/2012 16:48:09;0040;PBS_Server;Svr;tyrone-cluster;Scheduler was sent the command new
12/24/2012 16:48:37;0040;PBS_Server;Svr;tyrone-cluster;Scheduler was sent the command new
12/24/2012 16:49:08;0040;PBS_Server;Svr;tyrone-cluster;Scheduler was sent the command new
12/24/2012 16:49:39;0040;PBS_Server;Svr;tyrone-cluster;Scheduler was sent the command new
12/24/2012 16:50:08;0040;PBS_Server;Svr;tyrone-cluster;Scheduler was sent the command new
12/24/2012 16:50:11;0002;PBS_Server;Svr;PBS_Server;Torque Server Version = 3.0.5, loglevel = 0
12/24/2012 16:50:38;0040;PBS_Server;Svr;tyrone-cluster;Scheduler was sent the command new
12/24/2012 16:51:09;0040;PBS_Server;Svr;tyrone-cluster;Scheduler was sent the command new
12/24/2012 16:51:38;0040;PBS_Server;Svr;tyrone-cluster;Scheduler was sent the command new
12/24/2012 16:52:08;0040;PBS_Server;Svr;tyrone-cluster;Scheduler was sent the command new
12/24/2012 16:52:39;0040;PBS_Server;Svr;tyrone-cluster;Scheduler was sent the command new
12/24/2012 16:53:08;0040;PBS_Server;Svr;tyrone-cluster;Scheduler was sent the command new
12/24/2012 16:53:38;0040;PBS_Server;Svr;tyrone-cluster;Scheduler was sent the command new
12/24/2012 16:54:10;0040;PBS_Server;Svr;tyrone-cluster;Scheduler was sent the command new
12/24/2012 16:54:39;0040;PBS_Server;Svr;tyrone-cluster;Scheduler was sent the command new
12/24/2012 16:55:10;0040;PBS_Server;Svr;tyrone-cluster;Scheduler was sent the command new
12/24/2012 16:55:11;0002;PBS_Server;Svr;PBS_Server;Torque Server Version = 3.0.5, loglevel = 0
12/24/2012 16:55:42;0040;PBS_Server;Svr;tyrone-cluster;Scheduler was sent the command new
12/24/2012 16:56:09;0040;PBS_Server;Svr;tyrone-cluster;Scheduler was sent the command new
12/24/2012 16:56:40;0040;PBS_Server;Svr;tyrone-cluster;Scheduler was sent the command new
12/24/2012 16:57:12;0040;PBS_Server;Svr;tyrone-cluster;Scheduler was sent the command new
12/24/2012 16:57:39;0040;PBS_Server;Svr;tyrone-cluster;Scheduler was sent the command new
12/24/2012 16:58:10;0040;PBS_Server;Svr;tyrone-cluster;Scheduler was sent the command new
12/24/2012 16:58:42;0040;PBS_Server;Svr;tyrone-cluster;Scheduler was sent the command new
12/24/2012 16:59:13;0040;PBS_Server;Svr;tyrone-cluster;Scheduler was sent the command new
12/24/2012 16:59:42;0040;PBS_Server;Svr;tyrone-cluster;Scheduler was sent the command new
12/24/2012 17:00:11;0002;PBS_Server;Svr;PBS_Server;Torque Server Version = 3.0.5, loglevel = 0
12/24/2012 17:00:12;0040;PBS_Server;Svr;tyrone-cluster;Scheduler was sent the command new
12/24/2012 17:00:43;0040;PBS_Server;Svr;tyrone-cluster;Scheduler was sent the command new
12/24/2012 17:01:17;0040;PBS_Server;Svr;tyrone-cluster;Scheduler was sent the command new
12/24/2012 17:01:43;0040;PBS_Server;Svr;tyrone-cluster;Scheduler was sent the command new
12/24/2012 17:02:14;0040;PBS_Server;Svr;tyrone-cluster;Scheduler was sent the command new
12/24/2012 17:02:47;0040;PBS_Server;Svr;tyrone-cluster;Scheduler was sent the command new
12/24/2012 17:03:13;0040;PBS_Server;Svr;tyrone-cluster;Scheduler was sent the command new
12/24/2012 17:03:44;0040;PBS_Server;Svr;tyrone-cluster;Scheduler was sent the command new
12/24/2012 17:04:17;0040;PBS_Server;Svr;tyrone-cluster;Scheduler was sent the command new
12/24/2012 17:04:49;0040;PBS_Server;Svr;tyrone-cluster;Scheduler was sent the command new
12/24/2012 17:05:11;0002;PBS_Server;Svr;PBS_Server;Torque Server Version = 3.0.5, loglevel = 0
12/24/2012 17:05:23;0040;PBS_Server;Svr;tyrone-cluster;Scheduler was sent the command new
12/24/2012 17:05:52;0040;PBS_Server;Svr;tyrone-cluster;Scheduler was sent the command new
12/24/2012 17:06:23;0040;PBS_Server;Svr;tyrone-cluster;Scheduler was sent the command new
12/24/2012 17:06:54;0040;PBS_Server;Svr;tyrone-cluster;Scheduler was sent the command new
12/24/2012 17:07:23;0040;PBS_Server;Svr;tyrone-cluster;Scheduler was sent the command new
12/24/2012 17:07:44;000d;PBS_Server;Job;17521.tyrone-cluster;Not sending email: User does not want mail of this type.
12/24/2012 17:07:44;0010;PBS_Server;Job;17521.tyrone-cluster;Exit_status=0 resources_used.cput=192:57:19 resources_used.mem=5864748kb resources_used.vmem=13772872kb resources_used.walltime=06:16:10
12/24/2012 17:07:44;0008;PBS_Server;Job;NULL;on_job_exit valid pjob: 0x1b92e60 (substate=50)
12/24/2012 17:07:44;0008;PBS_Server;Job;NULL;on_job_exit valid pjob: 0x1b92e60 (substate=51)
12/24/2012 17:07:45;0008;PBS_Server;Job;NULL;on_job_exit valid pjob: 0x1b92e60 (substate=51)
12/24/2012 17:07:45;0008;PBS_Server;Job;NULL;on_job_exit valid pjob: 0x1b92e60 (substate=53)
12/24/2012 17:07:45;0100;PBS_Server;Job;17521.tyrone-cluster;dequeuing from qp32, state COMPLETE
12/24/2012 17:07:45;0040;PBS_Server;Svr;tyrone-cluster;Scheduler was sent the command term
12/24/2012 17:07:45;0008;PBS_Server;Job;17519.tyrone-cluster;Job Modified at request of Scheduler@tyrone-cluster
12/24/2012 17:07:45;0008;PBS_Server;Job;17522.tyrone-cluster;Job Modified at request of Scheduler@tyrone-cluster
12/24/2012 17:07:45;0008;PBS_Server;Job;17536.tyrone-cluster;Job Modified at request of Scheduler@tyrone-cluster
12/24/2012 17:07:45;0008;PBS_Server;Job;17536.tyrone-cluster;Job Run at request of Scheduler@tyrone-cluster
12/24/2012 17:07:46;0040;PBS_Server;Svr;tyrone-cluster;Scheduler was sent the command recyc
12/24/2012 17:07:46;000d;PBS_Server;Job;17536.tyrone-cluster;Not sending email: User does not want mail of this type.
12/24/2012 17:07:53;0040;PBS_Server;Svr;tyrone-cluster;Scheduler was sent the command new
12/24/2012 17:07:53;0008;PBS_Server;Job;17519.tyrone-cluster;Job Modified at request of Scheduler@tyrone-cluster
12/24/2012 17:07:53;0008;PBS_Server;Job;17522.tyrone-cluster;Job Modified at request of Scheduler@tyrone-cluster
12/24/2012 17:08:24;0040;PBS_Server;Svr;tyrone-cluster;Scheduler was sent the command new
12/24/2012 17:08:53;0040;PBS_Server;Svr;tyrone-cluster;Scheduler was sent the command new
12/24/2012 17:09:23;0040;PBS_Server;Svr;tyrone-cluster;Scheduler was sent the command new
12/24/2012 17:09:54;0040;PBS_Server;Svr;tyrone-cluster;Scheduler was sent the command new
12/24/2012 17:10:11;0002;PBS_Server;Svr;PBS_Server;Torque Server Version = 3.0.5, loglevel = 0
12/24/2012 17:10:23;0040;PBS_Server;Svr;tyrone-cluster;Scheduler was sent the command new
12/24/2012 17:10:53;0040;PBS_Server;Svr;tyrone-cluster;Scheduler was sent the command new
12/24/2012 17:11:24;0040;PBS_Server;Svr;tyrone-cluster;Scheduler was sent the command new
12/24/2012 17:11:53;0040;PBS_Server;Svr;tyrone-cluster;Scheduler was sent the command new
12/24/2012 17:12:23;0040;PBS_Server;Svr;tyrone-cluster;Scheduler was sent the command new
12/24/2012 17:12:54;0040;PBS_Server;Svr;tyrone-cluster;Scheduler was sent the command new
12/24/2012 17:13:23;0040;PBS_Server;Svr;tyrone-cluster;Scheduler was sent the command new
12/24/2012 17:13:53;0040;PBS_Server;Svr;tyrone-cluster;Scheduler was sent the command new
12/24/2012 17:14:24;0040;PBS_Server;Svr;tyrone-cluster;Scheduler was sent the command new
12/24/2012 17:14:53;0040;PBS_Server;Svr;tyrone-cluster;Scheduler was sent the command new
12/24/2012 17:15:11;0002;PBS_Server;Svr;PBS_Server;Torque Server Version = 3.0.5, loglevel = 0
12/24/2012 17:15:23;0040;PBS_Server;Svr;tyrone-cluster;Scheduler was sent the command new
12/24/2012 17:15:54;0040;PBS_Server;Svr;tyrone-cluster;Scheduler was sent the command new
12/24/2012 17:16:23;0040;PBS_Server;Svr;tyrone-cluster;Scheduler was sent the command new
12/24/2012 17:16:53;0040;PBS_Server;Svr;tyrone-cluster;Scheduler was sent the command new
12/24/2012 17:17:08;000d;PBS_Server;Job;17479.tyrone-cluster;Not sending email: User does not want mail of this type.
12/24/2012 17:17:08;0010;PBS_Server;Job;17479.tyrone-cluster;Exit_status=143 resources_used.cput=741:07:32 resources_used.mem=9178324kb resources_used.vmem=20796700kb resources_used.walltime=24:00:46
12/24/2012 17:17:08;0008;PBS_Server;Job;NULL;on_job_exit valid pjob: 0x1b96ff0 (substate=50)
12/24/2012 17:17:08;0008;PBS_Server;Job;NULL;on_job_exit valid pjob: 0x1b96ff0 (substate=51)
12/24/2012 17:17:08;0008;PBS_Server;Job;NULL;on_job_exit valid pjob: 0x1b96ff0 (substate=51)
12/24/2012 17:17:08;0008;PBS_Server;Job;NULL;on_job_exit valid pjob: 0x1b96ff0 (substate=53)
12/24/2012 17:17:08;0100;PBS_Server;Job;17479.tyrone-cluster;dequeuing from qp32, state COMPLETE
12/24/2012 17:17:08;0040;PBS_Server;Svr;tyrone-cluster;Scheduler was sent the command term
12/24/2012 17:17:09;0008;PBS_Server;Job;17519.tyrone-cluster;Job Modified at request of Scheduler@tyrone-cluster
12/24/2012 17:17:09;0008;PBS_Server;Job;17522.tyrone-cluster;Job Modified at request of Scheduler@tyrone-cluster
12/24/2012 17:17:09;0008;PBS_Server;Job;17539.tyrone-cluster;Job Modified at request of Scheduler@tyrone-cluster
12/24/2012 17:17:09;0008;PBS_Server;Job;17539.tyrone-cluster;Job Run at request of Scheduler@tyrone-cluster
12/24/2012 17:17:09;0040;PBS_Server;Svr;tyrone-cluster;Scheduler was sent the command recyc
12/24/2012 17:17:09;000d;PBS_Server;Job;17539.tyrone-cluster;Not sending email: User does not want mail of this type.
12/24/2012 17:17:23;0040;PBS_Server;Svr;tyrone-cluster;Scheduler was sent the command new
12/24/2012 17:17:23;0008;PBS_Server;Job;17519.tyrone-cluster;Job Modified at request of Scheduler@tyrone-cluster
12/24/2012 17:17:23;0008;PBS_Server;Job;17522.tyrone-cluster;Job Modified at request of Scheduler@tyrone-cluster
12/24/2012 17:17:53;0040;PBS_Server;Svr;tyrone-cluster;Scheduler was sent the command new
12/24/2012 17:18:23;0040;PBS_Server;Svr;tyrone-cluster;Scheduler was sent the command new
12/24/2012 17:18:53;0040;PBS_Server;Svr;tyrone-cluster;Scheduler was sent the command new
12/24/2012 17:19:23;0040;PBS_Server;Svr;tyrone-cluster;Scheduler was sent the command new
12/24/2012 17:19:53;0040;PBS_Server;Svr;tyrone-cluster;Scheduler was sent the command new
12/24/2012 17:20:11;0002;PBS_Server;Svr;PBS_Server;Torque Server Version = 3.0.5, loglevel = 0
12/24/2012 17:20:23;0040;PBS_Server;Svr;tyrone-cluster;Scheduler was sent the command new
12/24/2012 17:20:53;0040;PBS_Server;Svr;tyrone-cluster;Scheduler was sent the command new
12/24/2012 17:21:23;0040;PBS_Server;Svr;tyrone-cluster;Scheduler was sent the command new
12/24/2012 17:21:53;0040;PBS_Server;Svr;tyrone-cluster;Scheduler was sent the command new
12/24/2012 17:22:23;0040;PBS_Server;Svr;tyrone-cluster;Scheduler was sent the command new
12/24/2012 17:22:53;0040;PBS_Server;Svr;tyrone-cluster;Scheduler was sent the command new
12/24/2012 17:23:23;0040;PBS_Server;Svr;tyrone-cluster;Scheduler was sent the command new
12/24/2012 17:23:53;0040;PBS_Server;Svr;tyrone-cluster;Scheduler was sent the command new
12/24/2012 17:24:23;0040;PBS_Server;Svr;tyrone-cluster;Scheduler was sent the command new
12/24/2012 17:24:53;0040;PBS_Server;Svr;tyrone-cluster;Scheduler was sent the command new
12/24/2012 17:25:11;0002;PBS_Server;Svr;PBS_Server;Torque Server Version = 3.0.5, loglevel = 0
12/24/2012 17:25:23;0040;PBS_Server;Svr;tyrone-cluster;Scheduler was sent the command new
12/24/2012 17:25:53;0040;PBS_Server;Svr;tyrone-cluster;Scheduler was sent the command new
12/24/2012 17:26:23;0040;PBS_Server;Svr;tyrone-cluster;Scheduler was sent the command new
12/24/2012 17:26:53;0040;PBS_Server;Svr;tyrone-cluster;Scheduler was sent the command new
12/24/2012 17:27:23;0040;PBS_Server;Svr;tyrone-cluster;Scheduler was sent the command new
12/24/2012 17:27:38;0100;PBS_Server;Job;17555.tyrone-cluster;enqueuing into batch, state 1 hop 1
12/24/2012 17:27:38;0100;PBS_Server;Job;17555.tyrone-cluster;dequeuing from batch, state QUEUED
12/24/2012 17:27:38;0100;PBS_Server;Job;17555.tyrone-cluster;enqueuing into idqueue, state 1 hop 1
12/24/2012 17:27:38;0008;PBS_Server;Job;17555.tyrone-cluster;Job Queued at request of ipcdskp@tyrone-cluster, owner = ipcdskp@tyrone-cluster, job name = n10, queue = idqueue
12/24/2012 17:27:38;0040;PBS_Server;Svr;tyrone-cluster;Scheduler was sent the command new
12/24/2012 17:27:38;0008;PBS_Server;Job;17555.tyrone-cluster;Job Modified at request of Scheduler@tyrone-cluster
12/24/2012 17:27:38;0008;PBS_Server;Job;17555.tyrone-cluster;Job Run at request of Scheduler@tyrone-cluster
12/24/2012 17:27:38;0040;PBS_Server;Svr;tyrone-cluster;Scheduler was sent the command recyc
12/24/2012 17:27:38;000d;PBS_Server;Job;17555.tyrone-cluster;Not sending email: User does not want mail of this type.
12/24/2012 17:27:53;0040;PBS_Server;Svr;tyrone-cluster;Scheduler was sent the command new
12/24/2012 17:28:23;0040;PBS_Server;Svr;tyrone-cluster;Scheduler was sent the command new
12/24/2012 17:28:53;0040;PBS_Server;Svr;tyrone-cluster;Scheduler was sent the command new
12/24/2012 17:29:23;0040;PBS_Server;Svr;tyrone-cluster;Scheduler was sent the command new
12/24/2012 17:29:53;0040;PBS_Server;Svr;tyrone-cluster;Scheduler was sent the command new
12/24/2012 17:30:11;0002;PBS_Server;Svr;PBS_Server;Torque Server Version = 3.0.5, loglevel = 0
12/24/2012 17:30:23;0040;PBS_Server;Svr;tyrone-cluster;Scheduler was sent the command new
12/24/2012 17:30:53;0040;PBS_Server;Svr;tyrone-cluster;Scheduler was sent the command new
12/24/2012 17:31:23;0040;PBS_Server;Svr;tyrone-cluster;Scheduler was sent the command new
12/24/2012 17:31:53;0040;PBS_Server;Svr;tyrone-cluster;Scheduler was sent the command new
12/24/2012 17:32:23;0040;PBS_Server;Svr;tyrone-cluster;Scheduler was sent the command new
12/24/2012 17:32:53;0040;PBS_Server;Svr;tyrone-cluster;Scheduler was sent the command new
12/24/2012 17:33:23;0040;PBS_Server;Svr;tyrone-cluster;Scheduler was sent the command new
12/24/2012 17:33:53;0040;PBS_Server;Svr;tyrone-cluster;Scheduler was sent the command new
12/24/2012 17:34:23;0040;PBS_Server;Svr;tyrone-cluster;Scheduler was sent the command new
12/24/2012 17:34:53;0040;PBS_Server;Svr;tyrone-cluster;Scheduler was sent the command new
12/24/2012 17:35:11;0002;PBS_Server;Svr;PBS_Server;Torque Server Version = 3.0.5, loglevel = 0
12/24/2012 17:35:23;0040;PBS_Server;Svr;tyrone-cluster;Scheduler was sent the command new
12/24/2012 17:35:53;0040;PBS_Server;Svr;tyrone-cluster;Scheduler was sent the command new
12/24/2012 17:36:23;0040;PBS_Server;Svr;tyrone-cluster;Scheduler was sent the command new
12/24/2012 17:36:53;0040;PBS_Server;Svr;tyrone-cluster;Scheduler was sent the command new
12/24/2012 17:37:23;0040;PBS_Server;Svr;tyrone-cluster;Scheduler was sent the command new
12/24/2012 17:37:53;0040;PBS_Server;Svr;tyrone-cluster;Scheduler was sent the command new
12/24/2012 17:38:23;0040;PBS_Server;Svr;tyrone-cluster;Scheduler was sent the command new
12/24/2012 17:38:53;0040;PBS_Server;Svr;tyrone-cluster;Scheduler was sent the command new
12/24/2012 17:39:23;0040;PBS_Server;Svr;tyrone-cluster;Scheduler was sent the command new
12/24/2012 17:39:53;0040;PBS_Server;Svr;tyrone-cluster;Scheduler was sent the command new
12/24/2012 17:40:11;0002;PBS_Server;Svr;PBS_Server;Torque Server Version = 3.0.5, loglevel = 0
12/24/2012 17:40:23;0040;PBS_Server;Svr;tyrone-cluster;Scheduler was sent the command new
12/24/2012 17:40:53;0040;PBS_Server;Svr;tyrone-cluster;Scheduler was sent the command new
12/24/2012 17:41:23;0040;PBS_Server;Svr;tyrone-cluster;Scheduler was sent the command new
12/24/2012 17:41:53;0040;PBS_Server;Svr;tyrone-cluster;Scheduler was sent the command new
12/24/2012 17:42:23;0040;PBS_Server;Svr;tyrone-cluster;Scheduler was sent the command new
12/24/2012 17:42:53;0040;PBS_Server;Svr;tyrone-cluster;Scheduler was sent the command new
12/24/2012 17:43:23;0040;PBS_Server;Svr;tyrone-cluster;Scheduler was sent the command new
12/24/2012 17:43:53;0040;PBS_Server;Svr;tyrone-cluster;Scheduler was sent the command new
12/24/2012 17:44:23;0040;PBS_Server;Svr;tyrone-cluster;Scheduler was sent the command new
12/24/2012 17:44:53;0040;PBS_Server;Svr;tyrone-cluster;Scheduler was sent the command new
12/24/2012 17:45:11;0002;PBS_Server;Svr;PBS_Server;Torque Server Version = 3.0.5, loglevel = 0
12/24/2012 17:45:23;0040;PBS_Server;Svr;tyrone-cluster;Scheduler was sent the command new
12/24/2012 17:45:53;0040;PBS_Server;Svr;tyrone-cluster;Scheduler was sent the command new
12/24/2012 17:46:23;0040;PBS_Server;Svr;tyrone-cluster;Scheduler was sent the command new
12/24/2012 17:46:53;0040;PBS_Server;Svr;tyrone-cluster;Scheduler was sent the command new
12/24/2012 17:47:23;0040;PBS_Server;Svr;tyrone-cluster;Scheduler was sent the command new
12/24/2012 17:47:53;0040;PBS_Server;Svr;tyrone-cluster;Scheduler was sent the command new
12/24/2012 17:48:23;0040;PBS_Server;Svr;tyrone-cluster;Scheduler was sent the command new
12/24/2012 17:48:53;0040;PBS_Server;Svr;tyrone-cluster;Scheduler was sent the command new
12/24/2012 17:49:23;0040;PBS_Server;Svr;tyrone-cluster;Scheduler was sent the command new
12/24/2012 17:49:53;0040;PBS_Server;Svr;tyrone-cluster;Scheduler was sent the command new
12/24/2012 17:50:11;0002;PBS_Server;Svr;PBS_Server;Torque Server Version = 3.0.5, loglevel = 0
12/24/2012 17:50:23;0040;PBS_Server;Svr;tyrone-cluster;Scheduler was sent the command new
12/24/2012 17:50:53;0040;PBS_Server;Svr;tyrone-cluster;Scheduler was sent the command new
12/24/2012 17:51:23;0040;PBS_Server;Svr;tyrone-cluster;Scheduler was sent the command new
12/24/2012 17:51:53;0040;PBS_Server;Svr;tyrone-cluster;Scheduler was sent the command new
12/24/2012 17:52:23;0040;PBS_Server;Svr;tyrone-cluster;Scheduler was sent the command new
12/24/2012 17:52:53;0040;PBS_Server;Svr;tyrone-cluster;Scheduler was sent the command new
12/24/2012 17:53:23;0040;PBS_Server;Svr;tyrone-cluster;Scheduler was sent the command new
12/24/2012 17:53:53;0040;PBS_Server;Svr;tyrone-cluster;Scheduler was sent the command new
12/24/2012 17:54:23;0040;PBS_Server;Svr;tyrone-cluster;Scheduler was sent the command new
12/24/2012 17:54:53;0040;PBS_Server;Svr;tyrone-cluster;Scheduler was sent the command new
12/24/2012 17:55:11;0002;PBS_Server;Svr;PBS_Server;Torque Server Version = 3.0.5, loglevel = 0
12/24/2012 17:55:23;0040;PBS_Server;Svr;tyrone-cluster;Scheduler was sent the command new
12/24/2012 17:55:53;0040;PBS_Server;Svr;tyrone-cluster;Scheduler was sent the command new
12/24/2012 17:56:23;0040;PBS_Server;Svr;tyrone-cluster;Scheduler was sent the command new
12/24/2012 17:56:53;0040;PBS_Server;Svr;tyrone-cluster;Scheduler was sent the command new
12/24/2012 17:57:23;0040;PBS_Server;Svr;tyrone-cluster;Scheduler was sent the command new
12/24/2012 17:57:51;000d;PBS_Server;Job;17551.tyrone-cluster;Not sending email: User does not want mail of this type.
12/24/2012 17:57:51;0010;PBS_Server;Job;17551.tyrone-cluster;Exit_status=143 resources_used.cput=50:25:12 resources_used.mem=16071000kb resources_used.vmem=20783992kb resources_used.walltime=02:00:15
12/24/2012 17:57:51;0008;PBS_Server;Job;NULL;on_job_exit valid pjob: 0x1bb6ca0 (substate=50)
12/24/2012 17:57:51;0008;PBS_Server;Job;NULL;on_job_exit valid pjob: 0x1bb6ca0 (substate=51)
12/24/2012 17:57:51;0008;PBS_Server;Job;NULL;on_job_exit valid pjob: 0x1bb6ca0 (substate=51)
12/24/2012 17:57:51;0008;PBS_Server;Job;NULL;on_job_exit valid pjob: 0x1bb6ca0 (substate=53)
12/24/2012 17:57:51;0100;PBS_Server;Job;17551.tyrone-cluster;dequeuing from idqueue, state COMPLETE
12/24/2012 17:57:51;0040;PBS_Server;Svr;tyrone-cluster;Scheduler was sent the command term
12/24/2012 17:57:53;0040;PBS_Server;Svr;tyrone-cluster;Scheduler was sent the command new
12/24/2012 17:58:23;0040;PBS_Server;Svr;tyrone-cluster;Scheduler was sent the command new
12/24/2012 17:58:53;0040;PBS_Server;Svr;tyrone-cluster;Scheduler was sent the command new
12/24/2012 17:59:23;0040;PBS_Server;Svr;tyrone-cluster;Scheduler was sent the command new
12/24/2012 17:59:53;0040;PBS_Server;Svr;tyrone-cluster;Scheduler was sent the command new
12/24/2012 18:00:11;0002;PBS_Server;Svr;PBS_Server;Torque Server Version = 3.0.5, loglevel = 0
12/24/2012 18:00:23;0040;PBS_Server;Svr;tyrone-cluster;Scheduler was sent the command new
12/24/2012 18:00:53;0040;PBS_Server;Svr;tyrone-cluster;Scheduler was sent the command new
12/24/2012 18:01:23;0040;PBS_Server;Svr;tyrone-cluster;Scheduler was sent the command new
12/24/2012 18:01:53;0040;PBS_Server;Svr;tyrone-cluster;Scheduler was sent the command new
12/24/2012 18:02:23;0040;PBS_Server;Svr;tyrone-cluster;Scheduler was sent the command new
12/24/2012 18:02:53;0040;PBS_Server;Svr;tyrone-cluster;Scheduler was sent the command new
12/24/2012 18:03:23;0040;PBS_Server;Svr;tyrone-cluster;Scheduler was sent the command new
12/24/2012 18:03:53;0040;PBS_Server;Svr;tyrone-cluster;Scheduler was sent the command new
12/24/2012 18:04:23;0040;PBS_Server;Svr;tyrone-cluster;Scheduler was sent the command new
12/24/2012 18:04:53;0040;PBS_Server;Svr;tyrone-cluster;Scheduler was sent the command new
12/24/2012 18:05:11;0002;PBS_Server;Svr;PBS_Server;Torque Server Version = 3.0.5, loglevel = 0
12/24/2012 18:05:23;0040;PBS_Server;Svr;tyrone-cluster;Scheduler was sent the command new
12/24/2012 18:05:53;0040;PBS_Server;Svr;tyrone-cluster;Scheduler was sent the command new
12/24/2012 18:06:23;0040;PBS_Server;Svr;tyrone-cluster;Scheduler was sent the command new
12/24/2012 18:06:53;0040;PBS_Server;Svr;tyrone-cluster;Scheduler was sent the command new
12/24/2012 18:07:23;0040;PBS_Server;Svr;tyrone-cluster;Scheduler was sent the command new
12/24/2012 18:07:53;0040;PBS_Server;Svr;tyrone-cluster;Scheduler was sent the command new
12/24/2012 18:08:23;0040;PBS_Server;Svr;tyrone-cluster;Scheduler was sent the command new
12/24/2012 18:08:53;0040;PBS_Server;Svr;tyrone-cluster;Scheduler was sent the command new
12/24/2012 18:09:23;0040;PBS_Server;Svr;tyrone-cluster;Scheduler was sent the command new
12/24/2012 18:09:53;0040;PBS_Server;Svr;tyrone-cluster;Scheduler was sent the command new
12/24/2012 18:10:11;0002;PBS_Server;Svr;PBS_Server;Torque Server Version = 3.0.5, loglevel = 0
12/24/2012 18:10:23;0040;PBS_Server;Svr;tyrone-cluster;Scheduler was sent the command new
12/24/2012 18:10:53;0040;PBS_Server;Svr;tyrone-cluster;Scheduler was sent the command new
12/24/2012 18:11:23;0040;PBS_Server;Svr;tyrone-cluster;Scheduler was sent the command new
12/24/2012 18:11:53;0040;PBS_Server;Svr;tyrone-cluster;Scheduler was sent the command new
12/24/2012 18:12:23;0040;PBS_Server;Svr;tyrone-cluster;Scheduler was sent the command new
12/24/2012 18:12:53;0040;PBS_Server;Svr;tyrone-cluster;Scheduler was sent the command new
12/24/2012 18:13:23;0040;PBS_Server;Svr;tyrone-cluster;Scheduler was sent the command new
12/24/2012 18:13:53;0040;PBS_Server;Svr;tyrone-cluster;Scheduler was sent the command new
12/24/2012 18:14:23;0040;PBS_Server;Svr;tyrone-cluster;Scheduler was sent the command new
12/24/2012 18:14:53;0040;PBS_Server;Svr;tyrone-cluster;Scheduler was sent the command new
12/24/2012 18:15:11;0002;PBS_Server;Svr;PBS_Server;Torque Server Version = 3.0.5, loglevel = 0
12/24/2012 18:15:23;0040;PBS_Server;Svr;tyrone-cluster;Scheduler was sent the command new
12/24/2012 18:15:53;0040;PBS_Server;Svr;tyrone-cluster;Scheduler was sent the command new
12/24/2012 18:16:23;0040;PBS_Server;Svr;tyrone-cluster;Scheduler was sent the command new
12/24/2012 18:16:53;0040;PBS_Server;Svr;tyrone-cluster;Scheduler was sent the command new
12/24/2012 18:17:23;0040;PBS_Server;Svr;tyrone-cluster;Scheduler was sent the command new
12/24/2012 18:17:53;0040;PBS_Server;Svr;tyrone-cluster;Scheduler was sent the command new
12/24/2012 18:18:23;0040;PBS_Server;Svr;tyrone-cluster;Scheduler was sent the command new
12/24/2012 18:18:53;0040;PBS_Server;Svr;tyrone-cluster;Scheduler was sent the command new
12/24/2012 18:19:23;0040;PBS_Server;Svr;tyrone-cluster;Scheduler was sent the command new
12/24/2012 18:19:53;0040;PBS_Server;Svr;tyrone-cluster;Scheduler was sent the command new
12/24/2012 18:20:11;0002;PBS_Server;Svr;PBS_Server;Torque Server Version = 3.0.5, loglevel = 0
12/24/2012 18:20:23;0040;PBS_Server;Svr;tyrone-cluster;Scheduler was sent the command new
12/24/2012 18:20:55;0040;PBS_Server;Svr;tyrone-cluster;Scheduler was sent the command new
12/24/2012 18:21:23;0040;PBS_Server;Svr;tyrone-cluster;Scheduler was sent the command new
12/24/2012 18:21:53;0040;PBS_Server;Svr;tyrone-cluster;Scheduler was sent the command new
12/24/2012 18:22:23;0040;PBS_Server;Svr;tyrone-cluster;Scheduler was sent the command new
12/24/2012 18:22:53;0040;PBS_Server;Svr;tyrone-cluster;Scheduler was sent the command new
12/24/2012 18:23:23;0040;PBS_Server;Svr;tyrone-cluster;Scheduler was sent the command new
12/24/2012 18:23:53;0040;PBS_Server;Svr;tyrone-cluster;Scheduler was sent the command new
12/24/2012 18:24:23;0040;PBS_Server;Svr;tyrone-cluster;Scheduler was sent the command new
12/24/2012 18:24:53;0040;PBS_Server;Svr;tyrone-cluster;Scheduler was sent the command new
12/24/2012 18:25:11;0002;PBS_Server;Svr;PBS_Server;Torque Server Version = 3.0.5, loglevel = 0
12/24/2012 18:25:23;0040;PBS_Server;Svr;tyrone-cluster;Scheduler was sent the command new
12/24/2012 18:25:53;0040;PBS_Server;Svr;tyrone-cluster;Scheduler was sent the command new
12/24/2012 18:26:23;0040;PBS_Server;Svr;tyrone-cluster;Scheduler was sent the command new
12/24/2012 18:26:53;0040;PBS_Server;Svr;tyrone-cluster;Scheduler was sent the command new
12/24/2012 18:27:23;0040;PBS_Server;Svr;tyrone-cluster;Scheduler was sent the command new
12/24/2012 18:27:53;0040;PBS_Server;Svr;tyrone-cluster;Scheduler was sent the command new
12/24/2012 18:28:23;0040;PBS_Server;Svr;tyrone-cluster;Scheduler was sent the command new
12/24/2012 18:28:53;0040;PBS_Server;Svr;tyrone-cluster;Scheduler was sent the command new
12/24/2012 18:29:23;0040;PBS_Server;Svr;tyrone-cluster;Scheduler was sent the command new
12/24/2012 18:29:53;0040;PBS_Server;Svr;tyrone-cluster;Scheduler was sent the command new
12/24/2012 18:30:11;0002;PBS_Server;Svr;PBS_Server;Torque Server Version = 3.0.5, loglevel = 0
12/24/2012 18:30:23;0040;PBS_Server;Svr;tyrone-cluster;Scheduler was sent the command new
12/24/2012 18:30:53;0040;PBS_Server;Svr;tyrone-cluster;Scheduler was sent the command new
12/24/2012 18:31:23;0040;PBS_Server;Svr;tyrone-cluster;Scheduler was sent the command new
12/24/2012 18:31:53;0040;PBS_Server;Svr;tyrone-cluster;Scheduler was sent the command new
12/24/2012 18:32:23;0040;PBS_Server;Svr;tyrone-cluster;Scheduler was sent the command new
12/24/2012 18:32:53;0040;PBS_Server;Svr;tyrone-cluster;Scheduler was sent the command new
12/24/2012 18:33:23;0040;PBS_Server;Svr;tyrone-cluster;Scheduler was sent the command new
12/24/2012 18:33:53;0040;PBS_Server;Svr;tyrone-cluster;Scheduler was sent the command new
12/24/2012 18:34:23;0040;PBS_Server;Svr;tyrone-cluster;Scheduler was sent the command new
12/24/2012 18:34:53;0040;PBS_Server;Svr;tyrone-cluster;Scheduler was sent the command new
12/24/2012 18:35:11;0002;PBS_Server;Svr;PBS_Server;Torque Server Version = 3.0.5, loglevel = 0
12/24/2012 18:35:23;0040;PBS_Server;Svr;tyrone-cluster;Scheduler was sent the command new
12/24/2012 18:35:53;0040;PBS_Server;Svr;tyrone-cluster;Scheduler was sent the command new
12/24/2012 18:36:23;0040;PBS_Server;Svr;tyrone-cluster;Scheduler was sent the command new
12/24/2012 18:36:45;000d;PBS_Server;Job;17554.tyrone-cluster;Not sending email: User does not want mail of this type.
12/24/2012 18:36:45;0010;PBS_Server;Job;17554.tyrone-cluster;Exit_status=143 resources_used.cput=09:38:05 resources_used.mem=635032kb resources_used.vmem=1511336kb resources_used.walltime=02:00:39
12/24/2012 18:36:45;0008;PBS_Server;Job;NULL;on_job_exit valid pjob: 0x1b6a310 (substate=50)
12/24/2012 18:36:45;0008;PBS_Server;Job;NULL;on_job_exit valid pjob: 0x1b6a310 (substate=51)
12/24/2012 18:36:45;0008;PBS_Server;Job;NULL;on_job_exit valid pjob: 0x1b6a310 (substate=51)
12/24/2012 18:36:45;0008;PBS_Server;Job;NULL;on_job_exit valid pjob: 0x1b6a310 (substate=53)
12/24/2012 18:36:45;0100;PBS_Server;Job;17554.tyrone-cluster;dequeuing from idqueue, state COMPLETE
12/24/2012 18:36:45;0040;PBS_Server;Svr;tyrone-cluster;Scheduler was sent the command term
12/24/2012 18:36:53;0040;PBS_Server;Svr;tyrone-cluster;Scheduler was sent the command new
12/24/2012 18:37:24;0040;PBS_Server;Svr;tyrone-cluster;Scheduler was sent the command new
12/24/2012 18:37:55;0040;PBS_Server;Svr;tyrone-cluster;Scheduler was sent the command new
12/24/2012 18:38:27;0040;PBS_Server;Svr;tyrone-cluster;Scheduler was sent the command new
12/24/2012 18:38:58;0040;PBS_Server;Svr;tyrone-cluster;Scheduler was sent the command new
12/24/2012 18:39:37;0040;PBS_Server;Svr;tyrone-cluster;Scheduler was sent the command new
12/24/2012 18:40:08;0040;PBS_Server;Svr;tyrone-cluster;Scheduler was sent the command new
12/24/2012 18:40:11;0002;PBS_Server;Svr;PBS_Server;Torque Server Version = 3.0.5, loglevel = 0
12/24/2012 18:40:38;0040;PBS_Server;Svr;tyrone-cluster;Scheduler was sent the command new
12/24/2012 18:41:07;0040;PBS_Server;Svr;tyrone-cluster;Scheduler was sent the command new
12/24/2012 18:41:38;0040;PBS_Server;Svr;tyrone-cluster;Scheduler was sent the command new
12/24/2012 18:42:08;0040;PBS_Server;Svr;tyrone-cluster;Scheduler was sent the command new
12/24/2012 18:42:37;0040;PBS_Server;Svr;tyrone-cluster;Scheduler was sent the command new
12/24/2012 18:43:08;0040;PBS_Server;Svr;tyrone-cluster;Scheduler was sent the command new
12/24/2012 18:43:38;0040;PBS_Server;Svr;tyrone-cluster;Scheduler was sent the command new
12/24/2012 18:44:07;0040;PBS_Server;Svr;tyrone-cluster;Scheduler was sent the command new
12/24/2012 18:44:33;0100;PBS_Server;Job;17556.tyrone-cluster;enqueuing into batch, state 1 hop 1
12/24/2012 18:44:33;0100;PBS_Server;Job;17556.tyrone-cluster;dequeuing from batch, state QUEUED
12/24/2012 18:44:33;0100;PBS_Server;Job;17556.tyrone-cluster;enqueuing into idqueue, state 1 hop 1
12/24/2012 18:44:33;0008;PBS_Server;Job;17556.tyrone-cluster;Job Queued at request of ipcvrk@tyrone-cluster, owner = ipcvrk@tyrone-cluster, job name = pq14.cmd, queue = idqueue
12/24/2012 18:44:33;0040;PBS_Server;Svr;tyrone-cluster;Scheduler was sent the command new
12/24/2012 18:44:33;0008;PBS_Server;Job;17556.tyrone-cluster;Job Modified at request of Scheduler@tyrone-cluster
12/24/2012 18:44:33;0008;PBS_Server;Job;17556.tyrone-cluster;Job Run at request of Scheduler@tyrone-cluster
12/24/2012 18:44:33;0040;PBS_Server;Svr;tyrone-cluster;Scheduler was sent the command recyc
12/24/2012 18:44:33;000d;PBS_Server;Job;17556.tyrone-cluster;Not sending email: User does not want mail of this type.
12/24/2012 18:44:38;0040;PBS_Server;Svr;tyrone-cluster;Scheduler was sent the command new
12/24/2012 18:45:08;0040;PBS_Server;Svr;tyrone-cluster;Scheduler was sent the command new
12/24/2012 18:45:11;0002;PBS_Server;Svr;PBS_Server;Torque Server Version = 3.0.5, loglevel = 0
12/24/2012 18:45:37;0040;PBS_Server;Svr;tyrone-cluster;Scheduler was sent the command new
12/24/2012 18:46:08;0040;PBS_Server;Svr;tyrone-cluster;Scheduler was sent the command new
12/24/2012 18:46:38;0040;PBS_Server;Svr;tyrone-cluster;Scheduler was sent the command new
12/24/2012 18:47:07;0040;PBS_Server;Svr;tyrone-cluster;Scheduler was sent the command new
12/24/2012 18:47:38;0040;PBS_Server;Svr;tyrone-cluster;Scheduler was sent the command new
12/24/2012 18:48:08;0040;PBS_Server;Svr;tyrone-cluster;Scheduler was sent the command new
12/24/2012 18:48:37;0040;PBS_Server;Svr;tyrone-cluster;Scheduler was sent the command new
12/24/2012 18:49:08;0040;PBS_Server;Svr;tyrone-cluster;Scheduler was sent the command new
12/24/2012 18:49:27;000d;PBS_Server;Job;17555.tyrone-cluster;Not sending email: User does not want mail of this type.
12/24/2012 18:49:27;0010;PBS_Server;Job;17555.tyrone-cluster;Exit_status=0 resources_used.cput=29:32:44 resources_used.mem=4216332kb resources_used.vmem=8189692kb resources_used.walltime=01:21:49
12/24/2012 18:49:27;0008;PBS_Server;Job;NULL;on_job_exit valid pjob: 0x1b92e60 (substate=50)
12/24/2012 18:49:27;0008;PBS_Server;Job;NULL;on_job_exit valid pjob: 0x1b92e60 (substate=51)
12/24/2012 18:49:27;0008;PBS_Server;Job;NULL;on_job_exit valid pjob: 0x1b92e60 (substate=51)
12/24/2012 18:49:27;0008;PBS_Server;Job;NULL;on_job_exit valid pjob: 0x1b92e60 (substate=53)
12/24/2012 18:49:27;0100;PBS_Server;Job;17555.tyrone-cluster;dequeuing from idqueue, state COMPLETE
12/24/2012 18:49:27;0040;PBS_Server;Svr;tyrone-cluster;Scheduler was sent the command term
12/24/2012 18:49:38;0040;PBS_Server;Svr;tyrone-cluster;Scheduler was sent the command new
12/24/2012 18:50:07;0040;PBS_Server;Svr;tyrone-cluster;Scheduler was sent the command new
12/24/2012 18:50:11;0002;PBS_Server;Svr;PBS_Server;Torque Server Version = 3.0.5, loglevel = 0
12/24/2012 18:50:38;0040;PBS_Server;Svr;tyrone-cluster;Scheduler was sent the command new
12/24/2012 18:51:08;0040;PBS_Server;Svr;tyrone-cluster;Scheduler was sent the command new
12/24/2012 18:51:37;0040;PBS_Server;Svr;tyrone-cluster;Scheduler was sent the command new
12/24/2012 18:52:08;0040;PBS_Server;Svr;tyrone-cluster;Scheduler was sent the command new
12/24/2012 18:52:38;0040;PBS_Server;Svr;tyrone-cluster;Scheduler was sent the command new
12/24/2012 18:53:09;0040;PBS_Server;Svr;tyrone-cluster;Scheduler was sent the command new
12/24/2012 18:53:38;0040;PBS_Server;Svr;tyrone-cluster;Scheduler was sent the command new
12/24/2012 18:54:08;0040;PBS_Server;Svr;tyrone-cluster;Scheduler was sent the command new
12/24/2012 18:54:39;0040;PBS_Server;Svr;tyrone-cluster;Scheduler was sent the command new
12/24/2012 18:55:08;0040;PBS_Server;Svr;tyrone-cluster;Scheduler was sent the command new
12/24/2012 18:55:11;0002;PBS_Server;Svr;PBS_Server;Torque Server Version = 3.0.5, loglevel = 0
12/24/2012 18:55:38;0040;PBS_Server;Svr;tyrone-cluster;Scheduler was sent the command new
12/24/2012 18:56:08;0040;PBS_Server;Svr;tyrone-cluster;Scheduler was sent the command new
12/24/2012 18:56:38;0040;PBS_Server;Svr;tyrone-cluster;Scheduler was sent the command new
12/24/2012 18:57:08;0040;PBS_Server;Svr;tyrone-cluster;Scheduler was sent the command new
12/24/2012 18:57:38;0040;PBS_Server;Svr;tyrone-cluster;Scheduler was sent the command new
12/24/2012 18:58:08;0040;PBS_Server;Svr;tyrone-cluster;Scheduler was sent the command new
12/24/2012 18:58:38;0040;PBS_Server;Svr;tyrone-cluster;Scheduler was sent the command new
12/24/2012 18:59:09;0040;PBS_Server;Svr;tyrone-cluster;Scheduler was sent the command new
12/24/2012 18:59:40;0040;PBS_Server;Svr;tyrone-cluster;Scheduler was sent the command new
12/24/2012 19:00:11;0002;PBS_Server;Svr;PBS_Server;Torque Server Version = 3.0.5, loglevel = 0
12/24/2012 19:00:11;0040;PBS_Server;Svr;tyrone-cluster;Scheduler was sent the command new
12/24/2012 19:00:43;0040;PBS_Server;Svr;tyrone-cluster;Scheduler was sent the command new
12/24/2012 19:01:22;0040;PBS_Server;Svr;tyrone-cluster;Scheduler was sent the command new
12/24/2012 19:01:53;0040;PBS_Server;Svr;tyrone-cluster;Scheduler was sent the command new
12/24/2012 19:02:23;0040;PBS_Server;Svr;tyrone-cluster;Scheduler was sent the command new
12/24/2012 19:02:52;0040;PBS_Server;Svr;tyrone-cluster;Scheduler was sent the command new
12/24/2012 19:03:23;0040;PBS_Server;Svr;tyrone-cluster;Scheduler was sent the command new
12/24/2012 19:03:53;0040;PBS_Server;Svr;tyrone-cluster;Scheduler was sent the command new
12/24/2012 19:04:22;0040;PBS_Server;Svr;tyrone-cluster;Scheduler was sent the command new
12/24/2012 19:04:53;0040;PBS_Server;Svr;tyrone-cluster;Scheduler was sent the command new
12/24/2012 19:05:11;0002;PBS_Server;Svr;PBS_Server;Torque Server Version = 3.0.5, loglevel = 0
12/24/2012 19:05:23;0040;PBS_Server;Svr;tyrone-cluster;Scheduler was sent the command new
12/24/2012 19:05:54;0040;PBS_Server;Svr;tyrone-cluster;Scheduler was sent the command new
12/24/2012 19:06:23;0040;PBS_Server;Svr;tyrone-cluster;Scheduler was sent the command new
12/24/2012 19:06:53;0040;PBS_Server;Svr;tyrone-cluster;Scheduler was sent the command new
12/24/2012 19:07:24;0040;PBS_Server;Svr;tyrone-cluster;Scheduler was sent the command new
12/24/2012 19:07:53;0040;PBS_Server;Svr;tyrone-cluster;Scheduler was sent the command new
12/24/2012 19:08:23;0040;PBS_Server;Svr;tyrone-cluster;Scheduler was sent the command new
12/24/2012 19:08:54;0040;PBS_Server;Svr;tyrone-cluster;Scheduler was sent the command new
12/24/2012 19:09:24;0040;PBS_Server;Svr;tyrone-cluster;Scheduler was sent the command new
12/24/2012 19:09:24;0100;PBS_Server;Job;17557.tyrone-cluster;enqueuing into batch, state 1 hop 1
12/24/2012 19:09:24;0100;PBS_Server;Job;17557.tyrone-cluster;dequeuing from batch, state QUEUED
12/24/2012 19:09:24;0100;PBS_Server;Job;17557.tyrone-cluster;enqueuing into idqueue, state 1 hop 1
12/24/2012 19:09:24;0008;PBS_Server;Job;17557.tyrone-cluster;Job Queued at request of ipcvrk@tyrone-cluster, owner = ipcvrk@tyrone-cluster, job name = pq.cmd, queue = idqueue
12/24/2012 19:09:24;0008;PBS_Server;Job;17557.tyrone-cluster;Job Modified at request of Scheduler@tyrone-cluster
12/24/2012 19:09:24;0008;PBS_Server;Job;17557.tyrone-cluster;Job Run at request of Scheduler@tyrone-cluster
12/24/2012 19:09:24;0040;PBS_Server;Svr;tyrone-cluster;Scheduler was sent the command recyc
12/24/2012 19:09:24;000d;PBS_Server;Job;17557.tyrone-cluster;Not sending email: User does not want mail of this type.
12/24/2012 19:09:28;000d;PBS_Server;Job;17557.tyrone-cluster;Not sending email: User does not want mail of this type.
12/24/2012 19:09:28;0010;PBS_Server;Job;17557.tyrone-cluster;Exit_status=1 resources_used.cput=00:00:00 resources_used.mem=0kb resources_used.vmem=0kb resources_used.walltime=00:00:04
12/24/2012 19:09:28;0008;PBS_Server;Job;NULL;on_job_exit valid pjob: 0x1b92e60 (substate=50)
12/24/2012 19:09:28;0008;PBS_Server;Job;NULL;on_job_exit valid pjob: 0x1b92e60 (substate=51)
12/24/2012 19:09:28;0008;PBS_Server;Job;NULL;on_job_exit valid pjob: 0x1b92e60 (substate=51)
12/24/2012 19:09:28;0008;PBS_Server;Job;NULL;on_job_exit valid pjob: 0x1b92e60 (substate=53)
12/24/2012 19:09:28;0100;PBS_Server;Job;17557.tyrone-cluster;dequeuing from idqueue, state COMPLETE
12/24/2012 19:09:28;0040;PBS_Server;Svr;tyrone-cluster;Scheduler was sent the command term
12/24/2012 19:09:33;0080;PBS_Server;Job;17557.tyrone-cluster;Unknown Job Id
12/24/2012 19:09:33;0080;PBS_Server;Req;req_reject;Reject reply code=15001(Unknown Job Id), aux=0, type=DeleteJob, from ipcvrk@tyrone-cluster
12/24/2012 19:09:33;0080;PBS_Server;Req;req_reject;Reject reply code=15001(Unknown Job Id), aux=0, type=LocateJob, from ipcvrk@tyrone-cluster
12/24/2012 19:09:57;0040;PBS_Server;Svr;tyrone-cluster;Scheduler was sent the command new
12/24/2012 19:10:11;0002;PBS_Server;Svr;PBS_Server;Torque Server Version = 3.0.5, loglevel = 0
12/24/2012 19:10:28;0040;PBS_Server;Svr;tyrone-cluster;Scheduler was sent the command new
12/24/2012 19:11:07;0040;PBS_Server;Svr;tyrone-cluster;Scheduler was sent the command new
12/24/2012 19:11:38;0040;PBS_Server;Svr;tyrone-cluster;Scheduler was sent the command new
12/24/2012 19:12:08;0040;PBS_Server;Svr;tyrone-cluster;Scheduler was sent the command new
12/24/2012 19:12:37;0040;PBS_Server;Svr;tyrone-cluster;Scheduler was sent the command new
12/24/2012 19:12:59;0100;PBS_Server;Job;17558.tyrone-cluster;enqueuing into batch, state 1 hop 1
12/24/2012 19:12:59;0100;PBS_Server;Job;17558.tyrone-cluster;dequeuing from batch, state QUEUED
12/24/2012 19:12:59;0100;PBS_Server;Job;17558.tyrone-cluster;enqueuing into idqueue, state 1 hop 1
12/24/2012 19:12:59;0008;PBS_Server;Job;17558.tyrone-cluster;Job Queued at request of ipcvrk@tyrone-cluster, owner = ipcvrk@tyrone-cluster, job name = pq.cmd, queue = idqueue
12/24/2012 19:12:59;0040;PBS_Server;Svr;tyrone-cluster;Scheduler was sent the command new
12/24/2012 19:12:59;0008;PBS_Server;Job;17558.tyrone-cluster;Job Modified at request of Scheduler@tyrone-cluster
12/24/2012 19:12:59;0008;PBS_Server;Job;17558.tyrone-cluster;Job Run at request of Scheduler@tyrone-cluster
12/24/2012 19:12:59;0040;PBS_Server;Svr;tyrone-cluster;Scheduler was sent the command recyc
12/24/2012 19:12:59;000d;PBS_Server;Job;17558.tyrone-cluster;Not sending email: User does not want mail of this type.
12/24/2012 19:13:02;000d;PBS_Server;Job;17558.tyrone-cluster;Not sending email: User does not want mail of this type.
12/24/2012 19:13:02;0010;PBS_Server;Job;17558.tyrone-cluster;Exit_status=1 resources_used.cput=00:00:00 resources_used.mem=0kb resources_used.vmem=0kb resources_used.walltime=00:00:03
12/24/2012 19:13:02;0008;PBS_Server;Job;NULL;on_job_exit valid pjob: 0x1b92e60 (substate=50)
12/24/2012 19:13:02;0008;PBS_Server;Job;NULL;on_job_exit valid pjob: 0x1b92e60 (substate=51)
12/24/2012 19:13:02;0008;PBS_Server;Job;NULL;on_job_exit valid pjob: 0x1b92e60 (substate=51)
12/24/2012 19:13:02;0008;PBS_Server;Job;NULL;on_job_exit valid pjob: 0x1b92e60 (substate=53)
12/24/2012 19:13:02;0100;PBS_Server;Job;17558.tyrone-cluster;dequeuing from idqueue, state COMPLETE
12/24/2012 19:13:02;0040;PBS_Server;Svr;tyrone-cluster;Scheduler was sent the command term
12/24/2012 19:13:08;0040;PBS_Server;Svr;tyrone-cluster;Scheduler was sent the command new
12/24/2012 19:13:38;0040;PBS_Server;Svr;tyrone-cluster;Scheduler was sent the command new
12/24/2012 19:14:08;0040;PBS_Server;Svr;tyrone-cluster;Scheduler was sent the command new
12/24/2012 19:14:38;0040;PBS_Server;Svr;tyrone-cluster;Scheduler was sent the command new
12/24/2012 19:15:08;0040;PBS_Server;Svr;tyrone-cluster;Scheduler was sent the command new
12/24/2012 19:15:11;0002;PBS_Server;Svr;PBS_Server;Torque Server Version = 3.0.5, loglevel = 0
12/24/2012 19:15:39;0040;PBS_Server;Svr;tyrone-cluster;Scheduler was sent the command new
12/24/2012 19:16:08;0040;PBS_Server;Svr;tyrone-cluster;Scheduler was sent the command new
12/24/2012 19:16:38;0040;PBS_Server;Svr;tyrone-cluster;Scheduler was sent the command new
12/24/2012 19:17:09;0040;PBS_Server;Svr;tyrone-cluster;Scheduler was sent the command new
12/24/2012 19:17:38;0040;PBS_Server;Svr;tyrone-cluster;Scheduler was sent the command new
12/24/2012 19:18:08;0040;PBS_Server;Svr;tyrone-cluster;Scheduler was sent the command new
12/24/2012 19:18:39;0040;PBS_Server;Svr;tyrone-cluster;Scheduler was sent the command new
12/24/2012 19:19:08;0040;PBS_Server;Svr;tyrone-cluster;Scheduler was sent the command new
12/24/2012 19:19:38;0040;PBS_Server;Svr;tyrone-cluster;Scheduler was sent the command new
12/24/2012 19:20:09;0040;PBS_Server;Svr;tyrone-cluster;Scheduler was sent the command new
12/24/2012 19:20:11;0002;PBS_Server;Svr;PBS_Server;Torque Server Version = 3.0.5, loglevel = 0
12/24/2012 19:20:40;0040;PBS_Server;Svr;tyrone-cluster;Scheduler was sent the command new
12/24/2012 19:21:12;0040;PBS_Server;Svr;tyrone-cluster;Scheduler was sent the command new
12/24/2012 19:21:43;0040;PBS_Server;Svr;tyrone-cluster;Scheduler was sent the command new
12/24/2012 19:22:22;0040;PBS_Server;Svr;tyrone-cluster;Scheduler was sent the command new
12/24/2012 19:22:53;0040;PBS_Server;Svr;tyrone-cluster;Scheduler was sent the command new
12/24/2012 19:23:23;0040;PBS_Server;Svr;tyrone-cluster;Scheduler was sent the command new
12/24/2012 19:23:52;0040;PBS_Server;Svr;tyrone-cluster;Scheduler was sent the command new
12/24/2012 19:24:23;0040;PBS_Server;Svr;tyrone-cluster;Scheduler was sent the command new
12/24/2012 19:24:53;0040;PBS_Server;Svr;tyrone-cluster;Scheduler was sent the command new
12/24/2012 19:25:11;0002;PBS_Server;Svr;PBS_Server;Torque Server Version = 3.0.5, loglevel = 0
12/24/2012 19:25:24;0040;PBS_Server;Svr;tyrone-cluster;Scheduler was sent the command new
12/24/2012 19:25:53;0040;PBS_Server;Svr;tyrone-cluster;Scheduler was sent the command new
12/24/2012 19:26:23;0040;PBS_Server;Svr;tyrone-cluster;Scheduler was sent the command new
12/24/2012 19:26:54;0040;PBS_Server;Svr;tyrone-cluster;Scheduler was sent the command new
12/24/2012 19:27:24;0040;PBS_Server;Svr;tyrone-cluster;Scheduler was sent the command new
12/24/2012 19:27:57;0040;PBS_Server;Svr;tyrone-cluster;Scheduler was sent the command new
12/24/2012 19:28:28;0040;PBS_Server;Svr;tyrone-cluster;Scheduler was sent the command new
12/24/2012 19:29:07;0040;PBS_Server;Svr;tyrone-cluster;Scheduler was sent the command new
12/24/2012 19:29:38;0040;PBS_Server;Svr;tyrone-cluster;Scheduler was sent the command new
12/24/2012 19:30:08;0040;PBS_Server;Svr;tyrone-cluster;Scheduler was sent the command new
12/24/2012 19:30:11;0002;PBS_Server;Svr;PBS_Server;Torque Server Version = 3.0.5, loglevel = 0
12/24/2012 19:30:37;0040;PBS_Server;Svr;tyrone-cluster;Scheduler was sent the command new
12/24/2012 19:31:08;0040;PBS_Server;Svr;tyrone-cluster;Scheduler was sent the command new
12/24/2012 19:31:38;0040;PBS_Server;Svr;tyrone-cluster;Scheduler was sent the command new
12/24/2012 19:32:09;0040;PBS_Server;Svr;tyrone-cluster;Scheduler was sent the command new
12/24/2012 19:32:38;0040;PBS_Server;Svr;tyrone-cluster;Scheduler was sent the command new
12/24/2012 19:33:08;0040;PBS_Server;Svr;tyrone-cluster;Scheduler was sent the command new
12/24/2012 19:33:39;0040;PBS_Server;Svr;tyrone-cluster;Scheduler was sent the command new
12/24/2012 19:34:08;0040;PBS_Server;Svr;tyrone-cluster;Scheduler was sent the command new
12/24/2012 19:34:38;0040;PBS_Server;Svr;tyrone-cluster;Scheduler was sent the command new
12/24/2012 19:35:08;0040;PBS_Server;Svr;tyrone-cluster;Scheduler was sent the command new
12/24/2012 19:35:11;0002;PBS_Server;Svr;PBS_Server;Torque Server Version = 3.0.5, loglevel = 0
12/24/2012 19:35:38;0040;PBS_Server;Svr;tyrone-cluster;Scheduler was sent the command new
12/24/2012 19:36:08;0040;PBS_Server;Svr;tyrone-cluster;Scheduler was sent the command new
12/24/2012 19:36:39;0040;PBS_Server;Svr;tyrone-cluster;Scheduler was sent the command new
12/24/2012 19:37:09;0040;PBS_Server;Svr;tyrone-cluster;Scheduler was sent the command new
12/24/2012 19:37:41;0040;PBS_Server;Svr;tyrone-cluster;Scheduler was sent the command new
12/24/2012 19:38:13;0040;PBS_Server;Svr;tyrone-cluster;Scheduler was sent the command new
12/24/2012 19:38:52;0040;PBS_Server;Svr;tyrone-cluster;Scheduler was sent the command new
12/24/2012 19:39:23;0040;PBS_Server;Svr;tyrone-cluster;Scheduler was sent the command new
12/24/2012 19:39:53;0040;PBS_Server;Svr;tyrone-cluster;Scheduler was sent the command new
12/24/2012 19:40:11;0002;PBS_Server;Svr;PBS_Server;Torque Server Version = 3.0.5, loglevel = 0
12/24/2012 19:40:22;0040;PBS_Server;Svr;tyrone-cluster;Scheduler was sent the command new
12/24/2012 19:40:53;0040;PBS_Server;Svr;tyrone-cluster;Scheduler was sent the command new
12/24/2012 19:41:23;0040;PBS_Server;Svr;tyrone-cluster;Scheduler was sent the command new
12/24/2012 19:41:54;0040;PBS_Server;Svr;tyrone-cluster;Scheduler was sent the command new
12/24/2012 19:42:23;0040;PBS_Server;Svr;tyrone-cluster;Scheduler was sent the command new
12/24/2012 19:42:53;0040;PBS_Server;Svr;tyrone-cluster;Scheduler was sent the command new
12/24/2012 19:43:23;0040;PBS_Server;Svr;tyrone-cluster;Scheduler was sent the command new
12/24/2012 19:43:53;0040;PBS_Server;Svr;tyrone-cluster;Scheduler was sent the command new
12/24/2012 19:44:23;0040;PBS_Server;Svr;tyrone-cluster;Scheduler was sent the command new
12/24/2012 19:44:54;0040;PBS_Server;Svr;tyrone-cluster;Scheduler was sent the command new
12/24/2012 19:45:11;0002;PBS_Server;Svr;PBS_Server;Torque Server Version = 3.0.5, loglevel = 0
12/24/2012 19:45:23;0040;PBS_Server;Svr;tyrone-cluster;Scheduler was sent the command new
12/24/2012 19:45:53;0040;PBS_Server;Svr;tyrone-cluster;Scheduler was sent the command new
12/24/2012 19:46:24;0040;PBS_Server;Svr;tyrone-cluster;Scheduler was sent the command new
12/24/2012 19:46:53;0040;PBS_Server;Svr;tyrone-cluster;Scheduler was sent the command new
12/24/2012 19:47:23;0040;PBS_Server;Svr;tyrone-cluster;Scheduler was sent the command new
12/24/2012 19:47:53;0040;PBS_Server;Svr;tyrone-cluster;Scheduler was sent the command new
12/24/2012 19:48:23;0040;PBS_Server;Svr;tyrone-cluster;Scheduler was sent the command new
12/24/2012 19:48:53;0040;PBS_Server;Svr;tyrone-cluster;Scheduler was sent the command new
12/24/2012 19:49:18;0100;PBS_Server;Job;17559.tyrone-cluster;enqueuing into batch, state 1 hop 1
12/24/2012 19:49:18;0100;PBS_Server;Job;17559.tyrone-cluster;dequeuing from batch, state QUEUED
12/24/2012 19:49:18;0100;PBS_Server;Job;17559.tyrone-cluster;enqueuing into idqueue, state 1 hop 1
12/24/2012 19:49:18;0008;PBS_Server;Job;17559.tyrone-cluster;Job Queued at request of ipcdskp@tyrone-cluster, owner = ipcdskp@tyrone-cluster, job name = n10, queue = idqueue
12/24/2012 19:49:18;0040;PBS_Server;Svr;tyrone-cluster;Scheduler was sent the command new
12/24/2012 19:49:18;0008;PBS_Server;Job;17559.tyrone-cluster;Job Modified at request of Scheduler@tyrone-cluster
12/24/2012 19:49:18;0008;PBS_Server;Job;17559.tyrone-cluster;Job Run at request of Scheduler@tyrone-cluster
12/24/2012 19:49:18;0040;PBS_Server;Svr;tyrone-cluster;Scheduler was sent the command recyc
12/24/2012 19:49:18;000d;PBS_Server;Job;17559.tyrone-cluster;Not sending email: User does not want mail of this type.
12/24/2012 19:49:24;0040;PBS_Server;Svr;tyrone-cluster;Scheduler was sent the command new
12/24/2012 19:49:53;0040;PBS_Server;Svr;tyrone-cluster;Scheduler was sent the command new
12/24/2012 19:50:11;0002;PBS_Server;Svr;PBS_Server;Torque Server Version = 3.0.5, loglevel = 0
12/24/2012 19:50:23;0040;PBS_Server;Svr;tyrone-cluster;Scheduler was sent the command new
12/24/2012 19:50:53;0040;PBS_Server;Svr;tyrone-cluster;Scheduler was sent the command new
12/24/2012 19:51:23;0040;PBS_Server;Svr;tyrone-cluster;Scheduler was sent the command new
12/24/2012 19:51:53;0040;PBS_Server;Svr;tyrone-cluster;Scheduler was sent the command new
12/24/2012 19:52:24;0040;PBS_Server;Svr;tyrone-cluster;Scheduler was sent the command new
12/24/2012 19:52:54;0040;PBS_Server;Svr;tyrone-cluster;Scheduler was sent the command new
12/24/2012 19:53:27;0040;PBS_Server;Svr;tyrone-cluster;Scheduler was sent the command new
12/24/2012 19:53:58;0040;PBS_Server;Svr;tyrone-cluster;Scheduler was sent the command new
12/24/2012 19:54:37;0040;PBS_Server;Svr;tyrone-cluster;Scheduler was sent the command new
12/24/2012 19:55:08;0040;PBS_Server;Svr;tyrone-cluster;Scheduler was sent the command new
12/24/2012 19:55:11;0002;PBS_Server;Svr;PBS_Server;Torque Server Version = 3.0.5, loglevel = 0
12/24/2012 19:55:38;0040;PBS_Server;Svr;tyrone-cluster;Scheduler was sent the command new
12/24/2012 19:56:08;0040;PBS_Server;Svr;tyrone-cluster;Scheduler was sent the command new
12/24/2012 19:56:38;0040;PBS_Server;Svr;tyrone-cluster;Scheduler was sent the command new
12/24/2012 19:57:08;0040;PBS_Server;Svr;tyrone-cluster;Scheduler was sent the command new
12/24/2012 19:57:39;0040;PBS_Server;Svr;tyrone-cluster;Scheduler was sent the command new
12/24/2012 19:58:09;0040;PBS_Server;Svr;tyrone-cluster;Scheduler was sent the command new
12/24/2012 19:58:42;0040;PBS_Server;Svr;tyrone-cluster;Scheduler was sent the command new
12/24/2012 19:59:13;0040;PBS_Server;Svr;tyrone-cluster;Scheduler was sent the command new
12/24/2012 19:59:52;0040;PBS_Server;Svr;tyrone-cluster;Scheduler was sent the command new
12/24/2012 20:00:03;000d;PBS_Server;Job;17495.tyrone-cluster;Not sending email: User does not want mail of this type.
12/24/2012 20:00:03;0010;PBS_Server;Job;17495.tyrone-cluster;Exit_status=143 resources_used.cput=758:20:24 resources_used.mem=17737296kb resources_used.vmem=21451080kb resources_used.walltime=24:00:45
12/24/2012 20:00:03;0008;PBS_Server;Job;NULL;on_job_exit valid pjob: 0x1ba6f70 (substate=50)
12/24/2012 20:00:03;0008;PBS_Server;Job;NULL;on_job_exit valid pjob: 0x1ba6f70 (substate=51)
12/24/2012 20:00:05;0008;PBS_Server;Job;NULL;on_job_exit valid pjob: 0x1ba6f70 (substate=51)
12/24/2012 20:00:05;0008;PBS_Server;Job;NULL;on_job_exit valid pjob: 0x1ba6f70 (substate=53)
12/24/2012 20:00:05;0100;PBS_Server;Job;17495.tyrone-cluster;dequeuing from qp256, state COMPLETE
12/24/2012 20:00:05;0040;PBS_Server;Svr;tyrone-cluster;Scheduler was sent the command term
12/24/2012 20:00:11;0002;PBS_Server;Svr;PBS_Server;Torque Server Version = 3.0.5, loglevel = 0
12/24/2012 20:00:23;0040;PBS_Server;Svr;tyrone-cluster;Scheduler was sent the command new
12/24/2012 20:00:53;0040;PBS_Server;Svr;tyrone-cluster;Scheduler was sent the command new
12/24/2012 20:01:22;0040;PBS_Server;Svr;tyrone-cluster;Scheduler was sent the command new
12/24/2012 20:01:53;0040;PBS_Server;Svr;tyrone-cluster;Scheduler was sent the command new
12/24/2012 20:02:23;0040;PBS_Server;Svr;tyrone-cluster;Scheduler was sent the command new
12/24/2012 20:02:53;0040;PBS_Server;Svr;tyrone-cluster;Scheduler was sent the command new
12/24/2012 20:03:23;0040;PBS_Server;Svr;tyrone-cluster;Scheduler was sent the command new
12/24/2012 20:03:53;0040;PBS_Server;Svr;tyrone-cluster;Scheduler was sent the command new
12/24/2012 20:04:23;0040;PBS_Server;Svr;tyrone-cluster;Scheduler was sent the command new
12/24/2012 20:04:53;0040;PBS_Server;Svr;tyrone-cluster;Scheduler was sent the command new
12/24/2012 20:05:11;0002;PBS_Server;Svr;PBS_Server;Torque Server Version = 3.0.5, loglevel = 0
12/24/2012 20:05:23;0040;PBS_Server;Svr;tyrone-cluster;Scheduler was sent the command new
12/24/2012 20:05:54;0040;PBS_Server;Svr;tyrone-cluster;Scheduler was sent the command new
12/24/2012 20:06:24;0040;PBS_Server;Svr;tyrone-cluster;Scheduler was sent the command new
12/24/2012 20:06:58;0040;PBS_Server;Svr;tyrone-cluster;Scheduler was sent the command new
12/24/2012 20:07:28;0040;PBS_Server;Svr;tyrone-cluster;Scheduler was sent the command new
12/24/2012 20:08:07;0040;PBS_Server;Svr;tyrone-cluster;Scheduler was sent the command new
12/24/2012 20:08:38;0040;PBS_Server;Svr;tyrone-cluster;Scheduler was sent the command new
12/24/2012 20:09:08;0040;PBS_Server;Svr;tyrone-cluster;Scheduler was sent the command new
12/24/2012 20:09:38;0040;PBS_Server;Svr;tyrone-cluster;Scheduler was sent the command new
12/24/2012 20:10:08;0040;PBS_Server;Svr;tyrone-cluster;Scheduler was sent the command new
12/24/2012 20:10:11;0002;PBS_Server;Svr;PBS_Server;Torque Server Version = 3.0.5, loglevel = 0
12/24/2012 20:10:38;0040;PBS_Server;Svr;tyrone-cluster;Scheduler was sent the command new
12/24/2012 20:11:09;0040;PBS_Server;Svr;tyrone-cluster;Scheduler was sent the command new
12/24/2012 20:11:39;0040;PBS_Server;Svr;tyrone-cluster;Scheduler was sent the command new
12/24/2012 20:12:13;0040;PBS_Server;Svr;tyrone-cluster;Scheduler was sent the command new
12/24/2012 20:12:42;0040;PBS_Server;Svr;tyrone-cluster;Scheduler was sent the command new
12/24/2012 20:13:16;0040;PBS_Server;Svr;tyrone-cluster;Scheduler was sent the command new
12/24/2012 20:13:43;0040;PBS_Server;Svr;tyrone-cluster;Scheduler was sent the command new
12/24/2012 20:14:13;0040;PBS_Server;Svr;tyrone-cluster;Scheduler was sent the command new
12/24/2012 20:14:52;0040;PBS_Server;Svr;tyrone-cluster;Scheduler was sent the command new
12/24/2012 20:15:11;0002;PBS_Server;Svr;PBS_Server;Torque Server Version = 3.0.5, loglevel = 0
12/24/2012 20:15:23;0040;PBS_Server;Svr;tyrone-cluster;Scheduler was sent the command new
12/24/2012 20:15:52;0040;PBS_Server;Svr;tyrone-cluster;Scheduler was sent the command new
12/24/2012 20:16:22;0040;PBS_Server;Svr;tyrone-cluster;Scheduler was sent the command new
12/24/2012 20:16:53;0040;PBS_Server;Svr;tyrone-cluster;Scheduler was sent the command new
12/24/2012 20:17:23;0040;PBS_Server;Svr;tyrone-cluster;Scheduler was sent the command new
12/24/2012 20:17:53;0040;PBS_Server;Svr;tyrone-cluster;Scheduler was sent the command new
12/24/2012 20:18:23;0040;PBS_Server;Svr;tyrone-cluster;Scheduler was sent the command new
12/24/2012 20:18:53;0040;PBS_Server;Svr;tyrone-cluster;Scheduler was sent the command new
12/24/2012 20:19:23;0040;PBS_Server;Svr;tyrone-cluster;Scheduler was sent the command new
12/24/2012 20:19:53;0040;PBS_Server;Svr;tyrone-cluster;Scheduler was sent the command new
12/24/2012 20:20:11;0002;PBS_Server;Svr;PBS_Server;Torque Server Version = 3.0.5, loglevel = 0
12/24/2012 20:20:23;0040;PBS_Server;Svr;tyrone-cluster;Scheduler was sent the command new
12/24/2012 20:20:54;0040;PBS_Server;Svr;tyrone-cluster;Scheduler was sent the command new
12/24/2012 20:21:23;0040;PBS_Server;Svr;tyrone-cluster;Scheduler was sent the command new
12/24/2012 20:21:53;0040;PBS_Server;Svr;tyrone-cluster;Scheduler was sent the command new
12/24/2012 20:22:23;0040;PBS_Server;Svr;tyrone-cluster;Scheduler was sent the command new
12/24/2012 20:22:53;0040;PBS_Server;Svr;tyrone-cluster;Scheduler was sent the command new
12/24/2012 20:23:23;0040;PBS_Server;Svr;tyrone-cluster;Scheduler was sent the command new
12/24/2012 20:23:53;0040;PBS_Server;Svr;tyrone-cluster;Scheduler was sent the command new
12/24/2012 20:24:23;0040;PBS_Server;Svr;tyrone-cluster;Scheduler was sent the command new
12/24/2012 20:24:53;0040;PBS_Server;Svr;tyrone-cluster;Scheduler was sent the command new
12/24/2012 20:25:11;0002;PBS_Server;Svr;PBS_Server;Torque Server Version = 3.0.5, loglevel = 0
12/24/2012 20:25:24;0040;PBS_Server;Svr;tyrone-cluster;Scheduler was sent the command new
12/24/2012 20:25:53;0040;PBS_Server;Svr;tyrone-cluster;Scheduler was sent the command new
12/24/2012 20:26:23;0040;PBS_Server;Svr;tyrone-cluster;Scheduler was sent the command new
12/24/2012 20:26:53;0040;PBS_Server;Svr;tyrone-cluster;Scheduler was sent the command new
12/24/2012 20:27:23;0040;PBS_Server;Svr;tyrone-cluster;Scheduler was sent the command new
12/24/2012 20:27:53;0040;PBS_Server;Svr;tyrone-cluster;Scheduler was sent the command new
12/24/2012 20:28:23;0040;PBS_Server;Svr;tyrone-cluster;Scheduler was sent the command new
12/24/2012 20:28:53;0040;PBS_Server;Svr;tyrone-cluster;Scheduler was sent the command new
12/24/2012 20:29:23;0040;PBS_Server;Svr;tyrone-cluster;Scheduler was sent the command new
12/24/2012 20:29:53;0040;PBS_Server;Svr;tyrone-cluster;Scheduler was sent the command new
12/24/2012 20:30:11;0002;PBS_Server;Svr;PBS_Server;Torque Server Version = 3.0.5, loglevel = 0
12/24/2012 20:30:23;0040;PBS_Server;Svr;tyrone-cluster;Scheduler was sent the command new
12/24/2012 20:30:53;0040;PBS_Server;Svr;tyrone-cluster;Scheduler was sent the command new
12/24/2012 20:31:23;0040;PBS_Server;Svr;tyrone-cluster;Scheduler was sent the command new
12/24/2012 20:31:53;0040;PBS_Server;Svr;tyrone-cluster;Scheduler was sent the command new
12/24/2012 20:32:23;0040;PBS_Server;Svr;tyrone-cluster;Scheduler was sent the command new
12/24/2012 20:32:53;0040;PBS_Server;Svr;tyrone-cluster;Scheduler was sent the command new
12/24/2012 20:33:23;0040;PBS_Server;Svr;tyrone-cluster;Scheduler was sent the command new
12/24/2012 20:33:53;0040;PBS_Server;Svr;tyrone-cluster;Scheduler was sent the command new
12/24/2012 20:34:24;0040;PBS_Server;Svr;tyrone-cluster;Scheduler was sent the command new
12/24/2012 20:34:53;0040;PBS_Server;Svr;tyrone-cluster;Scheduler was sent the command new
12/24/2012 20:35:11;0002;PBS_Server;Svr;PBS_Server;Torque Server Version = 3.0.5, loglevel = 0
12/24/2012 20:35:23;0040;PBS_Server;Svr;tyrone-cluster;Scheduler was sent the command new
12/24/2012 20:35:53;0040;PBS_Server;Svr;tyrone-cluster;Scheduler was sent the command new
12/24/2012 20:36:23;0040;PBS_Server;Svr;tyrone-cluster;Scheduler was sent the command new
12/24/2012 20:36:53;0040;PBS_Server;Svr;tyrone-cluster;Scheduler was sent the command new
12/24/2012 20:37:23;0040;PBS_Server;Svr;tyrone-cluster;Scheduler was sent the command new
12/24/2012 20:37:53;0040;PBS_Server;Svr;tyrone-cluster;Scheduler was sent the command new
12/24/2012 20:38:23;0040;PBS_Server;Svr;tyrone-cluster;Scheduler was sent the command new
12/24/2012 20:38:53;0040;PBS_Server;Svr;tyrone-cluster;Scheduler was sent the command new
12/24/2012 20:39:23;0040;PBS_Server;Svr;tyrone-cluster;Scheduler was sent the command new
12/24/2012 20:39:53;0040;PBS_Server;Svr;tyrone-cluster;Scheduler was sent the command new
12/24/2012 20:40:11;0002;PBS_Server;Svr;PBS_Server;Torque Server Version = 3.0.5, loglevel = 0
12/24/2012 20:40:23;0040;PBS_Server;Svr;tyrone-cluster;Scheduler was sent the command new
12/24/2012 20:40:53;0040;PBS_Server;Svr;tyrone-cluster;Scheduler was sent the command new
12/24/2012 20:41:23;0040;PBS_Server;Svr;tyrone-cluster;Scheduler was sent the command new
12/24/2012 20:41:53;0040;PBS_Server;Svr;tyrone-cluster;Scheduler was sent the command new
12/24/2012 20:42:23;0040;PBS_Server;Svr;tyrone-cluster;Scheduler was sent the command new
12/24/2012 20:42:53;0040;PBS_Server;Svr;tyrone-cluster;Scheduler was sent the command new
12/24/2012 20:43:23;0040;PBS_Server;Svr;tyrone-cluster;Scheduler was sent the command new
12/24/2012 20:43:53;0040;PBS_Server;Svr;tyrone-cluster;Scheduler was sent the command new
12/24/2012 20:44:23;0040;PBS_Server;Svr;tyrone-cluster;Scheduler was sent the command new
12/24/2012 20:44:53;0040;PBS_Server;Svr;tyrone-cluster;Scheduler was sent the command new
12/24/2012 20:45:06;000d;PBS_Server;Job;17556.tyrone-cluster;Not sending email: User does not want mail of this type.
12/24/2012 20:45:06;0010;PBS_Server;Job;17556.tyrone-cluster;Exit_status=143 resources_used.cput=47:59:46 resources_used.mem=16156284kb resources_used.vmem=20801668kb resources_used.walltime=02:00:33
12/24/2012 20:45:06;0008;PBS_Server;Job;NULL;on_job_exit valid pjob: 0x1b96ff0 (substate=50)
12/24/2012 20:45:06;0008;PBS_Server;Job;NULL;on_job_exit valid pjob: 0x1b96ff0 (substate=51)
12/24/2012 20:45:08;0008;PBS_Server;Job;NULL;on_job_exit valid pjob: 0x1b96ff0 (substate=51)
12/24/2012 20:45:08;0008;PBS_Server;Job;NULL;on_job_exit valid pjob: 0x1b96ff0 (substate=53)
12/24/2012 20:45:08;0100;PBS_Server;Job;17556.tyrone-cluster;dequeuing from idqueue, state COMPLETE
12/24/2012 20:45:08;0040;PBS_Server;Svr;tyrone-cluster;Scheduler was sent the command term
12/24/2012 20:45:11;0002;PBS_Server;Svr;PBS_Server;Torque Server Version = 3.0.5, loglevel = 0
12/24/2012 20:45:23;0040;PBS_Server;Svr;tyrone-cluster;Scheduler was sent the command new
12/24/2012 20:45:53;0040;PBS_Server;Svr;tyrone-cluster;Scheduler was sent the command new
12/24/2012 20:46:23;0040;PBS_Server;Svr;tyrone-cluster;Scheduler was sent the command new
12/24/2012 20:46:53;0040;PBS_Server;Svr;tyrone-cluster;Scheduler was sent the command new
12/24/2012 20:47:23;0040;PBS_Server;Svr;tyrone-cluster;Scheduler was sent the command new
12/24/2012 20:47:54;0040;PBS_Server;Svr;tyrone-cluster;Scheduler was sent the command new
12/24/2012 20:48:23;0040;PBS_Server;Svr;tyrone-cluster;Scheduler was sent the command new
12/24/2012 20:48:53;0040;PBS_Server;Svr;tyrone-cluster;Scheduler was sent the command new
12/24/2012 20:49:23;0040;PBS_Server;Svr;tyrone-cluster;Scheduler was sent the command new
12/24/2012 20:49:53;0040;PBS_Server;Svr;tyrone-cluster;Scheduler was sent the command new
12/24/2012 20:50:11;0002;PBS_Server;Svr;PBS_Server;Torque Server Version = 3.0.5, loglevel = 0
12/24/2012 20:50:23;0040;PBS_Server;Svr;tyrone-cluster;Scheduler was sent the command new
12/24/2012 20:50:53;0040;PBS_Server;Svr;tyrone-cluster;Scheduler was sent the command new
12/24/2012 20:51:23;0040;PBS_Server;Svr;tyrone-cluster;Scheduler was sent the command new
12/24/2012 20:51:53;0040;PBS_Server;Svr;tyrone-cluster;Scheduler was sent the command new
12/24/2012 20:52:23;0040;PBS_Server;Svr;tyrone-cluster;Scheduler was sent the command new
12/24/2012 20:52:53;0040;PBS_Server;Svr;tyrone-cluster;Scheduler was sent the command new
12/24/2012 20:53:23;0040;PBS_Server;Svr;tyrone-cluster;Scheduler was sent the command new
12/24/2012 20:53:53;0040;PBS_Server;Svr;tyrone-cluster;Scheduler was sent the command new
12/24/2012 20:54:23;0040;PBS_Server;Svr;tyrone-cluster;Scheduler was sent the command new
12/24/2012 20:54:53;0040;PBS_Server;Svr;tyrone-cluster;Scheduler was sent the command new
12/24/2012 20:55:11;0002;PBS_Server;Svr;PBS_Server;Torque Server Version = 3.0.5, loglevel = 0
12/24/2012 20:55:23;0040;PBS_Server;Svr;tyrone-cluster;Scheduler was sent the command new
12/24/2012 20:55:53;0040;PBS_Server;Svr;tyrone-cluster;Scheduler was sent the command new
12/24/2012 20:56:23;0040;PBS_Server;Svr;tyrone-cluster;Scheduler was sent the command new
12/24/2012 20:56:53;0040;PBS_Server;Svr;tyrone-cluster;Scheduler was sent the command new
12/24/2012 20:57:23;0040;PBS_Server;Svr;tyrone-cluster;Scheduler was sent the command new
12/24/2012 20:57:53;0040;PBS_Server;Svr;tyrone-cluster;Scheduler was sent the command new
12/24/2012 20:58:23;0040;PBS_Server;Svr;tyrone-cluster;Scheduler was sent the command new
12/24/2012 20:58:53;0040;PBS_Server;Svr;tyrone-cluster;Scheduler was sent the command new
12/24/2012 20:59:23;0040;PBS_Server;Svr;tyrone-cluster;Scheduler was sent the command new
12/24/2012 20:59:53;0040;PBS_Server;Svr;tyrone-cluster;Scheduler was sent the command new
12/24/2012 21:00:11;0002;PBS_Server;Svr;PBS_Server;Torque Server Version = 3.0.5, loglevel = 0
12/24/2012 21:00:23;0040;PBS_Server;Svr;tyrone-cluster;Scheduler was sent the command new
12/24/2012 21:00:53;0040;PBS_Server;Svr;tyrone-cluster;Scheduler was sent the command new
12/24/2012 21:01:23;0040;PBS_Server;Svr;tyrone-cluster;Scheduler was sent the command new
12/24/2012 21:01:53;0040;PBS_Server;Svr;tyrone-cluster;Scheduler was sent the command new
12/24/2012 21:02:23;0040;PBS_Server;Svr;tyrone-cluster;Scheduler was sent the command new
12/24/2012 21:02:53;0040;PBS_Server;Svr;tyrone-cluster;Scheduler was sent the command new
12/24/2012 21:03:23;0040;PBS_Server;Svr;tyrone-cluster;Scheduler was sent the command new
12/24/2012 21:03:53;0040;PBS_Server;Svr;tyrone-cluster;Scheduler was sent the command new
12/24/2012 21:04:24;0040;PBS_Server;Svr;tyrone-cluster;Scheduler was sent the command new
12/24/2012 21:04:53;0040;PBS_Server;Svr;tyrone-cluster;Scheduler was sent the command new
12/24/2012 21:05:11;0002;PBS_Server;Svr;PBS_Server;Torque Server Version = 3.0.5, loglevel = 0
12/24/2012 21:05:23;0040;PBS_Server;Svr;tyrone-cluster;Scheduler was sent the command new
12/24/2012 21:05:54;0040;PBS_Server;Svr;tyrone-cluster;Scheduler was sent the command new
12/24/2012 21:06:23;0040;PBS_Server;Svr;tyrone-cluster;Scheduler was sent the command new
12/24/2012 21:06:53;0040;PBS_Server;Svr;tyrone-cluster;Scheduler was sent the command new
12/24/2012 21:07:23;0040;PBS_Server;Svr;tyrone-cluster;Scheduler was sent the command new
12/24/2012 21:07:53;0040;PBS_Server;Svr;tyrone-cluster;Scheduler was sent the command new
12/24/2012 21:08:23;0040;PBS_Server;Svr;tyrone-cluster;Scheduler was sent the command new
12/24/2012 21:08:53;0040;PBS_Server;Svr;tyrone-cluster;Scheduler was sent the command new
12/24/2012 21:09:23;0040;PBS_Server;Svr;tyrone-cluster;Scheduler was sent the command new
12/24/2012 21:09:53;0040;PBS_Server;Svr;tyrone-cluster;Scheduler was sent the command new
12/24/2012 21:10:11;0002;PBS_Server;Svr;PBS_Server;Torque Server Version = 3.0.5, loglevel = 0
12/24/2012 21:10:24;0040;PBS_Server;Svr;tyrone-cluster;Scheduler was sent the command new
12/24/2012 21:10:53;0040;PBS_Server;Svr;tyrone-cluster;Scheduler was sent the command new
12/24/2012 21:11:23;0040;PBS_Server;Svr;tyrone-cluster;Scheduler was sent the command new
12/24/2012 21:11:54;0040;PBS_Server;Svr;tyrone-cluster;Scheduler was sent the command new
12/24/2012 21:12:23;0040;PBS_Server;Svr;tyrone-cluster;Scheduler was sent the command new
12/24/2012 21:12:53;0040;PBS_Server;Svr;tyrone-cluster;Scheduler was sent the command new
12/24/2012 21:13:23;0040;PBS_Server;Svr;tyrone-cluster;Scheduler was sent the command new
12/24/2012 21:13:53;0040;PBS_Server;Svr;tyrone-cluster;Scheduler was sent the command new
12/24/2012 21:14:23;0040;PBS_Server;Svr;tyrone-cluster;Scheduler was sent the command new
12/24/2012 21:14:54;0040;PBS_Server;Svr;tyrone-cluster;Scheduler was sent the command new
12/24/2012 21:15:11;0002;PBS_Server;Svr;PBS_Server;Torque Server Version = 3.0.5, loglevel = 0
12/24/2012 21:15:23;0040;PBS_Server;Svr;tyrone-cluster;Scheduler was sent the command new
12/24/2012 21:15:53;0040;PBS_Server;Svr;tyrone-cluster;Scheduler was sent the command new
12/24/2012 21:16:24;0040;PBS_Server;Svr;tyrone-cluster;Scheduler was sent the command new
12/24/2012 21:16:53;0040;PBS_Server;Svr;tyrone-cluster;Scheduler was sent the command new
12/24/2012 21:17:23;0040;PBS_Server;Svr;tyrone-cluster;Scheduler was sent the command new
12/24/2012 21:17:53;0040;PBS_Server;Svr;tyrone-cluster;Scheduler was sent the command new
12/24/2012 21:18:23;0040;PBS_Server;Svr;tyrone-cluster;Scheduler was sent the command new
12/24/2012 21:18:53;0040;PBS_Server;Svr;tyrone-cluster;Scheduler was sent the command new
12/24/2012 21:19:24;0040;PBS_Server;Svr;tyrone-cluster;Scheduler was sent the command new
12/24/2012 21:19:53;0040;PBS_Server;Svr;tyrone-cluster;Scheduler was sent the command new
12/24/2012 21:20:11;0002;PBS_Server;Svr;PBS_Server;Torque Server Version = 3.0.5, loglevel = 0
12/24/2012 21:20:23;0040;PBS_Server;Svr;tyrone-cluster;Scheduler was sent the command new
12/24/2012 21:20:54;0040;PBS_Server;Svr;tyrone-cluster;Scheduler was sent the command new
12/24/2012 21:21:23;0040;PBS_Server;Svr;tyrone-cluster;Scheduler was sent the command new
12/24/2012 21:21:53;0040;PBS_Server;Svr;tyrone-cluster;Scheduler was sent the command new
12/24/2012 21:22:24;0040;PBS_Server;Svr;tyrone-cluster;Scheduler was sent the command new
12/24/2012 21:22:53;0040;PBS_Server;Svr;tyrone-cluster;Scheduler was sent the command new
12/24/2012 21:23:23;0040;PBS_Server;Svr;tyrone-cluster;Scheduler was sent the command new
12/24/2012 21:23:53;0040;PBS_Server;Svr;tyrone-cluster;Scheduler was sent the command new
12/24/2012 21:24:23;0040;PBS_Server;Svr;tyrone-cluster;Scheduler was sent the command new
12/24/2012 21:24:53;0040;PBS_Server;Svr;tyrone-cluster;Scheduler was sent the command new
12/24/2012 21:25:11;0002;PBS_Server;Svr;PBS_Server;Torque Server Version = 3.0.5, loglevel = 0
12/24/2012 21:25:24;0040;PBS_Server;Svr;tyrone-cluster;Scheduler was sent the command new
12/24/2012 21:25:53;0040;PBS_Server;Svr;tyrone-cluster;Scheduler was sent the command new
12/24/2012 21:26:23;0040;PBS_Server;Svr;tyrone-cluster;Scheduler was sent the command new
12/24/2012 21:26:54;0040;PBS_Server;Svr;tyrone-cluster;Scheduler was sent the command new
12/24/2012 21:27:23;0040;PBS_Server;Svr;tyrone-cluster;Scheduler was sent the command new
12/24/2012 21:27:53;0040;PBS_Server;Svr;tyrone-cluster;Scheduler was sent the command new
12/24/2012 21:28:24;0040;PBS_Server;Svr;tyrone-cluster;Scheduler was sent the command new
12/24/2012 21:28:53;0040;PBS_Server;Svr;tyrone-cluster;Scheduler was sent the command new
12/24/2012 21:29:23;0040;PBS_Server;Svr;tyrone-cluster;Scheduler was sent the command new
12/24/2012 21:29:53;0040;PBS_Server;Svr;tyrone-cluster;Scheduler was sent the command new
12/24/2012 21:30:11;0002;PBS_Server;Svr;PBS_Server;Torque Server Version = 3.0.5, loglevel = 0
12/24/2012 21:30:23;0040;PBS_Server;Svr;tyrone-cluster;Scheduler was sent the command new
12/24/2012 21:30:53;0040;PBS_Server;Svr;tyrone-cluster;Scheduler was sent the command new
12/24/2012 21:31:24;0040;PBS_Server;Svr;tyrone-cluster;Scheduler was sent the command new
12/24/2012 21:31:53;0040;PBS_Server;Svr;tyrone-cluster;Scheduler was sent the command new
12/24/2012 21:32:23;0040;PBS_Server;Svr;tyrone-cluster;Scheduler was sent the command new
12/24/2012 21:32:54;0040;PBS_Server;Svr;tyrone-cluster;Scheduler was sent the command new
12/24/2012 21:33:23;0040;PBS_Server;Svr;tyrone-cluster;Scheduler was sent the command new
12/24/2012 21:33:31;000d;PBS_Server;Job;17559.tyrone-cluster;Not sending email: User does not want mail of this type.
12/24/2012 21:33:31;0010;PBS_Server;Job;17559.tyrone-cluster;Exit_status=0 resources_used.cput=39:59:18 resources_used.mem=4468048kb resources_used.vmem=8189696kb resources_used.walltime=01:44:13
12/24/2012 21:33:31;0008;PBS_Server;Job;NULL;on_job_exit valid pjob: 0x1b92e60 (substate=50)
12/24/2012 21:33:31;0008;PBS_Server;Job;NULL;on_job_exit valid pjob: 0x1b92e60 (substate=51)
12/24/2012 21:33:31;0008;PBS_Server;Job;NULL;on_job_exit valid pjob: 0x1b92e60 (substate=51)
12/24/2012 21:33:31;0008;PBS_Server;Job;NULL;on_job_exit valid pjob: 0x1b92e60 (substate=53)
12/24/2012 21:33:31;0100;PBS_Server;Job;17559.tyrone-cluster;dequeuing from idqueue, state COMPLETE
12/24/2012 21:33:31;0040;PBS_Server;Svr;tyrone-cluster;Scheduler was sent the command term
12/24/2012 21:33:53;0040;PBS_Server;Svr;tyrone-cluster;Scheduler was sent the command new
12/24/2012 21:34:23;0040;PBS_Server;Svr;tyrone-cluster;Scheduler was sent the command new
12/24/2012 21:34:53;0040;PBS_Server;Svr;tyrone-cluster;Scheduler was sent the command new
12/24/2012 21:35:11;0002;PBS_Server;Svr;PBS_Server;Torque Server Version = 3.0.5, loglevel = 0
12/24/2012 21:35:23;0040;PBS_Server;Svr;tyrone-cluster;Scheduler was sent the command new
12/24/2012 21:35:54;0040;PBS_Server;Svr;tyrone-cluster;Scheduler was sent the command new
12/24/2012 21:36:23;0040;PBS_Server;Svr;tyrone-cluster;Scheduler was sent the command new
12/24/2012 21:36:53;0040;PBS_Server;Svr;tyrone-cluster;Scheduler was sent the command new
12/24/2012 21:37:24;0040;PBS_Server;Svr;tyrone-cluster;Scheduler was sent the command new
12/24/2012 21:37:53;0040;PBS_Server;Svr;tyrone-cluster;Scheduler was sent the command new
12/24/2012 21:38:23;0040;PBS_Server;Svr;tyrone-cluster;Scheduler was sent the command new
12/24/2012 21:38:54;0040;PBS_Server;Svr;tyrone-cluster;Scheduler was sent the command new
12/24/2012 21:39:23;0040;PBS_Server;Svr;tyrone-cluster;Scheduler was sent the command new
12/24/2012 21:39:53;0040;PBS_Server;Svr;tyrone-cluster;Scheduler was sent the command new
12/24/2012 21:40:11;0002;PBS_Server;Svr;PBS_Server;Torque Server Version = 3.0.5, loglevel = 0
12/24/2012 21:40:23;0040;PBS_Server;Svr;tyrone-cluster;Scheduler was sent the command new
12/24/2012 21:40:53;0040;PBS_Server;Svr;tyrone-cluster;Scheduler was sent the command new
12/24/2012 21:41:23;0040;PBS_Server;Svr;tyrone-cluster;Scheduler was sent the command new
12/24/2012 21:41:54;0040;PBS_Server;Svr;tyrone-cluster;Scheduler was sent the command new
12/24/2012 21:42:23;0040;PBS_Server;Svr;tyrone-cluster;Scheduler was sent the command new
12/24/2012 21:42:53;0040;PBS_Server;Svr;tyrone-cluster;Scheduler was sent the command new
12/24/2012 21:43:24;0040;PBS_Server;Svr;tyrone-cluster;Scheduler was sent the command new
12/24/2012 21:43:53;0040;PBS_Server;Svr;tyrone-cluster;Scheduler was sent the command new
12/24/2012 21:44:17;0100;PBS_Server;Job;17560.tyrone-cluster;enqueuing into batch, state 1 hop 1
12/24/2012 21:44:17;0100;PBS_Server;Job;17560.tyrone-cluster;dequeuing from batch, state QUEUED
12/24/2012 21:44:17;0100;PBS_Server;Job;17560.tyrone-cluster;enqueuing into idqueue, state 1 hop 1
12/24/2012 21:44:17;0008;PBS_Server;Job;17560.tyrone-cluster;Job Queued at request of ipcdskp@tyrone-cluster, owner = ipcdskp@tyrone-cluster, job name = n10, queue = idqueue
12/24/2012 21:44:17;0040;PBS_Server;Svr;tyrone-cluster;Scheduler was sent the command new
12/24/2012 21:44:17;0008;PBS_Server;Job;17560.tyrone-cluster;Job Modified at request of Scheduler@tyrone-cluster
12/24/2012 21:44:17;0008;PBS_Server;Job;17560.tyrone-cluster;Job Run at request of Scheduler@tyrone-cluster
12/24/2012 21:44:17;0040;PBS_Server;Svr;tyrone-cluster;Scheduler was sent the command recyc
12/24/2012 21:44:17;000d;PBS_Server;Job;17560.tyrone-cluster;Not sending email: User does not want mail of this type.
12/24/2012 21:44:23;0040;PBS_Server;Svr;tyrone-cluster;Scheduler was sent the command new
12/24/2012 21:44:54;0040;PBS_Server;Svr;tyrone-cluster;Scheduler was sent the command new
12/24/2012 21:45:11;0002;PBS_Server;Svr;PBS_Server;Torque Server Version = 3.0.5, loglevel = 0
12/24/2012 21:45:23;0040;PBS_Server;Svr;tyrone-cluster;Scheduler was sent the command new
12/24/2012 21:45:53;0040;PBS_Server;Svr;tyrone-cluster;Scheduler was sent the command new
12/24/2012 21:46:23;0040;PBS_Server;Svr;tyrone-cluster;Scheduler was sent the command new
12/24/2012 21:46:53;0040;PBS_Server;Svr;tyrone-cluster;Scheduler was sent the command new
12/24/2012 21:47:23;0040;PBS_Server;Svr;tyrone-cluster;Scheduler was sent the command new
12/24/2012 21:47:54;0040;PBS_Server;Svr;tyrone-cluster;Scheduler was sent the command new
12/24/2012 21:48:23;0040;PBS_Server;Svr;tyrone-cluster;Scheduler was sent the command new
12/24/2012 21:48:53;0040;PBS_Server;Svr;tyrone-cluster;Scheduler was sent the command new
12/24/2012 21:49:24;0040;PBS_Server;Svr;tyrone-cluster;Scheduler was sent the command new
12/24/2012 21:49:53;0040;PBS_Server;Svr;tyrone-cluster;Scheduler was sent the command new
12/24/2012 21:50:11;0002;PBS_Server;Svr;PBS_Server;Torque Server Version = 3.0.5, loglevel = 0
12/24/2012 21:50:23;0040;PBS_Server;Svr;tyrone-cluster;Scheduler was sent the command new
12/24/2012 21:50:54;0040;PBS_Server;Svr;tyrone-cluster;Scheduler was sent the command new
12/24/2012 21:51:23;0040;PBS_Server;Svr;tyrone-cluster;Scheduler was sent the command new
12/24/2012 21:51:53;0040;PBS_Server;Svr;tyrone-cluster;Scheduler was sent the command new
12/24/2012 21:52:24;0040;PBS_Server;Svr;tyrone-cluster;Scheduler was sent the command new
12/24/2012 21:52:53;0040;PBS_Server;Svr;tyrone-cluster;Scheduler was sent the command new
12/24/2012 21:53:23;0040;PBS_Server;Svr;tyrone-cluster;Scheduler was sent the command new
12/24/2012 21:53:54;0040;PBS_Server;Svr;tyrone-cluster;Scheduler was sent the command new
12/24/2012 21:54:23;0040;PBS_Server;Svr;tyrone-cluster;Scheduler was sent the command new
12/24/2012 21:54:53;0040;PBS_Server;Svr;tyrone-cluster;Scheduler was sent the command new
12/24/2012 21:55:11;0002;PBS_Server;Svr;PBS_Server;Torque Server Version = 3.0.5, loglevel = 0
12/24/2012 21:55:24;0040;PBS_Server;Svr;tyrone-cluster;Scheduler was sent the command new
12/24/2012 21:55:53;0040;PBS_Server;Svr;tyrone-cluster;Scheduler was sent the command new
12/24/2012 21:56:23;0040;PBS_Server;Svr;tyrone-cluster;Scheduler was sent the command new
12/24/2012 21:56:54;0040;PBS_Server;Svr;tyrone-cluster;Scheduler was sent the command new
12/24/2012 21:57:23;0040;PBS_Server;Svr;tyrone-cluster;Scheduler was sent the command new
12/24/2012 21:57:53;0040;PBS_Server;Svr;tyrone-cluster;Scheduler was sent the command new
12/24/2012 21:58:24;0040;PBS_Server;Svr;tyrone-cluster;Scheduler was sent the command new
12/24/2012 21:58:53;0040;PBS_Server;Svr;tyrone-cluster;Scheduler was sent the command new
12/24/2012 21:59:23;0040;PBS_Server;Svr;tyrone-cluster;Scheduler was sent the command new
12/24/2012 21:59:54;0040;PBS_Server;Svr;tyrone-cluster;Scheduler was sent the command new
12/24/2012 22:00:11;0002;PBS_Server;Svr;PBS_Server;Torque Server Version = 3.0.5, loglevel = 0
12/24/2012 22:00:23;0040;PBS_Server;Svr;tyrone-cluster;Scheduler was sent the command new
12/24/2012 22:00:53;0040;PBS_Server;Svr;tyrone-cluster;Scheduler was sent the command new
12/24/2012 22:01:24;0040;PBS_Server;Svr;tyrone-cluster;Scheduler was sent the command new
12/24/2012 22:01:53;0040;PBS_Server;Svr;tyrone-cluster;Scheduler was sent the command new
12/24/2012 22:02:23;0040;PBS_Server;Svr;tyrone-cluster;Scheduler was sent the command new
12/24/2012 22:02:54;0040;PBS_Server;Svr;tyrone-cluster;Scheduler was sent the command new
12/24/2012 22:03:23;0040;PBS_Server;Svr;tyrone-cluster;Scheduler was sent the command new
12/24/2012 22:03:53;0040;PBS_Server;Svr;tyrone-cluster;Scheduler was sent the command new
12/24/2012 22:04:24;0040;PBS_Server;Svr;tyrone-cluster;Scheduler was sent the command new
12/24/2012 22:04:53;0040;PBS_Server;Svr;tyrone-cluster;Scheduler was sent the command new
12/24/2012 22:05:11;0002;PBS_Server;Svr;PBS_Server;Torque Server Version = 3.0.5, loglevel = 0
12/24/2012 22:05:23;0040;PBS_Server;Svr;tyrone-cluster;Scheduler was sent the command new
12/24/2012 22:05:30;000d;PBS_Server;Job;17560.tyrone-cluster;Not sending email: User does not want mail of this type.
12/24/2012 22:05:30;0010;PBS_Server;Job;17560.tyrone-cluster;Exit_status=0 resources_used.cput=10:59:54 resources_used.mem=4109528kb resources_used.vmem=8189736kb resources_used.walltime=00:21:13
12/24/2012 22:05:30;0008;PBS_Server;Job;NULL;on_job_exit valid pjob: 0x1b96ff0 (substate=50)
12/24/2012 22:05:30;0008;PBS_Server;Job;NULL;on_job_exit valid pjob: 0x1b96ff0 (substate=51)
12/24/2012 22:05:30;0008;PBS_Server;Job;NULL;on_job_exit valid pjob: 0x1b96ff0 (substate=51)
12/24/2012 22:05:30;0008;PBS_Server;Job;NULL;on_job_exit valid pjob: 0x1b96ff0 (substate=53)
12/24/2012 22:05:30;0100;PBS_Server;Job;17560.tyrone-cluster;dequeuing from idqueue, state COMPLETE
12/24/2012 22:05:30;0040;PBS_Server;Svr;tyrone-cluster;Scheduler was sent the command term
12/24/2012 22:05:54;0040;PBS_Server;Svr;tyrone-cluster;Scheduler was sent the command new
12/24/2012 22:06:23;0040;PBS_Server;Svr;tyrone-cluster;Scheduler was sent the command new
12/24/2012 22:06:53;0040;PBS_Server;Svr;tyrone-cluster;Scheduler was sent the command new
12/24/2012 22:07:24;0040;PBS_Server;Svr;tyrone-cluster;Scheduler was sent the command new
12/24/2012 22:07:53;0040;PBS_Server;Svr;tyrone-cluster;Scheduler was sent the command new
12/24/2012 22:08:23;0040;PBS_Server;Svr;tyrone-cluster;Scheduler was sent the command new
12/24/2012 22:08:54;0040;PBS_Server;Svr;tyrone-cluster;Scheduler was sent the command new
12/24/2012 22:09:23;0040;PBS_Server;Svr;tyrone-cluster;Scheduler was sent the command new
12/24/2012 22:09:53;0040;PBS_Server;Svr;tyrone-cluster;Scheduler was sent the command new
12/24/2012 22:10:11;0002;PBS_Server;Svr;PBS_Server;Torque Server Version = 3.0.5, loglevel = 0
12/24/2012 22:10:24;0040;PBS_Server;Svr;tyrone-cluster;Scheduler was sent the command new
12/24/2012 22:10:53;0040;PBS_Server;Svr;tyrone-cluster;Scheduler was sent the command new
12/24/2012 22:11:23;0040;PBS_Server;Svr;tyrone-cluster;Scheduler was sent the command new
12/24/2012 22:11:54;0040;PBS_Server;Svr;tyrone-cluster;Scheduler was sent the command new
12/24/2012 22:12:23;0040;PBS_Server;Svr;tyrone-cluster;Scheduler was sent the command new
12/24/2012 22:12:53;0040;PBS_Server;Svr;tyrone-cluster;Scheduler was sent the command new
12/24/2012 22:13:24;0040;PBS_Server;Svr;tyrone-cluster;Scheduler was sent the command new
12/24/2012 22:13:53;0040;PBS_Server;Svr;tyrone-cluster;Scheduler was sent the command new
12/24/2012 22:14:23;0040;PBS_Server;Svr;tyrone-cluster;Scheduler was sent the command new
12/24/2012 22:14:54;0040;PBS_Server;Svr;tyrone-cluster;Scheduler was sent the command new
12/24/2012 22:15:11;0002;PBS_Server;Svr;PBS_Server;Torque Server Version = 3.0.5, loglevel = 0
12/24/2012 22:15:23;0040;PBS_Server;Svr;tyrone-cluster;Scheduler was sent the command new
12/24/2012 22:15:53;0040;PBS_Server;Svr;tyrone-cluster;Scheduler was sent the command new
12/24/2012 22:16:24;0040;PBS_Server;Svr;tyrone-cluster;Scheduler was sent the command new
12/24/2012 22:16:53;0040;PBS_Server;Svr;tyrone-cluster;Scheduler was sent the command new
12/24/2012 22:17:23;0040;PBS_Server;Svr;tyrone-cluster;Scheduler was sent the command new
12/24/2012 22:17:54;0040;PBS_Server;Svr;tyrone-cluster;Scheduler was sent the command new
12/24/2012 22:17:56;0100;PBS_Server;Job;17561.tyrone-cluster;enqueuing into batch, state 1 hop 1
12/24/2012 22:17:57;0100;PBS_Server;Job;17561.tyrone-cluster;dequeuing from batch, state QUEUED
12/24/2012 22:17:57;0100;PBS_Server;Job;17561.tyrone-cluster;enqueuing into idqueue, state 1 hop 1
12/24/2012 22:17:57;0008;PBS_Server;Job;17561.tyrone-cluster;Job Queued at request of ipcdskp@tyrone-cluster, owner = ipcdskp@tyrone-cluster, job name = n10, queue = idqueue
12/24/2012 22:17:57;0040;PBS_Server;Svr;tyrone-cluster;Scheduler was sent the command new
12/24/2012 22:17:57;0008;PBS_Server;Job;17561.tyrone-cluster;Job Modified at request of Scheduler@tyrone-cluster
12/24/2012 22:17:57;0008;PBS_Server;Job;17561.tyrone-cluster;Job Run at request of Scheduler@tyrone-cluster
12/24/2012 22:17:57;0040;PBS_Server;Svr;tyrone-cluster;Scheduler was sent the command recyc
12/24/2012 22:17:57;000d;PBS_Server;Job;17561.tyrone-cluster;Not sending email: User does not want mail of this type.
12/24/2012 22:18:23;0040;PBS_Server;Svr;tyrone-cluster;Scheduler was sent the command new
12/24/2012 22:18:53;0040;PBS_Server;Svr;tyrone-cluster;Scheduler was sent the command new
12/24/2012 22:19:24;0040;PBS_Server;Svr;tyrone-cluster;Scheduler was sent the command new
12/24/2012 22:19:53;0040;PBS_Server;Svr;tyrone-cluster;Scheduler was sent the command new
12/24/2012 22:20:11;0002;PBS_Server;Svr;PBS_Server;Torque Server Version = 3.0.5, loglevel = 0
12/24/2012 22:20:23;0040;PBS_Server;Svr;tyrone-cluster;Scheduler was sent the command new
12/24/2012 22:20:54;0040;PBS_Server;Svr;tyrone-cluster;Scheduler was sent the command new
12/24/2012 22:21:23;0040;PBS_Server;Svr;tyrone-cluster;Scheduler was sent the command new
12/24/2012 22:21:53;0040;PBS_Server;Svr;tyrone-cluster;Scheduler was sent the command new
12/24/2012 22:22:24;0040;PBS_Server;Svr;tyrone-cluster;Scheduler was sent the command new
12/24/2012 22:22:53;0040;PBS_Server;Svr;tyrone-cluster;Scheduler was sent the command new
12/24/2012 22:23:23;0040;PBS_Server;Svr;tyrone-cluster;Scheduler was sent the command new
12/24/2012 22:23:54;0040;PBS_Server;Svr;tyrone-cluster;Scheduler was sent the command new
12/24/2012 22:24:25;0040;PBS_Server;Svr;tyrone-cluster;Scheduler was sent the command new
12/24/2012 22:24:58;0040;PBS_Server;Svr;tyrone-cluster;Scheduler was sent the command new
12/24/2012 22:25:11;0002;PBS_Server;Svr;PBS_Server;Torque Server Version = 3.0.5, loglevel = 0
12/24/2012 22:25:27;0040;PBS_Server;Svr;tyrone-cluster;Scheduler was sent the command new
12/24/2012 22:26:01;0040;PBS_Server;Svr;tyrone-cluster;Scheduler was sent the command new
12/24/2012 22:26:28;0040;PBS_Server;Svr;tyrone-cluster;Scheduler was sent the command new
12/24/2012 22:26:57;0040;PBS_Server;Svr;tyrone-cluster;Scheduler was sent the command new
12/24/2012 22:27:37;0040;PBS_Server;Svr;tyrone-cluster;Scheduler was sent the command new
12/24/2012 22:28:07;0040;PBS_Server;Svr;tyrone-cluster;Scheduler was sent the command new
12/24/2012 22:28:37;0040;PBS_Server;Svr;tyrone-cluster;Scheduler was sent the command new
12/24/2012 22:29:07;0040;PBS_Server;Svr;tyrone-cluster;Scheduler was sent the command new
12/24/2012 22:29:38;0040;PBS_Server;Svr;tyrone-cluster;Scheduler was sent the command new
12/24/2012 22:30:07;0040;PBS_Server;Svr;tyrone-cluster;Scheduler was sent the command new
12/24/2012 22:30:11;0002;PBS_Server;Svr;PBS_Server;Torque Server Version = 3.0.5, loglevel = 0
12/24/2012 22:30:37;0040;PBS_Server;Svr;tyrone-cluster;Scheduler was sent the command new
12/24/2012 22:31:08;0040;PBS_Server;Svr;tyrone-cluster;Scheduler was sent the command new
12/24/2012 22:31:37;0040;PBS_Server;Svr;tyrone-cluster;Scheduler was sent the command new
12/24/2012 22:32:07;0040;PBS_Server;Svr;tyrone-cluster;Scheduler was sent the command new
12/24/2012 22:32:38;0040;PBS_Server;Svr;tyrone-cluster;Scheduler was sent the command new
12/24/2012 22:33:07;0040;PBS_Server;Svr;tyrone-cluster;Scheduler was sent the command new
12/24/2012 22:33:37;0040;PBS_Server;Svr;tyrone-cluster;Scheduler was sent the command new
12/24/2012 22:34:08;0040;PBS_Server;Svr;tyrone-cluster;Scheduler was sent the command new
12/24/2012 22:34:37;0040;PBS_Server;Svr;tyrone-cluster;Scheduler was sent the command new
12/24/2012 22:35:07;0040;PBS_Server;Svr;tyrone-cluster;Scheduler was sent the command new
12/24/2012 22:35:11;0002;PBS_Server;Svr;PBS_Server;Torque Server Version = 3.0.5, loglevel = 0
12/24/2012 22:35:38;0040;PBS_Server;Svr;tyrone-cluster;Scheduler was sent the command new
12/24/2012 22:36:07;0040;PBS_Server;Svr;tyrone-cluster;Scheduler was sent the command new
12/24/2012 22:36:37;0040;PBS_Server;Svr;tyrone-cluster;Scheduler was sent the command new
12/24/2012 22:37:08;0040;PBS_Server;Svr;tyrone-cluster;Scheduler was sent the command new
12/24/2012 22:37:37;0040;PBS_Server;Svr;tyrone-cluster;Scheduler was sent the command new
12/24/2012 22:38:07;0040;PBS_Server;Svr;tyrone-cluster;Scheduler was sent the command new
12/24/2012 22:38:38;0040;PBS_Server;Svr;tyrone-cluster;Scheduler was sent the command new
12/24/2012 22:39:08;0040;PBS_Server;Svr;tyrone-cluster;Scheduler was sent the command new
12/24/2012 22:39:39;0040;PBS_Server;Svr;tyrone-cluster;Scheduler was sent the command new
12/24/2012 22:40:10;0040;PBS_Server;Svr;tyrone-cluster;Scheduler was sent the command new
12/24/2012 22:40:11;0002;PBS_Server;Svr;PBS_Server;Torque Server Version = 3.0.5, loglevel = 0
12/24/2012 22:40:43;0040;PBS_Server;Svr;tyrone-cluster;Scheduler was sent the command new
12/24/2012 22:41:12;0040;PBS_Server;Svr;tyrone-cluster;Scheduler was sent the command new
12/24/2012 22:41:52;0040;PBS_Server;Svr;tyrone-cluster;Scheduler was sent the command new
12/24/2012 22:42:22;0040;PBS_Server;Svr;tyrone-cluster;Scheduler was sent the command new
12/24/2012 22:42:52;0040;PBS_Server;Svr;tyrone-cluster;Scheduler was sent the command new
12/24/2012 22:43:22;0040;PBS_Server;Svr;tyrone-cluster;Scheduler was sent the command new
12/24/2012 22:43:53;0040;PBS_Server;Svr;tyrone-cluster;Scheduler was sent the command new
12/24/2012 22:44:23;0040;PBS_Server;Svr;tyrone-cluster;Scheduler was sent the command new
12/24/2012 22:44:54;0040;PBS_Server;Svr;tyrone-cluster;Scheduler was sent the command new
12/24/2012 22:45:11;0002;PBS_Server;Svr;PBS_Server;Torque Server Version = 3.0.5, loglevel = 0
12/24/2012 22:45:23;0040;PBS_Server;Svr;tyrone-cluster;Scheduler was sent the command new
12/24/2012 22:45:53;0040;PBS_Server;Svr;tyrone-cluster;Scheduler was sent the command new
12/24/2012 22:46:24;0040;PBS_Server;Svr;tyrone-cluster;Scheduler was sent the command new
12/24/2012 22:46:55;0040;PBS_Server;Svr;tyrone-cluster;Scheduler was sent the command new
12/24/2012 22:47:28;0040;PBS_Server;Svr;tyrone-cluster;Scheduler was sent the command new
12/24/2012 22:47:57;0040;PBS_Server;Svr;tyrone-cluster;Scheduler was sent the command new
12/24/2012 22:48:37;0040;PBS_Server;Svr;tyrone-cluster;Scheduler was sent the command new
12/24/2012 22:49:07;0040;PBS_Server;Svr;tyrone-cluster;Scheduler was sent the command new
12/24/2012 22:49:37;0040;PBS_Server;Svr;tyrone-cluster;Scheduler was sent the command new
12/24/2012 22:50:07;0040;PBS_Server;Svr;tyrone-cluster;Scheduler was sent the command new
12/24/2012 22:50:11;0002;PBS_Server;Svr;PBS_Server;Torque Server Version = 3.0.5, loglevel = 0
12/24/2012 22:50:38;0040;PBS_Server;Svr;tyrone-cluster;Scheduler was sent the command new
12/24/2012 22:51:08;0040;PBS_Server;Svr;tyrone-cluster;Scheduler was sent the command new
12/24/2012 22:51:39;0040;PBS_Server;Svr;tyrone-cluster;Scheduler was sent the command new
12/24/2012 22:52:10;0040;PBS_Server;Svr;tyrone-cluster;Scheduler was sent the command new
12/24/2012 22:52:41;0040;PBS_Server;Svr;tyrone-cluster;Scheduler was sent the command new
12/24/2012 22:53:12;0040;PBS_Server;Svr;tyrone-cluster;Scheduler was sent the command new
12/24/2012 22:53:52;0040;PBS_Server;Svr;tyrone-cluster;Scheduler was sent the command new
12/24/2012 22:54:22;0040;PBS_Server;Svr;tyrone-cluster;Scheduler was sent the command new
12/24/2012 22:54:52;0040;PBS_Server;Svr;tyrone-cluster;Scheduler was sent the command new
12/24/2012 22:55:11;0002;PBS_Server;Svr;PBS_Server;Torque Server Version = 3.0.5, loglevel = 0
12/24/2012 22:55:22;0040;PBS_Server;Svr;tyrone-cluster;Scheduler was sent the command new
12/24/2012 22:55:53;0040;PBS_Server;Svr;tyrone-cluster;Scheduler was sent the command new
12/24/2012 22:56:22;0040;PBS_Server;Svr;tyrone-cluster;Scheduler was sent the command new
12/24/2012 22:56:52;0040;PBS_Server;Svr;tyrone-cluster;Scheduler was sent the command new
12/24/2012 22:57:23;0040;PBS_Server;Svr;tyrone-cluster;Scheduler was sent the command new
12/24/2012 22:57:52;0040;PBS_Server;Svr;tyrone-cluster;Scheduler was sent the command new
12/24/2012 22:58:22;0040;PBS_Server;Svr;tyrone-cluster;Scheduler was sent the command new
12/24/2012 22:58:53;0040;PBS_Server;Svr;tyrone-cluster;Scheduler was sent the command new
12/24/2012 22:59:23;0040;PBS_Server;Svr;tyrone-cluster;Scheduler was sent the command new
12/24/2012 22:59:54;0040;PBS_Server;Svr;tyrone-cluster;Scheduler was sent the command new
12/24/2012 23:00:11;0002;PBS_Server;Svr;PBS_Server;Torque Server Version = 3.0.5, loglevel = 0
12/24/2012 23:00:23;0040;PBS_Server;Svr;tyrone-cluster;Scheduler was sent the command new
12/24/2012 23:00:53;0040;PBS_Server;Svr;tyrone-cluster;Scheduler was sent the command new
12/24/2012 23:01:24;0040;PBS_Server;Svr;tyrone-cluster;Scheduler was sent the command new
12/24/2012 23:01:55;0040;PBS_Server;Svr;tyrone-cluster;Scheduler was sent the command new
12/24/2012 23:02:28;0040;PBS_Server;Svr;tyrone-cluster;Scheduler was sent the command new
12/24/2012 23:02:58;0040;PBS_Server;Svr;tyrone-cluster;Scheduler was sent the command new
12/24/2012 23:03:37;0040;PBS_Server;Svr;tyrone-cluster;Scheduler was sent the command new
12/24/2012 23:04:06;0040;PBS_Server;Svr;tyrone-cluster;Scheduler was sent the command new
12/24/2012 23:04:37;0040;PBS_Server;Svr;tyrone-cluster;Scheduler was sent the command new
12/24/2012 23:05:07;0040;PBS_Server;Svr;tyrone-cluster;Scheduler was sent the command new
12/24/2012 23:05:11;0002;PBS_Server;Svr;PBS_Server;Torque Server Version = 3.0.5, loglevel = 0
12/24/2012 23:05:38;0040;PBS_Server;Svr;tyrone-cluster;Scheduler was sent the command new
12/24/2012 23:06:07;0040;PBS_Server;Svr;tyrone-cluster;Scheduler was sent the command new
12/24/2012 23:06:37;0040;PBS_Server;Svr;tyrone-cluster;Scheduler was sent the command new
12/24/2012 23:07:08;0040;PBS_Server;Svr;tyrone-cluster;Scheduler was sent the command new
12/24/2012 23:07:37;0040;PBS_Server;Svr;tyrone-cluster;Scheduler was sent the command new
12/24/2012 23:08:07;0040;PBS_Server;Svr;tyrone-cluster;Scheduler was sent the command new
12/24/2012 23:08:38;0040;PBS_Server;Svr;tyrone-cluster;Scheduler was sent the command new
12/24/2012 23:09:08;0040;PBS_Server;Svr;tyrone-cluster;Scheduler was sent the command new
12/24/2012 23:09:39;0040;PBS_Server;Svr;tyrone-cluster;Scheduler was sent the command new
12/24/2012 23:10:08;0040;PBS_Server;Svr;tyrone-cluster;Scheduler was sent the command new
12/24/2012 23:10:11;0002;PBS_Server;Svr;PBS_Server;Torque Server Version = 3.0.5, loglevel = 0
12/24/2012 23:10:38;0040;PBS_Server;Svr;tyrone-cluster;Scheduler was sent the command new
12/24/2012 23:11:10;0040;PBS_Server;Svr;tyrone-cluster;Scheduler was sent the command new
12/24/2012 23:11:40;0040;PBS_Server;Svr;tyrone-cluster;Scheduler was sent the command new
12/24/2012 23:12:12;0040;PBS_Server;Svr;tyrone-cluster;Scheduler was sent the command new
12/24/2012 23:12:41;0040;PBS_Server;Svr;tyrone-cluster;Scheduler was sent the command new
12/24/2012 23:13:10;0040;PBS_Server;Svr;tyrone-cluster;Scheduler was sent the command new
12/24/2012 23:13:42;0040;PBS_Server;Svr;tyrone-cluster;Scheduler was sent the command new
12/24/2012 23:14:12;0040;PBS_Server;Svr;tyrone-cluster;Scheduler was sent the command new
12/24/2012 23:14:40;0040;PBS_Server;Svr;tyrone-cluster;Scheduler was sent the command new
12/24/2012 23:15:11;0002;PBS_Server;Svr;PBS_Server;Torque Server Version = 3.0.5, loglevel = 0
12/24/2012 23:15:11;0040;PBS_Server;Svr;tyrone-cluster;Scheduler was sent the command new
12/24/2012 23:15:42;0040;PBS_Server;Svr;tyrone-cluster;Scheduler was sent the command new
12/24/2012 23:16:10;0040;PBS_Server;Svr;tyrone-cluster;Scheduler was sent the command new
12/24/2012 23:16:42;0040;PBS_Server;Svr;tyrone-cluster;Scheduler was sent the command new
12/24/2012 23:17:12;0040;PBS_Server;Svr;tyrone-cluster;Scheduler was sent the command new
12/24/2012 23:17:40;0040;PBS_Server;Svr;tyrone-cluster;Scheduler was sent the command new
12/24/2012 23:18:13;0040;PBS_Server;Svr;tyrone-cluster;Scheduler was sent the command new
12/24/2012 23:18:43;0040;PBS_Server;Svr;tyrone-cluster;Scheduler was sent the command new
12/24/2012 23:19:22;0040;PBS_Server;Svr;tyrone-cluster;Scheduler was sent the command new
12/24/2012 23:19:51;0040;PBS_Server;Svr;tyrone-cluster;Scheduler was sent the command new
12/24/2012 23:20:11;0002;PBS_Server;Svr;PBS_Server;Torque Server Version = 3.0.5, loglevel = 0
12/24/2012 23:20:22;0040;PBS_Server;Svr;tyrone-cluster;Scheduler was sent the command new
12/24/2012 23:20:52;0040;PBS_Server;Svr;tyrone-cluster;Scheduler was sent the command new
12/24/2012 23:21:22;0040;PBS_Server;Svr;tyrone-cluster;Scheduler was sent the command new
12/24/2012 23:21:52;0040;PBS_Server;Svr;tyrone-cluster;Scheduler was sent the command new
12/24/2012 23:22:22;0040;PBS_Server;Svr;tyrone-cluster;Scheduler was sent the command new
12/24/2012 23:22:52;0040;PBS_Server;Svr;tyrone-cluster;Scheduler was sent the command new
12/24/2012 23:23:22;0040;PBS_Server;Svr;tyrone-cluster;Scheduler was sent the command new
12/24/2012 23:23:52;0040;PBS_Server;Svr;tyrone-cluster;Scheduler was sent the command new
12/24/2012 23:24:23;0040;PBS_Server;Svr;tyrone-cluster;Scheduler was sent the command new
12/24/2012 23:24:53;0040;PBS_Server;Svr;tyrone-cluster;Scheduler was sent the command new
12/24/2012 23:25:11;0002;PBS_Server;Svr;PBS_Server;Torque Server Version = 3.0.5, loglevel = 0
12/24/2012 23:25:24;0040;PBS_Server;Svr;tyrone-cluster;Scheduler was sent the command new
12/24/2012 23:25:53;0040;PBS_Server;Svr;tyrone-cluster;Scheduler was sent the command new
12/24/2012 23:26:23;0040;PBS_Server;Svr;tyrone-cluster;Scheduler was sent the command new
12/24/2012 23:26:54;0040;PBS_Server;Svr;tyrone-cluster;Scheduler was sent the command new
12/24/2012 23:27:23;0040;PBS_Server;Svr;tyrone-cluster;Scheduler was sent the command new
12/24/2012 23:27:53;0040;PBS_Server;Svr;tyrone-cluster;Scheduler was sent the command new
12/24/2012 23:28:24;0040;PBS_Server;Svr;tyrone-cluster;Scheduler was sent the command new
12/24/2012 23:28:55;0040;PBS_Server;Svr;tyrone-cluster;Scheduler was sent the command new
12/24/2012 23:29:27;0040;PBS_Server;Svr;tyrone-cluster;Scheduler was sent the command new
12/24/2012 23:29:57;0040;PBS_Server;Svr;tyrone-cluster;Scheduler was sent the command new
12/24/2012 23:30:11;0002;PBS_Server;Svr;PBS_Server;Torque Server Version = 3.0.5, loglevel = 0
12/24/2012 23:30:25;0040;PBS_Server;Svr;tyrone-cluster;Scheduler was sent the command new
12/24/2012 23:30:57;0040;PBS_Server;Svr;tyrone-cluster;Scheduler was sent the command new
12/24/2012 23:31:27;0040;PBS_Server;Svr;tyrone-cluster;Scheduler was sent the command new
12/24/2012 23:31:55;0040;PBS_Server;Svr;tyrone-cluster;Scheduler was sent the command new
12/24/2012 23:32:27;0040;PBS_Server;Svr;tyrone-cluster;Scheduler was sent the command new
12/24/2012 23:32:57;0040;PBS_Server;Svr;tyrone-cluster;Scheduler was sent the command new
12/24/2012 23:33:25;0040;PBS_Server;Svr;tyrone-cluster;Scheduler was sent the command new
12/24/2012 23:33:57;0040;PBS_Server;Svr;tyrone-cluster;Scheduler was sent the command new
12/24/2012 23:34:28;0040;PBS_Server;Svr;tyrone-cluster;Scheduler was sent the command new
12/24/2012 23:35:06;0040;PBS_Server;Svr;tyrone-cluster;Scheduler was sent the command new
12/24/2012 23:35:11;0002;PBS_Server;Svr;PBS_Server;Torque Server Version = 3.0.5, loglevel = 0
12/24/2012 23:35:35;0040;PBS_Server;Svr;tyrone-cluster;Scheduler was sent the command new
12/24/2012 23:36:02;0040;PBS_Server;Svr;tyrone-cluster;Scheduler was sent the command new
12/24/2012 23:36:37;0040;PBS_Server;Svr;tyrone-cluster;Scheduler was sent the command new
12/24/2012 23:37:08;0040;PBS_Server;Svr;tyrone-cluster;Scheduler was sent the command new
12/24/2012 23:37:37;0040;PBS_Server;Svr;tyrone-cluster;Scheduler was sent the command new
12/24/2012 23:38:07;0040;PBS_Server;Svr;tyrone-cluster;Scheduler was sent the command new
12/24/2012 23:38:37;0040;PBS_Server;Svr;tyrone-cluster;Scheduler was sent the command new
12/24/2012 23:39:07;0040;PBS_Server;Svr;tyrone-cluster;Scheduler was sent the command new
12/24/2012 23:39:37;0040;PBS_Server;Svr;tyrone-cluster;Scheduler was sent the command new
12/24/2012 23:40:07;0040;PBS_Server;Svr;tyrone-cluster;Scheduler was sent the command new
12/24/2012 23:40:11;0002;PBS_Server;Svr;PBS_Server;Torque Server Version = 3.0.5, loglevel = 0
12/24/2012 23:40:37;0040;PBS_Server;Svr;tyrone-cluster;Scheduler was sent the command new
12/24/2012 23:41:07;0040;PBS_Server;Svr;tyrone-cluster;Scheduler was sent the command new
12/24/2012 23:41:38;0040;PBS_Server;Svr;tyrone-cluster;Scheduler was sent the command new
12/24/2012 23:42:08;0040;PBS_Server;Svr;tyrone-cluster;Scheduler was sent the command new
12/24/2012 23:42:39;0040;PBS_Server;Svr;tyrone-cluster;Scheduler was sent the command new
12/24/2012 23:43:08;0040;PBS_Server;Svr;tyrone-cluster;Scheduler was sent the command new
12/24/2012 23:43:38;0040;PBS_Server;Svr;tyrone-cluster;Scheduler was sent the command new
12/24/2012 23:44:09;0040;PBS_Server;Svr;tyrone-cluster;Scheduler was sent the command new
12/24/2012 23:44:38;0040;PBS_Server;Svr;tyrone-cluster;Scheduler was sent the command new
12/24/2012 23:45:08;0040;PBS_Server;Svr;tyrone-cluster;Scheduler was sent the command new
12/24/2012 23:45:11;0002;PBS_Server;Svr;PBS_Server;Torque Server Version = 3.0.5, loglevel = 0
12/24/2012 23:45:39;0040;PBS_Server;Svr;tyrone-cluster;Scheduler was sent the command new
12/24/2012 23:46:10;0040;PBS_Server;Svr;tyrone-cluster;Scheduler was sent the command new
12/24/2012 23:46:42;0040;PBS_Server;Svr;tyrone-cluster;Scheduler was sent the command new
12/24/2012 23:47:12;0040;PBS_Server;Svr;tyrone-cluster;Scheduler was sent the command new
12/24/2012 23:47:40;0040;PBS_Server;Svr;tyrone-cluster;Scheduler was sent the command new
12/24/2012 23:48:12;0040;PBS_Server;Svr;tyrone-cluster;Scheduler was sent the command new
12/24/2012 23:48:42;0040;PBS_Server;Svr;tyrone-cluster;Scheduler was sent the command new
12/24/2012 23:49:10;0040;PBS_Server;Svr;tyrone-cluster;Scheduler was sent the command new
12/24/2012 23:49:42;0040;PBS_Server;Svr;tyrone-cluster;Scheduler was sent the command new
12/24/2012 23:50:11;0002;PBS_Server;Svr;PBS_Server;Torque Server Version = 3.0.5, loglevel = 0
12/24/2012 23:50:12;0040;PBS_Server;Svr;tyrone-cluster;Scheduler was sent the command new
12/24/2012 23:50:51;0040;PBS_Server;Svr;tyrone-cluster;Scheduler was sent the command new
12/24/2012 23:51:20;0040;PBS_Server;Svr;tyrone-cluster;Scheduler was sent the command new
12/24/2012 23:51:47;0040;PBS_Server;Svr;tyrone-cluster;Scheduler was sent the command new
12/24/2012 23:52:22;0040;PBS_Server;Svr;tyrone-cluster;Scheduler was sent the command new
12/24/2012 23:52:52;0040;PBS_Server;Svr;tyrone-cluster;Scheduler was sent the command new
12/24/2012 23:53:22;0040;PBS_Server;Svr;tyrone-cluster;Scheduler was sent the command new
12/24/2012 23:53:52;0040;PBS_Server;Svr;tyrone-cluster;Scheduler was sent the command new
12/24/2012 23:54:23;0040;PBS_Server;Svr;tyrone-cluster;Scheduler was sent the command new
12/24/2012 23:54:52;0040;PBS_Server;Svr;tyrone-cluster;Scheduler was sent the command new
12/24/2012 23:55:11;0002;PBS_Server;Svr;PBS_Server;Torque Server Version = 3.0.5, loglevel = 0
12/24/2012 23:55:22;0040;PBS_Server;Svr;tyrone-cluster;Scheduler was sent the command new
12/24/2012 23:55:52;0040;PBS_Server;Svr;tyrone-cluster;Scheduler was sent the command new
12/24/2012 23:56:22;0040;PBS_Server;Svr;tyrone-cluster;Scheduler was sent the command new
12/24/2012 23:56:52;0040;PBS_Server;Svr;tyrone-cluster;Scheduler was sent the command new
12/24/2012 23:57:22;0040;PBS_Server;Svr;tyrone-cluster;Scheduler was sent the command new
12/24/2012 23:57:52;0040;PBS_Server;Svr;tyrone-cluster;Scheduler was sent the command new
12/24/2012 23:58:22;0040;PBS_Server;Svr;tyrone-cluster;Scheduler was sent the command new
12/24/2012 23:58:52;0040;PBS_Server;Svr;tyrone-cluster;Scheduler was sent the command new
12/24/2012 23:59:22;0040;PBS_Server;Svr;tyrone-cluster;Scheduler was sent the command new
12/24/2012 23:59:52;0040;PBS_Server;Svr;tyrone-cluster;Scheduler was sent the command new
12/25/2012 00:00:11;0002;PBS_Server;Svr;Log;Log closed
