12/08/2012 00:00:04;0002;PBS_Server;Svr;Log;Log opened
12/08/2012 00:00:04;0040;PBS_Server;Svr;tyrone-cluster;Scheduler was sent the command new
12/08/2012 00:00:33;0040;PBS_Server;Svr;tyrone-cluster;Scheduler was sent the command new
12/08/2012 00:01:03;0040;PBS_Server;Svr;tyrone-cluster;Scheduler was sent the command new
12/08/2012 00:01:34;0040;PBS_Server;Svr;tyrone-cluster;Scheduler was sent the command new
12/08/2012 00:02:03;0040;PBS_Server;Svr;tyrone-cluster;Scheduler was sent the command new
12/08/2012 00:02:33;0040;PBS_Server;Svr;tyrone-cluster;Scheduler was sent the command new
12/08/2012 00:03:04;0040;PBS_Server;Svr;tyrone-cluster;Scheduler was sent the command new
12/08/2012 00:03:09;0002;PBS_Server;Svr;PBS_Server;Torque Server Version = 3.0.5, loglevel = 0
12/08/2012 00:03:33;0040;PBS_Server;Svr;tyrone-cluster;Scheduler was sent the command new
12/08/2012 00:04:03;0040;PBS_Server;Svr;tyrone-cluster;Scheduler was sent the command new
12/08/2012 00:04:34;0040;PBS_Server;Svr;tyrone-cluster;Scheduler was sent the command new
12/08/2012 00:05:03;0040;PBS_Server;Svr;tyrone-cluster;Scheduler was sent the command new
12/08/2012 00:05:33;0040;PBS_Server;Svr;tyrone-cluster;Scheduler was sent the command new
12/08/2012 00:06:04;0040;PBS_Server;Svr;tyrone-cluster;Scheduler was sent the command new
12/08/2012 00:06:44;0040;PBS_Server;Svr;tyrone-cluster;Scheduler was sent the command new
12/08/2012 00:07:13;0040;PBS_Server;Svr;tyrone-cluster;Scheduler was sent the command new
12/08/2012 00:07:43;0040;PBS_Server;Svr;tyrone-cluster;Scheduler was sent the command new
12/08/2012 00:08:09;0002;PBS_Server;Svr;PBS_Server;Torque Server Version = 3.0.5, loglevel = 0
12/08/2012 00:08:14;0040;PBS_Server;Svr;tyrone-cluster;Scheduler was sent the command new
12/08/2012 00:08:44;0040;PBS_Server;Svr;tyrone-cluster;Scheduler was sent the command new
12/08/2012 00:09:16;0040;PBS_Server;Svr;tyrone-cluster;Scheduler was sent the command new
12/08/2012 00:09:44;0040;PBS_Server;Svr;tyrone-cluster;Scheduler was sent the command new
12/08/2012 00:10:15;0040;PBS_Server;Svr;tyrone-cluster;Scheduler was sent the command new
12/08/2012 00:10:46;0040;PBS_Server;Svr;tyrone-cluster;Scheduler was sent the command new
12/08/2012 00:11:17;0040;PBS_Server;Svr;tyrone-cluster;Scheduler was sent the command new
12/08/2012 00:11:48;0040;PBS_Server;Svr;tyrone-cluster;Scheduler was sent the command new
12/08/2012 00:12:18;0040;PBS_Server;Svr;tyrone-cluster;Scheduler was sent the command new
12/08/2012 00:12:49;0040;PBS_Server;Svr;tyrone-cluster;Scheduler was sent the command new
12/08/2012 00:13:09;0002;PBS_Server;Svr;PBS_Server;Torque Server Version = 3.0.5, loglevel = 0
12/08/2012 00:13:18;0040;PBS_Server;Svr;tyrone-cluster;Scheduler was sent the command new
12/08/2012 00:13:48;0040;PBS_Server;Svr;tyrone-cluster;Scheduler was sent the command new
12/08/2012 00:14:19;0040;PBS_Server;Svr;tyrone-cluster;Scheduler was sent the command new
12/08/2012 00:14:48;0040;PBS_Server;Svr;tyrone-cluster;Scheduler was sent the command new
12/08/2012 00:15:09;000d;PBS_Server;Job;16752.tyrone-cluster;Not sending email: User does not want mail of this type.
12/08/2012 00:15:09;0002;PBS_Server;Svr;Act;Account file /var/spool/torque/server_priv/accounting/20121208 opened
12/08/2012 00:15:09;0010;PBS_Server;Job;16752.tyrone-cluster;Exit_status=143 resources_used.cput=23:32:38 resources_used.mem=936504kb resources_used.vmem=10820084kb resources_used.walltime=02:00:29
12/08/2012 00:15:09;0008;PBS_Server;Job;NULL;on_job_exit valid pjob: 0x1d1ecb0 (substate=50)
12/08/2012 00:15:09;0008;PBS_Server;Job;NULL;on_job_exit valid pjob: 0x1d1ecb0 (substate=51)
12/08/2012 00:15:10;0008;PBS_Server;Job;NULL;on_job_exit valid pjob: 0x1d1ecb0 (substate=51)
12/08/2012 00:15:10;0008;PBS_Server;Job;NULL;on_job_exit valid pjob: 0x1d1ecb0 (substate=53)
12/08/2012 00:15:10;0100;PBS_Server;Job;16752.tyrone-cluster;dequeuing from idqueue, state COMPLETE
12/08/2012 00:15:10;0040;PBS_Server;Svr;tyrone-cluster;Scheduler was sent the command term
12/08/2012 00:15:16;000d;PBS_Server;Job;16753.tyrone-cluster;Not sending email: User does not want mail of this type.
12/08/2012 00:15:16;0010;PBS_Server;Job;16753.tyrone-cluster;Exit_status=174 resources_used.cput=22:52:07 resources_used.mem=2055556kb resources_used.vmem=11941808kb resources_used.walltime=01:58:32
12/08/2012 00:15:16;0008;PBS_Server;Job;NULL;on_job_exit valid pjob: 0x1cf3b50 (substate=50)
12/08/2012 00:15:16;0008;PBS_Server;Job;NULL;on_job_exit valid pjob: 0x1cf3b50 (substate=51)
12/08/2012 00:15:16;0008;PBS_Server;Job;NULL;on_job_exit valid pjob: 0x1cf3b50 (substate=51)
12/08/2012 00:15:16;0008;PBS_Server;Job;NULL;on_job_exit valid pjob: 0x1cf3b50 (substate=53)
12/08/2012 00:15:16;0100;PBS_Server;Job;16753.tyrone-cluster;dequeuing from idqueue, state COMPLETE
12/08/2012 00:15:16;0040;PBS_Server;Svr;tyrone-cluster;Scheduler was sent the command term
12/08/2012 00:15:19;0040;PBS_Server;Svr;tyrone-cluster;Scheduler was sent the command new
12/08/2012 00:15:49;0040;PBS_Server;Svr;tyrone-cluster;Scheduler was sent the command new
12/08/2012 00:16:18;0040;PBS_Server;Svr;tyrone-cluster;Scheduler was sent the command new
12/08/2012 00:16:49;0040;PBS_Server;Svr;tyrone-cluster;Scheduler was sent the command new
12/08/2012 00:17:19;0040;PBS_Server;Svr;tyrone-cluster;Scheduler was sent the command new
12/08/2012 00:17:48;0040;PBS_Server;Svr;tyrone-cluster;Scheduler was sent the command new
12/08/2012 00:18:09;0002;PBS_Server;Svr;PBS_Server;Torque Server Version = 3.0.5, loglevel = 0
12/08/2012 00:18:19;0040;PBS_Server;Svr;tyrone-cluster;Scheduler was sent the command new
12/08/2012 00:18:49;0040;PBS_Server;Svr;tyrone-cluster;Scheduler was sent the command new
12/08/2012 00:19:28;0040;PBS_Server;Svr;tyrone-cluster;Scheduler was sent the command new
12/08/2012 00:19:56;0040;PBS_Server;Svr;tyrone-cluster;Scheduler was sent the command new
12/08/2012 00:20:27;0040;PBS_Server;Svr;tyrone-cluster;Scheduler was sent the command new
12/08/2012 00:20:58;0040;PBS_Server;Svr;tyrone-cluster;Scheduler was sent the command new
12/08/2012 00:21:26;0040;PBS_Server;Svr;tyrone-cluster;Scheduler was sent the command new
12/08/2012 00:21:56;0040;PBS_Server;Svr;tyrone-cluster;Scheduler was sent the command new
12/08/2012 00:22:28;0040;PBS_Server;Svr;tyrone-cluster;Scheduler was sent the command new
12/08/2012 00:22:56;0040;PBS_Server;Svr;tyrone-cluster;Scheduler was sent the command new
12/08/2012 00:23:09;0002;PBS_Server;Svr;PBS_Server;Torque Server Version = 3.0.5, loglevel = 0
12/08/2012 00:23:27;0040;PBS_Server;Svr;tyrone-cluster;Scheduler was sent the command new
12/08/2012 00:23:58;0040;PBS_Server;Svr;tyrone-cluster;Scheduler was sent the command new
12/08/2012 00:24:26;0040;PBS_Server;Svr;tyrone-cluster;Scheduler was sent the command new
12/08/2012 00:24:57;0040;PBS_Server;Svr;tyrone-cluster;Scheduler was sent the command new
12/08/2012 00:25:28;0040;PBS_Server;Svr;tyrone-cluster;Scheduler was sent the command new
12/08/2012 00:25:58;0040;PBS_Server;Svr;tyrone-cluster;Scheduler was sent the command new
12/08/2012 00:26:28;0040;PBS_Server;Svr;tyrone-cluster;Scheduler was sent the command new
12/08/2012 00:26:59;0040;PBS_Server;Svr;tyrone-cluster;Scheduler was sent the command new
12/08/2012 00:27:29;0040;PBS_Server;Svr;tyrone-cluster;Scheduler was sent the command new
12/08/2012 00:28:01;0040;PBS_Server;Svr;tyrone-cluster;Scheduler was sent the command new
12/08/2012 00:28:09;0002;PBS_Server;Svr;PBS_Server;Torque Server Version = 3.0.5, loglevel = 0
12/08/2012 00:28:20;0008;PBS_Server;Job;16061.tyrone-cluster;Job deleted at request of csdsuben@tyrone-node9
12/08/2012 00:28:20;0008;PBS_Server;Job;16061.tyrone-cluster;Job sent signal SIGTERM on delete
12/08/2012 00:28:21;0008;PBS_Server;Job;16061.tyrone-cluster;Job deleted at request of csdsuben@tyrone-node9
12/08/2012 00:28:21;0008;PBS_Server;Job;16061.tyrone-cluster;Job sent signal SIGTERM on delete
12/08/2012 00:28:22;0008;PBS_Server;Job;16061.tyrone-cluster;Job sent signal SIGKILL on delete
12/08/2012 00:28:25;000d;PBS_Server;Job;16061.tyrone-cluster;Not sending email: User does not want mail of this type.
12/08/2012 00:28:25;0010;PBS_Server;Job;16061.tyrone-cluster;Exit_status=143 resources_used.cput=575:46:46 resources_used.mem=6341984kb resources_used.vmem=12645184kb resources_used.walltime=09:05:36
12/08/2012 00:28:25;0008;PBS_Server;Job;NULL;on_job_exit valid pjob: 0x1b9fe10 (substate=50)
12/08/2012 00:28:25;0008;PBS_Server;Job;NULL;on_job_exit valid pjob: 0x1b9fe10 (substate=51)
12/08/2012 00:28:28;0100;PBS_Server;Job;16735.tyrone-cluster;dequeuing from batch, state QUEUED
12/08/2012 00:28:28;0100;PBS_Server;Job;16735.tyrone-cluster;enqueuing into qp64, state 1 hop 1
12/08/2012 00:28:28;0008;PBS_Server;Job;NULL;on_job_exit valid pjob: 0x1b9fe10 (substate=51)
12/08/2012 00:28:28;0008;PBS_Server;Job;NULL;on_job_exit valid pjob: 0x1b9fe10 (substate=53)
12/08/2012 00:28:28;0100;PBS_Server;Job;16061.tyrone-cluster;dequeuing from qp64, state COMPLETE
12/08/2012 00:28:28;0040;PBS_Server;Svr;tyrone-cluster;Scheduler was sent the command term
12/08/2012 00:28:28;0008;PBS_Server;Job;16587.tyrone-cluster;Job Modified at request of Scheduler@tyrone-cluster
12/08/2012 00:28:28;0008;PBS_Server;Job;16587.tyrone-cluster;Job Run at request of Scheduler@tyrone-cluster
12/08/2012 00:28:29;0008;PBS_Server;Job;16735.tyrone-cluster;Job Modified at request of Scheduler@tyrone-cluster
12/08/2012 00:28:29;000d;PBS_Server;Job;16587.tyrone-cluster;Not sending email: User does not want mail of this type.
12/08/2012 00:28:29;0040;PBS_Server;Svr;tyrone-cluster;Scheduler was sent the command recyc
12/08/2012 00:28:34;0080;PBS_Server;Job;16061.tyrone-cluster;Unknown Job Id
12/08/2012 00:28:34;0080;PBS_Server;Req;req_reject;Reject reply code=15001(Unknown Job Id), aux=0, type=DeleteJob, from csdsuben@tyrone-node9
12/08/2012 00:28:34;0080;PBS_Server;Req;req_reject;Reject reply code=15001(Unknown Job Id), aux=0, type=LocateJob, from csdsuben@tyrone-node9
12/08/2012 00:29:00;0040;PBS_Server;Svr;tyrone-cluster;Scheduler was sent the command new
12/08/2012 00:29:11;000d;PBS_Server;Job;16587.tyrone-cluster;Not sending email: User does not want mail of this type.
12/08/2012 00:29:11;0010;PBS_Server;Job;16587.tyrone-cluster;Exit_status=174 resources_used.cput=00:40:39 resources_used.mem=1090788kb resources_used.vmem=37702516kb resources_used.walltime=00:00:43
12/08/2012 00:29:11;0008;PBS_Server;Job;NULL;on_job_exit valid pjob: 0x1b95a80 (substate=50)
12/08/2012 00:29:11;0008;PBS_Server;Job;NULL;on_job_exit valid pjob: 0x1b95a80 (substate=51)
12/08/2012 00:29:11;0008;PBS_Server;Job;NULL;on_job_exit valid pjob: 0x1b95a80 (substate=51)
12/08/2012 00:29:11;0008;PBS_Server;Job;NULL;on_job_exit valid pjob: 0x1b95a80 (substate=53)
12/08/2012 00:29:11;0100;PBS_Server;Job;16587.tyrone-cluster;dequeuing from qp64, state COMPLETE
12/08/2012 00:29:11;0040;PBS_Server;Svr;tyrone-cluster;Scheduler was sent the command term
12/08/2012 00:29:11;0008;PBS_Server;Job;16588.tyrone-cluster;Job Modified at request of Scheduler@tyrone-cluster
12/08/2012 00:29:11;0008;PBS_Server;Job;16588.tyrone-cluster;Job Run at request of Scheduler@tyrone-cluster
12/08/2012 00:29:11;0040;PBS_Server;Svr;tyrone-cluster;Scheduler was sent the command recyc
12/08/2012 00:29:11;000d;PBS_Server;Job;16588.tyrone-cluster;Not sending email: User does not want mail of this type.
12/08/2012 00:29:31;0100;PBS_Server;Job;16596.tyrone-cluster;dequeuing from batch, state QUEUED
12/08/2012 00:29:31;0100;PBS_Server;Job;16596.tyrone-cluster;enqueuing into qp64, state 1 hop 1
12/08/2012 00:29:32;0040;PBS_Server;Svr;tyrone-cluster;Scheduler was sent the command new
12/08/2012 00:29:32;0008;PBS_Server;Job;16596.tyrone-cluster;Job Modified at request of Scheduler@tyrone-cluster
12/08/2012 00:30:02;0040;PBS_Server;Svr;tyrone-cluster;Scheduler was sent the command new
12/08/2012 00:30:33;0040;PBS_Server;Svr;tyrone-cluster;Scheduler was sent the command new
12/08/2012 00:31:04;0040;PBS_Server;Svr;tyrone-cluster;Scheduler was sent the command new
12/08/2012 00:31:34;0040;PBS_Server;Svr;tyrone-cluster;Scheduler was sent the command new
12/08/2012 00:32:13;0040;PBS_Server;Svr;tyrone-cluster;Scheduler was sent the command new
12/08/2012 00:32:41;0040;PBS_Server;Svr;tyrone-cluster;Scheduler was sent the command new
12/08/2012 00:33:09;0002;PBS_Server;Svr;PBS_Server;Torque Server Version = 3.0.5, loglevel = 0
12/08/2012 00:33:12;0040;PBS_Server;Svr;tyrone-cluster;Scheduler was sent the command new
12/08/2012 00:33:43;0040;PBS_Server;Svr;tyrone-cluster;Scheduler was sent the command new
12/08/2012 00:34:11;0040;PBS_Server;Svr;tyrone-cluster;Scheduler was sent the command new
12/08/2012 00:34:42;0040;PBS_Server;Svr;tyrone-cluster;Scheduler was sent the command new
12/08/2012 00:35:13;0040;PBS_Server;Svr;tyrone-cluster;Scheduler was sent the command new
12/08/2012 00:35:42;0040;PBS_Server;Svr;tyrone-cluster;Scheduler was sent the command new
12/08/2012 00:36:12;0040;PBS_Server;Svr;tyrone-cluster;Scheduler was sent the command new
12/08/2012 00:36:43;0040;PBS_Server;Svr;tyrone-cluster;Scheduler was sent the command new
12/08/2012 00:37:13;0040;PBS_Server;Svr;tyrone-cluster;Scheduler was sent the command new
12/08/2012 00:37:42;0040;PBS_Server;Svr;tyrone-cluster;Scheduler was sent the command new
12/08/2012 00:38:09;0002;PBS_Server;Svr;PBS_Server;Torque Server Version = 3.0.5, loglevel = 0
12/08/2012 00:38:14;0040;PBS_Server;Svr;tyrone-cluster;Scheduler was sent the command new
12/08/2012 00:38:45;0040;PBS_Server;Svr;tyrone-cluster;Scheduler was sent the command new
12/08/2012 00:39:14;0040;PBS_Server;Svr;tyrone-cluster;Scheduler was sent the command new
12/08/2012 00:39:44;0040;PBS_Server;Svr;tyrone-cluster;Scheduler was sent the command new
12/08/2012 00:40:15;0040;PBS_Server;Svr;tyrone-cluster;Scheduler was sent the command new
12/08/2012 00:40:44;0040;PBS_Server;Svr;tyrone-cluster;Scheduler was sent the command new
12/08/2012 00:41:14;0040;PBS_Server;Svr;tyrone-cluster;Scheduler was sent the command new
12/08/2012 00:41:45;0040;PBS_Server;Svr;tyrone-cluster;Scheduler was sent the command new
12/08/2012 00:42:14;0040;PBS_Server;Svr;tyrone-cluster;Scheduler was sent the command new
12/08/2012 00:42:44;0040;PBS_Server;Svr;tyrone-cluster;Scheduler was sent the command new
12/08/2012 00:43:09;0002;PBS_Server;Svr;PBS_Server;Torque Server Version = 3.0.5, loglevel = 0
12/08/2012 00:43:15;0040;PBS_Server;Svr;tyrone-cluster;Scheduler was sent the command new
12/08/2012 00:43:44;0040;PBS_Server;Svr;tyrone-cluster;Scheduler was sent the command new
12/08/2012 00:44:14;0040;PBS_Server;Svr;tyrone-cluster;Scheduler was sent the command new
12/08/2012 00:44:45;0040;PBS_Server;Svr;tyrone-cluster;Scheduler was sent the command new
12/08/2012 00:45:14;0040;PBS_Server;Svr;tyrone-cluster;Scheduler was sent the command new
12/08/2012 00:45:44;0040;PBS_Server;Svr;tyrone-cluster;Scheduler was sent the command new
12/08/2012 00:46:15;0040;PBS_Server;Svr;tyrone-cluster;Scheduler was sent the command new
12/08/2012 00:46:44;0040;PBS_Server;Svr;tyrone-cluster;Scheduler was sent the command new
12/08/2012 00:47:14;0040;PBS_Server;Svr;tyrone-cluster;Scheduler was sent the command new
12/08/2012 00:47:45;0040;PBS_Server;Svr;tyrone-cluster;Scheduler was sent the command new
12/08/2012 00:48:09;0002;PBS_Server;Svr;PBS_Server;Torque Server Version = 3.0.5, loglevel = 0
12/08/2012 00:48:14;0040;PBS_Server;Svr;tyrone-cluster;Scheduler was sent the command new
12/08/2012 00:48:44;0040;PBS_Server;Svr;tyrone-cluster;Scheduler was sent the command new
12/08/2012 00:49:15;0040;PBS_Server;Svr;tyrone-cluster;Scheduler was sent the command new
12/08/2012 00:49:44;0040;PBS_Server;Svr;tyrone-cluster;Scheduler was sent the command new
12/08/2012 00:50:14;0040;PBS_Server;Svr;tyrone-cluster;Scheduler was sent the command new
12/08/2012 00:50:45;0040;PBS_Server;Svr;tyrone-cluster;Scheduler was sent the command new
12/08/2012 00:51:14;0040;PBS_Server;Svr;tyrone-cluster;Scheduler was sent the command new
12/08/2012 00:51:44;0040;PBS_Server;Svr;tyrone-cluster;Scheduler was sent the command new
12/08/2012 00:52:15;0040;PBS_Server;Svr;tyrone-cluster;Scheduler was sent the command new
12/08/2012 00:52:44;0040;PBS_Server;Svr;tyrone-cluster;Scheduler was sent the command new
12/08/2012 00:53:09;0002;PBS_Server;Svr;PBS_Server;Torque Server Version = 3.0.5, loglevel = 0
12/08/2012 00:53:14;0040;PBS_Server;Svr;tyrone-cluster;Scheduler was sent the command new
12/08/2012 00:53:45;0040;PBS_Server;Svr;tyrone-cluster;Scheduler was sent the command new
12/08/2012 00:54:14;0040;PBS_Server;Svr;tyrone-cluster;Scheduler was sent the command new
12/08/2012 00:54:44;0040;PBS_Server;Svr;tyrone-cluster;Scheduler was sent the command new
12/08/2012 00:55:15;0040;PBS_Server;Svr;tyrone-cluster;Scheduler was sent the command new
12/08/2012 00:55:44;0040;PBS_Server;Svr;tyrone-cluster;Scheduler was sent the command new
12/08/2012 00:56:14;0040;PBS_Server;Svr;tyrone-cluster;Scheduler was sent the command new
12/08/2012 00:56:45;0040;PBS_Server;Svr;tyrone-cluster;Scheduler was sent the command new
12/08/2012 00:57:14;0040;PBS_Server;Svr;tyrone-cluster;Scheduler was sent the command new
12/08/2012 00:57:44;0040;PBS_Server;Svr;tyrone-cluster;Scheduler was sent the command new
12/08/2012 00:58:09;0002;PBS_Server;Svr;PBS_Server;Torque Server Version = 3.0.5, loglevel = 0
12/08/2012 00:58:15;0040;PBS_Server;Svr;tyrone-cluster;Scheduler was sent the command new
12/08/2012 00:58:44;0040;PBS_Server;Svr;tyrone-cluster;Scheduler was sent the command new
12/08/2012 00:59:14;0040;PBS_Server;Svr;tyrone-cluster;Scheduler was sent the command new
12/08/2012 00:59:45;0040;PBS_Server;Svr;tyrone-cluster;Scheduler was sent the command new
12/08/2012 01:00:14;0040;PBS_Server;Svr;tyrone-cluster;Scheduler was sent the command new
12/08/2012 01:00:44;0040;PBS_Server;Svr;tyrone-cluster;Scheduler was sent the command new
12/08/2012 01:01:15;0040;PBS_Server;Svr;tyrone-cluster;Scheduler was sent the command new
12/08/2012 01:01:44;0040;PBS_Server;Svr;tyrone-cluster;Scheduler was sent the command new
12/08/2012 01:02:14;0040;PBS_Server;Svr;tyrone-cluster;Scheduler was sent the command new
12/08/2012 01:02:45;0040;PBS_Server;Svr;tyrone-cluster;Scheduler was sent the command new
12/08/2012 01:03:09;0002;PBS_Server;Svr;PBS_Server;Torque Server Version = 3.0.5, loglevel = 0
12/08/2012 01:03:14;0040;PBS_Server;Svr;tyrone-cluster;Scheduler was sent the command new
12/08/2012 01:03:44;0040;PBS_Server;Svr;tyrone-cluster;Scheduler was sent the command new
12/08/2012 01:04:15;0040;PBS_Server;Svr;tyrone-cluster;Scheduler was sent the command new
12/08/2012 01:04:44;0040;PBS_Server;Svr;tyrone-cluster;Scheduler was sent the command new
12/08/2012 01:05:14;0040;PBS_Server;Svr;tyrone-cluster;Scheduler was sent the command new
12/08/2012 01:05:45;0040;PBS_Server;Svr;tyrone-cluster;Scheduler was sent the command new
12/08/2012 01:06:14;0040;PBS_Server;Svr;tyrone-cluster;Scheduler was sent the command new
12/08/2012 01:06:44;0040;PBS_Server;Svr;tyrone-cluster;Scheduler was sent the command new
12/08/2012 01:07:15;0040;PBS_Server;Svr;tyrone-cluster;Scheduler was sent the command new
12/08/2012 01:07:44;0040;PBS_Server;Svr;tyrone-cluster;Scheduler was sent the command new
12/08/2012 01:08:09;0002;PBS_Server;Svr;PBS_Server;Torque Server Version = 3.0.5, loglevel = 0
12/08/2012 01:08:14;0040;PBS_Server;Svr;tyrone-cluster;Scheduler was sent the command new
12/08/2012 01:08:45;0040;PBS_Server;Svr;tyrone-cluster;Scheduler was sent the command new
12/08/2012 01:09:14;0040;PBS_Server;Svr;tyrone-cluster;Scheduler was sent the command new
12/08/2012 01:09:44;0040;PBS_Server;Svr;tyrone-cluster;Scheduler was sent the command new
12/08/2012 01:10:15;0040;PBS_Server;Svr;tyrone-cluster;Scheduler was sent the command new
12/08/2012 01:10:44;0040;PBS_Server;Svr;tyrone-cluster;Scheduler was sent the command new
12/08/2012 01:11:14;0040;PBS_Server;Svr;tyrone-cluster;Scheduler was sent the command new
12/08/2012 01:11:45;0040;PBS_Server;Svr;tyrone-cluster;Scheduler was sent the command new
12/08/2012 01:12:14;0040;PBS_Server;Svr;tyrone-cluster;Scheduler was sent the command new
12/08/2012 01:12:44;0040;PBS_Server;Svr;tyrone-cluster;Scheduler was sent the command new
12/08/2012 01:13:09;0002;PBS_Server;Svr;PBS_Server;Torque Server Version = 3.0.5, loglevel = 0
12/08/2012 01:13:15;0040;PBS_Server;Svr;tyrone-cluster;Scheduler was sent the command new
12/08/2012 01:13:44;0040;PBS_Server;Svr;tyrone-cluster;Scheduler was sent the command new
12/08/2012 01:14:14;0040;PBS_Server;Svr;tyrone-cluster;Scheduler was sent the command new
12/08/2012 01:14:45;0040;PBS_Server;Svr;tyrone-cluster;Scheduler was sent the command new
12/08/2012 01:15:14;0040;PBS_Server;Svr;tyrone-cluster;Scheduler was sent the command new
12/08/2012 01:15:44;0040;PBS_Server;Svr;tyrone-cluster;Scheduler was sent the command new
12/08/2012 01:16:15;0040;PBS_Server;Svr;tyrone-cluster;Scheduler was sent the command new
12/08/2012 01:16:44;0040;PBS_Server;Svr;tyrone-cluster;Scheduler was sent the command new
12/08/2012 01:17:14;0040;PBS_Server;Svr;tyrone-cluster;Scheduler was sent the command new
12/08/2012 01:17:45;0040;PBS_Server;Svr;tyrone-cluster;Scheduler was sent the command new
12/08/2012 01:18:09;0002;PBS_Server;Svr;PBS_Server;Torque Server Version = 3.0.5, loglevel = 0
12/08/2012 01:18:14;0040;PBS_Server;Svr;tyrone-cluster;Scheduler was sent the command new
12/08/2012 01:18:30;000d;PBS_Server;Job;16586.tyrone-cluster;Not sending email: User does not want mail of this type.
12/08/2012 01:18:30;0010;PBS_Server;Job;16586.tyrone-cluster;Exit_status=0 resources_used.cput=141:24:46 resources_used.mem=16560284kb resources_used.vmem=30339880kb resources_used.walltime=16:20:50
12/08/2012 01:18:30;0008;PBS_Server;Job;NULL;on_job_exit valid pjob: 0x1bb3ce0 (substate=50)
12/08/2012 01:18:30;0008;PBS_Server;Job;NULL;on_job_exit valid pjob: 0x1bb3ce0 (substate=51)
12/08/2012 01:18:30;0008;PBS_Server;Job;NULL;on_job_exit valid pjob: 0x1bb3ce0 (substate=51)
12/08/2012 01:18:30;0008;PBS_Server;Job;NULL;on_job_exit valid pjob: 0x1bb3ce0 (substate=53)
12/08/2012 01:18:30;0100;PBS_Server;Job;16586.tyrone-cluster;dequeuing from qp64, state COMPLETE
12/08/2012 01:18:30;0040;PBS_Server;Svr;tyrone-cluster;Scheduler was sent the command term
12/08/2012 01:18:30;0008;PBS_Server;Job;16595.tyrone-cluster;Job Modified at request of Scheduler@tyrone-cluster
12/08/2012 01:18:30;0008;PBS_Server;Job;16589.tyrone-cluster;Job Modified at request of Scheduler@tyrone-cluster
12/08/2012 01:18:30;0008;PBS_Server;Job;16589.tyrone-cluster;Job Run at request of Scheduler@tyrone-cluster
12/08/2012 01:18:30;0040;PBS_Server;Svr;tyrone-cluster;Scheduler was sent the command recyc
12/08/2012 01:18:30;000d;PBS_Server;Job;16589.tyrone-cluster;Not sending email: User does not want mail of this type.
12/08/2012 01:18:44;0040;PBS_Server;Svr;tyrone-cluster;Scheduler was sent the command new
12/08/2012 01:18:44;0008;PBS_Server;Job;16595.tyrone-cluster;Job Modified at request of Scheduler@tyrone-cluster
12/08/2012 01:19:15;0040;PBS_Server;Svr;tyrone-cluster;Scheduler was sent the command new
12/08/2012 01:19:44;0040;PBS_Server;Svr;tyrone-cluster;Scheduler was sent the command new
12/08/2012 01:20:14;0040;PBS_Server;Svr;tyrone-cluster;Scheduler was sent the command new
12/08/2012 01:20:45;0040;PBS_Server;Svr;tyrone-cluster;Scheduler was sent the command new
12/08/2012 01:21:14;0040;PBS_Server;Svr;tyrone-cluster;Scheduler was sent the command new
12/08/2012 01:21:44;0040;PBS_Server;Svr;tyrone-cluster;Scheduler was sent the command new
12/08/2012 01:22:15;0040;PBS_Server;Svr;tyrone-cluster;Scheduler was sent the command new
12/08/2012 01:22:44;0040;PBS_Server;Svr;tyrone-cluster;Scheduler was sent the command new
12/08/2012 01:23:09;0002;PBS_Server;Svr;PBS_Server;Torque Server Version = 3.0.5, loglevel = 0
12/08/2012 01:23:14;0040;PBS_Server;Svr;tyrone-cluster;Scheduler was sent the command new
12/08/2012 01:23:45;0040;PBS_Server;Svr;tyrone-cluster;Scheduler was sent the command new
12/08/2012 01:24:14;0040;PBS_Server;Svr;tyrone-cluster;Scheduler was sent the command new
12/08/2012 01:24:44;0040;PBS_Server;Svr;tyrone-cluster;Scheduler was sent the command new
12/08/2012 01:25:15;0040;PBS_Server;Svr;tyrone-cluster;Scheduler was sent the command new
12/08/2012 01:25:44;0040;PBS_Server;Svr;tyrone-cluster;Scheduler was sent the command new
12/08/2012 01:26:14;0040;PBS_Server;Svr;tyrone-cluster;Scheduler was sent the command new
12/08/2012 01:26:45;0040;PBS_Server;Svr;tyrone-cluster;Scheduler was sent the command new
12/08/2012 01:27:14;0040;PBS_Server;Svr;tyrone-cluster;Scheduler was sent the command new
12/08/2012 01:27:44;0040;PBS_Server;Svr;tyrone-cluster;Scheduler was sent the command new
12/08/2012 01:28:09;0002;PBS_Server;Svr;PBS_Server;Torque Server Version = 3.0.5, loglevel = 0
12/08/2012 01:28:15;0040;PBS_Server;Svr;tyrone-cluster;Scheduler was sent the command new
12/08/2012 01:28:44;0040;PBS_Server;Svr;tyrone-cluster;Scheduler was sent the command new
12/08/2012 01:29:14;0040;PBS_Server;Svr;tyrone-cluster;Scheduler was sent the command new
12/08/2012 01:29:45;0040;PBS_Server;Svr;tyrone-cluster;Scheduler was sent the command new
12/08/2012 01:30:14;0040;PBS_Server;Svr;tyrone-cluster;Scheduler was sent the command new
12/08/2012 01:30:44;0040;PBS_Server;Svr;tyrone-cluster;Scheduler was sent the command new
12/08/2012 01:31:15;0040;PBS_Server;Svr;tyrone-cluster;Scheduler was sent the command new
12/08/2012 01:31:44;0040;PBS_Server;Svr;tyrone-cluster;Scheduler was sent the command new
12/08/2012 01:32:14;0040;PBS_Server;Svr;tyrone-cluster;Scheduler was sent the command new
12/08/2012 01:32:45;0040;PBS_Server;Svr;tyrone-cluster;Scheduler was sent the command new
12/08/2012 01:33:09;0002;PBS_Server;Svr;PBS_Server;Torque Server Version = 3.0.5, loglevel = 0
12/08/2012 01:33:14;0040;PBS_Server;Svr;tyrone-cluster;Scheduler was sent the command new
12/08/2012 01:33:45;0040;PBS_Server;Svr;tyrone-cluster;Scheduler was sent the command new
12/08/2012 01:34:18;0040;PBS_Server;Svr;tyrone-cluster;Scheduler was sent the command new
12/08/2012 01:34:47;0040;PBS_Server;Svr;tyrone-cluster;Scheduler was sent the command new
12/08/2012 01:35:17;0040;PBS_Server;Svr;tyrone-cluster;Scheduler was sent the command new
12/08/2012 01:35:48;0040;PBS_Server;Svr;tyrone-cluster;Scheduler was sent the command new
12/08/2012 01:36:19;0040;PBS_Server;Svr;tyrone-cluster;Scheduler was sent the command new
12/08/2012 01:36:49;0040;PBS_Server;Svr;tyrone-cluster;Scheduler was sent the command new
12/08/2012 01:37:28;0040;PBS_Server;Svr;tyrone-cluster;Scheduler was sent the command new
12/08/2012 01:37:56;0040;PBS_Server;Svr;tyrone-cluster;Scheduler was sent the command new
12/08/2012 01:38:09;0002;PBS_Server;Svr;PBS_Server;Torque Server Version = 3.0.5, loglevel = 0
12/08/2012 01:38:26;0040;PBS_Server;Svr;tyrone-cluster;Scheduler was sent the command new
12/08/2012 01:38:58;0040;PBS_Server;Svr;tyrone-cluster;Scheduler was sent the command new
12/08/2012 01:39:29;0040;PBS_Server;Svr;tyrone-cluster;Scheduler was sent the command new
12/08/2012 01:39:57;0040;PBS_Server;Svr;tyrone-cluster;Scheduler was sent the command new
12/08/2012 01:40:29;0040;PBS_Server;Svr;tyrone-cluster;Scheduler was sent the command new
12/08/2012 01:41:00;0040;PBS_Server;Svr;tyrone-cluster;Scheduler was sent the command new
12/08/2012 01:41:29;0040;PBS_Server;Svr;tyrone-cluster;Scheduler was sent the command new
12/08/2012 01:41:59;0040;PBS_Server;Svr;tyrone-cluster;Scheduler was sent the command new
12/08/2012 01:42:30;0040;PBS_Server;Svr;tyrone-cluster;Scheduler was sent the command new
12/08/2012 01:42:59;0040;PBS_Server;Svr;tyrone-cluster;Scheduler was sent the command new
12/08/2012 01:43:09;0002;PBS_Server;Svr;PBS_Server;Torque Server Version = 3.0.5, loglevel = 0
12/08/2012 01:43:29;0040;PBS_Server;Svr;tyrone-cluster;Scheduler was sent the command new
12/08/2012 01:44:00;0040;PBS_Server;Svr;tyrone-cluster;Scheduler was sent the command new
12/08/2012 01:44:29;0040;PBS_Server;Svr;tyrone-cluster;Scheduler was sent the command new
12/08/2012 01:44:59;0040;PBS_Server;Svr;tyrone-cluster;Scheduler was sent the command new
12/08/2012 01:45:30;0040;PBS_Server;Svr;tyrone-cluster;Scheduler was sent the command new
12/08/2012 01:45:59;0040;PBS_Server;Svr;tyrone-cluster;Scheduler was sent the command new
12/08/2012 01:46:29;0040;PBS_Server;Svr;tyrone-cluster;Scheduler was sent the command new
12/08/2012 01:47:00;0040;PBS_Server;Svr;tyrone-cluster;Scheduler was sent the command new
12/08/2012 01:47:29;0040;PBS_Server;Svr;tyrone-cluster;Scheduler was sent the command new
12/08/2012 01:47:59;0040;PBS_Server;Svr;tyrone-cluster;Scheduler was sent the command new
12/08/2012 01:48:09;0002;PBS_Server;Svr;PBS_Server;Torque Server Version = 3.0.5, loglevel = 0
12/08/2012 01:48:30;0040;PBS_Server;Svr;tyrone-cluster;Scheduler was sent the command new
12/08/2012 01:48:59;0040;PBS_Server;Svr;tyrone-cluster;Scheduler was sent the command new
12/08/2012 01:49:29;0040;PBS_Server;Svr;tyrone-cluster;Scheduler was sent the command new
12/08/2012 01:50:00;0040;PBS_Server;Svr;tyrone-cluster;Scheduler was sent the command new
12/08/2012 01:50:29;0040;PBS_Server;Svr;tyrone-cluster;Scheduler was sent the command new
12/08/2012 01:51:01;0040;PBS_Server;Svr;tyrone-cluster;Scheduler was sent the command new
12/08/2012 01:51:34;0040;PBS_Server;Svr;tyrone-cluster;Scheduler was sent the command new
12/08/2012 01:52:03;0040;PBS_Server;Svr;tyrone-cluster;Scheduler was sent the command new
12/08/2012 01:52:33;0040;PBS_Server;Svr;tyrone-cluster;Scheduler was sent the command new
12/08/2012 01:53:04;0040;PBS_Server;Svr;tyrone-cluster;Scheduler was sent the command new
12/08/2012 01:53:09;0002;PBS_Server;Svr;PBS_Server;Torque Server Version = 3.0.5, loglevel = 0
12/08/2012 01:53:35;0040;PBS_Server;Svr;tyrone-cluster;Scheduler was sent the command new
12/08/2012 01:54:05;0040;PBS_Server;Svr;tyrone-cluster;Scheduler was sent the command new
12/08/2012 01:54:43;0040;PBS_Server;Svr;tyrone-cluster;Scheduler was sent the command new
12/08/2012 01:55:11;0040;PBS_Server;Svr;tyrone-cluster;Scheduler was sent the command new
12/08/2012 01:55:42;0040;PBS_Server;Svr;tyrone-cluster;Scheduler was sent the command new
12/08/2012 01:56:13;0040;PBS_Server;Svr;tyrone-cluster;Scheduler was sent the command new
12/08/2012 01:56:42;0040;PBS_Server;Svr;tyrone-cluster;Scheduler was sent the command new
12/08/2012 01:57:12;0040;PBS_Server;Svr;tyrone-cluster;Scheduler was sent the command new
12/08/2012 01:57:45;0040;PBS_Server;Svr;tyrone-cluster;Scheduler was sent the command new
12/08/2012 01:58:09;0002;PBS_Server;Svr;PBS_Server;Torque Server Version = 3.0.5, loglevel = 0
12/08/2012 01:58:16;0040;PBS_Server;Svr;tyrone-cluster;Scheduler was sent the command new
12/08/2012 01:58:45;0040;PBS_Server;Svr;tyrone-cluster;Scheduler was sent the command new
12/08/2012 01:59:15;0040;PBS_Server;Svr;tyrone-cluster;Scheduler was sent the command new
12/08/2012 01:59:46;0040;PBS_Server;Svr;tyrone-cluster;Scheduler was sent the command new
12/08/2012 02:00:15;0040;PBS_Server;Svr;tyrone-cluster;Scheduler was sent the command new
12/08/2012 02:00:45;0040;PBS_Server;Svr;tyrone-cluster;Scheduler was sent the command new
12/08/2012 02:01:16;0040;PBS_Server;Svr;tyrone-cluster;Scheduler was sent the command new
12/08/2012 02:01:45;0040;PBS_Server;Svr;tyrone-cluster;Scheduler was sent the command new
12/08/2012 02:01:56;0100;PBS_Server;Job;16754.tyrone-cluster;enqueuing into batch, state 1 hop 1
12/08/2012 02:01:56;0100;PBS_Server;Job;16754.tyrone-cluster;dequeuing from batch, state QUEUED
12/08/2012 02:01:56;0100;PBS_Server;Job;16754.tyrone-cluster;enqueuing into qp256, state 1 hop 1
12/08/2012 02:01:56;0008;PBS_Server;Job;16754.tyrone-cluster;Job Queued at request of chesaket@tyrone-cluster, owner = chesaket@tyrone-cluster, job name = script_1000_RTRT, queue = qp256
12/08/2012 02:01:56;0040;PBS_Server;Svr;tyrone-cluster;Scheduler was sent the command new
12/08/2012 02:01:56;0008;PBS_Server;Job;16754.tyrone-cluster;Job Modified at request of Scheduler@tyrone-cluster
12/08/2012 02:02:15;0040;PBS_Server;Svr;tyrone-cluster;Scheduler was sent the command new
12/08/2012 02:02:46;0040;PBS_Server;Svr;tyrone-cluster;Scheduler was sent the command new
12/08/2012 02:03:09;0002;PBS_Server;Svr;PBS_Server;Torque Server Version = 3.0.5, loglevel = 0
12/08/2012 02:03:15;0040;PBS_Server;Svr;tyrone-cluster;Scheduler was sent the command new
12/08/2012 02:03:45;0040;PBS_Server;Svr;tyrone-cluster;Scheduler was sent the command new
12/08/2012 02:04:16;0040;PBS_Server;Svr;tyrone-cluster;Scheduler was sent the command new
12/08/2012 02:04:45;0040;PBS_Server;Svr;tyrone-cluster;Scheduler was sent the command new
12/08/2012 02:05:15;0040;PBS_Server;Svr;tyrone-cluster;Scheduler was sent the command new
12/08/2012 02:05:46;0040;PBS_Server;Svr;tyrone-cluster;Scheduler was sent the command new
12/08/2012 02:06:15;0040;PBS_Server;Svr;tyrone-cluster;Scheduler was sent the command new
12/08/2012 02:06:45;0040;PBS_Server;Svr;tyrone-cluster;Scheduler was sent the command new
12/08/2012 02:07:16;0040;PBS_Server;Svr;tyrone-cluster;Scheduler was sent the command new
12/08/2012 02:07:45;0040;PBS_Server;Svr;tyrone-cluster;Scheduler was sent the command new
12/08/2012 02:08:09;0002;PBS_Server;Svr;PBS_Server;Torque Server Version = 3.0.5, loglevel = 0
12/08/2012 02:08:15;0040;PBS_Server;Svr;tyrone-cluster;Scheduler was sent the command new
12/08/2012 02:08:46;0040;PBS_Server;Svr;tyrone-cluster;Scheduler was sent the command new
12/08/2012 02:09:15;0040;PBS_Server;Svr;tyrone-cluster;Scheduler was sent the command new
12/08/2012 02:09:45;0040;PBS_Server;Svr;tyrone-cluster;Scheduler was sent the command new
12/08/2012 02:10:16;0040;PBS_Server;Svr;tyrone-cluster;Scheduler was sent the command new
12/08/2012 02:10:45;0040;PBS_Server;Svr;tyrone-cluster;Scheduler was sent the command new
12/08/2012 02:11:15;0040;PBS_Server;Svr;tyrone-cluster;Scheduler was sent the command new
12/08/2012 02:11:46;0040;PBS_Server;Svr;tyrone-cluster;Scheduler was sent the command new
12/08/2012 02:12:15;0040;PBS_Server;Svr;tyrone-cluster;Scheduler was sent the command new
12/08/2012 02:12:45;0040;PBS_Server;Svr;tyrone-cluster;Scheduler was sent the command new
12/08/2012 02:13:09;0002;PBS_Server;Svr;PBS_Server;Torque Server Version = 3.0.5, loglevel = 0
12/08/2012 02:13:16;0040;PBS_Server;Svr;tyrone-cluster;Scheduler was sent the command new
12/08/2012 02:13:45;0040;PBS_Server;Svr;tyrone-cluster;Scheduler was sent the command new
12/08/2012 02:14:15;0040;PBS_Server;Svr;tyrone-cluster;Scheduler was sent the command new
12/08/2012 02:14:46;0040;PBS_Server;Svr;tyrone-cluster;Scheduler was sent the command new
12/08/2012 02:15:15;0040;PBS_Server;Svr;tyrone-cluster;Scheduler was sent the command new
12/08/2012 02:15:45;0040;PBS_Server;Svr;tyrone-cluster;Scheduler was sent the command new
12/08/2012 02:16:17;0040;PBS_Server;Svr;tyrone-cluster;Scheduler was sent the command new
12/08/2012 02:16:46;0040;PBS_Server;Svr;tyrone-cluster;Scheduler was sent the command new
12/08/2012 02:17:16;0040;PBS_Server;Svr;tyrone-cluster;Scheduler was sent the command new
12/08/2012 02:17:47;0040;PBS_Server;Svr;tyrone-cluster;Scheduler was sent the command new
12/08/2012 02:18:09;0002;PBS_Server;Svr;PBS_Server;Torque Server Version = 3.0.5, loglevel = 0
12/08/2012 02:18:16;0040;PBS_Server;Svr;tyrone-cluster;Scheduler was sent the command new
12/08/2012 02:18:46;0040;PBS_Server;Svr;tyrone-cluster;Scheduler was sent the command new
12/08/2012 02:19:17;0040;PBS_Server;Svr;tyrone-cluster;Scheduler was sent the command new
12/08/2012 02:19:46;0040;PBS_Server;Svr;tyrone-cluster;Scheduler was sent the command new
12/08/2012 02:20:16;0040;PBS_Server;Svr;tyrone-cluster;Scheduler was sent the command new
12/08/2012 02:20:47;0040;PBS_Server;Svr;tyrone-cluster;Scheduler was sent the command new
12/08/2012 02:21:16;0040;PBS_Server;Svr;tyrone-cluster;Scheduler was sent the command new
12/08/2012 02:21:46;0040;PBS_Server;Svr;tyrone-cluster;Scheduler was sent the command new
12/08/2012 02:22:17;0040;PBS_Server;Svr;tyrone-cluster;Scheduler was sent the command new
12/08/2012 02:22:46;0040;PBS_Server;Svr;tyrone-cluster;Scheduler was sent the command new
12/08/2012 02:23:09;0002;PBS_Server;Svr;PBS_Server;Torque Server Version = 3.0.5, loglevel = 0
12/08/2012 02:23:16;0040;PBS_Server;Svr;tyrone-cluster;Scheduler was sent the command new
12/08/2012 02:23:47;0040;PBS_Server;Svr;tyrone-cluster;Scheduler was sent the command new
12/08/2012 02:24:16;0040;PBS_Server;Svr;tyrone-cluster;Scheduler was sent the command new
12/08/2012 02:24:46;0040;PBS_Server;Svr;tyrone-cluster;Scheduler was sent the command new
12/08/2012 02:25:17;0040;PBS_Server;Svr;tyrone-cluster;Scheduler was sent the command new
12/08/2012 02:25:46;0040;PBS_Server;Svr;tyrone-cluster;Scheduler was sent the command new
12/08/2012 02:26:16;0040;PBS_Server;Svr;tyrone-cluster;Scheduler was sent the command new
12/08/2012 02:26:47;0040;PBS_Server;Svr;tyrone-cluster;Scheduler was sent the command new
12/08/2012 02:27:16;0040;PBS_Server;Svr;tyrone-cluster;Scheduler was sent the command new
12/08/2012 02:27:46;0040;PBS_Server;Svr;tyrone-cluster;Scheduler was sent the command new
12/08/2012 02:28:09;0002;PBS_Server;Svr;PBS_Server;Torque Server Version = 3.0.5, loglevel = 0
12/08/2012 02:28:17;0040;PBS_Server;Svr;tyrone-cluster;Scheduler was sent the command new
12/08/2012 02:28:46;0040;PBS_Server;Svr;tyrone-cluster;Scheduler was sent the command new
12/08/2012 02:29:16;0040;PBS_Server;Svr;tyrone-cluster;Scheduler was sent the command new
12/08/2012 02:29:47;0040;PBS_Server;Svr;tyrone-cluster;Scheduler was sent the command new
12/08/2012 02:30:16;0040;PBS_Server;Svr;tyrone-cluster;Scheduler was sent the command new
12/08/2012 02:30:46;0040;PBS_Server;Svr;tyrone-cluster;Scheduler was sent the command new
12/08/2012 02:31:17;0040;PBS_Server;Svr;tyrone-cluster;Scheduler was sent the command new
12/08/2012 02:31:46;0040;PBS_Server;Svr;tyrone-cluster;Scheduler was sent the command new
12/08/2012 02:32:16;0040;PBS_Server;Svr;tyrone-cluster;Scheduler was sent the command new
12/08/2012 02:32:47;0040;PBS_Server;Svr;tyrone-cluster;Scheduler was sent the command new
12/08/2012 02:33:09;0002;PBS_Server;Svr;PBS_Server;Torque Server Version = 3.0.5, loglevel = 0
12/08/2012 02:33:16;0040;PBS_Server;Svr;tyrone-cluster;Scheduler was sent the command new
12/08/2012 02:33:46;0040;PBS_Server;Svr;tyrone-cluster;Scheduler was sent the command new
12/08/2012 02:34:17;0040;PBS_Server;Svr;tyrone-cluster;Scheduler was sent the command new
12/08/2012 02:34:46;0040;PBS_Server;Svr;tyrone-cluster;Scheduler was sent the command new
12/08/2012 02:35:16;0040;PBS_Server;Svr;tyrone-cluster;Scheduler was sent the command new
12/08/2012 02:35:47;0040;PBS_Server;Svr;tyrone-cluster;Scheduler was sent the command new
12/08/2012 02:36:16;0040;PBS_Server;Svr;tyrone-cluster;Scheduler was sent the command new
12/08/2012 02:36:46;0040;PBS_Server;Svr;tyrone-cluster;Scheduler was sent the command new
12/08/2012 02:37:17;0040;PBS_Server;Svr;tyrone-cluster;Scheduler was sent the command new
12/08/2012 02:37:46;0040;PBS_Server;Svr;tyrone-cluster;Scheduler was sent the command new
12/08/2012 02:38:09;0002;PBS_Server;Svr;PBS_Server;Torque Server Version = 3.0.5, loglevel = 0
12/08/2012 02:38:16;0040;PBS_Server;Svr;tyrone-cluster;Scheduler was sent the command new
12/08/2012 02:38:47;0040;PBS_Server;Svr;tyrone-cluster;Scheduler was sent the command new
12/08/2012 02:39:16;0040;PBS_Server;Svr;tyrone-cluster;Scheduler was sent the command new
12/08/2012 02:39:46;0040;PBS_Server;Svr;tyrone-cluster;Scheduler was sent the command new
12/08/2012 02:40:17;0040;PBS_Server;Svr;tyrone-cluster;Scheduler was sent the command new
12/08/2012 02:40:46;0040;PBS_Server;Svr;tyrone-cluster;Scheduler was sent the command new
12/08/2012 02:41:16;0040;PBS_Server;Svr;tyrone-cluster;Scheduler was sent the command new
12/08/2012 02:41:47;0040;PBS_Server;Svr;tyrone-cluster;Scheduler was sent the command new
12/08/2012 02:42:16;0040;PBS_Server;Svr;tyrone-cluster;Scheduler was sent the command new
12/08/2012 02:42:46;0040;PBS_Server;Svr;tyrone-cluster;Scheduler was sent the command new
12/08/2012 02:43:09;0002;PBS_Server;Svr;PBS_Server;Torque Server Version = 3.0.5, loglevel = 0
12/08/2012 02:43:17;0040;PBS_Server;Svr;tyrone-cluster;Scheduler was sent the command new
12/08/2012 02:43:46;0040;PBS_Server;Svr;tyrone-cluster;Scheduler was sent the command new
12/08/2012 02:44:16;0040;PBS_Server;Svr;tyrone-cluster;Scheduler was sent the command new
12/08/2012 02:44:47;0040;PBS_Server;Svr;tyrone-cluster;Scheduler was sent the command new
12/08/2012 02:45:16;0040;PBS_Server;Svr;tyrone-cluster;Scheduler was sent the command new
12/08/2012 02:45:46;0040;PBS_Server;Svr;tyrone-cluster;Scheduler was sent the command new
12/08/2012 02:46:17;0040;PBS_Server;Svr;tyrone-cluster;Scheduler was sent the command new
12/08/2012 02:46:46;0040;PBS_Server;Svr;tyrone-cluster;Scheduler was sent the command new
12/08/2012 02:47:16;0040;PBS_Server;Svr;tyrone-cluster;Scheduler was sent the command new
12/08/2012 02:47:47;0040;PBS_Server;Svr;tyrone-cluster;Scheduler was sent the command new
12/08/2012 02:48:09;0002;PBS_Server;Svr;PBS_Server;Torque Server Version = 3.0.5, loglevel = 0
12/08/2012 02:48:16;0040;PBS_Server;Svr;tyrone-cluster;Scheduler was sent the command new
12/08/2012 02:48:46;0040;PBS_Server;Svr;tyrone-cluster;Scheduler was sent the command new
12/08/2012 02:49:17;0040;PBS_Server;Svr;tyrone-cluster;Scheduler was sent the command new
12/08/2012 02:49:46;0040;PBS_Server;Svr;tyrone-cluster;Scheduler was sent the command new
12/08/2012 02:50:16;0040;PBS_Server;Svr;tyrone-cluster;Scheduler was sent the command new
12/08/2012 02:50:47;0040;PBS_Server;Svr;tyrone-cluster;Scheduler was sent the command new
12/08/2012 02:51:16;0040;PBS_Server;Svr;tyrone-cluster;Scheduler was sent the command new
12/08/2012 02:51:46;0040;PBS_Server;Svr;tyrone-cluster;Scheduler was sent the command new
12/08/2012 02:52:17;0040;PBS_Server;Svr;tyrone-cluster;Scheduler was sent the command new
12/08/2012 02:52:46;0040;PBS_Server;Svr;tyrone-cluster;Scheduler was sent the command new
12/08/2012 02:53:09;0002;PBS_Server;Svr;PBS_Server;Torque Server Version = 3.0.5, loglevel = 0
12/08/2012 02:53:16;0040;PBS_Server;Svr;tyrone-cluster;Scheduler was sent the command new
12/08/2012 02:53:47;0040;PBS_Server;Svr;tyrone-cluster;Scheduler was sent the command new
12/08/2012 02:54:16;0040;PBS_Server;Svr;tyrone-cluster;Scheduler was sent the command new
12/08/2012 02:54:46;0040;PBS_Server;Svr;tyrone-cluster;Scheduler was sent the command new
12/08/2012 02:55:17;0040;PBS_Server;Svr;tyrone-cluster;Scheduler was sent the command new
12/08/2012 02:55:46;0040;PBS_Server;Svr;tyrone-cluster;Scheduler was sent the command new
12/08/2012 02:56:16;0040;PBS_Server;Svr;tyrone-cluster;Scheduler was sent the command new
12/08/2012 02:56:47;0040;PBS_Server;Svr;tyrone-cluster;Scheduler was sent the command new
12/08/2012 02:57:16;0040;PBS_Server;Svr;tyrone-cluster;Scheduler was sent the command new
12/08/2012 02:57:46;0040;PBS_Server;Svr;tyrone-cluster;Scheduler was sent the command new
12/08/2012 02:58:09;0002;PBS_Server;Svr;PBS_Server;Torque Server Version = 3.0.5, loglevel = 0
12/08/2012 02:58:17;0040;PBS_Server;Svr;tyrone-cluster;Scheduler was sent the command new
12/08/2012 02:58:46;0040;PBS_Server;Svr;tyrone-cluster;Scheduler was sent the command new
12/08/2012 02:59:16;0040;PBS_Server;Svr;tyrone-cluster;Scheduler was sent the command new
12/08/2012 02:59:47;0040;PBS_Server;Svr;tyrone-cluster;Scheduler was sent the command new
12/08/2012 03:00:16;0040;PBS_Server;Svr;tyrone-cluster;Scheduler was sent the command new
12/08/2012 03:00:46;0040;PBS_Server;Svr;tyrone-cluster;Scheduler was sent the command new
12/08/2012 03:01:17;0040;PBS_Server;Svr;tyrone-cluster;Scheduler was sent the command new
12/08/2012 03:01:46;0040;PBS_Server;Svr;tyrone-cluster;Scheduler was sent the command new
12/08/2012 03:02:16;0040;PBS_Server;Svr;tyrone-cluster;Scheduler was sent the command new
12/08/2012 03:02:47;0040;PBS_Server;Svr;tyrone-cluster;Scheduler was sent the command new
12/08/2012 03:03:09;0002;PBS_Server;Svr;PBS_Server;Torque Server Version = 3.0.5, loglevel = 0
12/08/2012 03:03:16;0040;PBS_Server;Svr;tyrone-cluster;Scheduler was sent the command new
12/08/2012 03:03:46;0040;PBS_Server;Svr;tyrone-cluster;Scheduler was sent the command new
12/08/2012 03:04:17;0040;PBS_Server;Svr;tyrone-cluster;Scheduler was sent the command new
12/08/2012 03:04:46;0040;PBS_Server;Svr;tyrone-cluster;Scheduler was sent the command new
12/08/2012 03:05:16;0040;PBS_Server;Svr;tyrone-cluster;Scheduler was sent the command new
12/08/2012 03:05:47;0040;PBS_Server;Svr;tyrone-cluster;Scheduler was sent the command new
12/08/2012 03:06:16;0040;PBS_Server;Svr;tyrone-cluster;Scheduler was sent the command new
12/08/2012 03:06:46;0040;PBS_Server;Svr;tyrone-cluster;Scheduler was sent the command new
12/08/2012 03:07:17;0040;PBS_Server;Svr;tyrone-cluster;Scheduler was sent the command new
12/08/2012 03:07:46;0040;PBS_Server;Svr;tyrone-cluster;Scheduler was sent the command new
12/08/2012 03:08:09;0002;PBS_Server;Svr;PBS_Server;Torque Server Version = 3.0.5, loglevel = 0
12/08/2012 03:08:16;0040;PBS_Server;Svr;tyrone-cluster;Scheduler was sent the command new
12/08/2012 03:08:47;0040;PBS_Server;Svr;tyrone-cluster;Scheduler was sent the command new
12/08/2012 03:09:16;0040;PBS_Server;Svr;tyrone-cluster;Scheduler was sent the command new
12/08/2012 03:09:46;0040;PBS_Server;Svr;tyrone-cluster;Scheduler was sent the command new
12/08/2012 03:10:17;0040;PBS_Server;Svr;tyrone-cluster;Scheduler was sent the command new
12/08/2012 03:10:46;0040;PBS_Server;Svr;tyrone-cluster;Scheduler was sent the command new
12/08/2012 03:11:16;0040;PBS_Server;Svr;tyrone-cluster;Scheduler was sent the command new
12/08/2012 03:11:47;0040;PBS_Server;Svr;tyrone-cluster;Scheduler was sent the command new
12/08/2012 03:12:16;0040;PBS_Server;Svr;tyrone-cluster;Scheduler was sent the command new
12/08/2012 03:12:46;0040;PBS_Server;Svr;tyrone-cluster;Scheduler was sent the command new
12/08/2012 03:13:09;0002;PBS_Server;Svr;PBS_Server;Torque Server Version = 3.0.5, loglevel = 0
12/08/2012 03:13:17;0040;PBS_Server;Svr;tyrone-cluster;Scheduler was sent the command new
12/08/2012 03:13:46;0040;PBS_Server;Svr;tyrone-cluster;Scheduler was sent the command new
12/08/2012 03:14:16;0040;PBS_Server;Svr;tyrone-cluster;Scheduler was sent the command new
12/08/2012 03:14:47;0040;PBS_Server;Svr;tyrone-cluster;Scheduler was sent the command new
12/08/2012 03:15:16;0040;PBS_Server;Svr;tyrone-cluster;Scheduler was sent the command new
12/08/2012 03:15:46;0040;PBS_Server;Svr;tyrone-cluster;Scheduler was sent the command new
12/08/2012 03:16:17;0040;PBS_Server;Svr;tyrone-cluster;Scheduler was sent the command new
12/08/2012 03:16:46;0040;PBS_Server;Svr;tyrone-cluster;Scheduler was sent the command new
12/08/2012 03:17:16;0040;PBS_Server;Svr;tyrone-cluster;Scheduler was sent the command new
12/08/2012 03:17:47;0040;PBS_Server;Svr;tyrone-cluster;Scheduler was sent the command new
12/08/2012 03:18:09;0002;PBS_Server;Svr;PBS_Server;Torque Server Version = 3.0.5, loglevel = 0
12/08/2012 03:18:16;0040;PBS_Server;Svr;tyrone-cluster;Scheduler was sent the command new
12/08/2012 03:18:46;0040;PBS_Server;Svr;tyrone-cluster;Scheduler was sent the command new
12/08/2012 03:19:17;0040;PBS_Server;Svr;tyrone-cluster;Scheduler was sent the command new
12/08/2012 03:19:46;0040;PBS_Server;Svr;tyrone-cluster;Scheduler was sent the command new
12/08/2012 03:20:16;0040;PBS_Server;Svr;tyrone-cluster;Scheduler was sent the command new
12/08/2012 03:20:47;0040;PBS_Server;Svr;tyrone-cluster;Scheduler was sent the command new
12/08/2012 03:21:16;0040;PBS_Server;Svr;tyrone-cluster;Scheduler was sent the command new
12/08/2012 03:21:46;0040;PBS_Server;Svr;tyrone-cluster;Scheduler was sent the command new
12/08/2012 03:22:17;0040;PBS_Server;Svr;tyrone-cluster;Scheduler was sent the command new
12/08/2012 03:22:46;0040;PBS_Server;Svr;tyrone-cluster;Scheduler was sent the command new
12/08/2012 03:23:09;0002;PBS_Server;Svr;PBS_Server;Torque Server Version = 3.0.5, loglevel = 0
12/08/2012 03:23:16;0040;PBS_Server;Svr;tyrone-cluster;Scheduler was sent the command new
12/08/2012 03:23:47;0040;PBS_Server;Svr;tyrone-cluster;Scheduler was sent the command new
12/08/2012 03:24:16;0040;PBS_Server;Svr;tyrone-cluster;Scheduler was sent the command new
12/08/2012 03:24:46;0040;PBS_Server;Svr;tyrone-cluster;Scheduler was sent the command new
12/08/2012 03:25:17;0040;PBS_Server;Svr;tyrone-cluster;Scheduler was sent the command new
12/08/2012 03:25:46;0040;PBS_Server;Svr;tyrone-cluster;Scheduler was sent the command new
12/08/2012 03:26:16;0040;PBS_Server;Svr;tyrone-cluster;Scheduler was sent the command new
12/08/2012 03:26:47;0040;PBS_Server;Svr;tyrone-cluster;Scheduler was sent the command new
12/08/2012 03:27:16;0040;PBS_Server;Svr;tyrone-cluster;Scheduler was sent the command new
12/08/2012 03:27:46;0040;PBS_Server;Svr;tyrone-cluster;Scheduler was sent the command new
12/08/2012 03:28:09;0002;PBS_Server;Svr;PBS_Server;Torque Server Version = 3.0.5, loglevel = 0
12/08/2012 03:28:17;0040;PBS_Server;Svr;tyrone-cluster;Scheduler was sent the command new
12/08/2012 03:28:46;0040;PBS_Server;Svr;tyrone-cluster;Scheduler was sent the command new
12/08/2012 03:29:16;0040;PBS_Server;Svr;tyrone-cluster;Scheduler was sent the command new
12/08/2012 03:29:47;0040;PBS_Server;Svr;tyrone-cluster;Scheduler was sent the command new
12/08/2012 03:30:16;0040;PBS_Server;Svr;tyrone-cluster;Scheduler was sent the command new
12/08/2012 03:30:46;0040;PBS_Server;Svr;tyrone-cluster;Scheduler was sent the command new
12/08/2012 03:31:17;0040;PBS_Server;Svr;tyrone-cluster;Scheduler was sent the command new
12/08/2012 03:31:46;0040;PBS_Server;Svr;tyrone-cluster;Scheduler was sent the command new
12/08/2012 03:32:16;0040;PBS_Server;Svr;tyrone-cluster;Scheduler was sent the command new
12/08/2012 03:32:47;0040;PBS_Server;Svr;tyrone-cluster;Scheduler was sent the command new
12/08/2012 03:33:09;0002;PBS_Server;Svr;PBS_Server;Torque Server Version = 3.0.5, loglevel = 0
12/08/2012 03:33:16;0040;PBS_Server;Svr;tyrone-cluster;Scheduler was sent the command new
12/08/2012 03:33:46;0040;PBS_Server;Svr;tyrone-cluster;Scheduler was sent the command new
12/08/2012 03:34:17;0040;PBS_Server;Svr;tyrone-cluster;Scheduler was sent the command new
12/08/2012 03:34:46;0040;PBS_Server;Svr;tyrone-cluster;Scheduler was sent the command new
12/08/2012 03:35:16;0040;PBS_Server;Svr;tyrone-cluster;Scheduler was sent the command new
12/08/2012 03:35:47;0040;PBS_Server;Svr;tyrone-cluster;Scheduler was sent the command new
12/08/2012 03:36:16;0040;PBS_Server;Svr;tyrone-cluster;Scheduler was sent the command new
12/08/2012 03:36:46;0040;PBS_Server;Svr;tyrone-cluster;Scheduler was sent the command new
12/08/2012 03:37:17;0040;PBS_Server;Svr;tyrone-cluster;Scheduler was sent the command new
12/08/2012 03:37:46;0040;PBS_Server;Svr;tyrone-cluster;Scheduler was sent the command new
12/08/2012 03:38:09;0002;PBS_Server;Svr;PBS_Server;Torque Server Version = 3.0.5, loglevel = 0
12/08/2012 03:38:16;0040;PBS_Server;Svr;tyrone-cluster;Scheduler was sent the command new
12/08/2012 03:38:47;0040;PBS_Server;Svr;tyrone-cluster;Scheduler was sent the command new
12/08/2012 03:39:16;0040;PBS_Server;Svr;tyrone-cluster;Scheduler was sent the command new
12/08/2012 03:39:46;0040;PBS_Server;Svr;tyrone-cluster;Scheduler was sent the command new
12/08/2012 03:40:17;0040;PBS_Server;Svr;tyrone-cluster;Scheduler was sent the command new
12/08/2012 03:40:46;0040;PBS_Server;Svr;tyrone-cluster;Scheduler was sent the command new
12/08/2012 03:41:16;0040;PBS_Server;Svr;tyrone-cluster;Scheduler was sent the command new
12/08/2012 03:41:47;0040;PBS_Server;Svr;tyrone-cluster;Scheduler was sent the command new
12/08/2012 03:42:16;0040;PBS_Server;Svr;tyrone-cluster;Scheduler was sent the command new
12/08/2012 03:42:46;0040;PBS_Server;Svr;tyrone-cluster;Scheduler was sent the command new
12/08/2012 03:43:09;0002;PBS_Server;Svr;PBS_Server;Torque Server Version = 3.0.5, loglevel = 0
12/08/2012 03:43:17;0040;PBS_Server;Svr;tyrone-cluster;Scheduler was sent the command new
12/08/2012 03:43:46;0040;PBS_Server;Svr;tyrone-cluster;Scheduler was sent the command new
12/08/2012 03:44:16;0040;PBS_Server;Svr;tyrone-cluster;Scheduler was sent the command new
12/08/2012 03:44:47;0040;PBS_Server;Svr;tyrone-cluster;Scheduler was sent the command new
12/08/2012 03:45:16;0040;PBS_Server;Svr;tyrone-cluster;Scheduler was sent the command new
12/08/2012 03:45:46;0040;PBS_Server;Svr;tyrone-cluster;Scheduler was sent the command new
12/08/2012 03:46:17;0040;PBS_Server;Svr;tyrone-cluster;Scheduler was sent the command new
12/08/2012 03:46:46;0040;PBS_Server;Svr;tyrone-cluster;Scheduler was sent the command new
12/08/2012 03:47:16;0040;PBS_Server;Svr;tyrone-cluster;Scheduler was sent the command new
12/08/2012 03:47:47;0040;PBS_Server;Svr;tyrone-cluster;Scheduler was sent the command new
12/08/2012 03:48:09;0002;PBS_Server;Svr;PBS_Server;Torque Server Version = 3.0.5, loglevel = 0
12/08/2012 03:48:16;0040;PBS_Server;Svr;tyrone-cluster;Scheduler was sent the command new
12/08/2012 03:48:46;0040;PBS_Server;Svr;tyrone-cluster;Scheduler was sent the command new
12/08/2012 03:49:17;0040;PBS_Server;Svr;tyrone-cluster;Scheduler was sent the command new
12/08/2012 03:49:46;0040;PBS_Server;Svr;tyrone-cluster;Scheduler was sent the command new
12/08/2012 03:50:16;0040;PBS_Server;Svr;tyrone-cluster;Scheduler was sent the command new
12/08/2012 03:50:47;0040;PBS_Server;Svr;tyrone-cluster;Scheduler was sent the command new
12/08/2012 03:51:16;0040;PBS_Server;Svr;tyrone-cluster;Scheduler was sent the command new
12/08/2012 03:51:46;0040;PBS_Server;Svr;tyrone-cluster;Scheduler was sent the command new
12/08/2012 03:52:17;0040;PBS_Server;Svr;tyrone-cluster;Scheduler was sent the command new
12/08/2012 03:52:46;0040;PBS_Server;Svr;tyrone-cluster;Scheduler was sent the command new
12/08/2012 03:53:09;0002;PBS_Server;Svr;PBS_Server;Torque Server Version = 3.0.5, loglevel = 0
12/08/2012 03:53:16;0040;PBS_Server;Svr;tyrone-cluster;Scheduler was sent the command new
12/08/2012 03:53:47;0040;PBS_Server;Svr;tyrone-cluster;Scheduler was sent the command new
12/08/2012 03:54:16;0040;PBS_Server;Svr;tyrone-cluster;Scheduler was sent the command new
12/08/2012 03:54:46;0040;PBS_Server;Svr;tyrone-cluster;Scheduler was sent the command new
12/08/2012 03:55:17;0040;PBS_Server;Svr;tyrone-cluster;Scheduler was sent the command new
12/08/2012 03:55:46;0040;PBS_Server;Svr;tyrone-cluster;Scheduler was sent the command new
12/08/2012 03:56:16;0040;PBS_Server;Svr;tyrone-cluster;Scheduler was sent the command new
12/08/2012 03:56:47;0040;PBS_Server;Svr;tyrone-cluster;Scheduler was sent the command new
12/08/2012 03:57:16;0040;PBS_Server;Svr;tyrone-cluster;Scheduler was sent the command new
12/08/2012 03:57:46;0040;PBS_Server;Svr;tyrone-cluster;Scheduler was sent the command new
12/08/2012 03:58:09;0002;PBS_Server;Svr;PBS_Server;Torque Server Version = 3.0.5, loglevel = 0
12/08/2012 03:58:17;0040;PBS_Server;Svr;tyrone-cluster;Scheduler was sent the command new
12/08/2012 03:58:46;0040;PBS_Server;Svr;tyrone-cluster;Scheduler was sent the command new
12/08/2012 03:59:16;0040;PBS_Server;Svr;tyrone-cluster;Scheduler was sent the command new
12/08/2012 03:59:47;0040;PBS_Server;Svr;tyrone-cluster;Scheduler was sent the command new
12/08/2012 04:00:16;0040;PBS_Server;Svr;tyrone-cluster;Scheduler was sent the command new
12/08/2012 04:00:46;0040;PBS_Server;Svr;tyrone-cluster;Scheduler was sent the command new
12/08/2012 04:01:17;0040;PBS_Server;Svr;tyrone-cluster;Scheduler was sent the command new
12/08/2012 04:01:46;0040;PBS_Server;Svr;tyrone-cluster;Scheduler was sent the command new
12/08/2012 04:02:16;0040;PBS_Server;Svr;tyrone-cluster;Scheduler was sent the command new
12/08/2012 04:02:47;0040;PBS_Server;Svr;tyrone-cluster;Scheduler was sent the command new
12/08/2012 04:03:09;0002;PBS_Server;Svr;PBS_Server;Torque Server Version = 3.0.5, loglevel = 0
12/08/2012 04:03:16;0040;PBS_Server;Svr;tyrone-cluster;Scheduler was sent the command new
12/08/2012 04:03:46;0040;PBS_Server;Svr;tyrone-cluster;Scheduler was sent the command new
12/08/2012 04:04:17;0040;PBS_Server;Svr;tyrone-cluster;Scheduler was sent the command new
12/08/2012 04:04:46;0040;PBS_Server;Svr;tyrone-cluster;Scheduler was sent the command new
12/08/2012 04:05:16;0040;PBS_Server;Svr;tyrone-cluster;Scheduler was sent the command new
12/08/2012 04:05:47;0040;PBS_Server;Svr;tyrone-cluster;Scheduler was sent the command new
12/08/2012 04:06:16;0040;PBS_Server;Svr;tyrone-cluster;Scheduler was sent the command new
12/08/2012 04:06:46;0040;PBS_Server;Svr;tyrone-cluster;Scheduler was sent the command new
12/08/2012 04:07:17;0040;PBS_Server;Svr;tyrone-cluster;Scheduler was sent the command new
12/08/2012 04:07:46;0040;PBS_Server;Svr;tyrone-cluster;Scheduler was sent the command new
12/08/2012 04:08:09;0002;PBS_Server;Svr;PBS_Server;Torque Server Version = 3.0.5, loglevel = 0
12/08/2012 04:08:16;0040;PBS_Server;Svr;tyrone-cluster;Scheduler was sent the command new
12/08/2012 04:08:47;0040;PBS_Server;Svr;tyrone-cluster;Scheduler was sent the command new
12/08/2012 04:09:16;0040;PBS_Server;Svr;tyrone-cluster;Scheduler was sent the command new
12/08/2012 04:09:46;0040;PBS_Server;Svr;tyrone-cluster;Scheduler was sent the command new
12/08/2012 04:10:17;0040;PBS_Server;Svr;tyrone-cluster;Scheduler was sent the command new
12/08/2012 04:10:46;0040;PBS_Server;Svr;tyrone-cluster;Scheduler was sent the command new
12/08/2012 04:11:16;0040;PBS_Server;Svr;tyrone-cluster;Scheduler was sent the command new
12/08/2012 04:11:47;0040;PBS_Server;Svr;tyrone-cluster;Scheduler was sent the command new
12/08/2012 04:12:16;0040;PBS_Server;Svr;tyrone-cluster;Scheduler was sent the command new
12/08/2012 04:12:46;0040;PBS_Server;Svr;tyrone-cluster;Scheduler was sent the command new
12/08/2012 04:13:09;0002;PBS_Server;Svr;PBS_Server;Torque Server Version = 3.0.5, loglevel = 0
12/08/2012 04:13:17;0040;PBS_Server;Svr;tyrone-cluster;Scheduler was sent the command new
12/08/2012 04:13:46;0040;PBS_Server;Svr;tyrone-cluster;Scheduler was sent the command new
12/08/2012 04:14:16;0040;PBS_Server;Svr;tyrone-cluster;Scheduler was sent the command new
12/08/2012 04:14:47;0040;PBS_Server;Svr;tyrone-cluster;Scheduler was sent the command new
12/08/2012 04:15:16;0040;PBS_Server;Svr;tyrone-cluster;Scheduler was sent the command new
12/08/2012 04:15:46;0040;PBS_Server;Svr;tyrone-cluster;Scheduler was sent the command new
12/08/2012 04:16:17;0040;PBS_Server;Svr;tyrone-cluster;Scheduler was sent the command new
12/08/2012 04:16:46;0040;PBS_Server;Svr;tyrone-cluster;Scheduler was sent the command new
12/08/2012 04:17:16;0040;PBS_Server;Svr;tyrone-cluster;Scheduler was sent the command new
12/08/2012 04:17:47;0040;PBS_Server;Svr;tyrone-cluster;Scheduler was sent the command new
12/08/2012 04:18:09;0002;PBS_Server;Svr;PBS_Server;Torque Server Version = 3.0.5, loglevel = 0
12/08/2012 04:18:16;0040;PBS_Server;Svr;tyrone-cluster;Scheduler was sent the command new
12/08/2012 04:18:46;0040;PBS_Server;Svr;tyrone-cluster;Scheduler was sent the command new
12/08/2012 04:19:17;0040;PBS_Server;Svr;tyrone-cluster;Scheduler was sent the command new
12/08/2012 04:19:46;0040;PBS_Server;Svr;tyrone-cluster;Scheduler was sent the command new
12/08/2012 04:20:16;0040;PBS_Server;Svr;tyrone-cluster;Scheduler was sent the command new
12/08/2012 04:20:47;0040;PBS_Server;Svr;tyrone-cluster;Scheduler was sent the command new
12/08/2012 04:21:16;0040;PBS_Server;Svr;tyrone-cluster;Scheduler was sent the command new
12/08/2012 04:21:46;0040;PBS_Server;Svr;tyrone-cluster;Scheduler was sent the command new
12/08/2012 04:22:17;0040;PBS_Server;Svr;tyrone-cluster;Scheduler was sent the command new
12/08/2012 04:22:46;0040;PBS_Server;Svr;tyrone-cluster;Scheduler was sent the command new
12/08/2012 04:23:09;0002;PBS_Server;Svr;PBS_Server;Torque Server Version = 3.0.5, loglevel = 0
12/08/2012 04:23:16;0040;PBS_Server;Svr;tyrone-cluster;Scheduler was sent the command new
12/08/2012 04:23:47;0040;PBS_Server;Svr;tyrone-cluster;Scheduler was sent the command new
12/08/2012 04:24:16;0040;PBS_Server;Svr;tyrone-cluster;Scheduler was sent the command new
12/08/2012 04:24:46;0040;PBS_Server;Svr;tyrone-cluster;Scheduler was sent the command new
12/08/2012 04:25:17;0040;PBS_Server;Svr;tyrone-cluster;Scheduler was sent the command new
12/08/2012 04:25:46;0040;PBS_Server;Svr;tyrone-cluster;Scheduler was sent the command new
12/08/2012 04:26:16;0040;PBS_Server;Svr;tyrone-cluster;Scheduler was sent the command new
12/08/2012 04:26:47;0040;PBS_Server;Svr;tyrone-cluster;Scheduler was sent the command new
12/08/2012 04:27:16;0040;PBS_Server;Svr;tyrone-cluster;Scheduler was sent the command new
12/08/2012 04:27:46;0040;PBS_Server;Svr;tyrone-cluster;Scheduler was sent the command new
12/08/2012 04:28:09;0002;PBS_Server;Svr;PBS_Server;Torque Server Version = 3.0.5, loglevel = 0
12/08/2012 04:28:17;0040;PBS_Server;Svr;tyrone-cluster;Scheduler was sent the command new
12/08/2012 04:28:46;0040;PBS_Server;Svr;tyrone-cluster;Scheduler was sent the command new
12/08/2012 04:29:16;0040;PBS_Server;Svr;tyrone-cluster;Scheduler was sent the command new
12/08/2012 04:29:47;0040;PBS_Server;Svr;tyrone-cluster;Scheduler was sent the command new
12/08/2012 04:30:16;0040;PBS_Server;Svr;tyrone-cluster;Scheduler was sent the command new
12/08/2012 04:30:46;0040;PBS_Server;Svr;tyrone-cluster;Scheduler was sent the command new
12/08/2012 04:31:17;0040;PBS_Server;Svr;tyrone-cluster;Scheduler was sent the command new
12/08/2012 04:31:46;0040;PBS_Server;Svr;tyrone-cluster;Scheduler was sent the command new
12/08/2012 04:32:16;0040;PBS_Server;Svr;tyrone-cluster;Scheduler was sent the command new
12/08/2012 04:32:47;0040;PBS_Server;Svr;tyrone-cluster;Scheduler was sent the command new
12/08/2012 04:33:09;0002;PBS_Server;Svr;PBS_Server;Torque Server Version = 3.0.5, loglevel = 0
12/08/2012 04:33:16;0040;PBS_Server;Svr;tyrone-cluster;Scheduler was sent the command new
12/08/2012 04:33:46;0040;PBS_Server;Svr;tyrone-cluster;Scheduler was sent the command new
12/08/2012 04:34:17;0040;PBS_Server;Svr;tyrone-cluster;Scheduler was sent the command new
12/08/2012 04:34:46;0040;PBS_Server;Svr;tyrone-cluster;Scheduler was sent the command new
12/08/2012 04:35:16;0040;PBS_Server;Svr;tyrone-cluster;Scheduler was sent the command new
12/08/2012 04:35:47;0040;PBS_Server;Svr;tyrone-cluster;Scheduler was sent the command new
12/08/2012 04:36:16;0040;PBS_Server;Svr;tyrone-cluster;Scheduler was sent the command new
12/08/2012 04:36:46;0040;PBS_Server;Svr;tyrone-cluster;Scheduler was sent the command new
12/08/2012 04:37:17;0040;PBS_Server;Svr;tyrone-cluster;Scheduler was sent the command new
12/08/2012 04:37:46;0040;PBS_Server;Svr;tyrone-cluster;Scheduler was sent the command new
12/08/2012 04:38:09;0002;PBS_Server;Svr;PBS_Server;Torque Server Version = 3.0.5, loglevel = 0
12/08/2012 04:38:16;0040;PBS_Server;Svr;tyrone-cluster;Scheduler was sent the command new
12/08/2012 04:38:47;0040;PBS_Server;Svr;tyrone-cluster;Scheduler was sent the command new
12/08/2012 04:39:16;0040;PBS_Server;Svr;tyrone-cluster;Scheduler was sent the command new
12/08/2012 04:39:46;0040;PBS_Server;Svr;tyrone-cluster;Scheduler was sent the command new
12/08/2012 04:40:17;0040;PBS_Server;Svr;tyrone-cluster;Scheduler was sent the command new
12/08/2012 04:40:46;0040;PBS_Server;Svr;tyrone-cluster;Scheduler was sent the command new
12/08/2012 04:41:16;0040;PBS_Server;Svr;tyrone-cluster;Scheduler was sent the command new
12/08/2012 04:41:47;0040;PBS_Server;Svr;tyrone-cluster;Scheduler was sent the command new
12/08/2012 04:42:16;0040;PBS_Server;Svr;tyrone-cluster;Scheduler was sent the command new
12/08/2012 04:42:46;0040;PBS_Server;Svr;tyrone-cluster;Scheduler was sent the command new
12/08/2012 04:43:09;0002;PBS_Server;Svr;PBS_Server;Torque Server Version = 3.0.5, loglevel = 0
12/08/2012 04:43:17;0040;PBS_Server;Svr;tyrone-cluster;Scheduler was sent the command new
12/08/2012 04:43:46;0040;PBS_Server;Svr;tyrone-cluster;Scheduler was sent the command new
12/08/2012 04:44:16;0040;PBS_Server;Svr;tyrone-cluster;Scheduler was sent the command new
12/08/2012 04:44:47;0040;PBS_Server;Svr;tyrone-cluster;Scheduler was sent the command new
12/08/2012 04:45:16;0040;PBS_Server;Svr;tyrone-cluster;Scheduler was sent the command new
12/08/2012 04:45:46;0040;PBS_Server;Svr;tyrone-cluster;Scheduler was sent the command new
12/08/2012 04:46:17;0040;PBS_Server;Svr;tyrone-cluster;Scheduler was sent the command new
12/08/2012 04:46:46;0040;PBS_Server;Svr;tyrone-cluster;Scheduler was sent the command new
12/08/2012 04:47:16;0040;PBS_Server;Svr;tyrone-cluster;Scheduler was sent the command new
12/08/2012 04:47:47;0040;PBS_Server;Svr;tyrone-cluster;Scheduler was sent the command new
12/08/2012 04:48:09;0002;PBS_Server;Svr;PBS_Server;Torque Server Version = 3.0.5, loglevel = 0
12/08/2012 04:48:16;0040;PBS_Server;Svr;tyrone-cluster;Scheduler was sent the command new
12/08/2012 04:48:46;0040;PBS_Server;Svr;tyrone-cluster;Scheduler was sent the command new
12/08/2012 04:49:17;0040;PBS_Server;Svr;tyrone-cluster;Scheduler was sent the command new
12/08/2012 04:49:46;0040;PBS_Server;Svr;tyrone-cluster;Scheduler was sent the command new
12/08/2012 04:50:16;0040;PBS_Server;Svr;tyrone-cluster;Scheduler was sent the command new
12/08/2012 04:50:47;0040;PBS_Server;Svr;tyrone-cluster;Scheduler was sent the command new
12/08/2012 04:50:50;000d;PBS_Server;Job;16688.tyrone-cluster;Not sending email: User does not want mail of this type.
12/08/2012 04:50:50;0010;PBS_Server;Job;16688.tyrone-cluster;Exit_status=0 resources_used.cput=281:16:17 resources_used.mem=533756kb resources_used.vmem=1410500kb resources_used.walltime=19:16:54
12/08/2012 04:50:50;0008;PBS_Server;Job;NULL;on_job_exit valid pjob: 0x1b5ae70 (substate=50)
12/08/2012 04:50:50;0008;PBS_Server;Job;NULL;on_job_exit valid pjob: 0x1b5ae70 (substate=51)
12/08/2012 04:50:53;0008;PBS_Server;Job;NULL;on_job_exit valid pjob: 0x1b5ae70 (substate=51)
12/08/2012 04:50:53;0008;PBS_Server;Job;NULL;on_job_exit valid pjob: 0x1b5ae70 (substate=53)
12/08/2012 04:50:53;0100;PBS_Server;Job;16688.tyrone-cluster;dequeuing from qp32, state COMPLETE
12/08/2012 04:50:53;0040;PBS_Server;Svr;tyrone-cluster;Scheduler was sent the command term
12/08/2012 04:50:53;0008;PBS_Server;Job;16509.tyrone-cluster;Job Modified at request of Scheduler@tyrone-cluster
12/08/2012 04:50:53;0008;PBS_Server;Job;16602.tyrone-cluster;Job Modified at request of Scheduler@tyrone-cluster
12/08/2012 04:50:53;0008;PBS_Server;Job;16700.tyrone-cluster;Job Modified at request of Scheduler@tyrone-cluster
12/08/2012 04:50:53;0008;PBS_Server;Job;16697.tyrone-cluster;Job Modified at request of Scheduler@tyrone-cluster
12/08/2012 04:50:53;0008;PBS_Server;Job;16697.tyrone-cluster;Job Run at request of Scheduler@tyrone-cluster
12/08/2012 04:50:53;0040;PBS_Server;Svr;tyrone-cluster;Scheduler was sent the command recyc
12/08/2012 04:50:53;000d;PBS_Server;Job;16697.tyrone-cluster;Not sending email: User does not want mail of this type.
12/08/2012 04:51:16;0040;PBS_Server;Svr;tyrone-cluster;Scheduler was sent the command new
12/08/2012 04:51:16;0008;PBS_Server;Job;16509.tyrone-cluster;Job Modified at request of Scheduler@tyrone-cluster
12/08/2012 04:51:16;0008;PBS_Server;Job;16602.tyrone-cluster;Job Modified at request of Scheduler@tyrone-cluster
12/08/2012 04:51:16;0008;PBS_Server;Job;16700.tyrone-cluster;Job Modified at request of Scheduler@tyrone-cluster
12/08/2012 04:51:46;0040;PBS_Server;Svr;tyrone-cluster;Scheduler was sent the command new
12/08/2012 04:52:17;0040;PBS_Server;Svr;tyrone-cluster;Scheduler was sent the command new
12/08/2012 04:52:46;0040;PBS_Server;Svr;tyrone-cluster;Scheduler was sent the command new
12/08/2012 04:53:09;0002;PBS_Server;Svr;PBS_Server;Torque Server Version = 3.0.5, loglevel = 0
12/08/2012 04:53:16;0040;PBS_Server;Svr;tyrone-cluster;Scheduler was sent the command new
12/08/2012 04:53:47;0040;PBS_Server;Svr;tyrone-cluster;Scheduler was sent the command new
12/08/2012 04:54:16;0040;PBS_Server;Svr;tyrone-cluster;Scheduler was sent the command new
12/08/2012 04:54:46;0040;PBS_Server;Svr;tyrone-cluster;Scheduler was sent the command new
12/08/2012 04:55:17;0040;PBS_Server;Svr;tyrone-cluster;Scheduler was sent the command new
12/08/2012 04:55:46;0040;PBS_Server;Svr;tyrone-cluster;Scheduler was sent the command new
12/08/2012 04:56:16;0040;PBS_Server;Svr;tyrone-cluster;Scheduler was sent the command new
12/08/2012 04:56:47;0040;PBS_Server;Svr;tyrone-cluster;Scheduler was sent the command new
12/08/2012 04:57:16;0040;PBS_Server;Svr;tyrone-cluster;Scheduler was sent the command new
12/08/2012 04:57:46;0040;PBS_Server;Svr;tyrone-cluster;Scheduler was sent the command new
12/08/2012 04:58:09;0002;PBS_Server;Svr;PBS_Server;Torque Server Version = 3.0.5, loglevel = 0
12/08/2012 04:58:17;0040;PBS_Server;Svr;tyrone-cluster;Scheduler was sent the command new
12/08/2012 04:58:46;0040;PBS_Server;Svr;tyrone-cluster;Scheduler was sent the command new
12/08/2012 04:59:16;0040;PBS_Server;Svr;tyrone-cluster;Scheduler was sent the command new
12/08/2012 04:59:47;0040;PBS_Server;Svr;tyrone-cluster;Scheduler was sent the command new
12/08/2012 05:00:16;0040;PBS_Server;Svr;tyrone-cluster;Scheduler was sent the command new
12/08/2012 05:00:46;0040;PBS_Server;Svr;tyrone-cluster;Scheduler was sent the command new
12/08/2012 05:01:17;0040;PBS_Server;Svr;tyrone-cluster;Scheduler was sent the command new
12/08/2012 05:01:46;0040;PBS_Server;Svr;tyrone-cluster;Scheduler was sent the command new
12/08/2012 05:02:16;0040;PBS_Server;Svr;tyrone-cluster;Scheduler was sent the command new
12/08/2012 05:02:47;0040;PBS_Server;Svr;tyrone-cluster;Scheduler was sent the command new
12/08/2012 05:03:09;0002;PBS_Server;Svr;PBS_Server;Torque Server Version = 3.0.5, loglevel = 0
12/08/2012 05:03:16;0040;PBS_Server;Svr;tyrone-cluster;Scheduler was sent the command new
12/08/2012 05:03:46;0040;PBS_Server;Svr;tyrone-cluster;Scheduler was sent the command new
12/08/2012 05:04:17;0040;PBS_Server;Svr;tyrone-cluster;Scheduler was sent the command new
12/08/2012 05:04:46;0040;PBS_Server;Svr;tyrone-cluster;Scheduler was sent the command new
12/08/2012 05:05:16;0040;PBS_Server;Svr;tyrone-cluster;Scheduler was sent the command new
12/08/2012 05:05:47;0040;PBS_Server;Svr;tyrone-cluster;Scheduler was sent the command new
12/08/2012 05:06:16;0040;PBS_Server;Svr;tyrone-cluster;Scheduler was sent the command new
12/08/2012 05:06:46;0040;PBS_Server;Svr;tyrone-cluster;Scheduler was sent the command new
12/08/2012 05:07:17;0040;PBS_Server;Svr;tyrone-cluster;Scheduler was sent the command new
12/08/2012 05:07:46;0040;PBS_Server;Svr;tyrone-cluster;Scheduler was sent the command new
12/08/2012 05:08:09;0002;PBS_Server;Svr;PBS_Server;Torque Server Version = 3.0.5, loglevel = 0
12/08/2012 05:08:16;0040;PBS_Server;Svr;tyrone-cluster;Scheduler was sent the command new
12/08/2012 05:08:47;0040;PBS_Server;Svr;tyrone-cluster;Scheduler was sent the command new
12/08/2012 05:09:16;0040;PBS_Server;Svr;tyrone-cluster;Scheduler was sent the command new
12/08/2012 05:09:46;0040;PBS_Server;Svr;tyrone-cluster;Scheduler was sent the command new
12/08/2012 05:10:17;0040;PBS_Server;Svr;tyrone-cluster;Scheduler was sent the command new
12/08/2012 05:10:46;0040;PBS_Server;Svr;tyrone-cluster;Scheduler was sent the command new
12/08/2012 05:11:16;0040;PBS_Server;Svr;tyrone-cluster;Scheduler was sent the command new
12/08/2012 05:11:47;0040;PBS_Server;Svr;tyrone-cluster;Scheduler was sent the command new
12/08/2012 05:12:16;0040;PBS_Server;Svr;tyrone-cluster;Scheduler was sent the command new
12/08/2012 05:12:46;0040;PBS_Server;Svr;tyrone-cluster;Scheduler was sent the command new
12/08/2012 05:13:09;0002;PBS_Server;Svr;PBS_Server;Torque Server Version = 3.0.5, loglevel = 0
12/08/2012 05:13:17;0040;PBS_Server;Svr;tyrone-cluster;Scheduler was sent the command new
12/08/2012 05:13:46;0040;PBS_Server;Svr;tyrone-cluster;Scheduler was sent the command new
12/08/2012 05:14:16;0040;PBS_Server;Svr;tyrone-cluster;Scheduler was sent the command new
12/08/2012 05:14:47;0040;PBS_Server;Svr;tyrone-cluster;Scheduler was sent the command new
12/08/2012 05:15:16;0040;PBS_Server;Svr;tyrone-cluster;Scheduler was sent the command new
12/08/2012 05:15:46;0040;PBS_Server;Svr;tyrone-cluster;Scheduler was sent the command new
12/08/2012 05:16:17;0040;PBS_Server;Svr;tyrone-cluster;Scheduler was sent the command new
12/08/2012 05:16:46;0040;PBS_Server;Svr;tyrone-cluster;Scheduler was sent the command new
12/08/2012 05:17:16;0040;PBS_Server;Svr;tyrone-cluster;Scheduler was sent the command new
12/08/2012 05:17:47;0040;PBS_Server;Svr;tyrone-cluster;Scheduler was sent the command new
12/08/2012 05:18:09;0002;PBS_Server;Svr;PBS_Server;Torque Server Version = 3.0.5, loglevel = 0
12/08/2012 05:18:16;0040;PBS_Server;Svr;tyrone-cluster;Scheduler was sent the command new
12/08/2012 05:18:46;0040;PBS_Server;Svr;tyrone-cluster;Scheduler was sent the command new
12/08/2012 05:19:17;0040;PBS_Server;Svr;tyrone-cluster;Scheduler was sent the command new
12/08/2012 05:19:46;0040;PBS_Server;Svr;tyrone-cluster;Scheduler was sent the command new
12/08/2012 05:20:16;0040;PBS_Server;Svr;tyrone-cluster;Scheduler was sent the command new
12/08/2012 05:20:47;0040;PBS_Server;Svr;tyrone-cluster;Scheduler was sent the command new
12/08/2012 05:21:16;0040;PBS_Server;Svr;tyrone-cluster;Scheduler was sent the command new
12/08/2012 05:21:46;0040;PBS_Server;Svr;tyrone-cluster;Scheduler was sent the command new
12/08/2012 05:22:17;0040;PBS_Server;Svr;tyrone-cluster;Scheduler was sent the command new
12/08/2012 05:22:46;0040;PBS_Server;Svr;tyrone-cluster;Scheduler was sent the command new
12/08/2012 05:23:09;0002;PBS_Server;Svr;PBS_Server;Torque Server Version = 3.0.5, loglevel = 0
12/08/2012 05:23:16;0040;PBS_Server;Svr;tyrone-cluster;Scheduler was sent the command new
12/08/2012 05:23:47;0040;PBS_Server;Svr;tyrone-cluster;Scheduler was sent the command new
12/08/2012 05:24:16;0040;PBS_Server;Svr;tyrone-cluster;Scheduler was sent the command new
12/08/2012 05:24:46;0040;PBS_Server;Svr;tyrone-cluster;Scheduler was sent the command new
12/08/2012 05:25:17;0040;PBS_Server;Svr;tyrone-cluster;Scheduler was sent the command new
12/08/2012 05:25:46;0040;PBS_Server;Svr;tyrone-cluster;Scheduler was sent the command new
12/08/2012 05:26:16;0040;PBS_Server;Svr;tyrone-cluster;Scheduler was sent the command new
12/08/2012 05:26:47;0040;PBS_Server;Svr;tyrone-cluster;Scheduler was sent the command new
12/08/2012 05:27:16;0040;PBS_Server;Svr;tyrone-cluster;Scheduler was sent the command new
12/08/2012 05:27:46;0040;PBS_Server;Svr;tyrone-cluster;Scheduler was sent the command new
12/08/2012 05:28:09;0002;PBS_Server;Svr;PBS_Server;Torque Server Version = 3.0.5, loglevel = 0
12/08/2012 05:28:17;0040;PBS_Server;Svr;tyrone-cluster;Scheduler was sent the command new
12/08/2012 05:28:46;0040;PBS_Server;Svr;tyrone-cluster;Scheduler was sent the command new
12/08/2012 05:29:16;0040;PBS_Server;Svr;tyrone-cluster;Scheduler was sent the command new
12/08/2012 05:29:47;0040;PBS_Server;Svr;tyrone-cluster;Scheduler was sent the command new
12/08/2012 05:30:16;0040;PBS_Server;Svr;tyrone-cluster;Scheduler was sent the command new
12/08/2012 05:30:46;0040;PBS_Server;Svr;tyrone-cluster;Scheduler was sent the command new
12/08/2012 05:31:17;0040;PBS_Server;Svr;tyrone-cluster;Scheduler was sent the command new
12/08/2012 05:31:46;0040;PBS_Server;Svr;tyrone-cluster;Scheduler was sent the command new
12/08/2012 05:32:16;0040;PBS_Server;Svr;tyrone-cluster;Scheduler was sent the command new
12/08/2012 05:32:47;0040;PBS_Server;Svr;tyrone-cluster;Scheduler was sent the command new
12/08/2012 05:33:09;0002;PBS_Server;Svr;PBS_Server;Torque Server Version = 3.0.5, loglevel = 0
12/08/2012 05:33:16;0040;PBS_Server;Svr;tyrone-cluster;Scheduler was sent the command new
12/08/2012 05:33:46;0040;PBS_Server;Svr;tyrone-cluster;Scheduler was sent the command new
12/08/2012 05:34:17;0040;PBS_Server;Svr;tyrone-cluster;Scheduler was sent the command new
12/08/2012 05:34:46;0040;PBS_Server;Svr;tyrone-cluster;Scheduler was sent the command new
12/08/2012 05:35:16;0040;PBS_Server;Svr;tyrone-cluster;Scheduler was sent the command new
12/08/2012 05:35:47;0040;PBS_Server;Svr;tyrone-cluster;Scheduler was sent the command new
12/08/2012 05:36:16;0040;PBS_Server;Svr;tyrone-cluster;Scheduler was sent the command new
12/08/2012 05:36:46;0040;PBS_Server;Svr;tyrone-cluster;Scheduler was sent the command new
12/08/2012 05:37:17;0040;PBS_Server;Svr;tyrone-cluster;Scheduler was sent the command new
12/08/2012 05:37:46;0040;PBS_Server;Svr;tyrone-cluster;Scheduler was sent the command new
12/08/2012 05:38:09;0002;PBS_Server;Svr;PBS_Server;Torque Server Version = 3.0.5, loglevel = 0
12/08/2012 05:38:16;0040;PBS_Server;Svr;tyrone-cluster;Scheduler was sent the command new
12/08/2012 05:38:47;0040;PBS_Server;Svr;tyrone-cluster;Scheduler was sent the command new
12/08/2012 05:39:16;0040;PBS_Server;Svr;tyrone-cluster;Scheduler was sent the command new
12/08/2012 05:39:46;0040;PBS_Server;Svr;tyrone-cluster;Scheduler was sent the command new
12/08/2012 05:40:17;0040;PBS_Server;Svr;tyrone-cluster;Scheduler was sent the command new
12/08/2012 05:40:46;0040;PBS_Server;Svr;tyrone-cluster;Scheduler was sent the command new
12/08/2012 05:41:16;0040;PBS_Server;Svr;tyrone-cluster;Scheduler was sent the command new
12/08/2012 05:41:47;0040;PBS_Server;Svr;tyrone-cluster;Scheduler was sent the command new
12/08/2012 05:42:16;0040;PBS_Server;Svr;tyrone-cluster;Scheduler was sent the command new
12/08/2012 05:42:46;0040;PBS_Server;Svr;tyrone-cluster;Scheduler was sent the command new
12/08/2012 05:43:09;0002;PBS_Server;Svr;PBS_Server;Torque Server Version = 3.0.5, loglevel = 0
12/08/2012 05:43:17;0040;PBS_Server;Svr;tyrone-cluster;Scheduler was sent the command new
12/08/2012 05:43:46;0040;PBS_Server;Svr;tyrone-cluster;Scheduler was sent the command new
12/08/2012 05:44:16;0040;PBS_Server;Svr;tyrone-cluster;Scheduler was sent the command new
12/08/2012 05:44:47;0040;PBS_Server;Svr;tyrone-cluster;Scheduler was sent the command new
12/08/2012 05:45:16;0040;PBS_Server;Svr;tyrone-cluster;Scheduler was sent the command new
12/08/2012 05:45:46;0040;PBS_Server;Svr;tyrone-cluster;Scheduler was sent the command new
12/08/2012 05:46:17;0040;PBS_Server;Svr;tyrone-cluster;Scheduler was sent the command new
12/08/2012 05:46:46;0040;PBS_Server;Svr;tyrone-cluster;Scheduler was sent the command new
12/08/2012 05:47:16;0040;PBS_Server;Svr;tyrone-cluster;Scheduler was sent the command new
12/08/2012 05:47:47;0040;PBS_Server;Svr;tyrone-cluster;Scheduler was sent the command new
12/08/2012 05:48:09;0002;PBS_Server;Svr;PBS_Server;Torque Server Version = 3.0.5, loglevel = 0
12/08/2012 05:48:16;0040;PBS_Server;Svr;tyrone-cluster;Scheduler was sent the command new
12/08/2012 05:48:16;000d;PBS_Server;Job;16697.tyrone-cluster;Not sending email: User does not want mail of this type.
12/08/2012 05:48:16;0010;PBS_Server;Job;16697.tyrone-cluster;Exit_status=0 resources_used.cput=30:28:58 resources_used.mem=5461076kb resources_used.vmem=13767408kb resources_used.walltime=00:57:23
12/08/2012 05:48:16;0008;PBS_Server;Job;NULL;on_job_exit valid pjob: 0x1c927f0 (substate=50)
12/08/2012 05:48:16;0008;PBS_Server;Job;NULL;on_job_exit valid pjob: 0x1c927f0 (substate=51)
12/08/2012 05:48:16;0008;PBS_Server;Job;16509.tyrone-cluster;Job Modified at request of Scheduler@tyrone-cluster
12/08/2012 05:48:16;0008;PBS_Server;Job;16602.tyrone-cluster;Job Modified at request of Scheduler@tyrone-cluster
12/08/2012 05:48:16;0008;PBS_Server;Job;16700.tyrone-cluster;Job Modified at request of Scheduler@tyrone-cluster
12/08/2012 05:48:16;0008;PBS_Server;Job;16696.tyrone-cluster;Job Modified at request of Scheduler@tyrone-cluster
12/08/2012 05:48:16;0008;PBS_Server;Job;16699.tyrone-cluster;Job Modified at request of Scheduler@tyrone-cluster
12/08/2012 05:48:16;0008;PBS_Server;Job;16725.tyrone-cluster;Job Modified at request of Scheduler@tyrone-cluster
12/08/2012 05:48:16;0008;PBS_Server;Job;16726.tyrone-cluster;Job Modified at request of Scheduler@tyrone-cluster
12/08/2012 05:48:16;0008;PBS_Server;Job;16727.tyrone-cluster;Job Modified at request of Scheduler@tyrone-cluster
12/08/2012 05:48:16;0008;PBS_Server;Job;16729.tyrone-cluster;Job Modified at request of Scheduler@tyrone-cluster
12/08/2012 05:48:16;0008;PBS_Server;Job;16741.tyrone-cluster;Job Modified at request of Scheduler@tyrone-cluster
12/08/2012 05:48:16;0008;PBS_Server;Job;16742.tyrone-cluster;Job Modified at request of Scheduler@tyrone-cluster
12/08/2012 05:48:16;0008;PBS_Server;Job;16743.tyrone-cluster;Job Modified at request of Scheduler@tyrone-cluster
12/08/2012 05:48:16;0008;PBS_Server;Job;16744.tyrone-cluster;Job Modified at request of Scheduler@tyrone-cluster
12/08/2012 05:48:16;0008;PBS_Server;Job;16745.tyrone-cluster;Job Modified at request of Scheduler@tyrone-cluster
12/08/2012 05:48:16;0008;PBS_Server;Job;16751.tyrone-cluster;Job Modified at request of Scheduler@tyrone-cluster
12/08/2012 05:48:16;0008;PBS_Server;Job;NULL;on_job_exit valid pjob: 0x1c927f0 (substate=51)
12/08/2012 05:48:16;0008;PBS_Server;Job;NULL;on_job_exit valid pjob: 0x1c927f0 (substate=53)
12/08/2012 05:48:16;0100;PBS_Server;Job;16697.tyrone-cluster;dequeuing from qp32, state COMPLETE
12/08/2012 05:48:16;0040;PBS_Server;Svr;tyrone-cluster;Scheduler was sent the command term
12/08/2012 05:48:16;0008;PBS_Server;Job;16696.tyrone-cluster;Job Modified at request of Scheduler@tyrone-cluster
12/08/2012 05:48:16;0008;PBS_Server;Job;16696.tyrone-cluster;Job Run at request of Scheduler@tyrone-cluster
12/08/2012 05:48:17;0008;PBS_Server;Job;16699.tyrone-cluster;Job Modified at request of Scheduler@tyrone-cluster
12/08/2012 05:48:17;000d;PBS_Server;Job;16696.tyrone-cluster;Not sending email: User does not want mail of this type.
12/08/2012 05:48:17;0008;PBS_Server;Job;16725.tyrone-cluster;Job Modified at request of Scheduler@tyrone-cluster
12/08/2012 05:48:17;0008;PBS_Server;Job;16726.tyrone-cluster;Job Modified at request of Scheduler@tyrone-cluster
12/08/2012 05:48:17;0008;PBS_Server;Job;16727.tyrone-cluster;Job Modified at request of Scheduler@tyrone-cluster
12/08/2012 05:48:17;0008;PBS_Server;Job;16729.tyrone-cluster;Job Modified at request of Scheduler@tyrone-cluster
12/08/2012 05:48:17;0008;PBS_Server;Job;16741.tyrone-cluster;Job Modified at request of Scheduler@tyrone-cluster
12/08/2012 05:48:17;0008;PBS_Server;Job;16742.tyrone-cluster;Job Modified at request of Scheduler@tyrone-cluster
12/08/2012 05:48:17;0008;PBS_Server;Job;16743.tyrone-cluster;Job Modified at request of Scheduler@tyrone-cluster
12/08/2012 05:48:17;0008;PBS_Server;Job;16744.tyrone-cluster;Job Modified at request of Scheduler@tyrone-cluster
12/08/2012 05:48:17;0008;PBS_Server;Job;16745.tyrone-cluster;Job Modified at request of Scheduler@tyrone-cluster
12/08/2012 05:48:17;0008;PBS_Server;Job;16751.tyrone-cluster;Job Modified at request of Scheduler@tyrone-cluster
12/08/2012 05:48:17;0040;PBS_Server;Svr;tyrone-cluster;Scheduler was sent the command recyc
12/08/2012 05:48:18;000d;PBS_Server;Job;16696.tyrone-cluster;Not sending email: User does not want mail of this type.
12/08/2012 05:48:18;0010;PBS_Server;Job;16696.tyrone-cluster;Exit_status=0 resources_used.cput=00:00:14 resources_used.mem=0kb resources_used.vmem=0kb resources_used.walltime=00:00:02
12/08/2012 05:48:18;0008;PBS_Server;Job;NULL;on_job_exit valid pjob: 0x1c2eb60 (substate=50)
12/08/2012 05:48:18;0008;PBS_Server;Job;NULL;on_job_exit valid pjob: 0x1c2eb60 (substate=51)
12/08/2012 05:48:18;0008;PBS_Server;Job;NULL;on_job_exit valid pjob: 0x1c2eb60 (substate=51)
12/08/2012 05:48:18;0008;PBS_Server;Job;NULL;on_job_exit valid pjob: 0x1c2eb60 (substate=53)
12/08/2012 05:48:18;0100;PBS_Server;Job;16696.tyrone-cluster;dequeuing from qp32, state COMPLETE
12/08/2012 05:48:18;0040;PBS_Server;Svr;tyrone-cluster;Scheduler was sent the command term
12/08/2012 05:48:18;0008;PBS_Server;Job;16699.tyrone-cluster;Job Modified at request of Scheduler@tyrone-cluster
12/08/2012 05:48:18;0008;PBS_Server;Job;16699.tyrone-cluster;Job Run at request of Scheduler@tyrone-cluster
12/08/2012 05:48:18;0040;PBS_Server;Svr;tyrone-cluster;Scheduler was sent the command recyc
12/08/2012 05:48:18;000d;PBS_Server;Job;16699.tyrone-cluster;Not sending email: User does not want mail of this type.
12/08/2012 05:48:46;0100;PBS_Server;Job;16701.tyrone-cluster;dequeuing from batch, state QUEUED
12/08/2012 05:48:46;0100;PBS_Server;Job;16701.tyrone-cluster;enqueuing into qp32, state 1 hop 1
12/08/2012 05:48:46;0100;PBS_Server;Job;16702.tyrone-cluster;dequeuing from batch, state QUEUED
12/08/2012 05:48:46;0100;PBS_Server;Job;16702.tyrone-cluster;enqueuing into qp32, state 1 hop 1
12/08/2012 05:48:46;0040;PBS_Server;Svr;tyrone-cluster;Scheduler was sent the command new
12/08/2012 05:48:46;0008;PBS_Server;Job;16509.tyrone-cluster;Job Modified at request of Scheduler@tyrone-cluster
12/08/2012 05:48:46;0008;PBS_Server;Job;16602.tyrone-cluster;Job Modified at request of Scheduler@tyrone-cluster
12/08/2012 05:48:46;0008;PBS_Server;Job;16700.tyrone-cluster;Job Modified at request of Scheduler@tyrone-cluster
12/08/2012 05:48:46;0008;PBS_Server;Job;16701.tyrone-cluster;Job Modified at request of Scheduler@tyrone-cluster
12/08/2012 05:48:46;0008;PBS_Server;Job;16702.tyrone-cluster;Job Modified at request of Scheduler@tyrone-cluster
12/08/2012 05:49:17;0040;PBS_Server;Svr;tyrone-cluster;Scheduler was sent the command new
12/08/2012 05:49:46;0040;PBS_Server;Svr;tyrone-cluster;Scheduler was sent the command new
12/08/2012 05:50:16;0040;PBS_Server;Svr;tyrone-cluster;Scheduler was sent the command new
12/08/2012 05:50:47;0040;PBS_Server;Svr;tyrone-cluster;Scheduler was sent the command new
12/08/2012 05:51:16;0040;PBS_Server;Svr;tyrone-cluster;Scheduler was sent the command new
12/08/2012 05:51:46;0040;PBS_Server;Svr;tyrone-cluster;Scheduler was sent the command new
12/08/2012 05:52:17;0040;PBS_Server;Svr;tyrone-cluster;Scheduler was sent the command new
12/08/2012 05:52:46;0040;PBS_Server;Svr;tyrone-cluster;Scheduler was sent the command new
12/08/2012 05:53:09;0002;PBS_Server;Svr;PBS_Server;Torque Server Version = 3.0.5, loglevel = 0
12/08/2012 05:53:16;0040;PBS_Server;Svr;tyrone-cluster;Scheduler was sent the command new
12/08/2012 05:53:47;0040;PBS_Server;Svr;tyrone-cluster;Scheduler was sent the command new
12/08/2012 05:54:16;0040;PBS_Server;Svr;tyrone-cluster;Scheduler was sent the command new
12/08/2012 05:54:46;0040;PBS_Server;Svr;tyrone-cluster;Scheduler was sent the command new
12/08/2012 05:55:04;000d;PBS_Server;Job;16456.tyrone-cluster;Not sending email: User does not want mail of this type.
12/08/2012 05:55:04;0010;PBS_Server;Job;16456.tyrone-cluster;Exit_status=143 resources_used.cput=736:36:25 resources_used.mem=15999316kb resources_used.vmem=20806536kb resources_used.walltime=24:00:48
12/08/2012 05:55:04;0008;PBS_Server;Job;NULL;on_job_exit valid pjob: 0x1b73720 (substate=50)
12/08/2012 05:55:04;0008;PBS_Server;Job;NULL;on_job_exit valid pjob: 0x1b73720 (substate=51)
12/08/2012 05:55:04;0008;PBS_Server;Job;NULL;on_job_exit valid pjob: 0x1b73720 (substate=51)
12/08/2012 05:55:04;0008;PBS_Server;Job;NULL;on_job_exit valid pjob: 0x1b73720 (substate=53)
12/08/2012 05:55:04;0100;PBS_Server;Job;16456.tyrone-cluster;dequeuing from qp32, state COMPLETE
12/08/2012 05:55:04;0040;PBS_Server;Svr;tyrone-cluster;Scheduler was sent the command term
12/08/2012 05:55:05;0008;PBS_Server;Job;16509.tyrone-cluster;Job Modified at request of Scheduler@tyrone-cluster
12/08/2012 05:55:05;0008;PBS_Server;Job;16509.tyrone-cluster;Job Run at request of Scheduler@tyrone-cluster
12/08/2012 05:55:05;0040;PBS_Server;Svr;tyrone-cluster;Scheduler was sent the command recyc
12/08/2012 05:55:05;000d;PBS_Server;Job;16509.tyrone-cluster;Not sending email: User does not want mail of this type.
12/08/2012 05:55:17;0100;PBS_Server;Job;16646.tyrone-cluster;dequeuing from batch, state QUEUED
12/08/2012 05:55:17;0100;PBS_Server;Job;16646.tyrone-cluster;enqueuing into qp32, state 1 hop 1
12/08/2012 05:55:18;0040;PBS_Server;Svr;tyrone-cluster;Scheduler was sent the command new
12/08/2012 05:55:18;0008;PBS_Server;Job;16646.tyrone-cluster;Job Modified at request of Scheduler@tyrone-cluster
12/08/2012 05:55:47;0040;PBS_Server;Svr;tyrone-cluster;Scheduler was sent the command new
12/08/2012 05:55:53;000d;PBS_Server;Job;16509.tyrone-cluster;Not sending email: User does not want mail of this type.
12/08/2012 05:55:53;0010;PBS_Server;Job;16509.tyrone-cluster;Exit_status=0 resources_used.cput=00:00:16 resources_used.mem=96492kb resources_used.vmem=1578532kb resources_used.walltime=00:00:49
12/08/2012 05:55:53;0008;PBS_Server;Job;NULL;on_job_exit valid pjob: 0x1b96ff0 (substate=50)
12/08/2012 05:55:53;0008;PBS_Server;Job;NULL;on_job_exit valid pjob: 0x1b96ff0 (substate=51)
12/08/2012 05:55:54;0008;PBS_Server;Job;NULL;on_job_exit valid pjob: 0x1b96ff0 (substate=51)
12/08/2012 05:55:54;0008;PBS_Server;Job;NULL;on_job_exit valid pjob: 0x1b96ff0 (substate=53)
12/08/2012 05:55:54;0100;PBS_Server;Job;16509.tyrone-cluster;dequeuing from qp32, state COMPLETE
12/08/2012 05:55:54;0040;PBS_Server;Svr;tyrone-cluster;Scheduler was sent the command term
12/08/2012 05:55:54;0008;PBS_Server;Job;16602.tyrone-cluster;Job Modified at request of Scheduler@tyrone-cluster
12/08/2012 05:55:54;0008;PBS_Server;Job;16602.tyrone-cluster;Job Run at request of Scheduler@tyrone-cluster
12/08/2012 05:55:54;0040;PBS_Server;Svr;tyrone-cluster;Scheduler was sent the command recyc
12/08/2012 05:55:54;000d;PBS_Server;Job;16602.tyrone-cluster;Not sending email: User does not want mail of this type.
12/08/2012 05:56:17;0040;PBS_Server;Svr;tyrone-cluster;Scheduler was sent the command new
12/08/2012 05:56:48;0040;PBS_Server;Svr;tyrone-cluster;Scheduler was sent the command new
12/08/2012 05:57:17;0040;PBS_Server;Svr;tyrone-cluster;Scheduler was sent the command new
12/08/2012 05:57:47;0040;PBS_Server;Svr;tyrone-cluster;Scheduler was sent the command new
12/08/2012 05:58:09;0002;PBS_Server;Svr;PBS_Server;Torque Server Version = 3.0.5, loglevel = 0
12/08/2012 05:58:18;0040;PBS_Server;Svr;tyrone-cluster;Scheduler was sent the command new
12/08/2012 05:58:47;0040;PBS_Server;Svr;tyrone-cluster;Scheduler was sent the command new
12/08/2012 05:59:17;0040;PBS_Server;Svr;tyrone-cluster;Scheduler was sent the command new
12/08/2012 05:59:25;000d;PBS_Server;Job;16699.tyrone-cluster;Not sending email: User does not want mail of this type.
12/08/2012 05:59:25;0010;PBS_Server;Job;16699.tyrone-cluster;Exit_status=0 resources_used.cput=05:52:29 resources_used.mem=5142920kb resources_used.vmem=13569908kb resources_used.walltime=00:11:07
12/08/2012 05:59:25;0008;PBS_Server;Job;NULL;on_job_exit valid pjob: 0x1c415f0 (substate=50)
12/08/2012 05:59:25;0008;PBS_Server;Job;NULL;on_job_exit valid pjob: 0x1c415f0 (substate=51)
12/08/2012 05:59:25;0008;PBS_Server;Job;NULL;on_job_exit valid pjob: 0x1c415f0 (substate=51)
12/08/2012 05:59:25;0008;PBS_Server;Job;NULL;on_job_exit valid pjob: 0x1c415f0 (substate=53)
12/08/2012 05:59:25;0100;PBS_Server;Job;16699.tyrone-cluster;dequeuing from qp32, state COMPLETE
12/08/2012 05:59:25;0040;PBS_Server;Svr;tyrone-cluster;Scheduler was sent the command term
12/08/2012 05:59:25;0008;PBS_Server;Job;16700.tyrone-cluster;Job Modified at request of Scheduler@tyrone-cluster
12/08/2012 05:59:25;0008;PBS_Server;Job;16725.tyrone-cluster;Job Modified at request of Scheduler@tyrone-cluster
12/08/2012 05:59:25;0008;PBS_Server;Job;16725.tyrone-cluster;Job Run at request of Scheduler@tyrone-cluster
12/08/2012 05:59:25;0040;PBS_Server;Svr;tyrone-cluster;Scheduler was sent the command recyc
12/08/2012 05:59:25;000d;PBS_Server;Job;16725.tyrone-cluster;Not sending email: User does not want mail of this type.
12/08/2012 05:59:47;0100;PBS_Server;Job;16712.tyrone-cluster;dequeuing from batch, state QUEUED
12/08/2012 05:59:47;0100;PBS_Server;Job;16712.tyrone-cluster;enqueuing into qp32, state 1 hop 1
12/08/2012 05:59:48;0040;PBS_Server;Svr;tyrone-cluster;Scheduler was sent the command new
12/08/2012 05:59:48;0008;PBS_Server;Job;16700.tyrone-cluster;Job Modified at request of Scheduler@tyrone-cluster
12/08/2012 05:59:48;0008;PBS_Server;Job;16712.tyrone-cluster;Job Modified at request of Scheduler@tyrone-cluster
12/08/2012 06:00:17;0040;PBS_Server;Svr;tyrone-cluster;Scheduler was sent the command new
12/08/2012 06:00:47;0040;PBS_Server;Svr;tyrone-cluster;Scheduler was sent the command new
12/08/2012 06:01:18;0040;PBS_Server;Svr;tyrone-cluster;Scheduler was sent the command new
12/08/2012 06:01:47;0040;PBS_Server;Svr;tyrone-cluster;Scheduler was sent the command new
12/08/2012 06:02:17;0040;PBS_Server;Svr;tyrone-cluster;Scheduler was sent the command new
12/08/2012 06:02:48;0040;PBS_Server;Svr;tyrone-cluster;Scheduler was sent the command new
12/08/2012 06:03:09;0002;PBS_Server;Svr;PBS_Server;Torque Server Version = 3.0.5, loglevel = 0
12/08/2012 06:03:17;0040;PBS_Server;Svr;tyrone-cluster;Scheduler was sent the command new
12/08/2012 06:03:47;0040;PBS_Server;Svr;tyrone-cluster;Scheduler was sent the command new
12/08/2012 06:04:18;0040;PBS_Server;Svr;tyrone-cluster;Scheduler was sent the command new
12/08/2012 06:04:47;0040;PBS_Server;Svr;tyrone-cluster;Scheduler was sent the command new
12/08/2012 06:05:17;0040;PBS_Server;Svr;tyrone-cluster;Scheduler was sent the command new
12/08/2012 06:05:48;0040;PBS_Server;Svr;tyrone-cluster;Scheduler was sent the command new
12/08/2012 06:06:17;0040;PBS_Server;Svr;tyrone-cluster;Scheduler was sent the command new
12/08/2012 06:06:47;0040;PBS_Server;Svr;tyrone-cluster;Scheduler was sent the command new
12/08/2012 06:07:18;0040;PBS_Server;Svr;tyrone-cluster;Scheduler was sent the command new
12/08/2012 06:07:47;0040;PBS_Server;Svr;tyrone-cluster;Scheduler was sent the command new
12/08/2012 06:08:09;0002;PBS_Server;Svr;PBS_Server;Torque Server Version = 3.0.5, loglevel = 0
12/08/2012 06:08:17;0040;PBS_Server;Svr;tyrone-cluster;Scheduler was sent the command new
12/08/2012 06:08:48;0040;PBS_Server;Svr;tyrone-cluster;Scheduler was sent the command new
12/08/2012 06:09:17;0040;PBS_Server;Svr;tyrone-cluster;Scheduler was sent the command new
12/08/2012 06:09:47;0040;PBS_Server;Svr;tyrone-cluster;Scheduler was sent the command new
12/08/2012 06:10:18;0040;PBS_Server;Svr;tyrone-cluster;Scheduler was sent the command new
12/08/2012 06:10:47;0040;PBS_Server;Svr;tyrone-cluster;Scheduler was sent the command new
12/08/2012 06:11:17;0040;PBS_Server;Svr;tyrone-cluster;Scheduler was sent the command new
12/08/2012 06:11:48;0040;PBS_Server;Svr;tyrone-cluster;Scheduler was sent the command new
12/08/2012 06:12:17;0040;PBS_Server;Svr;tyrone-cluster;Scheduler was sent the command new
12/08/2012 06:12:47;0040;PBS_Server;Svr;tyrone-cluster;Scheduler was sent the command new
12/08/2012 06:13:09;0002;PBS_Server;Svr;PBS_Server;Torque Server Version = 3.0.5, loglevel = 0
12/08/2012 06:13:18;0040;PBS_Server;Svr;tyrone-cluster;Scheduler was sent the command new
12/08/2012 06:13:47;0040;PBS_Server;Svr;tyrone-cluster;Scheduler was sent the command new
12/08/2012 06:14:17;0040;PBS_Server;Svr;tyrone-cluster;Scheduler was sent the command new
12/08/2012 06:14:48;0040;PBS_Server;Svr;tyrone-cluster;Scheduler was sent the command new
12/08/2012 06:15:17;0040;PBS_Server;Svr;tyrone-cluster;Scheduler was sent the command new
12/08/2012 06:15:47;0040;PBS_Server;Svr;tyrone-cluster;Scheduler was sent the command new
12/08/2012 06:16:18;0040;PBS_Server;Svr;tyrone-cluster;Scheduler was sent the command new
12/08/2012 06:16:47;0040;PBS_Server;Svr;tyrone-cluster;Scheduler was sent the command new
12/08/2012 06:17:17;0040;PBS_Server;Svr;tyrone-cluster;Scheduler was sent the command new
12/08/2012 06:17:48;0040;PBS_Server;Svr;tyrone-cluster;Scheduler was sent the command new
12/08/2012 06:18:09;0002;PBS_Server;Svr;PBS_Server;Torque Server Version = 3.0.5, loglevel = 0
12/08/2012 06:18:17;0040;PBS_Server;Svr;tyrone-cluster;Scheduler was sent the command new
12/08/2012 06:18:47;0040;PBS_Server;Svr;tyrone-cluster;Scheduler was sent the command new
12/08/2012 06:19:18;0040;PBS_Server;Svr;tyrone-cluster;Scheduler was sent the command new
12/08/2012 06:19:47;0040;PBS_Server;Svr;tyrone-cluster;Scheduler was sent the command new
12/08/2012 06:20:17;0040;PBS_Server;Svr;tyrone-cluster;Scheduler was sent the command new
12/08/2012 06:20:48;0040;PBS_Server;Svr;tyrone-cluster;Scheduler was sent the command new
12/08/2012 06:21:17;0040;PBS_Server;Svr;tyrone-cluster;Scheduler was sent the command new
12/08/2012 06:21:47;0040;PBS_Server;Svr;tyrone-cluster;Scheduler was sent the command new
12/08/2012 06:22:18;0040;PBS_Server;Svr;tyrone-cluster;Scheduler was sent the command new
12/08/2012 06:22:47;0040;PBS_Server;Svr;tyrone-cluster;Scheduler was sent the command new
12/08/2012 06:23:09;0002;PBS_Server;Svr;PBS_Server;Torque Server Version = 3.0.5, loglevel = 0
12/08/2012 06:23:17;0040;PBS_Server;Svr;tyrone-cluster;Scheduler was sent the command new
12/08/2012 06:23:48;0040;PBS_Server;Svr;tyrone-cluster;Scheduler was sent the command new
12/08/2012 06:24:17;0040;PBS_Server;Svr;tyrone-cluster;Scheduler was sent the command new
12/08/2012 06:24:47;0040;PBS_Server;Svr;tyrone-cluster;Scheduler was sent the command new
12/08/2012 06:25:18;0040;PBS_Server;Svr;tyrone-cluster;Scheduler was sent the command new
12/08/2012 06:25:47;0040;PBS_Server;Svr;tyrone-cluster;Scheduler was sent the command new
12/08/2012 06:26:17;0040;PBS_Server;Svr;tyrone-cluster;Scheduler was sent the command new
12/08/2012 06:26:48;0040;PBS_Server;Svr;tyrone-cluster;Scheduler was sent the command new
12/08/2012 06:27:17;0040;PBS_Server;Svr;tyrone-cluster;Scheduler was sent the command new
12/08/2012 06:27:47;0040;PBS_Server;Svr;tyrone-cluster;Scheduler was sent the command new
12/08/2012 06:28:09;0002;PBS_Server;Svr;PBS_Server;Torque Server Version = 3.0.5, loglevel = 0
12/08/2012 06:28:18;0040;PBS_Server;Svr;tyrone-cluster;Scheduler was sent the command new
12/08/2012 06:28:47;0040;PBS_Server;Svr;tyrone-cluster;Scheduler was sent the command new
12/08/2012 06:29:17;0040;PBS_Server;Svr;tyrone-cluster;Scheduler was sent the command new
12/08/2012 06:29:48;0040;PBS_Server;Svr;tyrone-cluster;Scheduler was sent the command new
12/08/2012 06:30:17;0040;PBS_Server;Svr;tyrone-cluster;Scheduler was sent the command new
12/08/2012 06:30:47;0040;PBS_Server;Svr;tyrone-cluster;Scheduler was sent the command new
12/08/2012 06:31:18;0040;PBS_Server;Svr;tyrone-cluster;Scheduler was sent the command new
12/08/2012 06:31:47;0040;PBS_Server;Svr;tyrone-cluster;Scheduler was sent the command new
12/08/2012 06:32:17;0040;PBS_Server;Svr;tyrone-cluster;Scheduler was sent the command new
12/08/2012 06:32:48;0040;PBS_Server;Svr;tyrone-cluster;Scheduler was sent the command new
12/08/2012 06:33:09;0002;PBS_Server;Svr;PBS_Server;Torque Server Version = 3.0.5, loglevel = 0
12/08/2012 06:33:17;0040;PBS_Server;Svr;tyrone-cluster;Scheduler was sent the command new
12/08/2012 06:33:47;0040;PBS_Server;Svr;tyrone-cluster;Scheduler was sent the command new
12/08/2012 06:34:18;0040;PBS_Server;Svr;tyrone-cluster;Scheduler was sent the command new
12/08/2012 06:34:47;0040;PBS_Server;Svr;tyrone-cluster;Scheduler was sent the command new
12/08/2012 06:35:17;0040;PBS_Server;Svr;tyrone-cluster;Scheduler was sent the command new
12/08/2012 06:35:48;0040;PBS_Server;Svr;tyrone-cluster;Scheduler was sent the command new
12/08/2012 06:36:17;0040;PBS_Server;Svr;tyrone-cluster;Scheduler was sent the command new
12/08/2012 06:36:47;0040;PBS_Server;Svr;tyrone-cluster;Scheduler was sent the command new
12/08/2012 06:37:18;0040;PBS_Server;Svr;tyrone-cluster;Scheduler was sent the command new
12/08/2012 06:37:47;0040;PBS_Server;Svr;tyrone-cluster;Scheduler was sent the command new
12/08/2012 06:38:09;0002;PBS_Server;Svr;PBS_Server;Torque Server Version = 3.0.5, loglevel = 0
12/08/2012 06:38:17;0040;PBS_Server;Svr;tyrone-cluster;Scheduler was sent the command new
12/08/2012 06:38:48;0040;PBS_Server;Svr;tyrone-cluster;Scheduler was sent the command new
12/08/2012 06:39:17;0040;PBS_Server;Svr;tyrone-cluster;Scheduler was sent the command new
12/08/2012 06:39:47;0040;PBS_Server;Svr;tyrone-cluster;Scheduler was sent the command new
12/08/2012 06:40:18;0040;PBS_Server;Svr;tyrone-cluster;Scheduler was sent the command new
12/08/2012 06:40:47;0040;PBS_Server;Svr;tyrone-cluster;Scheduler was sent the command new
12/08/2012 06:41:17;0040;PBS_Server;Svr;tyrone-cluster;Scheduler was sent the command new
12/08/2012 06:41:48;0040;PBS_Server;Svr;tyrone-cluster;Scheduler was sent the command new
12/08/2012 06:42:17;0040;PBS_Server;Svr;tyrone-cluster;Scheduler was sent the command new
12/08/2012 06:42:47;0040;PBS_Server;Svr;tyrone-cluster;Scheduler was sent the command new
12/08/2012 06:43:09;0002;PBS_Server;Svr;PBS_Server;Torque Server Version = 3.0.5, loglevel = 0
12/08/2012 06:43:18;0040;PBS_Server;Svr;tyrone-cluster;Scheduler was sent the command new
12/08/2012 06:43:47;0040;PBS_Server;Svr;tyrone-cluster;Scheduler was sent the command new
12/08/2012 06:44:17;0040;PBS_Server;Svr;tyrone-cluster;Scheduler was sent the command new
12/08/2012 06:44:48;0040;PBS_Server;Svr;tyrone-cluster;Scheduler was sent the command new
12/08/2012 06:45:17;0040;PBS_Server;Svr;tyrone-cluster;Scheduler was sent the command new
12/08/2012 06:45:47;0040;PBS_Server;Svr;tyrone-cluster;Scheduler was sent the command new
12/08/2012 06:46:18;0040;PBS_Server;Svr;tyrone-cluster;Scheduler was sent the command new
12/08/2012 06:46:47;0040;PBS_Server;Svr;tyrone-cluster;Scheduler was sent the command new
12/08/2012 06:47:17;0040;PBS_Server;Svr;tyrone-cluster;Scheduler was sent the command new
12/08/2012 06:47:48;0040;PBS_Server;Svr;tyrone-cluster;Scheduler was sent the command new
12/08/2012 06:48:09;0002;PBS_Server;Svr;PBS_Server;Torque Server Version = 3.0.5, loglevel = 0
12/08/2012 06:48:17;0040;PBS_Server;Svr;tyrone-cluster;Scheduler was sent the command new
12/08/2012 06:48:47;0040;PBS_Server;Svr;tyrone-cluster;Scheduler was sent the command new
12/08/2012 06:49:18;0040;PBS_Server;Svr;tyrone-cluster;Scheduler was sent the command new
12/08/2012 06:49:47;0040;PBS_Server;Svr;tyrone-cluster;Scheduler was sent the command new
12/08/2012 06:50:17;0040;PBS_Server;Svr;tyrone-cluster;Scheduler was sent the command new
12/08/2012 06:50:48;0040;PBS_Server;Svr;tyrone-cluster;Scheduler was sent the command new
12/08/2012 06:51:17;0040;PBS_Server;Svr;tyrone-cluster;Scheduler was sent the command new
12/08/2012 06:51:47;0040;PBS_Server;Svr;tyrone-cluster;Scheduler was sent the command new
12/08/2012 06:52:18;0040;PBS_Server;Svr;tyrone-cluster;Scheduler was sent the command new
12/08/2012 06:52:47;0040;PBS_Server;Svr;tyrone-cluster;Scheduler was sent the command new
12/08/2012 06:53:09;0002;PBS_Server;Svr;PBS_Server;Torque Server Version = 3.0.5, loglevel = 0
12/08/2012 06:53:17;0040;PBS_Server;Svr;tyrone-cluster;Scheduler was sent the command new
12/08/2012 06:53:48;0040;PBS_Server;Svr;tyrone-cluster;Scheduler was sent the command new
12/08/2012 06:54:17;0040;PBS_Server;Svr;tyrone-cluster;Scheduler was sent the command new
12/08/2012 06:54:47;0040;PBS_Server;Svr;tyrone-cluster;Scheduler was sent the command new
12/08/2012 06:55:18;0040;PBS_Server;Svr;tyrone-cluster;Scheduler was sent the command new
12/08/2012 06:55:47;0040;PBS_Server;Svr;tyrone-cluster;Scheduler was sent the command new
12/08/2012 06:56:17;0040;PBS_Server;Svr;tyrone-cluster;Scheduler was sent the command new
12/08/2012 06:56:48;0040;PBS_Server;Svr;tyrone-cluster;Scheduler was sent the command new
12/08/2012 06:57:17;0040;PBS_Server;Svr;tyrone-cluster;Scheduler was sent the command new
12/08/2012 06:57:47;0040;PBS_Server;Svr;tyrone-cluster;Scheduler was sent the command new
12/08/2012 06:58:09;0002;PBS_Server;Svr;PBS_Server;Torque Server Version = 3.0.5, loglevel = 0
12/08/2012 06:58:18;0040;PBS_Server;Svr;tyrone-cluster;Scheduler was sent the command new
12/08/2012 06:58:47;0040;PBS_Server;Svr;tyrone-cluster;Scheduler was sent the command new
12/08/2012 06:59:17;0040;PBS_Server;Svr;tyrone-cluster;Scheduler was sent the command new
12/08/2012 06:59:48;0040;PBS_Server;Svr;tyrone-cluster;Scheduler was sent the command new
12/08/2012 07:00:17;0040;PBS_Server;Svr;tyrone-cluster;Scheduler was sent the command new
12/08/2012 07:00:47;0040;PBS_Server;Svr;tyrone-cluster;Scheduler was sent the command new
12/08/2012 07:01:18;0040;PBS_Server;Svr;tyrone-cluster;Scheduler was sent the command new
12/08/2012 07:01:47;0040;PBS_Server;Svr;tyrone-cluster;Scheduler was sent the command new
12/08/2012 07:02:17;0040;PBS_Server;Svr;tyrone-cluster;Scheduler was sent the command new
12/08/2012 07:02:48;0040;PBS_Server;Svr;tyrone-cluster;Scheduler was sent the command new
12/08/2012 07:03:09;0002;PBS_Server;Svr;PBS_Server;Torque Server Version = 3.0.5, loglevel = 0
12/08/2012 07:03:17;0040;PBS_Server;Svr;tyrone-cluster;Scheduler was sent the command new
12/08/2012 07:03:47;0040;PBS_Server;Svr;tyrone-cluster;Scheduler was sent the command new
12/08/2012 07:04:18;0040;PBS_Server;Svr;tyrone-cluster;Scheduler was sent the command new
12/08/2012 07:04:47;0040;PBS_Server;Svr;tyrone-cluster;Scheduler was sent the command new
12/08/2012 07:05:17;0040;PBS_Server;Svr;tyrone-cluster;Scheduler was sent the command new
12/08/2012 07:05:48;0040;PBS_Server;Svr;tyrone-cluster;Scheduler was sent the command new
12/08/2012 07:06:17;0040;PBS_Server;Svr;tyrone-cluster;Scheduler was sent the command new
12/08/2012 07:06:47;0040;PBS_Server;Svr;tyrone-cluster;Scheduler was sent the command new
12/08/2012 07:07:18;0040;PBS_Server;Svr;tyrone-cluster;Scheduler was sent the command new
12/08/2012 07:07:47;0040;PBS_Server;Svr;tyrone-cluster;Scheduler was sent the command new
12/08/2012 07:08:09;0002;PBS_Server;Svr;PBS_Server;Torque Server Version = 3.0.5, loglevel = 0
12/08/2012 07:08:17;0040;PBS_Server;Svr;tyrone-cluster;Scheduler was sent the command new
12/08/2012 07:08:48;0040;PBS_Server;Svr;tyrone-cluster;Scheduler was sent the command new
12/08/2012 07:09:17;0040;PBS_Server;Svr;tyrone-cluster;Scheduler was sent the command new
12/08/2012 07:09:47;0040;PBS_Server;Svr;tyrone-cluster;Scheduler was sent the command new
12/08/2012 07:10:18;0040;PBS_Server;Svr;tyrone-cluster;Scheduler was sent the command new
12/08/2012 07:10:47;0040;PBS_Server;Svr;tyrone-cluster;Scheduler was sent the command new
12/08/2012 07:11:17;0040;PBS_Server;Svr;tyrone-cluster;Scheduler was sent the command new
12/08/2012 07:11:48;0040;PBS_Server;Svr;tyrone-cluster;Scheduler was sent the command new
12/08/2012 07:12:17;0040;PBS_Server;Svr;tyrone-cluster;Scheduler was sent the command new
12/08/2012 07:12:47;0040;PBS_Server;Svr;tyrone-cluster;Scheduler was sent the command new
12/08/2012 07:13:09;0002;PBS_Server;Svr;PBS_Server;Torque Server Version = 3.0.5, loglevel = 0
12/08/2012 07:13:18;0040;PBS_Server;Svr;tyrone-cluster;Scheduler was sent the command new
12/08/2012 07:13:47;0040;PBS_Server;Svr;tyrone-cluster;Scheduler was sent the command new
12/08/2012 07:14:17;0040;PBS_Server;Svr;tyrone-cluster;Scheduler was sent the command new
12/08/2012 07:14:48;0040;PBS_Server;Svr;tyrone-cluster;Scheduler was sent the command new
12/08/2012 07:15:17;0040;PBS_Server;Svr;tyrone-cluster;Scheduler was sent the command new
12/08/2012 07:15:47;0040;PBS_Server;Svr;tyrone-cluster;Scheduler was sent the command new
12/08/2012 07:16:18;0040;PBS_Server;Svr;tyrone-cluster;Scheduler was sent the command new
12/08/2012 07:16:47;0040;PBS_Server;Svr;tyrone-cluster;Scheduler was sent the command new
12/08/2012 07:17:17;0040;PBS_Server;Svr;tyrone-cluster;Scheduler was sent the command new
12/08/2012 07:17:48;0040;PBS_Server;Svr;tyrone-cluster;Scheduler was sent the command new
12/08/2012 07:18:09;0002;PBS_Server;Svr;PBS_Server;Torque Server Version = 3.0.5, loglevel = 0
12/08/2012 07:18:17;0040;PBS_Server;Svr;tyrone-cluster;Scheduler was sent the command new
12/08/2012 07:18:47;0040;PBS_Server;Svr;tyrone-cluster;Scheduler was sent the command new
12/08/2012 07:19:18;0040;PBS_Server;Svr;tyrone-cluster;Scheduler was sent the command new
12/08/2012 07:19:47;0040;PBS_Server;Svr;tyrone-cluster;Scheduler was sent the command new
12/08/2012 07:20:17;0040;PBS_Server;Svr;tyrone-cluster;Scheduler was sent the command new
12/08/2012 07:20:48;0040;PBS_Server;Svr;tyrone-cluster;Scheduler was sent the command new
12/08/2012 07:21:17;0040;PBS_Server;Svr;tyrone-cluster;Scheduler was sent the command new
12/08/2012 07:21:47;0040;PBS_Server;Svr;tyrone-cluster;Scheduler was sent the command new
12/08/2012 07:22:18;0040;PBS_Server;Svr;tyrone-cluster;Scheduler was sent the command new
12/08/2012 07:22:47;0040;PBS_Server;Svr;tyrone-cluster;Scheduler was sent the command new
12/08/2012 07:23:09;0002;PBS_Server;Svr;PBS_Server;Torque Server Version = 3.0.5, loglevel = 0
12/08/2012 07:23:17;0040;PBS_Server;Svr;tyrone-cluster;Scheduler was sent the command new
12/08/2012 07:23:48;0040;PBS_Server;Svr;tyrone-cluster;Scheduler was sent the command new
12/08/2012 07:24:17;0040;PBS_Server;Svr;tyrone-cluster;Scheduler was sent the command new
12/08/2012 07:24:47;0040;PBS_Server;Svr;tyrone-cluster;Scheduler was sent the command new
12/08/2012 07:25:18;0040;PBS_Server;Svr;tyrone-cluster;Scheduler was sent the command new
12/08/2012 07:25:47;0040;PBS_Server;Svr;tyrone-cluster;Scheduler was sent the command new
12/08/2012 07:26:17;0040;PBS_Server;Svr;tyrone-cluster;Scheduler was sent the command new
12/08/2012 07:26:48;0040;PBS_Server;Svr;tyrone-cluster;Scheduler was sent the command new
12/08/2012 07:27:17;0040;PBS_Server;Svr;tyrone-cluster;Scheduler was sent the command new
12/08/2012 07:27:47;0040;PBS_Server;Svr;tyrone-cluster;Scheduler was sent the command new
12/08/2012 07:28:09;0002;PBS_Server;Svr;PBS_Server;Torque Server Version = 3.0.5, loglevel = 0
12/08/2012 07:28:18;0040;PBS_Server;Svr;tyrone-cluster;Scheduler was sent the command new
12/08/2012 07:28:47;0040;PBS_Server;Svr;tyrone-cluster;Scheduler was sent the command new
12/08/2012 07:29:17;0040;PBS_Server;Svr;tyrone-cluster;Scheduler was sent the command new
12/08/2012 07:29:48;0040;PBS_Server;Svr;tyrone-cluster;Scheduler was sent the command new
12/08/2012 07:30:17;0040;PBS_Server;Svr;tyrone-cluster;Scheduler was sent the command new
12/08/2012 07:30:47;0040;PBS_Server;Svr;tyrone-cluster;Scheduler was sent the command new
12/08/2012 07:31:06;000d;PBS_Server;Job;16589.tyrone-cluster;Not sending email: User does not want mail of this type.
12/08/2012 07:31:06;0010;PBS_Server;Job;16589.tyrone-cluster;Exit_status=0 resources_used.cput=53:30:01 resources_used.mem=9574424kb resources_used.vmem=25570336kb resources_used.walltime=06:12:38
12/08/2012 07:31:06;0008;PBS_Server;Job;NULL;on_job_exit valid pjob: 0x1bb9bd0 (substate=50)
12/08/2012 07:31:06;0008;PBS_Server;Job;NULL;on_job_exit valid pjob: 0x1bb9bd0 (substate=51)
12/08/2012 07:31:06;0008;PBS_Server;Job;NULL;on_job_exit valid pjob: 0x1bb9bd0 (substate=51)
12/08/2012 07:31:06;0008;PBS_Server;Job;NULL;on_job_exit valid pjob: 0x1bb9bd0 (substate=53)
12/08/2012 07:31:06;0100;PBS_Server;Job;16589.tyrone-cluster;dequeuing from qp64, state COMPLETE
12/08/2012 07:31:06;0040;PBS_Server;Svr;tyrone-cluster;Scheduler was sent the command term
12/08/2012 07:31:06;0008;PBS_Server;Job;16595.tyrone-cluster;Job Modified at request of Scheduler@tyrone-cluster
12/08/2012 07:31:06;0008;PBS_Server;Job;16224.tyrone-cluster;Job Modified at request of Scheduler@tyrone-cluster
12/08/2012 07:31:06;0008;PBS_Server;Job;16224.tyrone-cluster;Job Run at request of Scheduler@tyrone-cluster
12/08/2012 07:31:06;0040;PBS_Server;Svr;tyrone-cluster;Scheduler was sent the command recyc
12/08/2012 07:31:06;000d;PBS_Server;Job;16224.tyrone-cluster;Not sending email: User does not want mail of this type.
12/08/2012 07:31:18;0040;PBS_Server;Svr;tyrone-cluster;Scheduler was sent the command new
12/08/2012 07:31:18;0008;PBS_Server;Job;16595.tyrone-cluster;Job Modified at request of Scheduler@tyrone-cluster
12/08/2012 07:31:47;0040;PBS_Server;Svr;tyrone-cluster;Scheduler was sent the command new
12/08/2012 07:32:17;0040;PBS_Server;Svr;tyrone-cluster;Scheduler was sent the command new
12/08/2012 07:32:48;0040;PBS_Server;Svr;tyrone-cluster;Scheduler was sent the command new
12/08/2012 07:33:09;0002;PBS_Server;Svr;PBS_Server;Torque Server Version = 3.0.5, loglevel = 0
12/08/2012 07:33:17;0040;PBS_Server;Svr;tyrone-cluster;Scheduler was sent the command new
12/08/2012 07:33:47;0040;PBS_Server;Svr;tyrone-cluster;Scheduler was sent the command new
12/08/2012 07:34:18;0040;PBS_Server;Svr;tyrone-cluster;Scheduler was sent the command new
12/08/2012 07:34:47;0040;PBS_Server;Svr;tyrone-cluster;Scheduler was sent the command new
12/08/2012 07:35:17;0040;PBS_Server;Svr;tyrone-cluster;Scheduler was sent the command new
12/08/2012 07:35:48;0040;PBS_Server;Svr;tyrone-cluster;Scheduler was sent the command new
12/08/2012 07:36:17;0040;PBS_Server;Svr;tyrone-cluster;Scheduler was sent the command new
12/08/2012 07:36:47;0040;PBS_Server;Svr;tyrone-cluster;Scheduler was sent the command new
12/08/2012 07:37:18;0040;PBS_Server;Svr;tyrone-cluster;Scheduler was sent the command new
12/08/2012 07:37:47;0040;PBS_Server;Svr;tyrone-cluster;Scheduler was sent the command new
12/08/2012 07:38:09;0002;PBS_Server;Svr;PBS_Server;Torque Server Version = 3.0.5, loglevel = 0
12/08/2012 07:38:17;0040;PBS_Server;Svr;tyrone-cluster;Scheduler was sent the command new
12/08/2012 07:38:48;0040;PBS_Server;Svr;tyrone-cluster;Scheduler was sent the command new
12/08/2012 07:39:17;0040;PBS_Server;Svr;tyrone-cluster;Scheduler was sent the command new
12/08/2012 07:39:47;0040;PBS_Server;Svr;tyrone-cluster;Scheduler was sent the command new
12/08/2012 07:40:18;0040;PBS_Server;Svr;tyrone-cluster;Scheduler was sent the command new
12/08/2012 07:40:47;0040;PBS_Server;Svr;tyrone-cluster;Scheduler was sent the command new
12/08/2012 07:41:17;0040;PBS_Server;Svr;tyrone-cluster;Scheduler was sent the command new
12/08/2012 07:41:48;0040;PBS_Server;Svr;tyrone-cluster;Scheduler was sent the command new
12/08/2012 07:42:17;0040;PBS_Server;Svr;tyrone-cluster;Scheduler was sent the command new
12/08/2012 07:42:47;0040;PBS_Server;Svr;tyrone-cluster;Scheduler was sent the command new
12/08/2012 07:43:09;0002;PBS_Server;Svr;PBS_Server;Torque Server Version = 3.0.5, loglevel = 0
12/08/2012 07:43:18;0040;PBS_Server;Svr;tyrone-cluster;Scheduler was sent the command new
12/08/2012 07:43:47;0040;PBS_Server;Svr;tyrone-cluster;Scheduler was sent the command new
12/08/2012 07:44:17;0040;PBS_Server;Svr;tyrone-cluster;Scheduler was sent the command new
12/08/2012 07:44:48;0040;PBS_Server;Svr;tyrone-cluster;Scheduler was sent the command new
12/08/2012 07:45:17;0040;PBS_Server;Svr;tyrone-cluster;Scheduler was sent the command new
12/08/2012 07:45:47;0040;PBS_Server;Svr;tyrone-cluster;Scheduler was sent the command new
12/08/2012 07:46:18;0040;PBS_Server;Svr;tyrone-cluster;Scheduler was sent the command new
12/08/2012 07:46:47;0040;PBS_Server;Svr;tyrone-cluster;Scheduler was sent the command new
12/08/2012 07:47:17;0040;PBS_Server;Svr;tyrone-cluster;Scheduler was sent the command new
12/08/2012 07:47:48;0040;PBS_Server;Svr;tyrone-cluster;Scheduler was sent the command new
12/08/2012 07:48:09;0002;PBS_Server;Svr;PBS_Server;Torque Server Version = 3.0.5, loglevel = 0
12/08/2012 07:48:17;0040;PBS_Server;Svr;tyrone-cluster;Scheduler was sent the command new
12/08/2012 07:48:47;0040;PBS_Server;Svr;tyrone-cluster;Scheduler was sent the command new
12/08/2012 07:49:18;0040;PBS_Server;Svr;tyrone-cluster;Scheduler was sent the command new
12/08/2012 07:49:47;0040;PBS_Server;Svr;tyrone-cluster;Scheduler was sent the command new
12/08/2012 07:50:17;0040;PBS_Server;Svr;tyrone-cluster;Scheduler was sent the command new
12/08/2012 07:50:48;0040;PBS_Server;Svr;tyrone-cluster;Scheduler was sent the command new
12/08/2012 07:51:17;0040;PBS_Server;Svr;tyrone-cluster;Scheduler was sent the command new
12/08/2012 07:51:47;0040;PBS_Server;Svr;tyrone-cluster;Scheduler was sent the command new
12/08/2012 07:52:18;0040;PBS_Server;Svr;tyrone-cluster;Scheduler was sent the command new
12/08/2012 07:52:47;0040;PBS_Server;Svr;tyrone-cluster;Scheduler was sent the command new
12/08/2012 07:53:09;0002;PBS_Server;Svr;PBS_Server;Torque Server Version = 3.0.5, loglevel = 0
12/08/2012 07:53:17;0040;PBS_Server;Svr;tyrone-cluster;Scheduler was sent the command new
12/08/2012 07:53:48;0040;PBS_Server;Svr;tyrone-cluster;Scheduler was sent the command new
12/08/2012 07:54:17;0040;PBS_Server;Svr;tyrone-cluster;Scheduler was sent the command new
12/08/2012 07:54:47;0040;PBS_Server;Svr;tyrone-cluster;Scheduler was sent the command new
12/08/2012 07:55:18;0040;PBS_Server;Svr;tyrone-cluster;Scheduler was sent the command new
12/08/2012 07:55:47;0040;PBS_Server;Svr;tyrone-cluster;Scheduler was sent the command new
12/08/2012 07:56:17;0040;PBS_Server;Svr;tyrone-cluster;Scheduler was sent the command new
12/08/2012 07:56:48;0040;PBS_Server;Svr;tyrone-cluster;Scheduler was sent the command new
12/08/2012 07:57:17;0040;PBS_Server;Svr;tyrone-cluster;Scheduler was sent the command new
12/08/2012 07:57:47;0040;PBS_Server;Svr;tyrone-cluster;Scheduler was sent the command new
12/08/2012 07:58:09;0002;PBS_Server;Svr;PBS_Server;Torque Server Version = 3.0.5, loglevel = 0
12/08/2012 07:58:18;0040;PBS_Server;Svr;tyrone-cluster;Scheduler was sent the command new
12/08/2012 07:58:47;0040;PBS_Server;Svr;tyrone-cluster;Scheduler was sent the command new
12/08/2012 07:59:17;0040;PBS_Server;Svr;tyrone-cluster;Scheduler was sent the command new
12/08/2012 07:59:48;0040;PBS_Server;Svr;tyrone-cluster;Scheduler was sent the command new
12/08/2012 08:00:17;0040;PBS_Server;Svr;tyrone-cluster;Scheduler was sent the command new
12/08/2012 08:00:47;0040;PBS_Server;Svr;tyrone-cluster;Scheduler was sent the command new
12/08/2012 08:01:18;0040;PBS_Server;Svr;tyrone-cluster;Scheduler was sent the command new
12/08/2012 08:01:47;0040;PBS_Server;Svr;tyrone-cluster;Scheduler was sent the command new
12/08/2012 08:02:17;0040;PBS_Server;Svr;tyrone-cluster;Scheduler was sent the command new
12/08/2012 08:02:48;0040;PBS_Server;Svr;tyrone-cluster;Scheduler was sent the command new
12/08/2012 08:03:09;0002;PBS_Server;Svr;PBS_Server;Torque Server Version = 3.0.5, loglevel = 0
12/08/2012 08:03:17;0040;PBS_Server;Svr;tyrone-cluster;Scheduler was sent the command new
12/08/2012 08:03:47;0040;PBS_Server;Svr;tyrone-cluster;Scheduler was sent the command new
12/08/2012 08:04:18;0040;PBS_Server;Svr;tyrone-cluster;Scheduler was sent the command new
12/08/2012 08:04:47;0040;PBS_Server;Svr;tyrone-cluster;Scheduler was sent the command new
12/08/2012 08:05:17;0040;PBS_Server;Svr;tyrone-cluster;Scheduler was sent the command new
12/08/2012 08:05:48;0040;PBS_Server;Svr;tyrone-cluster;Scheduler was sent the command new
12/08/2012 08:06:17;0040;PBS_Server;Svr;tyrone-cluster;Scheduler was sent the command new
12/08/2012 08:06:47;0040;PBS_Server;Svr;tyrone-cluster;Scheduler was sent the command new
12/08/2012 08:07:18;0040;PBS_Server;Svr;tyrone-cluster;Scheduler was sent the command new
12/08/2012 08:07:47;0040;PBS_Server;Svr;tyrone-cluster;Scheduler was sent the command new
12/08/2012 08:08:09;0002;PBS_Server;Svr;PBS_Server;Torque Server Version = 3.0.5, loglevel = 0
12/08/2012 08:08:17;0040;PBS_Server;Svr;tyrone-cluster;Scheduler was sent the command new
12/08/2012 08:08:48;0040;PBS_Server;Svr;tyrone-cluster;Scheduler was sent the command new
12/08/2012 08:09:17;0040;PBS_Server;Svr;tyrone-cluster;Scheduler was sent the command new
12/08/2012 08:09:47;0040;PBS_Server;Svr;tyrone-cluster;Scheduler was sent the command new
12/08/2012 08:10:18;0040;PBS_Server;Svr;tyrone-cluster;Scheduler was sent the command new
12/08/2012 08:10:47;0040;PBS_Server;Svr;tyrone-cluster;Scheduler was sent the command new
12/08/2012 08:11:17;0040;PBS_Server;Svr;tyrone-cluster;Scheduler was sent the command new
12/08/2012 08:11:48;0040;PBS_Server;Svr;tyrone-cluster;Scheduler was sent the command new
12/08/2012 08:12:17;0040;PBS_Server;Svr;tyrone-cluster;Scheduler was sent the command new
12/08/2012 08:12:47;0040;PBS_Server;Svr;tyrone-cluster;Scheduler was sent the command new
12/08/2012 08:13:09;0002;PBS_Server;Svr;PBS_Server;Torque Server Version = 3.0.5, loglevel = 0
12/08/2012 08:13:18;0040;PBS_Server;Svr;tyrone-cluster;Scheduler was sent the command new
12/08/2012 08:13:47;0040;PBS_Server;Svr;tyrone-cluster;Scheduler was sent the command new
12/08/2012 08:14:17;0040;PBS_Server;Svr;tyrone-cluster;Scheduler was sent the command new
12/08/2012 08:14:48;0040;PBS_Server;Svr;tyrone-cluster;Scheduler was sent the command new
12/08/2012 08:15:17;0040;PBS_Server;Svr;tyrone-cluster;Scheduler was sent the command new
12/08/2012 08:15:47;0040;PBS_Server;Svr;tyrone-cluster;Scheduler was sent the command new
12/08/2012 08:16:18;0040;PBS_Server;Svr;tyrone-cluster;Scheduler was sent the command new
12/08/2012 08:16:47;0040;PBS_Server;Svr;tyrone-cluster;Scheduler was sent the command new
12/08/2012 08:17:17;0040;PBS_Server;Svr;tyrone-cluster;Scheduler was sent the command new
12/08/2012 08:17:48;0040;PBS_Server;Svr;tyrone-cluster;Scheduler was sent the command new
12/08/2012 08:18:09;0002;PBS_Server;Svr;PBS_Server;Torque Server Version = 3.0.5, loglevel = 0
12/08/2012 08:18:17;0040;PBS_Server;Svr;tyrone-cluster;Scheduler was sent the command new
12/08/2012 08:18:47;0040;PBS_Server;Svr;tyrone-cluster;Scheduler was sent the command new
12/08/2012 08:19:18;0040;PBS_Server;Svr;tyrone-cluster;Scheduler was sent the command new
12/08/2012 08:19:47;0040;PBS_Server;Svr;tyrone-cluster;Scheduler was sent the command new
12/08/2012 08:20:17;0040;PBS_Server;Svr;tyrone-cluster;Scheduler was sent the command new
12/08/2012 08:20:48;0040;PBS_Server;Svr;tyrone-cluster;Scheduler was sent the command new
12/08/2012 08:21:17;0040;PBS_Server;Svr;tyrone-cluster;Scheduler was sent the command new
12/08/2012 08:21:47;0040;PBS_Server;Svr;tyrone-cluster;Scheduler was sent the command new
12/08/2012 08:22:18;0040;PBS_Server;Svr;tyrone-cluster;Scheduler was sent the command new
12/08/2012 08:22:47;0040;PBS_Server;Svr;tyrone-cluster;Scheduler was sent the command new
12/08/2012 08:23:09;0002;PBS_Server;Svr;PBS_Server;Torque Server Version = 3.0.5, loglevel = 0
12/08/2012 08:23:17;0040;PBS_Server;Svr;tyrone-cluster;Scheduler was sent the command new
12/08/2012 08:23:48;0040;PBS_Server;Svr;tyrone-cluster;Scheduler was sent the command new
12/08/2012 08:24:17;0040;PBS_Server;Svr;tyrone-cluster;Scheduler was sent the command new
12/08/2012 08:24:47;0040;PBS_Server;Svr;tyrone-cluster;Scheduler was sent the command new
12/08/2012 08:25:18;0040;PBS_Server;Svr;tyrone-cluster;Scheduler was sent the command new
12/08/2012 08:25:47;0040;PBS_Server;Svr;tyrone-cluster;Scheduler was sent the command new
12/08/2012 08:26:17;0040;PBS_Server;Svr;tyrone-cluster;Scheduler was sent the command new
12/08/2012 08:26:48;0040;PBS_Server;Svr;tyrone-cluster;Scheduler was sent the command new
12/08/2012 08:27:17;0040;PBS_Server;Svr;tyrone-cluster;Scheduler was sent the command new
12/08/2012 08:27:47;0040;PBS_Server;Svr;tyrone-cluster;Scheduler was sent the command new
12/08/2012 08:28:09;0002;PBS_Server;Svr;PBS_Server;Torque Server Version = 3.0.5, loglevel = 0
12/08/2012 08:28:18;0040;PBS_Server;Svr;tyrone-cluster;Scheduler was sent the command new
12/08/2012 08:28:47;0040;PBS_Server;Svr;tyrone-cluster;Scheduler was sent the command new
12/08/2012 08:29:17;0040;PBS_Server;Svr;tyrone-cluster;Scheduler was sent the command new
12/08/2012 08:29:48;0040;PBS_Server;Svr;tyrone-cluster;Scheduler was sent the command new
12/08/2012 08:30:17;0040;PBS_Server;Svr;tyrone-cluster;Scheduler was sent the command new
12/08/2012 08:30:47;0040;PBS_Server;Svr;tyrone-cluster;Scheduler was sent the command new
12/08/2012 08:31:18;0040;PBS_Server;Svr;tyrone-cluster;Scheduler was sent the command new
12/08/2012 08:31:47;0040;PBS_Server;Svr;tyrone-cluster;Scheduler was sent the command new
12/08/2012 08:32:17;0040;PBS_Server;Svr;tyrone-cluster;Scheduler was sent the command new
12/08/2012 08:32:48;0040;PBS_Server;Svr;tyrone-cluster;Scheduler was sent the command new
12/08/2012 08:33:09;0002;PBS_Server;Svr;PBS_Server;Torque Server Version = 3.0.5, loglevel = 0
12/08/2012 08:33:17;0040;PBS_Server;Svr;tyrone-cluster;Scheduler was sent the command new
12/08/2012 08:33:47;0040;PBS_Server;Svr;tyrone-cluster;Scheduler was sent the command new
12/08/2012 08:34:18;0040;PBS_Server;Svr;tyrone-cluster;Scheduler was sent the command new
12/08/2012 08:34:47;0040;PBS_Server;Svr;tyrone-cluster;Scheduler was sent the command new
12/08/2012 08:35:17;0040;PBS_Server;Svr;tyrone-cluster;Scheduler was sent the command new
12/08/2012 08:35:48;0040;PBS_Server;Svr;tyrone-cluster;Scheduler was sent the command new
12/08/2012 08:35:55;000d;PBS_Server;Job;16706.tyrone-cluster;Not sending email: User does not want mail of this type.
12/08/2012 08:35:55;0010;PBS_Server;Job;16706.tyrone-cluster;Exit_status=0 resources_used.cput=514:20:26 resources_used.mem=9102992kb resources_used.vmem=12968708kb resources_used.walltime=16:38:25
12/08/2012 08:35:55;0008;PBS_Server;Job;NULL;on_job_exit valid pjob: 0x1cd08d0 (substate=50)
12/08/2012 08:35:55;0008;PBS_Server;Job;NULL;on_job_exit valid pjob: 0x1cd08d0 (substate=51)
12/08/2012 08:35:57;0008;PBS_Server;Job;NULL;on_job_exit valid pjob: 0x1cd08d0 (substate=51)
12/08/2012 08:35:57;0008;PBS_Server;Job;NULL;on_job_exit valid pjob: 0x1cd08d0 (substate=53)
12/08/2012 08:35:57;0100;PBS_Server;Job;16706.tyrone-cluster;dequeuing from qp32, state COMPLETE
12/08/2012 08:35:57;0040;PBS_Server;Svr;tyrone-cluster;Scheduler was sent the command term
12/08/2012 08:35:57;0008;PBS_Server;Job;16700.tyrone-cluster;Job Modified at request of Scheduler@tyrone-cluster
12/08/2012 08:35:57;0008;PBS_Server;Job;16726.tyrone-cluster;Job Modified at request of Scheduler@tyrone-cluster
12/08/2012 08:35:57;0008;PBS_Server;Job;16726.tyrone-cluster;Job Run at request of Scheduler@tyrone-cluster
12/08/2012 08:35:57;0040;PBS_Server;Svr;tyrone-cluster;Scheduler was sent the command recyc
12/08/2012 08:35:57;000d;PBS_Server;Job;16726.tyrone-cluster;Not sending email: User does not want mail of this type.
12/08/2012 08:36:17;0040;PBS_Server;Svr;tyrone-cluster;Scheduler was sent the command new
12/08/2012 08:36:17;0008;PBS_Server;Job;16700.tyrone-cluster;Job Modified at request of Scheduler@tyrone-cluster
12/08/2012 08:36:47;0040;PBS_Server;Svr;tyrone-cluster;Scheduler was sent the command new
12/08/2012 08:37:18;0040;PBS_Server;Svr;tyrone-cluster;Scheduler was sent the command new
12/08/2012 08:37:47;0040;PBS_Server;Svr;tyrone-cluster;Scheduler was sent the command new
12/08/2012 08:38:10;0002;PBS_Server;Svr;PBS_Server;Torque Server Version = 3.0.5, loglevel = 0
12/08/2012 08:38:17;0040;PBS_Server;Svr;tyrone-cluster;Scheduler was sent the command new
12/08/2012 08:38:48;0040;PBS_Server;Svr;tyrone-cluster;Scheduler was sent the command new
12/08/2012 08:39:17;0040;PBS_Server;Svr;tyrone-cluster;Scheduler was sent the command new
12/08/2012 08:39:47;0040;PBS_Server;Svr;tyrone-cluster;Scheduler was sent the command new
12/08/2012 08:40:18;0040;PBS_Server;Svr;tyrone-cluster;Scheduler was sent the command new
12/08/2012 08:40:47;0040;PBS_Server;Svr;tyrone-cluster;Scheduler was sent the command new
12/08/2012 08:41:17;0040;PBS_Server;Svr;tyrone-cluster;Scheduler was sent the command new
12/08/2012 08:41:48;0040;PBS_Server;Svr;tyrone-cluster;Scheduler was sent the command new
12/08/2012 08:42:17;0040;PBS_Server;Svr;tyrone-cluster;Scheduler was sent the command new
12/08/2012 08:42:47;0040;PBS_Server;Svr;tyrone-cluster;Scheduler was sent the command new
12/08/2012 08:43:10;0002;PBS_Server;Svr;PBS_Server;Torque Server Version = 3.0.5, loglevel = 0
12/08/2012 08:43:18;0040;PBS_Server;Svr;tyrone-cluster;Scheduler was sent the command new
12/08/2012 08:43:47;0040;PBS_Server;Svr;tyrone-cluster;Scheduler was sent the command new
12/08/2012 08:44:17;0040;PBS_Server;Svr;tyrone-cluster;Scheduler was sent the command new
12/08/2012 08:44:48;0040;PBS_Server;Svr;tyrone-cluster;Scheduler was sent the command new
12/08/2012 08:45:17;0040;PBS_Server;Svr;tyrone-cluster;Scheduler was sent the command new
12/08/2012 08:45:47;0040;PBS_Server;Svr;tyrone-cluster;Scheduler was sent the command new
12/08/2012 08:46:18;0040;PBS_Server;Svr;tyrone-cluster;Scheduler was sent the command new
12/08/2012 08:46:47;0040;PBS_Server;Svr;tyrone-cluster;Scheduler was sent the command new
12/08/2012 08:47:17;0040;PBS_Server;Svr;tyrone-cluster;Scheduler was sent the command new
12/08/2012 08:47:48;0040;PBS_Server;Svr;tyrone-cluster;Scheduler was sent the command new
12/08/2012 08:48:10;0002;PBS_Server;Svr;PBS_Server;Torque Server Version = 3.0.5, loglevel = 0
12/08/2012 08:48:17;0040;PBS_Server;Svr;tyrone-cluster;Scheduler was sent the command new
12/08/2012 08:48:47;0040;PBS_Server;Svr;tyrone-cluster;Scheduler was sent the command new
12/08/2012 08:49:18;0040;PBS_Server;Svr;tyrone-cluster;Scheduler was sent the command new
12/08/2012 08:49:47;0040;PBS_Server;Svr;tyrone-cluster;Scheduler was sent the command new
12/08/2012 08:50:17;0040;PBS_Server;Svr;tyrone-cluster;Scheduler was sent the command new
12/08/2012 08:50:48;0040;PBS_Server;Svr;tyrone-cluster;Scheduler was sent the command new
12/08/2012 08:51:17;0040;PBS_Server;Svr;tyrone-cluster;Scheduler was sent the command new
12/08/2012 08:51:47;0040;PBS_Server;Svr;tyrone-cluster;Scheduler was sent the command new
12/08/2012 08:52:18;0040;PBS_Server;Svr;tyrone-cluster;Scheduler was sent the command new
12/08/2012 08:52:47;0040;PBS_Server;Svr;tyrone-cluster;Scheduler was sent the command new
12/08/2012 08:53:10;0002;PBS_Server;Svr;PBS_Server;Torque Server Version = 3.0.5, loglevel = 0
12/08/2012 08:53:17;0040;PBS_Server;Svr;tyrone-cluster;Scheduler was sent the command new
12/08/2012 08:53:48;0040;PBS_Server;Svr;tyrone-cluster;Scheduler was sent the command new
12/08/2012 08:54:17;0040;PBS_Server;Svr;tyrone-cluster;Scheduler was sent the command new
12/08/2012 08:54:47;0040;PBS_Server;Svr;tyrone-cluster;Scheduler was sent the command new
12/08/2012 08:55:18;0040;PBS_Server;Svr;tyrone-cluster;Scheduler was sent the command new
12/08/2012 08:55:47;0040;PBS_Server;Svr;tyrone-cluster;Scheduler was sent the command new
12/08/2012 08:56:17;0040;PBS_Server;Svr;tyrone-cluster;Scheduler was sent the command new
12/08/2012 08:56:48;0040;PBS_Server;Svr;tyrone-cluster;Scheduler was sent the command new
12/08/2012 08:57:17;0040;PBS_Server;Svr;tyrone-cluster;Scheduler was sent the command new
12/08/2012 08:57:47;0040;PBS_Server;Svr;tyrone-cluster;Scheduler was sent the command new
12/08/2012 08:58:10;0002;PBS_Server;Svr;PBS_Server;Torque Server Version = 3.0.5, loglevel = 0
12/08/2012 08:58:18;0040;PBS_Server;Svr;tyrone-cluster;Scheduler was sent the command new
12/08/2012 08:58:47;0040;PBS_Server;Svr;tyrone-cluster;Scheduler was sent the command new
12/08/2012 08:59:17;0040;PBS_Server;Svr;tyrone-cluster;Scheduler was sent the command new
12/08/2012 08:59:48;0040;PBS_Server;Svr;tyrone-cluster;Scheduler was sent the command new
12/08/2012 09:00:17;0040;PBS_Server;Svr;tyrone-cluster;Scheduler was sent the command new
12/08/2012 09:00:47;0040;PBS_Server;Svr;tyrone-cluster;Scheduler was sent the command new
12/08/2012 09:01:18;0040;PBS_Server;Svr;tyrone-cluster;Scheduler was sent the command new
12/08/2012 09:01:47;0040;PBS_Server;Svr;tyrone-cluster;Scheduler was sent the command new
12/08/2012 09:02:17;0040;PBS_Server;Svr;tyrone-cluster;Scheduler was sent the command new
12/08/2012 09:02:48;0040;PBS_Server;Svr;tyrone-cluster;Scheduler was sent the command new
12/08/2012 09:03:10;0002;PBS_Server;Svr;PBS_Server;Torque Server Version = 3.0.5, loglevel = 0
12/08/2012 09:03:18;0040;PBS_Server;Svr;tyrone-cluster;Scheduler was sent the command new
12/08/2012 09:03:51;0040;PBS_Server;Svr;tyrone-cluster;Scheduler was sent the command new
12/08/2012 09:04:27;0040;PBS_Server;Svr;tyrone-cluster;Scheduler was sent the command new
12/08/2012 09:04:58;0040;PBS_Server;Svr;tyrone-cluster;Scheduler was sent the command new
12/08/2012 09:05:28;0040;PBS_Server;Svr;tyrone-cluster;Scheduler was sent the command new
12/08/2012 09:06:00;0040;PBS_Server;Svr;tyrone-cluster;Scheduler was sent the command new
12/08/2012 09:06:28;0040;PBS_Server;Svr;tyrone-cluster;Scheduler was sent the command new
12/08/2012 09:06:58;0040;PBS_Server;Svr;tyrone-cluster;Scheduler was sent the command new
12/08/2012 09:07:31;0040;PBS_Server;Svr;tyrone-cluster;Scheduler was sent the command new
12/08/2012 09:07:58;0040;PBS_Server;Svr;tyrone-cluster;Scheduler was sent the command new
12/08/2012 09:08:10;0002;PBS_Server;Svr;PBS_Server;Torque Server Version = 3.0.5, loglevel = 0
12/08/2012 09:08:28;0040;PBS_Server;Svr;tyrone-cluster;Scheduler was sent the command new
12/08/2012 09:09:00;0040;PBS_Server;Svr;tyrone-cluster;Scheduler was sent the command new
12/08/2012 09:09:28;0040;PBS_Server;Svr;tyrone-cluster;Scheduler was sent the command new
12/08/2012 09:09:58;0040;PBS_Server;Svr;tyrone-cluster;Scheduler was sent the command new
12/08/2012 09:10:30;0040;PBS_Server;Svr;tyrone-cluster;Scheduler was sent the command new
12/08/2012 09:10:58;0040;PBS_Server;Svr;tyrone-cluster;Scheduler was sent the command new
12/08/2012 09:11:28;0040;PBS_Server;Svr;tyrone-cluster;Scheduler was sent the command new
12/08/2012 09:11:58;0040;PBS_Server;Svr;tyrone-cluster;Scheduler was sent the command new
12/08/2012 09:12:28;0040;PBS_Server;Svr;tyrone-cluster;Scheduler was sent the command new
12/08/2012 09:12:58;0040;PBS_Server;Svr;tyrone-cluster;Scheduler was sent the command new
12/08/2012 09:13:10;0002;PBS_Server;Svr;PBS_Server;Torque Server Version = 3.0.5, loglevel = 0
12/08/2012 09:13:30;0040;PBS_Server;Svr;tyrone-cluster;Scheduler was sent the command new
12/08/2012 09:13:58;0040;PBS_Server;Svr;tyrone-cluster;Scheduler was sent the command new
12/08/2012 09:14:28;0040;PBS_Server;Svr;tyrone-cluster;Scheduler was sent the command new
12/08/2012 09:15:00;0040;PBS_Server;Svr;tyrone-cluster;Scheduler was sent the command new
12/08/2012 09:15:28;0040;PBS_Server;Svr;tyrone-cluster;Scheduler was sent the command new
12/08/2012 09:15:58;0040;PBS_Server;Svr;tyrone-cluster;Scheduler was sent the command new
12/08/2012 09:16:31;0040;PBS_Server;Svr;tyrone-cluster;Scheduler was sent the command new
12/08/2012 09:16:58;0040;PBS_Server;Svr;tyrone-cluster;Scheduler was sent the command new
12/08/2012 09:17:28;0040;PBS_Server;Svr;tyrone-cluster;Scheduler was sent the command new
12/08/2012 09:18:00;0040;PBS_Server;Svr;tyrone-cluster;Scheduler was sent the command new
12/08/2012 09:18:10;0002;PBS_Server;Svr;PBS_Server;Torque Server Version = 3.0.5, loglevel = 0
12/08/2012 09:18:28;0040;PBS_Server;Svr;tyrone-cluster;Scheduler was sent the command new
12/08/2012 09:18:58;0040;PBS_Server;Svr;tyrone-cluster;Scheduler was sent the command new
12/08/2012 09:19:31;0040;PBS_Server;Svr;tyrone-cluster;Scheduler was sent the command new
12/08/2012 09:19:58;0040;PBS_Server;Svr;tyrone-cluster;Scheduler was sent the command new
12/08/2012 09:20:28;0040;PBS_Server;Svr;tyrone-cluster;Scheduler was sent the command new
12/08/2012 09:21:00;0040;PBS_Server;Svr;tyrone-cluster;Scheduler was sent the command new
12/08/2012 09:21:28;0040;PBS_Server;Svr;tyrone-cluster;Scheduler was sent the command new
12/08/2012 09:21:58;0040;PBS_Server;Svr;tyrone-cluster;Scheduler was sent the command new
12/08/2012 09:22:30;0040;PBS_Server;Svr;tyrone-cluster;Scheduler was sent the command new
12/08/2012 09:22:58;0040;PBS_Server;Svr;tyrone-cluster;Scheduler was sent the command new
12/08/2012 09:23:10;0002;PBS_Server;Svr;PBS_Server;Torque Server Version = 3.0.5, loglevel = 0
12/08/2012 09:23:28;0040;PBS_Server;Svr;tyrone-cluster;Scheduler was sent the command new
12/08/2012 09:24:01;0040;PBS_Server;Svr;tyrone-cluster;Scheduler was sent the command new
12/08/2012 09:24:28;0040;PBS_Server;Svr;tyrone-cluster;Scheduler was sent the command new
12/08/2012 09:24:58;0040;PBS_Server;Svr;tyrone-cluster;Scheduler was sent the command new
12/08/2012 09:25:30;0040;PBS_Server;Svr;tyrone-cluster;Scheduler was sent the command new
12/08/2012 09:25:58;0040;PBS_Server;Svr;tyrone-cluster;Scheduler was sent the command new
12/08/2012 09:26:28;0040;PBS_Server;Svr;tyrone-cluster;Scheduler was sent the command new
12/08/2012 09:26:58;0040;PBS_Server;Svr;tyrone-cluster;Scheduler was sent the command new
12/08/2012 09:27:28;0040;PBS_Server;Svr;tyrone-cluster;Scheduler was sent the command new
12/08/2012 09:27:58;0040;PBS_Server;Svr;tyrone-cluster;Scheduler was sent the command new
12/08/2012 09:28:10;0002;PBS_Server;Svr;PBS_Server;Torque Server Version = 3.0.5, loglevel = 0
12/08/2012 09:28:30;0040;PBS_Server;Svr;tyrone-cluster;Scheduler was sent the command new
12/08/2012 09:28:58;0040;PBS_Server;Svr;tyrone-cluster;Scheduler was sent the command new
12/08/2012 09:29:28;0040;PBS_Server;Svr;tyrone-cluster;Scheduler was sent the command new
12/08/2012 09:30:00;0040;PBS_Server;Svr;tyrone-cluster;Scheduler was sent the command new
12/08/2012 09:30:28;0040;PBS_Server;Svr;tyrone-cluster;Scheduler was sent the command new
12/08/2012 09:30:58;0040;PBS_Server;Svr;tyrone-cluster;Scheduler was sent the command new
12/08/2012 09:31:30;0040;PBS_Server;Svr;tyrone-cluster;Scheduler was sent the command new
12/08/2012 09:31:58;0040;PBS_Server;Svr;tyrone-cluster;Scheduler was sent the command new
12/08/2012 09:32:28;0040;PBS_Server;Svr;tyrone-cluster;Scheduler was sent the command new
12/08/2012 09:32:58;0040;PBS_Server;Svr;tyrone-cluster;Scheduler was sent the command new
12/08/2012 09:33:10;0002;PBS_Server;Svr;PBS_Server;Torque Server Version = 3.0.5, loglevel = 0
12/08/2012 09:33:28;0040;PBS_Server;Svr;tyrone-cluster;Scheduler was sent the command new
12/08/2012 09:33:58;0040;PBS_Server;Svr;tyrone-cluster;Scheduler was sent the command new
12/08/2012 09:34:30;0040;PBS_Server;Svr;tyrone-cluster;Scheduler was sent the command new
12/08/2012 09:34:58;0040;PBS_Server;Svr;tyrone-cluster;Scheduler was sent the command new
12/08/2012 09:35:28;0040;PBS_Server;Svr;tyrone-cluster;Scheduler was sent the command new
12/08/2012 09:36:00;0040;PBS_Server;Svr;tyrone-cluster;Scheduler was sent the command new
12/08/2012 09:36:28;0040;PBS_Server;Svr;tyrone-cluster;Scheduler was sent the command new
12/08/2012 09:36:58;0040;PBS_Server;Svr;tyrone-cluster;Scheduler was sent the command new
12/08/2012 09:37:28;0040;PBS_Server;Svr;tyrone-cluster;Scheduler was sent the command new
12/08/2012 09:37:58;0040;PBS_Server;Svr;tyrone-cluster;Scheduler was sent the command new
12/08/2012 09:38:10;0002;PBS_Server;Svr;PBS_Server;Torque Server Version = 3.0.5, loglevel = 0
12/08/2012 09:38:28;0040;PBS_Server;Svr;tyrone-cluster;Scheduler was sent the command new
12/08/2012 09:39:00;0040;PBS_Server;Svr;tyrone-cluster;Scheduler was sent the command new
12/08/2012 09:39:28;0040;PBS_Server;Svr;tyrone-cluster;Scheduler was sent the command new
12/08/2012 09:39:58;0040;PBS_Server;Svr;tyrone-cluster;Scheduler was sent the command new
12/08/2012 09:40:30;0040;PBS_Server;Svr;tyrone-cluster;Scheduler was sent the command new
12/08/2012 09:40:58;0040;PBS_Server;Svr;tyrone-cluster;Scheduler was sent the command new
12/08/2012 09:41:28;0040;PBS_Server;Svr;tyrone-cluster;Scheduler was sent the command new
12/08/2012 09:42:00;0040;PBS_Server;Svr;tyrone-cluster;Scheduler was sent the command new
12/08/2012 09:42:28;0040;PBS_Server;Svr;tyrone-cluster;Scheduler was sent the command new
12/08/2012 09:42:58;0040;PBS_Server;Svr;tyrone-cluster;Scheduler was sent the command new
12/08/2012 09:43:10;0002;PBS_Server;Svr;PBS_Server;Torque Server Version = 3.0.5, loglevel = 0
12/08/2012 09:43:30;0040;PBS_Server;Svr;tyrone-cluster;Scheduler was sent the command new
12/08/2012 09:43:58;0040;PBS_Server;Svr;tyrone-cluster;Scheduler was sent the command new
12/08/2012 09:44:28;0040;PBS_Server;Svr;tyrone-cluster;Scheduler was sent the command new
12/08/2012 09:44:58;0040;PBS_Server;Svr;tyrone-cluster;Scheduler was sent the command new
12/08/2012 09:45:28;0040;PBS_Server;Svr;tyrone-cluster;Scheduler was sent the command new
12/08/2012 09:45:58;0040;PBS_Server;Svr;tyrone-cluster;Scheduler was sent the command new
12/08/2012 09:46:30;0040;PBS_Server;Svr;tyrone-cluster;Scheduler was sent the command new
12/08/2012 09:46:58;0040;PBS_Server;Svr;tyrone-cluster;Scheduler was sent the command new
12/08/2012 09:47:28;0040;PBS_Server;Svr;tyrone-cluster;Scheduler was sent the command new
12/08/2012 09:48:00;0040;PBS_Server;Svr;tyrone-cluster;Scheduler was sent the command new
12/08/2012 09:48:10;0002;PBS_Server;Svr;PBS_Server;Torque Server Version = 3.0.5, loglevel = 0
12/08/2012 09:48:28;0040;PBS_Server;Svr;tyrone-cluster;Scheduler was sent the command new
12/08/2012 09:48:58;0040;PBS_Server;Svr;tyrone-cluster;Scheduler was sent the command new
12/08/2012 09:49:30;0040;PBS_Server;Svr;tyrone-cluster;Scheduler was sent the command new
12/08/2012 09:49:58;0040;PBS_Server;Svr;tyrone-cluster;Scheduler was sent the command new
12/08/2012 09:50:28;0040;PBS_Server;Svr;tyrone-cluster;Scheduler was sent the command new
12/08/2012 09:51:00;0040;PBS_Server;Svr;tyrone-cluster;Scheduler was sent the command new
12/08/2012 09:51:28;0040;PBS_Server;Svr;tyrone-cluster;Scheduler was sent the command new
12/08/2012 09:51:58;0040;PBS_Server;Svr;tyrone-cluster;Scheduler was sent the command new
12/08/2012 09:52:30;0040;PBS_Server;Svr;tyrone-cluster;Scheduler was sent the command new
12/08/2012 09:52:58;0040;PBS_Server;Svr;tyrone-cluster;Scheduler was sent the command new
12/08/2012 09:53:10;0002;PBS_Server;Svr;PBS_Server;Torque Server Version = 3.0.5, loglevel = 0
12/08/2012 09:53:28;0040;PBS_Server;Svr;tyrone-cluster;Scheduler was sent the command new
12/08/2012 09:53:58;0040;PBS_Server;Svr;tyrone-cluster;Scheduler was sent the command new
12/08/2012 09:54:28;0040;PBS_Server;Svr;tyrone-cluster;Scheduler was sent the command new
12/08/2012 09:54:58;0040;PBS_Server;Svr;tyrone-cluster;Scheduler was sent the command new
12/08/2012 09:55:30;0040;PBS_Server;Svr;tyrone-cluster;Scheduler was sent the command new
12/08/2012 09:55:58;0040;PBS_Server;Svr;tyrone-cluster;Scheduler was sent the command new
12/08/2012 09:56:28;0040;PBS_Server;Svr;tyrone-cluster;Scheduler was sent the command new
12/08/2012 09:57:00;0040;PBS_Server;Svr;tyrone-cluster;Scheduler was sent the command new
12/08/2012 09:57:28;0040;PBS_Server;Svr;tyrone-cluster;Scheduler was sent the command new
12/08/2012 09:57:58;0040;PBS_Server;Svr;tyrone-cluster;Scheduler was sent the command new
12/08/2012 09:58:10;0002;PBS_Server;Svr;PBS_Server;Torque Server Version = 3.0.5, loglevel = 0
12/08/2012 09:58:30;0040;PBS_Server;Svr;tyrone-cluster;Scheduler was sent the command new
12/08/2012 09:58:58;0040;PBS_Server;Svr;tyrone-cluster;Scheduler was sent the command new
12/08/2012 09:59:28;0040;PBS_Server;Svr;tyrone-cluster;Scheduler was sent the command new
12/08/2012 10:00:00;0040;PBS_Server;Svr;tyrone-cluster;Scheduler was sent the command new
12/08/2012 10:00:28;0040;PBS_Server;Svr;tyrone-cluster;Scheduler was sent the command new
12/08/2012 10:00:58;0040;PBS_Server;Svr;tyrone-cluster;Scheduler was sent the command new
12/08/2012 10:01:30;0040;PBS_Server;Svr;tyrone-cluster;Scheduler was sent the command new
12/08/2012 10:01:58;0040;PBS_Server;Svr;tyrone-cluster;Scheduler was sent the command new
12/08/2012 10:02:28;0040;PBS_Server;Svr;tyrone-cluster;Scheduler was sent the command new
12/08/2012 10:03:00;0040;PBS_Server;Svr;tyrone-cluster;Scheduler was sent the command new
12/08/2012 10:03:10;0002;PBS_Server;Svr;PBS_Server;Torque Server Version = 3.0.5, loglevel = 0
12/08/2012 10:03:28;0040;PBS_Server;Svr;tyrone-cluster;Scheduler was sent the command new
12/08/2012 10:03:58;0040;PBS_Server;Svr;tyrone-cluster;Scheduler was sent the command new
12/08/2012 10:04:30;0040;PBS_Server;Svr;tyrone-cluster;Scheduler was sent the command new
12/08/2012 10:04:58;0040;PBS_Server;Svr;tyrone-cluster;Scheduler was sent the command new
12/08/2012 10:05:28;0040;PBS_Server;Svr;tyrone-cluster;Scheduler was sent the command new
12/08/2012 10:06:00;0040;PBS_Server;Svr;tyrone-cluster;Scheduler was sent the command new
12/08/2012 10:06:28;0040;PBS_Server;Svr;tyrone-cluster;Scheduler was sent the command new
12/08/2012 10:06:58;0040;PBS_Server;Svr;tyrone-cluster;Scheduler was sent the command new
12/08/2012 10:07:28;0040;PBS_Server;Svr;tyrone-cluster;Scheduler was sent the command new
12/08/2012 10:07:58;0040;PBS_Server;Svr;tyrone-cluster;Scheduler was sent the command new
12/08/2012 10:08:10;0002;PBS_Server;Svr;PBS_Server;Torque Server Version = 3.0.5, loglevel = 0
12/08/2012 10:08:28;0040;PBS_Server;Svr;tyrone-cluster;Scheduler was sent the command new
12/08/2012 10:09:00;0040;PBS_Server;Svr;tyrone-cluster;Scheduler was sent the command new
12/08/2012 10:09:28;0040;PBS_Server;Svr;tyrone-cluster;Scheduler was sent the command new
12/08/2012 10:09:58;0040;PBS_Server;Svr;tyrone-cluster;Scheduler was sent the command new
12/08/2012 10:10:30;0040;PBS_Server;Svr;tyrone-cluster;Scheduler was sent the command new
12/08/2012 10:10:58;0040;PBS_Server;Svr;tyrone-cluster;Scheduler was sent the command new
12/08/2012 10:11:28;0040;PBS_Server;Svr;tyrone-cluster;Scheduler was sent the command new
12/08/2012 10:11:58;0040;PBS_Server;Svr;tyrone-cluster;Scheduler was sent the command new
12/08/2012 10:12:28;0040;PBS_Server;Svr;tyrone-cluster;Scheduler was sent the command new
12/08/2012 10:12:58;0040;PBS_Server;Svr;tyrone-cluster;Scheduler was sent the command new
12/08/2012 10:13:10;0002;PBS_Server;Svr;PBS_Server;Torque Server Version = 3.0.5, loglevel = 0
12/08/2012 10:13:30;0040;PBS_Server;Svr;tyrone-cluster;Scheduler was sent the command new
12/08/2012 10:13:58;0040;PBS_Server;Svr;tyrone-cluster;Scheduler was sent the command new
12/08/2012 10:14:28;0040;PBS_Server;Svr;tyrone-cluster;Scheduler was sent the command new
12/08/2012 10:14:59;0040;PBS_Server;Svr;tyrone-cluster;Scheduler was sent the command new
12/08/2012 10:15:28;0040;PBS_Server;Svr;tyrone-cluster;Scheduler was sent the command new
12/08/2012 10:15:58;0040;PBS_Server;Svr;tyrone-cluster;Scheduler was sent the command new
12/08/2012 10:16:28;0040;PBS_Server;Svr;tyrone-cluster;Scheduler was sent the command new
12/08/2012 10:16:58;0040;PBS_Server;Svr;tyrone-cluster;Scheduler was sent the command new
12/08/2012 10:17:28;0040;PBS_Server;Svr;tyrone-cluster;Scheduler was sent the command new
12/08/2012 10:18:00;0040;PBS_Server;Svr;tyrone-cluster;Scheduler was sent the command new
12/08/2012 10:18:10;0002;PBS_Server;Svr;PBS_Server;Torque Server Version = 3.0.5, loglevel = 0
12/08/2012 10:18:28;0040;PBS_Server;Svr;tyrone-cluster;Scheduler was sent the command new
12/08/2012 10:18:58;0040;PBS_Server;Svr;tyrone-cluster;Scheduler was sent the command new
12/08/2012 10:19:30;0040;PBS_Server;Svr;tyrone-cluster;Scheduler was sent the command new
12/08/2012 10:19:58;0040;PBS_Server;Svr;tyrone-cluster;Scheduler was sent the command new
12/08/2012 10:20:28;0040;PBS_Server;Svr;tyrone-cluster;Scheduler was sent the command new
12/08/2012 10:20:58;0040;PBS_Server;Svr;tyrone-cluster;Scheduler was sent the command new
12/08/2012 10:21:28;0040;PBS_Server;Svr;tyrone-cluster;Scheduler was sent the command new
12/08/2012 10:21:58;0040;PBS_Server;Svr;tyrone-cluster;Scheduler was sent the command new
12/08/2012 10:22:30;0040;PBS_Server;Svr;tyrone-cluster;Scheduler was sent the command new
12/08/2012 10:22:58;0040;PBS_Server;Svr;tyrone-cluster;Scheduler was sent the command new
12/08/2012 10:23:10;0002;PBS_Server;Svr;PBS_Server;Torque Server Version = 3.0.5, loglevel = 0
12/08/2012 10:23:28;0040;PBS_Server;Svr;tyrone-cluster;Scheduler was sent the command new
12/08/2012 10:24:00;0040;PBS_Server;Svr;tyrone-cluster;Scheduler was sent the command new
12/08/2012 10:24:28;0040;PBS_Server;Svr;tyrone-cluster;Scheduler was sent the command new
12/08/2012 10:24:58;0040;PBS_Server;Svr;tyrone-cluster;Scheduler was sent the command new
12/08/2012 10:25:30;0040;PBS_Server;Svr;tyrone-cluster;Scheduler was sent the command new
12/08/2012 10:25:58;0040;PBS_Server;Svr;tyrone-cluster;Scheduler was sent the command new
12/08/2012 10:26:28;0040;PBS_Server;Svr;tyrone-cluster;Scheduler was sent the command new
12/08/2012 10:27:00;0040;PBS_Server;Svr;tyrone-cluster;Scheduler was sent the command new
12/08/2012 10:27:28;0040;PBS_Server;Svr;tyrone-cluster;Scheduler was sent the command new
12/08/2012 10:27:58;0040;PBS_Server;Svr;tyrone-cluster;Scheduler was sent the command new
12/08/2012 10:28:10;0002;PBS_Server;Svr;PBS_Server;Torque Server Version = 3.0.5, loglevel = 0
12/08/2012 10:28:30;0040;PBS_Server;Svr;tyrone-cluster;Scheduler was sent the command new
12/08/2012 10:28:58;0040;PBS_Server;Svr;tyrone-cluster;Scheduler was sent the command new
12/08/2012 10:29:28;0040;PBS_Server;Svr;tyrone-cluster;Scheduler was sent the command new
12/08/2012 10:30:00;0040;PBS_Server;Svr;tyrone-cluster;Scheduler was sent the command new
12/08/2012 10:30:28;0040;PBS_Server;Svr;tyrone-cluster;Scheduler was sent the command new
12/08/2012 10:30:58;0040;PBS_Server;Svr;tyrone-cluster;Scheduler was sent the command new
12/08/2012 10:31:30;0040;PBS_Server;Svr;tyrone-cluster;Scheduler was sent the command new
12/08/2012 10:31:58;0040;PBS_Server;Svr;tyrone-cluster;Scheduler was sent the command new
12/08/2012 10:32:28;0040;PBS_Server;Svr;tyrone-cluster;Scheduler was sent the command new
12/08/2012 10:33:00;0040;PBS_Server;Svr;tyrone-cluster;Scheduler was sent the command new
12/08/2012 10:33:10;0002;PBS_Server;Svr;PBS_Server;Torque Server Version = 3.0.5, loglevel = 0
12/08/2012 10:33:28;0040;PBS_Server;Svr;tyrone-cluster;Scheduler was sent the command new
12/08/2012 10:33:58;0040;PBS_Server;Svr;tyrone-cluster;Scheduler was sent the command new
12/08/2012 10:34:30;0040;PBS_Server;Svr;tyrone-cluster;Scheduler was sent the command new
12/08/2012 10:34:58;0040;PBS_Server;Svr;tyrone-cluster;Scheduler was sent the command new
12/08/2012 10:35:28;0040;PBS_Server;Svr;tyrone-cluster;Scheduler was sent the command new
12/08/2012 10:36:00;0040;PBS_Server;Svr;tyrone-cluster;Scheduler was sent the command new
12/08/2012 10:36:28;0040;PBS_Server;Svr;tyrone-cluster;Scheduler was sent the command new
12/08/2012 10:36:58;0040;PBS_Server;Svr;tyrone-cluster;Scheduler was sent the command new
12/08/2012 10:37:30;0040;PBS_Server;Svr;tyrone-cluster;Scheduler was sent the command new
12/08/2012 10:37:58;0040;PBS_Server;Svr;tyrone-cluster;Scheduler was sent the command new
12/08/2012 10:38:10;0002;PBS_Server;Svr;PBS_Server;Torque Server Version = 3.0.5, loglevel = 0
12/08/2012 10:38:28;0040;PBS_Server;Svr;tyrone-cluster;Scheduler was sent the command new
12/08/2012 10:39:00;0040;PBS_Server;Svr;tyrone-cluster;Scheduler was sent the command new
12/08/2012 10:39:28;0040;PBS_Server;Svr;tyrone-cluster;Scheduler was sent the command new
12/08/2012 10:39:58;0040;PBS_Server;Svr;tyrone-cluster;Scheduler was sent the command new
12/08/2012 10:40:30;0040;PBS_Server;Svr;tyrone-cluster;Scheduler was sent the command new
12/08/2012 10:40:58;0040;PBS_Server;Svr;tyrone-cluster;Scheduler was sent the command new
12/08/2012 10:41:28;0040;PBS_Server;Svr;tyrone-cluster;Scheduler was sent the command new
12/08/2012 10:42:00;0040;PBS_Server;Svr;tyrone-cluster;Scheduler was sent the command new
12/08/2012 10:42:28;0040;PBS_Server;Svr;tyrone-cluster;Scheduler was sent the command new
12/08/2012 10:42:58;0040;PBS_Server;Svr;tyrone-cluster;Scheduler was sent the command new
12/08/2012 10:43:10;0002;PBS_Server;Svr;PBS_Server;Torque Server Version = 3.0.5, loglevel = 0
12/08/2012 10:43:30;0040;PBS_Server;Svr;tyrone-cluster;Scheduler was sent the command new
12/08/2012 10:43:58;0040;PBS_Server;Svr;tyrone-cluster;Scheduler was sent the command new
12/08/2012 10:44:28;0040;PBS_Server;Svr;tyrone-cluster;Scheduler was sent the command new
12/08/2012 10:45:00;0040;PBS_Server;Svr;tyrone-cluster;Scheduler was sent the command new
12/08/2012 10:45:28;0040;PBS_Server;Svr;tyrone-cluster;Scheduler was sent the command new
12/08/2012 10:45:58;0040;PBS_Server;Svr;tyrone-cluster;Scheduler was sent the command new
12/08/2012 10:46:30;0040;PBS_Server;Svr;tyrone-cluster;Scheduler was sent the command new
12/08/2012 10:46:58;0040;PBS_Server;Svr;tyrone-cluster;Scheduler was sent the command new
12/08/2012 10:47:28;0040;PBS_Server;Svr;tyrone-cluster;Scheduler was sent the command new
12/08/2012 10:48:00;0040;PBS_Server;Svr;tyrone-cluster;Scheduler was sent the command new
12/08/2012 10:48:10;0002;PBS_Server;Svr;PBS_Server;Torque Server Version = 3.0.5, loglevel = 0
12/08/2012 10:48:28;0040;PBS_Server;Svr;tyrone-cluster;Scheduler was sent the command new
12/08/2012 10:48:58;0040;PBS_Server;Svr;tyrone-cluster;Scheduler was sent the command new
12/08/2012 10:49:30;0040;PBS_Server;Svr;tyrone-cluster;Scheduler was sent the command new
12/08/2012 10:49:58;0040;PBS_Server;Svr;tyrone-cluster;Scheduler was sent the command new
12/08/2012 10:50:28;0040;PBS_Server;Svr;tyrone-cluster;Scheduler was sent the command new
12/08/2012 10:51:00;0040;PBS_Server;Svr;tyrone-cluster;Scheduler was sent the command new
12/08/2012 10:51:28;0040;PBS_Server;Svr;tyrone-cluster;Scheduler was sent the command new
12/08/2012 10:51:58;0040;PBS_Server;Svr;tyrone-cluster;Scheduler was sent the command new
12/08/2012 10:52:17;0100;PBS_Server;Job;16755.tyrone-cluster;enqueuing into batch, state 1 hop 1
12/08/2012 10:52:17;0100;PBS_Server;Job;16755.tyrone-cluster;dequeuing from batch, state QUEUED
12/08/2012 10:52:17;0100;PBS_Server;Job;16755.tyrone-cluster;enqueuing into qp64, state 1 hop 1
12/08/2012 10:52:17;0008;PBS_Server;Job;16755.tyrone-cluster;Job Queued at request of csdsuben@tyrone-cluster, owner = csdsuben@tyrone-cluster, job name = zralk-ph7a-7, queue = qp64
12/08/2012 10:52:17;0040;PBS_Server;Svr;tyrone-cluster;Scheduler was sent the command new
12/08/2012 10:52:17;0008;PBS_Server;Job;16755.tyrone-cluster;Job Modified at request of Scheduler@tyrone-cluster
12/08/2012 10:52:30;0040;PBS_Server;Svr;tyrone-cluster;Scheduler was sent the command new
12/08/2012 10:52:40;0100;PBS_Server;Job;16756.tyrone-cluster;enqueuing into batch, state 1 hop 1
12/08/2012 10:52:40;0008;PBS_Server;Job;16756.tyrone-cluster;Job Queued at request of csdsuben@tyrone-cluster, owner = csdsuben@tyrone-cluster, job name = zralk-ph7a-8, queue = batch
12/08/2012 10:52:40;0040;PBS_Server;Svr;tyrone-cluster;Scheduler was sent the command new
12/08/2012 10:52:40;0008;PBS_Server;Job;16756.tyrone-cluster;Job Modified at request of Scheduler@tyrone-cluster
12/08/2012 10:52:58;0040;PBS_Server;Svr;tyrone-cluster;Scheduler was sent the command new
12/08/2012 10:53:10;0002;PBS_Server;Svr;PBS_Server;Torque Server Version = 3.0.5, loglevel = 0
12/08/2012 10:53:12;0040;PBS_Server;Svr;tyrone-cluster;Scheduler was sent the command new
12/08/2012 10:53:28;0040;PBS_Server;Svr;tyrone-cluster;Scheduler was sent the command new
12/08/2012 10:53:43;0040;PBS_Server;Svr;tyrone-cluster;Scheduler was sent the command new
12/08/2012 10:53:59;0040;PBS_Server;Svr;tyrone-cluster;Scheduler was sent the command new
12/08/2012 10:54:13;0040;PBS_Server;Svr;tyrone-cluster;Scheduler was sent the command new
12/08/2012 10:54:28;0040;PBS_Server;Svr;tyrone-cluster;Scheduler was sent the command new
12/08/2012 10:54:45;0040;PBS_Server;Svr;tyrone-cluster;Scheduler was sent the command new
12/08/2012 10:54:58;0040;PBS_Server;Svr;tyrone-cluster;Scheduler was sent the command new
12/08/2012 10:55:13;0040;PBS_Server;Svr;tyrone-cluster;Scheduler was sent the command new
12/08/2012 10:55:30;0040;PBS_Server;Svr;tyrone-cluster;Scheduler was sent the command new
12/08/2012 10:55:43;0040;PBS_Server;Svr;tyrone-cluster;Scheduler was sent the command new
12/08/2012 10:55:58;0040;PBS_Server;Svr;tyrone-cluster;Scheduler was sent the command new
12/08/2012 10:56:14;0040;PBS_Server;Svr;tyrone-cluster;Scheduler was sent the command new
12/08/2012 10:56:28;0040;PBS_Server;Svr;tyrone-cluster;Scheduler was sent the command new
12/08/2012 10:56:43;0040;PBS_Server;Svr;tyrone-cluster;Scheduler was sent the command new
12/08/2012 10:57:00;0040;PBS_Server;Svr;tyrone-cluster;Scheduler was sent the command new
12/08/2012 10:57:13;0040;PBS_Server;Svr;tyrone-cluster;Scheduler was sent the command new
12/08/2012 10:57:28;0040;PBS_Server;Svr;tyrone-cluster;Scheduler was sent the command new
12/08/2012 10:57:41;0100;PBS_Server;Job;16757.tyrone-cluster;enqueuing into batch, state 1 hop 1
12/08/2012 10:57:41;0100;PBS_Server;Job;16757.tyrone-cluster;dequeuing from batch, state QUEUED
12/08/2012 10:57:41;0100;PBS_Server;Job;16757.tyrone-cluster;enqueuing into qp64, state 1 hop 1
12/08/2012 10:57:41;0008;PBS_Server;Job;16757.tyrone-cluster;Job Queued at request of ciesita@tyrone-cluster, owner = ciesita@tyrone-cluster, job name = R=10, queue = qp64
12/08/2012 10:57:41;0040;PBS_Server;Svr;tyrone-cluster;Scheduler was sent the command new
12/08/2012 10:57:41;0008;PBS_Server;Job;16757.tyrone-cluster;Job Modified at request of Scheduler@tyrone-cluster
12/08/2012 10:57:45;0040;PBS_Server;Svr;tyrone-cluster;Scheduler was sent the command new
12/08/2012 10:57:45;0100;PBS_Server;Job;16758.tyrone-cluster;enqueuing into batch, state 1 hop 1
12/08/2012 10:57:45;0008;PBS_Server;Job;16758.tyrone-cluster;Job Queued at request of ciesita@tyrone-cluster, owner = ciesita@tyrone-cluster, job name = R=20, queue = batch
12/08/2012 10:57:45;0040;PBS_Server;Svr;tyrone-cluster;Scheduler was sent the command new
12/08/2012 10:57:45;0008;PBS_Server;Job;16758.tyrone-cluster;Job Modified at request of Scheduler@tyrone-cluster
12/08/2012 10:57:58;0040;PBS_Server;Svr;tyrone-cluster;Scheduler was sent the command new
12/08/2012 10:58:10;0002;PBS_Server;Svr;PBS_Server;Torque Server Version = 3.0.5, loglevel = 0
12/08/2012 10:58:13;0040;PBS_Server;Svr;tyrone-cluster;Scheduler was sent the command new
12/08/2012 10:58:16;0040;PBS_Server;Svr;tyrone-cluster;Scheduler was sent the command new
12/08/2012 10:58:30;0040;PBS_Server;Svr;tyrone-cluster;Scheduler was sent the command new
12/08/2012 10:58:43;0040;PBS_Server;Svr;tyrone-cluster;Scheduler was sent the command new
12/08/2012 10:58:47;0040;PBS_Server;Svr;tyrone-cluster;Scheduler was sent the command new
12/08/2012 10:58:58;0040;PBS_Server;Svr;tyrone-cluster;Scheduler was sent the command new
12/08/2012 10:59:15;0040;PBS_Server;Svr;tyrone-cluster;Scheduler was sent the command new
12/08/2012 10:59:17;0040;PBS_Server;Svr;tyrone-cluster;Scheduler was sent the command new
12/08/2012 10:59:28;0040;PBS_Server;Svr;tyrone-cluster;Scheduler was sent the command new
12/08/2012 10:59:43;0040;PBS_Server;Svr;tyrone-cluster;Scheduler was sent the command new
12/08/2012 10:59:48;0040;PBS_Server;Svr;tyrone-cluster;Scheduler was sent the command new
12/08/2012 11:00:00;0040;PBS_Server;Svr;tyrone-cluster;Scheduler was sent the command new
12/08/2012 11:00:13;0040;PBS_Server;Svr;tyrone-cluster;Scheduler was sent the command new
12/08/2012 11:00:17;0040;PBS_Server;Svr;tyrone-cluster;Scheduler was sent the command new
12/08/2012 11:00:28;0040;PBS_Server;Svr;tyrone-cluster;Scheduler was sent the command new
12/08/2012 11:00:45;0040;PBS_Server;Svr;tyrone-cluster;Scheduler was sent the command new
12/08/2012 11:00:47;0040;PBS_Server;Svr;tyrone-cluster;Scheduler was sent the command new
12/08/2012 11:00:58;0040;PBS_Server;Svr;tyrone-cluster;Scheduler was sent the command new
12/08/2012 11:01:13;0040;PBS_Server;Svr;tyrone-cluster;Scheduler was sent the command new
12/08/2012 11:01:18;0040;PBS_Server;Svr;tyrone-cluster;Scheduler was sent the command new
12/08/2012 11:01:30;0040;PBS_Server;Svr;tyrone-cluster;Scheduler was sent the command new
12/08/2012 11:01:43;0040;PBS_Server;Svr;tyrone-cluster;Scheduler was sent the command new
12/08/2012 11:01:47;0040;PBS_Server;Svr;tyrone-cluster;Scheduler was sent the command new
12/08/2012 11:01:58;0040;PBS_Server;Svr;tyrone-cluster;Scheduler was sent the command new
12/08/2012 11:02:15;0040;PBS_Server;Svr;tyrone-cluster;Scheduler was sent the command new
12/08/2012 11:02:17;0040;PBS_Server;Svr;tyrone-cluster;Scheduler was sent the command new
12/08/2012 11:02:28;0040;PBS_Server;Svr;tyrone-cluster;Scheduler was sent the command new
12/08/2012 11:02:43;0040;PBS_Server;Svr;tyrone-cluster;Scheduler was sent the command new
12/08/2012 11:02:48;0040;PBS_Server;Svr;tyrone-cluster;Scheduler was sent the command new
12/08/2012 11:03:00;0040;PBS_Server;Svr;tyrone-cluster;Scheduler was sent the command new
12/08/2012 11:03:10;0002;PBS_Server;Svr;PBS_Server;Torque Server Version = 3.0.5, loglevel = 0
12/08/2012 11:03:13;0040;PBS_Server;Svr;tyrone-cluster;Scheduler was sent the command new
12/08/2012 11:03:17;0040;PBS_Server;Svr;tyrone-cluster;Scheduler was sent the command new
12/08/2012 11:03:29;0040;PBS_Server;Svr;tyrone-cluster;Scheduler was sent the command new
12/08/2012 11:03:45;0040;PBS_Server;Svr;tyrone-cluster;Scheduler was sent the command new
12/08/2012 11:03:47;0040;PBS_Server;Svr;tyrone-cluster;Scheduler was sent the command new
12/08/2012 11:04:00;0040;PBS_Server;Svr;tyrone-cluster;Scheduler was sent the command new
12/08/2012 11:04:13;0040;PBS_Server;Svr;tyrone-cluster;Scheduler was sent the command new
12/08/2012 11:04:18;0040;PBS_Server;Svr;tyrone-cluster;Scheduler was sent the command new
12/08/2012 11:04:32;0040;PBS_Server;Svr;tyrone-cluster;Scheduler was sent the command new
12/08/2012 11:04:43;0040;PBS_Server;Svr;tyrone-cluster;Scheduler was sent the command new
12/08/2012 11:04:47;0040;PBS_Server;Svr;tyrone-cluster;Scheduler was sent the command new
12/08/2012 11:05:03;0040;PBS_Server;Svr;tyrone-cluster;Scheduler was sent the command new
12/08/2012 11:05:15;0040;PBS_Server;Svr;tyrone-cluster;Scheduler was sent the command new
12/08/2012 11:05:17;0040;PBS_Server;Svr;tyrone-cluster;Scheduler was sent the command new
12/08/2012 11:05:32;0040;PBS_Server;Svr;tyrone-cluster;Scheduler was sent the command new
12/08/2012 11:05:43;0040;PBS_Server;Svr;tyrone-cluster;Scheduler was sent the command new
12/08/2012 11:05:48;0040;PBS_Server;Svr;tyrone-cluster;Scheduler was sent the command new
12/08/2012 11:06:02;0040;PBS_Server;Svr;tyrone-cluster;Scheduler was sent the command new
12/08/2012 11:06:13;0040;PBS_Server;Svr;tyrone-cluster;Scheduler was sent the command new
12/08/2012 11:06:17;0040;PBS_Server;Svr;tyrone-cluster;Scheduler was sent the command new
12/08/2012 11:06:33;0040;PBS_Server;Svr;tyrone-cluster;Scheduler was sent the command new
12/08/2012 11:06:45;0040;PBS_Server;Svr;tyrone-cluster;Scheduler was sent the command new
12/08/2012 11:06:47;0040;PBS_Server;Svr;tyrone-cluster;Scheduler was sent the command new
12/08/2012 11:07:02;0040;PBS_Server;Svr;tyrone-cluster;Scheduler was sent the command new
12/08/2012 11:07:13;0040;PBS_Server;Svr;tyrone-cluster;Scheduler was sent the command new
12/08/2012 11:07:18;0040;PBS_Server;Svr;tyrone-cluster;Scheduler was sent the command new
12/08/2012 11:07:32;0040;PBS_Server;Svr;tyrone-cluster;Scheduler was sent the command new
12/08/2012 11:07:43;0040;PBS_Server;Svr;tyrone-cluster;Scheduler was sent the command new
12/08/2012 11:07:47;0040;PBS_Server;Svr;tyrone-cluster;Scheduler was sent the command new
12/08/2012 11:08:03;0040;PBS_Server;Svr;tyrone-cluster;Scheduler was sent the command new
12/08/2012 11:08:10;0002;PBS_Server;Svr;PBS_Server;Torque Server Version = 3.0.5, loglevel = 0
12/08/2012 11:08:15;0040;PBS_Server;Svr;tyrone-cluster;Scheduler was sent the command new
12/08/2012 11:08:17;0040;PBS_Server;Svr;tyrone-cluster;Scheduler was sent the command new
12/08/2012 11:08:29;0100;PBS_Server;Job;16759.tyrone-cluster;enqueuing into batch, state 1 hop 1
12/08/2012 11:08:29;0100;PBS_Server;Job;16759.tyrone-cluster;dequeuing from batch, state QUEUED
12/08/2012 11:08:29;0100;PBS_Server;Job;16759.tyrone-cluster;enqueuing into idqueue, state 1 hop 1
12/08/2012 11:08:29;0008;PBS_Server;Job;16759.tyrone-cluster;Job Queued at request of sscdds1@tyrone-cluster, owner = sscdds1@tyrone-cluster, job name = job, queue = idqueue
12/08/2012 11:08:29;0040;PBS_Server;Svr;tyrone-cluster;Scheduler was sent the command new
12/08/2012 11:08:29;0008;PBS_Server;Job;16759.tyrone-cluster;Job Modified at request of Scheduler@tyrone-cluster
12/08/2012 11:08:29;0008;PBS_Server;Job;16759.tyrone-cluster;Job Run at request of Scheduler@tyrone-cluster
12/08/2012 11:08:29;0040;PBS_Server;Svr;tyrone-cluster;Scheduler was sent the command recyc
12/08/2012 11:08:29;000d;PBS_Server;Job;16759.tyrone-cluster;Not sending email: User does not want mail of this type.
12/08/2012 11:08:32;0040;PBS_Server;Svr;tyrone-cluster;Scheduler was sent the command new
12/08/2012 11:08:43;0040;PBS_Server;Svr;tyrone-cluster;Scheduler was sent the command new
12/08/2012 11:08:48;0040;PBS_Server;Svr;tyrone-cluster;Scheduler was sent the command new
12/08/2012 11:09:02;0040;PBS_Server;Svr;tyrone-cluster;Scheduler was sent the command new
12/08/2012 11:09:13;0040;PBS_Server;Svr;tyrone-cluster;Scheduler was sent the command new
12/08/2012 11:09:17;0040;PBS_Server;Svr;tyrone-cluster;Scheduler was sent the command new
12/08/2012 11:09:33;0040;PBS_Server;Svr;tyrone-cluster;Scheduler was sent the command new
12/08/2012 11:09:44;0040;PBS_Server;Svr;tyrone-cluster;Scheduler was sent the command new
12/08/2012 11:09:47;0040;PBS_Server;Svr;tyrone-cluster;Scheduler was sent the command new
12/08/2012 11:10:02;0040;PBS_Server;Svr;tyrone-cluster;Scheduler was sent the command new
12/08/2012 11:10:13;0040;PBS_Server;Svr;tyrone-cluster;Scheduler was sent the command new
12/08/2012 11:10:18;0040;PBS_Server;Svr;tyrone-cluster;Scheduler was sent the command new
12/08/2012 11:10:32;0040;PBS_Server;Svr;tyrone-cluster;Scheduler was sent the command new
12/08/2012 11:10:43;0040;PBS_Server;Svr;tyrone-cluster;Scheduler was sent the command new
12/08/2012 11:10:47;0040;PBS_Server;Svr;tyrone-cluster;Scheduler was sent the command new
12/08/2012 11:11:03;0040;PBS_Server;Svr;tyrone-cluster;Scheduler was sent the command new
12/08/2012 11:11:15;0040;PBS_Server;Svr;tyrone-cluster;Scheduler was sent the command new
12/08/2012 11:11:17;0040;PBS_Server;Svr;tyrone-cluster;Scheduler was sent the command new
12/08/2012 11:11:32;0040;PBS_Server;Svr;tyrone-cluster;Scheduler was sent the command new
12/08/2012 11:11:43;0040;PBS_Server;Svr;tyrone-cluster;Scheduler was sent the command new
12/08/2012 11:11:48;0040;PBS_Server;Svr;tyrone-cluster;Scheduler was sent the command new
12/08/2012 11:12:02;0040;PBS_Server;Svr;tyrone-cluster;Scheduler was sent the command new
12/08/2012 11:12:13;0040;PBS_Server;Svr;tyrone-cluster;Scheduler was sent the command new
12/08/2012 11:12:17;0040;PBS_Server;Svr;tyrone-cluster;Scheduler was sent the command new
12/08/2012 11:12:33;0040;PBS_Server;Svr;tyrone-cluster;Scheduler was sent the command new
12/08/2012 11:12:45;0040;PBS_Server;Svr;tyrone-cluster;Scheduler was sent the command new
12/08/2012 11:12:47;0040;PBS_Server;Svr;tyrone-cluster;Scheduler was sent the command new
12/08/2012 11:13:02;0040;PBS_Server;Svr;tyrone-cluster;Scheduler was sent the command new
12/08/2012 11:13:10;0002;PBS_Server;Svr;PBS_Server;Torque Server Version = 3.0.5, loglevel = 0
12/08/2012 11:13:13;0040;PBS_Server;Svr;tyrone-cluster;Scheduler was sent the command new
12/08/2012 11:13:18;0040;PBS_Server;Svr;tyrone-cluster;Scheduler was sent the command new
12/08/2012 11:13:32;0040;PBS_Server;Svr;tyrone-cluster;Scheduler was sent the command new
12/08/2012 11:13:43;0040;PBS_Server;Svr;tyrone-cluster;Scheduler was sent the command new
12/08/2012 11:13:47;0040;PBS_Server;Svr;tyrone-cluster;Scheduler was sent the command new
12/08/2012 11:14:03;0040;PBS_Server;Svr;tyrone-cluster;Scheduler was sent the command new
12/08/2012 11:14:14;0040;PBS_Server;Svr;tyrone-cluster;Scheduler was sent the command new
12/08/2012 11:14:17;0040;PBS_Server;Svr;tyrone-cluster;Scheduler was sent the command new
12/08/2012 11:14:32;0040;PBS_Server;Svr;tyrone-cluster;Scheduler was sent the command new
12/08/2012 11:14:43;0040;PBS_Server;Svr;tyrone-cluster;Scheduler was sent the command new
12/08/2012 11:14:48;0040;PBS_Server;Svr;tyrone-cluster;Scheduler was sent the command new
12/08/2012 11:15:02;0040;PBS_Server;Svr;tyrone-cluster;Scheduler was sent the command new
12/08/2012 11:15:13;0040;PBS_Server;Svr;tyrone-cluster;Scheduler was sent the command new
12/08/2012 11:15:17;0040;PBS_Server;Svr;tyrone-cluster;Scheduler was sent the command new
12/08/2012 11:15:33;0040;PBS_Server;Svr;tyrone-cluster;Scheduler was sent the command new
12/08/2012 11:15:45;0040;PBS_Server;Svr;tyrone-cluster;Scheduler was sent the command new
12/08/2012 11:15:47;0040;PBS_Server;Svr;tyrone-cluster;Scheduler was sent the command new
12/08/2012 11:16:02;0040;PBS_Server;Svr;tyrone-cluster;Scheduler was sent the command new
12/08/2012 11:16:13;0040;PBS_Server;Svr;tyrone-cluster;Scheduler was sent the command new
12/08/2012 11:16:18;0040;PBS_Server;Svr;tyrone-cluster;Scheduler was sent the command new
12/08/2012 11:16:32;0040;PBS_Server;Svr;tyrone-cluster;Scheduler was sent the command new
12/08/2012 11:16:43;0040;PBS_Server;Svr;tyrone-cluster;Scheduler was sent the command new
12/08/2012 11:16:47;0040;PBS_Server;Svr;tyrone-cluster;Scheduler was sent the command new
12/08/2012 11:17:03;0040;PBS_Server;Svr;tyrone-cluster;Scheduler was sent the command new
12/08/2012 11:17:14;0040;PBS_Server;Svr;tyrone-cluster;Scheduler was sent the command new
12/08/2012 11:17:17;0040;PBS_Server;Svr;tyrone-cluster;Scheduler was sent the command new
12/08/2012 11:17:32;0040;PBS_Server;Svr;tyrone-cluster;Scheduler was sent the command new
12/08/2012 11:17:43;0040;PBS_Server;Svr;tyrone-cluster;Scheduler was sent the command new
12/08/2012 11:17:48;0040;PBS_Server;Svr;tyrone-cluster;Scheduler was sent the command new
12/08/2012 11:18:02;0040;PBS_Server;Svr;tyrone-cluster;Scheduler was sent the command new
12/08/2012 11:18:10;0002;PBS_Server;Svr;PBS_Server;Torque Server Version = 3.0.5, loglevel = 0
12/08/2012 11:18:13;0040;PBS_Server;Svr;tyrone-cluster;Scheduler was sent the command new
12/08/2012 11:18:17;0040;PBS_Server;Svr;tyrone-cluster;Scheduler was sent the command new
12/08/2012 11:18:33;0040;PBS_Server;Svr;tyrone-cluster;Scheduler was sent the command new
12/08/2012 11:18:44;0040;PBS_Server;Svr;tyrone-cluster;Scheduler was sent the command new
12/08/2012 11:18:47;0040;PBS_Server;Svr;tyrone-cluster;Scheduler was sent the command new
12/08/2012 11:19:02;0040;PBS_Server;Svr;tyrone-cluster;Scheduler was sent the command new
12/08/2012 11:19:13;0040;PBS_Server;Svr;tyrone-cluster;Scheduler was sent the command new
12/08/2012 11:19:18;0040;PBS_Server;Svr;tyrone-cluster;Scheduler was sent the command new
12/08/2012 11:19:32;0040;PBS_Server;Svr;tyrone-cluster;Scheduler was sent the command new
12/08/2012 11:19:43;0040;PBS_Server;Svr;tyrone-cluster;Scheduler was sent the command new
12/08/2012 11:19:47;0040;PBS_Server;Svr;tyrone-cluster;Scheduler was sent the command new
12/08/2012 11:20:03;0040;PBS_Server;Svr;tyrone-cluster;Scheduler was sent the command new
12/08/2012 11:20:15;0040;PBS_Server;Svr;tyrone-cluster;Scheduler was sent the command new
12/08/2012 11:20:17;0040;PBS_Server;Svr;tyrone-cluster;Scheduler was sent the command new
12/08/2012 11:20:32;0040;PBS_Server;Svr;tyrone-cluster;Scheduler was sent the command new
12/08/2012 11:20:43;0040;PBS_Server;Svr;tyrone-cluster;Scheduler was sent the command new
12/08/2012 11:20:48;0040;PBS_Server;Svr;tyrone-cluster;Scheduler was sent the command new
12/08/2012 11:21:02;0040;PBS_Server;Svr;tyrone-cluster;Scheduler was sent the command new
12/08/2012 11:21:13;0040;PBS_Server;Svr;tyrone-cluster;Scheduler was sent the command new
12/08/2012 11:21:17;0040;PBS_Server;Svr;tyrone-cluster;Scheduler was sent the command new
12/08/2012 11:21:33;0040;PBS_Server;Svr;tyrone-cluster;Scheduler was sent the command new
12/08/2012 11:21:44;0040;PBS_Server;Svr;tyrone-cluster;Scheduler was sent the command new
12/08/2012 11:21:47;0040;PBS_Server;Svr;tyrone-cluster;Scheduler was sent the command new
12/08/2012 11:22:02;0040;PBS_Server;Svr;tyrone-cluster;Scheduler was sent the command new
12/08/2012 11:22:13;0040;PBS_Server;Svr;tyrone-cluster;Scheduler was sent the command new
12/08/2012 11:22:18;0040;PBS_Server;Svr;tyrone-cluster;Scheduler was sent the command new
12/08/2012 11:22:32;0040;PBS_Server;Svr;tyrone-cluster;Scheduler was sent the command new
12/08/2012 11:22:43;0040;PBS_Server;Svr;tyrone-cluster;Scheduler was sent the command new
12/08/2012 11:22:47;0040;PBS_Server;Svr;tyrone-cluster;Scheduler was sent the command new
12/08/2012 11:23:03;0040;PBS_Server;Svr;tyrone-cluster;Scheduler was sent the command new
12/08/2012 11:23:10;0002;PBS_Server;Svr;PBS_Server;Torque Server Version = 3.0.5, loglevel = 0
12/08/2012 11:23:14;0040;PBS_Server;Svr;tyrone-cluster;Scheduler was sent the command new
12/08/2012 11:23:17;0040;PBS_Server;Svr;tyrone-cluster;Scheduler was sent the command new
12/08/2012 11:23:32;0040;PBS_Server;Svr;tyrone-cluster;Scheduler was sent the command new
12/08/2012 11:23:43;0040;PBS_Server;Svr;tyrone-cluster;Scheduler was sent the command new
12/08/2012 11:23:48;0040;PBS_Server;Svr;tyrone-cluster;Scheduler was sent the command new
12/08/2012 11:24:02;0040;PBS_Server;Svr;tyrone-cluster;Scheduler was sent the command new
12/08/2012 11:24:13;0040;PBS_Server;Svr;tyrone-cluster;Scheduler was sent the command new
12/08/2012 11:24:17;0040;PBS_Server;Svr;tyrone-cluster;Scheduler was sent the command new
12/08/2012 11:24:33;0040;PBS_Server;Svr;tyrone-cluster;Scheduler was sent the command new
12/08/2012 11:24:44;0040;PBS_Server;Svr;tyrone-cluster;Scheduler was sent the command new
12/08/2012 11:24:47;0040;PBS_Server;Svr;tyrone-cluster;Scheduler was sent the command new
12/08/2012 11:25:02;0040;PBS_Server;Svr;tyrone-cluster;Scheduler was sent the command new
12/08/2012 11:25:13;0040;PBS_Server;Svr;tyrone-cluster;Scheduler was sent the command new
12/08/2012 11:25:18;0040;PBS_Server;Svr;tyrone-cluster;Scheduler was sent the command new
12/08/2012 11:25:32;0040;PBS_Server;Svr;tyrone-cluster;Scheduler was sent the command new
12/08/2012 11:25:43;0040;PBS_Server;Svr;tyrone-cluster;Scheduler was sent the command new
12/08/2012 11:25:47;0040;PBS_Server;Svr;tyrone-cluster;Scheduler was sent the command new
12/08/2012 11:26:03;0040;PBS_Server;Svr;tyrone-cluster;Scheduler was sent the command new
12/08/2012 11:26:14;0040;PBS_Server;Svr;tyrone-cluster;Scheduler was sent the command new
12/08/2012 11:26:17;0040;PBS_Server;Svr;tyrone-cluster;Scheduler was sent the command new
12/08/2012 11:26:32;0040;PBS_Server;Svr;tyrone-cluster;Scheduler was sent the command new
12/08/2012 11:26:43;0040;PBS_Server;Svr;tyrone-cluster;Scheduler was sent the command new
12/08/2012 11:26:48;0040;PBS_Server;Svr;tyrone-cluster;Scheduler was sent the command new
12/08/2012 11:27:02;0040;PBS_Server;Svr;tyrone-cluster;Scheduler was sent the command new
12/08/2012 11:27:13;0040;PBS_Server;Svr;tyrone-cluster;Scheduler was sent the command new
12/08/2012 11:27:17;0040;PBS_Server;Svr;tyrone-cluster;Scheduler was sent the command new
12/08/2012 11:27:33;0040;PBS_Server;Svr;tyrone-cluster;Scheduler was sent the command new
12/08/2012 11:27:44;0040;PBS_Server;Svr;tyrone-cluster;Scheduler was sent the command new
12/08/2012 11:27:47;0040;PBS_Server;Svr;tyrone-cluster;Scheduler was sent the command new
12/08/2012 11:28:02;0040;PBS_Server;Svr;tyrone-cluster;Scheduler was sent the command new
12/08/2012 11:28:10;0002;PBS_Server;Svr;PBS_Server;Torque Server Version = 3.0.5, loglevel = 0
12/08/2012 11:28:13;0040;PBS_Server;Svr;tyrone-cluster;Scheduler was sent the command new
12/08/2012 11:28:18;0040;PBS_Server;Svr;tyrone-cluster;Scheduler was sent the command new
12/08/2012 11:28:32;0040;PBS_Server;Svr;tyrone-cluster;Scheduler was sent the command new
12/08/2012 11:28:43;0040;PBS_Server;Svr;tyrone-cluster;Scheduler was sent the command new
12/08/2012 11:28:47;0040;PBS_Server;Svr;tyrone-cluster;Scheduler was sent the command new
12/08/2012 11:29:03;0040;PBS_Server;Svr;tyrone-cluster;Scheduler was sent the command new
12/08/2012 11:29:14;0040;PBS_Server;Svr;tyrone-cluster;Scheduler was sent the command new
12/08/2012 11:29:17;0040;PBS_Server;Svr;tyrone-cluster;Scheduler was sent the command new
12/08/2012 11:29:32;0040;PBS_Server;Svr;tyrone-cluster;Scheduler was sent the command new
12/08/2012 11:29:43;0040;PBS_Server;Svr;tyrone-cluster;Scheduler was sent the command new
12/08/2012 11:29:48;0040;PBS_Server;Svr;tyrone-cluster;Scheduler was sent the command new
12/08/2012 11:30:02;0040;PBS_Server;Svr;tyrone-cluster;Scheduler was sent the command new
12/08/2012 11:30:13;0040;PBS_Server;Svr;tyrone-cluster;Scheduler was sent the command new
12/08/2012 11:30:17;0040;PBS_Server;Svr;tyrone-cluster;Scheduler was sent the command new
12/08/2012 11:30:33;0040;PBS_Server;Svr;tyrone-cluster;Scheduler was sent the command new
12/08/2012 11:30:44;0040;PBS_Server;Svr;tyrone-cluster;Scheduler was sent the command new
12/08/2012 11:30:47;0040;PBS_Server;Svr;tyrone-cluster;Scheduler was sent the command new
12/08/2012 11:31:02;0040;PBS_Server;Svr;tyrone-cluster;Scheduler was sent the command new
12/08/2012 11:31:13;0040;PBS_Server;Svr;tyrone-cluster;Scheduler was sent the command new
12/08/2012 11:31:18;0040;PBS_Server;Svr;tyrone-cluster;Scheduler was sent the command new
12/08/2012 11:31:32;0040;PBS_Server;Svr;tyrone-cluster;Scheduler was sent the command new
12/08/2012 11:31:43;0040;PBS_Server;Svr;tyrone-cluster;Scheduler was sent the command new
12/08/2012 11:31:47;0040;PBS_Server;Svr;tyrone-cluster;Scheduler was sent the command new
12/08/2012 11:32:03;0040;PBS_Server;Svr;tyrone-cluster;Scheduler was sent the command new
12/08/2012 11:32:14;0040;PBS_Server;Svr;tyrone-cluster;Scheduler was sent the command new
12/08/2012 11:32:17;0040;PBS_Server;Svr;tyrone-cluster;Scheduler was sent the command new
12/08/2012 11:32:32;0040;PBS_Server;Svr;tyrone-cluster;Scheduler was sent the command new
12/08/2012 11:32:43;0040;PBS_Server;Svr;tyrone-cluster;Scheduler was sent the command new
12/08/2012 11:32:48;0040;PBS_Server;Svr;tyrone-cluster;Scheduler was sent the command new
12/08/2012 11:33:02;0040;PBS_Server;Svr;tyrone-cluster;Scheduler was sent the command new
12/08/2012 11:33:10;0002;PBS_Server;Svr;PBS_Server;Torque Server Version = 3.0.5, loglevel = 0
12/08/2012 11:33:13;0040;PBS_Server;Svr;tyrone-cluster;Scheduler was sent the command new
12/08/2012 11:33:17;0040;PBS_Server;Svr;tyrone-cluster;Scheduler was sent the command new
12/08/2012 11:33:33;0040;PBS_Server;Svr;tyrone-cluster;Scheduler was sent the command new
12/08/2012 11:33:44;0040;PBS_Server;Svr;tyrone-cluster;Scheduler was sent the command new
12/08/2012 11:33:47;0040;PBS_Server;Svr;tyrone-cluster;Scheduler was sent the command new
12/08/2012 11:34:02;0040;PBS_Server;Svr;tyrone-cluster;Scheduler was sent the command new
12/08/2012 11:34:13;0040;PBS_Server;Svr;tyrone-cluster;Scheduler was sent the command new
12/08/2012 11:34:18;0040;PBS_Server;Svr;tyrone-cluster;Scheduler was sent the command new
12/08/2012 11:34:32;0040;PBS_Server;Svr;tyrone-cluster;Scheduler was sent the command new
12/08/2012 11:34:43;0040;PBS_Server;Svr;tyrone-cluster;Scheduler was sent the command new
12/08/2012 11:34:47;0040;PBS_Server;Svr;tyrone-cluster;Scheduler was sent the command new
12/08/2012 11:35:03;0040;PBS_Server;Svr;tyrone-cluster;Scheduler was sent the command new
12/08/2012 11:35:14;0040;PBS_Server;Svr;tyrone-cluster;Scheduler was sent the command new
12/08/2012 11:35:17;0040;PBS_Server;Svr;tyrone-cluster;Scheduler was sent the command new
12/08/2012 11:35:32;0040;PBS_Server;Svr;tyrone-cluster;Scheduler was sent the command new
12/08/2012 11:35:43;0040;PBS_Server;Svr;tyrone-cluster;Scheduler was sent the command new
12/08/2012 11:35:48;0040;PBS_Server;Svr;tyrone-cluster;Scheduler was sent the command new
12/08/2012 11:36:02;0040;PBS_Server;Svr;tyrone-cluster;Scheduler was sent the command new
12/08/2012 11:36:13;0040;PBS_Server;Svr;tyrone-cluster;Scheduler was sent the command new
12/08/2012 11:36:17;0040;PBS_Server;Svr;tyrone-cluster;Scheduler was sent the command new
12/08/2012 11:36:33;0040;PBS_Server;Svr;tyrone-cluster;Scheduler was sent the command new
12/08/2012 11:36:44;0040;PBS_Server;Svr;tyrone-cluster;Scheduler was sent the command new
12/08/2012 11:36:47;0040;PBS_Server;Svr;tyrone-cluster;Scheduler was sent the command new
12/08/2012 11:37:02;0040;PBS_Server;Svr;tyrone-cluster;Scheduler was sent the command new
12/08/2012 11:37:13;0040;PBS_Server;Svr;tyrone-cluster;Scheduler was sent the command new
12/08/2012 11:37:18;0040;PBS_Server;Svr;tyrone-cluster;Scheduler was sent the command new
12/08/2012 11:37:23;0100;PBS_Server;Job;16760.tyrone-cluster;enqueuing into batch, state 1 hop 1
12/08/2012 11:37:23;0100;PBS_Server;Job;16760.tyrone-cluster;dequeuing from batch, state QUEUED
12/08/2012 11:37:23;0100;PBS_Server;Job;16760.tyrone-cluster;enqueuing into qp32, state 1 hop 1
12/08/2012 11:37:23;0008;PBS_Server;Job;16760.tyrone-cluster;Job Queued at request of csdsuben@tyrone-cluster, owner = csdsuben@tyrone-cluster, job name = zr-cum-zr-me-ts, queue = qp32
12/08/2012 11:37:23;0040;PBS_Server;Svr;tyrone-cluster;Scheduler was sent the command new
12/08/2012 11:37:23;0008;PBS_Server;Job;16760.tyrone-cluster;Job Modified at request of Scheduler@tyrone-cluster
12/08/2012 11:37:32;0040;PBS_Server;Svr;tyrone-cluster;Scheduler was sent the command new
12/08/2012 11:37:43;0040;PBS_Server;Svr;tyrone-cluster;Scheduler was sent the command new
12/08/2012 11:37:47;0040;PBS_Server;Svr;tyrone-cluster;Scheduler was sent the command new
12/08/2012 11:38:03;0040;PBS_Server;Svr;tyrone-cluster;Scheduler was sent the command new
12/08/2012 11:38:10;0002;PBS_Server;Svr;PBS_Server;Torque Server Version = 3.0.5, loglevel = 0
12/08/2012 11:38:14;0040;PBS_Server;Svr;tyrone-cluster;Scheduler was sent the command new
12/08/2012 11:38:17;0040;PBS_Server;Svr;tyrone-cluster;Scheduler was sent the command new
12/08/2012 11:38:32;0040;PBS_Server;Svr;tyrone-cluster;Scheduler was sent the command new
12/08/2012 11:38:43;0040;PBS_Server;Svr;tyrone-cluster;Scheduler was sent the command new
12/08/2012 11:38:48;0040;PBS_Server;Svr;tyrone-cluster;Scheduler was sent the command new
12/08/2012 11:39:02;0040;PBS_Server;Svr;tyrone-cluster;Scheduler was sent the command new
12/08/2012 11:39:13;0040;PBS_Server;Svr;tyrone-cluster;Scheduler was sent the command new
12/08/2012 11:39:17;0040;PBS_Server;Svr;tyrone-cluster;Scheduler was sent the command new
12/08/2012 11:39:33;0040;PBS_Server;Svr;tyrone-cluster;Scheduler was sent the command new
12/08/2012 11:39:44;0040;PBS_Server;Svr;tyrone-cluster;Scheduler was sent the command new
12/08/2012 11:39:47;0040;PBS_Server;Svr;tyrone-cluster;Scheduler was sent the command new
12/08/2012 11:40:02;0040;PBS_Server;Svr;tyrone-cluster;Scheduler was sent the command new
12/08/2012 11:40:13;0040;PBS_Server;Svr;tyrone-cluster;Scheduler was sent the command new
12/08/2012 11:40:18;0040;PBS_Server;Svr;tyrone-cluster;Scheduler was sent the command new
12/08/2012 11:40:32;0040;PBS_Server;Svr;tyrone-cluster;Scheduler was sent the command new
12/08/2012 11:40:43;0040;PBS_Server;Svr;tyrone-cluster;Scheduler was sent the command new
12/08/2012 11:40:47;0040;PBS_Server;Svr;tyrone-cluster;Scheduler was sent the command new
12/08/2012 11:41:03;0040;PBS_Server;Svr;tyrone-cluster;Scheduler was sent the command new
12/08/2012 11:41:15;0040;PBS_Server;Svr;tyrone-cluster;Scheduler was sent the command new
12/08/2012 11:41:17;0040;PBS_Server;Svr;tyrone-cluster;Scheduler was sent the command new
12/08/2012 11:41:32;0040;PBS_Server;Svr;tyrone-cluster;Scheduler was sent the command new
12/08/2012 11:41:44;0040;PBS_Server;Svr;tyrone-cluster;Scheduler was sent the command new
12/08/2012 11:41:48;0040;PBS_Server;Svr;tyrone-cluster;Scheduler was sent the command new
12/08/2012 11:42:02;0040;PBS_Server;Svr;tyrone-cluster;Scheduler was sent the command new
12/08/2012 11:42:15;0040;PBS_Server;Svr;tyrone-cluster;Scheduler was sent the command new
12/08/2012 11:42:17;0040;PBS_Server;Svr;tyrone-cluster;Scheduler was sent the command new
12/08/2012 11:42:33;0040;PBS_Server;Svr;tyrone-cluster;Scheduler was sent the command new
12/08/2012 11:42:47;0040;PBS_Server;Svr;tyrone-cluster;Scheduler was sent the command new
12/08/2012 11:43:02;0040;PBS_Server;Svr;tyrone-cluster;Scheduler was sent the command new
12/08/2012 11:43:10;0002;PBS_Server;Svr;PBS_Server;Torque Server Version = 3.0.5, loglevel = 0
12/08/2012 11:43:18;0040;PBS_Server;Svr;tyrone-cluster;Scheduler was sent the command new
12/08/2012 11:43:32;0040;PBS_Server;Svr;tyrone-cluster;Scheduler was sent the command new
12/08/2012 11:43:47;0040;PBS_Server;Svr;tyrone-cluster;Scheduler was sent the command new
12/08/2012 11:44:03;0040;PBS_Server;Svr;tyrone-cluster;Scheduler was sent the command new
12/08/2012 11:44:17;0040;PBS_Server;Svr;tyrone-cluster;Scheduler was sent the command new
12/08/2012 11:44:32;0040;PBS_Server;Svr;tyrone-cluster;Scheduler was sent the command new
12/08/2012 11:44:48;0040;PBS_Server;Svr;tyrone-cluster;Scheduler was sent the command new
12/08/2012 11:45:02;0040;PBS_Server;Svr;tyrone-cluster;Scheduler was sent the command new
12/08/2012 11:45:17;0040;PBS_Server;Svr;tyrone-cluster;Scheduler was sent the command new
12/08/2012 11:45:33;0040;PBS_Server;Svr;tyrone-cluster;Scheduler was sent the command new
12/08/2012 11:45:47;0040;PBS_Server;Svr;tyrone-cluster;Scheduler was sent the command new
12/08/2012 11:46:02;0040;PBS_Server;Svr;tyrone-cluster;Scheduler was sent the command new
12/08/2012 11:46:18;0040;PBS_Server;Svr;tyrone-cluster;Scheduler was sent the command new
12/08/2012 11:46:32;0040;PBS_Server;Svr;tyrone-cluster;Scheduler was sent the command new
12/08/2012 11:46:47;0040;PBS_Server;Svr;tyrone-cluster;Scheduler was sent the command new
12/08/2012 11:47:03;0040;PBS_Server;Svr;tyrone-cluster;Scheduler was sent the command new
12/08/2012 11:47:17;0040;PBS_Server;Svr;tyrone-cluster;Scheduler was sent the command new
12/08/2012 11:47:32;0040;PBS_Server;Svr;tyrone-cluster;Scheduler was sent the command new
12/08/2012 11:47:48;0040;PBS_Server;Svr;tyrone-cluster;Scheduler was sent the command new
12/08/2012 11:48:02;0040;PBS_Server;Svr;tyrone-cluster;Scheduler was sent the command new
12/08/2012 11:48:10;0002;PBS_Server;Svr;PBS_Server;Torque Server Version = 3.0.5, loglevel = 0
12/08/2012 11:48:17;0040;PBS_Server;Svr;tyrone-cluster;Scheduler was sent the command new
12/08/2012 11:48:33;0040;PBS_Server;Svr;tyrone-cluster;Scheduler was sent the command new
12/08/2012 11:48:47;0040;PBS_Server;Svr;tyrone-cluster;Scheduler was sent the command new
12/08/2012 11:49:02;0040;PBS_Server;Svr;tyrone-cluster;Scheduler was sent the command new
12/08/2012 11:49:18;0040;PBS_Server;Svr;tyrone-cluster;Scheduler was sent the command new
12/08/2012 11:49:32;0040;PBS_Server;Svr;tyrone-cluster;Scheduler was sent the command new
12/08/2012 11:49:47;0040;PBS_Server;Svr;tyrone-cluster;Scheduler was sent the command new
12/08/2012 11:50:03;0040;PBS_Server;Svr;tyrone-cluster;Scheduler was sent the command new
12/08/2012 11:50:17;0040;PBS_Server;Svr;tyrone-cluster;Scheduler was sent the command new
12/08/2012 11:50:32;0040;PBS_Server;Svr;tyrone-cluster;Scheduler was sent the command new
12/08/2012 11:50:48;0040;PBS_Server;Svr;tyrone-cluster;Scheduler was sent the command new
12/08/2012 11:51:02;0040;PBS_Server;Svr;tyrone-cluster;Scheduler was sent the command new
12/08/2012 11:51:17;0040;PBS_Server;Svr;tyrone-cluster;Scheduler was sent the command new
12/08/2012 11:51:33;0040;PBS_Server;Svr;tyrone-cluster;Scheduler was sent the command new
12/08/2012 11:51:47;0040;PBS_Server;Svr;tyrone-cluster;Scheduler was sent the command new
12/08/2012 11:52:02;0040;PBS_Server;Svr;tyrone-cluster;Scheduler was sent the command new
12/08/2012 11:52:18;0040;PBS_Server;Svr;tyrone-cluster;Scheduler was sent the command new
12/08/2012 11:52:32;0040;PBS_Server;Svr;tyrone-cluster;Scheduler was sent the command new
12/08/2012 11:52:47;0040;PBS_Server;Svr;tyrone-cluster;Scheduler was sent the command new
12/08/2012 11:53:03;0040;PBS_Server;Svr;tyrone-cluster;Scheduler was sent the command new
12/08/2012 11:53:10;0002;PBS_Server;Svr;PBS_Server;Torque Server Version = 3.0.5, loglevel = 0
12/08/2012 11:53:17;0040;PBS_Server;Svr;tyrone-cluster;Scheduler was sent the command new
12/08/2012 11:53:32;0040;PBS_Server;Svr;tyrone-cluster;Scheduler was sent the command new
12/08/2012 11:53:48;0040;PBS_Server;Svr;tyrone-cluster;Scheduler was sent the command new
12/08/2012 11:54:02;0040;PBS_Server;Svr;tyrone-cluster;Scheduler was sent the command new
12/08/2012 11:54:17;0040;PBS_Server;Svr;tyrone-cluster;Scheduler was sent the command new
12/08/2012 11:54:33;0040;PBS_Server;Svr;tyrone-cluster;Scheduler was sent the command new
12/08/2012 11:54:47;0040;PBS_Server;Svr;tyrone-cluster;Scheduler was sent the command new
12/08/2012 11:55:02;0040;PBS_Server;Svr;tyrone-cluster;Scheduler was sent the command new
12/08/2012 11:55:18;0040;PBS_Server;Svr;tyrone-cluster;Scheduler was sent the command new
12/08/2012 11:55:32;0040;PBS_Server;Svr;tyrone-cluster;Scheduler was sent the command new
12/08/2012 11:55:47;0040;PBS_Server;Svr;tyrone-cluster;Scheduler was sent the command new
12/08/2012 11:56:03;0040;PBS_Server;Svr;tyrone-cluster;Scheduler was sent the command new
12/08/2012 11:56:17;0040;PBS_Server;Svr;tyrone-cluster;Scheduler was sent the command new
12/08/2012 11:56:32;0040;PBS_Server;Svr;tyrone-cluster;Scheduler was sent the command new
12/08/2012 11:56:48;0040;PBS_Server;Svr;tyrone-cluster;Scheduler was sent the command new
12/08/2012 11:57:02;0040;PBS_Server;Svr;tyrone-cluster;Scheduler was sent the command new
12/08/2012 11:57:17;0040;PBS_Server;Svr;tyrone-cluster;Scheduler was sent the command new
12/08/2012 11:57:33;0040;PBS_Server;Svr;tyrone-cluster;Scheduler was sent the command new
12/08/2012 11:57:47;0040;PBS_Server;Svr;tyrone-cluster;Scheduler was sent the command new
12/08/2012 11:58:02;0040;PBS_Server;Svr;tyrone-cluster;Scheduler was sent the command new
12/08/2012 11:58:10;0002;PBS_Server;Svr;PBS_Server;Torque Server Version = 3.0.5, loglevel = 0
12/08/2012 11:58:18;0040;PBS_Server;Svr;tyrone-cluster;Scheduler was sent the command new
12/08/2012 11:58:32;0040;PBS_Server;Svr;tyrone-cluster;Scheduler was sent the command new
12/08/2012 11:58:47;0040;PBS_Server;Svr;tyrone-cluster;Scheduler was sent the command new
12/08/2012 11:59:03;0040;PBS_Server;Svr;tyrone-cluster;Scheduler was sent the command new
12/08/2012 11:59:17;0040;PBS_Server;Svr;tyrone-cluster;Scheduler was sent the command new
12/08/2012 11:59:32;0040;PBS_Server;Svr;tyrone-cluster;Scheduler was sent the command new
12/08/2012 11:59:48;0040;PBS_Server;Svr;tyrone-cluster;Scheduler was sent the command new
12/08/2012 12:00:02;0040;PBS_Server;Svr;tyrone-cluster;Scheduler was sent the command new
12/08/2012 12:00:17;0040;PBS_Server;Svr;tyrone-cluster;Scheduler was sent the command new
12/08/2012 12:00:33;0040;PBS_Server;Svr;tyrone-cluster;Scheduler was sent the command new
12/08/2012 12:00:47;0040;PBS_Server;Svr;tyrone-cluster;Scheduler was sent the command new
12/08/2012 12:01:02;0040;PBS_Server;Svr;tyrone-cluster;Scheduler was sent the command new
12/08/2012 12:01:18;0040;PBS_Server;Svr;tyrone-cluster;Scheduler was sent the command new
12/08/2012 12:01:32;0040;PBS_Server;Svr;tyrone-cluster;Scheduler was sent the command new
12/08/2012 12:01:47;0040;PBS_Server;Svr;tyrone-cluster;Scheduler was sent the command new
12/08/2012 12:02:03;0040;PBS_Server;Svr;tyrone-cluster;Scheduler was sent the command new
12/08/2012 12:02:17;0040;PBS_Server;Svr;tyrone-cluster;Scheduler was sent the command new
12/08/2012 12:02:32;0040;PBS_Server;Svr;tyrone-cluster;Scheduler was sent the command new
12/08/2012 12:02:48;0040;PBS_Server;Svr;tyrone-cluster;Scheduler was sent the command new
12/08/2012 12:03:02;0040;PBS_Server;Svr;tyrone-cluster;Scheduler was sent the command new
12/08/2012 12:03:10;0002;PBS_Server;Svr;PBS_Server;Torque Server Version = 3.0.5, loglevel = 0
12/08/2012 12:03:17;0040;PBS_Server;Svr;tyrone-cluster;Scheduler was sent the command new
12/08/2012 12:03:33;0040;PBS_Server;Svr;tyrone-cluster;Scheduler was sent the command new
12/08/2012 12:03:47;0040;PBS_Server;Svr;tyrone-cluster;Scheduler was sent the command new
12/08/2012 12:04:02;0040;PBS_Server;Svr;tyrone-cluster;Scheduler was sent the command new
12/08/2012 12:04:18;0040;PBS_Server;Svr;tyrone-cluster;Scheduler was sent the command new
12/08/2012 12:04:32;0040;PBS_Server;Svr;tyrone-cluster;Scheduler was sent the command new
12/08/2012 12:04:47;0040;PBS_Server;Svr;tyrone-cluster;Scheduler was sent the command new
12/08/2012 12:05:03;0040;PBS_Server;Svr;tyrone-cluster;Scheduler was sent the command new
12/08/2012 12:05:17;0040;PBS_Server;Svr;tyrone-cluster;Scheduler was sent the command new
12/08/2012 12:05:32;0040;PBS_Server;Svr;tyrone-cluster;Scheduler was sent the command new
12/08/2012 12:05:48;0040;PBS_Server;Svr;tyrone-cluster;Scheduler was sent the command new
12/08/2012 12:06:02;0040;PBS_Server;Svr;tyrone-cluster;Scheduler was sent the command new
12/08/2012 12:06:17;0040;PBS_Server;Svr;tyrone-cluster;Scheduler was sent the command new
12/08/2012 12:06:32;0040;PBS_Server;Svr;tyrone-cluster;Scheduler was sent the command new
12/08/2012 12:06:47;0040;PBS_Server;Svr;tyrone-cluster;Scheduler was sent the command new
12/08/2012 12:07:02;0040;PBS_Server;Svr;tyrone-cluster;Scheduler was sent the command new
12/08/2012 12:07:18;0040;PBS_Server;Svr;tyrone-cluster;Scheduler was sent the command new
12/08/2012 12:07:32;0040;PBS_Server;Svr;tyrone-cluster;Scheduler was sent the command new
12/08/2012 12:07:47;0040;PBS_Server;Svr;tyrone-cluster;Scheduler was sent the command new
12/08/2012 12:08:03;0040;PBS_Server;Svr;tyrone-cluster;Scheduler was sent the command new
12/08/2012 12:08:10;0002;PBS_Server;Svr;PBS_Server;Torque Server Version = 3.0.5, loglevel = 0
12/08/2012 12:08:17;0040;PBS_Server;Svr;tyrone-cluster;Scheduler was sent the command new
12/08/2012 12:08:32;0040;PBS_Server;Svr;tyrone-cluster;Scheduler was sent the command new
12/08/2012 12:08:48;0040;PBS_Server;Svr;tyrone-cluster;Scheduler was sent the command new
12/08/2012 12:09:02;0040;PBS_Server;Svr;tyrone-cluster;Scheduler was sent the command new
12/08/2012 12:09:17;0040;PBS_Server;Svr;tyrone-cluster;Scheduler was sent the command new
12/08/2012 12:09:33;0040;PBS_Server;Svr;tyrone-cluster;Scheduler was sent the command new
12/08/2012 12:09:47;0040;PBS_Server;Svr;tyrone-cluster;Scheduler was sent the command new
12/08/2012 12:10:02;0040;PBS_Server;Svr;tyrone-cluster;Scheduler was sent the command new
12/08/2012 12:10:18;0040;PBS_Server;Svr;tyrone-cluster;Scheduler was sent the command new
12/08/2012 12:10:32;0040;PBS_Server;Svr;tyrone-cluster;Scheduler was sent the command new
12/08/2012 12:10:47;0040;PBS_Server;Svr;tyrone-cluster;Scheduler was sent the command new
12/08/2012 12:11:03;0040;PBS_Server;Svr;tyrone-cluster;Scheduler was sent the command new
12/08/2012 12:11:17;0040;PBS_Server;Svr;tyrone-cluster;Scheduler was sent the command new
12/08/2012 12:11:32;0040;PBS_Server;Svr;tyrone-cluster;Scheduler was sent the command new
12/08/2012 12:11:48;0040;PBS_Server;Svr;tyrone-cluster;Scheduler was sent the command new
12/08/2012 12:12:02;0040;PBS_Server;Svr;tyrone-cluster;Scheduler was sent the command new
12/08/2012 12:12:17;0040;PBS_Server;Svr;tyrone-cluster;Scheduler was sent the command new
12/08/2012 12:12:33;0040;PBS_Server;Svr;tyrone-cluster;Scheduler was sent the command new
12/08/2012 12:12:47;0040;PBS_Server;Svr;tyrone-cluster;Scheduler was sent the command new
12/08/2012 12:13:02;0040;PBS_Server;Svr;tyrone-cluster;Scheduler was sent the command new
12/08/2012 12:13:10;0002;PBS_Server;Svr;PBS_Server;Torque Server Version = 3.0.5, loglevel = 0
12/08/2012 12:13:18;0040;PBS_Server;Svr;tyrone-cluster;Scheduler was sent the command new
12/08/2012 12:13:32;0040;PBS_Server;Svr;tyrone-cluster;Scheduler was sent the command new
12/08/2012 12:13:47;0040;PBS_Server;Svr;tyrone-cluster;Scheduler was sent the command new
12/08/2012 12:14:03;0040;PBS_Server;Svr;tyrone-cluster;Scheduler was sent the command new
12/08/2012 12:14:17;0040;PBS_Server;Svr;tyrone-cluster;Scheduler was sent the command new
12/08/2012 12:14:32;0040;PBS_Server;Svr;tyrone-cluster;Scheduler was sent the command new
12/08/2012 12:14:48;0040;PBS_Server;Svr;tyrone-cluster;Scheduler was sent the command new
12/08/2012 12:15:02;0040;PBS_Server;Svr;tyrone-cluster;Scheduler was sent the command new
12/08/2012 12:15:17;0040;PBS_Server;Svr;tyrone-cluster;Scheduler was sent the command new
12/08/2012 12:15:33;0040;PBS_Server;Svr;tyrone-cluster;Scheduler was sent the command new
12/08/2012 12:15:47;0040;PBS_Server;Svr;tyrone-cluster;Scheduler was sent the command new
12/08/2012 12:16:02;0040;PBS_Server;Svr;tyrone-cluster;Scheduler was sent the command new
12/08/2012 12:16:18;0040;PBS_Server;Svr;tyrone-cluster;Scheduler was sent the command new
12/08/2012 12:16:32;0040;PBS_Server;Svr;tyrone-cluster;Scheduler was sent the command new
12/08/2012 12:16:47;0040;PBS_Server;Svr;tyrone-cluster;Scheduler was sent the command new
12/08/2012 12:17:03;0040;PBS_Server;Svr;tyrone-cluster;Scheduler was sent the command new
12/08/2012 12:17:17;0040;PBS_Server;Svr;tyrone-cluster;Scheduler was sent the command new
12/08/2012 12:17:32;0040;PBS_Server;Svr;tyrone-cluster;Scheduler was sent the command new
12/08/2012 12:17:48;0040;PBS_Server;Svr;tyrone-cluster;Scheduler was sent the command new
12/08/2012 12:18:02;0040;PBS_Server;Svr;tyrone-cluster;Scheduler was sent the command new
12/08/2012 12:18:10;0002;PBS_Server;Svr;PBS_Server;Torque Server Version = 3.0.5, loglevel = 0
12/08/2012 12:18:17;0040;PBS_Server;Svr;tyrone-cluster;Scheduler was sent the command new
12/08/2012 12:18:33;0040;PBS_Server;Svr;tyrone-cluster;Scheduler was sent the command new
12/08/2012 12:18:47;0040;PBS_Server;Svr;tyrone-cluster;Scheduler was sent the command new
12/08/2012 12:19:02;0040;PBS_Server;Svr;tyrone-cluster;Scheduler was sent the command new
12/08/2012 12:19:18;0040;PBS_Server;Svr;tyrone-cluster;Scheduler was sent the command new
12/08/2012 12:19:32;0040;PBS_Server;Svr;tyrone-cluster;Scheduler was sent the command new
12/08/2012 12:19:47;0040;PBS_Server;Svr;tyrone-cluster;Scheduler was sent the command new
12/08/2012 12:20:03;0040;PBS_Server;Svr;tyrone-cluster;Scheduler was sent the command new
12/08/2012 12:20:17;0040;PBS_Server;Svr;tyrone-cluster;Scheduler was sent the command new
12/08/2012 12:20:32;0040;PBS_Server;Svr;tyrone-cluster;Scheduler was sent the command new
12/08/2012 12:20:48;0040;PBS_Server;Svr;tyrone-cluster;Scheduler was sent the command new
12/08/2012 12:21:02;0040;PBS_Server;Svr;tyrone-cluster;Scheduler was sent the command new
12/08/2012 12:21:17;0040;PBS_Server;Svr;tyrone-cluster;Scheduler was sent the command new
12/08/2012 12:21:33;0040;PBS_Server;Svr;tyrone-cluster;Scheduler was sent the command new
12/08/2012 12:21:47;0040;PBS_Server;Svr;tyrone-cluster;Scheduler was sent the command new
12/08/2012 12:22:02;0040;PBS_Server;Svr;tyrone-cluster;Scheduler was sent the command new
12/08/2012 12:22:18;0040;PBS_Server;Svr;tyrone-cluster;Scheduler was sent the command new
12/08/2012 12:22:32;0040;PBS_Server;Svr;tyrone-cluster;Scheduler was sent the command new
12/08/2012 12:22:47;0040;PBS_Server;Svr;tyrone-cluster;Scheduler was sent the command new
12/08/2012 12:23:03;0040;PBS_Server;Svr;tyrone-cluster;Scheduler was sent the command new
12/08/2012 12:23:10;0002;PBS_Server;Svr;PBS_Server;Torque Server Version = 3.0.5, loglevel = 0
12/08/2012 12:23:17;0040;PBS_Server;Svr;tyrone-cluster;Scheduler was sent the command new
12/08/2012 12:23:32;0040;PBS_Server;Svr;tyrone-cluster;Scheduler was sent the command new
12/08/2012 12:23:48;0040;PBS_Server;Svr;tyrone-cluster;Scheduler was sent the command new
12/08/2012 12:24:02;0040;PBS_Server;Svr;tyrone-cluster;Scheduler was sent the command new
12/08/2012 12:24:17;0040;PBS_Server;Svr;tyrone-cluster;Scheduler was sent the command new
12/08/2012 12:24:33;0040;PBS_Server;Svr;tyrone-cluster;Scheduler was sent the command new
12/08/2012 12:24:47;0040;PBS_Server;Svr;tyrone-cluster;Scheduler was sent the command new
12/08/2012 12:25:02;0040;PBS_Server;Svr;tyrone-cluster;Scheduler was sent the command new
12/08/2012 12:25:18;0040;PBS_Server;Svr;tyrone-cluster;Scheduler was sent the command new
12/08/2012 12:25:32;0040;PBS_Server;Svr;tyrone-cluster;Scheduler was sent the command new
12/08/2012 12:25:47;0040;PBS_Server;Svr;tyrone-cluster;Scheduler was sent the command new
12/08/2012 12:26:03;0040;PBS_Server;Svr;tyrone-cluster;Scheduler was sent the command new
12/08/2012 12:26:17;0040;PBS_Server;Svr;tyrone-cluster;Scheduler was sent the command new
12/08/2012 12:26:32;0040;PBS_Server;Svr;tyrone-cluster;Scheduler was sent the command new
12/08/2012 12:26:48;0040;PBS_Server;Svr;tyrone-cluster;Scheduler was sent the command new
12/08/2012 12:27:02;0040;PBS_Server;Svr;tyrone-cluster;Scheduler was sent the command new
12/08/2012 12:27:17;0040;PBS_Server;Svr;tyrone-cluster;Scheduler was sent the command new
12/08/2012 12:27:33;0040;PBS_Server;Svr;tyrone-cluster;Scheduler was sent the command new
12/08/2012 12:27:47;0040;PBS_Server;Svr;tyrone-cluster;Scheduler was sent the command new
12/08/2012 12:28:02;0040;PBS_Server;Svr;tyrone-cluster;Scheduler was sent the command new
12/08/2012 12:28:10;0002;PBS_Server;Svr;PBS_Server;Torque Server Version = 3.0.5, loglevel = 0
12/08/2012 12:28:18;0040;PBS_Server;Svr;tyrone-cluster;Scheduler was sent the command new
12/08/2012 12:28:32;0040;PBS_Server;Svr;tyrone-cluster;Scheduler was sent the command new
12/08/2012 12:28:47;0040;PBS_Server;Svr;tyrone-cluster;Scheduler was sent the command new
12/08/2012 12:29:03;0040;PBS_Server;Svr;tyrone-cluster;Scheduler was sent the command new
12/08/2012 12:29:17;0040;PBS_Server;Svr;tyrone-cluster;Scheduler was sent the command new
12/08/2012 12:29:32;0040;PBS_Server;Svr;tyrone-cluster;Scheduler was sent the command new
12/08/2012 12:29:48;0040;PBS_Server;Svr;tyrone-cluster;Scheduler was sent the command new
12/08/2012 12:30:02;0040;PBS_Server;Svr;tyrone-cluster;Scheduler was sent the command new
12/08/2012 12:30:17;0040;PBS_Server;Svr;tyrone-cluster;Scheduler was sent the command new
12/08/2012 12:30:33;0040;PBS_Server;Svr;tyrone-cluster;Scheduler was sent the command new
12/08/2012 12:30:47;0040;PBS_Server;Svr;tyrone-cluster;Scheduler was sent the command new
12/08/2012 12:31:02;0040;PBS_Server;Svr;tyrone-cluster;Scheduler was sent the command new
12/08/2012 12:31:18;0040;PBS_Server;Svr;tyrone-cluster;Scheduler was sent the command new
12/08/2012 12:31:32;0040;PBS_Server;Svr;tyrone-cluster;Scheduler was sent the command new
12/08/2012 12:31:47;0040;PBS_Server;Svr;tyrone-cluster;Scheduler was sent the command new
12/08/2012 12:32:03;0040;PBS_Server;Svr;tyrone-cluster;Scheduler was sent the command new
12/08/2012 12:32:17;0040;PBS_Server;Svr;tyrone-cluster;Scheduler was sent the command new
12/08/2012 12:32:32;0040;PBS_Server;Svr;tyrone-cluster;Scheduler was sent the command new
12/08/2012 12:32:48;0040;PBS_Server;Svr;tyrone-cluster;Scheduler was sent the command new
12/08/2012 12:33:02;0040;PBS_Server;Svr;tyrone-cluster;Scheduler was sent the command new
12/08/2012 12:33:10;0002;PBS_Server;Svr;PBS_Server;Torque Server Version = 3.0.5, loglevel = 0
12/08/2012 12:33:17;0040;PBS_Server;Svr;tyrone-cluster;Scheduler was sent the command new
12/08/2012 12:33:33;0040;PBS_Server;Svr;tyrone-cluster;Scheduler was sent the command new
12/08/2012 12:33:47;0040;PBS_Server;Svr;tyrone-cluster;Scheduler was sent the command new
12/08/2012 12:34:02;0040;PBS_Server;Svr;tyrone-cluster;Scheduler was sent the command new
12/08/2012 12:34:18;0040;PBS_Server;Svr;tyrone-cluster;Scheduler was sent the command new
12/08/2012 12:34:32;0040;PBS_Server;Svr;tyrone-cluster;Scheduler was sent the command new
12/08/2012 12:34:47;0040;PBS_Server;Svr;tyrone-cluster;Scheduler was sent the command new
12/08/2012 12:35:03;0040;PBS_Server;Svr;tyrone-cluster;Scheduler was sent the command new
12/08/2012 12:35:17;0040;PBS_Server;Svr;tyrone-cluster;Scheduler was sent the command new
12/08/2012 12:35:32;0040;PBS_Server;Svr;tyrone-cluster;Scheduler was sent the command new
12/08/2012 12:35:48;0040;PBS_Server;Svr;tyrone-cluster;Scheduler was sent the command new
12/08/2012 12:36:02;0040;PBS_Server;Svr;tyrone-cluster;Scheduler was sent the command new
12/08/2012 12:36:17;0040;PBS_Server;Svr;tyrone-cluster;Scheduler was sent the command new
12/08/2012 12:36:33;0040;PBS_Server;Svr;tyrone-cluster;Scheduler was sent the command new
12/08/2012 12:36:47;0040;PBS_Server;Svr;tyrone-cluster;Scheduler was sent the command new
12/08/2012 12:37:02;0040;PBS_Server;Svr;tyrone-cluster;Scheduler was sent the command new
12/08/2012 12:37:18;0040;PBS_Server;Svr;tyrone-cluster;Scheduler was sent the command new
12/08/2012 12:37:32;0040;PBS_Server;Svr;tyrone-cluster;Scheduler was sent the command new
12/08/2012 12:37:47;0040;PBS_Server;Svr;tyrone-cluster;Scheduler was sent the command new
12/08/2012 12:38:03;0040;PBS_Server;Svr;tyrone-cluster;Scheduler was sent the command new
12/08/2012 12:38:10;0002;PBS_Server;Svr;PBS_Server;Torque Server Version = 3.0.5, loglevel = 0
12/08/2012 12:38:17;0040;PBS_Server;Svr;tyrone-cluster;Scheduler was sent the command new
12/08/2012 12:38:32;0040;PBS_Server;Svr;tyrone-cluster;Scheduler was sent the command new
12/08/2012 12:38:48;0040;PBS_Server;Svr;tyrone-cluster;Scheduler was sent the command new
12/08/2012 12:39:02;0040;PBS_Server;Svr;tyrone-cluster;Scheduler was sent the command new
12/08/2012 12:39:17;0040;PBS_Server;Svr;tyrone-cluster;Scheduler was sent the command new
12/08/2012 12:39:33;0040;PBS_Server;Svr;tyrone-cluster;Scheduler was sent the command new
12/08/2012 12:39:47;0040;PBS_Server;Svr;tyrone-cluster;Scheduler was sent the command new
12/08/2012 12:40:02;0040;PBS_Server;Svr;tyrone-cluster;Scheduler was sent the command new
12/08/2012 12:40:18;0040;PBS_Server;Svr;tyrone-cluster;Scheduler was sent the command new
12/08/2012 12:40:32;0040;PBS_Server;Svr;tyrone-cluster;Scheduler was sent the command new
12/08/2012 12:40:47;0040;PBS_Server;Svr;tyrone-cluster;Scheduler was sent the command new
12/08/2012 12:41:03;0040;PBS_Server;Svr;tyrone-cluster;Scheduler was sent the command new
12/08/2012 12:41:17;0040;PBS_Server;Svr;tyrone-cluster;Scheduler was sent the command new
12/08/2012 12:41:32;0040;PBS_Server;Svr;tyrone-cluster;Scheduler was sent the command new
12/08/2012 12:41:48;0040;PBS_Server;Svr;tyrone-cluster;Scheduler was sent the command new
12/08/2012 12:42:02;0040;PBS_Server;Svr;tyrone-cluster;Scheduler was sent the command new
12/08/2012 12:42:17;0040;PBS_Server;Svr;tyrone-cluster;Scheduler was sent the command new
12/08/2012 12:42:33;0040;PBS_Server;Svr;tyrone-cluster;Scheduler was sent the command new
12/08/2012 12:42:47;0040;PBS_Server;Svr;tyrone-cluster;Scheduler was sent the command new
12/08/2012 12:43:02;0040;PBS_Server;Svr;tyrone-cluster;Scheduler was sent the command new
12/08/2012 12:43:10;0002;PBS_Server;Svr;PBS_Server;Torque Server Version = 3.0.5, loglevel = 0
12/08/2012 12:43:18;0040;PBS_Server;Svr;tyrone-cluster;Scheduler was sent the command new
12/08/2012 12:43:32;0040;PBS_Server;Svr;tyrone-cluster;Scheduler was sent the command new
12/08/2012 12:43:47;0040;PBS_Server;Svr;tyrone-cluster;Scheduler was sent the command new
12/08/2012 12:44:03;0040;PBS_Server;Svr;tyrone-cluster;Scheduler was sent the command new
12/08/2012 12:44:17;0040;PBS_Server;Svr;tyrone-cluster;Scheduler was sent the command new
12/08/2012 12:44:32;0040;PBS_Server;Svr;tyrone-cluster;Scheduler was sent the command new
12/08/2012 12:44:48;0040;PBS_Server;Svr;tyrone-cluster;Scheduler was sent the command new
12/08/2012 12:45:02;0040;PBS_Server;Svr;tyrone-cluster;Scheduler was sent the command new
12/08/2012 12:45:17;0040;PBS_Server;Svr;tyrone-cluster;Scheduler was sent the command new
12/08/2012 12:45:33;0040;PBS_Server;Svr;tyrone-cluster;Scheduler was sent the command new
12/08/2012 12:45:47;0040;PBS_Server;Svr;tyrone-cluster;Scheduler was sent the command new
12/08/2012 12:46:02;0040;PBS_Server;Svr;tyrone-cluster;Scheduler was sent the command new
12/08/2012 12:46:18;0040;PBS_Server;Svr;tyrone-cluster;Scheduler was sent the command new
12/08/2012 12:46:32;0040;PBS_Server;Svr;tyrone-cluster;Scheduler was sent the command new
12/08/2012 12:46:47;0040;PBS_Server;Svr;tyrone-cluster;Scheduler was sent the command new
12/08/2012 12:47:03;0040;PBS_Server;Svr;tyrone-cluster;Scheduler was sent the command new
12/08/2012 12:47:17;0040;PBS_Server;Svr;tyrone-cluster;Scheduler was sent the command new
12/08/2012 12:47:32;0040;PBS_Server;Svr;tyrone-cluster;Scheduler was sent the command new
12/08/2012 12:47:48;0040;PBS_Server;Svr;tyrone-cluster;Scheduler was sent the command new
12/08/2012 12:48:02;0040;PBS_Server;Svr;tyrone-cluster;Scheduler was sent the command new
12/08/2012 12:48:10;0002;PBS_Server;Svr;PBS_Server;Torque Server Version = 3.0.5, loglevel = 0
12/08/2012 12:48:17;0040;PBS_Server;Svr;tyrone-cluster;Scheduler was sent the command new
12/08/2012 12:48:33;0040;PBS_Server;Svr;tyrone-cluster;Scheduler was sent the command new
12/08/2012 12:48:47;0040;PBS_Server;Svr;tyrone-cluster;Scheduler was sent the command new
12/08/2012 12:49:02;0040;PBS_Server;Svr;tyrone-cluster;Scheduler was sent the command new
12/08/2012 12:49:18;0040;PBS_Server;Svr;tyrone-cluster;Scheduler was sent the command new
12/08/2012 12:49:32;0040;PBS_Server;Svr;tyrone-cluster;Scheduler was sent the command new
12/08/2012 12:49:47;0040;PBS_Server;Svr;tyrone-cluster;Scheduler was sent the command new
12/08/2012 12:50:03;0040;PBS_Server;Svr;tyrone-cluster;Scheduler was sent the command new
12/08/2012 12:50:17;0040;PBS_Server;Svr;tyrone-cluster;Scheduler was sent the command new
12/08/2012 12:50:32;0040;PBS_Server;Svr;tyrone-cluster;Scheduler was sent the command new
12/08/2012 12:50:48;0040;PBS_Server;Svr;tyrone-cluster;Scheduler was sent the command new
12/08/2012 12:51:02;0040;PBS_Server;Svr;tyrone-cluster;Scheduler was sent the command new
12/08/2012 12:51:17;0040;PBS_Server;Svr;tyrone-cluster;Scheduler was sent the command new
12/08/2012 12:51:33;0040;PBS_Server;Svr;tyrone-cluster;Scheduler was sent the command new
12/08/2012 12:51:47;0040;PBS_Server;Svr;tyrone-cluster;Scheduler was sent the command new
12/08/2012 12:52:02;0040;PBS_Server;Svr;tyrone-cluster;Scheduler was sent the command new
12/08/2012 12:52:18;0040;PBS_Server;Svr;tyrone-cluster;Scheduler was sent the command new
12/08/2012 12:52:32;0040;PBS_Server;Svr;tyrone-cluster;Scheduler was sent the command new
12/08/2012 12:52:47;0040;PBS_Server;Svr;tyrone-cluster;Scheduler was sent the command new
12/08/2012 12:53:03;0040;PBS_Server;Svr;tyrone-cluster;Scheduler was sent the command new
12/08/2012 12:53:10;0002;PBS_Server;Svr;PBS_Server;Torque Server Version = 3.0.5, loglevel = 0
12/08/2012 12:53:17;0040;PBS_Server;Svr;tyrone-cluster;Scheduler was sent the command new
12/08/2012 12:53:32;0040;PBS_Server;Svr;tyrone-cluster;Scheduler was sent the command new
12/08/2012 12:53:48;0040;PBS_Server;Svr;tyrone-cluster;Scheduler was sent the command new
12/08/2012 12:54:02;0040;PBS_Server;Svr;tyrone-cluster;Scheduler was sent the command new
12/08/2012 12:54:17;0040;PBS_Server;Svr;tyrone-cluster;Scheduler was sent the command new
12/08/2012 12:54:33;0040;PBS_Server;Svr;tyrone-cluster;Scheduler was sent the command new
12/08/2012 12:54:47;0040;PBS_Server;Svr;tyrone-cluster;Scheduler was sent the command new
12/08/2012 12:55:02;0040;PBS_Server;Svr;tyrone-cluster;Scheduler was sent the command new
12/08/2012 12:55:18;0040;PBS_Server;Svr;tyrone-cluster;Scheduler was sent the command new
12/08/2012 12:55:32;0040;PBS_Server;Svr;tyrone-cluster;Scheduler was sent the command new
12/08/2012 12:55:47;0040;PBS_Server;Svr;tyrone-cluster;Scheduler was sent the command new
12/08/2012 12:56:03;0040;PBS_Server;Svr;tyrone-cluster;Scheduler was sent the command new
12/08/2012 12:56:17;0040;PBS_Server;Svr;tyrone-cluster;Scheduler was sent the command new
12/08/2012 12:56:32;0040;PBS_Server;Svr;tyrone-cluster;Scheduler was sent the command new
12/08/2012 12:56:48;0040;PBS_Server;Svr;tyrone-cluster;Scheduler was sent the command new
12/08/2012 12:57:02;0040;PBS_Server;Svr;tyrone-cluster;Scheduler was sent the command new
12/08/2012 12:57:17;0040;PBS_Server;Svr;tyrone-cluster;Scheduler was sent the command new
12/08/2012 12:57:33;0040;PBS_Server;Svr;tyrone-cluster;Scheduler was sent the command new
12/08/2012 12:57:47;0040;PBS_Server;Svr;tyrone-cluster;Scheduler was sent the command new
12/08/2012 12:58:02;0040;PBS_Server;Svr;tyrone-cluster;Scheduler was sent the command new
12/08/2012 12:58:10;0002;PBS_Server;Svr;PBS_Server;Torque Server Version = 3.0.5, loglevel = 0
12/08/2012 12:58:18;0040;PBS_Server;Svr;tyrone-cluster;Scheduler was sent the command new
12/08/2012 12:58:32;0040;PBS_Server;Svr;tyrone-cluster;Scheduler was sent the command new
12/08/2012 12:58:47;0040;PBS_Server;Svr;tyrone-cluster;Scheduler was sent the command new
12/08/2012 12:59:03;0040;PBS_Server;Svr;tyrone-cluster;Scheduler was sent the command new
12/08/2012 12:59:17;0040;PBS_Server;Svr;tyrone-cluster;Scheduler was sent the command new
12/08/2012 12:59:32;0040;PBS_Server;Svr;tyrone-cluster;Scheduler was sent the command new
12/08/2012 12:59:48;0040;PBS_Server;Svr;tyrone-cluster;Scheduler was sent the command new
12/08/2012 13:00:02;0040;PBS_Server;Svr;tyrone-cluster;Scheduler was sent the command new
12/08/2012 13:00:17;0040;PBS_Server;Svr;tyrone-cluster;Scheduler was sent the command new
12/08/2012 13:00:33;0040;PBS_Server;Svr;tyrone-cluster;Scheduler was sent the command new
12/08/2012 13:00:47;0040;PBS_Server;Svr;tyrone-cluster;Scheduler was sent the command new
12/08/2012 13:01:02;0040;PBS_Server;Svr;tyrone-cluster;Scheduler was sent the command new
12/08/2012 13:01:18;0040;PBS_Server;Svr;tyrone-cluster;Scheduler was sent the command new
12/08/2012 13:01:32;0040;PBS_Server;Svr;tyrone-cluster;Scheduler was sent the command new
12/08/2012 13:01:47;0040;PBS_Server;Svr;tyrone-cluster;Scheduler was sent the command new
12/08/2012 13:02:03;0040;PBS_Server;Svr;tyrone-cluster;Scheduler was sent the command new
12/08/2012 13:02:17;0040;PBS_Server;Svr;tyrone-cluster;Scheduler was sent the command new
12/08/2012 13:02:32;0040;PBS_Server;Svr;tyrone-cluster;Scheduler was sent the command new
12/08/2012 13:02:48;0040;PBS_Server;Svr;tyrone-cluster;Scheduler was sent the command new
12/08/2012 13:03:02;0040;PBS_Server;Svr;tyrone-cluster;Scheduler was sent the command new
12/08/2012 13:03:10;0002;PBS_Server;Svr;PBS_Server;Torque Server Version = 3.0.5, loglevel = 0
12/08/2012 13:03:17;0040;PBS_Server;Svr;tyrone-cluster;Scheduler was sent the command new
12/08/2012 13:03:33;0040;PBS_Server;Svr;tyrone-cluster;Scheduler was sent the command new
12/08/2012 13:03:47;0040;PBS_Server;Svr;tyrone-cluster;Scheduler was sent the command new
12/08/2012 13:04:02;0040;PBS_Server;Svr;tyrone-cluster;Scheduler was sent the command new
12/08/2012 13:04:18;0040;PBS_Server;Svr;tyrone-cluster;Scheduler was sent the command new
12/08/2012 13:04:32;0040;PBS_Server;Svr;tyrone-cluster;Scheduler was sent the command new
12/08/2012 13:04:47;0040;PBS_Server;Svr;tyrone-cluster;Scheduler was sent the command new
12/08/2012 13:05:03;0040;PBS_Server;Svr;tyrone-cluster;Scheduler was sent the command new
12/08/2012 13:05:17;0040;PBS_Server;Svr;tyrone-cluster;Scheduler was sent the command new
12/08/2012 13:05:32;0040;PBS_Server;Svr;tyrone-cluster;Scheduler was sent the command new
12/08/2012 13:05:48;0040;PBS_Server;Svr;tyrone-cluster;Scheduler was sent the command new
12/08/2012 13:06:02;0040;PBS_Server;Svr;tyrone-cluster;Scheduler was sent the command new
12/08/2012 13:06:17;0040;PBS_Server;Svr;tyrone-cluster;Scheduler was sent the command new
12/08/2012 13:06:33;0040;PBS_Server;Svr;tyrone-cluster;Scheduler was sent the command new
12/08/2012 13:06:47;0040;PBS_Server;Svr;tyrone-cluster;Scheduler was sent the command new
12/08/2012 13:07:02;0040;PBS_Server;Svr;tyrone-cluster;Scheduler was sent the command new
12/08/2012 13:07:18;0040;PBS_Server;Svr;tyrone-cluster;Scheduler was sent the command new
12/08/2012 13:07:32;0040;PBS_Server;Svr;tyrone-cluster;Scheduler was sent the command new
12/08/2012 13:07:47;0040;PBS_Server;Svr;tyrone-cluster;Scheduler was sent the command new
12/08/2012 13:08:03;0040;PBS_Server;Svr;tyrone-cluster;Scheduler was sent the command new
12/08/2012 13:08:10;0002;PBS_Server;Svr;PBS_Server;Torque Server Version = 3.0.5, loglevel = 0
12/08/2012 13:08:17;0040;PBS_Server;Svr;tyrone-cluster;Scheduler was sent the command new
12/08/2012 13:08:32;0040;PBS_Server;Svr;tyrone-cluster;Scheduler was sent the command new
12/08/2012 13:08:48;0040;PBS_Server;Svr;tyrone-cluster;Scheduler was sent the command new
12/08/2012 13:09:02;0040;PBS_Server;Svr;tyrone-cluster;Scheduler was sent the command new
12/08/2012 13:09:10;000d;PBS_Server;Job;16759.tyrone-cluster;Not sending email: User does not want mail of this type.
12/08/2012 13:09:10;0010;PBS_Server;Job;16759.tyrone-cluster;Exit_status=143 resources_used.cput=64:16:49 resources_used.mem=9478172kb resources_used.vmem=19330740kb resources_used.walltime=02:00:41
12/08/2012 13:09:10;0008;PBS_Server;Job;NULL;on_job_exit valid pjob: 0x1c2eb20 (substate=50)
12/08/2012 13:09:10;0008;PBS_Server;Job;NULL;on_job_exit valid pjob: 0x1c2eb20 (substate=51)
12/08/2012 13:09:10;0008;PBS_Server;Job;NULL;on_job_exit valid pjob: 0x1c2eb20 (substate=51)
12/08/2012 13:09:10;0008;PBS_Server;Job;NULL;on_job_exit valid pjob: 0x1c2eb20 (substate=53)
12/08/2012 13:09:10;0100;PBS_Server;Job;16759.tyrone-cluster;dequeuing from idqueue, state COMPLETE
12/08/2012 13:09:10;0040;PBS_Server;Svr;tyrone-cluster;Scheduler was sent the command term
12/08/2012 13:09:17;0040;PBS_Server;Svr;tyrone-cluster;Scheduler was sent the command new
12/08/2012 13:09:33;0040;PBS_Server;Svr;tyrone-cluster;Scheduler was sent the command new
12/08/2012 13:09:47;0040;PBS_Server;Svr;tyrone-cluster;Scheduler was sent the command new
12/08/2012 13:10:02;0040;PBS_Server;Svr;tyrone-cluster;Scheduler was sent the command new
12/08/2012 13:10:18;0040;PBS_Server;Svr;tyrone-cluster;Scheduler was sent the command new
12/08/2012 13:10:32;0040;PBS_Server;Svr;tyrone-cluster;Scheduler was sent the command new
12/08/2012 13:10:47;0040;PBS_Server;Svr;tyrone-cluster;Scheduler was sent the command new
12/08/2012 13:11:03;0040;PBS_Server;Svr;tyrone-cluster;Scheduler was sent the command new
12/08/2012 13:11:17;0040;PBS_Server;Svr;tyrone-cluster;Scheduler was sent the command new
12/08/2012 13:11:32;0040;PBS_Server;Svr;tyrone-cluster;Scheduler was sent the command new
12/08/2012 13:11:48;0040;PBS_Server;Svr;tyrone-cluster;Scheduler was sent the command new
12/08/2012 13:12:02;0040;PBS_Server;Svr;tyrone-cluster;Scheduler was sent the command new
12/08/2012 13:12:17;0040;PBS_Server;Svr;tyrone-cluster;Scheduler was sent the command new
12/08/2012 13:12:33;0040;PBS_Server;Svr;tyrone-cluster;Scheduler was sent the command new
12/08/2012 13:12:47;0040;PBS_Server;Svr;tyrone-cluster;Scheduler was sent the command new
12/08/2012 13:13:02;0040;PBS_Server;Svr;tyrone-cluster;Scheduler was sent the command new
12/08/2012 13:13:10;0002;PBS_Server;Svr;PBS_Server;Torque Server Version = 3.0.5, loglevel = 0
12/08/2012 13:13:18;0040;PBS_Server;Svr;tyrone-cluster;Scheduler was sent the command new
12/08/2012 13:13:32;0040;PBS_Server;Svr;tyrone-cluster;Scheduler was sent the command new
12/08/2012 13:13:47;0040;PBS_Server;Svr;tyrone-cluster;Scheduler was sent the command new
12/08/2012 13:14:03;0040;PBS_Server;Svr;tyrone-cluster;Scheduler was sent the command new
12/08/2012 13:14:17;0040;PBS_Server;Svr;tyrone-cluster;Scheduler was sent the command new
12/08/2012 13:14:32;0040;PBS_Server;Svr;tyrone-cluster;Scheduler was sent the command new
12/08/2012 13:14:48;0040;PBS_Server;Svr;tyrone-cluster;Scheduler was sent the command new
12/08/2012 13:15:02;0040;PBS_Server;Svr;tyrone-cluster;Scheduler was sent the command new
12/08/2012 13:15:17;0040;PBS_Server;Svr;tyrone-cluster;Scheduler was sent the command new
12/08/2012 13:15:33;0040;PBS_Server;Svr;tyrone-cluster;Scheduler was sent the command new
12/08/2012 13:15:47;0040;PBS_Server;Svr;tyrone-cluster;Scheduler was sent the command new
12/08/2012 13:16:02;0040;PBS_Server;Svr;tyrone-cluster;Scheduler was sent the command new
12/08/2012 13:16:18;0040;PBS_Server;Svr;tyrone-cluster;Scheduler was sent the command new
12/08/2012 13:16:32;0040;PBS_Server;Svr;tyrone-cluster;Scheduler was sent the command new
12/08/2012 13:16:47;0040;PBS_Server;Svr;tyrone-cluster;Scheduler was sent the command new
12/08/2012 13:17:03;0040;PBS_Server;Svr;tyrone-cluster;Scheduler was sent the command new
12/08/2012 13:17:17;0040;PBS_Server;Svr;tyrone-cluster;Scheduler was sent the command new
12/08/2012 13:17:32;0040;PBS_Server;Svr;tyrone-cluster;Scheduler was sent the command new
12/08/2012 13:17:48;0040;PBS_Server;Svr;tyrone-cluster;Scheduler was sent the command new
12/08/2012 13:18:02;0040;PBS_Server;Svr;tyrone-cluster;Scheduler was sent the command new
12/08/2012 13:18:10;0002;PBS_Server;Svr;PBS_Server;Torque Server Version = 3.0.5, loglevel = 0
12/08/2012 13:18:17;0040;PBS_Server;Svr;tyrone-cluster;Scheduler was sent the command new
12/08/2012 13:18:33;0040;PBS_Server;Svr;tyrone-cluster;Scheduler was sent the command new
12/08/2012 13:18:47;0040;PBS_Server;Svr;tyrone-cluster;Scheduler was sent the command new
12/08/2012 13:19:02;0040;PBS_Server;Svr;tyrone-cluster;Scheduler was sent the command new
12/08/2012 13:19:18;0040;PBS_Server;Svr;tyrone-cluster;Scheduler was sent the command new
12/08/2012 13:19:32;0040;PBS_Server;Svr;tyrone-cluster;Scheduler was sent the command new
12/08/2012 13:19:47;0040;PBS_Server;Svr;tyrone-cluster;Scheduler was sent the command new
12/08/2012 13:20:03;0040;PBS_Server;Svr;tyrone-cluster;Scheduler was sent the command new
12/08/2012 13:20:17;0040;PBS_Server;Svr;tyrone-cluster;Scheduler was sent the command new
12/08/2012 13:20:32;0040;PBS_Server;Svr;tyrone-cluster;Scheduler was sent the command new
12/08/2012 13:20:48;0040;PBS_Server;Svr;tyrone-cluster;Scheduler was sent the command new
12/08/2012 13:21:02;0040;PBS_Server;Svr;tyrone-cluster;Scheduler was sent the command new
12/08/2012 13:21:17;0040;PBS_Server;Svr;tyrone-cluster;Scheduler was sent the command new
12/08/2012 13:21:33;0040;PBS_Server;Svr;tyrone-cluster;Scheduler was sent the command new
12/08/2012 13:21:48;0040;PBS_Server;Svr;tyrone-cluster;Scheduler was sent the command new
12/08/2012 13:22:02;0040;PBS_Server;Svr;tyrone-cluster;Scheduler was sent the command new
12/08/2012 13:22:23;0040;PBS_Server;Svr;tyrone-cluster;Scheduler was sent the command new
12/08/2012 13:22:32;0040;PBS_Server;Svr;tyrone-cluster;Scheduler was sent the command new
12/08/2012 13:22:49;0040;PBS_Server;Svr;tyrone-cluster;Scheduler was sent the command new
12/08/2012 13:23:03;0040;PBS_Server;Svr;tyrone-cluster;Scheduler was sent the command new
12/08/2012 13:23:10;0002;PBS_Server;Svr;PBS_Server;Torque Server Version = 3.0.5, loglevel = 0
12/08/2012 13:23:20;0040;PBS_Server;Svr;tyrone-cluster;Scheduler was sent the command new
12/08/2012 13:23:32;0040;PBS_Server;Svr;tyrone-cluster;Scheduler was sent the command new
12/08/2012 13:23:56;0040;PBS_Server;Svr;tyrone-cluster;Scheduler was sent the command new
12/08/2012 13:24:02;0040;PBS_Server;Svr;tyrone-cluster;Scheduler was sent the command new
12/08/2012 13:24:28;0040;PBS_Server;Svr;tyrone-cluster;Scheduler was sent the command new
12/08/2012 13:24:33;0040;PBS_Server;Svr;tyrone-cluster;Scheduler was sent the command new
12/08/2012 13:24:54;0040;PBS_Server;Svr;tyrone-cluster;Scheduler was sent the command new
12/08/2012 13:25:02;0040;PBS_Server;Svr;tyrone-cluster;Scheduler was sent the command new
12/08/2012 13:25:27;0040;PBS_Server;Svr;tyrone-cluster;Scheduler was sent the command new
12/08/2012 13:25:32;0040;PBS_Server;Svr;tyrone-cluster;Scheduler was sent the command new
12/08/2012 13:25:58;0040;PBS_Server;Svr;tyrone-cluster;Scheduler was sent the command new
12/08/2012 13:26:03;0040;PBS_Server;Svr;tyrone-cluster;Scheduler was sent the command new
12/08/2012 13:26:26;0040;PBS_Server;Svr;tyrone-cluster;Scheduler was sent the command new
12/08/2012 13:26:32;0040;PBS_Server;Svr;tyrone-cluster;Scheduler was sent the command new
12/08/2012 13:26:56;0040;PBS_Server;Svr;tyrone-cluster;Scheduler was sent the command new
12/08/2012 13:27:02;0040;PBS_Server;Svr;tyrone-cluster;Scheduler was sent the command new
12/08/2012 13:27:28;0040;PBS_Server;Svr;tyrone-cluster;Scheduler was sent the command new
12/08/2012 13:27:33;0040;PBS_Server;Svr;tyrone-cluster;Scheduler was sent the command new
12/08/2012 13:27:58;0040;PBS_Server;Svr;tyrone-cluster;Scheduler was sent the command new
12/08/2012 13:28:02;0040;PBS_Server;Svr;tyrone-cluster;Scheduler was sent the command new
12/08/2012 13:28:10;0002;PBS_Server;Svr;PBS_Server;Torque Server Version = 3.0.5, loglevel = 0
12/08/2012 13:28:29;0040;PBS_Server;Svr;tyrone-cluster;Scheduler was sent the command new
12/08/2012 13:28:32;0040;PBS_Server;Svr;tyrone-cluster;Scheduler was sent the command new
12/08/2012 13:28:58;0040;PBS_Server;Svr;tyrone-cluster;Scheduler was sent the command new
12/08/2012 13:29:03;0040;PBS_Server;Svr;tyrone-cluster;Scheduler was sent the command new
12/08/2012 13:29:28;0040;PBS_Server;Svr;tyrone-cluster;Scheduler was sent the command new
12/08/2012 13:29:32;0040;PBS_Server;Svr;tyrone-cluster;Scheduler was sent the command new
12/08/2012 13:29:59;0040;PBS_Server;Svr;tyrone-cluster;Scheduler was sent the command new
12/08/2012 13:30:02;0040;PBS_Server;Svr;tyrone-cluster;Scheduler was sent the command new
12/08/2012 13:30:28;0040;PBS_Server;Svr;tyrone-cluster;Scheduler was sent the command new
12/08/2012 13:30:33;0040;PBS_Server;Svr;tyrone-cluster;Scheduler was sent the command new
12/08/2012 13:30:58;0040;PBS_Server;Svr;tyrone-cluster;Scheduler was sent the command new
12/08/2012 13:31:02;0040;PBS_Server;Svr;tyrone-cluster;Scheduler was sent the command new
12/08/2012 13:31:29;0040;PBS_Server;Svr;tyrone-cluster;Scheduler was sent the command new
12/08/2012 13:31:34;000d;PBS_Server;Job;16698.tyrone-cluster;Not sending email: User does not want mail of this type.
12/08/2012 13:31:34;0010;PBS_Server;Job;16698.tyrone-cluster;Exit_status=143 resources_used.cput=733:48:31 resources_used.mem=2010356kb resources_used.vmem=8200540kb resources_used.walltime=24:00:28
12/08/2012 13:31:34;0008;PBS_Server;Job;NULL;on_job_exit valid pjob: 0x1c93ab0 (substate=50)
12/08/2012 13:31:34;0008;PBS_Server;Job;NULL;on_job_exit valid pjob: 0x1c93ab0 (substate=51)
12/08/2012 13:31:34;0008;PBS_Server;Job;NULL;on_job_exit valid pjob: 0x1c93ab0 (substate=51)
12/08/2012 13:31:34;0008;PBS_Server;Job;NULL;on_job_exit valid pjob: 0x1c93ab0 (substate=53)
12/08/2012 13:31:34;0100;PBS_Server;Job;16698.tyrone-cluster;dequeuing from qp32, state COMPLETE
12/08/2012 13:31:34;0040;PBS_Server;Svr;tyrone-cluster;Scheduler was sent the command term
12/08/2012 13:31:34;0008;PBS_Server;Job;16700.tyrone-cluster;Job Modified at request of Scheduler@tyrone-cluster
12/08/2012 13:31:34;0008;PBS_Server;Job;16700.tyrone-cluster;Job Run at request of Scheduler@tyrone-cluster
12/08/2012 13:31:34;0040;PBS_Server;Svr;tyrone-cluster;Scheduler was sent the command recyc
12/08/2012 13:31:34;000d;PBS_Server;Job;16700.tyrone-cluster;Not sending email: User does not want mail of this type.
12/08/2012 13:31:58;0040;PBS_Server;Svr;tyrone-cluster;Scheduler was sent the command new
12/08/2012 13:32:03;0040;PBS_Server;Svr;tyrone-cluster;Scheduler was sent the command new
12/08/2012 13:32:28;0040;PBS_Server;Svr;tyrone-cluster;Scheduler was sent the command new
12/08/2012 13:32:32;0040;PBS_Server;Svr;tyrone-cluster;Scheduler was sent the command new
12/08/2012 13:32:59;0040;PBS_Server;Svr;tyrone-cluster;Scheduler was sent the command new
12/08/2012 13:33:02;0040;PBS_Server;Svr;tyrone-cluster;Scheduler was sent the command new
12/08/2012 13:33:10;0002;PBS_Server;Svr;PBS_Server;Torque Server Version = 3.0.5, loglevel = 0
12/08/2012 13:33:28;0040;PBS_Server;Svr;tyrone-cluster;Scheduler was sent the command new
12/08/2012 13:33:33;0040;PBS_Server;Svr;tyrone-cluster;Scheduler was sent the command new
12/08/2012 13:33:58;0040;PBS_Server;Svr;tyrone-cluster;Scheduler was sent the command new
12/08/2012 13:34:02;0040;PBS_Server;Svr;tyrone-cluster;Scheduler was sent the command new
12/08/2012 13:34:29;0040;PBS_Server;Svr;tyrone-cluster;Scheduler was sent the command new
12/08/2012 13:34:32;0040;PBS_Server;Svr;tyrone-cluster;Scheduler was sent the command new
12/08/2012 13:34:58;0040;PBS_Server;Svr;tyrone-cluster;Scheduler was sent the command new
12/08/2012 13:35:03;0040;PBS_Server;Svr;tyrone-cluster;Scheduler was sent the command new
12/08/2012 13:35:28;0040;PBS_Server;Svr;tyrone-cluster;Scheduler was sent the command new
12/08/2012 13:35:32;0040;PBS_Server;Svr;tyrone-cluster;Scheduler was sent the command new
12/08/2012 13:35:59;0040;PBS_Server;Svr;tyrone-cluster;Scheduler was sent the command new
12/08/2012 13:36:02;0040;PBS_Server;Svr;tyrone-cluster;Scheduler was sent the command new
12/08/2012 13:36:28;0040;PBS_Server;Svr;tyrone-cluster;Scheduler was sent the command new
12/08/2012 13:36:33;0040;PBS_Server;Svr;tyrone-cluster;Scheduler was sent the command new
12/08/2012 13:36:58;0040;PBS_Server;Svr;tyrone-cluster;Scheduler was sent the command new
12/08/2012 13:37:02;0040;PBS_Server;Svr;tyrone-cluster;Scheduler was sent the command new
12/08/2012 13:37:29;0040;PBS_Server;Svr;tyrone-cluster;Scheduler was sent the command new
12/08/2012 13:37:32;0040;PBS_Server;Svr;tyrone-cluster;Scheduler was sent the command new
12/08/2012 13:37:58;0040;PBS_Server;Svr;tyrone-cluster;Scheduler was sent the command new
12/08/2012 13:38:03;0040;PBS_Server;Svr;tyrone-cluster;Scheduler was sent the command new
12/08/2012 13:38:10;0002;PBS_Server;Svr;PBS_Server;Torque Server Version = 3.0.5, loglevel = 0
12/08/2012 13:38:28;0040;PBS_Server;Svr;tyrone-cluster;Scheduler was sent the command new
12/08/2012 13:38:32;0040;PBS_Server;Svr;tyrone-cluster;Scheduler was sent the command new
12/08/2012 13:38:59;0040;PBS_Server;Svr;tyrone-cluster;Scheduler was sent the command new
12/08/2012 13:39:02;0040;PBS_Server;Svr;tyrone-cluster;Scheduler was sent the command new
12/08/2012 13:39:28;0040;PBS_Server;Svr;tyrone-cluster;Scheduler was sent the command new
12/08/2012 13:39:33;0040;PBS_Server;Svr;tyrone-cluster;Scheduler was sent the command new
12/08/2012 13:39:58;0040;PBS_Server;Svr;tyrone-cluster;Scheduler was sent the command new
12/08/2012 13:40:02;0040;PBS_Server;Svr;tyrone-cluster;Scheduler was sent the command new
12/08/2012 13:40:29;0040;PBS_Server;Svr;tyrone-cluster;Scheduler was sent the command new
12/08/2012 13:40:32;0040;PBS_Server;Svr;tyrone-cluster;Scheduler was sent the command new
12/08/2012 13:40:58;0040;PBS_Server;Svr;tyrone-cluster;Scheduler was sent the command new
12/08/2012 13:41:03;0040;PBS_Server;Svr;tyrone-cluster;Scheduler was sent the command new
12/08/2012 13:41:28;0040;PBS_Server;Svr;tyrone-cluster;Scheduler was sent the command new
12/08/2012 13:41:32;0040;PBS_Server;Svr;tyrone-cluster;Scheduler was sent the command new
12/08/2012 13:41:59;0040;PBS_Server;Svr;tyrone-cluster;Scheduler was sent the command new
12/08/2012 13:42:02;0040;PBS_Server;Svr;tyrone-cluster;Scheduler was sent the command new
12/08/2012 13:42:28;0040;PBS_Server;Svr;tyrone-cluster;Scheduler was sent the command new
12/08/2012 13:42:33;0040;PBS_Server;Svr;tyrone-cluster;Scheduler was sent the command new
12/08/2012 13:42:58;0040;PBS_Server;Svr;tyrone-cluster;Scheduler was sent the command new
12/08/2012 13:43:02;0040;PBS_Server;Svr;tyrone-cluster;Scheduler was sent the command new
12/08/2012 13:43:10;0002;PBS_Server;Svr;PBS_Server;Torque Server Version = 3.0.5, loglevel = 0
12/08/2012 13:43:29;0040;PBS_Server;Svr;tyrone-cluster;Scheduler was sent the command new
12/08/2012 13:43:32;0040;PBS_Server;Svr;tyrone-cluster;Scheduler was sent the command new
12/08/2012 13:43:58;0040;PBS_Server;Svr;tyrone-cluster;Scheduler was sent the command new
12/08/2012 13:44:03;0040;PBS_Server;Svr;tyrone-cluster;Scheduler was sent the command new
12/08/2012 13:44:28;0040;PBS_Server;Svr;tyrone-cluster;Scheduler was sent the command new
12/08/2012 13:44:32;0040;PBS_Server;Svr;tyrone-cluster;Scheduler was sent the command new
12/08/2012 13:44:59;0040;PBS_Server;Svr;tyrone-cluster;Scheduler was sent the command new
12/08/2012 13:45:02;0040;PBS_Server;Svr;tyrone-cluster;Scheduler was sent the command new
12/08/2012 13:45:28;0040;PBS_Server;Svr;tyrone-cluster;Scheduler was sent the command new
12/08/2012 13:45:33;0040;PBS_Server;Svr;tyrone-cluster;Scheduler was sent the command new
12/08/2012 13:45:58;0040;PBS_Server;Svr;tyrone-cluster;Scheduler was sent the command new
12/08/2012 13:46:02;0040;PBS_Server;Svr;tyrone-cluster;Scheduler was sent the command new
12/08/2012 13:46:29;0040;PBS_Server;Svr;tyrone-cluster;Scheduler was sent the command new
12/08/2012 13:46:32;0040;PBS_Server;Svr;tyrone-cluster;Scheduler was sent the command new
12/08/2012 13:46:58;0040;PBS_Server;Svr;tyrone-cluster;Scheduler was sent the command new
12/08/2012 13:47:03;0040;PBS_Server;Svr;tyrone-cluster;Scheduler was sent the command new
12/08/2012 13:47:28;0040;PBS_Server;Svr;tyrone-cluster;Scheduler was sent the command new
12/08/2012 13:47:32;0040;PBS_Server;Svr;tyrone-cluster;Scheduler was sent the command new
12/08/2012 13:47:59;0040;PBS_Server;Svr;tyrone-cluster;Scheduler was sent the command new
12/08/2012 13:48:02;0040;PBS_Server;Svr;tyrone-cluster;Scheduler was sent the command new
12/08/2012 13:48:10;0002;PBS_Server;Svr;PBS_Server;Torque Server Version = 3.0.5, loglevel = 0
12/08/2012 13:48:28;0040;PBS_Server;Svr;tyrone-cluster;Scheduler was sent the command new
12/08/2012 13:48:33;0040;PBS_Server;Svr;tyrone-cluster;Scheduler was sent the command new
12/08/2012 13:48:58;0040;PBS_Server;Svr;tyrone-cluster;Scheduler was sent the command new
12/08/2012 13:49:02;0040;PBS_Server;Svr;tyrone-cluster;Scheduler was sent the command new
12/08/2012 13:49:29;0040;PBS_Server;Svr;tyrone-cluster;Scheduler was sent the command new
12/08/2012 13:49:32;0040;PBS_Server;Svr;tyrone-cluster;Scheduler was sent the command new
12/08/2012 13:49:58;0040;PBS_Server;Svr;tyrone-cluster;Scheduler was sent the command new
12/08/2012 13:50:03;0040;PBS_Server;Svr;tyrone-cluster;Scheduler was sent the command new
12/08/2012 13:50:28;0040;PBS_Server;Svr;tyrone-cluster;Scheduler was sent the command new
12/08/2012 13:50:32;0040;PBS_Server;Svr;tyrone-cluster;Scheduler was sent the command new
12/08/2012 13:50:59;0040;PBS_Server;Svr;tyrone-cluster;Scheduler was sent the command new
12/08/2012 13:51:02;0040;PBS_Server;Svr;tyrone-cluster;Scheduler was sent the command new
12/08/2012 13:51:29;0040;PBS_Server;Svr;tyrone-cluster;Scheduler was sent the command new
12/08/2012 13:51:33;0040;PBS_Server;Svr;tyrone-cluster;Scheduler was sent the command new
12/08/2012 13:52:00;0040;PBS_Server;Svr;tyrone-cluster;Scheduler was sent the command new
12/08/2012 13:52:02;0040;PBS_Server;Svr;tyrone-cluster;Scheduler was sent the command new
12/08/2012 13:52:32;0040;PBS_Server;Svr;tyrone-cluster;Scheduler was sent the command new
12/08/2012 13:53:03;0040;PBS_Server;Svr;tyrone-cluster;Scheduler was sent the command new
12/08/2012 13:53:10;0002;PBS_Server;Svr;PBS_Server;Torque Server Version = 3.0.5, loglevel = 0
12/08/2012 13:53:32;0040;PBS_Server;Svr;tyrone-cluster;Scheduler was sent the command new
12/08/2012 13:54:02;0040;PBS_Server;Svr;tyrone-cluster;Scheduler was sent the command new
12/08/2012 13:54:33;0040;PBS_Server;Svr;tyrone-cluster;Scheduler was sent the command new
12/08/2012 13:55:02;0040;PBS_Server;Svr;tyrone-cluster;Scheduler was sent the command new
12/08/2012 13:55:32;0040;PBS_Server;Svr;tyrone-cluster;Scheduler was sent the command new
12/08/2012 13:56:03;0040;PBS_Server;Svr;tyrone-cluster;Scheduler was sent the command new
12/08/2012 13:56:32;0040;PBS_Server;Svr;tyrone-cluster;Scheduler was sent the command new
12/08/2012 13:57:02;0040;PBS_Server;Svr;tyrone-cluster;Scheduler was sent the command new
12/08/2012 13:57:33;0040;PBS_Server;Svr;tyrone-cluster;Scheduler was sent the command new
12/08/2012 13:58:02;0040;PBS_Server;Svr;tyrone-cluster;Scheduler was sent the command new
12/08/2012 13:58:10;0002;PBS_Server;Svr;PBS_Server;Torque Server Version = 3.0.5, loglevel = 0
12/08/2012 13:58:32;0040;PBS_Server;Svr;tyrone-cluster;Scheduler was sent the command new
12/08/2012 13:59:03;0040;PBS_Server;Svr;tyrone-cluster;Scheduler was sent the command new
12/08/2012 13:59:32;0040;PBS_Server;Svr;tyrone-cluster;Scheduler was sent the command new
12/08/2012 14:00:02;0040;PBS_Server;Svr;tyrone-cluster;Scheduler was sent the command new
12/08/2012 14:00:33;0040;PBS_Server;Svr;tyrone-cluster;Scheduler was sent the command new
12/08/2012 14:01:02;0040;PBS_Server;Svr;tyrone-cluster;Scheduler was sent the command new
12/08/2012 14:01:32;0040;PBS_Server;Svr;tyrone-cluster;Scheduler was sent the command new
12/08/2012 14:02:03;0040;PBS_Server;Svr;tyrone-cluster;Scheduler was sent the command new
12/08/2012 14:02:32;0040;PBS_Server;Svr;tyrone-cluster;Scheduler was sent the command new
12/08/2012 14:03:02;0040;PBS_Server;Svr;tyrone-cluster;Scheduler was sent the command new
12/08/2012 14:03:10;0002;PBS_Server;Svr;PBS_Server;Torque Server Version = 3.0.5, loglevel = 0
12/08/2012 14:03:33;0040;PBS_Server;Svr;tyrone-cluster;Scheduler was sent the command new
12/08/2012 14:04:02;0040;PBS_Server;Svr;tyrone-cluster;Scheduler was sent the command new
12/08/2012 14:04:32;0040;PBS_Server;Svr;tyrone-cluster;Scheduler was sent the command new
12/08/2012 14:05:03;0040;PBS_Server;Svr;tyrone-cluster;Scheduler was sent the command new
12/08/2012 14:05:32;0040;PBS_Server;Svr;tyrone-cluster;Scheduler was sent the command new
12/08/2012 14:06:02;0040;PBS_Server;Svr;tyrone-cluster;Scheduler was sent the command new
12/08/2012 14:06:29;0100;PBS_Server;Job;16761.tyrone-cluster;enqueuing into batch, state 1 hop 1
12/08/2012 14:06:29;0100;PBS_Server;Job;16761.tyrone-cluster;dequeuing from batch, state QUEUED
12/08/2012 14:06:29;0100;PBS_Server;Job;16761.tyrone-cluster;enqueuing into idqueue, state 1 hop 1
12/08/2012 14:06:29;0008;PBS_Server;Job;16761.tyrone-cluster;Job Queued at request of mrcatanu@tyrone-cluster, owner = mrcatanu@tyrone-cluster, job name = TSSDI, queue = idqueue
12/08/2012 14:06:29;0040;PBS_Server;Svr;tyrone-cluster;Scheduler was sent the command new
12/08/2012 14:06:30;0008;PBS_Server;Job;16761.tyrone-cluster;Job Modified at request of Scheduler@tyrone-cluster
12/08/2012 14:06:30;0008;PBS_Server;Job;16761.tyrone-cluster;Job Run at request of Scheduler@tyrone-cluster
12/08/2012 14:06:30;0040;PBS_Server;Svr;tyrone-cluster;Scheduler was sent the command recyc
12/08/2012 14:06:30;000d;PBS_Server;Job;16761.tyrone-cluster;Not sending email: User does not want mail of this type.
12/08/2012 14:06:33;0040;PBS_Server;Svr;tyrone-cluster;Scheduler was sent the command new
12/08/2012 14:07:02;0040;PBS_Server;Svr;tyrone-cluster;Scheduler was sent the command new
12/08/2012 14:07:32;0040;PBS_Server;Svr;tyrone-cluster;Scheduler was sent the command new
12/08/2012 14:08:03;0040;PBS_Server;Svr;tyrone-cluster;Scheduler was sent the command new
12/08/2012 14:08:10;0002;PBS_Server;Svr;PBS_Server;Torque Server Version = 3.0.5, loglevel = 0
12/08/2012 14:08:32;0040;PBS_Server;Svr;tyrone-cluster;Scheduler was sent the command new
12/08/2012 14:09:02;0040;PBS_Server;Svr;tyrone-cluster;Scheduler was sent the command new
12/08/2012 14:09:33;0040;PBS_Server;Svr;tyrone-cluster;Scheduler was sent the command new
12/08/2012 14:10:02;0040;PBS_Server;Svr;tyrone-cluster;Scheduler was sent the command new
12/08/2012 14:10:32;0040;PBS_Server;Svr;tyrone-cluster;Scheduler was sent the command new
12/08/2012 14:11:03;0040;PBS_Server;Svr;tyrone-cluster;Scheduler was sent the command new
12/08/2012 14:11:32;0040;PBS_Server;Svr;tyrone-cluster;Scheduler was sent the command new
12/08/2012 14:12:02;0040;PBS_Server;Svr;tyrone-cluster;Scheduler was sent the command new
12/08/2012 14:12:33;0040;PBS_Server;Svr;tyrone-cluster;Scheduler was sent the command new
12/08/2012 14:13:02;0040;PBS_Server;Svr;tyrone-cluster;Scheduler was sent the command new
12/08/2012 14:13:10;0002;PBS_Server;Svr;PBS_Server;Torque Server Version = 3.0.5, loglevel = 0
12/08/2012 14:13:32;0040;PBS_Server;Svr;tyrone-cluster;Scheduler was sent the command new
12/08/2012 14:14:03;0040;PBS_Server;Svr;tyrone-cluster;Scheduler was sent the command new
12/08/2012 14:14:32;0040;PBS_Server;Svr;tyrone-cluster;Scheduler was sent the command new
12/08/2012 14:15:02;0040;PBS_Server;Svr;tyrone-cluster;Scheduler was sent the command new
12/08/2012 14:15:26;0008;PBS_Server;Job;16761.tyrone-cluster;Job deleted at request of mrcatanu@tyrone-cluster
12/08/2012 14:15:26;0008;PBS_Server;Job;16761.tyrone-cluster;Job sent signal SIGTERM on delete
12/08/2012 14:15:26;000d;PBS_Server;Job;16761.tyrone-cluster;Not sending email: User does not want mail of this type.
12/08/2012 14:15:26;0010;PBS_Server;Job;16761.tyrone-cluster;Exit_status=143 resources_used.cput=04:44:31 resources_used.mem=4606492kb resources_used.vmem=12920828kb resources_used.walltime=00:08:56
12/08/2012 14:15:26;0008;PBS_Server;Job;NULL;on_job_exit valid pjob: 0x1c2eb20 (substate=50)
12/08/2012 14:15:26;0008;PBS_Server;Job;NULL;on_job_exit valid pjob: 0x1c2eb20 (substate=51)
12/08/2012 14:15:26;0008;PBS_Server;Job;NULL;on_job_exit valid pjob: 0x1c2eb20 (substate=51)
12/08/2012 14:15:26;0008;PBS_Server;Job;NULL;on_job_exit valid pjob: 0x1c2eb20 (substate=53)
12/08/2012 14:15:26;0100;PBS_Server;Job;16761.tyrone-cluster;dequeuing from idqueue, state COMPLETE
12/08/2012 14:15:26;0040;PBS_Server;Svr;tyrone-cluster;Scheduler was sent the command term
12/08/2012 14:15:33;0040;PBS_Server;Svr;tyrone-cluster;Scheduler was sent the command new
12/08/2012 14:15:55;0100;PBS_Server;Job;16762.tyrone-cluster;enqueuing into batch, state 1 hop 1
12/08/2012 14:15:55;0100;PBS_Server;Job;16762.tyrone-cluster;dequeuing from batch, state QUEUED
12/08/2012 14:15:55;0100;PBS_Server;Job;16762.tyrone-cluster;enqueuing into idqueue, state 1 hop 1
12/08/2012 14:15:55;0008;PBS_Server;Job;16762.tyrone-cluster;Job Queued at request of mrcatanu@tyrone-cluster, owner = mrcatanu@tyrone-cluster, job name = TSSDI2, queue = idqueue
12/08/2012 14:15:55;0040;PBS_Server;Svr;tyrone-cluster;Scheduler was sent the command new
12/08/2012 14:15:55;0008;PBS_Server;Job;16762.tyrone-cluster;Job Modified at request of Scheduler@tyrone-cluster
12/08/2012 14:15:55;0008;PBS_Server;Job;16762.tyrone-cluster;Job Run at request of Scheduler@tyrone-cluster
12/08/2012 14:15:55;0040;PBS_Server;Svr;tyrone-cluster;Scheduler was sent the command recyc
12/08/2012 14:15:55;000d;PBS_Server;Job;16762.tyrone-cluster;Not sending email: User does not want mail of this type.
12/08/2012 14:16:02;0040;PBS_Server;Svr;tyrone-cluster;Scheduler was sent the command new
12/08/2012 14:16:32;0040;PBS_Server;Svr;tyrone-cluster;Scheduler was sent the command new
12/08/2012 14:17:03;0040;PBS_Server;Svr;tyrone-cluster;Scheduler was sent the command new
12/08/2012 14:17:32;0040;PBS_Server;Svr;tyrone-cluster;Scheduler was sent the command new
12/08/2012 14:18:02;0040;PBS_Server;Svr;tyrone-cluster;Scheduler was sent the command new
12/08/2012 14:18:10;0002;PBS_Server;Svr;PBS_Server;Torque Server Version = 3.0.5, loglevel = 0
12/08/2012 14:18:33;0040;PBS_Server;Svr;tyrone-cluster;Scheduler was sent the command new
12/08/2012 14:19:02;0040;PBS_Server;Svr;tyrone-cluster;Scheduler was sent the command new
12/08/2012 14:19:32;0040;PBS_Server;Svr;tyrone-cluster;Scheduler was sent the command new
12/08/2012 14:20:03;0040;PBS_Server;Svr;tyrone-cluster;Scheduler was sent the command new
12/08/2012 14:20:32;0040;PBS_Server;Svr;tyrone-cluster;Scheduler was sent the command new
12/08/2012 14:21:02;0040;PBS_Server;Svr;tyrone-cluster;Scheduler was sent the command new
12/08/2012 14:21:33;0040;PBS_Server;Svr;tyrone-cluster;Scheduler was sent the command new
12/08/2012 14:22:02;0040;PBS_Server;Svr;tyrone-cluster;Scheduler was sent the command new
12/08/2012 14:22:32;0040;PBS_Server;Svr;tyrone-cluster;Scheduler was sent the command new
12/08/2012 14:23:03;0040;PBS_Server;Svr;tyrone-cluster;Scheduler was sent the command new
12/08/2012 14:23:10;0002;PBS_Server;Svr;PBS_Server;Torque Server Version = 3.0.5, loglevel = 0
12/08/2012 14:23:32;0040;PBS_Server;Svr;tyrone-cluster;Scheduler was sent the command new
12/08/2012 14:24:02;0040;PBS_Server;Svr;tyrone-cluster;Scheduler was sent the command new
12/08/2012 14:24:33;0040;PBS_Server;Svr;tyrone-cluster;Scheduler was sent the command new
12/08/2012 14:25:02;0040;PBS_Server;Svr;tyrone-cluster;Scheduler was sent the command new
12/08/2012 14:25:32;0040;PBS_Server;Svr;tyrone-cluster;Scheduler was sent the command new
12/08/2012 14:26:02;0040;PBS_Server;Svr;tyrone-cluster;Scheduler was sent the command new
12/08/2012 14:26:32;0040;PBS_Server;Svr;tyrone-cluster;Scheduler was sent the command new
12/08/2012 14:26:51;0100;PBS_Server;Job;16763.tyrone-cluster;enqueuing into batch, state 1 hop 1
12/08/2012 14:26:51;0100;PBS_Server;Job;16763.tyrone-cluster;dequeuing from batch, state QUEUED
12/08/2012 14:26:51;0100;PBS_Server;Job;16763.tyrone-cluster;enqueuing into qp32, state 1 hop 1
12/08/2012 14:26:51;0008;PBS_Server;Job;16763.tyrone-cluster;Job Queued at request of ipcvrk@tyrone-cluster, owner = ipcvrk@tyrone-cluster, job name = pq.cmd, queue = qp32
12/08/2012 14:26:51;0040;PBS_Server;Svr;tyrone-cluster;Scheduler was sent the command new
12/08/2012 14:26:51;0008;PBS_Server;Job;16763.tyrone-cluster;Job Modified at request of Scheduler@tyrone-cluster
12/08/2012 14:27:02;0040;PBS_Server;Svr;tyrone-cluster;Scheduler was sent the command new
12/08/2012 14:27:33;0040;PBS_Server;Svr;tyrone-cluster;Scheduler was sent the command new
12/08/2012 14:27:34;0100;PBS_Server;Job;16764.tyrone-cluster;enqueuing into batch, state 1 hop 1
12/08/2012 14:27:34;0008;PBS_Server;Job;16764.tyrone-cluster;Job Queued at request of ipcvrk@tyrone-cluster, owner = ipcvrk@tyrone-cluster, job name = pq1.cmd, queue = batch
12/08/2012 14:27:34;0040;PBS_Server;Svr;tyrone-cluster;Scheduler was sent the command new
12/08/2012 14:27:34;0008;PBS_Server;Job;16764.tyrone-cluster;Job Modified at request of Scheduler@tyrone-cluster
12/08/2012 14:27:52;0100;PBS_Server;Job;16765.tyrone-cluster;enqueuing into batch, state 1 hop 1
12/08/2012 14:27:52;0008;PBS_Server;Job;16765.tyrone-cluster;Job Queued at request of ipcvrk@tyrone-cluster, owner = ipcvrk@tyrone-cluster, job name = pq5.cmd, queue = batch
12/08/2012 14:27:52;0040;PBS_Server;Svr;tyrone-cluster;Scheduler was sent the command new
12/08/2012 14:27:52;0008;PBS_Server;Job;16765.tyrone-cluster;Job Modified at request of Scheduler@tyrone-cluster
12/08/2012 14:28:00;0100;PBS_Server;Job;16766.tyrone-cluster;enqueuing into batch, state 1 hop 1
12/08/2012 14:28:00;0008;PBS_Server;Job;16766.tyrone-cluster;Job Queued at request of ipcvrk@tyrone-cluster, owner = ipcvrk@tyrone-cluster, job name = pq7.cmd, queue = batch
12/08/2012 14:28:00;0040;PBS_Server;Svr;tyrone-cluster;Scheduler was sent the command new
12/08/2012 14:28:00;0008;PBS_Server;Job;16766.tyrone-cluster;Job Modified at request of Scheduler@tyrone-cluster
12/08/2012 14:28:02;0040;PBS_Server;Svr;tyrone-cluster;Scheduler was sent the command new
12/08/2012 14:28:05;0040;PBS_Server;Svr;tyrone-cluster;Scheduler was sent the command new
12/08/2012 14:28:10;0002;PBS_Server;Svr;PBS_Server;Torque Server Version = 3.0.5, loglevel = 0
12/08/2012 14:28:24;0040;PBS_Server;Svr;tyrone-cluster;Scheduler was sent the command new
12/08/2012 14:28:32;0040;PBS_Server;Svr;tyrone-cluster;Scheduler was sent the command new
12/08/2012 14:28:34;0040;PBS_Server;Svr;tyrone-cluster;Scheduler was sent the command new
12/08/2012 14:28:58;0040;PBS_Server;Svr;tyrone-cluster;Scheduler was sent the command new
12/08/2012 14:29:03;0040;PBS_Server;Svr;tyrone-cluster;Scheduler was sent the command new
12/08/2012 14:29:10;0040;PBS_Server;Svr;tyrone-cluster;Scheduler was sent the command new
12/08/2012 14:29:25;0040;PBS_Server;Svr;tyrone-cluster;Scheduler was sent the command new
12/08/2012 14:29:32;0040;PBS_Server;Svr;tyrone-cluster;Scheduler was sent the command new
12/08/2012 14:29:43;0040;PBS_Server;Svr;tyrone-cluster;Scheduler was sent the command new
12/08/2012 14:29:57;0040;PBS_Server;Svr;tyrone-cluster;Scheduler was sent the command new
12/08/2012 14:30:02;0040;PBS_Server;Svr;tyrone-cluster;Scheduler was sent the command new
12/08/2012 14:30:10;0040;PBS_Server;Svr;tyrone-cluster;Scheduler was sent the command new
12/08/2012 14:30:28;0040;PBS_Server;Svr;tyrone-cluster;Scheduler was sent the command new
12/08/2012 14:30:33;0040;PBS_Server;Svr;tyrone-cluster;Scheduler was sent the command new
12/08/2012 14:30:43;0040;PBS_Server;Svr;tyrone-cluster;Scheduler was sent the command new
12/08/2012 14:30:58;0040;PBS_Server;Svr;tyrone-cluster;Scheduler was sent the command new
12/08/2012 14:31:02;0040;PBS_Server;Svr;tyrone-cluster;Scheduler was sent the command new
12/08/2012 14:31:13;0040;PBS_Server;Svr;tyrone-cluster;Scheduler was sent the command new
12/08/2012 14:31:28;0040;PBS_Server;Svr;tyrone-cluster;Scheduler was sent the command new
12/08/2012 14:31:32;0040;PBS_Server;Svr;tyrone-cluster;Scheduler was sent the command new
12/08/2012 14:31:43;0040;PBS_Server;Svr;tyrone-cluster;Scheduler was sent the command new
12/08/2012 14:31:58;0040;PBS_Server;Svr;tyrone-cluster;Scheduler was sent the command new
12/08/2012 14:32:03;0040;PBS_Server;Svr;tyrone-cluster;Scheduler was sent the command new
12/08/2012 14:32:13;0040;PBS_Server;Svr;tyrone-cluster;Scheduler was sent the command new
12/08/2012 14:32:28;0040;PBS_Server;Svr;tyrone-cluster;Scheduler was sent the command new
12/08/2012 14:32:32;0040;PBS_Server;Svr;tyrone-cluster;Scheduler was sent the command new
12/08/2012 14:32:43;0040;PBS_Server;Svr;tyrone-cluster;Scheduler was sent the command new
12/08/2012 14:32:58;0040;PBS_Server;Svr;tyrone-cluster;Scheduler was sent the command new
12/08/2012 14:33:02;0040;PBS_Server;Svr;tyrone-cluster;Scheduler was sent the command new
12/08/2012 14:33:10;0002;PBS_Server;Svr;PBS_Server;Torque Server Version = 3.0.5, loglevel = 0
12/08/2012 14:33:13;0040;PBS_Server;Svr;tyrone-cluster;Scheduler was sent the command new
12/08/2012 14:33:28;0040;PBS_Server;Svr;tyrone-cluster;Scheduler was sent the command new
12/08/2012 14:33:33;0040;PBS_Server;Svr;tyrone-cluster;Scheduler was sent the command new
12/08/2012 14:33:43;0040;PBS_Server;Svr;tyrone-cluster;Scheduler was sent the command new
12/08/2012 14:33:58;0040;PBS_Server;Svr;tyrone-cluster;Scheduler was sent the command new
12/08/2012 14:34:02;0040;PBS_Server;Svr;tyrone-cluster;Scheduler was sent the command new
12/08/2012 14:34:13;0040;PBS_Server;Svr;tyrone-cluster;Scheduler was sent the command new
12/08/2012 14:34:28;0040;PBS_Server;Svr;tyrone-cluster;Scheduler was sent the command new
12/08/2012 14:34:32;0040;PBS_Server;Svr;tyrone-cluster;Scheduler was sent the command new
12/08/2012 14:34:43;0040;PBS_Server;Svr;tyrone-cluster;Scheduler was sent the command new
12/08/2012 14:34:58;0040;PBS_Server;Svr;tyrone-cluster;Scheduler was sent the command new
12/08/2012 14:35:03;0040;PBS_Server;Svr;tyrone-cluster;Scheduler was sent the command new
12/08/2012 14:35:13;0040;PBS_Server;Svr;tyrone-cluster;Scheduler was sent the command new
12/08/2012 14:35:28;0040;PBS_Server;Svr;tyrone-cluster;Scheduler was sent the command new
12/08/2012 14:35:32;0040;PBS_Server;Svr;tyrone-cluster;Scheduler was sent the command new
12/08/2012 14:35:43;0040;PBS_Server;Svr;tyrone-cluster;Scheduler was sent the command new
12/08/2012 14:35:58;0040;PBS_Server;Svr;tyrone-cluster;Scheduler was sent the command new
12/08/2012 14:36:02;0040;PBS_Server;Svr;tyrone-cluster;Scheduler was sent the command new
12/08/2012 14:36:13;0040;PBS_Server;Svr;tyrone-cluster;Scheduler was sent the command new
12/08/2012 14:36:28;0040;PBS_Server;Svr;tyrone-cluster;Scheduler was sent the command new
12/08/2012 14:36:33;0040;PBS_Server;Svr;tyrone-cluster;Scheduler was sent the command new
12/08/2012 14:36:43;0040;PBS_Server;Svr;tyrone-cluster;Scheduler was sent the command new
12/08/2012 14:36:58;0040;PBS_Server;Svr;tyrone-cluster;Scheduler was sent the command new
12/08/2012 14:37:02;0040;PBS_Server;Svr;tyrone-cluster;Scheduler was sent the command new
12/08/2012 14:37:13;0040;PBS_Server;Svr;tyrone-cluster;Scheduler was sent the command new
12/08/2012 14:37:28;0040;PBS_Server;Svr;tyrone-cluster;Scheduler was sent the command new
12/08/2012 14:37:32;0040;PBS_Server;Svr;tyrone-cluster;Scheduler was sent the command new
12/08/2012 14:37:43;0040;PBS_Server;Svr;tyrone-cluster;Scheduler was sent the command new
12/08/2012 14:37:58;0040;PBS_Server;Svr;tyrone-cluster;Scheduler was sent the command new
12/08/2012 14:38:03;0040;PBS_Server;Svr;tyrone-cluster;Scheduler was sent the command new
12/08/2012 14:38:10;0002;PBS_Server;Svr;PBS_Server;Torque Server Version = 3.0.5, loglevel = 0
12/08/2012 14:38:13;0040;PBS_Server;Svr;tyrone-cluster;Scheduler was sent the command new
12/08/2012 14:38:28;0040;PBS_Server;Svr;tyrone-cluster;Scheduler was sent the command new
12/08/2012 14:38:32;0040;PBS_Server;Svr;tyrone-cluster;Scheduler was sent the command new
12/08/2012 14:38:43;0040;PBS_Server;Svr;tyrone-cluster;Scheduler was sent the command new
12/08/2012 14:38:58;0040;PBS_Server;Svr;tyrone-cluster;Scheduler was sent the command new
12/08/2012 14:39:02;0040;PBS_Server;Svr;tyrone-cluster;Scheduler was sent the command new
12/08/2012 14:39:13;0040;PBS_Server;Svr;tyrone-cluster;Scheduler was sent the command new
12/08/2012 14:39:28;0040;PBS_Server;Svr;tyrone-cluster;Scheduler was sent the command new
12/08/2012 14:39:33;0040;PBS_Server;Svr;tyrone-cluster;Scheduler was sent the command new
12/08/2012 14:39:43;0040;PBS_Server;Svr;tyrone-cluster;Scheduler was sent the command new
12/08/2012 14:39:58;0040;PBS_Server;Svr;tyrone-cluster;Scheduler was sent the command new
12/08/2012 14:40:02;0040;PBS_Server;Svr;tyrone-cluster;Scheduler was sent the command new
12/08/2012 14:40:13;0040;PBS_Server;Svr;tyrone-cluster;Scheduler was sent the command new
12/08/2012 14:40:28;0040;PBS_Server;Svr;tyrone-cluster;Scheduler was sent the command new
12/08/2012 14:40:32;0040;PBS_Server;Svr;tyrone-cluster;Scheduler was sent the command new
12/08/2012 14:40:43;0040;PBS_Server;Svr;tyrone-cluster;Scheduler was sent the command new
12/08/2012 14:40:58;0040;PBS_Server;Svr;tyrone-cluster;Scheduler was sent the command new
12/08/2012 14:41:03;0040;PBS_Server;Svr;tyrone-cluster;Scheduler was sent the command new
12/08/2012 14:41:13;0040;PBS_Server;Svr;tyrone-cluster;Scheduler was sent the command new
12/08/2012 14:41:28;0040;PBS_Server;Svr;tyrone-cluster;Scheduler was sent the command new
12/08/2012 14:41:32;0040;PBS_Server;Svr;tyrone-cluster;Scheduler was sent the command new
12/08/2012 14:41:43;0040;PBS_Server;Svr;tyrone-cluster;Scheduler was sent the command new
12/08/2012 14:41:58;0040;PBS_Server;Svr;tyrone-cluster;Scheduler was sent the command new
12/08/2012 14:42:02;0040;PBS_Server;Svr;tyrone-cluster;Scheduler was sent the command new
12/08/2012 14:42:13;0040;PBS_Server;Svr;tyrone-cluster;Scheduler was sent the command new
12/08/2012 14:42:28;0040;PBS_Server;Svr;tyrone-cluster;Scheduler was sent the command new
12/08/2012 14:42:33;0040;PBS_Server;Svr;tyrone-cluster;Scheduler was sent the command new
12/08/2012 14:42:43;0040;PBS_Server;Svr;tyrone-cluster;Scheduler was sent the command new
12/08/2012 14:42:58;0040;PBS_Server;Svr;tyrone-cluster;Scheduler was sent the command new
12/08/2012 14:43:02;0040;PBS_Server;Svr;tyrone-cluster;Scheduler was sent the command new
12/08/2012 14:43:10;0002;PBS_Server;Svr;PBS_Server;Torque Server Version = 3.0.5, loglevel = 0
12/08/2012 14:43:13;0040;PBS_Server;Svr;tyrone-cluster;Scheduler was sent the command new
12/08/2012 14:43:28;0040;PBS_Server;Svr;tyrone-cluster;Scheduler was sent the command new
12/08/2012 14:43:32;0040;PBS_Server;Svr;tyrone-cluster;Scheduler was sent the command new
12/08/2012 14:43:43;0040;PBS_Server;Svr;tyrone-cluster;Scheduler was sent the command new
12/08/2012 14:43:58;0040;PBS_Server;Svr;tyrone-cluster;Scheduler was sent the command new
12/08/2012 14:44:03;0040;PBS_Server;Svr;tyrone-cluster;Scheduler was sent the command new
12/08/2012 14:44:13;0040;PBS_Server;Svr;tyrone-cluster;Scheduler was sent the command new
12/08/2012 14:44:28;0040;PBS_Server;Svr;tyrone-cluster;Scheduler was sent the command new
12/08/2012 14:44:32;0040;PBS_Server;Svr;tyrone-cluster;Scheduler was sent the command new
12/08/2012 14:44:43;0040;PBS_Server;Svr;tyrone-cluster;Scheduler was sent the command new
12/08/2012 14:44:58;0040;PBS_Server;Svr;tyrone-cluster;Scheduler was sent the command new
12/08/2012 14:45:02;0040;PBS_Server;Svr;tyrone-cluster;Scheduler was sent the command new
12/08/2012 14:45:13;0040;PBS_Server;Svr;tyrone-cluster;Scheduler was sent the command new
12/08/2012 14:45:28;0040;PBS_Server;Svr;tyrone-cluster;Scheduler was sent the command new
12/08/2012 14:45:33;0040;PBS_Server;Svr;tyrone-cluster;Scheduler was sent the command new
12/08/2012 14:45:43;0040;PBS_Server;Svr;tyrone-cluster;Scheduler was sent the command new
12/08/2012 14:45:58;0040;PBS_Server;Svr;tyrone-cluster;Scheduler was sent the command new
12/08/2012 14:46:02;0040;PBS_Server;Svr;tyrone-cluster;Scheduler was sent the command new
12/08/2012 14:46:13;0040;PBS_Server;Svr;tyrone-cluster;Scheduler was sent the command new
12/08/2012 14:46:28;0040;PBS_Server;Svr;tyrone-cluster;Scheduler was sent the command new
12/08/2012 14:46:32;0040;PBS_Server;Svr;tyrone-cluster;Scheduler was sent the command new
12/08/2012 14:46:43;0040;PBS_Server;Svr;tyrone-cluster;Scheduler was sent the command new
12/08/2012 14:46:58;0040;PBS_Server;Svr;tyrone-cluster;Scheduler was sent the command new
12/08/2012 14:47:03;0040;PBS_Server;Svr;tyrone-cluster;Scheduler was sent the command new
12/08/2012 14:47:13;0040;PBS_Server;Svr;tyrone-cluster;Scheduler was sent the command new
12/08/2012 14:47:28;0040;PBS_Server;Svr;tyrone-cluster;Scheduler was sent the command new
12/08/2012 14:47:32;0040;PBS_Server;Svr;tyrone-cluster;Scheduler was sent the command new
12/08/2012 14:47:43;0040;PBS_Server;Svr;tyrone-cluster;Scheduler was sent the command new
12/08/2012 14:47:58;0040;PBS_Server;Svr;tyrone-cluster;Scheduler was sent the command new
12/08/2012 14:48:02;0040;PBS_Server;Svr;tyrone-cluster;Scheduler was sent the command new
12/08/2012 14:48:10;0002;PBS_Server;Svr;PBS_Server;Torque Server Version = 3.0.5, loglevel = 0
12/08/2012 14:48:13;0040;PBS_Server;Svr;tyrone-cluster;Scheduler was sent the command new
12/08/2012 14:48:28;0040;PBS_Server;Svr;tyrone-cluster;Scheduler was sent the command new
12/08/2012 14:48:33;0040;PBS_Server;Svr;tyrone-cluster;Scheduler was sent the command new
12/08/2012 14:48:43;0040;PBS_Server;Svr;tyrone-cluster;Scheduler was sent the command new
12/08/2012 14:48:58;0040;PBS_Server;Svr;tyrone-cluster;Scheduler was sent the command new
12/08/2012 14:49:02;0040;PBS_Server;Svr;tyrone-cluster;Scheduler was sent the command new
12/08/2012 14:49:14;0040;PBS_Server;Svr;tyrone-cluster;Scheduler was sent the command new
12/08/2012 14:49:28;0040;PBS_Server;Svr;tyrone-cluster;Scheduler was sent the command new
12/08/2012 14:49:32;0040;PBS_Server;Svr;tyrone-cluster;Scheduler was sent the command new
12/08/2012 14:49:45;0040;PBS_Server;Svr;tyrone-cluster;Scheduler was sent the command new
12/08/2012 14:49:58;0040;PBS_Server;Svr;tyrone-cluster;Scheduler was sent the command new
12/08/2012 14:50:03;0040;PBS_Server;Svr;tyrone-cluster;Scheduler was sent the command new
12/08/2012 14:50:17;0040;PBS_Server;Svr;tyrone-cluster;Scheduler was sent the command new
12/08/2012 14:50:28;0040;PBS_Server;Svr;tyrone-cluster;Scheduler was sent the command new
12/08/2012 14:50:32;0040;PBS_Server;Svr;tyrone-cluster;Scheduler was sent the command new
12/08/2012 14:50:46;0040;PBS_Server;Svr;tyrone-cluster;Scheduler was sent the command new
12/08/2012 14:50:58;0040;PBS_Server;Svr;tyrone-cluster;Scheduler was sent the command new
12/08/2012 14:51:03;0040;PBS_Server;Svr;tyrone-cluster;Scheduler was sent the command new
12/08/2012 14:51:17;0040;PBS_Server;Svr;tyrone-cluster;Scheduler was sent the command new
12/08/2012 14:51:28;0040;PBS_Server;Svr;tyrone-cluster;Scheduler was sent the command new
12/08/2012 14:51:37;0040;PBS_Server;Svr;tyrone-cluster;Scheduler was sent the command new
12/08/2012 14:51:47;0040;PBS_Server;Svr;tyrone-cluster;Scheduler was sent the command new
12/08/2012 14:51:58;0040;PBS_Server;Svr;tyrone-cluster;Scheduler was sent the command new
12/08/2012 14:52:04;0040;PBS_Server;Svr;tyrone-cluster;Scheduler was sent the command new
12/08/2012 14:52:18;0040;PBS_Server;Svr;tyrone-cluster;Scheduler was sent the command new
12/08/2012 14:52:28;0040;PBS_Server;Svr;tyrone-cluster;Scheduler was sent the command new
12/08/2012 14:52:34;0040;PBS_Server;Svr;tyrone-cluster;Scheduler was sent the command new
12/08/2012 14:52:47;0040;PBS_Server;Svr;tyrone-cluster;Scheduler was sent the command new
12/08/2012 14:52:58;0040;PBS_Server;Svr;tyrone-cluster;Scheduler was sent the command new
12/08/2012 14:53:05;0040;PBS_Server;Svr;tyrone-cluster;Scheduler was sent the command new
12/08/2012 14:53:10;0002;PBS_Server;Svr;PBS_Server;Torque Server Version = 3.0.5, loglevel = 0
12/08/2012 14:53:17;0040;PBS_Server;Svr;tyrone-cluster;Scheduler was sent the command new
12/08/2012 14:53:28;0040;PBS_Server;Svr;tyrone-cluster;Scheduler was sent the command new
12/08/2012 14:53:34;0040;PBS_Server;Svr;tyrone-cluster;Scheduler was sent the command new
12/08/2012 14:53:48;0040;PBS_Server;Svr;tyrone-cluster;Scheduler was sent the command new
12/08/2012 14:53:58;0040;PBS_Server;Svr;tyrone-cluster;Scheduler was sent the command new
12/08/2012 14:54:04;0040;PBS_Server;Svr;tyrone-cluster;Scheduler was sent the command new
12/08/2012 14:54:17;0040;PBS_Server;Svr;tyrone-cluster;Scheduler was sent the command new
12/08/2012 14:54:28;0040;PBS_Server;Svr;tyrone-cluster;Scheduler was sent the command new
12/08/2012 14:54:40;0040;PBS_Server;Svr;tyrone-cluster;Scheduler was sent the command new
12/08/2012 14:54:47;0040;PBS_Server;Svr;tyrone-cluster;Scheduler was sent the command new
12/08/2012 14:54:58;0040;PBS_Server;Svr;tyrone-cluster;Scheduler was sent the command new
12/08/2012 14:55:08;0040;PBS_Server;Svr;tyrone-cluster;Scheduler was sent the command new
12/08/2012 14:55:18;0040;PBS_Server;Svr;tyrone-cluster;Scheduler was sent the command new
12/08/2012 14:55:28;0040;PBS_Server;Svr;tyrone-cluster;Scheduler was sent the command new
12/08/2012 14:55:37;0040;PBS_Server;Svr;tyrone-cluster;Scheduler was sent the command new
12/08/2012 14:55:47;0040;PBS_Server;Svr;tyrone-cluster;Scheduler was sent the command new
12/08/2012 14:55:58;0040;PBS_Server;Svr;tyrone-cluster;Scheduler was sent the command new
12/08/2012 14:56:10;0040;PBS_Server;Svr;tyrone-cluster;Scheduler was sent the command new
12/08/2012 14:56:17;0040;PBS_Server;Svr;tyrone-cluster;Scheduler was sent the command new
12/08/2012 14:56:28;0040;PBS_Server;Svr;tyrone-cluster;Scheduler was sent the command new
12/08/2012 14:56:38;0040;PBS_Server;Svr;tyrone-cluster;Scheduler was sent the command new
12/08/2012 14:56:48;0040;PBS_Server;Svr;tyrone-cluster;Scheduler was sent the command new
12/08/2012 14:56:58;0040;PBS_Server;Svr;tyrone-cluster;Scheduler was sent the command new
12/08/2012 14:57:09;0040;PBS_Server;Svr;tyrone-cluster;Scheduler was sent the command new
12/08/2012 14:57:17;0040;PBS_Server;Svr;tyrone-cluster;Scheduler was sent the command new
12/08/2012 14:57:28;0040;PBS_Server;Svr;tyrone-cluster;Scheduler was sent the command new
12/08/2012 14:57:43;0040;PBS_Server;Svr;tyrone-cluster;Scheduler was sent the command new
12/08/2012 14:57:47;0040;PBS_Server;Svr;tyrone-cluster;Scheduler was sent the command new
12/08/2012 14:57:58;0040;PBS_Server;Svr;tyrone-cluster;Scheduler was sent the command new
12/08/2012 14:58:10;0002;PBS_Server;Svr;PBS_Server;Torque Server Version = 3.0.5, loglevel = 0
12/08/2012 14:58:13;0040;PBS_Server;Svr;tyrone-cluster;Scheduler was sent the command new
12/08/2012 14:58:18;0040;PBS_Server;Svr;tyrone-cluster;Scheduler was sent the command new
12/08/2012 14:58:28;0040;PBS_Server;Svr;tyrone-cluster;Scheduler was sent the command new
12/08/2012 14:58:40;0040;PBS_Server;Svr;tyrone-cluster;Scheduler was sent the command new
12/08/2012 14:58:47;0040;PBS_Server;Svr;tyrone-cluster;Scheduler was sent the command new
12/08/2012 14:58:58;0040;PBS_Server;Svr;tyrone-cluster;Scheduler was sent the command new
12/08/2012 14:59:13;0040;PBS_Server;Svr;tyrone-cluster;Scheduler was sent the command new
12/08/2012 14:59:17;0040;PBS_Server;Svr;tyrone-cluster;Scheduler was sent the command new
12/08/2012 14:59:28;0040;PBS_Server;Svr;tyrone-cluster;Scheduler was sent the command new
12/08/2012 14:59:43;0040;PBS_Server;Svr;tyrone-cluster;Scheduler was sent the command new
12/08/2012 14:59:48;0040;PBS_Server;Svr;tyrone-cluster;Scheduler was sent the command new
12/08/2012 14:59:58;0040;PBS_Server;Svr;tyrone-cluster;Scheduler was sent the command new
12/08/2012 15:00:13;0040;PBS_Server;Svr;tyrone-cluster;Scheduler was sent the command new
12/08/2012 15:00:17;0040;PBS_Server;Svr;tyrone-cluster;Scheduler was sent the command new
12/08/2012 15:00:28;0040;PBS_Server;Svr;tyrone-cluster;Scheduler was sent the command new
12/08/2012 15:00:43;0040;PBS_Server;Svr;tyrone-cluster;Scheduler was sent the command new
12/08/2012 15:00:47;0040;PBS_Server;Svr;tyrone-cluster;Scheduler was sent the command new
12/08/2012 15:00:58;0040;PBS_Server;Svr;tyrone-cluster;Scheduler was sent the command new
12/08/2012 15:01:13;0040;PBS_Server;Svr;tyrone-cluster;Scheduler was sent the command new
12/08/2012 15:01:18;0040;PBS_Server;Svr;tyrone-cluster;Scheduler was sent the command new
12/08/2012 15:01:28;0040;PBS_Server;Svr;tyrone-cluster;Scheduler was sent the command new
12/08/2012 15:01:43;0040;PBS_Server;Svr;tyrone-cluster;Scheduler was sent the command new
12/08/2012 15:01:47;0040;PBS_Server;Svr;tyrone-cluster;Scheduler was sent the command new
12/08/2012 15:01:58;0040;PBS_Server;Svr;tyrone-cluster;Scheduler was sent the command new
12/08/2012 15:02:13;0040;PBS_Server;Svr;tyrone-cluster;Scheduler was sent the command new
12/08/2012 15:02:17;0040;PBS_Server;Svr;tyrone-cluster;Scheduler was sent the command new
12/08/2012 15:02:28;0040;PBS_Server;Svr;tyrone-cluster;Scheduler was sent the command new
12/08/2012 15:02:43;0040;PBS_Server;Svr;tyrone-cluster;Scheduler was sent the command new
12/08/2012 15:02:48;0040;PBS_Server;Svr;tyrone-cluster;Scheduler was sent the command new
12/08/2012 15:02:58;0040;PBS_Server;Svr;tyrone-cluster;Scheduler was sent the command new
12/08/2012 15:03:10;0002;PBS_Server;Svr;PBS_Server;Torque Server Version = 3.0.5, loglevel = 0
12/08/2012 15:03:13;0040;PBS_Server;Svr;tyrone-cluster;Scheduler was sent the command new
12/08/2012 15:03:17;0040;PBS_Server;Svr;tyrone-cluster;Scheduler was sent the command new
12/08/2012 15:03:28;0040;PBS_Server;Svr;tyrone-cluster;Scheduler was sent the command new
12/08/2012 15:03:43;0040;PBS_Server;Svr;tyrone-cluster;Scheduler was sent the command new
12/08/2012 15:03:47;0040;PBS_Server;Svr;tyrone-cluster;Scheduler was sent the command new
12/08/2012 15:03:58;0040;PBS_Server;Svr;tyrone-cluster;Scheduler was sent the command new
12/08/2012 15:04:13;0040;PBS_Server;Svr;tyrone-cluster;Scheduler was sent the command new
12/08/2012 15:04:18;0040;PBS_Server;Svr;tyrone-cluster;Scheduler was sent the command new
12/08/2012 15:04:28;0040;PBS_Server;Svr;tyrone-cluster;Scheduler was sent the command new
12/08/2012 15:04:43;0040;PBS_Server;Svr;tyrone-cluster;Scheduler was sent the command new
12/08/2012 15:04:47;0040;PBS_Server;Svr;tyrone-cluster;Scheduler was sent the command new
12/08/2012 15:04:58;0040;PBS_Server;Svr;tyrone-cluster;Scheduler was sent the command new
12/08/2012 15:05:13;0040;PBS_Server;Svr;tyrone-cluster;Scheduler was sent the command new
12/08/2012 15:05:17;0040;PBS_Server;Svr;tyrone-cluster;Scheduler was sent the command new
12/08/2012 15:05:28;0040;PBS_Server;Svr;tyrone-cluster;Scheduler was sent the command new
12/08/2012 15:05:43;0040;PBS_Server;Svr;tyrone-cluster;Scheduler was sent the command new
12/08/2012 15:05:48;0040;PBS_Server;Svr;tyrone-cluster;Scheduler was sent the command new
12/08/2012 15:05:58;0040;PBS_Server;Svr;tyrone-cluster;Scheduler was sent the command new
12/08/2012 15:06:13;0040;PBS_Server;Svr;tyrone-cluster;Scheduler was sent the command new
12/08/2012 15:06:17;0040;PBS_Server;Svr;tyrone-cluster;Scheduler was sent the command new
12/08/2012 15:06:28;0040;PBS_Server;Svr;tyrone-cluster;Scheduler was sent the command new
12/08/2012 15:06:43;0040;PBS_Server;Svr;tyrone-cluster;Scheduler was sent the command new
12/08/2012 15:06:47;0040;PBS_Server;Svr;tyrone-cluster;Scheduler was sent the command new
12/08/2012 15:06:58;0040;PBS_Server;Svr;tyrone-cluster;Scheduler was sent the command new
12/08/2012 15:07:13;0040;PBS_Server;Svr;tyrone-cluster;Scheduler was sent the command new
12/08/2012 15:07:18;0040;PBS_Server;Svr;tyrone-cluster;Scheduler was sent the command new
12/08/2012 15:07:28;0040;PBS_Server;Svr;tyrone-cluster;Scheduler was sent the command new
12/08/2012 15:07:43;0040;PBS_Server;Svr;tyrone-cluster;Scheduler was sent the command new
12/08/2012 15:07:47;0040;PBS_Server;Svr;tyrone-cluster;Scheduler was sent the command new
12/08/2012 15:07:58;0040;PBS_Server;Svr;tyrone-cluster;Scheduler was sent the command new
12/08/2012 15:08:10;0002;PBS_Server;Svr;PBS_Server;Torque Server Version = 3.0.5, loglevel = 0
12/08/2012 15:08:13;0040;PBS_Server;Svr;tyrone-cluster;Scheduler was sent the command new
12/08/2012 15:08:17;0040;PBS_Server;Svr;tyrone-cluster;Scheduler was sent the command new
12/08/2012 15:08:28;0040;PBS_Server;Svr;tyrone-cluster;Scheduler was sent the command new
12/08/2012 15:08:43;0040;PBS_Server;Svr;tyrone-cluster;Scheduler was sent the command new
12/08/2012 15:08:48;0040;PBS_Server;Svr;tyrone-cluster;Scheduler was sent the command new
12/08/2012 15:08:58;0040;PBS_Server;Svr;tyrone-cluster;Scheduler was sent the command new
12/08/2012 15:09:13;0040;PBS_Server;Svr;tyrone-cluster;Scheduler was sent the command new
12/08/2012 15:09:17;0040;PBS_Server;Svr;tyrone-cluster;Scheduler was sent the command new
12/08/2012 15:09:28;0040;PBS_Server;Svr;tyrone-cluster;Scheduler was sent the command new
12/08/2012 15:09:43;0040;PBS_Server;Svr;tyrone-cluster;Scheduler was sent the command new
12/08/2012 15:09:45;000d;PBS_Server;Job;16762.tyrone-cluster;Not sending email: User does not want mail of this type.
12/08/2012 15:09:45;0010;PBS_Server;Job;16762.tyrone-cluster;Exit_status=0 resources_used.cput=28:39:24 resources_used.mem=26566004kb resources_used.vmem=35272552kb resources_used.walltime=00:53:50
12/08/2012 15:09:45;0008;PBS_Server;Job;NULL;on_job_exit valid pjob: 0x1c2eb20 (substate=50)
12/08/2012 15:09:45;0008;PBS_Server;Job;NULL;on_job_exit valid pjob: 0x1c2eb20 (substate=51)
12/08/2012 15:09:45;0008;PBS_Server;Job;NULL;on_job_exit valid pjob: 0x1c2eb20 (substate=51)
12/08/2012 15:09:45;0008;PBS_Server;Job;NULL;on_job_exit valid pjob: 0x1c2eb20 (substate=53)
12/08/2012 15:09:45;0100;PBS_Server;Job;16762.tyrone-cluster;dequeuing from idqueue, state COMPLETE
12/08/2012 15:09:45;0040;PBS_Server;Svr;tyrone-cluster;Scheduler was sent the command term
12/08/2012 15:09:47;0040;PBS_Server;Svr;tyrone-cluster;Scheduler was sent the command new
12/08/2012 15:09:58;0040;PBS_Server;Svr;tyrone-cluster;Scheduler was sent the command new
12/08/2012 15:10:13;0040;PBS_Server;Svr;tyrone-cluster;Scheduler was sent the command new
12/08/2012 15:10:18;0040;PBS_Server;Svr;tyrone-cluster;Scheduler was sent the command new
12/08/2012 15:10:29;0040;PBS_Server;Svr;tyrone-cluster;Scheduler was sent the command new
12/08/2012 15:10:43;0040;PBS_Server;Svr;tyrone-cluster;Scheduler was sent the command new
12/08/2012 15:10:47;0040;PBS_Server;Svr;tyrone-cluster;Scheduler was sent the command new
12/08/2012 15:10:59;0040;PBS_Server;Svr;tyrone-cluster;Scheduler was sent the command new
12/08/2012 15:11:14;0040;PBS_Server;Svr;tyrone-cluster;Scheduler was sent the command new
12/08/2012 15:11:17;0040;PBS_Server;Svr;tyrone-cluster;Scheduler was sent the command new
12/08/2012 15:11:30;0040;PBS_Server;Svr;tyrone-cluster;Scheduler was sent the command new
12/08/2012 15:11:43;0040;PBS_Server;Svr;tyrone-cluster;Scheduler was sent the command new
12/08/2012 15:11:48;0040;PBS_Server;Svr;tyrone-cluster;Scheduler was sent the command new
12/08/2012 15:12:01;0040;PBS_Server;Svr;tyrone-cluster;Scheduler was sent the command new
12/08/2012 15:12:13;0040;PBS_Server;Svr;tyrone-cluster;Scheduler was sent the command new
12/08/2012 15:12:17;0040;PBS_Server;Svr;tyrone-cluster;Scheduler was sent the command new
12/08/2012 15:12:31;0040;PBS_Server;Svr;tyrone-cluster;Scheduler was sent the command new
12/08/2012 15:12:45;0040;PBS_Server;Svr;tyrone-cluster;Scheduler was sent the command new
12/08/2012 15:12:47;0040;PBS_Server;Svr;tyrone-cluster;Scheduler was sent the command new
12/08/2012 15:13:02;0040;PBS_Server;Svr;tyrone-cluster;Scheduler was sent the command new
12/08/2012 15:13:10;0002;PBS_Server;Svr;PBS_Server;Torque Server Version = 3.0.5, loglevel = 0
12/08/2012 15:13:14;0040;PBS_Server;Svr;tyrone-cluster;Scheduler was sent the command new
12/08/2012 15:13:18;0040;PBS_Server;Svr;tyrone-cluster;Scheduler was sent the command new
12/08/2012 15:13:32;0040;PBS_Server;Svr;tyrone-cluster;Scheduler was sent the command new
12/08/2012 15:13:45;0040;PBS_Server;Svr;tyrone-cluster;Scheduler was sent the command new
12/08/2012 15:13:47;0040;PBS_Server;Svr;tyrone-cluster;Scheduler was sent the command new
12/08/2012 15:14:03;0040;PBS_Server;Svr;tyrone-cluster;Scheduler was sent the command new
12/08/2012 15:14:16;0040;PBS_Server;Svr;tyrone-cluster;Scheduler was sent the command new
12/08/2012 15:14:17;0040;PBS_Server;Svr;tyrone-cluster;Scheduler was sent the command new
12/08/2012 15:14:32;0040;PBS_Server;Svr;tyrone-cluster;Scheduler was sent the command new
12/08/2012 15:14:46;0040;PBS_Server;Svr;tyrone-cluster;Scheduler was sent the command new
12/08/2012 15:14:48;0040;PBS_Server;Svr;tyrone-cluster;Scheduler was sent the command new
12/08/2012 15:15:02;0040;PBS_Server;Svr;tyrone-cluster;Scheduler was sent the command new
12/08/2012 15:15:17;0040;PBS_Server;Svr;tyrone-cluster;Scheduler was sent the command new
12/08/2012 15:15:33;0040;PBS_Server;Svr;tyrone-cluster;Scheduler was sent the command new
12/08/2012 15:15:47;0040;PBS_Server;Svr;tyrone-cluster;Scheduler was sent the command new
12/08/2012 15:16:02;0040;PBS_Server;Svr;tyrone-cluster;Scheduler was sent the command new
12/08/2012 15:16:18;0040;PBS_Server;Svr;tyrone-cluster;Scheduler was sent the command new
12/08/2012 15:16:32;0040;PBS_Server;Svr;tyrone-cluster;Scheduler was sent the command new
12/08/2012 15:16:47;0040;PBS_Server;Svr;tyrone-cluster;Scheduler was sent the command new
12/08/2012 15:17:03;0040;PBS_Server;Svr;tyrone-cluster;Scheduler was sent the command new
12/08/2012 15:17:17;0040;PBS_Server;Svr;tyrone-cluster;Scheduler was sent the command new
12/08/2012 15:17:32;0040;PBS_Server;Svr;tyrone-cluster;Scheduler was sent the command new
12/08/2012 15:17:48;0040;PBS_Server;Svr;tyrone-cluster;Scheduler was sent the command new
12/08/2012 15:18:02;0040;PBS_Server;Svr;tyrone-cluster;Scheduler was sent the command new
12/08/2012 15:18:10;0002;PBS_Server;Svr;PBS_Server;Torque Server Version = 3.0.5, loglevel = 0
12/08/2012 15:18:17;0040;PBS_Server;Svr;tyrone-cluster;Scheduler was sent the command new
12/08/2012 15:18:33;0040;PBS_Server;Svr;tyrone-cluster;Scheduler was sent the command new
12/08/2012 15:18:47;0040;PBS_Server;Svr;tyrone-cluster;Scheduler was sent the command new
12/08/2012 15:19:02;0040;PBS_Server;Svr;tyrone-cluster;Scheduler was sent the command new
12/08/2012 15:19:18;0040;PBS_Server;Svr;tyrone-cluster;Scheduler was sent the command new
12/08/2012 15:19:32;0040;PBS_Server;Svr;tyrone-cluster;Scheduler was sent the command new
12/08/2012 15:19:47;0040;PBS_Server;Svr;tyrone-cluster;Scheduler was sent the command new
12/08/2012 15:20:03;0040;PBS_Server;Svr;tyrone-cluster;Scheduler was sent the command new
12/08/2012 15:20:17;0040;PBS_Server;Svr;tyrone-cluster;Scheduler was sent the command new
12/08/2012 15:20:32;0040;PBS_Server;Svr;tyrone-cluster;Scheduler was sent the command new
12/08/2012 15:20:48;0040;PBS_Server;Svr;tyrone-cluster;Scheduler was sent the command new
12/08/2012 15:21:02;0040;PBS_Server;Svr;tyrone-cluster;Scheduler was sent the command new
12/08/2012 15:21:17;0040;PBS_Server;Svr;tyrone-cluster;Scheduler was sent the command new
12/08/2012 15:21:33;0040;PBS_Server;Svr;tyrone-cluster;Scheduler was sent the command new
12/08/2012 15:21:47;0040;PBS_Server;Svr;tyrone-cluster;Scheduler was sent the command new
12/08/2012 15:22:02;0040;PBS_Server;Svr;tyrone-cluster;Scheduler was sent the command new
12/08/2012 15:22:18;0040;PBS_Server;Svr;tyrone-cluster;Scheduler was sent the command new
12/08/2012 15:22:32;0040;PBS_Server;Svr;tyrone-cluster;Scheduler was sent the command new
12/08/2012 15:22:47;0040;PBS_Server;Svr;tyrone-cluster;Scheduler was sent the command new
12/08/2012 15:23:03;0040;PBS_Server;Svr;tyrone-cluster;Scheduler was sent the command new
12/08/2012 15:23:10;0002;PBS_Server;Svr;PBS_Server;Torque Server Version = 3.0.5, loglevel = 0
12/08/2012 15:23:17;0040;PBS_Server;Svr;tyrone-cluster;Scheduler was sent the command new
12/08/2012 15:23:32;0040;PBS_Server;Svr;tyrone-cluster;Scheduler was sent the command new
12/08/2012 15:23:48;0040;PBS_Server;Svr;tyrone-cluster;Scheduler was sent the command new
12/08/2012 15:24:02;0040;PBS_Server;Svr;tyrone-cluster;Scheduler was sent the command new
12/08/2012 15:24:17;0040;PBS_Server;Svr;tyrone-cluster;Scheduler was sent the command new
12/08/2012 15:24:33;0040;PBS_Server;Svr;tyrone-cluster;Scheduler was sent the command new
12/08/2012 15:24:47;0040;PBS_Server;Svr;tyrone-cluster;Scheduler was sent the command new
12/08/2012 15:25:02;0040;PBS_Server;Svr;tyrone-cluster;Scheduler was sent the command new
12/08/2012 15:25:18;0040;PBS_Server;Svr;tyrone-cluster;Scheduler was sent the command new
12/08/2012 15:25:32;0040;PBS_Server;Svr;tyrone-cluster;Scheduler was sent the command new
12/08/2012 15:25:47;0040;PBS_Server;Svr;tyrone-cluster;Scheduler was sent the command new
12/08/2012 15:26:03;0040;PBS_Server;Svr;tyrone-cluster;Scheduler was sent the command new
12/08/2012 15:26:17;0040;PBS_Server;Svr;tyrone-cluster;Scheduler was sent the command new
12/08/2012 15:26:32;0040;PBS_Server;Svr;tyrone-cluster;Scheduler was sent the command new
12/08/2012 15:26:48;0040;PBS_Server;Svr;tyrone-cluster;Scheduler was sent the command new
12/08/2012 15:27:02;0040;PBS_Server;Svr;tyrone-cluster;Scheduler was sent the command new
12/08/2012 15:27:17;0040;PBS_Server;Svr;tyrone-cluster;Scheduler was sent the command new
12/08/2012 15:27:33;0040;PBS_Server;Svr;tyrone-cluster;Scheduler was sent the command new
12/08/2012 15:27:47;0040;PBS_Server;Svr;tyrone-cluster;Scheduler was sent the command new
12/08/2012 15:28:02;0040;PBS_Server;Svr;tyrone-cluster;Scheduler was sent the command new
12/08/2012 15:28:10;0002;PBS_Server;Svr;PBS_Server;Torque Server Version = 3.0.5, loglevel = 0
12/08/2012 15:28:18;0040;PBS_Server;Svr;tyrone-cluster;Scheduler was sent the command new
12/08/2012 15:28:32;0040;PBS_Server;Svr;tyrone-cluster;Scheduler was sent the command new
12/08/2012 15:28:47;0040;PBS_Server;Svr;tyrone-cluster;Scheduler was sent the command new
12/08/2012 15:29:03;0040;PBS_Server;Svr;tyrone-cluster;Scheduler was sent the command new
12/08/2012 15:29:12;000d;PBS_Server;Job;16588.tyrone-cluster;Not sending email: User does not want mail of this type.
12/08/2012 15:29:12;0010;PBS_Server;Job;16588.tyrone-cluster;Exit_status=143 resources_used.cput=959:39:56 resources_used.mem=49144376kb resources_used.vmem=86535120kb resources_used.walltime=15:00:11
12/08/2012 15:29:12;0008;PBS_Server;Job;NULL;on_job_exit valid pjob: 0x1ba5550 (substate=50)
12/08/2012 15:29:12;0008;PBS_Server;Job;NULL;on_job_exit valid pjob: 0x1ba5550 (substate=51)
12/08/2012 15:29:12;0008;PBS_Server;Job;NULL;on_job_exit valid pjob: 0x1ba5550 (substate=51)
12/08/2012 15:29:12;0008;PBS_Server;Job;NULL;on_job_exit valid pjob: 0x1ba5550 (substate=53)
12/08/2012 15:29:12;0100;PBS_Server;Job;16588.tyrone-cluster;dequeuing from qp64, state COMPLETE
12/08/2012 15:29:12;0040;PBS_Server;Svr;tyrone-cluster;Scheduler was sent the command term
12/08/2012 15:29:12;0008;PBS_Server;Job;16595.tyrone-cluster;Job Modified at request of Scheduler@tyrone-cluster
12/08/2012 15:29:12;0008;PBS_Server;Job;16595.tyrone-cluster;Job Run at request of Scheduler@tyrone-cluster
12/08/2012 15:29:12;0040;PBS_Server;Svr;tyrone-cluster;Scheduler was sent the command recyc
12/08/2012 15:29:12;000d;PBS_Server;Job;16595.tyrone-cluster;Not sending email: User does not want mail of this type.
12/08/2012 15:29:17;0100;PBS_Server;Job;16758.tyrone-cluster;dequeuing from batch, state QUEUED
12/08/2012 15:29:17;0100;PBS_Server;Job;16758.tyrone-cluster;enqueuing into qp64, state 1 hop 1
12/08/2012 15:29:17;0040;PBS_Server;Svr;tyrone-cluster;Scheduler was sent the command new
12/08/2012 15:29:17;0008;PBS_Server;Job;16758.tyrone-cluster;Job Modified at request of Scheduler@tyrone-cluster
12/08/2012 15:29:25;000d;PBS_Server;Job;16595.tyrone-cluster;Not sending email: User does not want mail of this type.
12/08/2012 15:29:25;0010;PBS_Server;Job;16595.tyrone-cluster;Exit_status=174 resources_used.cput=00:10:22 resources_used.mem=0kb resources_used.vmem=0kb resources_used.walltime=00:00:13
12/08/2012 15:29:25;0008;PBS_Server;Job;NULL;on_job_exit valid pjob: 0x1b84550 (substate=50)
12/08/2012 15:29:25;0008;PBS_Server;Job;NULL;on_job_exit valid pjob: 0x1b84550 (substate=51)
12/08/2012 15:29:25;0008;PBS_Server;Job;NULL;on_job_exit valid pjob: 0x1b84550 (substate=51)
12/08/2012 15:29:25;0008;PBS_Server;Job;NULL;on_job_exit valid pjob: 0x1b84550 (substate=53)
12/08/2012 15:29:25;0100;PBS_Server;Job;16595.tyrone-cluster;dequeuing from qp64, state COMPLETE
12/08/2012 15:29:25;0040;PBS_Server;Svr;tyrone-cluster;Scheduler was sent the command term
12/08/2012 15:29:25;0008;PBS_Server;Job;16659.tyrone-cluster;Job Modified at request of Scheduler@tyrone-cluster
12/08/2012 15:29:25;0008;PBS_Server;Job;16659.tyrone-cluster;Job Run at request of Scheduler@tyrone-cluster
12/08/2012 15:29:26;000d;PBS_Server;Job;16659.tyrone-cluster;Not sending email: User does not want mail of this type.
12/08/2012 15:29:26;0040;PBS_Server;Svr;tyrone-cluster;Scheduler was sent the command recyc
12/08/2012 15:29:33;0040;PBS_Server;Svr;tyrone-cluster;Scheduler was sent the command new
12/08/2012 15:29:48;0040;PBS_Server;Svr;tyrone-cluster;Scheduler was sent the command new
12/08/2012 15:29:51;0100;PBS_Server;Job;16767.tyrone-cluster;enqueuing into batch, state 1 hop 1
12/08/2012 15:29:52;0100;PBS_Server;Job;16767.tyrone-cluster;dequeuing from batch, state QUEUED
12/08/2012 15:29:52;0100;PBS_Server;Job;16767.tyrone-cluster;enqueuing into idqueue, state 1 hop 1
12/08/2012 15:29:52;0008;PBS_Server;Job;16767.tyrone-cluster;Job Queued at request of mrcatanu@tyrone-cluster, owner = mrcatanu@tyrone-cluster, job name = TSSDI2, queue = idqueue
12/08/2012 15:29:52;0040;PBS_Server;Svr;tyrone-cluster;Scheduler was sent the command new
12/08/2012 15:29:52;0008;PBS_Server;Job;16767.tyrone-cluster;Job Modified at request of Scheduler@tyrone-cluster
12/08/2012 15:29:52;0008;PBS_Server;Job;16767.tyrone-cluster;Job Run at request of Scheduler@tyrone-cluster
12/08/2012 15:29:52;0040;PBS_Server;Svr;tyrone-cluster;Scheduler was sent the command recyc
12/08/2012 15:29:52;000d;PBS_Server;Job;16767.tyrone-cluster;Not sending email: User does not want mail of this type.
12/08/2012 15:30:02;0040;PBS_Server;Svr;tyrone-cluster;Scheduler was sent the command new
12/08/2012 15:30:19;0040;PBS_Server;Svr;tyrone-cluster;Scheduler was sent the command new
12/08/2012 15:30:33;0040;PBS_Server;Svr;tyrone-cluster;Scheduler was sent the command new
12/08/2012 15:30:47;0040;PBS_Server;Svr;tyrone-cluster;Scheduler was sent the command new
12/08/2012 15:31:04;0040;PBS_Server;Svr;tyrone-cluster;Scheduler was sent the command new
12/08/2012 15:31:18;0040;PBS_Server;Svr;tyrone-cluster;Scheduler was sent the command new
12/08/2012 15:31:32;0040;PBS_Server;Svr;tyrone-cluster;Scheduler was sent the command new
12/08/2012 15:31:48;0040;PBS_Server;Svr;tyrone-cluster;Scheduler was sent the command new
12/08/2012 15:32:03;0040;PBS_Server;Svr;tyrone-cluster;Scheduler was sent the command new
12/08/2012 15:32:17;0040;PBS_Server;Svr;tyrone-cluster;Scheduler was sent the command new
12/08/2012 15:32:34;0040;PBS_Server;Svr;tyrone-cluster;Scheduler was sent the command new
12/08/2012 15:32:48;0040;PBS_Server;Svr;tyrone-cluster;Scheduler was sent the command new
12/08/2012 15:33:02;0040;PBS_Server;Svr;tyrone-cluster;Scheduler was sent the command new
12/08/2012 15:33:10;0002;PBS_Server;Svr;PBS_Server;Torque Server Version = 3.0.5, loglevel = 0
12/08/2012 15:33:19;0040;PBS_Server;Svr;tyrone-cluster;Scheduler was sent the command new
12/08/2012 15:33:33;0040;PBS_Server;Svr;tyrone-cluster;Scheduler was sent the command new
12/08/2012 15:33:47;0040;PBS_Server;Svr;tyrone-cluster;Scheduler was sent the command new
12/08/2012 15:34:03;0040;PBS_Server;Svr;tyrone-cluster;Scheduler was sent the command new
12/08/2012 15:34:18;0040;PBS_Server;Svr;tyrone-cluster;Scheduler was sent the command new
12/08/2012 15:34:32;0040;PBS_Server;Svr;tyrone-cluster;Scheduler was sent the command new
12/08/2012 15:34:49;0040;PBS_Server;Svr;tyrone-cluster;Scheduler was sent the command new
12/08/2012 15:35:03;0040;PBS_Server;Svr;tyrone-cluster;Scheduler was sent the command new
12/08/2012 15:35:17;0040;PBS_Server;Svr;tyrone-cluster;Scheduler was sent the command new
12/08/2012 15:35:34;0040;PBS_Server;Svr;tyrone-cluster;Scheduler was sent the command new
12/08/2012 15:35:48;0040;PBS_Server;Svr;tyrone-cluster;Scheduler was sent the command new
12/08/2012 15:36:02;0040;PBS_Server;Svr;tyrone-cluster;Scheduler was sent the command new
12/08/2012 15:36:19;0040;PBS_Server;Svr;tyrone-cluster;Scheduler was sent the command new
12/08/2012 15:36:33;0040;PBS_Server;Svr;tyrone-cluster;Scheduler was sent the command new
12/08/2012 15:36:47;0040;PBS_Server;Svr;tyrone-cluster;Scheduler was sent the command new
12/08/2012 15:37:03;0040;PBS_Server;Svr;tyrone-cluster;Scheduler was sent the command new
12/08/2012 15:37:18;0040;PBS_Server;Svr;tyrone-cluster;Scheduler was sent the command new
12/08/2012 15:37:32;0040;PBS_Server;Svr;tyrone-cluster;Scheduler was sent the command new
12/08/2012 15:37:49;0040;PBS_Server;Svr;tyrone-cluster;Scheduler was sent the command new
12/08/2012 15:38:03;0040;PBS_Server;Svr;tyrone-cluster;Scheduler was sent the command new
12/08/2012 15:38:10;0002;PBS_Server;Svr;PBS_Server;Torque Server Version = 3.0.5, loglevel = 0
12/08/2012 15:38:17;0040;PBS_Server;Svr;tyrone-cluster;Scheduler was sent the command new
12/08/2012 15:38:34;0040;PBS_Server;Svr;tyrone-cluster;Scheduler was sent the command new
12/08/2012 15:38:48;0040;PBS_Server;Svr;tyrone-cluster;Scheduler was sent the command new
12/08/2012 15:39:02;0040;PBS_Server;Svr;tyrone-cluster;Scheduler was sent the command new
12/08/2012 15:39:18;0040;PBS_Server;Svr;tyrone-cluster;Scheduler was sent the command new
12/08/2012 15:39:33;0040;PBS_Server;Svr;tyrone-cluster;Scheduler was sent the command new
12/08/2012 15:39:47;0040;PBS_Server;Svr;tyrone-cluster;Scheduler was sent the command new
12/08/2012 15:40:04;0040;PBS_Server;Svr;tyrone-cluster;Scheduler was sent the command new
12/08/2012 15:40:18;0040;PBS_Server;Svr;tyrone-cluster;Scheduler was sent the command new
12/08/2012 15:40:32;0040;PBS_Server;Svr;tyrone-cluster;Scheduler was sent the command new
12/08/2012 15:40:49;0040;PBS_Server;Svr;tyrone-cluster;Scheduler was sent the command new
12/08/2012 15:41:03;0040;PBS_Server;Svr;tyrone-cluster;Scheduler was sent the command new
12/08/2012 15:41:17;0040;PBS_Server;Svr;tyrone-cluster;Scheduler was sent the command new
12/08/2012 15:41:33;0040;PBS_Server;Svr;tyrone-cluster;Scheduler was sent the command new
12/08/2012 15:41:48;0040;PBS_Server;Svr;tyrone-cluster;Scheduler was sent the command new
12/08/2012 15:42:02;0040;PBS_Server;Svr;tyrone-cluster;Scheduler was sent the command new
12/08/2012 15:42:19;0040;PBS_Server;Svr;tyrone-cluster;Scheduler was sent the command new
12/08/2012 15:42:33;0040;PBS_Server;Svr;tyrone-cluster;Scheduler was sent the command new
12/08/2012 15:42:47;0040;PBS_Server;Svr;tyrone-cluster;Scheduler was sent the command new
12/08/2012 15:43:04;0040;PBS_Server;Svr;tyrone-cluster;Scheduler was sent the command new
12/08/2012 15:43:10;0002;PBS_Server;Svr;PBS_Server;Torque Server Version = 3.0.5, loglevel = 0
12/08/2012 15:43:18;0040;PBS_Server;Svr;tyrone-cluster;Scheduler was sent the command new
12/08/2012 15:43:32;0040;PBS_Server;Svr;tyrone-cluster;Scheduler was sent the command new
12/08/2012 15:43:48;0040;PBS_Server;Svr;tyrone-cluster;Scheduler was sent the command new
12/08/2012 15:44:03;0040;PBS_Server;Svr;tyrone-cluster;Scheduler was sent the command new
12/08/2012 15:44:17;0040;PBS_Server;Svr;tyrone-cluster;Scheduler was sent the command new
12/08/2012 15:44:33;0040;PBS_Server;Svr;tyrone-cluster;Scheduler was sent the command new
12/08/2012 15:44:48;0040;PBS_Server;Svr;tyrone-cluster;Scheduler was sent the command new
12/08/2012 15:45:02;0040;PBS_Server;Svr;tyrone-cluster;Scheduler was sent the command new
12/08/2012 15:45:19;0040;PBS_Server;Svr;tyrone-cluster;Scheduler was sent the command new
12/08/2012 15:45:33;0040;PBS_Server;Svr;tyrone-cluster;Scheduler was sent the command new
12/08/2012 15:45:51;0040;PBS_Server;Svr;tyrone-cluster;Scheduler was sent the command new
12/08/2012 15:46:04;0040;PBS_Server;Svr;tyrone-cluster;Scheduler was sent the command new
12/08/2012 15:46:24;0040;PBS_Server;Svr;tyrone-cluster;Scheduler was sent the command new
12/08/2012 15:46:32;0040;PBS_Server;Svr;tyrone-cluster;Scheduler was sent the command new
12/08/2012 15:46:58;0040;PBS_Server;Svr;tyrone-cluster;Scheduler was sent the command new
12/08/2012 15:47:03;0040;PBS_Server;Svr;tyrone-cluster;Scheduler was sent the command new
12/08/2012 15:47:25;0040;PBS_Server;Svr;tyrone-cluster;Scheduler was sent the command new
12/08/2012 15:47:33;0040;PBS_Server;Svr;tyrone-cluster;Scheduler was sent the command new
12/08/2012 15:47:58;0040;PBS_Server;Svr;tyrone-cluster;Scheduler was sent the command new
12/08/2012 15:48:02;0040;PBS_Server;Svr;tyrone-cluster;Scheduler was sent the command new
12/08/2012 15:48:10;0002;PBS_Server;Svr;PBS_Server;Torque Server Version = 3.0.5, loglevel = 0
12/08/2012 15:48:28;0040;PBS_Server;Svr;tyrone-cluster;Scheduler was sent the command new
12/08/2012 15:48:33;0040;PBS_Server;Svr;tyrone-cluster;Scheduler was sent the command new
12/08/2012 15:48:58;0040;PBS_Server;Svr;tyrone-cluster;Scheduler was sent the command new
12/08/2012 15:49:04;0040;PBS_Server;Svr;tyrone-cluster;Scheduler was sent the command new
12/08/2012 15:49:30;0040;PBS_Server;Svr;tyrone-cluster;Scheduler was sent the command new
12/08/2012 15:49:32;0040;PBS_Server;Svr;tyrone-cluster;Scheduler was sent the command new
12/08/2012 15:49:58;0040;PBS_Server;Svr;tyrone-cluster;Scheduler was sent the command new
12/08/2012 15:50:03;0040;PBS_Server;Svr;tyrone-cluster;Scheduler was sent the command new
12/08/2012 15:50:28;0040;PBS_Server;Svr;tyrone-cluster;Scheduler was sent the command new
12/08/2012 15:50:34;0040;PBS_Server;Svr;tyrone-cluster;Scheduler was sent the command new
12/08/2012 15:50:59;0040;PBS_Server;Svr;tyrone-cluster;Scheduler was sent the command new
12/08/2012 15:51:02;0040;PBS_Server;Svr;tyrone-cluster;Scheduler was sent the command new
12/08/2012 15:51:28;0040;PBS_Server;Svr;tyrone-cluster;Scheduler was sent the command new
12/08/2012 15:51:33;0040;PBS_Server;Svr;tyrone-cluster;Scheduler was sent the command new
12/08/2012 15:51:58;0040;PBS_Server;Svr;tyrone-cluster;Scheduler was sent the command new
12/08/2012 15:52:03;0040;PBS_Server;Svr;tyrone-cluster;Scheduler was sent the command new
12/08/2012 15:52:30;0040;PBS_Server;Svr;tyrone-cluster;Scheduler was sent the command new
12/08/2012 15:52:32;0040;PBS_Server;Svr;tyrone-cluster;Scheduler was sent the command new
12/08/2012 15:52:58;0040;PBS_Server;Svr;tyrone-cluster;Scheduler was sent the command new
12/08/2012 15:53:03;0040;PBS_Server;Svr;tyrone-cluster;Scheduler was sent the command new
12/08/2012 15:53:10;0002;PBS_Server;Svr;PBS_Server;Torque Server Version = 3.0.5, loglevel = 0
12/08/2012 15:53:28;0040;PBS_Server;Svr;tyrone-cluster;Scheduler was sent the command new
12/08/2012 15:53:34;0040;PBS_Server;Svr;tyrone-cluster;Scheduler was sent the command new
12/08/2012 15:53:59;0040;PBS_Server;Svr;tyrone-cluster;Scheduler was sent the command new
12/08/2012 15:54:02;0040;PBS_Server;Svr;tyrone-cluster;Scheduler was sent the command new
12/08/2012 15:54:28;0040;PBS_Server;Svr;tyrone-cluster;Scheduler was sent the command new
12/08/2012 15:54:33;0040;PBS_Server;Svr;tyrone-cluster;Scheduler was sent the command new
12/08/2012 15:54:58;0040;PBS_Server;Svr;tyrone-cluster;Scheduler was sent the command new
12/08/2012 15:55:03;0040;PBS_Server;Svr;tyrone-cluster;Scheduler was sent the command new
12/08/2012 15:55:30;0040;PBS_Server;Svr;tyrone-cluster;Scheduler was sent the command new
12/08/2012 15:55:32;0040;PBS_Server;Svr;tyrone-cluster;Scheduler was sent the command new
12/08/2012 15:55:58;0040;PBS_Server;Svr;tyrone-cluster;Scheduler was sent the command new
12/08/2012 15:56:03;0040;PBS_Server;Svr;tyrone-cluster;Scheduler was sent the command new
12/08/2012 15:56:28;0040;PBS_Server;Svr;tyrone-cluster;Scheduler was sent the command new
12/08/2012 15:56:34;0040;PBS_Server;Svr;tyrone-cluster;Scheduler was sent the command new
12/08/2012 15:56:59;0040;PBS_Server;Svr;tyrone-cluster;Scheduler was sent the command new
12/08/2012 15:57:06;0040;PBS_Server;Svr;tyrone-cluster;Scheduler was sent the command new
12/08/2012 15:57:28;0040;PBS_Server;Svr;tyrone-cluster;Scheduler was sent the command new
12/08/2012 15:57:39;0040;PBS_Server;Svr;tyrone-cluster;Scheduler was sent the command new
12/08/2012 15:57:58;0040;PBS_Server;Svr;tyrone-cluster;Scheduler was sent the command new
12/08/2012 15:58:07;0040;PBS_Server;Svr;tyrone-cluster;Scheduler was sent the command new
12/08/2012 15:58:10;0002;PBS_Server;Svr;PBS_Server;Torque Server Version = 3.0.5, loglevel = 0
12/08/2012 15:58:30;0040;PBS_Server;Svr;tyrone-cluster;Scheduler was sent the command new
12/08/2012 15:58:36;0040;PBS_Server;Svr;tyrone-cluster;Scheduler was sent the command new
12/08/2012 15:58:58;0040;PBS_Server;Svr;tyrone-cluster;Scheduler was sent the command new
12/08/2012 15:59:12;0040;PBS_Server;Svr;tyrone-cluster;Scheduler was sent the command new
12/08/2012 15:59:28;0040;PBS_Server;Svr;tyrone-cluster;Scheduler was sent the command new
12/08/2012 15:59:43;0040;PBS_Server;Svr;tyrone-cluster;Scheduler was sent the command new
12/08/2012 16:00:00;0040;PBS_Server;Svr;tyrone-cluster;Scheduler was sent the command new
12/08/2012 16:00:10;0040;PBS_Server;Svr;tyrone-cluster;Scheduler was sent the command new
12/08/2012 16:00:28;0040;PBS_Server;Svr;tyrone-cluster;Scheduler was sent the command new
12/08/2012 16:00:43;0040;PBS_Server;Svr;tyrone-cluster;Scheduler was sent the command new
12/08/2012 16:00:58;0040;PBS_Server;Svr;tyrone-cluster;Scheduler was sent the command new
12/08/2012 16:01:13;0040;PBS_Server;Svr;tyrone-cluster;Scheduler was sent the command new
12/08/2012 16:01:29;0040;PBS_Server;Svr;tyrone-cluster;Scheduler was sent the command new
12/08/2012 16:01:43;0040;PBS_Server;Svr;tyrone-cluster;Scheduler was sent the command new
12/08/2012 16:01:58;0040;PBS_Server;Svr;tyrone-cluster;Scheduler was sent the command new
12/08/2012 16:02:14;0040;PBS_Server;Svr;tyrone-cluster;Scheduler was sent the command new
12/08/2012 16:02:28;0040;PBS_Server;Svr;tyrone-cluster;Scheduler was sent the command new
12/08/2012 16:02:43;0040;PBS_Server;Svr;tyrone-cluster;Scheduler was sent the command new
12/08/2012 16:03:00;0040;PBS_Server;Svr;tyrone-cluster;Scheduler was sent the command new
12/08/2012 16:03:10;0002;PBS_Server;Svr;PBS_Server;Torque Server Version = 3.0.5, loglevel = 0
12/08/2012 16:03:13;0040;PBS_Server;Svr;tyrone-cluster;Scheduler was sent the command new
12/08/2012 16:03:28;0040;PBS_Server;Svr;tyrone-cluster;Scheduler was sent the command new
12/08/2012 16:03:45;0040;PBS_Server;Svr;tyrone-cluster;Scheduler was sent the command new
12/08/2012 16:03:50;000d;PBS_Server;Job;16220.tyrone-cluster;Not sending email: User does not want mail of this type.
12/08/2012 16:03:50;0010;PBS_Server;Job;16220.tyrone-cluster;Exit_status=0 resources_used.cput=1309:24:42 resources_used.mem=7945576kb resources_used.vmem=14232748kb resources_used.walltime=21:21:12
12/08/2012 16:03:50;0008;PBS_Server;Job;NULL;on_job_exit valid pjob: 0x1b45ed0 (substate=50)
12/08/2012 16:03:50;0008;PBS_Server;Job;NULL;on_job_exit valid pjob: 0x1b45ed0 (substate=51)
12/08/2012 16:03:58;0100;PBS_Server;Job;16691.tyrone-cluster;dequeuing from batch, state QUEUED
12/08/2012 16:03:58;0100;PBS_Server;Job;16691.tyrone-cluster;enqueuing into qp64, state 1 hop 1
12/08/2012 16:03:58;0040;PBS_Server;Svr;tyrone-cluster;Scheduler was sent the command new
12/08/2012 16:03:59;0008;PBS_Server;Job;16661.tyrone-cluster;Job Modified at request of Scheduler@tyrone-cluster
12/08/2012 16:03:59;0008;PBS_Server;Job;16661.tyrone-cluster;Job Run at request of Scheduler@tyrone-cluster
12/08/2012 16:03:59;0008;PBS_Server;Job;16691.tyrone-cluster;Job Modified at request of Scheduler@tyrone-cluster
12/08/2012 16:03:59;000d;PBS_Server;Job;16661.tyrone-cluster;Not sending email: User does not want mail of this type.
12/08/2012 16:03:59;0040;PBS_Server;Svr;tyrone-cluster;Scheduler was sent the command recyc
12/08/2012 16:04:05;0008;PBS_Server;Job;NULL;on_job_exit valid pjob: 0x1b45ed0 (substate=51)
12/08/2012 16:04:05;000d;PBS_Server;Job;16220.tyrone-cluster;Post job file processing error; job 16220.tyrone-cluster on host tyrone-node13/63+tyrone-node13/62+tyrone-node13/61+tyrone-node13/60+tyrone-node13/59+tyrone-node13/58+tyrone-node13/57+tyrone-node13/56+tyrone-node13/55+tyrone-node13/54+tyrone-node13/53+tyrone-node13/52+tyrone-node13/51+tyrone-node13/50+tyrone-node13/49+tyrone-node13/48+tyrone-node13/47+tyrone-node13/46+tyrone-node13/45+tyrone-node13/44+tyrone-node13/43+tyrone-node13/42+tyrone-node13/41+tyrone-node13/40+tyrone-node13/39+tyrone-node13/38+tyrone-node13/37+tyrone-node13/36+tyrone-node13/35+tyrone-node13/34+tyrone-node13/33+tyrone-node13/32+tyrone-node13/31+tyrone-node13/30+tyrone-node13/29+tyrone-node13/28+tyrone-node13/27+tyrone-node13/26+tyrone-node13/25+tyrone-node13/24+tyrone-node13/23+tyrone-node13/22+tyrone-node13/21+tyrone-node13/20+tyrone-node13/19+tyrone-node13/18+tyrone-node13/17+tyrone-node13/16+tyrone-node13/15+tyrone-node13/14+tyrone-node13/13+tyrone-node13/12+tyrone-node13/11+tyrone-node13/10+tyrone-node13/9+tyrone-node13/8+tyrone-node13/7+tyrone-node13/6+tyrone-node13/5+tyrone-node13/4+tyrone-node13/3+tyrone-node13/2+tyrone-node13/1+tyrone-node13/0
12/08/2012 16:04:05;0008;PBS_Server;Job;NULL;on_job_exit valid pjob: 0x1b45ed0 (substate=53)
12/08/2012 16:04:05;0100;PBS_Server;Job;16220.tyrone-cluster;dequeuing from qp64, state COMPLETE
12/08/2012 16:04:05;0040;PBS_Server;Svr;tyrone-cluster;Scheduler was sent the command term
12/08/2012 16:04:13;0040;PBS_Server;Svr;tyrone-cluster;Scheduler was sent the command new
12/08/2012 16:04:30;0040;PBS_Server;Svr;tyrone-cluster;Scheduler was sent the command new
12/08/2012 16:04:43;0040;PBS_Server;Svr;tyrone-cluster;Scheduler was sent the command new
12/08/2012 16:04:58;0040;PBS_Server;Svr;tyrone-cluster;Scheduler was sent the command new
12/08/2012 16:05:14;0040;PBS_Server;Svr;tyrone-cluster;Scheduler was sent the command new
12/08/2012 16:05:28;0040;PBS_Server;Svr;tyrone-cluster;Scheduler was sent the command new
12/08/2012 16:05:43;0040;PBS_Server;Svr;tyrone-cluster;Scheduler was sent the command new
12/08/2012 16:05:59;0040;PBS_Server;Svr;tyrone-cluster;Scheduler was sent the command new
12/08/2012 16:06:13;0040;PBS_Server;Svr;tyrone-cluster;Scheduler was sent the command new
12/08/2012 16:06:28;0040;PBS_Server;Svr;tyrone-cluster;Scheduler was sent the command new
12/08/2012 16:06:45;0040;PBS_Server;Svr;tyrone-cluster;Scheduler was sent the command new
12/08/2012 16:06:58;0040;PBS_Server;Svr;tyrone-cluster;Scheduler was sent the command new
12/08/2012 16:07:13;0040;PBS_Server;Svr;tyrone-cluster;Scheduler was sent the command new
12/08/2012 16:07:29;0040;PBS_Server;Svr;tyrone-cluster;Scheduler was sent the command new
12/08/2012 16:07:43;0040;PBS_Server;Svr;tyrone-cluster;Scheduler was sent the command new
12/08/2012 16:07:58;0040;PBS_Server;Svr;tyrone-cluster;Scheduler was sent the command new
12/08/2012 16:08:10;0002;PBS_Server;Svr;PBS_Server;Torque Server Version = 3.0.5, loglevel = 0
12/08/2012 16:08:14;0040;PBS_Server;Svr;tyrone-cluster;Scheduler was sent the command new
12/08/2012 16:08:28;0040;PBS_Server;Svr;tyrone-cluster;Scheduler was sent the command new
12/08/2012 16:08:43;0040;PBS_Server;Svr;tyrone-cluster;Scheduler was sent the command new
12/08/2012 16:09:00;0040;PBS_Server;Svr;tyrone-cluster;Scheduler was sent the command new
12/08/2012 16:09:13;0040;PBS_Server;Svr;tyrone-cluster;Scheduler was sent the command new
12/08/2012 16:09:28;0040;PBS_Server;Svr;tyrone-cluster;Scheduler was sent the command new
12/08/2012 16:09:44;0040;PBS_Server;Svr;tyrone-cluster;Scheduler was sent the command new
12/08/2012 16:09:58;0040;PBS_Server;Svr;tyrone-cluster;Scheduler was sent the command new
12/08/2012 16:10:13;0040;PBS_Server;Svr;tyrone-cluster;Scheduler was sent the command new
12/08/2012 16:10:29;0040;PBS_Server;Svr;tyrone-cluster;Scheduler was sent the command new
12/08/2012 16:10:43;0040;PBS_Server;Svr;tyrone-cluster;Scheduler was sent the command new
12/08/2012 16:10:58;0040;PBS_Server;Svr;tyrone-cluster;Scheduler was sent the command new
12/08/2012 16:11:15;0040;PBS_Server;Svr;tyrone-cluster;Scheduler was sent the command new
12/08/2012 16:11:28;0040;PBS_Server;Svr;tyrone-cluster;Scheduler was sent the command new
12/08/2012 16:11:43;0040;PBS_Server;Svr;tyrone-cluster;Scheduler was sent the command new
12/08/2012 16:12:00;0040;PBS_Server;Svr;tyrone-cluster;Scheduler was sent the command new
12/08/2012 16:12:13;0040;PBS_Server;Svr;tyrone-cluster;Scheduler was sent the command new
12/08/2012 16:12:28;0040;PBS_Server;Svr;tyrone-cluster;Scheduler was sent the command new
12/08/2012 16:12:44;0040;PBS_Server;Svr;tyrone-cluster;Scheduler was sent the command new
12/08/2012 16:12:58;0040;PBS_Server;Svr;tyrone-cluster;Scheduler was sent the command new
12/08/2012 16:13:10;0002;PBS_Server;Svr;PBS_Server;Torque Server Version = 3.0.5, loglevel = 0
12/08/2012 16:13:13;0040;PBS_Server;Svr;tyrone-cluster;Scheduler was sent the command new
12/08/2012 16:13:30;0040;PBS_Server;Svr;tyrone-cluster;Scheduler was sent the command new
12/08/2012 16:13:43;0040;PBS_Server;Svr;tyrone-cluster;Scheduler was sent the command new
12/08/2012 16:13:58;0040;PBS_Server;Svr;tyrone-cluster;Scheduler was sent the command new
12/08/2012 16:14:15;0040;PBS_Server;Svr;tyrone-cluster;Scheduler was sent the command new
12/08/2012 16:14:28;0040;PBS_Server;Svr;tyrone-cluster;Scheduler was sent the command new
12/08/2012 16:14:43;0040;PBS_Server;Svr;tyrone-cluster;Scheduler was sent the command new
12/08/2012 16:14:59;0040;PBS_Server;Svr;tyrone-cluster;Scheduler was sent the command new
12/08/2012 16:15:13;0040;PBS_Server;Svr;tyrone-cluster;Scheduler was sent the command new
12/08/2012 16:15:28;0040;PBS_Server;Svr;tyrone-cluster;Scheduler was sent the command new
12/08/2012 16:15:44;0040;PBS_Server;Svr;tyrone-cluster;Scheduler was sent the command new
12/08/2012 16:15:58;0040;PBS_Server;Svr;tyrone-cluster;Scheduler was sent the command new
12/08/2012 16:16:13;0040;PBS_Server;Svr;tyrone-cluster;Scheduler was sent the command new
12/08/2012 16:16:30;0040;PBS_Server;Svr;tyrone-cluster;Scheduler was sent the command new
12/08/2012 16:16:43;0040;PBS_Server;Svr;tyrone-cluster;Scheduler was sent the command new
12/08/2012 16:16:58;0040;PBS_Server;Svr;tyrone-cluster;Scheduler was sent the command new
12/08/2012 16:17:15;0040;PBS_Server;Svr;tyrone-cluster;Scheduler was sent the command new
12/08/2012 16:17:28;0040;PBS_Server;Svr;tyrone-cluster;Scheduler was sent the command new
12/08/2012 16:17:43;0040;PBS_Server;Svr;tyrone-cluster;Scheduler was sent the command new
12/08/2012 16:17:59;0040;PBS_Server;Svr;tyrone-cluster;Scheduler was sent the command new
12/08/2012 16:18:10;0002;PBS_Server;Svr;PBS_Server;Torque Server Version = 3.0.5, loglevel = 0
12/08/2012 16:18:13;0040;PBS_Server;Svr;tyrone-cluster;Scheduler was sent the command new
12/08/2012 16:18:28;0040;PBS_Server;Svr;tyrone-cluster;Scheduler was sent the command new
12/08/2012 16:18:44;0040;PBS_Server;Svr;tyrone-cluster;Scheduler was sent the command new
12/08/2012 16:18:58;0040;PBS_Server;Svr;tyrone-cluster;Scheduler was sent the command new
12/08/2012 16:19:13;0040;PBS_Server;Svr;tyrone-cluster;Scheduler was sent the command new
12/08/2012 16:19:30;0040;PBS_Server;Svr;tyrone-cluster;Scheduler was sent the command new
12/08/2012 16:19:43;0040;PBS_Server;Svr;tyrone-cluster;Scheduler was sent the command new
12/08/2012 16:19:58;0040;PBS_Server;Svr;tyrone-cluster;Scheduler was sent the command new
12/08/2012 16:20:15;0040;PBS_Server;Svr;tyrone-cluster;Scheduler was sent the command new
12/08/2012 16:20:28;0040;PBS_Server;Svr;tyrone-cluster;Scheduler was sent the command new
12/08/2012 16:20:43;0040;PBS_Server;Svr;tyrone-cluster;Scheduler was sent the command new
12/08/2012 16:20:59;0040;PBS_Server;Svr;tyrone-cluster;Scheduler was sent the command new
12/08/2012 16:21:13;0040;PBS_Server;Svr;tyrone-cluster;Scheduler was sent the command new
12/08/2012 16:21:28;0040;PBS_Server;Svr;tyrone-cluster;Scheduler was sent the command new
12/08/2012 16:21:44;0040;PBS_Server;Svr;tyrone-cluster;Scheduler was sent the command new
12/08/2012 16:21:58;0040;PBS_Server;Svr;tyrone-cluster;Scheduler was sent the command new
12/08/2012 16:22:13;0040;PBS_Server;Svr;tyrone-cluster;Scheduler was sent the command new
12/08/2012 16:22:30;0040;PBS_Server;Svr;tyrone-cluster;Scheduler was sent the command new
12/08/2012 16:22:43;0040;PBS_Server;Svr;tyrone-cluster;Scheduler was sent the command new
12/08/2012 16:22:58;0040;PBS_Server;Svr;tyrone-cluster;Scheduler was sent the command new
12/08/2012 16:23:10;0002;PBS_Server;Svr;PBS_Server;Torque Server Version = 3.0.5, loglevel = 0
12/08/2012 16:23:14;0040;PBS_Server;Svr;tyrone-cluster;Scheduler was sent the command new
12/08/2012 16:23:28;0040;PBS_Server;Svr;tyrone-cluster;Scheduler was sent the command new
12/08/2012 16:23:43;0040;PBS_Server;Svr;tyrone-cluster;Scheduler was sent the command new
12/08/2012 16:23:59;0040;PBS_Server;Svr;tyrone-cluster;Scheduler was sent the command new
12/08/2012 16:24:13;0040;PBS_Server;Svr;tyrone-cluster;Scheduler was sent the command new
12/08/2012 16:24:28;0040;PBS_Server;Svr;tyrone-cluster;Scheduler was sent the command new
12/08/2012 16:24:45;0040;PBS_Server;Svr;tyrone-cluster;Scheduler was sent the command new
12/08/2012 16:24:58;0040;PBS_Server;Svr;tyrone-cluster;Scheduler was sent the command new
12/08/2012 16:25:13;0040;PBS_Server;Svr;tyrone-cluster;Scheduler was sent the command new
12/08/2012 16:25:29;0040;PBS_Server;Svr;tyrone-cluster;Scheduler was sent the command new
12/08/2012 16:25:43;0040;PBS_Server;Svr;tyrone-cluster;Scheduler was sent the command new
12/08/2012 16:25:58;0040;PBS_Server;Svr;tyrone-cluster;Scheduler was sent the command new
12/08/2012 16:26:14;0040;PBS_Server;Svr;tyrone-cluster;Scheduler was sent the command new
12/08/2012 16:26:28;0040;PBS_Server;Svr;tyrone-cluster;Scheduler was sent the command new
12/08/2012 16:26:43;0040;PBS_Server;Svr;tyrone-cluster;Scheduler was sent the command new
12/08/2012 16:27:00;0040;PBS_Server;Svr;tyrone-cluster;Scheduler was sent the command new
12/08/2012 16:27:13;0040;PBS_Server;Svr;tyrone-cluster;Scheduler was sent the command new
12/08/2012 16:27:28;0040;PBS_Server;Svr;tyrone-cluster;Scheduler was sent the command new
12/08/2012 16:27:44;0040;PBS_Server;Svr;tyrone-cluster;Scheduler was sent the command new
12/08/2012 16:27:58;0040;PBS_Server;Svr;tyrone-cluster;Scheduler was sent the command new
12/08/2012 16:28:10;0002;PBS_Server;Svr;PBS_Server;Torque Server Version = 3.0.5, loglevel = 0
12/08/2012 16:28:13;0040;PBS_Server;Svr;tyrone-cluster;Scheduler was sent the command new
12/08/2012 16:28:29;0040;PBS_Server;Svr;tyrone-cluster;Scheduler was sent the command new
12/08/2012 16:28:43;0040;PBS_Server;Svr;tyrone-cluster;Scheduler was sent the command new
12/08/2012 16:28:58;0040;PBS_Server;Svr;tyrone-cluster;Scheduler was sent the command new
12/08/2012 16:29:15;0040;PBS_Server;Svr;tyrone-cluster;Scheduler was sent the command new
12/08/2012 16:29:28;0040;PBS_Server;Svr;tyrone-cluster;Scheduler was sent the command new
12/08/2012 16:29:43;0040;PBS_Server;Svr;tyrone-cluster;Scheduler was sent the command new
12/08/2012 16:29:59;0040;PBS_Server;Svr;tyrone-cluster;Scheduler was sent the command new
12/08/2012 16:30:13;0040;PBS_Server;Svr;tyrone-cluster;Scheduler was sent the command new
12/08/2012 16:30:28;0040;PBS_Server;Svr;tyrone-cluster;Scheduler was sent the command new
12/08/2012 16:30:44;0040;PBS_Server;Svr;tyrone-cluster;Scheduler was sent the command new
12/08/2012 16:30:58;0040;PBS_Server;Svr;tyrone-cluster;Scheduler was sent the command new
12/08/2012 16:31:13;0040;PBS_Server;Svr;tyrone-cluster;Scheduler was sent the command new
12/08/2012 16:31:30;0040;PBS_Server;Svr;tyrone-cluster;Scheduler was sent the command new
12/08/2012 16:31:43;0040;PBS_Server;Svr;tyrone-cluster;Scheduler was sent the command new
12/08/2012 16:31:58;0040;PBS_Server;Svr;tyrone-cluster;Scheduler was sent the command new
12/08/2012 16:32:14;0040;PBS_Server;Svr;tyrone-cluster;Scheduler was sent the command new
12/08/2012 16:32:28;0040;PBS_Server;Svr;tyrone-cluster;Scheduler was sent the command new
12/08/2012 16:32:43;0040;PBS_Server;Svr;tyrone-cluster;Scheduler was sent the command new
12/08/2012 16:32:59;0040;PBS_Server;Svr;tyrone-cluster;Scheduler was sent the command new
12/08/2012 16:33:10;0002;PBS_Server;Svr;PBS_Server;Torque Server Version = 3.0.5, loglevel = 0
12/08/2012 16:33:13;0040;PBS_Server;Svr;tyrone-cluster;Scheduler was sent the command new
12/08/2012 16:33:28;0040;PBS_Server;Svr;tyrone-cluster;Scheduler was sent the command new
12/08/2012 16:33:44;0040;PBS_Server;Svr;tyrone-cluster;Scheduler was sent the command new
12/08/2012 16:33:58;0040;PBS_Server;Svr;tyrone-cluster;Scheduler was sent the command new
12/08/2012 16:34:13;0040;PBS_Server;Svr;tyrone-cluster;Scheduler was sent the command new
12/08/2012 16:34:30;0040;PBS_Server;Svr;tyrone-cluster;Scheduler was sent the command new
12/08/2012 16:34:43;0040;PBS_Server;Svr;tyrone-cluster;Scheduler was sent the command new
12/08/2012 16:34:58;0040;PBS_Server;Svr;tyrone-cluster;Scheduler was sent the command new
12/08/2012 16:35:14;0040;PBS_Server;Svr;tyrone-cluster;Scheduler was sent the command new
12/08/2012 16:35:28;0040;PBS_Server;Svr;tyrone-cluster;Scheduler was sent the command new
12/08/2012 16:35:43;0040;PBS_Server;Svr;tyrone-cluster;Scheduler was sent the command new
12/08/2012 16:35:59;0040;PBS_Server;Svr;tyrone-cluster;Scheduler was sent the command new
12/08/2012 16:36:13;0040;PBS_Server;Svr;tyrone-cluster;Scheduler was sent the command new
12/08/2012 16:36:28;0040;PBS_Server;Svr;tyrone-cluster;Scheduler was sent the command new
12/08/2012 16:36:45;0040;PBS_Server;Svr;tyrone-cluster;Scheduler was sent the command new
12/08/2012 16:36:58;0040;PBS_Server;Svr;tyrone-cluster;Scheduler was sent the command new
12/08/2012 16:37:13;0040;PBS_Server;Svr;tyrone-cluster;Scheduler was sent the command new
12/08/2012 16:37:30;0040;PBS_Server;Svr;tyrone-cluster;Scheduler was sent the command new
12/08/2012 16:37:43;0040;PBS_Server;Svr;tyrone-cluster;Scheduler was sent the command new
12/08/2012 16:37:58;0040;PBS_Server;Svr;tyrone-cluster;Scheduler was sent the command new
12/08/2012 16:38:10;0002;PBS_Server;Svr;PBS_Server;Torque Server Version = 3.0.5, loglevel = 0
12/08/2012 16:38:14;0040;PBS_Server;Svr;tyrone-cluster;Scheduler was sent the command new
12/08/2012 16:38:29;0040;PBS_Server;Svr;tyrone-cluster;Scheduler was sent the command new
12/08/2012 16:38:43;0040;PBS_Server;Svr;tyrone-cluster;Scheduler was sent the command new
12/08/2012 16:39:00;0040;PBS_Server;Svr;tyrone-cluster;Scheduler was sent the command new
12/08/2012 16:39:13;0040;PBS_Server;Svr;tyrone-cluster;Scheduler was sent the command new
12/08/2012 16:39:29;0040;PBS_Server;Svr;tyrone-cluster;Scheduler was sent the command new
12/08/2012 16:39:45;0040;PBS_Server;Svr;tyrone-cluster;Scheduler was sent the command new
12/08/2012 16:40:00;0040;PBS_Server;Svr;tyrone-cluster;Scheduler was sent the command new
12/08/2012 16:40:13;0040;PBS_Server;Svr;tyrone-cluster;Scheduler was sent the command new
12/08/2012 16:40:31;0040;PBS_Server;Svr;tyrone-cluster;Scheduler was sent the command new
12/08/2012 16:40:43;0040;PBS_Server;Svr;tyrone-cluster;Scheduler was sent the command new
12/08/2012 16:41:01;0040;PBS_Server;Svr;tyrone-cluster;Scheduler was sent the command new
12/08/2012 16:41:14;0040;PBS_Server;Svr;tyrone-cluster;Scheduler was sent the command new
12/08/2012 16:41:34;0040;PBS_Server;Svr;tyrone-cluster;Scheduler was sent the command new
12/08/2012 16:41:43;0040;PBS_Server;Svr;tyrone-cluster;Scheduler was sent the command new
12/08/2012 16:42:02;0040;PBS_Server;Svr;tyrone-cluster;Scheduler was sent the command new
12/08/2012 16:42:13;0040;PBS_Server;Svr;tyrone-cluster;Scheduler was sent the command new
12/08/2012 16:42:33;0040;PBS_Server;Svr;tyrone-cluster;Scheduler was sent the command new
12/08/2012 16:42:45;0040;PBS_Server;Svr;tyrone-cluster;Scheduler was sent the command new
12/08/2012 16:43:04;0040;PBS_Server;Svr;tyrone-cluster;Scheduler was sent the command new
12/08/2012 16:43:10;0002;PBS_Server;Svr;PBS_Server;Torque Server Version = 3.0.5, loglevel = 0
12/08/2012 16:43:13;0040;PBS_Server;Svr;tyrone-cluster;Scheduler was sent the command new
12/08/2012 16:43:35;0040;PBS_Server;Svr;tyrone-cluster;Scheduler was sent the command new
12/08/2012 16:43:43;0040;PBS_Server;Svr;tyrone-cluster;Scheduler was sent the command new
12/08/2012 16:44:07;0040;PBS_Server;Svr;tyrone-cluster;Scheduler was sent the command new
12/08/2012 16:44:14;0040;PBS_Server;Svr;tyrone-cluster;Scheduler was sent the command new
12/08/2012 16:44:38;0040;PBS_Server;Svr;tyrone-cluster;Scheduler was sent the command new
12/08/2012 16:44:43;0040;PBS_Server;Svr;tyrone-cluster;Scheduler was sent the command new
12/08/2012 16:45:10;0040;PBS_Server;Svr;tyrone-cluster;Scheduler was sent the command new
12/08/2012 16:45:13;0040;PBS_Server;Svr;tyrone-cluster;Scheduler was sent the command new
12/08/2012 16:45:43;0040;PBS_Server;Svr;tyrone-cluster;Scheduler was sent the command new
12/08/2012 16:46:13;0040;PBS_Server;Svr;tyrone-cluster;Scheduler was sent the command new
12/08/2012 16:46:43;0040;PBS_Server;Svr;tyrone-cluster;Scheduler was sent the command new
12/08/2012 16:47:14;0040;PBS_Server;Svr;tyrone-cluster;Scheduler was sent the command new
12/08/2012 16:47:43;0040;PBS_Server;Svr;tyrone-cluster;Scheduler was sent the command new
12/08/2012 16:48:10;0002;PBS_Server;Svr;PBS_Server;Torque Server Version = 3.0.5, loglevel = 0
12/08/2012 16:48:13;0040;PBS_Server;Svr;tyrone-cluster;Scheduler was sent the command new
12/08/2012 16:48:44;0040;PBS_Server;Svr;tyrone-cluster;Scheduler was sent the command new
12/08/2012 16:49:13;0040;PBS_Server;Svr;tyrone-cluster;Scheduler was sent the command new
12/08/2012 16:49:43;0040;PBS_Server;Svr;tyrone-cluster;Scheduler was sent the command new
12/08/2012 16:50:14;0040;PBS_Server;Svr;tyrone-cluster;Scheduler was sent the command new
12/08/2012 16:50:43;0040;PBS_Server;Svr;tyrone-cluster;Scheduler was sent the command new
12/08/2012 16:51:13;0040;PBS_Server;Svr;tyrone-cluster;Scheduler was sent the command new
12/08/2012 16:51:44;0040;PBS_Server;Svr;tyrone-cluster;Scheduler was sent the command new
12/08/2012 16:52:13;0040;PBS_Server;Svr;tyrone-cluster;Scheduler was sent the command new
12/08/2012 16:52:43;0040;PBS_Server;Svr;tyrone-cluster;Scheduler was sent the command new
12/08/2012 16:53:10;0002;PBS_Server;Svr;PBS_Server;Torque Server Version = 3.0.5, loglevel = 0
12/08/2012 16:53:14;0040;PBS_Server;Svr;tyrone-cluster;Scheduler was sent the command new
12/08/2012 16:53:43;0040;PBS_Server;Svr;tyrone-cluster;Scheduler was sent the command new
12/08/2012 16:54:13;0040;PBS_Server;Svr;tyrone-cluster;Scheduler was sent the command new
12/08/2012 16:54:44;0040;PBS_Server;Svr;tyrone-cluster;Scheduler was sent the command new
12/08/2012 16:54:53;0100;PBS_Server;Job;16768.tyrone-cluster;enqueuing into batch, state 1 hop 1
12/08/2012 16:54:53;0100;PBS_Server;Job;16768.tyrone-cluster;dequeuing from batch, state QUEUED
12/08/2012 16:54:53;0100;PBS_Server;Job;16768.tyrone-cluster;enqueuing into idqueue, state 1 hop 1
12/08/2012 16:54:53;0008;PBS_Server;Job;16768.tyrone-cluster;Job Queued at request of sscdds1@tyrone-cluster, owner = sscdds1@tyrone-cluster, job name = job, queue = idqueue
12/08/2012 16:54:53;0040;PBS_Server;Svr;tyrone-cluster;Scheduler was sent the command new
12/08/2012 16:54:54;0008;PBS_Server;Job;16768.tyrone-cluster;Job Modified at request of Scheduler@tyrone-cluster
12/08/2012 16:54:54;0008;PBS_Server;Job;16768.tyrone-cluster;Job Run at request of Scheduler@tyrone-cluster
12/08/2012 16:54:54;0040;PBS_Server;Svr;tyrone-cluster;Scheduler was sent the command recyc
12/08/2012 16:54:54;000d;PBS_Server;Job;16768.tyrone-cluster;Not sending email: User does not want mail of this type.
12/08/2012 16:55:13;0040;PBS_Server;Svr;tyrone-cluster;Scheduler was sent the command new
12/08/2012 16:55:43;0040;PBS_Server;Svr;tyrone-cluster;Scheduler was sent the command new
12/08/2012 16:56:14;0040;PBS_Server;Svr;tyrone-cluster;Scheduler was sent the command new
12/08/2012 16:56:43;0040;PBS_Server;Svr;tyrone-cluster;Scheduler was sent the command new
12/08/2012 16:57:13;0040;PBS_Server;Svr;tyrone-cluster;Scheduler was sent the command new
12/08/2012 16:57:44;0040;PBS_Server;Svr;tyrone-cluster;Scheduler was sent the command new
12/08/2012 16:58:10;0002;PBS_Server;Svr;PBS_Server;Torque Server Version = 3.0.5, loglevel = 0
12/08/2012 16:58:13;0040;PBS_Server;Svr;tyrone-cluster;Scheduler was sent the command new
12/08/2012 16:58:43;0040;PBS_Server;Svr;tyrone-cluster;Scheduler was sent the command new
12/08/2012 16:59:14;0040;PBS_Server;Svr;tyrone-cluster;Scheduler was sent the command new
12/08/2012 16:59:43;0040;PBS_Server;Svr;tyrone-cluster;Scheduler was sent the command new
12/08/2012 17:00:13;0040;PBS_Server;Svr;tyrone-cluster;Scheduler was sent the command new
12/08/2012 17:00:44;0040;PBS_Server;Svr;tyrone-cluster;Scheduler was sent the command new
12/08/2012 17:01:13;0040;PBS_Server;Svr;tyrone-cluster;Scheduler was sent the command new
12/08/2012 17:01:43;0040;PBS_Server;Svr;tyrone-cluster;Scheduler was sent the command new
12/08/2012 17:02:14;0040;PBS_Server;Svr;tyrone-cluster;Scheduler was sent the command new
12/08/2012 17:02:43;0040;PBS_Server;Svr;tyrone-cluster;Scheduler was sent the command new
12/08/2012 17:03:10;0002;PBS_Server;Svr;PBS_Server;Torque Server Version = 3.0.5, loglevel = 0
12/08/2012 17:03:13;0040;PBS_Server;Svr;tyrone-cluster;Scheduler was sent the command new
12/08/2012 17:03:44;0040;PBS_Server;Svr;tyrone-cluster;Scheduler was sent the command new
12/08/2012 17:04:13;0040;PBS_Server;Svr;tyrone-cluster;Scheduler was sent the command new
12/08/2012 17:04:43;0040;PBS_Server;Svr;tyrone-cluster;Scheduler was sent the command new
12/08/2012 17:05:14;0040;PBS_Server;Svr;tyrone-cluster;Scheduler was sent the command new
12/08/2012 17:05:43;0040;PBS_Server;Svr;tyrone-cluster;Scheduler was sent the command new
12/08/2012 17:06:13;0040;PBS_Server;Svr;tyrone-cluster;Scheduler was sent the command new
12/08/2012 17:06:44;0040;PBS_Server;Svr;tyrone-cluster;Scheduler was sent the command new
12/08/2012 17:07:13;0040;PBS_Server;Svr;tyrone-cluster;Scheduler was sent the command new
12/08/2012 17:07:43;0040;PBS_Server;Svr;tyrone-cluster;Scheduler was sent the command new
12/08/2012 17:08:07;0100;PBS_Server;Job;16769.tyrone-cluster;enqueuing into batch, state 1 hop 1
12/08/2012 17:08:07;0100;PBS_Server;Job;16769.tyrone-cluster;dequeuing from batch, state QUEUED
12/08/2012 17:08:07;0100;PBS_Server;Job;16769.tyrone-cluster;enqueuing into qp32, state 1 hop 1
12/08/2012 17:08:07;0008;PBS_Server;Job;16769.tyrone-cluster;Job Queued at request of csdsuben@tyrone-cluster, owner = csdsuben@tyrone-cluster, job name = ti-pen-alk2-ts-f1, queue = qp32
12/08/2012 17:08:07;0040;PBS_Server;Svr;tyrone-cluster;Scheduler was sent the command new
12/08/2012 17:08:07;0008;PBS_Server;Job;16769.tyrone-cluster;Job Modified at request of Scheduler@tyrone-cluster
12/08/2012 17:08:10;0002;PBS_Server;Svr;PBS_Server;Torque Server Version = 3.0.5, loglevel = 0
12/08/2012 17:08:15;0040;PBS_Server;Svr;tyrone-cluster;Scheduler was sent the command new
12/08/2012 17:08:32;0100;PBS_Server;Job;16770.tyrone-cluster;enqueuing into batch, state 1 hop 1
12/08/2012 17:08:32;0100;PBS_Server;Job;16770.tyrone-cluster;dequeuing from batch, state QUEUED
12/08/2012 17:08:32;0100;PBS_Server;Job;16770.tyrone-cluster;enqueuing into qp32, state 1 hop 1
12/08/2012 17:08:32;0008;PBS_Server;Job;16770.tyrone-cluster;Job Queued at request of csdsuben@tyrone-cluster, owner = csdsuben@tyrone-cluster, job name = ti-pen-alk2-ts-f2, queue = qp32
12/08/2012 17:08:32;0040;PBS_Server;Svr;tyrone-cluster;Scheduler was sent the command new
12/08/2012 17:08:32;0008;PBS_Server;Job;16770.tyrone-cluster;Job Modified at request of Scheduler@tyrone-cluster
12/08/2012 17:08:43;0040;PBS_Server;Svr;tyrone-cluster;Scheduler was sent the command new
12/08/2012 17:09:13;0040;PBS_Server;Svr;tyrone-cluster;Scheduler was sent the command new
12/08/2012 17:09:43;0040;PBS_Server;Svr;tyrone-cluster;Scheduler was sent the command new
12/08/2012 17:10:13;0040;PBS_Server;Svr;tyrone-cluster;Scheduler was sent the command new
12/08/2012 17:10:43;0040;PBS_Server;Svr;tyrone-cluster;Scheduler was sent the command new
12/08/2012 17:11:14;0040;PBS_Server;Svr;tyrone-cluster;Scheduler was sent the command new
12/08/2012 17:11:43;0040;PBS_Server;Svr;tyrone-cluster;Scheduler was sent the command new
12/08/2012 17:12:13;0040;PBS_Server;Svr;tyrone-cluster;Scheduler was sent the command new
12/08/2012 17:12:16;0100;PBS_Server;Job;16771.tyrone-cluster;enqueuing into batch, state 1 hop 1
12/08/2012 17:12:16;0008;PBS_Server;Job;16771.tyrone-cluster;Job Queued at request of csdsuben@tyrone-cluster, owner = csdsuben@tyrone-cluster, job name = zr-pen-alk2-ts-f1, queue = batch
12/08/2012 17:12:16;0040;PBS_Server;Svr;tyrone-cluster;Scheduler was sent the command new
12/08/2012 17:12:16;0008;PBS_Server;Job;16771.tyrone-cluster;Job Modified at request of Scheduler@tyrone-cluster
12/08/2012 17:12:44;0040;PBS_Server;Svr;tyrone-cluster;Scheduler was sent the command new
12/08/2012 17:12:45;0100;PBS_Server;Job;16772.tyrone-cluster;enqueuing into batch, state 1 hop 1
12/08/2012 17:12:45;0008;PBS_Server;Job;16772.tyrone-cluster;Job Queued at request of csdsuben@tyrone-cluster, owner = csdsuben@tyrone-cluster, job name = zr-pen-alk2-ts-f2, queue = batch
12/08/2012 17:12:45;0040;PBS_Server;Svr;tyrone-cluster;Scheduler was sent the command new
12/08/2012 17:12:45;0008;PBS_Server;Job;16772.tyrone-cluster;Job Modified at request of Scheduler@tyrone-cluster
12/08/2012 17:12:47;0040;PBS_Server;Svr;tyrone-cluster;Scheduler was sent the command new
12/08/2012 17:12:55;0008;PBS_Server;Job;16770.tyrone-cluster;Job deleted at request of csdsuben@tyrone-cluster
12/08/2012 17:12:55;0008;PBS_Server;Job;NULL;on_job_exit valid pjob: 0x1c2eb20 (substate=59)
12/08/2012 17:12:55;0100;PBS_Server;Job;16770.tyrone-cluster;dequeuing from qp32, state COMPLETE
12/08/2012 17:12:55;0040;PBS_Server;Svr;tyrone-cluster;Scheduler was sent the command term
12/08/2012 17:12:56;0080;PBS_Server;Job;16770.tyrone-cluster;Unknown Job Id
12/08/2012 17:12:56;0080;PBS_Server;Req;req_reject;Reject reply code=15001(Unknown Job Id), aux=0, type=DeleteJob, from csdsuben@tyrone-cluster
12/08/2012 17:12:56;0080;PBS_Server;Req;req_reject;Reject reply code=15001(Unknown Job Id), aux=0, type=LocateJob, from csdsuben@tyrone-cluster
12/08/2012 17:13:04;0100;PBS_Server;Job;16773.tyrone-cluster;enqueuing into batch, state 1 hop 1
12/08/2012 17:13:04;0100;PBS_Server;Job;16773.tyrone-cluster;dequeuing from batch, state QUEUED
12/08/2012 17:13:04;0100;PBS_Server;Job;16773.tyrone-cluster;enqueuing into qp32, state 1 hop 1
12/08/2012 17:13:04;0008;PBS_Server;Job;16773.tyrone-cluster;Job Queued at request of csdsuben@tyrone-cluster, owner = csdsuben@tyrone-cluster, job name = ti-pen-alk2-ts-f2, queue = qp32
12/08/2012 17:13:04;0040;PBS_Server;Svr;tyrone-cluster;Scheduler was sent the command new
12/08/2012 17:13:04;0008;PBS_Server;Job;16773.tyrone-cluster;Job Modified at request of Scheduler@tyrone-cluster
12/08/2012 17:13:10;0002;PBS_Server;Svr;PBS_Server;Torque Server Version = 3.0.5, loglevel = 0
12/08/2012 17:13:13;0040;PBS_Server;Svr;tyrone-cluster;Scheduler was sent the command new
12/08/2012 17:13:16;0040;PBS_Server;Svr;tyrone-cluster;Scheduler was sent the command new
12/08/2012 17:13:43;0040;PBS_Server;Svr;tyrone-cluster;Scheduler was sent the command new
12/08/2012 17:13:49;0040;PBS_Server;Svr;tyrone-cluster;Scheduler was sent the command new
12/08/2012 17:14:14;0040;PBS_Server;Svr;tyrone-cluster;Scheduler was sent the command new
12/08/2012 17:14:14;0100;PBS_Server;Job;16774.tyrone-cluster;enqueuing into batch, state 1 hop 1
12/08/2012 17:14:14;0100;PBS_Server;Job;16774.tyrone-cluster;dequeuing from batch, state QUEUED
12/08/2012 17:14:14;0100;PBS_Server;Job;16774.tyrone-cluster;enqueuing into qp32, state 1 hop 1
12/08/2012 17:14:14;0008;PBS_Server;Job;16774.tyrone-cluster;Job Queued at request of csddibye@tyrone-cluster, owner = csddibye@tyrone-cluster, job name = zr-cum-me, queue = qp32
12/08/2012 17:14:14;0040;PBS_Server;Svr;tyrone-cluster;Scheduler was sent the command new
12/08/2012 17:14:14;0008;PBS_Server;Job;16774.tyrone-cluster;Job Modified at request of Scheduler@tyrone-cluster
12/08/2012 17:14:16;0040;PBS_Server;Svr;tyrone-cluster;Scheduler was sent the command new
12/08/2012 17:14:43;0040;PBS_Server;Svr;tyrone-cluster;Scheduler was sent the command new
12/08/2012 17:14:46;0040;PBS_Server;Svr;tyrone-cluster;Scheduler was sent the command new
12/08/2012 17:15:13;0040;PBS_Server;Svr;tyrone-cluster;Scheduler was sent the command new
12/08/2012 17:15:19;0040;PBS_Server;Svr;tyrone-cluster;Scheduler was sent the command new
12/08/2012 17:15:24;0100;PBS_Server;Job;16775.tyrone-cluster;enqueuing into batch, state 1 hop 1
12/08/2012 17:15:24;0100;PBS_Server;Job;16775.tyrone-cluster;dequeuing from batch, state QUEUED
12/08/2012 17:15:24;0100;PBS_Server;Job;16775.tyrone-cluster;enqueuing into qp32, state 1 hop 1
12/08/2012 17:15:24;0008;PBS_Server;Job;16775.tyrone-cluster;Job Queued at request of csddibye@tyrone-cluster, owner = csddibye@tyrone-cluster, job name = ti-rad-me2, queue = qp32
12/08/2012 17:15:24;0040;PBS_Server;Svr;tyrone-cluster;Scheduler was sent the command new
12/08/2012 17:15:24;0008;PBS_Server;Job;16775.tyrone-cluster;Job Modified at request of Scheduler@tyrone-cluster
12/08/2012 17:15:44;0040;PBS_Server;Svr;tyrone-cluster;Scheduler was sent the command new
12/08/2012 17:15:50;0040;PBS_Server;Svr;tyrone-cluster;Scheduler was sent the command new
12/08/2012 17:15:51;0100;PBS_Server;Job;16776.tyrone-cluster;enqueuing into batch, state 1 hop 1
12/08/2012 17:15:51;0100;PBS_Server;Job;16776.tyrone-cluster;dequeuing from batch, state QUEUED
12/08/2012 17:15:51;0100;PBS_Server;Job;16776.tyrone-cluster;enqueuing into qp32, state 1 hop 1
12/08/2012 17:15:51;0008;PBS_Server;Job;16776.tyrone-cluster;Job Queued at request of csddibye@tyrone-cluster, owner = csddibye@tyrone-cluster, job name = ti-rad-me3, queue = qp32
12/08/2012 17:15:51;0040;PBS_Server;Svr;tyrone-cluster;Scheduler was sent the command new
12/08/2012 17:15:51;0008;PBS_Server;Job;16776.tyrone-cluster;Job Modified at request of Scheduler@tyrone-cluster
12/08/2012 17:16:13;0040;PBS_Server;Svr;tyrone-cluster;Scheduler was sent the command new
12/08/2012 17:16:22;0040;PBS_Server;Svr;tyrone-cluster;Scheduler was sent the command new
12/08/2012 17:16:22;0100;PBS_Server;Job;16777.tyrone-cluster;enqueuing into batch, state 1 hop 1
12/08/2012 17:16:22;0008;PBS_Server;Job;16777.tyrone-cluster;Job Queued at request of csddibye@tyrone-cluster, owner = csddibye@tyrone-cluster, job name = ti-rad-me4, queue = batch
12/08/2012 17:16:22;0008;PBS_Server;Job;16777.tyrone-cluster;Job Modified at request of Scheduler@tyrone-cluster
12/08/2012 17:16:43;0040;PBS_Server;Svr;tyrone-cluster;Scheduler was sent the command new
12/08/2012 17:16:49;0040;PBS_Server;Svr;tyrone-cluster;Scheduler was sent the command new
12/08/2012 17:16:53;0040;PBS_Server;Svr;tyrone-cluster;Scheduler was sent the command new
12/08/2012 17:17:13;0040;PBS_Server;Svr;tyrone-cluster;Scheduler was sent the command new
12/08/2012 17:17:20;0040;PBS_Server;Svr;tyrone-cluster;Scheduler was sent the command new
12/08/2012 17:17:24;0040;PBS_Server;Svr;tyrone-cluster;Scheduler was sent the command new
12/08/2012 17:17:43;0040;PBS_Server;Svr;tyrone-cluster;Scheduler was sent the command new
12/08/2012 17:17:52;0040;PBS_Server;Svr;tyrone-cluster;Scheduler was sent the command new
12/08/2012 17:17:58;0040;PBS_Server;Svr;tyrone-cluster;Scheduler was sent the command new
12/08/2012 17:18:10;0002;PBS_Server;Svr;PBS_Server;Torque Server Version = 3.0.5, loglevel = 0
12/08/2012 17:18:13;0040;PBS_Server;Svr;tyrone-cluster;Scheduler was sent the command new
12/08/2012 17:18:23;0040;PBS_Server;Svr;tyrone-cluster;Scheduler was sent the command new
12/08/2012 17:18:28;0040;PBS_Server;Svr;tyrone-cluster;Scheduler was sent the command new
12/08/2012 17:18:44;0040;PBS_Server;Svr;tyrone-cluster;Scheduler was sent the command new
12/08/2012 17:18:54;0040;PBS_Server;Svr;tyrone-cluster;Scheduler was sent the command new
12/08/2012 17:18:58;0040;PBS_Server;Svr;tyrone-cluster;Scheduler was sent the command new
12/08/2012 17:19:13;0040;PBS_Server;Svr;tyrone-cluster;Scheduler was sent the command new
12/08/2012 17:19:28;0040;PBS_Server;Svr;tyrone-cluster;Scheduler was sent the command new
12/08/2012 17:19:43;0040;PBS_Server;Svr;tyrone-cluster;Scheduler was sent the command new
12/08/2012 17:19:58;0040;PBS_Server;Svr;tyrone-cluster;Scheduler was sent the command new
12/08/2012 17:20:14;0040;PBS_Server;Svr;tyrone-cluster;Scheduler was sent the command new
12/08/2012 17:20:28;0040;PBS_Server;Svr;tyrone-cluster;Scheduler was sent the command new
12/08/2012 17:20:43;0040;PBS_Server;Svr;tyrone-cluster;Scheduler was sent the command new
12/08/2012 17:20:59;0040;PBS_Server;Svr;tyrone-cluster;Scheduler was sent the command new
12/08/2012 17:21:13;0040;PBS_Server;Svr;tyrone-cluster;Scheduler was sent the command new
12/08/2012 17:21:28;0040;PBS_Server;Svr;tyrone-cluster;Scheduler was sent the command new
12/08/2012 17:21:44;0040;PBS_Server;Svr;tyrone-cluster;Scheduler was sent the command new
12/08/2012 17:21:59;0040;PBS_Server;Svr;tyrone-cluster;Scheduler was sent the command new
12/08/2012 17:22:13;0040;PBS_Server;Svr;tyrone-cluster;Scheduler was sent the command new
12/08/2012 17:22:30;0040;PBS_Server;Svr;tyrone-cluster;Scheduler was sent the command new
12/08/2012 17:22:43;0040;PBS_Server;Svr;tyrone-cluster;Scheduler was sent the command new
12/08/2012 17:22:59;0040;PBS_Server;Svr;tyrone-cluster;Scheduler was sent the command new
12/08/2012 17:23:10;0002;PBS_Server;Svr;PBS_Server;Torque Server Version = 3.0.5, loglevel = 0
12/08/2012 17:23:14;0040;PBS_Server;Svr;tyrone-cluster;Scheduler was sent the command new
12/08/2012 17:23:30;0040;PBS_Server;Svr;tyrone-cluster;Scheduler was sent the command new
12/08/2012 17:23:43;0040;PBS_Server;Svr;tyrone-cluster;Scheduler was sent the command new
12/08/2012 17:24:01;0040;PBS_Server;Svr;tyrone-cluster;Scheduler was sent the command new
12/08/2012 17:24:13;0040;PBS_Server;Svr;tyrone-cluster;Scheduler was sent the command new
12/08/2012 17:24:31;0040;PBS_Server;Svr;tyrone-cluster;Scheduler was sent the command new
12/08/2012 17:24:44;0040;PBS_Server;Svr;tyrone-cluster;Scheduler was sent the command new
12/08/2012 17:25:03;0040;PBS_Server;Svr;tyrone-cluster;Scheduler was sent the command new
12/08/2012 17:25:13;0040;PBS_Server;Svr;tyrone-cluster;Scheduler was sent the command new
12/08/2012 17:25:34;0040;PBS_Server;Svr;tyrone-cluster;Scheduler was sent the command new
12/08/2012 17:25:43;0040;PBS_Server;Svr;tyrone-cluster;Scheduler was sent the command new
12/08/2012 17:26:07;0040;PBS_Server;Svr;tyrone-cluster;Scheduler was sent the command new
12/08/2012 17:26:14;0040;PBS_Server;Svr;tyrone-cluster;Scheduler was sent the command new
12/08/2012 17:26:38;0040;PBS_Server;Svr;tyrone-cluster;Scheduler was sent the command new
12/08/2012 17:26:43;0040;PBS_Server;Svr;tyrone-cluster;Scheduler was sent the command new
12/08/2012 17:27:09;0040;PBS_Server;Svr;tyrone-cluster;Scheduler was sent the command new
12/08/2012 17:27:13;0040;PBS_Server;Svr;tyrone-cluster;Scheduler was sent the command new
12/08/2012 17:27:42;0040;PBS_Server;Svr;tyrone-cluster;Scheduler was sent the command new
12/08/2012 17:28:10;0002;PBS_Server;Svr;PBS_Server;Torque Server Version = 3.0.5, loglevel = 0
12/08/2012 17:28:13;0040;PBS_Server;Svr;tyrone-cluster;Scheduler was sent the command new
12/08/2012 17:28:43;0040;PBS_Server;Svr;tyrone-cluster;Scheduler was sent the command new
12/08/2012 17:29:14;0040;PBS_Server;Svr;tyrone-cluster;Scheduler was sent the command new
12/08/2012 17:29:43;0040;PBS_Server;Svr;tyrone-cluster;Scheduler was sent the command new
12/08/2012 17:30:10;000d;PBS_Server;Job;16767.tyrone-cluster;Not sending email: User does not want mail of this type.
12/08/2012 17:30:10;0010;PBS_Server;Job;16767.tyrone-cluster;Exit_status=143 resources_used.cput=54:43:04 resources_used.mem=37935500kb resources_used.vmem=46114852kb resources_used.walltime=02:00:18
12/08/2012 17:30:10;0008;PBS_Server;Job;NULL;on_job_exit valid pjob: 0x1ba5550 (substate=50)
12/08/2012 17:30:10;0008;PBS_Server;Job;NULL;on_job_exit valid pjob: 0x1ba5550 (substate=51)
12/08/2012 17:30:10;0008;PBS_Server;Job;NULL;on_job_exit valid pjob: 0x1ba5550 (substate=51)
12/08/2012 17:30:10;0008;PBS_Server;Job;NULL;on_job_exit valid pjob: 0x1ba5550 (substate=53)
12/08/2012 17:30:10;0100;PBS_Server;Job;16767.tyrone-cluster;dequeuing from idqueue, state COMPLETE
12/08/2012 17:30:10;0040;PBS_Server;Svr;tyrone-cluster;Scheduler was sent the command term
12/08/2012 17:30:13;0040;PBS_Server;Svr;tyrone-cluster;Scheduler was sent the command new
12/08/2012 17:30:44;0040;PBS_Server;Svr;tyrone-cluster;Scheduler was sent the command new
12/08/2012 17:31:13;0040;PBS_Server;Svr;tyrone-cluster;Scheduler was sent the command new
12/08/2012 17:31:43;0040;PBS_Server;Svr;tyrone-cluster;Scheduler was sent the command new
12/08/2012 17:32:00;000d;PBS_Server;Job;16768.tyrone-cluster;Not sending email: User does not want mail of this type.
12/08/2012 17:32:00;0010;PBS_Server;Job;16768.tyrone-cluster;Exit_status=174 resources_used.cput=10:17:20 resources_used.mem=919200kb resources_used.vmem=10811788kb resources_used.walltime=00:37:05
12/08/2012 17:32:00;0008;PBS_Server;Job;NULL;on_job_exit valid pjob: 0x1b45ed0 (substate=50)
12/08/2012 17:32:00;0008;PBS_Server;Job;NULL;on_job_exit valid pjob: 0x1b45ed0 (substate=51)
12/08/2012 17:32:00;0008;PBS_Server;Job;NULL;on_job_exit valid pjob: 0x1b45ed0 (substate=51)
12/08/2012 17:32:00;0008;PBS_Server;Job;NULL;on_job_exit valid pjob: 0x1b45ed0 (substate=53)
12/08/2012 17:32:00;0100;PBS_Server;Job;16768.tyrone-cluster;dequeuing from idqueue, state COMPLETE
12/08/2012 17:32:00;0040;PBS_Server;Svr;tyrone-cluster;Scheduler was sent the command term
12/08/2012 17:32:14;0040;PBS_Server;Svr;tyrone-cluster;Scheduler was sent the command new
12/08/2012 17:32:40;000d;PBS_Server;Job;16308.tyrone-cluster;Not sending email: User does not want mail of this type.
12/08/2012 17:32:40;0010;PBS_Server;Job;16308.tyrone-cluster;Exit_status=143 resources_used.cput=1508:30:34 resources_used.mem=14643360kb resources_used.vmem=23155596kb resources_used.walltime=24:00:47
12/08/2012 17:32:40;0008;PBS_Server;Job;NULL;on_job_exit valid pjob: 0x1bb0180 (substate=50)
12/08/2012 17:32:40;0008;PBS_Server;Job;NULL;on_job_exit valid pjob: 0x1bb0180 (substate=51)
12/08/2012 17:32:40;0008;PBS_Server;Job;NULL;on_job_exit valid pjob: 0x1bb0180 (substate=51)
12/08/2012 17:32:40;0008;PBS_Server;Job;NULL;on_job_exit valid pjob: 0x1bb0180 (substate=53)
12/08/2012 17:32:40;0100;PBS_Server;Job;16308.tyrone-cluster;dequeuing from qp64, state COMPLETE
12/08/2012 17:32:40;0040;PBS_Server;Svr;tyrone-cluster;Scheduler was sent the command term
12/08/2012 17:32:40;0008;PBS_Server;Job;16576.tyrone-cluster;Job Modified at request of Scheduler@tyrone-cluster
12/08/2012 17:32:40;0008;PBS_Server;Job;16576.tyrone-cluster;Job Run at request of Scheduler@tyrone-cluster
12/08/2012 17:32:40;0040;PBS_Server;Svr;tyrone-cluster;Scheduler was sent the command recyc
12/08/2012 17:32:40;000d;PBS_Server;Job;16576.tyrone-cluster;Not sending email: User does not want mail of this type.
12/08/2012 17:32:43;0100;PBS_Server;Job;16766.tyrone-cluster;dequeuing from batch, state QUEUED
12/08/2012 17:32:43;0100;PBS_Server;Job;16766.tyrone-cluster;enqueuing into qp64, state 1 hop 1
12/08/2012 17:32:43;0040;PBS_Server;Svr;tyrone-cluster;Scheduler was sent the command new
12/08/2012 17:32:43;0008;PBS_Server;Job;16766.tyrone-cluster;Job Modified at request of Scheduler@tyrone-cluster
12/08/2012 17:33:10;0002;PBS_Server;Svr;PBS_Server;Torque Server Version = 3.0.5, loglevel = 0
12/08/2012 17:33:13;0040;PBS_Server;Svr;tyrone-cluster;Scheduler was sent the command new
12/08/2012 17:33:44;0040;PBS_Server;Svr;tyrone-cluster;Scheduler was sent the command new
12/08/2012 17:34:13;0040;PBS_Server;Svr;tyrone-cluster;Scheduler was sent the command new
12/08/2012 17:34:43;0040;PBS_Server;Svr;tyrone-cluster;Scheduler was sent the command new
12/08/2012 17:35:14;0040;PBS_Server;Svr;tyrone-cluster;Scheduler was sent the command new
12/08/2012 17:35:43;0040;PBS_Server;Svr;tyrone-cluster;Scheduler was sent the command new
12/08/2012 17:36:13;0040;PBS_Server;Svr;tyrone-cluster;Scheduler was sent the command new
12/08/2012 17:36:44;0040;PBS_Server;Svr;tyrone-cluster;Scheduler was sent the command new
12/08/2012 17:37:13;0040;PBS_Server;Svr;tyrone-cluster;Scheduler was sent the command new
12/08/2012 17:37:43;0040;PBS_Server;Svr;tyrone-cluster;Scheduler was sent the command new
12/08/2012 17:38:10;0002;PBS_Server;Svr;PBS_Server;Torque Server Version = 3.0.5, loglevel = 0
12/08/2012 17:38:14;0040;PBS_Server;Svr;tyrone-cluster;Scheduler was sent the command new
12/08/2012 17:38:43;0040;PBS_Server;Svr;tyrone-cluster;Scheduler was sent the command new
12/08/2012 17:39:13;0040;PBS_Server;Svr;tyrone-cluster;Scheduler was sent the command new
12/08/2012 17:39:44;0040;PBS_Server;Svr;tyrone-cluster;Scheduler was sent the command new
12/08/2012 17:40:13;0040;PBS_Server;Svr;tyrone-cluster;Scheduler was sent the command new
12/08/2012 17:40:43;0040;PBS_Server;Svr;tyrone-cluster;Scheduler was sent the command new
12/08/2012 17:41:14;0040;PBS_Server;Svr;tyrone-cluster;Scheduler was sent the command new
12/08/2012 17:41:43;0040;PBS_Server;Svr;tyrone-cluster;Scheduler was sent the command new
12/08/2012 17:42:13;0040;PBS_Server;Svr;tyrone-cluster;Scheduler was sent the command new
12/08/2012 17:42:44;0040;PBS_Server;Svr;tyrone-cluster;Scheduler was sent the command new
12/08/2012 17:43:10;0002;PBS_Server;Svr;PBS_Server;Torque Server Version = 3.0.5, loglevel = 0
12/08/2012 17:43:13;0040;PBS_Server;Svr;tyrone-cluster;Scheduler was sent the command new
12/08/2012 17:43:43;0040;PBS_Server;Svr;tyrone-cluster;Scheduler was sent the command new
12/08/2012 17:44:14;0040;PBS_Server;Svr;tyrone-cluster;Scheduler was sent the command new
12/08/2012 17:44:43;0040;PBS_Server;Svr;tyrone-cluster;Scheduler was sent the command new
12/08/2012 17:45:06;000d;PBS_Server;Job;16540.tyrone-cluster;Not sending email: User does not want mail of this type.
12/08/2012 17:45:06;0010;PBS_Server;Job;16540.tyrone-cluster;Exit_status=143 resources_used.cput=755:31:16 resources_used.mem=2284364kb resources_used.vmem=11044900kb resources_used.walltime=24:00:29
12/08/2012 17:45:06;0008;PBS_Server;Job;NULL;on_job_exit valid pjob: 0x1ba6ff0 (substate=50)
12/08/2012 17:45:06;0008;PBS_Server;Job;NULL;on_job_exit valid pjob: 0x1ba6ff0 (substate=51)
12/08/2012 17:45:11;0008;PBS_Server;Job;NULL;on_job_exit valid pjob: 0x1ba6ff0 (substate=51)
12/08/2012 17:45:11;000d;PBS_Server;Job;16540.tyrone-cluster;Post job file processing error; job 16540.tyrone-cluster on host tyrone-node8/31+tyrone-node8/30+tyrone-node8/29+tyrone-node8/28+tyrone-node8/27+tyrone-node8/26+tyrone-node8/25+tyrone-node8/24+tyrone-node8/23+tyrone-node8/22+tyrone-node8/21+tyrone-node8/20+tyrone-node8/19+tyrone-node8/18+tyrone-node8/17+tyrone-node8/16+tyrone-node8/15+tyrone-node8/14+tyrone-node8/13+tyrone-node8/12+tyrone-node8/11+tyrone-node8/10+tyrone-node8/9+tyrone-node8/8+tyrone-node8/7+tyrone-node8/6+tyrone-node8/5+tyrone-node8/4+tyrone-node8/3+tyrone-node8/2+tyrone-node8/1+tyrone-node8/0+tyrone-node7/31+tyrone-node7/30+tyrone-node7/29+tyrone-node7/28+tyrone-node7/27+tyrone-node7/26+tyrone-node7/25+tyrone-node7/24+tyrone-node7/23+tyrone-node7/22+tyrone-node7/21+tyrone-node7/20+tyrone-node7/19+tyrone-node7/18+tyrone-node7/17+tyrone-node7/16+tyrone-node7/15+tyrone-node7/14+tyrone-node7/13+tyrone-node7/12+tyrone-node7/11+tyrone-node7/10+tyrone-node7/9+tyrone-node7/8+tyrone-node7/7+tyrone-node7/6+tyrone-node7/5+tyrone-node7/4+tyrone-node7/3+tyrone-node7/2+tyrone-node7/1+tyrone-node7/0+tyrone-node6/31+tyrone-node6/30+tyrone-node6/29+tyrone-node6/28+tyrone-node6/27+tyrone-node6/26+tyrone-node6/25+tyrone-node6/24+tyrone-node6/23+tyrone-node6/22+tyrone-node6/21+tyrone-node6/20+tyrone-node6/19+tyrone-node6/18+tyrone-node6/17+tyrone-node6/16+tyrone-node6/15+tyrone-node6/14+tyrone-node6/13+tyrone-node6/12+tyrone-node6/11+tyrone-node6/10+tyrone-node6/9+tyrone-node6/8+tyrone-node6/7+tyrone-node6/6+tyrone-node6/5+tyrone-node6/4+tyrone-node6/3+tyrone-node6/2+tyrone-node6/1+tyrone-node6/0+tyrone-node5/31+tyrone-node5/30+tyrone-node5/29+tyrone-node5/28+tyrone-node5/27+tyrone-node5/26+tyrone-node5/25+tyrone-node5/24+tyrone-node5/23+tyrone-node5/22+tyrone-node5/21+tyrone-node5/20+tyrone-node5/19+tyrone-node5/18+tyrone-node5/17+tyrone-node5/16+tyrone-node5/15+tyrone-node5/14+tyrone-node5/13+tyrone-node5/12+tyrone-node5/11+tyrone-node5/10+tyrone-node5/9+tyrone-node5/8+tyrone-node5/7+tyrone-node5/6+tyrone-node5/5+tyrone-node5/4+tyrone-node5/3+tyrone-node5/2+tyrone-node5/1+tyrone-node5/0
12/08/2012 17:45:11;0008;PBS_Server;Job;NULL;on_job_exit valid pjob: 0x1ba6ff0 (substate=53)
12/08/2012 17:45:11;0100;PBS_Server;Job;16540.tyrone-cluster;dequeuing from qp256, state COMPLETE
12/08/2012 17:45:11;0040;PBS_Server;Svr;tyrone-cluster;Scheduler was sent the command term
12/08/2012 17:45:11;0008;PBS_Server;Job;16731.tyrone-cluster;Job Modified at request of Scheduler@tyrone-cluster
12/08/2012 17:45:11;0008;PBS_Server;Job;16731.tyrone-cluster;Job Run at request of Scheduler@tyrone-cluster
12/08/2012 17:45:11;0008;PBS_Server;Job;16754.tyrone-cluster;Job Modified at request of Scheduler@tyrone-cluster
12/08/2012 17:45:11;0008;PBS_Server;Job;16754.tyrone-cluster;Job Run at request of Scheduler@tyrone-cluster
12/08/2012 17:45:13;0040;PBS_Server;Svr;tyrone-cluster;Scheduler was sent the command new
12/08/2012 17:45:45;0040;PBS_Server;Svr;tyrone-cluster;Scheduler was sent the command new
12/08/2012 17:46:09;000d;PBS_Server;Job;16731.tyrone-cluster;Not sending email: User does not want mail of this type.
12/08/2012 17:46:10;000d;PBS_Server;Job;16754.tyrone-cluster;Not sending email: User does not want mail of this type.
12/08/2012 17:46:16;0040;PBS_Server;Svr;tyrone-cluster;Scheduler was sent the command new
12/08/2012 17:46:49;0040;PBS_Server;Svr;tyrone-cluster;Scheduler was sent the command new
12/08/2012 17:47:20;0040;PBS_Server;Svr;tyrone-cluster;Scheduler was sent the command new
12/08/2012 17:47:50;0040;PBS_Server;Svr;tyrone-cluster;Scheduler was sent the command new
12/08/2012 17:48:10;0002;PBS_Server;Svr;PBS_Server;Torque Server Version = 3.0.5, loglevel = 0
12/08/2012 17:48:23;0040;PBS_Server;Svr;tyrone-cluster;Scheduler was sent the command new
12/08/2012 17:48:55;0040;PBS_Server;Svr;tyrone-cluster;Scheduler was sent the command new
12/08/2012 17:49:28;0040;PBS_Server;Svr;tyrone-cluster;Scheduler was sent the command new
12/08/2012 17:50:01;0040;PBS_Server;Svr;tyrone-cluster;Scheduler was sent the command new
12/08/2012 17:50:33;0040;PBS_Server;Svr;tyrone-cluster;Scheduler was sent the command new
12/08/2012 17:51:05;0040;PBS_Server;Svr;tyrone-cluster;Scheduler was sent the command new
12/08/2012 17:51:35;0040;PBS_Server;Svr;tyrone-cluster;Scheduler was sent the command new
12/08/2012 17:52:08;0040;PBS_Server;Svr;tyrone-cluster;Scheduler was sent the command new
12/08/2012 17:52:40;0040;PBS_Server;Svr;tyrone-cluster;Scheduler was sent the command new
12/08/2012 17:53:10;0002;PBS_Server;Svr;PBS_Server;Torque Server Version = 3.0.5, loglevel = 0
12/08/2012 17:53:12;0040;PBS_Server;Svr;tyrone-cluster;Scheduler was sent the command new
12/08/2012 17:53:40;0040;PBS_Server;Svr;tyrone-cluster;Scheduler was sent the command new
12/08/2012 17:54:10;0040;PBS_Server;Svr;tyrone-cluster;Scheduler was sent the command new
12/08/2012 17:54:43;0040;PBS_Server;Svr;tyrone-cluster;Scheduler was sent the command new
12/08/2012 17:55:16;0040;PBS_Server;Svr;tyrone-cluster;Scheduler was sent the command new
12/08/2012 17:55:48;0040;PBS_Server;Svr;tyrone-cluster;Scheduler was sent the command new
12/08/2012 17:56:20;0040;PBS_Server;Svr;tyrone-cluster;Scheduler was sent the command new
12/08/2012 17:56:50;0040;PBS_Server;Svr;tyrone-cluster;Scheduler was sent the command new
12/08/2012 17:57:23;0040;PBS_Server;Svr;tyrone-cluster;Scheduler was sent the command new
12/08/2012 17:57:55;0040;PBS_Server;Svr;tyrone-cluster;Scheduler was sent the command new
12/08/2012 17:58:10;0002;PBS_Server;Svr;PBS_Server;Torque Server Version = 3.0.5, loglevel = 0
12/08/2012 17:58:28;0040;PBS_Server;Svr;tyrone-cluster;Scheduler was sent the command new
12/08/2012 17:59:01;0040;PBS_Server;Svr;tyrone-cluster;Scheduler was sent the command new
12/08/2012 17:59:34;0040;PBS_Server;Svr;tyrone-cluster;Scheduler was sent the command new
12/08/2012 18:00:05;0040;PBS_Server;Svr;tyrone-cluster;Scheduler was sent the command new
12/08/2012 18:00:35;0040;PBS_Server;Svr;tyrone-cluster;Scheduler was sent the command new
12/08/2012 18:01:08;0040;PBS_Server;Svr;tyrone-cluster;Scheduler was sent the command new
12/08/2012 18:01:40;0040;PBS_Server;Svr;tyrone-cluster;Scheduler was sent the command new
12/08/2012 18:02:13;0040;PBS_Server;Svr;tyrone-cluster;Scheduler was sent the command new
12/08/2012 18:02:46;0040;PBS_Server;Svr;tyrone-cluster;Scheduler was sent the command new
12/08/2012 18:03:10;0002;PBS_Server;Svr;PBS_Server;Torque Server Version = 3.0.5, loglevel = 0
12/08/2012 18:03:19;0040;PBS_Server;Svr;tyrone-cluster;Scheduler was sent the command new
12/08/2012 18:03:50;0040;PBS_Server;Svr;tyrone-cluster;Scheduler was sent the command new
12/08/2012 18:04:20;0040;PBS_Server;Svr;tyrone-cluster;Scheduler was sent the command new
12/08/2012 18:04:49;0040;PBS_Server;Svr;tyrone-cluster;Scheduler was sent the command new
12/08/2012 18:05:20;0040;PBS_Server;Svr;tyrone-cluster;Scheduler was sent the command new
12/08/2012 18:05:50;0040;PBS_Server;Svr;tyrone-cluster;Scheduler was sent the command new
12/08/2012 18:06:23;0040;PBS_Server;Svr;tyrone-cluster;Scheduler was sent the command new
12/08/2012 18:06:55;0040;PBS_Server;Svr;tyrone-cluster;Scheduler was sent the command new
12/08/2012 18:07:28;0040;PBS_Server;Svr;tyrone-cluster;Scheduler was sent the command new
12/08/2012 18:08:01;0040;PBS_Server;Svr;tyrone-cluster;Scheduler was sent the command new
12/08/2012 18:08:10;0002;PBS_Server;Svr;PBS_Server;Torque Server Version = 3.0.5, loglevel = 0
12/08/2012 18:08:33;0040;PBS_Server;Svr;tyrone-cluster;Scheduler was sent the command new
12/08/2012 18:09:04;0040;PBS_Server;Svr;tyrone-cluster;Scheduler was sent the command new
12/08/2012 18:09:35;0040;PBS_Server;Svr;tyrone-cluster;Scheduler was sent the command new
12/08/2012 18:10:08;0040;PBS_Server;Svr;tyrone-cluster;Scheduler was sent the command new
12/08/2012 18:10:40;0040;PBS_Server;Svr;tyrone-cluster;Scheduler was sent the command new
12/08/2012 18:11:13;0040;PBS_Server;Svr;tyrone-cluster;Scheduler was sent the command new
12/08/2012 18:11:46;0040;PBS_Server;Svr;tyrone-cluster;Scheduler was sent the command new
12/08/2012 18:12:18;0040;PBS_Server;Svr;tyrone-cluster;Scheduler was sent the command new
12/08/2012 18:12:50;0040;PBS_Server;Svr;tyrone-cluster;Scheduler was sent the command new
12/08/2012 18:13:10;0002;PBS_Server;Svr;PBS_Server;Torque Server Version = 3.0.5, loglevel = 0
12/08/2012 18:13:20;0040;PBS_Server;Svr;tyrone-cluster;Scheduler was sent the command new
12/08/2012 18:13:49;0040;PBS_Server;Svr;tyrone-cluster;Scheduler was sent the command new
12/08/2012 18:14:20;0040;PBS_Server;Svr;tyrone-cluster;Scheduler was sent the command new
12/08/2012 18:14:50;0040;PBS_Server;Svr;tyrone-cluster;Scheduler was sent the command new
12/08/2012 18:15:00;0100;PBS_Server;Job;16778.tyrone-cluster;enqueuing into batch, state 1 hop 1
12/08/2012 18:15:00;0100;PBS_Server;Job;16778.tyrone-cluster;dequeuing from batch, state QUEUED
12/08/2012 18:15:00;0100;PBS_Server;Job;16778.tyrone-cluster;enqueuing into idqueue, state 1 hop 1
12/08/2012 18:15:00;0008;PBS_Server;Job;16778.tyrone-cluster;Job Queued at request of mrcatanu@tyrone-cluster, owner = mrcatanu@tyrone-cluster, job name = TSSDI2, queue = idqueue
12/08/2012 18:15:00;0040;PBS_Server;Svr;tyrone-cluster;Scheduler was sent the command new
12/08/2012 18:15:00;0008;PBS_Server;Job;16778.tyrone-cluster;Job Modified at request of Scheduler@tyrone-cluster
12/08/2012 18:15:00;0008;PBS_Server;Job;16778.tyrone-cluster;Job Run at request of Scheduler@tyrone-cluster
12/08/2012 18:15:00;0040;PBS_Server;Svr;tyrone-cluster;Scheduler was sent the command recyc
12/08/2012 18:15:00;000d;PBS_Server;Job;16778.tyrone-cluster;Not sending email: User does not want mail of this type.
12/08/2012 18:15:15;000d;PBS_Server;Job;16778.tyrone-cluster;Not sending email: User does not want mail of this type.
12/08/2012 18:15:15;0010;PBS_Server;Job;16778.tyrone-cluster;Exit_status=174 resources_used.cput=00:06:30 resources_used.mem=577608kb resources_used.vmem=9133632kb resources_used.walltime=00:00:15
12/08/2012 18:15:15;0008;PBS_Server;Job;NULL;on_job_exit valid pjob: 0x1b45e70 (substate=50)
12/08/2012 18:15:15;0008;PBS_Server;Job;NULL;on_job_exit valid pjob: 0x1b45e70 (substate=51)
12/08/2012 18:15:15;0008;PBS_Server;Job;NULL;on_job_exit valid pjob: 0x1b45e70 (substate=51)
12/08/2012 18:15:15;0008;PBS_Server;Job;NULL;on_job_exit valid pjob: 0x1b45e70 (substate=53)
12/08/2012 18:15:15;0100;PBS_Server;Job;16778.tyrone-cluster;dequeuing from idqueue, state COMPLETE
12/08/2012 18:15:15;0040;PBS_Server;Svr;tyrone-cluster;Scheduler was sent the command term
12/08/2012 18:15:19;0040;PBS_Server;Svr;tyrone-cluster;Scheduler was sent the command new
12/08/2012 18:15:50;0040;PBS_Server;Svr;tyrone-cluster;Scheduler was sent the command new
12/08/2012 18:16:20;0040;PBS_Server;Svr;tyrone-cluster;Scheduler was sent the command new
12/08/2012 18:16:49;0040;PBS_Server;Svr;tyrone-cluster;Scheduler was sent the command new
12/08/2012 18:17:19;0040;PBS_Server;Svr;tyrone-cluster;Scheduler was sent the command new
12/08/2012 18:17:50;0040;PBS_Server;Svr;tyrone-cluster;Scheduler was sent the command new
12/08/2012 18:18:10;0002;PBS_Server;Svr;PBS_Server;Torque Server Version = 3.0.5, loglevel = 0
12/08/2012 18:18:19;0040;PBS_Server;Svr;tyrone-cluster;Scheduler was sent the command new
12/08/2012 18:18:50;0040;PBS_Server;Svr;tyrone-cluster;Scheduler was sent the command new
12/08/2012 18:19:20;0040;PBS_Server;Svr;tyrone-cluster;Scheduler was sent the command new
12/08/2012 18:19:49;0040;PBS_Server;Svr;tyrone-cluster;Scheduler was sent the command new
12/08/2012 18:20:20;0040;PBS_Server;Svr;tyrone-cluster;Scheduler was sent the command new
12/08/2012 18:20:50;0040;PBS_Server;Svr;tyrone-cluster;Scheduler was sent the command new
12/08/2012 18:21:23;0040;PBS_Server;Svr;tyrone-cluster;Scheduler was sent the command new
12/08/2012 18:21:55;0040;PBS_Server;Svr;tyrone-cluster;Scheduler was sent the command new
12/08/2012 18:22:28;0040;PBS_Server;Svr;tyrone-cluster;Scheduler was sent the command new
12/08/2012 18:22:58;0040;PBS_Server;Svr;tyrone-cluster;Scheduler was sent the command new
12/08/2012 18:23:10;0002;PBS_Server;Svr;PBS_Server;Torque Server Version = 3.0.5, loglevel = 0
12/08/2012 18:23:28;0040;PBS_Server;Svr;tyrone-cluster;Scheduler was sent the command new
12/08/2012 18:24:00;0040;PBS_Server;Svr;tyrone-cluster;Scheduler was sent the command new
12/08/2012 18:24:31;0040;PBS_Server;Svr;tyrone-cluster;Scheduler was sent the command new
12/08/2012 18:25:03;0040;PBS_Server;Svr;tyrone-cluster;Scheduler was sent the command new
12/08/2012 18:25:35;0040;PBS_Server;Svr;tyrone-cluster;Scheduler was sent the command new
12/08/2012 18:26:05;0040;PBS_Server;Svr;tyrone-cluster;Scheduler was sent the command new
12/08/2012 18:26:34;0040;PBS_Server;Svr;tyrone-cluster;Scheduler was sent the command new
12/08/2012 18:27:01;0100;PBS_Server;Job;16779.tyrone-cluster;enqueuing into batch, state 1 hop 1
12/08/2012 18:27:01;0100;PBS_Server;Job;16779.tyrone-cluster;dequeuing from batch, state QUEUED
12/08/2012 18:27:01;0100;PBS_Server;Job;16779.tyrone-cluster;enqueuing into idqueue, state 1 hop 1
12/08/2012 18:27:01;0008;PBS_Server;Job;16779.tyrone-cluster;Job Queued at request of sscdds1@tyrone-cluster, owner = sscdds1@tyrone-cluster, job name = job, queue = idqueue
12/08/2012 18:27:01;0040;PBS_Server;Svr;tyrone-cluster;Scheduler was sent the command new
12/08/2012 18:27:01;0008;PBS_Server;Job;16779.tyrone-cluster;Job Modified at request of Scheduler@tyrone-cluster
12/08/2012 18:27:01;0008;PBS_Server;Job;16779.tyrone-cluster;Job Run at request of Scheduler@tyrone-cluster
12/08/2012 18:27:01;0040;PBS_Server;Svr;tyrone-cluster;Scheduler was sent the command recyc
12/08/2012 18:27:01;000d;PBS_Server;Job;16779.tyrone-cluster;Not sending email: User does not want mail of this type.
12/08/2012 18:27:05;0040;PBS_Server;Svr;tyrone-cluster;Scheduler was sent the command new
12/08/2012 18:27:35;0040;PBS_Server;Svr;tyrone-cluster;Scheduler was sent the command new
12/08/2012 18:28:04;0040;PBS_Server;Svr;tyrone-cluster;Scheduler was sent the command new
12/08/2012 18:28:10;0002;PBS_Server;Svr;PBS_Server;Torque Server Version = 3.0.5, loglevel = 0
12/08/2012 18:28:35;0040;PBS_Server;Svr;tyrone-cluster;Scheduler was sent the command new
12/08/2012 18:29:05;0040;PBS_Server;Svr;tyrone-cluster;Scheduler was sent the command new
12/08/2012 18:29:34;0040;PBS_Server;Svr;tyrone-cluster;Scheduler was sent the command new
12/08/2012 18:30:05;0040;PBS_Server;Svr;tyrone-cluster;Scheduler was sent the command new
12/08/2012 18:30:35;0040;PBS_Server;Svr;tyrone-cluster;Scheduler was sent the command new
12/08/2012 18:30:42;000d;PBS_Server;Job;16779.tyrone-cluster;Not sending email: User does not want mail of this type.
12/08/2012 18:30:42;0010;PBS_Server;Job;16779.tyrone-cluster;Exit_status=0 resources_used.cput=01:53:58 resources_used.mem=1149068kb resources_used.vmem=11312464kb resources_used.walltime=00:03:41
12/08/2012 18:30:42;0008;PBS_Server;Job;NULL;on_job_exit valid pjob: 0x1ba6ff0 (substate=50)
12/08/2012 18:30:42;0008;PBS_Server;Job;NULL;on_job_exit valid pjob: 0x1ba6ff0 (substate=51)
12/08/2012 18:30:42;0008;PBS_Server;Job;NULL;on_job_exit valid pjob: 0x1ba6ff0 (substate=51)
12/08/2012 18:30:42;0008;PBS_Server;Job;NULL;on_job_exit valid pjob: 0x1ba6ff0 (substate=53)
12/08/2012 18:30:42;0100;PBS_Server;Job;16779.tyrone-cluster;dequeuing from idqueue, state COMPLETE
12/08/2012 18:30:42;0040;PBS_Server;Svr;tyrone-cluster;Scheduler was sent the command term
12/08/2012 18:31:04;0040;PBS_Server;Svr;tyrone-cluster;Scheduler was sent the command new
12/08/2012 18:31:35;0040;PBS_Server;Svr;tyrone-cluster;Scheduler was sent the command new
12/08/2012 18:32:05;0040;PBS_Server;Svr;tyrone-cluster;Scheduler was sent the command new
12/08/2012 18:32:38;0040;PBS_Server;Svr;tyrone-cluster;Scheduler was sent the command new
12/08/2012 18:33:09;0040;PBS_Server;Svr;tyrone-cluster;Scheduler was sent the command new
12/08/2012 18:33:10;0002;PBS_Server;Svr;PBS_Server;Torque Server Version = 3.0.5, loglevel = 0
12/08/2012 18:33:43;0040;PBS_Server;Svr;tyrone-cluster;Scheduler was sent the command new
12/08/2012 18:34:17;0040;PBS_Server;Svr;tyrone-cluster;Scheduler was sent the command new
12/08/2012 18:34:49;0040;PBS_Server;Svr;tyrone-cluster;Scheduler was sent the command new
12/08/2012 18:35:20;0040;PBS_Server;Svr;tyrone-cluster;Scheduler was sent the command new
12/08/2012 18:35:50;0040;PBS_Server;Svr;tyrone-cluster;Scheduler was sent the command new
12/08/2012 18:36:19;0040;PBS_Server;Svr;tyrone-cluster;Scheduler was sent the command new
12/08/2012 18:36:50;0040;PBS_Server;Svr;tyrone-cluster;Scheduler was sent the command new
12/08/2012 18:37:20;0040;PBS_Server;Svr;tyrone-cluster;Scheduler was sent the command new
12/08/2012 18:37:28;0100;PBS_Server;Job;16780.tyrone-cluster;enqueuing into batch, state 1 hop 1
12/08/2012 18:37:28;0100;PBS_Server;Job;16780.tyrone-cluster;dequeuing from batch, state QUEUED
12/08/2012 18:37:28;0100;PBS_Server;Job;16780.tyrone-cluster;enqueuing into idqueue, state 1 hop 1
12/08/2012 18:37:28;0008;PBS_Server;Job;16780.tyrone-cluster;Job Queued at request of sscdds1@tyrone-cluster, owner = sscdds1@tyrone-cluster, job name = job, queue = idqueue
12/08/2012 18:37:28;0040;PBS_Server;Svr;tyrone-cluster;Scheduler was sent the command new
12/08/2012 18:37:28;0008;PBS_Server;Job;16780.tyrone-cluster;Job Modified at request of Scheduler@tyrone-cluster
12/08/2012 18:37:28;0008;PBS_Server;Job;16780.tyrone-cluster;Job Run at request of Scheduler@tyrone-cluster
12/08/2012 18:37:28;0040;PBS_Server;Svr;tyrone-cluster;Scheduler was sent the command recyc
12/08/2012 18:37:28;000d;PBS_Server;Job;16780.tyrone-cluster;Not sending email: User does not want mail of this type.
12/08/2012 18:37:42;000d;PBS_Server;Job;16780.tyrone-cluster;Not sending email: User does not want mail of this type.
12/08/2012 18:37:42;0010;PBS_Server;Job;16780.tyrone-cluster;Exit_status=0 resources_used.cput=00:06:44 resources_used.mem=1258760kb resources_used.vmem=21537700kb resources_used.walltime=00:00:14
12/08/2012 18:37:42;0008;PBS_Server;Job;NULL;on_job_exit valid pjob: 0x1ba6ff0 (substate=50)
12/08/2012 18:37:42;0008;PBS_Server;Job;NULL;on_job_exit valid pjob: 0x1ba6ff0 (substate=51)
12/08/2012 18:37:42;0008;PBS_Server;Job;NULL;on_job_exit valid pjob: 0x1ba6ff0 (substate=51)
12/08/2012 18:37:42;0008;PBS_Server;Job;NULL;on_job_exit valid pjob: 0x1ba6ff0 (substate=53)
12/08/2012 18:37:42;0100;PBS_Server;Job;16780.tyrone-cluster;dequeuing from idqueue, state COMPLETE
12/08/2012 18:37:42;0040;PBS_Server;Svr;tyrone-cluster;Scheduler was sent the command term
12/08/2012 18:37:49;0040;PBS_Server;Svr;tyrone-cluster;Scheduler was sent the command new
12/08/2012 18:38:10;0002;PBS_Server;Svr;PBS_Server;Torque Server Version = 3.0.5, loglevel = 0
12/08/2012 18:38:19;0040;PBS_Server;Svr;tyrone-cluster;Scheduler was sent the command new
12/08/2012 18:38:50;0040;PBS_Server;Svr;tyrone-cluster;Scheduler was sent the command new
12/08/2012 18:39:19;0040;PBS_Server;Svr;tyrone-cluster;Scheduler was sent the command new
12/08/2012 18:39:50;0040;PBS_Server;Svr;tyrone-cluster;Scheduler was sent the command new
12/08/2012 18:40:20;0040;PBS_Server;Svr;tyrone-cluster;Scheduler was sent the command new
12/08/2012 18:40:49;0040;PBS_Server;Svr;tyrone-cluster;Scheduler was sent the command new
12/08/2012 18:41:20;0040;PBS_Server;Svr;tyrone-cluster;Scheduler was sent the command new
12/08/2012 18:41:50;0040;PBS_Server;Svr;tyrone-cluster;Scheduler was sent the command new
12/08/2012 18:42:19;0040;PBS_Server;Svr;tyrone-cluster;Scheduler was sent the command new
12/08/2012 18:42:50;0040;PBS_Server;Svr;tyrone-cluster;Scheduler was sent the command new
12/08/2012 18:43:10;0002;PBS_Server;Svr;PBS_Server;Torque Server Version = 3.0.5, loglevel = 0
12/08/2012 18:43:20;0040;PBS_Server;Svr;tyrone-cluster;Scheduler was sent the command new
12/08/2012 18:43:49;0040;PBS_Server;Svr;tyrone-cluster;Scheduler was sent the command new
12/08/2012 18:44:20;0040;PBS_Server;Svr;tyrone-cluster;Scheduler was sent the command new
12/08/2012 18:44:26;0100;PBS_Server;Job;16781.tyrone-cluster;enqueuing into batch, state 1 hop 1
12/08/2012 18:44:26;0100;PBS_Server;Job;16781.tyrone-cluster;dequeuing from batch, state QUEUED
12/08/2012 18:44:26;0100;PBS_Server;Job;16781.tyrone-cluster;enqueuing into idqueue, state 1 hop 1
12/08/2012 18:44:26;0008;PBS_Server;Job;16781.tyrone-cluster;Job Queued at request of sscdds1@tyrone-cluster, owner = sscdds1@tyrone-cluster, job name = job, queue = idqueue
12/08/2012 18:44:26;0040;PBS_Server;Svr;tyrone-cluster;Scheduler was sent the command new
12/08/2012 18:44:26;0008;PBS_Server;Job;16781.tyrone-cluster;Job Modified at request of Scheduler@tyrone-cluster
12/08/2012 18:44:26;0008;PBS_Server;Job;16781.tyrone-cluster;Job Run at request of Scheduler@tyrone-cluster
12/08/2012 18:44:27;0040;PBS_Server;Svr;tyrone-cluster;Scheduler was sent the command recyc
12/08/2012 18:44:27;000d;PBS_Server;Job;16781.tyrone-cluster;Not sending email: User does not want mail of this type.
12/08/2012 18:44:50;0040;PBS_Server;Svr;tyrone-cluster;Scheduler was sent the command new
12/08/2012 18:45:19;0040;PBS_Server;Svr;tyrone-cluster;Scheduler was sent the command new
12/08/2012 18:45:50;0040;PBS_Server;Svr;tyrone-cluster;Scheduler was sent the command new
12/08/2012 18:46:20;0040;PBS_Server;Svr;tyrone-cluster;Scheduler was sent the command new
12/08/2012 18:46:49;0040;PBS_Server;Svr;tyrone-cluster;Scheduler was sent the command new
12/08/2012 18:47:20;0040;PBS_Server;Svr;tyrone-cluster;Scheduler was sent the command new
12/08/2012 18:47:50;0040;PBS_Server;Svr;tyrone-cluster;Scheduler was sent the command new
12/08/2012 18:48:10;0002;PBS_Server;Svr;PBS_Server;Torque Server Version = 3.0.5, loglevel = 0
12/08/2012 18:48:23;0040;PBS_Server;Svr;tyrone-cluster;Scheduler was sent the command new
12/08/2012 18:48:55;0040;PBS_Server;Svr;tyrone-cluster;Scheduler was sent the command new
12/08/2012 18:49:29;0040;PBS_Server;Svr;tyrone-cluster;Scheduler was sent the command new
12/08/2012 18:50:01;0040;PBS_Server;Svr;tyrone-cluster;Scheduler was sent the command new
12/08/2012 18:50:33;0040;PBS_Server;Svr;tyrone-cluster;Scheduler was sent the command new
12/08/2012 18:51:04;0040;PBS_Server;Svr;tyrone-cluster;Scheduler was sent the command new
12/08/2012 18:51:33;0040;PBS_Server;Svr;tyrone-cluster;Scheduler was sent the command new
12/08/2012 18:52:03;0040;PBS_Server;Svr;tyrone-cluster;Scheduler was sent the command new
12/08/2012 18:52:35;0040;PBS_Server;Svr;tyrone-cluster;Scheduler was sent the command new
12/08/2012 18:53:05;0040;PBS_Server;Svr;tyrone-cluster;Scheduler was sent the command new
12/08/2012 18:53:10;0002;PBS_Server;Svr;PBS_Server;Torque Server Version = 3.0.5, loglevel = 0
12/08/2012 18:53:34;0040;PBS_Server;Svr;tyrone-cluster;Scheduler was sent the command new
12/08/2012 18:54:05;0040;PBS_Server;Svr;tyrone-cluster;Scheduler was sent the command new
12/08/2012 18:54:35;0040;PBS_Server;Svr;tyrone-cluster;Scheduler was sent the command new
12/08/2012 18:55:08;0040;PBS_Server;Svr;tyrone-cluster;Scheduler was sent the command new
12/08/2012 18:55:40;0040;PBS_Server;Svr;tyrone-cluster;Scheduler was sent the command new
12/08/2012 18:56:13;0040;PBS_Server;Svr;tyrone-cluster;Scheduler was sent the command new
12/08/2012 18:56:46;0040;PBS_Server;Svr;tyrone-cluster;Scheduler was sent the command new
12/08/2012 18:57:18;0040;PBS_Server;Svr;tyrone-cluster;Scheduler was sent the command new
12/08/2012 18:57:50;0040;PBS_Server;Svr;tyrone-cluster;Scheduler was sent the command new
12/08/2012 18:58:10;0002;PBS_Server;Svr;PBS_Server;Torque Server Version = 3.0.5, loglevel = 0
12/08/2012 18:58:20;0040;PBS_Server;Svr;tyrone-cluster;Scheduler was sent the command new
12/08/2012 18:58:49;0040;PBS_Server;Svr;tyrone-cluster;Scheduler was sent the command new
12/08/2012 18:59:20;0040;PBS_Server;Svr;tyrone-cluster;Scheduler was sent the command new
12/08/2012 18:59:50;0040;PBS_Server;Svr;tyrone-cluster;Scheduler was sent the command new
12/08/2012 19:00:13;0100;PBS_Server;Job;16782.tyrone-cluster;enqueuing into batch, state 1 hop 1
12/08/2012 19:00:13;0008;PBS_Server;Job;16782.tyrone-cluster;Job Queued at request of ipcvrk@tyrone-cluster, owner = ipcvrk@tyrone-cluster, job name = pq6.cmd, queue = batch
12/08/2012 19:00:13;0040;PBS_Server;Svr;tyrone-cluster;Scheduler was sent the command new
12/08/2012 19:00:13;0008;PBS_Server;Job;16782.tyrone-cluster;Job Modified at request of Scheduler@tyrone-cluster
12/08/2012 19:00:19;0040;PBS_Server;Svr;tyrone-cluster;Scheduler was sent the command new
12/08/2012 19:00:45;0040;PBS_Server;Svr;tyrone-cluster;Scheduler was sent the command new
12/08/2012 19:00:49;0040;PBS_Server;Svr;tyrone-cluster;Scheduler was sent the command new
12/08/2012 19:01:16;0040;PBS_Server;Svr;tyrone-cluster;Scheduler was sent the command new
12/08/2012 19:01:20;0040;PBS_Server;Svr;tyrone-cluster;Scheduler was sent the command new
12/08/2012 19:01:48;0040;PBS_Server;Svr;tyrone-cluster;Scheduler was sent the command new
12/08/2012 19:01:53;0040;PBS_Server;Svr;tyrone-cluster;Scheduler was sent the command new
12/08/2012 19:02:20;0040;PBS_Server;Svr;tyrone-cluster;Scheduler was sent the command new
12/08/2012 19:02:50;0040;PBS_Server;Svr;tyrone-cluster;Scheduler was sent the command new
12/08/2012 19:02:59;0040;PBS_Server;Svr;tyrone-cluster;Scheduler was sent the command new
12/08/2012 19:03:10;0002;PBS_Server;Svr;PBS_Server;Torque Server Version = 3.0.5, loglevel = 0
12/08/2012 19:03:19;0040;PBS_Server;Svr;tyrone-cluster;Scheduler was sent the command new
12/08/2012 19:03:31;0040;PBS_Server;Svr;tyrone-cluster;Scheduler was sent the command new
12/08/2012 19:03:50;0040;PBS_Server;Svr;tyrone-cluster;Scheduler was sent the command new
12/08/2012 19:04:03;0040;PBS_Server;Svr;tyrone-cluster;Scheduler was sent the command new
12/08/2012 19:04:20;0040;PBS_Server;Svr;tyrone-cluster;Scheduler was sent the command new
12/08/2012 19:04:34;0040;PBS_Server;Svr;tyrone-cluster;Scheduler was sent the command new
12/08/2012 19:04:53;0040;PBS_Server;Svr;tyrone-cluster;Scheduler was sent the command new
12/08/2012 19:05:03;0040;PBS_Server;Svr;tyrone-cluster;Scheduler was sent the command new
12/08/2012 19:05:25;0040;PBS_Server;Svr;tyrone-cluster;Scheduler was sent the command new
12/08/2012 19:05:33;0040;PBS_Server;Svr;tyrone-cluster;Scheduler was sent the command new
12/08/2012 19:05:59;0040;PBS_Server;Svr;tyrone-cluster;Scheduler was sent the command new
12/08/2012 19:06:05;0040;PBS_Server;Svr;tyrone-cluster;Scheduler was sent the command new
12/08/2012 19:06:31;0040;PBS_Server;Svr;tyrone-cluster;Scheduler was sent the command new
12/08/2012 19:06:35;0040;PBS_Server;Svr;tyrone-cluster;Scheduler was sent the command new
12/08/2012 19:07:03;0040;PBS_Server;Svr;tyrone-cluster;Scheduler was sent the command new
12/08/2012 19:07:04;0040;PBS_Server;Svr;tyrone-cluster;Scheduler was sent the command new
12/08/2012 19:07:34;0040;PBS_Server;Svr;tyrone-cluster;Scheduler was sent the command new
12/08/2012 19:08:03;0040;PBS_Server;Svr;tyrone-cluster;Scheduler was sent the command new
12/08/2012 19:08:10;0002;PBS_Server;Svr;PBS_Server;Torque Server Version = 3.0.5, loglevel = 0
12/08/2012 19:08:33;0040;PBS_Server;Svr;tyrone-cluster;Scheduler was sent the command new
12/08/2012 19:08:34;0040;PBS_Server;Svr;tyrone-cluster;Scheduler was sent the command new
12/08/2012 19:09:05;0040;PBS_Server;Svr;tyrone-cluster;Scheduler was sent the command new
12/08/2012 19:09:35;0040;PBS_Server;Svr;tyrone-cluster;Scheduler was sent the command new
12/08/2012 19:10:04;0040;PBS_Server;Svr;tyrone-cluster;Scheduler was sent the command new
12/08/2012 19:10:35;0040;PBS_Server;Svr;tyrone-cluster;Scheduler was sent the command new
12/08/2012 19:11:05;0040;PBS_Server;Svr;tyrone-cluster;Scheduler was sent the command new
12/08/2012 19:11:34;0040;PBS_Server;Svr;tyrone-cluster;Scheduler was sent the command new
12/08/2012 19:12:04;0040;PBS_Server;Svr;tyrone-cluster;Scheduler was sent the command new
12/08/2012 19:12:34;0040;PBS_Server;Svr;tyrone-cluster;Scheduler was sent the command new
12/08/2012 19:13:04;0040;PBS_Server;Svr;tyrone-cluster;Scheduler was sent the command new
12/08/2012 19:13:10;0002;PBS_Server;Svr;PBS_Server;Torque Server Version = 3.0.5, loglevel = 0
12/08/2012 19:13:35;0040;PBS_Server;Svr;tyrone-cluster;Scheduler was sent the command new
12/08/2012 19:14:05;0040;PBS_Server;Svr;tyrone-cluster;Scheduler was sent the command new
12/08/2012 19:14:34;0040;PBS_Server;Svr;tyrone-cluster;Scheduler was sent the command new
12/08/2012 19:15:05;0040;PBS_Server;Svr;tyrone-cluster;Scheduler was sent the command new
12/08/2012 19:15:35;0040;PBS_Server;Svr;tyrone-cluster;Scheduler was sent the command new
12/08/2012 19:16:08;0040;PBS_Server;Svr;tyrone-cluster;Scheduler was sent the command new
12/08/2012 19:16:39;0040;PBS_Server;Svr;tyrone-cluster;Scheduler was sent the command new
12/08/2012 19:16:45;000d;PBS_Server;Job;16781.tyrone-cluster;Not sending email: User does not want mail of this type.
12/08/2012 19:16:45;0010;PBS_Server;Job;16781.tyrone-cluster;Exit_status=0 resources_used.cput=16:59:00 resources_used.mem=12823368kb resources_used.vmem=22909252kb resources_used.walltime=00:32:19
12/08/2012 19:16:45;0008;PBS_Server;Job;NULL;on_job_exit valid pjob: 0x1ba6ff0 (substate=50)
12/08/2012 19:16:45;0008;PBS_Server;Job;NULL;on_job_exit valid pjob: 0x1ba6ff0 (substate=51)
12/08/2012 19:16:45;0008;PBS_Server;Job;NULL;on_job_exit valid pjob: 0x1ba6ff0 (substate=51)
12/08/2012 19:16:45;0008;PBS_Server;Job;NULL;on_job_exit valid pjob: 0x1ba6ff0 (substate=53)
12/08/2012 19:16:45;0100;PBS_Server;Job;16781.tyrone-cluster;dequeuing from idqueue, state COMPLETE
12/08/2012 19:16:45;0040;PBS_Server;Svr;tyrone-cluster;Scheduler was sent the command term
12/08/2012 19:17:13;0040;PBS_Server;Svr;tyrone-cluster;Scheduler was sent the command new
12/08/2012 19:17:46;0040;PBS_Server;Svr;tyrone-cluster;Scheduler was sent the command new
12/08/2012 19:18:10;0002;PBS_Server;Svr;PBS_Server;Torque Server Version = 3.0.5, loglevel = 0
12/08/2012 19:18:18;0040;PBS_Server;Svr;tyrone-cluster;Scheduler was sent the command new
12/08/2012 19:18:49;0040;PBS_Server;Svr;tyrone-cluster;Scheduler was sent the command new
12/08/2012 19:19:19;0040;PBS_Server;Svr;tyrone-cluster;Scheduler was sent the command new
12/08/2012 19:19:34;0100;PBS_Server;Job;16783.tyrone-cluster;enqueuing into batch, state 1 hop 1
12/08/2012 19:19:34;0100;PBS_Server;Job;16783.tyrone-cluster;dequeuing from batch, state QUEUED
12/08/2012 19:19:34;0100;PBS_Server;Job;16783.tyrone-cluster;enqueuing into idqueue, state 1 hop 1
12/08/2012 19:19:34;0008;PBS_Server;Job;16783.tyrone-cluster;Job Queued at request of mrcatanu@tyrone-cluster, owner = mrcatanu@tyrone-cluster, job name = TSSDI, queue = idqueue
12/08/2012 19:19:34;0040;PBS_Server;Svr;tyrone-cluster;Scheduler was sent the command new
12/08/2012 19:19:35;0008;PBS_Server;Job;16783.tyrone-cluster;Job Modified at request of Scheduler@tyrone-cluster
12/08/2012 19:19:35;0008;PBS_Server;Job;16783.tyrone-cluster;Job Run at request of Scheduler@tyrone-cluster
12/08/2012 19:19:35;0040;PBS_Server;Svr;tyrone-cluster;Scheduler was sent the command recyc
12/08/2012 19:19:35;000d;PBS_Server;Job;16783.tyrone-cluster;Not sending email: User does not want mail of this type.
12/08/2012 19:19:49;0040;PBS_Server;Svr;tyrone-cluster;Scheduler was sent the command new
12/08/2012 19:19:56;000d;PBS_Server;Job;16783.tyrone-cluster;Not sending email: User does not want mail of this type.
12/08/2012 19:19:56;0010;PBS_Server;Job;16783.tyrone-cluster;Exit_status=174 resources_used.cput=00:10:18 resources_used.mem=558624kb resources_used.vmem=9044288kb resources_used.walltime=00:00:21
12/08/2012 19:19:56;0008;PBS_Server;Job;NULL;on_job_exit valid pjob: 0x1ba6ff0 (substate=50)
12/08/2012 19:19:56;0008;PBS_Server;Job;NULL;on_job_exit valid pjob: 0x1ba6ff0 (substate=51)
12/08/2012 19:19:56;0008;PBS_Server;Job;NULL;on_job_exit valid pjob: 0x1ba6ff0 (substate=51)
12/08/2012 19:19:56;0008;PBS_Server;Job;NULL;on_job_exit valid pjob: 0x1ba6ff0 (substate=53)
12/08/2012 19:19:56;0100;PBS_Server;Job;16783.tyrone-cluster;dequeuing from idqueue, state COMPLETE
12/08/2012 19:19:56;0040;PBS_Server;Svr;tyrone-cluster;Scheduler was sent the command term
12/08/2012 19:20:19;0040;PBS_Server;Svr;tyrone-cluster;Scheduler was sent the command new
12/08/2012 19:20:49;0040;PBS_Server;Svr;tyrone-cluster;Scheduler was sent the command new
12/08/2012 19:21:19;0040;PBS_Server;Svr;tyrone-cluster;Scheduler was sent the command new
12/08/2012 19:21:49;0040;PBS_Server;Svr;tyrone-cluster;Scheduler was sent the command new
12/08/2012 19:22:20;0040;PBS_Server;Svr;tyrone-cluster;Scheduler was sent the command new
12/08/2012 19:22:49;0040;PBS_Server;Svr;tyrone-cluster;Scheduler was sent the command new
12/08/2012 19:23:10;0002;PBS_Server;Svr;PBS_Server;Torque Server Version = 3.0.5, loglevel = 0
12/08/2012 19:23:20;0040;PBS_Server;Svr;tyrone-cluster;Scheduler was sent the command new
12/08/2012 19:23:50;0040;PBS_Server;Svr;tyrone-cluster;Scheduler was sent the command new
12/08/2012 19:24:23;0040;PBS_Server;Svr;tyrone-cluster;Scheduler was sent the command new
12/08/2012 19:24:54;0040;PBS_Server;Svr;tyrone-cluster;Scheduler was sent the command new
12/08/2012 19:25:16;0100;PBS_Server;Job;16784.tyrone-cluster;enqueuing into batch, state 1 hop 1
12/08/2012 19:25:16;0100;PBS_Server;Job;16784.tyrone-cluster;dequeuing from batch, state QUEUED
12/08/2012 19:25:16;0100;PBS_Server;Job;16784.tyrone-cluster;enqueuing into idqueue, state 1 hop 1
12/08/2012 19:25:16;0008;PBS_Server;Job;16784.tyrone-cluster;Job Queued at request of mrcatanu@tyrone-cluster, owner = mrcatanu@tyrone-cluster, job name = TSSDI, queue = idqueue
12/08/2012 19:25:16;0040;PBS_Server;Svr;tyrone-cluster;Scheduler was sent the command new
12/08/2012 19:25:16;0008;PBS_Server;Job;16784.tyrone-cluster;Job Modified at request of Scheduler@tyrone-cluster
12/08/2012 19:25:16;0008;PBS_Server;Job;16784.tyrone-cluster;Job Run at request of Scheduler@tyrone-cluster
12/08/2012 19:25:16;0040;PBS_Server;Svr;tyrone-cluster;Scheduler was sent the command recyc
12/08/2012 19:25:16;000d;PBS_Server;Job;16784.tyrone-cluster;Not sending email: User does not want mail of this type.
12/08/2012 19:25:29;0040;PBS_Server;Svr;tyrone-cluster;Scheduler was sent the command new
12/08/2012 19:26:01;0040;PBS_Server;Svr;tyrone-cluster;Scheduler was sent the command new
12/08/2012 19:26:33;0040;PBS_Server;Svr;tyrone-cluster;Scheduler was sent the command new
12/08/2012 19:27:05;0040;PBS_Server;Svr;tyrone-cluster;Scheduler was sent the command new
12/08/2012 19:27:35;0040;PBS_Server;Svr;tyrone-cluster;Scheduler was sent the command new
12/08/2012 19:28:04;0040;PBS_Server;Svr;tyrone-cluster;Scheduler was sent the command new
12/08/2012 19:28:10;0002;PBS_Server;Svr;PBS_Server;Torque Server Version = 3.0.5, loglevel = 0
12/08/2012 19:28:35;0040;PBS_Server;Svr;tyrone-cluster;Scheduler was sent the command new
12/08/2012 19:29:05;0040;PBS_Server;Svr;tyrone-cluster;Scheduler was sent the command new
12/08/2012 19:29:34;0040;PBS_Server;Svr;tyrone-cluster;Scheduler was sent the command new
12/08/2012 19:30:04;0040;PBS_Server;Svr;tyrone-cluster;Scheduler was sent the command new
12/08/2012 19:30:34;0040;PBS_Server;Svr;tyrone-cluster;Scheduler was sent the command new
12/08/2012 19:31:04;0040;PBS_Server;Svr;tyrone-cluster;Scheduler was sent the command new
12/08/2012 19:31:35;0040;PBS_Server;Svr;tyrone-cluster;Scheduler was sent the command new
12/08/2012 19:32:05;0040;PBS_Server;Svr;tyrone-cluster;Scheduler was sent the command new
12/08/2012 19:32:34;0040;PBS_Server;Svr;tyrone-cluster;Scheduler was sent the command new
12/08/2012 19:33:05;0040;PBS_Server;Svr;tyrone-cluster;Scheduler was sent the command new
12/08/2012 19:33:10;0002;PBS_Server;Svr;PBS_Server;Torque Server Version = 3.0.5, loglevel = 0
12/08/2012 19:33:34;0040;PBS_Server;Svr;tyrone-cluster;Scheduler was sent the command new
12/08/2012 19:34:04;0040;PBS_Server;Svr;tyrone-cluster;Scheduler was sent the command new
12/08/2012 19:34:34;0040;PBS_Server;Svr;tyrone-cluster;Scheduler was sent the command new
12/08/2012 19:35:05;0040;PBS_Server;Svr;tyrone-cluster;Scheduler was sent the command new
12/08/2012 19:35:34;0040;PBS_Server;Svr;tyrone-cluster;Scheduler was sent the command new
12/08/2012 19:36:05;0040;PBS_Server;Svr;tyrone-cluster;Scheduler was sent the command new
12/08/2012 19:36:30;0100;PBS_Server;Job;16785.tyrone-cluster;enqueuing into batch, state 1 hop 1
12/08/2012 19:36:30;0008;PBS_Server;Job;16785.tyrone-cluster;Job Queued at request of mrcatanu@tyrone-cluster, owner = mrcatanu@tyrone-cluster, job name = TSSD2, queue = batch
12/08/2012 19:36:30;0040;PBS_Server;Svr;tyrone-cluster;Scheduler was sent the command new
12/08/2012 19:36:30;0008;PBS_Server;Job;16785.tyrone-cluster;Job Modified at request of Scheduler@tyrone-cluster
12/08/2012 19:36:34;0040;PBS_Server;Svr;tyrone-cluster;Scheduler was sent the command new
12/08/2012 19:37:00;0040;PBS_Server;Svr;tyrone-cluster;Scheduler was sent the command new
12/08/2012 19:37:04;0040;PBS_Server;Svr;tyrone-cluster;Scheduler was sent the command new
12/08/2012 19:37:30;0040;PBS_Server;Svr;tyrone-cluster;Scheduler was sent the command new
12/08/2012 19:37:34;0040;PBS_Server;Svr;tyrone-cluster;Scheduler was sent the command new
12/08/2012 19:38:01;0040;PBS_Server;Svr;tyrone-cluster;Scheduler was sent the command new
12/08/2012 19:38:04;0040;PBS_Server;Svr;tyrone-cluster;Scheduler was sent the command new
12/08/2012 19:38:10;0002;PBS_Server;Svr;PBS_Server;Torque Server Version = 3.0.5, loglevel = 0
12/08/2012 19:38:26;0008;PBS_Server;Job;16785.tyrone-cluster;Job deleted at request of mrcatanu@tyrone-cluster
12/08/2012 19:38:26;0008;PBS_Server;Job;NULL;on_job_exit valid pjob: 0x1b5cf00 (substate=59)
12/08/2012 19:38:26;0100;PBS_Server;Job;16785.tyrone-cluster;dequeuing from batch, state COMPLETE
12/08/2012 19:38:26;0040;PBS_Server;Svr;tyrone-cluster;Scheduler was sent the command term
12/08/2012 19:38:34;0040;PBS_Server;Svr;tyrone-cluster;Scheduler was sent the command new
12/08/2012 19:38:46;0100;PBS_Server;Job;16786.tyrone-cluster;enqueuing into batch, state 1 hop 1
12/08/2012 19:38:46;0008;PBS_Server;Job;16786.tyrone-cluster;Job Queued at request of mrcatanu@tyrone-cluster, owner = mrcatanu@tyrone-cluster, job name = TSSD2, queue = batch
12/08/2012 19:38:46;0040;PBS_Server;Svr;tyrone-cluster;Scheduler was sent the command new
12/08/2012 19:38:46;0008;PBS_Server;Job;16786.tyrone-cluster;Job Modified at request of Scheduler@tyrone-cluster
12/08/2012 19:39:05;0040;PBS_Server;Svr;tyrone-cluster;Scheduler was sent the command new
12/08/2012 19:39:18;0040;PBS_Server;Svr;tyrone-cluster;Scheduler was sent the command new
12/08/2012 19:39:34;0040;PBS_Server;Svr;tyrone-cluster;Scheduler was sent the command new
12/08/2012 19:39:49;0040;PBS_Server;Svr;tyrone-cluster;Scheduler was sent the command new
12/08/2012 19:40:04;0040;PBS_Server;Svr;tyrone-cluster;Scheduler was sent the command new
12/08/2012 19:40:19;0040;PBS_Server;Svr;tyrone-cluster;Scheduler was sent the command new
12/08/2012 19:40:34;0040;PBS_Server;Svr;tyrone-cluster;Scheduler was sent the command new
12/08/2012 19:40:49;0040;PBS_Server;Svr;tyrone-cluster;Scheduler was sent the command new
12/08/2012 19:41:05;0040;PBS_Server;Svr;tyrone-cluster;Scheduler was sent the command new
12/08/2012 19:41:19;0040;PBS_Server;Svr;tyrone-cluster;Scheduler was sent the command new
12/08/2012 19:41:38;0040;PBS_Server;Svr;tyrone-cluster;Scheduler was sent the command new
12/08/2012 19:41:49;0040;PBS_Server;Svr;tyrone-cluster;Scheduler was sent the command new
12/08/2012 19:42:10;0040;PBS_Server;Svr;tyrone-cluster;Scheduler was sent the command new
12/08/2012 19:42:19;0040;PBS_Server;Svr;tyrone-cluster;Scheduler was sent the command new
12/08/2012 19:42:43;0040;PBS_Server;Svr;tyrone-cluster;Scheduler was sent the command new
12/08/2012 19:42:50;0040;PBS_Server;Svr;tyrone-cluster;Scheduler was sent the command new
12/08/2012 19:43:10;0002;PBS_Server;Svr;PBS_Server;Torque Server Version = 3.0.5, loglevel = 0
12/08/2012 19:43:16;0040;PBS_Server;Svr;tyrone-cluster;Scheduler was sent the command new
12/08/2012 19:43:19;0040;PBS_Server;Svr;tyrone-cluster;Scheduler was sent the command new
12/08/2012 19:43:48;0040;PBS_Server;Svr;tyrone-cluster;Scheduler was sent the command new
12/08/2012 19:43:49;0040;PBS_Server;Svr;tyrone-cluster;Scheduler was sent the command new
12/08/2012 19:44:19;0040;PBS_Server;Svr;tyrone-cluster;Scheduler was sent the command new
12/08/2012 19:44:49;0040;PBS_Server;Svr;tyrone-cluster;Scheduler was sent the command new
12/08/2012 19:45:18;0040;PBS_Server;Svr;tyrone-cluster;Scheduler was sent the command new
12/08/2012 19:45:19;0040;PBS_Server;Svr;tyrone-cluster;Scheduler was sent the command new
12/08/2012 19:45:49;0040;PBS_Server;Svr;tyrone-cluster;Scheduler was sent the command new
12/08/2012 19:46:19;0040;PBS_Server;Svr;tyrone-cluster;Scheduler was sent the command new
12/08/2012 19:46:48;0040;PBS_Server;Svr;tyrone-cluster;Scheduler was sent the command new
12/08/2012 19:46:49;0040;PBS_Server;Svr;tyrone-cluster;Scheduler was sent the command new
12/08/2012 19:47:19;0040;PBS_Server;Svr;tyrone-cluster;Scheduler was sent the command new
12/08/2012 19:47:49;0040;PBS_Server;Svr;tyrone-cluster;Scheduler was sent the command new
12/08/2012 19:48:10;0002;PBS_Server;Svr;PBS_Server;Torque Server Version = 3.0.5, loglevel = 0
12/08/2012 19:48:18;0040;PBS_Server;Svr;tyrone-cluster;Scheduler was sent the command new
12/08/2012 19:48:19;0040;PBS_Server;Svr;tyrone-cluster;Scheduler was sent the command new
12/08/2012 19:48:49;0040;PBS_Server;Svr;tyrone-cluster;Scheduler was sent the command new
12/08/2012 19:49:19;0040;PBS_Server;Svr;tyrone-cluster;Scheduler was sent the command new
12/08/2012 19:49:48;0040;PBS_Server;Svr;tyrone-cluster;Scheduler was sent the command new
12/08/2012 19:49:49;0040;PBS_Server;Svr;tyrone-cluster;Scheduler was sent the command new
12/08/2012 19:50:19;0040;PBS_Server;Svr;tyrone-cluster;Scheduler was sent the command new
12/08/2012 19:50:49;0040;PBS_Server;Svr;tyrone-cluster;Scheduler was sent the command new
12/08/2012 19:51:19;0040;PBS_Server;Svr;tyrone-cluster;Scheduler was sent the command new
12/08/2012 19:51:49;0040;PBS_Server;Svr;tyrone-cluster;Scheduler was sent the command new
12/08/2012 19:52:19;0040;PBS_Server;Svr;tyrone-cluster;Scheduler was sent the command new
12/08/2012 19:52:49;0040;PBS_Server;Svr;tyrone-cluster;Scheduler was sent the command new
12/08/2012 19:53:10;0002;PBS_Server;Svr;PBS_Server;Torque Server Version = 3.0.5, loglevel = 0
12/08/2012 19:53:20;0040;PBS_Server;Svr;tyrone-cluster;Scheduler was sent the command new
12/08/2012 19:53:49;0040;PBS_Server;Svr;tyrone-cluster;Scheduler was sent the command new
12/08/2012 19:54:19;0040;PBS_Server;Svr;tyrone-cluster;Scheduler was sent the command new
12/08/2012 19:54:49;0040;PBS_Server;Svr;tyrone-cluster;Scheduler was sent the command new
12/08/2012 19:55:19;0040;PBS_Server;Svr;tyrone-cluster;Scheduler was sent the command new
12/08/2012 19:55:49;0040;PBS_Server;Svr;tyrone-cluster;Scheduler was sent the command new
12/08/2012 19:56:20;0040;PBS_Server;Svr;tyrone-cluster;Scheduler was sent the command new
12/08/2012 19:56:49;0040;PBS_Server;Svr;tyrone-cluster;Scheduler was sent the command new
12/08/2012 19:57:19;0040;PBS_Server;Svr;tyrone-cluster;Scheduler was sent the command new
12/08/2012 19:57:54;0040;PBS_Server;Svr;tyrone-cluster;Scheduler was sent the command new
12/08/2012 19:58:10;0002;PBS_Server;Svr;PBS_Server;Torque Server Version = 3.0.5, loglevel = 0
12/08/2012 19:58:19;0040;PBS_Server;Svr;tyrone-cluster;Scheduler was sent the command new
12/08/2012 19:58:49;0040;PBS_Server;Svr;tyrone-cluster;Scheduler was sent the command new
12/08/2012 19:59:20;0040;PBS_Server;Svr;tyrone-cluster;Scheduler was sent the command new
12/08/2012 19:59:49;0040;PBS_Server;Svr;tyrone-cluster;Scheduler was sent the command new
12/08/2012 20:00:19;0040;PBS_Server;Svr;tyrone-cluster;Scheduler was sent the command new
12/08/2012 20:00:49;0040;PBS_Server;Svr;tyrone-cluster;Scheduler was sent the command new
12/08/2012 20:01:20;0040;PBS_Server;Svr;tyrone-cluster;Scheduler was sent the command new
12/08/2012 20:01:49;0040;PBS_Server;Svr;tyrone-cluster;Scheduler was sent the command new
12/08/2012 20:02:20;0040;PBS_Server;Svr;tyrone-cluster;Scheduler was sent the command new
12/08/2012 20:02:50;0040;PBS_Server;Svr;tyrone-cluster;Scheduler was sent the command new
12/08/2012 20:03:10;0002;PBS_Server;Svr;PBS_Server;Torque Server Version = 3.0.5, loglevel = 0
12/08/2012 20:03:23;0040;PBS_Server;Svr;tyrone-cluster;Scheduler was sent the command new
12/08/2012 20:03:54;0040;PBS_Server;Svr;tyrone-cluster;Scheduler was sent the command new
12/08/2012 20:04:28;0040;PBS_Server;Svr;tyrone-cluster;Scheduler was sent the command new
12/08/2012 20:05:01;0040;PBS_Server;Svr;tyrone-cluster;Scheduler was sent the command new
12/08/2012 20:05:33;0040;PBS_Server;Svr;tyrone-cluster;Scheduler was sent the command new
12/08/2012 20:06:05;0040;PBS_Server;Svr;tyrone-cluster;Scheduler was sent the command new
12/08/2012 20:06:34;0040;PBS_Server;Svr;tyrone-cluster;Scheduler was sent the command new
12/08/2012 20:07:02;0100;PBS_Server;Job;16787.tyrone-cluster;enqueuing into batch, state 1 hop 1
12/08/2012 20:07:02;0100;PBS_Server;Job;16787.tyrone-cluster;dequeuing from batch, state QUEUED
12/08/2012 20:07:02;0100;PBS_Server;Job;16787.tyrone-cluster;enqueuing into idqueue, state 1 hop 1
12/08/2012 20:07:02;0008;PBS_Server;Job;16787.tyrone-cluster;Job Queued at request of sscdds1@tyrone-cluster, owner = sscdds1@tyrone-cluster, job name = job, queue = idqueue
12/08/2012 20:07:02;0040;PBS_Server;Svr;tyrone-cluster;Scheduler was sent the command new
12/08/2012 20:07:02;0008;PBS_Server;Job;16787.tyrone-cluster;Job Modified at request of Scheduler@tyrone-cluster
12/08/2012 20:07:02;0008;PBS_Server;Job;16787.tyrone-cluster;Job Run at request of Scheduler@tyrone-cluster
12/08/2012 20:07:02;0040;PBS_Server;Svr;tyrone-cluster;Scheduler was sent the command recyc
12/08/2012 20:07:02;000d;PBS_Server;Job;16787.tyrone-cluster;Not sending email: User does not want mail of this type.
12/08/2012 20:07:03;0040;PBS_Server;Svr;tyrone-cluster;Scheduler was sent the command new
12/08/2012 20:07:35;0040;PBS_Server;Svr;tyrone-cluster;Scheduler was sent the command new
12/08/2012 20:08:04;0040;PBS_Server;Svr;tyrone-cluster;Scheduler was sent the command new
12/08/2012 20:08:10;0002;PBS_Server;Svr;PBS_Server;Torque Server Version = 3.0.5, loglevel = 0
12/08/2012 20:08:33;0040;PBS_Server;Svr;tyrone-cluster;Scheduler was sent the command new
12/08/2012 20:09:05;0040;PBS_Server;Svr;tyrone-cluster;Scheduler was sent the command new
12/08/2012 20:09:34;0040;PBS_Server;Svr;tyrone-cluster;Scheduler was sent the command new
12/08/2012 20:10:03;0040;PBS_Server;Svr;tyrone-cluster;Scheduler was sent the command new
12/08/2012 20:10:34;0040;PBS_Server;Svr;tyrone-cluster;Scheduler was sent the command new
12/08/2012 20:11:03;0040;PBS_Server;Svr;tyrone-cluster;Scheduler was sent the command new
12/08/2012 20:11:33;0040;PBS_Server;Svr;tyrone-cluster;Scheduler was sent the command new
12/08/2012 20:12:05;0040;PBS_Server;Svr;tyrone-cluster;Scheduler was sent the command new
12/08/2012 20:12:34;0040;PBS_Server;Svr;tyrone-cluster;Scheduler was sent the command new
12/08/2012 20:13:04;0040;PBS_Server;Svr;tyrone-cluster;Scheduler was sent the command new
12/08/2012 20:13:10;0002;PBS_Server;Svr;PBS_Server;Torque Server Version = 3.0.5, loglevel = 0
12/08/2012 20:13:34;0040;PBS_Server;Svr;tyrone-cluster;Scheduler was sent the command new
12/08/2012 20:14:04;0040;PBS_Server;Svr;tyrone-cluster;Scheduler was sent the command new
12/08/2012 20:14:33;0040;PBS_Server;Svr;tyrone-cluster;Scheduler was sent the command new
12/08/2012 20:15:05;0040;PBS_Server;Svr;tyrone-cluster;Scheduler was sent the command new
12/08/2012 20:15:34;0040;PBS_Server;Svr;tyrone-cluster;Scheduler was sent the command new
12/08/2012 20:16:03;0040;PBS_Server;Svr;tyrone-cluster;Scheduler was sent the command new
12/08/2012 20:16:35;0040;PBS_Server;Svr;tyrone-cluster;Scheduler was sent the command new
12/08/2012 20:17:04;0040;PBS_Server;Svr;tyrone-cluster;Scheduler was sent the command new
12/08/2012 20:17:34;0040;PBS_Server;Svr;tyrone-cluster;Scheduler was sent the command new
12/08/2012 20:18:05;0040;PBS_Server;Svr;tyrone-cluster;Scheduler was sent the command new
12/08/2012 20:18:10;0002;PBS_Server;Svr;PBS_Server;Torque Server Version = 3.0.5, loglevel = 0
12/08/2012 20:18:34;0040;PBS_Server;Svr;tyrone-cluster;Scheduler was sent the command new
12/08/2012 20:19:04;0040;PBS_Server;Svr;tyrone-cluster;Scheduler was sent the command new
12/08/2012 20:19:35;0040;PBS_Server;Svr;tyrone-cluster;Scheduler was sent the command new
12/08/2012 20:20:05;0040;PBS_Server;Svr;tyrone-cluster;Scheduler was sent the command new
12/08/2012 20:20:38;0040;PBS_Server;Svr;tyrone-cluster;Scheduler was sent the command new
12/08/2012 20:21:09;0040;PBS_Server;Svr;tyrone-cluster;Scheduler was sent the command new
12/08/2012 20:21:42;0040;PBS_Server;Svr;tyrone-cluster;Scheduler was sent the command new
12/08/2012 20:22:16;0040;PBS_Server;Svr;tyrone-cluster;Scheduler was sent the command new
12/08/2012 20:22:48;0040;PBS_Server;Svr;tyrone-cluster;Scheduler was sent the command new
12/08/2012 20:23:10;0002;PBS_Server;Svr;PBS_Server;Torque Server Version = 3.0.5, loglevel = 0
12/08/2012 20:23:20;0040;PBS_Server;Svr;tyrone-cluster;Scheduler was sent the command new
12/08/2012 20:23:49;0040;PBS_Server;Svr;tyrone-cluster;Scheduler was sent the command new
12/08/2012 20:24:19;0040;PBS_Server;Svr;tyrone-cluster;Scheduler was sent the command new
12/08/2012 20:24:49;0040;PBS_Server;Svr;tyrone-cluster;Scheduler was sent the command new
12/08/2012 20:25:19;0040;PBS_Server;Svr;tyrone-cluster;Scheduler was sent the command new
12/08/2012 20:25:49;0040;PBS_Server;Svr;tyrone-cluster;Scheduler was sent the command new
12/08/2012 20:26:20;0040;PBS_Server;Svr;tyrone-cluster;Scheduler was sent the command new
12/08/2012 20:26:50;0040;PBS_Server;Svr;tyrone-cluster;Scheduler was sent the command new
12/08/2012 20:27:23;0040;PBS_Server;Svr;tyrone-cluster;Scheduler was sent the command new
12/08/2012 20:27:54;0040;PBS_Server;Svr;tyrone-cluster;Scheduler was sent the command new
12/08/2012 20:28:10;0002;PBS_Server;Svr;PBS_Server;Torque Server Version = 3.0.5, loglevel = 0
12/08/2012 20:28:27;0040;PBS_Server;Svr;tyrone-cluster;Scheduler was sent the command new
12/08/2012 20:29:01;0040;PBS_Server;Svr;tyrone-cluster;Scheduler was sent the command new
12/08/2012 20:29:33;0040;PBS_Server;Svr;tyrone-cluster;Scheduler was sent the command new
12/08/2012 20:30:04;0040;PBS_Server;Svr;tyrone-cluster;Scheduler was sent the command new
12/08/2012 20:30:33;0040;PBS_Server;Svr;tyrone-cluster;Scheduler was sent the command new
12/08/2012 20:31:04;0040;PBS_Server;Svr;tyrone-cluster;Scheduler was sent the command new
12/08/2012 20:31:34;0040;PBS_Server;Svr;tyrone-cluster;Scheduler was sent the command new
12/08/2012 20:32:03;0040;PBS_Server;Svr;tyrone-cluster;Scheduler was sent the command new
12/08/2012 20:32:34;0040;PBS_Server;Svr;tyrone-cluster;Scheduler was sent the command new
12/08/2012 20:33:05;0040;PBS_Server;Svr;tyrone-cluster;Scheduler was sent the command new
12/08/2012 20:33:10;0002;PBS_Server;Svr;PBS_Server;Torque Server Version = 3.0.5, loglevel = 0
12/08/2012 20:33:34;0040;PBS_Server;Svr;tyrone-cluster;Scheduler was sent the command new
12/08/2012 20:34:04;0040;PBS_Server;Svr;tyrone-cluster;Scheduler was sent the command new
12/08/2012 20:34:35;0040;PBS_Server;Svr;tyrone-cluster;Scheduler was sent the command new
12/08/2012 20:35:05;0040;PBS_Server;Svr;tyrone-cluster;Scheduler was sent the command new
12/08/2012 20:35:34;0040;PBS_Server;Svr;tyrone-cluster;Scheduler was sent the command new
12/08/2012 20:36:05;0040;PBS_Server;Svr;tyrone-cluster;Scheduler was sent the command new
12/08/2012 20:36:35;0040;PBS_Server;Svr;tyrone-cluster;Scheduler was sent the command new
12/08/2012 20:37:04;0040;PBS_Server;Svr;tyrone-cluster;Scheduler was sent the command new
12/08/2012 20:37:35;0040;PBS_Server;Svr;tyrone-cluster;Scheduler was sent the command new
12/08/2012 20:38:05;0040;PBS_Server;Svr;tyrone-cluster;Scheduler was sent the command new
12/08/2012 20:38:10;0002;PBS_Server;Svr;PBS_Server;Torque Server Version = 3.0.5, loglevel = 0
12/08/2012 20:38:38;0040;PBS_Server;Svr;tyrone-cluster;Scheduler was sent the command new
12/08/2012 20:39:09;0040;PBS_Server;Svr;tyrone-cluster;Scheduler was sent the command new
12/08/2012 20:39:42;0040;PBS_Server;Svr;tyrone-cluster;Scheduler was sent the command new
12/08/2012 20:40:16;0040;PBS_Server;Svr;tyrone-cluster;Scheduler was sent the command new
12/08/2012 20:40:47;0040;PBS_Server;Svr;tyrone-cluster;Scheduler was sent the command new
12/08/2012 20:41:19;0040;PBS_Server;Svr;tyrone-cluster;Scheduler was sent the command new
12/08/2012 20:41:48;0040;PBS_Server;Svr;tyrone-cluster;Scheduler was sent the command new
12/08/2012 20:42:18;0040;PBS_Server;Svr;tyrone-cluster;Scheduler was sent the command new
12/08/2012 20:42:50;0040;PBS_Server;Svr;tyrone-cluster;Scheduler was sent the command new
12/08/2012 20:43:10;0002;PBS_Server;Svr;PBS_Server;Torque Server Version = 3.0.5, loglevel = 0
12/08/2012 20:43:19;0040;PBS_Server;Svr;tyrone-cluster;Scheduler was sent the command new
12/08/2012 20:43:49;0040;PBS_Server;Svr;tyrone-cluster;Scheduler was sent the command new
12/08/2012 20:44:20;0040;PBS_Server;Svr;tyrone-cluster;Scheduler was sent the command new
12/08/2012 20:44:50;0040;PBS_Server;Svr;tyrone-cluster;Scheduler was sent the command new
12/08/2012 20:45:23;0040;PBS_Server;Svr;tyrone-cluster;Scheduler was sent the command new
12/08/2012 20:45:55;0040;PBS_Server;Svr;tyrone-cluster;Scheduler was sent the command new
12/08/2012 20:46:27;0040;PBS_Server;Svr;tyrone-cluster;Scheduler was sent the command new
12/08/2012 20:47:01;0040;PBS_Server;Svr;tyrone-cluster;Scheduler was sent the command new
12/08/2012 20:47:32;0040;PBS_Server;Svr;tyrone-cluster;Scheduler was sent the command new
12/08/2012 20:48:04;0040;PBS_Server;Svr;tyrone-cluster;Scheduler was sent the command new
12/08/2012 20:48:10;0002;PBS_Server;Svr;PBS_Server;Torque Server Version = 3.0.5, loglevel = 0
12/08/2012 20:48:33;0040;PBS_Server;Svr;tyrone-cluster;Scheduler was sent the command new
12/08/2012 20:49:03;0040;PBS_Server;Svr;tyrone-cluster;Scheduler was sent the command new
12/08/2012 20:49:35;0040;PBS_Server;Svr;tyrone-cluster;Scheduler was sent the command new
12/08/2012 20:50:04;0040;PBS_Server;Svr;tyrone-cluster;Scheduler was sent the command new
12/08/2012 20:50:33;0040;PBS_Server;Svr;tyrone-cluster;Scheduler was sent the command new
12/08/2012 20:51:05;0040;PBS_Server;Svr;tyrone-cluster;Scheduler was sent the command new
12/08/2012 20:51:35;0040;PBS_Server;Svr;tyrone-cluster;Scheduler was sent the command new
12/08/2012 20:52:08;0040;PBS_Server;Svr;tyrone-cluster;Scheduler was sent the command new
12/08/2012 20:52:40;0040;PBS_Server;Svr;tyrone-cluster;Scheduler was sent the command new
12/08/2012 20:53:10;0002;PBS_Server;Svr;PBS_Server;Torque Server Version = 3.0.5, loglevel = 0
12/08/2012 20:53:12;0040;PBS_Server;Svr;tyrone-cluster;Scheduler was sent the command new
12/08/2012 20:53:40;0040;PBS_Server;Svr;tyrone-cluster;Scheduler was sent the command new
12/08/2012 20:54:10;0040;PBS_Server;Svr;tyrone-cluster;Scheduler was sent the command new
12/08/2012 20:54:42;0040;PBS_Server;Svr;tyrone-cluster;Scheduler was sent the command new
12/08/2012 20:55:16;0040;PBS_Server;Svr;tyrone-cluster;Scheduler was sent the command new
12/08/2012 20:55:48;0040;PBS_Server;Svr;tyrone-cluster;Scheduler was sent the command new
12/08/2012 20:56:19;0040;PBS_Server;Svr;tyrone-cluster;Scheduler was sent the command new
12/08/2012 20:56:48;0040;PBS_Server;Svr;tyrone-cluster;Scheduler was sent the command new
12/08/2012 20:57:18;0040;PBS_Server;Svr;tyrone-cluster;Scheduler was sent the command new
12/08/2012 20:57:50;0040;PBS_Server;Svr;tyrone-cluster;Scheduler was sent the command new
12/08/2012 20:58:10;0002;PBS_Server;Svr;PBS_Server;Torque Server Version = 3.0.5, loglevel = 0
12/08/2012 20:58:20;0040;PBS_Server;Svr;tyrone-cluster;Scheduler was sent the command new
12/08/2012 20:58:53;0040;PBS_Server;Svr;tyrone-cluster;Scheduler was sent the command new
12/08/2012 20:59:20;0040;PBS_Server;Svr;tyrone-cluster;Scheduler was sent the command new
12/08/2012 20:59:50;0040;PBS_Server;Svr;tyrone-cluster;Scheduler was sent the command new
12/08/2012 21:00:23;0040;PBS_Server;Svr;tyrone-cluster;Scheduler was sent the command new
12/08/2012 21:00:55;0040;PBS_Server;Svr;tyrone-cluster;Scheduler was sent the command new
12/08/2012 21:01:27;0040;PBS_Server;Svr;tyrone-cluster;Scheduler was sent the command new
12/08/2012 21:02:01;0040;PBS_Server;Svr;tyrone-cluster;Scheduler was sent the command new
12/08/2012 21:02:33;0040;PBS_Server;Svr;tyrone-cluster;Scheduler was sent the command new
12/08/2012 21:03:04;0040;PBS_Server;Svr;tyrone-cluster;Scheduler was sent the command new
12/08/2012 21:03:10;0002;PBS_Server;Svr;PBS_Server;Torque Server Version = 3.0.5, loglevel = 0
12/08/2012 21:03:33;0040;PBS_Server;Svr;tyrone-cluster;Scheduler was sent the command new
