12/20/2013 00:04:33;0002;PBS_Server;Svr;Log;Log opened
12/20/2013 00:04:33;0002;PBS_Server;Svr;PBS_Server;Torque Server Version = 3.0.5, loglevel = 0
12/20/2013 00:06:05;0040;PBS_Server;Svr;tyrone-cluster;Scheduler was sent the command time
12/20/2013 00:09:33;0002;PBS_Server;Svr;PBS_Server;Torque Server Version = 3.0.5, loglevel = 0
12/20/2013 00:14:33;0002;PBS_Server;Svr;PBS_Server;Torque Server Version = 3.0.5, loglevel = 0
12/20/2013 00:16:05;0040;PBS_Server;Svr;tyrone-cluster;Scheduler was sent the command time
12/20/2013 00:19:33;0002;PBS_Server;Svr;PBS_Server;Torque Server Version = 3.0.5, loglevel = 0
12/20/2013 00:24:33;0002;PBS_Server;Svr;PBS_Server;Torque Server Version = 3.0.5, loglevel = 0
12/20/2013 00:26:05;0040;PBS_Server;Svr;tyrone-cluster;Scheduler was sent the command time
12/20/2013 00:29:33;0002;PBS_Server;Svr;PBS_Server;Torque Server Version = 3.0.5, loglevel = 0
12/20/2013 00:34:33;0002;PBS_Server;Svr;PBS_Server;Torque Server Version = 3.0.5, loglevel = 0
12/20/2013 00:36:05;0040;PBS_Server;Svr;tyrone-cluster;Scheduler was sent the command time
12/20/2013 00:39:33;0002;PBS_Server;Svr;PBS_Server;Torque Server Version = 3.0.5, loglevel = 0
12/20/2013 00:44:33;0002;PBS_Server;Svr;PBS_Server;Torque Server Version = 3.0.5, loglevel = 0
12/20/2013 00:46:05;0040;PBS_Server;Svr;tyrone-cluster;Scheduler was sent the command time
12/20/2013 00:49:33;0002;PBS_Server;Svr;PBS_Server;Torque Server Version = 3.0.5, loglevel = 0
12/20/2013 00:54:33;0002;PBS_Server;Svr;PBS_Server;Torque Server Version = 3.0.5, loglevel = 0
12/20/2013 00:56:05;0040;PBS_Server;Svr;tyrone-cluster;Scheduler was sent the command time
12/20/2013 00:59:33;0002;PBS_Server;Svr;PBS_Server;Torque Server Version = 3.0.5, loglevel = 0
12/20/2013 01:04:33;0002;PBS_Server;Svr;PBS_Server;Torque Server Version = 3.0.5, loglevel = 0
12/20/2013 01:06:05;0040;PBS_Server;Svr;tyrone-cluster;Scheduler was sent the command time
12/20/2013 01:09:33;0002;PBS_Server;Svr;PBS_Server;Torque Server Version = 3.0.5, loglevel = 0
12/20/2013 01:14:33;0002;PBS_Server;Svr;PBS_Server;Torque Server Version = 3.0.5, loglevel = 0
12/20/2013 01:15:58;000d;PBS_Server;Job;33349.tyrone-cluster;Not sending email: User does not want mail of this type.
12/20/2013 01:15:58;0002;PBS_Server;Svr;Act;Account file /var/spool/torque/server_priv/accounting/20131220 opened
12/20/2013 01:15:58;0010;PBS_Server;Job;33349.tyrone-cluster;Exit_status=0 resources_used.cput=49:06:34 resources_used.mem=1928452kb resources_used.vmem=4258016kb resources_used.walltime=01:32:17
12/20/2013 01:15:58;0008;PBS_Server;Job;NULL;on_job_exit valid pjob: 0x270b100 (substate=50)
12/20/2013 01:15:58;0008;PBS_Server;Job;NULL;on_job_exit valid pjob: 0x270b100 (substate=51)
12/20/2013 01:16:01;0008;PBS_Server;Job;NULL;on_job_exit valid pjob: 0x270b100 (substate=51)
12/20/2013 01:16:01;0008;PBS_Server;Job;NULL;on_job_exit valid pjob: 0x270b100 (substate=53)
12/20/2013 01:16:01;0100;PBS_Server;Job;33349.tyrone-cluster;dequeuing from qp32, state COMPLETE
12/20/2013 01:16:01;0040;PBS_Server;Svr;tyrone-cluster;Scheduler was sent the command term
12/20/2013 01:16:01;0008;PBS_Server;Job;33356.tyrone-cluster;Job Modified at request of Scheduler@tyrone-cluster
12/20/2013 01:16:01;0008;PBS_Server;Job;33350.tyrone-cluster;Job Modified at request of Scheduler@tyrone-cluster
12/20/2013 01:16:01;0008;PBS_Server;Job;33350.tyrone-cluster;Job Run at request of Scheduler@tyrone-cluster
12/20/2013 01:16:01;0040;PBS_Server;Svr;tyrone-cluster;Scheduler was sent the command recyc
12/20/2013 01:16:01;000d;PBS_Server;Job;33350.tyrone-cluster;Not sending email: User does not want mail of this type.
12/20/2013 01:19:33;0002;PBS_Server;Svr;PBS_Server;Torque Server Version = 3.0.5, loglevel = 0
12/20/2013 01:24:33;0002;PBS_Server;Svr;PBS_Server;Torque Server Version = 3.0.5, loglevel = 0
12/20/2013 01:26:01;0040;PBS_Server;Svr;tyrone-cluster;Scheduler was sent the command time
12/20/2013 01:26:01;0008;PBS_Server;Job;33356.tyrone-cluster;Job Modified at request of Scheduler@tyrone-cluster
12/20/2013 01:29:33;0002;PBS_Server;Svr;PBS_Server;Torque Server Version = 3.0.5, loglevel = 0
12/20/2013 01:34:33;0002;PBS_Server;Svr;PBS_Server;Torque Server Version = 3.0.5, loglevel = 0
12/20/2013 01:35:57;000d;PBS_Server;Job;33350.tyrone-cluster;Not sending email: User does not want mail of this type.
12/20/2013 01:35:57;0010;PBS_Server;Job;33350.tyrone-cluster;Exit_status=0 resources_used.cput=10:35:58 resources_used.mem=474544kb resources_used.vmem=2582224kb resources_used.walltime=00:19:56
12/20/2013 01:35:57;0008;PBS_Server;Job;NULL;on_job_exit valid pjob: 0x2669eb0 (substate=50)
12/20/2013 01:35:57;0008;PBS_Server;Job;NULL;on_job_exit valid pjob: 0x2669eb0 (substate=51)
12/20/2013 01:35:57;0008;PBS_Server;Job;NULL;on_job_exit valid pjob: 0x2669eb0 (substate=51)
12/20/2013 01:35:57;0008;PBS_Server;Job;NULL;on_job_exit valid pjob: 0x2669eb0 (substate=53)
12/20/2013 01:35:57;0100;PBS_Server;Job;33350.tyrone-cluster;dequeuing from qp32, state COMPLETE
12/20/2013 01:35:57;0040;PBS_Server;Svr;tyrone-cluster;Scheduler was sent the command term
12/20/2013 01:35:57;0008;PBS_Server;Job;33356.tyrone-cluster;Job Modified at request of Scheduler@tyrone-cluster
12/20/2013 01:39:33;0002;PBS_Server;Svr;PBS_Server;Torque Server Version = 3.0.5, loglevel = 0
12/20/2013 01:44:33;0002;PBS_Server;Svr;PBS_Server;Torque Server Version = 3.0.5, loglevel = 0
12/20/2013 01:45:57;0040;PBS_Server;Svr;tyrone-cluster;Scheduler was sent the command time
12/20/2013 01:49:33;0002;PBS_Server;Svr;PBS_Server;Torque Server Version = 3.0.5, loglevel = 0
12/20/2013 01:54:33;0002;PBS_Server;Svr;PBS_Server;Torque Server Version = 3.0.5, loglevel = 0
12/20/2013 01:55:57;0040;PBS_Server;Svr;tyrone-cluster;Scheduler was sent the command time
12/20/2013 01:59:33;0002;PBS_Server;Svr;PBS_Server;Torque Server Version = 3.0.5, loglevel = 0
12/20/2013 02:04:33;0002;PBS_Server;Svr;PBS_Server;Torque Server Version = 3.0.5, loglevel = 0
12/20/2013 02:05:57;0040;PBS_Server;Svr;tyrone-cluster;Scheduler was sent the command time
12/20/2013 02:09:33;0002;PBS_Server;Svr;PBS_Server;Torque Server Version = 3.0.5, loglevel = 0
12/20/2013 02:14:33;0002;PBS_Server;Svr;PBS_Server;Torque Server Version = 3.0.5, loglevel = 0
12/20/2013 02:15:57;0040;PBS_Server;Svr;tyrone-cluster;Scheduler was sent the command time
12/20/2013 02:19:33;0002;PBS_Server;Svr;PBS_Server;Torque Server Version = 3.0.5, loglevel = 0
12/20/2013 02:24:33;0002;PBS_Server;Svr;PBS_Server;Torque Server Version = 3.0.5, loglevel = 0
12/20/2013 02:25:57;0040;PBS_Server;Svr;tyrone-cluster;Scheduler was sent the command time
12/20/2013 02:29:33;0002;PBS_Server;Svr;PBS_Server;Torque Server Version = 3.0.5, loglevel = 0
12/20/2013 02:34:33;0002;PBS_Server;Svr;PBS_Server;Torque Server Version = 3.0.5, loglevel = 0
12/20/2013 02:35:57;0040;PBS_Server;Svr;tyrone-cluster;Scheduler was sent the command time
12/20/2013 02:39:33;0002;PBS_Server;Svr;PBS_Server;Torque Server Version = 3.0.5, loglevel = 0
12/20/2013 02:44:33;0002;PBS_Server;Svr;PBS_Server;Torque Server Version = 3.0.5, loglevel = 0
12/20/2013 02:45:57;0040;PBS_Server;Svr;tyrone-cluster;Scheduler was sent the command time
12/20/2013 02:49:33;0002;PBS_Server;Svr;PBS_Server;Torque Server Version = 3.0.5, loglevel = 0
12/20/2013 02:54:33;0002;PBS_Server;Svr;PBS_Server;Torque Server Version = 3.0.5, loglevel = 0
12/20/2013 02:55:57;0040;PBS_Server;Svr;tyrone-cluster;Scheduler was sent the command time
12/20/2013 02:59:33;0002;PBS_Server;Svr;PBS_Server;Torque Server Version = 3.0.5, loglevel = 0
12/20/2013 03:04:33;0002;PBS_Server;Svr;PBS_Server;Torque Server Version = 3.0.5, loglevel = 0
12/20/2013 03:05:57;0040;PBS_Server;Svr;tyrone-cluster;Scheduler was sent the command time
12/20/2013 03:09:33;0002;PBS_Server;Svr;PBS_Server;Torque Server Version = 3.0.5, loglevel = 0
12/20/2013 03:14:33;0002;PBS_Server;Svr;PBS_Server;Torque Server Version = 3.0.5, loglevel = 0
12/20/2013 03:15:57;0040;PBS_Server;Svr;tyrone-cluster;Scheduler was sent the command time
12/20/2013 03:19:33;0002;PBS_Server;Svr;PBS_Server;Torque Server Version = 3.0.5, loglevel = 0
12/20/2013 03:24:33;0002;PBS_Server;Svr;PBS_Server;Torque Server Version = 3.0.5, loglevel = 0
12/20/2013 03:25:57;0040;PBS_Server;Svr;tyrone-cluster;Scheduler was sent the command time
12/20/2013 03:27:53;000d;PBS_Server;Job;33337.tyrone-cluster;Not sending email: User does not want mail of this type.
12/20/2013 03:27:53;0010;PBS_Server;Job;33337.tyrone-cluster;Exit_status=0 resources_used.cput=445:34:56 resources_used.mem=673792kb resources_used.vmem=7129588kb resources_used.walltime=13:55:53
12/20/2013 03:27:53;0008;PBS_Server;Job;NULL;on_job_exit valid pjob: 0x26f14b0 (substate=50)
12/20/2013 03:27:53;0008;PBS_Server;Job;NULL;on_job_exit valid pjob: 0x26f14b0 (substate=51)
12/20/2013 03:27:53;0008;PBS_Server;Job;NULL;on_job_exit valid pjob: 0x26f14b0 (substate=51)
12/20/2013 03:27:53;0008;PBS_Server;Job;NULL;on_job_exit valid pjob: 0x26f14b0 (substate=53)
12/20/2013 03:27:53;0100;PBS_Server;Job;33337.tyrone-cluster;dequeuing from qp32, state COMPLETE
12/20/2013 03:27:53;0040;PBS_Server;Svr;tyrone-cluster;Scheduler was sent the command term
12/20/2013 03:29:33;0002;PBS_Server;Svr;PBS_Server;Torque Server Version = 3.0.5, loglevel = 0
12/20/2013 03:34:33;0002;PBS_Server;Svr;PBS_Server;Torque Server Version = 3.0.5, loglevel = 0
12/20/2013 03:37:53;0040;PBS_Server;Svr;tyrone-cluster;Scheduler was sent the command time
12/20/2013 03:39:33;0002;PBS_Server;Svr;PBS_Server;Torque Server Version = 3.0.5, loglevel = 0
12/20/2013 03:44:33;0002;PBS_Server;Svr;PBS_Server;Torque Server Version = 3.0.5, loglevel = 0
12/20/2013 03:47:53;0040;PBS_Server;Svr;tyrone-cluster;Scheduler was sent the command time
12/20/2013 03:49:33;0002;PBS_Server;Svr;PBS_Server;Torque Server Version = 3.0.5, loglevel = 0
12/20/2013 03:54:33;0002;PBS_Server;Svr;PBS_Server;Torque Server Version = 3.0.5, loglevel = 0
12/20/2013 03:57:53;0040;PBS_Server;Svr;tyrone-cluster;Scheduler was sent the command time
12/20/2013 03:59:33;0002;PBS_Server;Svr;PBS_Server;Torque Server Version = 3.0.5, loglevel = 0
12/20/2013 04:04:33;0002;PBS_Server;Svr;PBS_Server;Torque Server Version = 3.0.5, loglevel = 0
12/20/2013 04:07:53;0040;PBS_Server;Svr;tyrone-cluster;Scheduler was sent the command time
12/20/2013 04:09:33;0002;PBS_Server;Svr;PBS_Server;Torque Server Version = 3.0.5, loglevel = 0
12/20/2013 04:14:33;0002;PBS_Server;Svr;PBS_Server;Torque Server Version = 3.0.5, loglevel = 0
12/20/2013 04:17:53;0040;PBS_Server;Svr;tyrone-cluster;Scheduler was sent the command time
12/20/2013 04:19:33;0002;PBS_Server;Svr;PBS_Server;Torque Server Version = 3.0.5, loglevel = 0
12/20/2013 04:24:33;0002;PBS_Server;Svr;PBS_Server;Torque Server Version = 3.0.5, loglevel = 0
12/20/2013 04:27:53;0040;PBS_Server;Svr;tyrone-cluster;Scheduler was sent the command time
12/20/2013 04:29:33;0002;PBS_Server;Svr;PBS_Server;Torque Server Version = 3.0.5, loglevel = 0
12/20/2013 04:34:33;0002;PBS_Server;Svr;PBS_Server;Torque Server Version = 3.0.5, loglevel = 0
12/20/2013 04:37:53;0040;PBS_Server;Svr;tyrone-cluster;Scheduler was sent the command time
12/20/2013 04:39:33;0002;PBS_Server;Svr;PBS_Server;Torque Server Version = 3.0.5, loglevel = 0
12/20/2013 04:44:33;0002;PBS_Server;Svr;PBS_Server;Torque Server Version = 3.0.5, loglevel = 0
12/20/2013 04:47:53;0040;PBS_Server;Svr;tyrone-cluster;Scheduler was sent the command time
12/20/2013 04:49:33;0002;PBS_Server;Svr;PBS_Server;Torque Server Version = 3.0.5, loglevel = 0
12/20/2013 04:54:33;0002;PBS_Server;Svr;PBS_Server;Torque Server Version = 3.0.5, loglevel = 0
12/20/2013 04:57:53;0040;PBS_Server;Svr;tyrone-cluster;Scheduler was sent the command time
12/20/2013 04:59:33;0002;PBS_Server;Svr;PBS_Server;Torque Server Version = 3.0.5, loglevel = 0
12/20/2013 05:04:33;0002;PBS_Server;Svr;PBS_Server;Torque Server Version = 3.0.5, loglevel = 0
12/20/2013 05:07:53;0040;PBS_Server;Svr;tyrone-cluster;Scheduler was sent the command time
12/20/2013 05:09:33;0002;PBS_Server;Svr;PBS_Server;Torque Server Version = 3.0.5, loglevel = 0
12/20/2013 05:14:33;0002;PBS_Server;Svr;PBS_Server;Torque Server Version = 3.0.5, loglevel = 0
12/20/2013 05:17:53;0040;PBS_Server;Svr;tyrone-cluster;Scheduler was sent the command time
12/20/2013 05:19:33;0002;PBS_Server;Svr;PBS_Server;Torque Server Version = 3.0.5, loglevel = 0
12/20/2013 05:24:33;0002;PBS_Server;Svr;PBS_Server;Torque Server Version = 3.0.5, loglevel = 0
12/20/2013 05:27:53;0040;PBS_Server;Svr;tyrone-cluster;Scheduler was sent the command time
12/20/2013 05:29:33;0002;PBS_Server;Svr;PBS_Server;Torque Server Version = 3.0.5, loglevel = 0
12/20/2013 05:34:33;0002;PBS_Server;Svr;PBS_Server;Torque Server Version = 3.0.5, loglevel = 0
12/20/2013 05:37:53;0040;PBS_Server;Svr;tyrone-cluster;Scheduler was sent the command time
12/20/2013 05:39:33;0002;PBS_Server;Svr;PBS_Server;Torque Server Version = 3.0.5, loglevel = 0
12/20/2013 05:44:33;0002;PBS_Server;Svr;PBS_Server;Torque Server Version = 3.0.5, loglevel = 0
12/20/2013 05:47:48;000d;PBS_Server;Job;33333.tyrone-cluster;Not sending email: User does not want mail of this type.
12/20/2013 05:47:48;0010;PBS_Server;Job;33333.tyrone-cluster;Exit_status=0 resources_used.cput=616:18:18 resources_used.mem=668336kb resources_used.vmem=7127056kb resources_used.walltime=19:16:09
12/20/2013 05:47:48;0008;PBS_Server;Job;NULL;on_job_exit valid pjob: 0x26e9d70 (substate=50)
12/20/2013 05:47:48;0008;PBS_Server;Job;NULL;on_job_exit valid pjob: 0x26e9d70 (substate=51)
12/20/2013 05:47:52;0008;PBS_Server;Job;NULL;on_job_exit valid pjob: 0x26e9d70 (substate=51)
12/20/2013 05:47:52;000d;PBS_Server;Job;33333.tyrone-cluster;Post job file processing error; job 33333.tyrone-cluster on host tyrone-node5/31+tyrone-node5/30+tyrone-node5/29+tyrone-node5/28+tyrone-node5/27+tyrone-node5/26+tyrone-node5/25+tyrone-node5/24+tyrone-node5/23+tyrone-node5/22+tyrone-node5/21+tyrone-node5/20+tyrone-node5/19+tyrone-node5/18+tyrone-node5/17+tyrone-node5/16+tyrone-node5/15+tyrone-node5/14+tyrone-node5/13+tyrone-node5/12+tyrone-node5/11+tyrone-node5/10+tyrone-node5/9+tyrone-node5/8+tyrone-node5/7+tyrone-node5/6+tyrone-node5/5+tyrone-node5/4+tyrone-node5/3+tyrone-node5/2+tyrone-node5/1+tyrone-node5/0
12/20/2013 05:47:52;0008;PBS_Server;Job;NULL;on_job_exit valid pjob: 0x26e9d70 (substate=53)
12/20/2013 05:47:52;0100;PBS_Server;Job;33333.tyrone-cluster;dequeuing from qp32, state COMPLETE
12/20/2013 05:47:52;0040;PBS_Server;Svr;tyrone-cluster;Scheduler was sent the command term
12/20/2013 05:47:52;0008;PBS_Server;Job;33356.tyrone-cluster;Job Modified at request of Scheduler@tyrone-cluster
12/20/2013 05:47:52;0008;PBS_Server;Job;33356.tyrone-cluster;Job Run at request of Scheduler@tyrone-cluster
12/20/2013 05:47:52;0040;PBS_Server;Svr;tyrone-cluster;Scheduler was sent the command recyc
12/20/2013 05:47:52;000d;PBS_Server;Job;33356.tyrone-cluster;Not sending email: User does not want mail of this type.
12/20/2013 05:49:33;0002;PBS_Server;Svr;PBS_Server;Torque Server Version = 3.0.5, loglevel = 0
12/20/2013 05:54:33;0002;PBS_Server;Svr;PBS_Server;Torque Server Version = 3.0.5, loglevel = 0
12/20/2013 05:57:52;0040;PBS_Server;Svr;tyrone-cluster;Scheduler was sent the command time
12/20/2013 05:59:33;0002;PBS_Server;Svr;PBS_Server;Torque Server Version = 3.0.5, loglevel = 0
12/20/2013 06:04:33;0002;PBS_Server;Svr;PBS_Server;Torque Server Version = 3.0.5, loglevel = 0
12/20/2013 06:07:52;0040;PBS_Server;Svr;tyrone-cluster;Scheduler was sent the command time
12/20/2013 06:09:33;0002;PBS_Server;Svr;PBS_Server;Torque Server Version = 3.0.5, loglevel = 0
12/20/2013 06:14:33;0002;PBS_Server;Svr;PBS_Server;Torque Server Version = 3.0.5, loglevel = 0
12/20/2013 06:17:52;0040;PBS_Server;Svr;tyrone-cluster;Scheduler was sent the command time
12/20/2013 06:19:33;0002;PBS_Server;Svr;PBS_Server;Torque Server Version = 3.0.5, loglevel = 0
12/20/2013 06:24:33;0002;PBS_Server;Svr;PBS_Server;Torque Server Version = 3.0.5, loglevel = 0
12/20/2013 06:27:52;0040;PBS_Server;Svr;tyrone-cluster;Scheduler was sent the command time
12/20/2013 06:29:33;0002;PBS_Server;Svr;PBS_Server;Torque Server Version = 3.0.5, loglevel = 0
12/20/2013 06:34:33;0002;PBS_Server;Svr;PBS_Server;Torque Server Version = 3.0.5, loglevel = 0
12/20/2013 06:37:52;0040;PBS_Server;Svr;tyrone-cluster;Scheduler was sent the command time
12/20/2013 06:39:33;0002;PBS_Server;Svr;PBS_Server;Torque Server Version = 3.0.5, loglevel = 0
12/20/2013 06:44:33;0002;PBS_Server;Svr;PBS_Server;Torque Server Version = 3.0.5, loglevel = 0
12/20/2013 06:47:52;0040;PBS_Server;Svr;tyrone-cluster;Scheduler was sent the command time
12/20/2013 06:49:33;0002;PBS_Server;Svr;PBS_Server;Torque Server Version = 3.0.5, loglevel = 0
12/20/2013 06:54:33;0002;PBS_Server;Svr;PBS_Server;Torque Server Version = 3.0.5, loglevel = 0
12/20/2013 06:57:52;0040;PBS_Server;Svr;tyrone-cluster;Scheduler was sent the command time
12/20/2013 06:59:33;0002;PBS_Server;Svr;PBS_Server;Torque Server Version = 3.0.5, loglevel = 0
12/20/2013 07:04:33;0002;PBS_Server;Svr;PBS_Server;Torque Server Version = 3.0.5, loglevel = 0
12/20/2013 07:07:52;0040;PBS_Server;Svr;tyrone-cluster;Scheduler was sent the command time
12/20/2013 07:09:33;0002;PBS_Server;Svr;PBS_Server;Torque Server Version = 3.0.5, loglevel = 0
12/20/2013 07:14:33;0002;PBS_Server;Svr;PBS_Server;Torque Server Version = 3.0.5, loglevel = 0
12/20/2013 07:17:52;0040;PBS_Server;Svr;tyrone-cluster;Scheduler was sent the command time
12/20/2013 07:19:33;0002;PBS_Server;Svr;PBS_Server;Torque Server Version = 3.0.5, loglevel = 0
12/20/2013 07:24:33;0002;PBS_Server;Svr;PBS_Server;Torque Server Version = 3.0.5, loglevel = 0
12/20/2013 07:27:52;0040;PBS_Server;Svr;tyrone-cluster;Scheduler was sent the command time
12/20/2013 07:29:33;0002;PBS_Server;Svr;PBS_Server;Torque Server Version = 3.0.5, loglevel = 0
12/20/2013 07:34:33;0002;PBS_Server;Svr;PBS_Server;Torque Server Version = 3.0.5, loglevel = 0
12/20/2013 07:37:52;0040;PBS_Server;Svr;tyrone-cluster;Scheduler was sent the command time
12/20/2013 07:39:33;0002;PBS_Server;Svr;PBS_Server;Torque Server Version = 3.0.5, loglevel = 0
12/20/2013 07:44:33;0002;PBS_Server;Svr;PBS_Server;Torque Server Version = 3.0.5, loglevel = 0
12/20/2013 07:47:52;0040;PBS_Server;Svr;tyrone-cluster;Scheduler was sent the command time
12/20/2013 07:49:33;0002;PBS_Server;Svr;PBS_Server;Torque Server Version = 3.0.5, loglevel = 0
12/20/2013 07:54:33;0002;PBS_Server;Svr;PBS_Server;Torque Server Version = 3.0.5, loglevel = 0
12/20/2013 07:57:52;0040;PBS_Server;Svr;tyrone-cluster;Scheduler was sent the command time
12/20/2013 07:59:33;0002;PBS_Server;Svr;PBS_Server;Torque Server Version = 3.0.5, loglevel = 0
12/20/2013 08:04:33;0002;PBS_Server;Svr;PBS_Server;Torque Server Version = 3.0.5, loglevel = 0
12/20/2013 08:07:52;0040;PBS_Server;Svr;tyrone-cluster;Scheduler was sent the command time
12/20/2013 08:09:33;0002;PBS_Server;Svr;PBS_Server;Torque Server Version = 3.0.5, loglevel = 0
12/20/2013 08:14:33;0002;PBS_Server;Svr;PBS_Server;Torque Server Version = 3.0.5, loglevel = 0
12/20/2013 08:17:52;0040;PBS_Server;Svr;tyrone-cluster;Scheduler was sent the command time
12/20/2013 08:19:33;0002;PBS_Server;Svr;PBS_Server;Torque Server Version = 3.0.5, loglevel = 0
12/20/2013 08:24:33;0002;PBS_Server;Svr;PBS_Server;Torque Server Version = 3.0.5, loglevel = 0
12/20/2013 08:27:52;0040;PBS_Server;Svr;tyrone-cluster;Scheduler was sent the command time
12/20/2013 08:29:33;0002;PBS_Server;Svr;PBS_Server;Torque Server Version = 3.0.5, loglevel = 0
12/20/2013 08:34:33;0002;PBS_Server;Svr;PBS_Server;Torque Server Version = 3.0.5, loglevel = 0
12/20/2013 08:37:52;0040;PBS_Server;Svr;tyrone-cluster;Scheduler was sent the command time
12/20/2013 08:39:33;0002;PBS_Server;Svr;PBS_Server;Torque Server Version = 3.0.5, loglevel = 0
12/20/2013 08:44:33;0002;PBS_Server;Svr;PBS_Server;Torque Server Version = 3.0.5, loglevel = 0
12/20/2013 08:47:52;0040;PBS_Server;Svr;tyrone-cluster;Scheduler was sent the command time
12/20/2013 08:49:33;0002;PBS_Server;Svr;PBS_Server;Torque Server Version = 3.0.5, loglevel = 0
12/20/2013 08:54:33;0002;PBS_Server;Svr;PBS_Server;Torque Server Version = 3.0.5, loglevel = 0
12/20/2013 08:57:52;0040;PBS_Server;Svr;tyrone-cluster;Scheduler was sent the command time
12/20/2013 08:59:33;0002;PBS_Server;Svr;PBS_Server;Torque Server Version = 3.0.5, loglevel = 0
12/20/2013 09:04:33;0002;PBS_Server;Svr;PBS_Server;Torque Server Version = 3.0.5, loglevel = 0
12/20/2013 09:07:52;0040;PBS_Server;Svr;tyrone-cluster;Scheduler was sent the command time
12/20/2013 09:09:33;0002;PBS_Server;Svr;PBS_Server;Torque Server Version = 3.0.5, loglevel = 0
12/20/2013 09:14:33;0002;PBS_Server;Svr;PBS_Server;Torque Server Version = 3.0.5, loglevel = 0
12/20/2013 09:17:52;0040;PBS_Server;Svr;tyrone-cluster;Scheduler was sent the command time
12/20/2013 09:19:33;0002;PBS_Server;Svr;PBS_Server;Torque Server Version = 3.0.5, loglevel = 0
12/20/2013 09:24:33;0002;PBS_Server;Svr;PBS_Server;Torque Server Version = 3.0.5, loglevel = 0
12/20/2013 09:27:52;0040;PBS_Server;Svr;tyrone-cluster;Scheduler was sent the command time
12/20/2013 09:29:33;0002;PBS_Server;Svr;PBS_Server;Torque Server Version = 3.0.5, loglevel = 0
12/20/2013 09:34:33;0002;PBS_Server;Svr;PBS_Server;Torque Server Version = 3.0.5, loglevel = 0
12/20/2013 09:37:52;0040;PBS_Server;Svr;tyrone-cluster;Scheduler was sent the command time
12/20/2013 09:39:33;0002;PBS_Server;Svr;PBS_Server;Torque Server Version = 3.0.5, loglevel = 0
12/20/2013 09:44:33;0002;PBS_Server;Svr;PBS_Server;Torque Server Version = 3.0.5, loglevel = 0
12/20/2013 09:47:52;0040;PBS_Server;Svr;tyrone-cluster;Scheduler was sent the command time
12/20/2013 09:49:33;0002;PBS_Server;Svr;PBS_Server;Torque Server Version = 3.0.5, loglevel = 0
12/20/2013 09:54:33;0002;PBS_Server;Svr;PBS_Server;Torque Server Version = 3.0.5, loglevel = 0
12/20/2013 09:57:52;0040;PBS_Server;Svr;tyrone-cluster;Scheduler was sent the command time
12/20/2013 09:59:33;0002;PBS_Server;Svr;PBS_Server;Torque Server Version = 3.0.5, loglevel = 0
12/20/2013 10:04:33;0002;PBS_Server;Svr;PBS_Server;Torque Server Version = 3.0.5, loglevel = 0
12/20/2013 10:07:52;0040;PBS_Server;Svr;tyrone-cluster;Scheduler was sent the command time
12/20/2013 10:09:33;0002;PBS_Server;Svr;PBS_Server;Torque Server Version = 3.0.5, loglevel = 0
12/20/2013 10:11:03;0100;PBS_Server;Job;33377.tyrone-cluster;enqueuing into batch, state 1 hop 1
12/20/2013 10:11:03;0100;PBS_Server;Job;33377.tyrone-cluster;dequeuing from batch, state QUEUED
12/20/2013 10:11:03;0100;PBS_Server;Job;33377.tyrone-cluster;enqueuing into qp32, state 1 hop 1
12/20/2013 10:11:03;0008;PBS_Server;Job;33377.tyrone-cluster;Job Queued at request of mbunisha@tyrone-cluster, owner = mbunisha@tyrone-cluster, job name = calrtetras-16-12-13, queue = qp32
12/20/2013 10:11:03;0040;PBS_Server;Svr;tyrone-cluster;Scheduler was sent the command new
12/20/2013 10:11:03;0008;PBS_Server;Job;33377.tyrone-cluster;Job Modified at request of Scheduler@tyrone-cluster
12/20/2013 10:12:21;0100;PBS_Server;Job;33378.tyrone-cluster;enqueuing into batch, state 1 hop 1
12/20/2013 10:12:21;0100;PBS_Server;Job;33378.tyrone-cluster;dequeuing from batch, state QUEUED
12/20/2013 10:12:21;0100;PBS_Server;Job;33378.tyrone-cluster;enqueuing into qp32, state 1 hop 1
12/20/2013 10:12:21;0008;PBS_Server;Job;33378.tyrone-cluster;Job Queued at request of mbumasha@tyrone-cluster, owner = mbumasha@tyrone-cluster, job name = mlectrg-y162-16-12-13, queue = qp32
12/20/2013 10:12:21;0040;PBS_Server;Svr;tyrone-cluster;Scheduler was sent the command new
12/20/2013 10:12:21;0008;PBS_Server;Job;33378.tyrone-cluster;Job Modified at request of Scheduler@tyrone-cluster
12/20/2013 10:12:21;0008;PBS_Server;Job;33378.tyrone-cluster;Job Run at request of Scheduler@tyrone-cluster
12/20/2013 10:12:22;000d;PBS_Server;Job;33378.tyrone-cluster;Not sending email: User does not want mail of this type.
12/20/2013 10:12:22;0040;PBS_Server;Svr;tyrone-cluster;Scheduler was sent the command recyc
12/20/2013 10:14:33;0002;PBS_Server;Svr;PBS_Server;Torque Server Version = 3.0.5, loglevel = 0
12/20/2013 10:17:23;0100;PBS_Server;Job;33379.tyrone-cluster;enqueuing into batch, state 1 hop 1
12/20/2013 10:17:23;0100;PBS_Server;Job;33379.tyrone-cluster;dequeuing from batch, state QUEUED
12/20/2013 10:17:23;0100;PBS_Server;Job;33379.tyrone-cluster;enqueuing into qp64, state 1 hop 1
12/20/2013 10:17:23;0008;PBS_Server;Job;33379.tyrone-cluster;Job Queued at request of ipcanilk@tyrone-cluster, owner = ipcanilk@tyrone-cluster, job name = job64, queue = qp64
12/20/2013 10:17:23;0040;PBS_Server;Svr;tyrone-cluster;Scheduler was sent the command new
12/20/2013 10:17:23;0008;PBS_Server;Job;33379.tyrone-cluster;Job Modified at request of Scheduler@tyrone-cluster
12/20/2013 10:17:23;0008;PBS_Server;Job;33379.tyrone-cluster;Job Run at request of Scheduler@tyrone-cluster
12/20/2013 10:17:23;0040;PBS_Server;Svr;tyrone-cluster;Scheduler was sent the command recyc
12/20/2013 10:17:23;000d;PBS_Server;Job;33379.tyrone-cluster;Not sending email: User does not want mail of this type.
12/20/2013 10:18:01;000d;PBS_Server;Job;33366.tyrone-cluster;Not sending email: User does not want mail of this type.
12/20/2013 10:18:01;0010;PBS_Server;Job;33366.tyrone-cluster;Exit_status=0 resources_used.cput=289:35:44 resources_used.mem=1948312kb resources_used.vmem=20773480kb resources_used.walltime=11:24:25
12/20/2013 10:18:01;0008;PBS_Server;Job;NULL;on_job_exit valid pjob: 0x27618c0 (substate=50)
12/20/2013 10:18:01;0008;PBS_Server;Job;NULL;on_job_exit valid pjob: 0x27618c0 (substate=51)
12/20/2013 10:18:05;0008;PBS_Server;Job;NULL;on_job_exit valid pjob: 0x27618c0 (substate=51)
12/20/2013 10:18:05;000d;PBS_Server;Job;33366.tyrone-cluster;Post job file processing error; job 33366.tyrone-cluster on host tyrone-node8/31+tyrone-node8/30+tyrone-node8/29+tyrone-node8/28+tyrone-node8/27+tyrone-node8/26+tyrone-node8/25+tyrone-node8/24+tyrone-node8/23+tyrone-node8/22+tyrone-node8/21+tyrone-node8/20+tyrone-node8/19+tyrone-node8/18+tyrone-node8/17+tyrone-node8/16+tyrone-node8/15+tyrone-node8/14+tyrone-node8/13+tyrone-node8/12+tyrone-node8/11+tyrone-node8/10+tyrone-node8/9+tyrone-node8/8+tyrone-node8/7+tyrone-node8/6+tyrone-node8/5+tyrone-node8/4+tyrone-node8/3+tyrone-node8/2+tyrone-node8/1+tyrone-node8/0
12/20/2013 10:18:05;0008;PBS_Server;Job;NULL;on_job_exit valid pjob: 0x27618c0 (substate=53)
12/20/2013 10:18:05;0100;PBS_Server;Job;33366.tyrone-cluster;dequeuing from qp32, state COMPLETE
12/20/2013 10:18:05;0040;PBS_Server;Svr;tyrone-cluster;Scheduler was sent the command term
12/20/2013 10:18:16;0100;PBS_Server;Job;33380.tyrone-cluster;enqueuing into batch, state 1 hop 1
12/20/2013 10:18:16;0100;PBS_Server;Job;33380.tyrone-cluster;dequeuing from batch, state QUEUED
12/20/2013 10:18:16;0100;PBS_Server;Job;33380.tyrone-cluster;enqueuing into qp64, state 1 hop 1
12/20/2013 10:18:16;0008;PBS_Server;Job;33380.tyrone-cluster;Job Queued at request of mbuavdhs@tyrone-cluster, owner = mbuavdhs@tyrone-cluster, job name = mlecdigy162-12-12-13, queue = qp64
12/20/2013 10:18:16;0040;PBS_Server;Svr;tyrone-cluster;Scheduler was sent the command new
12/20/2013 10:18:16;0008;PBS_Server;Job;33380.tyrone-cluster;Job Modified at request of Scheduler@tyrone-cluster
12/20/2013 10:18:16;0008;PBS_Server;Job;33380.tyrone-cluster;Job Run at request of Scheduler@tyrone-cluster
12/20/2013 10:18:17;0040;PBS_Server;Svr;tyrone-cluster;Scheduler was sent the command recyc
12/20/2013 10:18:17;000d;PBS_Server;Job;33380.tyrone-cluster;Not sending email: User does not want mail of this type.
12/20/2013 10:18:18;000d;PBS_Server;Job;33380.tyrone-cluster;Not sending email: User does not want mail of this type.
12/20/2013 10:18:18;0010;PBS_Server;Job;33380.tyrone-cluster;Exit_status=1 resources_used.cput=00:00:00 resources_used.mem=0kb resources_used.vmem=0kb resources_used.walltime=00:00:01
12/20/2013 10:18:18;0008;PBS_Server;Job;NULL;on_job_exit valid pjob: 0x27618c0 (substate=50)
12/20/2013 10:18:18;0008;PBS_Server;Job;NULL;on_job_exit valid pjob: 0x27618c0 (substate=51)
12/20/2013 10:18:22;0008;PBS_Server;Job;NULL;on_job_exit valid pjob: 0x27618c0 (substate=51)
12/20/2013 10:18:22;000d;PBS_Server;Job;33380.tyrone-cluster;Post job file processing error; job 33380.tyrone-cluster on host tyrone-node15/63+tyrone-node15/62+tyrone-node15/61+tyrone-node15/60+tyrone-node15/59+tyrone-node15/58+tyrone-node15/57+tyrone-node15/56+tyrone-node15/55+tyrone-node15/54+tyrone-node15/53+tyrone-node15/52+tyrone-node15/51+tyrone-node15/50+tyrone-node15/49+tyrone-node15/48+tyrone-node15/47+tyrone-node15/46+tyrone-node15/45+tyrone-node15/44+tyrone-node15/43+tyrone-node15/42+tyrone-node15/41+tyrone-node15/40+tyrone-node15/39+tyrone-node15/38+tyrone-node15/37+tyrone-node15/36+tyrone-node15/35+tyrone-node15/34+tyrone-node15/33+tyrone-node15/32+tyrone-node15/31+tyrone-node15/30+tyrone-node15/29+tyrone-node15/28+tyrone-node15/27+tyrone-node15/26+tyrone-node15/25+tyrone-node15/24+tyrone-node15/23+tyrone-node15/22+tyrone-node15/21+tyrone-node15/20+tyrone-node15/19+tyrone-node15/18+tyrone-node15/17+tyrone-node15/16+tyrone-node15/15+tyrone-node15/14+tyrone-node15/13+tyrone-node15/12+tyrone-node15/11+tyrone-node15/10+tyrone-node15/9+tyrone-node15/8+tyrone-node15/7+tyrone-node15/6+tyrone-node15/5+tyrone-node15/4+tyrone-node15/3+tyrone-node15/2+tyrone-node15/1+tyrone-node15/0
12/20/2013 10:18:22;0008;PBS_Server;Job;NULL;on_job_exit valid pjob: 0x27618c0 (substate=53)
12/20/2013 10:18:22;0100;PBS_Server;Job;33380.tyrone-cluster;dequeuing from qp64, state COMPLETE
12/20/2013 10:18:22;0040;PBS_Server;Svr;tyrone-cluster;Scheduler was sent the command term
12/20/2013 10:19:33;0002;PBS_Server;Svr;PBS_Server;Torque Server Version = 3.0.5, loglevel = 0
12/20/2013 10:22:08;0100;PBS_Server;Job;33381.tyrone-cluster;enqueuing into batch, state 1 hop 1
12/20/2013 10:22:08;0100;PBS_Server;Job;33381.tyrone-cluster;dequeuing from batch, state QUEUED
12/20/2013 10:22:08;0100;PBS_Server;Job;33381.tyrone-cluster;enqueuing into qp64, state 1 hop 1
12/20/2013 10:22:08;0008;PBS_Server;Job;33381.tyrone-cluster;Job Queued at request of mbuavdhs@tyrone-cluster, owner = mbuavdhs@tyrone-cluster, job name = mlecdigy162-12-12-13, queue = qp64
12/20/2013 10:22:08;0040;PBS_Server;Svr;tyrone-cluster;Scheduler was sent the command new
12/20/2013 10:22:08;0008;PBS_Server;Job;33381.tyrone-cluster;Job Modified at request of Scheduler@tyrone-cluster
12/20/2013 10:22:08;0008;PBS_Server;Job;33381.tyrone-cluster;Job Run at request of Scheduler@tyrone-cluster
12/20/2013 10:22:08;0040;PBS_Server;Svr;tyrone-cluster;Scheduler was sent the command recyc
12/20/2013 10:22:08;000d;PBS_Server;Job;33381.tyrone-cluster;Not sending email: User does not want mail of this type.
12/20/2013 10:22:10;000d;PBS_Server;Job;33381.tyrone-cluster;Not sending email: User does not want mail of this type.
12/20/2013 10:22:10;0010;PBS_Server;Job;33381.tyrone-cluster;Exit_status=1 resources_used.cput=00:00:00 resources_used.mem=0kb resources_used.vmem=0kb resources_used.walltime=00:00:02
12/20/2013 10:22:10;0008;PBS_Server;Job;NULL;on_job_exit valid pjob: 0x26e3610 (substate=50)
12/20/2013 10:22:10;0008;PBS_Server;Job;NULL;on_job_exit valid pjob: 0x26e3610 (substate=51)
12/20/2013 10:22:14;0008;PBS_Server;Job;NULL;on_job_exit valid pjob: 0x26e3610 (substate=51)
12/20/2013 10:22:14;000d;PBS_Server;Job;33381.tyrone-cluster;Post job file processing error; job 33381.tyrone-cluster on host tyrone-node15/63+tyrone-node15/62+tyrone-node15/61+tyrone-node15/60+tyrone-node15/59+tyrone-node15/58+tyrone-node15/57+tyrone-node15/56+tyrone-node15/55+tyrone-node15/54+tyrone-node15/53+tyrone-node15/52+tyrone-node15/51+tyrone-node15/50+tyrone-node15/49+tyrone-node15/48+tyrone-node15/47+tyrone-node15/46+tyrone-node15/45+tyrone-node15/44+tyrone-node15/43+tyrone-node15/42+tyrone-node15/41+tyrone-node15/40+tyrone-node15/39+tyrone-node15/38+tyrone-node15/37+tyrone-node15/36+tyrone-node15/35+tyrone-node15/34+tyrone-node15/33+tyrone-node15/32+tyrone-node15/31+tyrone-node15/30+tyrone-node15/29+tyrone-node15/28+tyrone-node15/27+tyrone-node15/26+tyrone-node15/25+tyrone-node15/24+tyrone-node15/23+tyrone-node15/22+tyrone-node15/21+tyrone-node15/20+tyrone-node15/19+tyrone-node15/18+tyrone-node15/17+tyrone-node15/16+tyrone-node15/15+tyrone-node15/14+tyrone-node15/13+tyrone-node15/12+tyrone-node15/11+tyrone-node15/10+tyrone-node15/9+tyrone-node15/8+tyrone-node15/7+tyrone-node15/6+tyrone-node15/5+tyrone-node15/4+tyrone-node15/3+tyrone-node15/2+tyrone-node15/1+tyrone-node15/0
12/20/2013 10:22:14;0008;PBS_Server;Job;NULL;on_job_exit valid pjob: 0x26e3610 (substate=53)
12/20/2013 10:22:14;0100;PBS_Server;Job;33381.tyrone-cluster;dequeuing from qp64, state COMPLETE
12/20/2013 10:22:14;0040;PBS_Server;Svr;tyrone-cluster;Scheduler was sent the command term
12/20/2013 10:24:33;0002;PBS_Server;Svr;PBS_Server;Torque Server Version = 3.0.5, loglevel = 0
12/20/2013 10:27:59;0100;PBS_Server;Job;33382.tyrone-cluster;enqueuing into batch, state 1 hop 1
12/20/2013 10:27:59;0100;PBS_Server;Job;33382.tyrone-cluster;dequeuing from batch, state QUEUED
12/20/2013 10:27:59;0100;PBS_Server;Job;33382.tyrone-cluster;enqueuing into qp64, state 1 hop 1
12/20/2013 10:27:59;0008;PBS_Server;Job;33382.tyrone-cluster;Job Queued at request of mbuavdhs@tyrone-cluster, owner = mbuavdhs@tyrone-cluster, job name = mlecdigy162-12-12-13, queue = qp64
12/20/2013 10:27:59;0040;PBS_Server;Svr;tyrone-cluster;Scheduler was sent the command new
12/20/2013 10:28:00;0008;PBS_Server;Job;33382.tyrone-cluster;Job Modified at request of Scheduler@tyrone-cluster
12/20/2013 10:28:00;0008;PBS_Server;Job;33382.tyrone-cluster;Job Run at request of Scheduler@tyrone-cluster
12/20/2013 10:28:00;0040;PBS_Server;Svr;tyrone-cluster;Scheduler was sent the command recyc
12/20/2013 10:28:00;000d;PBS_Server;Job;33382.tyrone-cluster;Not sending email: User does not want mail of this type.
12/20/2013 10:29:33;0002;PBS_Server;Svr;PBS_Server;Torque Server Version = 3.0.5, loglevel = 0
12/20/2013 10:31:12;0100;PBS_Server;Job;33383.tyrone-cluster;enqueuing into batch, state 1 hop 1
12/20/2013 10:31:12;0100;PBS_Server;Job;33383.tyrone-cluster;dequeuing from batch, state QUEUED
12/20/2013 10:31:12;0100;PBS_Server;Job;33383.tyrone-cluster;enqueuing into qp64, state 1 hop 1
12/20/2013 10:31:12;0008;PBS_Server;Job;33383.tyrone-cluster;Job Queued at request of mbuteja@tyrone-cluster, owner = mbuteja@tyrone-cluster, job name = mlecman9-y162-16-12-13, queue = qp64
12/20/2013 10:31:12;0040;PBS_Server;Svr;tyrone-cluster;Scheduler was sent the command new
12/20/2013 10:31:13;0008;PBS_Server;Job;33383.tyrone-cluster;Job Modified at request of Scheduler@tyrone-cluster
12/20/2013 10:31:13;0008;PBS_Server;Job;33383.tyrone-cluster;Job Run at request of Scheduler@tyrone-cluster
12/20/2013 10:31:13;0040;PBS_Server;Svr;tyrone-cluster;Scheduler was sent the command recyc
12/20/2013 10:31:13;000d;PBS_Server;Job;33383.tyrone-cluster;Not sending email: User does not want mail of this type.
12/20/2013 10:31:42;0100;PBS_Server;Job;33384.tyrone-cluster;enqueuing into batch, state 1 hop 1
12/20/2013 10:31:42;0100;PBS_Server;Job;33384.tyrone-cluster;dequeuing from batch, state QUEUED
12/20/2013 10:31:42;0100;PBS_Server;Job;33384.tyrone-cluster;enqueuing into qp64, state 1 hop 1
12/20/2013 10:31:42;0008;PBS_Server;Job;33384.tyrone-cluster;Job Queued at request of mbuteja@tyrone-cluster, owner = mbuteja@tyrone-cluster, job name = mlecman9-y162-16-12-13, queue = qp64
12/20/2013 10:31:42;0040;PBS_Server;Svr;tyrone-cluster;Scheduler was sent the command new
12/20/2013 10:31:42;0008;PBS_Server;Job;33384.tyrone-cluster;Job Modified at request of Scheduler@tyrone-cluster
12/20/2013 10:34:33;0002;PBS_Server;Svr;PBS_Server;Torque Server Version = 3.0.5, loglevel = 0
12/20/2013 10:35:18;0100;PBS_Server;Job;33385.tyrone-cluster;enqueuing into batch, state 1 hop 1
12/20/2013 10:35:18;0100;PBS_Server;Job;33385.tyrone-cluster;dequeuing from batch, state QUEUED
12/20/2013 10:35:18;0100;PBS_Server;Job;33385.tyrone-cluster;enqueuing into qp32, state 1 hop 1
12/20/2013 10:35:18;0008;PBS_Server;Job;33385.tyrone-cluster;Job Queued at request of ipcdskp@tyrone-cluster, owner = ipcdskp@tyrone-cluster, job name = n10, queue = qp32
12/20/2013 10:35:18;0040;PBS_Server;Svr;tyrone-cluster;Scheduler was sent the command new
12/20/2013 10:35:18;0008;PBS_Server;Job;33385.tyrone-cluster;Job Modified at request of Scheduler@tyrone-cluster
12/20/2013 10:35:18;0008;PBS_Server;Job;33385.tyrone-cluster;Job Run at request of Scheduler@tyrone-cluster
12/20/2013 10:35:18;0040;PBS_Server;Svr;tyrone-cluster;Scheduler was sent the command recyc
12/20/2013 10:35:18;000d;PBS_Server;Job;33385.tyrone-cluster;Not sending email: User does not want mail of this type.
12/20/2013 10:36:50;0008;PBS_Server;Job;33379.tyrone-cluster;Job deleted at request of ipcanilk@tyrone-cluster
12/20/2013 10:36:50;0008;PBS_Server;Job;33379.tyrone-cluster;Job sent signal SIGTERM on delete
12/20/2013 10:36:52;0008;PBS_Server;Job;33379.tyrone-cluster;Job sent signal SIGKILL on delete
12/20/2013 10:36:52;000d;PBS_Server;Job;33379.tyrone-cluster;Not sending email: User does not want mail of this type.
12/20/2013 10:36:52;0010;PBS_Server;Job;33379.tyrone-cluster;Exit_status=143 resources_used.cput=20:39:02 resources_used.mem=50877560kb resources_used.vmem=95820544kb resources_used.walltime=00:19:29
12/20/2013 10:36:52;0008;PBS_Server;Job;NULL;on_job_exit valid pjob: 0x2669eb0 (substate=50)
12/20/2013 10:36:52;0008;PBS_Server;Job;NULL;on_job_exit valid pjob: 0x2669eb0 (substate=51)
12/20/2013 10:36:54;0008;PBS_Server;Job;NULL;on_job_exit valid pjob: 0x2669eb0 (substate=51)
12/20/2013 10:36:54;0008;PBS_Server;Job;NULL;on_job_exit valid pjob: 0x2669eb0 (substate=53)
12/20/2013 10:36:54;0100;PBS_Server;Job;33379.tyrone-cluster;dequeuing from qp64, state COMPLETE
12/20/2013 10:36:54;0040;PBS_Server;Svr;tyrone-cluster;Scheduler was sent the command term
12/20/2013 10:36:54;0008;PBS_Server;Job;33384.tyrone-cluster;Job Modified at request of Scheduler@tyrone-cluster
12/20/2013 10:37:56;0100;PBS_Server;Job;33386.tyrone-cluster;enqueuing into batch, state 1 hop 1
12/20/2013 10:37:56;0100;PBS_Server;Job;33386.tyrone-cluster;dequeuing from batch, state QUEUED
12/20/2013 10:37:56;0100;PBS_Server;Job;33386.tyrone-cluster;enqueuing into qp64, state 1 hop 1
12/20/2013 10:37:56;0008;PBS_Server;Job;33386.tyrone-cluster;Job Queued at request of ipcanilk@tyrone-cluster, owner = ipcanilk@tyrone-cluster, job name = job64, queue = qp64
12/20/2013 10:37:56;0040;PBS_Server;Svr;tyrone-cluster;Scheduler was sent the command new
12/20/2013 10:37:56;0008;PBS_Server;Job;33386.tyrone-cluster;Job Modified at request of Scheduler@tyrone-cluster
12/20/2013 10:37:56;0008;PBS_Server;Job;33386.tyrone-cluster;Job Run at request of Scheduler@tyrone-cluster
12/20/2013 10:37:56;0040;PBS_Server;Svr;tyrone-cluster;Scheduler was sent the command recyc
12/20/2013 10:37:56;000d;PBS_Server;Job;33386.tyrone-cluster;Not sending email: User does not want mail of this type.
12/20/2013 10:39:33;0002;PBS_Server;Svr;PBS_Server;Torque Server Version = 3.0.5, loglevel = 0
12/20/2013 10:44:33;0002;PBS_Server;Svr;PBS_Server;Torque Server Version = 3.0.5, loglevel = 0
12/20/2013 10:47:56;0040;PBS_Server;Svr;tyrone-cluster;Scheduler was sent the command time
12/20/2013 10:47:56;0008;PBS_Server;Job;33384.tyrone-cluster;Job Modified at request of Scheduler@tyrone-cluster
12/20/2013 10:49:33;0002;PBS_Server;Svr;PBS_Server;Torque Server Version = 3.0.5, loglevel = 0
12/20/2013 10:54:33;0002;PBS_Server;Svr;PBS_Server;Torque Server Version = 3.0.5, loglevel = 0
12/20/2013 10:57:56;0040;PBS_Server;Svr;tyrone-cluster;Scheduler was sent the command time
12/20/2013 10:59:33;0002;PBS_Server;Svr;PBS_Server;Torque Server Version = 3.0.5, loglevel = 0
12/20/2013 11:04:33;0002;PBS_Server;Svr;PBS_Server;Torque Server Version = 3.0.5, loglevel = 0
12/20/2013 11:07:56;0040;PBS_Server;Svr;tyrone-cluster;Scheduler was sent the command time
12/20/2013 11:09:33;0002;PBS_Server;Svr;PBS_Server;Torque Server Version = 3.0.5, loglevel = 0
12/20/2013 11:14:33;0002;PBS_Server;Svr;PBS_Server;Torque Server Version = 3.0.5, loglevel = 0
12/20/2013 11:17:56;0040;PBS_Server;Svr;tyrone-cluster;Scheduler was sent the command time
12/20/2013 11:19:33;0002;PBS_Server;Svr;PBS_Server;Torque Server Version = 3.0.5, loglevel = 0
12/20/2013 11:24:33;0002;PBS_Server;Svr;PBS_Server;Torque Server Version = 3.0.5, loglevel = 0
12/20/2013 11:27:56;0040;PBS_Server;Svr;tyrone-cluster;Scheduler was sent the command time
12/20/2013 11:29:33;0002;PBS_Server;Svr;PBS_Server;Torque Server Version = 3.0.5, loglevel = 0
12/20/2013 11:34:33;0002;PBS_Server;Svr;PBS_Server;Torque Server Version = 3.0.5, loglevel = 0
12/20/2013 11:37:56;0040;PBS_Server;Svr;tyrone-cluster;Scheduler was sent the command time
12/20/2013 11:39:33;0002;PBS_Server;Svr;PBS_Server;Torque Server Version = 3.0.5, loglevel = 0
12/20/2013 11:44:33;0002;PBS_Server;Svr;PBS_Server;Torque Server Version = 3.0.5, loglevel = 0
12/20/2013 11:47:56;0040;PBS_Server;Svr;tyrone-cluster;Scheduler was sent the command time
12/20/2013 11:49:33;0002;PBS_Server;Svr;PBS_Server;Torque Server Version = 3.0.5, loglevel = 0
12/20/2013 11:54:33;0002;PBS_Server;Svr;PBS_Server;Torque Server Version = 3.0.5, loglevel = 0
12/20/2013 11:55:43;0100;PBS_Server;Job;33387.tyrone-cluster;enqueuing into batch, state 1 hop 1
12/20/2013 11:55:43;0100;PBS_Server;Job;33387.tyrone-cluster;dequeuing from batch, state QUEUED
12/20/2013 11:55:43;0100;PBS_Server;Job;33387.tyrone-cluster;enqueuing into idqueue, state 1 hop 1
12/20/2013 11:55:43;0008;PBS_Server;Job;33387.tyrone-cluster;Job Queued at request of csdrjain@tyrone-cluster, owner = csdrjain@tyrone-cluster, job name = n14, queue = idqueue
12/20/2013 11:55:43;0040;PBS_Server;Svr;tyrone-cluster;Scheduler was sent the command new
12/20/2013 11:55:43;0008;PBS_Server;Job;33387.tyrone-cluster;Job Modified at request of Scheduler@tyrone-cluster
12/20/2013 11:55:43;0008;PBS_Server;Job;33387.tyrone-cluster;Job Run at request of Scheduler@tyrone-cluster
12/20/2013 11:55:43;0040;PBS_Server;Svr;tyrone-cluster;Scheduler was sent the command recyc
12/20/2013 11:55:43;000d;PBS_Server;Job;33387.tyrone-cluster;Not sending email: User does not want mail of this type.
12/20/2013 11:55:46;000d;PBS_Server;Job;33387.tyrone-cluster;Not sending email: User does not want mail of this type.
12/20/2013 11:55:46;0010;PBS_Server;Job;33387.tyrone-cluster;Exit_status=1 resources_used.cput=00:00:00 resources_used.mem=0kb resources_used.vmem=0kb resources_used.walltime=00:00:03
12/20/2013 11:55:46;0008;PBS_Server;Job;NULL;on_job_exit valid pjob: 0x26d7040 (substate=50)
12/20/2013 11:55:46;0008;PBS_Server;Job;NULL;on_job_exit valid pjob: 0x26d7040 (substate=51)
12/20/2013 11:55:46;0008;PBS_Server;Job;NULL;on_job_exit valid pjob: 0x26d7040 (substate=51)
12/20/2013 11:55:46;0008;PBS_Server;Job;NULL;on_job_exit valid pjob: 0x26d7040 (substate=53)
12/20/2013 11:55:46;0100;PBS_Server;Job;33387.tyrone-cluster;dequeuing from idqueue, state COMPLETE
12/20/2013 11:55:46;0040;PBS_Server;Svr;tyrone-cluster;Scheduler was sent the command term
12/20/2013 11:56:44;0100;PBS_Server;Job;33388.tyrone-cluster;enqueuing into batch, state 1 hop 1
12/20/2013 11:56:44;0100;PBS_Server;Job;33388.tyrone-cluster;dequeuing from batch, state QUEUED
12/20/2013 11:56:44;0100;PBS_Server;Job;33388.tyrone-cluster;enqueuing into qp32, state 1 hop 1
12/20/2013 11:56:44;0008;PBS_Server;Job;33388.tyrone-cluster;Job Queued at request of csdrjain@tyrone-cluster, owner = csdrjain@tyrone-cluster, job name = n24, queue = qp32
12/20/2013 11:56:44;0040;PBS_Server;Svr;tyrone-cluster;Scheduler was sent the command new
12/20/2013 11:56:44;0008;PBS_Server;Job;33388.tyrone-cluster;Job Modified at request of Scheduler@tyrone-cluster
12/20/2013 11:56:44;0008;PBS_Server;Job;33388.tyrone-cluster;Job Run at request of Scheduler@tyrone-cluster
12/20/2013 11:56:45;0040;PBS_Server;Svr;tyrone-cluster;Scheduler was sent the command recyc
12/20/2013 11:56:45;000d;PBS_Server;Job;33388.tyrone-cluster;Not sending email: User does not want mail of this type.
12/20/2013 11:56:47;000d;PBS_Server;Job;33388.tyrone-cluster;Not sending email: User does not want mail of this type.
12/20/2013 11:56:47;0010;PBS_Server;Job;33388.tyrone-cluster;Exit_status=1 resources_used.cput=00:00:00 resources_used.mem=1180kb resources_used.vmem=110472kb resources_used.walltime=00:00:03
12/20/2013 11:56:47;0008;PBS_Server;Job;NULL;on_job_exit valid pjob: 0x26d7040 (substate=50)
12/20/2013 11:56:47;0008;PBS_Server;Job;NULL;on_job_exit valid pjob: 0x26d7040 (substate=51)
12/20/2013 11:56:47;0008;PBS_Server;Job;NULL;on_job_exit valid pjob: 0x26d7040 (substate=51)
12/20/2013 11:56:47;0008;PBS_Server;Job;NULL;on_job_exit valid pjob: 0x26d7040 (substate=53)
12/20/2013 11:56:47;0100;PBS_Server;Job;33388.tyrone-cluster;dequeuing from qp32, state COMPLETE
12/20/2013 11:56:47;0040;PBS_Server;Svr;tyrone-cluster;Scheduler was sent the command term
12/20/2013 11:59:33;0002;PBS_Server;Svr;PBS_Server;Torque Server Version = 3.0.5, loglevel = 0
12/20/2013 12:04:33;0002;PBS_Server;Svr;PBS_Server;Torque Server Version = 3.0.5, loglevel = 0
12/20/2013 12:06:47;0040;PBS_Server;Svr;tyrone-cluster;Scheduler was sent the command time
12/20/2013 12:09:33;0002;PBS_Server;Svr;PBS_Server;Torque Server Version = 3.0.5, loglevel = 0
12/20/2013 12:14:33;0002;PBS_Server;Svr;PBS_Server;Torque Server Version = 3.0.5, loglevel = 0
12/20/2013 12:16:47;0040;PBS_Server;Svr;tyrone-cluster;Scheduler was sent the command time
12/20/2013 12:19:33;0002;PBS_Server;Svr;PBS_Server;Torque Server Version = 3.0.5, loglevel = 0
12/20/2013 12:24:33;0002;PBS_Server;Svr;PBS_Server;Torque Server Version = 3.0.5, loglevel = 0
12/20/2013 12:26:47;0040;PBS_Server;Svr;tyrone-cluster;Scheduler was sent the command time
12/20/2013 12:29:33;0002;PBS_Server;Svr;PBS_Server;Torque Server Version = 3.0.5, loglevel = 0
12/20/2013 12:34:33;0002;PBS_Server;Svr;PBS_Server;Torque Server Version = 3.0.5, loglevel = 0
12/20/2013 12:36:47;0040;PBS_Server;Svr;tyrone-cluster;Scheduler was sent the command time
12/20/2013 12:38:39;0100;PBS_Server;Job;33389.tyrone-cluster;enqueuing into batch, state 1 hop 1
12/20/2013 12:38:39;0100;PBS_Server;Job;33389.tyrone-cluster;dequeuing from batch, state QUEUED
12/20/2013 12:38:39;0100;PBS_Server;Job;33389.tyrone-cluster;enqueuing into qp32, state 1 hop 1
12/20/2013 12:38:39;0008;PBS_Server;Job;33389.tyrone-cluster;Job Queued at request of ciesita@tyrone-cluster, owner = ciesita@tyrone-cluster, job name = NE1=8, queue = qp32
12/20/2013 12:38:39;0040;PBS_Server;Svr;tyrone-cluster;Scheduler was sent the command new
12/20/2013 12:38:39;0008;PBS_Server;Job;33389.tyrone-cluster;Job Modified at request of Scheduler@tyrone-cluster
12/20/2013 12:38:39;0008;PBS_Server;Job;33389.tyrone-cluster;Job Run at request of Scheduler@tyrone-cluster
12/20/2013 12:38:39;0040;PBS_Server;Svr;tyrone-cluster;Scheduler was sent the command recyc
12/20/2013 12:38:39;000d;PBS_Server;Job;33389.tyrone-cluster;Not sending email: User does not want mail of this type.
12/20/2013 12:38:44;0100;PBS_Server;Job;33390.tyrone-cluster;enqueuing into batch, state 1 hop 1
12/20/2013 12:38:44;0100;PBS_Server;Job;33390.tyrone-cluster;dequeuing from batch, state QUEUED
12/20/2013 12:38:44;0100;PBS_Server;Job;33390.tyrone-cluster;enqueuing into qp64, state 1 hop 1
12/20/2013 12:38:44;0008;PBS_Server;Job;33390.tyrone-cluster;Job Queued at request of ciesita@tyrone-cluster, owner = ciesita@tyrone-cluster, job name = NE1=10, queue = qp64
12/20/2013 12:38:44;0040;PBS_Server;Svr;tyrone-cluster;Scheduler was sent the command new
12/20/2013 12:38:44;0008;PBS_Server;Job;33390.tyrone-cluster;Job Modified at request of Scheduler@tyrone-cluster
12/20/2013 12:38:44;0008;PBS_Server;Job;33377.tyrone-cluster;Job Modified at request of Scheduler@tyrone-cluster
12/20/2013 12:38:48;0100;PBS_Server;Job;33391.tyrone-cluster;enqueuing into batch, state 1 hop 1
12/20/2013 12:38:48;0100;PBS_Server;Job;33391.tyrone-cluster;dequeuing from batch, state QUEUED
12/20/2013 12:38:48;0100;PBS_Server;Job;33391.tyrone-cluster;enqueuing into qp32, state 1 hop 1
12/20/2013 12:38:48;0008;PBS_Server;Job;33391.tyrone-cluster;Job Queued at request of ciesita@tyrone-cluster, owner = ciesita@tyrone-cluster, job name = NE1=15, queue = qp32
12/20/2013 12:38:48;0040;PBS_Server;Svr;tyrone-cluster;Scheduler was sent the command new
12/20/2013 12:38:48;0008;PBS_Server;Job;33391.tyrone-cluster;Job Modified at request of Scheduler@tyrone-cluster
12/20/2013 12:38:51;0100;PBS_Server;Job;33392.tyrone-cluster;enqueuing into batch, state 1 hop 1
12/20/2013 12:38:51;0100;PBS_Server;Job;33392.tyrone-cluster;dequeuing from batch, state QUEUED
12/20/2013 12:38:51;0100;PBS_Server;Job;33392.tyrone-cluster;enqueuing into qp64, state 1 hop 1
12/20/2013 12:38:51;0008;PBS_Server;Job;33392.tyrone-cluster;Job Queued at request of ciesita@tyrone-cluster, owner = ciesita@tyrone-cluster, job name = NE1=20, queue = qp64
12/20/2013 12:38:51;0040;PBS_Server;Svr;tyrone-cluster;Scheduler was sent the command new
12/20/2013 12:38:51;0008;PBS_Server;Job;33392.tyrone-cluster;Job Modified at request of Scheduler@tyrone-cluster
12/20/2013 12:38:59;0100;PBS_Server;Job;33393.tyrone-cluster;enqueuing into batch, state 1 hop 1
12/20/2013 12:38:59;0100;PBS_Server;Job;33393.tyrone-cluster;dequeuing from batch, state QUEUED
12/20/2013 12:38:59;0100;PBS_Server;Job;33393.tyrone-cluster;enqueuing into qp64, state 1 hop 1
12/20/2013 12:38:59;0008;PBS_Server;Job;33393.tyrone-cluster;Job Queued at request of ciesita@tyrone-cluster, owner = ciesita@tyrone-cluster, job name = NE1=50, queue = qp64
12/20/2013 12:38:59;0040;PBS_Server;Svr;tyrone-cluster;Scheduler was sent the command new
12/20/2013 12:38:59;0008;PBS_Server;Job;33393.tyrone-cluster;Job Modified at request of Scheduler@tyrone-cluster
12/20/2013 12:39:33;0002;PBS_Server;Svr;PBS_Server;Torque Server Version = 3.0.5, loglevel = 0
12/20/2013 12:44:33;0002;PBS_Server;Svr;PBS_Server;Torque Server Version = 3.0.5, loglevel = 0
12/20/2013 12:48:59;0040;PBS_Server;Svr;tyrone-cluster;Scheduler was sent the command time
12/20/2013 12:49:33;0002;PBS_Server;Svr;PBS_Server;Torque Server Version = 3.0.5, loglevel = 0
12/20/2013 12:54:33;0002;PBS_Server;Svr;PBS_Server;Torque Server Version = 3.0.5, loglevel = 0
12/20/2013 12:58:59;0040;PBS_Server;Svr;tyrone-cluster;Scheduler was sent the command time
12/20/2013 12:59:33;0002;PBS_Server;Svr;PBS_Server;Torque Server Version = 3.0.5, loglevel = 0
12/20/2013 13:04:33;0002;PBS_Server;Svr;PBS_Server;Torque Server Version = 3.0.5, loglevel = 0
12/20/2013 13:08:59;0040;PBS_Server;Svr;tyrone-cluster;Scheduler was sent the command time
12/20/2013 13:09:33;0002;PBS_Server;Svr;PBS_Server;Torque Server Version = 3.0.5, loglevel = 0
12/20/2013 13:14:33;0002;PBS_Server;Svr;PBS_Server;Torque Server Version = 3.0.5, loglevel = 0
12/20/2013 13:18:59;0040;PBS_Server;Svr;tyrone-cluster;Scheduler was sent the command time
12/20/2013 13:19:33;0002;PBS_Server;Svr;PBS_Server;Torque Server Version = 3.0.5, loglevel = 0
12/20/2013 13:24:33;0002;PBS_Server;Svr;PBS_Server;Torque Server Version = 3.0.5, loglevel = 0
12/20/2013 13:28:59;0040;PBS_Server;Svr;tyrone-cluster;Scheduler was sent the command time
12/20/2013 13:29:33;0002;PBS_Server;Svr;PBS_Server;Torque Server Version = 3.0.5, loglevel = 0
12/20/2013 13:34:33;0002;PBS_Server;Svr;PBS_Server;Torque Server Version = 3.0.5, loglevel = 0
12/20/2013 13:38:59;0040;PBS_Server;Svr;tyrone-cluster;Scheduler was sent the command time
12/20/2013 13:39:33;0002;PBS_Server;Svr;PBS_Server;Torque Server Version = 3.0.5, loglevel = 0
12/20/2013 13:44:33;0002;PBS_Server;Svr;PBS_Server;Torque Server Version = 3.0.5, loglevel = 0
12/20/2013 13:48:59;0040;PBS_Server;Svr;tyrone-cluster;Scheduler was sent the command time
12/20/2013 13:49:33;0002;PBS_Server;Svr;PBS_Server;Torque Server Version = 3.0.5, loglevel = 0
12/20/2013 13:54:33;0002;PBS_Server;Svr;PBS_Server;Torque Server Version = 3.0.5, loglevel = 0
12/20/2013 13:58:59;0040;PBS_Server;Svr;tyrone-cluster;Scheduler was sent the command time
12/20/2013 13:59:33;0002;PBS_Server;Svr;PBS_Server;Torque Server Version = 3.0.5, loglevel = 0
12/20/2013 14:04:33;0002;PBS_Server;Svr;PBS_Server;Torque Server Version = 3.0.5, loglevel = 0
12/20/2013 14:08:59;0040;PBS_Server;Svr;tyrone-cluster;Scheduler was sent the command time
12/20/2013 14:09:33;0002;PBS_Server;Svr;PBS_Server;Torque Server Version = 3.0.5, loglevel = 0
12/20/2013 14:14:33;0002;PBS_Server;Svr;PBS_Server;Torque Server Version = 3.0.5, loglevel = 0
12/20/2013 14:18:59;0040;PBS_Server;Svr;tyrone-cluster;Scheduler was sent the command time
12/20/2013 14:19:33;0002;PBS_Server;Svr;PBS_Server;Torque Server Version = 3.0.5, loglevel = 0
12/20/2013 14:24:33;0002;PBS_Server;Svr;PBS_Server;Torque Server Version = 3.0.5, loglevel = 0
12/20/2013 14:28:59;0040;PBS_Server;Svr;tyrone-cluster;Scheduler was sent the command time
12/20/2013 14:29:33;0002;PBS_Server;Svr;PBS_Server;Torque Server Version = 3.0.5, loglevel = 0
12/20/2013 14:34:33;0002;PBS_Server;Svr;PBS_Server;Torque Server Version = 3.0.5, loglevel = 0
12/20/2013 14:38:59;0040;PBS_Server;Svr;tyrone-cluster;Scheduler was sent the command time
12/20/2013 14:39:33;0002;PBS_Server;Svr;PBS_Server;Torque Server Version = 3.0.5, loglevel = 0
12/20/2013 14:44:33;0002;PBS_Server;Svr;PBS_Server;Torque Server Version = 3.0.5, loglevel = 0
12/20/2013 14:48:59;0040;PBS_Server;Svr;tyrone-cluster;Scheduler was sent the command time
12/20/2013 14:49:11;000d;PBS_Server;Job;33342.tyrone-cluster;Not sending email: User does not want mail of this type.
12/20/2013 14:49:11;0010;PBS_Server;Job;33342.tyrone-cluster;Exit_status=143 resources_used.cput=1261:44:35 resources_used.mem=17777004kb resources_used.vmem=52689376kb resources_used.walltime=24:00:04
12/20/2013 14:49:11;0008;PBS_Server;Job;NULL;on_job_exit valid pjob: 0x26878b0 (substate=50)
12/20/2013 14:49:11;0008;PBS_Server;Job;NULL;on_job_exit valid pjob: 0x26878b0 (substate=51)
12/20/2013 14:49:14;0008;PBS_Server;Job;NULL;on_job_exit valid pjob: 0x26878b0 (substate=51)
12/20/2013 14:49:14;0008;PBS_Server;Job;NULL;on_job_exit valid pjob: 0x26878b0 (substate=53)
12/20/2013 14:49:14;0100;PBS_Server;Job;33342.tyrone-cluster;dequeuing from qp256, state COMPLETE
12/20/2013 14:49:14;0040;PBS_Server;Svr;tyrone-cluster;Scheduler was sent the command term
12/20/2013 14:49:15;0008;PBS_Server;Job;33242.tyrone-cluster;Job Modified at request of Scheduler@tyrone-cluster
12/20/2013 14:49:15;0008;PBS_Server;Job;33258.tyrone-cluster;Job Modified at request of Scheduler@tyrone-cluster
12/20/2013 14:49:33;0002;PBS_Server;Svr;PBS_Server;Torque Server Version = 3.0.5, loglevel = 0
12/20/2013 14:53:52;0100;PBS_Server;Job;33394.tyrone-cluster;enqueuing into batch, state 1 hop 1
12/20/2013 14:53:52;0100;PBS_Server;Job;33394.tyrone-cluster;dequeuing from batch, state QUEUED
12/20/2013 14:53:52;0100;PBS_Server;Job;33394.tyrone-cluster;enqueuing into idqueue, state 1 hop 1
12/20/2013 14:53:52;0008;PBS_Server;Job;33394.tyrone-cluster;Job Queued at request of csdrjain@tyrone-cluster, owner = csdrjain@tyrone-cluster, job name = n14, queue = idqueue
12/20/2013 14:53:52;0040;PBS_Server;Svr;tyrone-cluster;Scheduler was sent the command new
12/20/2013 14:53:52;0008;PBS_Server;Job;33394.tyrone-cluster;Job Modified at request of Scheduler@tyrone-cluster
12/20/2013 14:53:52;0008;PBS_Server;Job;33394.tyrone-cluster;Job Run at request of Scheduler@tyrone-cluster
12/20/2013 14:53:52;0040;PBS_Server;Svr;tyrone-cluster;Scheduler was sent the command recyc
12/20/2013 14:53:52;000d;PBS_Server;Job;33394.tyrone-cluster;Not sending email: User does not want mail of this type.
12/20/2013 14:54:33;0002;PBS_Server;Svr;PBS_Server;Torque Server Version = 3.0.5, loglevel = 0
12/20/2013 14:59:33;0002;PBS_Server;Svr;PBS_Server;Torque Server Version = 3.0.5, loglevel = 0
12/20/2013 15:02:12;0100;PBS_Server;Job;33395.tyrone-cluster;enqueuing into batch, state 1 hop 1
12/20/2013 15:02:12;0100;PBS_Server;Job;33395.tyrone-cluster;dequeuing from batch, state QUEUED
12/20/2013 15:02:12;0100;PBS_Server;Job;33395.tyrone-cluster;enqueuing into idqueue, state 1 hop 1
12/20/2013 15:02:12;0008;PBS_Server;Job;33395.tyrone-cluster;Job Queued at request of csdrjain@tyrone-cluster, owner = csdrjain@tyrone-cluster, job name = n15, queue = idqueue
12/20/2013 15:02:12;0040;PBS_Server;Svr;tyrone-cluster;Scheduler was sent the command new
12/20/2013 15:02:12;0008;PBS_Server;Job;33395.tyrone-cluster;Job Modified at request of Scheduler@tyrone-cluster
12/20/2013 15:04:33;0002;PBS_Server;Svr;PBS_Server;Torque Server Version = 3.0.5, loglevel = 0
12/20/2013 15:09:33;0002;PBS_Server;Svr;PBS_Server;Torque Server Version = 3.0.5, loglevel = 0
12/20/2013 15:12:12;0040;PBS_Server;Svr;tyrone-cluster;Scheduler was sent the command time
12/20/2013 15:14:33;0002;PBS_Server;Svr;PBS_Server;Torque Server Version = 3.0.5, loglevel = 0
12/20/2013 15:19:33;0002;PBS_Server;Svr;PBS_Server;Torque Server Version = 3.0.5, loglevel = 0
12/20/2013 15:22:12;0040;PBS_Server;Svr;tyrone-cluster;Scheduler was sent the command time
12/20/2013 15:24:33;0002;PBS_Server;Svr;PBS_Server;Torque Server Version = 3.0.5, loglevel = 0
12/20/2013 15:29:33;0002;PBS_Server;Svr;PBS_Server;Torque Server Version = 3.0.5, loglevel = 0
12/20/2013 15:32:12;0040;PBS_Server;Svr;tyrone-cluster;Scheduler was sent the command time
12/20/2013 15:33:54;0100;PBS_Server;Job;33396.tyrone-cluster;enqueuing into batch, state 1 hop 1
12/20/2013 15:33:54;0100;PBS_Server;Job;33396.tyrone-cluster;dequeuing from batch, state QUEUED
12/20/2013 15:33:54;0100;PBS_Server;Job;33396.tyrone-cluster;enqueuing into qp32, state 1 hop 1
12/20/2013 15:33:54;0008;PBS_Server;Job;33396.tyrone-cluster;Job Queued at request of csdrjain@tyrone-cluster, owner = csdrjain@tyrone-cluster, job name = n24, queue = qp32
12/20/2013 15:33:54;0040;PBS_Server;Svr;tyrone-cluster;Scheduler was sent the command new
12/20/2013 15:33:54;0008;PBS_Server;Job;33396.tyrone-cluster;Job Modified at request of Scheduler@tyrone-cluster
12/20/2013 15:34:33;0002;PBS_Server;Svr;PBS_Server;Torque Server Version = 3.0.5, loglevel = 0
12/20/2013 15:36:09;0100;PBS_Server;Job;33397.tyrone-cluster;enqueuing into batch, state 1 hop 1
12/20/2013 15:36:09;0100;PBS_Server;Job;33397.tyrone-cluster;dequeuing from batch, state QUEUED
12/20/2013 15:36:09;0100;PBS_Server;Job;33397.tyrone-cluster;enqueuing into qp32, state 1 hop 1
12/20/2013 15:36:09;0008;PBS_Server;Job;33397.tyrone-cluster;Job Queued at request of csdrjain@tyrone-cluster, owner = csdrjain@tyrone-cluster, job name = n24_1, queue = qp32
12/20/2013 15:36:09;0040;PBS_Server;Svr;tyrone-cluster;Scheduler was sent the command new
12/20/2013 15:36:09;0008;PBS_Server;Job;33397.tyrone-cluster;Job Modified at request of Scheduler@tyrone-cluster
12/20/2013 15:38:54;0100;PBS_Server;Job;33398.tyrone-cluster;enqueuing into batch, state 1 hop 1
12/20/2013 15:38:54;0100;PBS_Server;Job;33398.tyrone-cluster;dequeuing from batch, state QUEUED
12/20/2013 15:38:54;0100;PBS_Server;Job;33398.tyrone-cluster;enqueuing into qp32, state 1 hop 1
12/20/2013 15:38:54;0008;PBS_Server;Job;33398.tyrone-cluster;Job Queued at request of csdrjain@tyrone-cluster, owner = csdrjain@tyrone-cluster, job name = n24_2, queue = qp32
12/20/2013 15:38:54;0040;PBS_Server;Svr;tyrone-cluster;Scheduler was sent the command new
12/20/2013 15:38:54;0008;PBS_Server;Job;33398.tyrone-cluster;Job Modified at request of Scheduler@tyrone-cluster
12/20/2013 15:39:33;0002;PBS_Server;Svr;PBS_Server;Torque Server Version = 3.0.5, loglevel = 0
12/20/2013 15:41:49;0100;PBS_Server;Job;33399.tyrone-cluster;enqueuing into batch, state 1 hop 1
12/20/2013 15:41:49;0008;PBS_Server;Job;33399.tyrone-cluster;Job Queued at request of csdrjain@tyrone-cluster, owner = csdrjain@tyrone-cluster, job name = n24_3, queue = batch
12/20/2013 15:41:49;0040;PBS_Server;Svr;tyrone-cluster;Scheduler was sent the command new
12/20/2013 15:41:50;0008;PBS_Server;Job;33399.tyrone-cluster;Job Modified at request of Scheduler@tyrone-cluster
12/20/2013 15:42:23;0040;PBS_Server;Svr;tyrone-cluster;Scheduler was sent the command new
12/20/2013 15:42:54;0040;PBS_Server;Svr;tyrone-cluster;Scheduler was sent the command new
12/20/2013 15:43:25;0040;PBS_Server;Svr;tyrone-cluster;Scheduler was sent the command new
12/20/2013 15:43:58;0040;PBS_Server;Svr;tyrone-cluster;Scheduler was sent the command new
12/20/2013 15:44:28;0040;PBS_Server;Svr;tyrone-cluster;Scheduler was sent the command new
12/20/2013 15:44:33;0002;PBS_Server;Svr;PBS_Server;Torque Server Version = 3.0.5, loglevel = 0
12/20/2013 15:45:00;0040;PBS_Server;Svr;tyrone-cluster;Scheduler was sent the command new
12/20/2013 15:45:33;0040;PBS_Server;Svr;tyrone-cluster;Scheduler was sent the command new
12/20/2013 15:46:08;0040;PBS_Server;Svr;tyrone-cluster;Scheduler was sent the command new
12/20/2013 15:46:39;0040;PBS_Server;Svr;tyrone-cluster;Scheduler was sent the command new
12/20/2013 15:47:10;0040;PBS_Server;Svr;tyrone-cluster;Scheduler was sent the command new
12/20/2013 15:47:43;0040;PBS_Server;Svr;tyrone-cluster;Scheduler was sent the command new
12/20/2013 15:48:13;0040;PBS_Server;Svr;tyrone-cluster;Scheduler was sent the command new
12/20/2013 15:48:45;0040;PBS_Server;Svr;tyrone-cluster;Scheduler was sent the command new
12/20/2013 15:49:15;0040;PBS_Server;Svr;tyrone-cluster;Scheduler was sent the command new
12/20/2013 15:49:33;0002;PBS_Server;Svr;PBS_Server;Torque Server Version = 3.0.5, loglevel = 0
12/20/2013 15:49:45;0040;PBS_Server;Svr;tyrone-cluster;Scheduler was sent the command new
12/20/2013 15:50:15;0040;PBS_Server;Svr;tyrone-cluster;Scheduler was sent the command new
12/20/2013 15:50:48;0040;PBS_Server;Svr;tyrone-cluster;Scheduler was sent the command new
12/20/2013 15:51:15;0040;PBS_Server;Svr;tyrone-cluster;Scheduler was sent the command new
12/20/2013 15:51:45;0040;PBS_Server;Svr;tyrone-cluster;Scheduler was sent the command new
12/20/2013 15:52:18;0040;PBS_Server;Svr;tyrone-cluster;Scheduler was sent the command new
12/20/2013 15:52:53;0040;PBS_Server;Svr;tyrone-cluster;Scheduler was sent the command new
12/20/2013 15:53:24;0040;PBS_Server;Svr;tyrone-cluster;Scheduler was sent the command new
12/20/2013 15:53:35;000d;PBS_Server;Job;33394.tyrone-cluster;Not sending email: User does not want mail of this type.
12/20/2013 15:53:35;0010;PBS_Server;Job;33394.tyrone-cluster;Exit_status=0 resources_used.cput=28:28:33 resources_used.mem=412948kb resources_used.vmem=4250604kb resources_used.walltime=00:59:43
12/20/2013 15:53:35;0008;PBS_Server;Job;NULL;on_job_exit valid pjob: 0x26878b0 (substate=50)
12/20/2013 15:53:35;0008;PBS_Server;Job;NULL;on_job_exit valid pjob: 0x26878b0 (substate=51)
12/20/2013 15:53:35;0008;PBS_Server;Job;NULL;on_job_exit valid pjob: 0x26878b0 (substate=51)
12/20/2013 15:53:35;0008;PBS_Server;Job;NULL;on_job_exit valid pjob: 0x26878b0 (substate=53)
12/20/2013 15:53:35;0100;PBS_Server;Job;33394.tyrone-cluster;dequeuing from idqueue, state COMPLETE
12/20/2013 15:53:35;0040;PBS_Server;Svr;tyrone-cluster;Scheduler was sent the command term
12/20/2013 15:53:35;0008;PBS_Server;Job;33395.tyrone-cluster;Job Modified at request of Scheduler@tyrone-cluster
12/20/2013 15:53:35;0008;PBS_Server;Job;33395.tyrone-cluster;Job Run at request of Scheduler@tyrone-cluster
12/20/2013 15:53:35;0040;PBS_Server;Svr;tyrone-cluster;Scheduler was sent the command recyc
12/20/2013 15:53:35;000d;PBS_Server;Job;33395.tyrone-cluster;Not sending email: User does not want mail of this type.
12/20/2013 15:53:38;000d;PBS_Server;Job;33395.tyrone-cluster;Not sending email: User does not want mail of this type.
12/20/2013 15:53:38;0010;PBS_Server;Job;33395.tyrone-cluster;Exit_status=1 resources_used.cput=00:00:00 resources_used.mem=0kb resources_used.vmem=0kb resources_used.walltime=00:00:03
12/20/2013 15:53:38;0008;PBS_Server;Job;NULL;on_job_exit valid pjob: 0x26e0ee0 (substate=50)
12/20/2013 15:53:38;0008;PBS_Server;Job;NULL;on_job_exit valid pjob: 0x26e0ee0 (substate=51)
12/20/2013 15:53:38;0008;PBS_Server;Job;NULL;on_job_exit valid pjob: 0x26e0ee0 (substate=51)
12/20/2013 15:53:38;0008;PBS_Server;Job;NULL;on_job_exit valid pjob: 0x26e0ee0 (substate=53)
12/20/2013 15:53:38;0100;PBS_Server;Job;33395.tyrone-cluster;dequeuing from idqueue, state COMPLETE
12/20/2013 15:53:38;0040;PBS_Server;Svr;tyrone-cluster;Scheduler was sent the command term
12/20/2013 15:53:55;0040;PBS_Server;Svr;tyrone-cluster;Scheduler was sent the command new
12/20/2013 15:54:27;0040;PBS_Server;Svr;tyrone-cluster;Scheduler was sent the command new
12/20/2013 15:54:33;0002;PBS_Server;Svr;PBS_Server;Torque Server Version = 3.0.5, loglevel = 0
12/20/2013 15:54:56;0040;PBS_Server;Svr;tyrone-cluster;Scheduler was sent the command new
12/20/2013 15:55:25;0040;PBS_Server;Svr;tyrone-cluster;Scheduler was sent the command new
12/20/2013 15:55:57;0040;PBS_Server;Svr;tyrone-cluster;Scheduler was sent the command new
12/20/2013 15:56:26;0040;PBS_Server;Svr;tyrone-cluster;Scheduler was sent the command new
12/20/2013 15:56:55;0040;PBS_Server;Svr;tyrone-cluster;Scheduler was sent the command new
12/20/2013 15:57:27;0040;PBS_Server;Svr;tyrone-cluster;Scheduler was sent the command new
12/20/2013 15:57:56;0040;PBS_Server;Svr;tyrone-cluster;Scheduler was sent the command new
12/20/2013 15:58:30;0040;PBS_Server;Svr;tyrone-cluster;Scheduler was sent the command new
12/20/2013 15:59:00;0040;PBS_Server;Svr;tyrone-cluster;Scheduler was sent the command new
12/20/2013 15:59:30;0040;PBS_Server;Svr;tyrone-cluster;Scheduler was sent the command new
12/20/2013 15:59:33;0002;PBS_Server;Svr;PBS_Server;Torque Server Version = 3.0.5, loglevel = 0
12/20/2013 16:00:00;0040;PBS_Server;Svr;tyrone-cluster;Scheduler was sent the command new
12/20/2013 16:00:36;0040;PBS_Server;Svr;tyrone-cluster;Scheduler was sent the command new
12/20/2013 16:01:00;0040;PBS_Server;Svr;tyrone-cluster;Scheduler was sent the command new
12/20/2013 16:01:30;0040;PBS_Server;Svr;tyrone-cluster;Scheduler was sent the command new
12/20/2013 16:02:03;0040;PBS_Server;Svr;tyrone-cluster;Scheduler was sent the command new
12/20/2013 16:02:30;0040;PBS_Server;Svr;tyrone-cluster;Scheduler was sent the command new
12/20/2013 16:03:00;0040;PBS_Server;Svr;tyrone-cluster;Scheduler was sent the command new
12/20/2013 16:03:37;0040;PBS_Server;Svr;tyrone-cluster;Scheduler was sent the command new
12/20/2013 16:04:08;0040;PBS_Server;Svr;tyrone-cluster;Scheduler was sent the command new
12/20/2013 16:04:33;0002;PBS_Server;Svr;PBS_Server;Torque Server Version = 3.0.5, loglevel = 0
12/20/2013 16:04:39;0040;PBS_Server;Svr;tyrone-cluster;Scheduler was sent the command new
12/20/2013 16:05:10;0040;PBS_Server;Svr;tyrone-cluster;Scheduler was sent the command new
12/20/2013 16:05:42;0040;PBS_Server;Svr;tyrone-cluster;Scheduler was sent the command new
12/20/2013 16:06:11;0040;PBS_Server;Svr;tyrone-cluster;Scheduler was sent the command new
12/20/2013 16:06:45;0040;PBS_Server;Svr;tyrone-cluster;Scheduler was sent the command new
12/20/2013 16:07:15;0040;PBS_Server;Svr;tyrone-cluster;Scheduler was sent the command new
12/20/2013 16:07:45;0040;PBS_Server;Svr;tyrone-cluster;Scheduler was sent the command new
12/20/2013 16:08:15;0040;PBS_Server;Svr;tyrone-cluster;Scheduler was sent the command new
12/20/2013 16:08:51;0040;PBS_Server;Svr;tyrone-cluster;Scheduler was sent the command new
12/20/2013 16:09:16;0040;PBS_Server;Svr;tyrone-cluster;Scheduler was sent the command new
12/20/2013 16:09:33;0002;PBS_Server;Svr;PBS_Server;Torque Server Version = 3.0.5, loglevel = 0
12/20/2013 16:09:45;0040;PBS_Server;Svr;tyrone-cluster;Scheduler was sent the command new
12/20/2013 16:10:21;0040;PBS_Server;Svr;tyrone-cluster;Scheduler was sent the command new
12/20/2013 16:10:45;0040;PBS_Server;Svr;tyrone-cluster;Scheduler was sent the command new
12/20/2013 16:11:15;0040;PBS_Server;Svr;tyrone-cluster;Scheduler was sent the command new
12/20/2013 16:11:52;0040;PBS_Server;Svr;tyrone-cluster;Scheduler was sent the command new
12/20/2013 16:12:23;0040;PBS_Server;Svr;tyrone-cluster;Scheduler was sent the command new
12/20/2013 16:12:54;0040;PBS_Server;Svr;tyrone-cluster;Scheduler was sent the command new
12/20/2013 16:13:25;0040;PBS_Server;Svr;tyrone-cluster;Scheduler was sent the command new
12/20/2013 16:13:57;0040;PBS_Server;Svr;tyrone-cluster;Scheduler was sent the command new
12/20/2013 16:14:26;0040;PBS_Server;Svr;tyrone-cluster;Scheduler was sent the command new
12/20/2013 16:14:33;0002;PBS_Server;Svr;PBS_Server;Torque Server Version = 3.0.5, loglevel = 0
12/20/2013 16:15:00;0040;PBS_Server;Svr;tyrone-cluster;Scheduler was sent the command new
12/20/2013 16:15:36;0040;PBS_Server;Svr;tyrone-cluster;Scheduler was sent the command new
12/20/2013 16:16:00;0040;PBS_Server;Svr;tyrone-cluster;Scheduler was sent the command new
12/20/2013 16:16:30;0040;PBS_Server;Svr;tyrone-cluster;Scheduler was sent the command new
12/20/2013 16:17:03;0040;PBS_Server;Svr;tyrone-cluster;Scheduler was sent the command new
12/20/2013 16:17:30;0040;PBS_Server;Svr;tyrone-cluster;Scheduler was sent the command new
12/20/2013 16:18:00;0040;PBS_Server;Svr;tyrone-cluster;Scheduler was sent the command new
12/20/2013 16:18:37;0040;PBS_Server;Svr;tyrone-cluster;Scheduler was sent the command new
12/20/2013 16:19:08;0040;PBS_Server;Svr;tyrone-cluster;Scheduler was sent the command new
12/20/2013 16:19:33;0002;PBS_Server;Svr;PBS_Server;Torque Server Version = 3.0.5, loglevel = 0
12/20/2013 16:19:39;0040;PBS_Server;Svr;tyrone-cluster;Scheduler was sent the command new
12/20/2013 16:20:07;0100;PBS_Server;Job;33400.tyrone-cluster;enqueuing into batch, state 1 hop 1
12/20/2013 16:20:07;0100;PBS_Server;Job;33400.tyrone-cluster;dequeuing from batch, state QUEUED
12/20/2013 16:20:07;0100;PBS_Server;Job;33400.tyrone-cluster;enqueuing into idqueue, state 1 hop 1
12/20/2013 16:20:07;0008;PBS_Server;Job;33400.tyrone-cluster;Job Queued at request of csdrjain@tyrone-cluster, owner = csdrjain@tyrone-cluster, job name = n14, queue = idqueue
12/20/2013 16:20:07;0040;PBS_Server;Svr;tyrone-cluster;Scheduler was sent the command new
12/20/2013 16:20:07;0008;PBS_Server;Job;33400.tyrone-cluster;Job Modified at request of Scheduler@tyrone-cluster
12/20/2013 16:20:07;0008;PBS_Server;Job;33400.tyrone-cluster;Job Run at request of Scheduler@tyrone-cluster
12/20/2013 16:20:07;0040;PBS_Server;Svr;tyrone-cluster;Scheduler was sent the command recyc
12/20/2013 16:20:07;000d;PBS_Server;Job;33400.tyrone-cluster;Not sending email: User does not want mail of this type.
12/20/2013 16:20:10;0040;PBS_Server;Svr;tyrone-cluster;Scheduler was sent the command new
12/20/2013 16:20:42;0040;PBS_Server;Svr;tyrone-cluster;Scheduler was sent the command new
12/20/2013 16:21:11;0040;PBS_Server;Svr;tyrone-cluster;Scheduler was sent the command new
12/20/2013 16:21:40;0040;PBS_Server;Svr;tyrone-cluster;Scheduler was sent the command new
12/20/2013 16:22:13;0040;PBS_Server;Svr;tyrone-cluster;Scheduler was sent the command new
12/20/2013 16:22:43;0040;PBS_Server;Svr;tyrone-cluster;Scheduler was sent the command new
12/20/2013 16:23:14;0040;PBS_Server;Svr;tyrone-cluster;Scheduler was sent the command new
12/20/2013 16:23:33;000d;PBS_Server;Job;33400.tyrone-cluster;Not sending email: User does not want mail of this type.
12/20/2013 16:23:33;0010;PBS_Server;Job;33400.tyrone-cluster;Exit_status=0 resources_used.cput=01:40:32 resources_used.mem=352264kb resources_used.vmem=4252348kb resources_used.walltime=00:03:26
12/20/2013 16:23:33;0008;PBS_Server;Job;NULL;on_job_exit valid pjob: 0x26878b0 (substate=50)
12/20/2013 16:23:33;0008;PBS_Server;Job;NULL;on_job_exit valid pjob: 0x26878b0 (substate=51)
12/20/2013 16:23:33;0008;PBS_Server;Job;NULL;on_job_exit valid pjob: 0x26878b0 (substate=51)
12/20/2013 16:23:33;0008;PBS_Server;Job;NULL;on_job_exit valid pjob: 0x26878b0 (substate=53)
12/20/2013 16:23:33;0100;PBS_Server;Job;33400.tyrone-cluster;dequeuing from idqueue, state COMPLETE
12/20/2013 16:23:33;0040;PBS_Server;Svr;tyrone-cluster;Scheduler was sent the command term
12/20/2013 16:23:35;000d;PBS_Server;Job;33383.tyrone-cluster;Not sending email: User does not want mail of this type.
12/20/2013 16:23:35;0010;PBS_Server;Job;33383.tyrone-cluster;Exit_status=255 resources_used.cput=375:47:11 resources_used.mem=1343556kb resources_used.vmem=35026272kb resources_used.walltime=05:52:29
12/20/2013 16:23:35;0008;PBS_Server;Job;NULL;on_job_exit valid pjob: 0x26e9d70 (substate=50)
12/20/2013 16:23:35;0008;PBS_Server;Job;NULL;on_job_exit valid pjob: 0x26e9d70 (substate=51)
12/20/2013 16:23:40;0008;PBS_Server;Job;NULL;on_job_exit valid pjob: 0x26e9d70 (substate=51)
12/20/2013 16:23:40;000d;PBS_Server;Job;33383.tyrone-cluster;Post job file processing error; job 33383.tyrone-cluster on host tyrone-node16/63+tyrone-node16/62+tyrone-node16/61+tyrone-node16/60+tyrone-node16/59+tyrone-node16/58+tyrone-node16/57+tyrone-node16/56+tyrone-node16/55+tyrone-node16/54+tyrone-node16/53+tyrone-node16/52+tyrone-node16/51+tyrone-node16/50+tyrone-node16/49+tyrone-node16/48+tyrone-node16/47+tyrone-node16/46+tyrone-node16/45+tyrone-node16/44+tyrone-node16/43+tyrone-node16/42+tyrone-node16/41+tyrone-node16/40+tyrone-node16/39+tyrone-node16/38+tyrone-node16/37+tyrone-node16/36+tyrone-node16/35+tyrone-node16/34+tyrone-node16/33+tyrone-node16/32+tyrone-node16/31+tyrone-node16/30+tyrone-node16/29+tyrone-node16/28+tyrone-node16/27+tyrone-node16/26+tyrone-node16/25+tyrone-node16/24+tyrone-node16/23+tyrone-node16/22+tyrone-node16/21+tyrone-node16/20+tyrone-node16/19+tyrone-node16/18+tyrone-node16/17+tyrone-node16/16+tyrone-node16/15+tyrone-node16/14+tyrone-node16/13+tyrone-node16/12+tyrone-node16/11+tyrone-node16/10+tyrone-node16/9+tyrone-node16/8+tyrone-node16/7+tyrone-node16/6+tyrone-node16/5+tyrone-node16/4+tyrone-node16/3+tyrone-node16/2+tyrone-node16/1+tyrone-node16/0
12/20/2013 16:23:40;0008;PBS_Server;Job;NULL;on_job_exit valid pjob: 0x26e9d70 (substate=53)
12/20/2013 16:23:40;0100;PBS_Server;Job;33383.tyrone-cluster;dequeuing from qp64, state COMPLETE
12/20/2013 16:23:40;0040;PBS_Server;Svr;tyrone-cluster;Scheduler was sent the command term
12/20/2013 16:23:40;0008;PBS_Server;Job;33384.tyrone-cluster;Job Modified at request of Scheduler@tyrone-cluster
12/20/2013 16:23:40;0008;PBS_Server;Job;33384.tyrone-cluster;Job Run at request of Scheduler@tyrone-cluster
12/20/2013 16:23:40;000d;PBS_Server;Job;33384.tyrone-cluster;Not sending email: User does not want mail of this type.
12/20/2013 16:23:40;0040;PBS_Server;Svr;tyrone-cluster;Scheduler was sent the command recyc
12/20/2013 16:23:44;0040;PBS_Server;Svr;tyrone-cluster;Scheduler was sent the command new
12/20/2013 16:23:51;000d;PBS_Server;Job;33384.tyrone-cluster;Not sending email: User does not want mail of this type.
12/20/2013 16:23:51;0010;PBS_Server;Job;33384.tyrone-cluster;Exit_status=255 resources_used.cput=00:06:53 resources_used.mem=530536kb resources_used.vmem=34437316kb resources_used.walltime=00:00:11
12/20/2013 16:23:51;0008;PBS_Server;Job;NULL;on_job_exit valid pjob: 0x265bdb0 (substate=50)
12/20/2013 16:23:51;0008;PBS_Server;Job;NULL;on_job_exit valid pjob: 0x265bdb0 (substate=51)
12/20/2013 16:23:55;0008;PBS_Server;Job;NULL;on_job_exit valid pjob: 0x265bdb0 (substate=51)
12/20/2013 16:23:55;000d;PBS_Server;Job;33384.tyrone-cluster;Post job file processing error; job 33384.tyrone-cluster on host tyrone-node9/63+tyrone-node9/62+tyrone-node9/61+tyrone-node9/60+tyrone-node9/59+tyrone-node9/58+tyrone-node9/57+tyrone-node9/56+tyrone-node9/55+tyrone-node9/54+tyrone-node9/53+tyrone-node9/52+tyrone-node9/51+tyrone-node9/50+tyrone-node9/49+tyrone-node9/48+tyrone-node9/47+tyrone-node9/46+tyrone-node9/45+tyrone-node9/44+tyrone-node9/43+tyrone-node9/42+tyrone-node9/41+tyrone-node9/40+tyrone-node9/39+tyrone-node9/38+tyrone-node9/37+tyrone-node9/36+tyrone-node9/35+tyrone-node9/34+tyrone-node9/33+tyrone-node9/32+tyrone-node9/31+tyrone-node9/30+tyrone-node9/29+tyrone-node9/28+tyrone-node9/27+tyrone-node9/26+tyrone-node9/25+tyrone-node9/24+tyrone-node9/23+tyrone-node9/22+tyrone-node9/21+tyrone-node9/20+tyrone-node9/19+tyrone-node9/18+tyrone-node9/17+tyrone-node9/16+tyrone-node9/15+tyrone-node9/14+tyrone-node9/13+tyrone-node9/12+tyrone-node9/11+tyrone-node9/10+tyrone-node9/9+tyrone-node9/8+tyrone-node9/7+tyrone-node9/6+tyrone-node9/5+tyrone-node9/4+tyrone-node9/3+tyrone-node9/2+tyrone-node9/1+tyrone-node9/0
12/20/2013 16:23:55;0008;PBS_Server;Job;NULL;on_job_exit valid pjob: 0x265bdb0 (substate=53)
12/20/2013 16:23:55;0100;PBS_Server;Job;33384.tyrone-cluster;dequeuing from qp64, state COMPLETE
12/20/2013 16:23:55;0040;PBS_Server;Svr;tyrone-cluster;Scheduler was sent the command term
12/20/2013 16:23:55;0008;PBS_Server;Job;33390.tyrone-cluster;Job Modified at request of Scheduler@tyrone-cluster
12/20/2013 16:23:55;0008;PBS_Server;Job;33390.tyrone-cluster;Job Run at request of Scheduler@tyrone-cluster
12/20/2013 16:23:55;000d;PBS_Server;Job;33390.tyrone-cluster;Not sending email: User does not want mail of this type.
12/20/2013 16:23:55;0040;PBS_Server;Svr;tyrone-cluster;Scheduler was sent the command recyc
12/20/2013 16:24:15;0040;PBS_Server;Svr;tyrone-cluster;Scheduler was sent the command new
12/20/2013 16:24:33;0002;PBS_Server;Svr;PBS_Server;Torque Server Version = 3.0.5, loglevel = 0
12/20/2013 16:24:45;0040;PBS_Server;Svr;tyrone-cluster;Scheduler was sent the command new
12/20/2013 16:25:22;0040;PBS_Server;Svr;tyrone-cluster;Scheduler was sent the command new
12/20/2013 16:25:53;0040;PBS_Server;Svr;tyrone-cluster;Scheduler was sent the command new
12/20/2013 16:26:24;0040;PBS_Server;Svr;tyrone-cluster;Scheduler was sent the command new
12/20/2013 16:26:55;0040;PBS_Server;Svr;tyrone-cluster;Scheduler was sent the command new
12/20/2013 16:27:25;0040;PBS_Server;Svr;tyrone-cluster;Scheduler was sent the command new
12/20/2013 16:27:57;0040;PBS_Server;Svr;tyrone-cluster;Scheduler was sent the command new
12/20/2013 16:28:25;0040;PBS_Server;Svr;tyrone-cluster;Scheduler was sent the command new
12/20/2013 16:28:55;0040;PBS_Server;Svr;tyrone-cluster;Scheduler was sent the command new
12/20/2013 16:29:27;0040;PBS_Server;Svr;tyrone-cluster;Scheduler was sent the command new
12/20/2013 16:29:33;0002;PBS_Server;Svr;PBS_Server;Torque Server Version = 3.0.5, loglevel = 0
12/20/2013 16:29:55;0040;PBS_Server;Svr;tyrone-cluster;Scheduler was sent the command new
12/20/2013 16:30:25;0040;PBS_Server;Svr;tyrone-cluster;Scheduler was sent the command new
12/20/2013 16:30:57;0040;PBS_Server;Svr;tyrone-cluster;Scheduler was sent the command new
12/20/2013 16:31:25;0040;PBS_Server;Svr;tyrone-cluster;Scheduler was sent the command new
12/20/2013 16:31:55;0040;PBS_Server;Svr;tyrone-cluster;Scheduler was sent the command new
12/20/2013 16:32:28;0040;PBS_Server;Svr;tyrone-cluster;Scheduler was sent the command new
12/20/2013 16:33:00;0040;PBS_Server;Svr;tyrone-cluster;Scheduler was sent the command new
12/20/2013 16:33:35;0040;PBS_Server;Svr;tyrone-cluster;Scheduler was sent the command new
12/20/2013 16:34:00;0040;PBS_Server;Svr;tyrone-cluster;Scheduler was sent the command new
12/20/2013 16:34:30;0040;PBS_Server;Svr;tyrone-cluster;Scheduler was sent the command new
12/20/2013 16:34:33;0002;PBS_Server;Svr;PBS_Server;Torque Server Version = 3.0.5, loglevel = 0
12/20/2013 16:35:06;0040;PBS_Server;Svr;tyrone-cluster;Scheduler was sent the command new
12/20/2013 16:35:30;0040;PBS_Server;Svr;tyrone-cluster;Scheduler was sent the command new
12/20/2013 16:36:00;0040;PBS_Server;Svr;tyrone-cluster;Scheduler was sent the command new
12/20/2013 16:36:37;0040;PBS_Server;Svr;tyrone-cluster;Scheduler was sent the command new
12/20/2013 16:37:04;0008;PBS_Server;Job;33398.tyrone-cluster;Job deleted at request of csdrjain@tyrone-cluster
12/20/2013 16:37:04;0008;PBS_Server;Job;NULL;on_job_exit valid pjob: 0x26ddc50 (substate=59)
12/20/2013 16:37:04;0100;PBS_Server;Job;33398.tyrone-cluster;dequeuing from qp32, state COMPLETE
12/20/2013 16:37:04;0040;PBS_Server;Svr;tyrone-cluster;Scheduler was sent the command term
12/20/2013 16:37:05;0100;PBS_Server;Job;33399.tyrone-cluster;dequeuing from batch, state QUEUED
12/20/2013 16:37:05;0100;PBS_Server;Job;33399.tyrone-cluster;enqueuing into qp32, state 1 hop 1
12/20/2013 16:37:08;0040;PBS_Server;Svr;tyrone-cluster;Scheduler was sent the command new
12/20/2013 16:37:08;0008;PBS_Server;Job;33399.tyrone-cluster;Job Modified at request of Scheduler@tyrone-cluster
12/20/2013 16:39:30;0100;PBS_Server;Job;33401.tyrone-cluster;enqueuing into batch, state 1 hop 1
12/20/2013 16:39:30;0100;PBS_Server;Job;33401.tyrone-cluster;dequeuing from batch, state QUEUED
12/20/2013 16:39:30;0100;PBS_Server;Job;33401.tyrone-cluster;enqueuing into idqueue, state 1 hop 1
12/20/2013 16:39:30;0008;PBS_Server;Job;33401.tyrone-cluster;Job Queued at request of csdrjain@tyrone-cluster, owner = csdrjain@tyrone-cluster, job name = n14, queue = idqueue
12/20/2013 16:39:30;0040;PBS_Server;Svr;tyrone-cluster;Scheduler was sent the command new
12/20/2013 16:39:30;0008;PBS_Server;Job;33401.tyrone-cluster;Job Modified at request of Scheduler@tyrone-cluster
12/20/2013 16:39:30;0008;PBS_Server;Job;33401.tyrone-cluster;Job Run at request of Scheduler@tyrone-cluster
12/20/2013 16:39:30;0040;PBS_Server;Svr;tyrone-cluster;Scheduler was sent the command recyc
12/20/2013 16:39:30;000d;PBS_Server;Job;33401.tyrone-cluster;Not sending email: User does not want mail of this type.
12/20/2013 16:39:33;0002;PBS_Server;Svr;PBS_Server;Torque Server Version = 3.0.5, loglevel = 0
12/20/2013 16:44:33;0002;PBS_Server;Svr;PBS_Server;Torque Server Version = 3.0.5, loglevel = 0
12/20/2013 16:49:30;0040;PBS_Server;Svr;tyrone-cluster;Scheduler was sent the command time
12/20/2013 16:49:33;0002;PBS_Server;Svr;PBS_Server;Torque Server Version = 3.0.5, loglevel = 0
12/20/2013 16:53:02;0100;PBS_Server;Job;33402.tyrone-cluster;enqueuing into batch, state 1 hop 1
12/20/2013 16:53:02;0008;PBS_Server;Job;33402.tyrone-cluster;Job Queued at request of csdrjain@tyrone-cluster, owner = csdrjain@tyrone-cluster, job name = n24_2, queue = batch
12/20/2013 16:53:02;0040;PBS_Server;Svr;tyrone-cluster;Scheduler was sent the command new
12/20/2013 16:53:02;0008;PBS_Server;Job;33402.tyrone-cluster;Job Modified at request of Scheduler@tyrone-cluster
12/20/2013 16:53:32;0040;PBS_Server;Svr;tyrone-cluster;Scheduler was sent the command new
12/20/2013 16:54:02;0040;PBS_Server;Svr;tyrone-cluster;Scheduler was sent the command new
12/20/2013 16:54:33;0002;PBS_Server;Svr;PBS_Server;Torque Server Version = 3.0.5, loglevel = 0
12/20/2013 16:54:35;0040;PBS_Server;Svr;tyrone-cluster;Scheduler was sent the command new
12/20/2013 16:55:08;0040;PBS_Server;Svr;tyrone-cluster;Scheduler was sent the command new
12/20/2013 16:55:39;0040;PBS_Server;Svr;tyrone-cluster;Scheduler was sent the command new
12/20/2013 16:56:10;0040;PBS_Server;Svr;tyrone-cluster;Scheduler was sent the command new
12/20/2013 16:56:40;0040;PBS_Server;Svr;tyrone-cluster;Scheduler was sent the command new
12/20/2013 16:57:13;0040;PBS_Server;Svr;tyrone-cluster;Scheduler was sent the command new
12/20/2013 16:57:40;0040;PBS_Server;Svr;tyrone-cluster;Scheduler was sent the command new
12/20/2013 16:58:10;0040;PBS_Server;Svr;tyrone-cluster;Scheduler was sent the command new
12/20/2013 16:58:42;0040;PBS_Server;Svr;tyrone-cluster;Scheduler was sent the command new
12/20/2013 16:59:10;0040;PBS_Server;Svr;tyrone-cluster;Scheduler was sent the command new
12/20/2013 16:59:33;0002;PBS_Server;Svr;PBS_Server;Torque Server Version = 3.0.5, loglevel = 0
12/20/2013 16:59:40;0040;PBS_Server;Svr;tyrone-cluster;Scheduler was sent the command new
12/20/2013 17:00:12;0040;PBS_Server;Svr;tyrone-cluster;Scheduler was sent the command new
12/20/2013 17:00:40;0040;PBS_Server;Svr;tyrone-cluster;Scheduler was sent the command new
12/20/2013 17:01:10;0040;PBS_Server;Svr;tyrone-cluster;Scheduler was sent the command new
12/20/2013 17:01:43;0040;PBS_Server;Svr;tyrone-cluster;Scheduler was sent the command new
12/20/2013 17:02:15;0040;PBS_Server;Svr;tyrone-cluster;Scheduler was sent the command new
12/20/2013 17:02:52;0040;PBS_Server;Svr;tyrone-cluster;Scheduler was sent the command new
12/20/2013 17:03:23;0040;PBS_Server;Svr;tyrone-cluster;Scheduler was sent the command new
12/20/2013 17:03:54;0040;PBS_Server;Svr;tyrone-cluster;Scheduler was sent the command new
12/20/2013 17:04:25;0040;PBS_Server;Svr;tyrone-cluster;Scheduler was sent the command new
12/20/2013 17:04:33;0002;PBS_Server;Svr;PBS_Server;Torque Server Version = 3.0.5, loglevel = 0
12/20/2013 17:04:55;0040;PBS_Server;Svr;tyrone-cluster;Scheduler was sent the command new
12/20/2013 17:05:28;0040;PBS_Server;Svr;tyrone-cluster;Scheduler was sent the command new
12/20/2013 17:05:55;0040;PBS_Server;Svr;tyrone-cluster;Scheduler was sent the command new
12/20/2013 17:06:25;0040;PBS_Server;Svr;tyrone-cluster;Scheduler was sent the command new
12/20/2013 17:06:57;0040;PBS_Server;Svr;tyrone-cluster;Scheduler was sent the command new
12/20/2013 17:07:25;0040;PBS_Server;Svr;tyrone-cluster;Scheduler was sent the command new
12/20/2013 17:07:55;0040;PBS_Server;Svr;tyrone-cluster;Scheduler was sent the command new
12/20/2013 17:08:27;0040;PBS_Server;Svr;tyrone-cluster;Scheduler was sent the command new
12/20/2013 17:08:55;0040;PBS_Server;Svr;tyrone-cluster;Scheduler was sent the command new
12/20/2013 17:09:25;0040;PBS_Server;Svr;tyrone-cluster;Scheduler was sent the command new
12/20/2013 17:09:33;0002;PBS_Server;Svr;PBS_Server;Torque Server Version = 3.0.5, loglevel = 0
12/20/2013 17:09:58;0040;PBS_Server;Svr;tyrone-cluster;Scheduler was sent the command new
12/20/2013 17:10:30;0040;PBS_Server;Svr;tyrone-cluster;Scheduler was sent the command new
12/20/2013 17:11:07;0040;PBS_Server;Svr;tyrone-cluster;Scheduler was sent the command new
12/20/2013 17:11:38;0040;PBS_Server;Svr;tyrone-cluster;Scheduler was sent the command new
12/20/2013 17:12:09;0040;PBS_Server;Svr;tyrone-cluster;Scheduler was sent the command new
12/20/2013 17:12:40;0040;PBS_Server;Svr;tyrone-cluster;Scheduler was sent the command new
12/20/2013 17:13:10;0040;PBS_Server;Svr;tyrone-cluster;Scheduler was sent the command new
12/20/2013 17:13:42;0040;PBS_Server;Svr;tyrone-cluster;Scheduler was sent the command new
12/20/2013 17:14:10;0040;PBS_Server;Svr;tyrone-cluster;Scheduler was sent the command new
12/20/2013 17:14:33;0002;PBS_Server;Svr;PBS_Server;Torque Server Version = 3.0.5, loglevel = 0
12/20/2013 17:14:40;0040;PBS_Server;Svr;tyrone-cluster;Scheduler was sent the command new
12/20/2013 17:15:12;0040;PBS_Server;Svr;tyrone-cluster;Scheduler was sent the command new
12/20/2013 17:15:40;0040;PBS_Server;Svr;tyrone-cluster;Scheduler was sent the command new
12/20/2013 17:16:10;0040;PBS_Server;Svr;tyrone-cluster;Scheduler was sent the command new
12/20/2013 17:16:43;0040;PBS_Server;Svr;tyrone-cluster;Scheduler was sent the command new
12/20/2013 17:17:15;0040;PBS_Server;Svr;tyrone-cluster;Scheduler was sent the command new
12/20/2013 17:17:52;0040;PBS_Server;Svr;tyrone-cluster;Scheduler was sent the command new
12/20/2013 17:18:23;0040;PBS_Server;Svr;tyrone-cluster;Scheduler was sent the command new
12/20/2013 17:18:54;0040;PBS_Server;Svr;tyrone-cluster;Scheduler was sent the command new
12/20/2013 17:19:25;0040;PBS_Server;Svr;tyrone-cluster;Scheduler was sent the command new
12/20/2013 17:19:33;0002;PBS_Server;Svr;PBS_Server;Torque Server Version = 3.0.5, loglevel = 0
12/20/2013 17:19:55;0040;PBS_Server;Svr;tyrone-cluster;Scheduler was sent the command new
12/20/2013 17:20:27;0040;PBS_Server;Svr;tyrone-cluster;Scheduler was sent the command new
12/20/2013 17:20:55;0040;PBS_Server;Svr;tyrone-cluster;Scheduler was sent the command new
12/20/2013 17:21:25;0040;PBS_Server;Svr;tyrone-cluster;Scheduler was sent the command new
12/20/2013 17:21:57;0040;PBS_Server;Svr;tyrone-cluster;Scheduler was sent the command new
12/20/2013 17:22:25;0040;PBS_Server;Svr;tyrone-cluster;Scheduler was sent the command new
12/20/2013 17:22:55;0040;PBS_Server;Svr;tyrone-cluster;Scheduler was sent the command new
12/20/2013 17:23:27;0040;PBS_Server;Svr;tyrone-cluster;Scheduler was sent the command new
12/20/2013 17:23:55;0040;PBS_Server;Svr;tyrone-cluster;Scheduler was sent the command new
12/20/2013 17:24:25;0040;PBS_Server;Svr;tyrone-cluster;Scheduler was sent the command new
12/20/2013 17:24:33;0002;PBS_Server;Svr;PBS_Server;Torque Server Version = 3.0.5, loglevel = 0
12/20/2013 17:24:58;0040;PBS_Server;Svr;tyrone-cluster;Scheduler was sent the command new
12/20/2013 17:25:30;0040;PBS_Server;Svr;tyrone-cluster;Scheduler was sent the command new
12/20/2013 17:26:07;0040;PBS_Server;Svr;tyrone-cluster;Scheduler was sent the command new
12/20/2013 17:26:38;0040;PBS_Server;Svr;tyrone-cluster;Scheduler was sent the command new
12/20/2013 17:27:09;0040;PBS_Server;Svr;tyrone-cluster;Scheduler was sent the command new
12/20/2013 17:27:40;0040;PBS_Server;Svr;tyrone-cluster;Scheduler was sent the command new
12/20/2013 17:28:10;0040;PBS_Server;Svr;tyrone-cluster;Scheduler was sent the command new
12/20/2013 17:28:42;0040;PBS_Server;Svr;tyrone-cluster;Scheduler was sent the command new
12/20/2013 17:29:10;0040;PBS_Server;Svr;tyrone-cluster;Scheduler was sent the command new
12/20/2013 17:29:33;0002;PBS_Server;Svr;PBS_Server;Torque Server Version = 3.0.5, loglevel = 0
12/20/2013 17:29:40;0040;PBS_Server;Svr;tyrone-cluster;Scheduler was sent the command new
12/20/2013 17:30:12;0040;PBS_Server;Svr;tyrone-cluster;Scheduler was sent the command new
12/20/2013 17:30:40;0040;PBS_Server;Svr;tyrone-cluster;Scheduler was sent the command new
12/20/2013 17:31:10;0040;PBS_Server;Svr;tyrone-cluster;Scheduler was sent the command new
12/20/2013 17:31:43;0040;PBS_Server;Svr;tyrone-cluster;Scheduler was sent the command new
12/20/2013 17:32:15;0040;PBS_Server;Svr;tyrone-cluster;Scheduler was sent the command new
12/20/2013 17:32:52;0040;PBS_Server;Svr;tyrone-cluster;Scheduler was sent the command new
12/20/2013 17:33:23;0040;PBS_Server;Svr;tyrone-cluster;Scheduler was sent the command new
12/20/2013 17:33:54;0040;PBS_Server;Svr;tyrone-cluster;Scheduler was sent the command new
12/20/2013 17:34:25;0040;PBS_Server;Svr;tyrone-cluster;Scheduler was sent the command new
12/20/2013 17:34:33;0002;PBS_Server;Svr;PBS_Server;Torque Server Version = 3.0.5, loglevel = 0
12/20/2013 17:34:55;0040;PBS_Server;Svr;tyrone-cluster;Scheduler was sent the command new
12/20/2013 17:35:27;0040;PBS_Server;Svr;tyrone-cluster;Scheduler was sent the command new
12/20/2013 17:35:55;0040;PBS_Server;Svr;tyrone-cluster;Scheduler was sent the command new
12/20/2013 17:36:25;0040;PBS_Server;Svr;tyrone-cluster;Scheduler was sent the command new
12/20/2013 17:36:57;0040;PBS_Server;Svr;tyrone-cluster;Scheduler was sent the command new
12/20/2013 17:37:25;0040;PBS_Server;Svr;tyrone-cluster;Scheduler was sent the command new
12/20/2013 17:37:55;0040;PBS_Server;Svr;tyrone-cluster;Scheduler was sent the command new
12/20/2013 17:38:28;0040;PBS_Server;Svr;tyrone-cluster;Scheduler was sent the command new
12/20/2013 17:39:00;0040;PBS_Server;Svr;tyrone-cluster;Scheduler was sent the command new
12/20/2013 17:39:33;0002;PBS_Server;Svr;PBS_Server;Torque Server Version = 3.0.5, loglevel = 0
12/20/2013 17:39:34;0040;PBS_Server;Svr;tyrone-cluster;Scheduler was sent the command new
12/20/2013 17:40:08;0040;PBS_Server;Svr;tyrone-cluster;Scheduler was sent the command new
12/20/2013 17:40:39;0040;PBS_Server;Svr;tyrone-cluster;Scheduler was sent the command new
12/20/2013 17:41:10;0040;PBS_Server;Svr;tyrone-cluster;Scheduler was sent the command new
12/20/2013 17:41:40;0040;PBS_Server;Svr;tyrone-cluster;Scheduler was sent the command new
12/20/2013 17:42:12;0040;PBS_Server;Svr;tyrone-cluster;Scheduler was sent the command new
12/20/2013 17:42:40;0040;PBS_Server;Svr;tyrone-cluster;Scheduler was sent the command new
12/20/2013 17:43:10;0040;PBS_Server;Svr;tyrone-cluster;Scheduler was sent the command new
12/20/2013 17:43:42;0040;PBS_Server;Svr;tyrone-cluster;Scheduler was sent the command new
12/20/2013 17:44:10;0040;PBS_Server;Svr;tyrone-cluster;Scheduler was sent the command new
12/20/2013 17:44:33;0002;PBS_Server;Svr;PBS_Server;Torque Server Version = 3.0.5, loglevel = 0
12/20/2013 17:44:40;0040;PBS_Server;Svr;tyrone-cluster;Scheduler was sent the command new
12/20/2013 17:45:13;0040;PBS_Server;Svr;tyrone-cluster;Scheduler was sent the command new
12/20/2013 17:45:23;0100;PBS_Server;Job;33403.tyrone-cluster;enqueuing into batch, state 1 hop 1
12/20/2013 17:45:23;0100;PBS_Server;Job;33403.tyrone-cluster;dequeuing from batch, state QUEUED
12/20/2013 17:45:23;0100;PBS_Server;Job;33403.tyrone-cluster;enqueuing into idqueue, state 1 hop 1
12/20/2013 17:45:23;0008;PBS_Server;Job;33403.tyrone-cluster;Job Queued at request of ipckousi@tyrone-cluster, owner = ipckousi@tyrone-cluster, job name = n10, queue = idqueue
12/20/2013 17:45:23;0040;PBS_Server;Svr;tyrone-cluster;Scheduler was sent the command new
12/20/2013 17:45:23;0008;PBS_Server;Job;33403.tyrone-cluster;Job Modified at request of Scheduler@tyrone-cluster
12/20/2013 17:45:45;0040;PBS_Server;Svr;tyrone-cluster;Scheduler was sent the command new
12/20/2013 17:46:22;0040;PBS_Server;Svr;tyrone-cluster;Scheduler was sent the command new
12/20/2013 17:46:53;0040;PBS_Server;Svr;tyrone-cluster;Scheduler was sent the command new
12/20/2013 17:47:24;0040;PBS_Server;Svr;tyrone-cluster;Scheduler was sent the command new
12/20/2013 17:47:55;0040;PBS_Server;Svr;tyrone-cluster;Scheduler was sent the command new
12/20/2013 17:48:25;0040;PBS_Server;Svr;tyrone-cluster;Scheduler was sent the command new
12/20/2013 17:48:58;0040;PBS_Server;Svr;tyrone-cluster;Scheduler was sent the command new
12/20/2013 17:49:18;000d;PBS_Server;Job;33362.tyrone-cluster;Not sending email: User does not want mail of this type.
12/20/2013 17:49:18;0010;PBS_Server;Job;33362.tyrone-cluster;Exit_status=0 resources_used.cput=1162:36:24 resources_used.mem=7493728kb resources_used.vmem=132185068kb resources_used.walltime=20:03:09
12/20/2013 17:49:18;0008;PBS_Server;Job;NULL;on_job_exit valid pjob: 0x2760260 (substate=50)
12/20/2013 17:49:18;0008;PBS_Server;Job;NULL;on_job_exit valid pjob: 0x2760260 (substate=51)
12/20/2013 17:49:18;0008;PBS_Server;Job;NULL;on_job_exit valid pjob: 0x2760260 (substate=51)
12/20/2013 17:49:18;0008;PBS_Server;Job;NULL;on_job_exit valid pjob: 0x2760260 (substate=53)
12/20/2013 17:49:18;0100;PBS_Server;Job;33362.tyrone-cluster;dequeuing from qp64, state COMPLETE
12/20/2013 17:49:18;0040;PBS_Server;Svr;tyrone-cluster;Scheduler was sent the command term
12/20/2013 17:49:18;0008;PBS_Server;Job;33392.tyrone-cluster;Job Modified at request of Scheduler@tyrone-cluster
12/20/2013 17:49:18;0008;PBS_Server;Job;33393.tyrone-cluster;Job Modified at request of Scheduler@tyrone-cluster
12/20/2013 17:49:30;0040;PBS_Server;Svr;tyrone-cluster;Scheduler was sent the command new
12/20/2013 17:49:33;0002;PBS_Server;Svr;PBS_Server;Torque Server Version = 3.0.5, loglevel = 0
12/20/2013 17:50:07;0040;PBS_Server;Svr;tyrone-cluster;Scheduler was sent the command new
12/20/2013 17:50:38;0040;PBS_Server;Svr;tyrone-cluster;Scheduler was sent the command new
12/20/2013 17:51:09;0040;PBS_Server;Svr;tyrone-cluster;Scheduler was sent the command new
12/20/2013 17:51:40;0040;PBS_Server;Svr;tyrone-cluster;Scheduler was sent the command new
12/20/2013 17:52:10;0040;PBS_Server;Svr;tyrone-cluster;Scheduler was sent the command new
12/20/2013 17:52:45;0040;PBS_Server;Svr;tyrone-cluster;Scheduler was sent the command new
12/20/2013 17:53:15;0040;PBS_Server;Svr;tyrone-cluster;Scheduler was sent the command new
12/20/2013 17:53:52;0040;PBS_Server;Svr;tyrone-cluster;Scheduler was sent the command new
12/20/2013 17:54:22;0040;PBS_Server;Svr;tyrone-cluster;Scheduler was sent the command new
12/20/2013 17:54:33;0002;PBS_Server;Svr;PBS_Server;Torque Server Version = 3.0.5, loglevel = 0
12/20/2013 17:54:54;0040;PBS_Server;Svr;tyrone-cluster;Scheduler was sent the command new
12/20/2013 17:55:25;0040;PBS_Server;Svr;tyrone-cluster;Scheduler was sent the command new
12/20/2013 17:55:55;0040;PBS_Server;Svr;tyrone-cluster;Scheduler was sent the command new
12/20/2013 17:56:27;0040;PBS_Server;Svr;tyrone-cluster;Scheduler was sent the command new
12/20/2013 17:56:55;0040;PBS_Server;Svr;tyrone-cluster;Scheduler was sent the command new
12/20/2013 17:57:25;0040;PBS_Server;Svr;tyrone-cluster;Scheduler was sent the command new
12/20/2013 17:57:57;0040;PBS_Server;Svr;tyrone-cluster;Scheduler was sent the command new
12/20/2013 17:58:25;0040;PBS_Server;Svr;tyrone-cluster;Scheduler was sent the command new
12/20/2013 17:58:55;0040;PBS_Server;Svr;tyrone-cluster;Scheduler was sent the command new
12/20/2013 17:59:30;0040;PBS_Server;Svr;tyrone-cluster;Scheduler was sent the command new
12/20/2013 17:59:33;0002;PBS_Server;Svr;PBS_Server;Torque Server Version = 3.0.5, loglevel = 0
12/20/2013 18:00:00;0040;PBS_Server;Svr;tyrone-cluster;Scheduler was sent the command new
12/20/2013 18:00:37;0040;PBS_Server;Svr;tyrone-cluster;Scheduler was sent the command new
12/20/2013 18:01:07;0040;PBS_Server;Svr;tyrone-cluster;Scheduler was sent the command new
12/20/2013 18:01:39;0040;PBS_Server;Svr;tyrone-cluster;Scheduler was sent the command new
12/20/2013 18:02:10;0040;PBS_Server;Svr;tyrone-cluster;Scheduler was sent the command new
12/20/2013 18:02:40;0040;PBS_Server;Svr;tyrone-cluster;Scheduler was sent the command new
12/20/2013 18:03:15;0040;PBS_Server;Svr;tyrone-cluster;Scheduler was sent the command new
12/20/2013 18:03:45;0040;PBS_Server;Svr;tyrone-cluster;Scheduler was sent the command new
12/20/2013 18:04:22;0040;PBS_Server;Svr;tyrone-cluster;Scheduler was sent the command new
12/20/2013 18:04:33;0002;PBS_Server;Svr;PBS_Server;Torque Server Version = 3.0.5, loglevel = 0
12/20/2013 18:04:53;0040;PBS_Server;Svr;tyrone-cluster;Scheduler was sent the command new
12/20/2013 18:05:24;0040;PBS_Server;Svr;tyrone-cluster;Scheduler was sent the command new
12/20/2013 18:05:55;0040;PBS_Server;Svr;tyrone-cluster;Scheduler was sent the command new
12/20/2013 18:06:25;0040;PBS_Server;Svr;tyrone-cluster;Scheduler was sent the command new
12/20/2013 18:06:59;0040;PBS_Server;Svr;tyrone-cluster;Scheduler was sent the command new
12/20/2013 18:07:30;0040;PBS_Server;Svr;tyrone-cluster;Scheduler was sent the command new
12/20/2013 18:08:07;0040;PBS_Server;Svr;tyrone-cluster;Scheduler was sent the command new
12/20/2013 18:08:37;0040;PBS_Server;Svr;tyrone-cluster;Scheduler was sent the command new
12/20/2013 18:09:09;0040;PBS_Server;Svr;tyrone-cluster;Scheduler was sent the command new
12/20/2013 18:09:33;0002;PBS_Server;Svr;PBS_Server;Torque Server Version = 3.0.5, loglevel = 0
12/20/2013 18:09:40;0040;PBS_Server;Svr;tyrone-cluster;Scheduler was sent the command new
12/20/2013 18:10:10;0040;PBS_Server;Svr;tyrone-cluster;Scheduler was sent the command new
12/20/2013 18:10:42;0040;PBS_Server;Svr;tyrone-cluster;Scheduler was sent the command new
12/20/2013 18:11:10;0040;PBS_Server;Svr;tyrone-cluster;Scheduler was sent the command new
12/20/2013 18:11:40;0040;PBS_Server;Svr;tyrone-cluster;Scheduler was sent the command new
12/20/2013 18:12:15;0040;PBS_Server;Svr;tyrone-cluster;Scheduler was sent the command new
12/20/2013 18:12:45;0040;PBS_Server;Svr;tyrone-cluster;Scheduler was sent the command new
12/20/2013 18:13:22;0040;PBS_Server;Svr;tyrone-cluster;Scheduler was sent the command new
12/20/2013 18:13:52;0040;PBS_Server;Svr;tyrone-cluster;Scheduler was sent the command new
12/20/2013 18:14:24;0040;PBS_Server;Svr;tyrone-cluster;Scheduler was sent the command new
12/20/2013 18:14:33;0002;PBS_Server;Svr;PBS_Server;Torque Server Version = 3.0.5, loglevel = 0
12/20/2013 18:14:55;0040;PBS_Server;Svr;tyrone-cluster;Scheduler was sent the command new
12/20/2013 18:15:25;0040;PBS_Server;Svr;tyrone-cluster;Scheduler was sent the command new
12/20/2013 18:15:59;0040;PBS_Server;Svr;tyrone-cluster;Scheduler was sent the command new
12/20/2013 18:16:30;0040;PBS_Server;Svr;tyrone-cluster;Scheduler was sent the command new
12/20/2013 18:16:59;0040;PBS_Server;Svr;tyrone-cluster;Scheduler was sent the command new
12/20/2013 18:17:30;0040;PBS_Server;Svr;tyrone-cluster;Scheduler was sent the command new
12/20/2013 18:18:00;0040;PBS_Server;Svr;tyrone-cluster;Scheduler was sent the command new
12/20/2013 18:18:37;0040;PBS_Server;Svr;tyrone-cluster;Scheduler was sent the command new
12/20/2013 18:19:07;0040;PBS_Server;Svr;tyrone-cluster;Scheduler was sent the command new
12/20/2013 18:19:33;0002;PBS_Server;Svr;PBS_Server;Torque Server Version = 3.0.5, loglevel = 0
12/20/2013 18:19:39;0040;PBS_Server;Svr;tyrone-cluster;Scheduler was sent the command new
12/20/2013 18:20:10;0040;PBS_Server;Svr;tyrone-cluster;Scheduler was sent the command new
12/20/2013 18:20:40;0040;PBS_Server;Svr;tyrone-cluster;Scheduler was sent the command new
12/20/2013 18:21:14;0040;PBS_Server;Svr;tyrone-cluster;Scheduler was sent the command new
12/20/2013 18:21:45;0040;PBS_Server;Svr;tyrone-cluster;Scheduler was sent the command new
12/20/2013 18:22:22;0040;PBS_Server;Svr;tyrone-cluster;Scheduler was sent the command new
12/20/2013 18:22:52;0040;PBS_Server;Svr;tyrone-cluster;Scheduler was sent the command new
12/20/2013 18:23:24;0040;PBS_Server;Svr;tyrone-cluster;Scheduler was sent the command new
12/20/2013 18:23:55;0040;PBS_Server;Svr;tyrone-cluster;Scheduler was sent the command new
12/20/2013 18:24:25;0040;PBS_Server;Svr;tyrone-cluster;Scheduler was sent the command new
12/20/2013 18:24:33;0002;PBS_Server;Svr;PBS_Server;Torque Server Version = 3.0.5, loglevel = 0
12/20/2013 18:24:59;0040;PBS_Server;Svr;tyrone-cluster;Scheduler was sent the command new
12/20/2013 18:25:30;0040;PBS_Server;Svr;tyrone-cluster;Scheduler was sent the command new
12/20/2013 18:25:59;0040;PBS_Server;Svr;tyrone-cluster;Scheduler was sent the command new
12/20/2013 18:26:30;0040;PBS_Server;Svr;tyrone-cluster;Scheduler was sent the command new
12/20/2013 18:27:00;0040;PBS_Server;Svr;tyrone-cluster;Scheduler was sent the command new
12/20/2013 18:27:37;0040;PBS_Server;Svr;tyrone-cluster;Scheduler was sent the command new
12/20/2013 18:28:07;0040;PBS_Server;Svr;tyrone-cluster;Scheduler was sent the command new
12/20/2013 18:28:39;0040;PBS_Server;Svr;tyrone-cluster;Scheduler was sent the command new
12/20/2013 18:29:10;0040;PBS_Server;Svr;tyrone-cluster;Scheduler was sent the command new
12/20/2013 18:29:33;0002;PBS_Server;Svr;PBS_Server;Torque Server Version = 3.0.5, loglevel = 0
12/20/2013 18:29:40;0040;PBS_Server;Svr;tyrone-cluster;Scheduler was sent the command new
12/20/2013 18:30:14;0040;PBS_Server;Svr;tyrone-cluster;Scheduler was sent the command new
12/20/2013 18:30:44;0040;PBS_Server;Svr;tyrone-cluster;Scheduler was sent the command new
12/20/2013 18:31:14;0040;PBS_Server;Svr;tyrone-cluster;Scheduler was sent the command new
12/20/2013 18:31:45;0040;PBS_Server;Svr;tyrone-cluster;Scheduler was sent the command new
12/20/2013 18:32:15;0040;PBS_Server;Svr;tyrone-cluster;Scheduler was sent the command new
12/20/2013 18:32:52;0040;PBS_Server;Svr;tyrone-cluster;Scheduler was sent the command new
12/20/2013 18:33:22;0040;PBS_Server;Svr;tyrone-cluster;Scheduler was sent the command new
12/20/2013 18:33:54;0040;PBS_Server;Svr;tyrone-cluster;Scheduler was sent the command new
12/20/2013 18:34:25;0040;PBS_Server;Svr;tyrone-cluster;Scheduler was sent the command new
12/20/2013 18:34:33;0002;PBS_Server;Svr;PBS_Server;Torque Server Version = 3.0.5, loglevel = 0
12/20/2013 18:34:55;0040;PBS_Server;Svr;tyrone-cluster;Scheduler was sent the command new
12/20/2013 18:35:29;0040;PBS_Server;Svr;tyrone-cluster;Scheduler was sent the command new
12/20/2013 18:35:59;0040;PBS_Server;Svr;tyrone-cluster;Scheduler was sent the command new
12/20/2013 18:36:29;0040;PBS_Server;Svr;tyrone-cluster;Scheduler was sent the command new
12/20/2013 18:37:00;0040;PBS_Server;Svr;tyrone-cluster;Scheduler was sent the command new
12/20/2013 18:37:30;0040;PBS_Server;Svr;tyrone-cluster;Scheduler was sent the command new
12/20/2013 18:38:07;0040;PBS_Server;Svr;tyrone-cluster;Scheduler was sent the command new
12/20/2013 18:38:37;0040;PBS_Server;Svr;tyrone-cluster;Scheduler was sent the command new
12/20/2013 18:39:09;0040;PBS_Server;Svr;tyrone-cluster;Scheduler was sent the command new
12/20/2013 18:39:33;0002;PBS_Server;Svr;PBS_Server;Torque Server Version = 3.0.5, loglevel = 0
12/20/2013 18:39:40;0040;PBS_Server;Svr;tyrone-cluster;Scheduler was sent the command new
12/20/2013 18:39:43;000d;PBS_Server;Job;33401.tyrone-cluster;Not sending email: User does not want mail of this type.
12/20/2013 18:39:43;0010;PBS_Server;Job;33401.tyrone-cluster;Exit_status=143 resources_used.cput=47:57:29 resources_used.mem=439728kb resources_used.vmem=4248668kb resources_used.walltime=02:00:13
12/20/2013 18:39:43;0008;PBS_Server;Job;NULL;on_job_exit valid pjob: 0x26ddc50 (substate=50)
12/20/2013 18:39:43;0008;PBS_Server;Job;NULL;on_job_exit valid pjob: 0x26ddc50 (substate=51)
12/20/2013 18:39:43;0008;PBS_Server;Job;33403.tyrone-cluster;Job Modified at request of Scheduler@tyrone-cluster
12/20/2013 18:39:43;0008;PBS_Server;Job;NULL;on_job_exit valid pjob: 0x26ddc50 (substate=51)
12/20/2013 18:39:43;0008;PBS_Server;Job;NULL;on_job_exit valid pjob: 0x26ddc50 (substate=53)
12/20/2013 18:39:43;0100;PBS_Server;Job;33401.tyrone-cluster;dequeuing from idqueue, state COMPLETE
12/20/2013 18:39:43;0040;PBS_Server;Svr;tyrone-cluster;Scheduler was sent the command term
12/20/2013 18:39:43;0008;PBS_Server;Job;33403.tyrone-cluster;Job Modified at request of Scheduler@tyrone-cluster
12/20/2013 18:39:43;0008;PBS_Server;Job;33403.tyrone-cluster;Job Run at request of Scheduler@tyrone-cluster
12/20/2013 18:39:43;0040;PBS_Server;Svr;tyrone-cluster;Scheduler was sent the command recyc
12/20/2013 18:39:43;000d;PBS_Server;Job;33403.tyrone-cluster;Not sending email: User does not want mail of this type.
12/20/2013 18:39:51;000d;PBS_Server;Job;33403.tyrone-cluster;Not sending email: User does not want mail of this type.
12/20/2013 18:39:51;0010;PBS_Server;Job;33403.tyrone-cluster;Exit_status=1 resources_used.cput=00:00:02 resources_used.mem=0kb resources_used.vmem=0kb resources_used.walltime=00:00:08
12/20/2013 18:39:51;0008;PBS_Server;Job;NULL;on_job_exit valid pjob: 0x265bdb0 (substate=50)
12/20/2013 18:39:51;0008;PBS_Server;Job;NULL;on_job_exit valid pjob: 0x265bdb0 (substate=51)
12/20/2013 18:39:51;0008;PBS_Server;Job;NULL;on_job_exit valid pjob: 0x265bdb0 (substate=51)
12/20/2013 18:39:51;0008;PBS_Server;Job;NULL;on_job_exit valid pjob: 0x265bdb0 (substate=53)
12/20/2013 18:39:51;0100;PBS_Server;Job;33403.tyrone-cluster;dequeuing from idqueue, state COMPLETE
12/20/2013 18:39:51;0040;PBS_Server;Svr;tyrone-cluster;Scheduler was sent the command term
12/20/2013 18:40:10;0040;PBS_Server;Svr;tyrone-cluster;Scheduler was sent the command new
12/20/2013 18:40:44;0040;PBS_Server;Svr;tyrone-cluster;Scheduler was sent the command new
12/20/2013 18:41:15;0040;PBS_Server;Svr;tyrone-cluster;Scheduler was sent the command new
12/20/2013 18:41:52;0040;PBS_Server;Svr;tyrone-cluster;Scheduler was sent the command new
12/20/2013 18:42:22;0040;PBS_Server;Svr;tyrone-cluster;Scheduler was sent the command new
12/20/2013 18:42:54;0040;PBS_Server;Svr;tyrone-cluster;Scheduler was sent the command new
12/20/2013 18:43:25;0040;PBS_Server;Svr;tyrone-cluster;Scheduler was sent the command new
12/20/2013 18:43:55;0040;PBS_Server;Svr;tyrone-cluster;Scheduler was sent the command new
12/20/2013 18:44:26;0040;PBS_Server;Svr;tyrone-cluster;Scheduler was sent the command new
12/20/2013 18:44:33;0002;PBS_Server;Svr;PBS_Server;Torque Server Version = 3.0.5, loglevel = 0
12/20/2013 18:44:55;0040;PBS_Server;Svr;tyrone-cluster;Scheduler was sent the command new
12/20/2013 18:45:25;0040;PBS_Server;Svr;tyrone-cluster;Scheduler was sent the command new
12/20/2013 18:45:59;0040;PBS_Server;Svr;tyrone-cluster;Scheduler was sent the command new
12/20/2013 18:46:13;0100;PBS_Server;Job;33404.tyrone-cluster;enqueuing into batch, state 1 hop 1
12/20/2013 18:46:13;0100;PBS_Server;Job;33404.tyrone-cluster;dequeuing from batch, state QUEUED
12/20/2013 18:46:13;0100;PBS_Server;Job;33404.tyrone-cluster;enqueuing into qp256, state 1 hop 1
12/20/2013 18:46:13;0008;PBS_Server;Job;33404.tyrone-cluster;Job Queued at request of ipckousi@tyrone-cluster, owner = ipckousi@tyrone-cluster, job name = n11, queue = qp256
12/20/2013 18:46:13;0040;PBS_Server;Svr;tyrone-cluster;Scheduler was sent the command new
12/20/2013 18:46:13;0008;PBS_Server;Job;33404.tyrone-cluster;Job Modified at request of Scheduler@tyrone-cluster
12/20/2013 18:46:13;0008;PBS_Server;Job;33404.tyrone-cluster;Job Run at request of Scheduler@tyrone-cluster
12/20/2013 18:46:13;0040;PBS_Server;Svr;tyrone-cluster;Scheduler was sent the command recyc
12/20/2013 18:46:13;000d;PBS_Server;Job;33404.tyrone-cluster;Not sending email: User does not want mail of this type.
12/20/2013 18:46:14;000d;PBS_Server;Job;33404.tyrone-cluster;Not sending email: User does not want mail of this type.
12/20/2013 18:46:14;0010;PBS_Server;Job;33404.tyrone-cluster;Exit_status=127 resources_used.cput=00:00:00 resources_used.mem=0kb resources_used.vmem=0kb resources_used.walltime=00:00:01
12/20/2013 18:46:14;0008;PBS_Server;Job;NULL;on_job_exit valid pjob: 0x26ddc50 (substate=50)
12/20/2013 18:46:14;0008;PBS_Server;Job;NULL;on_job_exit valid pjob: 0x26ddc50 (substate=51)
12/20/2013 18:46:14;0008;PBS_Server;Job;NULL;on_job_exit valid pjob: 0x26ddc50 (substate=51)
12/20/2013 18:46:14;0008;PBS_Server;Job;NULL;on_job_exit valid pjob: 0x26ddc50 (substate=53)
12/20/2013 18:46:14;0100;PBS_Server;Job;33404.tyrone-cluster;dequeuing from qp256, state COMPLETE
12/20/2013 18:46:14;0040;PBS_Server;Svr;tyrone-cluster;Scheduler was sent the command term
12/20/2013 18:46:30;0040;PBS_Server;Svr;tyrone-cluster;Scheduler was sent the command new
12/20/2013 18:47:03;0040;PBS_Server;Svr;tyrone-cluster;Scheduler was sent the command new
12/20/2013 18:47:30;0040;PBS_Server;Svr;tyrone-cluster;Scheduler was sent the command new
12/20/2013 18:48:00;0040;PBS_Server;Svr;tyrone-cluster;Scheduler was sent the command new
12/20/2013 18:48:37;0040;PBS_Server;Svr;tyrone-cluster;Scheduler was sent the command new
12/20/2013 18:49:06;0040;PBS_Server;Svr;tyrone-cluster;Scheduler was sent the command new
12/20/2013 18:49:22;0100;PBS_Server;Job;33405.tyrone-cluster;enqueuing into batch, state 1 hop 1
12/20/2013 18:49:22;0100;PBS_Server;Job;33405.tyrone-cluster;dequeuing from batch, state QUEUED
12/20/2013 18:49:22;0100;PBS_Server;Job;33405.tyrone-cluster;enqueuing into idqueue, state 1 hop 1
12/20/2013 18:49:22;0008;PBS_Server;Job;33405.tyrone-cluster;Job Queued at request of ipckousi@tyrone-cluster, owner = ipckousi@tyrone-cluster, job name = n10, queue = idqueue
12/20/2013 18:49:22;0040;PBS_Server;Svr;tyrone-cluster;Scheduler was sent the command new
12/20/2013 18:49:22;0008;PBS_Server;Job;33405.tyrone-cluster;Job Modified at request of Scheduler@tyrone-cluster
12/20/2013 18:49:22;0008;PBS_Server;Job;33405.tyrone-cluster;Job Run at request of Scheduler@tyrone-cluster
12/20/2013 18:49:22;0040;PBS_Server;Svr;tyrone-cluster;Scheduler was sent the command recyc
12/20/2013 18:49:22;000d;PBS_Server;Job;33405.tyrone-cluster;Not sending email: User does not want mail of this type.
12/20/2013 18:49:33;0002;PBS_Server;Svr;PBS_Server;Torque Server Version = 3.0.5, loglevel = 0
12/20/2013 18:49:39;0040;PBS_Server;Svr;tyrone-cluster;Scheduler was sent the command new
12/20/2013 18:50:10;0040;PBS_Server;Svr;tyrone-cluster;Scheduler was sent the command new
12/20/2013 18:50:40;0040;PBS_Server;Svr;tyrone-cluster;Scheduler was sent the command new
12/20/2013 18:51:02;0100;PBS_Server;Job;33406.tyrone-cluster;enqueuing into batch, state 1 hop 1
12/20/2013 18:51:02;0100;PBS_Server;Job;33406.tyrone-cluster;dequeuing from batch, state QUEUED
12/20/2013 18:51:02;0100;PBS_Server;Job;33406.tyrone-cluster;enqueuing into qp256, state 1 hop 1
12/20/2013 18:51:02;0008;PBS_Server;Job;33406.tyrone-cluster;Job Queued at request of ipckousi@tyrone-cluster, owner = ipckousi@tyrone-cluster, job name = n11, queue = qp256
12/20/2013 18:51:02;0040;PBS_Server;Svr;tyrone-cluster;Scheduler was sent the command new
12/20/2013 18:51:02;0008;PBS_Server;Job;33406.tyrone-cluster;Job Modified at request of Scheduler@tyrone-cluster
12/20/2013 18:51:02;0008;PBS_Server;Job;33406.tyrone-cluster;Job Run at request of Scheduler@tyrone-cluster
12/20/2013 18:51:02;0040;PBS_Server;Svr;tyrone-cluster;Scheduler was sent the command recyc
12/20/2013 18:51:02;000d;PBS_Server;Job;33406.tyrone-cluster;Not sending email: User does not want mail of this type.
12/20/2013 18:51:02;000d;PBS_Server;Job;33406.tyrone-cluster;Not sending email: User does not want mail of this type.
12/20/2013 18:51:02;0010;PBS_Server;Job;33406.tyrone-cluster;Exit_status=127 resources_used.cput=00:00:00 resources_used.mem=0kb resources_used.vmem=0kb resources_used.walltime=00:00:00
12/20/2013 18:51:02;0008;PBS_Server;Job;NULL;on_job_exit valid pjob: 0x265bdb0 (substate=50)
12/20/2013 18:51:02;0008;PBS_Server;Job;NULL;on_job_exit valid pjob: 0x265bdb0 (substate=51)
12/20/2013 18:51:02;0008;PBS_Server;Job;NULL;on_job_exit valid pjob: 0x265bdb0 (substate=51)
12/20/2013 18:51:02;0008;PBS_Server;Job;NULL;on_job_exit valid pjob: 0x265bdb0 (substate=53)
12/20/2013 18:51:02;0100;PBS_Server;Job;33406.tyrone-cluster;dequeuing from qp256, state COMPLETE
12/20/2013 18:51:02;0040;PBS_Server;Svr;tyrone-cluster;Scheduler was sent the command term
12/20/2013 18:51:13;0040;PBS_Server;Svr;tyrone-cluster;Scheduler was sent the command new
12/20/2013 18:51:40;0040;PBS_Server;Svr;tyrone-cluster;Scheduler was sent the command new
12/20/2013 18:52:10;0040;PBS_Server;Svr;tyrone-cluster;Scheduler was sent the command new
12/20/2013 18:52:41;0040;PBS_Server;Svr;tyrone-cluster;Scheduler was sent the command new
12/20/2013 18:53:10;0040;PBS_Server;Svr;tyrone-cluster;Scheduler was sent the command new
12/20/2013 18:53:40;0040;PBS_Server;Svr;tyrone-cluster;Scheduler was sent the command new
12/20/2013 18:54:14;0040;PBS_Server;Svr;tyrone-cluster;Scheduler was sent the command new
12/20/2013 18:54:33;0002;PBS_Server;Svr;PBS_Server;Torque Server Version = 3.0.5, loglevel = 0
12/20/2013 18:54:45;0040;PBS_Server;Svr;tyrone-cluster;Scheduler was sent the command new
12/20/2013 18:55:22;0040;PBS_Server;Svr;tyrone-cluster;Scheduler was sent the command new
12/20/2013 18:55:52;0040;PBS_Server;Svr;tyrone-cluster;Scheduler was sent the command new
12/20/2013 18:56:24;0040;PBS_Server;Svr;tyrone-cluster;Scheduler was sent the command new
12/20/2013 18:56:55;0040;PBS_Server;Svr;tyrone-cluster;Scheduler was sent the command new
12/20/2013 18:57:25;0040;PBS_Server;Svr;tyrone-cluster;Scheduler was sent the command new
12/20/2013 18:57:58;0040;PBS_Server;Svr;tyrone-cluster;Scheduler was sent the command new
12/20/2013 18:58:25;0040;PBS_Server;Svr;tyrone-cluster;Scheduler was sent the command new
12/20/2013 18:58:33;0100;PBS_Server;Job;33407.tyrone-cluster;enqueuing into batch, state 1 hop 1
12/20/2013 18:58:33;0100;PBS_Server;Job;33407.tyrone-cluster;dequeuing from batch, state QUEUED
12/20/2013 18:58:33;0100;PBS_Server;Job;33407.tyrone-cluster;enqueuing into idqueue, state 1 hop 1
12/20/2013 18:58:33;0008;PBS_Server;Job;33407.tyrone-cluster;Job Queued at request of ipckousi@tyrone-cluster, owner = ipckousi@tyrone-cluster, job name = n11, queue = idqueue
12/20/2013 18:58:33;0040;PBS_Server;Svr;tyrone-cluster;Scheduler was sent the command new
12/20/2013 18:58:33;0008;PBS_Server;Job;33407.tyrone-cluster;Job Modified at request of Scheduler@tyrone-cluster
12/20/2013 18:58:55;0040;PBS_Server;Svr;tyrone-cluster;Scheduler was sent the command new
12/20/2013 18:59:29;0040;PBS_Server;Svr;tyrone-cluster;Scheduler was sent the command new
12/20/2013 18:59:33;0002;PBS_Server;Svr;PBS_Server;Torque Server Version = 3.0.5, loglevel = 0
12/20/2013 19:00:00;0040;PBS_Server;Svr;tyrone-cluster;Scheduler was sent the command new
12/20/2013 19:00:37;0040;PBS_Server;Svr;tyrone-cluster;Scheduler was sent the command new
12/20/2013 19:01:06;0040;PBS_Server;Svr;tyrone-cluster;Scheduler was sent the command new
12/20/2013 19:01:39;0040;PBS_Server;Svr;tyrone-cluster;Scheduler was sent the command new
12/20/2013 19:02:10;0040;PBS_Server;Svr;tyrone-cluster;Scheduler was sent the command new
12/20/2013 19:02:40;0040;PBS_Server;Svr;tyrone-cluster;Scheduler was sent the command new
12/20/2013 19:03:14;0040;PBS_Server;Svr;tyrone-cluster;Scheduler was sent the command new
12/20/2013 19:03:40;0040;PBS_Server;Svr;tyrone-cluster;Scheduler was sent the command new
12/20/2013 19:04:10;0040;PBS_Server;Svr;tyrone-cluster;Scheduler was sent the command new
12/20/2013 19:04:33;0002;PBS_Server;Svr;PBS_Server;Torque Server Version = 3.0.5, loglevel = 0
12/20/2013 19:04:44;0040;PBS_Server;Svr;tyrone-cluster;Scheduler was sent the command new
12/20/2013 19:05:15;0040;PBS_Server;Svr;tyrone-cluster;Scheduler was sent the command new
12/20/2013 19:05:48;0040;PBS_Server;Svr;tyrone-cluster;Scheduler was sent the command new
12/20/2013 19:06:15;0040;PBS_Server;Svr;tyrone-cluster;Scheduler was sent the command new
12/20/2013 19:06:45;0040;PBS_Server;Svr;tyrone-cluster;Scheduler was sent the command new
12/20/2013 19:07:22;0040;PBS_Server;Svr;tyrone-cluster;Scheduler was sent the command new
12/20/2013 19:07:51;0040;PBS_Server;Svr;tyrone-cluster;Scheduler was sent the command new
12/20/2013 19:08:24;0040;PBS_Server;Svr;tyrone-cluster;Scheduler was sent the command new
12/20/2013 19:08:55;0040;PBS_Server;Svr;tyrone-cluster;Scheduler was sent the command new
12/20/2013 19:09:25;0040;PBS_Server;Svr;tyrone-cluster;Scheduler was sent the command new
12/20/2013 19:09:33;0002;PBS_Server;Svr;PBS_Server;Torque Server Version = 3.0.5, loglevel = 0
12/20/2013 19:09:59;0040;PBS_Server;Svr;tyrone-cluster;Scheduler was sent the command new
12/20/2013 19:10:30;0040;PBS_Server;Svr;tyrone-cluster;Scheduler was sent the command new
12/20/2013 19:11:03;0040;PBS_Server;Svr;tyrone-cluster;Scheduler was sent the command new
12/20/2013 19:11:30;0040;PBS_Server;Svr;tyrone-cluster;Scheduler was sent the command new
12/20/2013 19:12:00;0040;PBS_Server;Svr;tyrone-cluster;Scheduler was sent the command new
12/20/2013 19:12:37;0040;PBS_Server;Svr;tyrone-cluster;Scheduler was sent the command new
12/20/2013 19:13:06;0040;PBS_Server;Svr;tyrone-cluster;Scheduler was sent the command new
12/20/2013 19:13:39;0040;PBS_Server;Svr;tyrone-cluster;Scheduler was sent the command new
12/20/2013 19:14:10;0040;PBS_Server;Svr;tyrone-cluster;Scheduler was sent the command new
12/20/2013 19:14:33;0002;PBS_Server;Svr;PBS_Server;Torque Server Version = 3.0.5, loglevel = 0
12/20/2013 19:14:40;0040;PBS_Server;Svr;tyrone-cluster;Scheduler was sent the command new
12/20/2013 19:15:13;0040;PBS_Server;Svr;tyrone-cluster;Scheduler was sent the command new
12/20/2013 19:15:40;0040;PBS_Server;Svr;tyrone-cluster;Scheduler was sent the command new
12/20/2013 19:16:10;0040;PBS_Server;Svr;tyrone-cluster;Scheduler was sent the command new
12/20/2013 19:16:44;0040;PBS_Server;Svr;tyrone-cluster;Scheduler was sent the command new
12/20/2013 19:17:15;0040;PBS_Server;Svr;tyrone-cluster;Scheduler was sent the command new
12/20/2013 19:17:48;0040;PBS_Server;Svr;tyrone-cluster;Scheduler was sent the command new
12/20/2013 19:18:15;0040;PBS_Server;Svr;tyrone-cluster;Scheduler was sent the command new
12/20/2013 19:18:45;0040;PBS_Server;Svr;tyrone-cluster;Scheduler was sent the command new
12/20/2013 19:19:22;0040;PBS_Server;Svr;tyrone-cluster;Scheduler was sent the command new
12/20/2013 19:19:33;0002;PBS_Server;Svr;PBS_Server;Torque Server Version = 3.0.5, loglevel = 0
12/20/2013 19:19:51;0040;PBS_Server;Svr;tyrone-cluster;Scheduler was sent the command new
12/20/2013 19:20:24;0040;PBS_Server;Svr;tyrone-cluster;Scheduler was sent the command new
12/20/2013 19:20:55;0040;PBS_Server;Svr;tyrone-cluster;Scheduler was sent the command new
12/20/2013 19:21:25;0040;PBS_Server;Svr;tyrone-cluster;Scheduler was sent the command new
12/20/2013 19:21:58;0040;PBS_Server;Svr;tyrone-cluster;Scheduler was sent the command new
12/20/2013 19:22:25;0040;PBS_Server;Svr;tyrone-cluster;Scheduler was sent the command new
12/20/2013 19:22:55;0040;PBS_Server;Svr;tyrone-cluster;Scheduler was sent the command new
12/20/2013 19:23:29;0040;PBS_Server;Svr;tyrone-cluster;Scheduler was sent the command new
12/20/2013 19:24:00;0040;PBS_Server;Svr;tyrone-cluster;Scheduler was sent the command new
12/20/2013 19:24:33;0002;PBS_Server;Svr;PBS_Server;Torque Server Version = 3.0.5, loglevel = 0
12/20/2013 19:24:37;0040;PBS_Server;Svr;tyrone-cluster;Scheduler was sent the command new
12/20/2013 19:25:06;0040;PBS_Server;Svr;tyrone-cluster;Scheduler was sent the command new
12/20/2013 19:25:39;0040;PBS_Server;Svr;tyrone-cluster;Scheduler was sent the command new
12/20/2013 19:26:10;0040;PBS_Server;Svr;tyrone-cluster;Scheduler was sent the command new
12/20/2013 19:26:40;0040;PBS_Server;Svr;tyrone-cluster;Scheduler was sent the command new
12/20/2013 19:27:13;0040;PBS_Server;Svr;tyrone-cluster;Scheduler was sent the command new
12/20/2013 19:27:40;0040;PBS_Server;Svr;tyrone-cluster;Scheduler was sent the command new
12/20/2013 19:28:10;0040;PBS_Server;Svr;tyrone-cluster;Scheduler was sent the command new
12/20/2013 19:28:43;0040;PBS_Server;Svr;tyrone-cluster;Scheduler was sent the command new
12/20/2013 19:29:10;0040;PBS_Server;Svr;tyrone-cluster;Scheduler was sent the command new
12/20/2013 19:29:33;0002;PBS_Server;Svr;PBS_Server;Torque Server Version = 3.0.5, loglevel = 0
12/20/2013 19:29:40;0040;PBS_Server;Svr;tyrone-cluster;Scheduler was sent the command new
12/20/2013 19:30:14;0040;PBS_Server;Svr;tyrone-cluster;Scheduler was sent the command new
12/20/2013 19:30:45;0040;PBS_Server;Svr;tyrone-cluster;Scheduler was sent the command new
12/20/2013 19:31:18;0040;PBS_Server;Svr;tyrone-cluster;Scheduler was sent the command new
12/20/2013 19:31:45;0040;PBS_Server;Svr;tyrone-cluster;Scheduler was sent the command new
12/20/2013 19:32:15;0040;PBS_Server;Svr;tyrone-cluster;Scheduler was sent the command new
12/20/2013 19:32:52;0040;PBS_Server;Svr;tyrone-cluster;Scheduler was sent the command new
12/20/2013 19:33:21;0040;PBS_Server;Svr;tyrone-cluster;Scheduler was sent the command new
12/20/2013 19:33:54;0040;PBS_Server;Svr;tyrone-cluster;Scheduler was sent the command new
12/20/2013 19:34:25;0040;PBS_Server;Svr;tyrone-cluster;Scheduler was sent the command new
12/20/2013 19:34:33;0002;PBS_Server;Svr;PBS_Server;Torque Server Version = 3.0.5, loglevel = 0
12/20/2013 19:34:55;0040;PBS_Server;Svr;tyrone-cluster;Scheduler was sent the command new
12/20/2013 19:35:28;0040;PBS_Server;Svr;tyrone-cluster;Scheduler was sent the command new
12/20/2013 19:35:55;0040;PBS_Server;Svr;tyrone-cluster;Scheduler was sent the command new
12/20/2013 19:36:25;0040;PBS_Server;Svr;tyrone-cluster;Scheduler was sent the command new
12/20/2013 19:36:58;0040;PBS_Server;Svr;tyrone-cluster;Scheduler was sent the command new
12/20/2013 19:37:30;0040;PBS_Server;Svr;tyrone-cluster;Scheduler was sent the command new
12/20/2013 19:38:03;0040;PBS_Server;Svr;tyrone-cluster;Scheduler was sent the command new
12/20/2013 19:38:30;0040;PBS_Server;Svr;tyrone-cluster;Scheduler was sent the command new
12/20/2013 19:39:00;0040;PBS_Server;Svr;tyrone-cluster;Scheduler was sent the command new
12/20/2013 19:39:33;0002;PBS_Server;Svr;PBS_Server;Torque Server Version = 3.0.5, loglevel = 0
12/20/2013 19:39:37;0040;PBS_Server;Svr;tyrone-cluster;Scheduler was sent the command new
12/20/2013 19:40:06;0040;PBS_Server;Svr;tyrone-cluster;Scheduler was sent the command new
12/20/2013 19:40:39;0040;PBS_Server;Svr;tyrone-cluster;Scheduler was sent the command new
12/20/2013 19:41:10;0040;PBS_Server;Svr;tyrone-cluster;Scheduler was sent the command new
12/20/2013 19:41:40;0040;PBS_Server;Svr;tyrone-cluster;Scheduler was sent the command new
12/20/2013 19:42:13;0040;PBS_Server;Svr;tyrone-cluster;Scheduler was sent the command new
12/20/2013 19:42:40;0040;PBS_Server;Svr;tyrone-cluster;Scheduler was sent the command new
12/20/2013 19:43:10;0040;PBS_Server;Svr;tyrone-cluster;Scheduler was sent the command new
12/20/2013 19:43:42;0040;PBS_Server;Svr;tyrone-cluster;Scheduler was sent the command new
12/20/2013 19:44:10;0040;PBS_Server;Svr;tyrone-cluster;Scheduler was sent the command new
12/20/2013 19:44:33;0002;PBS_Server;Svr;PBS_Server;Torque Server Version = 3.0.5, loglevel = 0
12/20/2013 19:44:40;0040;PBS_Server;Svr;tyrone-cluster;Scheduler was sent the command new
12/20/2013 19:45:13;0040;PBS_Server;Svr;tyrone-cluster;Scheduler was sent the command new
12/20/2013 19:45:40;0040;PBS_Server;Svr;tyrone-cluster;Scheduler was sent the command new
12/20/2013 19:46:10;0040;PBS_Server;Svr;tyrone-cluster;Scheduler was sent the command new
12/20/2013 19:46:43;0040;PBS_Server;Svr;tyrone-cluster;Scheduler was sent the command new
12/20/2013 19:47:10;0040;PBS_Server;Svr;tyrone-cluster;Scheduler was sent the command new
12/20/2013 19:47:40;0040;PBS_Server;Svr;tyrone-cluster;Scheduler was sent the command new
12/20/2013 19:48:13;0040;PBS_Server;Svr;tyrone-cluster;Scheduler was sent the command new
12/20/2013 19:48:40;0040;PBS_Server;Svr;tyrone-cluster;Scheduler was sent the command new
12/20/2013 19:49:10;0040;PBS_Server;Svr;tyrone-cluster;Scheduler was sent the command new
12/20/2013 19:49:33;0002;PBS_Server;Svr;PBS_Server;Torque Server Version = 3.0.5, loglevel = 0
12/20/2013 19:49:42;0040;PBS_Server;Svr;tyrone-cluster;Scheduler was sent the command new
12/20/2013 19:50:10;0040;PBS_Server;Svr;tyrone-cluster;Scheduler was sent the command new
12/20/2013 19:50:40;0040;PBS_Server;Svr;tyrone-cluster;Scheduler was sent the command new
12/20/2013 19:51:12;0040;PBS_Server;Svr;tyrone-cluster;Scheduler was sent the command new
12/20/2013 19:51:40;0040;PBS_Server;Svr;tyrone-cluster;Scheduler was sent the command new
12/20/2013 19:52:10;0040;PBS_Server;Svr;tyrone-cluster;Scheduler was sent the command new
12/20/2013 19:52:43;0040;PBS_Server;Svr;tyrone-cluster;Scheduler was sent the command new
12/20/2013 19:53:10;0040;PBS_Server;Svr;tyrone-cluster;Scheduler was sent the command new
12/20/2013 19:53:40;0040;PBS_Server;Svr;tyrone-cluster;Scheduler was sent the command new
12/20/2013 19:54:13;0040;PBS_Server;Svr;tyrone-cluster;Scheduler was sent the command new
12/20/2013 19:54:33;0002;PBS_Server;Svr;PBS_Server;Torque Server Version = 3.0.5, loglevel = 0
12/20/2013 19:54:40;0040;PBS_Server;Svr;tyrone-cluster;Scheduler was sent the command new
12/20/2013 19:55:10;0040;PBS_Server;Svr;tyrone-cluster;Scheduler was sent the command new
12/20/2013 19:55:43;0040;PBS_Server;Svr;tyrone-cluster;Scheduler was sent the command new
12/20/2013 19:56:10;0040;PBS_Server;Svr;tyrone-cluster;Scheduler was sent the command new
12/20/2013 19:56:40;0040;PBS_Server;Svr;tyrone-cluster;Scheduler was sent the command new
12/20/2013 19:57:12;0040;PBS_Server;Svr;tyrone-cluster;Scheduler was sent the command new
12/20/2013 19:57:40;0040;PBS_Server;Svr;tyrone-cluster;Scheduler was sent the command new
12/20/2013 19:58:10;0040;PBS_Server;Svr;tyrone-cluster;Scheduler was sent the command new
12/20/2013 19:58:45;0040;PBS_Server;Svr;tyrone-cluster;Scheduler was sent the command new
12/20/2013 19:59:15;0040;PBS_Server;Svr;tyrone-cluster;Scheduler was sent the command new
12/20/2013 19:59:33;0002;PBS_Server;Svr;PBS_Server;Torque Server Version = 3.0.5, loglevel = 0
12/20/2013 19:59:44;0040;PBS_Server;Svr;tyrone-cluster;Scheduler was sent the command new
12/20/2013 20:00:15;0040;PBS_Server;Svr;tyrone-cluster;Scheduler was sent the command new
12/20/2013 20:00:45;0040;PBS_Server;Svr;tyrone-cluster;Scheduler was sent the command new
12/20/2013 20:01:14;0040;PBS_Server;Svr;tyrone-cluster;Scheduler was sent the command new
12/20/2013 20:01:45;0040;PBS_Server;Svr;tyrone-cluster;Scheduler was sent the command new
12/20/2013 20:02:14;0040;PBS_Server;Svr;tyrone-cluster;Scheduler was sent the command new
12/20/2013 20:02:43;0040;PBS_Server;Svr;tyrone-cluster;Scheduler was sent the command new
12/20/2013 20:03:15;0040;PBS_Server;Svr;tyrone-cluster;Scheduler was sent the command new
12/20/2013 20:03:45;0040;PBS_Server;Svr;tyrone-cluster;Scheduler was sent the command new
12/20/2013 20:04:18;0040;PBS_Server;Svr;tyrone-cluster;Scheduler was sent the command new
12/20/2013 20:04:33;0002;PBS_Server;Svr;PBS_Server;Torque Server Version = 3.0.5, loglevel = 0
12/20/2013 20:04:45;0040;PBS_Server;Svr;tyrone-cluster;Scheduler was sent the command new
12/20/2013 20:05:15;0040;PBS_Server;Svr;tyrone-cluster;Scheduler was sent the command new
12/20/2013 20:05:52;0040;PBS_Server;Svr;tyrone-cluster;Scheduler was sent the command new
12/20/2013 20:06:17;0040;PBS_Server;Svr;tyrone-cluster;Scheduler was sent the command new
12/20/2013 20:06:47;0040;PBS_Server;Svr;tyrone-cluster;Scheduler was sent the command new
12/20/2013 20:07:22;0040;PBS_Server;Svr;tyrone-cluster;Scheduler was sent the command new
12/20/2013 20:07:47;0040;PBS_Server;Svr;tyrone-cluster;Scheduler was sent the command new
12/20/2013 20:08:24;0040;PBS_Server;Svr;tyrone-cluster;Scheduler was sent the command new
12/20/2013 20:08:55;0040;PBS_Server;Svr;tyrone-cluster;Scheduler was sent the command new
12/20/2013 20:09:25;0040;PBS_Server;Svr;tyrone-cluster;Scheduler was sent the command new
12/20/2013 20:09:33;0002;PBS_Server;Svr;PBS_Server;Torque Server Version = 3.0.5, loglevel = 0
12/20/2013 20:09:59;0040;PBS_Server;Svr;tyrone-cluster;Scheduler was sent the command new
12/20/2013 20:10:25;0040;PBS_Server;Svr;tyrone-cluster;Scheduler was sent the command new
12/20/2013 20:10:55;0040;PBS_Server;Svr;tyrone-cluster;Scheduler was sent the command new
12/20/2013 20:11:29;0040;PBS_Server;Svr;tyrone-cluster;Scheduler was sent the command new
12/20/2013 20:12:00;0040;PBS_Server;Svr;tyrone-cluster;Scheduler was sent the command new
12/20/2013 20:12:29;0040;PBS_Server;Svr;tyrone-cluster;Scheduler was sent the command new
12/20/2013 20:13:00;0040;PBS_Server;Svr;tyrone-cluster;Scheduler was sent the command new
12/20/2013 20:13:29;0040;PBS_Server;Svr;tyrone-cluster;Scheduler was sent the command new
12/20/2013 20:14:02;0040;PBS_Server;Svr;tyrone-cluster;Scheduler was sent the command new
12/20/2013 20:14:30;0040;PBS_Server;Svr;tyrone-cluster;Scheduler was sent the command new
12/20/2013 20:14:33;0002;PBS_Server;Svr;PBS_Server;Torque Server Version = 3.0.5, loglevel = 0
12/20/2013 20:15:00;0040;PBS_Server;Svr;tyrone-cluster;Scheduler was sent the command new
12/20/2013 20:15:33;0040;PBS_Server;Svr;tyrone-cluster;Scheduler was sent the command new
12/20/2013 20:16:00;0040;PBS_Server;Svr;tyrone-cluster;Scheduler was sent the command new
12/20/2013 20:16:30;0040;PBS_Server;Svr;tyrone-cluster;Scheduler was sent the command new
12/20/2013 20:17:03;0040;PBS_Server;Svr;tyrone-cluster;Scheduler was sent the command new
12/20/2013 20:17:32;0040;PBS_Server;Svr;tyrone-cluster;Scheduler was sent the command new
12/20/2013 20:18:02;0040;PBS_Server;Svr;tyrone-cluster;Scheduler was sent the command new
12/20/2013 20:18:37;0040;PBS_Server;Svr;tyrone-cluster;Scheduler was sent the command new
12/20/2013 20:19:02;0040;PBS_Server;Svr;tyrone-cluster;Scheduler was sent the command new
12/20/2013 20:19:33;0002;PBS_Server;Svr;PBS_Server;Torque Server Version = 3.0.5, loglevel = 0
12/20/2013 20:19:39;0040;PBS_Server;Svr;tyrone-cluster;Scheduler was sent the command new
12/20/2013 20:20:10;0040;PBS_Server;Svr;tyrone-cluster;Scheduler was sent the command new
12/20/2013 20:20:38;0040;PBS_Server;Svr;tyrone-cluster;Scheduler was sent the command new
12/20/2013 20:21:09;0040;PBS_Server;Svr;tyrone-cluster;Scheduler was sent the command new
12/20/2013 20:21:41;0040;PBS_Server;Svr;tyrone-cluster;Scheduler was sent the command new
12/20/2013 20:22:12;0040;PBS_Server;Svr;tyrone-cluster;Scheduler was sent the command new
12/20/2013 20:22:45;0040;PBS_Server;Svr;tyrone-cluster;Scheduler was sent the command new
12/20/2013 20:23:15;0040;PBS_Server;Svr;tyrone-cluster;Scheduler was sent the command new
12/20/2013 20:23:52;0040;PBS_Server;Svr;tyrone-cluster;Scheduler was sent the command new
12/20/2013 20:24:17;0040;PBS_Server;Svr;tyrone-cluster;Scheduler was sent the command new
12/20/2013 20:24:33;0002;PBS_Server;Svr;PBS_Server;Torque Server Version = 3.0.5, loglevel = 0
12/20/2013 20:24:54;0040;PBS_Server;Svr;tyrone-cluster;Scheduler was sent the command new
12/20/2013 20:25:22;0040;PBS_Server;Svr;tyrone-cluster;Scheduler was sent the command new
12/20/2013 20:25:47;0040;PBS_Server;Svr;tyrone-cluster;Scheduler was sent the command new
12/20/2013 20:26:24;0040;PBS_Server;Svr;tyrone-cluster;Scheduler was sent the command new
12/20/2013 20:26:55;0040;PBS_Server;Svr;tyrone-cluster;Scheduler was sent the command new
12/20/2013 20:27:25;0040;PBS_Server;Svr;tyrone-cluster;Scheduler was sent the command new
12/20/2013 20:27:59;0040;PBS_Server;Svr;tyrone-cluster;Scheduler was sent the command new
12/20/2013 20:28:30;0040;PBS_Server;Svr;tyrone-cluster;Scheduler was sent the command new
12/20/2013 20:28:59;0040;PBS_Server;Svr;tyrone-cluster;Scheduler was sent the command new
12/20/2013 20:29:30;0040;PBS_Server;Svr;tyrone-cluster;Scheduler was sent the command new
12/20/2013 20:29:33;0002;PBS_Server;Svr;PBS_Server;Torque Server Version = 3.0.5, loglevel = 0
12/20/2013 20:29:59;0040;PBS_Server;Svr;tyrone-cluster;Scheduler was sent the command new
12/20/2013 20:30:32;0040;PBS_Server;Svr;tyrone-cluster;Scheduler was sent the command new
12/20/2013 20:31:00;0040;PBS_Server;Svr;tyrone-cluster;Scheduler was sent the command new
12/20/2013 20:31:30;0040;PBS_Server;Svr;tyrone-cluster;Scheduler was sent the command new
12/20/2013 20:32:03;0040;PBS_Server;Svr;tyrone-cluster;Scheduler was sent the command new
12/20/2013 20:32:32;0040;PBS_Server;Svr;tyrone-cluster;Scheduler was sent the command new
12/20/2013 20:33:09;0040;PBS_Server;Svr;tyrone-cluster;Scheduler was sent the command new
12/20/2013 20:33:40;0040;PBS_Server;Svr;tyrone-cluster;Scheduler was sent the command new
12/20/2013 20:34:10;0040;PBS_Server;Svr;tyrone-cluster;Scheduler was sent the command new
12/20/2013 20:34:33;0002;PBS_Server;Svr;PBS_Server;Torque Server Version = 3.0.5, loglevel = 0
12/20/2013 20:34:43;0040;PBS_Server;Svr;tyrone-cluster;Scheduler was sent the command new
12/20/2013 20:35:15;0040;PBS_Server;Svr;tyrone-cluster;Scheduler was sent the command new
12/20/2013 20:35:44;0040;PBS_Server;Svr;tyrone-cluster;Scheduler was sent the command new
12/20/2013 20:36:15;0040;PBS_Server;Svr;tyrone-cluster;Scheduler was sent the command new
12/20/2013 20:36:44;0040;PBS_Server;Svr;tyrone-cluster;Scheduler was sent the command new
12/20/2013 20:37:17;0040;PBS_Server;Svr;tyrone-cluster;Scheduler was sent the command new
12/20/2013 20:37:45;0040;PBS_Server;Svr;tyrone-cluster;Scheduler was sent the command new
12/20/2013 20:38:15;0040;PBS_Server;Svr;tyrone-cluster;Scheduler was sent the command new
12/20/2013 20:38:52;0040;PBS_Server;Svr;tyrone-cluster;Scheduler was sent the command new
12/20/2013 20:39:17;0040;PBS_Server;Svr;tyrone-cluster;Scheduler was sent the command new
12/20/2013 20:39:33;0002;PBS_Server;Svr;PBS_Server;Torque Server Version = 3.0.5, loglevel = 0
12/20/2013 20:39:54;0040;PBS_Server;Svr;tyrone-cluster;Scheduler was sent the command new
12/20/2013 20:40:25;0040;PBS_Server;Svr;tyrone-cluster;Scheduler was sent the command new
12/20/2013 20:40:55;0040;PBS_Server;Svr;tyrone-cluster;Scheduler was sent the command new
12/20/2013 20:41:28;0040;PBS_Server;Svr;tyrone-cluster;Scheduler was sent the command new
12/20/2013 20:41:59;0040;PBS_Server;Svr;tyrone-cluster;Scheduler was sent the command new
12/20/2013 20:42:28;0040;PBS_Server;Svr;tyrone-cluster;Scheduler was sent the command new
12/20/2013 20:43:00;0040;PBS_Server;Svr;tyrone-cluster;Scheduler was sent the command new
12/20/2013 20:43:29;0040;PBS_Server;Svr;tyrone-cluster;Scheduler was sent the command new
12/20/2013 20:44:02;0040;PBS_Server;Svr;tyrone-cluster;Scheduler was sent the command new
12/20/2013 20:44:30;0040;PBS_Server;Svr;tyrone-cluster;Scheduler was sent the command new
12/20/2013 20:44:33;0002;PBS_Server;Svr;PBS_Server;Torque Server Version = 3.0.5, loglevel = 0
12/20/2013 20:45:00;0040;PBS_Server;Svr;tyrone-cluster;Scheduler was sent the command new
12/20/2013 20:45:37;0040;PBS_Server;Svr;tyrone-cluster;Scheduler was sent the command new
12/20/2013 20:46:02;0040;PBS_Server;Svr;tyrone-cluster;Scheduler was sent the command new
12/20/2013 20:46:32;0040;PBS_Server;Svr;tyrone-cluster;Scheduler was sent the command new
12/20/2013 20:47:03;0040;PBS_Server;Svr;tyrone-cluster;Scheduler was sent the command new
12/20/2013 20:47:32;0040;PBS_Server;Svr;tyrone-cluster;Scheduler was sent the command new
12/20/2013 20:48:09;0040;PBS_Server;Svr;tyrone-cluster;Scheduler was sent the command new
12/20/2013 20:48:40;0040;PBS_Server;Svr;tyrone-cluster;Scheduler was sent the command new
12/20/2013 20:49:10;0040;PBS_Server;Svr;tyrone-cluster;Scheduler was sent the command new
12/20/2013 20:49:33;0002;PBS_Server;Svr;PBS_Server;Torque Server Version = 3.0.5, loglevel = 0
12/20/2013 20:49:42;0040;PBS_Server;Svr;tyrone-cluster;Scheduler was sent the command new
12/20/2013 20:50:10;0040;PBS_Server;Svr;tyrone-cluster;Scheduler was sent the command new
12/20/2013 20:50:13;000d;PBS_Server;Job;33405.tyrone-cluster;Not sending email: User does not want mail of this type.
12/20/2013 20:50:13;0010;PBS_Server;Job;33405.tyrone-cluster;Exit_status=143 resources_used.cput=62:20:22 resources_used.mem=399208kb resources_used.vmem=9964748kb resources_used.walltime=02:00:51
12/20/2013 20:50:13;0008;PBS_Server;Job;NULL;on_job_exit valid pjob: 0x26ddc50 (substate=50)
12/20/2013 20:50:13;0008;PBS_Server;Job;NULL;on_job_exit valid pjob: 0x26ddc50 (substate=51)
12/20/2013 20:50:13;0008;PBS_Server;Job;33407.tyrone-cluster;Job Modified at request of Scheduler@tyrone-cluster
12/20/2013 20:50:13;0008;PBS_Server;Job;NULL;on_job_exit valid pjob: 0x26ddc50 (substate=51)
12/20/2013 20:50:13;0008;PBS_Server;Job;NULL;on_job_exit valid pjob: 0x26ddc50 (substate=53)
12/20/2013 20:50:13;0100;PBS_Server;Job;33405.tyrone-cluster;dequeuing from idqueue, state COMPLETE
12/20/2013 20:50:13;0040;PBS_Server;Svr;tyrone-cluster;Scheduler was sent the command term
12/20/2013 20:50:13;0008;PBS_Server;Job;33407.tyrone-cluster;Job Modified at request of Scheduler@tyrone-cluster
12/20/2013 20:50:13;0008;PBS_Server;Job;33407.tyrone-cluster;Job Run at request of Scheduler@tyrone-cluster
12/20/2013 20:50:13;0040;PBS_Server;Svr;tyrone-cluster;Scheduler was sent the command recyc
12/20/2013 20:50:13;000d;PBS_Server;Job;33407.tyrone-cluster;Not sending email: User does not want mail of this type.
12/20/2013 20:50:40;0040;PBS_Server;Svr;tyrone-cluster;Scheduler was sent the command new
12/20/2013 20:51:13;0040;PBS_Server;Svr;tyrone-cluster;Scheduler was sent the command new
12/20/2013 20:51:40;0040;PBS_Server;Svr;tyrone-cluster;Scheduler was sent the command new
12/20/2013 20:52:10;0040;PBS_Server;Svr;tyrone-cluster;Scheduler was sent the command new
12/20/2013 20:52:42;0040;PBS_Server;Svr;tyrone-cluster;Scheduler was sent the command new
12/20/2013 20:53:10;0040;PBS_Server;Svr;tyrone-cluster;Scheduler was sent the command new
12/20/2013 20:53:40;0040;PBS_Server;Svr;tyrone-cluster;Scheduler was sent the command new
12/20/2013 20:54:13;0040;PBS_Server;Svr;tyrone-cluster;Scheduler was sent the command new
12/20/2013 20:54:33;0002;PBS_Server;Svr;PBS_Server;Torque Server Version = 3.0.5, loglevel = 0
12/20/2013 20:54:45;0040;PBS_Server;Svr;tyrone-cluster;Scheduler was sent the command new
12/20/2013 20:55:13;0040;PBS_Server;Svr;tyrone-cluster;Scheduler was sent the command new
12/20/2013 20:55:43;0040;PBS_Server;Svr;tyrone-cluster;Scheduler was sent the command new
12/20/2013 20:56:14;0040;PBS_Server;Svr;tyrone-cluster;Scheduler was sent the command new
12/20/2013 20:56:47;0040;PBS_Server;Svr;tyrone-cluster;Scheduler was sent the command new
12/20/2013 20:57:15;0040;PBS_Server;Svr;tyrone-cluster;Scheduler was sent the command new
12/20/2013 20:57:45;0040;PBS_Server;Svr;tyrone-cluster;Scheduler was sent the command new
12/20/2013 20:58:12;0100;PBS_Server;Job;33408.tyrone-cluster;enqueuing into batch, state 1 hop 1
12/20/2013 20:58:12;0100;PBS_Server;Job;33408.tyrone-cluster;dequeuing from batch, state QUEUED
12/20/2013 20:58:12;0100;PBS_Server;Job;33408.tyrone-cluster;enqueuing into qp64, state 1 hop 1
12/20/2013 20:58:12;0008;PBS_Server;Job;33408.tyrone-cluster;Job Queued at request of csdpalvi@tyrone-cluster, owner = csdpalvi@tyrone-cluster, job name = n12, queue = qp64
12/20/2013 20:58:12;0040;PBS_Server;Svr;tyrone-cluster;Scheduler was sent the command new
12/20/2013 20:58:12;0008;PBS_Server;Job;33408.tyrone-cluster;Job Modified at request of Scheduler@tyrone-cluster
12/20/2013 20:58:12;0008;PBS_Server;Job;33408.tyrone-cluster;Job Run at request of Scheduler@tyrone-cluster
12/20/2013 20:58:12;0040;PBS_Server;Svr;tyrone-cluster;Scheduler was sent the command recyc
12/20/2013 20:58:12;000d;PBS_Server;Job;33408.tyrone-cluster;Not sending email: User does not want mail of this type.
12/20/2013 20:58:22;0040;PBS_Server;Svr;tyrone-cluster;Scheduler was sent the command new
12/20/2013 20:58:22;0008;PBS_Server;Job;33392.tyrone-cluster;Job Modified at request of Scheduler@tyrone-cluster
12/20/2013 20:58:22;0008;PBS_Server;Job;33393.tyrone-cluster;Job Modified at request of Scheduler@tyrone-cluster
12/20/2013 20:58:47;0040;PBS_Server;Svr;tyrone-cluster;Scheduler was sent the command new
12/20/2013 20:59:17;0040;PBS_Server;Svr;tyrone-cluster;Scheduler was sent the command new
12/20/2013 20:59:33;0002;PBS_Server;Svr;PBS_Server;Torque Server Version = 3.0.5, loglevel = 0
12/20/2013 20:59:52;0040;PBS_Server;Svr;tyrone-cluster;Scheduler was sent the command new
12/20/2013 21:00:17;0040;PBS_Server;Svr;tyrone-cluster;Scheduler was sent the command new
12/20/2013 21:00:47;0040;PBS_Server;Svr;tyrone-cluster;Scheduler was sent the command new
12/20/2013 21:01:22;0040;PBS_Server;Svr;tyrone-cluster;Scheduler was sent the command new
12/20/2013 21:01:47;0040;PBS_Server;Svr;tyrone-cluster;Scheduler was sent the command new
12/20/2013 21:02:24;0040;PBS_Server;Svr;tyrone-cluster;Scheduler was sent the command new
12/20/2013 21:02:55;0040;PBS_Server;Svr;tyrone-cluster;Scheduler was sent the command new
12/20/2013 21:03:25;0040;PBS_Server;Svr;tyrone-cluster;Scheduler was sent the command new
12/20/2013 21:03:57;0040;PBS_Server;Svr;tyrone-cluster;Scheduler was sent the command new
12/20/2013 21:04:25;0040;PBS_Server;Svr;tyrone-cluster;Scheduler was sent the command new
12/20/2013 21:04:33;0002;PBS_Server;Svr;PBS_Server;Torque Server Version = 3.0.5, loglevel = 0
12/20/2013 21:04:55;0040;PBS_Server;Svr;tyrone-cluster;Scheduler was sent the command new
12/20/2013 21:05:28;0040;PBS_Server;Svr;tyrone-cluster;Scheduler was sent the command new
12/20/2013 21:05:55;0040;PBS_Server;Svr;tyrone-cluster;Scheduler was sent the command new
12/20/2013 21:06:25;0040;PBS_Server;Svr;tyrone-cluster;Scheduler was sent the command new
12/20/2013 21:06:58;0040;PBS_Server;Svr;tyrone-cluster;Scheduler was sent the command new
12/20/2013 21:07:25;0040;PBS_Server;Svr;tyrone-cluster;Scheduler was sent the command new
12/20/2013 21:07:55;0040;PBS_Server;Svr;tyrone-cluster;Scheduler was sent the command new
12/20/2013 21:08:27;0040;PBS_Server;Svr;tyrone-cluster;Scheduler was sent the command new
12/20/2013 21:08:55;0040;PBS_Server;Svr;tyrone-cluster;Scheduler was sent the command new
12/20/2013 21:09:25;0040;PBS_Server;Svr;tyrone-cluster;Scheduler was sent the command new
12/20/2013 21:09:33;0002;PBS_Server;Svr;PBS_Server;Torque Server Version = 3.0.5, loglevel = 0
12/20/2013 21:09:57;0040;PBS_Server;Svr;tyrone-cluster;Scheduler was sent the command new
12/20/2013 21:10:25;0040;PBS_Server;Svr;tyrone-cluster;Scheduler was sent the command new
12/20/2013 21:10:55;0040;PBS_Server;Svr;tyrone-cluster;Scheduler was sent the command new
12/20/2013 21:11:28;0040;PBS_Server;Svr;tyrone-cluster;Scheduler was sent the command new
12/20/2013 21:12:00;0040;PBS_Server;Svr;tyrone-cluster;Scheduler was sent the command new
12/20/2013 21:12:32;0040;PBS_Server;Svr;tyrone-cluster;Scheduler was sent the command new
12/20/2013 21:13:00;0040;PBS_Server;Svr;tyrone-cluster;Scheduler was sent the command new
12/20/2013 21:13:30;0040;PBS_Server;Svr;tyrone-cluster;Scheduler was sent the command new
12/20/2013 21:14:07;0040;PBS_Server;Svr;tyrone-cluster;Scheduler was sent the command new
12/20/2013 21:14:32;0040;PBS_Server;Svr;tyrone-cluster;Scheduler was sent the command new
12/20/2013 21:14:33;0002;PBS_Server;Svr;PBS_Server;Torque Server Version = 3.0.5, loglevel = 0
12/20/2013 21:15:09;0040;PBS_Server;Svr;tyrone-cluster;Scheduler was sent the command new
12/20/2013 21:15:40;0040;PBS_Server;Svr;tyrone-cluster;Scheduler was sent the command new
12/20/2013 21:16:10;0040;PBS_Server;Svr;tyrone-cluster;Scheduler was sent the command new
12/20/2013 21:16:43;0040;PBS_Server;Svr;tyrone-cluster;Scheduler was sent the command new
12/20/2013 21:17:15;0040;PBS_Server;Svr;tyrone-cluster;Scheduler was sent the command new
12/20/2013 21:17:52;0040;PBS_Server;Svr;tyrone-cluster;Scheduler was sent the command new
12/20/2013 21:18:17;0040;PBS_Server;Svr;tyrone-cluster;Scheduler was sent the command new
12/20/2013 21:18:54;0040;PBS_Server;Svr;tyrone-cluster;Scheduler was sent the command new
12/20/2013 21:19:25;0040;PBS_Server;Svr;tyrone-cluster;Scheduler was sent the command new
12/20/2013 21:19:33;0002;PBS_Server;Svr;PBS_Server;Torque Server Version = 3.0.5, loglevel = 0
12/20/2013 21:19:53;0040;PBS_Server;Svr;tyrone-cluster;Scheduler was sent the command new
12/20/2013 21:20:24;0040;PBS_Server;Svr;tyrone-cluster;Scheduler was sent the command new
12/20/2013 21:20:55;0040;PBS_Server;Svr;tyrone-cluster;Scheduler was sent the command new
12/20/2013 21:21:25;0040;PBS_Server;Svr;tyrone-cluster;Scheduler was sent the command new
12/20/2013 21:21:57;0040;PBS_Server;Svr;tyrone-cluster;Scheduler was sent the command new
12/20/2013 21:22:25;0040;PBS_Server;Svr;tyrone-cluster;Scheduler was sent the command new
12/20/2013 21:22:55;0040;PBS_Server;Svr;tyrone-cluster;Scheduler was sent the command new
12/20/2013 21:23:28;0040;PBS_Server;Svr;tyrone-cluster;Scheduler was sent the command new
12/20/2013 21:23:55;0040;PBS_Server;Svr;tyrone-cluster;Scheduler was sent the command new
12/20/2013 21:24:25;0040;PBS_Server;Svr;tyrone-cluster;Scheduler was sent the command new
12/20/2013 21:24:33;0002;PBS_Server;Svr;PBS_Server;Torque Server Version = 3.0.5, loglevel = 0
12/20/2013 21:24:57;0040;PBS_Server;Svr;tyrone-cluster;Scheduler was sent the command new
12/20/2013 21:25:25;0040;PBS_Server;Svr;tyrone-cluster;Scheduler was sent the command new
12/20/2013 21:25:55;0040;PBS_Server;Svr;tyrone-cluster;Scheduler was sent the command new
12/20/2013 21:26:27;0040;PBS_Server;Svr;tyrone-cluster;Scheduler was sent the command new
12/20/2013 21:26:55;0040;PBS_Server;Svr;tyrone-cluster;Scheduler was sent the command new
12/20/2013 21:27:25;0040;PBS_Server;Svr;tyrone-cluster;Scheduler was sent the command new
12/20/2013 21:27:58;0040;PBS_Server;Svr;tyrone-cluster;Scheduler was sent the command new
12/20/2013 21:28:29;0040;PBS_Server;Svr;tyrone-cluster;Scheduler was sent the command new
12/20/2013 21:28:58;0040;PBS_Server;Svr;tyrone-cluster;Scheduler was sent the command new
12/20/2013 21:29:28;0040;PBS_Server;Svr;tyrone-cluster;Scheduler was sent the command new
12/20/2013 21:29:33;0002;PBS_Server;Svr;PBS_Server;Torque Server Version = 3.0.5, loglevel = 0
12/20/2013 21:29:59;0040;PBS_Server;Svr;tyrone-cluster;Scheduler was sent the command new
12/20/2013 21:30:31;0040;PBS_Server;Svr;tyrone-cluster;Scheduler was sent the command new
12/20/2013 21:31:00;0040;PBS_Server;Svr;tyrone-cluster;Scheduler was sent the command new
12/20/2013 21:31:30;0040;PBS_Server;Svr;tyrone-cluster;Scheduler was sent the command new
12/20/2013 21:32:03;0040;PBS_Server;Svr;tyrone-cluster;Scheduler was sent the command new
12/20/2013 21:32:32;0040;PBS_Server;Svr;tyrone-cluster;Scheduler was sent the command new
12/20/2013 21:33:02;0040;PBS_Server;Svr;tyrone-cluster;Scheduler was sent the command new
12/20/2013 21:33:40;0040;PBS_Server;Svr;tyrone-cluster;Scheduler was sent the command new
12/20/2013 21:34:08;0040;PBS_Server;Svr;tyrone-cluster;Scheduler was sent the command new
12/20/2013 21:34:33;0002;PBS_Server;Svr;PBS_Server;Torque Server Version = 3.0.5, loglevel = 0
12/20/2013 21:34:39;0040;PBS_Server;Svr;tyrone-cluster;Scheduler was sent the command new
12/20/2013 21:35:10;0040;PBS_Server;Svr;tyrone-cluster;Scheduler was sent the command new
12/20/2013 21:35:40;0040;PBS_Server;Svr;tyrone-cluster;Scheduler was sent the command new
12/20/2013 21:36:12;0040;PBS_Server;Svr;tyrone-cluster;Scheduler was sent the command new
12/20/2013 21:36:44;0040;PBS_Server;Svr;tyrone-cluster;Scheduler was sent the command new
12/20/2013 21:37:12;0040;PBS_Server;Svr;tyrone-cluster;Scheduler was sent the command new
12/20/2013 21:37:43;0040;PBS_Server;Svr;tyrone-cluster;Scheduler was sent the command new
12/20/2013 21:38:14;0040;PBS_Server;Svr;tyrone-cluster;Scheduler was sent the command new
12/20/2013 21:38:46;0040;PBS_Server;Svr;tyrone-cluster;Scheduler was sent the command new
12/20/2013 21:39:15;0040;PBS_Server;Svr;tyrone-cluster;Scheduler was sent the command new
12/20/2013 21:39:33;0002;PBS_Server;Svr;PBS_Server;Torque Server Version = 3.0.5, loglevel = 0
12/20/2013 21:39:45;0040;PBS_Server;Svr;tyrone-cluster;Scheduler was sent the command new
12/20/2013 21:40:22;0040;PBS_Server;Svr;tyrone-cluster;Scheduler was sent the command new
12/20/2013 21:40:47;0040;PBS_Server;Svr;tyrone-cluster;Scheduler was sent the command new
12/20/2013 21:41:24;0040;PBS_Server;Svr;tyrone-cluster;Scheduler was sent the command new
12/20/2013 21:41:55;0040;PBS_Server;Svr;tyrone-cluster;Scheduler was sent the command new
12/20/2013 21:42:25;0040;PBS_Server;Svr;tyrone-cluster;Scheduler was sent the command new
12/20/2013 21:42:57;0040;PBS_Server;Svr;tyrone-cluster;Scheduler was sent the command new
12/20/2013 21:43:25;0040;PBS_Server;Svr;tyrone-cluster;Scheduler was sent the command new
12/20/2013 21:43:55;0040;PBS_Server;Svr;tyrone-cluster;Scheduler was sent the command new
12/20/2013 21:44:27;0040;PBS_Server;Svr;tyrone-cluster;Scheduler was sent the command new
12/20/2013 21:44:33;0002;PBS_Server;Svr;PBS_Server;Torque Server Version = 3.0.5, loglevel = 0
12/20/2013 21:44:55;0040;PBS_Server;Svr;tyrone-cluster;Scheduler was sent the command new
12/20/2013 21:45:25;0040;PBS_Server;Svr;tyrone-cluster;Scheduler was sent the command new
12/20/2013 21:45:58;0040;PBS_Server;Svr;tyrone-cluster;Scheduler was sent the command new
12/20/2013 21:46:29;0040;PBS_Server;Svr;tyrone-cluster;Scheduler was sent the command new
12/20/2013 21:47:01;0040;PBS_Server;Svr;tyrone-cluster;Scheduler was sent the command new
12/20/2013 21:47:31;0040;PBS_Server;Svr;tyrone-cluster;Scheduler was sent the command new
12/20/2013 21:48:01;0040;PBS_Server;Svr;tyrone-cluster;Scheduler was sent the command new
12/20/2013 21:48:37;0040;PBS_Server;Svr;tyrone-cluster;Scheduler was sent the command new
12/20/2013 21:49:02;0040;PBS_Server;Svr;tyrone-cluster;Scheduler was sent the command new
12/20/2013 21:49:33;0002;PBS_Server;Svr;PBS_Server;Torque Server Version = 3.0.5, loglevel = 0
12/20/2013 21:49:39;0040;PBS_Server;Svr;tyrone-cluster;Scheduler was sent the command new
12/20/2013 21:50:10;0040;PBS_Server;Svr;tyrone-cluster;Scheduler was sent the command new
12/20/2013 21:50:38;0040;PBS_Server;Svr;tyrone-cluster;Scheduler was sent the command new
12/20/2013 21:51:09;0040;PBS_Server;Svr;tyrone-cluster;Scheduler was sent the command new
12/20/2013 21:51:40;0040;PBS_Server;Svr;tyrone-cluster;Scheduler was sent the command new
12/20/2013 21:51:47;000d;PBS_Server;Job;33306.tyrone-cluster;Not sending email: User does not want mail of this type.
12/20/2013 21:51:47;0010;PBS_Server;Job;33306.tyrone-cluster;Exit_status=143 resources_used.cput=761:11:47 resources_used.mem=985956kb resources_used.vmem=7479908kb resources_used.walltime=24:00:38
12/20/2013 21:51:47;0008;PBS_Server;Job;NULL;on_job_exit valid pjob: 0x26895e0 (substate=50)
12/20/2013 21:51:47;0008;PBS_Server;Job;NULL;on_job_exit valid pjob: 0x26895e0 (substate=51)
12/20/2013 21:51:47;0008;PBS_Server;Job;NULL;on_job_exit valid pjob: 0x26895e0 (substate=51)
12/20/2013 21:51:47;0008;PBS_Server;Job;NULL;on_job_exit valid pjob: 0x26895e0 (substate=53)
12/20/2013 21:51:47;0100;PBS_Server;Job;33306.tyrone-cluster;dequeuing from qp128, state COMPLETE
12/20/2013 21:51:47;0040;PBS_Server;Svr;tyrone-cluster;Scheduler was sent the command term
12/20/2013 21:51:47;0008;PBS_Server;Job;33359.tyrone-cluster;Job Modified at request of Scheduler@tyrone-cluster
12/20/2013 21:51:47;0008;PBS_Server;Job;33359.tyrone-cluster;Job Run at request of Scheduler@tyrone-cluster
12/20/2013 21:51:47;0040;PBS_Server;Svr;tyrone-cluster;Scheduler was sent the command recyc
12/20/2013 21:51:48;000d;PBS_Server;Job;33359.tyrone-cluster;Not sending email: User does not want mail of this type.
12/20/2013 21:51:48;0010;PBS_Server;Job;33359.tyrone-cluster;Exit_status=1 resources_used.cput=00:00:00 resources_used.mem=812kb resources_used.vmem=13628kb resources_used.walltime=00:00:01
12/20/2013 21:51:48;0008;PBS_Server;Job;NULL;on_job_exit valid pjob: 0x2659510 (substate=50)
12/20/2013 21:51:48;0008;PBS_Server;Job;NULL;on_job_exit valid pjob: 0x2659510 (substate=51)
12/20/2013 21:51:49;0008;PBS_Server;Job;NULL;on_job_exit valid pjob: 0x2659510 (substate=51)
12/20/2013 21:51:49;0008;PBS_Server;Job;NULL;on_job_exit valid pjob: 0x2659510 (substate=53)
12/20/2013 21:51:49;0100;PBS_Server;Job;33359.tyrone-cluster;dequeuing from qp128, state COMPLETE
12/20/2013 21:51:49;0040;PBS_Server;Svr;tyrone-cluster;Scheduler was sent the command term
12/20/2013 21:51:49;0008;PBS_Server;Job;33242.tyrone-cluster;Job Modified at request of Scheduler@tyrone-cluster
12/20/2013 21:51:49;0008;PBS_Server;Job;33242.tyrone-cluster;Job Run at request of Scheduler@tyrone-cluster
12/20/2013 21:51:49;0008;PBS_Server;Job;33258.tyrone-cluster;Job Modified at request of Scheduler@tyrone-cluster
12/20/2013 21:51:49;0040;PBS_Server;Svr;tyrone-cluster;Scheduler was sent the command recyc
12/20/2013 21:52:10;0040;PBS_Server;Svr;tyrone-cluster;Scheduler was sent the command new
12/20/2013 21:52:33;000d;PBS_Server;Job;33242.tyrone-cluster;Not sending email: User does not want mail of this type.
12/20/2013 21:52:43;0040;PBS_Server;Svr;tyrone-cluster;Scheduler was sent the command new
12/20/2013 21:53:14;0040;PBS_Server;Svr;tyrone-cluster;Scheduler was sent the command new
12/20/2013 21:53:42;0040;PBS_Server;Svr;tyrone-cluster;Scheduler was sent the command new
12/20/2013 21:54:13;0040;PBS_Server;Svr;tyrone-cluster;Scheduler was sent the command new
12/20/2013 21:54:33;0002;PBS_Server;Svr;PBS_Server;Torque Server Version = 3.0.5, loglevel = 0
12/20/2013 21:54:44;0040;PBS_Server;Svr;tyrone-cluster;Scheduler was sent the command new
12/20/2013 21:55:16;0040;PBS_Server;Svr;tyrone-cluster;Scheduler was sent the command new
12/20/2013 21:55:45;0040;PBS_Server;Svr;tyrone-cluster;Scheduler was sent the command new
12/20/2013 21:56:15;0040;PBS_Server;Svr;tyrone-cluster;Scheduler was sent the command new
12/20/2013 21:56:52;0040;PBS_Server;Svr;tyrone-cluster;Scheduler was sent the command new
12/20/2013 21:57:17;0040;PBS_Server;Svr;tyrone-cluster;Scheduler was sent the command new
12/20/2013 21:57:48;0040;PBS_Server;Svr;tyrone-cluster;Scheduler was sent the command new
12/20/2013 21:58:26;0040;PBS_Server;Svr;tyrone-cluster;Scheduler was sent the command new
12/20/2013 21:58:53;0040;PBS_Server;Svr;tyrone-cluster;Scheduler was sent the command new
12/20/2013 21:59:24;0040;PBS_Server;Svr;tyrone-cluster;Scheduler was sent the command new
12/20/2013 21:59:33;0002;PBS_Server;Svr;PBS_Server;Torque Server Version = 3.0.5, loglevel = 0
12/20/2013 21:59:58;0040;PBS_Server;Svr;tyrone-cluster;Scheduler was sent the command new
12/20/2013 22:00:25;0040;PBS_Server;Svr;tyrone-cluster;Scheduler was sent the command new
12/20/2013 22:00:57;0040;PBS_Server;Svr;tyrone-cluster;Scheduler was sent the command new
12/20/2013 22:01:29;0040;PBS_Server;Svr;tyrone-cluster;Scheduler was sent the command new
12/20/2013 22:01:57;0040;PBS_Server;Svr;tyrone-cluster;Scheduler was sent the command new
12/20/2013 22:02:28;0040;PBS_Server;Svr;tyrone-cluster;Scheduler was sent the command new
12/20/2013 22:02:59;0040;PBS_Server;Svr;tyrone-cluster;Scheduler was sent the command new
12/20/2013 22:03:31;0040;PBS_Server;Svr;tyrone-cluster;Scheduler was sent the command new
12/20/2013 22:04:00;0040;PBS_Server;Svr;tyrone-cluster;Scheduler was sent the command new
12/20/2013 22:04:30;0040;PBS_Server;Svr;tyrone-cluster;Scheduler was sent the command new
12/20/2013 22:04:33;0002;PBS_Server;Svr;PBS_Server;Torque Server Version = 3.0.5, loglevel = 0
12/20/2013 22:05:07;0040;PBS_Server;Svr;tyrone-cluster;Scheduler was sent the command new
12/20/2013 22:05:30;0040;PBS_Server;Svr;tyrone-cluster;Scheduler was sent the command new
12/20/2013 22:06:00;0040;PBS_Server;Svr;tyrone-cluster;Scheduler was sent the command new
12/20/2013 22:06:37;0040;PBS_Server;Svr;tyrone-cluster;Scheduler was sent the command new
12/20/2013 22:07:02;0040;PBS_Server;Svr;tyrone-cluster;Scheduler was sent the command new
12/20/2013 22:07:33;0040;PBS_Server;Svr;tyrone-cluster;Scheduler was sent the command new
12/20/2013 22:08:11;0040;PBS_Server;Svr;tyrone-cluster;Scheduler was sent the command new
12/20/2013 22:08:38;0040;PBS_Server;Svr;tyrone-cluster;Scheduler was sent the command new
12/20/2013 22:09:09;0040;PBS_Server;Svr;tyrone-cluster;Scheduler was sent the command new
12/20/2013 22:09:33;0002;PBS_Server;Svr;PBS_Server;Torque Server Version = 3.0.5, loglevel = 0
12/20/2013 22:09:43;0040;PBS_Server;Svr;tyrone-cluster;Scheduler was sent the command new
12/20/2013 22:10:10;0040;PBS_Server;Svr;tyrone-cluster;Scheduler was sent the command new
12/20/2013 22:10:42;0040;PBS_Server;Svr;tyrone-cluster;Scheduler was sent the command new
12/20/2013 22:11:14;0040;PBS_Server;Svr;tyrone-cluster;Scheduler was sent the command new
12/20/2013 22:11:42;0040;PBS_Server;Svr;tyrone-cluster;Scheduler was sent the command new
12/20/2013 22:12:13;0040;PBS_Server;Svr;tyrone-cluster;Scheduler was sent the command new
12/20/2013 22:12:44;0040;PBS_Server;Svr;tyrone-cluster;Scheduler was sent the command new
12/20/2013 22:13:16;0040;PBS_Server;Svr;tyrone-cluster;Scheduler was sent the command new
12/20/2013 22:13:45;0040;PBS_Server;Svr;tyrone-cluster;Scheduler was sent the command new
12/20/2013 22:14:15;0040;PBS_Server;Svr;tyrone-cluster;Scheduler was sent the command new
12/20/2013 22:14:33;0002;PBS_Server;Svr;PBS_Server;Torque Server Version = 3.0.5, loglevel = 0
12/20/2013 22:14:52;0040;PBS_Server;Svr;tyrone-cluster;Scheduler was sent the command new
12/20/2013 22:15:17;0040;PBS_Server;Svr;tyrone-cluster;Scheduler was sent the command new
12/20/2013 22:15:48;0040;PBS_Server;Svr;tyrone-cluster;Scheduler was sent the command new
12/20/2013 22:16:25;0040;PBS_Server;Svr;tyrone-cluster;Scheduler was sent the command new
12/20/2013 22:16:53;0040;PBS_Server;Svr;tyrone-cluster;Scheduler was sent the command new
12/20/2013 22:17:24;0040;PBS_Server;Svr;tyrone-cluster;Scheduler was sent the command new
12/20/2013 22:17:24;000d;PBS_Server;Job;33408.tyrone-cluster;Not sending email: User does not want mail of this type.
12/20/2013 22:17:24;0010;PBS_Server;Job;33408.tyrone-cluster;Exit_status=0 resources_used.cput=73:58:19 resources_used.mem=7361444kb resources_used.vmem=132202548kb resources_used.walltime=01:19:13
12/20/2013 22:17:24;0008;PBS_Server;Job;NULL;on_job_exit valid pjob: 0x265bdb0 (substate=50)
12/20/2013 22:17:24;0008;PBS_Server;Job;NULL;on_job_exit valid pjob: 0x265bdb0 (substate=51)
12/20/2013 22:17:24;0008;PBS_Server;Job;33392.tyrone-cluster;Job Modified at request of Scheduler@tyrone-cluster
12/20/2013 22:17:24;0008;PBS_Server;Job;33393.tyrone-cluster;Job Modified at request of Scheduler@tyrone-cluster
12/20/2013 22:17:24;0008;PBS_Server;Job;NULL;on_job_exit valid pjob: 0x265bdb0 (substate=51)
12/20/2013 22:17:24;0008;PBS_Server;Job;NULL;on_job_exit valid pjob: 0x265bdb0 (substate=53)
12/20/2013 22:17:24;0100;PBS_Server;Job;33408.tyrone-cluster;dequeuing from qp64, state COMPLETE
12/20/2013 22:17:24;0040;PBS_Server;Svr;tyrone-cluster;Scheduler was sent the command term
12/20/2013 22:17:58;0040;PBS_Server;Svr;tyrone-cluster;Scheduler was sent the command new
12/20/2013 22:18:25;0040;PBS_Server;Svr;tyrone-cluster;Scheduler was sent the command new
12/20/2013 22:18:58;0040;PBS_Server;Svr;tyrone-cluster;Scheduler was sent the command new
12/20/2013 22:19:29;0040;PBS_Server;Svr;tyrone-cluster;Scheduler was sent the command new
12/20/2013 22:19:33;0002;PBS_Server;Svr;PBS_Server;Torque Server Version = 3.0.5, loglevel = 0
12/20/2013 22:20:01;0040;PBS_Server;Svr;tyrone-cluster;Scheduler was sent the command new
12/20/2013 22:20:30;0040;PBS_Server;Svr;tyrone-cluster;Scheduler was sent the command new
12/20/2013 22:21:00;0040;PBS_Server;Svr;tyrone-cluster;Scheduler was sent the command new
12/20/2013 22:21:37;0040;PBS_Server;Svr;tyrone-cluster;Scheduler was sent the command new
12/20/2013 22:22:00;0040;PBS_Server;Svr;tyrone-cluster;Scheduler was sent the command new
12/20/2013 22:22:30;0040;PBS_Server;Svr;tyrone-cluster;Scheduler was sent the command new
12/20/2013 22:23:07;0040;PBS_Server;Svr;tyrone-cluster;Scheduler was sent the command new
12/20/2013 22:23:32;0040;PBS_Server;Svr;tyrone-cluster;Scheduler was sent the command new
12/20/2013 22:24:03;0040;PBS_Server;Svr;tyrone-cluster;Scheduler was sent the command new
12/20/2013 22:24:33;0002;PBS_Server;Svr;PBS_Server;Torque Server Version = 3.0.5, loglevel = 0
12/20/2013 22:24:37;0040;PBS_Server;Svr;tyrone-cluster;Scheduler was sent the command new
12/20/2013 22:25:04;0040;PBS_Server;Svr;tyrone-cluster;Scheduler was sent the command new
12/20/2013 22:25:33;0040;PBS_Server;Svr;tyrone-cluster;Scheduler was sent the command new
12/20/2013 22:26:10;0040;PBS_Server;Svr;tyrone-cluster;Scheduler was sent the command new
12/20/2013 22:26:38;0040;PBS_Server;Svr;tyrone-cluster;Scheduler was sent the command new
12/20/2013 22:27:09;0040;PBS_Server;Svr;tyrone-cluster;Scheduler was sent the command new
12/20/2013 22:27:43;0040;PBS_Server;Svr;tyrone-cluster;Scheduler was sent the command new
12/20/2013 22:28:10;0040;PBS_Server;Svr;tyrone-cluster;Scheduler was sent the command new
12/20/2013 22:28:43;0040;PBS_Server;Svr;tyrone-cluster;Scheduler was sent the command new
12/20/2013 22:29:14;0040;PBS_Server;Svr;tyrone-cluster;Scheduler was sent the command new
12/20/2013 22:29:33;0002;PBS_Server;Svr;PBS_Server;Torque Server Version = 3.0.5, loglevel = 0
12/20/2013 22:29:42;0040;PBS_Server;Svr;tyrone-cluster;Scheduler was sent the command new
12/20/2013 22:30:13;0040;PBS_Server;Svr;tyrone-cluster;Scheduler was sent the command new
12/20/2013 22:30:44;0040;PBS_Server;Svr;tyrone-cluster;Scheduler was sent the command new
12/20/2013 22:31:15;0040;PBS_Server;Svr;tyrone-cluster;Scheduler was sent the command new
12/20/2013 22:31:45;0040;PBS_Server;Svr;tyrone-cluster;Scheduler was sent the command new
12/20/2013 22:32:15;0040;PBS_Server;Svr;tyrone-cluster;Scheduler was sent the command new
12/20/2013 22:32:52;0040;PBS_Server;Svr;tyrone-cluster;Scheduler was sent the command new
12/20/2013 22:33:15;0040;PBS_Server;Svr;tyrone-cluster;Scheduler was sent the command new
12/20/2013 22:33:45;0040;PBS_Server;Svr;tyrone-cluster;Scheduler was sent the command new
12/20/2013 22:33:57;0100;PBS_Server;Job;33409.tyrone-cluster;enqueuing into batch, state 1 hop 1
12/20/2013 22:33:57;0100;PBS_Server;Job;33409.tyrone-cluster;dequeuing from batch, state QUEUED
12/20/2013 22:33:57;0100;PBS_Server;Job;33409.tyrone-cluster;enqueuing into idqueue, state 1 hop 1
12/20/2013 22:33:57;0008;PBS_Server;Job;33409.tyrone-cluster;Job Queued at request of ipckousi@tyrone-cluster, owner = ipckousi@tyrone-cluster, job name = n11, queue = idqueue
12/20/2013 22:33:57;0040;PBS_Server;Svr;tyrone-cluster;Scheduler was sent the command new
12/20/2013 22:33:57;0008;PBS_Server;Job;33409.tyrone-cluster;Job Modified at request of Scheduler@tyrone-cluster
12/20/2013 22:34:22;0040;PBS_Server;Svr;tyrone-cluster;Scheduler was sent the command new
12/20/2013 22:34:33;0002;PBS_Server;Svr;PBS_Server;Torque Server Version = 3.0.5, loglevel = 0
12/20/2013 22:34:45;0040;PBS_Server;Svr;tyrone-cluster;Scheduler was sent the command new
12/20/2013 22:35:15;0040;PBS_Server;Svr;tyrone-cluster;Scheduler was sent the command new
12/20/2013 22:35:52;0040;PBS_Server;Svr;tyrone-cluster;Scheduler was sent the command new
12/20/2013 22:36:17;0040;PBS_Server;Svr;tyrone-cluster;Scheduler was sent the command new
12/20/2013 22:36:48;0040;PBS_Server;Svr;tyrone-cluster;Scheduler was sent the command new
12/20/2013 22:37:25;0040;PBS_Server;Svr;tyrone-cluster;Scheduler was sent the command new
12/20/2013 22:37:53;0040;PBS_Server;Svr;tyrone-cluster;Scheduler was sent the command new
12/20/2013 22:38:24;0040;PBS_Server;Svr;tyrone-cluster;Scheduler was sent the command new
12/20/2013 22:38:58;0040;PBS_Server;Svr;tyrone-cluster;Scheduler was sent the command new
12/20/2013 22:39:25;0040;PBS_Server;Svr;tyrone-cluster;Scheduler was sent the command new
12/20/2013 22:39:33;0002;PBS_Server;Svr;PBS_Server;Torque Server Version = 3.0.5, loglevel = 0
12/20/2013 22:39:58;0040;PBS_Server;Svr;tyrone-cluster;Scheduler was sent the command new
12/20/2013 22:40:29;0040;PBS_Server;Svr;tyrone-cluster;Scheduler was sent the command new
12/20/2013 22:40:57;0040;PBS_Server;Svr;tyrone-cluster;Scheduler was sent the command new
12/20/2013 22:41:28;0040;PBS_Server;Svr;tyrone-cluster;Scheduler was sent the command new
12/20/2013 22:41:59;0040;PBS_Server;Svr;tyrone-cluster;Scheduler was sent the command new
12/20/2013 22:42:30;0040;PBS_Server;Svr;tyrone-cluster;Scheduler was sent the command new
12/20/2013 22:43:00;0040;PBS_Server;Svr;tyrone-cluster;Scheduler was sent the command new
12/20/2013 22:43:30;0040;PBS_Server;Svr;tyrone-cluster;Scheduler was sent the command new
12/20/2013 22:44:07;0040;PBS_Server;Svr;tyrone-cluster;Scheduler was sent the command new
12/20/2013 22:44:30;0040;PBS_Server;Svr;tyrone-cluster;Scheduler was sent the command new
12/20/2013 22:44:33;0002;PBS_Server;Svr;PBS_Server;Torque Server Version = 3.0.5, loglevel = 0
12/20/2013 22:45:00;0040;PBS_Server;Svr;tyrone-cluster;Scheduler was sent the command new
12/20/2013 22:45:37;0040;PBS_Server;Svr;tyrone-cluster;Scheduler was sent the command new
12/20/2013 22:46:02;0040;PBS_Server;Svr;tyrone-cluster;Scheduler was sent the command new
12/20/2013 22:46:33;0040;PBS_Server;Svr;tyrone-cluster;Scheduler was sent the command new
12/20/2013 22:47:07;0040;PBS_Server;Svr;tyrone-cluster;Scheduler was sent the command new
12/20/2013 22:47:34;0040;PBS_Server;Svr;tyrone-cluster;Scheduler was sent the command new
12/20/2013 22:48:03;0040;PBS_Server;Svr;tyrone-cluster;Scheduler was sent the command new
12/20/2013 22:48:40;0040;PBS_Server;Svr;tyrone-cluster;Scheduler was sent the command new
12/20/2013 22:49:08;0040;PBS_Server;Svr;tyrone-cluster;Scheduler was sent the command new
12/20/2013 22:49:33;0002;PBS_Server;Svr;PBS_Server;Torque Server Version = 3.0.5, loglevel = 0
12/20/2013 22:49:38;0040;PBS_Server;Svr;tyrone-cluster;Scheduler was sent the command new
12/20/2013 22:50:13;0040;PBS_Server;Svr;tyrone-cluster;Scheduler was sent the command new
12/20/2013 22:50:40;0040;PBS_Server;Svr;tyrone-cluster;Scheduler was sent the command new
12/20/2013 22:50:57;000d;PBS_Server;Job;33407.tyrone-cluster;Not sending email: User does not want mail of this type.
12/20/2013 22:50:57;0010;PBS_Server;Job;33407.tyrone-cluster;Exit_status=143 resources_used.cput=62:16:27 resources_used.mem=403296kb resources_used.vmem=9964744kb resources_used.walltime=02:00:44
12/20/2013 22:50:57;0008;PBS_Server;Job;NULL;on_job_exit valid pjob: 0x2760260 (substate=50)
12/20/2013 22:50:57;0008;PBS_Server;Job;NULL;on_job_exit valid pjob: 0x2760260 (substate=51)
12/20/2013 22:50:57;0008;PBS_Server;Job;NULL;on_job_exit valid pjob: 0x2760260 (substate=51)
12/20/2013 22:50:57;0008;PBS_Server;Job;NULL;on_job_exit valid pjob: 0x2760260 (substate=53)
12/20/2013 22:50:57;0100;PBS_Server;Job;33407.tyrone-cluster;dequeuing from idqueue, state COMPLETE
12/20/2013 22:50:57;0040;PBS_Server;Svr;tyrone-cluster;Scheduler was sent the command term
12/20/2013 22:50:57;0008;PBS_Server;Job;33409.tyrone-cluster;Job Modified at request of Scheduler@tyrone-cluster
12/20/2013 22:50:57;0008;PBS_Server;Job;33409.tyrone-cluster;Job Run at request of Scheduler@tyrone-cluster
12/20/2013 22:50:57;0040;PBS_Server;Svr;tyrone-cluster;Scheduler was sent the command recyc
12/20/2013 22:50:57;000d;PBS_Server;Job;33409.tyrone-cluster;Not sending email: User does not want mail of this type.
12/20/2013 22:51:15;0040;PBS_Server;Svr;tyrone-cluster;Scheduler was sent the command new
12/20/2013 22:51:43;0040;PBS_Server;Svr;tyrone-cluster;Scheduler was sent the command new
12/20/2013 22:52:15;0040;PBS_Server;Svr;tyrone-cluster;Scheduler was sent the command new
12/20/2013 22:52:45;0040;PBS_Server;Svr;tyrone-cluster;Scheduler was sent the command new
12/20/2013 22:53:15;0040;PBS_Server;Svr;tyrone-cluster;Scheduler was sent the command new
12/20/2013 22:53:52;0040;PBS_Server;Svr;tyrone-cluster;Scheduler was sent the command new
12/20/2013 22:54:15;0040;PBS_Server;Svr;tyrone-cluster;Scheduler was sent the command new
12/20/2013 22:54:33;0002;PBS_Server;Svr;PBS_Server;Torque Server Version = 3.0.5, loglevel = 0
12/20/2013 22:54:45;0040;PBS_Server;Svr;tyrone-cluster;Scheduler was sent the command new
12/20/2013 22:55:22;0040;PBS_Server;Svr;tyrone-cluster;Scheduler was sent the command new
12/20/2013 22:55:45;0040;PBS_Server;Svr;tyrone-cluster;Scheduler was sent the command new
12/20/2013 22:56:15;0040;PBS_Server;Svr;tyrone-cluster;Scheduler was sent the command new
12/20/2013 22:56:52;0040;PBS_Server;Svr;tyrone-cluster;Scheduler was sent the command new
12/20/2013 22:57:16;0040;PBS_Server;Svr;tyrone-cluster;Scheduler was sent the command new
12/20/2013 22:57:46;0040;PBS_Server;Svr;tyrone-cluster;Scheduler was sent the command new
12/20/2013 22:58:25;0040;PBS_Server;Svr;tyrone-cluster;Scheduler was sent the command new
12/20/2013 22:58:53;0040;PBS_Server;Svr;tyrone-cluster;Scheduler was sent the command new
12/20/2013 22:59:24;0040;PBS_Server;Svr;tyrone-cluster;Scheduler was sent the command new
12/20/2013 22:59:33;0002;PBS_Server;Svr;PBS_Server;Torque Server Version = 3.0.5, loglevel = 0
12/20/2013 22:59:58;0040;PBS_Server;Svr;tyrone-cluster;Scheduler was sent the command new
12/20/2013 23:00:25;0040;PBS_Server;Svr;tyrone-cluster;Scheduler was sent the command new
12/20/2013 23:01:00;0040;PBS_Server;Svr;tyrone-cluster;Scheduler was sent the command new
12/20/2013 23:01:28;0040;PBS_Server;Svr;tyrone-cluster;Scheduler was sent the command new
12/20/2013 23:01:55;0040;PBS_Server;Svr;tyrone-cluster;Scheduler was sent the command new
12/20/2013 23:02:30;0040;PBS_Server;Svr;tyrone-cluster;Scheduler was sent the command new
12/20/2013 23:02:58;0040;PBS_Server;Svr;tyrone-cluster;Scheduler was sent the command new
12/20/2013 23:03:28;0040;PBS_Server;Svr;tyrone-cluster;Scheduler was sent the command new
12/20/2013 23:04:00;0040;PBS_Server;Svr;tyrone-cluster;Scheduler was sent the command new
12/20/2013 23:04:30;0040;PBS_Server;Svr;tyrone-cluster;Scheduler was sent the command new
12/20/2013 23:04:33;0002;PBS_Server;Svr;PBS_Server;Torque Server Version = 3.0.5, loglevel = 0
12/20/2013 23:05:07;0040;PBS_Server;Svr;tyrone-cluster;Scheduler was sent the command new
12/20/2013 23:05:30;0040;PBS_Server;Svr;tyrone-cluster;Scheduler was sent the command new
12/20/2013 23:06:00;0040;PBS_Server;Svr;tyrone-cluster;Scheduler was sent the command new
12/20/2013 23:06:37;0040;PBS_Server;Svr;tyrone-cluster;Scheduler was sent the command new
12/20/2013 23:07:00;0040;PBS_Server;Svr;tyrone-cluster;Scheduler was sent the command new
12/20/2013 23:07:30;0040;PBS_Server;Svr;tyrone-cluster;Scheduler was sent the command new
12/20/2013 23:08:09;0040;PBS_Server;Svr;tyrone-cluster;Scheduler was sent the command new
12/20/2013 23:08:38;0040;PBS_Server;Svr;tyrone-cluster;Scheduler was sent the command new
12/20/2013 23:09:09;0040;PBS_Server;Svr;tyrone-cluster;Scheduler was sent the command new
12/20/2013 23:09:33;0002;PBS_Server;Svr;PBS_Server;Torque Server Version = 3.0.5, loglevel = 0
12/20/2013 23:09:43;0040;PBS_Server;Svr;tyrone-cluster;Scheduler was sent the command new
12/20/2013 23:10:10;0040;PBS_Server;Svr;tyrone-cluster;Scheduler was sent the command new
12/20/2013 23:10:45;0040;PBS_Server;Svr;tyrone-cluster;Scheduler was sent the command new
12/20/2013 23:11:13;0040;PBS_Server;Svr;tyrone-cluster;Scheduler was sent the command new
12/20/2013 23:11:40;0040;PBS_Server;Svr;tyrone-cluster;Scheduler was sent the command new
12/20/2013 23:12:15;0040;PBS_Server;Svr;tyrone-cluster;Scheduler was sent the command new
12/20/2013 23:12:43;0040;PBS_Server;Svr;tyrone-cluster;Scheduler was sent the command new
12/20/2013 23:13:15;0040;PBS_Server;Svr;tyrone-cluster;Scheduler was sent the command new
12/20/2013 23:13:45;0040;PBS_Server;Svr;tyrone-cluster;Scheduler was sent the command new
12/20/2013 23:14:15;0040;PBS_Server;Svr;tyrone-cluster;Scheduler was sent the command new
12/20/2013 23:14:33;0002;PBS_Server;Svr;PBS_Server;Torque Server Version = 3.0.5, loglevel = 0
12/20/2013 23:14:52;0040;PBS_Server;Svr;tyrone-cluster;Scheduler was sent the command new
12/20/2013 23:15:15;0040;PBS_Server;Svr;tyrone-cluster;Scheduler was sent the command new
12/20/2013 23:15:45;0040;PBS_Server;Svr;tyrone-cluster;Scheduler was sent the command new
12/20/2013 23:16:22;0040;PBS_Server;Svr;tyrone-cluster;Scheduler was sent the command new
12/20/2013 23:16:45;0040;PBS_Server;Svr;tyrone-cluster;Scheduler was sent the command new
12/20/2013 23:17:15;0040;PBS_Server;Svr;tyrone-cluster;Scheduler was sent the command new
12/20/2013 23:17:54;0040;PBS_Server;Svr;tyrone-cluster;Scheduler was sent the command new
12/20/2013 23:18:23;0040;PBS_Server;Svr;tyrone-cluster;Scheduler was sent the command new
12/20/2013 23:18:54;0040;PBS_Server;Svr;tyrone-cluster;Scheduler was sent the command new
12/20/2013 23:19:28;0040;PBS_Server;Svr;tyrone-cluster;Scheduler was sent the command new
12/20/2013 23:19:33;0002;PBS_Server;Svr;PBS_Server;Torque Server Version = 3.0.5, loglevel = 0
12/20/2013 23:19:55;0040;PBS_Server;Svr;tyrone-cluster;Scheduler was sent the command new
12/20/2013 23:20:30;0040;PBS_Server;Svr;tyrone-cluster;Scheduler was sent the command new
12/20/2013 23:20:58;0040;PBS_Server;Svr;tyrone-cluster;Scheduler was sent the command new
12/20/2013 23:21:29;0040;PBS_Server;Svr;tyrone-cluster;Scheduler was sent the command new
12/20/2013 23:22:00;0040;PBS_Server;Svr;tyrone-cluster;Scheduler was sent the command new
12/20/2013 23:22:30;0040;PBS_Server;Svr;tyrone-cluster;Scheduler was sent the command new
12/20/2013 23:23:07;0040;PBS_Server;Svr;tyrone-cluster;Scheduler was sent the command new
12/20/2013 23:23:30;0040;PBS_Server;Svr;tyrone-cluster;Scheduler was sent the command new
12/20/2013 23:24:00;0040;PBS_Server;Svr;tyrone-cluster;Scheduler was sent the command new
12/20/2013 23:24:33;0002;PBS_Server;Svr;PBS_Server;Torque Server Version = 3.0.5, loglevel = 0
12/20/2013 23:24:33;0040;PBS_Server;Svr;tyrone-cluster;Scheduler was sent the command new
12/20/2013 23:25:00;0040;PBS_Server;Svr;tyrone-cluster;Scheduler was sent the command new
12/20/2013 23:25:30;0040;PBS_Server;Svr;tyrone-cluster;Scheduler was sent the command new
12/20/2013 23:26:07;0040;PBS_Server;Svr;tyrone-cluster;Scheduler was sent the command new
12/20/2013 23:26:30;0040;PBS_Server;Svr;tyrone-cluster;Scheduler was sent the command new
12/20/2013 23:27:00;0040;PBS_Server;Svr;tyrone-cluster;Scheduler was sent the command new
12/20/2013 23:27:39;0040;PBS_Server;Svr;tyrone-cluster;Scheduler was sent the command new
12/20/2013 23:28:08;0040;PBS_Server;Svr;tyrone-cluster;Scheduler was sent the command new
12/20/2013 23:28:39;0040;PBS_Server;Svr;tyrone-cluster;Scheduler was sent the command new
12/20/2013 23:29:13;0040;PBS_Server;Svr;tyrone-cluster;Scheduler was sent the command new
12/20/2013 23:29:33;0002;PBS_Server;Svr;PBS_Server;Torque Server Version = 3.0.5, loglevel = 0
12/20/2013 23:29:40;0040;PBS_Server;Svr;tyrone-cluster;Scheduler was sent the command new
12/20/2013 23:30:15;0040;PBS_Server;Svr;tyrone-cluster;Scheduler was sent the command new
12/20/2013 23:30:44;0040;PBS_Server;Svr;tyrone-cluster;Scheduler was sent the command new
12/20/2013 23:31:14;0040;PBS_Server;Svr;tyrone-cluster;Scheduler was sent the command new
12/20/2013 23:31:45;0040;PBS_Server;Svr;tyrone-cluster;Scheduler was sent the command new
12/20/2013 23:32:15;0040;PBS_Server;Svr;tyrone-cluster;Scheduler was sent the command new
12/20/2013 23:32:54;0040;PBS_Server;Svr;tyrone-cluster;Scheduler was sent the command new
12/20/2013 23:33:23;0040;PBS_Server;Svr;tyrone-cluster;Scheduler was sent the command new
12/20/2013 23:33:54;0040;PBS_Server;Svr;tyrone-cluster;Scheduler was sent the command new
12/20/2013 23:34:28;0040;PBS_Server;Svr;tyrone-cluster;Scheduler was sent the command new
12/20/2013 23:34:33;0002;PBS_Server;Svr;PBS_Server;Torque Server Version = 3.0.5, loglevel = 0
12/20/2013 23:34:55;0040;PBS_Server;Svr;tyrone-cluster;Scheduler was sent the command new
12/20/2013 23:35:30;0040;PBS_Server;Svr;tyrone-cluster;Scheduler was sent the command new
12/20/2013 23:35:59;0040;PBS_Server;Svr;tyrone-cluster;Scheduler was sent the command new
12/20/2013 23:36:29;0040;PBS_Server;Svr;tyrone-cluster;Scheduler was sent the command new
12/20/2013 23:37:00;0040;PBS_Server;Svr;tyrone-cluster;Scheduler was sent the command new
12/20/2013 23:37:30;0040;PBS_Server;Svr;tyrone-cluster;Scheduler was sent the command new
12/20/2013 23:38:09;0040;PBS_Server;Svr;tyrone-cluster;Scheduler was sent the command new
12/20/2013 23:38:38;0040;PBS_Server;Svr;tyrone-cluster;Scheduler was sent the command new
12/20/2013 23:39:09;0040;PBS_Server;Svr;tyrone-cluster;Scheduler was sent the command new
12/20/2013 23:39:33;0002;PBS_Server;Svr;PBS_Server;Torque Server Version = 3.0.5, loglevel = 0
12/20/2013 23:39:44;0040;PBS_Server;Svr;tyrone-cluster;Scheduler was sent the command new
12/20/2013 23:40:01;000d;PBS_Server;Job;33389.tyrone-cluster;Not sending email: User does not want mail of this type.
12/20/2013 23:40:01;0010;PBS_Server;Job;33389.tyrone-cluster;Exit_status=0 resources_used.cput=56:12:31 resources_used.mem=9566412kb resources_used.vmem=17824964kb resources_used.walltime=11:01:24
12/20/2013 23:40:01;0008;PBS_Server;Job;NULL;on_job_exit valid pjob: 0x26d7040 (substate=50)
12/20/2013 23:40:01;0008;PBS_Server;Job;NULL;on_job_exit valid pjob: 0x26d7040 (substate=51)
12/20/2013 23:40:01;0008;PBS_Server;Job;NULL;on_job_exit valid pjob: 0x26d7040 (substate=51)
12/20/2013 23:40:01;0008;PBS_Server;Job;NULL;on_job_exit valid pjob: 0x26d7040 (substate=53)
12/20/2013 23:40:01;0100;PBS_Server;Job;33389.tyrone-cluster;dequeuing from qp32, state COMPLETE
12/20/2013 23:40:01;0040;PBS_Server;Svr;tyrone-cluster;Scheduler was sent the command term
12/20/2013 23:40:01;0008;PBS_Server;Job;33377.tyrone-cluster;Job Modified at request of Scheduler@tyrone-cluster
12/20/2013 23:40:01;0008;PBS_Server;Job;33391.tyrone-cluster;Job Modified at request of Scheduler@tyrone-cluster
12/20/2013 23:40:01;0008;PBS_Server;Job;33391.tyrone-cluster;Job Run at request of Scheduler@tyrone-cluster
12/20/2013 23:40:01;0040;PBS_Server;Svr;tyrone-cluster;Scheduler was sent the command recyc
12/20/2013 23:40:01;000d;PBS_Server;Job;33391.tyrone-cluster;Not sending email: User does not want mail of this type.
12/20/2013 23:40:10;0040;PBS_Server;Svr;tyrone-cluster;Scheduler was sent the command new
12/20/2013 23:40:10;0008;PBS_Server;Job;33377.tyrone-cluster;Job Modified at request of Scheduler@tyrone-cluster
12/20/2013 23:40:45;0040;PBS_Server;Svr;tyrone-cluster;Scheduler was sent the command new
12/20/2013 23:41:14;0040;PBS_Server;Svr;tyrone-cluster;Scheduler was sent the command new
12/20/2013 23:41:44;0040;PBS_Server;Svr;tyrone-cluster;Scheduler was sent the command new
12/20/2013 23:42:15;0040;PBS_Server;Svr;tyrone-cluster;Scheduler was sent the command new
12/20/2013 23:42:45;0040;PBS_Server;Svr;tyrone-cluster;Scheduler was sent the command new
12/20/2013 23:43:24;0040;PBS_Server;Svr;tyrone-cluster;Scheduler was sent the command new
12/20/2013 23:43:55;0040;PBS_Server;Svr;tyrone-cluster;Scheduler was sent the command new
12/20/2013 23:44:30;0040;PBS_Server;Svr;tyrone-cluster;Scheduler was sent the command new
12/20/2013 23:44:33;0002;PBS_Server;Svr;PBS_Server;Torque Server Version = 3.0.5, loglevel = 0
12/20/2013 23:44:59;0040;PBS_Server;Svr;tyrone-cluster;Scheduler was sent the command new
12/20/2013 23:45:30;0040;PBS_Server;Svr;tyrone-cluster;Scheduler was sent the command new
12/20/2013 23:46:00;0040;PBS_Server;Svr;tyrone-cluster;Scheduler was sent the command new
12/20/2013 23:46:30;0040;PBS_Server;Svr;tyrone-cluster;Scheduler was sent the command new
12/20/2013 23:47:07;0040;PBS_Server;Svr;tyrone-cluster;Scheduler was sent the command new
12/20/2013 23:47:35;0040;PBS_Server;Svr;tyrone-cluster;Scheduler was sent the command new
12/20/2013 23:48:03;0040;PBS_Server;Svr;tyrone-cluster;Scheduler was sent the command new
12/20/2013 23:48:39;0040;PBS_Server;Svr;tyrone-cluster;Scheduler was sent the command new
12/20/2013 23:49:10;0040;PBS_Server;Svr;tyrone-cluster;Scheduler was sent the command new
12/20/2013 23:49:33;0002;PBS_Server;Svr;PBS_Server;Torque Server Version = 3.0.5, loglevel = 0
12/20/2013 23:49:45;0040;PBS_Server;Svr;tyrone-cluster;Scheduler was sent the command new
12/20/2013 23:50:14;0040;PBS_Server;Svr;tyrone-cluster;Scheduler was sent the command new
12/20/2013 23:50:44;0040;PBS_Server;Svr;tyrone-cluster;Scheduler was sent the command new
12/20/2013 23:51:15;0040;PBS_Server;Svr;tyrone-cluster;Scheduler was sent the command new
12/20/2013 23:51:45;0040;PBS_Server;Svr;tyrone-cluster;Scheduler was sent the command new
12/20/2013 23:52:24;0040;PBS_Server;Svr;tyrone-cluster;Scheduler was sent the command new
12/20/2013 23:52:55;0040;PBS_Server;Svr;tyrone-cluster;Scheduler was sent the command new
12/20/2013 23:53:30;0040;PBS_Server;Svr;tyrone-cluster;Scheduler was sent the command new
12/20/2013 23:54:00;0040;PBS_Server;Svr;tyrone-cluster;Scheduler was sent the command new
12/20/2013 23:54:33;0002;PBS_Server;Svr;PBS_Server;Torque Server Version = 3.0.5, loglevel = 0
12/20/2013 23:54:37;0040;PBS_Server;Svr;tyrone-cluster;Scheduler was sent the command new
12/20/2013 23:55:05;0040;PBS_Server;Svr;tyrone-cluster;Scheduler was sent the command new
12/20/2013 23:55:38;0040;PBS_Server;Svr;tyrone-cluster;Scheduler was sent the command new
12/20/2013 23:56:14;0040;PBS_Server;Svr;tyrone-cluster;Scheduler was sent the command new
12/20/2013 23:56:40;0040;PBS_Server;Svr;tyrone-cluster;Scheduler was sent the command new
12/20/2013 23:57:15;0040;PBS_Server;Svr;tyrone-cluster;Scheduler was sent the command new
12/20/2013 23:57:43;0040;PBS_Server;Svr;tyrone-cluster;Scheduler was sent the command new
12/20/2013 23:58:14;0040;PBS_Server;Svr;tyrone-cluster;Scheduler was sent the command new
12/20/2013 23:58:45;0040;PBS_Server;Svr;tyrone-cluster;Scheduler was sent the command new
12/20/2013 23:59:15;0040;PBS_Server;Svr;tyrone-cluster;Scheduler was sent the command new
12/20/2013 23:59:33;0002;PBS_Server;Svr;PBS_Server;Torque Server Version = 3.0.5, loglevel = 0
12/20/2013 23:59:53;0040;PBS_Server;Svr;tyrone-cluster;Scheduler was sent the command new
12/21/2013 00:00:25;0002;PBS_Server;Svr;Log;Log closed
