11/02/2013 00:00:02;0002;PBS_Server;Svr;Log;Log opened
11/02/2013 00:00:02;0040;PBS_Server;Svr;tyrone-cluster;Scheduler was sent the command new
11/02/2013 00:00:30;0040;PBS_Server;Svr;tyrone-cluster;Scheduler was sent the command new
11/02/2013 00:01:03;0040;PBS_Server;Svr;tyrone-cluster;Scheduler was sent the command new
11/02/2013 00:01:38;0040;PBS_Server;Svr;tyrone-cluster;Scheduler was sent the command new
11/02/2013 00:02:05;0040;PBS_Server;Svr;tyrone-cluster;Scheduler was sent the command new
11/02/2013 00:02:34;0040;PBS_Server;Svr;tyrone-cluster;Scheduler was sent the command new
11/02/2013 00:02:41;0002;PBS_Server;Svr;PBS_Server;Torque Server Version = 3.0.5, loglevel = 0
11/02/2013 00:03:08;0040;PBS_Server;Svr;tyrone-cluster;Scheduler was sent the command new
11/02/2013 00:03:38;0040;PBS_Server;Svr;tyrone-cluster;Scheduler was sent the command new
11/02/2013 00:04:11;0040;PBS_Server;Svr;tyrone-cluster;Scheduler was sent the command new
11/02/2013 00:04:38;0040;PBS_Server;Svr;tyrone-cluster;Scheduler was sent the command new
11/02/2013 00:05:09;0040;PBS_Server;Svr;tyrone-cluster;Scheduler was sent the command new
11/02/2013 00:05:40;0040;PBS_Server;Svr;tyrone-cluster;Scheduler was sent the command new
11/02/2013 00:06:12;0040;PBS_Server;Svr;tyrone-cluster;Scheduler was sent the command new
11/02/2013 00:06:41;0040;PBS_Server;Svr;tyrone-cluster;Scheduler was sent the command new
11/02/2013 00:07:11;0040;PBS_Server;Svr;tyrone-cluster;Scheduler was sent the command new
11/02/2013 00:07:41;0002;PBS_Server;Svr;PBS_Server;Torque Server Version = 3.0.5, loglevel = 0
11/02/2013 00:07:42;0040;PBS_Server;Svr;tyrone-cluster;Scheduler was sent the command new
11/02/2013 00:08:11;0040;PBS_Server;Svr;tyrone-cluster;Scheduler was sent the command new
11/02/2013 00:08:41;0040;PBS_Server;Svr;tyrone-cluster;Scheduler was sent the command new
11/02/2013 00:09:12;0040;PBS_Server;Svr;tyrone-cluster;Scheduler was sent the command new
11/02/2013 00:09:41;0040;PBS_Server;Svr;tyrone-cluster;Scheduler was sent the command new
11/02/2013 00:10:14;0040;PBS_Server;Svr;tyrone-cluster;Scheduler was sent the command new
11/02/2013 00:10:42;0040;PBS_Server;Svr;tyrone-cluster;Scheduler was sent the command new
11/02/2013 00:11:11;0040;PBS_Server;Svr;tyrone-cluster;Scheduler was sent the command new
11/02/2013 00:11:41;0040;PBS_Server;Svr;tyrone-cluster;Scheduler was sent the command new
11/02/2013 00:12:12;0040;PBS_Server;Svr;tyrone-cluster;Scheduler was sent the command new
11/02/2013 00:12:41;0002;PBS_Server;Svr;PBS_Server;Torque Server Version = 3.0.5, loglevel = 0
11/02/2013 00:12:41;0040;PBS_Server;Svr;tyrone-cluster;Scheduler was sent the command new
11/02/2013 00:13:13;0040;PBS_Server;Svr;tyrone-cluster;Scheduler was sent the command new
11/02/2013 00:13:42;0040;PBS_Server;Svr;tyrone-cluster;Scheduler was sent the command new
11/02/2013 00:14:11;0040;PBS_Server;Svr;tyrone-cluster;Scheduler was sent the command new
11/02/2013 00:14:45;0040;PBS_Server;Svr;tyrone-cluster;Scheduler was sent the command new
11/02/2013 00:15:15;0040;PBS_Server;Svr;tyrone-cluster;Scheduler was sent the command new
11/02/2013 00:15:47;0040;PBS_Server;Svr;tyrone-cluster;Scheduler was sent the command new
11/02/2013 00:16:15;0040;PBS_Server;Svr;tyrone-cluster;Scheduler was sent the command new
11/02/2013 00:16:48;0040;PBS_Server;Svr;tyrone-cluster;Scheduler was sent the command new
11/02/2013 00:17:22;0040;PBS_Server;Svr;tyrone-cluster;Scheduler was sent the command new
11/02/2013 00:17:41;0002;PBS_Server;Svr;PBS_Server;Torque Server Version = 3.0.5, loglevel = 0
11/02/2013 00:17:50;0040;PBS_Server;Svr;tyrone-cluster;Scheduler was sent the command new
11/02/2013 00:18:18;0040;PBS_Server;Svr;tyrone-cluster;Scheduler was sent the command new
11/02/2013 00:18:53;0040;PBS_Server;Svr;tyrone-cluster;Scheduler was sent the command new
11/02/2013 00:19:24;0040;PBS_Server;Svr;tyrone-cluster;Scheduler was sent the command new
11/02/2013 00:19:56;0040;PBS_Server;Svr;tyrone-cluster;Scheduler was sent the command new
11/02/2013 00:20:27;0040;PBS_Server;Svr;tyrone-cluster;Scheduler was sent the command new
11/02/2013 00:20:56;0040;PBS_Server;Svr;tyrone-cluster;Scheduler was sent the command new
11/02/2013 00:21:26;0040;PBS_Server;Svr;tyrone-cluster;Scheduler was sent the command new
11/02/2013 00:21:57;0040;PBS_Server;Svr;tyrone-cluster;Scheduler was sent the command new
11/02/2013 00:22:26;0040;PBS_Server;Svr;tyrone-cluster;Scheduler was sent the command new
11/02/2013 00:22:41;0002;PBS_Server;Svr;PBS_Server;Torque Server Version = 3.0.5, loglevel = 0
11/02/2013 00:22:58;0040;PBS_Server;Svr;tyrone-cluster;Scheduler was sent the command new
11/02/2013 00:23:27;0040;PBS_Server;Svr;tyrone-cluster;Scheduler was sent the command new
11/02/2013 00:23:56;0040;PBS_Server;Svr;tyrone-cluster;Scheduler was sent the command new
11/02/2013 00:24:30;0040;PBS_Server;Svr;tyrone-cluster;Scheduler was sent the command new
11/02/2013 00:24:59;0040;PBS_Server;Svr;tyrone-cluster;Scheduler was sent the command new
11/02/2013 00:25:32;0040;PBS_Server;Svr;tyrone-cluster;Scheduler was sent the command new
11/02/2013 00:26:00;0040;PBS_Server;Svr;tyrone-cluster;Scheduler was sent the command new
11/02/2013 00:26:33;0040;PBS_Server;Svr;tyrone-cluster;Scheduler was sent the command new
11/02/2013 00:27:07;0040;PBS_Server;Svr;tyrone-cluster;Scheduler was sent the command new
11/02/2013 00:27:35;0040;PBS_Server;Svr;tyrone-cluster;Scheduler was sent the command new
11/02/2013 00:27:41;0002;PBS_Server;Svr;PBS_Server;Torque Server Version = 3.0.5, loglevel = 0
11/02/2013 00:28:03;0040;PBS_Server;Svr;tyrone-cluster;Scheduler was sent the command new
11/02/2013 00:28:38;0040;PBS_Server;Svr;tyrone-cluster;Scheduler was sent the command new
11/02/2013 00:29:09;0040;PBS_Server;Svr;tyrone-cluster;Scheduler was sent the command new
11/02/2013 00:29:40;0040;PBS_Server;Svr;tyrone-cluster;Scheduler was sent the command new
11/02/2013 00:30:12;0040;PBS_Server;Svr;tyrone-cluster;Scheduler was sent the command new
11/02/2013 00:30:41;0040;PBS_Server;Svr;tyrone-cluster;Scheduler was sent the command new
11/02/2013 00:31:11;0040;PBS_Server;Svr;tyrone-cluster;Scheduler was sent the command new
11/02/2013 00:31:42;0040;PBS_Server;Svr;tyrone-cluster;Scheduler was sent the command new
11/02/2013 00:32:11;0040;PBS_Server;Svr;tyrone-cluster;Scheduler was sent the command new
11/02/2013 00:32:41;0002;PBS_Server;Svr;PBS_Server;Torque Server Version = 3.0.5, loglevel = 0
11/02/2013 00:32:41;0040;PBS_Server;Svr;tyrone-cluster;Scheduler was sent the command new
11/02/2013 00:33:12;0040;PBS_Server;Svr;tyrone-cluster;Scheduler was sent the command new
11/02/2013 00:33:41;0040;PBS_Server;Svr;tyrone-cluster;Scheduler was sent the command new
11/02/2013 00:34:14;0040;PBS_Server;Svr;tyrone-cluster;Scheduler was sent the command new
11/02/2013 00:34:42;0040;PBS_Server;Svr;tyrone-cluster;Scheduler was sent the command new
11/02/2013 00:35:11;0040;PBS_Server;Svr;tyrone-cluster;Scheduler was sent the command new
11/02/2013 00:35:43;0040;PBS_Server;Svr;tyrone-cluster;Scheduler was sent the command new
11/02/2013 00:36:12;0040;PBS_Server;Svr;tyrone-cluster;Scheduler was sent the command new
11/02/2013 00:36:42;0040;PBS_Server;Svr;tyrone-cluster;Scheduler was sent the command new
11/02/2013 00:37:15;0040;PBS_Server;Svr;tyrone-cluster;Scheduler was sent the command new
11/02/2013 00:37:41;0002;PBS_Server;Svr;PBS_Server;Torque Server Version = 3.0.5, loglevel = 0
11/02/2013 00:37:44;0040;PBS_Server;Svr;tyrone-cluster;Scheduler was sent the command new
11/02/2013 00:38:17;0040;PBS_Server;Svr;tyrone-cluster;Scheduler was sent the command new
11/02/2013 00:38:44;0040;PBS_Server;Svr;tyrone-cluster;Scheduler was sent the command new
11/02/2013 00:39:14;0040;PBS_Server;Svr;tyrone-cluster;Scheduler was sent the command new
11/02/2013 00:39:52;0040;PBS_Server;Svr;tyrone-cluster;Scheduler was sent the command new
11/02/2013 00:40:16;0040;PBS_Server;Svr;tyrone-cluster;Scheduler was sent the command new
11/02/2013 00:40:47;0040;PBS_Server;Svr;tyrone-cluster;Scheduler was sent the command new
11/02/2013 00:41:23;0040;PBS_Server;Svr;tyrone-cluster;Scheduler was sent the command new
11/02/2013 00:41:50;0040;PBS_Server;Svr;tyrone-cluster;Scheduler was sent the command new
11/02/2013 00:42:18;0040;PBS_Server;Svr;tyrone-cluster;Scheduler was sent the command new
11/02/2013 00:42:41;0002;PBS_Server;Svr;PBS_Server;Torque Server Version = 3.0.5, loglevel = 0
11/02/2013 00:42:53;0040;PBS_Server;Svr;tyrone-cluster;Scheduler was sent the command new
11/02/2013 00:43:24;0040;PBS_Server;Svr;tyrone-cluster;Scheduler was sent the command new
11/02/2013 00:43:56;0040;PBS_Server;Svr;tyrone-cluster;Scheduler was sent the command new
11/02/2013 00:44:27;0040;PBS_Server;Svr;tyrone-cluster;Scheduler was sent the command new
11/02/2013 00:44:56;0040;PBS_Server;Svr;tyrone-cluster;Scheduler was sent the command new
11/02/2013 00:45:25;0040;PBS_Server;Svr;tyrone-cluster;Scheduler was sent the command new
11/02/2013 00:45:57;0040;PBS_Server;Svr;tyrone-cluster;Scheduler was sent the command new
11/02/2013 00:46:26;0040;PBS_Server;Svr;tyrone-cluster;Scheduler was sent the command new
11/02/2013 00:46:55;0040;PBS_Server;Svr;tyrone-cluster;Scheduler was sent the command new
11/02/2013 00:47:27;0040;PBS_Server;Svr;tyrone-cluster;Scheduler was sent the command new
11/02/2013 00:47:41;0002;PBS_Server;Svr;PBS_Server;Torque Server Version = 3.0.5, loglevel = 0
11/02/2013 00:47:56;0040;PBS_Server;Svr;tyrone-cluster;Scheduler was sent the command new
11/02/2013 00:48:26;0040;PBS_Server;Svr;tyrone-cluster;Scheduler was sent the command new
11/02/2013 00:48:57;0040;PBS_Server;Svr;tyrone-cluster;Scheduler was sent the command new
11/02/2013 00:49:26;0040;PBS_Server;Svr;tyrone-cluster;Scheduler was sent the command new
11/02/2013 00:49:58;0040;PBS_Server;Svr;tyrone-cluster;Scheduler was sent the command new
11/02/2013 00:50:27;0040;PBS_Server;Svr;tyrone-cluster;Scheduler was sent the command new
11/02/2013 00:50:57;0040;PBS_Server;Svr;tyrone-cluster;Scheduler was sent the command new
11/02/2013 00:51:30;0040;PBS_Server;Svr;tyrone-cluster;Scheduler was sent the command new
11/02/2013 00:51:59;0040;PBS_Server;Svr;tyrone-cluster;Scheduler was sent the command new
11/02/2013 00:52:37;0040;PBS_Server;Svr;tyrone-cluster;Scheduler was sent the command new
11/02/2013 00:52:41;0002;PBS_Server;Svr;PBS_Server;Torque Server Version = 3.0.5, loglevel = 0
11/02/2013 00:53:01;0040;PBS_Server;Svr;tyrone-cluster;Scheduler was sent the command new
11/02/2013 00:53:32;0040;PBS_Server;Svr;tyrone-cluster;Scheduler was sent the command new
11/02/2013 00:54:08;0040;PBS_Server;Svr;tyrone-cluster;Scheduler was sent the command new
11/02/2013 00:54:35;0040;PBS_Server;Svr;tyrone-cluster;Scheduler was sent the command new
11/02/2013 00:55:03;0040;PBS_Server;Svr;tyrone-cluster;Scheduler was sent the command new
11/02/2013 00:55:38;0040;PBS_Server;Svr;tyrone-cluster;Scheduler was sent the command new
11/02/2013 00:56:09;0040;PBS_Server;Svr;tyrone-cluster;Scheduler was sent the command new
11/02/2013 00:56:41;0040;PBS_Server;Svr;tyrone-cluster;Scheduler was sent the command new
11/02/2013 00:57:12;0040;PBS_Server;Svr;tyrone-cluster;Scheduler was sent the command new
11/02/2013 00:57:41;0002;PBS_Server;Svr;PBS_Server;Torque Server Version = 3.0.5, loglevel = 0
11/02/2013 00:57:41;0040;PBS_Server;Svr;tyrone-cluster;Scheduler was sent the command new
11/02/2013 00:58:11;0040;PBS_Server;Svr;tyrone-cluster;Scheduler was sent the command new
11/02/2013 00:58:42;0040;PBS_Server;Svr;tyrone-cluster;Scheduler was sent the command new
11/02/2013 00:59:11;0040;PBS_Server;Svr;tyrone-cluster;Scheduler was sent the command new
11/02/2013 00:59:40;0040;PBS_Server;Svr;tyrone-cluster;Scheduler was sent the command new
11/02/2013 01:00:12;0040;PBS_Server;Svr;tyrone-cluster;Scheduler was sent the command new
11/02/2013 01:00:41;0040;PBS_Server;Svr;tyrone-cluster;Scheduler was sent the command new
11/02/2013 01:01:11;0040;PBS_Server;Svr;tyrone-cluster;Scheduler was sent the command new
11/02/2013 01:01:42;0040;PBS_Server;Svr;tyrone-cluster;Scheduler was sent the command new
11/02/2013 01:02:11;0040;PBS_Server;Svr;tyrone-cluster;Scheduler was sent the command new
11/02/2013 01:02:41;0002;PBS_Server;Svr;PBS_Server;Torque Server Version = 3.0.5, loglevel = 0
11/02/2013 01:02:43;0040;PBS_Server;Svr;tyrone-cluster;Scheduler was sent the command new
11/02/2013 01:03:02;0100;PBS_Server;Job;31379.tyrone-cluster;enqueuing into batch, state 1 hop 1
11/02/2013 01:03:02;0002;PBS_Server;Svr;Act;Account file /var/spool/torque/server_priv/accounting/20131102 opened
11/02/2013 01:03:02;0100;PBS_Server;Job;31379.tyrone-cluster;dequeuing from batch, state QUEUED
11/02/2013 01:03:02;0100;PBS_Server;Job;31379.tyrone-cluster;enqueuing into qp256, state 1 hop 1
11/02/2013 01:03:02;0008;PBS_Server;Job;31379.tyrone-cluster;Job Queued at request of secbadar@tyrone-cluster, owner = secbadar@tyrone-cluster, job name = Unif01Sch, queue = qp256
11/02/2013 01:03:02;0040;PBS_Server;Svr;tyrone-cluster;Scheduler was sent the command new
11/02/2013 01:03:02;0008;PBS_Server;Job;31379.tyrone-cluster;Job Modified at request of Scheduler@tyrone-cluster
11/02/2013 01:03:02;0008;PBS_Server;Job;31379.tyrone-cluster;Job Run at request of Scheduler@tyrone-cluster
11/02/2013 01:03:02;0040;PBS_Server;Svr;tyrone-cluster;Scheduler was sent the command recyc
11/02/2013 01:03:12;0040;PBS_Server;Svr;tyrone-cluster;Scheduler was sent the command new
11/02/2013 01:03:14;000d;PBS_Server;Job;31379.tyrone-cluster;Not sending email: User does not want mail of this type.
11/02/2013 01:03:14;0010;PBS_Server;Job;31379.tyrone-cluster;Exit_status=255 resources_used.cput=00:00:00 resources_used.mem=800kb resources_used.vmem=13624kb resources_used.walltime=00:00:12
11/02/2013 01:03:14;0008;PBS_Server;Job;NULL;on_job_exit valid pjob: 0x31714a0 (substate=50)
11/02/2013 01:03:14;0008;PBS_Server;Job;NULL;on_job_exit valid pjob: 0x31714a0 (substate=51)
11/02/2013 01:03:14;0008;PBS_Server;Job;NULL;on_job_exit valid pjob: 0x31714a0 (substate=51)
11/02/2013 01:03:14;0008;PBS_Server;Job;NULL;on_job_exit valid pjob: 0x31714a0 (substate=53)
11/02/2013 01:03:14;0100;PBS_Server;Job;31379.tyrone-cluster;dequeuing from qp256, state COMPLETE
11/02/2013 01:03:14;0040;PBS_Server;Svr;tyrone-cluster;Scheduler was sent the command term
11/02/2013 01:03:42;0040;PBS_Server;Svr;tyrone-cluster;Scheduler was sent the command new
11/02/2013 01:04:15;0040;PBS_Server;Svr;tyrone-cluster;Scheduler was sent the command new
11/02/2013 01:04:48;0040;PBS_Server;Svr;tyrone-cluster;Scheduler was sent the command new
11/02/2013 01:05:22;0040;PBS_Server;Svr;tyrone-cluster;Scheduler was sent the command new
11/02/2013 01:05:46;0040;PBS_Server;Svr;tyrone-cluster;Scheduler was sent the command new
11/02/2013 01:05:55;0100;PBS_Server;Job;31380.tyrone-cluster;enqueuing into batch, state 1 hop 1
11/02/2013 01:05:55;0100;PBS_Server;Job;31380.tyrone-cluster;dequeuing from batch, state QUEUED
11/02/2013 01:05:55;0100;PBS_Server;Job;31380.tyrone-cluster;enqueuing into qp256, state 1 hop 1
11/02/2013 01:05:55;0008;PBS_Server;Job;31380.tyrone-cluster;Job Queued at request of secbadar@tyrone-cluster, owner = secbadar@tyrone-cluster, job name = Unif01Sch, queue = qp256
11/02/2013 01:05:55;0040;PBS_Server;Svr;tyrone-cluster;Scheduler was sent the command new
11/02/2013 01:05:55;0008;PBS_Server;Job;31380.tyrone-cluster;Job Modified at request of Scheduler@tyrone-cluster
11/02/2013 01:05:55;0008;PBS_Server;Job;31380.tyrone-cluster;Job Run at request of Scheduler@tyrone-cluster
11/02/2013 01:05:56;0040;PBS_Server;Svr;tyrone-cluster;Scheduler was sent the command recyc
11/02/2013 01:06:18;0040;PBS_Server;Svr;tyrone-cluster;Scheduler was sent the command new
11/02/2013 01:06:53;0040;PBS_Server;Svr;tyrone-cluster;Scheduler was sent the command new
11/02/2013 01:06:53;000d;PBS_Server;Job;31380.tyrone-cluster;Not sending email: User does not want mail of this type.
11/02/2013 01:07:23;0040;PBS_Server;Svr;tyrone-cluster;Scheduler was sent the command new
11/02/2013 01:07:41;0002;PBS_Server;Svr;PBS_Server;Torque Server Version = 3.0.5, loglevel = 0
11/02/2013 01:07:55;0040;PBS_Server;Svr;tyrone-cluster;Scheduler was sent the command new
11/02/2013 01:08:27;0040;PBS_Server;Svr;tyrone-cluster;Scheduler was sent the command new
11/02/2013 01:08:56;0040;PBS_Server;Svr;tyrone-cluster;Scheduler was sent the command new
11/02/2013 01:09:26;0040;PBS_Server;Svr;tyrone-cluster;Scheduler was sent the command new
11/02/2013 01:09:55;0040;PBS_Server;Svr;tyrone-cluster;Scheduler was sent the command new
11/02/2013 01:10:26;0040;PBS_Server;Svr;tyrone-cluster;Scheduler was sent the command new
11/02/2013 01:10:56;0040;PBS_Server;Svr;tyrone-cluster;Scheduler was sent the command new
11/02/2013 01:11:27;0040;PBS_Server;Svr;tyrone-cluster;Scheduler was sent the command new
11/02/2013 01:11:56;0040;PBS_Server;Svr;tyrone-cluster;Scheduler was sent the command new
11/02/2013 01:12:26;0040;PBS_Server;Svr;tyrone-cluster;Scheduler was sent the command new
11/02/2013 01:12:41;0002;PBS_Server;Svr;PBS_Server;Torque Server Version = 3.0.5, loglevel = 0
11/02/2013 01:12:57;0040;PBS_Server;Svr;tyrone-cluster;Scheduler was sent the command new
11/02/2013 01:13:26;0040;PBS_Server;Svr;tyrone-cluster;Scheduler was sent the command new
11/02/2013 01:13:58;0040;PBS_Server;Svr;tyrone-cluster;Scheduler was sent the command new
11/02/2013 01:14:27;0040;PBS_Server;Svr;tyrone-cluster;Scheduler was sent the command new
11/02/2013 01:14:57;0040;PBS_Server;Svr;tyrone-cluster;Scheduler was sent the command new
11/02/2013 01:15:30;0040;PBS_Server;Svr;tyrone-cluster;Scheduler was sent the command new
11/02/2013 01:16:00;0040;PBS_Server;Svr;tyrone-cluster;Scheduler was sent the command new
11/02/2013 01:16:37;0040;PBS_Server;Svr;tyrone-cluster;Scheduler was sent the command new
11/02/2013 01:17:01;0040;PBS_Server;Svr;tyrone-cluster;Scheduler was sent the command new
11/02/2013 01:17:09;0008;PBS_Server;Job;31380.tyrone-cluster;Job deleted at request of secbadar@tyrone-cluster
11/02/2013 01:17:09;0008;PBS_Server;Job;31380.tyrone-cluster;Job sent signal SIGTERM on delete
11/02/2013 01:17:09;000d;PBS_Server;Job;31380.tyrone-cluster;Not sending email: User does not want mail of this type.
11/02/2013 01:17:09;0010;PBS_Server;Job;31380.tyrone-cluster;Exit_status=143 resources_used.cput=02:16:25 resources_used.mem=1568644kb resources_used.vmem=36920968kb resources_used.walltime=00:11:13
11/02/2013 01:17:09;0008;PBS_Server;Job;NULL;on_job_exit valid pjob: 0x31714a0 (substate=50)
11/02/2013 01:17:09;0008;PBS_Server;Job;NULL;on_job_exit valid pjob: 0x31714a0 (substate=51)
11/02/2013 01:17:09;0008;PBS_Server;Job;NULL;on_job_exit valid pjob: 0x31714a0 (substate=51)
11/02/2013 01:17:09;0008;PBS_Server;Job;NULL;on_job_exit valid pjob: 0x31714a0 (substate=53)
11/02/2013 01:17:09;0100;PBS_Server;Job;31380.tyrone-cluster;dequeuing from qp256, state COMPLETE
11/02/2013 01:17:09;0040;PBS_Server;Svr;tyrone-cluster;Scheduler was sent the command term
11/02/2013 01:17:12;0100;PBS_Server;Job;31381.tyrone-cluster;enqueuing into batch, state 1 hop 1
11/02/2013 01:17:12;0100;PBS_Server;Job;31381.tyrone-cluster;dequeuing from batch, state QUEUED
11/02/2013 01:17:12;0100;PBS_Server;Job;31381.tyrone-cluster;enqueuing into qp256, state 1 hop 1
11/02/2013 01:17:12;0008;PBS_Server;Job;31381.tyrone-cluster;Job Queued at request of secbadar@tyrone-cluster, owner = secbadar@tyrone-cluster, job name = Unif01Sch, queue = qp256
11/02/2013 01:17:12;0040;PBS_Server;Svr;tyrone-cluster;Scheduler was sent the command new
11/02/2013 01:17:12;0008;PBS_Server;Job;31381.tyrone-cluster;Job Modified at request of Scheduler@tyrone-cluster
11/02/2013 01:17:12;0008;PBS_Server;Job;31381.tyrone-cluster;Job Run at request of Scheduler@tyrone-cluster
11/02/2013 01:17:12;0040;PBS_Server;Svr;tyrone-cluster;Scheduler was sent the command recyc
11/02/2013 01:17:33;0040;PBS_Server;Svr;tyrone-cluster;Scheduler was sent the command new
11/02/2013 01:17:41;0002;PBS_Server;Svr;PBS_Server;Torque Server Version = 3.0.5, loglevel = 0
11/02/2013 01:18:08;0040;PBS_Server;Svr;tyrone-cluster;Scheduler was sent the command new
11/02/2013 01:18:10;000d;PBS_Server;Job;31381.tyrone-cluster;Not sending email: User does not want mail of this type.
11/02/2013 01:18:37;0040;PBS_Server;Svr;tyrone-cluster;Scheduler was sent the command new
11/02/2013 01:19:11;0040;PBS_Server;Svr;tyrone-cluster;Scheduler was sent the command new
11/02/2013 01:19:40;0040;PBS_Server;Svr;tyrone-cluster;Scheduler was sent the command new
11/02/2013 01:20:11;0040;PBS_Server;Svr;tyrone-cluster;Scheduler was sent the command new
11/02/2013 01:20:40;0040;PBS_Server;Svr;tyrone-cluster;Scheduler was sent the command new
11/02/2013 01:21:10;0040;PBS_Server;Svr;tyrone-cluster;Scheduler was sent the command new
11/02/2013 01:21:41;0040;PBS_Server;Svr;tyrone-cluster;Scheduler was sent the command new
11/02/2013 01:22:11;0040;PBS_Server;Svr;tyrone-cluster;Scheduler was sent the command new
11/02/2013 01:22:40;0040;PBS_Server;Svr;tyrone-cluster;Scheduler was sent the command new
11/02/2013 01:22:41;0002;PBS_Server;Svr;PBS_Server;Torque Server Version = 3.0.5, loglevel = 0
11/02/2013 01:23:11;0040;PBS_Server;Svr;tyrone-cluster;Scheduler was sent the command new
11/02/2013 01:23:41;0040;PBS_Server;Svr;tyrone-cluster;Scheduler was sent the command new
11/02/2013 01:24:10;0040;PBS_Server;Svr;tyrone-cluster;Scheduler was sent the command new
11/02/2013 01:24:41;0040;PBS_Server;Svr;tyrone-cluster;Scheduler was sent the command new
11/02/2013 01:25:10;0040;PBS_Server;Svr;tyrone-cluster;Scheduler was sent the command new
11/02/2013 01:25:40;0040;PBS_Server;Svr;tyrone-cluster;Scheduler was sent the command new
11/02/2013 01:26:11;0040;PBS_Server;Svr;tyrone-cluster;Scheduler was sent the command new
11/02/2013 01:26:41;0040;PBS_Server;Svr;tyrone-cluster;Scheduler was sent the command new
11/02/2013 01:27:10;0040;PBS_Server;Svr;tyrone-cluster;Scheduler was sent the command new
11/02/2013 01:27:41;0002;PBS_Server;Svr;PBS_Server;Torque Server Version = 3.0.5, loglevel = 0
11/02/2013 01:27:41;0040;PBS_Server;Svr;tyrone-cluster;Scheduler was sent the command new
11/02/2013 01:28:11;0040;PBS_Server;Svr;tyrone-cluster;Scheduler was sent the command new
11/02/2013 01:28:40;0040;PBS_Server;Svr;tyrone-cluster;Scheduler was sent the command new
11/02/2013 01:29:10;0040;PBS_Server;Svr;tyrone-cluster;Scheduler was sent the command new
11/02/2013 01:29:41;0040;PBS_Server;Svr;tyrone-cluster;Scheduler was sent the command new
11/02/2013 01:30:06;000d;PBS_Server;Job;31381.tyrone-cluster;Not sending email: User does not want mail of this type.
11/02/2013 01:30:06;0010;PBS_Server;Job;31381.tyrone-cluster;Exit_status=0 resources_used.cput=02:37:16 resources_used.mem=1600188kb resources_used.vmem=36957548kb resources_used.walltime=00:12:54
11/02/2013 01:30:06;0008;PBS_Server;Job;NULL;on_job_exit valid pjob: 0x31714a0 (substate=50)
11/02/2013 01:30:06;0008;PBS_Server;Job;NULL;on_job_exit valid pjob: 0x31714a0 (substate=51)
11/02/2013 01:30:06;0008;PBS_Server;Job;NULL;on_job_exit valid pjob: 0x31714a0 (substate=51)
11/02/2013 01:30:06;0008;PBS_Server;Job;NULL;on_job_exit valid pjob: 0x31714a0 (substate=53)
11/02/2013 01:30:06;0100;PBS_Server;Job;31381.tyrone-cluster;dequeuing from qp256, state COMPLETE
11/02/2013 01:30:06;0040;PBS_Server;Svr;tyrone-cluster;Scheduler was sent the command term
11/02/2013 01:30:12;0040;PBS_Server;Svr;tyrone-cluster;Scheduler was sent the command new
11/02/2013 01:30:41;0040;PBS_Server;Svr;tyrone-cluster;Scheduler was sent the command new
11/02/2013 01:31:10;0040;PBS_Server;Svr;tyrone-cluster;Scheduler was sent the command new
11/02/2013 01:31:42;0040;PBS_Server;Svr;tyrone-cluster;Scheduler was sent the command new
11/02/2013 01:32:11;0040;PBS_Server;Svr;tyrone-cluster;Scheduler was sent the command new
11/02/2013 01:32:41;0002;PBS_Server;Svr;PBS_Server;Torque Server Version = 3.0.5, loglevel = 0
11/02/2013 01:32:41;0040;PBS_Server;Svr;tyrone-cluster;Scheduler was sent the command new
11/02/2013 01:33:12;0040;PBS_Server;Svr;tyrone-cluster;Scheduler was sent the command new
11/02/2013 01:33:41;0040;PBS_Server;Svr;tyrone-cluster;Scheduler was sent the command new
11/02/2013 01:34:13;0040;PBS_Server;Svr;tyrone-cluster;Scheduler was sent the command new
11/02/2013 01:34:42;0040;PBS_Server;Svr;tyrone-cluster;Scheduler was sent the command new
11/02/2013 01:35:11;0040;PBS_Server;Svr;tyrone-cluster;Scheduler was sent the command new
11/02/2013 01:35:41;0040;PBS_Server;Svr;tyrone-cluster;Scheduler was sent the command new
11/02/2013 01:36:12;0040;PBS_Server;Svr;tyrone-cluster;Scheduler was sent the command new
11/02/2013 01:36:41;0040;PBS_Server;Svr;tyrone-cluster;Scheduler was sent the command new
11/02/2013 01:37:11;0040;PBS_Server;Svr;tyrone-cluster;Scheduler was sent the command new
11/02/2013 01:37:41;0002;PBS_Server;Svr;PBS_Server;Torque Server Version = 3.0.5, loglevel = 0
11/02/2013 01:37:41;0040;PBS_Server;Svr;tyrone-cluster;Scheduler was sent the command new
11/02/2013 01:38:11;0040;PBS_Server;Svr;tyrone-cluster;Scheduler was sent the command new
11/02/2013 01:38:41;0040;PBS_Server;Svr;tyrone-cluster;Scheduler was sent the command new
11/02/2013 01:39:12;0040;PBS_Server;Svr;tyrone-cluster;Scheduler was sent the command new
11/02/2013 01:39:41;0040;PBS_Server;Svr;tyrone-cluster;Scheduler was sent the command new
11/02/2013 01:40:11;0040;PBS_Server;Svr;tyrone-cluster;Scheduler was sent the command new
11/02/2013 01:40:42;0040;PBS_Server;Svr;tyrone-cluster;Scheduler was sent the command new
11/02/2013 01:41:11;0040;PBS_Server;Svr;tyrone-cluster;Scheduler was sent the command new
11/02/2013 01:41:43;0040;PBS_Server;Svr;tyrone-cluster;Scheduler was sent the command new
11/02/2013 01:42:12;0040;PBS_Server;Svr;tyrone-cluster;Scheduler was sent the command new
11/02/2013 01:42:41;0002;PBS_Server;Svr;PBS_Server;Torque Server Version = 3.0.5, loglevel = 0
11/02/2013 01:42:42;0040;PBS_Server;Svr;tyrone-cluster;Scheduler was sent the command new
11/02/2013 01:43:15;0040;PBS_Server;Svr;tyrone-cluster;Scheduler was sent the command new
11/02/2013 01:43:45;0040;PBS_Server;Svr;tyrone-cluster;Scheduler was sent the command new
11/02/2013 01:44:22;0040;PBS_Server;Svr;tyrone-cluster;Scheduler was sent the command new
11/02/2013 01:44:46;0040;PBS_Server;Svr;tyrone-cluster;Scheduler was sent the command new
11/02/2013 01:45:18;0040;PBS_Server;Svr;tyrone-cluster;Scheduler was sent the command new
11/02/2013 01:45:53;0040;PBS_Server;Svr;tyrone-cluster;Scheduler was sent the command new
11/02/2013 01:46:22;0040;PBS_Server;Svr;tyrone-cluster;Scheduler was sent the command new
11/02/2013 01:46:55;0040;PBS_Server;Svr;tyrone-cluster;Scheduler was sent the command new
11/02/2013 01:47:27;0040;PBS_Server;Svr;tyrone-cluster;Scheduler was sent the command new
11/02/2013 01:47:41;0002;PBS_Server;Svr;PBS_Server;Torque Server Version = 3.0.5, loglevel = 0
11/02/2013 01:47:56;0040;PBS_Server;Svr;tyrone-cluster;Scheduler was sent the command new
11/02/2013 01:48:26;0040;PBS_Server;Svr;tyrone-cluster;Scheduler was sent the command new
11/02/2013 01:48:57;0040;PBS_Server;Svr;tyrone-cluster;Scheduler was sent the command new
11/02/2013 01:49:26;0040;PBS_Server;Svr;tyrone-cluster;Scheduler was sent the command new
11/02/2013 01:49:56;0040;PBS_Server;Svr;tyrone-cluster;Scheduler was sent the command new
11/02/2013 01:50:27;0040;PBS_Server;Svr;tyrone-cluster;Scheduler was sent the command new
11/02/2013 01:50:56;0040;PBS_Server;Svr;tyrone-cluster;Scheduler was sent the command new
11/02/2013 01:51:25;0040;PBS_Server;Svr;tyrone-cluster;Scheduler was sent the command new
11/02/2013 01:51:57;0040;PBS_Server;Svr;tyrone-cluster;Scheduler was sent the command new
11/02/2013 01:52:26;0040;PBS_Server;Svr;tyrone-cluster;Scheduler was sent the command new
11/02/2013 01:52:41;0002;PBS_Server;Svr;PBS_Server;Torque Server Version = 3.0.5, loglevel = 0
11/02/2013 01:52:56;0040;PBS_Server;Svr;tyrone-cluster;Scheduler was sent the command new
11/02/2013 01:53:27;0040;PBS_Server;Svr;tyrone-cluster;Scheduler was sent the command new
11/02/2013 01:53:56;0040;PBS_Server;Svr;tyrone-cluster;Scheduler was sent the command new
11/02/2013 01:54:26;0040;PBS_Server;Svr;tyrone-cluster;Scheduler was sent the command new
11/02/2013 01:54:57;0040;PBS_Server;Svr;tyrone-cluster;Scheduler was sent the command new
11/02/2013 01:55:26;0040;PBS_Server;Svr;tyrone-cluster;Scheduler was sent the command new
11/02/2013 01:55:58;0040;PBS_Server;Svr;tyrone-cluster;Scheduler was sent the command new
11/02/2013 01:56:27;0040;PBS_Server;Svr;tyrone-cluster;Scheduler was sent the command new
11/02/2013 01:56:56;0040;PBS_Server;Svr;tyrone-cluster;Scheduler was sent the command new
11/02/2013 01:57:28;0040;PBS_Server;Svr;tyrone-cluster;Scheduler was sent the command new
11/02/2013 01:57:41;0002;PBS_Server;Svr;PBS_Server;Torque Server Version = 3.0.5, loglevel = 0
11/02/2013 01:57:57;0040;PBS_Server;Svr;tyrone-cluster;Scheduler was sent the command new
11/02/2013 01:58:27;0040;PBS_Server;Svr;tyrone-cluster;Scheduler was sent the command new
11/02/2013 01:59:00;0040;PBS_Server;Svr;tyrone-cluster;Scheduler was sent the command new
11/02/2013 01:59:30;0040;PBS_Server;Svr;tyrone-cluster;Scheduler was sent the command new
11/02/2013 02:00:08;0040;PBS_Server;Svr;tyrone-cluster;Scheduler was sent the command new
11/02/2013 02:00:31;0040;PBS_Server;Svr;tyrone-cluster;Scheduler was sent the command new
11/02/2013 02:01:02;0040;PBS_Server;Svr;tyrone-cluster;Scheduler was sent the command new
11/02/2013 02:01:38;0040;PBS_Server;Svr;tyrone-cluster;Scheduler was sent the command new
11/02/2013 02:02:11;0040;PBS_Server;Svr;tyrone-cluster;Scheduler was sent the command new
11/02/2013 02:02:41;0002;PBS_Server;Svr;PBS_Server;Torque Server Version = 3.0.5, loglevel = 0
11/02/2013 02:02:41;0040;PBS_Server;Svr;tyrone-cluster;Scheduler was sent the command new
11/02/2013 02:03:12;0040;PBS_Server;Svr;tyrone-cluster;Scheduler was sent the command new
11/02/2013 02:03:42;0040;PBS_Server;Svr;tyrone-cluster;Scheduler was sent the command new
11/02/2013 02:04:15;0040;PBS_Server;Svr;tyrone-cluster;Scheduler was sent the command new
11/02/2013 02:04:45;0040;PBS_Server;Svr;tyrone-cluster;Scheduler was sent the command new
11/02/2013 02:05:23;0040;PBS_Server;Svr;tyrone-cluster;Scheduler was sent the command new
11/02/2013 02:05:46;0040;PBS_Server;Svr;tyrone-cluster;Scheduler was sent the command new
11/02/2013 02:06:17;0040;PBS_Server;Svr;tyrone-cluster;Scheduler was sent the command new
11/02/2013 02:06:53;0040;PBS_Server;Svr;tyrone-cluster;Scheduler was sent the command new
11/02/2013 02:07:26;0040;PBS_Server;Svr;tyrone-cluster;Scheduler was sent the command new
11/02/2013 02:07:41;0002;PBS_Server;Svr;PBS_Server;Torque Server Version = 3.0.5, loglevel = 0
11/02/2013 02:07:57;0040;PBS_Server;Svr;tyrone-cluster;Scheduler was sent the command new
11/02/2013 02:08:27;0040;PBS_Server;Svr;tyrone-cluster;Scheduler was sent the command new
11/02/2013 02:08:57;0040;PBS_Server;Svr;tyrone-cluster;Scheduler was sent the command new
11/02/2013 02:09:29;0040;PBS_Server;Svr;tyrone-cluster;Scheduler was sent the command new
11/02/2013 02:09:57;0040;PBS_Server;Svr;tyrone-cluster;Scheduler was sent the command new
11/02/2013 02:10:27;0040;PBS_Server;Svr;tyrone-cluster;Scheduler was sent the command new
11/02/2013 02:10:44;0100;PBS_Server;Job;31382.tyrone-cluster;enqueuing into batch, state 1 hop 1
11/02/2013 02:10:44;0100;PBS_Server;Job;31382.tyrone-cluster;dequeuing from batch, state QUEUED
11/02/2013 02:10:44;0100;PBS_Server;Job;31382.tyrone-cluster;enqueuing into qp256, state 1 hop 1
11/02/2013 02:10:44;0008;PBS_Server;Job;31382.tyrone-cluster;Job Queued at request of secbadar@tyrone-cluster, owner = secbadar@tyrone-cluster, job name = Unif05Sch, queue = qp256
11/02/2013 02:10:44;0040;PBS_Server;Svr;tyrone-cluster;Scheduler was sent the command new
11/02/2013 02:10:44;0008;PBS_Server;Job;31382.tyrone-cluster;Job Modified at request of Scheduler@tyrone-cluster
11/02/2013 02:10:44;0008;PBS_Server;Job;31382.tyrone-cluster;Job Run at request of Scheduler@tyrone-cluster
11/02/2013 02:10:44;0040;PBS_Server;Svr;tyrone-cluster;Scheduler was sent the command recyc
11/02/2013 02:11:00;0040;PBS_Server;Svr;tyrone-cluster;Scheduler was sent the command new
11/02/2013 02:11:27;000d;PBS_Server;Job;31382.tyrone-cluster;Not sending email: User does not want mail of this type.
11/02/2013 02:11:29;0040;PBS_Server;Svr;tyrone-cluster;Scheduler was sent the command new
11/02/2013 02:11:31;0100;PBS_Server;Job;31383.tyrone-cluster;enqueuing into batch, state 1 hop 1
11/02/2013 02:11:31;0100;PBS_Server;Job;31383.tyrone-cluster;dequeuing from batch, state QUEUED
11/02/2013 02:11:31;0100;PBS_Server;Job;31383.tyrone-cluster;enqueuing into qp256, state 1 hop 1
11/02/2013 02:11:31;0008;PBS_Server;Job;31383.tyrone-cluster;Job Queued at request of secbadar@tyrone-cluster, owner = secbadar@tyrone-cluster, job name = Unif05Mpi, queue = qp256
11/02/2013 02:11:31;0040;PBS_Server;Svr;tyrone-cluster;Scheduler was sent the command new
11/02/2013 02:11:31;0008;PBS_Server;Job;31383.tyrone-cluster;Job Modified at request of Scheduler@tyrone-cluster
11/02/2013 02:12:08;0040;PBS_Server;Svr;tyrone-cluster;Scheduler was sent the command new
11/02/2013 02:12:31;0040;PBS_Server;Svr;tyrone-cluster;Scheduler was sent the command new
11/02/2013 02:12:41;0002;PBS_Server;Svr;PBS_Server;Torque Server Version = 3.0.5, loglevel = 0
11/02/2013 02:13:03;0040;PBS_Server;Svr;tyrone-cluster;Scheduler was sent the command new
11/02/2013 02:13:38;0040;PBS_Server;Svr;tyrone-cluster;Scheduler was sent the command new
11/02/2013 02:14:11;0040;PBS_Server;Svr;tyrone-cluster;Scheduler was sent the command new
11/02/2013 02:14:41;0040;PBS_Server;Svr;tyrone-cluster;Scheduler was sent the command new
11/02/2013 02:15:12;0040;PBS_Server;Svr;tyrone-cluster;Scheduler was sent the command new
11/02/2013 02:15:41;0040;PBS_Server;Svr;tyrone-cluster;Scheduler was sent the command new
11/02/2013 02:16:10;0040;PBS_Server;Svr;tyrone-cluster;Scheduler was sent the command new
11/02/2013 02:16:42;0040;PBS_Server;Svr;tyrone-cluster;Scheduler was sent the command new
11/02/2013 02:17:11;0040;PBS_Server;Svr;tyrone-cluster;Scheduler was sent the command new
11/02/2013 02:17:41;0002;PBS_Server;Svr;PBS_Server;Torque Server Version = 3.0.5, loglevel = 0
11/02/2013 02:17:41;0040;PBS_Server;Svr;tyrone-cluster;Scheduler was sent the command new
11/02/2013 02:18:12;0040;PBS_Server;Svr;tyrone-cluster;Scheduler was sent the command new
11/02/2013 02:18:32;0008;PBS_Server;Job;31382.tyrone-cluster;Job deleted at request of secbadar@tyrone-cluster
11/02/2013 02:18:32;0008;PBS_Server;Job;31382.tyrone-cluster;Job sent signal SIGTERM on delete
11/02/2013 02:18:32;000d;PBS_Server;Job;31382.tyrone-cluster;Not sending email: User does not want mail of this type.
11/02/2013 02:18:32;0010;PBS_Server;Job;31382.tyrone-cluster;Exit_status=143 resources_used.cput=04:44:16 resources_used.mem=1602144kb resources_used.vmem=36961848kb resources_used.walltime=00:07:48
11/02/2013 02:18:32;0008;PBS_Server;Job;NULL;on_job_exit valid pjob: 0x31714a0 (substate=50)
11/02/2013 02:18:32;0008;PBS_Server;Job;NULL;on_job_exit valid pjob: 0x31714a0 (substate=51)
11/02/2013 02:18:32;0008;PBS_Server;Job;NULL;on_job_exit valid pjob: 0x31714a0 (substate=51)
11/02/2013 02:18:32;0008;PBS_Server;Job;NULL;on_job_exit valid pjob: 0x31714a0 (substate=53)
11/02/2013 02:18:32;0100;PBS_Server;Job;31382.tyrone-cluster;dequeuing from qp256, state COMPLETE
11/02/2013 02:18:32;0040;PBS_Server;Svr;tyrone-cluster;Scheduler was sent the command term
11/02/2013 02:18:32;0008;PBS_Server;Job;31383.tyrone-cluster;Job Modified at request of Scheduler@tyrone-cluster
11/02/2013 02:18:32;0008;PBS_Server;Job;31383.tyrone-cluster;Job Run at request of Scheduler@tyrone-cluster
11/02/2013 02:18:32;0040;PBS_Server;Svr;tyrone-cluster;Scheduler was sent the command recyc
11/02/2013 02:18:41;0040;PBS_Server;Svr;tyrone-cluster;Scheduler was sent the command new
11/02/2013 02:18:59;000d;PBS_Server;Job;31383.tyrone-cluster;Not sending email: User does not want mail of this type.
11/02/2013 02:19:11;0040;PBS_Server;Svr;tyrone-cluster;Scheduler was sent the command new
11/02/2013 02:19:42;0040;PBS_Server;Svr;tyrone-cluster;Scheduler was sent the command new
11/02/2013 02:20:12;0040;PBS_Server;Svr;tyrone-cluster;Scheduler was sent the command new
11/02/2013 02:20:32;0100;PBS_Server;Job;31384.tyrone-cluster;enqueuing into batch, state 1 hop 1
11/02/2013 02:20:33;0100;PBS_Server;Job;31384.tyrone-cluster;dequeuing from batch, state QUEUED
11/02/2013 02:20:33;0100;PBS_Server;Job;31384.tyrone-cluster;enqueuing into qp256, state 1 hop 1
11/02/2013 02:20:33;0008;PBS_Server;Job;31384.tyrone-cluster;Job Queued at request of secbadar@tyrone-cluster, owner = secbadar@tyrone-cluster, job name = Unif05Sch, queue = qp256
11/02/2013 02:20:33;0040;PBS_Server;Svr;tyrone-cluster;Scheduler was sent the command new
11/02/2013 02:20:33;0008;PBS_Server;Job;31384.tyrone-cluster;Job Modified at request of Scheduler@tyrone-cluster
11/02/2013 02:20:45;0040;PBS_Server;Svr;tyrone-cluster;Scheduler was sent the command new
11/02/2013 02:21:14;0040;PBS_Server;Svr;tyrone-cluster;Scheduler was sent the command new
11/02/2013 02:21:53;0040;PBS_Server;Svr;tyrone-cluster;Scheduler was sent the command new
11/02/2013 02:22:15;0040;PBS_Server;Svr;tyrone-cluster;Scheduler was sent the command new
11/02/2013 02:22:41;0002;PBS_Server;Svr;PBS_Server;Torque Server Version = 3.0.5, loglevel = 0
11/02/2013 02:22:47;0040;PBS_Server;Svr;tyrone-cluster;Scheduler was sent the command new
11/02/2013 02:23:23;0040;PBS_Server;Svr;tyrone-cluster;Scheduler was sent the command new
11/02/2013 02:23:56;0040;PBS_Server;Svr;tyrone-cluster;Scheduler was sent the command new
11/02/2013 02:24:26;0040;PBS_Server;Svr;tyrone-cluster;Scheduler was sent the command new
11/02/2013 02:24:57;0040;PBS_Server;Svr;tyrone-cluster;Scheduler was sent the command new
11/02/2013 02:25:27;0040;PBS_Server;Svr;tyrone-cluster;Scheduler was sent the command new
11/02/2013 02:25:59;0040;PBS_Server;Svr;tyrone-cluster;Scheduler was sent the command new
11/02/2013 02:26:27;0040;PBS_Server;Svr;tyrone-cluster;Scheduler was sent the command new
11/02/2013 02:26:57;0040;PBS_Server;Svr;tyrone-cluster;Scheduler was sent the command new
11/02/2013 02:27:29;0040;PBS_Server;Svr;tyrone-cluster;Scheduler was sent the command new
11/02/2013 02:27:41;0002;PBS_Server;Svr;PBS_Server;Torque Server Version = 3.0.5, loglevel = 0
11/02/2013 02:27:59;0040;PBS_Server;Svr;tyrone-cluster;Scheduler was sent the command new
11/02/2013 02:28:38;0040;PBS_Server;Svr;tyrone-cluster;Scheduler was sent the command new
11/02/2013 02:29:00;0040;PBS_Server;Svr;tyrone-cluster;Scheduler was sent the command new
11/02/2013 02:29:32;0040;PBS_Server;Svr;tyrone-cluster;Scheduler was sent the command new
11/02/2013 02:30:08;0040;PBS_Server;Svr;tyrone-cluster;Scheduler was sent the command new
11/02/2013 02:30:41;0040;PBS_Server;Svr;tyrone-cluster;Scheduler was sent the command new
11/02/2013 02:31:12;0040;PBS_Server;Svr;tyrone-cluster;Scheduler was sent the command new
11/02/2013 02:31:42;0040;PBS_Server;Svr;tyrone-cluster;Scheduler was sent the command new
11/02/2013 02:32:14;0040;PBS_Server;Svr;tyrone-cluster;Scheduler was sent the command new
11/02/2013 02:32:41;0002;PBS_Server;Svr;PBS_Server;Torque Server Version = 3.0.5, loglevel = 0
11/02/2013 02:32:44;0040;PBS_Server;Svr;tyrone-cluster;Scheduler was sent the command new
11/02/2013 02:33:12;0040;PBS_Server;Svr;tyrone-cluster;Scheduler was sent the command new
11/02/2013 02:33:13;000d;PBS_Server;Job;31383.tyrone-cluster;Not sending email: User does not want mail of this type.
11/02/2013 02:33:13;0010;PBS_Server;Job;31383.tyrone-cluster;Exit_status=0 resources_used.cput=02:37:17 resources_used.mem=1600000kb resources_used.vmem=36959264kb resources_used.walltime=00:14:40
11/02/2013 02:33:13;0008;PBS_Server;Job;NULL;on_job_exit valid pjob: 0x2e60d70 (substate=50)
11/02/2013 02:33:13;0008;PBS_Server;Job;NULL;on_job_exit valid pjob: 0x2e60d70 (substate=51)
11/02/2013 02:33:13;0008;PBS_Server;Job;NULL;on_job_exit valid pjob: 0x2e60d70 (substate=51)
11/02/2013 02:33:13;0008;PBS_Server;Job;NULL;on_job_exit valid pjob: 0x2e60d70 (substate=53)
11/02/2013 02:33:13;0100;PBS_Server;Job;31383.tyrone-cluster;dequeuing from qp256, state COMPLETE
11/02/2013 02:33:13;0040;PBS_Server;Svr;tyrone-cluster;Scheduler was sent the command term
11/02/2013 02:33:13;0008;PBS_Server;Job;31384.tyrone-cluster;Job Modified at request of Scheduler@tyrone-cluster
11/02/2013 02:33:13;0008;PBS_Server;Job;31384.tyrone-cluster;Job Run at request of Scheduler@tyrone-cluster
11/02/2013 02:33:13;0040;PBS_Server;Svr;tyrone-cluster;Scheduler was sent the command recyc
11/02/2013 02:33:42;0040;PBS_Server;Svr;tyrone-cluster;Scheduler was sent the command new
11/02/2013 02:34:01;000d;PBS_Server;Job;31384.tyrone-cluster;Not sending email: User does not want mail of this type.
11/02/2013 02:34:14;0040;PBS_Server;Svr;tyrone-cluster;Scheduler was sent the command new
11/02/2013 02:34:42;0040;PBS_Server;Svr;tyrone-cluster;Scheduler was sent the command new
11/02/2013 02:35:12;0040;PBS_Server;Svr;tyrone-cluster;Scheduler was sent the command new
11/02/2013 02:35:44;0040;PBS_Server;Svr;tyrone-cluster;Scheduler was sent the command new
11/02/2013 02:36:12;0040;PBS_Server;Svr;tyrone-cluster;Scheduler was sent the command new
11/02/2013 02:36:42;0040;PBS_Server;Svr;tyrone-cluster;Scheduler was sent the command new
11/02/2013 02:37:15;0040;PBS_Server;Svr;tyrone-cluster;Scheduler was sent the command new
11/02/2013 02:37:41;0002;PBS_Server;Svr;PBS_Server;Torque Server Version = 3.0.5, loglevel = 0
11/02/2013 02:37:44;0040;PBS_Server;Svr;tyrone-cluster;Scheduler was sent the command new
11/02/2013 02:38:23;0040;PBS_Server;Svr;tyrone-cluster;Scheduler was sent the command new
11/02/2013 02:38:45;0040;PBS_Server;Svr;tyrone-cluster;Scheduler was sent the command new
11/02/2013 02:39:16;0040;PBS_Server;Svr;tyrone-cluster;Scheduler was sent the command new
11/02/2013 02:39:53;0040;PBS_Server;Svr;tyrone-cluster;Scheduler was sent the command new
11/02/2013 02:40:26;0040;PBS_Server;Svr;tyrone-cluster;Scheduler was sent the command new
11/02/2013 02:40:56;0040;PBS_Server;Svr;tyrone-cluster;Scheduler was sent the command new
11/02/2013 02:41:27;0040;PBS_Server;Svr;tyrone-cluster;Scheduler was sent the command new
11/02/2013 02:41:57;0040;PBS_Server;Svr;tyrone-cluster;Scheduler was sent the command new
11/02/2013 02:42:29;0040;PBS_Server;Svr;tyrone-cluster;Scheduler was sent the command new
11/02/2013 02:42:41;0002;PBS_Server;Svr;PBS_Server;Torque Server Version = 3.0.5, loglevel = 0
11/02/2013 02:42:57;0040;PBS_Server;Svr;tyrone-cluster;Scheduler was sent the command new
11/02/2013 02:43:27;0040;PBS_Server;Svr;tyrone-cluster;Scheduler was sent the command new
11/02/2013 02:43:59;0040;PBS_Server;Svr;tyrone-cluster;Scheduler was sent the command new
11/02/2013 02:44:27;0040;PBS_Server;Svr;tyrone-cluster;Scheduler was sent the command new
11/02/2013 02:44:40;000d;PBS_Server;Job;31384.tyrone-cluster;Not sending email: User does not want mail of this type.
11/02/2013 02:44:40;0010;PBS_Server;Job;31384.tyrone-cluster;Exit_status=0 resources_used.cput=02:24:51 resources_used.mem=1572696kb resources_used.vmem=36927272kb resources_used.walltime=00:11:27
11/02/2013 02:44:40;0008;PBS_Server;Job;NULL;on_job_exit valid pjob: 0x31714a0 (substate=50)
11/02/2013 02:44:40;0008;PBS_Server;Job;NULL;on_job_exit valid pjob: 0x31714a0 (substate=51)
11/02/2013 02:44:40;0008;PBS_Server;Job;NULL;on_job_exit valid pjob: 0x31714a0 (substate=51)
11/02/2013 02:44:40;0008;PBS_Server;Job;NULL;on_job_exit valid pjob: 0x31714a0 (substate=53)
11/02/2013 02:44:40;0100;PBS_Server;Job;31384.tyrone-cluster;dequeuing from qp256, state COMPLETE
11/02/2013 02:44:40;0040;PBS_Server;Svr;tyrone-cluster;Scheduler was sent the command term
11/02/2013 02:45:00;0040;PBS_Server;Svr;tyrone-cluster;Scheduler was sent the command new
11/02/2013 02:45:29;0040;PBS_Server;Svr;tyrone-cluster;Scheduler was sent the command new
11/02/2013 02:46:00;0040;PBS_Server;Svr;tyrone-cluster;Scheduler was sent the command new
11/02/2013 02:46:38;0040;PBS_Server;Svr;tyrone-cluster;Scheduler was sent the command new
11/02/2013 02:47:00;0040;PBS_Server;Svr;tyrone-cluster;Scheduler was sent the command new
11/02/2013 02:47:33;0040;PBS_Server;Svr;tyrone-cluster;Scheduler was sent the command new
11/02/2013 02:47:41;0002;PBS_Server;Svr;PBS_Server;Torque Server Version = 3.0.5, loglevel = 0
11/02/2013 02:48:08;0040;PBS_Server;Svr;tyrone-cluster;Scheduler was sent the command new
11/02/2013 02:48:41;0040;PBS_Server;Svr;tyrone-cluster;Scheduler was sent the command new
11/02/2013 02:49:12;0040;PBS_Server;Svr;tyrone-cluster;Scheduler was sent the command new
11/02/2013 02:49:42;0040;PBS_Server;Svr;tyrone-cluster;Scheduler was sent the command new
11/02/2013 02:50:12;0040;PBS_Server;Svr;tyrone-cluster;Scheduler was sent the command new
11/02/2013 02:50:44;0040;PBS_Server;Svr;tyrone-cluster;Scheduler was sent the command new
11/02/2013 02:51:12;0040;PBS_Server;Svr;tyrone-cluster;Scheduler was sent the command new
11/02/2013 02:51:42;0040;PBS_Server;Svr;tyrone-cluster;Scheduler was sent the command new
11/02/2013 02:52:14;0040;PBS_Server;Svr;tyrone-cluster;Scheduler was sent the command new
11/02/2013 02:52:41;0002;PBS_Server;Svr;PBS_Server;Torque Server Version = 3.0.5, loglevel = 0
11/02/2013 02:52:42;0040;PBS_Server;Svr;tyrone-cluster;Scheduler was sent the command new
11/02/2013 02:53:13;0040;PBS_Server;Svr;tyrone-cluster;Scheduler was sent the command new
11/02/2013 02:53:42;0040;PBS_Server;Svr;tyrone-cluster;Scheduler was sent the command new
11/02/2013 02:54:12;0040;PBS_Server;Svr;tyrone-cluster;Scheduler was sent the command new
11/02/2013 02:54:42;0040;PBS_Server;Svr;tyrone-cluster;Scheduler was sent the command new
11/02/2013 02:55:12;0040;PBS_Server;Svr;tyrone-cluster;Scheduler was sent the command new
11/02/2013 02:55:42;0040;PBS_Server;Svr;tyrone-cluster;Scheduler was sent the command new
11/02/2013 02:56:12;0040;PBS_Server;Svr;tyrone-cluster;Scheduler was sent the command new
11/02/2013 02:56:42;0040;PBS_Server;Svr;tyrone-cluster;Scheduler was sent the command new
11/02/2013 02:57:12;0040;PBS_Server;Svr;tyrone-cluster;Scheduler was sent the command new
11/02/2013 02:57:41;0002;PBS_Server;Svr;PBS_Server;Torque Server Version = 3.0.5, loglevel = 0
11/02/2013 02:57:42;0040;PBS_Server;Svr;tyrone-cluster;Scheduler was sent the command new
11/02/2013 02:58:13;0040;PBS_Server;Svr;tyrone-cluster;Scheduler was sent the command new
11/02/2013 02:58:44;0040;PBS_Server;Svr;tyrone-cluster;Scheduler was sent the command new
11/02/2013 02:59:23;0040;PBS_Server;Svr;tyrone-cluster;Scheduler was sent the command new
11/02/2013 02:59:45;0040;PBS_Server;Svr;tyrone-cluster;Scheduler was sent the command new
11/02/2013 03:00:18;0040;PBS_Server;Svr;tyrone-cluster;Scheduler was sent the command new
11/02/2013 03:00:53;0040;PBS_Server;Svr;tyrone-cluster;Scheduler was sent the command new
11/02/2013 03:01:26;0040;PBS_Server;Svr;tyrone-cluster;Scheduler was sent the command new
11/02/2013 03:01:57;0040;PBS_Server;Svr;tyrone-cluster;Scheduler was sent the command new
11/02/2013 03:02:27;0040;PBS_Server;Svr;tyrone-cluster;Scheduler was sent the command new
11/02/2013 03:02:41;0002;PBS_Server;Svr;PBS_Server;Torque Server Version = 3.0.5, loglevel = 0
11/02/2013 03:02:57;0040;PBS_Server;Svr;tyrone-cluster;Scheduler was sent the command new
11/02/2013 03:03:28;0040;PBS_Server;Svr;tyrone-cluster;Scheduler was sent the command new
11/02/2013 03:04:00;0040;PBS_Server;Svr;tyrone-cluster;Scheduler was sent the command new
11/02/2013 03:04:38;0040;PBS_Server;Svr;tyrone-cluster;Scheduler was sent the command new
11/02/2013 03:05:00;0040;PBS_Server;Svr;tyrone-cluster;Scheduler was sent the command new
11/02/2013 03:05:33;0040;PBS_Server;Svr;tyrone-cluster;Scheduler was sent the command new
11/02/2013 03:06:08;0040;PBS_Server;Svr;tyrone-cluster;Scheduler was sent the command new
11/02/2013 03:06:41;0040;PBS_Server;Svr;tyrone-cluster;Scheduler was sent the command new
11/02/2013 03:07:12;0040;PBS_Server;Svr;tyrone-cluster;Scheduler was sent the command new
11/02/2013 03:07:41;0002;PBS_Server;Svr;PBS_Server;Torque Server Version = 3.0.5, loglevel = 0
11/02/2013 03:07:42;0040;PBS_Server;Svr;tyrone-cluster;Scheduler was sent the command new
11/02/2013 03:08:12;0040;PBS_Server;Svr;tyrone-cluster;Scheduler was sent the command new
11/02/2013 03:08:17;0100;PBS_Server;Job;31385.tyrone-cluster;enqueuing into batch, state 1 hop 1
11/02/2013 03:08:17;0100;PBS_Server;Job;31385.tyrone-cluster;dequeuing from batch, state QUEUED
11/02/2013 03:08:17;0100;PBS_Server;Job;31385.tyrone-cluster;enqueuing into qp256, state 1 hop 1
11/02/2013 03:08:17;0008;PBS_Server;Job;31385.tyrone-cluster;Job Queued at request of secbadar@tyrone-cluster, owner = secbadar@tyrone-cluster, job name = Unif06Sch, queue = qp256
11/02/2013 03:08:17;0040;PBS_Server;Svr;tyrone-cluster;Scheduler was sent the command new
11/02/2013 03:08:17;0008;PBS_Server;Job;31385.tyrone-cluster;Job Modified at request of Scheduler@tyrone-cluster
11/02/2013 03:08:17;0008;PBS_Server;Job;31385.tyrone-cluster;Job Run at request of Scheduler@tyrone-cluster
11/02/2013 03:08:17;0040;PBS_Server;Svr;tyrone-cluster;Scheduler was sent the command recyc
11/02/2013 03:08:42;0040;PBS_Server;Svr;tyrone-cluster;Scheduler was sent the command new
11/02/2013 03:09:00;0100;PBS_Server;Job;31386.tyrone-cluster;enqueuing into batch, state 1 hop 1
11/02/2013 03:09:00;0100;PBS_Server;Job;31386.tyrone-cluster;dequeuing from batch, state QUEUED
11/02/2013 03:09:00;0100;PBS_Server;Job;31386.tyrone-cluster;enqueuing into qp256, state 1 hop 1
11/02/2013 03:09:00;0008;PBS_Server;Job;31386.tyrone-cluster;Job Queued at request of secbadar@tyrone-cluster, owner = secbadar@tyrone-cluster, job name = Unif06Edg, queue = qp256
11/02/2013 03:09:00;0040;PBS_Server;Svr;tyrone-cluster;Scheduler was sent the command new
11/02/2013 03:09:00;0008;PBS_Server;Job;31386.tyrone-cluster;Job Modified at request of Scheduler@tyrone-cluster
11/02/2013 03:09:12;0040;PBS_Server;Svr;tyrone-cluster;Scheduler was sent the command new
11/02/2013 03:09:18;000d;PBS_Server;Job;31385.tyrone-cluster;Not sending email: User does not want mail of this type.
11/02/2013 03:09:25;0100;PBS_Server;Job;31387.tyrone-cluster;enqueuing into batch, state 1 hop 1
11/02/2013 03:09:25;0008;PBS_Server;Job;31387.tyrone-cluster;Job Queued at request of secbadar@tyrone-cluster, owner = secbadar@tyrone-cluster, job name = Unif05Sch, queue = batch
11/02/2013 03:09:25;0040;PBS_Server;Svr;tyrone-cluster;Scheduler was sent the command new
11/02/2013 03:09:25;0008;PBS_Server;Job;31387.tyrone-cluster;Job Modified at request of Scheduler@tyrone-cluster
11/02/2013 03:09:42;0040;PBS_Server;Svr;tyrone-cluster;Scheduler was sent the command new
11/02/2013 03:09:44;0100;PBS_Server;Job;31388.tyrone-cluster;enqueuing into batch, state 1 hop 1
11/02/2013 03:09:44;0008;PBS_Server;Job;31388.tyrone-cluster;Job Queued at request of secbadar@tyrone-cluster, owner = secbadar@tyrone-cluster, job name = Unif05Sch, queue = batch
11/02/2013 03:09:44;0040;PBS_Server;Svr;tyrone-cluster;Scheduler was sent the command new
11/02/2013 03:09:44;0008;PBS_Server;Job;31388.tyrone-cluster;Job Modified at request of Scheduler@tyrone-cluster
11/02/2013 03:09:57;0040;PBS_Server;Svr;tyrone-cluster;Scheduler was sent the command new
11/02/2013 03:09:58;0008;PBS_Server;Job;31388.tyrone-cluster;Job deleted at request of secbadar@tyrone-cluster
11/02/2013 03:09:58;0008;PBS_Server;Job;NULL;on_job_exit valid pjob: 0x2df3ca0 (substate=59)
11/02/2013 03:09:58;0100;PBS_Server;Job;31388.tyrone-cluster;dequeuing from batch, state COMPLETE
11/02/2013 03:09:58;0040;PBS_Server;Svr;tyrone-cluster;Scheduler was sent the command term
11/02/2013 03:10:14;0040;PBS_Server;Svr;tyrone-cluster;Scheduler was sent the command new
11/02/2013 03:10:20;0008;PBS_Server;Job;31387.tyrone-cluster;Job deleted at request of secbadar@tyrone-cluster
11/02/2013 03:10:20;0008;PBS_Server;Job;NULL;on_job_exit valid pjob: 0x2e6ec10 (substate=59)
11/02/2013 03:10:20;0100;PBS_Server;Job;31387.tyrone-cluster;dequeuing from batch, state COMPLETE
11/02/2013 03:10:20;0040;PBS_Server;Svr;tyrone-cluster;Scheduler was sent the command term
11/02/2013 03:10:42;0040;PBS_Server;Svr;tyrone-cluster;Scheduler was sent the command new
11/02/2013 03:10:43;0100;PBS_Server;Job;31389.tyrone-cluster;enqueuing into batch, state 1 hop 1
11/02/2013 03:10:43;0008;PBS_Server;Job;31389.tyrone-cluster;Job Queued at request of secbadar@tyrone-cluster, owner = secbadar@tyrone-cluster, job name = Unif05Mpi, queue = batch
11/02/2013 03:10:43;0040;PBS_Server;Svr;tyrone-cluster;Scheduler was sent the command new
11/02/2013 03:10:43;0008;PBS_Server;Job;31389.tyrone-cluster;Job Modified at request of Scheduler@tyrone-cluster
11/02/2013 03:11:10;0100;PBS_Server;Job;31390.tyrone-cluster;enqueuing into batch, state 1 hop 1
11/02/2013 03:11:10;0008;PBS_Server;Job;31390.tyrone-cluster;Job Queued at request of secbadar@tyrone-cluster, owner = secbadar@tyrone-cluster, job name = Unif05Sch, queue = batch
11/02/2013 03:11:10;0040;PBS_Server;Svr;tyrone-cluster;Scheduler was sent the command new
11/02/2013 03:11:11;0008;PBS_Server;Job;31390.tyrone-cluster;Job Modified at request of Scheduler@tyrone-cluster
11/02/2013 03:11:12;0040;PBS_Server;Svr;tyrone-cluster;Scheduler was sent the command new
11/02/2013 03:11:23;0040;PBS_Server;Svr;tyrone-cluster;Scheduler was sent the command new
11/02/2013 03:11:42;0040;PBS_Server;Svr;tyrone-cluster;Scheduler was sent the command new
11/02/2013 03:11:46;0040;PBS_Server;Svr;tyrone-cluster;Scheduler was sent the command new
11/02/2013 03:11:46;0008;PBS_Server;Job;31386.tyrone-cluster;Job deleted at request of secbadar@tyrone-cluster
11/02/2013 03:11:46;0008;PBS_Server;Job;NULL;on_job_exit valid pjob: 0x31714a0 (substate=59)
11/02/2013 03:11:46;0100;PBS_Server;Job;31386.tyrone-cluster;dequeuing from qp256, state COMPLETE
11/02/2013 03:11:46;0040;PBS_Server;Svr;tyrone-cluster;Scheduler was sent the command term
11/02/2013 03:11:48;0008;PBS_Server;Job;31385.tyrone-cluster;Job deleted at request of secbadar@tyrone-cluster
11/02/2013 03:11:48;0008;PBS_Server;Job;31385.tyrone-cluster;Job sent signal SIGTERM on delete
11/02/2013 03:11:49;000d;PBS_Server;Job;31385.tyrone-cluster;Not sending email: User does not want mail of this type.
11/02/2013 03:11:49;0010;PBS_Server;Job;31385.tyrone-cluster;Exit_status=143 resources_used.cput=00:18:53 resources_used.mem=1544640kb resources_used.vmem=36892448kb resources_used.walltime=00:03:32
11/02/2013 03:11:49;0008;PBS_Server;Job;NULL;on_job_exit valid pjob: 0x2e60d70 (substate=50)
11/02/2013 03:11:49;0008;PBS_Server;Job;NULL;on_job_exit valid pjob: 0x2e60d70 (substate=51)
11/02/2013 03:11:49;0008;PBS_Server;Job;NULL;on_job_exit valid pjob: 0x2e60d70 (substate=51)
11/02/2013 03:11:49;0008;PBS_Server;Job;NULL;on_job_exit valid pjob: 0x2e60d70 (substate=53)
11/02/2013 03:11:49;0100;PBS_Server;Job;31385.tyrone-cluster;dequeuing from qp256, state COMPLETE
11/02/2013 03:11:49;0040;PBS_Server;Svr;tyrone-cluster;Scheduler was sent the command term
11/02/2013 03:12:12;0100;PBS_Server;Job;31390.tyrone-cluster;dequeuing from batch, state QUEUED
11/02/2013 03:12:12;0100;PBS_Server;Job;31390.tyrone-cluster;enqueuing into qp256, state 1 hop 1
11/02/2013 03:12:12;0040;PBS_Server;Svr;tyrone-cluster;Scheduler was sent the command new
11/02/2013 03:12:12;0008;PBS_Server;Job;31390.tyrone-cluster;Job Modified at request of Scheduler@tyrone-cluster
11/02/2013 03:12:12;0008;PBS_Server;Job;31390.tyrone-cluster;Job Run at request of Scheduler@tyrone-cluster
11/02/2013 03:12:12;0040;PBS_Server;Svr;tyrone-cluster;Scheduler was sent the command recyc
11/02/2013 03:12:14;0100;PBS_Server;Job;31391.tyrone-cluster;enqueuing into batch, state 1 hop 1
11/02/2013 03:12:14;0100;PBS_Server;Job;31391.tyrone-cluster;dequeuing from batch, state QUEUED
11/02/2013 03:12:14;0100;PBS_Server;Job;31391.tyrone-cluster;enqueuing into qp256, state 1 hop 1
11/02/2013 03:12:14;0008;PBS_Server;Job;31391.tyrone-cluster;Job Queued at request of secbadar@tyrone-cluster, owner = secbadar@tyrone-cluster, job name = Unif06Mpi, queue = qp256
11/02/2013 03:12:14;0040;PBS_Server;Svr;tyrone-cluster;Scheduler was sent the command new
11/02/2013 03:12:14;0008;PBS_Server;Job;31391.tyrone-cluster;Job Modified at request of Scheduler@tyrone-cluster
11/02/2013 03:12:19;0040;PBS_Server;Svr;tyrone-cluster;Scheduler was sent the command new
11/02/2013 03:12:41;0002;PBS_Server;Svr;PBS_Server;Torque Server Version = 3.0.5, loglevel = 0
11/02/2013 03:12:42;0040;PBS_Server;Svr;tyrone-cluster;Scheduler was sent the command new
11/02/2013 03:12:53;0040;PBS_Server;Svr;tyrone-cluster;Scheduler was sent the command new
11/02/2013 03:13:10;000d;PBS_Server;Job;31390.tyrone-cluster;Not sending email: User does not want mail of this type.
11/02/2013 03:13:10;0100;PBS_Server;Job;31392.tyrone-cluster;enqueuing into batch, state 1 hop 1
11/02/2013 03:13:10;0008;PBS_Server;Job;31392.tyrone-cluster;Job Queued at request of secbadar@tyrone-cluster, owner = secbadar@tyrone-cluster, job name = Unif06Sch, queue = batch
11/02/2013 03:13:10;0040;PBS_Server;Svr;tyrone-cluster;Scheduler was sent the command new
11/02/2013 03:13:10;0008;PBS_Server;Job;31392.tyrone-cluster;Job Modified at request of Scheduler@tyrone-cluster
11/02/2013 03:13:12;0040;PBS_Server;Svr;tyrone-cluster;Scheduler was sent the command new
11/02/2013 03:13:26;0040;PBS_Server;Svr;tyrone-cluster;Scheduler was sent the command new
11/02/2013 03:13:34;0100;PBS_Server;Job;31393.tyrone-cluster;enqueuing into batch, state 1 hop 1
11/02/2013 03:13:34;0008;PBS_Server;Job;31393.tyrone-cluster;Job Queued at request of secbadar@tyrone-cluster, owner = secbadar@tyrone-cluster, job name = Unif05Sch, queue = batch
11/02/2013 03:13:34;0040;PBS_Server;Svr;tyrone-cluster;Scheduler was sent the command new
11/02/2013 03:13:36;0008;PBS_Server;Job;31393.tyrone-cluster;Job Modified at request of Scheduler@tyrone-cluster
11/02/2013 03:13:42;0040;PBS_Server;Svr;tyrone-cluster;Scheduler was sent the command new
11/02/2013 03:13:55;0040;PBS_Server;Svr;tyrone-cluster;Scheduler was sent the command new
11/02/2013 03:14:03;0100;PBS_Server;Job;31394.tyrone-cluster;enqueuing into batch, state 1 hop 1
11/02/2013 03:14:03;0008;PBS_Server;Job;31394.tyrone-cluster;Job Queued at request of secbadar@tyrone-cluster, owner = secbadar@tyrone-cluster, job name = Unif04Mpi, queue = batch
11/02/2013 03:14:03;0040;PBS_Server;Svr;tyrone-cluster;Scheduler was sent the command new
11/02/2013 03:14:03;0008;PBS_Server;Job;31394.tyrone-cluster;Job Modified at request of Scheduler@tyrone-cluster
11/02/2013 03:14:04;0040;PBS_Server;Svr;tyrone-cluster;Scheduler was sent the command new
11/02/2013 03:14:12;0040;PBS_Server;Svr;tyrone-cluster;Scheduler was sent the command new
11/02/2013 03:14:17;0008;PBS_Server;Job;31393.tyrone-cluster;Job deleted at request of secbadar@tyrone-cluster
11/02/2013 03:14:17;0008;PBS_Server;Job;NULL;on_job_exit valid pjob: 0x338fb80 (substate=59)
11/02/2013 03:14:17;0100;PBS_Server;Job;31393.tyrone-cluster;dequeuing from batch, state COMPLETE
11/02/2013 03:14:17;0040;PBS_Server;Svr;tyrone-cluster;Scheduler was sent the command term
11/02/2013 03:14:27;0040;PBS_Server;Svr;tyrone-cluster;Scheduler was sent the command new
11/02/2013 03:14:35;0040;PBS_Server;Svr;tyrone-cluster;Scheduler was sent the command new
11/02/2013 03:14:43;0040;PBS_Server;Svr;tyrone-cluster;Scheduler was sent the command new
11/02/2013 03:14:44;0100;PBS_Server;Job;31395.tyrone-cluster;enqueuing into batch, state 1 hop 1
11/02/2013 03:14:44;0008;PBS_Server;Job;31395.tyrone-cluster;Job Queued at request of secbadar@tyrone-cluster, owner = secbadar@tyrone-cluster, job name = Unif04Sch, queue = batch
11/02/2013 03:14:44;0040;PBS_Server;Svr;tyrone-cluster;Scheduler was sent the command new
11/02/2013 03:14:44;0008;PBS_Server;Job;31395.tyrone-cluster;Job Modified at request of Scheduler@tyrone-cluster
11/02/2013 03:15:00;0040;PBS_Server;Svr;tyrone-cluster;Scheduler was sent the command new
11/02/2013 03:15:12;0040;PBS_Server;Svr;tyrone-cluster;Scheduler was sent the command new
11/02/2013 03:15:12;0100;PBS_Server;Job;31396.tyrone-cluster;enqueuing into batch, state 1 hop 1
11/02/2013 03:15:12;0008;PBS_Server;Job;31396.tyrone-cluster;Job Queued at request of secbadar@tyrone-cluster, owner = secbadar@tyrone-cluster, job name = Unif03Sch, queue = batch
11/02/2013 03:15:12;0008;PBS_Server;Job;31396.tyrone-cluster;Job Modified at request of Scheduler@tyrone-cluster
11/02/2013 03:15:14;0040;PBS_Server;Svr;tyrone-cluster;Scheduler was sent the command new
11/02/2013 03:15:27;0040;PBS_Server;Svr;tyrone-cluster;Scheduler was sent the command new
11/02/2013 03:15:35;0040;PBS_Server;Svr;tyrone-cluster;Scheduler was sent the command new
11/02/2013 03:15:41;0100;PBS_Server;Job;31397.tyrone-cluster;enqueuing into batch, state 1 hop 1
11/02/2013 03:15:41;0008;PBS_Server;Job;31397.tyrone-cluster;Job Queued at request of secbadar@tyrone-cluster, owner = secbadar@tyrone-cluster, job name = Unif03Mpi, queue = batch
11/02/2013 03:15:41;0040;PBS_Server;Svr;tyrone-cluster;Scheduler was sent the command new
11/02/2013 03:15:41;0008;PBS_Server;Job;31397.tyrone-cluster;Job Modified at request of Scheduler@tyrone-cluster
11/02/2013 03:15:42;0040;PBS_Server;Svr;tyrone-cluster;Scheduler was sent the command new
11/02/2013 03:15:53;0040;PBS_Server;Svr;tyrone-cluster;Scheduler was sent the command new
11/02/2013 03:16:09;0040;PBS_Server;Svr;tyrone-cluster;Scheduler was sent the command new
11/02/2013 03:16:12;0040;PBS_Server;Svr;tyrone-cluster;Scheduler was sent the command new
11/02/2013 03:16:15;0040;PBS_Server;Svr;tyrone-cluster;Scheduler was sent the command new
11/02/2013 03:16:29;0040;PBS_Server;Svr;tyrone-cluster;Scheduler was sent the command new
11/02/2013 03:16:38;0040;PBS_Server;Svr;tyrone-cluster;Scheduler was sent the command new
11/02/2013 03:16:42;0040;PBS_Server;Svr;tyrone-cluster;Scheduler was sent the command new
11/02/2013 03:16:46;0040;PBS_Server;Svr;tyrone-cluster;Scheduler was sent the command new
11/02/2013 03:16:58;0040;PBS_Server;Svr;tyrone-cluster;Scheduler was sent the command new
11/02/2013 03:17:11;0040;PBS_Server;Svr;tyrone-cluster;Scheduler was sent the command new
11/02/2013 03:17:23;0040;PBS_Server;Svr;tyrone-cluster;Scheduler was sent the command new
11/02/2013 03:17:28;0008;PBS_Server;Job;31391.tyrone-cluster;Job deleted at request of secbadar@tyrone-cluster
11/02/2013 03:17:28;0008;PBS_Server;Job;NULL;on_job_exit valid pjob: 0x2e60d70 (substate=59)
11/02/2013 03:17:28;0100;PBS_Server;Job;31391.tyrone-cluster;dequeuing from qp256, state COMPLETE
11/02/2013 03:17:28;0040;PBS_Server;Svr;tyrone-cluster;Scheduler was sent the command term
11/02/2013 03:17:33;0008;PBS_Server;Job;31392.tyrone-cluster;Job deleted at request of secbadar@tyrone-cluster
11/02/2013 03:17:33;0008;PBS_Server;Job;NULL;on_job_exit valid pjob: 0x31714a0 (substate=59)
11/02/2013 03:17:33;0100;PBS_Server;Job;31392.tyrone-cluster;dequeuing from batch, state COMPLETE
11/02/2013 03:17:33;0040;PBS_Server;Svr;tyrone-cluster;Scheduler was sent the command term
11/02/2013 03:17:40;0100;PBS_Server;Job;31394.tyrone-cluster;dequeuing from batch, state QUEUED
11/02/2013 03:17:40;0100;PBS_Server;Job;31394.tyrone-cluster;enqueuing into qp256, state 1 hop 1
11/02/2013 03:17:40;0040;PBS_Server;Svr;tyrone-cluster;Scheduler was sent the command new
11/02/2013 03:17:40;0008;PBS_Server;Job;31394.tyrone-cluster;Job Modified at request of Scheduler@tyrone-cluster
11/02/2013 03:17:41;0002;PBS_Server;Svr;PBS_Server;Torque Server Version = 3.0.5, loglevel = 0
11/02/2013 03:17:43;0040;PBS_Server;Svr;tyrone-cluster;Scheduler was sent the command new
11/02/2013 03:17:56;0040;PBS_Server;Svr;tyrone-cluster;Scheduler was sent the command new
11/02/2013 03:18:08;0040;PBS_Server;Svr;tyrone-cluster;Scheduler was sent the command new
11/02/2013 03:18:14;0040;PBS_Server;Svr;tyrone-cluster;Scheduler was sent the command new
11/02/2013 03:18:25;0040;PBS_Server;Svr;tyrone-cluster;Scheduler was sent the command new
11/02/2013 03:18:28;0100;PBS_Server;Job;31398.tyrone-cluster;enqueuing into batch, state 1 hop 1
11/02/2013 03:18:28;0008;PBS_Server;Job;31398.tyrone-cluster;Job Queued at request of secbadar@tyrone-cluster, owner = secbadar@tyrone-cluster, job name = Unif06Mpi, queue = batch
11/02/2013 03:18:28;0040;PBS_Server;Svr;tyrone-cluster;Scheduler was sent the command new
11/02/2013 03:18:28;0008;PBS_Server;Job;31398.tyrone-cluster;Job Modified at request of Scheduler@tyrone-cluster
11/02/2013 03:18:30;0040;PBS_Server;Svr;tyrone-cluster;Scheduler was sent the command new
11/02/2013 03:18:45;0040;PBS_Server;Svr;tyrone-cluster;Scheduler was sent the command new
11/02/2013 03:18:52;0100;PBS_Server;Job;31399.tyrone-cluster;enqueuing into batch, state 1 hop 1
11/02/2013 03:18:52;0008;PBS_Server;Job;31399.tyrone-cluster;Job Queued at request of secbadar@tyrone-cluster, owner = secbadar@tyrone-cluster, job name = Unif06Sch, queue = batch
11/02/2013 03:18:52;0040;PBS_Server;Svr;tyrone-cluster;Scheduler was sent the command new
11/02/2013 03:18:52;0008;PBS_Server;Job;31399.tyrone-cluster;Job Modified at request of Scheduler@tyrone-cluster
11/02/2013 03:18:57;0040;PBS_Server;Svr;tyrone-cluster;Scheduler was sent the command new
11/02/2013 03:18:59;0040;PBS_Server;Svr;tyrone-cluster;Scheduler was sent the command new
11/02/2013 03:19:03;0040;PBS_Server;Svr;tyrone-cluster;Scheduler was sent the command new
11/02/2013 03:19:15;0040;PBS_Server;Svr;tyrone-cluster;Scheduler was sent the command new
11/02/2013 03:19:26;0040;PBS_Server;Svr;tyrone-cluster;Scheduler was sent the command new
11/02/2013 03:19:27;0040;PBS_Server;Svr;tyrone-cluster;Scheduler was sent the command new
11/02/2013 03:19:38;0040;PBS_Server;Svr;tyrone-cluster;Scheduler was sent the command new
11/02/2013 03:19:44;0040;PBS_Server;Svr;tyrone-cluster;Scheduler was sent the command new
11/02/2013 03:19:55;0040;PBS_Server;Svr;tyrone-cluster;Scheduler was sent the command new
11/02/2013 03:19:57;0040;PBS_Server;Svr;tyrone-cluster;Scheduler was sent the command new
11/02/2013 03:20:00;0040;PBS_Server;Svr;tyrone-cluster;Scheduler was sent the command new
11/02/2013 03:20:11;0040;PBS_Server;Svr;tyrone-cluster;Scheduler was sent the command new
11/02/2013 03:20:23;0040;PBS_Server;Svr;tyrone-cluster;Scheduler was sent the command new
11/02/2013 03:20:27;0040;PBS_Server;Svr;tyrone-cluster;Scheduler was sent the command new
11/02/2013 03:20:31;0040;PBS_Server;Svr;tyrone-cluster;Scheduler was sent the command new
11/02/2013 03:20:40;0040;PBS_Server;Svr;tyrone-cluster;Scheduler was sent the command new
11/02/2013 03:20:45;0040;PBS_Server;Svr;tyrone-cluster;Scheduler was sent the command new
11/02/2013 03:20:57;0040;PBS_Server;Svr;tyrone-cluster;Scheduler was sent the command new
11/02/2013 03:21:08;0040;PBS_Server;Svr;tyrone-cluster;Scheduler was sent the command new
11/02/2013 03:21:12;0040;PBS_Server;Svr;tyrone-cluster;Scheduler was sent the command new
11/02/2013 03:21:18;0040;PBS_Server;Svr;tyrone-cluster;Scheduler was sent the command new
11/02/2013 03:21:28;0040;PBS_Server;Svr;tyrone-cluster;Scheduler was sent the command new
11/02/2013 03:21:41;0040;PBS_Server;Svr;tyrone-cluster;Scheduler was sent the command new
11/02/2013 03:21:42;0040;PBS_Server;Svr;tyrone-cluster;Scheduler was sent the command new
11/02/2013 03:21:53;0040;PBS_Server;Svr;tyrone-cluster;Scheduler was sent the command new
11/02/2013 03:21:57;0040;PBS_Server;Svr;tyrone-cluster;Scheduler was sent the command new
11/02/2013 03:22:10;0040;PBS_Server;Svr;tyrone-cluster;Scheduler was sent the command new
11/02/2013 03:22:14;0040;PBS_Server;Svr;tyrone-cluster;Scheduler was sent the command new
11/02/2013 03:22:26;0040;PBS_Server;Svr;tyrone-cluster;Scheduler was sent the command new
11/02/2013 03:22:27;0040;PBS_Server;Svr;tyrone-cluster;Scheduler was sent the command new
11/02/2013 03:22:41;0002;PBS_Server;Svr;PBS_Server;Torque Server Version = 3.0.5, loglevel = 0
11/02/2013 03:22:42;0040;PBS_Server;Svr;tyrone-cluster;Scheduler was sent the command new
11/02/2013 03:22:55;0040;PBS_Server;Svr;tyrone-cluster;Scheduler was sent the command new
11/02/2013 03:22:59;0040;PBS_Server;Svr;tyrone-cluster;Scheduler was sent the command new
11/02/2013 03:23:11;0040;PBS_Server;Svr;tyrone-cluster;Scheduler was sent the command new
11/02/2013 03:23:12;0040;PBS_Server;Svr;tyrone-cluster;Scheduler was sent the command new
11/02/2013 03:23:27;0040;PBS_Server;Svr;tyrone-cluster;Scheduler was sent the command new
11/02/2013 03:23:29;0040;PBS_Server;Svr;tyrone-cluster;Scheduler was sent the command new
11/02/2013 03:23:44;0040;PBS_Server;Svr;tyrone-cluster;Scheduler was sent the command new
11/02/2013 03:23:57;0040;PBS_Server;Svr;tyrone-cluster;Scheduler was sent the command new
11/02/2013 03:24:08;0040;PBS_Server;Svr;tyrone-cluster;Scheduler was sent the command new
11/02/2013 03:24:12;0040;PBS_Server;Svr;tyrone-cluster;Scheduler was sent the command new
11/02/2013 03:24:28;0040;PBS_Server;Svr;tyrone-cluster;Scheduler was sent the command new
11/02/2013 03:24:42;0040;PBS_Server;Svr;tyrone-cluster;Scheduler was sent the command new
11/02/2013 03:24:57;0040;PBS_Server;Svr;tyrone-cluster;Scheduler was sent the command new
11/02/2013 03:25:00;0040;PBS_Server;Svr;tyrone-cluster;Scheduler was sent the command new
11/02/2013 03:25:14;0040;PBS_Server;Svr;tyrone-cluster;Scheduler was sent the command new
11/02/2013 03:25:27;0040;PBS_Server;Svr;tyrone-cluster;Scheduler was sent the command new
11/02/2013 03:25:38;0040;PBS_Server;Svr;tyrone-cluster;Scheduler was sent the command new
11/02/2013 03:25:42;0040;PBS_Server;Svr;tyrone-cluster;Scheduler was sent the command new
11/02/2013 03:25:58;0040;PBS_Server;Svr;tyrone-cluster;Scheduler was sent the command new
11/02/2013 03:26:00;0040;PBS_Server;Svr;tyrone-cluster;Scheduler was sent the command new
11/02/2013 03:26:12;0040;PBS_Server;Svr;tyrone-cluster;Scheduler was sent the command new
11/02/2013 03:26:27;0040;PBS_Server;Svr;tyrone-cluster;Scheduler was sent the command new
11/02/2013 03:26:33;0040;PBS_Server;Svr;tyrone-cluster;Scheduler was sent the command new
11/02/2013 03:26:43;0040;PBS_Server;Svr;tyrone-cluster;Scheduler was sent the command new
11/02/2013 03:26:59;0040;PBS_Server;Svr;tyrone-cluster;Scheduler was sent the command new
11/02/2013 03:27:12;0040;PBS_Server;Svr;tyrone-cluster;Scheduler was sent the command new
11/02/2013 03:27:28;0040;PBS_Server;Svr;tyrone-cluster;Scheduler was sent the command new
11/02/2013 03:27:35;0040;PBS_Server;Svr;tyrone-cluster;Scheduler was sent the command new
11/02/2013 03:27:41;0002;PBS_Server;Svr;PBS_Server;Torque Server Version = 3.0.5, loglevel = 0
11/02/2013 03:27:42;0040;PBS_Server;Svr;tyrone-cluster;Scheduler was sent the command new
11/02/2013 03:27:57;0040;PBS_Server;Svr;tyrone-cluster;Scheduler was sent the command new
11/02/2013 03:28:09;0040;PBS_Server;Svr;tyrone-cluster;Scheduler was sent the command new
11/02/2013 03:28:14;0040;PBS_Server;Svr;tyrone-cluster;Scheduler was sent the command new
11/02/2013 03:28:27;0040;PBS_Server;Svr;tyrone-cluster;Scheduler was sent the command new
11/02/2013 03:28:38;0040;PBS_Server;Svr;tyrone-cluster;Scheduler was sent the command new
11/02/2013 03:28:42;0040;PBS_Server;Svr;tyrone-cluster;Scheduler was sent the command new
11/02/2013 03:28:58;0040;PBS_Server;Svr;tyrone-cluster;Scheduler was sent the command new
11/02/2013 03:29:11;0040;PBS_Server;Svr;tyrone-cluster;Scheduler was sent the command new
11/02/2013 03:29:12;0040;PBS_Server;Svr;tyrone-cluster;Scheduler was sent the command new
11/02/2013 03:29:27;0040;PBS_Server;Svr;tyrone-cluster;Scheduler was sent the command new
11/02/2013 03:29:40;0040;PBS_Server;Svr;tyrone-cluster;Scheduler was sent the command new
11/02/2013 03:29:44;0040;PBS_Server;Svr;tyrone-cluster;Scheduler was sent the command new
11/02/2013 03:29:57;0040;PBS_Server;Svr;tyrone-cluster;Scheduler was sent the command new
11/02/2013 03:30:12;0040;PBS_Server;Svr;tyrone-cluster;Scheduler was sent the command new
11/02/2013 03:30:14;0040;PBS_Server;Svr;tyrone-cluster;Scheduler was sent the command new
11/02/2013 03:30:29;0040;PBS_Server;Svr;tyrone-cluster;Scheduler was sent the command new
11/02/2013 03:30:29;000d;PBS_Server;Job;31390.tyrone-cluster;Not sending email: User does not want mail of this type.
11/02/2013 03:30:29;0010;PBS_Server;Job;31390.tyrone-cluster;Exit_status=0 resources_used.cput=08:55:51 resources_used.mem=2977356kb resources_used.vmem=38101160kb resources_used.walltime=00:18:17
11/02/2013 03:30:29;0008;PBS_Server;Job;NULL;on_job_exit valid pjob: 0x2df3ca0 (substate=50)
11/02/2013 03:30:29;0008;PBS_Server;Job;NULL;on_job_exit valid pjob: 0x2df3ca0 (substate=51)
11/02/2013 03:30:29;0008;PBS_Server;Job;NULL;on_job_exit valid pjob: 0x2df3ca0 (substate=51)
11/02/2013 03:30:29;0008;PBS_Server;Job;NULL;on_job_exit valid pjob: 0x2df3ca0 (substate=53)
11/02/2013 03:30:29;0100;PBS_Server;Job;31390.tyrone-cluster;dequeuing from qp256, state COMPLETE
11/02/2013 03:30:32;0008;PBS_Server;Job;31394.tyrone-cluster;Job Modified at request of Scheduler@tyrone-cluster
11/02/2013 03:30:32;0008;PBS_Server;Job;31394.tyrone-cluster;Job Run at request of Scheduler@tyrone-cluster
11/02/2013 03:30:32;0040;PBS_Server;Svr;tyrone-cluster;Scheduler was sent the command recyc
11/02/2013 03:30:42;0100;PBS_Server;Job;31395.tyrone-cluster;dequeuing from batch, state QUEUED
11/02/2013 03:30:42;0100;PBS_Server;Job;31395.tyrone-cluster;enqueuing into qp256, state 1 hop 1
11/02/2013 03:30:42;0040;PBS_Server;Svr;tyrone-cluster;Scheduler was sent the command new
11/02/2013 03:30:42;0008;PBS_Server;Job;31395.tyrone-cluster;Job Modified at request of Scheduler@tyrone-cluster
11/02/2013 03:30:53;0040;PBS_Server;Svr;tyrone-cluster;Scheduler was sent the command new
11/02/2013 03:30:57;0040;PBS_Server;Svr;tyrone-cluster;Scheduler was sent the command new
11/02/2013 03:31:14;0040;PBS_Server;Svr;tyrone-cluster;Scheduler was sent the command new
11/02/2013 03:31:19;000d;PBS_Server;Job;31394.tyrone-cluster;Not sending email: User does not want mail of this type.
11/02/2013 03:31:30;0040;PBS_Server;Svr;tyrone-cluster;Scheduler was sent the command new
11/02/2013 03:31:42;0040;PBS_Server;Svr;tyrone-cluster;Scheduler was sent the command new
11/02/2013 03:31:48;0040;PBS_Server;Svr;tyrone-cluster;Scheduler was sent the command new
11/02/2013 03:31:58;0040;PBS_Server;Svr;tyrone-cluster;Scheduler was sent the command new
11/02/2013 03:32:12;0040;PBS_Server;Svr;tyrone-cluster;Scheduler was sent the command new
11/02/2013 03:32:23;0040;PBS_Server;Svr;tyrone-cluster;Scheduler was sent the command new
11/02/2013 03:32:41;0002;PBS_Server;Svr;PBS_Server;Torque Server Version = 3.0.5, loglevel = 0
11/02/2013 03:32:43;0040;PBS_Server;Svr;tyrone-cluster;Scheduler was sent the command new
11/02/2013 03:32:56;0040;PBS_Server;Svr;tyrone-cluster;Scheduler was sent the command new
11/02/2013 03:32:59;0040;PBS_Server;Svr;tyrone-cluster;Scheduler was sent the command new
11/02/2013 03:33:14;0040;PBS_Server;Svr;tyrone-cluster;Scheduler was sent the command new
11/02/2013 03:33:28;0040;PBS_Server;Svr;tyrone-cluster;Scheduler was sent the command new
11/02/2013 03:33:45;0040;PBS_Server;Svr;tyrone-cluster;Scheduler was sent the command new
11/02/2013 03:33:57;0040;PBS_Server;Svr;tyrone-cluster;Scheduler was sent the command new
11/02/2013 03:34:14;0040;PBS_Server;Svr;tyrone-cluster;Scheduler was sent the command new
11/02/2013 03:34:27;0040;PBS_Server;Svr;tyrone-cluster;Scheduler was sent the command new
11/02/2013 03:34:44;0040;PBS_Server;Svr;tyrone-cluster;Scheduler was sent the command new
11/02/2013 03:34:58;0040;PBS_Server;Svr;tyrone-cluster;Scheduler was sent the command new
11/02/2013 03:35:23;0040;PBS_Server;Svr;tyrone-cluster;Scheduler was sent the command new
11/02/2013 03:35:27;0040;PBS_Server;Svr;tyrone-cluster;Scheduler was sent the command new
11/02/2013 03:35:45;0040;PBS_Server;Svr;tyrone-cluster;Scheduler was sent the command new
11/02/2013 03:35:58;0040;PBS_Server;Svr;tyrone-cluster;Scheduler was sent the command new
11/02/2013 03:36:19;0040;PBS_Server;Svr;tyrone-cluster;Scheduler was sent the command new
11/02/2013 03:36:29;0040;PBS_Server;Svr;tyrone-cluster;Scheduler was sent the command new
11/02/2013 03:36:53;0040;PBS_Server;Svr;tyrone-cluster;Scheduler was sent the command new
11/02/2013 03:36:57;0040;PBS_Server;Svr;tyrone-cluster;Scheduler was sent the command new
11/02/2013 03:37:25;0040;PBS_Server;Svr;tyrone-cluster;Scheduler was sent the command new
11/02/2013 03:37:27;0040;PBS_Server;Svr;tyrone-cluster;Scheduler was sent the command new
11/02/2013 03:37:41;0002;PBS_Server;Svr;PBS_Server;Torque Server Version = 3.0.5, loglevel = 0
11/02/2013 03:37:58;0040;PBS_Server;Svr;tyrone-cluster;Scheduler was sent the command new
11/02/2013 03:38:27;0040;PBS_Server;Svr;tyrone-cluster;Scheduler was sent the command new
11/02/2013 03:38:57;0040;PBS_Server;Svr;tyrone-cluster;Scheduler was sent the command new
11/02/2013 03:39:28;0040;PBS_Server;Svr;tyrone-cluster;Scheduler was sent the command new
11/02/2013 03:39:57;0040;PBS_Server;Svr;tyrone-cluster;Scheduler was sent the command new
11/02/2013 03:40:27;0040;PBS_Server;Svr;tyrone-cluster;Scheduler was sent the command new
11/02/2013 03:40:58;0040;PBS_Server;Svr;tyrone-cluster;Scheduler was sent the command new
11/02/2013 03:41:27;0040;PBS_Server;Svr;tyrone-cluster;Scheduler was sent the command new
11/02/2013 03:41:57;0040;PBS_Server;Svr;tyrone-cluster;Scheduler was sent the command new
11/02/2013 03:42:29;0040;PBS_Server;Svr;tyrone-cluster;Scheduler was sent the command new
11/02/2013 03:42:41;0002;PBS_Server;Svr;PBS_Server;Torque Server Version = 3.0.5, loglevel = 0
11/02/2013 03:42:57;0040;PBS_Server;Svr;tyrone-cluster;Scheduler was sent the command new
11/02/2013 03:43:27;0040;PBS_Server;Svr;tyrone-cluster;Scheduler was sent the command new
11/02/2013 03:43:58;0040;PBS_Server;Svr;tyrone-cluster;Scheduler was sent the command new
11/02/2013 03:44:27;0040;PBS_Server;Svr;tyrone-cluster;Scheduler was sent the command new
11/02/2013 03:44:57;0040;PBS_Server;Svr;tyrone-cluster;Scheduler was sent the command new
11/02/2013 03:45:29;0040;PBS_Server;Svr;tyrone-cluster;Scheduler was sent the command new
11/02/2013 03:45:57;0040;PBS_Server;Svr;tyrone-cluster;Scheduler was sent the command new
11/02/2013 03:46:27;0040;PBS_Server;Svr;tyrone-cluster;Scheduler was sent the command new
11/02/2013 03:46:58;0040;PBS_Server;Svr;tyrone-cluster;Scheduler was sent the command new
11/02/2013 03:47:27;0040;PBS_Server;Svr;tyrone-cluster;Scheduler was sent the command new
11/02/2013 03:47:41;0002;PBS_Server;Svr;PBS_Server;Torque Server Version = 3.0.5, loglevel = 0
11/02/2013 03:47:57;0040;PBS_Server;Svr;tyrone-cluster;Scheduler was sent the command new
11/02/2013 03:48:28;0040;PBS_Server;Svr;tyrone-cluster;Scheduler was sent the command new
11/02/2013 03:48:57;0040;PBS_Server;Svr;tyrone-cluster;Scheduler was sent the command new
11/02/2013 03:49:27;0040;PBS_Server;Svr;tyrone-cluster;Scheduler was sent the command new
11/02/2013 03:49:58;0040;PBS_Server;Svr;tyrone-cluster;Scheduler was sent the command new
11/02/2013 03:50:27;0040;PBS_Server;Svr;tyrone-cluster;Scheduler was sent the command new
11/02/2013 03:50:57;0040;PBS_Server;Svr;tyrone-cluster;Scheduler was sent the command new
11/02/2013 03:51:29;0040;PBS_Server;Svr;tyrone-cluster;Scheduler was sent the command new
11/02/2013 03:51:57;0040;PBS_Server;Svr;tyrone-cluster;Scheduler was sent the command new
11/02/2013 03:52:27;0040;PBS_Server;Svr;tyrone-cluster;Scheduler was sent the command new
11/02/2013 03:52:41;0002;PBS_Server;Svr;PBS_Server;Torque Server Version = 3.0.5, loglevel = 0
11/02/2013 03:52:59;0040;PBS_Server;Svr;tyrone-cluster;Scheduler was sent the command new
11/02/2013 03:53:27;0040;PBS_Server;Svr;tyrone-cluster;Scheduler was sent the command new
11/02/2013 03:53:57;0040;PBS_Server;Svr;tyrone-cluster;Scheduler was sent the command new
11/02/2013 03:54:29;0040;PBS_Server;Svr;tyrone-cluster;Scheduler was sent the command new
11/02/2013 03:54:57;0040;PBS_Server;Svr;tyrone-cluster;Scheduler was sent the command new
11/02/2013 03:55:27;0040;PBS_Server;Svr;tyrone-cluster;Scheduler was sent the command new
11/02/2013 03:56:00;0040;PBS_Server;Svr;tyrone-cluster;Scheduler was sent the command new
11/02/2013 03:56:29;0040;PBS_Server;Svr;tyrone-cluster;Scheduler was sent the command new
11/02/2013 03:57:08;0040;PBS_Server;Svr;tyrone-cluster;Scheduler was sent the command new
11/02/2013 03:57:30;0040;PBS_Server;Svr;tyrone-cluster;Scheduler was sent the command new
11/02/2013 03:57:41;0002;PBS_Server;Svr;PBS_Server;Torque Server Version = 3.0.5, loglevel = 0
11/02/2013 03:57:59;0040;PBS_Server;Svr;tyrone-cluster;Scheduler was sent the command new
11/02/2013 03:58:38;0040;PBS_Server;Svr;tyrone-cluster;Scheduler was sent the command new
11/02/2013 03:59:00;0040;PBS_Server;Svr;tyrone-cluster;Scheduler was sent the command new
11/02/2013 03:59:29;0040;PBS_Server;Svr;tyrone-cluster;Scheduler was sent the command new
11/02/2013 04:00:08;0040;PBS_Server;Svr;tyrone-cluster;Scheduler was sent the command new
11/02/2013 04:00:30;0040;PBS_Server;Svr;tyrone-cluster;Scheduler was sent the command new
11/02/2013 04:01:04;0040;PBS_Server;Svr;tyrone-cluster;Scheduler was sent the command new
11/02/2013 04:01:38;0040;PBS_Server;Svr;tyrone-cluster;Scheduler was sent the command new
11/02/2013 04:02:10;0040;PBS_Server;Svr;tyrone-cluster;Scheduler was sent the command new
11/02/2013 04:02:41;0002;PBS_Server;Svr;PBS_Server;Torque Server Version = 3.0.5, loglevel = 0
11/02/2013 04:02:41;0040;PBS_Server;Svr;tyrone-cluster;Scheduler was sent the command new
11/02/2013 04:03:12;0040;PBS_Server;Svr;tyrone-cluster;Scheduler was sent the command new
11/02/2013 04:03:44;0040;PBS_Server;Svr;tyrone-cluster;Scheduler was sent the command new
11/02/2013 04:04:14;0040;PBS_Server;Svr;tyrone-cluster;Scheduler was sent the command new
11/02/2013 04:04:42;0040;PBS_Server;Svr;tyrone-cluster;Scheduler was sent the command new
11/02/2013 04:05:12;0040;PBS_Server;Svr;tyrone-cluster;Scheduler was sent the command new
11/02/2013 04:05:44;0040;PBS_Server;Svr;tyrone-cluster;Scheduler was sent the command new
11/02/2013 04:06:12;0040;PBS_Server;Svr;tyrone-cluster;Scheduler was sent the command new
11/02/2013 04:06:44;0040;PBS_Server;Svr;tyrone-cluster;Scheduler was sent the command new
11/02/2013 04:07:14;0040;PBS_Server;Svr;tyrone-cluster;Scheduler was sent the command new
11/02/2013 04:07:41;0002;PBS_Server;Svr;PBS_Server;Torque Server Version = 3.0.5, loglevel = 0
11/02/2013 04:07:42;0040;PBS_Server;Svr;tyrone-cluster;Scheduler was sent the command new
11/02/2013 04:08:12;0040;PBS_Server;Svr;tyrone-cluster;Scheduler was sent the command new
11/02/2013 04:08:44;0040;PBS_Server;Svr;tyrone-cluster;Scheduler was sent the command new
11/02/2013 04:09:12;0040;PBS_Server;Svr;tyrone-cluster;Scheduler was sent the command new
11/02/2013 04:09:44;0040;PBS_Server;Svr;tyrone-cluster;Scheduler was sent the command new
11/02/2013 04:10:14;0040;PBS_Server;Svr;tyrone-cluster;Scheduler was sent the command new
11/02/2013 04:10:42;0040;PBS_Server;Svr;tyrone-cluster;Scheduler was sent the command new
11/02/2013 04:11:12;0040;PBS_Server;Svr;tyrone-cluster;Scheduler was sent the command new
11/02/2013 04:11:45;0040;PBS_Server;Svr;tyrone-cluster;Scheduler was sent the command new
11/02/2013 04:12:14;0040;PBS_Server;Svr;tyrone-cluster;Scheduler was sent the command new
11/02/2013 04:12:41;0002;PBS_Server;Svr;PBS_Server;Torque Server Version = 3.0.5, loglevel = 0
11/02/2013 04:12:45;0040;PBS_Server;Svr;tyrone-cluster;Scheduler was sent the command new
11/02/2013 04:13:15;0040;PBS_Server;Svr;tyrone-cluster;Scheduler was sent the command new
11/02/2013 04:13:44;0040;PBS_Server;Svr;tyrone-cluster;Scheduler was sent the command new
11/02/2013 04:14:22;0040;PBS_Server;Svr;tyrone-cluster;Scheduler was sent the command new
11/02/2013 04:14:45;0040;PBS_Server;Svr;tyrone-cluster;Scheduler was sent the command new
11/02/2013 04:15:15;0040;PBS_Server;Svr;tyrone-cluster;Scheduler was sent the command new
11/02/2013 04:15:53;0040;PBS_Server;Svr;tyrone-cluster;Scheduler was sent the command new
11/02/2013 04:16:14;0040;PBS_Server;Svr;tyrone-cluster;Scheduler was sent the command new
11/02/2013 04:16:44;0040;PBS_Server;Svr;tyrone-cluster;Scheduler was sent the command new
11/02/2013 04:17:23;0040;PBS_Server;Svr;tyrone-cluster;Scheduler was sent the command new
11/02/2013 04:17:41;0002;PBS_Server;Svr;PBS_Server;Torque Server Version = 3.0.5, loglevel = 0
11/02/2013 04:17:45;0040;PBS_Server;Svr;tyrone-cluster;Scheduler was sent the command new
11/02/2013 04:18:14;0040;PBS_Server;Svr;tyrone-cluster;Scheduler was sent the command new
11/02/2013 04:18:52;0040;PBS_Server;Svr;tyrone-cluster;Scheduler was sent the command new
11/02/2013 04:19:15;0040;PBS_Server;Svr;tyrone-cluster;Scheduler was sent the command new
11/02/2013 04:19:45;0040;PBS_Server;Svr;tyrone-cluster;Scheduler was sent the command new
11/02/2013 04:20:23;0040;PBS_Server;Svr;tyrone-cluster;Scheduler was sent the command new
11/02/2013 04:20:45;0040;PBS_Server;Svr;tyrone-cluster;Scheduler was sent the command new
11/02/2013 04:21:14;0040;PBS_Server;Svr;tyrone-cluster;Scheduler was sent the command new
11/02/2013 04:21:53;0040;PBS_Server;Svr;tyrone-cluster;Scheduler was sent the command new
11/02/2013 04:22:15;0040;PBS_Server;Svr;tyrone-cluster;Scheduler was sent the command new
11/02/2013 04:22:41;0002;PBS_Server;Svr;PBS_Server;Torque Server Version = 3.0.5, loglevel = 0
11/02/2013 04:22:44;0040;PBS_Server;Svr;tyrone-cluster;Scheduler was sent the command new
11/02/2013 04:23:23;0040;PBS_Server;Svr;tyrone-cluster;Scheduler was sent the command new
11/02/2013 04:23:44;0040;PBS_Server;Svr;tyrone-cluster;Scheduler was sent the command new
11/02/2013 04:24:15;0040;PBS_Server;Svr;tyrone-cluster;Scheduler was sent the command new
11/02/2013 04:24:53;0040;PBS_Server;Svr;tyrone-cluster;Scheduler was sent the command new
11/02/2013 04:25:15;0040;PBS_Server;Svr;tyrone-cluster;Scheduler was sent the command new
11/02/2013 04:25:44;0040;PBS_Server;Svr;tyrone-cluster;Scheduler was sent the command new
11/02/2013 04:26:14;0040;PBS_Server;Svr;tyrone-cluster;Scheduler was sent the command new
11/02/2013 04:26:45;0040;PBS_Server;Svr;tyrone-cluster;Scheduler was sent the command new
11/02/2013 04:27:14;0040;PBS_Server;Svr;tyrone-cluster;Scheduler was sent the command new
11/02/2013 04:27:41;0002;PBS_Server;Svr;PBS_Server;Torque Server Version = 3.0.5, loglevel = 0
11/02/2013 04:27:44;0040;PBS_Server;Svr;tyrone-cluster;Scheduler was sent the command new
11/02/2013 04:28:15;0040;PBS_Server;Svr;tyrone-cluster;Scheduler was sent the command new
11/02/2013 04:28:44;0040;PBS_Server;Svr;tyrone-cluster;Scheduler was sent the command new
11/02/2013 04:29:23;0040;PBS_Server;Svr;tyrone-cluster;Scheduler was sent the command new
11/02/2013 04:29:56;0040;PBS_Server;Svr;tyrone-cluster;Scheduler was sent the command new
11/02/2013 04:30:28;0040;PBS_Server;Svr;tyrone-cluster;Scheduler was sent the command new
11/02/2013 04:30:57;0040;PBS_Server;Svr;tyrone-cluster;Scheduler was sent the command new
11/02/2013 04:31:27;0040;PBS_Server;Svr;tyrone-cluster;Scheduler was sent the command new
11/02/2013 04:31:59;0040;PBS_Server;Svr;tyrone-cluster;Scheduler was sent the command new
11/02/2013 04:32:27;0040;PBS_Server;Svr;tyrone-cluster;Scheduler was sent the command new
11/02/2013 04:32:41;0002;PBS_Server;Svr;PBS_Server;Torque Server Version = 3.0.5, loglevel = 0
11/02/2013 04:32:57;0040;PBS_Server;Svr;tyrone-cluster;Scheduler was sent the command new
11/02/2013 04:33:29;0040;PBS_Server;Svr;tyrone-cluster;Scheduler was sent the command new
11/02/2013 04:33:57;0040;PBS_Server;Svr;tyrone-cluster;Scheduler was sent the command new
11/02/2013 04:34:27;0040;PBS_Server;Svr;tyrone-cluster;Scheduler was sent the command new
11/02/2013 04:34:58;0040;PBS_Server;Svr;tyrone-cluster;Scheduler was sent the command new
11/02/2013 04:35:27;0040;PBS_Server;Svr;tyrone-cluster;Scheduler was sent the command new
11/02/2013 04:35:57;0040;PBS_Server;Svr;tyrone-cluster;Scheduler was sent the command new
11/02/2013 04:36:30;0040;PBS_Server;Svr;tyrone-cluster;Scheduler was sent the command new
11/02/2013 04:36:59;0040;PBS_Server;Svr;tyrone-cluster;Scheduler was sent the command new
11/02/2013 04:37:38;0040;PBS_Server;Svr;tyrone-cluster;Scheduler was sent the command new
11/02/2013 04:37:41;0002;PBS_Server;Svr;PBS_Server;Torque Server Version = 3.0.5, loglevel = 0
11/02/2013 04:38:11;0040;PBS_Server;Svr;tyrone-cluster;Scheduler was sent the command new
11/02/2013 04:38:43;0040;PBS_Server;Svr;tyrone-cluster;Scheduler was sent the command new
11/02/2013 04:39:12;0040;PBS_Server;Svr;tyrone-cluster;Scheduler was sent the command new
11/02/2013 04:39:42;0040;PBS_Server;Svr;tyrone-cluster;Scheduler was sent the command new
11/02/2013 04:40:14;0040;PBS_Server;Svr;tyrone-cluster;Scheduler was sent the command new
11/02/2013 04:40:42;0040;PBS_Server;Svr;tyrone-cluster;Scheduler was sent the command new
11/02/2013 04:41:12;0040;PBS_Server;Svr;tyrone-cluster;Scheduler was sent the command new
11/02/2013 04:41:44;0040;PBS_Server;Svr;tyrone-cluster;Scheduler was sent the command new
11/02/2013 04:42:12;0040;PBS_Server;Svr;tyrone-cluster;Scheduler was sent the command new
11/02/2013 04:42:41;0002;PBS_Server;Svr;PBS_Server;Torque Server Version = 3.0.5, loglevel = 0
11/02/2013 04:42:42;0040;PBS_Server;Svr;tyrone-cluster;Scheduler was sent the command new
11/02/2013 04:43:15;0040;PBS_Server;Svr;tyrone-cluster;Scheduler was sent the command new
11/02/2013 04:43:44;0040;PBS_Server;Svr;tyrone-cluster;Scheduler was sent the command new
11/02/2013 04:44:22;0040;PBS_Server;Svr;tyrone-cluster;Scheduler was sent the command new
11/02/2013 04:44:56;0040;PBS_Server;Svr;tyrone-cluster;Scheduler was sent the command new
11/02/2013 04:45:29;0040;PBS_Server;Svr;tyrone-cluster;Scheduler was sent the command new
11/02/2013 04:45:57;0040;PBS_Server;Svr;tyrone-cluster;Scheduler was sent the command new
11/02/2013 04:46:27;0040;PBS_Server;Svr;tyrone-cluster;Scheduler was sent the command new
11/02/2013 04:47:00;0040;PBS_Server;Svr;tyrone-cluster;Scheduler was sent the command new
11/02/2013 04:47:29;0040;PBS_Server;Svr;tyrone-cluster;Scheduler was sent the command new
11/02/2013 04:47:41;0002;PBS_Server;Svr;PBS_Server;Torque Server Version = 3.0.5, loglevel = 0
11/02/2013 04:48:00;0040;PBS_Server;Svr;tyrone-cluster;Scheduler was sent the command new
11/02/2013 04:48:30;0040;PBS_Server;Svr;tyrone-cluster;Scheduler was sent the command new
11/02/2013 04:48:59;0040;PBS_Server;Svr;tyrone-cluster;Scheduler was sent the command new
11/02/2013 04:49:37;0040;PBS_Server;Svr;tyrone-cluster;Scheduler was sent the command new
11/02/2013 04:50:10;0040;PBS_Server;Svr;tyrone-cluster;Scheduler was sent the command new
11/02/2013 04:50:42;0040;PBS_Server;Svr;tyrone-cluster;Scheduler was sent the command new
11/02/2013 04:51:12;0040;PBS_Server;Svr;tyrone-cluster;Scheduler was sent the command new
11/02/2013 04:51:42;0040;PBS_Server;Svr;tyrone-cluster;Scheduler was sent the command new
11/02/2013 04:52:14;0040;PBS_Server;Svr;tyrone-cluster;Scheduler was sent the command new
11/02/2013 04:52:41;0002;PBS_Server;Svr;PBS_Server;Torque Server Version = 3.0.5, loglevel = 0
11/02/2013 04:52:42;0040;PBS_Server;Svr;tyrone-cluster;Scheduler was sent the command new
11/02/2013 04:53:12;0040;PBS_Server;Svr;tyrone-cluster;Scheduler was sent the command new
11/02/2013 04:53:44;0040;PBS_Server;Svr;tyrone-cluster;Scheduler was sent the command new
11/02/2013 04:54:14;0040;PBS_Server;Svr;tyrone-cluster;Scheduler was sent the command new
11/02/2013 04:54:53;0040;PBS_Server;Svr;tyrone-cluster;Scheduler was sent the command new
11/02/2013 04:55:25;0040;PBS_Server;Svr;tyrone-cluster;Scheduler was sent the command new
11/02/2013 04:55:58;0040;PBS_Server;Svr;tyrone-cluster;Scheduler was sent the command new
11/02/2013 04:56:27;0040;PBS_Server;Svr;tyrone-cluster;Scheduler was sent the command new
11/02/2013 04:56:57;0040;PBS_Server;Svr;tyrone-cluster;Scheduler was sent the command new
11/02/2013 04:57:29;0040;PBS_Server;Svr;tyrone-cluster;Scheduler was sent the command new
11/02/2013 04:57:41;0002;PBS_Server;Svr;PBS_Server;Torque Server Version = 3.0.5, loglevel = 0
11/02/2013 04:57:59;0040;PBS_Server;Svr;tyrone-cluster;Scheduler was sent the command new
11/02/2013 04:58:38;0040;PBS_Server;Svr;tyrone-cluster;Scheduler was sent the command new
11/02/2013 04:59:10;0040;PBS_Server;Svr;tyrone-cluster;Scheduler was sent the command new
11/02/2013 04:59:43;0040;PBS_Server;Svr;tyrone-cluster;Scheduler was sent the command new
11/02/2013 05:00:12;0040;PBS_Server;Svr;tyrone-cluster;Scheduler was sent the command new
11/02/2013 05:00:42;0040;PBS_Server;Svr;tyrone-cluster;Scheduler was sent the command new
11/02/2013 05:01:13;0040;PBS_Server;Svr;tyrone-cluster;Scheduler was sent the command new
11/02/2013 05:01:42;0040;PBS_Server;Svr;tyrone-cluster;Scheduler was sent the command new
11/02/2013 05:02:14;0040;PBS_Server;Svr;tyrone-cluster;Scheduler was sent the command new
11/02/2013 05:02:41;0002;PBS_Server;Svr;PBS_Server;Torque Server Version = 3.0.5, loglevel = 0
11/02/2013 05:02:44;0040;PBS_Server;Svr;tyrone-cluster;Scheduler was sent the command new
11/02/2013 05:03:14;0040;PBS_Server;Svr;tyrone-cluster;Scheduler was sent the command new
11/02/2013 05:03:53;0040;PBS_Server;Svr;tyrone-cluster;Scheduler was sent the command new
11/02/2013 05:04:15;0040;PBS_Server;Svr;tyrone-cluster;Scheduler was sent the command new
11/02/2013 05:04:48;0040;PBS_Server;Svr;tyrone-cluster;Scheduler was sent the command new
11/02/2013 05:05:23;0040;PBS_Server;Svr;tyrone-cluster;Scheduler was sent the command new
11/02/2013 05:05:54;0040;PBS_Server;Svr;tyrone-cluster;Scheduler was sent the command new
11/02/2013 05:06:27;0040;PBS_Server;Svr;tyrone-cluster;Scheduler was sent the command new
11/02/2013 05:06:53;0040;PBS_Server;Svr;tyrone-cluster;Scheduler was sent the command new
11/02/2013 05:07:25;0040;PBS_Server;Svr;tyrone-cluster;Scheduler was sent the command new
11/02/2013 05:07:41;0002;PBS_Server;Svr;PBS_Server;Torque Server Version = 3.0.5, loglevel = 0
11/02/2013 05:07:58;0040;PBS_Server;Svr;tyrone-cluster;Scheduler was sent the command new
11/02/2013 05:08:29;0040;PBS_Server;Svr;tyrone-cluster;Scheduler was sent the command new
11/02/2013 05:09:07;0040;PBS_Server;Svr;tyrone-cluster;Scheduler was sent the command new
11/02/2013 05:09:30;0040;PBS_Server;Svr;tyrone-cluster;Scheduler was sent the command new
11/02/2013 05:09:59;0040;PBS_Server;Svr;tyrone-cluster;Scheduler was sent the command new
11/02/2013 05:10:37;0040;PBS_Server;Svr;tyrone-cluster;Scheduler was sent the command new
11/02/2013 05:11:10;0040;PBS_Server;Svr;tyrone-cluster;Scheduler was sent the command new
11/02/2013 05:11:43;0040;PBS_Server;Svr;tyrone-cluster;Scheduler was sent the command new
11/02/2013 05:12:12;0040;PBS_Server;Svr;tyrone-cluster;Scheduler was sent the command new
11/02/2013 05:12:41;0002;PBS_Server;Svr;PBS_Server;Torque Server Version = 3.0.5, loglevel = 0
11/02/2013 05:12:42;0040;PBS_Server;Svr;tyrone-cluster;Scheduler was sent the command new
11/02/2013 05:13:14;0040;PBS_Server;Svr;tyrone-cluster;Scheduler was sent the command new
11/02/2013 05:13:44;0040;PBS_Server;Svr;tyrone-cluster;Scheduler was sent the command new
11/02/2013 05:14:23;0040;PBS_Server;Svr;tyrone-cluster;Scheduler was sent the command new
11/02/2013 05:14:46;0040;PBS_Server;Svr;tyrone-cluster;Scheduler was sent the command new
11/02/2013 05:15:18;0040;PBS_Server;Svr;tyrone-cluster;Scheduler was sent the command new
11/02/2013 05:15:53;0040;PBS_Server;Svr;tyrone-cluster;Scheduler was sent the command new
11/02/2013 05:16:25;0040;PBS_Server;Svr;tyrone-cluster;Scheduler was sent the command new
11/02/2013 05:16:58;0040;PBS_Server;Svr;tyrone-cluster;Scheduler was sent the command new
11/02/2013 05:17:27;0040;PBS_Server;Svr;tyrone-cluster;Scheduler was sent the command new
11/02/2013 05:17:41;0002;PBS_Server;Svr;PBS_Server;Torque Server Version = 3.0.5, loglevel = 0
11/02/2013 05:17:57;0040;PBS_Server;Svr;tyrone-cluster;Scheduler was sent the command new
11/02/2013 05:18:28;0040;PBS_Server;Svr;tyrone-cluster;Scheduler was sent the command new
11/02/2013 05:18:59;0040;PBS_Server;Svr;tyrone-cluster;Scheduler was sent the command new
11/02/2013 05:19:31;0040;PBS_Server;Svr;tyrone-cluster;Scheduler was sent the command new
11/02/2013 05:20:00;0040;PBS_Server;Svr;tyrone-cluster;Scheduler was sent the command new
11/02/2013 05:20:29;0040;PBS_Server;Svr;tyrone-cluster;Scheduler was sent the command new
11/02/2013 05:21:08;0040;PBS_Server;Svr;tyrone-cluster;Scheduler was sent the command new
11/02/2013 05:21:40;0040;PBS_Server;Svr;tyrone-cluster;Scheduler was sent the command new
11/02/2013 05:22:13;0040;PBS_Server;Svr;tyrone-cluster;Scheduler was sent the command new
11/02/2013 05:22:41;0002;PBS_Server;Svr;PBS_Server;Torque Server Version = 3.0.5, loglevel = 0
11/02/2013 05:22:42;0040;PBS_Server;Svr;tyrone-cluster;Scheduler was sent the command new
11/02/2013 05:23:12;0040;PBS_Server;Svr;tyrone-cluster;Scheduler was sent the command new
11/02/2013 05:23:43;0040;PBS_Server;Svr;tyrone-cluster;Scheduler was sent the command new
11/02/2013 05:24:12;0040;PBS_Server;Svr;tyrone-cluster;Scheduler was sent the command new
11/02/2013 05:24:42;0040;PBS_Server;Svr;tyrone-cluster;Scheduler was sent the command new
11/02/2013 05:25:12;0040;PBS_Server;Svr;tyrone-cluster;Scheduler was sent the command new
11/02/2013 05:25:42;0040;PBS_Server;Svr;tyrone-cluster;Scheduler was sent the command new
11/02/2013 05:26:12;0040;PBS_Server;Svr;tyrone-cluster;Scheduler was sent the command new
11/02/2013 05:26:43;0040;PBS_Server;Svr;tyrone-cluster;Scheduler was sent the command new
11/02/2013 05:27:12;0040;PBS_Server;Svr;tyrone-cluster;Scheduler was sent the command new
11/02/2013 05:27:41;0002;PBS_Server;Svr;PBS_Server;Torque Server Version = 3.0.5, loglevel = 0
11/02/2013 05:27:42;0040;PBS_Server;Svr;tyrone-cluster;Scheduler was sent the command new
11/02/2013 05:28:13;0040;PBS_Server;Svr;tyrone-cluster;Scheduler was sent the command new
11/02/2013 05:28:42;0040;PBS_Server;Svr;tyrone-cluster;Scheduler was sent the command new
11/02/2013 05:29:12;0040;PBS_Server;Svr;tyrone-cluster;Scheduler was sent the command new
11/02/2013 05:29:42;0040;PBS_Server;Svr;tyrone-cluster;Scheduler was sent the command new
11/02/2013 05:30:12;0040;PBS_Server;Svr;tyrone-cluster;Scheduler was sent the command new
11/02/2013 05:30:42;0040;PBS_Server;Svr;tyrone-cluster;Scheduler was sent the command new
11/02/2013 05:31:13;0040;PBS_Server;Svr;tyrone-cluster;Scheduler was sent the command new
11/02/2013 05:31:44;0040;PBS_Server;Svr;tyrone-cluster;Scheduler was sent the command new
11/02/2013 05:32:23;0040;PBS_Server;Svr;tyrone-cluster;Scheduler was sent the command new
11/02/2013 05:32:41;0002;PBS_Server;Svr;PBS_Server;Torque Server Version = 3.0.5, loglevel = 0
11/02/2013 05:32:55;0040;PBS_Server;Svr;tyrone-cluster;Scheduler was sent the command new
11/02/2013 05:33:28;0040;PBS_Server;Svr;tyrone-cluster;Scheduler was sent the command new
11/02/2013 05:33:57;0040;PBS_Server;Svr;tyrone-cluster;Scheduler was sent the command new
11/02/2013 05:34:27;0040;PBS_Server;Svr;tyrone-cluster;Scheduler was sent the command new
11/02/2013 05:34:57;0040;PBS_Server;Svr;tyrone-cluster;Scheduler was sent the command new
11/02/2013 05:35:28;0040;PBS_Server;Svr;tyrone-cluster;Scheduler was sent the command new
11/02/2013 05:35:58;0040;PBS_Server;Svr;tyrone-cluster;Scheduler was sent the command new
11/02/2013 05:36:31;0040;PBS_Server;Svr;tyrone-cluster;Scheduler was sent the command new
11/02/2013 05:36:58;0040;PBS_Server;Svr;tyrone-cluster;Scheduler was sent the command new
11/02/2013 05:37:28;0040;PBS_Server;Svr;tyrone-cluster;Scheduler was sent the command new
11/02/2013 05:37:41;0002;PBS_Server;Svr;PBS_Server;Torque Server Version = 3.0.5, loglevel = 0
11/02/2013 05:38:01;0040;PBS_Server;Svr;tyrone-cluster;Scheduler was sent the command new
11/02/2013 05:38:32;0040;PBS_Server;Svr;tyrone-cluster;Scheduler was sent the command new
11/02/2013 05:39:07;0040;PBS_Server;Svr;tyrone-cluster;Scheduler was sent the command new
11/02/2013 05:39:41;0040;PBS_Server;Svr;tyrone-cluster;Scheduler was sent the command new
11/02/2013 05:40:13;0040;PBS_Server;Svr;tyrone-cluster;Scheduler was sent the command new
11/02/2013 05:40:43;0040;PBS_Server;Svr;tyrone-cluster;Scheduler was sent the command new
11/02/2013 05:41:13;0040;PBS_Server;Svr;tyrone-cluster;Scheduler was sent the command new
11/02/2013 05:41:43;0040;PBS_Server;Svr;tyrone-cluster;Scheduler was sent the command new
11/02/2013 05:42:13;0040;PBS_Server;Svr;tyrone-cluster;Scheduler was sent the command new
11/02/2013 05:42:41;0002;PBS_Server;Svr;PBS_Server;Torque Server Version = 3.0.5, loglevel = 0
11/02/2013 05:42:43;0040;PBS_Server;Svr;tyrone-cluster;Scheduler was sent the command new
11/02/2013 05:43:16;0040;PBS_Server;Svr;tyrone-cluster;Scheduler was sent the command new
11/02/2013 05:43:43;0040;PBS_Server;Svr;tyrone-cluster;Scheduler was sent the command new
11/02/2013 05:44:13;0040;PBS_Server;Svr;tyrone-cluster;Scheduler was sent the command new
11/02/2013 05:44:46;0040;PBS_Server;Svr;tyrone-cluster;Scheduler was sent the command new
11/02/2013 05:45:19;0040;PBS_Server;Svr;tyrone-cluster;Scheduler was sent the command new
11/02/2013 05:45:53;0040;PBS_Server;Svr;tyrone-cluster;Scheduler was sent the command new
11/02/2013 05:46:26;0040;PBS_Server;Svr;tyrone-cluster;Scheduler was sent the command new
11/02/2013 05:46:57;0040;PBS_Server;Svr;tyrone-cluster;Scheduler was sent the command new
11/02/2013 05:47:28;0040;PBS_Server;Svr;tyrone-cluster;Scheduler was sent the command new
11/02/2013 05:47:41;0002;PBS_Server;Svr;PBS_Server;Torque Server Version = 3.0.5, loglevel = 0
11/02/2013 05:47:58;0040;PBS_Server;Svr;tyrone-cluster;Scheduler was sent the command new
11/02/2013 05:48:31;0040;PBS_Server;Svr;tyrone-cluster;Scheduler was sent the command new
11/02/2013 05:48:58;0040;PBS_Server;Svr;tyrone-cluster;Scheduler was sent the command new
11/02/2013 05:49:28;0040;PBS_Server;Svr;tyrone-cluster;Scheduler was sent the command new
11/02/2013 05:50:01;0040;PBS_Server;Svr;tyrone-cluster;Scheduler was sent the command new
11/02/2013 05:50:33;0040;PBS_Server;Svr;tyrone-cluster;Scheduler was sent the command new
11/02/2013 05:51:07;0040;PBS_Server;Svr;tyrone-cluster;Scheduler was sent the command new
11/02/2013 05:51:41;0040;PBS_Server;Svr;tyrone-cluster;Scheduler was sent the command new
11/02/2013 05:52:12;0040;PBS_Server;Svr;tyrone-cluster;Scheduler was sent the command new
11/02/2013 05:52:41;0002;PBS_Server;Svr;PBS_Server;Torque Server Version = 3.0.5, loglevel = 0
11/02/2013 05:52:43;0040;PBS_Server;Svr;tyrone-cluster;Scheduler was sent the command new
11/02/2013 05:53:13;0040;PBS_Server;Svr;tyrone-cluster;Scheduler was sent the command new
11/02/2013 05:53:44;0040;PBS_Server;Svr;tyrone-cluster;Scheduler was sent the command new
11/02/2013 05:54:13;0040;PBS_Server;Svr;tyrone-cluster;Scheduler was sent the command new
11/02/2013 05:54:43;0040;PBS_Server;Svr;tyrone-cluster;Scheduler was sent the command new
11/02/2013 05:55:16;0040;PBS_Server;Svr;tyrone-cluster;Scheduler was sent the command new
11/02/2013 05:55:48;0040;PBS_Server;Svr;tyrone-cluster;Scheduler was sent the command new
11/02/2013 05:56:22;0040;PBS_Server;Svr;tyrone-cluster;Scheduler was sent the command new
11/02/2013 05:56:56;0040;PBS_Server;Svr;tyrone-cluster;Scheduler was sent the command new
11/02/2013 05:57:27;0040;PBS_Server;Svr;tyrone-cluster;Scheduler was sent the command new
11/02/2013 05:57:41;0002;PBS_Server;Svr;PBS_Server;Torque Server Version = 3.0.5, loglevel = 0
11/02/2013 05:57:58;0040;PBS_Server;Svr;tyrone-cluster;Scheduler was sent the command new
11/02/2013 05:58:28;0040;PBS_Server;Svr;tyrone-cluster;Scheduler was sent the command new
11/02/2013 05:59:01;0040;PBS_Server;Svr;tyrone-cluster;Scheduler was sent the command new
11/02/2013 05:59:28;0040;PBS_Server;Svr;tyrone-cluster;Scheduler was sent the command new
11/02/2013 05:59:58;0040;PBS_Server;Svr;tyrone-cluster;Scheduler was sent the command new
11/02/2013 06:00:31;0040;PBS_Server;Svr;tyrone-cluster;Scheduler was sent the command new
11/02/2013 06:01:03;0040;PBS_Server;Svr;tyrone-cluster;Scheduler was sent the command new
11/02/2013 06:01:37;0040;PBS_Server;Svr;tyrone-cluster;Scheduler was sent the command new
11/02/2013 06:02:11;0040;PBS_Server;Svr;tyrone-cluster;Scheduler was sent the command new
11/02/2013 06:02:41;0002;PBS_Server;Svr;PBS_Server;Torque Server Version = 3.0.5, loglevel = 0
11/02/2013 06:02:42;0040;PBS_Server;Svr;tyrone-cluster;Scheduler was sent the command new
11/02/2013 06:03:13;0040;PBS_Server;Svr;tyrone-cluster;Scheduler was sent the command new
11/02/2013 06:03:42;0040;PBS_Server;Svr;tyrone-cluster;Scheduler was sent the command new
11/02/2013 06:04:13;0040;PBS_Server;Svr;tyrone-cluster;Scheduler was sent the command new
11/02/2013 06:04:43;0040;PBS_Server;Svr;tyrone-cluster;Scheduler was sent the command new
11/02/2013 06:05:13;0040;PBS_Server;Svr;tyrone-cluster;Scheduler was sent the command new
11/02/2013 06:05:46;0040;PBS_Server;Svr;tyrone-cluster;Scheduler was sent the command new
11/02/2013 06:06:18;0040;PBS_Server;Svr;tyrone-cluster;Scheduler was sent the command new
11/02/2013 06:06:52;0040;PBS_Server;Svr;tyrone-cluster;Scheduler was sent the command new
11/02/2013 06:07:26;0040;PBS_Server;Svr;tyrone-cluster;Scheduler was sent the command new
11/02/2013 06:07:41;0002;PBS_Server;Svr;PBS_Server;Torque Server Version = 3.0.5, loglevel = 0
11/02/2013 06:07:57;0040;PBS_Server;Svr;tyrone-cluster;Scheduler was sent the command new
11/02/2013 06:08:28;0040;PBS_Server;Svr;tyrone-cluster;Scheduler was sent the command new
11/02/2013 06:08:58;0040;PBS_Server;Svr;tyrone-cluster;Scheduler was sent the command new
11/02/2013 06:09:31;0040;PBS_Server;Svr;tyrone-cluster;Scheduler was sent the command new
11/02/2013 06:09:58;0040;PBS_Server;Svr;tyrone-cluster;Scheduler was sent the command new
11/02/2013 06:10:28;0040;PBS_Server;Svr;tyrone-cluster;Scheduler was sent the command new
11/02/2013 06:11:01;0040;PBS_Server;Svr;tyrone-cluster;Scheduler was sent the command new
11/02/2013 06:11:28;0040;PBS_Server;Svr;tyrone-cluster;Scheduler was sent the command new
11/02/2013 06:11:58;0040;PBS_Server;Svr;tyrone-cluster;Scheduler was sent the command new
11/02/2013 06:12:31;0040;PBS_Server;Svr;tyrone-cluster;Scheduler was sent the command new
11/02/2013 06:12:41;0002;PBS_Server;Svr;PBS_Server;Torque Server Version = 3.0.5, loglevel = 0
11/02/2013 06:13:03;0040;PBS_Server;Svr;tyrone-cluster;Scheduler was sent the command new
11/02/2013 06:13:37;0040;PBS_Server;Svr;tyrone-cluster;Scheduler was sent the command new
11/02/2013 06:14:11;0040;PBS_Server;Svr;tyrone-cluster;Scheduler was sent the command new
11/02/2013 06:14:43;0040;PBS_Server;Svr;tyrone-cluster;Scheduler was sent the command new
11/02/2013 06:15:13;0040;PBS_Server;Svr;tyrone-cluster;Scheduler was sent the command new
11/02/2013 06:15:43;0040;PBS_Server;Svr;tyrone-cluster;Scheduler was sent the command new
11/02/2013 06:16:16;0040;PBS_Server;Svr;tyrone-cluster;Scheduler was sent the command new
11/02/2013 06:16:47;0040;PBS_Server;Svr;tyrone-cluster;Scheduler was sent the command new
11/02/2013 06:17:22;0040;PBS_Server;Svr;tyrone-cluster;Scheduler was sent the command new
11/02/2013 06:17:41;0002;PBS_Server;Svr;PBS_Server;Torque Server Version = 3.0.5, loglevel = 0
11/02/2013 06:17:46;0040;PBS_Server;Svr;tyrone-cluster;Scheduler was sent the command new
11/02/2013 06:18:18;0040;PBS_Server;Svr;tyrone-cluster;Scheduler was sent the command new
11/02/2013 06:18:52;0040;PBS_Server;Svr;tyrone-cluster;Scheduler was sent the command new
11/02/2013 06:19:21;0040;PBS_Server;Svr;tyrone-cluster;Scheduler was sent the command new
11/02/2013 06:19:57;0040;PBS_Server;Svr;tyrone-cluster;Scheduler was sent the command new
11/02/2013 06:20:23;0040;PBS_Server;Svr;tyrone-cluster;Scheduler was sent the command new
11/02/2013 06:20:56;0040;PBS_Server;Svr;tyrone-cluster;Scheduler was sent the command new
11/02/2013 06:21:27;0040;PBS_Server;Svr;tyrone-cluster;Scheduler was sent the command new
11/02/2013 06:21:58;0040;PBS_Server;Svr;tyrone-cluster;Scheduler was sent the command new
11/02/2013 06:22:28;0040;PBS_Server;Svr;tyrone-cluster;Scheduler was sent the command new
11/02/2013 06:22:41;0002;PBS_Server;Svr;PBS_Server;Torque Server Version = 3.0.5, loglevel = 0
11/02/2013 06:23:01;0040;PBS_Server;Svr;tyrone-cluster;Scheduler was sent the command new
11/02/2013 06:23:33;0040;PBS_Server;Svr;tyrone-cluster;Scheduler was sent the command new
11/02/2013 06:24:07;0040;PBS_Server;Svr;tyrone-cluster;Scheduler was sent the command new
11/02/2013 06:24:36;0040;PBS_Server;Svr;tyrone-cluster;Scheduler was sent the command new
11/02/2013 06:25:12;0040;PBS_Server;Svr;tyrone-cluster;Scheduler was sent the command new
11/02/2013 06:25:38;0040;PBS_Server;Svr;tyrone-cluster;Scheduler was sent the command new
11/02/2013 06:26:11;0040;PBS_Server;Svr;tyrone-cluster;Scheduler was sent the command new
11/02/2013 06:26:42;0040;PBS_Server;Svr;tyrone-cluster;Scheduler was sent the command new
11/02/2013 06:27:13;0040;PBS_Server;Svr;tyrone-cluster;Scheduler was sent the command new
11/02/2013 06:27:41;0002;PBS_Server;Svr;PBS_Server;Torque Server Version = 3.0.5, loglevel = 0
11/02/2013 06:27:46;0040;PBS_Server;Svr;tyrone-cluster;Scheduler was sent the command new
11/02/2013 06:28:16;0040;PBS_Server;Svr;tyrone-cluster;Scheduler was sent the command new
11/02/2013 06:28:48;0040;PBS_Server;Svr;tyrone-cluster;Scheduler was sent the command new
11/02/2013 06:29:23;0040;PBS_Server;Svr;tyrone-cluster;Scheduler was sent the command new
11/02/2013 06:29:56;0040;PBS_Server;Svr;tyrone-cluster;Scheduler was sent the command new
11/02/2013 06:30:27;0040;PBS_Server;Svr;tyrone-cluster;Scheduler was sent the command new
11/02/2013 06:30:58;0040;PBS_Server;Svr;tyrone-cluster;Scheduler was sent the command new
11/02/2013 06:31:28;0040;PBS_Server;Svr;tyrone-cluster;Scheduler was sent the command new
11/02/2013 06:32:01;0040;PBS_Server;Svr;tyrone-cluster;Scheduler was sent the command new
11/02/2013 06:32:33;0040;PBS_Server;Svr;tyrone-cluster;Scheduler was sent the command new
11/02/2013 06:32:41;0002;PBS_Server;Svr;PBS_Server;Torque Server Version = 3.0.5, loglevel = 0
11/02/2013 06:33:07;0040;PBS_Server;Svr;tyrone-cluster;Scheduler was sent the command new
11/02/2013 06:33:36;0040;PBS_Server;Svr;tyrone-cluster;Scheduler was sent the command new
11/02/2013 06:34:12;0040;PBS_Server;Svr;tyrone-cluster;Scheduler was sent the command new
11/02/2013 06:34:38;0040;PBS_Server;Svr;tyrone-cluster;Scheduler was sent the command new
11/02/2013 06:35:11;0040;PBS_Server;Svr;tyrone-cluster;Scheduler was sent the command new
11/02/2013 06:35:42;0040;PBS_Server;Svr;tyrone-cluster;Scheduler was sent the command new
11/02/2013 06:36:08;0040;PBS_Server;Svr;tyrone-cluster;Scheduler was sent the command new
11/02/2013 06:36:41;0040;PBS_Server;Svr;tyrone-cluster;Scheduler was sent the command new
11/02/2013 06:37:12;0040;PBS_Server;Svr;tyrone-cluster;Scheduler was sent the command new
11/02/2013 06:37:39;0040;PBS_Server;Svr;tyrone-cluster;Scheduler was sent the command new
11/02/2013 06:37:41;0002;PBS_Server;Svr;PBS_Server;Torque Server Version = 3.0.5, loglevel = 0
11/02/2013 06:38:11;0040;PBS_Server;Svr;tyrone-cluster;Scheduler was sent the command new
11/02/2013 06:38:42;0040;PBS_Server;Svr;tyrone-cluster;Scheduler was sent the command new
11/02/2013 06:39:13;0040;PBS_Server;Svr;tyrone-cluster;Scheduler was sent the command new
11/02/2013 06:39:48;0040;PBS_Server;Svr;tyrone-cluster;Scheduler was sent the command new
11/02/2013 06:40:16;0040;PBS_Server;Svr;tyrone-cluster;Scheduler was sent the command new
11/02/2013 06:40:48;0040;PBS_Server;Svr;tyrone-cluster;Scheduler was sent the command new
11/02/2013 06:41:23;0040;PBS_Server;Svr;tyrone-cluster;Scheduler was sent the command new
11/02/2013 06:41:56;0040;PBS_Server;Svr;tyrone-cluster;Scheduler was sent the command new
11/02/2013 06:42:05;0100;PBS_Server;Job;31400.tyrone-cluster;enqueuing into batch, state 1 hop 1
11/02/2013 06:42:05;0100;PBS_Server;Job;31400.tyrone-cluster;dequeuing from batch, state QUEUED
11/02/2013 06:42:05;0100;PBS_Server;Job;31400.tyrone-cluster;enqueuing into qp128, state 1 hop 1
11/02/2013 06:42:05;0008;PBS_Server;Job;31400.tyrone-cluster;Job Queued at request of metsomya@tyrone-cluster, owner = metsomya@tyrone-cluster, job name = relaxdope335, queue = qp128
11/02/2013 06:42:05;0040;PBS_Server;Svr;tyrone-cluster;Scheduler was sent the command new
11/02/2013 06:42:05;0008;PBS_Server;Job;31400.tyrone-cluster;Job Modified at request of Scheduler@tyrone-cluster
11/02/2013 06:42:05;0008;PBS_Server;Job;31400.tyrone-cluster;Job Run at request of Scheduler@tyrone-cluster
11/02/2013 06:42:05;0040;PBS_Server;Svr;tyrone-cluster;Scheduler was sent the command recyc
11/02/2013 06:42:27;0040;PBS_Server;Svr;tyrone-cluster;Scheduler was sent the command new
11/02/2013 06:42:28;000d;PBS_Server;Job;31400.tyrone-cluster;Not sending email: User does not want mail of this type.
11/02/2013 06:42:28;0010;PBS_Server;Job;31400.tyrone-cluster;Exit_status=2 resources_used.cput=00:01:52 resources_used.mem=804kb resources_used.vmem=13628kb resources_used.walltime=00:00:22
11/02/2013 06:42:28;0008;PBS_Server;Job;NULL;on_job_exit valid pjob: 0x2df3ca0 (substate=50)
11/02/2013 06:42:28;0008;PBS_Server;Job;NULL;on_job_exit valid pjob: 0x2df3ca0 (substate=51)
11/02/2013 06:42:29;0008;PBS_Server;Job;NULL;on_job_exit valid pjob: 0x2df3ca0 (substate=51)
11/02/2013 06:42:29;0008;PBS_Server;Job;NULL;on_job_exit valid pjob: 0x2df3ca0 (substate=53)
11/02/2013 06:42:29;0100;PBS_Server;Job;31400.tyrone-cluster;dequeuing from qp128, state COMPLETE
11/02/2013 06:42:29;0040;PBS_Server;Svr;tyrone-cluster;Scheduler was sent the command term
11/02/2013 06:42:41;0002;PBS_Server;Svr;PBS_Server;Torque Server Version = 3.0.5, loglevel = 0
11/02/2013 06:42:58;0040;PBS_Server;Svr;tyrone-cluster;Scheduler was sent the command new
11/02/2013 06:43:28;0040;PBS_Server;Svr;tyrone-cluster;Scheduler was sent the command new
11/02/2013 06:43:43;0100;PBS_Server;Job;31401.tyrone-cluster;enqueuing into batch, state 1 hop 1
11/02/2013 06:43:43;0100;PBS_Server;Job;31401.tyrone-cluster;dequeuing from batch, state QUEUED
11/02/2013 06:43:43;0100;PBS_Server;Job;31401.tyrone-cluster;enqueuing into qp128, state 1 hop 1
11/02/2013 06:43:43;0008;PBS_Server;Job;31401.tyrone-cluster;Job Queued at request of metsomya@tyrone-cluster, owner = metsomya@tyrone-cluster, job name = relaxdope335, queue = qp128
11/02/2013 06:43:43;0040;PBS_Server;Svr;tyrone-cluster;Scheduler was sent the command new
11/02/2013 06:43:43;0008;PBS_Server;Job;31401.tyrone-cluster;Job Modified at request of Scheduler@tyrone-cluster
11/02/2013 06:43:43;0008;PBS_Server;Job;31401.tyrone-cluster;Job Run at request of Scheduler@tyrone-cluster
11/02/2013 06:43:43;0040;PBS_Server;Svr;tyrone-cluster;Scheduler was sent the command recyc
11/02/2013 06:43:56;000d;PBS_Server;Job;31401.tyrone-cluster;Not sending email: User does not want mail of this type.
11/02/2013 06:43:56;0010;PBS_Server;Job;31401.tyrone-cluster;Exit_status=2 resources_used.cput=00:01:45 resources_used.mem=804kb resources_used.vmem=13628kb resources_used.walltime=00:00:12
11/02/2013 06:43:56;0008;PBS_Server;Job;NULL;on_job_exit valid pjob: 0x2df3ca0 (substate=50)
11/02/2013 06:43:56;0008;PBS_Server;Job;NULL;on_job_exit valid pjob: 0x2df3ca0 (substate=51)
11/02/2013 06:43:56;0008;PBS_Server;Job;NULL;on_job_exit valid pjob: 0x2df3ca0 (substate=51)
11/02/2013 06:43:56;0008;PBS_Server;Job;NULL;on_job_exit valid pjob: 0x2df3ca0 (substate=53)
11/02/2013 06:43:56;0100;PBS_Server;Job;31401.tyrone-cluster;dequeuing from qp128, state COMPLETE
11/02/2013 06:43:56;0040;PBS_Server;Svr;tyrone-cluster;Scheduler was sent the command term
11/02/2013 06:44:01;0040;PBS_Server;Svr;tyrone-cluster;Scheduler was sent the command new
11/02/2013 06:44:33;0040;PBS_Server;Svr;tyrone-cluster;Scheduler was sent the command new
11/02/2013 06:45:08;0040;PBS_Server;Svr;tyrone-cluster;Scheduler was sent the command new
11/02/2013 06:45:41;0040;PBS_Server;Svr;tyrone-cluster;Scheduler was sent the command new
11/02/2013 06:46:12;0040;PBS_Server;Svr;tyrone-cluster;Scheduler was sent the command new
11/02/2013 06:46:38;0040;PBS_Server;Svr;tyrone-cluster;Scheduler was sent the command new
11/02/2013 06:47:11;0040;PBS_Server;Svr;tyrone-cluster;Scheduler was sent the command new
11/02/2013 06:47:41;0002;PBS_Server;Svr;PBS_Server;Torque Server Version = 3.0.5, loglevel = 0
11/02/2013 06:47:41;0040;PBS_Server;Svr;tyrone-cluster;Scheduler was sent the command new
11/02/2013 06:48:09;0040;PBS_Server;Svr;tyrone-cluster;Scheduler was sent the command new
11/02/2013 06:48:41;0040;PBS_Server;Svr;tyrone-cluster;Scheduler was sent the command new
11/02/2013 06:49:12;0040;PBS_Server;Svr;tyrone-cluster;Scheduler was sent the command new
11/02/2013 06:49:43;0040;PBS_Server;Svr;tyrone-cluster;Scheduler was sent the command new
11/02/2013 06:50:18;0040;PBS_Server;Svr;tyrone-cluster;Scheduler was sent the command new
11/02/2013 06:50:46;0040;PBS_Server;Svr;tyrone-cluster;Scheduler was sent the command new
11/02/2013 06:51:18;0040;PBS_Server;Svr;tyrone-cluster;Scheduler was sent the command new
11/02/2013 06:51:52;0040;PBS_Server;Svr;tyrone-cluster;Scheduler was sent the command new
11/02/2013 06:52:26;0040;PBS_Server;Svr;tyrone-cluster;Scheduler was sent the command new
11/02/2013 06:52:41;0002;PBS_Server;Svr;PBS_Server;Torque Server Version = 3.0.5, loglevel = 0
11/02/2013 06:52:57;0040;PBS_Server;Svr;tyrone-cluster;Scheduler was sent the command new
11/02/2013 06:53:23;0040;PBS_Server;Svr;tyrone-cluster;Scheduler was sent the command new
11/02/2013 06:53:56;0040;PBS_Server;Svr;tyrone-cluster;Scheduler was sent the command new
11/02/2013 06:54:27;0040;PBS_Server;Svr;tyrone-cluster;Scheduler was sent the command new
11/02/2013 06:54:58;0040;PBS_Server;Svr;tyrone-cluster;Scheduler was sent the command new
11/02/2013 06:55:28;0040;PBS_Server;Svr;tyrone-cluster;Scheduler was sent the command new
11/02/2013 06:56:01;0040;PBS_Server;Svr;tyrone-cluster;Scheduler was sent the command new
11/02/2013 06:56:33;0040;PBS_Server;Svr;tyrone-cluster;Scheduler was sent the command new
11/02/2013 06:57:06;0040;PBS_Server;Svr;tyrone-cluster;Scheduler was sent the command new
11/02/2013 06:57:34;0040;PBS_Server;Svr;tyrone-cluster;Scheduler was sent the command new
11/02/2013 06:57:41;0002;PBS_Server;Svr;PBS_Server;Torque Server Version = 3.0.5, loglevel = 0
11/02/2013 06:58:08;0040;PBS_Server;Svr;tyrone-cluster;Scheduler was sent the command new
11/02/2013 06:58:38;0040;PBS_Server;Svr;tyrone-cluster;Scheduler was sent the command new
11/02/2013 06:59:11;0040;PBS_Server;Svr;tyrone-cluster;Scheduler was sent the command new
11/02/2013 06:59:42;0040;PBS_Server;Svr;tyrone-cluster;Scheduler was sent the command new
11/02/2013 07:00:13;0040;PBS_Server;Svr;tyrone-cluster;Scheduler was sent the command new
11/02/2013 07:00:43;0040;PBS_Server;Svr;tyrone-cluster;Scheduler was sent the command new
11/02/2013 07:01:16;0040;PBS_Server;Svr;tyrone-cluster;Scheduler was sent the command new
11/02/2013 07:01:46;0040;PBS_Server;Svr;tyrone-cluster;Scheduler was sent the command new
11/02/2013 07:02:22;0040;PBS_Server;Svr;tyrone-cluster;Scheduler was sent the command new
11/02/2013 07:02:41;0002;PBS_Server;Svr;PBS_Server;Torque Server Version = 3.0.5, loglevel = 0
11/02/2013 07:02:51;0040;PBS_Server;Svr;tyrone-cluster;Scheduler was sent the command new
11/02/2013 07:03:26;0040;PBS_Server;Svr;tyrone-cluster;Scheduler was sent the command new
11/02/2013 07:03:52;0040;PBS_Server;Svr;tyrone-cluster;Scheduler was sent the command new
11/02/2013 07:04:26;0040;PBS_Server;Svr;tyrone-cluster;Scheduler was sent the command new
11/02/2013 07:04:57;0040;PBS_Server;Svr;tyrone-cluster;Scheduler was sent the command new
11/02/2013 07:05:23;0040;PBS_Server;Svr;tyrone-cluster;Scheduler was sent the command new
11/02/2013 07:05:56;0040;PBS_Server;Svr;tyrone-cluster;Scheduler was sent the command new
11/02/2013 07:06:27;0040;PBS_Server;Svr;tyrone-cluster;Scheduler was sent the command new
11/02/2013 07:06:58;0040;PBS_Server;Svr;tyrone-cluster;Scheduler was sent the command new
11/02/2013 07:07:28;0040;PBS_Server;Svr;tyrone-cluster;Scheduler was sent the command new
11/02/2013 07:07:41;0002;PBS_Server;Svr;PBS_Server;Torque Server Version = 3.0.5, loglevel = 0
11/02/2013 07:08:01;0040;PBS_Server;Svr;tyrone-cluster;Scheduler was sent the command new
11/02/2013 07:08:33;0040;PBS_Server;Svr;tyrone-cluster;Scheduler was sent the command new
11/02/2013 07:09:07;0040;PBS_Server;Svr;tyrone-cluster;Scheduler was sent the command new
11/02/2013 07:09:36;0040;PBS_Server;Svr;tyrone-cluster;Scheduler was sent the command new
11/02/2013 07:10:11;0040;PBS_Server;Svr;tyrone-cluster;Scheduler was sent the command new
11/02/2013 07:10:38;0040;PBS_Server;Svr;tyrone-cluster;Scheduler was sent the command new
11/02/2013 07:11:11;0040;PBS_Server;Svr;tyrone-cluster;Scheduler was sent the command new
11/02/2013 07:11:42;0040;PBS_Server;Svr;tyrone-cluster;Scheduler was sent the command new
11/02/2013 07:12:08;0040;PBS_Server;Svr;tyrone-cluster;Scheduler was sent the command new
11/02/2013 07:12:41;0002;PBS_Server;Svr;PBS_Server;Torque Server Version = 3.0.5, loglevel = 0
11/02/2013 07:12:41;0040;PBS_Server;Svr;tyrone-cluster;Scheduler was sent the command new
11/02/2013 07:13:12;0040;PBS_Server;Svr;tyrone-cluster;Scheduler was sent the command new
11/02/2013 07:13:43;0040;PBS_Server;Svr;tyrone-cluster;Scheduler was sent the command new
11/02/2013 07:14:18;0040;PBS_Server;Svr;tyrone-cluster;Scheduler was sent the command new
11/02/2013 07:14:46;0040;PBS_Server;Svr;tyrone-cluster;Scheduler was sent the command new
11/02/2013 07:15:18;0040;PBS_Server;Svr;tyrone-cluster;Scheduler was sent the command new
11/02/2013 07:15:52;0040;PBS_Server;Svr;tyrone-cluster;Scheduler was sent the command new
11/02/2013 07:16:21;0040;PBS_Server;Svr;tyrone-cluster;Scheduler was sent the command new
11/02/2013 07:16:56;0040;PBS_Server;Svr;tyrone-cluster;Scheduler was sent the command new
11/02/2013 07:17:22;0040;PBS_Server;Svr;tyrone-cluster;Scheduler was sent the command new
11/02/2013 07:17:41;0002;PBS_Server;Svr;PBS_Server;Torque Server Version = 3.0.5, loglevel = 0
11/02/2013 07:17:56;0040;PBS_Server;Svr;tyrone-cluster;Scheduler was sent the command new
11/02/2013 07:18:27;0040;PBS_Server;Svr;tyrone-cluster;Scheduler was sent the command new
11/02/2013 07:18:53;0040;PBS_Server;Svr;tyrone-cluster;Scheduler was sent the command new
11/02/2013 07:19:26;0040;PBS_Server;Svr;tyrone-cluster;Scheduler was sent the command new
11/02/2013 07:19:56;0040;PBS_Server;Svr;tyrone-cluster;Scheduler was sent the command new
11/02/2013 07:20:27;0040;PBS_Server;Svr;tyrone-cluster;Scheduler was sent the command new
11/02/2013 07:20:57;0040;PBS_Server;Svr;tyrone-cluster;Scheduler was sent the command new
11/02/2013 07:20:58;000d;PBS_Server;Job;31287.tyrone-cluster;Not sending email: User does not want mail of this type.
11/02/2013 07:20:58;0010;PBS_Server;Job;31287.tyrone-cluster;Exit_status=143 resources_used.cput=1501:51:22 resources_used.mem=8128260kb resources_used.vmem=132394904kb resources_used.walltime=24:00:50
11/02/2013 07:20:58;0008;PBS_Server;Job;NULL;on_job_exit valid pjob: 0x2e2c540 (substate=50)
11/02/2013 07:20:58;0008;PBS_Server;Job;NULL;on_job_exit valid pjob: 0x2e2c540 (substate=51)
11/02/2013 07:20:58;0008;PBS_Server;Job;NULL;on_job_exit valid pjob: 0x2e2c540 (substate=51)
11/02/2013 07:20:58;0008;PBS_Server;Job;NULL;on_job_exit valid pjob: 0x2e2c540 (substate=53)
11/02/2013 07:20:58;0100;PBS_Server;Job;31287.tyrone-cluster;dequeuing from qp64, state COMPLETE
11/02/2013 07:20:58;0040;PBS_Server;Svr;tyrone-cluster;Scheduler was sent the command term
11/02/2013 07:21:02;0008;PBS_Server;Job;31232.tyrone-cluster;Job Modified at request of Scheduler@tyrone-cluster
11/02/2013 07:21:02;0008;PBS_Server;Job;31155.tyrone-cluster;Job Modified at request of Scheduler@tyrone-cluster
11/02/2013 07:21:02;0008;PBS_Server;Job;31156.tyrone-cluster;Job Modified at request of Scheduler@tyrone-cluster
11/02/2013 07:21:02;0008;PBS_Server;Job;31233.tyrone-cluster;Job Modified at request of Scheduler@tyrone-cluster
11/02/2013 07:21:02;0008;PBS_Server;Job;31348.tyrone-cluster;Job Modified at request of Scheduler@tyrone-cluster
11/02/2013 07:21:02;0008;PBS_Server;Job;31349.tyrone-cluster;Job Modified at request of Scheduler@tyrone-cluster
11/02/2013 07:21:31;0040;PBS_Server;Svr;tyrone-cluster;Scheduler was sent the command new
11/02/2013 07:22:03;0040;PBS_Server;Svr;tyrone-cluster;Scheduler was sent the command new
11/02/2013 07:22:37;0040;PBS_Server;Svr;tyrone-cluster;Scheduler was sent the command new
11/02/2013 07:22:42;0002;PBS_Server;Svr;PBS_Server;Torque Server Version = 3.0.5, loglevel = 0
11/02/2013 07:23:06;0040;PBS_Server;Svr;tyrone-cluster;Scheduler was sent the command new
11/02/2013 07:23:38;0040;PBS_Server;Svr;tyrone-cluster;Scheduler was sent the command new
11/02/2013 07:24:07;0040;PBS_Server;Svr;tyrone-cluster;Scheduler was sent the command new
11/02/2013 07:24:36;0040;PBS_Server;Svr;tyrone-cluster;Scheduler was sent the command new
11/02/2013 07:25:07;0040;PBS_Server;Svr;tyrone-cluster;Scheduler was sent the command new
11/02/2013 07:25:37;0040;PBS_Server;Svr;tyrone-cluster;Scheduler was sent the command new
11/02/2013 07:26:06;0040;PBS_Server;Svr;tyrone-cluster;Scheduler was sent the command new
11/02/2013 07:26:37;0040;PBS_Server;Svr;tyrone-cluster;Scheduler was sent the command new
11/02/2013 07:27:07;0040;PBS_Server;Svr;tyrone-cluster;Scheduler was sent the command new
11/02/2013 07:27:36;0040;PBS_Server;Svr;tyrone-cluster;Scheduler was sent the command new
11/02/2013 07:27:42;0002;PBS_Server;Svr;PBS_Server;Torque Server Version = 3.0.5, loglevel = 0
11/02/2013 07:28:08;0040;PBS_Server;Svr;tyrone-cluster;Scheduler was sent the command new
11/02/2013 07:28:38;0040;PBS_Server;Svr;tyrone-cluster;Scheduler was sent the command new
11/02/2013 07:29:06;0040;PBS_Server;Svr;tyrone-cluster;Scheduler was sent the command new
11/02/2013 07:29:41;0040;PBS_Server;Svr;tyrone-cluster;Scheduler was sent the command new
11/02/2013 07:30:08;0040;PBS_Server;Svr;tyrone-cluster;Scheduler was sent the command new
11/02/2013 07:30:41;0040;PBS_Server;Svr;tyrone-cluster;Scheduler was sent the command new
11/02/2013 07:31:11;0040;PBS_Server;Svr;tyrone-cluster;Scheduler was sent the command new
11/02/2013 07:31:42;0040;PBS_Server;Svr;tyrone-cluster;Scheduler was sent the command new
11/02/2013 07:32:12;0040;PBS_Server;Svr;tyrone-cluster;Scheduler was sent the command new
11/02/2013 07:32:42;0002;PBS_Server;Svr;PBS_Server;Torque Server Version = 3.0.5, loglevel = 0
11/02/2013 07:32:46;0040;PBS_Server;Svr;tyrone-cluster;Scheduler was sent the command new
11/02/2013 07:33:13;0040;PBS_Server;Svr;tyrone-cluster;Scheduler was sent the command new
11/02/2013 07:33:43;0040;PBS_Server;Svr;tyrone-cluster;Scheduler was sent the command new
11/02/2013 07:34:16;0040;PBS_Server;Svr;tyrone-cluster;Scheduler was sent the command new
11/02/2013 07:34:48;0040;PBS_Server;Svr;tyrone-cluster;Scheduler was sent the command new
11/02/2013 07:35:22;0040;PBS_Server;Svr;tyrone-cluster;Scheduler was sent the command new
11/02/2013 07:35:51;0040;PBS_Server;Svr;tyrone-cluster;Scheduler was sent the command new
11/02/2013 07:36:22;0040;PBS_Server;Svr;tyrone-cluster;Scheduler was sent the command new
11/02/2013 07:36:53;0040;PBS_Server;Svr;tyrone-cluster;Scheduler was sent the command new
11/02/2013 07:37:21;0040;PBS_Server;Svr;tyrone-cluster;Scheduler was sent the command new
11/02/2013 07:37:42;0002;PBS_Server;Svr;PBS_Server;Torque Server Version = 3.0.5, loglevel = 0
11/02/2013 07:37:52;0040;PBS_Server;Svr;tyrone-cluster;Scheduler was sent the command new
11/02/2013 07:38:23;0040;PBS_Server;Svr;tyrone-cluster;Scheduler was sent the command new
11/02/2013 07:38:51;0040;PBS_Server;Svr;tyrone-cluster;Scheduler was sent the command new
11/02/2013 07:39:22;0040;PBS_Server;Svr;tyrone-cluster;Scheduler was sent the command new
11/02/2013 07:39:52;0040;PBS_Server;Svr;tyrone-cluster;Scheduler was sent the command new
11/02/2013 07:40:21;0040;PBS_Server;Svr;tyrone-cluster;Scheduler was sent the command new
11/02/2013 07:40:52;0040;PBS_Server;Svr;tyrone-cluster;Scheduler was sent the command new
11/02/2013 07:41:22;0040;PBS_Server;Svr;tyrone-cluster;Scheduler was sent the command new
11/02/2013 07:41:51;0040;PBS_Server;Svr;tyrone-cluster;Scheduler was sent the command new
11/02/2013 07:42:22;0040;PBS_Server;Svr;tyrone-cluster;Scheduler was sent the command new
11/02/2013 07:42:42;0002;PBS_Server;Svr;PBS_Server;Torque Server Version = 3.0.5, loglevel = 0
11/02/2013 07:42:53;0040;PBS_Server;Svr;tyrone-cluster;Scheduler was sent the command new
11/02/2013 07:43:21;0040;PBS_Server;Svr;tyrone-cluster;Scheduler was sent the command new
11/02/2013 07:43:52;0040;PBS_Server;Svr;tyrone-cluster;Scheduler was sent the command new
11/02/2013 07:44:22;0040;PBS_Server;Svr;tyrone-cluster;Scheduler was sent the command new
11/02/2013 07:44:51;0040;PBS_Server;Svr;tyrone-cluster;Scheduler was sent the command new
11/02/2013 07:45:22;0040;PBS_Server;Svr;tyrone-cluster;Scheduler was sent the command new
11/02/2013 07:45:52;0040;PBS_Server;Svr;tyrone-cluster;Scheduler was sent the command new
11/02/2013 07:46:21;0040;PBS_Server;Svr;tyrone-cluster;Scheduler was sent the command new
11/02/2013 07:46:52;0040;PBS_Server;Svr;tyrone-cluster;Scheduler was sent the command new
11/02/2013 07:47:22;0040;PBS_Server;Svr;tyrone-cluster;Scheduler was sent the command new
11/02/2013 07:47:42;0002;PBS_Server;Svr;PBS_Server;Torque Server Version = 3.0.5, loglevel = 0
11/02/2013 07:47:56;0040;PBS_Server;Svr;tyrone-cluster;Scheduler was sent the command new
11/02/2013 07:48:26;0040;PBS_Server;Svr;tyrone-cluster;Scheduler was sent the command new
11/02/2013 07:48:53;0040;PBS_Server;Svr;tyrone-cluster;Scheduler was sent the command new
11/02/2013 07:49:26;0040;PBS_Server;Svr;tyrone-cluster;Scheduler was sent the command new
11/02/2013 07:49:56;0040;PBS_Server;Svr;tyrone-cluster;Scheduler was sent the command new
11/02/2013 07:50:27;0040;PBS_Server;Svr;tyrone-cluster;Scheduler was sent the command new
11/02/2013 07:50:57;0040;PBS_Server;Svr;tyrone-cluster;Scheduler was sent the command new
11/02/2013 07:51:31;0040;PBS_Server;Svr;tyrone-cluster;Scheduler was sent the command new
11/02/2013 07:52:03;0040;PBS_Server;Svr;tyrone-cluster;Scheduler was sent the command new
11/02/2013 07:52:37;0040;PBS_Server;Svr;tyrone-cluster;Scheduler was sent the command new
11/02/2013 07:52:42;0002;PBS_Server;Svr;PBS_Server;Torque Server Version = 3.0.5, loglevel = 0
11/02/2013 07:53:05;0040;PBS_Server;Svr;tyrone-cluster;Scheduler was sent the command new
11/02/2013 07:53:41;0040;PBS_Server;Svr;tyrone-cluster;Scheduler was sent the command new
11/02/2013 07:54:08;0040;PBS_Server;Svr;tyrone-cluster;Scheduler was sent the command new
11/02/2013 07:54:41;0040;PBS_Server;Svr;tyrone-cluster;Scheduler was sent the command new
11/02/2013 07:55:11;0040;PBS_Server;Svr;tyrone-cluster;Scheduler was sent the command new
11/02/2013 07:55:38;0040;PBS_Server;Svr;tyrone-cluster;Scheduler was sent the command new
11/02/2013 07:56:11;0040;PBS_Server;Svr;tyrone-cluster;Scheduler was sent the command new
11/02/2013 07:56:41;0040;PBS_Server;Svr;tyrone-cluster;Scheduler was sent the command new
11/02/2013 07:57:07;0040;PBS_Server;Svr;tyrone-cluster;Scheduler was sent the command new
11/02/2013 07:57:41;0040;PBS_Server;Svr;tyrone-cluster;Scheduler was sent the command new
11/02/2013 07:57:42;0002;PBS_Server;Svr;PBS_Server;Torque Server Version = 3.0.5, loglevel = 0
11/02/2013 07:58:11;0040;PBS_Server;Svr;tyrone-cluster;Scheduler was sent the command new
11/02/2013 07:58:38;0040;PBS_Server;Svr;tyrone-cluster;Scheduler was sent the command new
11/02/2013 07:59:11;0040;PBS_Server;Svr;tyrone-cluster;Scheduler was sent the command new
11/02/2013 07:59:41;0040;PBS_Server;Svr;tyrone-cluster;Scheduler was sent the command new
11/02/2013 08:00:12;0040;PBS_Server;Svr;tyrone-cluster;Scheduler was sent the command new
11/02/2013 08:00:42;0040;PBS_Server;Svr;tyrone-cluster;Scheduler was sent the command new
11/02/2013 08:01:16;0040;PBS_Server;Svr;tyrone-cluster;Scheduler was sent the command new
11/02/2013 08:01:47;0040;PBS_Server;Svr;tyrone-cluster;Scheduler was sent the command new
11/02/2013 08:02:22;0040;PBS_Server;Svr;tyrone-cluster;Scheduler was sent the command new
11/02/2013 08:02:42;0002;PBS_Server;Svr;PBS_Server;Torque Server Version = 3.0.5, loglevel = 0
11/02/2013 08:02:50;0040;PBS_Server;Svr;tyrone-cluster;Scheduler was sent the command new
11/02/2013 08:03:26;0040;PBS_Server;Svr;tyrone-cluster;Scheduler was sent the command new
11/02/2013 08:03:53;0040;PBS_Server;Svr;tyrone-cluster;Scheduler was sent the command new
11/02/2013 08:04:26;0040;PBS_Server;Svr;tyrone-cluster;Scheduler was sent the command new
11/02/2013 08:04:56;0040;PBS_Server;Svr;tyrone-cluster;Scheduler was sent the command new
11/02/2013 08:05:27;0040;PBS_Server;Svr;tyrone-cluster;Scheduler was sent the command new
11/02/2013 08:05:57;0040;PBS_Server;Svr;tyrone-cluster;Scheduler was sent the command new
11/02/2013 08:06:31;0040;PBS_Server;Svr;tyrone-cluster;Scheduler was sent the command new
11/02/2013 08:07:03;0040;PBS_Server;Svr;tyrone-cluster;Scheduler was sent the command new
11/02/2013 08:07:38;0040;PBS_Server;Svr;tyrone-cluster;Scheduler was sent the command new
11/02/2013 08:07:42;0002;PBS_Server;Svr;PBS_Server;Torque Server Version = 3.0.5, loglevel = 0
11/02/2013 08:08:05;0040;PBS_Server;Svr;tyrone-cluster;Scheduler was sent the command new
11/02/2013 08:08:41;0040;PBS_Server;Svr;tyrone-cluster;Scheduler was sent the command new
11/02/2013 08:09:08;0040;PBS_Server;Svr;tyrone-cluster;Scheduler was sent the command new
11/02/2013 08:09:41;0040;PBS_Server;Svr;tyrone-cluster;Scheduler was sent the command new
11/02/2013 08:10:16;0040;PBS_Server;Svr;tyrone-cluster;Scheduler was sent the command new
11/02/2013 08:10:42;0040;PBS_Server;Svr;tyrone-cluster;Scheduler was sent the command new
11/02/2013 08:11:12;0040;PBS_Server;Svr;tyrone-cluster;Scheduler was sent the command new
11/02/2013 08:11:46;0040;PBS_Server;Svr;tyrone-cluster;Scheduler was sent the command new
11/02/2013 08:12:18;0040;PBS_Server;Svr;tyrone-cluster;Scheduler was sent the command new
11/02/2013 08:12:42;0002;PBS_Server;Svr;PBS_Server;Torque Server Version = 3.0.5, loglevel = 0
11/02/2013 08:12:53;0040;PBS_Server;Svr;tyrone-cluster;Scheduler was sent the command new
11/02/2013 08:13:21;0040;PBS_Server;Svr;tyrone-cluster;Scheduler was sent the command new
11/02/2013 08:13:56;0040;PBS_Server;Svr;tyrone-cluster;Scheduler was sent the command new
11/02/2013 08:14:23;0040;PBS_Server;Svr;tyrone-cluster;Scheduler was sent the command new
11/02/2013 08:14:56;0040;PBS_Server;Svr;tyrone-cluster;Scheduler was sent the command new
11/02/2013 08:15:31;0040;PBS_Server;Svr;tyrone-cluster;Scheduler was sent the command new
11/02/2013 08:15:57;0040;PBS_Server;Svr;tyrone-cluster;Scheduler was sent the command new
11/02/2013 08:16:27;0040;PBS_Server;Svr;tyrone-cluster;Scheduler was sent the command new
11/02/2013 08:17:01;0040;PBS_Server;Svr;tyrone-cluster;Scheduler was sent the command new
11/02/2013 08:17:32;0040;PBS_Server;Svr;tyrone-cluster;Scheduler was sent the command new
11/02/2013 08:17:42;0002;PBS_Server;Svr;PBS_Server;Torque Server Version = 3.0.5, loglevel = 0
11/02/2013 08:18:08;0040;PBS_Server;Svr;tyrone-cluster;Scheduler was sent the command new
11/02/2013 08:18:36;0040;PBS_Server;Svr;tyrone-cluster;Scheduler was sent the command new
11/02/2013 08:19:10;0040;PBS_Server;Svr;tyrone-cluster;Scheduler was sent the command new
11/02/2013 08:19:38;0040;PBS_Server;Svr;tyrone-cluster;Scheduler was sent the command new
11/02/2013 08:20:11;0040;PBS_Server;Svr;tyrone-cluster;Scheduler was sent the command new
11/02/2013 08:20:46;0040;PBS_Server;Svr;tyrone-cluster;Scheduler was sent the command new
11/02/2013 08:21:12;0040;PBS_Server;Svr;tyrone-cluster;Scheduler was sent the command new
11/02/2013 08:21:41;0040;PBS_Server;Svr;tyrone-cluster;Scheduler was sent the command new
11/02/2013 08:22:16;0040;PBS_Server;Svr;tyrone-cluster;Scheduler was sent the command new
11/02/2013 08:22:42;0002;PBS_Server;Svr;PBS_Server;Torque Server Version = 3.0.5, loglevel = 0
11/02/2013 08:22:42;0040;PBS_Server;Svr;tyrone-cluster;Scheduler was sent the command new
11/02/2013 08:23:12;0040;PBS_Server;Svr;tyrone-cluster;Scheduler was sent the command new
11/02/2013 08:23:46;0040;PBS_Server;Svr;tyrone-cluster;Scheduler was sent the command new
11/02/2013 08:24:16;0040;PBS_Server;Svr;tyrone-cluster;Scheduler was sent the command new
11/02/2013 08:24:53;0040;PBS_Server;Svr;tyrone-cluster;Scheduler was sent the command new
11/02/2013 08:25:21;0040;PBS_Server;Svr;tyrone-cluster;Scheduler was sent the command new
11/02/2013 08:25:56;0040;PBS_Server;Svr;tyrone-cluster;Scheduler was sent the command new
11/02/2013 08:26:23;0040;PBS_Server;Svr;tyrone-cluster;Scheduler was sent the command new
11/02/2013 08:26:56;0040;PBS_Server;Svr;tyrone-cluster;Scheduler was sent the command new
11/02/2013 08:27:31;0040;PBS_Server;Svr;tyrone-cluster;Scheduler was sent the command new
11/02/2013 08:27:42;0002;PBS_Server;Svr;PBS_Server;Torque Server Version = 3.0.5, loglevel = 0
11/02/2013 08:27:57;0040;PBS_Server;Svr;tyrone-cluster;Scheduler was sent the command new
11/02/2013 08:28:27;0040;PBS_Server;Svr;tyrone-cluster;Scheduler was sent the command new
11/02/2013 08:29:01;0040;PBS_Server;Svr;tyrone-cluster;Scheduler was sent the command new
11/02/2013 08:29:33;0040;PBS_Server;Svr;tyrone-cluster;Scheduler was sent the command new
11/02/2013 08:30:07;0040;PBS_Server;Svr;tyrone-cluster;Scheduler was sent the command new
11/02/2013 08:30:36;0040;PBS_Server;Svr;tyrone-cluster;Scheduler was sent the command new
11/02/2013 08:31:10;0040;PBS_Server;Svr;tyrone-cluster;Scheduler was sent the command new
11/02/2013 08:31:37;0040;PBS_Server;Svr;tyrone-cluster;Scheduler was sent the command new
11/02/2013 08:32:11;0040;PBS_Server;Svr;tyrone-cluster;Scheduler was sent the command new
11/02/2013 08:32:40;0040;PBS_Server;Svr;tyrone-cluster;Scheduler was sent the command new
11/02/2013 08:32:42;0002;PBS_Server;Svr;PBS_Server;Torque Server Version = 3.0.5, loglevel = 0
11/02/2013 08:33:13;0040;PBS_Server;Svr;tyrone-cluster;Scheduler was sent the command new
11/02/2013 08:33:42;0040;PBS_Server;Svr;tyrone-cluster;Scheduler was sent the command new
11/02/2013 08:34:16;0040;PBS_Server;Svr;tyrone-cluster;Scheduler was sent the command new
11/02/2013 08:34:48;0040;PBS_Server;Svr;tyrone-cluster;Scheduler was sent the command new
11/02/2013 08:35:22;0040;PBS_Server;Svr;tyrone-cluster;Scheduler was sent the command new
11/02/2013 08:35:50;0040;PBS_Server;Svr;tyrone-cluster;Scheduler was sent the command new
11/02/2013 08:36:22;0040;PBS_Server;Svr;tyrone-cluster;Scheduler was sent the command new
11/02/2013 08:36:52;0040;PBS_Server;Svr;tyrone-cluster;Scheduler was sent the command new
11/02/2013 08:37:20;0040;PBS_Server;Svr;tyrone-cluster;Scheduler was sent the command new
11/02/2013 08:37:42;0002;PBS_Server;Svr;PBS_Server;Torque Server Version = 3.0.5, loglevel = 0
11/02/2013 08:37:55;0040;PBS_Server;Svr;tyrone-cluster;Scheduler was sent the command new
11/02/2013 08:38:22;0040;PBS_Server;Svr;tyrone-cluster;Scheduler was sent the command new
11/02/2013 08:38:56;0040;PBS_Server;Svr;tyrone-cluster;Scheduler was sent the command new
11/02/2013 08:39:25;0040;PBS_Server;Svr;tyrone-cluster;Scheduler was sent the command new
11/02/2013 08:39:53;0040;PBS_Server;Svr;tyrone-cluster;Scheduler was sent the command new
11/02/2013 08:40:26;0040;PBS_Server;Svr;tyrone-cluster;Scheduler was sent the command new
11/02/2013 08:41:01;0040;PBS_Server;Svr;tyrone-cluster;Scheduler was sent the command new
11/02/2013 08:41:27;0040;PBS_Server;Svr;tyrone-cluster;Scheduler was sent the command new
11/02/2013 08:41:57;0040;PBS_Server;Svr;tyrone-cluster;Scheduler was sent the command new
11/02/2013 08:42:31;0040;PBS_Server;Svr;tyrone-cluster;Scheduler was sent the command new
11/02/2013 08:42:42;0002;PBS_Server;Svr;PBS_Server;Torque Server Version = 3.0.5, loglevel = 0
11/02/2013 08:43:03;0040;PBS_Server;Svr;tyrone-cluster;Scheduler was sent the command new
11/02/2013 08:43:38;0040;PBS_Server;Svr;tyrone-cluster;Scheduler was sent the command new
11/02/2013 08:44:06;0040;PBS_Server;Svr;tyrone-cluster;Scheduler was sent the command new
11/02/2013 08:44:40;0040;PBS_Server;Svr;tyrone-cluster;Scheduler was sent the command new
11/02/2013 08:45:09;0040;PBS_Server;Svr;tyrone-cluster;Scheduler was sent the command new
11/02/2013 08:45:42;0040;PBS_Server;Svr;tyrone-cluster;Scheduler was sent the command new
11/02/2013 08:46:14;0040;PBS_Server;Svr;tyrone-cluster;Scheduler was sent the command new
11/02/2013 08:46:43;0040;PBS_Server;Svr;tyrone-cluster;Scheduler was sent the command new
11/02/2013 08:47:12;0040;PBS_Server;Svr;tyrone-cluster;Scheduler was sent the command new
11/02/2013 08:47:42;0002;PBS_Server;Svr;PBS_Server;Torque Server Version = 3.0.5, loglevel = 0
11/02/2013 08:47:42;0040;PBS_Server;Svr;tyrone-cluster;Scheduler was sent the command new
11/02/2013 08:48:14;0040;PBS_Server;Svr;tyrone-cluster;Scheduler was sent the command new
11/02/2013 08:48:42;0040;PBS_Server;Svr;tyrone-cluster;Scheduler was sent the command new
11/02/2013 08:49:16;0040;PBS_Server;Svr;tyrone-cluster;Scheduler was sent the command new
11/02/2013 08:49:48;0040;PBS_Server;Svr;tyrone-cluster;Scheduler was sent the command new
11/02/2013 08:50:22;0040;PBS_Server;Svr;tyrone-cluster;Scheduler was sent the command new
11/02/2013 08:50:50;0040;PBS_Server;Svr;tyrone-cluster;Scheduler was sent the command new
11/02/2013 08:51:25;0040;PBS_Server;Svr;tyrone-cluster;Scheduler was sent the command new
11/02/2013 08:51:52;0040;PBS_Server;Svr;tyrone-cluster;Scheduler was sent the command new
11/02/2013 08:52:26;0040;PBS_Server;Svr;tyrone-cluster;Scheduler was sent the command new
11/02/2013 08:52:42;0002;PBS_Server;Svr;PBS_Server;Torque Server Version = 3.0.5, loglevel = 0
11/02/2013 08:53:01;0040;PBS_Server;Svr;tyrone-cluster;Scheduler was sent the command new
11/02/2013 08:53:29;0040;PBS_Server;Svr;tyrone-cluster;Scheduler was sent the command new
11/02/2013 08:53:57;0040;PBS_Server;Svr;tyrone-cluster;Scheduler was sent the command new
11/02/2013 08:54:31;0040;PBS_Server;Svr;tyrone-cluster;Scheduler was sent the command new
11/02/2013 08:55:03;0040;PBS_Server;Svr;tyrone-cluster;Scheduler was sent the command new
11/02/2013 08:55:37;0040;PBS_Server;Svr;tyrone-cluster;Scheduler was sent the command new
11/02/2013 08:56:05;0040;PBS_Server;Svr;tyrone-cluster;Scheduler was sent the command new
11/02/2013 08:56:37;0040;PBS_Server;Svr;tyrone-cluster;Scheduler was sent the command new
11/02/2013 08:57:07;0040;PBS_Server;Svr;tyrone-cluster;Scheduler was sent the command new
11/02/2013 08:57:41;0040;PBS_Server;Svr;tyrone-cluster;Scheduler was sent the command new
11/02/2013 08:57:42;0002;PBS_Server;Svr;PBS_Server;Torque Server Version = 3.0.5, loglevel = 0
11/02/2013 08:58:16;0040;PBS_Server;Svr;tyrone-cluster;Scheduler was sent the command new
11/02/2013 08:58:43;0040;PBS_Server;Svr;tyrone-cluster;Scheduler was sent the command new
11/02/2013 08:59:12;0040;PBS_Server;Svr;tyrone-cluster;Scheduler was sent the command new
11/02/2013 08:59:46;0040;PBS_Server;Svr;tyrone-cluster;Scheduler was sent the command new
11/02/2013 09:00:13;0040;PBS_Server;Svr;tyrone-cluster;Scheduler was sent the command new
11/02/2013 09:00:42;0040;PBS_Server;Svr;tyrone-cluster;Scheduler was sent the command new
11/02/2013 09:01:16;0040;PBS_Server;Svr;tyrone-cluster;Scheduler was sent the command new
11/02/2013 09:01:47;0040;PBS_Server;Svr;tyrone-cluster;Scheduler was sent the command new
11/02/2013 09:02:23;0040;PBS_Server;Svr;tyrone-cluster;Scheduler was sent the command new
11/02/2013 09:02:42;0002;PBS_Server;Svr;PBS_Server;Torque Server Version = 3.0.5, loglevel = 0
11/02/2013 09:02:50;0040;PBS_Server;Svr;tyrone-cluster;Scheduler was sent the command new
11/02/2013 09:03:25;0040;PBS_Server;Svr;tyrone-cluster;Scheduler was sent the command new
11/02/2013 09:03:54;0040;PBS_Server;Svr;tyrone-cluster;Scheduler was sent the command new
11/02/2013 09:04:25;0040;PBS_Server;Svr;tyrone-cluster;Scheduler was sent the command new
11/02/2013 09:04:56;0040;PBS_Server;Svr;tyrone-cluster;Scheduler was sent the command new
11/02/2013 09:05:28;0040;PBS_Server;Svr;tyrone-cluster;Scheduler was sent the command new
11/02/2013 09:05:57;0040;PBS_Server;Svr;tyrone-cluster;Scheduler was sent the command new
11/02/2013 09:06:31;0040;PBS_Server;Svr;tyrone-cluster;Scheduler was sent the command new
11/02/2013 09:07:03;0040;PBS_Server;Svr;tyrone-cluster;Scheduler was sent the command new
11/02/2013 09:07:37;0040;PBS_Server;Svr;tyrone-cluster;Scheduler was sent the command new
11/02/2013 09:07:42;0002;PBS_Server;Svr;PBS_Server;Torque Server Version = 3.0.5, loglevel = 0
11/02/2013 09:08:05;0040;PBS_Server;Svr;tyrone-cluster;Scheduler was sent the command new
11/02/2013 09:08:38;0040;PBS_Server;Svr;tyrone-cluster;Scheduler was sent the command new
11/02/2013 09:09:07;0040;PBS_Server;Svr;tyrone-cluster;Scheduler was sent the command new
11/02/2013 09:09:35;0040;PBS_Server;Svr;tyrone-cluster;Scheduler was sent the command new
11/02/2013 09:10:06;0040;PBS_Server;Svr;tyrone-cluster;Scheduler was sent the command new
11/02/2013 09:10:37;0040;PBS_Server;Svr;tyrone-cluster;Scheduler was sent the command new
11/02/2013 09:11:11;0040;PBS_Server;Svr;tyrone-cluster;Scheduler was sent the command new
11/02/2013 09:11:46;0040;PBS_Server;Svr;tyrone-cluster;Scheduler was sent the command new
11/02/2013 09:12:14;0040;PBS_Server;Svr;tyrone-cluster;Scheduler was sent the command new
11/02/2013 09:12:42;0002;PBS_Server;Svr;PBS_Server;Torque Server Version = 3.0.5, loglevel = 0
11/02/2013 09:12:42;0040;PBS_Server;Svr;tyrone-cluster;Scheduler was sent the command new
11/02/2013 09:13:16;0040;PBS_Server;Svr;tyrone-cluster;Scheduler was sent the command new
11/02/2013 09:13:48;0040;PBS_Server;Svr;tyrone-cluster;Scheduler was sent the command new
11/02/2013 09:14:22;0040;PBS_Server;Svr;tyrone-cluster;Scheduler was sent the command new
11/02/2013 09:14:50;0040;PBS_Server;Svr;tyrone-cluster;Scheduler was sent the command new
11/02/2013 09:15:24;0040;PBS_Server;Svr;tyrone-cluster;Scheduler was sent the command new
11/02/2013 09:15:52;0040;PBS_Server;Svr;tyrone-cluster;Scheduler was sent the command new
11/02/2013 09:16:27;0040;PBS_Server;Svr;tyrone-cluster;Scheduler was sent the command new
11/02/2013 09:17:01;0040;PBS_Server;Svr;tyrone-cluster;Scheduler was sent the command new
11/02/2013 09:17:28;0040;PBS_Server;Svr;tyrone-cluster;Scheduler was sent the command new
11/02/2013 09:17:42;0002;PBS_Server;Svr;PBS_Server;Torque Server Version = 3.0.5, loglevel = 0
11/02/2013 09:17:57;0040;PBS_Server;Svr;tyrone-cluster;Scheduler was sent the command new
11/02/2013 09:18:31;0040;PBS_Server;Svr;tyrone-cluster;Scheduler was sent the command new
11/02/2013 09:19:03;0040;PBS_Server;Svr;tyrone-cluster;Scheduler was sent the command new
11/02/2013 09:19:37;0040;PBS_Server;Svr;tyrone-cluster;Scheduler was sent the command new
11/02/2013 09:20:05;0040;PBS_Server;Svr;tyrone-cluster;Scheduler was sent the command new
11/02/2013 09:20:39;0040;PBS_Server;Svr;tyrone-cluster;Scheduler was sent the command new
11/02/2013 09:21:07;0040;PBS_Server;Svr;tyrone-cluster;Scheduler was sent the command new
11/02/2013 09:21:41;0040;PBS_Server;Svr;tyrone-cluster;Scheduler was sent the command new
11/02/2013 09:22:11;0040;PBS_Server;Svr;tyrone-cluster;Scheduler was sent the command new
11/02/2013 09:22:42;0002;PBS_Server;Svr;PBS_Server;Torque Server Version = 3.0.5, loglevel = 0
11/02/2013 09:22:42;0040;PBS_Server;Svr;tyrone-cluster;Scheduler was sent the command new
11/02/2013 09:23:12;0040;PBS_Server;Svr;tyrone-cluster;Scheduler was sent the command new
11/02/2013 09:23:46;0040;PBS_Server;Svr;tyrone-cluster;Scheduler was sent the command new
11/02/2013 09:24:16;0040;PBS_Server;Svr;tyrone-cluster;Scheduler was sent the command new
11/02/2013 09:24:52;0040;PBS_Server;Svr;tyrone-cluster;Scheduler was sent the command new
11/02/2013 09:25:20;0040;PBS_Server;Svr;tyrone-cluster;Scheduler was sent the command new
11/02/2013 09:25:55;0040;PBS_Server;Svr;tyrone-cluster;Scheduler was sent the command new
11/02/2013 09:26:23;0040;PBS_Server;Svr;tyrone-cluster;Scheduler was sent the command new
11/02/2013 09:26:56;0040;PBS_Server;Svr;tyrone-cluster;Scheduler was sent the command new
11/02/2013 09:27:31;0040;PBS_Server;Svr;tyrone-cluster;Scheduler was sent the command new
11/02/2013 09:27:42;0002;PBS_Server;Svr;PBS_Server;Torque Server Version = 3.0.5, loglevel = 0
11/02/2013 09:27:58;0040;PBS_Server;Svr;tyrone-cluster;Scheduler was sent the command new
11/02/2013 09:28:27;0040;PBS_Server;Svr;tyrone-cluster;Scheduler was sent the command new
11/02/2013 09:29:01;0040;PBS_Server;Svr;tyrone-cluster;Scheduler was sent the command new
11/02/2013 09:29:38;0040;PBS_Server;Svr;tyrone-cluster;Scheduler was sent the command new
11/02/2013 09:30:08;0040;PBS_Server;Svr;tyrone-cluster;Scheduler was sent the command new
11/02/2013 09:30:36;0040;PBS_Server;Svr;tyrone-cluster;Scheduler was sent the command new
11/02/2013 09:31:10;0040;PBS_Server;Svr;tyrone-cluster;Scheduler was sent the command new
11/02/2013 09:31:38;0040;PBS_Server;Svr;tyrone-cluster;Scheduler was sent the command new
11/02/2013 09:32:07;0040;PBS_Server;Svr;tyrone-cluster;Scheduler was sent the command new
11/02/2013 09:32:39;0040;PBS_Server;Svr;tyrone-cluster;Scheduler was sent the command new
11/02/2013 09:32:42;0002;PBS_Server;Svr;PBS_Server;Torque Server Version = 3.0.5, loglevel = 0
11/02/2013 09:33:07;0040;PBS_Server;Svr;tyrone-cluster;Scheduler was sent the command new
11/02/2013 09:33:37;0040;PBS_Server;Svr;tyrone-cluster;Scheduler was sent the command new
11/02/2013 09:34:09;0040;PBS_Server;Svr;tyrone-cluster;Scheduler was sent the command new
11/02/2013 09:34:37;0040;PBS_Server;Svr;tyrone-cluster;Scheduler was sent the command new
11/02/2013 09:35:07;0040;PBS_Server;Svr;tyrone-cluster;Scheduler was sent the command new
11/02/2013 09:35:39;0040;PBS_Server;Svr;tyrone-cluster;Scheduler was sent the command new
11/02/2013 09:36:07;0040;PBS_Server;Svr;tyrone-cluster;Scheduler was sent the command new
11/02/2013 09:36:37;0040;PBS_Server;Svr;tyrone-cluster;Scheduler was sent the command new
11/02/2013 09:37:09;0040;PBS_Server;Svr;tyrone-cluster;Scheduler was sent the command new
11/02/2013 09:37:37;0040;PBS_Server;Svr;tyrone-cluster;Scheduler was sent the command new
11/02/2013 09:37:42;0002;PBS_Server;Svr;PBS_Server;Torque Server Version = 3.0.5, loglevel = 0
11/02/2013 09:38:07;0040;PBS_Server;Svr;tyrone-cluster;Scheduler was sent the command new
11/02/2013 09:38:40;0040;PBS_Server;Svr;tyrone-cluster;Scheduler was sent the command new
11/02/2013 09:39:08;0040;PBS_Server;Svr;tyrone-cluster;Scheduler was sent the command new
11/02/2013 09:39:37;0040;PBS_Server;Svr;tyrone-cluster;Scheduler was sent the command new
11/02/2013 09:40:09;0040;PBS_Server;Svr;tyrone-cluster;Scheduler was sent the command new
11/02/2013 09:40:38;0040;PBS_Server;Svr;tyrone-cluster;Scheduler was sent the command new
11/02/2013 09:41:07;0040;PBS_Server;Svr;tyrone-cluster;Scheduler was sent the command new
11/02/2013 09:41:39;0040;PBS_Server;Svr;tyrone-cluster;Scheduler was sent the command new
11/02/2013 09:42:07;0040;PBS_Server;Svr;tyrone-cluster;Scheduler was sent the command new
11/02/2013 09:42:37;0040;PBS_Server;Svr;tyrone-cluster;Scheduler was sent the command new
11/02/2013 09:42:42;0002;PBS_Server;Svr;PBS_Server;Torque Server Version = 3.0.5, loglevel = 0
11/02/2013 09:43:09;0040;PBS_Server;Svr;tyrone-cluster;Scheduler was sent the command new
11/02/2013 09:43:37;0040;PBS_Server;Svr;tyrone-cluster;Scheduler was sent the command new
11/02/2013 09:44:07;0040;PBS_Server;Svr;tyrone-cluster;Scheduler was sent the command new
11/02/2013 09:44:39;0040;PBS_Server;Svr;tyrone-cluster;Scheduler was sent the command new
11/02/2013 09:45:07;0040;PBS_Server;Svr;tyrone-cluster;Scheduler was sent the command new
11/02/2013 09:45:37;0040;PBS_Server;Svr;tyrone-cluster;Scheduler was sent the command new
11/02/2013 09:46:08;0040;PBS_Server;Svr;tyrone-cluster;Scheduler was sent the command new
11/02/2013 09:46:40;0040;PBS_Server;Svr;tyrone-cluster;Scheduler was sent the command new
11/02/2013 09:47:12;0040;PBS_Server;Svr;tyrone-cluster;Scheduler was sent the command new
11/02/2013 09:47:42;0002;PBS_Server;Svr;PBS_Server;Torque Server Version = 3.0.5, loglevel = 0
11/02/2013 09:47:42;0040;PBS_Server;Svr;tyrone-cluster;Scheduler was sent the command new
11/02/2013 09:48:10;0040;PBS_Server;Svr;tyrone-cluster;Scheduler was sent the command new
11/02/2013 09:48:43;0040;PBS_Server;Svr;tyrone-cluster;Scheduler was sent the command new
11/02/2013 09:49:17;0040;PBS_Server;Svr;tyrone-cluster;Scheduler was sent the command new
11/02/2013 09:49:48;0040;PBS_Server;Svr;tyrone-cluster;Scheduler was sent the command new
11/02/2013 09:50:21;0040;PBS_Server;Svr;tyrone-cluster;Scheduler was sent the command new
11/02/2013 09:50:51;0040;PBS_Server;Svr;tyrone-cluster;Scheduler was sent the command new
11/02/2013 09:51:24;0040;PBS_Server;Svr;tyrone-cluster;Scheduler was sent the command new
11/02/2013 09:51:52;0040;PBS_Server;Svr;tyrone-cluster;Scheduler was sent the command new
11/02/2013 09:52:22;0040;PBS_Server;Svr;tyrone-cluster;Scheduler was sent the command new
11/02/2013 09:52:42;0002;PBS_Server;Svr;PBS_Server;Torque Server Version = 3.0.5, loglevel = 0
11/02/2013 09:52:53;0040;PBS_Server;Svr;tyrone-cluster;Scheduler was sent the command new
11/02/2013 09:53:23;0040;PBS_Server;Svr;tyrone-cluster;Scheduler was sent the command new
11/02/2013 09:53:52;0040;PBS_Server;Svr;tyrone-cluster;Scheduler was sent the command new
11/02/2013 09:54:24;0040;PBS_Server;Svr;tyrone-cluster;Scheduler was sent the command new
11/02/2013 09:54:53;0040;PBS_Server;Svr;tyrone-cluster;Scheduler was sent the command new
11/02/2013 09:55:22;0040;PBS_Server;Svr;tyrone-cluster;Scheduler was sent the command new
11/02/2013 09:55:54;0040;PBS_Server;Svr;tyrone-cluster;Scheduler was sent the command new
11/02/2013 09:56:22;0040;PBS_Server;Svr;tyrone-cluster;Scheduler was sent the command new
11/02/2013 09:56:52;0040;PBS_Server;Svr;tyrone-cluster;Scheduler was sent the command new
11/02/2013 09:57:24;0040;PBS_Server;Svr;tyrone-cluster;Scheduler was sent the command new
11/02/2013 09:57:42;0002;PBS_Server;Svr;PBS_Server;Torque Server Version = 3.0.5, loglevel = 0
11/02/2013 09:57:52;0040;PBS_Server;Svr;tyrone-cluster;Scheduler was sent the command new
11/02/2013 09:58:22;0040;PBS_Server;Svr;tyrone-cluster;Scheduler was sent the command new
11/02/2013 09:58:53;0040;PBS_Server;Svr;tyrone-cluster;Scheduler was sent the command new
11/02/2013 09:59:22;0040;PBS_Server;Svr;tyrone-cluster;Scheduler was sent the command new
11/02/2013 09:59:52;0040;PBS_Server;Svr;tyrone-cluster;Scheduler was sent the command new
11/02/2013 10:00:24;0040;PBS_Server;Svr;tyrone-cluster;Scheduler was sent the command new
11/02/2013 10:00:53;0040;PBS_Server;Svr;tyrone-cluster;Scheduler was sent the command new
11/02/2013 10:01:22;0040;PBS_Server;Svr;tyrone-cluster;Scheduler was sent the command new
11/02/2013 10:01:54;0040;PBS_Server;Svr;tyrone-cluster;Scheduler was sent the command new
11/02/2013 10:02:22;0040;PBS_Server;Svr;tyrone-cluster;Scheduler was sent the command new
11/02/2013 10:02:42;0002;PBS_Server;Svr;PBS_Server;Torque Server Version = 3.0.5, loglevel = 0
11/02/2013 10:02:52;0040;PBS_Server;Svr;tyrone-cluster;Scheduler was sent the command new
11/02/2013 10:03:23;0040;PBS_Server;Svr;tyrone-cluster;Scheduler was sent the command new
11/02/2013 10:03:53;0040;PBS_Server;Svr;tyrone-cluster;Scheduler was sent the command new
11/02/2013 10:04:27;0040;PBS_Server;Svr;tyrone-cluster;Scheduler was sent the command new
11/02/2013 10:05:01;0040;PBS_Server;Svr;tyrone-cluster;Scheduler was sent the command new
11/02/2013 10:05:25;0040;PBS_Server;Svr;tyrone-cluster;Scheduler was sent the command new
11/02/2013 10:05:57;0040;PBS_Server;Svr;tyrone-cluster;Scheduler was sent the command new
11/02/2013 10:06:31;0040;PBS_Server;Svr;tyrone-cluster;Scheduler was sent the command new
11/02/2013 10:06:55;0040;PBS_Server;Svr;tyrone-cluster;Scheduler was sent the command new
11/02/2013 10:07:28;0040;PBS_Server;Svr;tyrone-cluster;Scheduler was sent the command new
11/02/2013 10:07:42;0002;PBS_Server;Svr;PBS_Server;Torque Server Version = 3.0.5, loglevel = 0
11/02/2013 10:08:02;0040;PBS_Server;Svr;tyrone-cluster;Scheduler was sent the command new
11/02/2013 10:08:33;0040;PBS_Server;Svr;tyrone-cluster;Scheduler was sent the command new
11/02/2013 10:09:07;0040;PBS_Server;Svr;tyrone-cluster;Scheduler was sent the command new
11/02/2013 10:09:36;0040;PBS_Server;Svr;tyrone-cluster;Scheduler was sent the command new
11/02/2013 10:10:09;0040;PBS_Server;Svr;tyrone-cluster;Scheduler was sent the command new
11/02/2013 10:10:38;0040;PBS_Server;Svr;tyrone-cluster;Scheduler was sent the command new
11/02/2013 10:11:07;0040;PBS_Server;Svr;tyrone-cluster;Scheduler was sent the command new
11/02/2013 10:11:39;0040;PBS_Server;Svr;tyrone-cluster;Scheduler was sent the command new
11/02/2013 10:12:07;0040;PBS_Server;Svr;tyrone-cluster;Scheduler was sent the command new
11/02/2013 10:12:37;0040;PBS_Server;Svr;tyrone-cluster;Scheduler was sent the command new
11/02/2013 10:12:42;0002;PBS_Server;Svr;PBS_Server;Torque Server Version = 3.0.5, loglevel = 0
11/02/2013 10:13:08;0040;PBS_Server;Svr;tyrone-cluster;Scheduler was sent the command new
11/02/2013 10:13:37;0040;PBS_Server;Svr;tyrone-cluster;Scheduler was sent the command new
11/02/2013 10:14:07;0040;PBS_Server;Svr;tyrone-cluster;Scheduler was sent the command new
11/02/2013 10:14:39;0040;PBS_Server;Svr;tyrone-cluster;Scheduler was sent the command new
11/02/2013 10:15:08;0040;PBS_Server;Svr;tyrone-cluster;Scheduler was sent the command new
11/02/2013 10:15:42;0040;PBS_Server;Svr;tyrone-cluster;Scheduler was sent the command new
11/02/2013 10:16:14;0040;PBS_Server;Svr;tyrone-cluster;Scheduler was sent the command new
11/02/2013 10:16:40;0040;PBS_Server;Svr;tyrone-cluster;Scheduler was sent the command new
11/02/2013 10:17:13;0040;PBS_Server;Svr;tyrone-cluster;Scheduler was sent the command new
11/02/2013 10:17:42;0002;PBS_Server;Svr;PBS_Server;Torque Server Version = 3.0.5, loglevel = 0
11/02/2013 10:17:45;0040;PBS_Server;Svr;tyrone-cluster;Scheduler was sent the command new
11/02/2013 10:18:14;0040;PBS_Server;Svr;tyrone-cluster;Scheduler was sent the command new
11/02/2013 10:18:43;0040;PBS_Server;Svr;tyrone-cluster;Scheduler was sent the command new
11/02/2013 10:19:16;0040;PBS_Server;Svr;tyrone-cluster;Scheduler was sent the command new
11/02/2013 10:19:46;0040;PBS_Server;Svr;tyrone-cluster;Scheduler was sent the command new
11/02/2013 10:20:22;0040;PBS_Server;Svr;tyrone-cluster;Scheduler was sent the command new
11/02/2013 10:20:51;0040;PBS_Server;Svr;tyrone-cluster;Scheduler was sent the command new
11/02/2013 10:21:24;0040;PBS_Server;Svr;tyrone-cluster;Scheduler was sent the command new
11/02/2013 10:21:53;0040;PBS_Server;Svr;tyrone-cluster;Scheduler was sent the command new
11/02/2013 10:22:22;0040;PBS_Server;Svr;tyrone-cluster;Scheduler was sent the command new
11/02/2013 10:22:42;0002;PBS_Server;Svr;PBS_Server;Torque Server Version = 3.0.5, loglevel = 0
11/02/2013 10:22:53;0040;PBS_Server;Svr;tyrone-cluster;Scheduler was sent the command new
11/02/2013 10:23:22;0040;PBS_Server;Svr;tyrone-cluster;Scheduler was sent the command new
11/02/2013 10:23:52;0040;PBS_Server;Svr;tyrone-cluster;Scheduler was sent the command new
11/02/2013 10:24:25;0040;PBS_Server;Svr;tyrone-cluster;Scheduler was sent the command new
11/02/2013 10:24:55;0040;PBS_Server;Svr;tyrone-cluster;Scheduler was sent the command new
11/02/2013 10:25:27;0040;PBS_Server;Svr;tyrone-cluster;Scheduler was sent the command new
11/02/2013 10:26:01;0040;PBS_Server;Svr;tyrone-cluster;Scheduler was sent the command new
11/02/2013 10:26:25;0040;PBS_Server;Svr;tyrone-cluster;Scheduler was sent the command new
11/02/2013 10:26:58;0040;PBS_Server;Svr;tyrone-cluster;Scheduler was sent the command new
11/02/2013 10:27:31;0040;PBS_Server;Svr;tyrone-cluster;Scheduler was sent the command new
11/02/2013 10:27:42;0002;PBS_Server;Svr;PBS_Server;Torque Server Version = 3.0.5, loglevel = 0
11/02/2013 10:28:00;0040;PBS_Server;Svr;tyrone-cluster;Scheduler was sent the command new
11/02/2013 10:28:37;0040;PBS_Server;Svr;tyrone-cluster;Scheduler was sent the command new
11/02/2013 10:29:06;0040;PBS_Server;Svr;tyrone-cluster;Scheduler was sent the command new
11/02/2013 10:29:39;0040;PBS_Server;Svr;tyrone-cluster;Scheduler was sent the command new
11/02/2013 10:30:08;0040;PBS_Server;Svr;tyrone-cluster;Scheduler was sent the command new
11/02/2013 10:30:37;0040;PBS_Server;Svr;tyrone-cluster;Scheduler was sent the command new
11/02/2013 10:31:08;0040;PBS_Server;Svr;tyrone-cluster;Scheduler was sent the command new
11/02/2013 10:31:37;0040;PBS_Server;Svr;tyrone-cluster;Scheduler was sent the command new
11/02/2013 10:32:07;0040;PBS_Server;Svr;tyrone-cluster;Scheduler was sent the command new
11/02/2013 10:32:40;0040;PBS_Server;Svr;tyrone-cluster;Scheduler was sent the command new
11/02/2013 10:32:42;0002;PBS_Server;Svr;PBS_Server;Torque Server Version = 3.0.5, loglevel = 0
11/02/2013 10:33:10;0040;PBS_Server;Svr;tyrone-cluster;Scheduler was sent the command new
11/02/2013 10:33:42;0040;PBS_Server;Svr;tyrone-cluster;Scheduler was sent the command new
11/02/2013 10:34:16;0040;PBS_Server;Svr;tyrone-cluster;Scheduler was sent the command new
11/02/2013 10:34:40;0040;PBS_Server;Svr;tyrone-cluster;Scheduler was sent the command new
11/02/2013 10:35:13;0040;PBS_Server;Svr;tyrone-cluster;Scheduler was sent the command new
11/02/2013 10:35:46;0040;PBS_Server;Svr;tyrone-cluster;Scheduler was sent the command new
11/02/2013 10:36:15;0040;PBS_Server;Svr;tyrone-cluster;Scheduler was sent the command new
11/02/2013 10:36:52;0040;PBS_Server;Svr;tyrone-cluster;Scheduler was sent the command new
11/02/2013 10:37:18;0040;PBS_Server;Svr;tyrone-cluster;Scheduler was sent the command new
11/02/2013 10:37:42;0002;PBS_Server;Svr;PBS_Server;Torque Server Version = 3.0.5, loglevel = 0
11/02/2013 10:37:52;0040;PBS_Server;Svr;tyrone-cluster;Scheduler was sent the command new
11/02/2013 10:38:22;0040;PBS_Server;Svr;tyrone-cluster;Scheduler was sent the command new
11/02/2013 10:38:51;0040;PBS_Server;Svr;tyrone-cluster;Scheduler was sent the command new
11/02/2013 10:39:23;0040;PBS_Server;Svr;tyrone-cluster;Scheduler was sent the command new
11/02/2013 10:39:52;0040;PBS_Server;Svr;tyrone-cluster;Scheduler was sent the command new
11/02/2013 10:40:22;0040;PBS_Server;Svr;tyrone-cluster;Scheduler was sent the command new
11/02/2013 10:40:53;0040;PBS_Server;Svr;tyrone-cluster;Scheduler was sent the command new
11/02/2013 10:41:22;0040;PBS_Server;Svr;tyrone-cluster;Scheduler was sent the command new
11/02/2013 10:41:52;0040;PBS_Server;Svr;tyrone-cluster;Scheduler was sent the command new
11/02/2013 10:42:24;0040;PBS_Server;Svr;tyrone-cluster;Scheduler was sent the command new
11/02/2013 10:42:42;0002;PBS_Server;Svr;PBS_Server;Torque Server Version = 3.0.5, loglevel = 0
11/02/2013 10:42:55;0040;PBS_Server;Svr;tyrone-cluster;Scheduler was sent the command new
11/02/2013 10:43:27;0040;PBS_Server;Svr;tyrone-cluster;Scheduler was sent the command new
11/02/2013 10:44:00;0040;PBS_Server;Svr;tyrone-cluster;Scheduler was sent the command new
11/02/2013 10:44:25;0040;PBS_Server;Svr;tyrone-cluster;Scheduler was sent the command new
11/02/2013 10:44:58;0040;PBS_Server;Svr;tyrone-cluster;Scheduler was sent the command new
11/02/2013 10:45:31;0040;PBS_Server;Svr;tyrone-cluster;Scheduler was sent the command new
11/02/2013 10:46:00;0040;PBS_Server;Svr;tyrone-cluster;Scheduler was sent the command new
11/02/2013 10:46:26;0008;PBS_Server;Job;31394.tyrone-cluster;Job deleted at request of secbadar@tyrone-cluster
11/02/2013 10:46:26;0008;PBS_Server;Job;31394.tyrone-cluster;Job sent signal SIGTERM on delete
11/02/2013 10:46:26;000d;PBS_Server;Job;31394.tyrone-cluster;Not sending email: User does not want mail of this type.
11/02/2013 10:46:26;0010;PBS_Server;Job;31394.tyrone-cluster;Exit_status=143 resources_used.cput=07:13:55 resources_used.mem=2924124kb resources_used.vmem=38046024kb resources_used.walltime=07:15:59
11/02/2013 10:46:26;0008;PBS_Server;Job;NULL;on_job_exit valid pjob: 0x2dee690 (substate=50)
11/02/2013 10:46:26;0008;PBS_Server;Job;NULL;on_job_exit valid pjob: 0x2dee690 (substate=51)
11/02/2013 10:46:26;0008;PBS_Server;Job;NULL;on_job_exit valid pjob: 0x2dee690 (substate=51)
11/02/2013 10:46:26;0008;PBS_Server;Job;NULL;on_job_exit valid pjob: 0x2dee690 (substate=53)
11/02/2013 10:46:26;0100;PBS_Server;Job;31394.tyrone-cluster;dequeuing from qp256, state COMPLETE
11/02/2013 10:46:26;0040;PBS_Server;Svr;tyrone-cluster;Scheduler was sent the command term
11/02/2013 10:46:27;0008;PBS_Server;Job;31395.tyrone-cluster;Job Modified at request of Scheduler@tyrone-cluster
11/02/2013 10:46:27;0008;PBS_Server;Job;31395.tyrone-cluster;Job Run at request of Scheduler@tyrone-cluster
11/02/2013 10:46:27;0040;PBS_Server;Svr;tyrone-cluster;Scheduler was sent the command recyc
11/02/2013 10:46:33;0100;PBS_Server;Job;31389.tyrone-cluster;dequeuing from batch, state QUEUED
11/02/2013 10:46:33;0100;PBS_Server;Job;31389.tyrone-cluster;enqueuing into qp256, state 1 hop 1
11/02/2013 10:46:37;0040;PBS_Server;Svr;tyrone-cluster;Scheduler was sent the command new
11/02/2013 10:46:38;0008;PBS_Server;Job;31389.tyrone-cluster;Job Modified at request of Scheduler@tyrone-cluster
11/02/2013 10:47:03;0040;PBS_Server;Svr;tyrone-cluster;Scheduler was sent the command new
11/02/2013 10:47:37;0040;PBS_Server;Svr;tyrone-cluster;Scheduler was sent the command new
11/02/2013 10:47:42;0002;PBS_Server;Svr;PBS_Server;Torque Server Version = 3.0.5, loglevel = 0
11/02/2013 10:47:54;000d;PBS_Server;Job;31395.tyrone-cluster;Not sending email: User does not want mail of this type.
11/02/2013 10:48:07;0040;PBS_Server;Svr;tyrone-cluster;Scheduler was sent the command new
11/02/2013 10:48:37;0040;PBS_Server;Svr;tyrone-cluster;Scheduler was sent the command new
11/02/2013 10:49:08;0040;PBS_Server;Svr;tyrone-cluster;Scheduler was sent the command new
11/02/2013 10:49:37;0040;PBS_Server;Svr;tyrone-cluster;Scheduler was sent the command new
11/02/2013 10:50:07;0040;PBS_Server;Svr;tyrone-cluster;Scheduler was sent the command new
11/02/2013 10:50:39;0040;PBS_Server;Svr;tyrone-cluster;Scheduler was sent the command new
11/02/2013 10:51:10;0040;PBS_Server;Svr;tyrone-cluster;Scheduler was sent the command new
11/02/2013 10:51:43;0040;PBS_Server;Svr;tyrone-cluster;Scheduler was sent the command new
11/02/2013 10:52:15;0040;PBS_Server;Svr;tyrone-cluster;Scheduler was sent the command new
11/02/2013 10:52:42;0002;PBS_Server;Svr;PBS_Server;Torque Server Version = 3.0.5, loglevel = 0
11/02/2013 10:52:43;0040;PBS_Server;Svr;tyrone-cluster;Scheduler was sent the command new
11/02/2013 10:53:00;000d;PBS_Server;Job;31231.tyrone-cluster;Not sending email: User does not want mail of this type.
11/02/2013 10:53:00;0010;PBS_Server;Job;31231.tyrone-cluster;Exit_status=143 resources_used.cput=1531:13:24 resources_used.mem=6614280kb resources_used.vmem=39440740kb resources_used.walltime=24:00:42
11/02/2013 10:53:00;0008;PBS_Server;Job;NULL;on_job_exit valid pjob: 0x2efae20 (substate=50)
11/02/2013 10:53:00;0008;PBS_Server;Job;NULL;on_job_exit valid pjob: 0x2efae20 (substate=51)
11/02/2013 10:53:01;0008;PBS_Server;Job;NULL;on_job_exit valid pjob: 0x2efae20 (substate=51)
11/02/2013 10:53:01;0008;PBS_Server;Job;NULL;on_job_exit valid pjob: 0x2efae20 (substate=53)
11/02/2013 10:53:01;0100;PBS_Server;Job;31231.tyrone-cluster;dequeuing from qp64, state COMPLETE
11/02/2013 10:53:01;0040;PBS_Server;Svr;tyrone-cluster;Scheduler was sent the command term
11/02/2013 10:53:05;0008;PBS_Server;Job;31232.tyrone-cluster;Job Modified at request of Scheduler@tyrone-cluster
11/02/2013 10:53:05;0008;PBS_Server;Job;31232.tyrone-cluster;Job Run at request of Scheduler@tyrone-cluster
11/02/2013 10:53:06;0040;PBS_Server;Svr;tyrone-cluster;Scheduler was sent the command recyc
11/02/2013 10:53:06;000d;PBS_Server;Job;31232.tyrone-cluster;Not sending email: User does not want mail of this type.
11/02/2013 10:53:12;0100;PBS_Server;Job;31234.tyrone-cluster;dequeuing from batch, state QUEUED
11/02/2013 10:53:12;0100;PBS_Server;Job;31234.tyrone-cluster;enqueuing into qp64, state 1 hop 1
11/02/2013 10:53:13;0040;PBS_Server;Svr;tyrone-cluster;Scheduler was sent the command new
11/02/2013 10:53:17;0008;PBS_Server;Job;31234.tyrone-cluster;Job Modified at request of Scheduler@tyrone-cluster
11/02/2013 10:53:45;0040;PBS_Server;Svr;tyrone-cluster;Scheduler was sent the command new
11/02/2013 10:54:15;0040;PBS_Server;Svr;tyrone-cluster;Scheduler was sent the command new
11/02/2013 10:54:45;0040;PBS_Server;Svr;tyrone-cluster;Scheduler was sent the command new
11/02/2013 10:55:16;0040;PBS_Server;Svr;tyrone-cluster;Scheduler was sent the command new
11/02/2013 10:55:45;0040;PBS_Server;Svr;tyrone-cluster;Scheduler was sent the command new
11/02/2013 10:56:15;0040;PBS_Server;Svr;tyrone-cluster;Scheduler was sent the command new
11/02/2013 10:56:46;0040;PBS_Server;Svr;tyrone-cluster;Scheduler was sent the command new
11/02/2013 10:57:17;0040;PBS_Server;Svr;tyrone-cluster;Scheduler was sent the command new
11/02/2013 10:57:42;0002;PBS_Server;Svr;PBS_Server;Torque Server Version = 3.0.5, loglevel = 0
11/02/2013 10:57:45;0040;PBS_Server;Svr;tyrone-cluster;Scheduler was sent the command new
11/02/2013 10:58:16;0040;PBS_Server;Svr;tyrone-cluster;Scheduler was sent the command new
11/02/2013 10:58:45;0040;PBS_Server;Svr;tyrone-cluster;Scheduler was sent the command new
11/02/2013 10:59:15;0040;PBS_Server;Svr;tyrone-cluster;Scheduler was sent the command new
11/02/2013 10:59:46;0040;PBS_Server;Svr;tyrone-cluster;Scheduler was sent the command new
11/02/2013 11:00:18;0040;PBS_Server;Svr;tyrone-cluster;Scheduler was sent the command new
11/02/2013 11:00:45;0040;PBS_Server;Svr;tyrone-cluster;Scheduler was sent the command new
11/02/2013 11:01:17;0040;PBS_Server;Svr;tyrone-cluster;Scheduler was sent the command new
11/02/2013 11:01:52;0040;PBS_Server;Svr;tyrone-cluster;Scheduler was sent the command new
11/02/2013 11:02:22;0040;PBS_Server;Svr;tyrone-cluster;Scheduler was sent the command new
11/02/2013 11:02:42;0002;PBS_Server;Svr;PBS_Server;Torque Server Version = 3.0.5, loglevel = 0
11/02/2013 11:02:52;0040;PBS_Server;Svr;tyrone-cluster;Scheduler was sent the command new
11/02/2013 11:03:23;0040;PBS_Server;Svr;tyrone-cluster;Scheduler was sent the command new
11/02/2013 11:03:52;0040;PBS_Server;Svr;tyrone-cluster;Scheduler was sent the command new
11/02/2013 11:04:22;0040;PBS_Server;Svr;tyrone-cluster;Scheduler was sent the command new
11/02/2013 11:04:54;0040;PBS_Server;Svr;tyrone-cluster;Scheduler was sent the command new
11/02/2013 11:05:25;0040;PBS_Server;Svr;tyrone-cluster;Scheduler was sent the command new
11/02/2013 11:05:54;0040;PBS_Server;Svr;tyrone-cluster;Scheduler was sent the command new
11/02/2013 11:06:27;0040;PBS_Server;Svr;tyrone-cluster;Scheduler was sent the command new
11/02/2013 11:06:55;0040;PBS_Server;Svr;tyrone-cluster;Scheduler was sent the command new
11/02/2013 11:07:28;0040;PBS_Server;Svr;tyrone-cluster;Scheduler was sent the command new
11/02/2013 11:07:42;0002;PBS_Server;Svr;PBS_Server;Torque Server Version = 3.0.5, loglevel = 0
11/02/2013 11:08:00;0040;PBS_Server;Svr;tyrone-cluster;Scheduler was sent the command new
11/02/2013 11:08:29;0040;PBS_Server;Svr;tyrone-cluster;Scheduler was sent the command new
11/02/2013 11:08:58;0040;PBS_Server;Svr;tyrone-cluster;Scheduler was sent the command new
11/02/2013 11:09:30;0040;PBS_Server;Svr;tyrone-cluster;Scheduler was sent the command new
11/02/2013 11:10:00;0040;PBS_Server;Svr;tyrone-cluster;Scheduler was sent the command new
11/02/2013 11:10:30;0040;PBS_Server;Svr;tyrone-cluster;Scheduler was sent the command new
11/02/2013 11:11:01;0040;PBS_Server;Svr;tyrone-cluster;Scheduler was sent the command new
11/02/2013 11:11:30;0040;PBS_Server;Svr;tyrone-cluster;Scheduler was sent the command new
11/02/2013 11:12:00;0040;PBS_Server;Svr;tyrone-cluster;Scheduler was sent the command new
11/02/2013 11:12:32;0040;PBS_Server;Svr;tyrone-cluster;Scheduler was sent the command new
11/02/2013 11:12:42;0002;PBS_Server;Svr;PBS_Server;Torque Server Version = 3.0.5, loglevel = 0
11/02/2013 11:13:02;0040;PBS_Server;Svr;tyrone-cluster;Scheduler was sent the command new
11/02/2013 11:13:30;0040;PBS_Server;Svr;tyrone-cluster;Scheduler was sent the command new
11/02/2013 11:14:01;0040;PBS_Server;Svr;tyrone-cluster;Scheduler was sent the command new
11/02/2013 11:14:30;0040;PBS_Server;Svr;tyrone-cluster;Scheduler was sent the command new
11/02/2013 11:15:00;0040;PBS_Server;Svr;tyrone-cluster;Scheduler was sent the command new
11/02/2013 11:15:31;0040;PBS_Server;Svr;tyrone-cluster;Scheduler was sent the command new
11/02/2013 11:16:03;0040;PBS_Server;Svr;tyrone-cluster;Scheduler was sent the command new
11/02/2013 11:16:30;0040;PBS_Server;Svr;tyrone-cluster;Scheduler was sent the command new
11/02/2013 11:17:02;0040;PBS_Server;Svr;tyrone-cluster;Scheduler was sent the command new
11/02/2013 11:17:36;0040;PBS_Server;Svr;tyrone-cluster;Scheduler was sent the command new
11/02/2013 11:17:42;0002;PBS_Server;Svr;PBS_Server;Torque Server Version = 3.0.5, loglevel = 0
11/02/2013 11:18:07;0040;PBS_Server;Svr;tyrone-cluster;Scheduler was sent the command new
11/02/2013 11:18:33;0040;PBS_Server;Svr;tyrone-cluster;Scheduler was sent the command new
11/02/2013 11:19:07;0040;PBS_Server;Svr;tyrone-cluster;Scheduler was sent the command new
11/02/2013 11:19:37;0040;PBS_Server;Svr;tyrone-cluster;Scheduler was sent the command new
11/02/2013 11:20:08;0040;PBS_Server;Svr;tyrone-cluster;Scheduler was sent the command new
11/02/2013 11:20:40;0040;PBS_Server;Svr;tyrone-cluster;Scheduler was sent the command new
11/02/2013 11:21:08;0040;PBS_Server;Svr;tyrone-cluster;Scheduler was sent the command new
11/02/2013 11:21:38;0040;PBS_Server;Svr;tyrone-cluster;Scheduler was sent the command new
11/02/2013 11:22:14;0040;PBS_Server;Svr;tyrone-cluster;Scheduler was sent the command new
11/02/2013 11:22:41;0040;PBS_Server;Svr;tyrone-cluster;Scheduler was sent the command new
11/02/2013 11:22:42;0002;PBS_Server;Svr;PBS_Server;Torque Server Version = 3.0.5, loglevel = 0
11/02/2013 11:22:43;0008;PBS_Server;Job;31395.tyrone-cluster;Job deleted at request of secbadar@tyrone-cluster
11/02/2013 11:22:43;0008;PBS_Server;Job;31395.tyrone-cluster;Job sent signal SIGTERM on delete
11/02/2013 11:22:43;000d;PBS_Server;Job;31395.tyrone-cluster;Not sending email: User does not want mail of this type.
11/02/2013 11:22:43;0010;PBS_Server;Job;31395.tyrone-cluster;Exit_status=143 resources_used.cput=00:53:48 resources_used.mem=721472kb resources_used.vmem=8883992kb resources_used.walltime=00:36:16
11/02/2013 11:22:43;0008;PBS_Server;Job;NULL;on_job_exit valid pjob: 0x338fb80 (substate=50)
11/02/2013 11:22:43;0008;PBS_Server;Job;NULL;on_job_exit valid pjob: 0x338fb80 (substate=51)
11/02/2013 11:22:43;0008;PBS_Server;Job;NULL;on_job_exit valid pjob: 0x338fb80 (substate=51)
11/02/2013 11:22:43;0008;PBS_Server;Job;NULL;on_job_exit valid pjob: 0x338fb80 (substate=53)
11/02/2013 11:22:43;0100;PBS_Server;Job;31395.tyrone-cluster;dequeuing from qp256, state COMPLETE
11/02/2013 11:22:43;0040;PBS_Server;Svr;tyrone-cluster;Scheduler was sent the command term
11/02/2013 11:22:43;0008;PBS_Server;Job;31389.tyrone-cluster;Job Modified at request of Scheduler@tyrone-cluster
11/02/2013 11:22:43;0008;PBS_Server;Job;31389.tyrone-cluster;Job Run at request of Scheduler@tyrone-cluster
11/02/2013 11:22:43;0040;PBS_Server;Svr;tyrone-cluster;Scheduler was sent the command recyc
11/02/2013 11:23:09;0100;PBS_Server;Job;31396.tyrone-cluster;dequeuing from batch, state QUEUED
11/02/2013 11:23:09;0100;PBS_Server;Job;31396.tyrone-cluster;enqueuing into qp256, state 1 hop 1
11/02/2013 11:23:13;0040;PBS_Server;Svr;tyrone-cluster;Scheduler was sent the command new
11/02/2013 11:23:13;0008;PBS_Server;Job;31396.tyrone-cluster;Job Modified at request of Scheduler@tyrone-cluster
11/02/2013 11:23:15;000d;PBS_Server;Job;31389.tyrone-cluster;Not sending email: User does not want mail of this type.
11/02/2013 11:23:44;0040;PBS_Server;Svr;tyrone-cluster;Scheduler was sent the command new
11/02/2013 11:24:12;0040;PBS_Server;Svr;tyrone-cluster;Scheduler was sent the command new
11/02/2013 11:24:45;0040;PBS_Server;Svr;tyrone-cluster;Scheduler was sent the command new
11/02/2013 11:25:07;000d;PBS_Server;Job;31334.tyrone-cluster;Not sending email: User does not want mail of this type.
11/02/2013 11:25:07;0010;PBS_Server;Job;31334.tyrone-cluster;Exit_status=0 resources_used.cput=621:46:55 resources_used.mem=676240kb resources_used.vmem=7136416kb resources_used.walltime=19:26:19
11/02/2013 11:25:07;0008;PBS_Server;Job;NULL;on_job_exit valid pjob: 0x2df7980 (substate=50)
11/02/2013 11:25:07;0008;PBS_Server;Job;NULL;on_job_exit valid pjob: 0x2df7980 (substate=51)
11/02/2013 11:25:11;0008;PBS_Server;Job;NULL;on_job_exit valid pjob: 0x2df7980 (substate=51)
11/02/2013 11:25:11;000d;PBS_Server;Job;31334.tyrone-cluster;Post job file processing error; job 31334.tyrone-cluster on host tyrone-node2/31+tyrone-node2/30+tyrone-node2/29+tyrone-node2/28+tyrone-node2/27+tyrone-node2/26+tyrone-node2/25+tyrone-node2/24+tyrone-node2/23+tyrone-node2/22+tyrone-node2/21+tyrone-node2/20+tyrone-node2/19+tyrone-node2/18+tyrone-node2/17+tyrone-node2/16+tyrone-node2/15+tyrone-node2/14+tyrone-node2/13+tyrone-node2/12+tyrone-node2/11+tyrone-node2/10+tyrone-node2/9+tyrone-node2/8+tyrone-node2/7+tyrone-node2/6+tyrone-node2/5+tyrone-node2/4+tyrone-node2/3+tyrone-node2/2+tyrone-node2/1+tyrone-node2/0
11/02/2013 11:25:11;0008;PBS_Server;Job;NULL;on_job_exit valid pjob: 0x2df7980 (substate=53)
11/02/2013 11:25:11;0100;PBS_Server;Job;31334.tyrone-cluster;dequeuing from qp32, state COMPLETE
11/02/2013 11:25:11;0040;PBS_Server;Svr;tyrone-cluster;Scheduler was sent the command term
11/02/2013 11:25:11;0008;PBS_Server;Job;31335.tyrone-cluster;Job Modified at request of Scheduler@tyrone-cluster
11/02/2013 11:25:11;0008;PBS_Server;Job;31335.tyrone-cluster;Job Run at request of Scheduler@tyrone-cluster
11/02/2013 11:25:12;0040;PBS_Server;Svr;tyrone-cluster;Scheduler was sent the command recyc
11/02/2013 11:25:12;000d;PBS_Server;Job;31335.tyrone-cluster;Not sending email: User does not want mail of this type.
11/02/2013 11:25:14;0100;PBS_Server;Job;31337.tyrone-cluster;dequeuing from batch, state QUEUED
11/02/2013 11:25:14;0100;PBS_Server;Job;31337.tyrone-cluster;enqueuing into qp32, state 1 hop 1
11/02/2013 11:25:16;0040;PBS_Server;Svr;tyrone-cluster;Scheduler was sent the command new
11/02/2013 11:25:16;0008;PBS_Server;Job;31337.tyrone-cluster;Job Modified at request of Scheduler@tyrone-cluster
11/02/2013 11:25:44;0040;PBS_Server;Svr;tyrone-cluster;Scheduler was sent the command new
11/02/2013 11:26:15;0040;PBS_Server;Svr;tyrone-cluster;Scheduler was sent the command new
11/02/2013 11:26:45;0040;PBS_Server;Svr;tyrone-cluster;Scheduler was sent the command new
11/02/2013 11:27:14;0040;PBS_Server;Svr;tyrone-cluster;Scheduler was sent the command new
11/02/2013 11:27:42;0002;PBS_Server;Svr;PBS_Server;Torque Server Version = 3.0.5, loglevel = 0
11/02/2013 11:27:45;0040;PBS_Server;Svr;tyrone-cluster;Scheduler was sent the command new
11/02/2013 11:28:16;0040;PBS_Server;Svr;tyrone-cluster;Scheduler was sent the command new
11/02/2013 11:28:45;0040;PBS_Server;Svr;tyrone-cluster;Scheduler was sent the command new
11/02/2013 11:29:16;0040;PBS_Server;Svr;tyrone-cluster;Scheduler was sent the command new
11/02/2013 11:29:47;0040;PBS_Server;Svr;tyrone-cluster;Scheduler was sent the command new
11/02/2013 11:30:17;0040;PBS_Server;Svr;tyrone-cluster;Scheduler was sent the command new
11/02/2013 11:30:47;0040;PBS_Server;Svr;tyrone-cluster;Scheduler was sent the command new
11/02/2013 11:31:19;0040;PBS_Server;Svr;tyrone-cluster;Scheduler was sent the command new
11/02/2013 11:31:30;0100;PBS_Server;Job;31402.tyrone-cluster;enqueuing into batch, state 1 hop 1
11/02/2013 11:31:30;0100;PBS_Server;Job;31402.tyrone-cluster;dequeuing from batch, state QUEUED
11/02/2013 11:31:30;0100;PBS_Server;Job;31402.tyrone-cluster;enqueuing into qp64, state 1 hop 1
11/02/2013 11:31:30;0008;PBS_Server;Job;31402.tyrone-cluster;Job Queued at request of ipcbbala@tyrone-cluster, owner = ipcbbala@tyrone-cluster, job name = n10, queue = qp64
11/02/2013 11:31:30;0040;PBS_Server;Svr;tyrone-cluster;Scheduler was sent the command new
11/02/2013 11:31:34;0008;PBS_Server;Job;31402.tyrone-cluster;Job Modified at request of Scheduler@tyrone-cluster
11/02/2013 11:31:34;0008;PBS_Server;Job;31402.tyrone-cluster;Job Run at request of Scheduler@tyrone-cluster
11/02/2013 11:31:34;0040;PBS_Server;Svr;tyrone-cluster;Scheduler was sent the command recyc
11/02/2013 11:31:34;000d;PBS_Server;Job;31402.tyrone-cluster;Not sending email: User does not want mail of this type.
11/02/2013 11:31:51;0040;PBS_Server;Svr;tyrone-cluster;Scheduler was sent the command new
11/02/2013 11:31:51;0008;PBS_Server;Job;31155.tyrone-cluster;Job Modified at request of Scheduler@tyrone-cluster
11/02/2013 11:31:51;0008;PBS_Server;Job;31156.tyrone-cluster;Job Modified at request of Scheduler@tyrone-cluster
11/02/2013 11:31:51;0008;PBS_Server;Job;31233.tyrone-cluster;Job Modified at request of Scheduler@tyrone-cluster
11/02/2013 11:31:51;0008;PBS_Server;Job;31348.tyrone-cluster;Job Modified at request of Scheduler@tyrone-cluster
11/02/2013 11:31:51;0008;PBS_Server;Job;31349.tyrone-cluster;Job Modified at request of Scheduler@tyrone-cluster
11/02/2013 11:31:51;0008;PBS_Server;Job;31234.tyrone-cluster;Job Modified at request of Scheduler@tyrone-cluster
11/02/2013 11:32:21;0040;PBS_Server;Svr;tyrone-cluster;Scheduler was sent the command new
11/02/2013 11:32:42;0002;PBS_Server;Svr;PBS_Server;Torque Server Version = 3.0.5, loglevel = 0
11/02/2013 11:32:54;0040;PBS_Server;Svr;tyrone-cluster;Scheduler was sent the command new
11/02/2013 11:33:26;0040;PBS_Server;Svr;tyrone-cluster;Scheduler was sent the command new
11/02/2013 11:33:57;0040;PBS_Server;Svr;tyrone-cluster;Scheduler was sent the command new
11/02/2013 11:34:24;0040;PBS_Server;Svr;tyrone-cluster;Scheduler was sent the command new
11/02/2013 11:34:56;0040;PBS_Server;Svr;tyrone-cluster;Scheduler was sent the command new
11/02/2013 11:35:28;0040;PBS_Server;Svr;tyrone-cluster;Scheduler was sent the command new
11/02/2013 11:36:00;0040;PBS_Server;Svr;tyrone-cluster;Scheduler was sent the command new
11/02/2013 11:36:31;0040;PBS_Server;Svr;tyrone-cluster;Scheduler was sent the command new
11/02/2013 11:36:59;0040;PBS_Server;Svr;tyrone-cluster;Scheduler was sent the command new
11/02/2013 11:37:30;0040;PBS_Server;Svr;tyrone-cluster;Scheduler was sent the command new
11/02/2013 11:37:42;0002;PBS_Server;Svr;PBS_Server;Torque Server Version = 3.0.5, loglevel = 0
11/02/2013 11:38:00;0040;PBS_Server;Svr;tyrone-cluster;Scheduler was sent the command new
11/02/2013 11:38:29;0040;PBS_Server;Svr;tyrone-cluster;Scheduler was sent the command new
11/02/2013 11:39:00;0040;PBS_Server;Svr;tyrone-cluster;Scheduler was sent the command new
11/02/2013 11:39:31;0040;PBS_Server;Svr;tyrone-cluster;Scheduler was sent the command new
11/02/2013 11:40:04;0040;PBS_Server;Svr;tyrone-cluster;Scheduler was sent the command new
11/02/2013 11:40:31;0040;PBS_Server;Svr;tyrone-cluster;Scheduler was sent the command new
11/02/2013 11:41:02;0040;PBS_Server;Svr;tyrone-cluster;Scheduler was sent the command new
11/02/2013 11:41:34;0040;PBS_Server;Svr;tyrone-cluster;Scheduler was sent the command new
11/02/2013 11:42:01;0040;PBS_Server;Svr;tyrone-cluster;Scheduler was sent the command new
11/02/2013 11:42:31;0040;PBS_Server;Svr;tyrone-cluster;Scheduler was sent the command new
11/02/2013 11:42:42;0002;PBS_Server;Svr;PBS_Server;Torque Server Version = 3.0.5, loglevel = 0
11/02/2013 11:43:00;0040;PBS_Server;Svr;tyrone-cluster;Scheduler was sent the command new
11/02/2013 11:43:31;0040;PBS_Server;Svr;tyrone-cluster;Scheduler was sent the command new
11/02/2013 11:44:02;0040;PBS_Server;Svr;tyrone-cluster;Scheduler was sent the command new
11/02/2013 11:44:29;000d;PBS_Server;Job;31389.tyrone-cluster;Not sending email: User does not want mail of this type.
11/02/2013 11:44:29;0010;PBS_Server;Job;31389.tyrone-cluster;Exit_status=0 resources_used.cput=10:36:52 resources_used.mem=2976516kb resources_used.vmem=38103100kb resources_used.walltime=00:21:45
11/02/2013 11:44:29;0008;PBS_Server;Job;NULL;on_job_exit valid pjob: 0x2e6ec10 (substate=50)
11/02/2013 11:44:29;0008;PBS_Server;Job;NULL;on_job_exit valid pjob: 0x2e6ec10 (substate=51)
11/02/2013 11:44:29;0008;PBS_Server;Job;NULL;on_job_exit valid pjob: 0x2e6ec10 (substate=51)
11/02/2013 11:44:29;0008;PBS_Server;Job;NULL;on_job_exit valid pjob: 0x2e6ec10 (substate=53)
11/02/2013 11:44:29;0100;PBS_Server;Job;31389.tyrone-cluster;dequeuing from qp256, state COMPLETE
11/02/2013 11:44:29;0040;PBS_Server;Svr;tyrone-cluster;Scheduler was sent the command term
11/02/2013 11:44:29;0008;PBS_Server;Job;31396.tyrone-cluster;Job Modified at request of Scheduler@tyrone-cluster
11/02/2013 11:44:29;0008;PBS_Server;Job;31396.tyrone-cluster;Job Run at request of Scheduler@tyrone-cluster
11/02/2013 11:44:29;0040;PBS_Server;Svr;tyrone-cluster;Scheduler was sent the command recyc
11/02/2013 11:44:30;0100;PBS_Server;Job;31397.tyrone-cluster;dequeuing from batch, state QUEUED
11/02/2013 11:44:30;0100;PBS_Server;Job;31397.tyrone-cluster;enqueuing into qp256, state 1 hop 1
11/02/2013 11:44:33;0040;PBS_Server;Svr;tyrone-cluster;Scheduler was sent the command new
11/02/2013 11:44:33;0008;PBS_Server;Job;31397.tyrone-cluster;Job Modified at request of Scheduler@tyrone-cluster
11/02/2013 11:45:01;0040;PBS_Server;Svr;tyrone-cluster;Scheduler was sent the command new
11/02/2013 11:45:03;000d;PBS_Server;Job;31396.tyrone-cluster;Not sending email: User does not want mail of this type.
11/02/2013 11:45:31;0040;PBS_Server;Svr;tyrone-cluster;Scheduler was sent the command new
11/02/2013 11:46:04;0040;PBS_Server;Svr;tyrone-cluster;Scheduler was sent the command new
11/02/2013 11:46:31;0040;PBS_Server;Svr;tyrone-cluster;Scheduler was sent the command new
11/02/2013 11:47:01;0040;PBS_Server;Svr;tyrone-cluster;Scheduler was sent the command new
11/02/2013 11:47:30;0040;PBS_Server;Svr;tyrone-cluster;Scheduler was sent the command new
11/02/2013 11:47:42;0002;PBS_Server;Svr;PBS_Server;Torque Server Version = 3.0.5, loglevel = 0
11/02/2013 11:48:01;0040;PBS_Server;Svr;tyrone-cluster;Scheduler was sent the command new
11/02/2013 11:48:32;0040;PBS_Server;Svr;tyrone-cluster;Scheduler was sent the command new
11/02/2013 11:49:06;0040;PBS_Server;Svr;tyrone-cluster;Scheduler was sent the command new
11/02/2013 11:49:36;0040;PBS_Server;Svr;tyrone-cluster;Scheduler was sent the command new
11/02/2013 11:50:09;0040;PBS_Server;Svr;tyrone-cluster;Scheduler was sent the command new
11/02/2013 11:50:44;0040;PBS_Server;Svr;tyrone-cluster;Scheduler was sent the command new
11/02/2013 11:51:12;0040;PBS_Server;Svr;tyrone-cluster;Scheduler was sent the command new
11/02/2013 11:51:39;0040;PBS_Server;Svr;tyrone-cluster;Scheduler was sent the command new
11/02/2013 11:52:14;0040;PBS_Server;Svr;tyrone-cluster;Scheduler was sent the command new
11/02/2013 11:52:42;0002;PBS_Server;Svr;PBS_Server;Torque Server Version = 3.0.5, loglevel = 0
11/02/2013 11:52:42;0040;PBS_Server;Svr;tyrone-cluster;Scheduler was sent the command new
11/02/2013 11:53:15;0040;PBS_Server;Svr;tyrone-cluster;Scheduler was sent the command new
11/02/2013 11:53:45;0040;PBS_Server;Svr;tyrone-cluster;Scheduler was sent the command new
11/02/2013 11:54:14;0040;PBS_Server;Svr;tyrone-cluster;Scheduler was sent the command new
11/02/2013 11:54:45;0040;PBS_Server;Svr;tyrone-cluster;Scheduler was sent the command new
11/02/2013 11:55:15;0040;PBS_Server;Svr;tyrone-cluster;Scheduler was sent the command new
11/02/2013 11:55:44;0040;PBS_Server;Svr;tyrone-cluster;Scheduler was sent the command new
11/02/2013 11:56:15;0040;PBS_Server;Svr;tyrone-cluster;Scheduler was sent the command new
11/02/2013 11:56:45;0040;PBS_Server;Svr;tyrone-cluster;Scheduler was sent the command new
11/02/2013 11:57:14;0040;PBS_Server;Svr;tyrone-cluster;Scheduler was sent the command new
11/02/2013 11:57:42;0002;PBS_Server;Svr;PBS_Server;Torque Server Version = 3.0.5, loglevel = 0
11/02/2013 11:57:45;0040;PBS_Server;Svr;tyrone-cluster;Scheduler was sent the command new
11/02/2013 11:58:16;0040;PBS_Server;Svr;tyrone-cluster;Scheduler was sent the command new
11/02/2013 11:58:44;0040;PBS_Server;Svr;tyrone-cluster;Scheduler was sent the command new
11/02/2013 11:59:15;0040;PBS_Server;Svr;tyrone-cluster;Scheduler was sent the command new
11/02/2013 11:59:45;0040;PBS_Server;Svr;tyrone-cluster;Scheduler was sent the command new
11/02/2013 12:00:14;0040;PBS_Server;Svr;tyrone-cluster;Scheduler was sent the command new
11/02/2013 12:00:45;0040;PBS_Server;Svr;tyrone-cluster;Scheduler was sent the command new
11/02/2013 12:01:16;0040;PBS_Server;Svr;tyrone-cluster;Scheduler was sent the command new
11/02/2013 12:01:20;0100;PBS_Server;Job;31403.tyrone-cluster;enqueuing into batch, state 1 hop 1
11/02/2013 12:01:20;0100;PBS_Server;Job;31403.tyrone-cluster;dequeuing from batch, state QUEUED
11/02/2013 12:01:20;0100;PBS_Server;Job;31403.tyrone-cluster;enqueuing into qp32, state 1 hop 1
11/02/2013 12:01:20;0008;PBS_Server;Job;31403.tyrone-cluster;Job Queued at request of mbumasha@tyrone-cluster, owner = mbumasha@tyrone-cluster, job name = calrman9-16-02-11-13, queue = qp32
11/02/2013 12:01:20;0040;PBS_Server;Svr;tyrone-cluster;Scheduler was sent the command new
11/02/2013 12:01:20;0008;PBS_Server;Job;31403.tyrone-cluster;Job Modified at request of Scheduler@tyrone-cluster
11/02/2013 12:01:20;0008;PBS_Server;Job;31403.tyrone-cluster;Job Run at request of Scheduler@tyrone-cluster
11/02/2013 12:01:20;0040;PBS_Server;Svr;tyrone-cluster;Scheduler was sent the command recyc
11/02/2013 12:01:20;000d;PBS_Server;Job;31403.tyrone-cluster;Not sending email: User does not want mail of this type.
11/02/2013 12:01:26;000d;PBS_Server;Job;31403.tyrone-cluster;Not sending email: User does not want mail of this type.
11/02/2013 12:01:26;0010;PBS_Server;Job;31403.tyrone-cluster;Exit_status=255 resources_used.cput=00:00:44 resources_used.mem=0kb resources_used.vmem=0kb resources_used.walltime=00:00:06
11/02/2013 12:01:26;0008;PBS_Server;Job;NULL;on_job_exit valid pjob: 0x2df7980 (substate=50)
11/02/2013 12:01:26;0008;PBS_Server;Job;NULL;on_job_exit valid pjob: 0x2df7980 (substate=51)
11/02/2013 12:01:26;0008;PBS_Server;Job;NULL;on_job_exit valid pjob: 0x2df7980 (substate=51)
11/02/2013 12:01:26;0008;PBS_Server;Job;NULL;on_job_exit valid pjob: 0x2df7980 (substate=53)
11/02/2013 12:01:26;0100;PBS_Server;Job;31403.tyrone-cluster;dequeuing from qp32, state COMPLETE
11/02/2013 12:01:26;0040;PBS_Server;Svr;tyrone-cluster;Scheduler was sent the command term
11/02/2013 12:01:37;0100;PBS_Server;Job;31404.tyrone-cluster;enqueuing into batch, state 1 hop 1
11/02/2013 12:01:37;0100;PBS_Server;Job;31404.tyrone-cluster;dequeuing from batch, state QUEUED
11/02/2013 12:01:37;0100;PBS_Server;Job;31404.tyrone-cluster;enqueuing into qp32, state 1 hop 1
11/02/2013 12:01:37;0008;PBS_Server;Job;31404.tyrone-cluster;Job Queued at request of mbumasha@tyrone-cluster, owner = mbumasha@tyrone-cluster, job name = calrman9-16-02-11-13, queue = qp32
11/02/2013 12:01:37;0040;PBS_Server;Svr;tyrone-cluster;Scheduler was sent the command new
11/02/2013 12:01:41;0008;PBS_Server;Job;31404.tyrone-cluster;Job Modified at request of Scheduler@tyrone-cluster
11/02/2013 12:01:41;0008;PBS_Server;Job;31404.tyrone-cluster;Job Run at request of Scheduler@tyrone-cluster
11/02/2013 12:01:41;0040;PBS_Server;Svr;tyrone-cluster;Scheduler was sent the command recyc
11/02/2013 12:01:41;000d;PBS_Server;Job;31404.tyrone-cluster;Not sending email: User does not want mail of this type.
11/02/2013 12:01:44;0040;PBS_Server;Svr;tyrone-cluster;Scheduler was sent the command new
11/02/2013 12:01:47;000d;PBS_Server;Job;31404.tyrone-cluster;Not sending email: User does not want mail of this type.
11/02/2013 12:01:47;0010;PBS_Server;Job;31404.tyrone-cluster;Exit_status=255 resources_used.cput=00:00:51 resources_used.mem=0kb resources_used.vmem=0kb resources_used.walltime=00:00:06
11/02/2013 12:01:47;0008;PBS_Server;Job;NULL;on_job_exit valid pjob: 0x2e2c540 (substate=50)
11/02/2013 12:01:47;0008;PBS_Server;Job;NULL;on_job_exit valid pjob: 0x2e2c540 (substate=51)
11/02/2013 12:01:48;0008;PBS_Server;Job;NULL;on_job_exit valid pjob: 0x2e2c540 (substate=51)
11/02/2013 12:01:48;0008;PBS_Server;Job;NULL;on_job_exit valid pjob: 0x2e2c540 (substate=53)
11/02/2013 12:01:48;0100;PBS_Server;Job;31404.tyrone-cluster;dequeuing from qp32, state COMPLETE
11/02/2013 12:01:50;0100;PBS_Server;Job;31405.tyrone-cluster;enqueuing into batch, state 1 hop 1
11/02/2013 12:01:50;0100;PBS_Server;Job;31405.tyrone-cluster;dequeuing from batch, state QUEUED
11/02/2013 12:01:50;0100;PBS_Server;Job;31405.tyrone-cluster;enqueuing into qp32, state 1 hop 1
11/02/2013 12:01:50;0008;PBS_Server;Job;31405.tyrone-cluster;Job Queued at request of mbumasha@tyrone-cluster, owner = mbumasha@tyrone-cluster, job name = calrman9-16-02-11-13, queue = qp32
11/02/2013 12:01:50;0040;PBS_Server;Svr;tyrone-cluster;Scheduler was sent the command new
11/02/2013 12:01:55;0008;PBS_Server;Job;31405.tyrone-cluster;Job Modified at request of Scheduler@tyrone-cluster
11/02/2013 12:01:55;0008;PBS_Server;Job;31405.tyrone-cluster;Job Run at request of Scheduler@tyrone-cluster
11/02/2013 12:01:55;0040;PBS_Server;Svr;tyrone-cluster;Scheduler was sent the command recyc
11/02/2013 12:01:55;000d;PBS_Server;Job;31405.tyrone-cluster;Not sending email: User does not want mail of this type.
11/02/2013 12:02:01;000d;PBS_Server;Job;31405.tyrone-cluster;Not sending email: User does not want mail of this type.
11/02/2013 12:02:01;0010;PBS_Server;Job;31405.tyrone-cluster;Exit_status=255 resources_used.cput=00:00:55 resources_used.mem=0kb resources_used.vmem=0kb resources_used.walltime=00:00:06
11/02/2013 12:02:01;0008;PBS_Server;Job;NULL;on_job_exit valid pjob: 0x2e2c540 (substate=50)
11/02/2013 12:02:01;0008;PBS_Server;Job;NULL;on_job_exit valid pjob: 0x2e2c540 (substate=51)
11/02/2013 12:02:01;0008;PBS_Server;Job;NULL;on_job_exit valid pjob: 0x2e2c540 (substate=51)
11/02/2013 12:02:01;0008;PBS_Server;Job;NULL;on_job_exit valid pjob: 0x2e2c540 (substate=53)
11/02/2013 12:02:01;0100;PBS_Server;Job;31405.tyrone-cluster;dequeuing from qp32, state COMPLETE
11/02/2013 12:02:01;0040;PBS_Server;Svr;tyrone-cluster;Scheduler was sent the command term
11/02/2013 12:02:03;0100;PBS_Server;Job;31406.tyrone-cluster;enqueuing into batch, state 1 hop 1
11/02/2013 12:02:03;0100;PBS_Server;Job;31406.tyrone-cluster;dequeuing from batch, state QUEUED
11/02/2013 12:02:03;0100;PBS_Server;Job;31406.tyrone-cluster;enqueuing into qp32, state 1 hop 1
11/02/2013 12:02:03;0008;PBS_Server;Job;31406.tyrone-cluster;Job Queued at request of mbumasha@tyrone-cluster, owner = mbumasha@tyrone-cluster, job name = calrman9-16-02-11-13, queue = qp32
11/02/2013 12:02:05;0008;PBS_Server;Job;31406.tyrone-cluster;Job Modified at request of Scheduler@tyrone-cluster
11/02/2013 12:02:05;0008;PBS_Server;Job;31406.tyrone-cluster;Job Run at request of Scheduler@tyrone-cluster
11/02/2013 12:02:05;0040;PBS_Server;Svr;tyrone-cluster;Scheduler was sent the command recyc
11/02/2013 12:02:05;000d;PBS_Server;Job;31406.tyrone-cluster;Not sending email: User does not want mail of this type.
11/02/2013 12:02:11;000d;PBS_Server;Job;31406.tyrone-cluster;Not sending email: User does not want mail of this type.
11/02/2013 12:02:11;0010;PBS_Server;Job;31406.tyrone-cluster;Exit_status=255 resources_used.cput=00:00:49 resources_used.mem=0kb resources_used.vmem=0kb resources_used.walltime=00:00:06
11/02/2013 12:02:11;0008;PBS_Server;Job;NULL;on_job_exit valid pjob: 0x2e2c540 (substate=50)
11/02/2013 12:02:11;0008;PBS_Server;Job;NULL;on_job_exit valid pjob: 0x2e2c540 (substate=51)
11/02/2013 12:02:12;0008;PBS_Server;Job;NULL;on_job_exit valid pjob: 0x2e2c540 (substate=51)
11/02/2013 12:02:12;0008;PBS_Server;Job;NULL;on_job_exit valid pjob: 0x2e2c540 (substate=53)
11/02/2013 12:02:12;0100;PBS_Server;Job;31406.tyrone-cluster;dequeuing from qp32, state COMPLETE
11/02/2013 12:02:12;0040;PBS_Server;Svr;tyrone-cluster;Scheduler was sent the command term
11/02/2013 12:02:42;0002;PBS_Server;Svr;PBS_Server;Torque Server Version = 3.0.5, loglevel = 0
11/02/2013 12:02:45;0040;PBS_Server;Svr;tyrone-cluster;Scheduler was sent the command new
11/02/2013 12:03:14;0040;PBS_Server;Svr;tyrone-cluster;Scheduler was sent the command new
11/02/2013 12:03:45;0040;PBS_Server;Svr;tyrone-cluster;Scheduler was sent the command new
11/02/2013 12:04:15;0040;PBS_Server;Svr;tyrone-cluster;Scheduler was sent the command new
11/02/2013 12:04:25;0100;PBS_Server;Job;31407.tyrone-cluster;enqueuing into batch, state 1 hop 1
11/02/2013 12:04:25;0100;PBS_Server;Job;31407.tyrone-cluster;dequeuing from batch, state QUEUED
11/02/2013 12:04:25;0100;PBS_Server;Job;31407.tyrone-cluster;enqueuing into qp32, state 1 hop 1
11/02/2013 12:04:25;0008;PBS_Server;Job;31407.tyrone-cluster;Job Queued at request of mbumasha@tyrone-cluster, owner = mbumasha@tyrone-cluster, job name = calrman9-16-02-11-13, queue = qp32
11/02/2013 12:04:25;0040;PBS_Server;Svr;tyrone-cluster;Scheduler was sent the command new
11/02/2013 12:04:25;0008;PBS_Server;Job;31407.tyrone-cluster;Job Modified at request of Scheduler@tyrone-cluster
11/02/2013 12:04:25;0008;PBS_Server;Job;31407.tyrone-cluster;Job Run at request of Scheduler@tyrone-cluster
11/02/2013 12:04:25;0040;PBS_Server;Svr;tyrone-cluster;Scheduler was sent the command recyc
11/02/2013 12:04:25;000d;PBS_Server;Job;31407.tyrone-cluster;Not sending email: User does not want mail of this type.
11/02/2013 12:04:44;0040;PBS_Server;Svr;tyrone-cluster;Scheduler was sent the command new
11/02/2013 12:04:44;0008;PBS_Server;Job;31324.tyrone-cluster;Job Modified at request of Scheduler@tyrone-cluster
11/02/2013 12:04:44;0008;PBS_Server;Job;31336.tyrone-cluster;Job Modified at request of Scheduler@tyrone-cluster
11/02/2013 12:04:44;0008;PBS_Server;Job;31377.tyrone-cluster;Job Modified at request of Scheduler@tyrone-cluster
11/02/2013 12:04:44;0008;PBS_Server;Job;31378.tyrone-cluster;Job Modified at request of Scheduler@tyrone-cluster
11/02/2013 12:04:44;0008;PBS_Server;Job;31325.tyrone-cluster;Job Modified at request of Scheduler@tyrone-cluster
11/02/2013 12:04:44;0008;PBS_Server;Job;31337.tyrone-cluster;Job Modified at request of Scheduler@tyrone-cluster
11/02/2013 12:04:56;0100;PBS_Server;Job;31408.tyrone-cluster;enqueuing into batch, state 1 hop 1
11/02/2013 12:04:56;0100;PBS_Server;Job;31408.tyrone-cluster;dequeuing from batch, state QUEUED
11/02/2013 12:04:56;0100;PBS_Server;Job;31408.tyrone-cluster;enqueuing into qp32, state 1 hop 1
11/02/2013 12:04:56;0008;PBS_Server;Job;31408.tyrone-cluster;Job Queued at request of mbumasha@tyrone-cluster, owner = mbumasha@tyrone-cluster, job name = calrman9-16-02-11-13, queue = qp32
11/02/2013 12:04:56;0040;PBS_Server;Svr;tyrone-cluster;Scheduler was sent the command new
11/02/2013 12:05:00;0008;PBS_Server;Job;31408.tyrone-cluster;Job Modified at request of Scheduler@tyrone-cluster
11/02/2013 12:05:14;0040;PBS_Server;Svr;tyrone-cluster;Scheduler was sent the command new
11/02/2013 12:05:14;0100;PBS_Server;Job;31409.tyrone-cluster;enqueuing into batch, state 1 hop 1
11/02/2013 12:05:14;0100;PBS_Server;Job;31409.tyrone-cluster;dequeuing from batch, state QUEUED
11/02/2013 12:05:14;0100;PBS_Server;Job;31409.tyrone-cluster;enqueuing into qp32, state 1 hop 1
11/02/2013 12:05:14;0008;PBS_Server;Job;31409.tyrone-cluster;Job Queued at request of mbumasha@tyrone-cluster, owner = mbumasha@tyrone-cluster, job name = calrman9-16-02-11-13, queue = qp32
11/02/2013 12:05:18;0008;PBS_Server;Job;31409.tyrone-cluster;Job Modified at request of Scheduler@tyrone-cluster
11/02/2013 12:05:29;0100;PBS_Server;Job;31410.tyrone-cluster;enqueuing into batch, state 1 hop 1
11/02/2013 12:05:29;0008;PBS_Server;Job;31410.tyrone-cluster;Job Queued at request of mbumasha@tyrone-cluster, owner = mbumasha@tyrone-cluster, job name = calrman9-16-02-11-13, queue = batch
11/02/2013 12:05:29;0040;PBS_Server;Svr;tyrone-cluster;Scheduler was sent the command new
11/02/2013 12:05:30;0008;PBS_Server;Job;31410.tyrone-cluster;Job Modified at request of Scheduler@tyrone-cluster
11/02/2013 12:05:46;0040;PBS_Server;Svr;tyrone-cluster;Scheduler was sent the command new
11/02/2013 12:06:00;0040;PBS_Server;Svr;tyrone-cluster;Scheduler was sent the command new
11/02/2013 12:06:14;0040;PBS_Server;Svr;tyrone-cluster;Scheduler was sent the command new
11/02/2013 12:06:30;0040;PBS_Server;Svr;tyrone-cluster;Scheduler was sent the command new
11/02/2013 12:06:45;0040;PBS_Server;Svr;tyrone-cluster;Scheduler was sent the command new
11/02/2013 12:06:59;0040;PBS_Server;Svr;tyrone-cluster;Scheduler was sent the command new
11/02/2013 12:07:15;0040;PBS_Server;Svr;tyrone-cluster;Scheduler was sent the command new
11/02/2013 12:07:30;0040;PBS_Server;Svr;tyrone-cluster;Scheduler was sent the command new
11/02/2013 12:07:42;0002;PBS_Server;Svr;PBS_Server;Torque Server Version = 3.0.5, loglevel = 0
11/02/2013 12:07:44;0040;PBS_Server;Svr;tyrone-cluster;Scheduler was sent the command new
11/02/2013 12:08:00;0040;PBS_Server;Svr;tyrone-cluster;Scheduler was sent the command new
11/02/2013 12:08:15;0040;PBS_Server;Svr;tyrone-cluster;Scheduler was sent the command new
11/02/2013 12:08:29;0040;PBS_Server;Svr;tyrone-cluster;Scheduler was sent the command new
11/02/2013 12:08:45;0040;PBS_Server;Svr;tyrone-cluster;Scheduler was sent the command new
11/02/2013 12:09:00;0040;PBS_Server;Svr;tyrone-cluster;Scheduler was sent the command new
11/02/2013 12:09:14;0040;PBS_Server;Svr;tyrone-cluster;Scheduler was sent the command new
11/02/2013 12:09:30;0040;PBS_Server;Svr;tyrone-cluster;Scheduler was sent the command new
11/02/2013 12:09:45;0040;PBS_Server;Svr;tyrone-cluster;Scheduler was sent the command new
11/02/2013 12:09:59;0040;PBS_Server;Svr;tyrone-cluster;Scheduler was sent the command new
11/02/2013 12:10:15;0040;PBS_Server;Svr;tyrone-cluster;Scheduler was sent the command new
11/02/2013 12:10:30;0040;PBS_Server;Svr;tyrone-cluster;Scheduler was sent the command new
11/02/2013 12:10:44;0040;PBS_Server;Svr;tyrone-cluster;Scheduler was sent the command new
11/02/2013 12:11:01;0040;PBS_Server;Svr;tyrone-cluster;Scheduler was sent the command new
11/02/2013 12:11:15;0040;PBS_Server;Svr;tyrone-cluster;Scheduler was sent the command new
11/02/2013 12:11:29;0040;PBS_Server;Svr;tyrone-cluster;Scheduler was sent the command new
11/02/2013 12:11:45;0040;PBS_Server;Svr;tyrone-cluster;Scheduler was sent the command new
11/02/2013 12:12:00;0040;PBS_Server;Svr;tyrone-cluster;Scheduler was sent the command new
11/02/2013 12:12:14;0040;PBS_Server;Svr;tyrone-cluster;Scheduler was sent the command new
11/02/2013 12:12:30;0040;PBS_Server;Svr;tyrone-cluster;Scheduler was sent the command new
11/02/2013 12:12:42;0002;PBS_Server;Svr;PBS_Server;Torque Server Version = 3.0.5, loglevel = 0
11/02/2013 12:12:45;0040;PBS_Server;Svr;tyrone-cluster;Scheduler was sent the command new
11/02/2013 12:12:59;0040;PBS_Server;Svr;tyrone-cluster;Scheduler was sent the command new
11/02/2013 12:13:15;0040;PBS_Server;Svr;tyrone-cluster;Scheduler was sent the command new
11/02/2013 12:13:30;0040;PBS_Server;Svr;tyrone-cluster;Scheduler was sent the command new
11/02/2013 12:13:44;0040;PBS_Server;Svr;tyrone-cluster;Scheduler was sent the command new
11/02/2013 12:14:02;0040;PBS_Server;Svr;tyrone-cluster;Scheduler was sent the command new
11/02/2013 12:14:15;0040;PBS_Server;Svr;tyrone-cluster;Scheduler was sent the command new
11/02/2013 12:14:32;0040;PBS_Server;Svr;tyrone-cluster;Scheduler was sent the command new
11/02/2013 12:14:45;0040;PBS_Server;Svr;tyrone-cluster;Scheduler was sent the command new
11/02/2013 12:15:02;0040;PBS_Server;Svr;tyrone-cluster;Scheduler was sent the command new
11/02/2013 12:15:14;0040;PBS_Server;Svr;tyrone-cluster;Scheduler was sent the command new
11/02/2013 12:15:34;0040;PBS_Server;Svr;tyrone-cluster;Scheduler was sent the command new
11/02/2013 12:15:45;0040;PBS_Server;Svr;tyrone-cluster;Scheduler was sent the command new
11/02/2013 12:16:06;0040;PBS_Server;Svr;tyrone-cluster;Scheduler was sent the command new
11/02/2013 12:16:15;0040;PBS_Server;Svr;tyrone-cluster;Scheduler was sent the command new
11/02/2013 12:16:36;0040;PBS_Server;Svr;tyrone-cluster;Scheduler was sent the command new
11/02/2013 12:16:44;0040;PBS_Server;Svr;tyrone-cluster;Scheduler was sent the command new
11/02/2013 12:17:09;0040;PBS_Server;Svr;tyrone-cluster;Scheduler was sent the command new
11/02/2013 12:17:15;0040;PBS_Server;Svr;tyrone-cluster;Scheduler was sent the command new
11/02/2013 12:17:42;0002;PBS_Server;Svr;PBS_Server;Torque Server Version = 3.0.5, loglevel = 0
11/02/2013 12:17:42;0040;PBS_Server;Svr;tyrone-cluster;Scheduler was sent the command new
11/02/2013 12:17:45;0040;PBS_Server;Svr;tyrone-cluster;Scheduler was sent the command new
11/02/2013 12:18:12;0040;PBS_Server;Svr;tyrone-cluster;Scheduler was sent the command new
11/02/2013 12:18:14;0040;PBS_Server;Svr;tyrone-cluster;Scheduler was sent the command new
11/02/2013 12:18:39;0040;PBS_Server;Svr;tyrone-cluster;Scheduler was sent the command new
11/02/2013 12:18:45;0040;PBS_Server;Svr;tyrone-cluster;Scheduler was sent the command new
11/02/2013 12:19:13;0040;PBS_Server;Svr;tyrone-cluster;Scheduler was sent the command new
11/02/2013 12:19:41;0040;PBS_Server;Svr;tyrone-cluster;Scheduler was sent the command new
11/02/2013 12:19:45;0040;PBS_Server;Svr;tyrone-cluster;Scheduler was sent the command new
11/02/2013 12:20:15;0040;PBS_Server;Svr;tyrone-cluster;Scheduler was sent the command new
11/02/2013 12:20:45;0040;PBS_Server;Svr;tyrone-cluster;Scheduler was sent the command new
11/02/2013 12:21:14;0040;PBS_Server;Svr;tyrone-cluster;Scheduler was sent the command new
11/02/2013 12:21:45;0040;PBS_Server;Svr;tyrone-cluster;Scheduler was sent the command new
11/02/2013 12:22:15;0040;PBS_Server;Svr;tyrone-cluster;Scheduler was sent the command new
11/02/2013 12:22:42;0002;PBS_Server;Svr;PBS_Server;Torque Server Version = 3.0.5, loglevel = 0
11/02/2013 12:22:44;0040;PBS_Server;Svr;tyrone-cluster;Scheduler was sent the command new
11/02/2013 12:23:15;0040;PBS_Server;Svr;tyrone-cluster;Scheduler was sent the command new
11/02/2013 12:23:26;0100;PBS_Server;Job;31411.tyrone-cluster;enqueuing into batch, state 1 hop 1
11/02/2013 12:23:26;0100;PBS_Server;Job;31411.tyrone-cluster;dequeuing from batch, state QUEUED
11/02/2013 12:23:26;0100;PBS_Server;Job;31411.tyrone-cluster;enqueuing into qp64, state 1 hop 1
11/02/2013 12:23:26;0008;PBS_Server;Job;31411.tyrone-cluster;Job Queued at request of mbumasha@tyrone-cluster, owner = mbumasha@tyrone-cluster, job name = calrtrg16-02-11-13, queue = qp64
11/02/2013 12:23:26;0040;PBS_Server;Svr;tyrone-cluster;Scheduler was sent the command new
11/02/2013 12:23:26;0008;PBS_Server;Job;31411.tyrone-cluster;Job Modified at request of Scheduler@tyrone-cluster
11/02/2013 12:23:45;0040;PBS_Server;Svr;tyrone-cluster;Scheduler was sent the command new
11/02/2013 12:24:02;0100;PBS_Server;Job;31412.tyrone-cluster;enqueuing into batch, state 1 hop 1
11/02/2013 12:24:02;0100;PBS_Server;Job;31412.tyrone-cluster;dequeuing from batch, state QUEUED
11/02/2013 12:24:02;0100;PBS_Server;Job;31412.tyrone-cluster;enqueuing into qp64, state 1 hop 1
11/02/2013 12:24:02;0008;PBS_Server;Job;31412.tyrone-cluster;Job Queued at request of mbumasha@tyrone-cluster, owner = mbumasha@tyrone-cluster, job name = calrtrg16-02-11-13, queue = qp64
11/02/2013 12:24:02;0040;PBS_Server;Svr;tyrone-cluster;Scheduler was sent the command new
11/02/2013 12:24:03;0008;PBS_Server;Job;31412.tyrone-cluster;Job Modified at request of Scheduler@tyrone-cluster
11/02/2013 12:24:13;0100;PBS_Server;Job;31413.tyrone-cluster;enqueuing into batch, state 1 hop 1
11/02/2013 12:24:13;0100;PBS_Server;Job;31413.tyrone-cluster;dequeuing from batch, state QUEUED
11/02/2013 12:24:13;0100;PBS_Server;Job;31413.tyrone-cluster;enqueuing into qp64, state 1 hop 1
11/02/2013 12:24:13;0008;PBS_Server;Job;31413.tyrone-cluster;Job Queued at request of mbumasha@tyrone-cluster, owner = mbumasha@tyrone-cluster, job name = calrtrg16-02-11-13, queue = qp64
11/02/2013 12:24:13;0040;PBS_Server;Svr;tyrone-cluster;Scheduler was sent the command new
11/02/2013 12:24:13;0008;PBS_Server;Job;31413.tyrone-cluster;Job Modified at request of Scheduler@tyrone-cluster
11/02/2013 12:24:14;0040;PBS_Server;Svr;tyrone-cluster;Scheduler was sent the command new
11/02/2013 12:24:17;0040;PBS_Server;Svr;tyrone-cluster;Scheduler was sent the command new
11/02/2013 12:24:25;0100;PBS_Server;Job;31414.tyrone-cluster;enqueuing into batch, state 1 hop 1
11/02/2013 12:24:25;0008;PBS_Server;Job;31414.tyrone-cluster;Job Queued at request of mbumasha@tyrone-cluster, owner = mbumasha@tyrone-cluster, job name = calrtrg16-02-11-13, queue = batch
11/02/2013 12:24:25;0040;PBS_Server;Svr;tyrone-cluster;Scheduler was sent the command new
11/02/2013 12:24:25;0008;PBS_Server;Job;31414.tyrone-cluster;Job Modified at request of Scheduler@tyrone-cluster
11/02/2013 12:24:45;0040;PBS_Server;Svr;tyrone-cluster;Scheduler was sent the command new
11/02/2013 12:24:59;0040;PBS_Server;Svr;tyrone-cluster;Scheduler was sent the command new
11/02/2013 12:25:15;0040;PBS_Server;Svr;tyrone-cluster;Scheduler was sent the command new
11/02/2013 12:25:30;0040;PBS_Server;Svr;tyrone-cluster;Scheduler was sent the command new
11/02/2013 12:25:44;0040;PBS_Server;Svr;tyrone-cluster;Scheduler was sent the command new
11/02/2013 12:25:47;0040;PBS_Server;Svr;tyrone-cluster;Scheduler was sent the command new
11/02/2013 12:26:01;0040;PBS_Server;Svr;tyrone-cluster;Scheduler was sent the command new
11/02/2013 12:26:15;0040;PBS_Server;Svr;tyrone-cluster;Scheduler was sent the command new
11/02/2013 12:26:32;0040;PBS_Server;Svr;tyrone-cluster;Scheduler was sent the command new
11/02/2013 12:26:46;0040;PBS_Server;Svr;tyrone-cluster;Scheduler was sent the command new
11/02/2013 12:27:01;0040;PBS_Server;Svr;tyrone-cluster;Scheduler was sent the command new
11/02/2013 12:27:17;0040;PBS_Server;Svr;tyrone-cluster;Scheduler was sent the command new
11/02/2013 12:27:31;0040;PBS_Server;Svr;tyrone-cluster;Scheduler was sent the command new
11/02/2013 12:27:42;0002;PBS_Server;Svr;PBS_Server;Torque Server Version = 3.0.5, loglevel = 0
11/02/2013 12:27:46;0040;PBS_Server;Svr;tyrone-cluster;Scheduler was sent the command new
11/02/2013 12:28:01;0040;PBS_Server;Svr;tyrone-cluster;Scheduler was sent the command new
11/02/2013 12:28:16;0040;PBS_Server;Svr;tyrone-cluster;Scheduler was sent the command new
11/02/2013 12:28:31;0040;PBS_Server;Svr;tyrone-cluster;Scheduler was sent the command new
11/02/2013 12:28:47;0040;PBS_Server;Svr;tyrone-cluster;Scheduler was sent the command new
11/02/2013 12:29:01;0040;PBS_Server;Svr;tyrone-cluster;Scheduler was sent the command new
11/02/2013 12:29:16;0040;PBS_Server;Svr;tyrone-cluster;Scheduler was sent the command new
11/02/2013 12:29:31;0040;PBS_Server;Svr;tyrone-cluster;Scheduler was sent the command new
11/02/2013 12:29:49;0040;PBS_Server;Svr;tyrone-cluster;Scheduler was sent the command new
11/02/2013 12:30:01;0040;PBS_Server;Svr;tyrone-cluster;Scheduler was sent the command new
11/02/2013 12:30:17;0040;PBS_Server;Svr;tyrone-cluster;Scheduler was sent the command new
11/02/2013 12:30:31;0040;PBS_Server;Svr;tyrone-cluster;Scheduler was sent the command new
11/02/2013 12:30:46;0040;PBS_Server;Svr;tyrone-cluster;Scheduler was sent the command new
11/02/2013 12:31:02;0040;PBS_Server;Svr;tyrone-cluster;Scheduler was sent the command new
11/02/2013 12:31:19;0040;PBS_Server;Svr;tyrone-cluster;Scheduler was sent the command new
11/02/2013 12:31:31;0040;PBS_Server;Svr;tyrone-cluster;Scheduler was sent the command new
11/02/2013 12:31:47;0040;PBS_Server;Svr;tyrone-cluster;Scheduler was sent the command new
11/02/2013 12:32:01;0040;PBS_Server;Svr;tyrone-cluster;Scheduler was sent the command new
11/02/2013 12:32:17;0040;PBS_Server;Svr;tyrone-cluster;Scheduler was sent the command new
11/02/2013 12:32:32;0040;PBS_Server;Svr;tyrone-cluster;Scheduler was sent the command new
11/02/2013 12:32:42;0002;PBS_Server;Svr;PBS_Server;Torque Server Version = 3.0.5, loglevel = 0
11/02/2013 12:32:49;0040;PBS_Server;Svr;tyrone-cluster;Scheduler was sent the command new
11/02/2013 12:33:00;0040;PBS_Server;Svr;tyrone-cluster;Scheduler was sent the command new
11/02/2013 12:33:21;0040;PBS_Server;Svr;tyrone-cluster;Scheduler was sent the command new
11/02/2013 12:33:31;0040;PBS_Server;Svr;tyrone-cluster;Scheduler was sent the command new
11/02/2013 12:33:51;0040;PBS_Server;Svr;tyrone-cluster;Scheduler was sent the command new
11/02/2013 12:34:02;0040;PBS_Server;Svr;tyrone-cluster;Scheduler was sent the command new
11/02/2013 12:34:24;0040;PBS_Server;Svr;tyrone-cluster;Scheduler was sent the command new
11/02/2013 12:34:31;0040;PBS_Server;Svr;tyrone-cluster;Scheduler was sent the command new
11/02/2013 12:34:59;0040;PBS_Server;Svr;tyrone-cluster;Scheduler was sent the command new
11/02/2013 12:35:27;0040;PBS_Server;Svr;tyrone-cluster;Scheduler was sent the command new
11/02/2013 12:35:32;0040;PBS_Server;Svr;tyrone-cluster;Scheduler was sent the command new
11/02/2013 12:35:48;0008;PBS_Server;Job;31154.tyrone-cluster;Job deleted at request of mbuanuv@tyrone-node9
11/02/2013 12:35:48;0008;PBS_Server;Job;31154.tyrone-cluster;Job sent signal SIGTERM on delete
11/02/2013 12:35:50;0008;PBS_Server;Job;31154.tyrone-cluster;Job sent signal SIGKILL on delete
11/02/2013 12:35:50;0008;PBS_Server;Job;31155.tyrone-cluster;Job deleted at request of mbuanuv@tyrone-node9
11/02/2013 12:35:50;0008;PBS_Server;Job;NULL;on_job_exit valid pjob: 0x2ef8580 (substate=59)
11/02/2013 12:35:50;0100;PBS_Server;Job;31155.tyrone-cluster;dequeuing from qp64, state COMPLETE
11/02/2013 12:35:50;0040;PBS_Server;Svr;tyrone-cluster;Scheduler was sent the command term
11/02/2013 12:35:51;000d;PBS_Server;Job;31154.tyrone-cluster;Not sending email: User does not want mail of this type.
11/02/2013 12:35:51;0010;PBS_Server;Job;31154.tyrone-cluster;Exit_status=271 resources_used.cput=1314:09:02 resources_used.mem=1919184kb resources_used.vmem=34996896kb resources_used.walltime=20:32:33
11/02/2013 12:35:51;0008;PBS_Server;Job;NULL;on_job_exit valid pjob: 0x3169d10 (substate=50)
11/02/2013 12:35:51;0008;PBS_Server;Job;NULL;on_job_exit valid pjob: 0x3169d10 (substate=51)
11/02/2013 12:35:51;0008;PBS_Server;Job;31156.tyrone-cluster;Job Modified at request of Scheduler@tyrone-cluster
11/02/2013 12:35:51;0008;PBS_Server;Job;31233.tyrone-cluster;Job Modified at request of Scheduler@tyrone-cluster
11/02/2013 12:35:51;0008;PBS_Server;Job;31348.tyrone-cluster;Job Modified at request of Scheduler@tyrone-cluster
11/02/2013 12:35:51;0008;PBS_Server;Job;31349.tyrone-cluster;Job Modified at request of Scheduler@tyrone-cluster
11/02/2013 12:35:51;0008;PBS_Server;Job;31234.tyrone-cluster;Job Modified at request of Scheduler@tyrone-cluster
11/02/2013 12:35:51;0008;PBS_Server;Job;31411.tyrone-cluster;Job Modified at request of Scheduler@tyrone-cluster
11/02/2013 12:35:51;0008;PBS_Server;Job;31412.tyrone-cluster;Job Modified at request of Scheduler@tyrone-cluster
11/02/2013 12:35:51;0008;PBS_Server;Job;31413.tyrone-cluster;Job Modified at request of Scheduler@tyrone-cluster
11/02/2013 12:35:52;0008;PBS_Server;Job;31156.tyrone-cluster;Job deleted at request of mbuanuv@tyrone-node9
11/02/2013 12:35:52;0008;PBS_Server;Job;NULL;on_job_exit valid pjob: 0x2fb24f0 (substate=59)
11/02/2013 12:35:52;0100;PBS_Server;Job;31156.tyrone-cluster;dequeuing from qp64, state COMPLETE
11/02/2013 12:35:52;0040;PBS_Server;Svr;tyrone-cluster;Scheduler was sent the command term
11/02/2013 12:35:52;0008;PBS_Server;Job;NULL;on_job_exit valid pjob: 0x3169d10 (substate=51)
11/02/2013 12:35:52;0008;PBS_Server;Job;NULL;on_job_exit valid pjob: 0x3169d10 (substate=53)
11/02/2013 12:35:52;0100;PBS_Server;Job;31154.tyrone-cluster;dequeuing from qp64, state COMPLETE
11/02/2013 12:35:52;0040;PBS_Server;Svr;tyrone-cluster;Scheduler was sent the command term
11/02/2013 12:35:52;0008;PBS_Server;Job;31411.tyrone-cluster;Job Modified at request of Scheduler@tyrone-cluster
11/02/2013 12:35:52;0008;PBS_Server;Job;31411.tyrone-cluster;Job Run at request of Scheduler@tyrone-cluster
11/02/2013 12:35:52;0008;PBS_Server;Job;31412.tyrone-cluster;Job Modified at request of Scheduler@tyrone-cluster
11/02/2013 12:35:52;000d;PBS_Server;Job;31411.tyrone-cluster;Not sending email: User does not want mail of this type.
11/02/2013 12:35:52;0008;PBS_Server;Job;31413.tyrone-cluster;Job Modified at request of Scheduler@tyrone-cluster
11/02/2013 12:35:52;0040;PBS_Server;Svr;tyrone-cluster;Scheduler was sent the command recyc
11/02/2013 12:35:53;0008;PBS_Server;Job;31157.tyrone-cluster;Job deleted at request of mbuanuv@tyrone-node9
11/02/2013 12:35:53;0008;PBS_Server;Job;NULL;on_job_exit valid pjob: 0x2ed2ba0 (substate=59)
11/02/2013 12:35:53;0100;PBS_Server;Job;31157.tyrone-cluster;dequeuing from batch, state COMPLETE
11/02/2013 12:35:53;0040;PBS_Server;Svr;tyrone-cluster;Scheduler was sent the command term
11/02/2013 12:35:57;0008;PBS_Server;Job;31233.tyrone-cluster;Job Modified at request of Scheduler@tyrone-cluster
11/02/2013 12:35:57;0008;PBS_Server;Job;31348.tyrone-cluster;Job Modified at request of Scheduler@tyrone-cluster
11/02/2013 12:35:57;0008;PBS_Server;Job;31349.tyrone-cluster;Job Modified at request of Scheduler@tyrone-cluster
11/02/2013 12:35:57;0008;PBS_Server;Job;31234.tyrone-cluster;Job Modified at request of Scheduler@tyrone-cluster
11/02/2013 12:36:00;0040;PBS_Server;Svr;tyrone-cluster;Scheduler was sent the command new
11/02/2013 12:36:24;0040;PBS_Server;Svr;tyrone-cluster;Scheduler was sent the command new
11/02/2013 12:36:31;0040;PBS_Server;Svr;tyrone-cluster;Scheduler was sent the command new
11/02/2013 12:36:58;0040;PBS_Server;Svr;tyrone-cluster;Scheduler was sent the command new
11/02/2013 12:37:02;0040;PBS_Server;Svr;tyrone-cluster;Scheduler was sent the command new
11/02/2013 12:37:30;0040;PBS_Server;Svr;tyrone-cluster;Scheduler was sent the command new
11/02/2013 12:37:42;0002;PBS_Server;Svr;PBS_Server;Torque Server Version = 3.0.5, loglevel = 0
11/02/2013 12:38:01;0040;PBS_Server;Svr;tyrone-cluster;Scheduler was sent the command new
11/02/2013 12:38:30;0040;PBS_Server;Svr;tyrone-cluster;Scheduler was sent the command new
11/02/2013 12:39:01;0040;PBS_Server;Svr;tyrone-cluster;Scheduler was sent the command new
11/02/2013 12:39:31;0040;PBS_Server;Svr;tyrone-cluster;Scheduler was sent the command new
11/02/2013 12:39:41;0008;PBS_Server;Job;31396.tyrone-cluster;Job deleted at request of secbadar@tyrone-cluster
11/02/2013 12:39:41;0008;PBS_Server;Job;31396.tyrone-cluster;Job sent signal SIGTERM on delete
11/02/2013 12:39:41;000d;PBS_Server;Job;31396.tyrone-cluster;Not sending email: User does not want mail of this type.
11/02/2013 12:39:41;0010;PBS_Server;Job;31396.tyrone-cluster;Exit_status=143 resources_used.cput=15:08:43 resources_used.mem=2907272kb resources_used.vmem=38032904kb resources_used.walltime=00:55:12
11/02/2013 12:39:41;0008;PBS_Server;Job;NULL;on_job_exit valid pjob: 0x2e0d0b0 (substate=50)
11/02/2013 12:39:41;0008;PBS_Server;Job;NULL;on_job_exit valid pjob: 0x2e0d0b0 (substate=51)
11/02/2013 12:39:41;0008;PBS_Server;Job;NULL;on_job_exit valid pjob: 0x2e0d0b0 (substate=51)
11/02/2013 12:39:41;0008;PBS_Server;Job;NULL;on_job_exit valid pjob: 0x2e0d0b0 (substate=53)
11/02/2013 12:39:41;0100;PBS_Server;Job;31396.tyrone-cluster;dequeuing from qp256, state COMPLETE
11/02/2013 12:39:41;0040;PBS_Server;Svr;tyrone-cluster;Scheduler was sent the command term
11/02/2013 12:39:45;0008;PBS_Server;Job;31397.tyrone-cluster;Job Modified at request of Scheduler@tyrone-cluster
11/02/2013 12:39:45;0008;PBS_Server;Job;31397.tyrone-cluster;Job Run at request of Scheduler@tyrone-cluster
11/02/2013 12:39:45;0040;PBS_Server;Svr;tyrone-cluster;Scheduler was sent the command recyc
11/02/2013 12:40:00;0100;PBS_Server;Job;31398.tyrone-cluster;dequeuing from batch, state QUEUED
11/02/2013 12:40:00;0100;PBS_Server;Job;31398.tyrone-cluster;enqueuing into qp256, state 1 hop 1
11/02/2013 12:40:00;0040;PBS_Server;Svr;tyrone-cluster;Scheduler was sent the command new
11/02/2013 12:40:00;0008;PBS_Server;Job;31398.tyrone-cluster;Job Modified at request of Scheduler@tyrone-cluster
11/02/2013 12:40:31;0040;PBS_Server;Svr;tyrone-cluster;Scheduler was sent the command new
11/02/2013 12:40:38;000d;PBS_Server;Job;31397.tyrone-cluster;Not sending email: User does not want mail of this type.
11/02/2013 12:41:01;0040;PBS_Server;Svr;tyrone-cluster;Scheduler was sent the command new
11/02/2013 12:41:30;0040;PBS_Server;Svr;tyrone-cluster;Scheduler was sent the command new
11/02/2013 12:42:01;0040;PBS_Server;Svr;tyrone-cluster;Scheduler was sent the command new
11/02/2013 12:42:06;0008;PBS_Server;Job;31397.tyrone-cluster;Job deleted at request of secbadar@tyrone-cluster
11/02/2013 12:42:06;0008;PBS_Server;Job;31397.tyrone-cluster;Job sent signal SIGTERM on delete
11/02/2013 12:42:07;000d;PBS_Server;Job;31397.tyrone-cluster;Not sending email: User does not want mail of this type.
11/02/2013 12:42:07;0010;PBS_Server;Job;31397.tyrone-cluster;Exit_status=143 resources_used.cput=00:06:54 resources_used.mem=1534784kb resources_used.vmem=36879652kb resources_used.walltime=00:02:21
11/02/2013 12:42:07;0008;PBS_Server;Job;NULL;on_job_exit valid pjob: 0x2e56cc0 (substate=50)
11/02/2013 12:42:07;0008;PBS_Server;Job;NULL;on_job_exit valid pjob: 0x2e56cc0 (substate=51)
11/02/2013 12:42:07;0008;PBS_Server;Job;NULL;on_job_exit valid pjob: 0x2e56cc0 (substate=51)
11/02/2013 12:42:07;0008;PBS_Server;Job;NULL;on_job_exit valid pjob: 0x2e56cc0 (substate=53)
11/02/2013 12:42:07;0100;PBS_Server;Job;31397.tyrone-cluster;dequeuing from qp256, state COMPLETE
11/02/2013 12:42:07;0040;PBS_Server;Svr;tyrone-cluster;Scheduler was sent the command term
11/02/2013 12:42:07;0008;PBS_Server;Job;31398.tyrone-cluster;Job Modified at request of Scheduler@tyrone-cluster
11/02/2013 12:42:07;0008;PBS_Server;Job;31398.tyrone-cluster;Job Run at request of Scheduler@tyrone-cluster
11/02/2013 12:42:07;0040;PBS_Server;Svr;tyrone-cluster;Scheduler was sent the command recyc
11/02/2013 12:42:30;0100;PBS_Server;Job;31399.tyrone-cluster;dequeuing from batch, state QUEUED
11/02/2013 12:42:30;0100;PBS_Server;Job;31399.tyrone-cluster;enqueuing into qp256, state 1 hop 1
11/02/2013 12:42:31;0040;PBS_Server;Svr;tyrone-cluster;Scheduler was sent the command new
11/02/2013 12:42:31;0008;PBS_Server;Job;31399.tyrone-cluster;Job Modified at request of Scheduler@tyrone-cluster
11/02/2013 12:42:42;0002;PBS_Server;Svr;PBS_Server;Torque Server Version = 3.0.5, loglevel = 0
11/02/2013 12:43:00;0040;PBS_Server;Svr;tyrone-cluster;Scheduler was sent the command new
11/02/2013 12:43:16;000d;PBS_Server;Job;31398.tyrone-cluster;Not sending email: User does not want mail of this type.
11/02/2013 12:43:31;0040;PBS_Server;Svr;tyrone-cluster;Scheduler was sent the command new
11/02/2013 12:44:01;0040;PBS_Server;Svr;tyrone-cluster;Scheduler was sent the command new
11/02/2013 12:44:30;0040;PBS_Server;Svr;tyrone-cluster;Scheduler was sent the command new
11/02/2013 12:45:01;0040;PBS_Server;Svr;tyrone-cluster;Scheduler was sent the command new
11/02/2013 12:45:31;0040;PBS_Server;Svr;tyrone-cluster;Scheduler was sent the command new
11/02/2013 12:46:00;0040;PBS_Server;Svr;tyrone-cluster;Scheduler was sent the command new
11/02/2013 12:46:31;0040;PBS_Server;Svr;tyrone-cluster;Scheduler was sent the command new
11/02/2013 12:47:01;0040;PBS_Server;Svr;tyrone-cluster;Scheduler was sent the command new
11/02/2013 12:47:30;0040;PBS_Server;Svr;tyrone-cluster;Scheduler was sent the command new
11/02/2013 12:47:42;0002;PBS_Server;Svr;PBS_Server;Torque Server Version = 3.0.5, loglevel = 0
11/02/2013 12:48:01;0040;PBS_Server;Svr;tyrone-cluster;Scheduler was sent the command new
11/02/2013 12:48:31;0040;PBS_Server;Svr;tyrone-cluster;Scheduler was sent the command new
11/02/2013 12:49:00;0040;PBS_Server;Svr;tyrone-cluster;Scheduler was sent the command new
11/02/2013 12:49:31;0040;PBS_Server;Svr;tyrone-cluster;Scheduler was sent the command new
11/02/2013 12:50:01;0040;PBS_Server;Svr;tyrone-cluster;Scheduler was sent the command new
11/02/2013 12:50:30;0040;PBS_Server;Svr;tyrone-cluster;Scheduler was sent the command new
11/02/2013 12:51:01;0040;PBS_Server;Svr;tyrone-cluster;Scheduler was sent the command new
11/02/2013 12:51:31;0040;PBS_Server;Svr;tyrone-cluster;Scheduler was sent the command new
11/02/2013 12:52:00;0040;PBS_Server;Svr;tyrone-cluster;Scheduler was sent the command new
11/02/2013 12:52:31;0040;PBS_Server;Svr;tyrone-cluster;Scheduler was sent the command new
11/02/2013 12:52:42;0002;PBS_Server;Svr;PBS_Server;Torque Server Version = 3.0.5, loglevel = 0
11/02/2013 12:52:44;0100;PBS_Server;Job;31415.tyrone-cluster;enqueuing into batch, state 1 hop 1
11/02/2013 12:52:44;0100;PBS_Server;Job;31415.tyrone-cluster;dequeuing from batch, state QUEUED
11/02/2013 12:52:44;0100;PBS_Server;Job;31415.tyrone-cluster;enqueuing into qp128, state 1 hop 1
11/02/2013 12:52:44;0008;PBS_Server;Job;31415.tyrone-cluster;Job Queued at request of secbadar@tyrone-cluster, owner = secbadar@tyrone-cluster, job name = 128Edge4, queue = qp128
11/02/2013 12:52:44;0040;PBS_Server;Svr;tyrone-cluster;Scheduler was sent the command new
11/02/2013 12:52:44;0008;PBS_Server;Job;31415.tyrone-cluster;Job Modified at request of Scheduler@tyrone-cluster
11/02/2013 12:52:44;0008;PBS_Server;Job;31415.tyrone-cluster;Job Run at request of Scheduler@tyrone-cluster
11/02/2013 12:52:44;0040;PBS_Server;Svr;tyrone-cluster;Scheduler was sent the command recyc
11/02/2013 12:52:47;000d;PBS_Server;Job;31415.tyrone-cluster;Not sending email: User does not want mail of this type.
11/02/2013 12:52:47;0010;PBS_Server;Job;31415.tyrone-cluster;Exit_status=255 resources_used.cput=00:00:00 resources_used.mem=800kb resources_used.vmem=13624kb resources_used.walltime=00:00:03
11/02/2013 12:52:47;0008;PBS_Server;Job;NULL;on_job_exit valid pjob: 0x2fb24f0 (substate=50)
11/02/2013 12:52:47;0008;PBS_Server;Job;NULL;on_job_exit valid pjob: 0x2fb24f0 (substate=51)
11/02/2013 12:52:47;0008;PBS_Server;Job;NULL;on_job_exit valid pjob: 0x2fb24f0 (substate=51)
11/02/2013 12:52:47;0008;PBS_Server;Job;NULL;on_job_exit valid pjob: 0x2fb24f0 (substate=53)
11/02/2013 12:52:47;0100;PBS_Server;Job;31415.tyrone-cluster;dequeuing from qp128, state COMPLETE
11/02/2013 12:52:47;0040;PBS_Server;Svr;tyrone-cluster;Scheduler was sent the command term
11/02/2013 12:53:01;0040;PBS_Server;Svr;tyrone-cluster;Scheduler was sent the command new
11/02/2013 12:53:30;0040;PBS_Server;Svr;tyrone-cluster;Scheduler was sent the command new
11/02/2013 12:53:51;0100;PBS_Server;Job;31416.tyrone-cluster;enqueuing into batch, state 1 hop 1
11/02/2013 12:53:51;0100;PBS_Server;Job;31416.tyrone-cluster;dequeuing from batch, state QUEUED
11/02/2013 12:53:51;0100;PBS_Server;Job;31416.tyrone-cluster;enqueuing into qp128, state 1 hop 1
11/02/2013 12:53:51;0008;PBS_Server;Job;31416.tyrone-cluster;Job Queued at request of secbadar@tyrone-cluster, owner = secbadar@tyrone-cluster, job name = 128Edge4, queue = qp128
11/02/2013 12:53:51;0040;PBS_Server;Svr;tyrone-cluster;Scheduler was sent the command new
11/02/2013 12:53:51;0008;PBS_Server;Job;31416.tyrone-cluster;Job Modified at request of Scheduler@tyrone-cluster
11/02/2013 12:53:51;0008;PBS_Server;Job;31416.tyrone-cluster;Job Run at request of Scheduler@tyrone-cluster
11/02/2013 12:53:51;0040;PBS_Server;Svr;tyrone-cluster;Scheduler was sent the command recyc
11/02/2013 12:54:01;0040;PBS_Server;Svr;tyrone-cluster;Scheduler was sent the command new
11/02/2013 12:54:31;0040;PBS_Server;Svr;tyrone-cluster;Scheduler was sent the command new
11/02/2013 12:54:36;000d;PBS_Server;Job;31416.tyrone-cluster;Not sending email: User does not want mail of this type.
11/02/2013 12:55:00;0040;PBS_Server;Svr;tyrone-cluster;Scheduler was sent the command new
11/02/2013 12:55:31;0040;PBS_Server;Svr;tyrone-cluster;Scheduler was sent the command new
11/02/2013 12:56:01;0040;PBS_Server;Svr;tyrone-cluster;Scheduler was sent the command new
11/02/2013 12:56:30;0040;PBS_Server;Svr;tyrone-cluster;Scheduler was sent the command new
11/02/2013 12:57:01;0040;PBS_Server;Svr;tyrone-cluster;Scheduler was sent the command new
11/02/2013 12:57:31;0040;PBS_Server;Svr;tyrone-cluster;Scheduler was sent the command new
11/02/2013 12:57:42;0002;PBS_Server;Svr;PBS_Server;Torque Server Version = 3.0.5, loglevel = 0
11/02/2013 12:58:00;0040;PBS_Server;Svr;tyrone-cluster;Scheduler was sent the command new
11/02/2013 12:58:31;0040;PBS_Server;Svr;tyrone-cluster;Scheduler was sent the command new
11/02/2013 12:59:01;0040;PBS_Server;Svr;tyrone-cluster;Scheduler was sent the command new
11/02/2013 12:59:30;0040;PBS_Server;Svr;tyrone-cluster;Scheduler was sent the command new
11/02/2013 13:00:01;0040;PBS_Server;Svr;tyrone-cluster;Scheduler was sent the command new
11/02/2013 13:00:31;0040;PBS_Server;Svr;tyrone-cluster;Scheduler was sent the command new
11/02/2013 13:01:00;0040;PBS_Server;Svr;tyrone-cluster;Scheduler was sent the command new
11/02/2013 13:01:31;0040;PBS_Server;Svr;tyrone-cluster;Scheduler was sent the command new
11/02/2013 13:02:01;0040;PBS_Server;Svr;tyrone-cluster;Scheduler was sent the command new
11/02/2013 13:02:30;0040;PBS_Server;Svr;tyrone-cluster;Scheduler was sent the command new
11/02/2013 13:02:42;0002;PBS_Server;Svr;PBS_Server;Torque Server Version = 3.0.5, loglevel = 0
11/02/2013 13:03:01;0040;PBS_Server;Svr;tyrone-cluster;Scheduler was sent the command new
11/02/2013 13:03:31;0040;PBS_Server;Svr;tyrone-cluster;Scheduler was sent the command new
11/02/2013 13:04:00;0040;PBS_Server;Svr;tyrone-cluster;Scheduler was sent the command new
11/02/2013 13:04:31;0040;PBS_Server;Svr;tyrone-cluster;Scheduler was sent the command new
11/02/2013 13:05:01;0040;PBS_Server;Svr;tyrone-cluster;Scheduler was sent the command new
11/02/2013 13:05:30;0040;PBS_Server;Svr;tyrone-cluster;Scheduler was sent the command new
11/02/2013 13:06:01;0040;PBS_Server;Svr;tyrone-cluster;Scheduler was sent the command new
11/02/2013 13:06:31;0040;PBS_Server;Svr;tyrone-cluster;Scheduler was sent the command new
11/02/2013 13:07:00;0040;PBS_Server;Svr;tyrone-cluster;Scheduler was sent the command new
11/02/2013 13:07:31;0040;PBS_Server;Svr;tyrone-cluster;Scheduler was sent the command new
11/02/2013 13:07:42;0002;PBS_Server;Svr;PBS_Server;Torque Server Version = 3.0.5, loglevel = 0
11/02/2013 13:07:43;000d;PBS_Server;Job;31416.tyrone-cluster;Not sending email: User does not want mail of this type.
11/02/2013 13:07:43;0010;PBS_Server;Job;31416.tyrone-cluster;Exit_status=0 resources_used.cput=01:00:41 resources_used.mem=1185252kb resources_used.vmem=8357940kb resources_used.walltime=00:13:52
11/02/2013 13:07:43;0008;PBS_Server;Job;NULL;on_job_exit valid pjob: 0x2ed2ba0 (substate=50)
11/02/2013 13:07:43;0008;PBS_Server;Job;NULL;on_job_exit valid pjob: 0x2ed2ba0 (substate=51)
11/02/2013 13:07:43;0008;PBS_Server;Job;NULL;on_job_exit valid pjob: 0x2ed2ba0 (substate=51)
11/02/2013 13:07:43;0008;PBS_Server;Job;NULL;on_job_exit valid pjob: 0x2ed2ba0 (substate=53)
11/02/2013 13:07:43;0100;PBS_Server;Job;31416.tyrone-cluster;dequeuing from qp128, state COMPLETE
11/02/2013 13:07:43;0040;PBS_Server;Svr;tyrone-cluster;Scheduler was sent the command term
11/02/2013 13:08:01;0040;PBS_Server;Svr;tyrone-cluster;Scheduler was sent the command new
11/02/2013 13:08:30;0040;PBS_Server;Svr;tyrone-cluster;Scheduler was sent the command new
11/02/2013 13:09:01;0040;PBS_Server;Svr;tyrone-cluster;Scheduler was sent the command new
11/02/2013 13:09:31;0040;PBS_Server;Svr;tyrone-cluster;Scheduler was sent the command new
11/02/2013 13:10:00;0040;PBS_Server;Svr;tyrone-cluster;Scheduler was sent the command new
11/02/2013 13:10:31;0040;PBS_Server;Svr;tyrone-cluster;Scheduler was sent the command new
11/02/2013 13:11:01;0040;PBS_Server;Svr;tyrone-cluster;Scheduler was sent the command new
11/02/2013 13:11:30;0040;PBS_Server;Svr;tyrone-cluster;Scheduler was sent the command new
11/02/2013 13:12:01;0040;PBS_Server;Svr;tyrone-cluster;Scheduler was sent the command new
11/02/2013 13:12:31;0040;PBS_Server;Svr;tyrone-cluster;Scheduler was sent the command new
11/02/2013 13:12:42;0002;PBS_Server;Svr;PBS_Server;Torque Server Version = 3.0.5, loglevel = 0
11/02/2013 13:13:00;0040;PBS_Server;Svr;tyrone-cluster;Scheduler was sent the command new
11/02/2013 13:13:31;0040;PBS_Server;Svr;tyrone-cluster;Scheduler was sent the command new
11/02/2013 13:14:01;0040;PBS_Server;Svr;tyrone-cluster;Scheduler was sent the command new
11/02/2013 13:14:30;0040;PBS_Server;Svr;tyrone-cluster;Scheduler was sent the command new
11/02/2013 13:15:01;0040;PBS_Server;Svr;tyrone-cluster;Scheduler was sent the command new
11/02/2013 13:15:30;0040;PBS_Server;Svr;tyrone-cluster;Scheduler was sent the command new
11/02/2013 13:16:00;0040;PBS_Server;Svr;tyrone-cluster;Scheduler was sent the command new
11/02/2013 13:16:31;0040;PBS_Server;Svr;tyrone-cluster;Scheduler was sent the command new
11/02/2013 13:17:01;0040;PBS_Server;Svr;tyrone-cluster;Scheduler was sent the command new
11/02/2013 13:17:30;0040;PBS_Server;Svr;tyrone-cluster;Scheduler was sent the command new
11/02/2013 13:17:42;0002;PBS_Server;Svr;PBS_Server;Torque Server Version = 3.0.5, loglevel = 0
11/02/2013 13:18:01;0040;PBS_Server;Svr;tyrone-cluster;Scheduler was sent the command new
11/02/2013 13:18:31;0040;PBS_Server;Svr;tyrone-cluster;Scheduler was sent the command new
11/02/2013 13:19:00;0040;PBS_Server;Svr;tyrone-cluster;Scheduler was sent the command new
11/02/2013 13:19:31;0040;PBS_Server;Svr;tyrone-cluster;Scheduler was sent the command new
11/02/2013 13:20:01;0040;PBS_Server;Svr;tyrone-cluster;Scheduler was sent the command new
11/02/2013 13:20:30;0040;PBS_Server;Svr;tyrone-cluster;Scheduler was sent the command new
11/02/2013 13:21:01;0040;PBS_Server;Svr;tyrone-cluster;Scheduler was sent the command new
11/02/2013 13:21:31;0040;PBS_Server;Svr;tyrone-cluster;Scheduler was sent the command new
11/02/2013 13:22:00;0040;PBS_Server;Svr;tyrone-cluster;Scheduler was sent the command new
11/02/2013 13:22:31;0040;PBS_Server;Svr;tyrone-cluster;Scheduler was sent the command new
11/02/2013 13:22:42;0002;PBS_Server;Svr;PBS_Server;Torque Server Version = 3.0.5, loglevel = 0
11/02/2013 13:23:01;0040;PBS_Server;Svr;tyrone-cluster;Scheduler was sent the command new
11/02/2013 13:23:30;0040;PBS_Server;Svr;tyrone-cluster;Scheduler was sent the command new
11/02/2013 13:24:01;0040;PBS_Server;Svr;tyrone-cluster;Scheduler was sent the command new
11/02/2013 13:24:30;0040;PBS_Server;Svr;tyrone-cluster;Scheduler was sent the command new
11/02/2013 13:25:00;0040;PBS_Server;Svr;tyrone-cluster;Scheduler was sent the command new
11/02/2013 13:25:31;0040;PBS_Server;Svr;tyrone-cluster;Scheduler was sent the command new
11/02/2013 13:26:01;0040;PBS_Server;Svr;tyrone-cluster;Scheduler was sent the command new
11/02/2013 13:26:30;0040;PBS_Server;Svr;tyrone-cluster;Scheduler was sent the command new
11/02/2013 13:27:01;0040;PBS_Server;Svr;tyrone-cluster;Scheduler was sent the command new
11/02/2013 13:27:31;0040;PBS_Server;Svr;tyrone-cluster;Scheduler was sent the command new
11/02/2013 13:27:42;0002;PBS_Server;Svr;PBS_Server;Torque Server Version = 3.0.5, loglevel = 0
11/02/2013 13:28:00;0040;PBS_Server;Svr;tyrone-cluster;Scheduler was sent the command new
11/02/2013 13:28:31;0040;PBS_Server;Svr;tyrone-cluster;Scheduler was sent the command new
11/02/2013 13:28:46;0100;PBS_Server;Job;31417.tyrone-cluster;enqueuing into batch, state 1 hop 1
11/02/2013 13:28:46;0100;PBS_Server;Job;31417.tyrone-cluster;dequeuing from batch, state QUEUED
11/02/2013 13:28:46;0100;PBS_Server;Job;31417.tyrone-cluster;enqueuing into qp64, state 1 hop 1
11/02/2013 13:28:46;0008;PBS_Server;Job;31417.tyrone-cluster;Job Queued at request of csdpalvi@tyrone-cluster, owner = csdpalvi@tyrone-cluster, job name = n10, queue = qp64
11/02/2013 13:28:46;0040;PBS_Server;Svr;tyrone-cluster;Scheduler was sent the command new
11/02/2013 13:28:46;0008;PBS_Server;Job;31417.tyrone-cluster;Job Modified at request of Scheduler@tyrone-cluster
11/02/2013 13:29:01;0040;PBS_Server;Svr;tyrone-cluster;Scheduler was sent the command new
11/02/2013 13:29:30;0040;PBS_Server;Svr;tyrone-cluster;Scheduler was sent the command new
11/02/2013 13:30:01;0040;PBS_Server;Svr;tyrone-cluster;Scheduler was sent the command new
11/02/2013 13:30:31;0040;PBS_Server;Svr;tyrone-cluster;Scheduler was sent the command new
11/02/2013 13:31:00;0040;PBS_Server;Svr;tyrone-cluster;Scheduler was sent the command new
11/02/2013 13:31:31;0040;PBS_Server;Svr;tyrone-cluster;Scheduler was sent the command new
11/02/2013 13:32:01;0040;PBS_Server;Svr;tyrone-cluster;Scheduler was sent the command new
11/02/2013 13:32:30;0040;PBS_Server;Svr;tyrone-cluster;Scheduler was sent the command new
11/02/2013 13:32:42;0002;PBS_Server;Svr;PBS_Server;Torque Server Version = 3.0.5, loglevel = 0
11/02/2013 13:33:01;0040;PBS_Server;Svr;tyrone-cluster;Scheduler was sent the command new
11/02/2013 13:33:30;0040;PBS_Server;Svr;tyrone-cluster;Scheduler was sent the command new
11/02/2013 13:34:00;0040;PBS_Server;Svr;tyrone-cluster;Scheduler was sent the command new
11/02/2013 13:34:31;0040;PBS_Server;Svr;tyrone-cluster;Scheduler was sent the command new
11/02/2013 13:35:01;0040;PBS_Server;Svr;tyrone-cluster;Scheduler was sent the command new
11/02/2013 13:35:30;0040;PBS_Server;Svr;tyrone-cluster;Scheduler was sent the command new
11/02/2013 13:36:01;0040;PBS_Server;Svr;tyrone-cluster;Scheduler was sent the command new
11/02/2013 13:36:31;0040;PBS_Server;Svr;tyrone-cluster;Scheduler was sent the command new
11/02/2013 13:37:00;0040;PBS_Server;Svr;tyrone-cluster;Scheduler was sent the command new
11/02/2013 13:37:31;0040;PBS_Server;Svr;tyrone-cluster;Scheduler was sent the command new
11/02/2013 13:37:42;0002;PBS_Server;Svr;PBS_Server;Torque Server Version = 3.0.5, loglevel = 0
11/02/2013 13:38:01;0040;PBS_Server;Svr;tyrone-cluster;Scheduler was sent the command new
11/02/2013 13:38:20;000d;PBS_Server;Job;31323.tyrone-cluster;Not sending email: User does not want mail of this type.
11/02/2013 13:38:20;0010;PBS_Server;Job;31323.tyrone-cluster;Exit_status=0 resources_used.cput=510:33:51 resources_used.mem=599260kb resources_used.vmem=6656940kb resources_used.walltime=16:07:09
11/02/2013 13:38:20;0008;PBS_Server;Job;NULL;on_job_exit valid pjob: 0x2e50420 (substate=50)
11/02/2013 13:38:20;0008;PBS_Server;Job;NULL;on_job_exit valid pjob: 0x2e50420 (substate=51)
11/02/2013 13:38:29;0008;PBS_Server;Job;NULL;on_job_exit valid pjob: 0x2e50420 (substate=51)
11/02/2013 13:38:29;000d;PBS_Server;Job;31323.tyrone-cluster;Post job file processing error; job 31323.tyrone-cluster on host tyrone-node1/31+tyrone-node1/30+tyrone-node1/29+tyrone-node1/28+tyrone-node1/27+tyrone-node1/26+tyrone-node1/25+tyrone-node1/24+tyrone-node1/23+tyrone-node1/22+tyrone-node1/21+tyrone-node1/20+tyrone-node1/19+tyrone-node1/18+tyrone-node1/17+tyrone-node1/16+tyrone-node1/15+tyrone-node1/14+tyrone-node1/13+tyrone-node1/12+tyrone-node1/11+tyrone-node1/10+tyrone-node1/9+tyrone-node1/8+tyrone-node1/7+tyrone-node1/6+tyrone-node1/5+tyrone-node1/4+tyrone-node1/3+tyrone-node1/2+tyrone-node1/1+tyrone-node1/0
11/02/2013 13:38:29;0008;PBS_Server;Job;NULL;on_job_exit valid pjob: 0x2e50420 (substate=53)
11/02/2013 13:38:29;0100;PBS_Server;Job;31323.tyrone-cluster;dequeuing from qp32, state COMPLETE
11/02/2013 13:38:29;0040;PBS_Server;Svr;tyrone-cluster;Scheduler was sent the command term
11/02/2013 13:38:29;0008;PBS_Server;Job;31324.tyrone-cluster;Job Modified at request of Scheduler@tyrone-cluster
11/02/2013 13:38:29;0008;PBS_Server;Job;31324.tyrone-cluster;Job Run at request of Scheduler@tyrone-cluster
11/02/2013 13:38:30;0100;PBS_Server;Job;31326.tyrone-cluster;dequeuing from batch, state QUEUED
11/02/2013 13:38:30;0100;PBS_Server;Job;31326.tyrone-cluster;enqueuing into qp32, state 1 hop 1
11/02/2013 13:38:30;000d;PBS_Server;Job;31324.tyrone-cluster;Not sending email: User does not want mail of this type.
11/02/2013 13:38:30;0040;PBS_Server;Svr;tyrone-cluster;Scheduler was sent the command recyc
11/02/2013 13:39:01;0040;PBS_Server;Svr;tyrone-cluster;Scheduler was sent the command new
11/02/2013 13:39:01;0008;PBS_Server;Job;31326.tyrone-cluster;Job Modified at request of Scheduler@tyrone-cluster
11/02/2013 13:39:31;0040;PBS_Server;Svr;tyrone-cluster;Scheduler was sent the command new
11/02/2013 13:40:00;0040;PBS_Server;Svr;tyrone-cluster;Scheduler was sent the command new
11/02/2013 13:40:31;0040;PBS_Server;Svr;tyrone-cluster;Scheduler was sent the command new
11/02/2013 13:41:01;0040;PBS_Server;Svr;tyrone-cluster;Scheduler was sent the command new
11/02/2013 13:41:30;0040;PBS_Server;Svr;tyrone-cluster;Scheduler was sent the command new
11/02/2013 13:42:02;0040;PBS_Server;Svr;tyrone-cluster;Scheduler was sent the command new
11/02/2013 13:42:32;0040;PBS_Server;Svr;tyrone-cluster;Scheduler was sent the command new
11/02/2013 13:42:42;0002;PBS_Server;Svr;PBS_Server;Torque Server Version = 3.0.5, loglevel = 0
11/02/2013 13:43:04;0040;PBS_Server;Svr;tyrone-cluster;Scheduler was sent the command new
11/02/2013 13:43:34;0040;PBS_Server;Svr;tyrone-cluster;Scheduler was sent the command new
11/02/2013 13:44:07;0040;PBS_Server;Svr;tyrone-cluster;Scheduler was sent the command new
11/02/2013 13:44:40;0040;PBS_Server;Svr;tyrone-cluster;Scheduler was sent the command new
11/02/2013 13:45:08;0040;PBS_Server;Svr;tyrone-cluster;Scheduler was sent the command new
11/02/2013 13:45:43;0040;PBS_Server;Svr;tyrone-cluster;Scheduler was sent the command new
11/02/2013 13:46:14;0040;PBS_Server;Svr;tyrone-cluster;Scheduler was sent the command new
11/02/2013 13:46:45;0040;PBS_Server;Svr;tyrone-cluster;Scheduler was sent the command new
11/02/2013 13:47:13;0040;PBS_Server;Svr;tyrone-cluster;Scheduler was sent the command new
11/02/2013 13:47:42;0002;PBS_Server;Svr;PBS_Server;Torque Server Version = 3.0.5, loglevel = 0
11/02/2013 13:47:45;0040;PBS_Server;Svr;tyrone-cluster;Scheduler was sent the command new
11/02/2013 13:48:16;0040;PBS_Server;Svr;tyrone-cluster;Scheduler was sent the command new
11/02/2013 13:48:46;0040;PBS_Server;Svr;tyrone-cluster;Scheduler was sent the command new
11/02/2013 13:49:17;0040;PBS_Server;Svr;tyrone-cluster;Scheduler was sent the command new
11/02/2013 13:49:49;0040;PBS_Server;Svr;tyrone-cluster;Scheduler was sent the command new
11/02/2013 13:50:19;0040;PBS_Server;Svr;tyrone-cluster;Scheduler was sent the command new
11/02/2013 13:50:52;0040;PBS_Server;Svr;tyrone-cluster;Scheduler was sent the command new
11/02/2013 13:51:19;0040;PBS_Server;Svr;tyrone-cluster;Scheduler was sent the command new
11/02/2013 13:51:49;0040;PBS_Server;Svr;tyrone-cluster;Scheduler was sent the command new
11/02/2013 13:52:22;0040;PBS_Server;Svr;tyrone-cluster;Scheduler was sent the command new
11/02/2013 13:52:42;0002;PBS_Server;Svr;PBS_Server;Torque Server Version = 3.0.5, loglevel = 0
11/02/2013 13:52:56;0040;PBS_Server;Svr;tyrone-cluster;Scheduler was sent the command new
11/02/2013 13:53:23;0040;PBS_Server;Svr;tyrone-cluster;Scheduler was sent the command new
11/02/2013 13:53:58;0040;PBS_Server;Svr;tyrone-cluster;Scheduler was sent the command new
11/02/2013 13:54:16;0001;PBS_Server;Svr;PBS_Server;LOG_ERROR::stream_eof, connection to tyrone-node4 is no longer valid, connection may have been closed remotely, remote service may be down, or message may be corrupt (End of File).  setting node state to down
11/02/2013 13:54:30;0040;PBS_Server;Svr;tyrone-cluster;Scheduler was sent the command new
11/02/2013 13:55:00;0040;PBS_Server;Svr;tyrone-cluster;Scheduler was sent the command new
11/02/2013 13:55:28;0040;PBS_Server;Svr;tyrone-cluster;Scheduler was sent the command new
11/02/2013 13:56:00;0040;PBS_Server;Svr;tyrone-cluster;Scheduler was sent the command new
11/02/2013 13:56:31;0040;PBS_Server;Svr;tyrone-cluster;Scheduler was sent the command new
11/02/2013 13:57:02;0040;PBS_Server;Svr;tyrone-cluster;Scheduler was sent the command new
11/02/2013 13:57:32;0040;PBS_Server;Svr;tyrone-cluster;Scheduler was sent the command new
11/02/2013 13:57:42;0002;PBS_Server;Svr;PBS_Server;Torque Server Version = 3.0.5, loglevel = 0
11/02/2013 13:58:04;0040;PBS_Server;Svr;tyrone-cluster;Scheduler was sent the command new
11/02/2013 13:58:34;0040;PBS_Server;Svr;tyrone-cluster;Scheduler was sent the command new
11/02/2013 13:59:07;0040;PBS_Server;Svr;tyrone-cluster;Scheduler was sent the command new
11/02/2013 13:59:34;0040;PBS_Server;Svr;tyrone-cluster;Scheduler was sent the command new
11/02/2013 14:00:04;0040;PBS_Server;Svr;tyrone-cluster;Scheduler was sent the command new
11/02/2013 14:00:37;0040;PBS_Server;Svr;tyrone-cluster;Scheduler was sent the command new
11/02/2013 14:01:08;0040;PBS_Server;Svr;tyrone-cluster;Scheduler was sent the command new
11/02/2013 14:01:37;0040;PBS_Server;Svr;tyrone-cluster;Scheduler was sent the command new
11/02/2013 14:02:07;0040;PBS_Server;Svr;tyrone-cluster;Scheduler was sent the command new
11/02/2013 14:02:12;000d;PBS_Server;Job;31398.tyrone-cluster;Not sending email: User does not want mail of this type.
11/02/2013 14:02:12;0010;PBS_Server;Job;31398.tyrone-cluster;Exit_status=0 resources_used.cput=12:20:40 resources_used.mem=3181524kb resources_used.vmem=38327724kb resources_used.walltime=01:20:05
11/02/2013 14:02:12;0008;PBS_Server;Job;NULL;on_job_exit valid pjob: 0x31714a0 (substate=50)
11/02/2013 14:02:12;0008;PBS_Server;Job;NULL;on_job_exit valid pjob: 0x31714a0 (substate=51)
11/02/2013 14:02:12;0008;PBS_Server;Job;NULL;on_job_exit valid pjob: 0x31714a0 (substate=51)
11/02/2013 14:02:12;0008;PBS_Server;Job;NULL;on_job_exit valid pjob: 0x31714a0 (substate=53)
11/02/2013 14:02:12;0100;PBS_Server;Job;31398.tyrone-cluster;dequeuing from qp256, state COMPLETE
11/02/2013 14:02:12;0040;PBS_Server;Svr;tyrone-cluster;Scheduler was sent the command term
11/02/2013 14:02:12;0008;PBS_Server;Job;31399.tyrone-cluster;Job Modified at request of Scheduler@tyrone-cluster
11/02/2013 14:02:12;0008;PBS_Server;Job;31399.tyrone-cluster;Job Run at request of Scheduler@tyrone-cluster
11/02/2013 14:02:12;0040;PBS_Server;Svr;tyrone-cluster;Scheduler was sent the command recyc
11/02/2013 14:02:38;0040;PBS_Server;Svr;tyrone-cluster;Scheduler was sent the command new
11/02/2013 14:02:42;0002;PBS_Server;Svr;PBS_Server;Torque Server Version = 3.0.5, loglevel = 0
11/02/2013 14:02:48;000d;PBS_Server;Job;31399.tyrone-cluster;Not sending email: User does not want mail of this type.
11/02/2013 14:03:07;0040;PBS_Server;Svr;tyrone-cluster;Scheduler was sent the command new
11/02/2013 14:03:37;0040;PBS_Server;Svr;tyrone-cluster;Scheduler was sent the command new
11/02/2013 14:04:08;0040;PBS_Server;Svr;tyrone-cluster;Scheduler was sent the command new
11/02/2013 14:04:38;0040;PBS_Server;Svr;tyrone-cluster;Scheduler was sent the command new
11/02/2013 14:05:07;0040;PBS_Server;Svr;tyrone-cluster;Scheduler was sent the command new
11/02/2013 14:05:38;0040;PBS_Server;Svr;tyrone-cluster;Scheduler was sent the command new
11/02/2013 14:06:07;0040;PBS_Server;Svr;tyrone-cluster;Scheduler was sent the command new
11/02/2013 14:06:37;0040;PBS_Server;Svr;tyrone-cluster;Scheduler was sent the command new
11/02/2013 14:07:08;0040;PBS_Server;Svr;tyrone-cluster;Scheduler was sent the command new
11/02/2013 14:07:37;0040;PBS_Server;Svr;tyrone-cluster;Scheduler was sent the command new
11/02/2013 14:07:42;0002;PBS_Server;Svr;PBS_Server;Torque Server Version = 3.0.5, loglevel = 0
11/02/2013 14:08:07;0040;PBS_Server;Svr;tyrone-cluster;Scheduler was sent the command new
11/02/2013 14:08:38;0040;PBS_Server;Svr;tyrone-cluster;Scheduler was sent the command new
11/02/2013 14:09:07;0040;PBS_Server;Svr;tyrone-cluster;Scheduler was sent the command new
11/02/2013 14:09:37;0040;PBS_Server;Svr;tyrone-cluster;Scheduler was sent the command new
11/02/2013 14:10:08;0040;PBS_Server;Svr;tyrone-cluster;Scheduler was sent the command new
11/02/2013 14:10:37;0040;PBS_Server;Svr;tyrone-cluster;Scheduler was sent the command new
11/02/2013 14:11:07;0040;PBS_Server;Svr;tyrone-cluster;Scheduler was sent the command new
11/02/2013 14:11:38;0040;PBS_Server;Svr;tyrone-cluster;Scheduler was sent the command new
11/02/2013 14:12:07;0040;PBS_Server;Svr;tyrone-cluster;Scheduler was sent the command new
11/02/2013 14:12:37;0040;PBS_Server;Svr;tyrone-cluster;Scheduler was sent the command new
11/02/2013 14:12:42;0002;PBS_Server;Svr;PBS_Server;Torque Server Version = 3.0.5, loglevel = 0
11/02/2013 14:13:08;0040;PBS_Server;Svr;tyrone-cluster;Scheduler was sent the command new
11/02/2013 14:13:37;0040;PBS_Server;Svr;tyrone-cluster;Scheduler was sent the command new
11/02/2013 14:14:07;0040;PBS_Server;Svr;tyrone-cluster;Scheduler was sent the command new
11/02/2013 14:14:39;0040;PBS_Server;Svr;tyrone-cluster;Scheduler was sent the command new
11/02/2013 14:15:07;0040;PBS_Server;Svr;tyrone-cluster;Scheduler was sent the command new
11/02/2013 14:15:37;0040;PBS_Server;Svr;tyrone-cluster;Scheduler was sent the command new
11/02/2013 14:16:08;0040;PBS_Server;Svr;tyrone-cluster;Scheduler was sent the command new
11/02/2013 14:16:37;0040;PBS_Server;Svr;tyrone-cluster;Scheduler was sent the command new
11/02/2013 14:17:07;0040;PBS_Server;Svr;tyrone-cluster;Scheduler was sent the command new
11/02/2013 14:17:38;0040;PBS_Server;Svr;tyrone-cluster;Scheduler was sent the command new
11/02/2013 14:17:42;0002;PBS_Server;Svr;PBS_Server;Torque Server Version = 3.0.5, loglevel = 0
11/02/2013 14:18:07;0040;PBS_Server;Svr;tyrone-cluster;Scheduler was sent the command new
11/02/2013 14:18:37;0040;PBS_Server;Svr;tyrone-cluster;Scheduler was sent the command new
11/02/2013 14:19:08;0040;PBS_Server;Svr;tyrone-cluster;Scheduler was sent the command new
11/02/2013 14:19:37;0040;PBS_Server;Svr;tyrone-cluster;Scheduler was sent the command new
11/02/2013 14:20:07;0040;PBS_Server;Svr;tyrone-cluster;Scheduler was sent the command new
11/02/2013 14:20:39;0040;PBS_Server;Svr;tyrone-cluster;Scheduler was sent the command new
11/02/2013 14:21:07;0040;PBS_Server;Svr;tyrone-cluster;Scheduler was sent the command new
11/02/2013 14:21:37;0040;PBS_Server;Svr;tyrone-cluster;Scheduler was sent the command new
11/02/2013 14:22:08;0040;PBS_Server;Svr;tyrone-cluster;Scheduler was sent the command new
11/02/2013 14:22:37;0040;PBS_Server;Svr;tyrone-cluster;Scheduler was sent the command new
11/02/2013 14:22:42;0002;PBS_Server;Svr;PBS_Server;Torque Server Version = 3.0.5, loglevel = 0
11/02/2013 14:23:07;0040;PBS_Server;Svr;tyrone-cluster;Scheduler was sent the command new
11/02/2013 14:23:38;0040;PBS_Server;Svr;tyrone-cluster;Scheduler was sent the command new
11/02/2013 14:24:08;0040;PBS_Server;Svr;tyrone-cluster;Scheduler was sent the command new
11/02/2013 14:24:37;0040;PBS_Server;Svr;tyrone-cluster;Scheduler was sent the command new
11/02/2013 14:25:08;0040;PBS_Server;Svr;tyrone-cluster;Scheduler was sent the command new
11/02/2013 14:25:37;0040;PBS_Server;Svr;tyrone-cluster;Scheduler was sent the command new
11/02/2013 14:26:07;0040;PBS_Server;Svr;tyrone-cluster;Scheduler was sent the command new
11/02/2013 14:26:38;0040;PBS_Server;Svr;tyrone-cluster;Scheduler was sent the command new
11/02/2013 14:27:07;0040;PBS_Server;Svr;tyrone-cluster;Scheduler was sent the command new
11/02/2013 14:27:37;0040;PBS_Server;Svr;tyrone-cluster;Scheduler was sent the command new
11/02/2013 14:27:42;0002;PBS_Server;Svr;PBS_Server;Torque Server Version = 3.0.5, loglevel = 0
11/02/2013 14:28:11;0040;PBS_Server;Svr;tyrone-cluster;Scheduler was sent the command new
11/02/2013 14:28:38;0040;PBS_Server;Svr;tyrone-cluster;Scheduler was sent the command new
11/02/2013 14:29:13;0040;PBS_Server;Svr;tyrone-cluster;Scheduler was sent the command new
11/02/2013 14:29:45;0040;PBS_Server;Svr;tyrone-cluster;Scheduler was sent the command new
11/02/2013 14:30:16;0040;PBS_Server;Svr;tyrone-cluster;Scheduler was sent the command new
11/02/2013 14:30:46;0040;PBS_Server;Svr;tyrone-cluster;Scheduler was sent the command new
11/02/2013 14:31:17;0040;PBS_Server;Svr;tyrone-cluster;Scheduler was sent the command new
11/02/2013 14:31:46;0040;PBS_Server;Svr;tyrone-cluster;Scheduler was sent the command new
11/02/2013 14:32:16;0040;PBS_Server;Svr;tyrone-cluster;Scheduler was sent the command new
11/02/2013 14:32:42;0002;PBS_Server;Svr;PBS_Server;Torque Server Version = 3.0.5, loglevel = 0
11/02/2013 14:32:48;0040;PBS_Server;Svr;tyrone-cluster;Scheduler was sent the command new
11/02/2013 14:33:19;0040;PBS_Server;Svr;tyrone-cluster;Scheduler was sent the command new
11/02/2013 14:33:49;0040;PBS_Server;Svr;tyrone-cluster;Scheduler was sent the command new
11/02/2013 14:34:22;0040;PBS_Server;Svr;tyrone-cluster;Scheduler was sent the command new
11/02/2013 14:34:54;0040;PBS_Server;Svr;tyrone-cluster;Scheduler was sent the command new
11/02/2013 14:35:22;0040;PBS_Server;Svr;tyrone-cluster;Scheduler was sent the command new
11/02/2013 14:35:52;0040;PBS_Server;Svr;tyrone-cluster;Scheduler was sent the command new
11/02/2013 14:36:26;0040;PBS_Server;Svr;tyrone-cluster;Scheduler was sent the command new
11/02/2013 14:36:57;0040;PBS_Server;Svr;tyrone-cluster;Scheduler was sent the command new
11/02/2013 14:37:28;0040;PBS_Server;Svr;tyrone-cluster;Scheduler was sent the command new
11/02/2013 14:37:42;0002;PBS_Server;Svr;PBS_Server;Torque Server Version = 3.0.5, loglevel = 0
11/02/2013 14:37:59;0040;PBS_Server;Svr;tyrone-cluster;Scheduler was sent the command new
11/02/2013 14:38:31;0040;PBS_Server;Svr;tyrone-cluster;Scheduler was sent the command new
11/02/2013 14:39:02;0040;PBS_Server;Svr;tyrone-cluster;Scheduler was sent the command new
11/02/2013 14:39:33;0040;PBS_Server;Svr;tyrone-cluster;Scheduler was sent the command new
11/02/2013 14:40:04;0040;PBS_Server;Svr;tyrone-cluster;Scheduler was sent the command new
11/02/2013 14:40:34;0040;PBS_Server;Svr;tyrone-cluster;Scheduler was sent the command new
11/02/2013 14:41:06;0040;PBS_Server;Svr;tyrone-cluster;Scheduler was sent the command new
11/02/2013 14:41:34;0040;PBS_Server;Svr;tyrone-cluster;Scheduler was sent the command new
11/02/2013 14:42:04;0040;PBS_Server;Svr;tyrone-cluster;Scheduler was sent the command new
11/02/2013 14:42:36;0040;PBS_Server;Svr;tyrone-cluster;Scheduler was sent the command new
11/02/2013 14:42:42;0002;PBS_Server;Svr;PBS_Server;Torque Server Version = 3.0.5, loglevel = 0
11/02/2013 14:43:04;0040;PBS_Server;Svr;tyrone-cluster;Scheduler was sent the command new
11/02/2013 14:43:34;0040;PBS_Server;Svr;tyrone-cluster;Scheduler was sent the command new
11/02/2013 14:44:06;0040;PBS_Server;Svr;tyrone-cluster;Scheduler was sent the command new
11/02/2013 14:44:35;0040;PBS_Server;Svr;tyrone-cluster;Scheduler was sent the command new
11/02/2013 14:45:07;0040;PBS_Server;Svr;tyrone-cluster;Scheduler was sent the command new
11/02/2013 14:45:37;0040;PBS_Server;Svr;tyrone-cluster;Scheduler was sent the command new
11/02/2013 14:46:11;0040;PBS_Server;Svr;tyrone-cluster;Scheduler was sent the command new
11/02/2013 14:46:41;0040;PBS_Server;Svr;tyrone-cluster;Scheduler was sent the command new
11/02/2013 14:47:13;0040;PBS_Server;Svr;tyrone-cluster;Scheduler was sent the command new
11/02/2013 14:47:42;0002;PBS_Server;Svr;PBS_Server;Torque Server Version = 3.0.5, loglevel = 0
11/02/2013 14:47:45;0040;PBS_Server;Svr;tyrone-cluster;Scheduler was sent the command new
11/02/2013 14:48:16;0040;PBS_Server;Svr;tyrone-cluster;Scheduler was sent the command new
11/02/2013 14:48:46;0040;PBS_Server;Svr;tyrone-cluster;Scheduler was sent the command new
11/02/2013 14:49:18;0040;PBS_Server;Svr;tyrone-cluster;Scheduler was sent the command new
11/02/2013 14:49:49;0040;PBS_Server;Svr;tyrone-cluster;Scheduler was sent the command new
11/02/2013 14:50:19;0040;PBS_Server;Svr;tyrone-cluster;Scheduler was sent the command new
11/02/2013 14:50:52;0040;PBS_Server;Svr;tyrone-cluster;Scheduler was sent the command new
11/02/2013 14:51:24;0040;PBS_Server;Svr;tyrone-cluster;Scheduler was sent the command new
11/02/2013 14:51:52;0040;PBS_Server;Svr;tyrone-cluster;Scheduler was sent the command new
11/02/2013 14:52:22;0040;PBS_Server;Svr;tyrone-cluster;Scheduler was sent the command new
11/02/2013 14:52:42;0002;PBS_Server;Svr;PBS_Server;Torque Server Version = 3.0.5, loglevel = 0
11/02/2013 14:52:54;0040;PBS_Server;Svr;tyrone-cluster;Scheduler was sent the command new
11/02/2013 14:53:22;0040;PBS_Server;Svr;tyrone-cluster;Scheduler was sent the command new
11/02/2013 14:53:52;0040;PBS_Server;Svr;tyrone-cluster;Scheduler was sent the command new
11/02/2013 14:54:26;0040;PBS_Server;Svr;tyrone-cluster;Scheduler was sent the command new
11/02/2013 14:54:56;0040;PBS_Server;Svr;tyrone-cluster;Scheduler was sent the command new
11/02/2013 14:55:28;0040;PBS_Server;Svr;tyrone-cluster;Scheduler was sent the command new
11/02/2013 14:56:00;0040;PBS_Server;Svr;tyrone-cluster;Scheduler was sent the command new
11/02/2013 14:56:31;0040;PBS_Server;Svr;tyrone-cluster;Scheduler was sent the command new
11/02/2013 14:57:01;0040;PBS_Server;Svr;tyrone-cluster;Scheduler was sent the command new
11/02/2013 14:57:32;0040;PBS_Server;Svr;tyrone-cluster;Scheduler was sent the command new
11/02/2013 14:57:42;0002;PBS_Server;Svr;PBS_Server;Torque Server Version = 3.0.5, loglevel = 0
11/02/2013 14:58:04;0040;PBS_Server;Svr;tyrone-cluster;Scheduler was sent the command new
11/02/2013 14:58:34;0040;PBS_Server;Svr;tyrone-cluster;Scheduler was sent the command new
11/02/2013 14:59:07;0040;PBS_Server;Svr;tyrone-cluster;Scheduler was sent the command new
11/02/2013 14:59:35;0040;PBS_Server;Svr;tyrone-cluster;Scheduler was sent the command new
11/02/2013 15:00:07;0040;PBS_Server;Svr;tyrone-cluster;Scheduler was sent the command new
11/02/2013 15:00:37;0040;PBS_Server;Svr;tyrone-cluster;Scheduler was sent the command new
11/02/2013 15:01:11;0040;PBS_Server;Svr;tyrone-cluster;Scheduler was sent the command new
11/02/2013 15:01:13;0100;PBS_Server;Job;31418.tyrone-cluster;enqueuing into batch, state 1 hop 1
11/02/2013 15:01:13;0100;PBS_Server;Job;31418.tyrone-cluster;dequeuing from batch, state QUEUED
11/02/2013 15:01:13;0100;PBS_Server;Job;31418.tyrone-cluster;enqueuing into qp128, state 1 hop 1
11/02/2013 15:01:13;0008;PBS_Server;Job;31418.tyrone-cluster;Job Queued at request of secbadar@tyrone-cluster, owner = secbadar@tyrone-cluster, job name = 128Edge4, queue = qp128
11/02/2013 15:01:16;0008;PBS_Server;Job;31418.tyrone-cluster;Job Modified at request of Scheduler@tyrone-cluster
11/02/2013 15:01:16;0008;PBS_Server;Job;31418.tyrone-cluster;Job Run at request of Scheduler@tyrone-cluster
11/02/2013 15:01:16;0040;PBS_Server;Svr;tyrone-cluster;Scheduler was sent the command recyc
11/02/2013 15:01:38;0040;PBS_Server;Svr;tyrone-cluster;Scheduler was sent the command new
11/02/2013 15:02:12;000d;PBS_Server;Job;31418.tyrone-cluster;Not sending email: User does not want mail of this type.
11/02/2013 15:02:12;0040;PBS_Server;Svr;tyrone-cluster;Scheduler was sent the command new
11/02/2013 15:02:42;0002;PBS_Server;Svr;PBS_Server;Torque Server Version = 3.0.5, loglevel = 0
11/02/2013 15:02:44;0040;PBS_Server;Svr;tyrone-cluster;Scheduler was sent the command new
11/02/2013 15:03:15;0040;PBS_Server;Svr;tyrone-cluster;Scheduler was sent the command new
11/02/2013 15:03:42;0040;PBS_Server;Svr;tyrone-cluster;Scheduler was sent the command new
11/02/2013 15:04:15;0040;PBS_Server;Svr;tyrone-cluster;Scheduler was sent the command new
11/02/2013 15:04:46;0040;PBS_Server;Svr;tyrone-cluster;Scheduler was sent the command new
11/02/2013 15:05:17;0040;PBS_Server;Svr;tyrone-cluster;Scheduler was sent the command new
11/02/2013 15:05:48;0040;PBS_Server;Svr;tyrone-cluster;Scheduler was sent the command new
11/02/2013 15:06:19;0040;PBS_Server;Svr;tyrone-cluster;Scheduler was sent the command new
11/02/2013 15:06:49;0040;PBS_Server;Svr;tyrone-cluster;Scheduler was sent the command new
11/02/2013 15:07:19;0040;PBS_Server;Svr;tyrone-cluster;Scheduler was sent the command new
11/02/2013 15:07:42;0002;PBS_Server;Svr;PBS_Server;Torque Server Version = 3.0.5, loglevel = 0
11/02/2013 15:07:49;0040;PBS_Server;Svr;tyrone-cluster;Scheduler was sent the command new
11/02/2013 15:08:19;0040;PBS_Server;Svr;tyrone-cluster;Scheduler was sent the command new
11/02/2013 15:08:52;0040;PBS_Server;Svr;tyrone-cluster;Scheduler was sent the command new
11/02/2013 15:09:23;0040;PBS_Server;Svr;tyrone-cluster;Scheduler was sent the command new
11/02/2013 15:09:51;0040;PBS_Server;Svr;tyrone-cluster;Scheduler was sent the command new
11/02/2013 15:10:22;0040;PBS_Server;Svr;tyrone-cluster;Scheduler was sent the command new
11/02/2013 15:10:54;0040;PBS_Server;Svr;tyrone-cluster;Scheduler was sent the command new
11/02/2013 15:11:22;0040;PBS_Server;Svr;tyrone-cluster;Scheduler was sent the command new
11/02/2013 15:11:52;0040;PBS_Server;Svr;tyrone-cluster;Scheduler was sent the command new
11/02/2013 15:12:24;0040;PBS_Server;Svr;tyrone-cluster;Scheduler was sent the command new
11/02/2013 15:12:42;0002;PBS_Server;Svr;PBS_Server;Torque Server Version = 3.0.5, loglevel = 0
11/02/2013 15:12:53;0040;PBS_Server;Svr;tyrone-cluster;Scheduler was sent the command new
11/02/2013 15:12:56;000d;PBS_Server;Job;31399.tyrone-cluster;Not sending email: User does not want mail of this type.
11/02/2013 15:12:56;0010;PBS_Server;Job;31399.tyrone-cluster;Exit_status=0 resources_used.cput=10:35:03 resources_used.mem=3184316kb resources_used.vmem=38327496kb resources_used.walltime=01:10:44
11/02/2013 15:12:56;0008;PBS_Server;Job;NULL;on_job_exit valid pjob: 0x2e60d70 (substate=50)
11/02/2013 15:12:56;0008;PBS_Server;Job;NULL;on_job_exit valid pjob: 0x2e60d70 (substate=51)
11/02/2013 15:12:56;0008;PBS_Server;Job;NULL;on_job_exit valid pjob: 0x2e60d70 (substate=51)
11/02/2013 15:12:56;0008;PBS_Server;Job;NULL;on_job_exit valid pjob: 0x2e60d70 (substate=53)
11/02/2013 15:12:56;0100;PBS_Server;Job;31399.tyrone-cluster;dequeuing from qp256, state COMPLETE
11/02/2013 15:12:56;0040;PBS_Server;Svr;tyrone-cluster;Scheduler was sent the command term
11/02/2013 15:13:22;0040;PBS_Server;Svr;tyrone-cluster;Scheduler was sent the command new
11/02/2013 15:13:56;0040;PBS_Server;Svr;tyrone-cluster;Scheduler was sent the command new
11/02/2013 15:14:27;0040;PBS_Server;Svr;tyrone-cluster;Scheduler was sent the command new
11/02/2013 15:14:57;0040;PBS_Server;Svr;tyrone-cluster;Scheduler was sent the command new
11/02/2013 15:15:30;0040;PBS_Server;Svr;tyrone-cluster;Scheduler was sent the command new
11/02/2013 15:16:01;0040;PBS_Server;Svr;tyrone-cluster;Scheduler was sent the command new
11/02/2013 15:16:32;0040;PBS_Server;Svr;tyrone-cluster;Scheduler was sent the command new
11/02/2013 15:17:03;0040;PBS_Server;Svr;tyrone-cluster;Scheduler was sent the command new
11/02/2013 15:17:32;0008;PBS_Server;Job;31418.tyrone-cluster;Job deleted at request of secbadar@tyrone-cluster
11/02/2013 15:17:32;0008;PBS_Server;Job;31418.tyrone-cluster;Job sent signal SIGTERM on delete
11/02/2013 15:17:32;0040;PBS_Server;Svr;tyrone-cluster;Scheduler was sent the command new
11/02/2013 15:17:33;000d;PBS_Server;Job;31418.tyrone-cluster;Not sending email: User does not want mail of this type.
11/02/2013 15:17:33;0010;PBS_Server;Job;31418.tyrone-cluster;Exit_status=143 resources_used.cput=00:00:31 resources_used.mem=334884kb resources_used.vmem=2642572kb resources_used.walltime=00:16:16
11/02/2013 15:17:33;0008;PBS_Server;Job;NULL;on_job_exit valid pjob: 0x2ed2ba0 (substate=50)
11/02/2013 15:17:33;0008;PBS_Server;Job;NULL;on_job_exit valid pjob: 0x2ed2ba0 (substate=51)
11/02/2013 15:17:33;0008;PBS_Server;Job;NULL;on_job_exit valid pjob: 0x2ed2ba0 (substate=51)
11/02/2013 15:17:33;0008;PBS_Server;Job;NULL;on_job_exit valid pjob: 0x2ed2ba0 (substate=53)
11/02/2013 15:17:33;0100;PBS_Server;Job;31418.tyrone-cluster;dequeuing from qp128, state COMPLETE
11/02/2013 15:17:33;0040;PBS_Server;Svr;tyrone-cluster;Scheduler was sent the command term
11/02/2013 15:17:42;0002;PBS_Server;Svr;PBS_Server;Torque Server Version = 3.0.5, loglevel = 0
11/02/2013 15:18:03;0040;PBS_Server;Svr;tyrone-cluster;Scheduler was sent the command new
11/02/2013 15:18:37;0040;PBS_Server;Svr;tyrone-cluster;Scheduler was sent the command new
11/02/2013 15:19:09;0040;PBS_Server;Svr;tyrone-cluster;Scheduler was sent the command new
11/02/2013 15:19:37;0040;PBS_Server;Svr;tyrone-cluster;Scheduler was sent the command new
11/02/2013 15:20:07;0040;PBS_Server;Svr;tyrone-cluster;Scheduler was sent the command new
11/02/2013 15:20:39;0040;PBS_Server;Svr;tyrone-cluster;Scheduler was sent the command new
11/02/2013 15:21:06;0040;PBS_Server;Svr;tyrone-cluster;Scheduler was sent the command new
11/02/2013 15:21:37;0040;PBS_Server;Svr;tyrone-cluster;Scheduler was sent the command new
11/02/2013 15:22:09;0040;PBS_Server;Svr;tyrone-cluster;Scheduler was sent the command new
11/02/2013 15:22:38;0040;PBS_Server;Svr;tyrone-cluster;Scheduler was sent the command new
11/02/2013 15:22:42;0002;PBS_Server;Svr;PBS_Server;Torque Server Version = 3.0.5, loglevel = 0
11/02/2013 15:23:13;0040;PBS_Server;Svr;tyrone-cluster;Scheduler was sent the command new
11/02/2013 15:23:44;0040;PBS_Server;Svr;tyrone-cluster;Scheduler was sent the command new
11/02/2013 15:24:16;0040;PBS_Server;Svr;tyrone-cluster;Scheduler was sent the command new
11/02/2013 15:24:47;0040;PBS_Server;Svr;tyrone-cluster;Scheduler was sent the command new
11/02/2013 15:25:21;0040;PBS_Server;Svr;tyrone-cluster;Scheduler was sent the command new
11/02/2013 15:25:49;0040;PBS_Server;Svr;tyrone-cluster;Scheduler was sent the command new
11/02/2013 15:26:18;0040;PBS_Server;Svr;tyrone-cluster;Scheduler was sent the command new
11/02/2013 15:26:52;0040;PBS_Server;Svr;tyrone-cluster;Scheduler was sent the command new
11/02/2013 15:27:23;0040;PBS_Server;Svr;tyrone-cluster;Scheduler was sent the command new
11/02/2013 15:27:42;0002;PBS_Server;Svr;PBS_Server;Torque Server Version = 3.0.5, loglevel = 0
11/02/2013 15:27:51;0040;PBS_Server;Svr;tyrone-cluster;Scheduler was sent the command new
11/02/2013 15:28:22;0040;PBS_Server;Svr;tyrone-cluster;Scheduler was sent the command new
11/02/2013 15:28:54;0040;PBS_Server;Svr;tyrone-cluster;Scheduler was sent the command new
11/02/2013 15:29:22;0040;PBS_Server;Svr;tyrone-cluster;Scheduler was sent the command new
11/02/2013 15:29:52;0040;PBS_Server;Svr;tyrone-cluster;Scheduler was sent the command new
11/02/2013 15:30:26;0040;PBS_Server;Svr;tyrone-cluster;Scheduler was sent the command new
11/02/2013 15:30:56;0040;PBS_Server;Svr;tyrone-cluster;Scheduler was sent the command new
11/02/2013 15:31:28;0040;PBS_Server;Svr;tyrone-cluster;Scheduler was sent the command new
11/02/2013 15:31:59;0040;PBS_Server;Svr;tyrone-cluster;Scheduler was sent the command new
11/02/2013 15:32:31;0040;PBS_Server;Svr;tyrone-cluster;Scheduler was sent the command new
11/02/2013 15:32:35;0001;PBS_Server;Svr;PBS_Server;LOG_ERROR::stream_eof, connection to tyrone-node4 is no longer valid, connection may have been closed remotely, remote service may be down, or message may be corrupt (End of File).  setting node state to down
11/02/2013 15:32:42;0002;PBS_Server;Svr;PBS_Server;Torque Server Version = 3.0.5, loglevel = 0
11/02/2013 15:33:02;0040;PBS_Server;Svr;tyrone-cluster;Scheduler was sent the command new
11/02/2013 15:33:36;0040;PBS_Server;Svr;tyrone-cluster;Scheduler was sent the command new
11/02/2013 15:34:04;0040;PBS_Server;Svr;tyrone-cluster;Scheduler was sent the command new
11/02/2013 15:34:34;0040;PBS_Server;Svr;tyrone-cluster;Scheduler was sent the command new
11/02/2013 15:35:07;0040;PBS_Server;Svr;tyrone-cluster;Scheduler was sent the command new
11/02/2013 15:35:36;0040;PBS_Server;Svr;tyrone-cluster;Scheduler was sent the command new
11/02/2013 15:36:06;0040;PBS_Server;Svr;tyrone-cluster;Scheduler was sent the command new
11/02/2013 15:36:37;0040;PBS_Server;Svr;tyrone-cluster;Scheduler was sent the command new
11/02/2013 15:37:06;0040;PBS_Server;Svr;tyrone-cluster;Scheduler was sent the command new
11/02/2013 15:37:36;0040;PBS_Server;Svr;tyrone-cluster;Scheduler was sent the command new
11/02/2013 15:37:42;0002;PBS_Server;Svr;PBS_Server;Torque Server Version = 3.0.5, loglevel = 0
11/02/2013 15:38:07;0040;PBS_Server;Svr;tyrone-cluster;Scheduler was sent the command new
11/02/2013 15:38:40;0040;PBS_Server;Svr;tyrone-cluster;Scheduler was sent the command new
11/02/2013 15:39:08;0040;PBS_Server;Svr;tyrone-cluster;Scheduler was sent the command new
11/02/2013 15:39:43;0040;PBS_Server;Svr;tyrone-cluster;Scheduler was sent the command new
11/02/2013 15:40:14;0040;PBS_Server;Svr;tyrone-cluster;Scheduler was sent the command new
11/02/2013 15:40:46;0040;PBS_Server;Svr;tyrone-cluster;Scheduler was sent the command new
11/02/2013 15:41:16;0040;PBS_Server;Svr;tyrone-cluster;Scheduler was sent the command new
11/02/2013 15:41:50;0040;PBS_Server;Svr;tyrone-cluster;Scheduler was sent the command new
11/02/2013 15:42:19;0040;PBS_Server;Svr;tyrone-cluster;Scheduler was sent the command new
11/02/2013 15:42:42;0002;PBS_Server;Svr;PBS_Server;Torque Server Version = 3.0.5, loglevel = 0
11/02/2013 15:42:49;0040;PBS_Server;Svr;tyrone-cluster;Scheduler was sent the command new
11/02/2013 15:43:20;0040;PBS_Server;Svr;tyrone-cluster;Scheduler was sent the command new
11/02/2013 15:43:53;0040;PBS_Server;Svr;tyrone-cluster;Scheduler was sent the command new
11/02/2013 15:44:20;0040;PBS_Server;Svr;tyrone-cluster;Scheduler was sent the command new
11/02/2013 15:44:51;0040;PBS_Server;Svr;tyrone-cluster;Scheduler was sent the command new
11/02/2013 15:45:20;0040;PBS_Server;Svr;tyrone-cluster;Scheduler was sent the command new
11/02/2013 15:45:52;0040;PBS_Server;Svr;tyrone-cluster;Scheduler was sent the command new
11/02/2013 15:46:22;0040;PBS_Server;Svr;tyrone-cluster;Scheduler was sent the command new
11/02/2013 15:46:54;0040;PBS_Server;Svr;tyrone-cluster;Scheduler was sent the command new
11/02/2013 15:47:21;0040;PBS_Server;Svr;tyrone-cluster;Scheduler was sent the command new
11/02/2013 15:47:42;0002;PBS_Server;Svr;PBS_Server;Torque Server Version = 3.0.5, loglevel = 0
11/02/2013 15:47:52;0040;PBS_Server;Svr;tyrone-cluster;Scheduler was sent the command new
11/02/2013 15:48:25;0040;PBS_Server;Svr;tyrone-cluster;Scheduler was sent the command new
11/02/2013 15:48:53;0040;PBS_Server;Svr;tyrone-cluster;Scheduler was sent the command new
11/02/2013 15:49:28;0040;PBS_Server;Svr;tyrone-cluster;Scheduler was sent the command new
11/02/2013 15:49:59;0040;PBS_Server;Svr;tyrone-cluster;Scheduler was sent the command new
11/02/2013 15:50:31;0040;PBS_Server;Svr;tyrone-cluster;Scheduler was sent the command new
11/02/2013 15:51:02;0040;PBS_Server;Svr;tyrone-cluster;Scheduler was sent the command new
11/02/2013 15:51:33;0040;PBS_Server;Svr;tyrone-cluster;Scheduler was sent the command new
11/02/2013 15:52:04;0040;PBS_Server;Svr;tyrone-cluster;Scheduler was sent the command new
11/02/2013 15:52:34;0040;PBS_Server;Svr;tyrone-cluster;Scheduler was sent the command new
11/02/2013 15:52:42;0002;PBS_Server;Svr;PBS_Server;Torque Server Version = 3.0.5, loglevel = 0
11/02/2013 15:53:07;0040;PBS_Server;Svr;tyrone-cluster;Scheduler was sent the command new
11/02/2013 15:53:38;0040;PBS_Server;Svr;tyrone-cluster;Scheduler was sent the command new
11/02/2013 15:54:07;0040;PBS_Server;Svr;tyrone-cluster;Scheduler was sent the command new
11/02/2013 15:54:37;0040;PBS_Server;Svr;tyrone-cluster;Scheduler was sent the command new
11/02/2013 15:55:09;0040;PBS_Server;Svr;tyrone-cluster;Scheduler was sent the command new
11/02/2013 15:55:37;0040;PBS_Server;Svr;tyrone-cluster;Scheduler was sent the command new
11/02/2013 15:56:07;0040;PBS_Server;Svr;tyrone-cluster;Scheduler was sent the command new
11/02/2013 15:56:40;0040;PBS_Server;Svr;tyrone-cluster;Scheduler was sent the command new
11/02/2013 15:57:08;0040;PBS_Server;Svr;tyrone-cluster;Scheduler was sent the command new
11/02/2013 15:57:42;0002;PBS_Server;Svr;PBS_Server;Torque Server Version = 3.0.5, loglevel = 0
11/02/2013 15:57:43;0040;PBS_Server;Svr;tyrone-cluster;Scheduler was sent the command new
11/02/2013 15:58:13;0040;PBS_Server;Svr;tyrone-cluster;Scheduler was sent the command new
11/02/2013 15:58:46;0040;PBS_Server;Svr;tyrone-cluster;Scheduler was sent the command new
11/02/2013 15:59:16;0040;PBS_Server;Svr;tyrone-cluster;Scheduler was sent the command new
11/02/2013 15:59:51;0040;PBS_Server;Svr;tyrone-cluster;Scheduler was sent the command new
11/02/2013 16:00:19;0040;PBS_Server;Svr;tyrone-cluster;Scheduler was sent the command new
11/02/2013 16:00:49;0040;PBS_Server;Svr;tyrone-cluster;Scheduler was sent the command new
11/02/2013 16:01:22;0040;PBS_Server;Svr;tyrone-cluster;Scheduler was sent the command new
11/02/2013 16:01:51;0040;PBS_Server;Svr;tyrone-cluster;Scheduler was sent the command new
11/02/2013 16:02:22;0040;PBS_Server;Svr;tyrone-cluster;Scheduler was sent the command new
11/02/2013 16:02:42;0002;PBS_Server;Svr;PBS_Server;Torque Server Version = 3.0.5, loglevel = 0
11/02/2013 16:02:52;0040;PBS_Server;Svr;tyrone-cluster;Scheduler was sent the command new
11/02/2013 16:03:25;0040;PBS_Server;Svr;tyrone-cluster;Scheduler was sent the command new
11/02/2013 16:03:53;0040;PBS_Server;Svr;tyrone-cluster;Scheduler was sent the command new
11/02/2013 16:04:28;0040;PBS_Server;Svr;tyrone-cluster;Scheduler was sent the command new
11/02/2013 16:04:58;0040;PBS_Server;Svr;tyrone-cluster;Scheduler was sent the command new
11/02/2013 16:05:31;0040;PBS_Server;Svr;tyrone-cluster;Scheduler was sent the command new
11/02/2013 16:06:02;0040;PBS_Server;Svr;tyrone-cluster;Scheduler was sent the command new
11/02/2013 16:06:34;0040;PBS_Server;Svr;tyrone-cluster;Scheduler was sent the command new
11/02/2013 16:07:04;0040;PBS_Server;Svr;tyrone-cluster;Scheduler was sent the command new
11/02/2013 16:07:34;0040;PBS_Server;Svr;tyrone-cluster;Scheduler was sent the command new
11/02/2013 16:07:42;0002;PBS_Server;Svr;PBS_Server;Torque Server Version = 3.0.5, loglevel = 0
11/02/2013 16:08:05;0040;PBS_Server;Svr;tyrone-cluster;Scheduler was sent the command new
11/02/2013 16:08:34;0040;PBS_Server;Svr;tyrone-cluster;Scheduler was sent the command new
11/02/2013 16:09:04;0040;PBS_Server;Svr;tyrone-cluster;Scheduler was sent the command new
11/02/2013 16:09:35;0040;PBS_Server;Svr;tyrone-cluster;Scheduler was sent the command new
11/02/2013 16:10:04;0040;PBS_Server;Svr;tyrone-cluster;Scheduler was sent the command new
11/02/2013 16:10:34;0040;PBS_Server;Svr;tyrone-cluster;Scheduler was sent the command new
11/02/2013 16:11:05;0040;PBS_Server;Svr;tyrone-cluster;Scheduler was sent the command new
11/02/2013 16:11:34;0040;PBS_Server;Svr;tyrone-cluster;Scheduler was sent the command new
11/02/2013 16:12:04;0040;PBS_Server;Svr;tyrone-cluster;Scheduler was sent the command new
11/02/2013 16:12:35;0040;PBS_Server;Svr;tyrone-cluster;Scheduler was sent the command new
11/02/2013 16:12:42;0002;PBS_Server;Svr;PBS_Server;Torque Server Version = 3.0.5, loglevel = 0
11/02/2013 16:13:04;0040;PBS_Server;Svr;tyrone-cluster;Scheduler was sent the command new
11/02/2013 16:13:34;0040;PBS_Server;Svr;tyrone-cluster;Scheduler was sent the command new
11/02/2013 16:14:07;0040;PBS_Server;Svr;tyrone-cluster;Scheduler was sent the command new
11/02/2013 16:14:38;0040;PBS_Server;Svr;tyrone-cluster;Scheduler was sent the command new
11/02/2013 16:15:06;0040;PBS_Server;Svr;tyrone-cluster;Scheduler was sent the command new
11/02/2013 16:15:37;0040;PBS_Server;Svr;tyrone-cluster;Scheduler was sent the command new
11/02/2013 16:16:06;0040;PBS_Server;Svr;tyrone-cluster;Scheduler was sent the command new
11/02/2013 16:16:37;0040;PBS_Server;Svr;tyrone-cluster;Scheduler was sent the command new
11/02/2013 16:17:07;0040;PBS_Server;Svr;tyrone-cluster;Scheduler was sent the command new
11/02/2013 16:17:40;0040;PBS_Server;Svr;tyrone-cluster;Scheduler was sent the command new
11/02/2013 16:17:42;0002;PBS_Server;Svr;PBS_Server;Torque Server Version = 3.0.5, loglevel = 0
11/02/2013 16:18:08;0040;PBS_Server;Svr;tyrone-cluster;Scheduler was sent the command new
11/02/2013 16:18:43;0040;PBS_Server;Svr;tyrone-cluster;Scheduler was sent the command new
11/02/2013 16:19:13;0040;PBS_Server;Svr;tyrone-cluster;Scheduler was sent the command new
11/02/2013 16:19:46;0040;PBS_Server;Svr;tyrone-cluster;Scheduler was sent the command new
11/02/2013 16:20:16;0040;PBS_Server;Svr;tyrone-cluster;Scheduler was sent the command new
11/02/2013 16:20:50;0040;PBS_Server;Svr;tyrone-cluster;Scheduler was sent the command new
11/02/2013 16:21:16;0040;PBS_Server;Svr;tyrone-cluster;Scheduler was sent the command new
11/02/2013 16:21:24;0100;PBS_Server;Job;31419.tyrone-cluster;enqueuing into batch, state 1 hop 1
11/02/2013 16:21:24;0100;PBS_Server;Job;31419.tyrone-cluster;dequeuing from batch, state QUEUED
11/02/2013 16:21:24;0100;PBS_Server;Job;31419.tyrone-cluster;enqueuing into qp256, state 1 hop 1
11/02/2013 16:21:24;0008;PBS_Server;Job;31419.tyrone-cluster;Job Queued at request of secbadar@tyrone-cluster, owner = secbadar@tyrone-cluster, job name = Unif05Sch, queue = qp256
11/02/2013 16:21:24;0040;PBS_Server;Svr;tyrone-cluster;Scheduler was sent the command new
11/02/2013 16:21:29;0008;PBS_Server;Job;31419.tyrone-cluster;Job Modified at request of Scheduler@tyrone-cluster
11/02/2013 16:21:29;0008;PBS_Server;Job;31419.tyrone-cluster;Job Run at request of Scheduler@tyrone-cluster
11/02/2013 16:21:29;0040;PBS_Server;Svr;tyrone-cluster;Scheduler was sent the command recyc
11/02/2013 16:21:47;0040;PBS_Server;Svr;tyrone-cluster;Scheduler was sent the command new
11/02/2013 16:22:05;0100;PBS_Server;Job;31420.tyrone-cluster;enqueuing into batch, state 1 hop 1
11/02/2013 16:22:05;0100;PBS_Server;Job;31420.tyrone-cluster;dequeuing from batch, state QUEUED
11/02/2013 16:22:05;0100;PBS_Server;Job;31420.tyrone-cluster;enqueuing into qp256, state 1 hop 1
11/02/2013 16:22:05;0008;PBS_Server;Job;31420.tyrone-cluster;Job Queued at request of secbadar@tyrone-cluster, owner = secbadar@tyrone-cluster, job name = Unif05Ser, queue = qp256
11/02/2013 16:22:05;0040;PBS_Server;Svr;tyrone-cluster;Scheduler was sent the command new
11/02/2013 16:22:05;0008;PBS_Server;Job;31420.tyrone-cluster;Job Modified at request of Scheduler@tyrone-cluster
11/02/2013 16:22:20;0040;PBS_Server;Svr;tyrone-cluster;Scheduler was sent the command new
11/02/2013 16:22:29;000d;PBS_Server;Job;31419.tyrone-cluster;Not sending email: User does not want mail of this type.
11/02/2013 16:22:42;0002;PBS_Server;Svr;PBS_Server;Torque Server Version = 3.0.5, loglevel = 0
11/02/2013 16:22:46;0040;PBS_Server;Svr;tyrone-cluster;Scheduler was sent the command new
11/02/2013 16:22:56;0100;PBS_Server;Job;31421.tyrone-cluster;enqueuing into batch, state 1 hop 1
11/02/2013 16:22:56;0008;PBS_Server;Job;31421.tyrone-cluster;Job Queued at request of secbadar@tyrone-cluster, owner = secbadar@tyrone-cluster, job name = Unif04Ser, queue = batch
11/02/2013 16:22:56;0040;PBS_Server;Svr;tyrone-cluster;Scheduler was sent the command new
11/02/2013 16:23:00;0008;PBS_Server;Job;31421.tyrone-cluster;Job Modified at request of Scheduler@tyrone-cluster
11/02/2013 16:23:08;0001;PBS_Server;Svr;PBS_Server;LOG_ERROR::stream_eof, connection to tyrone-node4 is no longer valid, connection may have been closed remotely, remote service may be down, or message may be corrupt (End of File).  setting node state to down
11/02/2013 16:23:17;0040;PBS_Server;Svr;tyrone-cluster;Scheduler was sent the command new
11/02/2013 16:23:25;0008;PBS_Server;Job;31419.tyrone-cluster;Job deleted at request of secbadar@tyrone-cluster
11/02/2013 16:23:25;0008;PBS_Server;Job;31419.tyrone-cluster;Job sent signal SIGTERM on delete
11/02/2013 16:23:25;000d;PBS_Server;Job;31419.tyrone-cluster;Not sending email: User does not want mail of this type.
11/02/2013 16:23:25;0010;PBS_Server;Job;31419.tyrone-cluster;Exit_status=143 resources_used.cput=00:09:37 resources_used.mem=1532328kb resources_used.vmem=36878368kb resources_used.walltime=00:01:56
11/02/2013 16:23:25;0008;PBS_Server;Job;NULL;on_job_exit valid pjob: 0x2ed2ba0 (substate=50)
11/02/2013 16:23:25;0008;PBS_Server;Job;NULL;on_job_exit valid pjob: 0x2ed2ba0 (substate=51)
11/02/2013 16:23:25;0008;PBS_Server;Job;NULL;on_job_exit valid pjob: 0x2ed2ba0 (substate=51)
11/02/2013 16:23:25;0008;PBS_Server;Job;NULL;on_job_exit valid pjob: 0x2ed2ba0 (substate=53)
11/02/2013 16:23:25;0100;PBS_Server;Job;31419.tyrone-cluster;dequeuing from qp256, state COMPLETE
11/02/2013 16:23:25;0040;PBS_Server;Svr;tyrone-cluster;Scheduler was sent the command term
11/02/2013 16:23:25;0008;PBS_Server;Job;31420.tyrone-cluster;Job Modified at request of Scheduler@tyrone-cluster
11/02/2013 16:23:25;0008;PBS_Server;Job;31420.tyrone-cluster;Job Run at request of Scheduler@tyrone-cluster
11/02/2013 16:23:26;0100;PBS_Server;Job;31421.tyrone-cluster;dequeuing from batch, state QUEUED
11/02/2013 16:23:26;0100;PBS_Server;Job;31421.tyrone-cluster;enqueuing into qp256, state 1 hop 1
11/02/2013 16:23:26;0040;PBS_Server;Svr;tyrone-cluster;Scheduler was sent the command recyc
11/02/2013 16:23:27;000d;PBS_Server;Job;31420.tyrone-cluster;Not sending email: User does not want mail of this type.
11/02/2013 16:23:27;0010;PBS_Server;Job;31420.tyrone-cluster;Exit_status=255 resources_used.cput=00:00:00 resources_used.mem=804kb resources_used.vmem=13624kb resources_used.walltime=00:00:01
11/02/2013 16:23:27;0008;PBS_Server;Job;NULL;on_job_exit valid pjob: 0x2e60d70 (substate=50)
11/02/2013 16:23:27;0008;PBS_Server;Job;NULL;on_job_exit valid pjob: 0x2e60d70 (substate=51)
11/02/2013 16:23:27;0008;PBS_Server;Job;NULL;on_job_exit valid pjob: 0x2e60d70 (substate=51)
11/02/2013 16:23:27;0008;PBS_Server;Job;NULL;on_job_exit valid pjob: 0x2e60d70 (substate=53)
11/02/2013 16:23:27;0100;PBS_Server;Job;31420.tyrone-cluster;dequeuing from qp256, state COMPLETE
11/02/2013 16:23:27;0040;PBS_Server;Svr;tyrone-cluster;Scheduler was sent the command term
11/02/2013 16:23:27;0008;PBS_Server;Job;31421.tyrone-cluster;Job Modified at request of Scheduler@tyrone-cluster
11/02/2013 16:23:27;0008;PBS_Server;Job;31421.tyrone-cluster;Job Run at request of Scheduler@tyrone-cluster
11/02/2013 16:23:27;0040;PBS_Server;Svr;tyrone-cluster;Scheduler was sent the command recyc
11/02/2013 16:23:29;000d;PBS_Server;Job;31421.tyrone-cluster;Not sending email: User does not want mail of this type.
11/02/2013 16:23:29;0010;PBS_Server;Job;31421.tyrone-cluster;Exit_status=0 resources_used.cput=00:00:00 resources_used.mem=800kb resources_used.vmem=13624kb resources_used.walltime=00:00:01
11/02/2013 16:23:29;0008;PBS_Server;Job;NULL;on_job_exit valid pjob: 0x2ef8580 (substate=50)
11/02/2013 16:23:29;0008;PBS_Server;Job;NULL;on_job_exit valid pjob: 0x2ef8580 (substate=51)
11/02/2013 16:23:29;0008;PBS_Server;Job;NULL;on_job_exit valid pjob: 0x2ef8580 (substate=51)
11/02/2013 16:23:29;0008;PBS_Server;Job;NULL;on_job_exit valid pjob: 0x2ef8580 (substate=53)
11/02/2013 16:23:29;0100;PBS_Server;Job;31421.tyrone-cluster;dequeuing from qp256, state COMPLETE
11/02/2013 16:23:29;0040;PBS_Server;Svr;tyrone-cluster;Scheduler was sent the command term
11/02/2013 16:23:32;0100;PBS_Server;Job;31422.tyrone-cluster;enqueuing into batch, state 1 hop 1
11/02/2013 16:23:32;0100;PBS_Server;Job;31422.tyrone-cluster;dequeuing from batch, state QUEUED
11/02/2013 16:23:32;0100;PBS_Server;Job;31422.tyrone-cluster;enqueuing into qp256, state 1 hop 1
11/02/2013 16:23:32;0008;PBS_Server;Job;31422.tyrone-cluster;Job Queued at request of secbadar@tyrone-cluster, owner = secbadar@tyrone-cluster, job name = Unif06Ser, queue = qp256
11/02/2013 16:23:33;0008;PBS_Server;Job;31422.tyrone-cluster;Job Modified at request of Scheduler@tyrone-cluster
11/02/2013 16:23:33;0008;PBS_Server;Job;31422.tyrone-cluster;Job Run at request of Scheduler@tyrone-cluster
11/02/2013 16:23:34;0040;PBS_Server;Svr;tyrone-cluster;Scheduler was sent the command recyc
11/02/2013 16:23:46;0040;PBS_Server;Svr;tyrone-cluster;Scheduler was sent the command new
11/02/2013 16:24:05;000d;PBS_Server;Job;31422.tyrone-cluster;Not sending email: User does not want mail of this type.
11/02/2013 16:24:16;0040;PBS_Server;Svr;tyrone-cluster;Scheduler was sent the command new
11/02/2013 16:24:47;0040;PBS_Server;Svr;tyrone-cluster;Scheduler was sent the command new
11/02/2013 16:25:19;0040;PBS_Server;Svr;tyrone-cluster;Scheduler was sent the command new
11/02/2013 16:25:19;0100;PBS_Server;Job;31423.tyrone-cluster;enqueuing into batch, state 1 hop 1
11/02/2013 16:25:19;0100;PBS_Server;Job;31423.tyrone-cluster;dequeuing from batch, state QUEUED
11/02/2013 16:25:19;0100;PBS_Server;Job;31423.tyrone-cluster;enqueuing into qp256, state 1 hop 1
11/02/2013 16:25:19;0008;PBS_Server;Job;31423.tyrone-cluster;Job Queued at request of secbadar@tyrone-cluster, owner = secbadar@tyrone-cluster, job name = Unif05Ser, queue = qp256
11/02/2013 16:25:19;0008;PBS_Server;Job;31423.tyrone-cluster;Job Modified at request of Scheduler@tyrone-cluster
11/02/2013 16:25:46;0040;PBS_Server;Svr;tyrone-cluster;Scheduler was sent the command new
11/02/2013 16:26:17;0040;PBS_Server;Svr;tyrone-cluster;Scheduler was sent the command new
11/02/2013 16:26:50;0040;PBS_Server;Svr;tyrone-cluster;Scheduler was sent the command new
11/02/2013 16:27:16;0040;PBS_Server;Svr;tyrone-cluster;Scheduler was sent the command new
11/02/2013 16:27:42;0002;PBS_Server;Svr;PBS_Server;Torque Server Version = 3.0.5, loglevel = 0
11/02/2013 16:27:47;0040;PBS_Server;Svr;tyrone-cluster;Scheduler was sent the command new
11/02/2013 16:28:20;0040;PBS_Server;Svr;tyrone-cluster;Scheduler was sent the command new
11/02/2013 16:28:46;0040;PBS_Server;Svr;tyrone-cluster;Scheduler was sent the command new
11/02/2013 16:29:17;0040;PBS_Server;Svr;tyrone-cluster;Scheduler was sent the command new
11/02/2013 16:29:50;0040;PBS_Server;Svr;tyrone-cluster;Scheduler was sent the command new
11/02/2013 16:30:16;0040;PBS_Server;Svr;tyrone-cluster;Scheduler was sent the command new
11/02/2013 16:30:47;0040;PBS_Server;Svr;tyrone-cluster;Scheduler was sent the command new
11/02/2013 16:31:20;0040;PBS_Server;Svr;tyrone-cluster;Scheduler was sent the command new
11/02/2013 16:31:46;0040;PBS_Server;Svr;tyrone-cluster;Scheduler was sent the command new
11/02/2013 16:32:17;0040;PBS_Server;Svr;tyrone-cluster;Scheduler was sent the command new
11/02/2013 16:32:42;0002;PBS_Server;Svr;PBS_Server;Torque Server Version = 3.0.5, loglevel = 0
11/02/2013 16:32:50;0040;PBS_Server;Svr;tyrone-cluster;Scheduler was sent the command new
11/02/2013 16:33:16;0040;PBS_Server;Svr;tyrone-cluster;Scheduler was sent the command new
11/02/2013 16:33:47;0040;PBS_Server;Svr;tyrone-cluster;Scheduler was sent the command new
11/02/2013 16:34:20;0040;PBS_Server;Svr;tyrone-cluster;Scheduler was sent the command new
11/02/2013 16:34:46;0040;PBS_Server;Svr;tyrone-cluster;Scheduler was sent the command new
11/02/2013 16:35:17;0040;PBS_Server;Svr;tyrone-cluster;Scheduler was sent the command new
11/02/2013 16:35:52;0040;PBS_Server;Svr;tyrone-cluster;Scheduler was sent the command new
11/02/2013 16:36:19;0040;PBS_Server;Svr;tyrone-cluster;Scheduler was sent the command new
11/02/2013 16:36:49;0040;PBS_Server;Svr;tyrone-cluster;Scheduler was sent the command new
11/02/2013 16:37:22;0040;PBS_Server;Svr;tyrone-cluster;Scheduler was sent the command new
11/02/2013 16:37:42;0002;PBS_Server;Svr;PBS_Server;Torque Server Version = 3.0.5, loglevel = 0
11/02/2013 16:37:50;0040;PBS_Server;Svr;tyrone-cluster;Scheduler was sent the command new
11/02/2013 16:38:20;0040;PBS_Server;Svr;tyrone-cluster;Scheduler was sent the command new
11/02/2013 16:38:52;0040;PBS_Server;Svr;tyrone-cluster;Scheduler was sent the command new
11/02/2013 16:39:20;0040;PBS_Server;Svr;tyrone-cluster;Scheduler was sent the command new
11/02/2013 16:39:50;0040;PBS_Server;Svr;tyrone-cluster;Scheduler was sent the command new
11/02/2013 16:40:22;0040;PBS_Server;Svr;tyrone-cluster;Scheduler was sent the command new
11/02/2013 16:40:54;0040;PBS_Server;Svr;tyrone-cluster;Scheduler was sent the command new
11/02/2013 16:41:23;0040;PBS_Server;Svr;tyrone-cluster;Scheduler was sent the command new
11/02/2013 16:41:58;0040;PBS_Server;Svr;tyrone-cluster;Scheduler was sent the command new
11/02/2013 16:42:29;0040;PBS_Server;Svr;tyrone-cluster;Scheduler was sent the command new
11/02/2013 16:42:42;0002;PBS_Server;Svr;PBS_Server;Torque Server Version = 3.0.5, loglevel = 0
11/02/2013 16:43:01;0040;PBS_Server;Svr;tyrone-cluster;Scheduler was sent the command new
11/02/2013 16:43:31;0040;PBS_Server;Svr;tyrone-cluster;Scheduler was sent the command new
11/02/2013 16:44:05;0040;PBS_Server;Svr;tyrone-cluster;Scheduler was sent the command new
11/02/2013 16:44:31;0040;PBS_Server;Svr;tyrone-cluster;Scheduler was sent the command new
11/02/2013 16:45:02;0040;PBS_Server;Svr;tyrone-cluster;Scheduler was sent the command new
11/02/2013 16:45:09;000d;PBS_Server;Job;31422.tyrone-cluster;Not sending email: User does not want mail of this type.
11/02/2013 16:45:09;0010;PBS_Server;Job;31422.tyrone-cluster;Exit_status=0 resources_used.cput=00:21:33 resources_used.mem=1297020kb resources_used.vmem=1577192kb resources_used.walltime=00:21:35
11/02/2013 16:45:09;0008;PBS_Server;Job;NULL;on_job_exit valid pjob: 0x2ef8580 (substate=50)
11/02/2013 16:45:09;0008;PBS_Server;Job;NULL;on_job_exit valid pjob: 0x2ef8580 (substate=51)
11/02/2013 16:45:09;0008;PBS_Server;Job;NULL;on_job_exit valid pjob: 0x2ef8580 (substate=51)
11/02/2013 16:45:09;0008;PBS_Server;Job;NULL;on_job_exit valid pjob: 0x2ef8580 (substate=53)
11/02/2013 16:45:09;0100;PBS_Server;Job;31422.tyrone-cluster;dequeuing from qp256, state COMPLETE
11/02/2013 16:45:09;0040;PBS_Server;Svr;tyrone-cluster;Scheduler was sent the command term
11/02/2013 16:45:09;0008;PBS_Server;Job;31423.tyrone-cluster;Job Modified at request of Scheduler@tyrone-cluster
11/02/2013 16:45:09;0008;PBS_Server;Job;31423.tyrone-cluster;Job Run at request of Scheduler@tyrone-cluster
11/02/2013 16:45:09;0040;PBS_Server;Svr;tyrone-cluster;Scheduler was sent the command recyc
11/02/2013 16:45:32;0040;PBS_Server;Svr;tyrone-cluster;Scheduler was sent the command new
11/02/2013 16:45:32;000d;PBS_Server;Job;31423.tyrone-cluster;Not sending email: User does not want mail of this type.
11/02/2013 16:45:32;0010;PBS_Server;Job;31423.tyrone-cluster;Exit_status=0 resources_used.cput=00:00:21 resources_used.mem=115956kb resources_used.vmem=393140kb resources_used.walltime=00:00:22
11/02/2013 16:45:32;0008;PBS_Server;Job;NULL;on_job_exit valid pjob: 0x31714a0 (substate=50)
11/02/2013 16:45:32;0008;PBS_Server;Job;NULL;on_job_exit valid pjob: 0x31714a0 (substate=51)
11/02/2013 16:45:32;0008;PBS_Server;Job;NULL;on_job_exit valid pjob: 0x31714a0 (substate=51)
11/02/2013 16:45:32;0008;PBS_Server;Job;NULL;on_job_exit valid pjob: 0x31714a0 (substate=53)
11/02/2013 16:45:32;0100;PBS_Server;Job;31423.tyrone-cluster;dequeuing from qp256, state COMPLETE
11/02/2013 16:45:32;0040;PBS_Server;Svr;tyrone-cluster;Scheduler was sent the command term
11/02/2013 16:46:01;0040;PBS_Server;Svr;tyrone-cluster;Scheduler was sent the command new
11/02/2013 16:46:32;0040;PBS_Server;Svr;tyrone-cluster;Scheduler was sent the command new
11/02/2013 16:47:05;0040;PBS_Server;Svr;tyrone-cluster;Scheduler was sent the command new
11/02/2013 16:47:31;0040;PBS_Server;Svr;tyrone-cluster;Scheduler was sent the command new
11/02/2013 16:47:42;0002;PBS_Server;Svr;PBS_Server;Torque Server Version = 3.0.5, loglevel = 0
11/02/2013 16:48:02;0040;PBS_Server;Svr;tyrone-cluster;Scheduler was sent the command new
11/02/2013 16:48:37;0040;PBS_Server;Svr;tyrone-cluster;Scheduler was sent the command new
11/02/2013 16:49:04;0040;PBS_Server;Svr;tyrone-cluster;Scheduler was sent the command new
11/02/2013 16:49:34;0040;PBS_Server;Svr;tyrone-cluster;Scheduler was sent the command new
11/02/2013 16:50:07;0040;PBS_Server;Svr;tyrone-cluster;Scheduler was sent the command new
11/02/2013 16:50:35;0040;PBS_Server;Svr;tyrone-cluster;Scheduler was sent the command new
11/02/2013 16:51:07;0040;PBS_Server;Svr;tyrone-cluster;Scheduler was sent the command new
11/02/2013 16:51:17;000d;PBS_Server;Job;31347.tyrone-cluster;Not sending email: User does not want mail of this type.
11/02/2013 16:51:17;0010;PBS_Server;Job;31347.tyrone-cluster;Exit_status=0 resources_used.cput=1125:01:36 resources_used.mem=1382648kb resources_used.vmem=35056628kb resources_used.walltime=17:35:13
11/02/2013 16:51:17;0008;PBS_Server;Job;NULL;on_job_exit valid pjob: 0x2f687c0 (substate=50)
11/02/2013 16:51:17;0008;PBS_Server;Job;NULL;on_job_exit valid pjob: 0x2f687c0 (substate=51)
11/02/2013 16:51:22;0008;PBS_Server;Job;NULL;on_job_exit valid pjob: 0x2f687c0 (substate=51)
11/02/2013 16:51:22;000d;PBS_Server;Job;31347.tyrone-cluster;Post job file processing error; job 31347.tyrone-cluster on host tyrone-node10/63+tyrone-node10/62+tyrone-node10/61+tyrone-node10/60+tyrone-node10/59+tyrone-node10/58+tyrone-node10/57+tyrone-node10/56+tyrone-node10/55+tyrone-node10/54+tyrone-node10/53+tyrone-node10/52+tyrone-node10/51+tyrone-node10/50+tyrone-node10/49+tyrone-node10/48+tyrone-node10/47+tyrone-node10/46+tyrone-node10/45+tyrone-node10/44+tyrone-node10/43+tyrone-node10/42+tyrone-node10/41+tyrone-node10/40+tyrone-node10/39+tyrone-node10/38+tyrone-node10/37+tyrone-node10/36+tyrone-node10/35+tyrone-node10/34+tyrone-node10/33+tyrone-node10/32+tyrone-node10/31+tyrone-node10/30+tyrone-node10/29+tyrone-node10/28+tyrone-node10/27+tyrone-node10/26+tyrone-node10/25+tyrone-node10/24+tyrone-node10/23+tyrone-node10/22+tyrone-node10/21+tyrone-node10/20+tyrone-node10/19+tyrone-node10/18+tyrone-node10/17+tyrone-node10/16+tyrone-node10/15+tyrone-node10/14+tyrone-node10/13+tyrone-node10/12+tyrone-node10/11+tyrone-node10/10+tyrone-node10/9+tyrone-node10/8+tyrone-node10/7+tyrone-node10/6+tyrone-node10/5+tyrone-node10/4+tyrone-node10/3+tyrone-node10/2+tyrone-node10/1+tyrone-node10/0
11/02/2013 16:51:22;0008;PBS_Server;Job;NULL;on_job_exit valid pjob: 0x2f687c0 (substate=53)
11/02/2013 16:51:22;0100;PBS_Server;Job;31347.tyrone-cluster;dequeuing from qp64, state COMPLETE
11/02/2013 16:51:22;0040;PBS_Server;Svr;tyrone-cluster;Scheduler was sent the command term
11/02/2013 16:51:26;0008;PBS_Server;Job;31233.tyrone-cluster;Job Modified at request of Scheduler@tyrone-cluster
11/02/2013 16:51:26;0008;PBS_Server;Job;31348.tyrone-cluster;Job Modified at request of Scheduler@tyrone-cluster
11/02/2013 16:51:26;0008;PBS_Server;Job;31348.tyrone-cluster;Job Run at request of Scheduler@tyrone-cluster
11/02/2013 16:51:26;0040;PBS_Server;Svr;tyrone-cluster;Scheduler was sent the command recyc
11/02/2013 16:51:26;000d;PBS_Server;Job;31348.tyrone-cluster;Not sending email: User does not want mail of this type.
11/02/2013 16:51:35;0100;PBS_Server;Job;31350.tyrone-cluster;dequeuing from batch, state QUEUED
11/02/2013 16:51:35;0100;PBS_Server;Job;31350.tyrone-cluster;enqueuing into qp64, state 1 hop 1
11/02/2013 16:51:43;0040;PBS_Server;Svr;tyrone-cluster;Scheduler was sent the command new
11/02/2013 16:51:43;0008;PBS_Server;Job;31233.tyrone-cluster;Job Modified at request of Scheduler@tyrone-cluster
11/02/2013 16:51:43;0008;PBS_Server;Job;31350.tyrone-cluster;Job Modified at request of Scheduler@tyrone-cluster
11/02/2013 16:52:05;0040;PBS_Server;Svr;tyrone-cluster;Scheduler was sent the command new
11/02/2013 16:52:37;0040;PBS_Server;Svr;tyrone-cluster;Scheduler was sent the command new
11/02/2013 16:52:42;0002;PBS_Server;Svr;PBS_Server;Torque Server Version = 3.0.5, loglevel = 0
11/02/2013 16:53:09;0040;PBS_Server;Svr;tyrone-cluster;Scheduler was sent the command new
11/02/2013 16:53:35;0040;PBS_Server;Svr;tyrone-cluster;Scheduler was sent the command new
11/02/2013 16:54:06;0040;PBS_Server;Svr;tyrone-cluster;Scheduler was sent the command new
11/02/2013 16:54:39;0040;PBS_Server;Svr;tyrone-cluster;Scheduler was sent the command new
11/02/2013 16:55:11;0040;PBS_Server;Svr;tyrone-cluster;Scheduler was sent the command new
11/02/2013 16:55:42;0040;PBS_Server;Svr;tyrone-cluster;Scheduler was sent the command new
11/02/2013 16:56:13;0040;PBS_Server;Svr;tyrone-cluster;Scheduler was sent the command new
11/02/2013 16:56:43;0040;PBS_Server;Svr;tyrone-cluster;Scheduler was sent the command new
11/02/2013 16:57:16;0040;PBS_Server;Svr;tyrone-cluster;Scheduler was sent the command new
11/02/2013 16:57:42;0002;PBS_Server;Svr;PBS_Server;Torque Server Version = 3.0.5, loglevel = 0
11/02/2013 16:57:46;0040;PBS_Server;Svr;tyrone-cluster;Scheduler was sent the command new
11/02/2013 16:58:20;0040;PBS_Server;Svr;tyrone-cluster;Scheduler was sent the command new
11/02/2013 16:58:46;0040;PBS_Server;Svr;tyrone-cluster;Scheduler was sent the command new
11/02/2013 16:59:17;0040;PBS_Server;Svr;tyrone-cluster;Scheduler was sent the command new
11/02/2013 16:59:54;0040;PBS_Server;Svr;tyrone-cluster;Scheduler was sent the command new
11/02/2013 17:00:19;0040;PBS_Server;Svr;tyrone-cluster;Scheduler was sent the command new
11/02/2013 17:00:49;0040;PBS_Server;Svr;tyrone-cluster;Scheduler was sent the command new
11/02/2013 17:01:24;0040;PBS_Server;Svr;tyrone-cluster;Scheduler was sent the command new
11/02/2013 17:01:50;0040;PBS_Server;Svr;tyrone-cluster;Scheduler was sent the command new
11/02/2013 17:02:21;0040;PBS_Server;Svr;tyrone-cluster;Scheduler was sent the command new
11/02/2013 17:02:42;0002;PBS_Server;Svr;PBS_Server;Torque Server Version = 3.0.5, loglevel = 0
11/02/2013 17:02:54;0040;PBS_Server;Svr;tyrone-cluster;Scheduler was sent the command new
11/02/2013 17:03:26;0040;PBS_Server;Svr;tyrone-cluster;Scheduler was sent the command new
11/02/2013 17:03:57;0040;PBS_Server;Svr;tyrone-cluster;Scheduler was sent the command new
11/02/2013 17:04:28;0040;PBS_Server;Svr;tyrone-cluster;Scheduler was sent the command new
11/02/2013 17:04:58;0040;PBS_Server;Svr;tyrone-cluster;Scheduler was sent the command new
11/02/2013 17:05:31;0040;PBS_Server;Svr;tyrone-cluster;Scheduler was sent the command new
11/02/2013 17:06:01;0040;PBS_Server;Svr;tyrone-cluster;Scheduler was sent the command new
11/02/2013 17:06:35;0040;PBS_Server;Svr;tyrone-cluster;Scheduler was sent the command new
11/02/2013 17:07:01;0040;PBS_Server;Svr;tyrone-cluster;Scheduler was sent the command new
11/02/2013 17:07:31;0040;PBS_Server;Svr;tyrone-cluster;Scheduler was sent the command new
11/02/2013 17:07:42;0002;PBS_Server;Svr;PBS_Server;Torque Server Version = 3.0.5, loglevel = 0
11/02/2013 17:08:04;0040;PBS_Server;Svr;tyrone-cluster;Scheduler was sent the command new
11/02/2013 17:08:31;0040;PBS_Server;Svr;tyrone-cluster;Scheduler was sent the command new
11/02/2013 17:09:02;0040;PBS_Server;Svr;tyrone-cluster;Scheduler was sent the command new
11/02/2013 17:09:38;0040;PBS_Server;Svr;tyrone-cluster;Scheduler was sent the command new
11/02/2013 17:10:04;0040;PBS_Server;Svr;tyrone-cluster;Scheduler was sent the command new
11/02/2013 17:10:34;0040;PBS_Server;Svr;tyrone-cluster;Scheduler was sent the command new
11/02/2013 17:11:09;0040;PBS_Server;Svr;tyrone-cluster;Scheduler was sent the command new
11/02/2013 17:11:34;0040;PBS_Server;Svr;tyrone-cluster;Scheduler was sent the command new
11/02/2013 17:12:04;0040;PBS_Server;Svr;tyrone-cluster;Scheduler was sent the command new
11/02/2013 17:12:39;0040;PBS_Server;Svr;tyrone-cluster;Scheduler was sent the command new
11/02/2013 17:12:42;0002;PBS_Server;Svr;PBS_Server;Torque Server Version = 3.0.5, loglevel = 0
11/02/2013 17:13:04;0040;PBS_Server;Svr;tyrone-cluster;Scheduler was sent the command new
11/02/2013 17:13:34;0040;PBS_Server;Svr;tyrone-cluster;Scheduler was sent the command new
11/02/2013 17:14:09;0040;PBS_Server;Svr;tyrone-cluster;Scheduler was sent the command new
11/02/2013 17:14:34;0040;PBS_Server;Svr;tyrone-cluster;Scheduler was sent the command new
11/02/2013 17:15:04;0040;PBS_Server;Svr;tyrone-cluster;Scheduler was sent the command new
11/02/2013 17:15:39;0040;PBS_Server;Svr;tyrone-cluster;Scheduler was sent the command new
11/02/2013 17:16:04;0040;PBS_Server;Svr;tyrone-cluster;Scheduler was sent the command new
11/02/2013 17:16:34;0040;PBS_Server;Svr;tyrone-cluster;Scheduler was sent the command new
11/02/2013 17:17:09;0040;PBS_Server;Svr;tyrone-cluster;Scheduler was sent the command new
11/02/2013 17:17:34;0040;PBS_Server;Svr;tyrone-cluster;Scheduler was sent the command new
11/02/2013 17:17:42;0002;PBS_Server;Svr;PBS_Server;Torque Server Version = 3.0.5, loglevel = 0
11/02/2013 17:18:04;0040;PBS_Server;Svr;tyrone-cluster;Scheduler was sent the command new
11/02/2013 17:18:39;0040;PBS_Server;Svr;tyrone-cluster;Scheduler was sent the command new
11/02/2013 17:19:05;0040;PBS_Server;Svr;tyrone-cluster;Scheduler was sent the command new
11/02/2013 17:19:37;0040;PBS_Server;Svr;tyrone-cluster;Scheduler was sent the command new
11/02/2013 17:20:09;0040;PBS_Server;Svr;tyrone-cluster;Scheduler was sent the command new
11/02/2013 17:20:41;0040;PBS_Server;Svr;tyrone-cluster;Scheduler was sent the command new
11/02/2013 17:21:11;0040;PBS_Server;Svr;tyrone-cluster;Scheduler was sent the command new
11/02/2013 17:21:43;0040;PBS_Server;Svr;tyrone-cluster;Scheduler was sent the command new
11/02/2013 17:22:15;0040;PBS_Server;Svr;tyrone-cluster;Scheduler was sent the command new
11/02/2013 17:22:42;0002;PBS_Server;Svr;PBS_Server;Torque Server Version = 3.0.5, loglevel = 0
11/02/2013 17:22:46;0040;PBS_Server;Svr;tyrone-cluster;Scheduler was sent the command new
11/02/2013 17:23:16;0040;PBS_Server;Svr;tyrone-cluster;Scheduler was sent the command new
11/02/2013 17:23:46;0040;PBS_Server;Svr;tyrone-cluster;Scheduler was sent the command new
11/02/2013 17:24:16;0040;PBS_Server;Svr;tyrone-cluster;Scheduler was sent the command new
11/02/2013 17:24:47;0040;PBS_Server;Svr;tyrone-cluster;Scheduler was sent the command new
11/02/2013 17:25:24;0040;PBS_Server;Svr;tyrone-cluster;Scheduler was sent the command new
11/02/2013 17:25:49;0040;PBS_Server;Svr;tyrone-cluster;Scheduler was sent the command new
11/02/2013 17:26:19;0040;PBS_Server;Svr;tyrone-cluster;Scheduler was sent the command new
11/02/2013 17:26:54;0040;PBS_Server;Svr;tyrone-cluster;Scheduler was sent the command new
11/02/2013 17:27:19;0040;PBS_Server;Svr;tyrone-cluster;Scheduler was sent the command new
11/02/2013 17:27:42;0002;PBS_Server;Svr;PBS_Server;Torque Server Version = 3.0.5, loglevel = 0
11/02/2013 17:27:49;0040;PBS_Server;Svr;tyrone-cluster;Scheduler was sent the command new
11/02/2013 17:28:20;0040;PBS_Server;Svr;tyrone-cluster;Scheduler was sent the command new
11/02/2013 17:28:53;0040;PBS_Server;Svr;tyrone-cluster;Scheduler was sent the command new
11/02/2013 17:29:22;0040;PBS_Server;Svr;tyrone-cluster;Scheduler was sent the command new
11/02/2013 17:29:54;0040;PBS_Server;Svr;tyrone-cluster;Scheduler was sent the command new
11/02/2013 17:30:26;0040;PBS_Server;Svr;tyrone-cluster;Scheduler was sent the command new
11/02/2013 17:30:56;0040;PBS_Server;Svr;tyrone-cluster;Scheduler was sent the command new
11/02/2013 17:31:28;0040;PBS_Server;Svr;tyrone-cluster;Scheduler was sent the command new
11/02/2013 17:32:04;0040;PBS_Server;Svr;tyrone-cluster;Scheduler was sent the command new
11/02/2013 17:32:31;0040;PBS_Server;Svr;tyrone-cluster;Scheduler was sent the command new
11/02/2013 17:32:42;0002;PBS_Server;Svr;PBS_Server;Torque Server Version = 3.0.5, loglevel = 0
11/02/2013 17:33:02;0040;PBS_Server;Svr;tyrone-cluster;Scheduler was sent the command new
11/02/2013 17:33:39;0040;PBS_Server;Svr;tyrone-cluster;Scheduler was sent the command new
11/02/2013 17:34:08;0040;PBS_Server;Svr;tyrone-cluster;Scheduler was sent the command new
11/02/2013 17:34:37;0040;PBS_Server;Svr;tyrone-cluster;Scheduler was sent the command new
11/02/2013 17:35:09;0040;PBS_Server;Svr;tyrone-cluster;Scheduler was sent the command new
11/02/2013 17:35:41;0040;PBS_Server;Svr;tyrone-cluster;Scheduler was sent the command new
11/02/2013 17:36:11;0040;PBS_Server;Svr;tyrone-cluster;Scheduler was sent the command new
11/02/2013 17:36:43;0040;PBS_Server;Svr;tyrone-cluster;Scheduler was sent the command new
11/02/2013 17:37:19;0040;PBS_Server;Svr;tyrone-cluster;Scheduler was sent the command new
11/02/2013 17:37:42;0002;PBS_Server;Svr;PBS_Server;Torque Server Version = 3.0.5, loglevel = 0
11/02/2013 17:37:46;0040;PBS_Server;Svr;tyrone-cluster;Scheduler was sent the command new
11/02/2013 17:38:17;0040;PBS_Server;Svr;tyrone-cluster;Scheduler was sent the command new
11/02/2013 17:38:49;0040;PBS_Server;Svr;tyrone-cluster;Scheduler was sent the command new
11/02/2013 17:39:16;0040;PBS_Server;Svr;tyrone-cluster;Scheduler was sent the command new
11/02/2013 17:39:47;0040;PBS_Server;Svr;tyrone-cluster;Scheduler was sent the command new
11/02/2013 17:40:24;0040;PBS_Server;Svr;tyrone-cluster;Scheduler was sent the command new
11/02/2013 17:40:49;0040;PBS_Server;Svr;tyrone-cluster;Scheduler was sent the command new
11/02/2013 17:41:19;0040;PBS_Server;Svr;tyrone-cluster;Scheduler was sent the command new
11/02/2013 17:41:54;0040;PBS_Server;Svr;tyrone-cluster;Scheduler was sent the command new
11/02/2013 17:42:19;0040;PBS_Server;Svr;tyrone-cluster;Scheduler was sent the command new
11/02/2013 17:42:42;0002;PBS_Server;Svr;PBS_Server;Torque Server Version = 3.0.5, loglevel = 0
11/02/2013 17:42:49;0040;PBS_Server;Svr;tyrone-cluster;Scheduler was sent the command new
11/02/2013 17:43:24;0040;PBS_Server;Svr;tyrone-cluster;Scheduler was sent the command new
11/02/2013 17:43:49;0040;PBS_Server;Svr;tyrone-cluster;Scheduler was sent the command new
11/02/2013 17:44:19;0040;PBS_Server;Svr;tyrone-cluster;Scheduler was sent the command new
11/02/2013 17:44:54;0040;PBS_Server;Svr;tyrone-cluster;Scheduler was sent the command new
11/02/2013 17:45:26;0040;PBS_Server;Svr;tyrone-cluster;Scheduler was sent the command new
11/02/2013 17:45:56;0040;PBS_Server;Svr;tyrone-cluster;Scheduler was sent the command new
11/02/2013 17:46:24;0040;PBS_Server;Svr;tyrone-cluster;Scheduler was sent the command new
11/02/2013 17:46:56;0040;PBS_Server;Svr;tyrone-cluster;Scheduler was sent the command new
11/02/2013 17:47:31;0040;PBS_Server;Svr;tyrone-cluster;Scheduler was sent the command new
11/02/2013 17:47:42;0002;PBS_Server;Svr;PBS_Server;Torque Server Version = 3.0.5, loglevel = 0
11/02/2013 17:48:02;0040;PBS_Server;Svr;tyrone-cluster;Scheduler was sent the command new
11/02/2013 17:48:39;0040;PBS_Server;Svr;tyrone-cluster;Scheduler was sent the command new
11/02/2013 17:49:04;0040;PBS_Server;Svr;tyrone-cluster;Scheduler was sent the command new
11/02/2013 17:49:34;0040;PBS_Server;Svr;tyrone-cluster;Scheduler was sent the command new
11/02/2013 17:50:09;0040;PBS_Server;Svr;tyrone-cluster;Scheduler was sent the command new
11/02/2013 17:50:34;0040;PBS_Server;Svr;tyrone-cluster;Scheduler was sent the command new
11/02/2013 17:51:04;0040;PBS_Server;Svr;tyrone-cluster;Scheduler was sent the command new
11/02/2013 17:51:39;0040;PBS_Server;Svr;tyrone-cluster;Scheduler was sent the command new
11/02/2013 17:52:11;0040;PBS_Server;Svr;tyrone-cluster;Scheduler was sent the command new
11/02/2013 17:52:41;0040;PBS_Server;Svr;tyrone-cluster;Scheduler was sent the command new
11/02/2013 17:52:42;0002;PBS_Server;Svr;PBS_Server;Torque Server Version = 3.0.5, loglevel = 0
11/02/2013 17:53:13;0040;PBS_Server;Svr;tyrone-cluster;Scheduler was sent the command new
11/02/2013 17:53:42;0040;PBS_Server;Svr;tyrone-cluster;Scheduler was sent the command new
11/02/2013 17:54:17;0040;PBS_Server;Svr;tyrone-cluster;Scheduler was sent the command new
11/02/2013 17:54:48;0040;PBS_Server;Svr;tyrone-cluster;Scheduler was sent the command new
11/02/2013 17:55:25;0040;PBS_Server;Svr;tyrone-cluster;Scheduler was sent the command new
11/02/2013 17:55:49;0040;PBS_Server;Svr;tyrone-cluster;Scheduler was sent the command new
11/02/2013 17:56:19;0040;PBS_Server;Svr;tyrone-cluster;Scheduler was sent the command new
11/02/2013 17:56:55;0040;PBS_Server;Svr;tyrone-cluster;Scheduler was sent the command new
11/02/2013 17:57:19;0040;PBS_Server;Svr;tyrone-cluster;Scheduler was sent the command new
11/02/2013 17:57:42;0002;PBS_Server;Svr;PBS_Server;Torque Server Version = 3.0.5, loglevel = 0
11/02/2013 17:57:49;0040;PBS_Server;Svr;tyrone-cluster;Scheduler was sent the command new
11/02/2013 17:58:25;0040;PBS_Server;Svr;tyrone-cluster;Scheduler was sent the command new
11/02/2013 17:58:57;0040;PBS_Server;Svr;tyrone-cluster;Scheduler was sent the command new
11/02/2013 17:59:32;0040;PBS_Server;Svr;tyrone-cluster;Scheduler was sent the command new
11/02/2013 18:00:03;0040;PBS_Server;Svr;tyrone-cluster;Scheduler was sent the command new
11/02/2013 18:00:40;0040;PBS_Server;Svr;tyrone-cluster;Scheduler was sent the command new
11/02/2013 18:01:04;0040;PBS_Server;Svr;tyrone-cluster;Scheduler was sent the command new
11/02/2013 18:01:34;0040;PBS_Server;Svr;tyrone-cluster;Scheduler was sent the command new
11/02/2013 18:02:10;0040;PBS_Server;Svr;tyrone-cluster;Scheduler was sent the command new
11/02/2013 18:02:34;0040;PBS_Server;Svr;tyrone-cluster;Scheduler was sent the command new
11/02/2013 18:02:42;0002;PBS_Server;Svr;PBS_Server;Torque Server Version = 3.0.5, loglevel = 0
11/02/2013 18:03:04;0040;PBS_Server;Svr;tyrone-cluster;Scheduler was sent the command new
11/02/2013 18:03:40;0040;PBS_Server;Svr;tyrone-cluster;Scheduler was sent the command new
11/02/2013 18:04:04;0040;PBS_Server;Svr;tyrone-cluster;Scheduler was sent the command new
11/02/2013 18:04:34;0040;PBS_Server;Svr;tyrone-cluster;Scheduler was sent the command new
11/02/2013 18:05:10;0040;PBS_Server;Svr;tyrone-cluster;Scheduler was sent the command new
11/02/2013 18:05:34;0040;PBS_Server;Svr;tyrone-cluster;Scheduler was sent the command new
11/02/2013 18:06:04;0040;PBS_Server;Svr;tyrone-cluster;Scheduler was sent the command new
11/02/2013 18:06:40;0040;PBS_Server;Svr;tyrone-cluster;Scheduler was sent the command new
11/02/2013 18:07:04;0040;PBS_Server;Svr;tyrone-cluster;Scheduler was sent the command new
11/02/2013 18:07:34;0040;PBS_Server;Svr;tyrone-cluster;Scheduler was sent the command new
11/02/2013 18:07:42;0002;PBS_Server;Svr;PBS_Server;Torque Server Version = 3.0.5, loglevel = 0
11/02/2013 18:08:10;0040;PBS_Server;Svr;tyrone-cluster;Scheduler was sent the command new
11/02/2013 18:08:34;0040;PBS_Server;Svr;tyrone-cluster;Scheduler was sent the command new
11/02/2013 18:09:04;0040;PBS_Server;Svr;tyrone-cluster;Scheduler was sent the command new
11/02/2013 18:09:40;0040;PBS_Server;Svr;tyrone-cluster;Scheduler was sent the command new
11/02/2013 18:10:12;0040;PBS_Server;Svr;tyrone-cluster;Scheduler was sent the command new
11/02/2013 18:10:45;0040;PBS_Server;Svr;tyrone-cluster;Scheduler was sent the command new
11/02/2013 18:11:14;0040;PBS_Server;Svr;tyrone-cluster;Scheduler was sent the command new
11/02/2013 18:11:48;0040;PBS_Server;Svr;tyrone-cluster;Scheduler was sent the command new
11/02/2013 18:12:16;0040;PBS_Server;Svr;tyrone-cluster;Scheduler was sent the command new
11/02/2013 18:12:42;0002;PBS_Server;Svr;PBS_Server;Torque Server Version = 3.0.5, loglevel = 0
11/02/2013 18:12:48;0040;PBS_Server;Svr;tyrone-cluster;Scheduler was sent the command new
11/02/2013 18:13:25;0040;PBS_Server;Svr;tyrone-cluster;Scheduler was sent the command new
11/02/2013 18:13:49;0040;PBS_Server;Svr;tyrone-cluster;Scheduler was sent the command new
11/02/2013 18:14:19;0040;PBS_Server;Svr;tyrone-cluster;Scheduler was sent the command new
11/02/2013 18:14:55;0040;PBS_Server;Svr;tyrone-cluster;Scheduler was sent the command new
11/02/2013 18:15:19;0040;PBS_Server;Svr;tyrone-cluster;Scheduler was sent the command new
11/02/2013 18:15:49;0040;PBS_Server;Svr;tyrone-cluster;Scheduler was sent the command new
11/02/2013 18:16:25;0040;PBS_Server;Svr;tyrone-cluster;Scheduler was sent the command new
11/02/2013 18:16:57;0040;PBS_Server;Svr;tyrone-cluster;Scheduler was sent the command new
11/02/2013 18:17:32;0040;PBS_Server;Svr;tyrone-cluster;Scheduler was sent the command new
11/02/2013 18:17:42;0002;PBS_Server;Svr;PBS_Server;Torque Server Version = 3.0.5, loglevel = 0
11/02/2013 18:18:03;0040;PBS_Server;Svr;tyrone-cluster;Scheduler was sent the command new
11/02/2013 18:18:41;0040;PBS_Server;Svr;tyrone-cluster;Scheduler was sent the command new
11/02/2013 18:19:04;0040;PBS_Server;Svr;tyrone-cluster;Scheduler was sent the command new
11/02/2013 18:19:34;0040;PBS_Server;Svr;tyrone-cluster;Scheduler was sent the command new
11/02/2013 18:20:10;0040;PBS_Server;Svr;tyrone-cluster;Scheduler was sent the command new
11/02/2013 18:20:34;0040;PBS_Server;Svr;tyrone-cluster;Scheduler was sent the command new
11/02/2013 18:21:04;0040;PBS_Server;Svr;tyrone-cluster;Scheduler was sent the command new
11/02/2013 18:21:40;0040;PBS_Server;Svr;tyrone-cluster;Scheduler was sent the command new
11/02/2013 18:22:05;0040;PBS_Server;Svr;tyrone-cluster;Scheduler was sent the command new
11/02/2013 18:22:34;0040;PBS_Server;Svr;tyrone-cluster;Scheduler was sent the command new
11/02/2013 18:22:42;0002;PBS_Server;Svr;PBS_Server;Torque Server Version = 3.0.5, loglevel = 0
11/02/2013 18:23:10;0040;PBS_Server;Svr;tyrone-cluster;Scheduler was sent the command new
11/02/2013 18:23:42;0040;PBS_Server;Svr;tyrone-cluster;Scheduler was sent the command new
11/02/2013 18:24:17;0040;PBS_Server;Svr;tyrone-cluster;Scheduler was sent the command new
11/02/2013 18:24:48;0040;PBS_Server;Svr;tyrone-cluster;Scheduler was sent the command new
11/02/2013 18:25:25;0040;PBS_Server;Svr;tyrone-cluster;Scheduler was sent the command new
11/02/2013 18:25:49;0040;PBS_Server;Svr;tyrone-cluster;Scheduler was sent the command new
11/02/2013 18:26:19;0040;PBS_Server;Svr;tyrone-cluster;Scheduler was sent the command new
11/02/2013 18:26:55;0040;PBS_Server;Svr;tyrone-cluster;Scheduler was sent the command new
11/02/2013 18:27:19;0040;PBS_Server;Svr;tyrone-cluster;Scheduler was sent the command new
11/02/2013 18:27:42;0002;PBS_Server;Svr;PBS_Server;Torque Server Version = 3.0.5, loglevel = 0
11/02/2013 18:27:49;0040;PBS_Server;Svr;tyrone-cluster;Scheduler was sent the command new
11/02/2013 18:28:25;0040;PBS_Server;Svr;tyrone-cluster;Scheduler was sent the command new
11/02/2013 18:28:50;0040;PBS_Server;Svr;tyrone-cluster;Scheduler was sent the command new
11/02/2013 18:29:20;0040;PBS_Server;Svr;tyrone-cluster;Scheduler was sent the command new
11/02/2013 18:29:55;0040;PBS_Server;Svr;tyrone-cluster;Scheduler was sent the command new
11/02/2013 18:30:27;0040;PBS_Server;Svr;tyrone-cluster;Scheduler was sent the command new
11/02/2013 18:31:02;0040;PBS_Server;Svr;tyrone-cluster;Scheduler was sent the command new
11/02/2013 18:31:33;0040;PBS_Server;Svr;tyrone-cluster;Scheduler was sent the command new
11/02/2013 18:32:10;0040;PBS_Server;Svr;tyrone-cluster;Scheduler was sent the command new
11/02/2013 18:32:34;0040;PBS_Server;Svr;tyrone-cluster;Scheduler was sent the command new
11/02/2013 18:32:42;0002;PBS_Server;Svr;PBS_Server;Torque Server Version = 3.0.5, loglevel = 0
11/02/2013 18:33:05;0040;PBS_Server;Svr;tyrone-cluster;Scheduler was sent the command new
11/02/2013 18:33:40;0040;PBS_Server;Svr;tyrone-cluster;Scheduler was sent the command new
11/02/2013 18:34:12;0040;PBS_Server;Svr;tyrone-cluster;Scheduler was sent the command new
11/02/2013 18:34:47;0040;PBS_Server;Svr;tyrone-cluster;Scheduler was sent the command new
11/02/2013 18:35:18;0040;PBS_Server;Svr;tyrone-cluster;Scheduler was sent the command new
11/02/2013 18:35:55;0040;PBS_Server;Svr;tyrone-cluster;Scheduler was sent the command new
11/02/2013 18:36:20;0040;PBS_Server;Svr;tyrone-cluster;Scheduler was sent the command new
11/02/2013 18:36:49;0040;PBS_Server;Svr;tyrone-cluster;Scheduler was sent the command new
11/02/2013 18:37:25;0040;PBS_Server;Svr;tyrone-cluster;Scheduler was sent the command new
11/02/2013 18:37:42;0002;PBS_Server;Svr;PBS_Server;Torque Server Version = 3.0.5, loglevel = 0
11/02/2013 18:37:57;0040;PBS_Server;Svr;tyrone-cluster;Scheduler was sent the command new
11/02/2013 18:38:30;0040;PBS_Server;Svr;tyrone-cluster;Scheduler was sent the command new
11/02/2013 18:38:59;0040;PBS_Server;Svr;tyrone-cluster;Scheduler was sent the command new
11/02/2013 18:39:31;0040;PBS_Server;Svr;tyrone-cluster;Scheduler was sent the command new
11/02/2013 18:40:02;0040;PBS_Server;Svr;tyrone-cluster;Scheduler was sent the command new
11/02/2013 18:40:33;0040;PBS_Server;Svr;tyrone-cluster;Scheduler was sent the command new
11/02/2013 18:41:10;0040;PBS_Server;Svr;tyrone-cluster;Scheduler was sent the command new
11/02/2013 18:41:34;0040;PBS_Server;Svr;tyrone-cluster;Scheduler was sent the command new
11/02/2013 18:42:04;0040;PBS_Server;Svr;tyrone-cluster;Scheduler was sent the command new
11/02/2013 18:42:40;0040;PBS_Server;Svr;tyrone-cluster;Scheduler was sent the command new
11/02/2013 18:42:42;0002;PBS_Server;Svr;PBS_Server;Torque Server Version = 3.0.5, loglevel = 0
11/02/2013 18:43:04;0040;PBS_Server;Svr;tyrone-cluster;Scheduler was sent the command new
11/02/2013 18:43:34;0040;PBS_Server;Svr;tyrone-cluster;Scheduler was sent the command new
11/02/2013 18:44:10;0040;PBS_Server;Svr;tyrone-cluster;Scheduler was sent the command new
11/02/2013 18:44:34;0040;PBS_Server;Svr;tyrone-cluster;Scheduler was sent the command new
11/02/2013 18:45:04;0040;PBS_Server;Svr;tyrone-cluster;Scheduler was sent the command new
11/02/2013 18:45:40;0040;PBS_Server;Svr;tyrone-cluster;Scheduler was sent the command new
11/02/2013 18:46:03;0040;PBS_Server;Svr;tyrone-cluster;Scheduler was sent the command new
11/02/2013 18:46:34;0040;PBS_Server;Svr;tyrone-cluster;Scheduler was sent the command new
11/02/2013 18:47:10;0040;PBS_Server;Svr;tyrone-cluster;Scheduler was sent the command new
11/02/2013 18:47:34;0040;PBS_Server;Svr;tyrone-cluster;Scheduler was sent the command new
11/02/2013 18:47:42;0002;PBS_Server;Svr;PBS_Server;Torque Server Version = 3.0.5, loglevel = 0
11/02/2013 18:48:04;0040;PBS_Server;Svr;tyrone-cluster;Scheduler was sent the command new
11/02/2013 18:48:40;0040;PBS_Server;Svr;tyrone-cluster;Scheduler was sent the command new
11/02/2013 18:49:12;0040;PBS_Server;Svr;tyrone-cluster;Scheduler was sent the command new
11/02/2013 18:49:47;0040;PBS_Server;Svr;tyrone-cluster;Scheduler was sent the command new
11/02/2013 18:50:18;0040;PBS_Server;Svr;tyrone-cluster;Scheduler was sent the command new
11/02/2013 18:50:55;0040;PBS_Server;Svr;tyrone-cluster;Scheduler was sent the command new
11/02/2013 18:51:19;0040;PBS_Server;Svr;tyrone-cluster;Scheduler was sent the command new
11/02/2013 18:51:48;0040;PBS_Server;Svr;tyrone-cluster;Scheduler was sent the command new
11/02/2013 18:52:25;0040;PBS_Server;Svr;tyrone-cluster;Scheduler was sent the command new
11/02/2013 18:52:42;0002;PBS_Server;Svr;PBS_Server;Torque Server Version = 3.0.5, loglevel = 0
11/02/2013 18:52:48;0040;PBS_Server;Svr;tyrone-cluster;Scheduler was sent the command new
11/02/2013 18:53:19;0040;PBS_Server;Svr;tyrone-cluster;Scheduler was sent the command new
11/02/2013 18:53:55;0040;PBS_Server;Svr;tyrone-cluster;Scheduler was sent the command new
11/02/2013 18:54:19;0040;PBS_Server;Svr;tyrone-cluster;Scheduler was sent the command new
11/02/2013 18:54:49;0040;PBS_Server;Svr;tyrone-cluster;Scheduler was sent the command new
11/02/2013 18:55:25;0040;PBS_Server;Svr;tyrone-cluster;Scheduler was sent the command new
11/02/2013 18:55:39;0100;PBS_Server;Job;31424.tyrone-cluster;enqueuing into batch, state 1 hop 1
11/02/2013 18:55:39;0100;PBS_Server;Job;31424.tyrone-cluster;dequeuing from batch, state QUEUED
11/02/2013 18:55:39;0100;PBS_Server;Job;31424.tyrone-cluster;enqueuing into qp64, state 1 hop 1
11/02/2013 18:55:39;0008;PBS_Server;Job;31424.tyrone-cluster;Job Queued at request of secbadar@tyrone-cluster, owner = secbadar@tyrone-cluster, job name = Unif06Sch64, queue = qp64
11/02/2013 18:55:39;0040;PBS_Server;Svr;tyrone-cluster;Scheduler was sent the command new
11/02/2013 18:55:41;0100;PBS_Server;Job;31425.tyrone-cluster;enqueuing into batch, state 1 hop 1
11/02/2013 18:55:41;0100;PBS_Server;Job;31425.tyrone-cluster;dequeuing from batch, state QUEUED
11/02/2013 18:55:41;0100;PBS_Server;Job;31425.tyrone-cluster;enqueuing into qp64, state 1 hop 1
11/02/2013 18:55:41;0008;PBS_Server;Job;31425.tyrone-cluster;Job Queued at request of secbadar@tyrone-cluster, owner = secbadar@tyrone-cluster, job name = Unif05Sch64, queue = qp64
11/02/2013 18:55:43;0008;PBS_Server;Job;31424.tyrone-cluster;Job Modified at request of Scheduler@tyrone-cluster
11/02/2013 18:55:43;0008;PBS_Server;Job;31425.tyrone-cluster;Job Modified at request of Scheduler@tyrone-cluster
11/02/2013 18:55:56;0040;PBS_Server;Svr;tyrone-cluster;Scheduler was sent the command new
11/02/2013 18:56:30;0040;PBS_Server;Svr;tyrone-cluster;Scheduler was sent the command new
11/02/2013 18:56:59;0040;PBS_Server;Svr;tyrone-cluster;Scheduler was sent the command new
11/02/2013 18:57:14;0100;PBS_Server;Job;31426.tyrone-cluster;enqueuing into batch, state 1 hop 1
11/02/2013 18:57:14;0100;PBS_Server;Job;31426.tyrone-cluster;dequeuing from batch, state QUEUED
11/02/2013 18:57:14;0100;PBS_Server;Job;31426.tyrone-cluster;enqueuing into qp64, state 1 hop 1
11/02/2013 18:57:14;0008;PBS_Server;Job;31426.tyrone-cluster;Job Queued at request of secbadar@tyrone-cluster, owner = secbadar@tyrone-cluster, job name = Unif06Mpi64, queue = qp64
11/02/2013 18:57:14;0040;PBS_Server;Svr;tyrone-cluster;Scheduler was sent the command new
11/02/2013 18:57:14;0008;PBS_Server;Job;31426.tyrone-cluster;Job Modified at request of Scheduler@tyrone-cluster
11/02/2013 18:57:15;0100;PBS_Server;Job;31427.tyrone-cluster;enqueuing into batch, state 1 hop 1
11/02/2013 18:57:15;0008;PBS_Server;Job;31427.tyrone-cluster;Job Queued at request of secbadar@tyrone-cluster, owner = secbadar@tyrone-cluster, job name = Unif05Mpi64, queue = batch
11/02/2013 18:57:15;0040;PBS_Server;Svr;tyrone-cluster;Scheduler was sent the command new
11/02/2013 18:57:19;0008;PBS_Server;Job;31427.tyrone-cluster;Job Modified at request of Scheduler@tyrone-cluster
11/02/2013 18:57:39;0040;PBS_Server;Svr;tyrone-cluster;Scheduler was sent the command new
11/02/2013 18:57:42;0002;PBS_Server;Svr;PBS_Server;Torque Server Version = 3.0.5, loglevel = 0
11/02/2013 18:57:48;0040;PBS_Server;Svr;tyrone-cluster;Scheduler was sent the command new
11/02/2013 18:58:04;0040;PBS_Server;Svr;tyrone-cluster;Scheduler was sent the command new
11/02/2013 18:58:25;0040;PBS_Server;Svr;tyrone-cluster;Scheduler was sent the command new
11/02/2013 18:58:34;0040;PBS_Server;Svr;tyrone-cluster;Scheduler was sent the command new
11/02/2013 18:58:49;0040;PBS_Server;Svr;tyrone-cluster;Scheduler was sent the command new
11/02/2013 18:59:10;0040;PBS_Server;Svr;tyrone-cluster;Scheduler was sent the command new
11/02/2013 18:59:19;0040;PBS_Server;Svr;tyrone-cluster;Scheduler was sent the command new
11/02/2013 18:59:34;0040;PBS_Server;Svr;tyrone-cluster;Scheduler was sent the command new
11/02/2013 18:59:55;0040;PBS_Server;Svr;tyrone-cluster;Scheduler was sent the command new
11/02/2013 19:00:05;0040;PBS_Server;Svr;tyrone-cluster;Scheduler was sent the command new
11/02/2013 19:00:27;0040;PBS_Server;Svr;tyrone-cluster;Scheduler was sent the command new
11/02/2013 19:00:40;0040;PBS_Server;Svr;tyrone-cluster;Scheduler was sent the command new
11/02/2013 19:01:02;0040;PBS_Server;Svr;tyrone-cluster;Scheduler was sent the command new
11/02/2013 19:01:11;0040;PBS_Server;Svr;tyrone-cluster;Scheduler was sent the command new
11/02/2013 19:01:33;0040;PBS_Server;Svr;tyrone-cluster;Scheduler was sent the command new
11/02/2013 19:01:45;0040;PBS_Server;Svr;tyrone-cluster;Scheduler was sent the command new
11/02/2013 19:02:09;0040;PBS_Server;Svr;tyrone-cluster;Scheduler was sent the command new
11/02/2013 19:02:18;0040;PBS_Server;Svr;tyrone-cluster;Scheduler was sent the command new
11/02/2013 19:02:32;0040;PBS_Server;Svr;tyrone-cluster;Scheduler was sent the command new
11/02/2013 19:02:42;0002;PBS_Server;Svr;PBS_Server;Torque Server Version = 3.0.5, loglevel = 0
11/02/2013 19:02:55;0040;PBS_Server;Svr;tyrone-cluster;Scheduler was sent the command new
11/02/2013 19:03:03;0040;PBS_Server;Svr;tyrone-cluster;Scheduler was sent the command new
11/02/2013 19:03:19;0040;PBS_Server;Svr;tyrone-cluster;Scheduler was sent the command new
11/02/2013 19:03:40;0040;PBS_Server;Svr;tyrone-cluster;Scheduler was sent the command new
11/02/2013 19:03:49;0040;PBS_Server;Svr;tyrone-cluster;Scheduler was sent the command new
11/02/2013 19:04:04;0040;PBS_Server;Svr;tyrone-cluster;Scheduler was sent the command new
11/02/2013 19:04:25;0040;PBS_Server;Svr;tyrone-cluster;Scheduler was sent the command new
11/02/2013 19:04:34;0040;PBS_Server;Svr;tyrone-cluster;Scheduler was sent the command new
11/02/2013 19:04:57;0040;PBS_Server;Svr;tyrone-cluster;Scheduler was sent the command new
11/02/2013 19:05:10;0040;PBS_Server;Svr;tyrone-cluster;Scheduler was sent the command new
11/02/2013 19:05:26;0040;PBS_Server;Svr;tyrone-cluster;Scheduler was sent the command new
11/02/2013 19:05:41;0040;PBS_Server;Svr;tyrone-cluster;Scheduler was sent the command new
11/02/2013 19:05:59;0040;PBS_Server;Svr;tyrone-cluster;Scheduler was sent the command new
11/02/2013 19:06:15;0040;PBS_Server;Svr;tyrone-cluster;Scheduler was sent the command new
11/02/2013 19:06:33;0040;PBS_Server;Svr;tyrone-cluster;Scheduler was sent the command new
11/02/2013 19:06:44;0040;PBS_Server;Svr;tyrone-cluster;Scheduler was sent the command new
11/02/2013 19:07:02;0040;PBS_Server;Svr;tyrone-cluster;Scheduler was sent the command new
11/02/2013 19:07:18;0040;PBS_Server;Svr;tyrone-cluster;Scheduler was sent the command new
11/02/2013 19:07:33;0040;PBS_Server;Svr;tyrone-cluster;Scheduler was sent the command new
11/02/2013 19:07:42;0002;PBS_Server;Svr;PBS_Server;Torque Server Version = 3.0.5, loglevel = 0
11/02/2013 19:07:47;0040;PBS_Server;Svr;tyrone-cluster;Scheduler was sent the command new
11/02/2013 19:08:10;0040;PBS_Server;Svr;tyrone-cluster;Scheduler was sent the command new
11/02/2013 19:08:18;0040;PBS_Server;Svr;tyrone-cluster;Scheduler was sent the command new
11/02/2013 19:08:33;0040;PBS_Server;Svr;tyrone-cluster;Scheduler was sent the command new
11/02/2013 19:08:55;0040;PBS_Server;Svr;tyrone-cluster;Scheduler was sent the command new
11/02/2013 19:09:03;0040;PBS_Server;Svr;tyrone-cluster;Scheduler was sent the command new
11/02/2013 19:09:18;0040;PBS_Server;Svr;tyrone-cluster;Scheduler was sent the command new
11/02/2013 19:09:40;0040;PBS_Server;Svr;tyrone-cluster;Scheduler was sent the command new
11/02/2013 19:09:49;0040;PBS_Server;Svr;tyrone-cluster;Scheduler was sent the command new
11/02/2013 19:10:03;0040;PBS_Server;Svr;tyrone-cluster;Scheduler was sent the command new
11/02/2013 19:10:25;0040;PBS_Server;Svr;tyrone-cluster;Scheduler was sent the command new
11/02/2013 19:10:33;0040;PBS_Server;Svr;tyrone-cluster;Scheduler was sent the command new
11/02/2013 19:10:48;0040;PBS_Server;Svr;tyrone-cluster;Scheduler was sent the command new
11/02/2013 19:11:10;0040;PBS_Server;Svr;tyrone-cluster;Scheduler was sent the command new
11/02/2013 19:11:19;0040;PBS_Server;Svr;tyrone-cluster;Scheduler was sent the command new
11/02/2013 19:11:34;0040;PBS_Server;Svr;tyrone-cluster;Scheduler was sent the command new
11/02/2013 19:11:55;0040;PBS_Server;Svr;tyrone-cluster;Scheduler was sent the command new
11/02/2013 19:12:05;0040;PBS_Server;Svr;tyrone-cluster;Scheduler was sent the command new
11/02/2013 19:12:19;0040;PBS_Server;Svr;tyrone-cluster;Scheduler was sent the command new
11/02/2013 19:12:40;0040;PBS_Server;Svr;tyrone-cluster;Scheduler was sent the command new
11/02/2013 19:12:42;0002;PBS_Server;Svr;PBS_Server;Torque Server Version = 3.0.5, loglevel = 0
11/02/2013 19:12:50;0040;PBS_Server;Svr;tyrone-cluster;Scheduler was sent the command new
11/02/2013 19:13:11;0040;PBS_Server;Svr;tyrone-cluster;Scheduler was sent the command new
11/02/2013 19:13:25;0040;PBS_Server;Svr;tyrone-cluster;Scheduler was sent the command new
11/02/2013 19:13:45;0040;PBS_Server;Svr;tyrone-cluster;Scheduler was sent the command new
11/02/2013 19:13:56;0040;PBS_Server;Svr;tyrone-cluster;Scheduler was sent the command new
11/02/2013 19:14:14;0040;PBS_Server;Svr;tyrone-cluster;Scheduler was sent the command new
11/02/2013 19:14:28;0040;PBS_Server;Svr;tyrone-cluster;Scheduler was sent the command new
11/02/2013 19:14:55;0040;PBS_Server;Svr;tyrone-cluster;Scheduler was sent the command new
11/02/2013 19:14:59;0040;PBS_Server;Svr;tyrone-cluster;Scheduler was sent the command new
11/02/2013 19:15:18;0040;PBS_Server;Svr;tyrone-cluster;Scheduler was sent the command new
11/02/2013 19:15:32;0040;PBS_Server;Svr;tyrone-cluster;Scheduler was sent the command new
11/02/2013 19:15:49;0040;PBS_Server;Svr;tyrone-cluster;Scheduler was sent the command new
11/02/2013 19:16:02;0040;PBS_Server;Svr;tyrone-cluster;Scheduler was sent the command new
11/02/2013 19:16:25;0040;PBS_Server;Svr;tyrone-cluster;Scheduler was sent the command new
11/02/2013 19:16:33;0040;PBS_Server;Svr;tyrone-cluster;Scheduler was sent the command new
11/02/2013 19:16:49;0040;PBS_Server;Svr;tyrone-cluster;Scheduler was sent the command new
11/02/2013 19:17:10;0040;PBS_Server;Svr;tyrone-cluster;Scheduler was sent the command new
11/02/2013 19:17:19;0040;PBS_Server;Svr;tyrone-cluster;Scheduler was sent the command new
11/02/2013 19:17:34;0040;PBS_Server;Svr;tyrone-cluster;Scheduler was sent the command new
11/02/2013 19:17:42;0002;PBS_Server;Svr;PBS_Server;Torque Server Version = 3.0.5, loglevel = 0
11/02/2013 19:17:55;0040;PBS_Server;Svr;tyrone-cluster;Scheduler was sent the command new
11/02/2013 19:18:03;0040;PBS_Server;Svr;tyrone-cluster;Scheduler was sent the command new
11/02/2013 19:18:27;0040;PBS_Server;Svr;tyrone-cluster;Scheduler was sent the command new
11/02/2013 19:18:40;0040;PBS_Server;Svr;tyrone-cluster;Scheduler was sent the command new
11/02/2013 19:19:00;0040;PBS_Server;Svr;tyrone-cluster;Scheduler was sent the command new
11/02/2013 19:19:04;0040;PBS_Server;Svr;tyrone-cluster;Scheduler was sent the command new
11/02/2013 19:19:29;0040;PBS_Server;Svr;tyrone-cluster;Scheduler was sent the command new
11/02/2013 19:19:34;0040;PBS_Server;Svr;tyrone-cluster;Scheduler was sent the command new
11/02/2013 19:20:03;0040;PBS_Server;Svr;tyrone-cluster;Scheduler was sent the command new
11/02/2013 19:20:32;0040;PBS_Server;Svr;tyrone-cluster;Scheduler was sent the command new
11/02/2013 19:21:03;0040;PBS_Server;Svr;tyrone-cluster;Scheduler was sent the command new
11/02/2013 19:21:40;0040;PBS_Server;Svr;tyrone-cluster;Scheduler was sent the command new
11/02/2013 19:22:03;0040;PBS_Server;Svr;tyrone-cluster;Scheduler was sent the command new
11/02/2013 19:22:33;0040;PBS_Server;Svr;tyrone-cluster;Scheduler was sent the command new
11/02/2013 19:22:42;0002;PBS_Server;Svr;PBS_Server;Torque Server Version = 3.0.5, loglevel = 0
11/02/2013 19:23:10;0040;PBS_Server;Svr;tyrone-cluster;Scheduler was sent the command new
11/02/2013 19:23:42;0040;PBS_Server;Svr;tyrone-cluster;Scheduler was sent the command new
11/02/2013 19:24:16;0040;PBS_Server;Svr;tyrone-cluster;Scheduler was sent the command new
11/02/2013 19:24:43;0040;PBS_Server;Svr;tyrone-cluster;Scheduler was sent the command new
11/02/2013 19:25:18;0040;PBS_Server;Svr;tyrone-cluster;Scheduler was sent the command new
11/02/2013 19:25:47;0040;PBS_Server;Svr;tyrone-cluster;Scheduler was sent the command new
11/02/2013 19:26:17;0040;PBS_Server;Svr;tyrone-cluster;Scheduler was sent the command new
11/02/2013 19:26:55;0040;PBS_Server;Svr;tyrone-cluster;Scheduler was sent the command new
11/02/2013 19:27:18;0040;PBS_Server;Svr;tyrone-cluster;Scheduler was sent the command new
11/02/2013 19:27:42;0002;PBS_Server;Svr;PBS_Server;Torque Server Version = 3.0.5, loglevel = 0
11/02/2013 19:27:49;0040;PBS_Server;Svr;tyrone-cluster;Scheduler was sent the command new
11/02/2013 19:28:25;0040;PBS_Server;Svr;tyrone-cluster;Scheduler was sent the command new
11/02/2013 19:28:50;0040;PBS_Server;Svr;tyrone-cluster;Scheduler was sent the command new
11/02/2013 19:29:20;0040;PBS_Server;Svr;tyrone-cluster;Scheduler was sent the command new
11/02/2013 19:29:55;0040;PBS_Server;Svr;tyrone-cluster;Scheduler was sent the command new
11/02/2013 19:30:27;0040;PBS_Server;Svr;tyrone-cluster;Scheduler was sent the command new
11/02/2013 19:31:02;0040;PBS_Server;Svr;tyrone-cluster;Scheduler was sent the command new
11/02/2013 19:31:33;0040;PBS_Server;Svr;tyrone-cluster;Scheduler was sent the command new
11/02/2013 19:32:10;0040;PBS_Server;Svr;tyrone-cluster;Scheduler was sent the command new
11/02/2013 19:32:33;0040;PBS_Server;Svr;tyrone-cluster;Scheduler was sent the command new
11/02/2013 19:32:42;0002;PBS_Server;Svr;PBS_Server;Torque Server Version = 3.0.5, loglevel = 0
11/02/2013 19:33:04;0040;PBS_Server;Svr;tyrone-cluster;Scheduler was sent the command new
11/02/2013 19:33:40;0040;PBS_Server;Svr;tyrone-cluster;Scheduler was sent the command new
11/02/2013 19:34:12;0040;PBS_Server;Svr;tyrone-cluster;Scheduler was sent the command new
11/02/2013 19:34:43;0040;PBS_Server;Svr;tyrone-cluster;Scheduler was sent the command new
11/02/2013 19:35:14;0040;PBS_Server;Svr;tyrone-cluster;Scheduler was sent the command new
11/02/2013 19:35:48;0040;PBS_Server;Svr;tyrone-cluster;Scheduler was sent the command new
11/02/2013 19:36:14;0040;PBS_Server;Svr;tyrone-cluster;Scheduler was sent the command new
11/02/2013 19:36:44;0040;PBS_Server;Svr;tyrone-cluster;Scheduler was sent the command new
11/02/2013 19:36:55;0100;PBS_Server;Job;31428.tyrone-cluster;enqueuing into batch, state 1 hop 1
11/02/2013 19:36:55;0100;PBS_Server;Job;31428.tyrone-cluster;dequeuing from batch, state QUEUED
11/02/2013 19:36:55;0100;PBS_Server;Job;31428.tyrone-cluster;enqueuing into qp256, state 1 hop 1
11/02/2013 19:36:55;0008;PBS_Server;Job;31428.tyrone-cluster;Job Queued at request of secbadar@tyrone-cluster, owner = secbadar@tyrone-cluster, job name = Unif04Sch, queue = qp256
11/02/2013 19:36:55;0040;PBS_Server;Svr;tyrone-cluster;Scheduler was sent the command new
11/02/2013 19:36:55;0008;PBS_Server;Job;31428.tyrone-cluster;Job Modified at request of Scheduler@tyrone-cluster
11/02/2013 19:36:55;0008;PBS_Server;Job;31428.tyrone-cluster;Job Run at request of Scheduler@tyrone-cluster
11/02/2013 19:36:55;0040;PBS_Server;Svr;tyrone-cluster;Scheduler was sent the command recyc
11/02/2013 19:37:25;0040;PBS_Server;Svr;tyrone-cluster;Scheduler was sent the command new
11/02/2013 19:37:42;0002;PBS_Server;Svr;PBS_Server;Torque Server Version = 3.0.5, loglevel = 0
11/02/2013 19:37:48;000d;PBS_Server;Job;31428.tyrone-cluster;Not sending email: User does not want mail of this type.
11/02/2013 19:37:48;0040;PBS_Server;Svr;tyrone-cluster;Scheduler was sent the command new
11/02/2013 19:38:19;0040;PBS_Server;Svr;tyrone-cluster;Scheduler was sent the command new
11/02/2013 19:38:22;0100;PBS_Server;Job;31429.tyrone-cluster;enqueuing into batch, state 1 hop 1
11/02/2013 19:38:22;0100;PBS_Server;Job;31429.tyrone-cluster;dequeuing from batch, state QUEUED
11/02/2013 19:38:22;0100;PBS_Server;Job;31429.tyrone-cluster;enqueuing into qp256, state 1 hop 1
11/02/2013 19:38:22;0008;PBS_Server;Job;31429.tyrone-cluster;Job Queued at request of secbadar@tyrone-cluster, owner = secbadar@tyrone-cluster, job name = Unif04Mpi, queue = qp256
11/02/2013 19:38:22;0040;PBS_Server;Svr;tyrone-cluster;Scheduler was sent the command new
11/02/2013 19:38:22;0008;PBS_Server;Job;31429.tyrone-cluster;Job Modified at request of Scheduler@tyrone-cluster
11/02/2013 19:38:55;0040;PBS_Server;Svr;tyrone-cluster;Scheduler was sent the command new
11/02/2013 19:39:26;0040;PBS_Server;Svr;tyrone-cluster;Scheduler was sent the command new
11/02/2013 19:39:50;0100;PBS_Server;Job;31430.tyrone-cluster;enqueuing into batch, state 1 hop 1
11/02/2013 19:39:50;0008;PBS_Server;Job;31430.tyrone-cluster;Job Queued at request of secbadar@tyrone-cluster, owner = secbadar@tyrone-cluster, job name = Unif04Sch64, queue = batch
11/02/2013 19:39:50;0040;PBS_Server;Svr;tyrone-cluster;Scheduler was sent the command new
11/02/2013 19:39:50;0008;PBS_Server;Job;31430.tyrone-cluster;Job Modified at request of Scheduler@tyrone-cluster
11/02/2013 19:40:01;0040;PBS_Server;Svr;tyrone-cluster;Scheduler was sent the command new
11/02/2013 19:40:25;0040;PBS_Server;Svr;tyrone-cluster;Scheduler was sent the command new
11/02/2013 19:40:42;0100;PBS_Server;Job;31431.tyrone-cluster;enqueuing into batch, state 1 hop 1
11/02/2013 19:40:42;0008;PBS_Server;Job;31431.tyrone-cluster;Job Queued at request of secbadar@tyrone-cluster, owner = secbadar@tyrone-cluster, job name = Unif04Mpi64, queue = batch
11/02/2013 19:40:42;0040;PBS_Server;Svr;tyrone-cluster;Scheduler was sent the command new
11/02/2013 19:40:43;0008;PBS_Server;Job;31431.tyrone-cluster;Job Modified at request of Scheduler@tyrone-cluster
11/02/2013 19:40:57;0040;PBS_Server;Svr;tyrone-cluster;Scheduler was sent the command new
11/02/2013 19:41:14;0040;PBS_Server;Svr;tyrone-cluster;Scheduler was sent the command new
11/02/2013 19:41:32;0040;PBS_Server;Svr;tyrone-cluster;Scheduler was sent the command new
11/02/2013 19:41:43;0040;PBS_Server;Svr;tyrone-cluster;Scheduler was sent the command new
11/02/2013 19:42:03;0040;PBS_Server;Svr;tyrone-cluster;Scheduler was sent the command new
11/02/2013 19:42:17;0040;PBS_Server;Svr;tyrone-cluster;Scheduler was sent the command new
11/02/2013 19:42:40;0040;PBS_Server;Svr;tyrone-cluster;Scheduler was sent the command new
11/02/2013 19:42:42;0002;PBS_Server;Svr;PBS_Server;Torque Server Version = 3.0.5, loglevel = 0
11/02/2013 19:42:44;0040;PBS_Server;Svr;tyrone-cluster;Scheduler was sent the command new
11/02/2013 19:43:02;0040;PBS_Server;Svr;tyrone-cluster;Scheduler was sent the command new
11/02/2013 19:43:25;0040;PBS_Server;Svr;tyrone-cluster;Scheduler was sent the command new
11/02/2013 19:43:33;0040;PBS_Server;Svr;tyrone-cluster;Scheduler was sent the command new
11/02/2013 19:43:48;0040;PBS_Server;Svr;tyrone-cluster;Scheduler was sent the command new
11/02/2013 19:44:10;0040;PBS_Server;Svr;tyrone-cluster;Scheduler was sent the command new
11/02/2013 19:44:19;0040;PBS_Server;Svr;tyrone-cluster;Scheduler was sent the command new
11/02/2013 19:44:32;0040;PBS_Server;Svr;tyrone-cluster;Scheduler was sent the command new
11/02/2013 19:44:51;0040;PBS_Server;Svr;tyrone-cluster;Scheduler was sent the command new
11/02/2013 19:45:03;0040;PBS_Server;Svr;tyrone-cluster;Scheduler was sent the command new
11/02/2013 19:45:18;0040;PBS_Server;Svr;tyrone-cluster;Scheduler was sent the command new
11/02/2013 19:45:40;0040;PBS_Server;Svr;tyrone-cluster;Scheduler was sent the command new
11/02/2013 19:45:49;0040;PBS_Server;Svr;tyrone-cluster;Scheduler was sent the command new
11/02/2013 19:46:02;0040;PBS_Server;Svr;tyrone-cluster;Scheduler was sent the command new
11/02/2013 19:46:25;0040;PBS_Server;Svr;tyrone-cluster;Scheduler was sent the command new
11/02/2013 19:46:33;0040;PBS_Server;Svr;tyrone-cluster;Scheduler was sent the command new
11/02/2013 19:46:48;0040;PBS_Server;Svr;tyrone-cluster;Scheduler was sent the command new
11/02/2013 19:47:10;0040;PBS_Server;Svr;tyrone-cluster;Scheduler was sent the command new
11/02/2013 19:47:18;0040;PBS_Server;Svr;tyrone-cluster;Scheduler was sent the command new
11/02/2013 19:47:32;0040;PBS_Server;Svr;tyrone-cluster;Scheduler was sent the command new
11/02/2013 19:47:42;0002;PBS_Server;Svr;PBS_Server;Torque Server Version = 3.0.5, loglevel = 0
11/02/2013 19:47:55;0040;PBS_Server;Svr;tyrone-cluster;Scheduler was sent the command new
11/02/2013 19:48:03;0040;PBS_Server;Svr;tyrone-cluster;Scheduler was sent the command new
11/02/2013 19:48:26;0040;PBS_Server;Svr;tyrone-cluster;Scheduler was sent the command new
11/02/2013 19:48:40;0040;PBS_Server;Svr;tyrone-cluster;Scheduler was sent the command new
11/02/2013 19:48:41;0100;PBS_Server;Job;31432.tyrone-cluster;enqueuing into batch, state 1 hop 1
11/02/2013 19:48:41;0100;PBS_Server;Job;31432.tyrone-cluster;dequeuing from batch, state QUEUED
11/02/2013 19:48:41;0100;PBS_Server;Job;31432.tyrone-cluster;enqueuing into qp128, state 1 hop 1
11/02/2013 19:48:41;0008;PBS_Server;Job;31432.tyrone-cluster;Job Queued at request of secbadar@tyrone-cluster, owner = secbadar@tyrone-cluster, job name = 128Edge4, queue = qp128
11/02/2013 19:48:41;0040;PBS_Server;Svr;tyrone-cluster;Scheduler was sent the command new
11/02/2013 19:48:41;0008;PBS_Server;Job;31432.tyrone-cluster;Job Modified at request of Scheduler@tyrone-cluster
11/02/2013 19:48:41;0008;PBS_Server;Job;31432.tyrone-cluster;Job Run at request of Scheduler@tyrone-cluster
11/02/2013 19:48:41;0040;PBS_Server;Svr;tyrone-cluster;Scheduler was sent the command recyc
11/02/2013 19:48:59;0040;PBS_Server;Svr;tyrone-cluster;Scheduler was sent the command new
11/02/2013 19:49:03;0040;PBS_Server;Svr;tyrone-cluster;Scheduler was sent the command new
11/02/2013 19:49:09;000d;PBS_Server;Job;31432.tyrone-cluster;Not sending email: User does not want mail of this type.
11/02/2013 19:49:25;0040;PBS_Server;Svr;tyrone-cluster;Scheduler was sent the command new
11/02/2013 19:49:33;0040;PBS_Server;Svr;tyrone-cluster;Scheduler was sent the command new
11/02/2013 19:49:56;0040;PBS_Server;Svr;tyrone-cluster;Scheduler was sent the command new
11/02/2013 19:50:10;0040;PBS_Server;Svr;tyrone-cluster;Scheduler was sent the command new
11/02/2013 19:50:27;0040;PBS_Server;Svr;tyrone-cluster;Scheduler was sent the command new
11/02/2013 19:50:41;0040;PBS_Server;Svr;tyrone-cluster;Scheduler was sent the command new
11/02/2013 19:50:55;0040;PBS_Server;Svr;tyrone-cluster;Scheduler was sent the command new
11/02/2013 19:51:10;0040;PBS_Server;Svr;tyrone-cluster;Scheduler was sent the command new
11/02/2013 19:51:26;0040;PBS_Server;Svr;tyrone-cluster;Scheduler was sent the command new
11/02/2013 19:51:40;0040;PBS_Server;Svr;tyrone-cluster;Scheduler was sent the command new
11/02/2013 19:52:02;0040;PBS_Server;Svr;tyrone-cluster;Scheduler was sent the command new
11/02/2013 19:52:11;0040;PBS_Server;Svr;tyrone-cluster;Scheduler was sent the command new
11/02/2013 19:52:25;0040;PBS_Server;Svr;tyrone-cluster;Scheduler was sent the command new
11/02/2013 19:52:42;0002;PBS_Server;Svr;PBS_Server;Torque Server Version = 3.0.5, loglevel = 0
11/02/2013 19:52:42;0040;PBS_Server;Svr;tyrone-cluster;Scheduler was sent the command new
11/02/2013 19:52:56;0040;PBS_Server;Svr;tyrone-cluster;Scheduler was sent the command new
11/02/2013 19:53:10;0040;PBS_Server;Svr;tyrone-cluster;Scheduler was sent the command new
11/02/2013 19:53:30;0040;PBS_Server;Svr;tyrone-cluster;Scheduler was sent the command new
11/02/2013 19:53:42;0040;PBS_Server;Svr;tyrone-cluster;Scheduler was sent the command new
11/02/2013 19:54:03;0040;PBS_Server;Svr;tyrone-cluster;Scheduler was sent the command new
11/02/2013 19:54:17;0040;PBS_Server;Svr;tyrone-cluster;Scheduler was sent the command new
11/02/2013 19:54:40;0040;PBS_Server;Svr;tyrone-cluster;Scheduler was sent the command new
11/02/2013 19:54:48;0040;PBS_Server;Svr;tyrone-cluster;Scheduler was sent the command new
11/02/2013 19:55:03;0040;PBS_Server;Svr;tyrone-cluster;Scheduler was sent the command new
11/02/2013 19:55:25;0040;PBS_Server;Svr;tyrone-cluster;Scheduler was sent the command new
11/02/2013 19:55:33;0040;PBS_Server;Svr;tyrone-cluster;Scheduler was sent the command new
11/02/2013 19:55:47;0040;PBS_Server;Svr;tyrone-cluster;Scheduler was sent the command new
11/02/2013 19:56:10;0040;PBS_Server;Svr;tyrone-cluster;Scheduler was sent the command new
11/02/2013 19:56:18;0040;PBS_Server;Svr;tyrone-cluster;Scheduler was sent the command new
11/02/2013 19:56:41;0040;PBS_Server;Svr;tyrone-cluster;Scheduler was sent the command new
11/02/2013 19:56:55;0040;PBS_Server;Svr;tyrone-cluster;Scheduler was sent the command new
11/02/2013 19:57:17;0040;PBS_Server;Svr;tyrone-cluster;Scheduler was sent the command new
11/02/2013 19:57:40;0040;PBS_Server;Svr;tyrone-cluster;Scheduler was sent the command new
11/02/2013 19:57:42;0002;PBS_Server;Svr;PBS_Server;Torque Server Version = 3.0.5, loglevel = 0
11/02/2013 19:57:48;0040;PBS_Server;Svr;tyrone-cluster;Scheduler was sent the command new
11/02/2013 19:58:12;0040;PBS_Server;Svr;tyrone-cluster;Scheduler was sent the command new
11/02/2013 19:58:25;0040;PBS_Server;Svr;tyrone-cluster;Scheduler was sent the command new
11/02/2013 19:58:47;0040;PBS_Server;Svr;tyrone-cluster;Scheduler was sent the command new
11/02/2013 19:58:48;0040;PBS_Server;Svr;tyrone-cluster;Scheduler was sent the command new
11/02/2013 19:59:18;0040;PBS_Server;Svr;tyrone-cluster;Scheduler was sent the command new
11/02/2013 19:59:55;0040;PBS_Server;Svr;tyrone-cluster;Scheduler was sent the command new
11/02/2013 20:00:17;0040;PBS_Server;Svr;tyrone-cluster;Scheduler was sent the command new
11/02/2013 20:00:23;0008;PBS_Server;Job;31432.tyrone-cluster;Job deleted at request of secbadar@tyrone-cluster
11/02/2013 20:00:23;0008;PBS_Server;Job;31432.tyrone-cluster;Job sent signal SIGTERM on delete
11/02/2013 20:00:23;000d;PBS_Server;Job;31432.tyrone-cluster;Not sending email: User does not want mail of this type.
11/02/2013 20:00:23;0010;PBS_Server;Job;31432.tyrone-cluster;Exit_status=143 resources_used.cput=00:08:12 resources_used.mem=341276kb resources_used.vmem=2647056kb resources_used.walltime=00:11:42
11/02/2013 20:00:23;0008;PBS_Server;Job;NULL;on_job_exit valid pjob: 0x2e0d0b0 (substate=50)
11/02/2013 20:00:23;0008;PBS_Server;Job;NULL;on_job_exit valid pjob: 0x2e0d0b0 (substate=51)
11/02/2013 20:00:23;0008;PBS_Server;Job;NULL;on_job_exit valid pjob: 0x2e0d0b0 (substate=51)
11/02/2013 20:00:23;0008;PBS_Server;Job;NULL;on_job_exit valid pjob: 0x2e0d0b0 (substate=53)
11/02/2013 20:00:23;0100;PBS_Server;Job;31432.tyrone-cluster;dequeuing from qp128, state COMPLETE
11/02/2013 20:00:23;0040;PBS_Server;Svr;tyrone-cluster;Scheduler was sent the command term
11/02/2013 20:00:26;0040;PBS_Server;Svr;tyrone-cluster;Scheduler was sent the command new
11/02/2013 20:00:48;0040;PBS_Server;Svr;tyrone-cluster;Scheduler was sent the command new
11/02/2013 20:01:02;0040;PBS_Server;Svr;tyrone-cluster;Scheduler was sent the command new
11/02/2013 20:01:25;0040;PBS_Server;Svr;tyrone-cluster;Scheduler was sent the command new
11/02/2013 20:01:37;0100;PBS_Server;Job;31433.tyrone-cluster;enqueuing into batch, state 1 hop 1
11/02/2013 20:01:37;0100;PBS_Server;Job;31433.tyrone-cluster;dequeuing from batch, state QUEUED
11/02/2013 20:01:37;0100;PBS_Server;Job;31433.tyrone-cluster;enqueuing into qp128, state 1 hop 1
11/02/2013 20:01:37;0008;PBS_Server;Job;31433.tyrone-cluster;Job Queued at request of secbadar@tyrone-cluster, owner = secbadar@tyrone-cluster, job name = 128Edge4, queue = qp128
11/02/2013 20:01:37;0040;PBS_Server;Svr;tyrone-cluster;Scheduler was sent the command new
11/02/2013 20:01:37;0008;PBS_Server;Job;31433.tyrone-cluster;Job Modified at request of Scheduler@tyrone-cluster
11/02/2013 20:01:37;0008;PBS_Server;Job;31433.tyrone-cluster;Job Run at request of Scheduler@tyrone-cluster
11/02/2013 20:01:37;0040;PBS_Server;Svr;tyrone-cluster;Scheduler was sent the command recyc
11/02/2013 20:01:48;0040;PBS_Server;Svr;tyrone-cluster;Scheduler was sent the command new
11/02/2013 20:01:56;0040;PBS_Server;Svr;tyrone-cluster;Scheduler was sent the command new
11/02/2013 20:02:19;0040;PBS_Server;Svr;tyrone-cluster;Scheduler was sent the command new
11/02/2013 20:02:32;0040;PBS_Server;Svr;tyrone-cluster;Scheduler was sent the command new
11/02/2013 20:02:41;000d;PBS_Server;Job;31433.tyrone-cluster;Not sending email: User does not want mail of this type.
11/02/2013 20:02:42;0002;PBS_Server;Svr;PBS_Server;Torque Server Version = 3.0.5, loglevel = 0
11/02/2013 20:02:55;0040;PBS_Server;Svr;tyrone-cluster;Scheduler was sent the command new
11/02/2013 20:03:03;0040;PBS_Server;Svr;tyrone-cluster;Scheduler was sent the command new
11/02/2013 20:03:15;000d;PBS_Server;Job;31433.tyrone-cluster;Not sending email: User does not want mail of this type.
11/02/2013 20:03:15;0010;PBS_Server;Job;31433.tyrone-cluster;Exit_status=0 resources_used.cput=00:01:23 resources_used.mem=165404kb resources_used.vmem=1211320kb resources_used.walltime=00:01:37
11/02/2013 20:03:15;0008;PBS_Server;Job;NULL;on_job_exit valid pjob: 0x2e0d0b0 (substate=50)
11/02/2013 20:03:15;0008;PBS_Server;Job;NULL;on_job_exit valid pjob: 0x2e0d0b0 (substate=51)
11/02/2013 20:03:15;0008;PBS_Server;Job;NULL;on_job_exit valid pjob: 0x2e0d0b0 (substate=51)
11/02/2013 20:03:15;0008;PBS_Server;Job;NULL;on_job_exit valid pjob: 0x2e0d0b0 (substate=53)
11/02/2013 20:03:15;0100;PBS_Server;Job;31433.tyrone-cluster;dequeuing from qp128, state COMPLETE
11/02/2013 20:03:15;0040;PBS_Server;Svr;tyrone-cluster;Scheduler was sent the command term
11/02/2013 20:03:26;0040;PBS_Server;Svr;tyrone-cluster;Scheduler was sent the command new
11/02/2013 20:03:40;0040;PBS_Server;Svr;tyrone-cluster;Scheduler was sent the command new
11/02/2013 20:04:02;0040;PBS_Server;Svr;tyrone-cluster;Scheduler was sent the command new
11/02/2013 20:04:25;0040;PBS_Server;Svr;tyrone-cluster;Scheduler was sent the command new
11/02/2013 20:04:33;0040;PBS_Server;Svr;tyrone-cluster;Scheduler was sent the command new
11/02/2013 20:04:57;0040;PBS_Server;Svr;tyrone-cluster;Scheduler was sent the command new
11/02/2013 20:05:10;0040;PBS_Server;Svr;tyrone-cluster;Scheduler was sent the command new
11/02/2013 20:05:31;0040;PBS_Server;Svr;tyrone-cluster;Scheduler was sent the command new
11/02/2013 20:05:33;0040;PBS_Server;Svr;tyrone-cluster;Scheduler was sent the command new
11/02/2013 20:05:55;0040;PBS_Server;Svr;tyrone-cluster;Scheduler was sent the command new
11/02/2013 20:06:03;0040;PBS_Server;Svr;tyrone-cluster;Scheduler was sent the command new
11/02/2013 20:06:26;0040;PBS_Server;Svr;tyrone-cluster;Scheduler was sent the command new
11/02/2013 20:06:40;0040;PBS_Server;Svr;tyrone-cluster;Scheduler was sent the command new
11/02/2013 20:07:02;0040;PBS_Server;Svr;tyrone-cluster;Scheduler was sent the command new
11/02/2013 20:07:11;0040;PBS_Server;Svr;tyrone-cluster;Scheduler was sent the command new
11/02/2013 20:07:25;0040;PBS_Server;Svr;tyrone-cluster;Scheduler was sent the command new
11/02/2013 20:07:29;0100;PBS_Server;Job;31434.tyrone-cluster;enqueuing into batch, state 1 hop 1
11/02/2013 20:07:29;0100;PBS_Server;Job;31434.tyrone-cluster;dequeuing from batch, state QUEUED
11/02/2013 20:07:29;0100;PBS_Server;Job;31434.tyrone-cluster;enqueuing into qp128, state 1 hop 1
11/02/2013 20:07:29;0008;PBS_Server;Job;31434.tyrone-cluster;Job Queued at request of secbadar@tyrone-cluster, owner = secbadar@tyrone-cluster, job name = 128Edge4, queue = qp128
11/02/2013 20:07:29;0040;PBS_Server;Svr;tyrone-cluster;Scheduler was sent the command new
11/02/2013 20:07:29;0008;PBS_Server;Job;31434.tyrone-cluster;Job Modified at request of Scheduler@tyrone-cluster
11/02/2013 20:07:29;0008;PBS_Server;Job;31434.tyrone-cluster;Job Run at request of Scheduler@tyrone-cluster
11/02/2013 20:07:29;0040;PBS_Server;Svr;tyrone-cluster;Scheduler was sent the command recyc
11/02/2013 20:07:42;0002;PBS_Server;Svr;PBS_Server;Torque Server Version = 3.0.5, loglevel = 0
11/02/2013 20:07:47;0040;PBS_Server;Svr;tyrone-cluster;Scheduler was sent the command new
11/02/2013 20:07:56;0040;PBS_Server;Svr;tyrone-cluster;Scheduler was sent the command new
11/02/2013 20:07:58;000d;PBS_Server;Job;31434.tyrone-cluster;Not sending email: User does not want mail of this type.
11/02/2013 20:08:14;0040;PBS_Server;Svr;tyrone-cluster;Scheduler was sent the command new
11/02/2013 20:08:32;0040;PBS_Server;Svr;tyrone-cluster;Scheduler was sent the command new
11/02/2013 20:08:42;0040;PBS_Server;Svr;tyrone-cluster;Scheduler was sent the command new
11/02/2013 20:08:55;0040;PBS_Server;Svr;tyrone-cluster;Scheduler was sent the command new
11/02/2013 20:09:17;0040;PBS_Server;Svr;tyrone-cluster;Scheduler was sent the command new
11/02/2013 20:09:48;0040;PBS_Server;Svr;tyrone-cluster;Scheduler was sent the command new
11/02/2013 20:10:02;0040;PBS_Server;Svr;tyrone-cluster;Scheduler was sent the command new
11/02/2013 20:10:25;0040;PBS_Server;Svr;tyrone-cluster;Scheduler was sent the command new
11/02/2013 20:10:47;0040;PBS_Server;Svr;tyrone-cluster;Scheduler was sent the command new
11/02/2013 20:10:56;0040;PBS_Server;Svr;tyrone-cluster;Scheduler was sent the command new
11/02/2013 20:11:18;0040;PBS_Server;Svr;tyrone-cluster;Scheduler was sent the command new
11/02/2013 20:11:32;0040;PBS_Server;Svr;tyrone-cluster;Scheduler was sent the command new
11/02/2013 20:11:48;0040;PBS_Server;Svr;tyrone-cluster;Scheduler was sent the command new
11/02/2013 20:11:55;0040;PBS_Server;Svr;tyrone-cluster;Scheduler was sent the command new
11/02/2013 20:11:56;0010;PBS_Server;Job;31376.tyrone-cluster;Exit_status=143 resources_used.cput=111:50:06 resources_used.mem=64281960kb resources_used.vmem=158591416kb resources_used.walltime=24:01:20
11/02/2013 20:11:56;0008;PBS_Server;Job;NULL;on_job_exit valid pjob: 0x31f6020 (substate=50)
11/02/2013 20:11:56;0008;PBS_Server;Job;NULL;on_job_exit valid pjob: 0x31f6020 (substate=51)
11/02/2013 20:11:57;0008;PBS_Server;Job;NULL;on_job_exit valid pjob: 0x31f6020 (substate=51)
11/02/2013 20:11:57;0008;PBS_Server;Job;NULL;on_job_exit valid pjob: 0x31f6020 (substate=53)
11/02/2013 20:11:57;0100;PBS_Server;Job;31376.tyrone-cluster;dequeuing from qp32, state COMPLETE
11/02/2013 20:11:57;0040;PBS_Server;Svr;tyrone-cluster;Scheduler was sent the command term
11/02/2013 20:11:57;0008;PBS_Server;Job;31336.tyrone-cluster;Job Modified at request of Scheduler@tyrone-cluster
11/02/2013 20:11:57;0008;PBS_Server;Job;31377.tyrone-cluster;Job Modified at request of Scheduler@tyrone-cluster
11/02/2013 20:11:57;0008;PBS_Server;Job;31377.tyrone-cluster;Job Run at request of Scheduler@tyrone-cluster
11/02/2013 20:11:58;0040;PBS_Server;Svr;tyrone-cluster;Scheduler was sent the command recyc
11/02/2013 20:12:17;0040;PBS_Server;Svr;tyrone-cluster;Scheduler was sent the command new
11/02/2013 20:12:17;0008;PBS_Server;Job;31336.tyrone-cluster;Job Modified at request of Scheduler@tyrone-cluster
11/02/2013 20:12:26;0040;PBS_Server;Svr;tyrone-cluster;Scheduler was sent the command new
11/02/2013 20:12:42;0002;PBS_Server;Svr;PBS_Server;Torque Server Version = 3.0.5, loglevel = 0
11/02/2013 20:12:47;0040;PBS_Server;Svr;tyrone-cluster;Scheduler was sent the command new
11/02/2013 20:13:02;0040;PBS_Server;Svr;tyrone-cluster;Scheduler was sent the command new
11/02/2013 20:13:25;0040;PBS_Server;Svr;tyrone-cluster;Scheduler was sent the command new
11/02/2013 20:13:48;0040;PBS_Server;Svr;tyrone-cluster;Scheduler was sent the command new
11/02/2013 20:13:56;0040;PBS_Server;Svr;tyrone-cluster;Scheduler was sent the command new
11/02/2013 20:14:20;0040;PBS_Server;Svr;tyrone-cluster;Scheduler was sent the command new
11/02/2013 20:14:32;0040;PBS_Server;Svr;tyrone-cluster;Scheduler was sent the command new
11/02/2013 20:14:49;0040;PBS_Server;Svr;tyrone-cluster;Scheduler was sent the command new
11/02/2013 20:15:03;0040;PBS_Server;Svr;tyrone-cluster;Scheduler was sent the command new
11/02/2013 20:15:20;0040;PBS_Server;Svr;tyrone-cluster;Scheduler was sent the command new
11/02/2013 20:15:37;0040;PBS_Server;Svr;tyrone-cluster;Scheduler was sent the command new
11/02/2013 20:15:37;0020;PBS_Server;Job;31232.tyrone-cluster;Unauthorized Request, request type: 6, Object: Job, Name: 31232.tyrone-cluster, request from: ecesmndl@tyrone-cluster
11/02/2013 20:15:37;0080;PBS_Server;Req;req_reject;Reject reply code=15007(Unauthorized Request  MSG=operation not permitted), aux=0, type=DeleteJob, from ecesmndl@tyrone-cluster
11/02/2013 20:15:37;0020;PBS_Server;Job;31233.tyrone-cluster;Unauthorized Request, request type: 6, Object: Job, Name: 31233.tyrone-cluster, request from: ecesmndl@tyrone-cluster
11/02/2013 20:15:37;0080;PBS_Server;Req;req_reject;Reject reply code=15007(Unauthorized Request  MSG=operation not permitted), aux=0, type=DeleteJob, from ecesmndl@tyrone-cluster
11/02/2013 20:15:37;0020;PBS_Server;Job;31324.tyrone-cluster;Unauthorized Request, request type: 6, Object: Job, Name: 31324.tyrone-cluster, request from: ecesmndl@tyrone-cluster
11/02/2013 20:15:37;0080;PBS_Server;Req;req_reject;Reject reply code=15007(Unauthorized Request  MSG=operation not permitted), aux=0, type=DeleteJob, from ecesmndl@tyrone-cluster
11/02/2013 20:15:37;0020;PBS_Server;Job;31327.tyrone-cluster;Unauthorized Request, request type: 6, Object: Job, Name: 31327.tyrone-cluster, request from: ecesmndl@tyrone-cluster
11/02/2013 20:15:37;0080;PBS_Server;Req;req_reject;Reject reply code=15007(Unauthorized Request  MSG=operation not permitted), aux=0, type=DeleteJob, from ecesmndl@tyrone-cluster
11/02/2013 20:15:37;0020;PBS_Server;Job;31335.tyrone-cluster;Unauthorized Request, request type: 6, Object: Job, Name: 31335.tyrone-cluster, request from: ecesmndl@tyrone-cluster
11/02/2013 20:15:37;0080;PBS_Server;Req;req_reject;Reject reply code=15007(Unauthorized Request  MSG=operation not permitted), aux=0, type=DeleteJob, from ecesmndl@tyrone-cluster
11/02/2013 20:15:37;0020;PBS_Server;Job;31336.tyrone-cluster;Unauthorized Request, request type: 6, Object: Job, Name: 31336.tyrone-cluster, request from: ecesmndl@tyrone-cluster
11/02/2013 20:15:37;0080;PBS_Server;Req;req_reject;Reject reply code=15007(Unauthorized Request  MSG=operation not permitted), aux=0, type=DeleteJob, from ecesmndl@tyrone-cluster
11/02/2013 20:15:37;0020;PBS_Server;Job;31348.tyrone-cluster;Unauthorized Request, request type: 6, Object: Job, Name: 31348.tyrone-cluster, request from: ecesmndl@tyrone-cluster
11/02/2013 20:15:37;0080;PBS_Server;Req;req_reject;Reject reply code=15007(Unauthorized Request  MSG=operation not permitted), aux=0, type=DeleteJob, from ecesmndl@tyrone-cluster
11/02/2013 20:15:37;0008;PBS_Server;Job;31377.tyrone-cluster;Job deleted at request of ecesmndl@tyrone-cluster
11/02/2013 20:15:37;0008;PBS_Server;Job;31377.tyrone-cluster;Job sent signal SIGTERM on delete
11/02/2013 20:15:37;0008;PBS_Server;Job;31378.tyrone-cluster;Job deleted at request of ecesmndl@tyrone-cluster
11/02/2013 20:15:37;0008;PBS_Server;Job;NULL;on_job_exit valid pjob: 0x2f96c00 (substate=59)
11/02/2013 20:15:37;0100;PBS_Server;Job;31378.tyrone-cluster;dequeuing from qp32, state COMPLETE
11/02/2013 20:15:37;0020;PBS_Server;Job;31325.tyrone-cluster;Unauthorized Request, request type: 6, Object: Job, Name: 31325.tyrone-cluster, request from: ecesmndl@tyrone-cluster
11/02/2013 20:15:37;0080;PBS_Server;Req;req_reject;Reject reply code=15007(Unauthorized Request  MSG=operation not permitted), aux=0, type=DeleteJob, from ecesmndl@tyrone-cluster
11/02/2013 20:15:37;0020;PBS_Server;Job;31349.tyrone-cluster;Unauthorized Request, request type: 6, Object: Job, Name: 31349.tyrone-cluster, request from: ecesmndl@tyrone-cluster
11/02/2013 20:15:37;0080;PBS_Server;Req;req_reject;Reject reply code=15007(Unauthorized Request  MSG=operation not permitted), aux=0, type=DeleteJob, from ecesmndl@tyrone-cluster
11/02/2013 20:15:37;0020;PBS_Server;Job;31234.tyrone-cluster;Unauthorized Request, request type: 6, Object: Job, Name: 31234.tyrone-cluster, request from: ecesmndl@tyrone-cluster
11/02/2013 20:15:37;0080;PBS_Server;Req;req_reject;Reject reply code=15007(Unauthorized Request  MSG=operation not permitted), aux=0, type=DeleteJob, from ecesmndl@tyrone-cluster
11/02/2013 20:15:37;0020;PBS_Server;Job;31337.tyrone-cluster;Unauthorized Request, request type: 6, Object: Job, Name: 31337.tyrone-cluster, request from: ecesmndl@tyrone-cluster
11/02/2013 20:15:37;0080;PBS_Server;Req;req_reject;Reject reply code=15007(Unauthorized Request  MSG=operation not permitted), aux=0, type=DeleteJob, from ecesmndl@tyrone-cluster
11/02/2013 20:15:37;0020;PBS_Server;Job;31402.tyrone-cluster;Unauthorized Request, request type: 6, Object: Job, Name: 31402.tyrone-cluster, request from: ecesmndl@tyrone-cluster
11/02/2013 20:15:37;0080;PBS_Server;Req;req_reject;Reject reply code=15007(Unauthorized Request  MSG=operation not permitted), aux=0, type=DeleteJob, from ecesmndl@tyrone-cluster
11/02/2013 20:15:37;0020;PBS_Server;Job;31407.tyrone-cluster;Unauthorized Request, request type: 6, Object: Job, Name: 31407.tyrone-cluster, request from: ecesmndl@tyrone-cluster
11/02/2013 20:15:37;0080;PBS_Server;Req;req_reject;Reject reply code=15007(Unauthorized Request  MSG=operation not permitted), aux=0, type=DeleteJob, from ecesmndl@tyrone-cluster
11/02/2013 20:15:37;0020;PBS_Server;Job;31408.tyrone-cluster;Unauthorized Request, request type: 6, Object: Job, Name: 31408.tyrone-cluster, request from: ecesmndl@tyrone-cluster
11/02/2013 20:15:37;0080;PBS_Server;Req;req_reject;Reject reply code=15007(Unauthorized Request  MSG=operation not permitted), aux=0, type=DeleteJob, from ecesmndl@tyrone-cluster
11/02/2013 20:15:37;0020;PBS_Server;Job;31409.tyrone-cluster;Unauthorized Request, request type: 6, Object: Job, Name: 31409.tyrone-cluster, request from: ecesmndl@tyrone-cluster
11/02/2013 20:15:37;0080;PBS_Server;Req;req_reject;Reject reply code=15007(Unauthorized Request  MSG=operation not permitted), aux=0, type=DeleteJob, from ecesmndl@tyrone-cluster
11/02/2013 20:15:37;0020;PBS_Server;Job;31410.tyrone-cluster;Unauthorized Request, request type: 6, Object: Job, Name: 31410.tyrone-cluster, request from: ecesmndl@tyrone-cluster
11/02/2013 20:15:37;0080;PBS_Server;Req;req_reject;Reject reply code=15007(Unauthorized Request  MSG=operation not permitted), aux=0, type=DeleteJob, from ecesmndl@tyrone-cluster
11/02/2013 20:15:37;0020;PBS_Server;Job;31411.tyrone-cluster;Unauthorized Request, request type: 6, Object: Job, Name: 31411.tyrone-cluster, request from: ecesmndl@tyrone-cluster
11/02/2013 20:15:37;0080;PBS_Server;Req;req_reject;Reject reply code=15007(Unauthorized Request  MSG=operation not permitted), aux=0, type=DeleteJob, from ecesmndl@tyrone-cluster
11/02/2013 20:15:37;0020;PBS_Server;Job;31412.tyrone-cluster;Unauthorized Request, request type: 6, Object: Job, Name: 31412.tyrone-cluster, request from: ecesmndl@tyrone-cluster
11/02/2013 20:15:37;0080;PBS_Server;Req;req_reject;Reject reply code=15007(Unauthorized Request  MSG=operation not permitted), aux=0, type=DeleteJob, from ecesmndl@tyrone-cluster
11/02/2013 20:15:37;0020;PBS_Server;Job;31413.tyrone-cluster;Unauthorized Request, request type: 6, Object: Job, Name: 31413.tyrone-cluster, request from: ecesmndl@tyrone-cluster
11/02/2013 20:15:37;0080;PBS_Server;Req;req_reject;Reject reply code=15007(Unauthorized Request  MSG=operation not permitted), aux=0, type=DeleteJob, from ecesmndl@tyrone-cluster
11/02/2013 20:15:37;0020;PBS_Server;Job;31414.tyrone-cluster;Unauthorized Request, request type: 6, Object: Job, Name: 31414.tyrone-cluster, request from: ecesmndl@tyrone-cluster
11/02/2013 20:15:37;0080;PBS_Server;Req;req_reject;Reject reply code=15007(Unauthorized Request  MSG=operation not permitted), aux=0, type=DeleteJob, from ecesmndl@tyrone-cluster
11/02/2013 20:15:37;0020;PBS_Server;Job;31417.tyrone-cluster;Unauthorized Request, request type: 6, Object: Job, Name: 31417.tyrone-cluster, request from: ecesmndl@tyrone-cluster
11/02/2013 20:15:37;0080;PBS_Server;Req;req_reject;Reject reply code=15007(Unauthorized Request  MSG=operation not permitted), aux=0, type=DeleteJob, from ecesmndl@tyrone-cluster
11/02/2013 20:15:37;0020;PBS_Server;Job;31326.tyrone-cluster;Unauthorized Request, request type: 6, Object: Job, Name: 31326.tyrone-cluster, request from: ecesmndl@tyrone-cluster
11/02/2013 20:15:37;0080;PBS_Server;Req;req_reject;Reject reply code=15007(Unauthorized Request  MSG=operation not permitted), aux=0, type=DeleteJob, from ecesmndl@tyrone-cluster
11/02/2013 20:15:37;0020;PBS_Server;Job;31350.tyrone-cluster;Unauthorized Request, request type: 6, Object: Job, Name: 31350.tyrone-cluster, request from: ecesmndl@tyrone-cluster
11/02/2013 20:15:37;0080;PBS_Server;Req;req_reject;Reject reply code=15007(Unauthorized Request  MSG=operation not permitted), aux=0, type=DeleteJob, from ecesmndl@tyrone-cluster
11/02/2013 20:15:37;0020;PBS_Server;Job;31424.tyrone-cluster;Unauthorized Request, request type: 6, Object: Job, Name: 31424.tyrone-cluster, request from: ecesmndl@tyrone-cluster
11/02/2013 20:15:37;0080;PBS_Server;Req;req_reject;Reject reply code=15007(Unauthorized Request  MSG=operation not permitted), aux=0, type=DeleteJob, from ecesmndl@tyrone-cluster
11/02/2013 20:15:37;0020;PBS_Server;Job;31425.tyrone-cluster;Unauthorized Request, request type: 6, Object: Job, Name: 31425.tyrone-cluster, request from: ecesmndl@tyrone-cluster
11/02/2013 20:15:37;0080;PBS_Server;Req;req_reject;Reject reply code=15007(Unauthorized Request  MSG=operation not permitted), aux=0, type=DeleteJob, from ecesmndl@tyrone-cluster
11/02/2013 20:15:37;0020;PBS_Server;Job;31426.tyrone-cluster;Unauthorized Request, request type: 6, Object: Job, Name: 31426.tyrone-cluster, request from: ecesmndl@tyrone-cluster
11/02/2013 20:15:37;0080;PBS_Server;Req;req_reject;Reject reply code=15007(Unauthorized Request  MSG=operation not permitted), aux=0, type=DeleteJob, from ecesmndl@tyrone-cluster
11/02/2013 20:15:37;0020;PBS_Server;Job;31427.tyrone-cluster;Unauthorized Request, request type: 6, Object: Job, Name: 31427.tyrone-cluster, request from: ecesmndl@tyrone-cluster
11/02/2013 20:15:37;0080;PBS_Server;Req;req_reject;Reject reply code=15007(Unauthorized Request  MSG=operation not permitted), aux=0, type=DeleteJob, from ecesmndl@tyrone-cluster
11/02/2013 20:15:37;0020;PBS_Server;Job;31428.tyrone-cluster;Unauthorized Request, request type: 6, Object: Job, Name: 31428.tyrone-cluster, request from: ecesmndl@tyrone-cluster
11/02/2013 20:15:37;0080;PBS_Server;Req;req_reject;Reject reply code=15007(Unauthorized Request  MSG=operation not permitted), aux=0, type=DeleteJob, from ecesmndl@tyrone-cluster
11/02/2013 20:15:37;0020;PBS_Server;Job;31429.tyrone-cluster;Unauthorized Request, request type: 6, Object: Job, Name: 31429.tyrone-cluster, request from: ecesmndl@tyrone-cluster
11/02/2013 20:15:37;0080;PBS_Server;Req;req_reject;Reject reply code=15007(Unauthorized Request  MSG=operation not permitted), aux=0, type=DeleteJob, from ecesmndl@tyrone-cluster
11/02/2013 20:15:37;0020;PBS_Server;Job;31430.tyrone-cluster;Unauthorized Request, request type: 6, Object: Job, Name: 31430.tyrone-cluster, request from: ecesmndl@tyrone-cluster
11/02/2013 20:15:37;0080;PBS_Server;Req;req_reject;Reject reply code=15007(Unauthorized Request  MSG=operation not permitted), aux=0, type=DeleteJob, from ecesmndl@tyrone-cluster
11/02/2013 20:15:37;0020;PBS_Server;Job;31431.tyrone-cluster;Unauthorized Request, request type: 6, Object: Job, Name: 31431.tyrone-cluster, request from: ecesmndl@tyrone-cluster
11/02/2013 20:15:37;0080;PBS_Server;Req;req_reject;Reject reply code=15007(Unauthorized Request  MSG=operation not permitted), aux=0, type=DeleteJob, from ecesmndl@tyrone-cluster
11/02/2013 20:15:37;0020;PBS_Server;Job;31434.tyrone-cluster;Unauthorized Request, request type: 6, Object: Job, Name: 31434.tyrone-cluster, request from: ecesmndl@tyrone-cluster
11/02/2013 20:15:37;0080;PBS_Server;Req;req_reject;Reject reply code=15007(Unauthorized Request  MSG=operation not permitted), aux=0, type=DeleteJob, from ecesmndl@tyrone-cluster
11/02/2013 20:15:37;0010;PBS_Server;Job;31377.tyrone-cluster;Exit_status=143 resources_used.cput=00:25:53 resources_used.mem=244068kb resources_used.vmem=6538712kb resources_used.walltime=00:03:39
11/02/2013 20:15:37;0008;PBS_Server;Job;NULL;on_job_exit valid pjob: 0x31e51d0 (substate=50)
11/02/2013 20:15:37;0008;PBS_Server;Job;NULL;on_job_exit valid pjob: 0x31e51d0 (substate=51)
11/02/2013 20:15:37;0008;PBS_Server;Job;NULL;on_job_exit valid pjob: 0x31e51d0 (substate=51)
11/02/2013 20:15:37;0008;PBS_Server;Job;NULL;on_job_exit valid pjob: 0x31e51d0 (substate=53)
11/02/2013 20:15:37;0100;PBS_Server;Job;31377.tyrone-cluster;dequeuing from qp32, state COMPLETE
11/02/2013 20:15:37;0040;PBS_Server;Svr;tyrone-cluster;Scheduler was sent the command term
11/02/2013 20:15:37;0008;PBS_Server;Job;31336.tyrone-cluster;Job Modified at request of Scheduler@tyrone-cluster
11/02/2013 20:15:37;0008;PBS_Server;Job;31325.tyrone-cluster;Job Modified at request of Scheduler@tyrone-cluster
11/02/2013 20:15:37;0008;PBS_Server;Job;31337.tyrone-cluster;Job Modified at request of Scheduler@tyrone-cluster
11/02/2013 20:15:37;0008;PBS_Server;Job;31408.tyrone-cluster;Job Modified at request of Scheduler@tyrone-cluster
11/02/2013 20:15:37;0008;PBS_Server;Job;31409.tyrone-cluster;Job Modified at request of Scheduler@tyrone-cluster
11/02/2013 20:15:37;0008;PBS_Server;Job;31326.tyrone-cluster;Job Modified at request of Scheduler@tyrone-cluster
11/02/2013 20:15:50;0040;PBS_Server;Svr;tyrone-cluster;Scheduler was sent the command new
11/02/2013 20:16:02;0040;PBS_Server;Svr;tyrone-cluster;Scheduler was sent the command new
11/02/2013 20:16:25;0040;PBS_Server;Svr;tyrone-cluster;Scheduler was sent the command new
11/02/2013 20:16:33;0040;PBS_Server;Svr;tyrone-cluster;Scheduler was sent the command new
11/02/2013 20:16:56;0040;PBS_Server;Svr;tyrone-cluster;Scheduler was sent the command new
11/02/2013 20:17:10;0040;PBS_Server;Svr;tyrone-cluster;Scheduler was sent the command new
11/02/2013 20:17:13;0100;PBS_Server;Job;31435.tyrone-cluster;enqueuing into batch, state 1 hop 1
11/02/2013 20:17:13;0100;PBS_Server;Job;31435.tyrone-cluster;dequeuing from batch, state QUEUED
11/02/2013 20:17:13;0100;PBS_Server;Job;31435.tyrone-cluster;enqueuing into qp32, state 1 hop 1
11/02/2013 20:17:13;0008;PBS_Server;Job;31435.tyrone-cluster;Job Queued at request of ecesmndl@tyrone-cluster, owner = ecesmndl@tyrone-cluster, job name = again, queue = qp32
11/02/2013 20:17:13;0040;PBS_Server;Svr;tyrone-cluster;Scheduler was sent the command new
11/02/2013 20:17:14;0008;PBS_Server;Job;31435.tyrone-cluster;Job Modified at request of Scheduler@tyrone-cluster
11/02/2013 20:17:14;0008;PBS_Server;Job;31435.tyrone-cluster;Job Run at request of Scheduler@tyrone-cluster
11/02/2013 20:17:14;0040;PBS_Server;Svr;tyrone-cluster;Scheduler was sent the command recyc
11/02/2013 20:17:19;0100;PBS_Server;Job;31436.tyrone-cluster;enqueuing into batch, state 1 hop 1
11/02/2013 20:17:19;0100;PBS_Server;Job;31436.tyrone-cluster;dequeuing from batch, state QUEUED
11/02/2013 20:17:19;0100;PBS_Server;Job;31436.tyrone-cluster;enqueuing into qp32, state 1 hop 1
11/02/2013 20:17:19;0008;PBS_Server;Job;31436.tyrone-cluster;Job Queued at request of ecesmndl@tyrone-cluster, owner = ecesmndl@tyrone-cluster, job name = again, queue = qp32
11/02/2013 20:17:19;0040;PBS_Server;Svr;tyrone-cluster;Scheduler was sent the command new
11/02/2013 20:17:19;0008;PBS_Server;Job;31336.tyrone-cluster;Job Modified at request of Scheduler@tyrone-cluster
11/02/2013 20:17:19;0008;PBS_Server;Job;31325.tyrone-cluster;Job Modified at request of Scheduler@tyrone-cluster
11/02/2013 20:17:19;0008;PBS_Server;Job;31337.tyrone-cluster;Job Modified at request of Scheduler@tyrone-cluster
11/02/2013 20:17:19;0008;PBS_Server;Job;31408.tyrone-cluster;Job Modified at request of Scheduler@tyrone-cluster
11/02/2013 20:17:19;0008;PBS_Server;Job;31409.tyrone-cluster;Job Modified at request of Scheduler@tyrone-cluster
11/02/2013 20:17:19;0008;PBS_Server;Job;31326.tyrone-cluster;Job Modified at request of Scheduler@tyrone-cluster
11/02/2013 20:17:19;0008;PBS_Server;Job;31436.tyrone-cluster;Job Modified at request of Scheduler@tyrone-cluster
11/02/2013 20:17:19;0100;PBS_Server;Job;31437.tyrone-cluster;enqueuing into batch, state 1 hop 1
11/02/2013 20:17:19;0100;PBS_Server;Job;31437.tyrone-cluster;dequeuing from batch, state QUEUED
11/02/2013 20:17:19;0100;PBS_Server;Job;31437.tyrone-cluster;enqueuing into qp32, state 1 hop 1
11/02/2013 20:17:19;0008;PBS_Server;Job;31437.tyrone-cluster;Job Queued at request of ecesmndl@tyrone-cluster, owner = ecesmndl@tyrone-cluster, job name = again, queue = qp32
11/02/2013 20:17:19;0040;PBS_Server;Svr;tyrone-cluster;Scheduler was sent the command new
11/02/2013 20:17:19;0008;PBS_Server;Job;31437.tyrone-cluster;Job Modified at request of Scheduler@tyrone-cluster
11/02/2013 20:17:32;0040;PBS_Server;Svr;tyrone-cluster;Scheduler was sent the command new
11/02/2013 20:17:35;0020;PBS_Server;Job;31232.tyrone-cluster;Unauthorized Request, request type: 6, Object: Job, Name: 31232.tyrone-cluster, request from: ecesmndl@tyrone-cluster
11/02/2013 20:17:35;0080;PBS_Server;Req;req_reject;Reject reply code=15007(Unauthorized Request  MSG=operation not permitted), aux=0, type=DeleteJob, from ecesmndl@tyrone-cluster
11/02/2013 20:17:35;0020;PBS_Server;Job;31233.tyrone-cluster;Unauthorized Request, request type: 6, Object: Job, Name: 31233.tyrone-cluster, request from: ecesmndl@tyrone-cluster
11/02/2013 20:17:35;0080;PBS_Server;Req;req_reject;Reject reply code=15007(Unauthorized Request  MSG=operation not permitted), aux=0, type=DeleteJob, from ecesmndl@tyrone-cluster
11/02/2013 20:17:35;0020;PBS_Server;Job;31324.tyrone-cluster;Unauthorized Request, request type: 6, Object: Job, Name: 31324.tyrone-cluster, request from: ecesmndl@tyrone-cluster
11/02/2013 20:17:35;0080;PBS_Server;Req;req_reject;Reject reply code=15007(Unauthorized Request  MSG=operation not permitted), aux=0, type=DeleteJob, from ecesmndl@tyrone-cluster
11/02/2013 20:17:35;0020;PBS_Server;Job;31327.tyrone-cluster;Unauthorized Request, request type: 6, Object: Job, Name: 31327.tyrone-cluster, request from: ecesmndl@tyrone-cluster
11/02/2013 20:17:35;0080;PBS_Server;Req;req_reject;Reject reply code=15007(Unauthorized Request  MSG=operation not permitted), aux=0, type=DeleteJob, from ecesmndl@tyrone-cluster
11/02/2013 20:17:35;0020;PBS_Server;Job;31335.tyrone-cluster;Unauthorized Request, request type: 6, Object: Job, Name: 31335.tyrone-cluster, request from: ecesmndl@tyrone-cluster
11/02/2013 20:17:35;0080;PBS_Server;Req;req_reject;Reject reply code=15007(Unauthorized Request  MSG=operation not permitted), aux=0, type=DeleteJob, from ecesmndl@tyrone-cluster
11/02/2013 20:17:35;0020;PBS_Server;Job;31336.tyrone-cluster;Unauthorized Request, request type: 6, Object: Job, Name: 31336.tyrone-cluster, request from: ecesmndl@tyrone-cluster
11/02/2013 20:17:35;0080;PBS_Server;Req;req_reject;Reject reply code=15007(Unauthorized Request  MSG=operation not permitted), aux=0, type=DeleteJob, from ecesmndl@tyrone-cluster
11/02/2013 20:17:35;0020;PBS_Server;Job;31348.tyrone-cluster;Unauthorized Request, request type: 6, Object: Job, Name: 31348.tyrone-cluster, request from: ecesmndl@tyrone-cluster
11/02/2013 20:17:35;0080;PBS_Server;Req;req_reject;Reject reply code=15007(Unauthorized Request  MSG=operation not permitted), aux=0, type=DeleteJob, from ecesmndl@tyrone-cluster
11/02/2013 20:17:35;0020;PBS_Server;Job;31325.tyrone-cluster;Unauthorized Request, request type: 6, Object: Job, Name: 31325.tyrone-cluster, request from: ecesmndl@tyrone-cluster
11/02/2013 20:17:35;0080;PBS_Server;Req;req_reject;Reject reply code=15007(Unauthorized Request  MSG=operation not permitted), aux=0, type=DeleteJob, from ecesmndl@tyrone-cluster
11/02/2013 20:17:35;0020;PBS_Server;Job;31349.tyrone-cluster;Unauthorized Request, request type: 6, Object: Job, Name: 31349.tyrone-cluster, request from: ecesmndl@tyrone-cluster
11/02/2013 20:17:35;0080;PBS_Server;Req;req_reject;Reject reply code=15007(Unauthorized Request  MSG=operation not permitted), aux=0, type=DeleteJob, from ecesmndl@tyrone-cluster
11/02/2013 20:17:35;0020;PBS_Server;Job;31234.tyrone-cluster;Unauthorized Request, request type: 6, Object: Job, Name: 31234.tyrone-cluster, request from: ecesmndl@tyrone-cluster
11/02/2013 20:17:35;0080;PBS_Server;Req;req_reject;Reject reply code=15007(Unauthorized Request  MSG=operation not permitted), aux=0, type=DeleteJob, from ecesmndl@tyrone-cluster
11/02/2013 20:17:35;0020;PBS_Server;Job;31337.tyrone-cluster;Unauthorized Request, request type: 6, Object: Job, Name: 31337.tyrone-cluster, request from: ecesmndl@tyrone-cluster
11/02/2013 20:17:35;0080;PBS_Server;Req;req_reject;Reject reply code=15007(Unauthorized Request  MSG=operation not permitted), aux=0, type=DeleteJob, from ecesmndl@tyrone-cluster
11/02/2013 20:17:35;0020;PBS_Server;Job;31402.tyrone-cluster;Unauthorized Request, request type: 6, Object: Job, Name: 31402.tyrone-cluster, request from: ecesmndl@tyrone-cluster
11/02/2013 20:17:35;0080;PBS_Server;Req;req_reject;Reject reply code=15007(Unauthorized Request  MSG=operation not permitted), aux=0, type=DeleteJob, from ecesmndl@tyrone-cluster
11/02/2013 20:17:35;0020;PBS_Server;Job;31407.tyrone-cluster;Unauthorized Request, request type: 6, Object: Job, Name: 31407.tyrone-cluster, request from: ecesmndl@tyrone-cluster
11/02/2013 20:17:35;0080;PBS_Server;Req;req_reject;Reject reply code=15007(Unauthorized Request  MSG=operation not permitted), aux=0, type=DeleteJob, from ecesmndl@tyrone-cluster
11/02/2013 20:17:35;0020;PBS_Server;Job;31408.tyrone-cluster;Unauthorized Request, request type: 6, Object: Job, Name: 31408.tyrone-cluster, request from: ecesmndl@tyrone-cluster
11/02/2013 20:17:35;0080;PBS_Server;Req;req_reject;Reject reply code=15007(Unauthorized Request  MSG=operation not permitted), aux=0, type=DeleteJob, from ecesmndl@tyrone-cluster
11/02/2013 20:17:35;0020;PBS_Server;Job;31409.tyrone-cluster;Unauthorized Request, request type: 6, Object: Job, Name: 31409.tyrone-cluster, request from: ecesmndl@tyrone-cluster
11/02/2013 20:17:35;0080;PBS_Server;Req;req_reject;Reject reply code=15007(Unauthorized Request  MSG=operation not permitted), aux=0, type=DeleteJob, from ecesmndl@tyrone-cluster
11/02/2013 20:17:35;0020;PBS_Server;Job;31410.tyrone-cluster;Unauthorized Request, request type: 6, Object: Job, Name: 31410.tyrone-cluster, request from: ecesmndl@tyrone-cluster
11/02/2013 20:17:35;0080;PBS_Server;Req;req_reject;Reject reply code=15007(Unauthorized Request  MSG=operation not permitted), aux=0, type=DeleteJob, from ecesmndl@tyrone-cluster
11/02/2013 20:17:35;0020;PBS_Server;Job;31411.tyrone-cluster;Unauthorized Request, request type: 6, Object: Job, Name: 31411.tyrone-cluster, request from: ecesmndl@tyrone-cluster
11/02/2013 20:17:35;0080;PBS_Server;Req;req_reject;Reject reply code=15007(Unauthorized Request  MSG=operation not permitted), aux=0, type=DeleteJob, from ecesmndl@tyrone-cluster
11/02/2013 20:17:35;0020;PBS_Server;Job;31412.tyrone-cluster;Unauthorized Request, request type: 6, Object: Job, Name: 31412.tyrone-cluster, request from: ecesmndl@tyrone-cluster
11/02/2013 20:17:35;0080;PBS_Server;Req;req_reject;Reject reply code=15007(Unauthorized Request  MSG=operation not permitted), aux=0, type=DeleteJob, from ecesmndl@tyrone-cluster
11/02/2013 20:17:35;0020;PBS_Server;Job;31413.tyrone-cluster;Unauthorized Request, request type: 6, Object: Job, Name: 31413.tyrone-cluster, request from: ecesmndl@tyrone-cluster
11/02/2013 20:17:35;0080;PBS_Server;Req;req_reject;Reject reply code=15007(Unauthorized Request  MSG=operation not permitted), aux=0, type=DeleteJob, from ecesmndl@tyrone-cluster
11/02/2013 20:17:35;0020;PBS_Server;Job;31414.tyrone-cluster;Unauthorized Request, request type: 6, Object: Job, Name: 31414.tyrone-cluster, request from: ecesmndl@tyrone-cluster
11/02/2013 20:17:35;0080;PBS_Server;Req;req_reject;Reject reply code=15007(Unauthorized Request  MSG=operation not permitted), aux=0, type=DeleteJob, from ecesmndl@tyrone-cluster
11/02/2013 20:17:35;0020;PBS_Server;Job;31417.tyrone-cluster;Unauthorized Request, request type: 6, Object: Job, Name: 31417.tyrone-cluster, request from: ecesmndl@tyrone-cluster
11/02/2013 20:17:35;0080;PBS_Server;Req;req_reject;Reject reply code=15007(Unauthorized Request  MSG=operation not permitted), aux=0, type=DeleteJob, from ecesmndl@tyrone-cluster
11/02/2013 20:17:35;0020;PBS_Server;Job;31326.tyrone-cluster;Unauthorized Request, request type: 6, Object: Job, Name: 31326.tyrone-cluster, request from: ecesmndl@tyrone-cluster
11/02/2013 20:17:35;0080;PBS_Server;Req;req_reject;Reject reply code=15007(Unauthorized Request  MSG=operation not permitted), aux=0, type=DeleteJob, from ecesmndl@tyrone-cluster
11/02/2013 20:17:35;0020;PBS_Server;Job;31350.tyrone-cluster;Unauthorized Request, request type: 6, Object: Job, Name: 31350.tyrone-cluster, request from: ecesmndl@tyrone-cluster
11/02/2013 20:17:35;0080;PBS_Server;Req;req_reject;Reject reply code=15007(Unauthorized Request  MSG=operation not permitted), aux=0, type=DeleteJob, from ecesmndl@tyrone-cluster
11/02/2013 20:17:35;0020;PBS_Server;Job;31424.tyrone-cluster;Unauthorized Request, request type: 6, Object: Job, Name: 31424.tyrone-cluster, request from: ecesmndl@tyrone-cluster
11/02/2013 20:17:35;0080;PBS_Server;Req;req_reject;Reject reply code=15007(Unauthorized Request  MSG=operation not permitted), aux=0, type=DeleteJob, from ecesmndl@tyrone-cluster
11/02/2013 20:17:35;0020;PBS_Server;Job;31425.tyrone-cluster;Unauthorized Request, request type: 6, Object: Job, Name: 31425.tyrone-cluster, request from: ecesmndl@tyrone-cluster
11/02/2013 20:17:35;0080;PBS_Server;Req;req_reject;Reject reply code=15007(Unauthorized Request  MSG=operation not permitted), aux=0, type=DeleteJob, from ecesmndl@tyrone-cluster
11/02/2013 20:17:35;0020;PBS_Server;Job;31426.tyrone-cluster;Unauthorized Request, request type: 6, Object: Job, Name: 31426.tyrone-cluster, request from: ecesmndl@tyrone-cluster
11/02/2013 20:17:35;0080;PBS_Server;Req;req_reject;Reject reply code=15007(Unauthorized Request  MSG=operation not permitted), aux=0, type=DeleteJob, from ecesmndl@tyrone-cluster
11/02/2013 20:17:35;0020;PBS_Server;Job;31427.tyrone-cluster;Unauthorized Request, request type: 6, Object: Job, Name: 31427.tyrone-cluster, request from: ecesmndl@tyrone-cluster
11/02/2013 20:17:35;0080;PBS_Server;Req;req_reject;Reject reply code=15007(Unauthorized Request  MSG=operation not permitted), aux=0, type=DeleteJob, from ecesmndl@tyrone-cluster
11/02/2013 20:17:35;0020;PBS_Server;Job;31428.tyrone-cluster;Unauthorized Request, request type: 6, Object: Job, Name: 31428.tyrone-cluster, request from: ecesmndl@tyrone-cluster
11/02/2013 20:17:35;0080;PBS_Server;Req;req_reject;Reject reply code=15007(Unauthorized Request  MSG=operation not permitted), aux=0, type=DeleteJob, from ecesmndl@tyrone-cluster
11/02/2013 20:17:35;0020;PBS_Server;Job;31429.tyrone-cluster;Unauthorized Request, request type: 6, Object: Job, Name: 31429.tyrone-cluster, request from: ecesmndl@tyrone-cluster
11/02/2013 20:17:35;0080;PBS_Server;Req;req_reject;Reject reply code=15007(Unauthorized Request  MSG=operation not permitted), aux=0, type=DeleteJob, from ecesmndl@tyrone-cluster
11/02/2013 20:17:35;0020;PBS_Server;Job;31430.tyrone-cluster;Unauthorized Request, request type: 6, Object: Job, Name: 31430.tyrone-cluster, request from: ecesmndl@tyrone-cluster
11/02/2013 20:17:35;0080;PBS_Server;Req;req_reject;Reject reply code=15007(Unauthorized Request  MSG=operation not permitted), aux=0, type=DeleteJob, from ecesmndl@tyrone-cluster
11/02/2013 20:17:35;0020;PBS_Server;Job;31431.tyrone-cluster;Unauthorized Request, request type: 6, Object: Job, Name: 31431.tyrone-cluster, request from: ecesmndl@tyrone-cluster
11/02/2013 20:17:35;0080;PBS_Server;Req;req_reject;Reject reply code=15007(Unauthorized Request  MSG=operation not permitted), aux=0, type=DeleteJob, from ecesmndl@tyrone-cluster
11/02/2013 20:17:35;0020;PBS_Server;Job;31434.tyrone-cluster;Unauthorized Request, request type: 6, Object: Job, Name: 31434.tyrone-cluster, request from: ecesmndl@tyrone-cluster
11/02/2013 20:17:35;0080;PBS_Server;Req;req_reject;Reject reply code=15007(Unauthorized Request  MSG=operation not permitted), aux=0, type=DeleteJob, from ecesmndl@tyrone-cluster
11/02/2013 20:17:35;0008;PBS_Server;Job;31435.tyrone-cluster;Job deleted at request of ecesmndl@tyrone-cluster
11/02/2013 20:17:35;0008;PBS_Server;Job;31435.tyrone-cluster;Job sent signal SIGTERM on delete
11/02/2013 20:17:35;0008;PBS_Server;Job;31436.tyrone-cluster;Job deleted at request of ecesmndl@tyrone-cluster
11/02/2013 20:17:35;0008;PBS_Server;Job;NULL;on_job_exit valid pjob: 0x31e51d0 (substate=59)
11/02/2013 20:17:35;0100;PBS_Server;Job;31436.tyrone-cluster;dequeuing from qp32, state COMPLETE
11/02/2013 20:17:35;0040;PBS_Server;Svr;tyrone-cluster;Scheduler was sent the command term
11/02/2013 20:17:35;0008;PBS_Server;Job;31437.tyrone-cluster;Job deleted at request of ecesmndl@tyrone-cluster
11/02/2013 20:17:35;0008;PBS_Server;Job;NULL;on_job_exit valid pjob: 0x2e26c30 (substate=59)
11/02/2013 20:17:35;0100;PBS_Server;Job;31437.tyrone-cluster;dequeuing from qp32, state COMPLETE
11/02/2013 20:17:35;0010;PBS_Server;Job;31435.tyrone-cluster;Exit_status=143 resources_used.cput=00:00:00 resources_used.mem=0kb resources_used.vmem=0kb resources_used.walltime=00:00:21
11/02/2013 20:17:35;0008;PBS_Server;Job;NULL;on_job_exit valid pjob: 0x31f6020 (substate=50)
11/02/2013 20:17:35;0008;PBS_Server;Job;NULL;on_job_exit valid pjob: 0x31f6020 (substate=51)
11/02/2013 20:17:35;0008;PBS_Server;Job;31336.tyrone-cluster;Job Modified at request of Scheduler@tyrone-cluster
11/02/2013 20:17:35;0008;PBS_Server;Job;31325.tyrone-cluster;Job Modified at request of Scheduler@tyrone-cluster
11/02/2013 20:17:35;0008;PBS_Server;Job;31337.tyrone-cluster;Job Modified at request of Scheduler@tyrone-cluster
11/02/2013 20:17:35;0008;PBS_Server;Job;31408.tyrone-cluster;Job Modified at request of Scheduler@tyrone-cluster
11/02/2013 20:17:35;0008;PBS_Server;Job;31409.tyrone-cluster;Job Modified at request of Scheduler@tyrone-cluster
11/02/2013 20:17:35;0008;PBS_Server;Job;31326.tyrone-cluster;Job Modified at request of Scheduler@tyrone-cluster
11/02/2013 20:17:35;0008;PBS_Server;Job;NULL;on_job_exit valid pjob: 0x31f6020 (substate=51)
11/02/2013 20:17:35;0008;PBS_Server;Job;NULL;on_job_exit valid pjob: 0x31f6020 (substate=53)
11/02/2013 20:17:35;0100;PBS_Server;Job;31435.tyrone-cluster;dequeuing from qp32, state COMPLETE
11/02/2013 20:17:35;0040;PBS_Server;Svr;tyrone-cluster;Scheduler was sent the command term
11/02/2013 20:17:42;0002;PBS_Server;Svr;PBS_Server;Torque Server Version = 3.0.5, loglevel = 0
11/02/2013 20:18:01;0100;PBS_Server;Job;31438.tyrone-cluster;enqueuing into batch, state 1 hop 1
11/02/2013 20:18:01;0100;PBS_Server;Job;31438.tyrone-cluster;dequeuing from batch, state QUEUED
11/02/2013 20:18:01;0100;PBS_Server;Job;31438.tyrone-cluster;enqueuing into qp32, state 1 hop 1
11/02/2013 20:18:01;0008;PBS_Server;Job;31438.tyrone-cluster;Job Queued at request of ecesmndl@tyrone-cluster, owner = ecesmndl@tyrone-cluster, job name = again, queue = qp32
11/02/2013 20:18:01;0040;PBS_Server;Svr;tyrone-cluster;Scheduler was sent the command new
11/02/2013 20:18:01;0008;PBS_Server;Job;31438.tyrone-cluster;Job Modified at request of Scheduler@tyrone-cluster
11/02/2013 20:18:01;0008;PBS_Server;Job;31438.tyrone-cluster;Job Run at request of Scheduler@tyrone-cluster
11/02/2013 20:18:01;0040;PBS_Server;Svr;tyrone-cluster;Scheduler was sent the command recyc
11/02/2013 20:18:01;0100;PBS_Server;Job;31439.tyrone-cluster;enqueuing into batch, state 1 hop 1
11/02/2013 20:18:01;0100;PBS_Server;Job;31439.tyrone-cluster;dequeuing from batch, state QUEUED
11/02/2013 20:18:01;0100;PBS_Server;Job;31439.tyrone-cluster;enqueuing into qp32, state 1 hop 1
11/02/2013 20:18:01;0008;PBS_Server;Job;31439.tyrone-cluster;Job Queued at request of ecesmndl@tyrone-cluster, owner = ecesmndl@tyrone-cluster, job name = again, queue = qp32
11/02/2013 20:18:01;0040;PBS_Server;Svr;tyrone-cluster;Scheduler was sent the command new
11/02/2013 20:18:01;0008;PBS_Server;Job;31336.tyrone-cluster;Job Modified at request of Scheduler@tyrone-cluster
11/02/2013 20:18:01;0008;PBS_Server;Job;31325.tyrone-cluster;Job Modified at request of Scheduler@tyrone-cluster
11/02/2013 20:18:01;0008;PBS_Server;Job;31337.tyrone-cluster;Job Modified at request of Scheduler@tyrone-cluster
11/02/2013 20:18:01;0008;PBS_Server;Job;31408.tyrone-cluster;Job Modified at request of Scheduler@tyrone-cluster
11/02/2013 20:18:01;0008;PBS_Server;Job;31409.tyrone-cluster;Job Modified at request of Scheduler@tyrone-cluster
11/02/2013 20:18:01;0008;PBS_Server;Job;31326.tyrone-cluster;Job Modified at request of Scheduler@tyrone-cluster
11/02/2013 20:18:01;0008;PBS_Server;Job;31439.tyrone-cluster;Job Modified at request of Scheduler@tyrone-cluster
11/02/2013 20:18:02;0040;PBS_Server;Svr;tyrone-cluster;Scheduler was sent the command new
11/02/2013 20:18:02;0100;PBS_Server;Job;31440.tyrone-cluster;enqueuing into batch, state 1 hop 1
11/02/2013 20:18:02;0100;PBS_Server;Job;31440.tyrone-cluster;dequeuing from batch, state QUEUED
11/02/2013 20:18:02;0100;PBS_Server;Job;31440.tyrone-cluster;enqueuing into qp32, state 1 hop 1
11/02/2013 20:18:02;0008;PBS_Server;Job;31440.tyrone-cluster;Job Queued at request of ecesmndl@tyrone-cluster, owner = ecesmndl@tyrone-cluster, job name = again, queue = qp32
11/02/2013 20:18:02;0008;PBS_Server;Job;31440.tyrone-cluster;Job Modified at request of Scheduler@tyrone-cluster
11/02/2013 20:18:36;0040;PBS_Server;Svr;tyrone-cluster;Scheduler was sent the command new
11/02/2013 20:19:02;0040;PBS_Server;Svr;tyrone-cluster;Scheduler was sent the command new
11/02/2013 20:19:32;0040;PBS_Server;Svr;tyrone-cluster;Scheduler was sent the command new
11/02/2013 20:20:06;0040;PBS_Server;Svr;tyrone-cluster;Scheduler was sent the command new
11/02/2013 20:20:32;0040;PBS_Server;Svr;tyrone-cluster;Scheduler was sent the command new
11/02/2013 20:21:03;0040;PBS_Server;Svr;tyrone-cluster;Scheduler was sent the command new
11/02/2013 20:21:36;0040;PBS_Server;Svr;tyrone-cluster;Scheduler was sent the command new
11/02/2013 20:22:02;0040;PBS_Server;Svr;tyrone-cluster;Scheduler was sent the command new
11/02/2013 20:22:33;0040;PBS_Server;Svr;tyrone-cluster;Scheduler was sent the command new
11/02/2013 20:22:42;0002;PBS_Server;Svr;PBS_Server;Torque Server Version = 3.0.5, loglevel = 0
11/02/2013 20:23:06;0040;PBS_Server;Svr;tyrone-cluster;Scheduler was sent the command new
11/02/2013 20:23:32;0040;PBS_Server;Svr;tyrone-cluster;Scheduler was sent the command new
11/02/2013 20:24:03;0040;PBS_Server;Svr;tyrone-cluster;Scheduler was sent the command new
11/02/2013 20:24:36;0040;PBS_Server;Svr;tyrone-cluster;Scheduler was sent the command new
11/02/2013 20:25:02;0040;PBS_Server;Svr;tyrone-cluster;Scheduler was sent the command new
11/02/2013 20:25:33;0040;PBS_Server;Svr;tyrone-cluster;Scheduler was sent the command new
11/02/2013 20:26:06;0040;PBS_Server;Svr;tyrone-cluster;Scheduler was sent the command new
11/02/2013 20:26:32;0040;PBS_Server;Svr;tyrone-cluster;Scheduler was sent the command new
11/02/2013 20:27:03;0040;PBS_Server;Svr;tyrone-cluster;Scheduler was sent the command new
11/02/2013 20:27:36;0040;PBS_Server;Svr;tyrone-cluster;Scheduler was sent the command new
11/02/2013 20:27:42;0002;PBS_Server;Svr;PBS_Server;Torque Server Version = 3.0.5, loglevel = 0
11/02/2013 20:28:02;0040;PBS_Server;Svr;tyrone-cluster;Scheduler was sent the command new
11/02/2013 20:28:33;0040;PBS_Server;Svr;tyrone-cluster;Scheduler was sent the command new
11/02/2013 20:29:06;0040;PBS_Server;Svr;tyrone-cluster;Scheduler was sent the command new
11/02/2013 20:29:39;0040;PBS_Server;Svr;tyrone-cluster;Scheduler was sent the command new
11/02/2013 20:30:08;0040;PBS_Server;Svr;tyrone-cluster;Scheduler was sent the command new
11/02/2013 20:30:40;0040;PBS_Server;Svr;tyrone-cluster;Scheduler was sent the command new
11/02/2013 20:31:11;0040;PBS_Server;Svr;tyrone-cluster;Scheduler was sent the command new
11/02/2013 20:31:47;0040;PBS_Server;Svr;tyrone-cluster;Scheduler was sent the command new
11/02/2013 20:32:10;0040;PBS_Server;Svr;tyrone-cluster;Scheduler was sent the command new
11/02/2013 20:32:41;0040;PBS_Server;Svr;tyrone-cluster;Scheduler was sent the command new
11/02/2013 20:32:42;0002;PBS_Server;Svr;PBS_Server;Torque Server Version = 3.0.5, loglevel = 0
11/02/2013 20:33:17;0040;PBS_Server;Svr;tyrone-cluster;Scheduler was sent the command new
11/02/2013 20:33:40;0040;PBS_Server;Svr;tyrone-cluster;Scheduler was sent the command new
11/02/2013 20:34:12;0040;PBS_Server;Svr;tyrone-cluster;Scheduler was sent the command new
11/02/2013 20:34:47;0040;PBS_Server;Svr;tyrone-cluster;Scheduler was sent the command new
11/02/2013 20:35:10;0040;PBS_Server;Svr;tyrone-cluster;Scheduler was sent the command new
11/02/2013 20:35:41;0040;PBS_Server;Svr;tyrone-cluster;Scheduler was sent the command new
11/02/2013 20:36:16;0040;PBS_Server;Svr;tyrone-cluster;Scheduler was sent the command new
11/02/2013 20:36:40;0040;PBS_Server;Svr;tyrone-cluster;Scheduler was sent the command new
11/02/2013 20:37:11;0040;PBS_Server;Svr;tyrone-cluster;Scheduler was sent the command new
11/02/2013 20:37:42;0002;PBS_Server;Svr;PBS_Server;Torque Server Version = 3.0.5, loglevel = 0
11/02/2013 20:37:47;0040;PBS_Server;Svr;tyrone-cluster;Scheduler was sent the command new
11/02/2013 20:38:14;0040;PBS_Server;Svr;tyrone-cluster;Scheduler was sent the command new
11/02/2013 20:38:42;0040;PBS_Server;Svr;tyrone-cluster;Scheduler was sent the command new
11/02/2013 20:39:17;0040;PBS_Server;Svr;tyrone-cluster;Scheduler was sent the command new
11/02/2013 20:39:48;0040;PBS_Server;Svr;tyrone-cluster;Scheduler was sent the command new
11/02/2013 20:40:21;0040;PBS_Server;Svr;tyrone-cluster;Scheduler was sent the command new
11/02/2013 20:40:47;0040;PBS_Server;Svr;tyrone-cluster;Scheduler was sent the command new
11/02/2013 20:41:18;0040;PBS_Server;Svr;tyrone-cluster;Scheduler was sent the command new
11/02/2013 20:41:51;0040;PBS_Server;Svr;tyrone-cluster;Scheduler was sent the command new
11/02/2013 20:42:17;0040;PBS_Server;Svr;tyrone-cluster;Scheduler was sent the command new
11/02/2013 20:42:42;0002;PBS_Server;Svr;PBS_Server;Torque Server Version = 3.0.5, loglevel = 0
11/02/2013 20:42:48;0040;PBS_Server;Svr;tyrone-cluster;Scheduler was sent the command new
11/02/2013 20:43:21;0040;PBS_Server;Svr;tyrone-cluster;Scheduler was sent the command new
11/02/2013 20:43:47;0040;PBS_Server;Svr;tyrone-cluster;Scheduler was sent the command new
11/02/2013 20:44:18;0040;PBS_Server;Svr;tyrone-cluster;Scheduler was sent the command new
11/02/2013 20:44:51;0040;PBS_Server;Svr;tyrone-cluster;Scheduler was sent the command new
11/02/2013 20:45:17;0040;PBS_Server;Svr;tyrone-cluster;Scheduler was sent the command new
11/02/2013 20:45:48;0040;PBS_Server;Svr;tyrone-cluster;Scheduler was sent the command new
11/02/2013 20:46:21;0040;PBS_Server;Svr;tyrone-cluster;Scheduler was sent the command new
11/02/2013 20:46:47;0040;PBS_Server;Svr;tyrone-cluster;Scheduler was sent the command new
11/02/2013 20:47:18;0040;PBS_Server;Svr;tyrone-cluster;Scheduler was sent the command new
11/02/2013 20:47:42;0002;PBS_Server;Svr;PBS_Server;Torque Server Version = 3.0.5, loglevel = 0
11/02/2013 20:47:51;0040;PBS_Server;Svr;tyrone-cluster;Scheduler was sent the command new
11/02/2013 20:48:17;0040;PBS_Server;Svr;tyrone-cluster;Scheduler was sent the command new
11/02/2013 20:48:48;0040;PBS_Server;Svr;tyrone-cluster;Scheduler was sent the command new
11/02/2013 20:49:21;0040;PBS_Server;Svr;tyrone-cluster;Scheduler was sent the command new
11/02/2013 20:49:47;0040;PBS_Server;Svr;tyrone-cluster;Scheduler was sent the command new
11/02/2013 20:50:18;0040;PBS_Server;Svr;tyrone-cluster;Scheduler was sent the command new
11/02/2013 20:50:51;0040;PBS_Server;Svr;tyrone-cluster;Scheduler was sent the command new
11/02/2013 20:51:24;0040;PBS_Server;Svr;tyrone-cluster;Scheduler was sent the command new
11/02/2013 20:51:54;0040;PBS_Server;Svr;tyrone-cluster;Scheduler was sent the command new
11/02/2013 20:52:25;0040;PBS_Server;Svr;tyrone-cluster;Scheduler was sent the command new
11/02/2013 20:52:42;0002;PBS_Server;Svr;PBS_Server;Torque Server Version = 3.0.5, loglevel = 0
11/02/2013 20:52:56;0040;PBS_Server;Svr;tyrone-cluster;Scheduler was sent the command new
11/02/2013 20:53:32;0040;PBS_Server;Svr;tyrone-cluster;Scheduler was sent the command new
11/02/2013 20:53:55;0040;PBS_Server;Svr;tyrone-cluster;Scheduler was sent the command new
11/02/2013 20:54:25;0040;PBS_Server;Svr;tyrone-cluster;Scheduler was sent the command new
11/02/2013 20:55:02;0040;PBS_Server;Svr;tyrone-cluster;Scheduler was sent the command new
11/02/2013 20:55:33;0040;PBS_Server;Svr;tyrone-cluster;Scheduler was sent the command new
11/02/2013 20:56:06;0040;PBS_Server;Svr;tyrone-cluster;Scheduler was sent the command new
11/02/2013 20:56:32;0040;PBS_Server;Svr;tyrone-cluster;Scheduler was sent the command new
11/02/2013 20:57:03;0040;PBS_Server;Svr;tyrone-cluster;Scheduler was sent the command new
11/02/2013 20:57:34;0040;PBS_Server;Svr;tyrone-cluster;Scheduler was sent the command new
11/02/2013 20:57:42;0002;PBS_Server;Svr;PBS_Server;Torque Server Version = 3.0.5, loglevel = 0
11/02/2013 20:58:02;0040;PBS_Server;Svr;tyrone-cluster;Scheduler was sent the command new
11/02/2013 20:58:33;0040;PBS_Server;Svr;tyrone-cluster;Scheduler was sent the command new
11/02/2013 20:59:06;0040;PBS_Server;Svr;tyrone-cluster;Scheduler was sent the command new
11/02/2013 20:59:32;0040;PBS_Server;Svr;tyrone-cluster;Scheduler was sent the command new
11/02/2013 21:00:03;0040;PBS_Server;Svr;tyrone-cluster;Scheduler was sent the command new
11/02/2013 21:00:36;0040;PBS_Server;Svr;tyrone-cluster;Scheduler was sent the command new
11/02/2013 21:01:09;0040;PBS_Server;Svr;tyrone-cluster;Scheduler was sent the command new
11/02/2013 21:01:39;0040;PBS_Server;Svr;tyrone-cluster;Scheduler was sent the command new
11/02/2013 21:02:10;0040;PBS_Server;Svr;tyrone-cluster;Scheduler was sent the command new
11/02/2013 21:02:41;0040;PBS_Server;Svr;tyrone-cluster;Scheduler was sent the command new
11/02/2013 21:02:42;0002;PBS_Server;Svr;PBS_Server;Torque Server Version = 3.0.5, loglevel = 0
11/02/2013 21:02:52;0008;PBS_Server;Job;31434.tyrone-cluster;Job deleted at request of secbadar@tyrone-cluster
11/02/2013 21:02:52;0008;PBS_Server;Job;31434.tyrone-cluster;Job sent signal SIGTERM on delete
11/02/2013 21:02:52;000d;PBS_Server;Job;31434.tyrone-cluster;Not sending email: User does not want mail of this type.
11/02/2013 21:02:52;0010;PBS_Server;Job;31434.tyrone-cluster;Exit_status=143 resources_used.cput=01:55:11 resources_used.mem=1225988kb resources_used.vmem=8362492kb resources_used.walltime=00:55:23
11/02/2013 21:02:52;0008;PBS_Server;Job;NULL;on_job_exit valid pjob: 0x2e0d0b0 (substate=50)
