04/03/2013 00:00:00;0002;PBS_Server;Svr;Log;Log opened
04/03/2013 00:00:00;0001;PBS_Server;Svr;PBS_Server;LOG_ERROR::sync_node_jobs, stray job 21190.tyrone-cluster found on tyrone-node6
04/03/2013 00:00:03;0001;PBS_Server;Svr;PBS_Server;LOG_ERROR::sync_node_jobs, stray job 21306.tyrone-cluster found on tyrone-node5
04/03/2013 00:00:38;0001;PBS_Server;Svr;PBS_Server;LOG_ERROR::sync_node_jobs, stray job 21312.tyrone-cluster found on tyrone-node4
04/03/2013 00:00:45;0001;PBS_Server;Svr;PBS_Server;LOG_ERROR::sync_node_jobs, stray job 21190.tyrone-cluster found on tyrone-node6
04/03/2013 00:00:48;0001;PBS_Server;Svr;PBS_Server;LOG_ERROR::sync_node_jobs, stray job 21306.tyrone-cluster found on tyrone-node5
04/03/2013 00:00:51;0040;PBS_Server;Svr;tyrone-cluster;Scheduler was sent the command time
04/03/2013 00:01:23;0001;PBS_Server;Svr;PBS_Server;LOG_ERROR::sync_node_jobs, stray job 21312.tyrone-cluster found on tyrone-node4
04/03/2013 00:01:30;0001;PBS_Server;Svr;PBS_Server;LOG_ERROR::sync_node_jobs, stray job 21190.tyrone-cluster found on tyrone-node6
04/03/2013 00:01:33;0001;PBS_Server;Svr;PBS_Server;LOG_ERROR::sync_node_jobs, stray job 21306.tyrone-cluster found on tyrone-node5
04/03/2013 00:02:08;0001;PBS_Server;Svr;PBS_Server;LOG_ERROR::sync_node_jobs, stray job 21312.tyrone-cluster found on tyrone-node4
04/03/2013 00:02:15;0001;PBS_Server;Svr;PBS_Server;LOG_ERROR::sync_node_jobs, stray job 21190.tyrone-cluster found on tyrone-node6
04/03/2013 00:02:18;0001;PBS_Server;Svr;PBS_Server;LOG_ERROR::sync_node_jobs, stray job 21306.tyrone-cluster found on tyrone-node5
04/03/2013 00:02:53;0001;PBS_Server;Svr;PBS_Server;LOG_ERROR::sync_node_jobs, stray job 21312.tyrone-cluster found on tyrone-node4
04/03/2013 00:03:00;0001;PBS_Server;Svr;PBS_Server;LOG_ERROR::sync_node_jobs, stray job 21190.tyrone-cluster found on tyrone-node6
04/03/2013 00:03:03;0001;PBS_Server;Svr;PBS_Server;LOG_ERROR::sync_node_jobs, stray job 21306.tyrone-cluster found on tyrone-node5
04/03/2013 00:03:30;0002;PBS_Server;Svr;PBS_Server;Torque Server Version = 3.0.5, loglevel = 0
04/03/2013 00:03:38;0001;PBS_Server;Svr;PBS_Server;LOG_ERROR::sync_node_jobs, stray job 21312.tyrone-cluster found on tyrone-node4
04/03/2013 00:03:45;0001;PBS_Server;Svr;PBS_Server;LOG_ERROR::sync_node_jobs, stray job 21190.tyrone-cluster found on tyrone-node6
04/03/2013 00:03:48;0001;PBS_Server;Svr;PBS_Server;LOG_ERROR::sync_node_jobs, stray job 21306.tyrone-cluster found on tyrone-node5
04/03/2013 00:04:23;0001;PBS_Server;Svr;PBS_Server;LOG_ERROR::sync_node_jobs, stray job 21312.tyrone-cluster found on tyrone-node4
04/03/2013 00:04:31;0001;PBS_Server;Svr;PBS_Server;LOG_ERROR::sync_node_jobs, stray job 21190.tyrone-cluster found on tyrone-node6
04/03/2013 00:04:34;0001;PBS_Server;Svr;PBS_Server;LOG_ERROR::sync_node_jobs, stray job 21306.tyrone-cluster found on tyrone-node5
04/03/2013 00:05:08;0001;PBS_Server;Svr;PBS_Server;LOG_ERROR::sync_node_jobs, stray job 21312.tyrone-cluster found on tyrone-node4
04/03/2013 00:05:16;0001;PBS_Server;Svr;PBS_Server;LOG_ERROR::sync_node_jobs, stray job 21190.tyrone-cluster found on tyrone-node6
04/03/2013 00:05:19;0001;PBS_Server;Svr;PBS_Server;LOG_ERROR::sync_node_jobs, stray job 21306.tyrone-cluster found on tyrone-node5
04/03/2013 00:05:53;0001;PBS_Server;Svr;PBS_Server;LOG_ERROR::sync_node_jobs, stray job 21312.tyrone-cluster found on tyrone-node4
04/03/2013 00:06:01;0001;PBS_Server;Svr;PBS_Server;LOG_ERROR::sync_node_jobs, stray job 21190.tyrone-cluster found on tyrone-node6
04/03/2013 00:06:03;0001;PBS_Server;Svr;PBS_Server;LOG_ERROR::sync_node_jobs, stray job 21306.tyrone-cluster found on tyrone-node5
04/03/2013 00:06:38;0001;PBS_Server;Svr;PBS_Server;LOG_ERROR::sync_node_jobs, stray job 21312.tyrone-cluster found on tyrone-node4
04/03/2013 00:06:45;0001;PBS_Server;Svr;PBS_Server;LOG_ERROR::sync_node_jobs, stray job 21190.tyrone-cluster found on tyrone-node6
04/03/2013 00:06:48;0001;PBS_Server;Svr;PBS_Server;LOG_ERROR::sync_node_jobs, stray job 21306.tyrone-cluster found on tyrone-node5
04/03/2013 00:07:23;0001;PBS_Server;Svr;PBS_Server;LOG_ERROR::sync_node_jobs, stray job 21312.tyrone-cluster found on tyrone-node4
04/03/2013 00:07:30;0001;PBS_Server;Svr;PBS_Server;LOG_ERROR::sync_node_jobs, stray job 21190.tyrone-cluster found on tyrone-node6
04/03/2013 00:07:33;0001;PBS_Server;Svr;PBS_Server;LOG_ERROR::sync_node_jobs, stray job 21306.tyrone-cluster found on tyrone-node5
04/03/2013 00:08:08;0001;PBS_Server;Svr;PBS_Server;LOG_ERROR::sync_node_jobs, stray job 21312.tyrone-cluster found on tyrone-node4
04/03/2013 00:08:15;0001;PBS_Server;Svr;PBS_Server;LOG_ERROR::sync_node_jobs, stray job 21190.tyrone-cluster found on tyrone-node6
04/03/2013 00:08:18;0001;PBS_Server;Svr;PBS_Server;LOG_ERROR::sync_node_jobs, stray job 21306.tyrone-cluster found on tyrone-node5
04/03/2013 00:08:30;0002;PBS_Server;Svr;PBS_Server;Torque Server Version = 3.0.5, loglevel = 0
04/03/2013 00:08:53;0001;PBS_Server;Svr;PBS_Server;LOG_ERROR::sync_node_jobs, stray job 21312.tyrone-cluster found on tyrone-node4
04/03/2013 00:09:00;0001;PBS_Server;Svr;PBS_Server;LOG_ERROR::sync_node_jobs, stray job 21190.tyrone-cluster found on tyrone-node6
04/03/2013 00:09:03;0001;PBS_Server;Svr;PBS_Server;LOG_ERROR::sync_node_jobs, stray job 21306.tyrone-cluster found on tyrone-node5
04/03/2013 00:09:38;0001;PBS_Server;Svr;PBS_Server;LOG_ERROR::sync_node_jobs, stray job 21312.tyrone-cluster found on tyrone-node4
04/03/2013 00:09:45;0001;PBS_Server;Svr;PBS_Server;LOG_ERROR::sync_node_jobs, stray job 21190.tyrone-cluster found on tyrone-node6
04/03/2013 00:09:48;0001;PBS_Server;Svr;PBS_Server;LOG_ERROR::sync_node_jobs, stray job 21306.tyrone-cluster found on tyrone-node5
04/03/2013 00:10:23;0001;PBS_Server;Svr;PBS_Server;LOG_ERROR::sync_node_jobs, stray job 21312.tyrone-cluster found on tyrone-node4
04/03/2013 00:10:30;0001;PBS_Server;Svr;PBS_Server;LOG_ERROR::sync_node_jobs, stray job 21190.tyrone-cluster found on tyrone-node6
04/03/2013 00:10:33;0001;PBS_Server;Svr;PBS_Server;LOG_ERROR::sync_node_jobs, stray job 21306.tyrone-cluster found on tyrone-node5
04/03/2013 00:10:51;0040;PBS_Server;Svr;tyrone-cluster;Scheduler was sent the command time
04/03/2013 00:11:08;0001;PBS_Server;Svr;PBS_Server;LOG_ERROR::sync_node_jobs, stray job 21312.tyrone-cluster found on tyrone-node4
04/03/2013 00:11:15;0001;PBS_Server;Svr;PBS_Server;LOG_ERROR::sync_node_jobs, stray job 21190.tyrone-cluster found on tyrone-node6
04/03/2013 00:11:18;0001;PBS_Server;Svr;PBS_Server;LOG_ERROR::sync_node_jobs, stray job 21306.tyrone-cluster found on tyrone-node5
04/03/2013 00:11:53;0001;PBS_Server;Svr;PBS_Server;LOG_ERROR::sync_node_jobs, stray job 21312.tyrone-cluster found on tyrone-node4
04/03/2013 00:12:00;0001;PBS_Server;Svr;PBS_Server;LOG_ERROR::sync_node_jobs, stray job 21190.tyrone-cluster found on tyrone-node6
04/03/2013 00:12:03;0001;PBS_Server;Svr;PBS_Server;LOG_ERROR::sync_node_jobs, stray job 21306.tyrone-cluster found on tyrone-node5
04/03/2013 00:12:38;0001;PBS_Server;Svr;PBS_Server;LOG_ERROR::sync_node_jobs, stray job 21312.tyrone-cluster found on tyrone-node4
04/03/2013 00:12:45;0001;PBS_Server;Svr;PBS_Server;LOG_ERROR::sync_node_jobs, stray job 21190.tyrone-cluster found on tyrone-node6
04/03/2013 00:12:48;0001;PBS_Server;Svr;PBS_Server;LOG_ERROR::sync_node_jobs, stray job 21306.tyrone-cluster found on tyrone-node5
04/03/2013 00:13:23;0001;PBS_Server;Svr;PBS_Server;LOG_ERROR::sync_node_jobs, stray job 21312.tyrone-cluster found on tyrone-node4
04/03/2013 00:13:30;0001;PBS_Server;Svr;PBS_Server;LOG_ERROR::sync_node_jobs, stray job 21190.tyrone-cluster found on tyrone-node6
04/03/2013 00:13:30;0002;PBS_Server;Svr;PBS_Server;Torque Server Version = 3.0.5, loglevel = 0
04/03/2013 00:13:33;0001;PBS_Server;Svr;PBS_Server;LOG_ERROR::sync_node_jobs, stray job 21306.tyrone-cluster found on tyrone-node5
04/03/2013 00:14:08;0001;PBS_Server;Svr;PBS_Server;LOG_ERROR::sync_node_jobs, stray job 21312.tyrone-cluster found on tyrone-node4
04/03/2013 00:14:15;0001;PBS_Server;Svr;PBS_Server;LOG_ERROR::sync_node_jobs, stray job 21190.tyrone-cluster found on tyrone-node6
04/03/2013 00:14:18;0001;PBS_Server;Svr;PBS_Server;LOG_ERROR::sync_node_jobs, stray job 21306.tyrone-cluster found on tyrone-node5
04/03/2013 00:14:52;0001;PBS_Server;Svr;PBS_Server;LOG_ERROR::sync_node_jobs, stray job 21312.tyrone-cluster found on tyrone-node4
04/03/2013 00:15:00;0001;PBS_Server;Svr;PBS_Server;LOG_ERROR::sync_node_jobs, stray job 21190.tyrone-cluster found on tyrone-node6
04/03/2013 00:15:03;0001;PBS_Server;Svr;PBS_Server;LOG_ERROR::sync_node_jobs, stray job 21306.tyrone-cluster found on tyrone-node5
04/03/2013 00:15:37;0001;PBS_Server;Svr;PBS_Server;LOG_ERROR::sync_node_jobs, stray job 21312.tyrone-cluster found on tyrone-node4
04/03/2013 00:15:45;0001;PBS_Server;Svr;PBS_Server;LOG_ERROR::sync_node_jobs, stray job 21190.tyrone-cluster found on tyrone-node6
04/03/2013 00:15:48;0001;PBS_Server;Svr;PBS_Server;LOG_ERROR::sync_node_jobs, stray job 21306.tyrone-cluster found on tyrone-node5
04/03/2013 00:16:22;0001;PBS_Server;Svr;PBS_Server;LOG_ERROR::sync_node_jobs, stray job 21312.tyrone-cluster found on tyrone-node4
04/03/2013 00:16:30;0001;PBS_Server;Svr;PBS_Server;LOG_ERROR::sync_node_jobs, stray job 21190.tyrone-cluster found on tyrone-node6
04/03/2013 00:16:33;0001;PBS_Server;Svr;PBS_Server;LOG_ERROR::sync_node_jobs, stray job 21306.tyrone-cluster found on tyrone-node5
04/03/2013 00:17:08;0001;PBS_Server;Svr;PBS_Server;LOG_ERROR::sync_node_jobs, stray job 21312.tyrone-cluster found on tyrone-node4
04/03/2013 00:17:16;0001;PBS_Server;Svr;PBS_Server;LOG_ERROR::sync_node_jobs, stray job 21190.tyrone-cluster found on tyrone-node6
04/03/2013 00:17:19;0001;PBS_Server;Svr;PBS_Server;LOG_ERROR::sync_node_jobs, stray job 21306.tyrone-cluster found on tyrone-node5
04/03/2013 00:17:53;0001;PBS_Server;Svr;PBS_Server;LOG_ERROR::sync_node_jobs, stray job 21312.tyrone-cluster found on tyrone-node4
04/03/2013 00:18:01;0001;PBS_Server;Svr;PBS_Server;LOG_ERROR::sync_node_jobs, stray job 21190.tyrone-cluster found on tyrone-node6
04/03/2013 00:18:04;0001;PBS_Server;Svr;PBS_Server;LOG_ERROR::sync_node_jobs, stray job 21306.tyrone-cluster found on tyrone-node5
04/03/2013 00:18:30;0002;PBS_Server;Svr;PBS_Server;Torque Server Version = 3.0.5, loglevel = 0
04/03/2013 00:18:38;0001;PBS_Server;Svr;PBS_Server;LOG_ERROR::sync_node_jobs, stray job 21312.tyrone-cluster found on tyrone-node4
04/03/2013 00:18:45;0001;PBS_Server;Svr;PBS_Server;LOG_ERROR::sync_node_jobs, stray job 21190.tyrone-cluster found on tyrone-node6
04/03/2013 00:18:48;0001;PBS_Server;Svr;PBS_Server;LOG_ERROR::sync_node_jobs, stray job 21306.tyrone-cluster found on tyrone-node5
04/03/2013 00:19:23;0001;PBS_Server;Svr;PBS_Server;LOG_ERROR::sync_node_jobs, stray job 21312.tyrone-cluster found on tyrone-node4
04/03/2013 00:19:30;0001;PBS_Server;Svr;PBS_Server;LOG_ERROR::sync_node_jobs, stray job 21190.tyrone-cluster found on tyrone-node6
04/03/2013 00:19:33;0001;PBS_Server;Svr;PBS_Server;LOG_ERROR::sync_node_jobs, stray job 21306.tyrone-cluster found on tyrone-node5
04/03/2013 00:20:08;0001;PBS_Server;Svr;PBS_Server;LOG_ERROR::sync_node_jobs, stray job 21312.tyrone-cluster found on tyrone-node4
04/03/2013 00:20:15;0001;PBS_Server;Svr;PBS_Server;LOG_ERROR::sync_node_jobs, stray job 21190.tyrone-cluster found on tyrone-node6
04/03/2013 00:20:18;0001;PBS_Server;Svr;PBS_Server;LOG_ERROR::sync_node_jobs, stray job 21306.tyrone-cluster found on tyrone-node5
04/03/2013 00:20:51;0040;PBS_Server;Svr;tyrone-cluster;Scheduler was sent the command time
04/03/2013 00:20:53;0001;PBS_Server;Svr;PBS_Server;LOG_ERROR::sync_node_jobs, stray job 21312.tyrone-cluster found on tyrone-node4
04/03/2013 00:21:00;0001;PBS_Server;Svr;PBS_Server;LOG_ERROR::sync_node_jobs, stray job 21190.tyrone-cluster found on tyrone-node6
04/03/2013 00:21:03;0001;PBS_Server;Svr;PBS_Server;LOG_ERROR::sync_node_jobs, stray job 21306.tyrone-cluster found on tyrone-node5
04/03/2013 00:21:38;0001;PBS_Server;Svr;PBS_Server;LOG_ERROR::sync_node_jobs, stray job 21312.tyrone-cluster found on tyrone-node4
04/03/2013 00:21:45;0001;PBS_Server;Svr;PBS_Server;LOG_ERROR::sync_node_jobs, stray job 21190.tyrone-cluster found on tyrone-node6
04/03/2013 00:21:48;0001;PBS_Server;Svr;PBS_Server;LOG_ERROR::sync_node_jobs, stray job 21306.tyrone-cluster found on tyrone-node5
04/03/2013 00:22:23;0001;PBS_Server;Svr;PBS_Server;LOG_ERROR::sync_node_jobs, stray job 21312.tyrone-cluster found on tyrone-node4
04/03/2013 00:22:30;0001;PBS_Server;Svr;PBS_Server;LOG_ERROR::sync_node_jobs, stray job 21190.tyrone-cluster found on tyrone-node6
04/03/2013 00:22:33;0001;PBS_Server;Svr;PBS_Server;LOG_ERROR::sync_node_jobs, stray job 21306.tyrone-cluster found on tyrone-node5
04/03/2013 00:23:08;0001;PBS_Server;Svr;PBS_Server;LOG_ERROR::sync_node_jobs, stray job 21312.tyrone-cluster found on tyrone-node4
04/03/2013 00:23:15;0001;PBS_Server;Svr;PBS_Server;LOG_ERROR::sync_node_jobs, stray job 21190.tyrone-cluster found on tyrone-node6
04/03/2013 00:23:18;0001;PBS_Server;Svr;PBS_Server;LOG_ERROR::sync_node_jobs, stray job 21306.tyrone-cluster found on tyrone-node5
04/03/2013 00:23:30;0002;PBS_Server;Svr;PBS_Server;Torque Server Version = 3.0.5, loglevel = 0
04/03/2013 00:23:53;0001;PBS_Server;Svr;PBS_Server;LOG_ERROR::sync_node_jobs, stray job 21312.tyrone-cluster found on tyrone-node4
04/03/2013 00:24:00;0001;PBS_Server;Svr;PBS_Server;LOG_ERROR::sync_node_jobs, stray job 21190.tyrone-cluster found on tyrone-node6
04/03/2013 00:24:03;0001;PBS_Server;Svr;PBS_Server;LOG_ERROR::sync_node_jobs, stray job 21306.tyrone-cluster found on tyrone-node5
04/03/2013 00:24:37;0001;PBS_Server;Svr;PBS_Server;LOG_ERROR::sync_node_jobs, stray job 21312.tyrone-cluster found on tyrone-node4
04/03/2013 00:24:45;0001;PBS_Server;Svr;PBS_Server;LOG_ERROR::sync_node_jobs, stray job 21190.tyrone-cluster found on tyrone-node6
04/03/2013 00:24:48;0001;PBS_Server;Svr;PBS_Server;LOG_ERROR::sync_node_jobs, stray job 21306.tyrone-cluster found on tyrone-node5
04/03/2013 00:25:22;0001;PBS_Server;Svr;PBS_Server;LOG_ERROR::sync_node_jobs, stray job 21312.tyrone-cluster found on tyrone-node4
04/03/2013 00:25:30;0001;PBS_Server;Svr;PBS_Server;LOG_ERROR::sync_node_jobs, stray job 21190.tyrone-cluster found on tyrone-node6
04/03/2013 00:25:33;0001;PBS_Server;Svr;PBS_Server;LOG_ERROR::sync_node_jobs, stray job 21306.tyrone-cluster found on tyrone-node5
04/03/2013 00:26:07;0001;PBS_Server;Svr;PBS_Server;LOG_ERROR::sync_node_jobs, stray job 21312.tyrone-cluster found on tyrone-node4
04/03/2013 00:26:15;0001;PBS_Server;Svr;PBS_Server;LOG_ERROR::sync_node_jobs, stray job 21190.tyrone-cluster found on tyrone-node6
04/03/2013 00:26:18;0001;PBS_Server;Svr;PBS_Server;LOG_ERROR::sync_node_jobs, stray job 21306.tyrone-cluster found on tyrone-node5
04/03/2013 00:26:52;0001;PBS_Server;Svr;PBS_Server;LOG_ERROR::sync_node_jobs, stray job 21312.tyrone-cluster found on tyrone-node4
04/03/2013 00:27:00;0001;PBS_Server;Svr;PBS_Server;LOG_ERROR::sync_node_jobs, stray job 21190.tyrone-cluster found on tyrone-node6
04/03/2013 00:27:03;0001;PBS_Server;Svr;PBS_Server;LOG_ERROR::sync_node_jobs, stray job 21306.tyrone-cluster found on tyrone-node5
04/03/2013 00:27:37;0001;PBS_Server;Svr;PBS_Server;LOG_ERROR::sync_node_jobs, stray job 21312.tyrone-cluster found on tyrone-node4
04/03/2013 00:27:45;0001;PBS_Server;Svr;PBS_Server;LOG_ERROR::sync_node_jobs, stray job 21190.tyrone-cluster found on tyrone-node6
04/03/2013 00:27:48;0001;PBS_Server;Svr;PBS_Server;LOG_ERROR::sync_node_jobs, stray job 21306.tyrone-cluster found on tyrone-node5
04/03/2013 00:28:22;0001;PBS_Server;Svr;PBS_Server;LOG_ERROR::sync_node_jobs, stray job 21312.tyrone-cluster found on tyrone-node4
04/03/2013 00:28:30;0001;PBS_Server;Svr;PBS_Server;LOG_ERROR::sync_node_jobs, stray job 21190.tyrone-cluster found on tyrone-node6
04/03/2013 00:28:30;0002;PBS_Server;Svr;PBS_Server;Torque Server Version = 3.0.5, loglevel = 0
04/03/2013 00:28:33;000d;PBS_Server;Job;21309.tyrone-cluster;Not sending email: User does not want mail of this type.
04/03/2013 00:28:33;0002;PBS_Server;Svr;Act;Account file /var/spool/torque/server_priv/accounting/20130403 opened
04/03/2013 00:28:33;0010;PBS_Server;Job;21309.tyrone-cluster;Exit_status=0 resources_used.cput=87:28:00 resources_used.mem=4410756kb resources_used.vmem=10562888kb resources_used.walltime=01:25:08
04/03/2013 00:28:33;0008;PBS_Server;Job;NULL;on_job_exit valid pjob: 0x2063e10 (substate=50)
04/03/2013 00:28:33;0008;PBS_Server;Job;NULL;on_job_exit valid pjob: 0x2063e10 (substate=51)
04/03/2013 00:28:33;0008;PBS_Server;Job;NULL;on_job_exit valid pjob: 0x2063e10 (substate=51)
04/03/2013 00:28:33;0008;PBS_Server;Job;NULL;on_job_exit valid pjob: 0x2063e10 (substate=53)
04/03/2013 00:28:33;0100;PBS_Server;Job;21309.tyrone-cluster;dequeuing from qp64, state COMPLETE
04/03/2013 00:28:33;0040;PBS_Server;Svr;tyrone-cluster;Scheduler was sent the command term
04/03/2013 00:28:33;0001;PBS_Server;Svr;PBS_Server;LOG_ERROR::sync_node_jobs, stray job 21306.tyrone-cluster found on tyrone-node5
04/03/2013 00:28:33;0008;PBS_Server;Job;21311.tyrone-cluster;Job Modified at request of Scheduler@tyrone-cluster
04/03/2013 00:28:33;0008;PBS_Server;Job;21311.tyrone-cluster;Job Run at request of Scheduler@tyrone-cluster
04/03/2013 00:28:33;0040;PBS_Server;Svr;tyrone-cluster;Scheduler was sent the command recyc
04/03/2013 00:28:33;000d;PBS_Server;Job;21311.tyrone-cluster;Not sending email: User does not want mail of this type.
04/03/2013 00:29:08;0001;PBS_Server;Svr;PBS_Server;LOG_ERROR::sync_node_jobs, stray job 21312.tyrone-cluster found on tyrone-node4
04/03/2013 00:29:15;0001;PBS_Server;Svr;PBS_Server;LOG_ERROR::sync_node_jobs, stray job 21190.tyrone-cluster found on tyrone-node6
04/03/2013 00:29:18;0001;PBS_Server;Svr;PBS_Server;LOG_ERROR::sync_node_jobs, stray job 21306.tyrone-cluster found on tyrone-node5
04/03/2013 00:29:53;0001;PBS_Server;Svr;PBS_Server;LOG_ERROR::sync_node_jobs, stray job 21312.tyrone-cluster found on tyrone-node4
04/03/2013 00:30:00;0001;PBS_Server;Svr;PBS_Server;LOG_ERROR::sync_node_jobs, stray job 21190.tyrone-cluster found on tyrone-node6
04/03/2013 00:30:03;0001;PBS_Server;Svr;PBS_Server;LOG_ERROR::sync_node_jobs, stray job 21306.tyrone-cluster found on tyrone-node5
04/03/2013 00:30:38;0001;PBS_Server;Svr;PBS_Server;LOG_ERROR::sync_node_jobs, stray job 21312.tyrone-cluster found on tyrone-node4
04/03/2013 00:30:45;0001;PBS_Server;Svr;PBS_Server;LOG_ERROR::sync_node_jobs, stray job 21190.tyrone-cluster found on tyrone-node6
04/03/2013 00:30:48;0001;PBS_Server;Svr;PBS_Server;LOG_ERROR::sync_node_jobs, stray job 21306.tyrone-cluster found on tyrone-node5
04/03/2013 00:31:23;0001;PBS_Server;Svr;PBS_Server;LOG_ERROR::sync_node_jobs, stray job 21312.tyrone-cluster found on tyrone-node4
04/03/2013 00:31:30;0001;PBS_Server;Svr;PBS_Server;LOG_ERROR::sync_node_jobs, stray job 21190.tyrone-cluster found on tyrone-node6
04/03/2013 00:31:33;0001;PBS_Server;Svr;PBS_Server;LOG_ERROR::sync_node_jobs, stray job 21306.tyrone-cluster found on tyrone-node5
04/03/2013 00:32:07;0001;PBS_Server;Svr;PBS_Server;LOG_ERROR::sync_node_jobs, stray job 21312.tyrone-cluster found on tyrone-node4
04/03/2013 00:32:15;0001;PBS_Server;Svr;PBS_Server;LOG_ERROR::sync_node_jobs, stray job 21190.tyrone-cluster found on tyrone-node6
04/03/2013 00:32:18;0001;PBS_Server;Svr;PBS_Server;LOG_ERROR::sync_node_jobs, stray job 21306.tyrone-cluster found on tyrone-node5
04/03/2013 00:32:52;0001;PBS_Server;Svr;PBS_Server;LOG_ERROR::sync_node_jobs, stray job 21312.tyrone-cluster found on tyrone-node4
04/03/2013 00:33:00;0001;PBS_Server;Svr;PBS_Server;LOG_ERROR::sync_node_jobs, stray job 21190.tyrone-cluster found on tyrone-node6
04/03/2013 00:33:03;0001;PBS_Server;Svr;PBS_Server;LOG_ERROR::sync_node_jobs, stray job 21306.tyrone-cluster found on tyrone-node5
04/03/2013 00:33:30;0002;PBS_Server;Svr;PBS_Server;Torque Server Version = 3.0.5, loglevel = 0
04/03/2013 00:33:37;0001;PBS_Server;Svr;PBS_Server;LOG_ERROR::sync_node_jobs, stray job 21312.tyrone-cluster found on tyrone-node4
04/03/2013 00:33:45;0001;PBS_Server;Svr;PBS_Server;LOG_ERROR::sync_node_jobs, stray job 21190.tyrone-cluster found on tyrone-node6
04/03/2013 00:33:48;0001;PBS_Server;Svr;PBS_Server;LOG_ERROR::sync_node_jobs, stray job 21306.tyrone-cluster found on tyrone-node5
04/03/2013 00:34:22;0001;PBS_Server;Svr;PBS_Server;LOG_ERROR::sync_node_jobs, stray job 21312.tyrone-cluster found on tyrone-node4
04/03/2013 00:34:30;0001;PBS_Server;Svr;PBS_Server;LOG_ERROR::sync_node_jobs, stray job 21190.tyrone-cluster found on tyrone-node6
04/03/2013 00:34:33;0001;PBS_Server;Svr;PBS_Server;LOG_ERROR::sync_node_jobs, stray job 21306.tyrone-cluster found on tyrone-node5
04/03/2013 00:35:07;0001;PBS_Server;Svr;PBS_Server;LOG_ERROR::sync_node_jobs, stray job 21312.tyrone-cluster found on tyrone-node4
04/03/2013 00:35:15;0001;PBS_Server;Svr;PBS_Server;LOG_ERROR::sync_node_jobs, stray job 21190.tyrone-cluster found on tyrone-node6
04/03/2013 00:35:18;0001;PBS_Server;Svr;PBS_Server;LOG_ERROR::sync_node_jobs, stray job 21306.tyrone-cluster found on tyrone-node5
04/03/2013 00:35:52;0001;PBS_Server;Svr;PBS_Server;LOG_ERROR::sync_node_jobs, stray job 21312.tyrone-cluster found on tyrone-node4
04/03/2013 00:36:00;0001;PBS_Server;Svr;PBS_Server;LOG_ERROR::sync_node_jobs, stray job 21190.tyrone-cluster found on tyrone-node6
04/03/2013 00:36:03;0001;PBS_Server;Svr;PBS_Server;LOG_ERROR::sync_node_jobs, stray job 21306.tyrone-cluster found on tyrone-node5
04/03/2013 00:36:37;0001;PBS_Server;Svr;PBS_Server;LOG_ERROR::sync_node_jobs, stray job 21312.tyrone-cluster found on tyrone-node4
04/03/2013 00:36:45;0001;PBS_Server;Svr;PBS_Server;LOG_ERROR::sync_node_jobs, stray job 21190.tyrone-cluster found on tyrone-node6
04/03/2013 00:36:48;0001;PBS_Server;Svr;PBS_Server;LOG_ERROR::sync_node_jobs, stray job 21306.tyrone-cluster found on tyrone-node5
04/03/2013 00:37:22;0001;PBS_Server;Svr;PBS_Server;LOG_ERROR::sync_node_jobs, stray job 21312.tyrone-cluster found on tyrone-node4
04/03/2013 00:37:30;0001;PBS_Server;Svr;PBS_Server;LOG_ERROR::sync_node_jobs, stray job 21190.tyrone-cluster found on tyrone-node6
04/03/2013 00:37:33;0001;PBS_Server;Svr;PBS_Server;LOG_ERROR::sync_node_jobs, stray job 21306.tyrone-cluster found on tyrone-node5
04/03/2013 00:38:07;0001;PBS_Server;Svr;PBS_Server;LOG_ERROR::sync_node_jobs, stray job 21312.tyrone-cluster found on tyrone-node4
04/03/2013 00:38:15;0001;PBS_Server;Svr;PBS_Server;LOG_ERROR::sync_node_jobs, stray job 21190.tyrone-cluster found on tyrone-node6
04/03/2013 00:38:18;0001;PBS_Server;Svr;PBS_Server;LOG_ERROR::sync_node_jobs, stray job 21306.tyrone-cluster found on tyrone-node5
04/03/2013 00:38:30;0002;PBS_Server;Svr;PBS_Server;Torque Server Version = 3.0.5, loglevel = 0
04/03/2013 00:38:33;0040;PBS_Server;Svr;tyrone-cluster;Scheduler was sent the command time
04/03/2013 00:38:52;0001;PBS_Server;Svr;PBS_Server;LOG_ERROR::sync_node_jobs, stray job 21312.tyrone-cluster found on tyrone-node4
04/03/2013 00:39:00;0001;PBS_Server;Svr;PBS_Server;LOG_ERROR::sync_node_jobs, stray job 21190.tyrone-cluster found on tyrone-node6
04/03/2013 00:39:04;0001;PBS_Server;Svr;PBS_Server;LOG_ERROR::sync_node_jobs, stray job 21306.tyrone-cluster found on tyrone-node5
04/03/2013 00:39:38;0001;PBS_Server;Svr;PBS_Server;LOG_ERROR::sync_node_jobs, stray job 21312.tyrone-cluster found on tyrone-node4
04/03/2013 00:39:45;0001;PBS_Server;Svr;PBS_Server;LOG_ERROR::sync_node_jobs, stray job 21190.tyrone-cluster found on tyrone-node6
04/03/2013 00:39:49;0001;PBS_Server;Svr;PBS_Server;LOG_ERROR::sync_node_jobs, stray job 21306.tyrone-cluster found on tyrone-node5
04/03/2013 00:40:23;0001;PBS_Server;Svr;PBS_Server;LOG_ERROR::sync_node_jobs, stray job 21312.tyrone-cluster found on tyrone-node4
04/03/2013 00:40:30;0001;PBS_Server;Svr;PBS_Server;LOG_ERROR::sync_node_jobs, stray job 21190.tyrone-cluster found on tyrone-node6
04/03/2013 00:40:33;0001;PBS_Server;Svr;PBS_Server;LOG_ERROR::sync_node_jobs, stray job 21306.tyrone-cluster found on tyrone-node5
04/03/2013 00:41:08;0001;PBS_Server;Svr;PBS_Server;LOG_ERROR::sync_node_jobs, stray job 21312.tyrone-cluster found on tyrone-node4
04/03/2013 00:41:15;0001;PBS_Server;Svr;PBS_Server;LOG_ERROR::sync_node_jobs, stray job 21190.tyrone-cluster found on tyrone-node6
04/03/2013 00:41:18;0001;PBS_Server;Svr;PBS_Server;LOG_ERROR::sync_node_jobs, stray job 21306.tyrone-cluster found on tyrone-node5
04/03/2013 00:41:53;0001;PBS_Server;Svr;PBS_Server;LOG_ERROR::sync_node_jobs, stray job 21312.tyrone-cluster found on tyrone-node4
04/03/2013 00:42:00;0001;PBS_Server;Svr;PBS_Server;LOG_ERROR::sync_node_jobs, stray job 21190.tyrone-cluster found on tyrone-node6
04/03/2013 00:42:03;0001;PBS_Server;Svr;PBS_Server;LOG_ERROR::sync_node_jobs, stray job 21306.tyrone-cluster found on tyrone-node5
04/03/2013 00:42:37;0001;PBS_Server;Svr;PBS_Server;LOG_ERROR::sync_node_jobs, stray job 21312.tyrone-cluster found on tyrone-node4
04/03/2013 00:42:45;0001;PBS_Server;Svr;PBS_Server;LOG_ERROR::sync_node_jobs, stray job 21190.tyrone-cluster found on tyrone-node6
04/03/2013 00:42:48;0001;PBS_Server;Svr;PBS_Server;LOG_ERROR::sync_node_jobs, stray job 21306.tyrone-cluster found on tyrone-node5
04/03/2013 00:43:22;0001;PBS_Server;Svr;PBS_Server;LOG_ERROR::sync_node_jobs, stray job 21312.tyrone-cluster found on tyrone-node4
04/03/2013 00:43:30;0002;PBS_Server;Svr;PBS_Server;Torque Server Version = 3.0.5, loglevel = 0
04/03/2013 00:43:30;0001;PBS_Server;Svr;PBS_Server;LOG_ERROR::sync_node_jobs, stray job 21190.tyrone-cluster found on tyrone-node6
04/03/2013 00:43:33;0001;PBS_Server;Svr;PBS_Server;LOG_ERROR::sync_node_jobs, stray job 21306.tyrone-cluster found on tyrone-node5
04/03/2013 00:44:07;0001;PBS_Server;Svr;PBS_Server;LOG_ERROR::sync_node_jobs, stray job 21312.tyrone-cluster found on tyrone-node4
04/03/2013 00:44:15;0001;PBS_Server;Svr;PBS_Server;LOG_ERROR::sync_node_jobs, stray job 21190.tyrone-cluster found on tyrone-node6
04/03/2013 00:44:18;0001;PBS_Server;Svr;PBS_Server;LOG_ERROR::sync_node_jobs, stray job 21306.tyrone-cluster found on tyrone-node5
04/03/2013 00:44:52;0001;PBS_Server;Svr;PBS_Server;LOG_ERROR::sync_node_jobs, stray job 21312.tyrone-cluster found on tyrone-node4
04/03/2013 00:45:00;0001;PBS_Server;Svr;PBS_Server;LOG_ERROR::sync_node_jobs, stray job 21190.tyrone-cluster found on tyrone-node6
04/03/2013 00:45:03;0001;PBS_Server;Svr;PBS_Server;LOG_ERROR::sync_node_jobs, stray job 21306.tyrone-cluster found on tyrone-node5
04/03/2013 00:45:37;0001;PBS_Server;Svr;PBS_Server;LOG_ERROR::sync_node_jobs, stray job 21312.tyrone-cluster found on tyrone-node4
04/03/2013 00:45:45;0001;PBS_Server;Svr;PBS_Server;LOG_ERROR::sync_node_jobs, stray job 21190.tyrone-cluster found on tyrone-node6
04/03/2013 00:45:48;0001;PBS_Server;Svr;PBS_Server;LOG_ERROR::sync_node_jobs, stray job 21306.tyrone-cluster found on tyrone-node5
04/03/2013 00:46:22;0001;PBS_Server;Svr;PBS_Server;LOG_ERROR::sync_node_jobs, stray job 21312.tyrone-cluster found on tyrone-node4
04/03/2013 00:46:30;0001;PBS_Server;Svr;PBS_Server;LOG_ERROR::sync_node_jobs, stray job 21190.tyrone-cluster found on tyrone-node6
04/03/2013 00:46:33;0001;PBS_Server;Svr;PBS_Server;LOG_ERROR::sync_node_jobs, stray job 21306.tyrone-cluster found on tyrone-node5
04/03/2013 00:47:07;0001;PBS_Server;Svr;PBS_Server;LOG_ERROR::sync_node_jobs, stray job 21312.tyrone-cluster found on tyrone-node4
04/03/2013 00:47:15;0001;PBS_Server;Svr;PBS_Server;LOG_ERROR::sync_node_jobs, stray job 21190.tyrone-cluster found on tyrone-node6
04/03/2013 00:47:18;0001;PBS_Server;Svr;PBS_Server;LOG_ERROR::sync_node_jobs, stray job 21306.tyrone-cluster found on tyrone-node5
04/03/2013 00:47:52;0001;PBS_Server;Svr;PBS_Server;LOG_ERROR::sync_node_jobs, stray job 21312.tyrone-cluster found on tyrone-node4
04/03/2013 00:48:00;0001;PBS_Server;Svr;PBS_Server;LOG_ERROR::sync_node_jobs, stray job 21190.tyrone-cluster found on tyrone-node6
04/03/2013 00:48:03;0001;PBS_Server;Svr;PBS_Server;LOG_ERROR::sync_node_jobs, stray job 21306.tyrone-cluster found on tyrone-node5
04/03/2013 00:48:30;0002;PBS_Server;Svr;PBS_Server;Torque Server Version = 3.0.5, loglevel = 0
04/03/2013 00:48:33;0040;PBS_Server;Svr;tyrone-cluster;Scheduler was sent the command time
04/03/2013 00:48:37;0001;PBS_Server;Svr;PBS_Server;LOG_ERROR::sync_node_jobs, stray job 21312.tyrone-cluster found on tyrone-node4
04/03/2013 00:48:45;0001;PBS_Server;Svr;PBS_Server;LOG_ERROR::sync_node_jobs, stray job 21190.tyrone-cluster found on tyrone-node6
04/03/2013 00:48:48;0001;PBS_Server;Svr;PBS_Server;LOG_ERROR::sync_node_jobs, stray job 21306.tyrone-cluster found on tyrone-node5
04/03/2013 00:49:22;0001;PBS_Server;Svr;PBS_Server;LOG_ERROR::sync_node_jobs, stray job 21312.tyrone-cluster found on tyrone-node4
04/03/2013 00:49:30;0001;PBS_Server;Svr;PBS_Server;LOG_ERROR::sync_node_jobs, stray job 21190.tyrone-cluster found on tyrone-node6
04/03/2013 00:49:33;0001;PBS_Server;Svr;PBS_Server;LOG_ERROR::sync_node_jobs, stray job 21306.tyrone-cluster found on tyrone-node5
04/03/2013 00:50:07;0001;PBS_Server;Svr;PBS_Server;LOG_ERROR::sync_node_jobs, stray job 21312.tyrone-cluster found on tyrone-node4
04/03/2013 00:50:15;0001;PBS_Server;Svr;PBS_Server;LOG_ERROR::sync_node_jobs, stray job 21190.tyrone-cluster found on tyrone-node6
04/03/2013 00:50:18;0001;PBS_Server;Svr;PBS_Server;LOG_ERROR::sync_node_jobs, stray job 21306.tyrone-cluster found on tyrone-node5
04/03/2013 00:50:52;0001;PBS_Server;Svr;PBS_Server;LOG_ERROR::sync_node_jobs, stray job 21312.tyrone-cluster found on tyrone-node4
04/03/2013 00:51:00;0001;PBS_Server;Svr;PBS_Server;LOG_ERROR::sync_node_jobs, stray job 21190.tyrone-cluster found on tyrone-node6
04/03/2013 00:51:03;0001;PBS_Server;Svr;PBS_Server;LOG_ERROR::sync_node_jobs, stray job 21306.tyrone-cluster found on tyrone-node5
04/03/2013 00:51:38;0001;PBS_Server;Svr;PBS_Server;LOG_ERROR::sync_node_jobs, stray job 21312.tyrone-cluster found on tyrone-node4
04/03/2013 00:51:45;0001;PBS_Server;Svr;PBS_Server;LOG_ERROR::sync_node_jobs, stray job 21190.tyrone-cluster found on tyrone-node6
04/03/2013 00:51:49;0001;PBS_Server;Svr;PBS_Server;LOG_ERROR::sync_node_jobs, stray job 21306.tyrone-cluster found on tyrone-node5
04/03/2013 00:52:22;0001;PBS_Server;Svr;PBS_Server;LOG_ERROR::sync_node_jobs, stray job 21312.tyrone-cluster found on tyrone-node4
04/03/2013 00:52:30;0001;PBS_Server;Svr;PBS_Server;LOG_ERROR::sync_node_jobs, stray job 21190.tyrone-cluster found on tyrone-node6
04/03/2013 00:52:33;0001;PBS_Server;Svr;PBS_Server;LOG_ERROR::sync_node_jobs, stray job 21306.tyrone-cluster found on tyrone-node5
04/03/2013 00:53:07;0001;PBS_Server;Svr;PBS_Server;LOG_ERROR::sync_node_jobs, stray job 21312.tyrone-cluster found on tyrone-node4
04/03/2013 00:53:15;0001;PBS_Server;Svr;PBS_Server;LOG_ERROR::sync_node_jobs, stray job 21190.tyrone-cluster found on tyrone-node6
04/03/2013 00:53:18;0001;PBS_Server;Svr;PBS_Server;LOG_ERROR::sync_node_jobs, stray job 21306.tyrone-cluster found on tyrone-node5
04/03/2013 00:53:30;0002;PBS_Server;Svr;PBS_Server;Torque Server Version = 3.0.5, loglevel = 0
04/03/2013 00:53:52;0001;PBS_Server;Svr;PBS_Server;LOG_ERROR::sync_node_jobs, stray job 21312.tyrone-cluster found on tyrone-node4
04/03/2013 00:54:00;0001;PBS_Server;Svr;PBS_Server;LOG_ERROR::sync_node_jobs, stray job 21190.tyrone-cluster found on tyrone-node6
04/03/2013 00:54:03;0001;PBS_Server;Svr;PBS_Server;LOG_ERROR::sync_node_jobs, stray job 21306.tyrone-cluster found on tyrone-node5
04/03/2013 00:54:37;0001;PBS_Server;Svr;PBS_Server;LOG_ERROR::sync_node_jobs, stray job 21312.tyrone-cluster found on tyrone-node4
04/03/2013 00:54:45;0001;PBS_Server;Svr;PBS_Server;LOG_ERROR::sync_node_jobs, stray job 21190.tyrone-cluster found on tyrone-node6
04/03/2013 00:54:48;0001;PBS_Server;Svr;PBS_Server;LOG_ERROR::sync_node_jobs, stray job 21306.tyrone-cluster found on tyrone-node5
04/03/2013 00:55:22;0001;PBS_Server;Svr;PBS_Server;LOG_ERROR::sync_node_jobs, stray job 21312.tyrone-cluster found on tyrone-node4
04/03/2013 00:55:30;0001;PBS_Server;Svr;PBS_Server;LOG_ERROR::sync_node_jobs, stray job 21190.tyrone-cluster found on tyrone-node6
04/03/2013 00:55:33;0001;PBS_Server;Svr;PBS_Server;LOG_ERROR::sync_node_jobs, stray job 21306.tyrone-cluster found on tyrone-node5
04/03/2013 00:56:07;0001;PBS_Server;Svr;PBS_Server;LOG_ERROR::sync_node_jobs, stray job 21312.tyrone-cluster found on tyrone-node4
04/03/2013 00:56:15;0001;PBS_Server;Svr;PBS_Server;LOG_ERROR::sync_node_jobs, stray job 21190.tyrone-cluster found on tyrone-node6
04/03/2013 00:56:18;0001;PBS_Server;Svr;PBS_Server;LOG_ERROR::sync_node_jobs, stray job 21306.tyrone-cluster found on tyrone-node5
04/03/2013 00:56:52;0001;PBS_Server;Svr;PBS_Server;LOG_ERROR::sync_node_jobs, stray job 21312.tyrone-cluster found on tyrone-node4
04/03/2013 00:57:00;0001;PBS_Server;Svr;PBS_Server;LOG_ERROR::sync_node_jobs, stray job 21190.tyrone-cluster found on tyrone-node6
04/03/2013 00:57:03;0001;PBS_Server;Svr;PBS_Server;LOG_ERROR::sync_node_jobs, stray job 21306.tyrone-cluster found on tyrone-node5
04/03/2013 00:57:37;0001;PBS_Server;Svr;PBS_Server;LOG_ERROR::sync_node_jobs, stray job 21312.tyrone-cluster found on tyrone-node4
04/03/2013 00:57:45;0001;PBS_Server;Svr;PBS_Server;LOG_ERROR::sync_node_jobs, stray job 21190.tyrone-cluster found on tyrone-node6
04/03/2013 00:57:48;0001;PBS_Server;Svr;PBS_Server;LOG_ERROR::sync_node_jobs, stray job 21306.tyrone-cluster found on tyrone-node5
04/03/2013 00:58:22;0001;PBS_Server;Svr;PBS_Server;LOG_ERROR::sync_node_jobs, stray job 21312.tyrone-cluster found on tyrone-node4
04/03/2013 00:58:30;0001;PBS_Server;Svr;PBS_Server;LOG_ERROR::sync_node_jobs, stray job 21190.tyrone-cluster found on tyrone-node6
04/03/2013 00:58:30;0002;PBS_Server;Svr;PBS_Server;Torque Server Version = 3.0.5, loglevel = 0
04/03/2013 00:58:33;0001;PBS_Server;Svr;PBS_Server;LOG_ERROR::sync_node_jobs, stray job 21306.tyrone-cluster found on tyrone-node5
04/03/2013 00:58:33;0040;PBS_Server;Svr;tyrone-cluster;Scheduler was sent the command time
04/03/2013 00:59:07;0001;PBS_Server;Svr;PBS_Server;LOG_ERROR::sync_node_jobs, stray job 21312.tyrone-cluster found on tyrone-node4
04/03/2013 00:59:15;0001;PBS_Server;Svr;PBS_Server;LOG_ERROR::sync_node_jobs, stray job 21190.tyrone-cluster found on tyrone-node6
04/03/2013 00:59:18;0001;PBS_Server;Svr;PBS_Server;LOG_ERROR::sync_node_jobs, stray job 21306.tyrone-cluster found on tyrone-node5
04/03/2013 00:59:52;0001;PBS_Server;Svr;PBS_Server;LOG_ERROR::sync_node_jobs, stray job 21312.tyrone-cluster found on tyrone-node4
04/03/2013 01:00:00;0001;PBS_Server;Svr;PBS_Server;LOG_ERROR::sync_node_jobs, stray job 21190.tyrone-cluster found on tyrone-node6
04/03/2013 01:00:03;0001;PBS_Server;Svr;PBS_Server;LOG_ERROR::sync_node_jobs, stray job 21306.tyrone-cluster found on tyrone-node5
04/03/2013 01:00:37;0001;PBS_Server;Svr;PBS_Server;LOG_ERROR::sync_node_jobs, stray job 21312.tyrone-cluster found on tyrone-node4
04/03/2013 01:00:45;0001;PBS_Server;Svr;PBS_Server;LOG_ERROR::sync_node_jobs, stray job 21190.tyrone-cluster found on tyrone-node6
04/03/2013 01:00:48;0001;PBS_Server;Svr;PBS_Server;LOG_ERROR::sync_node_jobs, stray job 21306.tyrone-cluster found on tyrone-node5
04/03/2013 01:01:22;0001;PBS_Server;Svr;PBS_Server;LOG_ERROR::sync_node_jobs, stray job 21312.tyrone-cluster found on tyrone-node4
04/03/2013 01:01:30;0001;PBS_Server;Svr;PBS_Server;LOG_ERROR::sync_node_jobs, stray job 21190.tyrone-cluster found on tyrone-node6
04/03/2013 01:01:33;0001;PBS_Server;Svr;PBS_Server;LOG_ERROR::sync_node_jobs, stray job 21306.tyrone-cluster found on tyrone-node5
04/03/2013 01:02:06;0001;PBS_Server;Svr;PBS_Server;LOG_ERROR::sync_node_jobs, stray job 21312.tyrone-cluster found on tyrone-node4
04/03/2013 01:02:15;0001;PBS_Server;Svr;PBS_Server;LOG_ERROR::sync_node_jobs, stray job 21190.tyrone-cluster found on tyrone-node6
04/03/2013 01:02:18;0001;PBS_Server;Svr;PBS_Server;LOG_ERROR::sync_node_jobs, stray job 21306.tyrone-cluster found on tyrone-node5
04/03/2013 01:02:51;0001;PBS_Server;Svr;PBS_Server;LOG_ERROR::sync_node_jobs, stray job 21312.tyrone-cluster found on tyrone-node4
04/03/2013 01:02:59;0001;PBS_Server;Svr;PBS_Server;LOG_ERROR::sync_node_jobs, stray job 21190.tyrone-cluster found on tyrone-node6
04/03/2013 01:03:03;0001;PBS_Server;Svr;PBS_Server;LOG_ERROR::sync_node_jobs, stray job 21306.tyrone-cluster found on tyrone-node5
04/03/2013 01:03:30;0002;PBS_Server;Svr;PBS_Server;Torque Server Version = 3.0.5, loglevel = 0
04/03/2013 01:03:36;0001;PBS_Server;Svr;PBS_Server;LOG_ERROR::sync_node_jobs, stray job 21312.tyrone-cluster found on tyrone-node4
04/03/2013 01:03:44;0001;PBS_Server;Svr;PBS_Server;LOG_ERROR::sync_node_jobs, stray job 21190.tyrone-cluster found on tyrone-node6
04/03/2013 01:03:48;0001;PBS_Server;Svr;PBS_Server;LOG_ERROR::sync_node_jobs, stray job 21306.tyrone-cluster found on tyrone-node5
04/03/2013 01:04:22;0001;PBS_Server;Svr;PBS_Server;LOG_ERROR::sync_node_jobs, stray job 21312.tyrone-cluster found on tyrone-node4
04/03/2013 01:04:28;000d;PBS_Server;Job;21311.tyrone-cluster;Not sending email: User does not want mail of this type.
04/03/2013 01:04:28;0010;PBS_Server;Job;21311.tyrone-cluster;Exit_status=0 resources_used.cput=35:51:04 resources_used.mem=2549612kb resources_used.vmem=10547776kb resources_used.walltime=00:35:56
04/03/2013 01:04:28;0008;PBS_Server;Job;NULL;on_job_exit valid pjob: 0x1fa2f10 (substate=50)
04/03/2013 01:04:28;0008;PBS_Server;Job;NULL;on_job_exit valid pjob: 0x1fa2f10 (substate=51)
04/03/2013 01:04:29;0008;PBS_Server;Job;NULL;on_job_exit valid pjob: 0x1fa2f10 (substate=51)
04/03/2013 01:04:29;0008;PBS_Server;Job;NULL;on_job_exit valid pjob: 0x1fa2f10 (substate=53)
04/03/2013 01:04:29;0100;PBS_Server;Job;21311.tyrone-cluster;dequeuing from qp64, state COMPLETE
04/03/2013 01:04:29;0040;PBS_Server;Svr;tyrone-cluster;Scheduler was sent the command term
04/03/2013 01:04:30;0001;PBS_Server;Svr;PBS_Server;LOG_ERROR::sync_node_jobs, stray job 21190.tyrone-cluster found on tyrone-node6
04/03/2013 01:04:33;0001;PBS_Server;Svr;PBS_Server;LOG_ERROR::sync_node_jobs, stray job 21306.tyrone-cluster found on tyrone-node5
04/03/2013 01:05:07;0001;PBS_Server;Svr;PBS_Server;LOG_ERROR::sync_node_jobs, stray job 21312.tyrone-cluster found on tyrone-node4
04/03/2013 01:05:15;0001;PBS_Server;Svr;PBS_Server;LOG_ERROR::sync_node_jobs, stray job 21190.tyrone-cluster found on tyrone-node6
04/03/2013 01:05:18;0001;PBS_Server;Svr;PBS_Server;LOG_ERROR::sync_node_jobs, stray job 21306.tyrone-cluster found on tyrone-node5
04/03/2013 01:05:52;0001;PBS_Server;Svr;PBS_Server;LOG_ERROR::sync_node_jobs, stray job 21312.tyrone-cluster found on tyrone-node4
04/03/2013 01:06:00;0001;PBS_Server;Svr;PBS_Server;LOG_ERROR::sync_node_jobs, stray job 21190.tyrone-cluster found on tyrone-node6
04/03/2013 01:06:03;0001;PBS_Server;Svr;PBS_Server;LOG_ERROR::sync_node_jobs, stray job 21306.tyrone-cluster found on tyrone-node5
04/03/2013 01:06:37;0001;PBS_Server;Svr;PBS_Server;LOG_ERROR::sync_node_jobs, stray job 21312.tyrone-cluster found on tyrone-node4
04/03/2013 01:06:45;0001;PBS_Server;Svr;PBS_Server;LOG_ERROR::sync_node_jobs, stray job 21190.tyrone-cluster found on tyrone-node6
04/03/2013 01:06:48;0001;PBS_Server;Svr;PBS_Server;LOG_ERROR::sync_node_jobs, stray job 21306.tyrone-cluster found on tyrone-node5
04/03/2013 01:07:22;0001;PBS_Server;Svr;PBS_Server;LOG_ERROR::sync_node_jobs, stray job 21312.tyrone-cluster found on tyrone-node4
04/03/2013 01:07:30;0001;PBS_Server;Svr;PBS_Server;LOG_ERROR::sync_node_jobs, stray job 21190.tyrone-cluster found on tyrone-node6
04/03/2013 01:07:33;0001;PBS_Server;Svr;PBS_Server;LOG_ERROR::sync_node_jobs, stray job 21306.tyrone-cluster found on tyrone-node5
04/03/2013 01:08:07;0001;PBS_Server;Svr;PBS_Server;LOG_ERROR::sync_node_jobs, stray job 21312.tyrone-cluster found on tyrone-node4
04/03/2013 01:08:15;0001;PBS_Server;Svr;PBS_Server;LOG_ERROR::sync_node_jobs, stray job 21190.tyrone-cluster found on tyrone-node6
04/03/2013 01:08:18;0001;PBS_Server;Svr;PBS_Server;LOG_ERROR::sync_node_jobs, stray job 21306.tyrone-cluster found on tyrone-node5
04/03/2013 01:08:30;0002;PBS_Server;Svr;PBS_Server;Torque Server Version = 3.0.5, loglevel = 0
04/03/2013 01:08:52;0001;PBS_Server;Svr;PBS_Server;LOG_ERROR::sync_node_jobs, stray job 21312.tyrone-cluster found on tyrone-node4
04/03/2013 01:09:00;0001;PBS_Server;Svr;PBS_Server;LOG_ERROR::sync_node_jobs, stray job 21190.tyrone-cluster found on tyrone-node6
04/03/2013 01:09:03;0001;PBS_Server;Svr;PBS_Server;LOG_ERROR::sync_node_jobs, stray job 21306.tyrone-cluster found on tyrone-node5
04/03/2013 01:09:37;0001;PBS_Server;Svr;PBS_Server;LOG_ERROR::sync_node_jobs, stray job 21312.tyrone-cluster found on tyrone-node4
04/03/2013 01:09:45;0001;PBS_Server;Svr;PBS_Server;LOG_ERROR::sync_node_jobs, stray job 21190.tyrone-cluster found on tyrone-node6
04/03/2013 01:09:48;0001;PBS_Server;Svr;PBS_Server;LOG_ERROR::sync_node_jobs, stray job 21306.tyrone-cluster found on tyrone-node5
04/03/2013 01:10:22;0001;PBS_Server;Svr;PBS_Server;LOG_ERROR::sync_node_jobs, stray job 21312.tyrone-cluster found on tyrone-node4
04/03/2013 01:10:30;0001;PBS_Server;Svr;PBS_Server;LOG_ERROR::sync_node_jobs, stray job 21190.tyrone-cluster found on tyrone-node6
04/03/2013 01:10:33;0001;PBS_Server;Svr;PBS_Server;LOG_ERROR::sync_node_jobs, stray job 21306.tyrone-cluster found on tyrone-node5
04/03/2013 01:11:07;0001;PBS_Server;Svr;PBS_Server;LOG_ERROR::sync_node_jobs, stray job 21312.tyrone-cluster found on tyrone-node4
04/03/2013 01:11:15;0001;PBS_Server;Svr;PBS_Server;LOG_ERROR::sync_node_jobs, stray job 21190.tyrone-cluster found on tyrone-node6
04/03/2013 01:11:18;0001;PBS_Server;Svr;PBS_Server;LOG_ERROR::sync_node_jobs, stray job 21306.tyrone-cluster found on tyrone-node5
04/03/2013 01:11:51;0001;PBS_Server;Svr;PBS_Server;LOG_ERROR::sync_node_jobs, stray job 21312.tyrone-cluster found on tyrone-node4
04/03/2013 01:12:00;0001;PBS_Server;Svr;PBS_Server;LOG_ERROR::sync_node_jobs, stray job 21190.tyrone-cluster found on tyrone-node6
04/03/2013 01:12:03;0001;PBS_Server;Svr;PBS_Server;LOG_ERROR::sync_node_jobs, stray job 21306.tyrone-cluster found on tyrone-node5
04/03/2013 01:12:36;0001;PBS_Server;Svr;PBS_Server;LOG_ERROR::sync_node_jobs, stray job 21312.tyrone-cluster found on tyrone-node4
04/03/2013 01:12:45;0001;PBS_Server;Svr;PBS_Server;LOG_ERROR::sync_node_jobs, stray job 21190.tyrone-cluster found on tyrone-node6
04/03/2013 01:12:48;0001;PBS_Server;Svr;PBS_Server;LOG_ERROR::sync_node_jobs, stray job 21306.tyrone-cluster found on tyrone-node5
04/03/2013 01:13:21;0001;PBS_Server;Svr;PBS_Server;LOG_ERROR::sync_node_jobs, stray job 21312.tyrone-cluster found on tyrone-node4
04/03/2013 01:13:30;0002;PBS_Server;Svr;PBS_Server;Torque Server Version = 3.0.5, loglevel = 0
04/03/2013 01:13:30;0001;PBS_Server;Svr;PBS_Server;LOG_ERROR::sync_node_jobs, stray job 21190.tyrone-cluster found on tyrone-node6
04/03/2013 01:13:33;0001;PBS_Server;Svr;PBS_Server;LOG_ERROR::sync_node_jobs, stray job 21306.tyrone-cluster found on tyrone-node5
04/03/2013 01:14:06;0001;PBS_Server;Svr;PBS_Server;LOG_ERROR::sync_node_jobs, stray job 21312.tyrone-cluster found on tyrone-node4
04/03/2013 01:14:14;0001;PBS_Server;Svr;PBS_Server;LOG_ERROR::sync_node_jobs, stray job 21190.tyrone-cluster found on tyrone-node6
04/03/2013 01:14:18;0001;PBS_Server;Svr;PBS_Server;LOG_ERROR::sync_node_jobs, stray job 21306.tyrone-cluster found on tyrone-node5
04/03/2013 01:14:29;0040;PBS_Server;Svr;tyrone-cluster;Scheduler was sent the command time
04/03/2013 01:14:51;0001;PBS_Server;Svr;PBS_Server;LOG_ERROR::sync_node_jobs, stray job 21312.tyrone-cluster found on tyrone-node4
04/03/2013 01:14:59;0001;PBS_Server;Svr;PBS_Server;LOG_ERROR::sync_node_jobs, stray job 21190.tyrone-cluster found on tyrone-node6
04/03/2013 01:15:03;0001;PBS_Server;Svr;PBS_Server;LOG_ERROR::sync_node_jobs, stray job 21306.tyrone-cluster found on tyrone-node5
04/03/2013 01:15:36;0001;PBS_Server;Svr;PBS_Server;LOG_ERROR::sync_node_jobs, stray job 21312.tyrone-cluster found on tyrone-node4
04/03/2013 01:15:44;0001;PBS_Server;Svr;PBS_Server;LOG_ERROR::sync_node_jobs, stray job 21190.tyrone-cluster found on tyrone-node6
04/03/2013 01:15:48;0001;PBS_Server;Svr;PBS_Server;LOG_ERROR::sync_node_jobs, stray job 21306.tyrone-cluster found on tyrone-node5
04/03/2013 01:16:22;0001;PBS_Server;Svr;PBS_Server;LOG_ERROR::sync_node_jobs, stray job 21312.tyrone-cluster found on tyrone-node4
04/03/2013 01:16:30;0001;PBS_Server;Svr;PBS_Server;LOG_ERROR::sync_node_jobs, stray job 21190.tyrone-cluster found on tyrone-node6
04/03/2013 01:16:33;0001;PBS_Server;Svr;PBS_Server;LOG_ERROR::sync_node_jobs, stray job 21306.tyrone-cluster found on tyrone-node5
04/03/2013 01:17:07;0001;PBS_Server;Svr;PBS_Server;LOG_ERROR::sync_node_jobs, stray job 21312.tyrone-cluster found on tyrone-node4
04/03/2013 01:17:15;0001;PBS_Server;Svr;PBS_Server;LOG_ERROR::sync_node_jobs, stray job 21190.tyrone-cluster found on tyrone-node6
04/03/2013 01:17:18;0001;PBS_Server;Svr;PBS_Server;LOG_ERROR::sync_node_jobs, stray job 21306.tyrone-cluster found on tyrone-node5
04/03/2013 01:17:52;0001;PBS_Server;Svr;PBS_Server;LOG_ERROR::sync_node_jobs, stray job 21312.tyrone-cluster found on tyrone-node4
04/03/2013 01:18:00;0001;PBS_Server;Svr;PBS_Server;LOG_ERROR::sync_node_jobs, stray job 21190.tyrone-cluster found on tyrone-node6
04/03/2013 01:18:03;0001;PBS_Server;Svr;PBS_Server;LOG_ERROR::sync_node_jobs, stray job 21306.tyrone-cluster found on tyrone-node5
04/03/2013 01:18:30;0002;PBS_Server;Svr;PBS_Server;Torque Server Version = 3.0.5, loglevel = 0
04/03/2013 01:18:37;0001;PBS_Server;Svr;PBS_Server;LOG_ERROR::sync_node_jobs, stray job 21312.tyrone-cluster found on tyrone-node4
04/03/2013 01:18:45;0001;PBS_Server;Svr;PBS_Server;LOG_ERROR::sync_node_jobs, stray job 21190.tyrone-cluster found on tyrone-node6
04/03/2013 01:18:48;0001;PBS_Server;Svr;PBS_Server;LOG_ERROR::sync_node_jobs, stray job 21306.tyrone-cluster found on tyrone-node5
04/03/2013 01:19:22;0001;PBS_Server;Svr;PBS_Server;LOG_ERROR::sync_node_jobs, stray job 21312.tyrone-cluster found on tyrone-node4
04/03/2013 01:19:30;0001;PBS_Server;Svr;PBS_Server;LOG_ERROR::sync_node_jobs, stray job 21190.tyrone-cluster found on tyrone-node6
04/03/2013 01:19:33;0001;PBS_Server;Svr;PBS_Server;LOG_ERROR::sync_node_jobs, stray job 21306.tyrone-cluster found on tyrone-node5
04/03/2013 01:20:07;0001;PBS_Server;Svr;PBS_Server;LOG_ERROR::sync_node_jobs, stray job 21312.tyrone-cluster found on tyrone-node4
04/03/2013 01:20:15;0001;PBS_Server;Svr;PBS_Server;LOG_ERROR::sync_node_jobs, stray job 21190.tyrone-cluster found on tyrone-node6
04/03/2013 01:20:18;0001;PBS_Server;Svr;PBS_Server;LOG_ERROR::sync_node_jobs, stray job 21306.tyrone-cluster found on tyrone-node5
04/03/2013 01:20:52;0001;PBS_Server;Svr;PBS_Server;LOG_ERROR::sync_node_jobs, stray job 21312.tyrone-cluster found on tyrone-node4
04/03/2013 01:21:00;0001;PBS_Server;Svr;PBS_Server;LOG_ERROR::sync_node_jobs, stray job 21190.tyrone-cluster found on tyrone-node6
04/03/2013 01:21:03;0001;PBS_Server;Svr;PBS_Server;LOG_ERROR::sync_node_jobs, stray job 21306.tyrone-cluster found on tyrone-node5
04/03/2013 01:21:36;0001;PBS_Server;Svr;PBS_Server;LOG_ERROR::sync_node_jobs, stray job 21312.tyrone-cluster found on tyrone-node4
04/03/2013 01:21:45;0001;PBS_Server;Svr;PBS_Server;LOG_ERROR::sync_node_jobs, stray job 21190.tyrone-cluster found on tyrone-node6
04/03/2013 01:21:48;0001;PBS_Server;Svr;PBS_Server;LOG_ERROR::sync_node_jobs, stray job 21306.tyrone-cluster found on tyrone-node5
04/03/2013 01:22:21;0001;PBS_Server;Svr;PBS_Server;LOG_ERROR::sync_node_jobs, stray job 21312.tyrone-cluster found on tyrone-node4
04/03/2013 01:22:30;0001;PBS_Server;Svr;PBS_Server;LOG_ERROR::sync_node_jobs, stray job 21190.tyrone-cluster found on tyrone-node6
04/03/2013 01:22:33;0001;PBS_Server;Svr;PBS_Server;LOG_ERROR::sync_node_jobs, stray job 21306.tyrone-cluster found on tyrone-node5
04/03/2013 01:23:06;0001;PBS_Server;Svr;PBS_Server;LOG_ERROR::sync_node_jobs, stray job 21312.tyrone-cluster found on tyrone-node4
04/03/2013 01:23:15;0001;PBS_Server;Svr;PBS_Server;LOG_ERROR::sync_node_jobs, stray job 21190.tyrone-cluster found on tyrone-node6
04/03/2013 01:23:18;0100;PBS_Server;Job;21313.tyrone-cluster;enqueuing into batch, state 1 hop 1
04/03/2013 01:23:18;0100;PBS_Server;Job;21313.tyrone-cluster;dequeuing from batch, state QUEUED
04/03/2013 01:23:18;0100;PBS_Server;Job;21313.tyrone-cluster;enqueuing into qp32, state 1 hop 1
04/03/2013 01:23:18;0008;PBS_Server;Job;21313.tyrone-cluster;Job Queued at request of secgeet@tyrone-cluster, owner = secgeet@tyrone-cluster, job name = run, queue = qp32
04/03/2013 01:23:18;0040;PBS_Server;Svr;tyrone-cluster;Scheduler was sent the command new
04/03/2013 01:23:18;0001;PBS_Server;Svr;PBS_Server;LOG_ERROR::sync_node_jobs, stray job 21306.tyrone-cluster found on tyrone-node5
04/03/2013 01:23:18;0008;PBS_Server;Job;21313.tyrone-cluster;Job Modified at request of Scheduler@tyrone-cluster
04/03/2013 01:23:18;0008;PBS_Server;Job;21313.tyrone-cluster;Job Run at request of Scheduler@tyrone-cluster
04/03/2013 01:23:18;0040;PBS_Server;Svr;tyrone-cluster;Scheduler was sent the command recyc
04/03/2013 01:23:18;000d;PBS_Server;Job;21313.tyrone-cluster;Not sending email: User does not want mail of this type.
04/03/2013 01:23:27;000d;PBS_Server;Job;21313.tyrone-cluster;Not sending email: User does not want mail of this type.
04/03/2013 01:23:27;0010;PBS_Server;Job;21313.tyrone-cluster;Exit_status=0 resources_used.cput=00:02:03 resources_used.mem=0kb resources_used.vmem=0kb resources_used.walltime=00:00:09
04/03/2013 01:23:27;0008;PBS_Server;Job;NULL;on_job_exit valid pjob: 0x1fd3700 (substate=50)
04/03/2013 01:23:27;0008;PBS_Server;Job;NULL;on_job_exit valid pjob: 0x1fd3700 (substate=51)
04/03/2013 01:23:27;0008;PBS_Server;Job;NULL;on_job_exit valid pjob: 0x1fd3700 (substate=51)
04/03/2013 01:23:27;0008;PBS_Server;Job;NULL;on_job_exit valid pjob: 0x1fd3700 (substate=53)
04/03/2013 01:23:27;0100;PBS_Server;Job;21313.tyrone-cluster;dequeuing from qp32, state COMPLETE
04/03/2013 01:23:27;0040;PBS_Server;Svr;tyrone-cluster;Scheduler was sent the command term
04/03/2013 01:23:30;0002;PBS_Server;Svr;PBS_Server;Torque Server Version = 3.0.5, loglevel = 0
04/03/2013 01:23:51;0001;PBS_Server;Svr;PBS_Server;LOG_ERROR::sync_node_jobs, stray job 21312.tyrone-cluster found on tyrone-node4
04/03/2013 01:23:59;0001;PBS_Server;Svr;PBS_Server;LOG_ERROR::sync_node_jobs, stray job 21190.tyrone-cluster found on tyrone-node6
04/03/2013 01:24:03;0001;PBS_Server;Svr;PBS_Server;LOG_ERROR::sync_node_jobs, stray job 21306.tyrone-cluster found on tyrone-node5
04/03/2013 01:24:36;0001;PBS_Server;Svr;PBS_Server;LOG_ERROR::sync_node_jobs, stray job 21312.tyrone-cluster found on tyrone-node4
04/03/2013 01:24:44;0001;PBS_Server;Svr;PBS_Server;LOG_ERROR::sync_node_jobs, stray job 21190.tyrone-cluster found on tyrone-node6
04/03/2013 01:24:48;0001;PBS_Server;Svr;PBS_Server;LOG_ERROR::sync_node_jobs, stray job 21306.tyrone-cluster found on tyrone-node5
04/03/2013 01:25:21;0001;PBS_Server;Svr;PBS_Server;LOG_ERROR::sync_node_jobs, stray job 21312.tyrone-cluster found on tyrone-node4
04/03/2013 01:25:29;0001;PBS_Server;Svr;PBS_Server;LOG_ERROR::sync_node_jobs, stray job 21190.tyrone-cluster found on tyrone-node6
04/03/2013 01:25:33;0001;PBS_Server;Svr;PBS_Server;LOG_ERROR::sync_node_jobs, stray job 21306.tyrone-cluster found on tyrone-node5
04/03/2013 01:26:07;0001;PBS_Server;Svr;PBS_Server;LOG_ERROR::sync_node_jobs, stray job 21312.tyrone-cluster found on tyrone-node4
04/03/2013 01:26:15;0001;PBS_Server;Svr;PBS_Server;LOG_ERROR::sync_node_jobs, stray job 21190.tyrone-cluster found on tyrone-node6
04/03/2013 01:26:18;0001;PBS_Server;Svr;PBS_Server;LOG_ERROR::sync_node_jobs, stray job 21306.tyrone-cluster found on tyrone-node5
04/03/2013 01:26:52;0001;PBS_Server;Svr;PBS_Server;LOG_ERROR::sync_node_jobs, stray job 21312.tyrone-cluster found on tyrone-node4
04/03/2013 01:27:00;0001;PBS_Server;Svr;PBS_Server;LOG_ERROR::sync_node_jobs, stray job 21190.tyrone-cluster found on tyrone-node6
04/03/2013 01:27:03;0001;PBS_Server;Svr;PBS_Server;LOG_ERROR::sync_node_jobs, stray job 21306.tyrone-cluster found on tyrone-node5
04/03/2013 01:27:37;0001;PBS_Server;Svr;PBS_Server;LOG_ERROR::sync_node_jobs, stray job 21312.tyrone-cluster found on tyrone-node4
04/03/2013 01:27:45;0001;PBS_Server;Svr;PBS_Server;LOG_ERROR::sync_node_jobs, stray job 21190.tyrone-cluster found on tyrone-node6
04/03/2013 01:27:48;0001;PBS_Server;Svr;PBS_Server;LOG_ERROR::sync_node_jobs, stray job 21306.tyrone-cluster found on tyrone-node5
04/03/2013 01:28:22;0001;PBS_Server;Svr;PBS_Server;LOG_ERROR::sync_node_jobs, stray job 21312.tyrone-cluster found on tyrone-node4
04/03/2013 01:28:30;0002;PBS_Server;Svr;PBS_Server;Torque Server Version = 3.0.5, loglevel = 0
04/03/2013 01:28:30;0001;PBS_Server;Svr;PBS_Server;LOG_ERROR::sync_node_jobs, stray job 21190.tyrone-cluster found on tyrone-node6
04/03/2013 01:28:33;0001;PBS_Server;Svr;PBS_Server;LOG_ERROR::sync_node_jobs, stray job 21306.tyrone-cluster found on tyrone-node5
04/03/2013 01:29:06;0001;PBS_Server;Svr;PBS_Server;LOG_ERROR::sync_node_jobs, stray job 21312.tyrone-cluster found on tyrone-node4
04/03/2013 01:29:15;0001;PBS_Server;Svr;PBS_Server;LOG_ERROR::sync_node_jobs, stray job 21190.tyrone-cluster found on tyrone-node6
04/03/2013 01:29:18;0001;PBS_Server;Svr;PBS_Server;LOG_ERROR::sync_node_jobs, stray job 21306.tyrone-cluster found on tyrone-node5
04/03/2013 01:29:51;0001;PBS_Server;Svr;PBS_Server;LOG_ERROR::sync_node_jobs, stray job 21312.tyrone-cluster found on tyrone-node4
04/03/2013 01:30:00;0001;PBS_Server;Svr;PBS_Server;LOG_ERROR::sync_node_jobs, stray job 21190.tyrone-cluster found on tyrone-node6
04/03/2013 01:30:03;0001;PBS_Server;Svr;PBS_Server;LOG_ERROR::sync_node_jobs, stray job 21306.tyrone-cluster found on tyrone-node5
04/03/2013 01:30:36;0001;PBS_Server;Svr;PBS_Server;LOG_ERROR::sync_node_jobs, stray job 21312.tyrone-cluster found on tyrone-node4
04/03/2013 01:30:45;0001;PBS_Server;Svr;PBS_Server;LOG_ERROR::sync_node_jobs, stray job 21190.tyrone-cluster found on tyrone-node6
04/03/2013 01:30:48;0001;PBS_Server;Svr;PBS_Server;LOG_ERROR::sync_node_jobs, stray job 21306.tyrone-cluster found on tyrone-node5
04/03/2013 01:31:21;0001;PBS_Server;Svr;PBS_Server;LOG_ERROR::sync_node_jobs, stray job 21312.tyrone-cluster found on tyrone-node4
04/03/2013 01:31:30;0001;PBS_Server;Svr;PBS_Server;LOG_ERROR::sync_node_jobs, stray job 21190.tyrone-cluster found on tyrone-node6
04/03/2013 01:31:33;0001;PBS_Server;Svr;PBS_Server;LOG_ERROR::sync_node_jobs, stray job 21306.tyrone-cluster found on tyrone-node5
04/03/2013 01:32:06;0001;PBS_Server;Svr;PBS_Server;LOG_ERROR::sync_node_jobs, stray job 21312.tyrone-cluster found on tyrone-node4
04/03/2013 01:32:15;0001;PBS_Server;Svr;PBS_Server;LOG_ERROR::sync_node_jobs, stray job 21190.tyrone-cluster found on tyrone-node6
04/03/2013 01:32:18;0001;PBS_Server;Svr;PBS_Server;LOG_ERROR::sync_node_jobs, stray job 21306.tyrone-cluster found on tyrone-node5
04/03/2013 01:32:51;0001;PBS_Server;Svr;PBS_Server;LOG_ERROR::sync_node_jobs, stray job 21312.tyrone-cluster found on tyrone-node4
04/03/2013 01:33:00;0001;PBS_Server;Svr;PBS_Server;LOG_ERROR::sync_node_jobs, stray job 21190.tyrone-cluster found on tyrone-node6
04/03/2013 01:33:03;0001;PBS_Server;Svr;PBS_Server;LOG_ERROR::sync_node_jobs, stray job 21306.tyrone-cluster found on tyrone-node5
04/03/2013 01:33:27;0040;PBS_Server;Svr;tyrone-cluster;Scheduler was sent the command time
04/03/2013 01:33:30;0002;PBS_Server;Svr;PBS_Server;Torque Server Version = 3.0.5, loglevel = 0
04/03/2013 01:33:36;0001;PBS_Server;Svr;PBS_Server;LOG_ERROR::sync_node_jobs, stray job 21312.tyrone-cluster found on tyrone-node4
04/03/2013 01:33:45;0001;PBS_Server;Svr;PBS_Server;LOG_ERROR::sync_node_jobs, stray job 21190.tyrone-cluster found on tyrone-node6
04/03/2013 01:33:48;0001;PBS_Server;Svr;PBS_Server;LOG_ERROR::sync_node_jobs, stray job 21306.tyrone-cluster found on tyrone-node5
04/03/2013 01:34:21;0001;PBS_Server;Svr;PBS_Server;LOG_ERROR::sync_node_jobs, stray job 21312.tyrone-cluster found on tyrone-node4
04/03/2013 01:34:30;0001;PBS_Server;Svr;PBS_Server;LOG_ERROR::sync_node_jobs, stray job 21190.tyrone-cluster found on tyrone-node6
04/03/2013 01:34:33;0001;PBS_Server;Svr;PBS_Server;LOG_ERROR::sync_node_jobs, stray job 21306.tyrone-cluster found on tyrone-node5
04/03/2013 01:35:06;0001;PBS_Server;Svr;PBS_Server;LOG_ERROR::sync_node_jobs, stray job 21312.tyrone-cluster found on tyrone-node4
04/03/2013 01:35:14;0001;PBS_Server;Svr;PBS_Server;LOG_ERROR::sync_node_jobs, stray job 21190.tyrone-cluster found on tyrone-node6
04/03/2013 01:35:18;0001;PBS_Server;Svr;PBS_Server;LOG_ERROR::sync_node_jobs, stray job 21306.tyrone-cluster found on tyrone-node5
04/03/2013 01:35:51;0001;PBS_Server;Svr;PBS_Server;LOG_ERROR::sync_node_jobs, stray job 21312.tyrone-cluster found on tyrone-node4
04/03/2013 01:35:59;0001;PBS_Server;Svr;PBS_Server;LOG_ERROR::sync_node_jobs, stray job 21190.tyrone-cluster found on tyrone-node6
04/03/2013 01:36:03;0001;PBS_Server;Svr;PBS_Server;LOG_ERROR::sync_node_jobs, stray job 21306.tyrone-cluster found on tyrone-node5
04/03/2013 01:36:35;0100;PBS_Server;Job;21314.tyrone-cluster;enqueuing into batch, state 1 hop 1
04/03/2013 01:36:35;0100;PBS_Server;Job;21314.tyrone-cluster;dequeuing from batch, state QUEUED
04/03/2013 01:36:35;0100;PBS_Server;Job;21314.tyrone-cluster;enqueuing into qp32, state 1 hop 1
04/03/2013 01:36:35;0008;PBS_Server;Job;21314.tyrone-cluster;Job Queued at request of secgeet@tyrone-cluster, owner = secgeet@tyrone-cluster, job name = run, queue = qp32
04/03/2013 01:36:35;0040;PBS_Server;Svr;tyrone-cluster;Scheduler was sent the command new
04/03/2013 01:36:35;0008;PBS_Server;Job;21314.tyrone-cluster;Job Modified at request of Scheduler@tyrone-cluster
04/03/2013 01:36:35;0008;PBS_Server;Job;21314.tyrone-cluster;Job Run at request of Scheduler@tyrone-cluster
04/03/2013 01:36:35;0040;PBS_Server;Svr;tyrone-cluster;Scheduler was sent the command recyc
04/03/2013 01:36:35;000d;PBS_Server;Job;21314.tyrone-cluster;Not sending email: User does not want mail of this type.
04/03/2013 01:36:36;0001;PBS_Server;Svr;PBS_Server;LOG_ERROR::sync_node_jobs, stray job 21312.tyrone-cluster found on tyrone-node4
04/03/2013 01:36:44;000d;PBS_Server;Job;21314.tyrone-cluster;Not sending email: User does not want mail of this type.
04/03/2013 01:36:44;0010;PBS_Server;Job;21314.tyrone-cluster;Exit_status=0 resources_used.cput=00:02:02 resources_used.mem=0kb resources_used.vmem=0kb resources_used.walltime=00:00:09
04/03/2013 01:36:44;0008;PBS_Server;Job;NULL;on_job_exit valid pjob: 0x1fd3700 (substate=50)
04/03/2013 01:36:44;0008;PBS_Server;Job;NULL;on_job_exit valid pjob: 0x1fd3700 (substate=51)
04/03/2013 01:36:44;0008;PBS_Server;Job;NULL;on_job_exit valid pjob: 0x1fd3700 (substate=51)
04/03/2013 01:36:44;0008;PBS_Server;Job;NULL;on_job_exit valid pjob: 0x1fd3700 (substate=53)
04/03/2013 01:36:44;0100;PBS_Server;Job;21314.tyrone-cluster;dequeuing from qp32, state COMPLETE
04/03/2013 01:36:44;0040;PBS_Server;Svr;tyrone-cluster;Scheduler was sent the command term
04/03/2013 01:36:45;0001;PBS_Server;Svr;PBS_Server;LOG_ERROR::sync_node_jobs, stray job 21190.tyrone-cluster found on tyrone-node6
04/03/2013 01:36:48;0001;PBS_Server;Svr;PBS_Server;LOG_ERROR::sync_node_jobs, stray job 21306.tyrone-cluster found on tyrone-node5
04/03/2013 01:37:22;0001;PBS_Server;Svr;PBS_Server;LOG_ERROR::sync_node_jobs, stray job 21312.tyrone-cluster found on tyrone-node4
04/03/2013 01:37:30;0001;PBS_Server;Svr;PBS_Server;LOG_ERROR::sync_node_jobs, stray job 21190.tyrone-cluster found on tyrone-node6
04/03/2013 01:37:33;0001;PBS_Server;Svr;PBS_Server;LOG_ERROR::sync_node_jobs, stray job 21306.tyrone-cluster found on tyrone-node5
04/03/2013 01:38:06;0001;PBS_Server;Svr;PBS_Server;LOG_ERROR::sync_node_jobs, stray job 21312.tyrone-cluster found on tyrone-node4
04/03/2013 01:38:15;0001;PBS_Server;Svr;PBS_Server;LOG_ERROR::sync_node_jobs, stray job 21190.tyrone-cluster found on tyrone-node6
04/03/2013 01:38:18;0001;PBS_Server;Svr;PBS_Server;LOG_ERROR::sync_node_jobs, stray job 21306.tyrone-cluster found on tyrone-node5
04/03/2013 01:38:30;0002;PBS_Server;Svr;PBS_Server;Torque Server Version = 3.0.5, loglevel = 0
04/03/2013 01:38:51;0001;PBS_Server;Svr;PBS_Server;LOG_ERROR::sync_node_jobs, stray job 21312.tyrone-cluster found on tyrone-node4
04/03/2013 01:39:00;0001;PBS_Server;Svr;PBS_Server;LOG_ERROR::sync_node_jobs, stray job 21190.tyrone-cluster found on tyrone-node6
04/03/2013 01:39:03;0001;PBS_Server;Svr;PBS_Server;LOG_ERROR::sync_node_jobs, stray job 21306.tyrone-cluster found on tyrone-node5
04/03/2013 01:39:36;0001;PBS_Server;Svr;PBS_Server;LOG_ERROR::sync_node_jobs, stray job 21312.tyrone-cluster found on tyrone-node4
04/03/2013 01:39:45;0001;PBS_Server;Svr;PBS_Server;LOG_ERROR::sync_node_jobs, stray job 21190.tyrone-cluster found on tyrone-node6
04/03/2013 01:39:48;0001;PBS_Server;Svr;PBS_Server;LOG_ERROR::sync_node_jobs, stray job 21306.tyrone-cluster found on tyrone-node5
04/03/2013 01:40:21;0001;PBS_Server;Svr;PBS_Server;LOG_ERROR::sync_node_jobs, stray job 21312.tyrone-cluster found on tyrone-node4
04/03/2013 01:40:30;0001;PBS_Server;Svr;PBS_Server;LOG_ERROR::sync_node_jobs, stray job 21190.tyrone-cluster found on tyrone-node6
04/03/2013 01:40:33;0001;PBS_Server;Svr;PBS_Server;LOG_ERROR::sync_node_jobs, stray job 21306.tyrone-cluster found on tyrone-node5
04/03/2013 01:41:06;0001;PBS_Server;Svr;PBS_Server;LOG_ERROR::sync_node_jobs, stray job 21312.tyrone-cluster found on tyrone-node4
04/03/2013 01:41:15;0001;PBS_Server;Svr;PBS_Server;LOG_ERROR::sync_node_jobs, stray job 21190.tyrone-cluster found on tyrone-node6
04/03/2013 01:41:18;0001;PBS_Server;Svr;PBS_Server;LOG_ERROR::sync_node_jobs, stray job 21306.tyrone-cluster found on tyrone-node5
04/03/2013 01:41:51;0001;PBS_Server;Svr;PBS_Server;LOG_ERROR::sync_node_jobs, stray job 21312.tyrone-cluster found on tyrone-node4
04/03/2013 01:42:00;0001;PBS_Server;Svr;PBS_Server;LOG_ERROR::sync_node_jobs, stray job 21190.tyrone-cluster found on tyrone-node6
04/03/2013 01:42:03;0001;PBS_Server;Svr;PBS_Server;LOG_ERROR::sync_node_jobs, stray job 21306.tyrone-cluster found on tyrone-node5
04/03/2013 01:42:22;0100;PBS_Server;Job;21315.tyrone-cluster;enqueuing into batch, state 1 hop 1
04/03/2013 01:42:22;0100;PBS_Server;Job;21315.tyrone-cluster;dequeuing from batch, state QUEUED
04/03/2013 01:42:22;0100;PBS_Server;Job;21315.tyrone-cluster;enqueuing into qp32, state 1 hop 1
04/03/2013 01:42:22;0008;PBS_Server;Job;21315.tyrone-cluster;Job Queued at request of secgeet@tyrone-cluster, owner = secgeet@tyrone-cluster, job name = run, queue = qp32
04/03/2013 01:42:22;0040;PBS_Server;Svr;tyrone-cluster;Scheduler was sent the command new
04/03/2013 01:42:22;0008;PBS_Server;Job;21315.tyrone-cluster;Job Modified at request of Scheduler@tyrone-cluster
04/03/2013 01:42:22;0008;PBS_Server;Job;21315.tyrone-cluster;Job Run at request of Scheduler@tyrone-cluster
04/03/2013 01:42:22;0040;PBS_Server;Svr;tyrone-cluster;Scheduler was sent the command recyc
04/03/2013 01:42:22;000d;PBS_Server;Job;21315.tyrone-cluster;Not sending email: User does not want mail of this type.
04/03/2013 01:42:36;0001;PBS_Server;Svr;PBS_Server;LOG_ERROR::sync_node_jobs, stray job 21312.tyrone-cluster found on tyrone-node4
04/03/2013 01:42:45;0001;PBS_Server;Svr;PBS_Server;LOG_ERROR::sync_node_jobs, stray job 21190.tyrone-cluster found on tyrone-node6
04/03/2013 01:42:48;0001;PBS_Server;Svr;PBS_Server;LOG_ERROR::sync_node_jobs, stray job 21306.tyrone-cluster found on tyrone-node5
04/03/2013 01:43:21;0001;PBS_Server;Svr;PBS_Server;LOG_ERROR::sync_node_jobs, stray job 21312.tyrone-cluster found on tyrone-node4
04/03/2013 01:43:30;0002;PBS_Server;Svr;PBS_Server;Torque Server Version = 3.0.5, loglevel = 0
04/03/2013 01:43:30;0001;PBS_Server;Svr;PBS_Server;LOG_ERROR::sync_node_jobs, stray job 21190.tyrone-cluster found on tyrone-node6
04/03/2013 01:43:30;000d;PBS_Server;Job;21315.tyrone-cluster;Not sending email: User does not want mail of this type.
04/03/2013 01:43:30;0010;PBS_Server;Job;21315.tyrone-cluster;Exit_status=0 resources_used.cput=00:01:07 resources_used.mem=106336kb resources_used.vmem=802040kb resources_used.walltime=00:01:08
04/03/2013 01:43:30;0008;PBS_Server;Job;NULL;on_job_exit valid pjob: 0x2051580 (substate=50)
04/03/2013 01:43:30;0008;PBS_Server;Job;NULL;on_job_exit valid pjob: 0x2051580 (substate=51)
04/03/2013 01:43:31;0008;PBS_Server;Job;NULL;on_job_exit valid pjob: 0x2051580 (substate=51)
04/03/2013 01:43:31;0008;PBS_Server;Job;NULL;on_job_exit valid pjob: 0x2051580 (substate=53)
04/03/2013 01:43:31;0100;PBS_Server;Job;21315.tyrone-cluster;dequeuing from qp32, state COMPLETE
04/03/2013 01:43:31;0040;PBS_Server;Svr;tyrone-cluster;Scheduler was sent the command term
04/03/2013 01:43:33;0001;PBS_Server;Svr;PBS_Server;LOG_ERROR::sync_node_jobs, stray job 21306.tyrone-cluster found on tyrone-node5
04/03/2013 01:44:06;0001;PBS_Server;Svr;PBS_Server;LOG_ERROR::sync_node_jobs, stray job 21312.tyrone-cluster found on tyrone-node4
04/03/2013 01:44:15;0001;PBS_Server;Svr;PBS_Server;LOG_ERROR::sync_node_jobs, stray job 21190.tyrone-cluster found on tyrone-node6
04/03/2013 01:44:18;0001;PBS_Server;Svr;PBS_Server;LOG_ERROR::sync_node_jobs, stray job 21306.tyrone-cluster found on tyrone-node5
04/03/2013 01:44:51;0001;PBS_Server;Svr;PBS_Server;LOG_ERROR::sync_node_jobs, stray job 21312.tyrone-cluster found on tyrone-node4
04/03/2013 01:45:00;0001;PBS_Server;Svr;PBS_Server;LOG_ERROR::sync_node_jobs, stray job 21190.tyrone-cluster found on tyrone-node6
04/03/2013 01:45:03;0001;PBS_Server;Svr;PBS_Server;LOG_ERROR::sync_node_jobs, stray job 21306.tyrone-cluster found on tyrone-node5
04/03/2013 01:45:36;0001;PBS_Server;Svr;PBS_Server;LOG_ERROR::sync_node_jobs, stray job 21312.tyrone-cluster found on tyrone-node4
04/03/2013 01:45:45;0001;PBS_Server;Svr;PBS_Server;LOG_ERROR::sync_node_jobs, stray job 21190.tyrone-cluster found on tyrone-node6
04/03/2013 01:45:48;0001;PBS_Server;Svr;PBS_Server;LOG_ERROR::sync_node_jobs, stray job 21306.tyrone-cluster found on tyrone-node5
04/03/2013 01:46:21;0001;PBS_Server;Svr;PBS_Server;LOG_ERROR::sync_node_jobs, stray job 21312.tyrone-cluster found on tyrone-node4
04/03/2013 01:46:30;0001;PBS_Server;Svr;PBS_Server;LOG_ERROR::sync_node_jobs, stray job 21190.tyrone-cluster found on tyrone-node6
04/03/2013 01:46:33;0001;PBS_Server;Svr;PBS_Server;LOG_ERROR::sync_node_jobs, stray job 21306.tyrone-cluster found on tyrone-node5
04/03/2013 01:46:40;0100;PBS_Server;Job;21316.tyrone-cluster;enqueuing into batch, state 1 hop 1
04/03/2013 01:46:40;0100;PBS_Server;Job;21316.tyrone-cluster;dequeuing from batch, state QUEUED
04/03/2013 01:46:40;0100;PBS_Server;Job;21316.tyrone-cluster;enqueuing into qp32, state 1 hop 1
04/03/2013 01:46:40;0008;PBS_Server;Job;21316.tyrone-cluster;Job Queued at request of secgeet@tyrone-cluster, owner = secgeet@tyrone-cluster, job name = run, queue = qp32
04/03/2013 01:46:40;0040;PBS_Server;Svr;tyrone-cluster;Scheduler was sent the command new
04/03/2013 01:46:41;0008;PBS_Server;Job;21316.tyrone-cluster;Job Modified at request of Scheduler@tyrone-cluster
04/03/2013 01:46:41;0008;PBS_Server;Job;21316.tyrone-cluster;Job Run at request of Scheduler@tyrone-cluster
04/03/2013 01:46:41;0040;PBS_Server;Svr;tyrone-cluster;Scheduler was sent the command recyc
04/03/2013 01:46:41;000d;PBS_Server;Job;21316.tyrone-cluster;Not sending email: User does not want mail of this type.
04/03/2013 01:47:06;0001;PBS_Server;Svr;PBS_Server;LOG_ERROR::sync_node_jobs, stray job 21312.tyrone-cluster found on tyrone-node4
04/03/2013 01:47:15;0001;PBS_Server;Svr;PBS_Server;LOG_ERROR::sync_node_jobs, stray job 21190.tyrone-cluster found on tyrone-node6
04/03/2013 01:47:18;0001;PBS_Server;Svr;PBS_Server;LOG_ERROR::sync_node_jobs, stray job 21306.tyrone-cluster found on tyrone-node5
04/03/2013 01:47:25;0100;PBS_Server;Job;21317.tyrone-cluster;enqueuing into batch, state 1 hop 1
04/03/2013 01:47:25;0100;PBS_Server;Job;21317.tyrone-cluster;dequeuing from batch, state QUEUED
04/03/2013 01:47:25;0100;PBS_Server;Job;21317.tyrone-cluster;enqueuing into qp32, state 1 hop 1
04/03/2013 01:47:25;0008;PBS_Server;Job;21317.tyrone-cluster;Job Queued at request of secgeet@tyrone-cluster, owner = secgeet@tyrone-cluster, job name = run, queue = qp32
04/03/2013 01:47:25;0040;PBS_Server;Svr;tyrone-cluster;Scheduler was sent the command new
04/03/2013 01:47:25;0008;PBS_Server;Job;21317.tyrone-cluster;Job Modified at request of Scheduler@tyrone-cluster
04/03/2013 01:47:25;0008;PBS_Server;Job;21317.tyrone-cluster;Job Run at request of Scheduler@tyrone-cluster
04/03/2013 01:47:25;0040;PBS_Server;Svr;tyrone-cluster;Scheduler was sent the command recyc
04/03/2013 01:47:25;000d;PBS_Server;Job;21317.tyrone-cluster;Not sending email: User does not want mail of this type.
04/03/2013 01:47:41;000d;PBS_Server;Job;21317.tyrone-cluster;Not sending email: User does not want mail of this type.
04/03/2013 01:47:41;0010;PBS_Server;Job;21317.tyrone-cluster;Exit_status=0 resources_used.cput=00:05:19 resources_used.mem=228460kb resources_used.vmem=2232880kb resources_used.walltime=00:00:16
04/03/2013 01:47:41;0008;PBS_Server;Job;NULL;on_job_exit valid pjob: 0x1fd3700 (substate=50)
04/03/2013 01:47:41;0008;PBS_Server;Job;NULL;on_job_exit valid pjob: 0x1fd3700 (substate=51)
04/03/2013 01:47:41;0008;PBS_Server;Job;NULL;on_job_exit valid pjob: 0x1fd3700 (substate=51)
04/03/2013 01:47:41;0008;PBS_Server;Job;NULL;on_job_exit valid pjob: 0x1fd3700 (substate=53)
04/03/2013 01:47:41;0100;PBS_Server;Job;21317.tyrone-cluster;dequeuing from qp32, state COMPLETE
04/03/2013 01:47:41;0040;PBS_Server;Svr;tyrone-cluster;Scheduler was sent the command term
04/03/2013 01:47:49;000d;PBS_Server;Job;21316.tyrone-cluster;Not sending email: User does not want mail of this type.
04/03/2013 01:47:49;0010;PBS_Server;Job;21316.tyrone-cluster;Exit_status=0 resources_used.cput=00:01:04 resources_used.mem=88392kb resources_used.vmem=919424kb resources_used.walltime=00:01:08
04/03/2013 01:47:49;0008;PBS_Server;Job;NULL;on_job_exit valid pjob: 0x1fa2f10 (substate=50)
04/03/2013 01:47:49;0008;PBS_Server;Job;NULL;on_job_exit valid pjob: 0x1fa2f10 (substate=51)
04/03/2013 01:47:49;0008;PBS_Server;Job;NULL;on_job_exit valid pjob: 0x1fa2f10 (substate=51)
04/03/2013 01:47:49;0008;PBS_Server;Job;NULL;on_job_exit valid pjob: 0x1fa2f10 (substate=53)
04/03/2013 01:47:49;0100;PBS_Server;Job;21316.tyrone-cluster;dequeuing from qp32, state COMPLETE
04/03/2013 01:47:49;0040;PBS_Server;Svr;tyrone-cluster;Scheduler was sent the command term
04/03/2013 01:47:51;0001;PBS_Server;Svr;PBS_Server;LOG_ERROR::sync_node_jobs, stray job 21312.tyrone-cluster found on tyrone-node4
04/03/2013 01:48:00;0001;PBS_Server;Svr;PBS_Server;LOG_ERROR::sync_node_jobs, stray job 21190.tyrone-cluster found on tyrone-node6
04/03/2013 01:48:03;0001;PBS_Server;Svr;PBS_Server;LOG_ERROR::sync_node_jobs, stray job 21306.tyrone-cluster found on tyrone-node5
04/03/2013 01:48:30;0002;PBS_Server;Svr;PBS_Server;Torque Server Version = 3.0.5, loglevel = 0
04/03/2013 01:48:36;0001;PBS_Server;Svr;PBS_Server;LOG_ERROR::sync_node_jobs, stray job 21312.tyrone-cluster found on tyrone-node4
04/03/2013 01:48:45;0001;PBS_Server;Svr;PBS_Server;LOG_ERROR::sync_node_jobs, stray job 21190.tyrone-cluster found on tyrone-node6
04/03/2013 01:48:48;0001;PBS_Server;Svr;PBS_Server;LOG_ERROR::sync_node_jobs, stray job 21306.tyrone-cluster found on tyrone-node5
04/03/2013 01:49:21;0001;PBS_Server;Svr;PBS_Server;LOG_ERROR::sync_node_jobs, stray job 21312.tyrone-cluster found on tyrone-node4
04/03/2013 01:49:30;0001;PBS_Server;Svr;PBS_Server;LOG_ERROR::sync_node_jobs, stray job 21190.tyrone-cluster found on tyrone-node6
04/03/2013 01:49:33;0001;PBS_Server;Svr;PBS_Server;LOG_ERROR::sync_node_jobs, stray job 21306.tyrone-cluster found on tyrone-node5
04/03/2013 01:50:06;0001;PBS_Server;Svr;PBS_Server;LOG_ERROR::sync_node_jobs, stray job 21312.tyrone-cluster found on tyrone-node4
04/03/2013 01:50:14;0001;PBS_Server;Svr;PBS_Server;LOG_ERROR::sync_node_jobs, stray job 21190.tyrone-cluster found on tyrone-node6
04/03/2013 01:50:18;0001;PBS_Server;Svr;PBS_Server;LOG_ERROR::sync_node_jobs, stray job 21306.tyrone-cluster found on tyrone-node5
04/03/2013 01:50:51;0001;PBS_Server;Svr;PBS_Server;LOG_ERROR::sync_node_jobs, stray job 21312.tyrone-cluster found on tyrone-node4
04/03/2013 01:50:59;0001;PBS_Server;Svr;PBS_Server;LOG_ERROR::sync_node_jobs, stray job 21190.tyrone-cluster found on tyrone-node6
04/03/2013 01:51:03;0001;PBS_Server;Svr;PBS_Server;LOG_ERROR::sync_node_jobs, stray job 21306.tyrone-cluster found on tyrone-node5
04/03/2013 01:51:36;0001;PBS_Server;Svr;PBS_Server;LOG_ERROR::sync_node_jobs, stray job 21312.tyrone-cluster found on tyrone-node4
04/03/2013 01:51:44;0001;PBS_Server;Svr;PBS_Server;LOG_ERROR::sync_node_jobs, stray job 21190.tyrone-cluster found on tyrone-node6
04/03/2013 01:51:48;0001;PBS_Server;Svr;PBS_Server;LOG_ERROR::sync_node_jobs, stray job 21306.tyrone-cluster found on tyrone-node5
04/03/2013 01:52:20;0001;PBS_Server;Svr;PBS_Server;LOG_ERROR::sync_node_jobs, stray job 21312.tyrone-cluster found on tyrone-node4
04/03/2013 01:52:29;0001;PBS_Server;Svr;PBS_Server;LOG_ERROR::sync_node_jobs, stray job 21190.tyrone-cluster found on tyrone-node6
04/03/2013 01:52:33;0001;PBS_Server;Svr;PBS_Server;LOG_ERROR::sync_node_jobs, stray job 21306.tyrone-cluster found on tyrone-node5
04/03/2013 01:52:46;0100;PBS_Server;Job;21318.tyrone-cluster;enqueuing into batch, state 1 hop 1
04/03/2013 01:52:46;0100;PBS_Server;Job;21318.tyrone-cluster;dequeuing from batch, state QUEUED
04/03/2013 01:52:46;0100;PBS_Server;Job;21318.tyrone-cluster;enqueuing into qp32, state 1 hop 1
04/03/2013 01:52:46;0008;PBS_Server;Job;21318.tyrone-cluster;Job Queued at request of secgeet@tyrone-cluster, owner = secgeet@tyrone-cluster, job name = run, queue = qp32
04/03/2013 01:52:46;0040;PBS_Server;Svr;tyrone-cluster;Scheduler was sent the command new
04/03/2013 01:52:46;0008;PBS_Server;Job;21318.tyrone-cluster;Job Modified at request of Scheduler@tyrone-cluster
04/03/2013 01:52:46;0008;PBS_Server;Job;21318.tyrone-cluster;Job Run at request of Scheduler@tyrone-cluster
04/03/2013 01:52:46;0040;PBS_Server;Svr;tyrone-cluster;Scheduler was sent the command recyc
04/03/2013 01:52:46;000d;PBS_Server;Job;21318.tyrone-cluster;Not sending email: User does not want mail of this type.
04/03/2013 01:53:05;0001;PBS_Server;Svr;PBS_Server;LOG_ERROR::sync_node_jobs, stray job 21312.tyrone-cluster found on tyrone-node4
04/03/2013 01:53:08;000d;PBS_Server;Job;21318.tyrone-cluster;Not sending email: User does not want mail of this type.
04/03/2013 01:53:08;0010;PBS_Server;Job;21318.tyrone-cluster;Exit_status=0 resources_used.cput=00:05:37 resources_used.mem=0kb resources_used.vmem=0kb resources_used.walltime=00:00:22
04/03/2013 01:53:08;0008;PBS_Server;Job;NULL;on_job_exit valid pjob: 0x1fd3700 (substate=50)
04/03/2013 01:53:08;0008;PBS_Server;Job;NULL;on_job_exit valid pjob: 0x1fd3700 (substate=51)
04/03/2013 01:53:08;0008;PBS_Server;Job;NULL;on_job_exit valid pjob: 0x1fd3700 (substate=51)
04/03/2013 01:53:08;0008;PBS_Server;Job;NULL;on_job_exit valid pjob: 0x1fd3700 (substate=53)
04/03/2013 01:53:08;0100;PBS_Server;Job;21318.tyrone-cluster;dequeuing from qp32, state COMPLETE
04/03/2013 01:53:08;0040;PBS_Server;Svr;tyrone-cluster;Scheduler was sent the command term
04/03/2013 01:53:15;0001;PBS_Server;Svr;PBS_Server;LOG_ERROR::sync_node_jobs, stray job 21190.tyrone-cluster found on tyrone-node6
04/03/2013 01:53:18;0001;PBS_Server;Svr;PBS_Server;LOG_ERROR::sync_node_jobs, stray job 21306.tyrone-cluster found on tyrone-node5
04/03/2013 01:53:30;0002;PBS_Server;Svr;PBS_Server;Torque Server Version = 3.0.5, loglevel = 0
04/03/2013 01:53:51;0001;PBS_Server;Svr;PBS_Server;LOG_ERROR::sync_node_jobs, stray job 21312.tyrone-cluster found on tyrone-node4
04/03/2013 01:54:00;0001;PBS_Server;Svr;PBS_Server;LOG_ERROR::sync_node_jobs, stray job 21190.tyrone-cluster found on tyrone-node6
04/03/2013 01:54:03;0001;PBS_Server;Svr;PBS_Server;LOG_ERROR::sync_node_jobs, stray job 21306.tyrone-cluster found on tyrone-node5
04/03/2013 01:54:36;0001;PBS_Server;Svr;PBS_Server;LOG_ERROR::sync_node_jobs, stray job 21312.tyrone-cluster found on tyrone-node4
04/03/2013 01:54:44;0001;PBS_Server;Svr;PBS_Server;LOG_ERROR::sync_node_jobs, stray job 21190.tyrone-cluster found on tyrone-node6
04/03/2013 01:54:48;0001;PBS_Server;Svr;PBS_Server;LOG_ERROR::sync_node_jobs, stray job 21306.tyrone-cluster found on tyrone-node5
04/03/2013 01:55:21;0001;PBS_Server;Svr;PBS_Server;LOG_ERROR::sync_node_jobs, stray job 21312.tyrone-cluster found on tyrone-node4
04/03/2013 01:55:29;0001;PBS_Server;Svr;PBS_Server;LOG_ERROR::sync_node_jobs, stray job 21190.tyrone-cluster found on tyrone-node6
04/03/2013 01:55:33;0001;PBS_Server;Svr;PBS_Server;LOG_ERROR::sync_node_jobs, stray job 21306.tyrone-cluster found on tyrone-node5
04/03/2013 01:56:05;0001;PBS_Server;Svr;PBS_Server;LOG_ERROR::sync_node_jobs, stray job 21312.tyrone-cluster found on tyrone-node4
04/03/2013 01:56:14;0001;PBS_Server;Svr;PBS_Server;LOG_ERROR::sync_node_jobs, stray job 21190.tyrone-cluster found on tyrone-node6
04/03/2013 01:56:18;0001;PBS_Server;Svr;PBS_Server;LOG_ERROR::sync_node_jobs, stray job 21306.tyrone-cluster found on tyrone-node5
04/03/2013 01:56:31;0100;PBS_Server;Job;21319.tyrone-cluster;enqueuing into batch, state 1 hop 1
04/03/2013 01:56:31;0100;PBS_Server;Job;21319.tyrone-cluster;dequeuing from batch, state QUEUED
04/03/2013 01:56:31;0100;PBS_Server;Job;21319.tyrone-cluster;enqueuing into qp32, state 1 hop 1
04/03/2013 01:56:31;0008;PBS_Server;Job;21319.tyrone-cluster;Job Queued at request of secgeet@tyrone-cluster, owner = secgeet@tyrone-cluster, job name = run, queue = qp32
04/03/2013 01:56:31;0040;PBS_Server;Svr;tyrone-cluster;Scheduler was sent the command new
04/03/2013 01:56:31;0008;PBS_Server;Job;21319.tyrone-cluster;Job Modified at request of Scheduler@tyrone-cluster
04/03/2013 01:56:31;0008;PBS_Server;Job;21319.tyrone-cluster;Job Run at request of Scheduler@tyrone-cluster
04/03/2013 01:56:32;000d;PBS_Server;Job;21319.tyrone-cluster;Not sending email: User does not want mail of this type.
04/03/2013 01:56:32;0040;PBS_Server;Svr;tyrone-cluster;Scheduler was sent the command recyc
04/03/2013 01:56:50;0001;PBS_Server;Svr;PBS_Server;LOG_ERROR::sync_node_jobs, stray job 21312.tyrone-cluster found on tyrone-node4
04/03/2013 01:56:59;0001;PBS_Server;Svr;PBS_Server;LOG_ERROR::sync_node_jobs, stray job 21190.tyrone-cluster found on tyrone-node6
04/03/2013 01:57:03;0001;PBS_Server;Svr;PBS_Server;LOG_ERROR::sync_node_jobs, stray job 21306.tyrone-cluster found on tyrone-node5
04/03/2013 01:57:34;000d;PBS_Server;Job;21319.tyrone-cluster;Not sending email: User does not want mail of this type.
04/03/2013 01:57:34;0010;PBS_Server;Job;21319.tyrone-cluster;Exit_status=0 resources_used.cput=00:01:02 resources_used.mem=40428kb resources_used.vmem=919424kb resources_used.walltime=00:01:03
04/03/2013 01:57:34;0008;PBS_Server;Job;NULL;on_job_exit valid pjob: 0x1fd3700 (substate=50)
04/03/2013 01:57:34;0008;PBS_Server;Job;NULL;on_job_exit valid pjob: 0x1fd3700 (substate=51)
04/03/2013 01:57:35;0008;PBS_Server;Job;NULL;on_job_exit valid pjob: 0x1fd3700 (substate=51)
04/03/2013 01:57:35;0008;PBS_Server;Job;NULL;on_job_exit valid pjob: 0x1fd3700 (substate=53)
04/03/2013 01:57:35;0100;PBS_Server;Job;21319.tyrone-cluster;dequeuing from qp32, state COMPLETE
04/03/2013 01:57:35;0040;PBS_Server;Svr;tyrone-cluster;Scheduler was sent the command term
04/03/2013 01:57:36;0001;PBS_Server;Svr;PBS_Server;LOG_ERROR::sync_node_jobs, stray job 21312.tyrone-cluster found on tyrone-node4
04/03/2013 01:57:45;0001;PBS_Server;Svr;PBS_Server;LOG_ERROR::sync_node_jobs, stray job 21190.tyrone-cluster found on tyrone-node6
04/03/2013 01:57:48;0001;PBS_Server;Svr;PBS_Server;LOG_ERROR::sync_node_jobs, stray job 21306.tyrone-cluster found on tyrone-node5
04/03/2013 01:58:21;0001;PBS_Server;Svr;PBS_Server;LOG_ERROR::sync_node_jobs, stray job 21312.tyrone-cluster found on tyrone-node4
04/03/2013 01:58:30;0002;PBS_Server;Svr;PBS_Server;Torque Server Version = 3.0.5, loglevel = 0
04/03/2013 01:58:30;0001;PBS_Server;Svr;PBS_Server;LOG_ERROR::sync_node_jobs, stray job 21190.tyrone-cluster found on tyrone-node6
04/03/2013 01:58:33;0001;PBS_Server;Svr;PBS_Server;LOG_ERROR::sync_node_jobs, stray job 21306.tyrone-cluster found on tyrone-node5
04/03/2013 01:59:06;0001;PBS_Server;Svr;PBS_Server;LOG_ERROR::sync_node_jobs, stray job 21312.tyrone-cluster found on tyrone-node4
04/03/2013 01:59:15;0001;PBS_Server;Svr;PBS_Server;LOG_ERROR::sync_node_jobs, stray job 21190.tyrone-cluster found on tyrone-node6
04/03/2013 01:59:18;0001;PBS_Server;Svr;PBS_Server;LOG_ERROR::sync_node_jobs, stray job 21306.tyrone-cluster found on tyrone-node5
04/03/2013 01:59:51;0001;PBS_Server;Svr;PBS_Server;LOG_ERROR::sync_node_jobs, stray job 21312.tyrone-cluster found on tyrone-node4
04/03/2013 02:00:00;0001;PBS_Server;Svr;PBS_Server;LOG_ERROR::sync_node_jobs, stray job 21190.tyrone-cluster found on tyrone-node6
04/03/2013 02:00:03;0001;PBS_Server;Svr;PBS_Server;LOG_ERROR::sync_node_jobs, stray job 21306.tyrone-cluster found on tyrone-node5
04/03/2013 02:00:36;0001;PBS_Server;Svr;PBS_Server;LOG_ERROR::sync_node_jobs, stray job 21312.tyrone-cluster found on tyrone-node4
04/03/2013 02:00:45;0001;PBS_Server;Svr;PBS_Server;LOG_ERROR::sync_node_jobs, stray job 21190.tyrone-cluster found on tyrone-node6
04/03/2013 02:00:48;0001;PBS_Server;Svr;PBS_Server;LOG_ERROR::sync_node_jobs, stray job 21306.tyrone-cluster found on tyrone-node5
04/03/2013 02:01:20;0001;PBS_Server;Svr;PBS_Server;LOG_ERROR::sync_node_jobs, stray job 21312.tyrone-cluster found on tyrone-node4
04/03/2013 02:01:29;0001;PBS_Server;Svr;PBS_Server;LOG_ERROR::sync_node_jobs, stray job 21190.tyrone-cluster found on tyrone-node6
04/03/2013 02:01:33;0001;PBS_Server;Svr;PBS_Server;LOG_ERROR::sync_node_jobs, stray job 21306.tyrone-cluster found on tyrone-node5
04/03/2013 02:02:05;0001;PBS_Server;Svr;PBS_Server;LOG_ERROR::sync_node_jobs, stray job 21312.tyrone-cluster found on tyrone-node4
04/03/2013 02:02:14;0001;PBS_Server;Svr;PBS_Server;LOG_ERROR::sync_node_jobs, stray job 21190.tyrone-cluster found on tyrone-node6
04/03/2013 02:02:18;0001;PBS_Server;Svr;PBS_Server;LOG_ERROR::sync_node_jobs, stray job 21306.tyrone-cluster found on tyrone-node5
04/03/2013 02:02:50;0001;PBS_Server;Svr;PBS_Server;LOG_ERROR::sync_node_jobs, stray job 21312.tyrone-cluster found on tyrone-node4
04/03/2013 02:02:59;0001;PBS_Server;Svr;PBS_Server;LOG_ERROR::sync_node_jobs, stray job 21190.tyrone-cluster found on tyrone-node6
04/03/2013 02:03:03;0001;PBS_Server;Svr;PBS_Server;LOG_ERROR::sync_node_jobs, stray job 21306.tyrone-cluster found on tyrone-node5
04/03/2013 02:03:30;0002;PBS_Server;Svr;PBS_Server;Torque Server Version = 3.0.5, loglevel = 0
04/03/2013 02:03:35;0001;PBS_Server;Svr;PBS_Server;LOG_ERROR::sync_node_jobs, stray job 21312.tyrone-cluster found on tyrone-node4
04/03/2013 02:03:44;0001;PBS_Server;Svr;PBS_Server;LOG_ERROR::sync_node_jobs, stray job 21190.tyrone-cluster found on tyrone-node6
04/03/2013 02:03:48;0001;PBS_Server;Svr;PBS_Server;LOG_ERROR::sync_node_jobs, stray job 21306.tyrone-cluster found on tyrone-node5
04/03/2013 02:04:20;0001;PBS_Server;Svr;PBS_Server;LOG_ERROR::sync_node_jobs, stray job 21312.tyrone-cluster found on tyrone-node4
04/03/2013 02:04:29;0001;PBS_Server;Svr;PBS_Server;LOG_ERROR::sync_node_jobs, stray job 21190.tyrone-cluster found on tyrone-node6
04/03/2013 02:04:33;0001;PBS_Server;Svr;PBS_Server;LOG_ERROR::sync_node_jobs, stray job 21306.tyrone-cluster found on tyrone-node5
04/03/2013 02:05:05;0001;PBS_Server;Svr;PBS_Server;LOG_ERROR::sync_node_jobs, stray job 21312.tyrone-cluster found on tyrone-node4
04/03/2013 02:05:14;0001;PBS_Server;Svr;PBS_Server;LOG_ERROR::sync_node_jobs, stray job 21190.tyrone-cluster found on tyrone-node6
04/03/2013 02:05:17;0001;PBS_Server;Svr;PBS_Server;LOG_ERROR::sync_node_jobs, stray job 21306.tyrone-cluster found on tyrone-node5
04/03/2013 02:05:50;0001;PBS_Server;Svr;PBS_Server;LOG_ERROR::sync_node_jobs, stray job 21312.tyrone-cluster found on tyrone-node4
04/03/2013 02:06:00;0001;PBS_Server;Svr;PBS_Server;LOG_ERROR::sync_node_jobs, stray job 21190.tyrone-cluster found on tyrone-node6
04/03/2013 02:06:02;0001;PBS_Server;Svr;PBS_Server;LOG_ERROR::sync_node_jobs, stray job 21306.tyrone-cluster found on tyrone-node5
04/03/2013 02:06:36;0001;PBS_Server;Svr;PBS_Server;LOG_ERROR::sync_node_jobs, stray job 21312.tyrone-cluster found on tyrone-node4
04/03/2013 02:06:45;0001;PBS_Server;Svr;PBS_Server;LOG_ERROR::sync_node_jobs, stray job 21190.tyrone-cluster found on tyrone-node6
04/03/2013 02:06:48;0001;PBS_Server;Svr;PBS_Server;LOG_ERROR::sync_node_jobs, stray job 21306.tyrone-cluster found on tyrone-node5
04/03/2013 02:07:21;0001;PBS_Server;Svr;PBS_Server;LOG_ERROR::sync_node_jobs, stray job 21312.tyrone-cluster found on tyrone-node4
04/03/2013 02:07:30;0001;PBS_Server;Svr;PBS_Server;LOG_ERROR::sync_node_jobs, stray job 21190.tyrone-cluster found on tyrone-node6
04/03/2013 02:07:33;0001;PBS_Server;Svr;PBS_Server;LOG_ERROR::sync_node_jobs, stray job 21306.tyrone-cluster found on tyrone-node5
04/03/2013 02:07:35;0040;PBS_Server;Svr;tyrone-cluster;Scheduler was sent the command time
04/03/2013 02:08:06;0001;PBS_Server;Svr;PBS_Server;LOG_ERROR::sync_node_jobs, stray job 21312.tyrone-cluster found on tyrone-node4
04/03/2013 02:08:15;0001;PBS_Server;Svr;PBS_Server;LOG_ERROR::sync_node_jobs, stray job 21190.tyrone-cluster found on tyrone-node6
04/03/2013 02:08:18;0001;PBS_Server;Svr;PBS_Server;LOG_ERROR::sync_node_jobs, stray job 21306.tyrone-cluster found on tyrone-node5
04/03/2013 02:08:30;0002;PBS_Server;Svr;PBS_Server;Torque Server Version = 3.0.5, loglevel = 0
04/03/2013 02:08:51;0001;PBS_Server;Svr;PBS_Server;LOG_ERROR::sync_node_jobs, stray job 21312.tyrone-cluster found on tyrone-node4
04/03/2013 02:09:00;0001;PBS_Server;Svr;PBS_Server;LOG_ERROR::sync_node_jobs, stray job 21190.tyrone-cluster found on tyrone-node6
04/03/2013 02:09:03;0001;PBS_Server;Svr;PBS_Server;LOG_ERROR::sync_node_jobs, stray job 21306.tyrone-cluster found on tyrone-node5
04/03/2013 02:09:36;0001;PBS_Server;Svr;PBS_Server;LOG_ERROR::sync_node_jobs, stray job 21312.tyrone-cluster found on tyrone-node4
04/03/2013 02:09:45;0001;PBS_Server;Svr;PBS_Server;LOG_ERROR::sync_node_jobs, stray job 21190.tyrone-cluster found on tyrone-node6
04/03/2013 02:09:48;0001;PBS_Server;Svr;PBS_Server;LOG_ERROR::sync_node_jobs, stray job 21306.tyrone-cluster found on tyrone-node5
04/03/2013 02:10:21;0001;PBS_Server;Svr;PBS_Server;LOG_ERROR::sync_node_jobs, stray job 21312.tyrone-cluster found on tyrone-node4
04/03/2013 02:10:30;0001;PBS_Server;Svr;PBS_Server;LOG_ERROR::sync_node_jobs, stray job 21190.tyrone-cluster found on tyrone-node6
04/03/2013 02:10:33;0001;PBS_Server;Svr;PBS_Server;LOG_ERROR::sync_node_jobs, stray job 21306.tyrone-cluster found on tyrone-node5
04/03/2013 02:11:05;0001;PBS_Server;Svr;PBS_Server;LOG_ERROR::sync_node_jobs, stray job 21312.tyrone-cluster found on tyrone-node4
04/03/2013 02:11:15;0001;PBS_Server;Svr;PBS_Server;LOG_ERROR::sync_node_jobs, stray job 21190.tyrone-cluster found on tyrone-node6
04/03/2013 02:11:18;0001;PBS_Server;Svr;PBS_Server;LOG_ERROR::sync_node_jobs, stray job 21306.tyrone-cluster found on tyrone-node5
04/03/2013 02:11:50;0001;PBS_Server;Svr;PBS_Server;LOG_ERROR::sync_node_jobs, stray job 21312.tyrone-cluster found on tyrone-node4
04/03/2013 02:12:00;0001;PBS_Server;Svr;PBS_Server;LOG_ERROR::sync_node_jobs, stray job 21190.tyrone-cluster found on tyrone-node6
04/03/2013 02:12:03;0001;PBS_Server;Svr;PBS_Server;LOG_ERROR::sync_node_jobs, stray job 21306.tyrone-cluster found on tyrone-node5
04/03/2013 02:12:35;0001;PBS_Server;Svr;PBS_Server;LOG_ERROR::sync_node_jobs, stray job 21312.tyrone-cluster found on tyrone-node4
04/03/2013 02:12:44;0001;PBS_Server;Svr;PBS_Server;LOG_ERROR::sync_node_jobs, stray job 21190.tyrone-cluster found on tyrone-node6
04/03/2013 02:12:48;0001;PBS_Server;Svr;PBS_Server;LOG_ERROR::sync_node_jobs, stray job 21306.tyrone-cluster found on tyrone-node5
04/03/2013 02:13:20;0001;PBS_Server;Svr;PBS_Server;LOG_ERROR::sync_node_jobs, stray job 21312.tyrone-cluster found on tyrone-node4
04/03/2013 02:13:29;0001;PBS_Server;Svr;PBS_Server;LOG_ERROR::sync_node_jobs, stray job 21190.tyrone-cluster found on tyrone-node6
04/03/2013 02:13:30;0002;PBS_Server;Svr;PBS_Server;Torque Server Version = 3.0.5, loglevel = 0
04/03/2013 02:13:33;0001;PBS_Server;Svr;PBS_Server;LOG_ERROR::sync_node_jobs, stray job 21306.tyrone-cluster found on tyrone-node5
04/03/2013 02:14:05;0001;PBS_Server;Svr;PBS_Server;LOG_ERROR::sync_node_jobs, stray job 21312.tyrone-cluster found on tyrone-node4
04/03/2013 02:14:14;0001;PBS_Server;Svr;PBS_Server;LOG_ERROR::sync_node_jobs, stray job 21190.tyrone-cluster found on tyrone-node6
04/03/2013 02:14:18;0001;PBS_Server;Svr;PBS_Server;LOG_ERROR::sync_node_jobs, stray job 21306.tyrone-cluster found on tyrone-node5
04/03/2013 02:14:50;0001;PBS_Server;Svr;PBS_Server;LOG_ERROR::sync_node_jobs, stray job 21312.tyrone-cluster found on tyrone-node4
04/03/2013 02:14:59;0001;PBS_Server;Svr;PBS_Server;LOG_ERROR::sync_node_jobs, stray job 21190.tyrone-cluster found on tyrone-node6
04/03/2013 02:15:03;0001;PBS_Server;Svr;PBS_Server;LOG_ERROR::sync_node_jobs, stray job 21306.tyrone-cluster found on tyrone-node5
04/03/2013 02:15:35;0001;PBS_Server;Svr;PBS_Server;LOG_ERROR::sync_node_jobs, stray job 21312.tyrone-cluster found on tyrone-node4
04/03/2013 02:15:44;0001;PBS_Server;Svr;PBS_Server;LOG_ERROR::sync_node_jobs, stray job 21190.tyrone-cluster found on tyrone-node6
04/03/2013 02:15:48;0001;PBS_Server;Svr;PBS_Server;LOG_ERROR::sync_node_jobs, stray job 21306.tyrone-cluster found on tyrone-node5
04/03/2013 02:16:20;0001;PBS_Server;Svr;PBS_Server;LOG_ERROR::sync_node_jobs, stray job 21312.tyrone-cluster found on tyrone-node4
04/03/2013 02:16:29;0001;PBS_Server;Svr;PBS_Server;LOG_ERROR::sync_node_jobs, stray job 21190.tyrone-cluster found on tyrone-node6
04/03/2013 02:16:33;0001;PBS_Server;Svr;PBS_Server;LOG_ERROR::sync_node_jobs, stray job 21306.tyrone-cluster found on tyrone-node5
04/03/2013 02:17:05;0001;PBS_Server;Svr;PBS_Server;LOG_ERROR::sync_node_jobs, stray job 21312.tyrone-cluster found on tyrone-node4
04/03/2013 02:17:14;0001;PBS_Server;Svr;PBS_Server;LOG_ERROR::sync_node_jobs, stray job 21190.tyrone-cluster found on tyrone-node6
04/03/2013 02:17:18;0001;PBS_Server;Svr;PBS_Server;LOG_ERROR::sync_node_jobs, stray job 21306.tyrone-cluster found on tyrone-node5
04/03/2013 02:17:35;0040;PBS_Server;Svr;tyrone-cluster;Scheduler was sent the command time
04/03/2013 02:17:50;0001;PBS_Server;Svr;PBS_Server;LOG_ERROR::sync_node_jobs, stray job 21312.tyrone-cluster found on tyrone-node4
04/03/2013 02:18:00;0001;PBS_Server;Svr;PBS_Server;LOG_ERROR::sync_node_jobs, stray job 21190.tyrone-cluster found on tyrone-node6
04/03/2013 02:18:03;0001;PBS_Server;Svr;PBS_Server;LOG_ERROR::sync_node_jobs, stray job 21306.tyrone-cluster found on tyrone-node5
04/03/2013 02:18:30;0002;PBS_Server;Svr;PBS_Server;Torque Server Version = 3.0.5, loglevel = 0
04/03/2013 02:18:36;0001;PBS_Server;Svr;PBS_Server;LOG_ERROR::sync_node_jobs, stray job 21312.tyrone-cluster found on tyrone-node4
04/03/2013 02:18:45;0001;PBS_Server;Svr;PBS_Server;LOG_ERROR::sync_node_jobs, stray job 21190.tyrone-cluster found on tyrone-node6
04/03/2013 02:18:48;0001;PBS_Server;Svr;PBS_Server;LOG_ERROR::sync_node_jobs, stray job 21306.tyrone-cluster found on tyrone-node5
04/03/2013 02:19:21;0001;PBS_Server;Svr;PBS_Server;LOG_ERROR::sync_node_jobs, stray job 21312.tyrone-cluster found on tyrone-node4
04/03/2013 02:19:30;0001;PBS_Server;Svr;PBS_Server;LOG_ERROR::sync_node_jobs, stray job 21190.tyrone-cluster found on tyrone-node6
04/03/2013 02:19:33;0001;PBS_Server;Svr;PBS_Server;LOG_ERROR::sync_node_jobs, stray job 21306.tyrone-cluster found on tyrone-node5
04/03/2013 02:20:06;0001;PBS_Server;Svr;PBS_Server;LOG_ERROR::sync_node_jobs, stray job 21312.tyrone-cluster found on tyrone-node4
04/03/2013 02:20:15;0001;PBS_Server;Svr;PBS_Server;LOG_ERROR::sync_node_jobs, stray job 21190.tyrone-cluster found on tyrone-node6
04/03/2013 02:20:18;0001;PBS_Server;Svr;PBS_Server;LOG_ERROR::sync_node_jobs, stray job 21306.tyrone-cluster found on tyrone-node5
04/03/2013 02:20:51;0001;PBS_Server;Svr;PBS_Server;LOG_ERROR::sync_node_jobs, stray job 21312.tyrone-cluster found on tyrone-node4
04/03/2013 02:21:00;0001;PBS_Server;Svr;PBS_Server;LOG_ERROR::sync_node_jobs, stray job 21190.tyrone-cluster found on tyrone-node6
04/03/2013 02:21:03;0001;PBS_Server;Svr;PBS_Server;LOG_ERROR::sync_node_jobs, stray job 21306.tyrone-cluster found on tyrone-node5
04/03/2013 02:21:35;0001;PBS_Server;Svr;PBS_Server;LOG_ERROR::sync_node_jobs, stray job 21312.tyrone-cluster found on tyrone-node4
04/03/2013 02:21:45;0001;PBS_Server;Svr;PBS_Server;LOG_ERROR::sync_node_jobs, stray job 21190.tyrone-cluster found on tyrone-node6
04/03/2013 02:21:48;0001;PBS_Server;Svr;PBS_Server;LOG_ERROR::sync_node_jobs, stray job 21306.tyrone-cluster found on tyrone-node5
04/03/2013 02:22:20;0001;PBS_Server;Svr;PBS_Server;LOG_ERROR::sync_node_jobs, stray job 21312.tyrone-cluster found on tyrone-node4
04/03/2013 02:22:30;0001;PBS_Server;Svr;PBS_Server;LOG_ERROR::sync_node_jobs, stray job 21190.tyrone-cluster found on tyrone-node6
04/03/2013 02:22:33;0001;PBS_Server;Svr;PBS_Server;LOG_ERROR::sync_node_jobs, stray job 21306.tyrone-cluster found on tyrone-node5
04/03/2013 02:23:05;0001;PBS_Server;Svr;PBS_Server;LOG_ERROR::sync_node_jobs, stray job 21312.tyrone-cluster found on tyrone-node4
04/03/2013 02:23:15;0001;PBS_Server;Svr;PBS_Server;LOG_ERROR::sync_node_jobs, stray job 21190.tyrone-cluster found on tyrone-node6
04/03/2013 02:23:18;0001;PBS_Server;Svr;PBS_Server;LOG_ERROR::sync_node_jobs, stray job 21306.tyrone-cluster found on tyrone-node5
04/03/2013 02:23:30;0002;PBS_Server;Svr;PBS_Server;Torque Server Version = 3.0.5, loglevel = 0
04/03/2013 02:23:50;0001;PBS_Server;Svr;PBS_Server;LOG_ERROR::sync_node_jobs, stray job 21312.tyrone-cluster found on tyrone-node4
04/03/2013 02:24:00;0001;PBS_Server;Svr;PBS_Server;LOG_ERROR::sync_node_jobs, stray job 21190.tyrone-cluster found on tyrone-node6
04/03/2013 02:24:03;0001;PBS_Server;Svr;PBS_Server;LOG_ERROR::sync_node_jobs, stray job 21306.tyrone-cluster found on tyrone-node5
04/03/2013 02:24:35;0001;PBS_Server;Svr;PBS_Server;LOG_ERROR::sync_node_jobs, stray job 21312.tyrone-cluster found on tyrone-node4
04/03/2013 02:24:44;0001;PBS_Server;Svr;PBS_Server;LOG_ERROR::sync_node_jobs, stray job 21190.tyrone-cluster found on tyrone-node6
04/03/2013 02:24:48;0001;PBS_Server;Svr;PBS_Server;LOG_ERROR::sync_node_jobs, stray job 21306.tyrone-cluster found on tyrone-node5
04/03/2013 02:25:20;0001;PBS_Server;Svr;PBS_Server;LOG_ERROR::sync_node_jobs, stray job 21312.tyrone-cluster found on tyrone-node4
04/03/2013 02:25:29;0001;PBS_Server;Svr;PBS_Server;LOG_ERROR::sync_node_jobs, stray job 21190.tyrone-cluster found on tyrone-node6
04/03/2013 02:25:33;0001;PBS_Server;Svr;PBS_Server;LOG_ERROR::sync_node_jobs, stray job 21306.tyrone-cluster found on tyrone-node5
04/03/2013 02:26:05;0001;PBS_Server;Svr;PBS_Server;LOG_ERROR::sync_node_jobs, stray job 21312.tyrone-cluster found on tyrone-node4
04/03/2013 02:26:14;0001;PBS_Server;Svr;PBS_Server;LOG_ERROR::sync_node_jobs, stray job 21190.tyrone-cluster found on tyrone-node6
04/03/2013 02:26:18;0001;PBS_Server;Svr;PBS_Server;LOG_ERROR::sync_node_jobs, stray job 21306.tyrone-cluster found on tyrone-node5
04/03/2013 02:26:50;0001;PBS_Server;Svr;PBS_Server;LOG_ERROR::sync_node_jobs, stray job 21312.tyrone-cluster found on tyrone-node4
04/03/2013 02:26:59;0001;PBS_Server;Svr;PBS_Server;LOG_ERROR::sync_node_jobs, stray job 21190.tyrone-cluster found on tyrone-node6
04/03/2013 02:27:03;0001;PBS_Server;Svr;PBS_Server;LOG_ERROR::sync_node_jobs, stray job 21306.tyrone-cluster found on tyrone-node5
04/03/2013 02:27:35;0001;PBS_Server;Svr;PBS_Server;LOG_ERROR::sync_node_jobs, stray job 21312.tyrone-cluster found on tyrone-node4
04/03/2013 02:27:35;0040;PBS_Server;Svr;tyrone-cluster;Scheduler was sent the command time
04/03/2013 02:27:44;0001;PBS_Server;Svr;PBS_Server;LOG_ERROR::sync_node_jobs, stray job 21190.tyrone-cluster found on tyrone-node6
04/03/2013 02:27:48;0001;PBS_Server;Svr;PBS_Server;LOG_ERROR::sync_node_jobs, stray job 21306.tyrone-cluster found on tyrone-node5
04/03/2013 02:28:20;0001;PBS_Server;Svr;PBS_Server;LOG_ERROR::sync_node_jobs, stray job 21312.tyrone-cluster found on tyrone-node4
04/03/2013 02:28:29;0001;PBS_Server;Svr;PBS_Server;LOG_ERROR::sync_node_jobs, stray job 21190.tyrone-cluster found on tyrone-node6
04/03/2013 02:28:30;0002;PBS_Server;Svr;PBS_Server;Torque Server Version = 3.0.5, loglevel = 0
04/03/2013 02:28:33;0001;PBS_Server;Svr;PBS_Server;LOG_ERROR::sync_node_jobs, stray job 21306.tyrone-cluster found on tyrone-node5
04/03/2013 02:29:05;0001;PBS_Server;Svr;PBS_Server;LOG_ERROR::sync_node_jobs, stray job 21312.tyrone-cluster found on tyrone-node4
04/03/2013 02:29:14;0001;PBS_Server;Svr;PBS_Server;LOG_ERROR::sync_node_jobs, stray job 21190.tyrone-cluster found on tyrone-node6
04/03/2013 02:29:18;0001;PBS_Server;Svr;PBS_Server;LOG_ERROR::sync_node_jobs, stray job 21306.tyrone-cluster found on tyrone-node5
04/03/2013 02:29:50;0001;PBS_Server;Svr;PBS_Server;LOG_ERROR::sync_node_jobs, stray job 21312.tyrone-cluster found on tyrone-node4
04/03/2013 02:29:59;0001;PBS_Server;Svr;PBS_Server;LOG_ERROR::sync_node_jobs, stray job 21190.tyrone-cluster found on tyrone-node6
04/03/2013 02:30:02;0001;PBS_Server;Svr;PBS_Server;LOG_ERROR::sync_node_jobs, stray job 21306.tyrone-cluster found on tyrone-node5
04/03/2013 02:30:35;0001;PBS_Server;Svr;PBS_Server;LOG_ERROR::sync_node_jobs, stray job 21312.tyrone-cluster found on tyrone-node4
04/03/2013 02:30:45;0001;PBS_Server;Svr;PBS_Server;LOG_ERROR::sync_node_jobs, stray job 21190.tyrone-cluster found on tyrone-node6
04/03/2013 02:30:47;0001;PBS_Server;Svr;PBS_Server;LOG_ERROR::sync_node_jobs, stray job 21306.tyrone-cluster found on tyrone-node5
04/03/2013 02:31:20;0001;PBS_Server;Svr;PBS_Server;LOG_ERROR::sync_node_jobs, stray job 21312.tyrone-cluster found on tyrone-node4
04/03/2013 02:31:30;0001;PBS_Server;Svr;PBS_Server;LOG_ERROR::sync_node_jobs, stray job 21190.tyrone-cluster found on tyrone-node6
04/03/2013 02:31:33;0001;PBS_Server;Svr;PBS_Server;LOG_ERROR::sync_node_jobs, stray job 21306.tyrone-cluster found on tyrone-node5
04/03/2013 02:32:05;0001;PBS_Server;Svr;PBS_Server;LOG_ERROR::sync_node_jobs, stray job 21312.tyrone-cluster found on tyrone-node4
04/03/2013 02:32:15;0001;PBS_Server;Svr;PBS_Server;LOG_ERROR::sync_node_jobs, stray job 21190.tyrone-cluster found on tyrone-node6
04/03/2013 02:32:18;0001;PBS_Server;Svr;PBS_Server;LOG_ERROR::sync_node_jobs, stray job 21306.tyrone-cluster found on tyrone-node5
04/03/2013 02:32:50;0001;PBS_Server;Svr;PBS_Server;LOG_ERROR::sync_node_jobs, stray job 21312.tyrone-cluster found on tyrone-node4
04/03/2013 02:33:00;0001;PBS_Server;Svr;PBS_Server;LOG_ERROR::sync_node_jobs, stray job 21190.tyrone-cluster found on tyrone-node6
04/03/2013 02:33:03;0001;PBS_Server;Svr;PBS_Server;LOG_ERROR::sync_node_jobs, stray job 21306.tyrone-cluster found on tyrone-node5
04/03/2013 02:33:22;0100;PBS_Server;Job;21320.tyrone-cluster;enqueuing into batch, state 1 hop 1
04/03/2013 02:33:22;0100;PBS_Server;Job;21320.tyrone-cluster;dequeuing from batch, state QUEUED
04/03/2013 02:33:22;0100;PBS_Server;Job;21320.tyrone-cluster;enqueuing into qp32, state 1 hop 1
04/03/2013 02:33:22;0008;PBS_Server;Job;21320.tyrone-cluster;Job Queued at request of secbadar@tyrone-cluster, owner = secbadar@tyrone-cluster, job name = myjob, queue = qp32
04/03/2013 02:33:22;0040;PBS_Server;Svr;tyrone-cluster;Scheduler was sent the command new
04/03/2013 02:33:22;0008;PBS_Server;Job;21320.tyrone-cluster;Job Modified at request of Scheduler@tyrone-cluster
04/03/2013 02:33:22;0008;PBS_Server;Job;21320.tyrone-cluster;Job Run at request of Scheduler@tyrone-cluster
04/03/2013 02:33:22;0040;PBS_Server;Svr;tyrone-cluster;Scheduler was sent the command recyc
04/03/2013 02:33:22;000d;PBS_Server;Job;21320.tyrone-cluster;Not sending email: User does not want mail of this type.
04/03/2013 02:33:30;0002;PBS_Server;Svr;PBS_Server;Torque Server Version = 3.0.5, loglevel = 0
04/03/2013 02:33:35;0001;PBS_Server;Svr;PBS_Server;LOG_ERROR::sync_node_jobs, stray job 21312.tyrone-cluster found on tyrone-node4
04/03/2013 02:33:44;0001;PBS_Server;Svr;PBS_Server;LOG_ERROR::sync_node_jobs, stray job 21190.tyrone-cluster found on tyrone-node6
04/03/2013 02:33:48;0001;PBS_Server;Svr;PBS_Server;LOG_ERROR::sync_node_jobs, stray job 21306.tyrone-cluster found on tyrone-node5
04/03/2013 02:34:20;0001;PBS_Server;Svr;PBS_Server;LOG_ERROR::sync_node_jobs, stray job 21312.tyrone-cluster found on tyrone-node4
04/03/2013 02:34:28;0100;PBS_Server;Job;21321.tyrone-cluster;enqueuing into batch, state 1 hop 1
04/03/2013 02:34:28;0100;PBS_Server;Job;21321.tyrone-cluster;dequeuing from batch, state QUEUED
04/03/2013 02:34:28;0100;PBS_Server;Job;21321.tyrone-cluster;enqueuing into qp32, state 1 hop 1
04/03/2013 02:34:28;0008;PBS_Server;Job;21321.tyrone-cluster;Job Queued at request of secbadar@tyrone-cluster, owner = secbadar@tyrone-cluster, job name = myjob, queue = qp32
04/03/2013 02:34:28;0040;PBS_Server;Svr;tyrone-cluster;Scheduler was sent the command new
04/03/2013 02:34:29;0008;PBS_Server;Job;21321.tyrone-cluster;Job Modified at request of Scheduler@tyrone-cluster
04/03/2013 02:34:29;0008;PBS_Server;Job;21321.tyrone-cluster;Job Run at request of Scheduler@tyrone-cluster
04/03/2013 02:34:29;0040;PBS_Server;Svr;tyrone-cluster;Scheduler was sent the command recyc
04/03/2013 02:34:29;000d;PBS_Server;Job;21321.tyrone-cluster;Not sending email: User does not want mail of this type.
04/03/2013 02:34:30;0001;PBS_Server;Svr;PBS_Server;LOG_ERROR::sync_node_jobs, stray job 21190.tyrone-cluster found on tyrone-node6
04/03/2013 02:34:33;0001;PBS_Server;Svr;PBS_Server;LOG_ERROR::sync_node_jobs, stray job 21306.tyrone-cluster found on tyrone-node5
04/03/2013 02:34:54;000d;PBS_Server;Job;21321.tyrone-cluster;Not sending email: User does not want mail of this type.
04/03/2013 02:34:54;0010;PBS_Server;Job;21321.tyrone-cluster;Exit_status=0 resources_used.cput=00:08:40 resources_used.mem=65348kb resources_used.vmem=1493344kb resources_used.walltime=00:00:25
04/03/2013 02:34:54;0008;PBS_Server;Job;NULL;on_job_exit valid pjob: 0x1fd3700 (substate=50)
04/03/2013 02:34:54;0008;PBS_Server;Job;NULL;on_job_exit valid pjob: 0x1fd3700 (substate=51)
04/03/2013 02:34:54;0008;PBS_Server;Job;NULL;on_job_exit valid pjob: 0x1fd3700 (substate=51)
04/03/2013 02:34:54;0008;PBS_Server;Job;NULL;on_job_exit valid pjob: 0x1fd3700 (substate=53)
04/03/2013 02:34:54;0100;PBS_Server;Job;21321.tyrone-cluster;dequeuing from qp32, state COMPLETE
04/03/2013 02:34:54;0040;PBS_Server;Svr;tyrone-cluster;Scheduler was sent the command term
04/03/2013 02:35:04;0001;PBS_Server;Svr;PBS_Server;LOG_ERROR::sync_node_jobs, stray job 21312.tyrone-cluster found on tyrone-node4
04/03/2013 02:35:05;000d;PBS_Server;Job;21320.tyrone-cluster;Not sending email: User does not want mail of this type.
04/03/2013 02:35:05;0010;PBS_Server;Job;21320.tyrone-cluster;Exit_status=0 resources_used.cput=00:01:40 resources_used.mem=9922372kb resources_used.vmem=19865116kb resources_used.walltime=00:01:43
04/03/2013 02:35:05;0008;PBS_Server;Job;NULL;on_job_exit valid pjob: 0x1fa2f10 (substate=50)
04/03/2013 02:35:05;0008;PBS_Server;Job;NULL;on_job_exit valid pjob: 0x1fa2f10 (substate=51)
04/03/2013 02:35:05;0008;PBS_Server;Job;NULL;on_job_exit valid pjob: 0x1fa2f10 (substate=51)
04/03/2013 02:35:05;0008;PBS_Server;Job;NULL;on_job_exit valid pjob: 0x1fa2f10 (substate=53)
04/03/2013 02:35:05;0100;PBS_Server;Job;21320.tyrone-cluster;dequeuing from qp32, state COMPLETE
04/03/2013 02:35:05;0040;PBS_Server;Svr;tyrone-cluster;Scheduler was sent the command term
04/03/2013 02:35:14;0001;PBS_Server;Svr;PBS_Server;LOG_ERROR::sync_node_jobs, stray job 21190.tyrone-cluster found on tyrone-node6
04/03/2013 02:35:17;0001;PBS_Server;Svr;PBS_Server;LOG_ERROR::sync_node_jobs, stray job 21306.tyrone-cluster found on tyrone-node5
04/03/2013 02:35:49;0001;PBS_Server;Svr;PBS_Server;LOG_ERROR::sync_node_jobs, stray job 21312.tyrone-cluster found on tyrone-node4
04/03/2013 02:35:59;0001;PBS_Server;Svr;PBS_Server;LOG_ERROR::sync_node_jobs, stray job 21190.tyrone-cluster found on tyrone-node6
04/03/2013 02:36:02;0001;PBS_Server;Svr;PBS_Server;LOG_ERROR::sync_node_jobs, stray job 21306.tyrone-cluster found on tyrone-node5
04/03/2013 02:36:35;0001;PBS_Server;Svr;PBS_Server;LOG_ERROR::sync_node_jobs, stray job 21312.tyrone-cluster found on tyrone-node4
04/03/2013 02:36:45;0001;PBS_Server;Svr;PBS_Server;LOG_ERROR::sync_node_jobs, stray job 21190.tyrone-cluster found on tyrone-node6
04/03/2013 02:36:48;0001;PBS_Server;Svr;PBS_Server;LOG_ERROR::sync_node_jobs, stray job 21306.tyrone-cluster found on tyrone-node5
04/03/2013 02:37:20;0001;PBS_Server;Svr;PBS_Server;LOG_ERROR::sync_node_jobs, stray job 21312.tyrone-cluster found on tyrone-node4
04/03/2013 02:37:30;0001;PBS_Server;Svr;PBS_Server;LOG_ERROR::sync_node_jobs, stray job 21190.tyrone-cluster found on tyrone-node6
04/03/2013 02:37:33;0001;PBS_Server;Svr;PBS_Server;LOG_ERROR::sync_node_jobs, stray job 21306.tyrone-cluster found on tyrone-node5
04/03/2013 02:38:05;0001;PBS_Server;Svr;PBS_Server;LOG_ERROR::sync_node_jobs, stray job 21312.tyrone-cluster found on tyrone-node4
04/03/2013 02:38:15;0001;PBS_Server;Svr;PBS_Server;LOG_ERROR::sync_node_jobs, stray job 21190.tyrone-cluster found on tyrone-node6
04/03/2013 02:38:18;0001;PBS_Server;Svr;PBS_Server;LOG_ERROR::sync_node_jobs, stray job 21306.tyrone-cluster found on tyrone-node5
04/03/2013 02:38:30;0002;PBS_Server;Svr;PBS_Server;Torque Server Version = 3.0.5, loglevel = 0
04/03/2013 02:38:50;0001;PBS_Server;Svr;PBS_Server;LOG_ERROR::sync_node_jobs, stray job 21312.tyrone-cluster found on tyrone-node4
04/03/2013 02:39:00;0001;PBS_Server;Svr;PBS_Server;LOG_ERROR::sync_node_jobs, stray job 21190.tyrone-cluster found on tyrone-node6
04/03/2013 02:39:03;0001;PBS_Server;Svr;PBS_Server;LOG_ERROR::sync_node_jobs, stray job 21306.tyrone-cluster found on tyrone-node5
04/03/2013 02:39:35;0001;PBS_Server;Svr;PBS_Server;LOG_ERROR::sync_node_jobs, stray job 21312.tyrone-cluster found on tyrone-node4
04/03/2013 02:39:45;0001;PBS_Server;Svr;PBS_Server;LOG_ERROR::sync_node_jobs, stray job 21190.tyrone-cluster found on tyrone-node6
04/03/2013 02:39:48;0001;PBS_Server;Svr;PBS_Server;LOG_ERROR::sync_node_jobs, stray job 21306.tyrone-cluster found on tyrone-node5
04/03/2013 02:40:20;0001;PBS_Server;Svr;PBS_Server;LOG_ERROR::sync_node_jobs, stray job 21312.tyrone-cluster found on tyrone-node4
04/03/2013 02:40:30;0001;PBS_Server;Svr;PBS_Server;LOG_ERROR::sync_node_jobs, stray job 21190.tyrone-cluster found on tyrone-node6
04/03/2013 02:40:33;0001;PBS_Server;Svr;PBS_Server;LOG_ERROR::sync_node_jobs, stray job 21306.tyrone-cluster found on tyrone-node5
04/03/2013 02:41:05;0001;PBS_Server;Svr;PBS_Server;LOG_ERROR::sync_node_jobs, stray job 21312.tyrone-cluster found on tyrone-node4
04/03/2013 02:41:15;0001;PBS_Server;Svr;PBS_Server;LOG_ERROR::sync_node_jobs, stray job 21190.tyrone-cluster found on tyrone-node6
04/03/2013 02:41:18;0001;PBS_Server;Svr;PBS_Server;LOG_ERROR::sync_node_jobs, stray job 21306.tyrone-cluster found on tyrone-node5
04/03/2013 02:41:50;0001;PBS_Server;Svr;PBS_Server;LOG_ERROR::sync_node_jobs, stray job 21312.tyrone-cluster found on tyrone-node4
04/03/2013 02:42:00;0001;PBS_Server;Svr;PBS_Server;LOG_ERROR::sync_node_jobs, stray job 21190.tyrone-cluster found on tyrone-node6
04/03/2013 02:42:03;0001;PBS_Server;Svr;PBS_Server;LOG_ERROR::sync_node_jobs, stray job 21306.tyrone-cluster found on tyrone-node5
04/03/2013 02:42:35;0001;PBS_Server;Svr;PBS_Server;LOG_ERROR::sync_node_jobs, stray job 21312.tyrone-cluster found on tyrone-node4
04/03/2013 02:42:45;0001;PBS_Server;Svr;PBS_Server;LOG_ERROR::sync_node_jobs, stray job 21190.tyrone-cluster found on tyrone-node6
04/03/2013 02:42:48;0001;PBS_Server;Svr;PBS_Server;LOG_ERROR::sync_node_jobs, stray job 21306.tyrone-cluster found on tyrone-node5
04/03/2013 02:43:20;0001;PBS_Server;Svr;PBS_Server;LOG_ERROR::sync_node_jobs, stray job 21312.tyrone-cluster found on tyrone-node4
04/03/2013 02:43:30;0002;PBS_Server;Svr;PBS_Server;Torque Server Version = 3.0.5, loglevel = 0
04/03/2013 02:43:30;0001;PBS_Server;Svr;PBS_Server;LOG_ERROR::sync_node_jobs, stray job 21190.tyrone-cluster found on tyrone-node6
04/03/2013 02:43:33;0001;PBS_Server;Svr;PBS_Server;LOG_ERROR::sync_node_jobs, stray job 21306.tyrone-cluster found on tyrone-node5
04/03/2013 02:44:05;0001;PBS_Server;Svr;PBS_Server;LOG_ERROR::sync_node_jobs, stray job 21312.tyrone-cluster found on tyrone-node4
04/03/2013 02:44:15;0001;PBS_Server;Svr;PBS_Server;LOG_ERROR::sync_node_jobs, stray job 21190.tyrone-cluster found on tyrone-node6
04/03/2013 02:44:18;0001;PBS_Server;Svr;PBS_Server;LOG_ERROR::sync_node_jobs, stray job 21306.tyrone-cluster found on tyrone-node5
04/03/2013 02:44:50;0001;PBS_Server;Svr;PBS_Server;LOG_ERROR::sync_node_jobs, stray job 21312.tyrone-cluster found on tyrone-node4
04/03/2013 02:45:00;0001;PBS_Server;Svr;PBS_Server;LOG_ERROR::sync_node_jobs, stray job 21190.tyrone-cluster found on tyrone-node6
04/03/2013 02:45:03;0001;PBS_Server;Svr;PBS_Server;LOG_ERROR::sync_node_jobs, stray job 21306.tyrone-cluster found on tyrone-node5
04/03/2013 02:45:05;0040;PBS_Server;Svr;tyrone-cluster;Scheduler was sent the command time
04/03/2013 02:45:05;0100;PBS_Server;Job;21322.tyrone-cluster;enqueuing into batch, state 1 hop 1
04/03/2013 02:45:05;0100;PBS_Server;Job;21322.tyrone-cluster;dequeuing from batch, state QUEUED
04/03/2013 02:45:05;0100;PBS_Server;Job;21322.tyrone-cluster;enqueuing into qp32, state 1 hop 1
04/03/2013 02:45:05;0008;PBS_Server;Job;21322.tyrone-cluster;Job Queued at request of secbadar@tyrone-cluster, owner = secbadar@tyrone-cluster, job name = myjob, queue = qp32
04/03/2013 02:45:34;0001;PBS_Server;Svr;PBS_Server;LOG_ERROR::sync_node_jobs, stray job 21312.tyrone-cluster found on tyrone-node4
04/03/2013 02:45:45;0001;PBS_Server;Svr;PBS_Server;LOG_ERROR::sync_node_jobs, stray job 21190.tyrone-cluster found on tyrone-node6
04/03/2013 02:45:48;0001;PBS_Server;Svr;PBS_Server;LOG_ERROR::sync_node_jobs, stray job 21306.tyrone-cluster found on tyrone-node5
04/03/2013 02:46:19;0001;PBS_Server;Svr;PBS_Server;LOG_ERROR::sync_node_jobs, stray job 21312.tyrone-cluster found on tyrone-node4
04/03/2013 02:46:27;0100;PBS_Server;Job;21323.tyrone-cluster;enqueuing into batch, state 1 hop 1
04/03/2013 02:46:27;0100;PBS_Server;Job;21323.tyrone-cluster;dequeuing from batch, state QUEUED
04/03/2013 02:46:27;0100;PBS_Server;Job;21323.tyrone-cluster;enqueuing into qp32, state 1 hop 1
04/03/2013 02:46:27;0008;PBS_Server;Job;21323.tyrone-cluster;Job Queued at request of secbadar@tyrone-cluster, owner = secbadar@tyrone-cluster, job name = myjob, queue = qp32
04/03/2013 02:46:27;0040;PBS_Server;Svr;tyrone-cluster;Scheduler was sent the command new
04/03/2013 02:46:27;0008;PBS_Server;Job;21322.tyrone-cluster;Job Modified at request of Scheduler@tyrone-cluster
04/03/2013 02:46:27;0008;PBS_Server;Job;21322.tyrone-cluster;Job Run at request of Scheduler@tyrone-cluster
04/03/2013 02:46:27;0008;PBS_Server;Job;21323.tyrone-cluster;Job Modified at request of Scheduler@tyrone-cluster
04/03/2013 02:46:27;000d;PBS_Server;Job;21322.tyrone-cluster;Not sending email: User does not want mail of this type.
04/03/2013 02:46:27;0008;PBS_Server;Job;21323.tyrone-cluster;Job Run at request of Scheduler@tyrone-cluster
04/03/2013 02:46:27;000d;PBS_Server;Job;21323.tyrone-cluster;Not sending email: User does not want mail of this type.
04/03/2013 02:46:30;0001;PBS_Server;Svr;PBS_Server;LOG_ERROR::sync_node_jobs, stray job 21190.tyrone-cluster found on tyrone-node6
04/03/2013 02:46:33;0001;PBS_Server;Svr;PBS_Server;LOG_ERROR::sync_node_jobs, stray job 21306.tyrone-cluster found on tyrone-node5
04/03/2013 02:46:33;000d;PBS_Server;Job;21322.tyrone-cluster;Not sending email: User does not want mail of this type.
04/03/2013 02:46:33;0010;PBS_Server;Job;21322.tyrone-cluster;Exit_status=11 resources_used.cput=00:01:40 resources_used.mem=0kb resources_used.vmem=0kb resources_used.walltime=00:00:06
04/03/2013 02:46:33;0008;PBS_Server;Job;NULL;on_job_exit valid pjob: 0x1fa2f10 (substate=50)
04/03/2013 02:46:33;0008;PBS_Server;Job;NULL;on_job_exit valid pjob: 0x1fa2f10 (substate=51)
04/03/2013 02:46:34;0008;PBS_Server;Job;NULL;on_job_exit valid pjob: 0x1fa2f10 (substate=51)
04/03/2013 02:46:34;0008;PBS_Server;Job;NULL;on_job_exit valid pjob: 0x1fa2f10 (substate=53)
04/03/2013 02:46:34;0100;PBS_Server;Job;21322.tyrone-cluster;dequeuing from qp32, state COMPLETE
04/03/2013 02:46:34;0040;PBS_Server;Svr;tyrone-cluster;Scheduler was sent the command term
04/03/2013 02:47:05;0001;PBS_Server;Svr;PBS_Server;LOG_ERROR::sync_node_jobs, stray job 21312.tyrone-cluster found on tyrone-node4
04/03/2013 02:47:16;0001;PBS_Server;Svr;PBS_Server;LOG_ERROR::sync_node_jobs, stray job 21190.tyrone-cluster found on tyrone-node6
04/03/2013 02:47:18;0001;PBS_Server;Svr;PBS_Server;LOG_ERROR::sync_node_jobs, stray job 21306.tyrone-cluster found on tyrone-node5
04/03/2013 02:47:50;0001;PBS_Server;Svr;PBS_Server;LOG_ERROR::sync_node_jobs, stray job 21312.tyrone-cluster found on tyrone-node4
04/03/2013 02:48:01;0001;PBS_Server;Svr;PBS_Server;LOG_ERROR::sync_node_jobs, stray job 21190.tyrone-cluster found on tyrone-node6
04/03/2013 02:48:01;000d;PBS_Server;Job;21323.tyrone-cluster;Not sending email: User does not want mail of this type.
04/03/2013 02:48:01;0010;PBS_Server;Job;21323.tyrone-cluster;Exit_status=0 resources_used.cput=00:01:31 resources_used.mem=3076424kb resources_used.vmem=19865116kb resources_used.walltime=00:01:34
04/03/2013 02:48:01;0008;PBS_Server;Job;NULL;on_job_exit valid pjob: 0x2051580 (substate=50)
04/03/2013 02:48:01;0008;PBS_Server;Job;NULL;on_job_exit valid pjob: 0x2051580 (substate=51)
04/03/2013 02:48:01;0008;PBS_Server;Job;NULL;on_job_exit valid pjob: 0x2051580 (substate=51)
04/03/2013 02:48:01;0008;PBS_Server;Job;NULL;on_job_exit valid pjob: 0x2051580 (substate=53)
04/03/2013 02:48:01;0100;PBS_Server;Job;21323.tyrone-cluster;dequeuing from qp32, state COMPLETE
04/03/2013 02:48:01;0040;PBS_Server;Svr;tyrone-cluster;Scheduler was sent the command term
04/03/2013 02:48:03;0001;PBS_Server;Svr;PBS_Server;LOG_ERROR::sync_node_jobs, stray job 21306.tyrone-cluster found on tyrone-node5
04/03/2013 02:48:30;0002;PBS_Server;Svr;PBS_Server;Torque Server Version = 3.0.5, loglevel = 0
04/03/2013 02:48:35;0001;PBS_Server;Svr;PBS_Server;LOG_ERROR::sync_node_jobs, stray job 21312.tyrone-cluster found on tyrone-node4
04/03/2013 02:48:46;0001;PBS_Server;Svr;PBS_Server;LOG_ERROR::sync_node_jobs, stray job 21190.tyrone-cluster found on tyrone-node6
04/03/2013 02:48:48;0001;PBS_Server;Svr;PBS_Server;LOG_ERROR::sync_node_jobs, stray job 21306.tyrone-cluster found on tyrone-node5
04/03/2013 02:49:20;0001;PBS_Server;Svr;PBS_Server;LOG_ERROR::sync_node_jobs, stray job 21312.tyrone-cluster found on tyrone-node4
04/03/2013 02:49:31;0001;PBS_Server;Svr;PBS_Server;LOG_ERROR::sync_node_jobs, stray job 21190.tyrone-cluster found on tyrone-node6
04/03/2013 02:49:33;0001;PBS_Server;Svr;PBS_Server;LOG_ERROR::sync_node_jobs, stray job 21306.tyrone-cluster found on tyrone-node5
04/03/2013 02:50:05;0001;PBS_Server;Svr;PBS_Server;LOG_ERROR::sync_node_jobs, stray job 21312.tyrone-cluster found on tyrone-node4
04/03/2013 02:50:16;0001;PBS_Server;Svr;PBS_Server;LOG_ERROR::sync_node_jobs, stray job 21190.tyrone-cluster found on tyrone-node6
04/03/2013 02:50:18;0001;PBS_Server;Svr;PBS_Server;LOG_ERROR::sync_node_jobs, stray job 21306.tyrone-cluster found on tyrone-node5
04/03/2013 02:50:50;0001;PBS_Server;Svr;PBS_Server;LOG_ERROR::sync_node_jobs, stray job 21312.tyrone-cluster found on tyrone-node4
04/03/2013 02:51:01;0001;PBS_Server;Svr;PBS_Server;LOG_ERROR::sync_node_jobs, stray job 21190.tyrone-cluster found on tyrone-node6
04/03/2013 02:51:03;0001;PBS_Server;Svr;PBS_Server;LOG_ERROR::sync_node_jobs, stray job 21306.tyrone-cluster found on tyrone-node5
04/03/2013 02:51:35;0001;PBS_Server;Svr;PBS_Server;LOG_ERROR::sync_node_jobs, stray job 21312.tyrone-cluster found on tyrone-node4
04/03/2013 02:51:46;0001;PBS_Server;Svr;PBS_Server;LOG_ERROR::sync_node_jobs, stray job 21190.tyrone-cluster found on tyrone-node6
04/03/2013 02:51:48;0001;PBS_Server;Svr;PBS_Server;LOG_ERROR::sync_node_jobs, stray job 21306.tyrone-cluster found on tyrone-node5
04/03/2013 02:52:20;0001;PBS_Server;Svr;PBS_Server;LOG_ERROR::sync_node_jobs, stray job 21312.tyrone-cluster found on tyrone-node4
04/03/2013 02:52:30;0001;PBS_Server;Svr;PBS_Server;LOG_ERROR::sync_node_jobs, stray job 21190.tyrone-cluster found on tyrone-node6
04/03/2013 02:52:33;0001;PBS_Server;Svr;PBS_Server;LOG_ERROR::sync_node_jobs, stray job 21306.tyrone-cluster found on tyrone-node5
04/03/2013 02:52:42;0100;PBS_Server;Job;21324.tyrone-cluster;enqueuing into batch, state 1 hop 1
04/03/2013 02:52:42;0100;PBS_Server;Job;21324.tyrone-cluster;dequeuing from batch, state QUEUED
04/03/2013 02:52:42;0100;PBS_Server;Job;21324.tyrone-cluster;enqueuing into qp32, state 1 hop 1
04/03/2013 02:52:42;0008;PBS_Server;Job;21324.tyrone-cluster;Job Queued at request of secbadar@tyrone-cluster, owner = secbadar@tyrone-cluster, job name = myjob, queue = qp32
04/03/2013 02:52:42;0040;PBS_Server;Svr;tyrone-cluster;Scheduler was sent the command new
04/03/2013 02:52:42;0008;PBS_Server;Job;21324.tyrone-cluster;Job Modified at request of Scheduler@tyrone-cluster
04/03/2013 02:52:42;0008;PBS_Server;Job;21324.tyrone-cluster;Job Run at request of Scheduler@tyrone-cluster
04/03/2013 02:52:42;0040;PBS_Server;Svr;tyrone-cluster;Scheduler was sent the command recyc
04/03/2013 02:52:42;000d;PBS_Server;Job;21324.tyrone-cluster;Not sending email: User does not want mail of this type.
04/03/2013 02:52:43;000d;PBS_Server;Job;21324.tyrone-cluster;Not sending email: User does not want mail of this type.
04/03/2013 02:52:43;0010;PBS_Server;Job;21324.tyrone-cluster;Exit_status=255 resources_used.cput=00:00:00 resources_used.mem=0kb resources_used.vmem=0kb resources_used.walltime=00:00:01
04/03/2013 02:52:43;0008;PBS_Server;Job;NULL;on_job_exit valid pjob: 0x2051580 (substate=50)
04/03/2013 02:52:43;0008;PBS_Server;Job;NULL;on_job_exit valid pjob: 0x2051580 (substate=51)
04/03/2013 02:52:43;0008;PBS_Server;Job;NULL;on_job_exit valid pjob: 0x2051580 (substate=51)
04/03/2013 02:52:43;0008;PBS_Server;Job;NULL;on_job_exit valid pjob: 0x2051580 (substate=53)
04/03/2013 02:52:43;0100;PBS_Server;Job;21324.tyrone-cluster;dequeuing from qp32, state COMPLETE
04/03/2013 02:52:43;0040;PBS_Server;Svr;tyrone-cluster;Scheduler was sent the command term
04/03/2013 02:53:04;0001;PBS_Server;Svr;PBS_Server;LOG_ERROR::sync_node_jobs, stray job 21312.tyrone-cluster found on tyrone-node4
04/03/2013 02:53:16;0001;PBS_Server;Svr;PBS_Server;LOG_ERROR::sync_node_jobs, stray job 21190.tyrone-cluster found on tyrone-node6
04/03/2013 02:53:17;0001;PBS_Server;Svr;PBS_Server;LOG_ERROR::sync_node_jobs, stray job 21306.tyrone-cluster found on tyrone-node5
04/03/2013 02:53:30;0002;PBS_Server;Svr;PBS_Server;Torque Server Version = 3.0.5, loglevel = 0
04/03/2013 02:53:50;0001;PBS_Server;Svr;PBS_Server;LOG_ERROR::sync_node_jobs, stray job 21312.tyrone-cluster found on tyrone-node4
04/03/2013 02:54:01;0001;PBS_Server;Svr;PBS_Server;LOG_ERROR::sync_node_jobs, stray job 21190.tyrone-cluster found on tyrone-node6
04/03/2013 02:54:03;0001;PBS_Server;Svr;PBS_Server;LOG_ERROR::sync_node_jobs, stray job 21306.tyrone-cluster found on tyrone-node5
04/03/2013 02:54:35;0001;PBS_Server;Svr;PBS_Server;LOG_ERROR::sync_node_jobs, stray job 21312.tyrone-cluster found on tyrone-node4
04/03/2013 02:54:46;0001;PBS_Server;Svr;PBS_Server;LOG_ERROR::sync_node_jobs, stray job 21190.tyrone-cluster found on tyrone-node6
04/03/2013 02:54:48;0001;PBS_Server;Svr;PBS_Server;LOG_ERROR::sync_node_jobs, stray job 21306.tyrone-cluster found on tyrone-node5
04/03/2013 02:54:50;0100;PBS_Server;Job;21325.tyrone-cluster;enqueuing into batch, state 1 hop 1
04/03/2013 02:54:50;0100;PBS_Server;Job;21325.tyrone-cluster;dequeuing from batch, state QUEUED
04/03/2013 02:54:50;0100;PBS_Server;Job;21325.tyrone-cluster;enqueuing into qp32, state 1 hop 1
04/03/2013 02:54:50;0008;PBS_Server;Job;21325.tyrone-cluster;Job Queued at request of secbadar@tyrone-cluster, owner = secbadar@tyrone-cluster, job name = myjob, queue = qp32
04/03/2013 02:54:50;0040;PBS_Server;Svr;tyrone-cluster;Scheduler was sent the command new
04/03/2013 02:54:50;0008;PBS_Server;Job;21325.tyrone-cluster;Job Modified at request of Scheduler@tyrone-cluster
04/03/2013 02:54:50;0008;PBS_Server;Job;21325.tyrone-cluster;Job Run at request of Scheduler@tyrone-cluster
04/03/2013 02:54:50;0040;PBS_Server;Svr;tyrone-cluster;Scheduler was sent the command recyc
04/03/2013 02:54:50;000d;PBS_Server;Job;21325.tyrone-cluster;Not sending email: User does not want mail of this type.
04/03/2013 02:54:51;000d;PBS_Server;Job;21325.tyrone-cluster;Not sending email: User does not want mail of this type.
04/03/2013 02:54:51;0010;PBS_Server;Job;21325.tyrone-cluster;Exit_status=255 resources_used.cput=00:00:00 resources_used.mem=0kb resources_used.vmem=0kb resources_used.walltime=00:00:01
04/03/2013 02:54:51;0008;PBS_Server;Job;NULL;on_job_exit valid pjob: 0x1fa2f10 (substate=50)
04/03/2013 02:54:51;0008;PBS_Server;Job;NULL;on_job_exit valid pjob: 0x1fa2f10 (substate=51)
04/03/2013 02:54:52;0008;PBS_Server;Job;NULL;on_job_exit valid pjob: 0x1fa2f10 (substate=51)
04/03/2013 02:54:52;0008;PBS_Server;Job;NULL;on_job_exit valid pjob: 0x1fa2f10 (substate=53)
04/03/2013 02:54:52;0100;PBS_Server;Job;21325.tyrone-cluster;dequeuing from qp32, state COMPLETE
04/03/2013 02:54:52;0040;PBS_Server;Svr;tyrone-cluster;Scheduler was sent the command term
04/03/2013 02:55:20;0001;PBS_Server;Svr;PBS_Server;LOG_ERROR::sync_node_jobs, stray job 21312.tyrone-cluster found on tyrone-node4
04/03/2013 02:55:30;0001;PBS_Server;Svr;PBS_Server;LOG_ERROR::sync_node_jobs, stray job 21190.tyrone-cluster found on tyrone-node6
04/03/2013 02:55:33;0001;PBS_Server;Svr;PBS_Server;LOG_ERROR::sync_node_jobs, stray job 21306.tyrone-cluster found on tyrone-node5
04/03/2013 02:56:05;0001;PBS_Server;Svr;PBS_Server;LOG_ERROR::sync_node_jobs, stray job 21312.tyrone-cluster found on tyrone-node4
04/03/2013 02:56:09;0100;PBS_Server;Job;21326.tyrone-cluster;enqueuing into batch, state 1 hop 1
04/03/2013 02:56:09;0100;PBS_Server;Job;21326.tyrone-cluster;dequeuing from batch, state QUEUED
04/03/2013 02:56:09;0100;PBS_Server;Job;21326.tyrone-cluster;enqueuing into qp32, state 1 hop 1
04/03/2013 02:56:09;0008;PBS_Server;Job;21326.tyrone-cluster;Job Queued at request of secbadar@tyrone-cluster, owner = secbadar@tyrone-cluster, job name = myjob, queue = qp32
04/03/2013 02:56:09;0040;PBS_Server;Svr;tyrone-cluster;Scheduler was sent the command new
04/03/2013 02:56:09;0008;PBS_Server;Job;21326.tyrone-cluster;Job Modified at request of Scheduler@tyrone-cluster
04/03/2013 02:56:09;0008;PBS_Server;Job;21326.tyrone-cluster;Job Run at request of Scheduler@tyrone-cluster
04/03/2013 02:56:10;0040;PBS_Server;Svr;tyrone-cluster;Scheduler was sent the command recyc
04/03/2013 02:56:10;000d;PBS_Server;Job;21326.tyrone-cluster;Not sending email: User does not want mail of this type.
04/03/2013 02:56:15;0001;PBS_Server;Svr;PBS_Server;LOG_ERROR::sync_node_jobs, stray job 21190.tyrone-cluster found on tyrone-node6
04/03/2013 02:56:17;0001;PBS_Server;Svr;PBS_Server;LOG_ERROR::sync_node_jobs, stray job 21306.tyrone-cluster found on tyrone-node5
04/03/2013 02:56:35;000d;PBS_Server;Job;21326.tyrone-cluster;Not sending email: User does not want mail of this type.
04/03/2013 02:56:35;0010;PBS_Server;Job;21326.tyrone-cluster;Exit_status=0 resources_used.cput=00:08:32 resources_used.mem=65368kb resources_used.vmem=1493344kb resources_used.walltime=00:00:26
04/03/2013 02:56:35;0008;PBS_Server;Job;NULL;on_job_exit valid pjob: 0x2051580 (substate=50)
04/03/2013 02:56:35;0008;PBS_Server;Job;NULL;on_job_exit valid pjob: 0x2051580 (substate=51)
04/03/2013 02:56:36;0008;PBS_Server;Job;NULL;on_job_exit valid pjob: 0x2051580 (substate=51)
04/03/2013 02:56:36;0008;PBS_Server;Job;NULL;on_job_exit valid pjob: 0x2051580 (substate=53)
04/03/2013 02:56:36;0100;PBS_Server;Job;21326.tyrone-cluster;dequeuing from qp32, state COMPLETE
04/03/2013 02:56:36;0040;PBS_Server;Svr;tyrone-cluster;Scheduler was sent the command term
04/03/2013 02:56:49;0001;PBS_Server;Svr;PBS_Server;LOG_ERROR::sync_node_jobs, stray job 21312.tyrone-cluster found on tyrone-node4
04/03/2013 02:57:00;0001;PBS_Server;Svr;PBS_Server;LOG_ERROR::sync_node_jobs, stray job 21190.tyrone-cluster found on tyrone-node6
04/03/2013 02:57:03;0001;PBS_Server;Svr;PBS_Server;LOG_ERROR::sync_node_jobs, stray job 21306.tyrone-cluster found on tyrone-node5
04/03/2013 02:57:34;0001;PBS_Server;Svr;PBS_Server;LOG_ERROR::sync_node_jobs, stray job 21312.tyrone-cluster found on tyrone-node4
04/03/2013 02:57:45;0001;PBS_Server;Svr;PBS_Server;LOG_ERROR::sync_node_jobs, stray job 21190.tyrone-cluster found on tyrone-node6
04/03/2013 02:57:48;0001;PBS_Server;Svr;PBS_Server;LOG_ERROR::sync_node_jobs, stray job 21306.tyrone-cluster found on tyrone-node5
04/03/2013 02:58:19;0001;PBS_Server;Svr;PBS_Server;LOG_ERROR::sync_node_jobs, stray job 21312.tyrone-cluster found on tyrone-node4
04/03/2013 02:58:30;0002;PBS_Server;Svr;PBS_Server;Torque Server Version = 3.0.5, loglevel = 0
04/03/2013 02:58:30;0001;PBS_Server;Svr;PBS_Server;LOG_ERROR::sync_node_jobs, stray job 21190.tyrone-cluster found on tyrone-node6
04/03/2013 02:58:32;0001;PBS_Server;Svr;PBS_Server;LOG_ERROR::sync_node_jobs, stray job 21306.tyrone-cluster found on tyrone-node5
04/03/2013 02:59:04;0001;PBS_Server;Svr;PBS_Server;LOG_ERROR::sync_node_jobs, stray job 21312.tyrone-cluster found on tyrone-node4
04/03/2013 02:59:15;0001;PBS_Server;Svr;PBS_Server;LOG_ERROR::sync_node_jobs, stray job 21190.tyrone-cluster found on tyrone-node6
04/03/2013 02:59:17;0001;PBS_Server;Svr;PBS_Server;LOG_ERROR::sync_node_jobs, stray job 21306.tyrone-cluster found on tyrone-node5
04/03/2013 02:59:49;0001;PBS_Server;Svr;PBS_Server;LOG_ERROR::sync_node_jobs, stray job 21312.tyrone-cluster found on tyrone-node4
04/03/2013 03:00:01;0001;PBS_Server;Svr;PBS_Server;LOG_ERROR::sync_node_jobs, stray job 21190.tyrone-cluster found on tyrone-node6
04/03/2013 03:00:02;0001;PBS_Server;Svr;PBS_Server;LOG_ERROR::sync_node_jobs, stray job 21306.tyrone-cluster found on tyrone-node5
04/03/2013 03:00:12;0100;PBS_Server;Job;21327.tyrone-cluster;enqueuing into batch, state 1 hop 1
04/03/2013 03:00:12;0100;PBS_Server;Job;21327.tyrone-cluster;dequeuing from batch, state QUEUED
04/03/2013 03:00:12;0100;PBS_Server;Job;21327.tyrone-cluster;enqueuing into qp32, state 1 hop 1
04/03/2013 03:00:12;0008;PBS_Server;Job;21327.tyrone-cluster;Job Queued at request of secbadar@tyrone-cluster, owner = secbadar@tyrone-cluster, job name = myjob, queue = qp32
04/03/2013 03:00:12;0040;PBS_Server;Svr;tyrone-cluster;Scheduler was sent the command new
04/03/2013 03:00:12;0008;PBS_Server;Job;21327.tyrone-cluster;Job Modified at request of Scheduler@tyrone-cluster
04/03/2013 03:00:12;0008;PBS_Server;Job;21327.tyrone-cluster;Job Run at request of Scheduler@tyrone-cluster
04/03/2013 03:00:12;0040;PBS_Server;Svr;tyrone-cluster;Scheduler was sent the command recyc
04/03/2013 03:00:12;000d;PBS_Server;Job;21327.tyrone-cluster;Not sending email: User does not want mail of this type.
04/03/2013 03:00:35;0001;PBS_Server;Svr;PBS_Server;LOG_ERROR::sync_node_jobs, stray job 21312.tyrone-cluster found on tyrone-node4
04/03/2013 03:00:37;000d;PBS_Server;Job;21327.tyrone-cluster;Not sending email: User does not want mail of this type.
04/03/2013 03:00:37;0010;PBS_Server;Job;21327.tyrone-cluster;Exit_status=0 resources_used.cput=00:08:46 resources_used.mem=1739404kb resources_used.vmem=3429316kb resources_used.walltime=00:00:25
04/03/2013 03:00:37;0008;PBS_Server;Job;NULL;on_job_exit valid pjob: 0x1fa2f10 (substate=50)
04/03/2013 03:00:37;0008;PBS_Server;Job;NULL;on_job_exit valid pjob: 0x1fa2f10 (substate=51)
04/03/2013 03:00:37;0008;PBS_Server;Job;NULL;on_job_exit valid pjob: 0x1fa2f10 (substate=51)
04/03/2013 03:00:37;0008;PBS_Server;Job;NULL;on_job_exit valid pjob: 0x1fa2f10 (substate=53)
04/03/2013 03:00:37;0100;PBS_Server;Job;21327.tyrone-cluster;dequeuing from qp32, state COMPLETE
04/03/2013 03:00:37;0040;PBS_Server;Svr;tyrone-cluster;Scheduler was sent the command term
04/03/2013 03:00:46;0001;PBS_Server;Svr;PBS_Server;LOG_ERROR::sync_node_jobs, stray job 21190.tyrone-cluster found on tyrone-node6
04/03/2013 03:00:47;0001;PBS_Server;Svr;PBS_Server;LOG_ERROR::sync_node_jobs, stray job 21306.tyrone-cluster found on tyrone-node5
04/03/2013 03:01:20;0001;PBS_Server;Svr;PBS_Server;LOG_ERROR::sync_node_jobs, stray job 21312.tyrone-cluster found on tyrone-node4
04/03/2013 03:01:31;0001;PBS_Server;Svr;PBS_Server;LOG_ERROR::sync_node_jobs, stray job 21190.tyrone-cluster found on tyrone-node6
04/03/2013 03:01:33;0001;PBS_Server;Svr;PBS_Server;LOG_ERROR::sync_node_jobs, stray job 21306.tyrone-cluster found on tyrone-node5
04/03/2013 03:02:05;0001;PBS_Server;Svr;PBS_Server;LOG_ERROR::sync_node_jobs, stray job 21312.tyrone-cluster found on tyrone-node4
04/03/2013 03:02:16;0001;PBS_Server;Svr;PBS_Server;LOG_ERROR::sync_node_jobs, stray job 21190.tyrone-cluster found on tyrone-node6
04/03/2013 03:02:18;0001;PBS_Server;Svr;PBS_Server;LOG_ERROR::sync_node_jobs, stray job 21306.tyrone-cluster found on tyrone-node5
04/03/2013 03:02:50;0001;PBS_Server;Svr;PBS_Server;LOG_ERROR::sync_node_jobs, stray job 21312.tyrone-cluster found on tyrone-node4
04/03/2013 03:03:01;0001;PBS_Server;Svr;PBS_Server;LOG_ERROR::sync_node_jobs, stray job 21190.tyrone-cluster found on tyrone-node6
04/03/2013 03:03:03;0001;PBS_Server;Svr;PBS_Server;LOG_ERROR::sync_node_jobs, stray job 21306.tyrone-cluster found on tyrone-node5
04/03/2013 03:03:24;0100;PBS_Server;Job;21328.tyrone-cluster;enqueuing into batch, state 1 hop 1
04/03/2013 03:03:24;0100;PBS_Server;Job;21328.tyrone-cluster;dequeuing from batch, state QUEUED
04/03/2013 03:03:24;0100;PBS_Server;Job;21328.tyrone-cluster;enqueuing into idqueue, state 1 hop 1
04/03/2013 03:03:24;0008;PBS_Server;Job;21328.tyrone-cluster;Job Queued at request of secjsht@tyrone-cluster, owner = secjsht@tyrone-cluster, job name = us1proc, queue = idqueue
04/03/2013 03:03:24;0040;PBS_Server;Svr;tyrone-cluster;Scheduler was sent the command new
04/03/2013 03:03:24;0008;PBS_Server;Job;21328.tyrone-cluster;Job Modified at request of Scheduler@tyrone-cluster
04/03/2013 03:03:24;0008;PBS_Server;Job;21328.tyrone-cluster;Job Run at request of Scheduler@tyrone-cluster
04/03/2013 03:03:25;0040;PBS_Server;Svr;tyrone-cluster;Scheduler was sent the command recyc
04/03/2013 03:03:25;000d;PBS_Server;Job;21328.tyrone-cluster;Not sending email: User does not want mail of this type.
04/03/2013 03:03:30;0002;PBS_Server;Svr;PBS_Server;Torque Server Version = 3.0.5, loglevel = 0
04/03/2013 03:03:35;0001;PBS_Server;Svr;PBS_Server;LOG_ERROR::sync_node_jobs, stray job 21312.tyrone-cluster found on tyrone-node4
04/03/2013 03:03:45;0001;PBS_Server;Svr;PBS_Server;LOG_ERROR::sync_node_jobs, stray job 21190.tyrone-cluster found on tyrone-node6
04/03/2013 03:03:47;0001;PBS_Server;Svr;PBS_Server;LOG_ERROR::sync_node_jobs, stray job 21306.tyrone-cluster found on tyrone-node5
04/03/2013 03:04:03;0008;PBS_Server;Job;21328.tyrone-cluster;Job deleted at request of secjsht@tyrone-cluster
04/03/2013 03:04:03;0008;PBS_Server;Job;21328.tyrone-cluster;Job sent signal SIGTERM on delete
04/03/2013 03:04:04;000d;PBS_Server;Job;21328.tyrone-cluster;Not sending email: User does not want mail of this type.
04/03/2013 03:04:04;0010;PBS_Server;Job;21328.tyrone-cluster;Exit_status=143 resources_used.cput=00:00:23 resources_used.mem=4844132kb resources_used.vmem=10087308kb resources_used.walltime=00:00:38
04/03/2013 03:04:04;0008;PBS_Server;Job;NULL;on_job_exit valid pjob: 0x1fa2f10 (substate=50)
04/03/2013 03:04:04;0008;PBS_Server;Job;NULL;on_job_exit valid pjob: 0x1fa2f10 (substate=51)
04/03/2013 03:04:04;0008;PBS_Server;Job;NULL;on_job_exit valid pjob: 0x1fa2f10 (substate=51)
04/03/2013 03:04:04;0008;PBS_Server;Job;NULL;on_job_exit valid pjob: 0x1fa2f10 (substate=53)
04/03/2013 03:04:04;0100;PBS_Server;Job;21328.tyrone-cluster;dequeuing from idqueue, state COMPLETE
04/03/2013 03:04:04;0040;PBS_Server;Svr;tyrone-cluster;Scheduler was sent the command term
04/03/2013 03:04:19;0001;PBS_Server;Svr;PBS_Server;LOG_ERROR::sync_node_jobs, stray job 21312.tyrone-cluster found on tyrone-node4
04/03/2013 03:04:30;0001;PBS_Server;Svr;PBS_Server;LOG_ERROR::sync_node_jobs, stray job 21190.tyrone-cluster found on tyrone-node6
04/03/2013 03:04:32;0001;PBS_Server;Svr;PBS_Server;LOG_ERROR::sync_node_jobs, stray job 21306.tyrone-cluster found on tyrone-node5
04/03/2013 03:05:05;0001;PBS_Server;Svr;PBS_Server;LOG_ERROR::sync_node_jobs, stray job 21312.tyrone-cluster found on tyrone-node4
04/03/2013 03:05:16;0001;PBS_Server;Svr;PBS_Server;LOG_ERROR::sync_node_jobs, stray job 21190.tyrone-cluster found on tyrone-node6
04/03/2013 03:05:17;0001;PBS_Server;Svr;PBS_Server;LOG_ERROR::sync_node_jobs, stray job 21306.tyrone-cluster found on tyrone-node5
04/03/2013 03:05:50;0001;PBS_Server;Svr;PBS_Server;LOG_ERROR::sync_node_jobs, stray job 21312.tyrone-cluster found on tyrone-node4
04/03/2013 03:06:01;0001;PBS_Server;Svr;PBS_Server;LOG_ERROR::sync_node_jobs, stray job 21190.tyrone-cluster found on tyrone-node6
04/03/2013 03:06:03;0001;PBS_Server;Svr;PBS_Server;LOG_ERROR::sync_node_jobs, stray job 21306.tyrone-cluster found on tyrone-node5
04/03/2013 03:06:35;0001;PBS_Server;Svr;PBS_Server;LOG_ERROR::sync_node_jobs, stray job 21312.tyrone-cluster found on tyrone-node4
04/03/2013 03:06:46;0001;PBS_Server;Svr;PBS_Server;LOG_ERROR::sync_node_jobs, stray job 21190.tyrone-cluster found on tyrone-node6
04/03/2013 03:06:48;0001;PBS_Server;Svr;PBS_Server;LOG_ERROR::sync_node_jobs, stray job 21306.tyrone-cluster found on tyrone-node5
04/03/2013 03:07:20;0001;PBS_Server;Svr;PBS_Server;LOG_ERROR::sync_node_jobs, stray job 21312.tyrone-cluster found on tyrone-node4
04/03/2013 03:07:31;0001;PBS_Server;Svr;PBS_Server;LOG_ERROR::sync_node_jobs, stray job 21190.tyrone-cluster found on tyrone-node6
04/03/2013 03:07:33;0001;PBS_Server;Svr;PBS_Server;LOG_ERROR::sync_node_jobs, stray job 21306.tyrone-cluster found on tyrone-node5
04/03/2013 03:08:05;0001;PBS_Server;Svr;PBS_Server;LOG_ERROR::sync_node_jobs, stray job 21312.tyrone-cluster found on tyrone-node4
04/03/2013 03:08:15;0001;PBS_Server;Svr;PBS_Server;LOG_ERROR::sync_node_jobs, stray job 21190.tyrone-cluster found on tyrone-node6
04/03/2013 03:08:18;0001;PBS_Server;Svr;PBS_Server;LOG_ERROR::sync_node_jobs, stray job 21306.tyrone-cluster found on tyrone-node5
04/03/2013 03:08:30;0002;PBS_Server;Svr;PBS_Server;Torque Server Version = 3.0.5, loglevel = 0
04/03/2013 03:08:49;0001;PBS_Server;Svr;PBS_Server;LOG_ERROR::sync_node_jobs, stray job 21312.tyrone-cluster found on tyrone-node4
04/03/2013 03:09:00;0001;PBS_Server;Svr;PBS_Server;LOG_ERROR::sync_node_jobs, stray job 21190.tyrone-cluster found on tyrone-node6
04/03/2013 03:09:03;0001;PBS_Server;Svr;PBS_Server;LOG_ERROR::sync_node_jobs, stray job 21306.tyrone-cluster found on tyrone-node5
04/03/2013 03:09:34;0001;PBS_Server;Svr;PBS_Server;LOG_ERROR::sync_node_jobs, stray job 21312.tyrone-cluster found on tyrone-node4
04/03/2013 03:09:45;0001;PBS_Server;Svr;PBS_Server;LOG_ERROR::sync_node_jobs, stray job 21190.tyrone-cluster found on tyrone-node6
04/03/2013 03:09:48;0001;PBS_Server;Svr;PBS_Server;LOG_ERROR::sync_node_jobs, stray job 21306.tyrone-cluster found on tyrone-node5
04/03/2013 03:10:19;0001;PBS_Server;Svr;PBS_Server;LOG_ERROR::sync_node_jobs, stray job 21312.tyrone-cluster found on tyrone-node4
04/03/2013 03:10:30;0001;PBS_Server;Svr;PBS_Server;LOG_ERROR::sync_node_jobs, stray job 21190.tyrone-cluster found on tyrone-node6
04/03/2013 03:10:33;0001;PBS_Server;Svr;PBS_Server;LOG_ERROR::sync_node_jobs, stray job 21306.tyrone-cluster found on tyrone-node5
04/03/2013 03:11:04;0001;PBS_Server;Svr;PBS_Server;LOG_ERROR::sync_node_jobs, stray job 21312.tyrone-cluster found on tyrone-node4
04/03/2013 03:11:15;0001;PBS_Server;Svr;PBS_Server;LOG_ERROR::sync_node_jobs, stray job 21190.tyrone-cluster found on tyrone-node6
04/03/2013 03:11:18;0001;PBS_Server;Svr;PBS_Server;LOG_ERROR::sync_node_jobs, stray job 21306.tyrone-cluster found on tyrone-node5
04/03/2013 03:11:49;0001;PBS_Server;Svr;PBS_Server;LOG_ERROR::sync_node_jobs, stray job 21312.tyrone-cluster found on tyrone-node4
04/03/2013 03:12:00;0001;PBS_Server;Svr;PBS_Server;LOG_ERROR::sync_node_jobs, stray job 21190.tyrone-cluster found on tyrone-node6
04/03/2013 03:12:03;0001;PBS_Server;Svr;PBS_Server;LOG_ERROR::sync_node_jobs, stray job 21306.tyrone-cluster found on tyrone-node5
04/03/2013 03:12:34;0001;PBS_Server;Svr;PBS_Server;LOG_ERROR::sync_node_jobs, stray job 21312.tyrone-cluster found on tyrone-node4
04/03/2013 03:12:45;0001;PBS_Server;Svr;PBS_Server;LOG_ERROR::sync_node_jobs, stray job 21190.tyrone-cluster found on tyrone-node6
04/03/2013 03:12:48;0001;PBS_Server;Svr;PBS_Server;LOG_ERROR::sync_node_jobs, stray job 21306.tyrone-cluster found on tyrone-node5
04/03/2013 03:13:19;0001;PBS_Server;Svr;PBS_Server;LOG_ERROR::sync_node_jobs, stray job 21312.tyrone-cluster found on tyrone-node4
04/03/2013 03:13:30;0002;PBS_Server;Svr;PBS_Server;Torque Server Version = 3.0.5, loglevel = 0
04/03/2013 03:13:30;0001;PBS_Server;Svr;PBS_Server;LOG_ERROR::sync_node_jobs, stray job 21190.tyrone-cluster found on tyrone-node6
04/03/2013 03:13:33;0001;PBS_Server;Svr;PBS_Server;LOG_ERROR::sync_node_jobs, stray job 21306.tyrone-cluster found on tyrone-node5
04/03/2013 03:14:04;0001;PBS_Server;Svr;PBS_Server;LOG_ERROR::sync_node_jobs, stray job 21312.tyrone-cluster found on tyrone-node4
04/03/2013 03:14:04;0040;PBS_Server;Svr;tyrone-cluster;Scheduler was sent the command time
04/03/2013 03:14:15;0001;PBS_Server;Svr;PBS_Server;LOG_ERROR::sync_node_jobs, stray job 21190.tyrone-cluster found on tyrone-node6
04/03/2013 03:14:18;0001;PBS_Server;Svr;PBS_Server;LOG_ERROR::sync_node_jobs, stray job 21306.tyrone-cluster found on tyrone-node5
04/03/2013 03:14:49;0001;PBS_Server;Svr;PBS_Server;LOG_ERROR::sync_node_jobs, stray job 21312.tyrone-cluster found on tyrone-node4
04/03/2013 03:15:00;0001;PBS_Server;Svr;PBS_Server;LOG_ERROR::sync_node_jobs, stray job 21190.tyrone-cluster found on tyrone-node6
04/03/2013 03:15:03;0001;PBS_Server;Svr;PBS_Server;LOG_ERROR::sync_node_jobs, stray job 21306.tyrone-cluster found on tyrone-node5
04/03/2013 03:15:34;0001;PBS_Server;Svr;PBS_Server;LOG_ERROR::sync_node_jobs, stray job 21312.tyrone-cluster found on tyrone-node4
04/03/2013 03:15:45;0001;PBS_Server;Svr;PBS_Server;LOG_ERROR::sync_node_jobs, stray job 21190.tyrone-cluster found on tyrone-node6
04/03/2013 03:15:47;0001;PBS_Server;Svr;PBS_Server;LOG_ERROR::sync_node_jobs, stray job 21306.tyrone-cluster found on tyrone-node5
04/03/2013 03:16:08;0100;PBS_Server;Job;21329.tyrone-cluster;enqueuing into batch, state 1 hop 1
04/03/2013 03:16:08;0100;PBS_Server;Job;21329.tyrone-cluster;dequeuing from batch, state QUEUED
04/03/2013 03:16:08;0100;PBS_Server;Job;21329.tyrone-cluster;enqueuing into qp32, state 1 hop 1
04/03/2013 03:16:08;0008;PBS_Server;Job;21329.tyrone-cluster;Job Queued at request of secvkm@tyrone-cluster, owner = secvkm@tyrone-cluster, job name = myjob, queue = qp32
04/03/2013 03:16:08;0040;PBS_Server;Svr;tyrone-cluster;Scheduler was sent the command new
04/03/2013 03:16:08;0008;PBS_Server;Job;21329.tyrone-cluster;Job Modified at request of Scheduler@tyrone-cluster
04/03/2013 03:16:08;0008;PBS_Server;Job;21329.tyrone-cluster;Job Run at request of Scheduler@tyrone-cluster
04/03/2013 03:16:08;0040;PBS_Server;Svr;tyrone-cluster;Scheduler was sent the command recyc
04/03/2013 03:16:08;000d;PBS_Server;Job;21329.tyrone-cluster;Not sending email: User does not want mail of this type.
04/03/2013 03:16:09;000d;PBS_Server;Job;21329.tyrone-cluster;Not sending email: User does not want mail of this type.
04/03/2013 03:16:09;0010;PBS_Server;Job;21329.tyrone-cluster;Exit_status=255 resources_used.cput=00:00:00 resources_used.mem=0kb resources_used.vmem=0kb resources_used.walltime=00:00:01
04/03/2013 03:16:09;0008;PBS_Server;Job;NULL;on_job_exit valid pjob: 0x2051580 (substate=50)
04/03/2013 03:16:09;0008;PBS_Server;Job;NULL;on_job_exit valid pjob: 0x2051580 (substate=51)
04/03/2013 03:16:09;0008;PBS_Server;Job;NULL;on_job_exit valid pjob: 0x2051580 (substate=51)
04/03/2013 03:16:09;0008;PBS_Server;Job;NULL;on_job_exit valid pjob: 0x2051580 (substate=53)
04/03/2013 03:16:09;0100;PBS_Server;Job;21329.tyrone-cluster;dequeuing from qp32, state COMPLETE
04/03/2013 03:16:09;0040;PBS_Server;Svr;tyrone-cluster;Scheduler was sent the command term
04/03/2013 03:16:19;0001;PBS_Server;Svr;PBS_Server;LOG_ERROR::sync_node_jobs, stray job 21312.tyrone-cluster found on tyrone-node4
04/03/2013 03:16:30;0001;PBS_Server;Svr;PBS_Server;LOG_ERROR::sync_node_jobs, stray job 21190.tyrone-cluster found on tyrone-node6
04/03/2013 03:16:32;0001;PBS_Server;Svr;PBS_Server;LOG_ERROR::sync_node_jobs, stray job 21306.tyrone-cluster found on tyrone-node5
04/03/2013 03:17:04;0001;PBS_Server;Svr;PBS_Server;LOG_ERROR::sync_node_jobs, stray job 21312.tyrone-cluster found on tyrone-node4
04/03/2013 03:17:15;0001;PBS_Server;Svr;PBS_Server;LOG_ERROR::sync_node_jobs, stray job 21190.tyrone-cluster found on tyrone-node6
04/03/2013 03:17:17;0001;PBS_Server;Svr;PBS_Server;LOG_ERROR::sync_node_jobs, stray job 21306.tyrone-cluster found on tyrone-node5
04/03/2013 03:17:49;0001;PBS_Server;Svr;PBS_Server;LOG_ERROR::sync_node_jobs, stray job 21312.tyrone-cluster found on tyrone-node4
04/03/2013 03:18:01;0001;PBS_Server;Svr;PBS_Server;LOG_ERROR::sync_node_jobs, stray job 21190.tyrone-cluster found on tyrone-node6
04/03/2013 03:18:02;0001;PBS_Server;Svr;PBS_Server;LOG_ERROR::sync_node_jobs, stray job 21306.tyrone-cluster found on tyrone-node5
04/03/2013 03:18:30;0002;PBS_Server;Svr;PBS_Server;Torque Server Version = 3.0.5, loglevel = 0
04/03/2013 03:18:34;0001;PBS_Server;Svr;PBS_Server;LOG_ERROR::sync_node_jobs, stray job 21312.tyrone-cluster found on tyrone-node4
04/03/2013 03:18:46;0001;PBS_Server;Svr;PBS_Server;LOG_ERROR::sync_node_jobs, stray job 21190.tyrone-cluster found on tyrone-node6
04/03/2013 03:18:48;0001;PBS_Server;Svr;PBS_Server;LOG_ERROR::sync_node_jobs, stray job 21306.tyrone-cluster found on tyrone-node5
04/03/2013 03:19:19;0001;PBS_Server;Svr;PBS_Server;LOG_ERROR::sync_node_jobs, stray job 21312.tyrone-cluster found on tyrone-node4
04/03/2013 03:19:31;0001;PBS_Server;Svr;PBS_Server;LOG_ERROR::sync_node_jobs, stray job 21190.tyrone-cluster found on tyrone-node6
04/03/2013 03:19:33;0001;PBS_Server;Svr;PBS_Server;LOG_ERROR::sync_node_jobs, stray job 21306.tyrone-cluster found on tyrone-node5
04/03/2013 03:20:04;0001;PBS_Server;Svr;PBS_Server;LOG_ERROR::sync_node_jobs, stray job 21312.tyrone-cluster found on tyrone-node4
04/03/2013 03:20:16;0001;PBS_Server;Svr;PBS_Server;LOG_ERROR::sync_node_jobs, stray job 21190.tyrone-cluster found on tyrone-node6
04/03/2013 03:20:18;0001;PBS_Server;Svr;PBS_Server;LOG_ERROR::sync_node_jobs, stray job 21306.tyrone-cluster found on tyrone-node5
04/03/2013 03:20:33;0100;PBS_Server;Job;21330.tyrone-cluster;enqueuing into batch, state 1 hop 1
04/03/2013 03:20:33;0100;PBS_Server;Job;21330.tyrone-cluster;dequeuing from batch, state QUEUED
04/03/2013 03:20:33;0100;PBS_Server;Job;21330.tyrone-cluster;enqueuing into qp32, state 1 hop 1
04/03/2013 03:20:33;0008;PBS_Server;Job;21330.tyrone-cluster;Job Queued at request of secvkm@tyrone-cluster, owner = secvkm@tyrone-cluster, job name = myjob, queue = qp32
04/03/2013 03:20:33;0040;PBS_Server;Svr;tyrone-cluster;Scheduler was sent the command new
04/03/2013 03:20:33;0008;PBS_Server;Job;21330.tyrone-cluster;Job Modified at request of Scheduler@tyrone-cluster
04/03/2013 03:20:33;0008;PBS_Server;Job;21330.tyrone-cluster;Job Run at request of Scheduler@tyrone-cluster
04/03/2013 03:20:33;0040;PBS_Server;Svr;tyrone-cluster;Scheduler was sent the command recyc
04/03/2013 03:20:33;000d;PBS_Server;Job;21330.tyrone-cluster;Not sending email: User does not want mail of this type.
04/03/2013 03:20:38;000d;PBS_Server;Job;21330.tyrone-cluster;Not sending email: User does not want mail of this type.
04/03/2013 03:20:38;0010;PBS_Server;Job;21330.tyrone-cluster;Exit_status=0 resources_used.cput=00:02:07 resources_used.mem=0kb resources_used.vmem=0kb resources_used.walltime=00:00:05
04/03/2013 03:20:38;0008;PBS_Server;Job;NULL;on_job_exit valid pjob: 0x2063e10 (substate=50)
04/03/2013 03:20:38;0008;PBS_Server;Job;NULL;on_job_exit valid pjob: 0x2063e10 (substate=51)
04/03/2013 03:20:38;0008;PBS_Server;Job;NULL;on_job_exit valid pjob: 0x2063e10 (substate=51)
04/03/2013 03:20:38;0008;PBS_Server;Job;NULL;on_job_exit valid pjob: 0x2063e10 (substate=53)
04/03/2013 03:20:38;0100;PBS_Server;Job;21330.tyrone-cluster;dequeuing from qp32, state COMPLETE
04/03/2013 03:20:38;0040;PBS_Server;Svr;tyrone-cluster;Scheduler was sent the command term
04/03/2013 03:20:49;0001;PBS_Server;Svr;PBS_Server;LOG_ERROR::sync_node_jobs, stray job 21312.tyrone-cluster found on tyrone-node4
04/03/2013 03:21:00;0001;PBS_Server;Svr;PBS_Server;LOG_ERROR::sync_node_jobs, stray job 21190.tyrone-cluster found on tyrone-node6
04/03/2013 03:21:02;0001;PBS_Server;Svr;PBS_Server;LOG_ERROR::sync_node_jobs, stray job 21306.tyrone-cluster found on tyrone-node5
04/03/2013 03:21:34;0001;PBS_Server;Svr;PBS_Server;LOG_ERROR::sync_node_jobs, stray job 21312.tyrone-cluster found on tyrone-node4
04/03/2013 03:21:46;0001;PBS_Server;Svr;PBS_Server;LOG_ERROR::sync_node_jobs, stray job 21190.tyrone-cluster found on tyrone-node6
04/03/2013 03:21:47;0001;PBS_Server;Svr;PBS_Server;LOG_ERROR::sync_node_jobs, stray job 21306.tyrone-cluster found on tyrone-node5
04/03/2013 03:22:19;0001;PBS_Server;Svr;PBS_Server;LOG_ERROR::sync_node_jobs, stray job 21312.tyrone-cluster found on tyrone-node4
04/03/2013 03:22:31;0001;PBS_Server;Svr;PBS_Server;LOG_ERROR::sync_node_jobs, stray job 21190.tyrone-cluster found on tyrone-node6
04/03/2013 03:22:33;0001;PBS_Server;Svr;PBS_Server;LOG_ERROR::sync_node_jobs, stray job 21306.tyrone-cluster found on tyrone-node5
04/03/2013 03:22:43;000d;PBS_Server;Job;21196.tyrone-cluster;Not sending email: User does not want mail of this type.
04/03/2013 03:22:43;0010;PBS_Server;Job;21196.tyrone-cluster;Exit_status=1 resources_used.cput=179:30:32 resources_used.mem=13031076kb resources_used.vmem=46298356kb resources_used.walltime=14:04:54
04/03/2013 03:22:43;0008;PBS_Server;Job;NULL;on_job_exit valid pjob: 0x2062480 (substate=50)
04/03/2013 03:22:43;0008;PBS_Server;Job;NULL;on_job_exit valid pjob: 0x2062480 (substate=51)
04/03/2013 03:22:44;0008;PBS_Server;Job;NULL;on_job_exit valid pjob: 0x2062480 (substate=51)
04/03/2013 03:22:44;0008;PBS_Server;Job;NULL;on_job_exit valid pjob: 0x2062480 (substate=53)
04/03/2013 03:22:44;0100;PBS_Server;Job;21196.tyrone-cluster;dequeuing from qp64, state COMPLETE
04/03/2013 03:22:44;0040;PBS_Server;Svr;tyrone-cluster;Scheduler was sent the command term
04/03/2013 03:23:04;0001;PBS_Server;Svr;PBS_Server;LOG_ERROR::sync_node_jobs, stray job 21312.tyrone-cluster found on tyrone-node4
04/03/2013 03:23:16;0001;PBS_Server;Svr;PBS_Server;LOG_ERROR::sync_node_jobs, stray job 21190.tyrone-cluster found on tyrone-node6
04/03/2013 03:23:18;0001;PBS_Server;Svr;PBS_Server;LOG_ERROR::sync_node_jobs, stray job 21306.tyrone-cluster found on tyrone-node5
04/03/2013 03:23:30;0002;PBS_Server;Svr;PBS_Server;Torque Server Version = 3.0.5, loglevel = 0
04/03/2013 03:23:49;0001;PBS_Server;Svr;PBS_Server;LOG_ERROR::sync_node_jobs, stray job 21312.tyrone-cluster found on tyrone-node4
04/03/2013 03:24:00;0001;PBS_Server;Svr;PBS_Server;LOG_ERROR::sync_node_jobs, stray job 21190.tyrone-cluster found on tyrone-node6
04/03/2013 03:24:03;0001;PBS_Server;Svr;PBS_Server;LOG_ERROR::sync_node_jobs, stray job 21306.tyrone-cluster found on tyrone-node5
04/03/2013 03:24:34;0001;PBS_Server;Svr;PBS_Server;LOG_ERROR::sync_node_jobs, stray job 21312.tyrone-cluster found on tyrone-node4
04/03/2013 03:24:45;0001;PBS_Server;Svr;PBS_Server;LOG_ERROR::sync_node_jobs, stray job 21190.tyrone-cluster found on tyrone-node6
04/03/2013 03:24:48;0001;PBS_Server;Svr;PBS_Server;LOG_ERROR::sync_node_jobs, stray job 21306.tyrone-cluster found on tyrone-node5
04/03/2013 03:25:19;0001;PBS_Server;Svr;PBS_Server;LOG_ERROR::sync_node_jobs, stray job 21312.tyrone-cluster found on tyrone-node4
04/03/2013 03:25:30;0001;PBS_Server;Svr;PBS_Server;LOG_ERROR::sync_node_jobs, stray job 21190.tyrone-cluster found on tyrone-node6
04/03/2013 03:25:33;0001;PBS_Server;Svr;PBS_Server;LOG_ERROR::sync_node_jobs, stray job 21306.tyrone-cluster found on tyrone-node5
04/03/2013 03:26:04;0001;PBS_Server;Svr;PBS_Server;LOG_ERROR::sync_node_jobs, stray job 21312.tyrone-cluster found on tyrone-node4
04/03/2013 03:26:15;0001;PBS_Server;Svr;PBS_Server;LOG_ERROR::sync_node_jobs, stray job 21190.tyrone-cluster found on tyrone-node6
04/03/2013 03:26:18;0001;PBS_Server;Svr;PBS_Server;LOG_ERROR::sync_node_jobs, stray job 21306.tyrone-cluster found on tyrone-node5
04/03/2013 03:26:49;0001;PBS_Server;Svr;PBS_Server;LOG_ERROR::sync_node_jobs, stray job 21312.tyrone-cluster found on tyrone-node4
04/03/2013 03:27:00;0001;PBS_Server;Svr;PBS_Server;LOG_ERROR::sync_node_jobs, stray job 21190.tyrone-cluster found on tyrone-node6
04/03/2013 03:27:03;0001;PBS_Server;Svr;PBS_Server;LOG_ERROR::sync_node_jobs, stray job 21306.tyrone-cluster found on tyrone-node5
04/03/2013 03:27:34;0001;PBS_Server;Svr;PBS_Server;LOG_ERROR::sync_node_jobs, stray job 21312.tyrone-cluster found on tyrone-node4
04/03/2013 03:27:45;0001;PBS_Server;Svr;PBS_Server;LOG_ERROR::sync_node_jobs, stray job 21190.tyrone-cluster found on tyrone-node6
04/03/2013 03:27:48;0001;PBS_Server;Svr;PBS_Server;LOG_ERROR::sync_node_jobs, stray job 21306.tyrone-cluster found on tyrone-node5
04/03/2013 03:28:19;0001;PBS_Server;Svr;PBS_Server;LOG_ERROR::sync_node_jobs, stray job 21312.tyrone-cluster found on tyrone-node4
04/03/2013 03:28:30;0001;PBS_Server;Svr;PBS_Server;LOG_ERROR::sync_node_jobs, stray job 21190.tyrone-cluster found on tyrone-node6
04/03/2013 03:28:30;0002;PBS_Server;Svr;PBS_Server;Torque Server Version = 3.0.5, loglevel = 0
04/03/2013 03:28:33;0001;PBS_Server;Svr;PBS_Server;LOG_ERROR::sync_node_jobs, stray job 21306.tyrone-cluster found on tyrone-node5
04/03/2013 03:29:04;0001;PBS_Server;Svr;PBS_Server;LOG_ERROR::sync_node_jobs, stray job 21312.tyrone-cluster found on tyrone-node4
04/03/2013 03:29:15;0001;PBS_Server;Svr;PBS_Server;LOG_ERROR::sync_node_jobs, stray job 21190.tyrone-cluster found on tyrone-node6
04/03/2013 03:29:18;0001;PBS_Server;Svr;PBS_Server;LOG_ERROR::sync_node_jobs, stray job 21306.tyrone-cluster found on tyrone-node5
04/03/2013 03:29:49;0001;PBS_Server;Svr;PBS_Server;LOG_ERROR::sync_node_jobs, stray job 21312.tyrone-cluster found on tyrone-node4
04/03/2013 03:30:00;0001;PBS_Server;Svr;PBS_Server;LOG_ERROR::sync_node_jobs, stray job 21190.tyrone-cluster found on tyrone-node6
04/03/2013 03:30:03;0001;PBS_Server;Svr;PBS_Server;LOG_ERROR::sync_node_jobs, stray job 21306.tyrone-cluster found on tyrone-node5
04/03/2013 03:30:34;0001;PBS_Server;Svr;PBS_Server;LOG_ERROR::sync_node_jobs, stray job 21312.tyrone-cluster found on tyrone-node4
04/03/2013 03:30:45;0001;PBS_Server;Svr;PBS_Server;LOG_ERROR::sync_node_jobs, stray job 21190.tyrone-cluster found on tyrone-node6
04/03/2013 03:30:48;0001;PBS_Server;Svr;PBS_Server;LOG_ERROR::sync_node_jobs, stray job 21306.tyrone-cluster found on tyrone-node5
04/03/2013 03:31:19;0001;PBS_Server;Svr;PBS_Server;LOG_ERROR::sync_node_jobs, stray job 21312.tyrone-cluster found on tyrone-node4
04/03/2013 03:31:30;0001;PBS_Server;Svr;PBS_Server;LOG_ERROR::sync_node_jobs, stray job 21190.tyrone-cluster found on tyrone-node6
04/03/2013 03:31:33;0001;PBS_Server;Svr;PBS_Server;LOG_ERROR::sync_node_jobs, stray job 21306.tyrone-cluster found on tyrone-node5
04/03/2013 03:32:03;0001;PBS_Server;Svr;PBS_Server;LOG_ERROR::sync_node_jobs, stray job 21312.tyrone-cluster found on tyrone-node4
04/03/2013 03:32:15;0001;PBS_Server;Svr;PBS_Server;LOG_ERROR::sync_node_jobs, stray job 21190.tyrone-cluster found on tyrone-node6
04/03/2013 03:32:17;0001;PBS_Server;Svr;PBS_Server;LOG_ERROR::sync_node_jobs, stray job 21306.tyrone-cluster found on tyrone-node5
04/03/2013 03:32:44;0040;PBS_Server;Svr;tyrone-cluster;Scheduler was sent the command time
04/03/2013 03:32:48;0001;PBS_Server;Svr;PBS_Server;LOG_ERROR::sync_node_jobs, stray job 21312.tyrone-cluster found on tyrone-node4
04/03/2013 03:33:00;0001;PBS_Server;Svr;PBS_Server;LOG_ERROR::sync_node_jobs, stray job 21190.tyrone-cluster found on tyrone-node6
04/03/2013 03:33:02;0001;PBS_Server;Svr;PBS_Server;LOG_ERROR::sync_node_jobs, stray job 21306.tyrone-cluster found on tyrone-node5
04/03/2013 03:33:30;0002;PBS_Server;Svr;PBS_Server;Torque Server Version = 3.0.5, loglevel = 0
04/03/2013 03:33:33;0001;PBS_Server;Svr;PBS_Server;LOG_ERROR::sync_node_jobs, stray job 21312.tyrone-cluster found on tyrone-node4
04/03/2013 03:33:45;0001;PBS_Server;Svr;PBS_Server;LOG_ERROR::sync_node_jobs, stray job 21190.tyrone-cluster found on tyrone-node6
04/03/2013 03:33:47;0001;PBS_Server;Svr;PBS_Server;LOG_ERROR::sync_node_jobs, stray job 21306.tyrone-cluster found on tyrone-node5
04/03/2013 03:34:18;0001;PBS_Server;Svr;PBS_Server;LOG_ERROR::sync_node_jobs, stray job 21312.tyrone-cluster found on tyrone-node4
04/03/2013 03:34:31;0001;PBS_Server;Svr;PBS_Server;LOG_ERROR::sync_node_jobs, stray job 21190.tyrone-cluster found on tyrone-node6
04/03/2013 03:34:32;0001;PBS_Server;Svr;PBS_Server;LOG_ERROR::sync_node_jobs, stray job 21306.tyrone-cluster found on tyrone-node5
04/03/2013 03:35:04;0001;PBS_Server;Svr;PBS_Server;LOG_ERROR::sync_node_jobs, stray job 21312.tyrone-cluster found on tyrone-node4
04/03/2013 03:35:16;0001;PBS_Server;Svr;PBS_Server;LOG_ERROR::sync_node_jobs, stray job 21190.tyrone-cluster found on tyrone-node6
04/03/2013 03:35:18;0001;PBS_Server;Svr;PBS_Server;LOG_ERROR::sync_node_jobs, stray job 21306.tyrone-cluster found on tyrone-node5
04/03/2013 03:35:49;0001;PBS_Server;Svr;PBS_Server;LOG_ERROR::sync_node_jobs, stray job 21312.tyrone-cluster found on tyrone-node4
04/03/2013 03:36:00;0001;PBS_Server;Svr;PBS_Server;LOG_ERROR::sync_node_jobs, stray job 21190.tyrone-cluster found on tyrone-node6
04/03/2013 03:36:03;0001;PBS_Server;Svr;PBS_Server;LOG_ERROR::sync_node_jobs, stray job 21306.tyrone-cluster found on tyrone-node5
04/03/2013 03:36:34;0001;PBS_Server;Svr;PBS_Server;LOG_ERROR::sync_node_jobs, stray job 21312.tyrone-cluster found on tyrone-node4
04/03/2013 03:36:45;0001;PBS_Server;Svr;PBS_Server;LOG_ERROR::sync_node_jobs, stray job 21190.tyrone-cluster found on tyrone-node6
04/03/2013 03:36:48;0001;PBS_Server;Svr;PBS_Server;LOG_ERROR::sync_node_jobs, stray job 21306.tyrone-cluster found on tyrone-node5
04/03/2013 03:37:19;0001;PBS_Server;Svr;PBS_Server;LOG_ERROR::sync_node_jobs, stray job 21312.tyrone-cluster found on tyrone-node4
04/03/2013 03:37:30;0001;PBS_Server;Svr;PBS_Server;LOG_ERROR::sync_node_jobs, stray job 21190.tyrone-cluster found on tyrone-node6
04/03/2013 03:37:33;0001;PBS_Server;Svr;PBS_Server;LOG_ERROR::sync_node_jobs, stray job 21306.tyrone-cluster found on tyrone-node5
04/03/2013 03:38:04;0001;PBS_Server;Svr;PBS_Server;LOG_ERROR::sync_node_jobs, stray job 21312.tyrone-cluster found on tyrone-node4
04/03/2013 03:38:15;0001;PBS_Server;Svr;PBS_Server;LOG_ERROR::sync_node_jobs, stray job 21190.tyrone-cluster found on tyrone-node6
04/03/2013 03:38:18;0001;PBS_Server;Svr;PBS_Server;LOG_ERROR::sync_node_jobs, stray job 21306.tyrone-cluster found on tyrone-node5
04/03/2013 03:38:30;0002;PBS_Server;Svr;PBS_Server;Torque Server Version = 3.0.5, loglevel = 0
04/03/2013 03:38:49;0001;PBS_Server;Svr;PBS_Server;LOG_ERROR::sync_node_jobs, stray job 21312.tyrone-cluster found on tyrone-node4
04/03/2013 03:39:00;0001;PBS_Server;Svr;PBS_Server;LOG_ERROR::sync_node_jobs, stray job 21190.tyrone-cluster found on tyrone-node6
04/03/2013 03:39:03;0001;PBS_Server;Svr;PBS_Server;LOG_ERROR::sync_node_jobs, stray job 21306.tyrone-cluster found on tyrone-node5
04/03/2013 03:39:34;0001;PBS_Server;Svr;PBS_Server;LOG_ERROR::sync_node_jobs, stray job 21312.tyrone-cluster found on tyrone-node4
04/03/2013 03:39:45;0001;PBS_Server;Svr;PBS_Server;LOG_ERROR::sync_node_jobs, stray job 21190.tyrone-cluster found on tyrone-node6
04/03/2013 03:39:48;0001;PBS_Server;Svr;PBS_Server;LOG_ERROR::sync_node_jobs, stray job 21306.tyrone-cluster found on tyrone-node5
04/03/2013 03:40:19;0001;PBS_Server;Svr;PBS_Server;LOG_ERROR::sync_node_jobs, stray job 21312.tyrone-cluster found on tyrone-node4
04/03/2013 03:40:30;0001;PBS_Server;Svr;PBS_Server;LOG_ERROR::sync_node_jobs, stray job 21190.tyrone-cluster found on tyrone-node6
04/03/2013 03:40:33;0001;PBS_Server;Svr;PBS_Server;LOG_ERROR::sync_node_jobs, stray job 21306.tyrone-cluster found on tyrone-node5
04/03/2013 03:41:04;0001;PBS_Server;Svr;PBS_Server;LOG_ERROR::sync_node_jobs, stray job 21312.tyrone-cluster found on tyrone-node4
04/03/2013 03:41:15;0001;PBS_Server;Svr;PBS_Server;LOG_ERROR::sync_node_jobs, stray job 21190.tyrone-cluster found on tyrone-node6
04/03/2013 03:41:18;0001;PBS_Server;Svr;PBS_Server;LOG_ERROR::sync_node_jobs, stray job 21306.tyrone-cluster found on tyrone-node5
04/03/2013 03:41:48;0001;PBS_Server;Svr;PBS_Server;LOG_ERROR::sync_node_jobs, stray job 21312.tyrone-cluster found on tyrone-node4
04/03/2013 03:42:00;0001;PBS_Server;Svr;PBS_Server;LOG_ERROR::sync_node_jobs, stray job 21190.tyrone-cluster found on tyrone-node6
04/03/2013 03:42:03;0001;PBS_Server;Svr;PBS_Server;LOG_ERROR::sync_node_jobs, stray job 21306.tyrone-cluster found on tyrone-node5
04/03/2013 03:42:33;0001;PBS_Server;Svr;PBS_Server;LOG_ERROR::sync_node_jobs, stray job 21312.tyrone-cluster found on tyrone-node4
04/03/2013 03:42:44;0040;PBS_Server;Svr;tyrone-cluster;Scheduler was sent the command time
04/03/2013 03:42:45;0001;PBS_Server;Svr;PBS_Server;LOG_ERROR::sync_node_jobs, stray job 21190.tyrone-cluster found on tyrone-node6
04/03/2013 03:42:48;0001;PBS_Server;Svr;PBS_Server;LOG_ERROR::sync_node_jobs, stray job 21306.tyrone-cluster found on tyrone-node5
04/03/2013 03:43:18;0001;PBS_Server;Svr;PBS_Server;LOG_ERROR::sync_node_jobs, stray job 21312.tyrone-cluster found on tyrone-node4
04/03/2013 03:43:30;0002;PBS_Server;Svr;PBS_Server;Torque Server Version = 3.0.5, loglevel = 0
04/03/2013 03:43:30;0001;PBS_Server;Svr;PBS_Server;LOG_ERROR::sync_node_jobs, stray job 21190.tyrone-cluster found on tyrone-node6
04/03/2013 03:43:33;0001;PBS_Server;Svr;PBS_Server;LOG_ERROR::sync_node_jobs, stray job 21306.tyrone-cluster found on tyrone-node5
04/03/2013 03:44:03;0001;PBS_Server;Svr;PBS_Server;LOG_ERROR::sync_node_jobs, stray job 21312.tyrone-cluster found on tyrone-node4
04/03/2013 03:44:15;0001;PBS_Server;Svr;PBS_Server;LOG_ERROR::sync_node_jobs, stray job 21190.tyrone-cluster found on tyrone-node6
04/03/2013 03:44:17;0001;PBS_Server;Svr;PBS_Server;LOG_ERROR::sync_node_jobs, stray job 21306.tyrone-cluster found on tyrone-node5
04/03/2013 03:44:48;0001;PBS_Server;Svr;PBS_Server;LOG_ERROR::sync_node_jobs, stray job 21312.tyrone-cluster found on tyrone-node4
04/03/2013 03:45:00;0001;PBS_Server;Svr;PBS_Server;LOG_ERROR::sync_node_jobs, stray job 21190.tyrone-cluster found on tyrone-node6
04/03/2013 03:45:02;0001;PBS_Server;Svr;PBS_Server;LOG_ERROR::sync_node_jobs, stray job 21306.tyrone-cluster found on tyrone-node5
04/03/2013 03:45:33;0001;PBS_Server;Svr;PBS_Server;LOG_ERROR::sync_node_jobs, stray job 21312.tyrone-cluster found on tyrone-node4
04/03/2013 03:45:45;0001;PBS_Server;Svr;PBS_Server;LOG_ERROR::sync_node_jobs, stray job 21190.tyrone-cluster found on tyrone-node6
04/03/2013 03:45:47;0001;PBS_Server;Svr;PBS_Server;LOG_ERROR::sync_node_jobs, stray job 21306.tyrone-cluster found on tyrone-node5
04/03/2013 03:46:18;0001;PBS_Server;Svr;PBS_Server;LOG_ERROR::sync_node_jobs, stray job 21312.tyrone-cluster found on tyrone-node4
04/03/2013 03:46:30;0001;PBS_Server;Svr;PBS_Server;LOG_ERROR::sync_node_jobs, stray job 21190.tyrone-cluster found on tyrone-node6
04/03/2013 03:46:32;0001;PBS_Server;Svr;PBS_Server;LOG_ERROR::sync_node_jobs, stray job 21306.tyrone-cluster found on tyrone-node5
04/03/2013 03:47:03;0001;PBS_Server;Svr;PBS_Server;LOG_ERROR::sync_node_jobs, stray job 21312.tyrone-cluster found on tyrone-node4
04/03/2013 03:47:16;0001;PBS_Server;Svr;PBS_Server;LOG_ERROR::sync_node_jobs, stray job 21190.tyrone-cluster found on tyrone-node6
04/03/2013 03:47:17;0001;PBS_Server;Svr;PBS_Server;LOG_ERROR::sync_node_jobs, stray job 21306.tyrone-cluster found on tyrone-node5
04/03/2013 03:47:49;0001;PBS_Server;Svr;PBS_Server;LOG_ERROR::sync_node_jobs, stray job 21312.tyrone-cluster found on tyrone-node4
04/03/2013 03:48:00;0001;PBS_Server;Svr;PBS_Server;LOG_ERROR::sync_node_jobs, stray job 21190.tyrone-cluster found on tyrone-node6
04/03/2013 03:48:03;0001;PBS_Server;Svr;PBS_Server;LOG_ERROR::sync_node_jobs, stray job 21306.tyrone-cluster found on tyrone-node5
04/03/2013 03:48:30;0002;PBS_Server;Svr;PBS_Server;Torque Server Version = 3.0.5, loglevel = 0
04/03/2013 03:48:34;0001;PBS_Server;Svr;PBS_Server;LOG_ERROR::sync_node_jobs, stray job 21312.tyrone-cluster found on tyrone-node4
04/03/2013 03:48:45;0001;PBS_Server;Svr;PBS_Server;LOG_ERROR::sync_node_jobs, stray job 21190.tyrone-cluster found on tyrone-node6
04/03/2013 03:48:48;0001;PBS_Server;Svr;PBS_Server;LOG_ERROR::sync_node_jobs, stray job 21306.tyrone-cluster found on tyrone-node5
04/03/2013 03:49:19;0001;PBS_Server;Svr;PBS_Server;LOG_ERROR::sync_node_jobs, stray job 21312.tyrone-cluster found on tyrone-node4
04/03/2013 03:49:30;0001;PBS_Server;Svr;PBS_Server;LOG_ERROR::sync_node_jobs, stray job 21190.tyrone-cluster found on tyrone-node6
04/03/2013 03:49:33;0001;PBS_Server;Svr;PBS_Server;LOG_ERROR::sync_node_jobs, stray job 21306.tyrone-cluster found on tyrone-node5
04/03/2013 03:50:04;0001;PBS_Server;Svr;PBS_Server;LOG_ERROR::sync_node_jobs, stray job 21312.tyrone-cluster found on tyrone-node4
04/03/2013 03:50:15;0001;PBS_Server;Svr;PBS_Server;LOG_ERROR::sync_node_jobs, stray job 21190.tyrone-cluster found on tyrone-node6
04/03/2013 03:50:18;0001;PBS_Server;Svr;PBS_Server;LOG_ERROR::sync_node_jobs, stray job 21306.tyrone-cluster found on tyrone-node5
04/03/2013 03:50:49;0001;PBS_Server;Svr;PBS_Server;LOG_ERROR::sync_node_jobs, stray job 21312.tyrone-cluster found on tyrone-node4
04/03/2013 03:51:00;0001;PBS_Server;Svr;PBS_Server;LOG_ERROR::sync_node_jobs, stray job 21190.tyrone-cluster found on tyrone-node6
04/03/2013 03:51:03;0001;PBS_Server;Svr;PBS_Server;LOG_ERROR::sync_node_jobs, stray job 21306.tyrone-cluster found on tyrone-node5
04/03/2013 03:51:34;0001;PBS_Server;Svr;PBS_Server;LOG_ERROR::sync_node_jobs, stray job 21312.tyrone-cluster found on tyrone-node4
04/03/2013 03:51:45;0001;PBS_Server;Svr;PBS_Server;LOG_ERROR::sync_node_jobs, stray job 21190.tyrone-cluster found on tyrone-node6
04/03/2013 03:51:48;0001;PBS_Server;Svr;PBS_Server;LOG_ERROR::sync_node_jobs, stray job 21306.tyrone-cluster found on tyrone-node5
04/03/2013 03:52:18;0001;PBS_Server;Svr;PBS_Server;LOG_ERROR::sync_node_jobs, stray job 21312.tyrone-cluster found on tyrone-node4
04/03/2013 03:52:30;0001;PBS_Server;Svr;PBS_Server;LOG_ERROR::sync_node_jobs, stray job 21190.tyrone-cluster found on tyrone-node6
04/03/2013 03:52:33;0001;PBS_Server;Svr;PBS_Server;LOG_ERROR::sync_node_jobs, stray job 21306.tyrone-cluster found on tyrone-node5
04/03/2013 03:52:44;0040;PBS_Server;Svr;tyrone-cluster;Scheduler was sent the command time
04/03/2013 03:53:03;0001;PBS_Server;Svr;PBS_Server;LOG_ERROR::sync_node_jobs, stray job 21312.tyrone-cluster found on tyrone-node4
04/03/2013 03:53:15;0001;PBS_Server;Svr;PBS_Server;LOG_ERROR::sync_node_jobs, stray job 21190.tyrone-cluster found on tyrone-node6
04/03/2013 03:53:18;0001;PBS_Server;Svr;PBS_Server;LOG_ERROR::sync_node_jobs, stray job 21306.tyrone-cluster found on tyrone-node5
04/03/2013 03:53:30;0002;PBS_Server;Svr;PBS_Server;Torque Server Version = 3.0.5, loglevel = 0
04/03/2013 03:53:48;0001;PBS_Server;Svr;PBS_Server;LOG_ERROR::sync_node_jobs, stray job 21312.tyrone-cluster found on tyrone-node4
04/03/2013 03:54:00;0001;PBS_Server;Svr;PBS_Server;LOG_ERROR::sync_node_jobs, stray job 21190.tyrone-cluster found on tyrone-node6
04/03/2013 03:54:03;0001;PBS_Server;Svr;PBS_Server;LOG_ERROR::sync_node_jobs, stray job 21306.tyrone-cluster found on tyrone-node5
04/03/2013 03:54:33;0001;PBS_Server;Svr;PBS_Server;LOG_ERROR::sync_node_jobs, stray job 21312.tyrone-cluster found on tyrone-node4
04/03/2013 03:54:45;0001;PBS_Server;Svr;PBS_Server;LOG_ERROR::sync_node_jobs, stray job 21190.tyrone-cluster found on tyrone-node6
04/03/2013 03:54:48;0001;PBS_Server;Svr;PBS_Server;LOG_ERROR::sync_node_jobs, stray job 21306.tyrone-cluster found on tyrone-node5
04/03/2013 03:55:18;0001;PBS_Server;Svr;PBS_Server;LOG_ERROR::sync_node_jobs, stray job 21312.tyrone-cluster found on tyrone-node4
04/03/2013 03:55:30;0001;PBS_Server;Svr;PBS_Server;LOG_ERROR::sync_node_jobs, stray job 21190.tyrone-cluster found on tyrone-node6
04/03/2013 03:55:33;0001;PBS_Server;Svr;PBS_Server;LOG_ERROR::sync_node_jobs, stray job 21306.tyrone-cluster found on tyrone-node5
04/03/2013 03:56:03;0001;PBS_Server;Svr;PBS_Server;LOG_ERROR::sync_node_jobs, stray job 21312.tyrone-cluster found on tyrone-node4
04/03/2013 03:56:15;0001;PBS_Server;Svr;PBS_Server;LOG_ERROR::sync_node_jobs, stray job 21190.tyrone-cluster found on tyrone-node6
04/03/2013 03:56:18;0001;PBS_Server;Svr;PBS_Server;LOG_ERROR::sync_node_jobs, stray job 21306.tyrone-cluster found on tyrone-node5
04/03/2013 03:56:48;0001;PBS_Server;Svr;PBS_Server;LOG_ERROR::sync_node_jobs, stray job 21312.tyrone-cluster found on tyrone-node4
04/03/2013 03:57:00;0001;PBS_Server;Svr;PBS_Server;LOG_ERROR::sync_node_jobs, stray job 21190.tyrone-cluster found on tyrone-node6
04/03/2013 03:57:02;0001;PBS_Server;Svr;PBS_Server;LOG_ERROR::sync_node_jobs, stray job 21306.tyrone-cluster found on tyrone-node5
04/03/2013 03:57:33;0001;PBS_Server;Svr;PBS_Server;LOG_ERROR::sync_node_jobs, stray job 21312.tyrone-cluster found on tyrone-node4
04/03/2013 03:57:45;0001;PBS_Server;Svr;PBS_Server;LOG_ERROR::sync_node_jobs, stray job 21190.tyrone-cluster found on tyrone-node6
04/03/2013 03:57:47;0001;PBS_Server;Svr;PBS_Server;LOG_ERROR::sync_node_jobs, stray job 21306.tyrone-cluster found on tyrone-node5
04/03/2013 03:58:18;0001;PBS_Server;Svr;PBS_Server;LOG_ERROR::sync_node_jobs, stray job 21312.tyrone-cluster found on tyrone-node4
04/03/2013 03:58:30;0001;PBS_Server;Svr;PBS_Server;LOG_ERROR::sync_node_jobs, stray job 21190.tyrone-cluster found on tyrone-node6
04/03/2013 03:58:30;0002;PBS_Server;Svr;PBS_Server;Torque Server Version = 3.0.5, loglevel = 0
04/03/2013 03:58:32;0001;PBS_Server;Svr;PBS_Server;LOG_ERROR::sync_node_jobs, stray job 21306.tyrone-cluster found on tyrone-node5
04/03/2013 03:59:04;0001;PBS_Server;Svr;PBS_Server;LOG_ERROR::sync_node_jobs, stray job 21312.tyrone-cluster found on tyrone-node4
04/03/2013 03:59:15;0001;PBS_Server;Svr;PBS_Server;LOG_ERROR::sync_node_jobs, stray job 21190.tyrone-cluster found on tyrone-node6
04/03/2013 03:59:17;0001;PBS_Server;Svr;PBS_Server;LOG_ERROR::sync_node_jobs, stray job 21306.tyrone-cluster found on tyrone-node5
04/03/2013 03:59:49;0001;PBS_Server;Svr;PBS_Server;LOG_ERROR::sync_node_jobs, stray job 21312.tyrone-cluster found on tyrone-node4
04/03/2013 04:00:00;0001;PBS_Server;Svr;PBS_Server;LOG_ERROR::sync_node_jobs, stray job 21190.tyrone-cluster found on tyrone-node6
04/03/2013 04:00:03;0001;PBS_Server;Svr;PBS_Server;LOG_ERROR::sync_node_jobs, stray job 21306.tyrone-cluster found on tyrone-node5
04/03/2013 04:00:34;0001;PBS_Server;Svr;PBS_Server;LOG_ERROR::sync_node_jobs, stray job 21312.tyrone-cluster found on tyrone-node4
04/03/2013 04:00:45;0001;PBS_Server;Svr;PBS_Server;LOG_ERROR::sync_node_jobs, stray job 21190.tyrone-cluster found on tyrone-node6
04/03/2013 04:00:48;0001;PBS_Server;Svr;PBS_Server;LOG_ERROR::sync_node_jobs, stray job 21306.tyrone-cluster found on tyrone-node5
04/03/2013 04:01:19;0001;PBS_Server;Svr;PBS_Server;LOG_ERROR::sync_node_jobs, stray job 21312.tyrone-cluster found on tyrone-node4
04/03/2013 04:01:30;0001;PBS_Server;Svr;PBS_Server;LOG_ERROR::sync_node_jobs, stray job 21190.tyrone-cluster found on tyrone-node6
04/03/2013 04:01:33;0001;PBS_Server;Svr;PBS_Server;LOG_ERROR::sync_node_jobs, stray job 21306.tyrone-cluster found on tyrone-node5
04/03/2013 04:02:03;0001;PBS_Server;Svr;PBS_Server;LOG_ERROR::sync_node_jobs, stray job 21312.tyrone-cluster found on tyrone-node4
04/03/2013 04:02:15;0001;PBS_Server;Svr;PBS_Server;LOG_ERROR::sync_node_jobs, stray job 21190.tyrone-cluster found on tyrone-node6
04/03/2013 04:02:18;0001;PBS_Server;Svr;PBS_Server;LOG_ERROR::sync_node_jobs, stray job 21306.tyrone-cluster found on tyrone-node5
04/03/2013 04:02:44;0040;PBS_Server;Svr;tyrone-cluster;Scheduler was sent the command time
04/03/2013 04:02:48;0001;PBS_Server;Svr;PBS_Server;LOG_ERROR::sync_node_jobs, stray job 21312.tyrone-cluster found on tyrone-node4
04/03/2013 04:03:00;0001;PBS_Server;Svr;PBS_Server;LOG_ERROR::sync_node_jobs, stray job 21190.tyrone-cluster found on tyrone-node6
04/03/2013 04:03:03;0001;PBS_Server;Svr;PBS_Server;LOG_ERROR::sync_node_jobs, stray job 21306.tyrone-cluster found on tyrone-node5
04/03/2013 04:03:30;0002;PBS_Server;Svr;PBS_Server;Torque Server Version = 3.0.5, loglevel = 0
04/03/2013 04:03:33;0001;PBS_Server;Svr;PBS_Server;LOG_ERROR::sync_node_jobs, stray job 21312.tyrone-cluster found on tyrone-node4
04/03/2013 04:03:45;0001;PBS_Server;Svr;PBS_Server;LOG_ERROR::sync_node_jobs, stray job 21190.tyrone-cluster found on tyrone-node6
04/03/2013 04:03:48;0001;PBS_Server;Svr;PBS_Server;LOG_ERROR::sync_node_jobs, stray job 21306.tyrone-cluster found on tyrone-node5
04/03/2013 04:04:18;0001;PBS_Server;Svr;PBS_Server;LOG_ERROR::sync_node_jobs, stray job 21312.tyrone-cluster found on tyrone-node4
04/03/2013 04:04:30;0001;PBS_Server;Svr;PBS_Server;LOG_ERROR::sync_node_jobs, stray job 21190.tyrone-cluster found on tyrone-node6
04/03/2013 04:04:33;0001;PBS_Server;Svr;PBS_Server;LOG_ERROR::sync_node_jobs, stray job 21306.tyrone-cluster found on tyrone-node5
04/03/2013 04:05:03;0001;PBS_Server;Svr;PBS_Server;LOG_ERROR::sync_node_jobs, stray job 21312.tyrone-cluster found on tyrone-node4
04/03/2013 04:05:15;0001;PBS_Server;Svr;PBS_Server;LOG_ERROR::sync_node_jobs, stray job 21190.tyrone-cluster found on tyrone-node6
04/03/2013 04:05:18;0001;PBS_Server;Svr;PBS_Server;LOG_ERROR::sync_node_jobs, stray job 21306.tyrone-cluster found on tyrone-node5
04/03/2013 04:05:48;0001;PBS_Server;Svr;PBS_Server;LOG_ERROR::sync_node_jobs, stray job 21312.tyrone-cluster found on tyrone-node4
04/03/2013 04:06:00;0001;PBS_Server;Svr;PBS_Server;LOG_ERROR::sync_node_jobs, stray job 21190.tyrone-cluster found on tyrone-node6
04/03/2013 04:06:03;0001;PBS_Server;Svr;PBS_Server;LOG_ERROR::sync_node_jobs, stray job 21306.tyrone-cluster found on tyrone-node5
04/03/2013 04:06:33;0001;PBS_Server;Svr;PBS_Server;LOG_ERROR::sync_node_jobs, stray job 21312.tyrone-cluster found on tyrone-node4
04/03/2013 04:06:45;0001;PBS_Server;Svr;PBS_Server;LOG_ERROR::sync_node_jobs, stray job 21190.tyrone-cluster found on tyrone-node6
04/03/2013 04:06:48;0001;PBS_Server;Svr;PBS_Server;LOG_ERROR::sync_node_jobs, stray job 21306.tyrone-cluster found on tyrone-node5
04/03/2013 04:07:18;0001;PBS_Server;Svr;PBS_Server;LOG_ERROR::sync_node_jobs, stray job 21312.tyrone-cluster found on tyrone-node4
04/03/2013 04:07:30;0001;PBS_Server;Svr;PBS_Server;LOG_ERROR::sync_node_jobs, stray job 21190.tyrone-cluster found on tyrone-node6
04/03/2013 04:07:33;0001;PBS_Server;Svr;PBS_Server;LOG_ERROR::sync_node_jobs, stray job 21306.tyrone-cluster found on tyrone-node5
04/03/2013 04:08:03;0001;PBS_Server;Svr;PBS_Server;LOG_ERROR::sync_node_jobs, stray job 21312.tyrone-cluster found on tyrone-node4
04/03/2013 04:08:15;0001;PBS_Server;Svr;PBS_Server;LOG_ERROR::sync_node_jobs, stray job 21190.tyrone-cluster found on tyrone-node6
04/03/2013 04:08:18;0001;PBS_Server;Svr;PBS_Server;LOG_ERROR::sync_node_jobs, stray job 21306.tyrone-cluster found on tyrone-node5
04/03/2013 04:08:30;0002;PBS_Server;Svr;PBS_Server;Torque Server Version = 3.0.5, loglevel = 0
04/03/2013 04:08:48;0001;PBS_Server;Svr;PBS_Server;LOG_ERROR::sync_node_jobs, stray job 21312.tyrone-cluster found on tyrone-node4
04/03/2013 04:09:00;0001;PBS_Server;Svr;PBS_Server;LOG_ERROR::sync_node_jobs, stray job 21190.tyrone-cluster found on tyrone-node6
04/03/2013 04:09:02;0001;PBS_Server;Svr;PBS_Server;LOG_ERROR::sync_node_jobs, stray job 21306.tyrone-cluster found on tyrone-node5
04/03/2013 04:09:33;0001;PBS_Server;Svr;PBS_Server;LOG_ERROR::sync_node_jobs, stray job 21312.tyrone-cluster found on tyrone-node4
04/03/2013 04:09:45;0001;PBS_Server;Svr;PBS_Server;LOG_ERROR::sync_node_jobs, stray job 21190.tyrone-cluster found on tyrone-node6
04/03/2013 04:09:47;0001;PBS_Server;Svr;PBS_Server;LOG_ERROR::sync_node_jobs, stray job 21306.tyrone-cluster found on tyrone-node5
04/03/2013 04:10:18;0001;PBS_Server;Svr;PBS_Server;LOG_ERROR::sync_node_jobs, stray job 21312.tyrone-cluster found on tyrone-node4
04/03/2013 04:10:30;0001;PBS_Server;Svr;PBS_Server;LOG_ERROR::sync_node_jobs, stray job 21190.tyrone-cluster found on tyrone-node6
04/03/2013 04:10:32;0001;PBS_Server;Svr;PBS_Server;LOG_ERROR::sync_node_jobs, stray job 21306.tyrone-cluster found on tyrone-node5
04/03/2013 04:11:02;0001;PBS_Server;Svr;PBS_Server;LOG_ERROR::sync_node_jobs, stray job 21312.tyrone-cluster found on tyrone-node4
04/03/2013 04:11:14;0001;PBS_Server;Svr;PBS_Server;LOG_ERROR::sync_node_jobs, stray job 21190.tyrone-cluster found on tyrone-node6
04/03/2013 04:11:17;0001;PBS_Server;Svr;PBS_Server;LOG_ERROR::sync_node_jobs, stray job 21306.tyrone-cluster found on tyrone-node5
04/03/2013 04:11:48;0001;PBS_Server;Svr;PBS_Server;LOG_ERROR::sync_node_jobs, stray job 21312.tyrone-cluster found on tyrone-node4
04/03/2013 04:11:59;0001;PBS_Server;Svr;PBS_Server;LOG_ERROR::sync_node_jobs, stray job 21190.tyrone-cluster found on tyrone-node6
04/03/2013 04:12:02;0001;PBS_Server;Svr;PBS_Server;LOG_ERROR::sync_node_jobs, stray job 21306.tyrone-cluster found on tyrone-node5
04/03/2013 04:12:33;0001;PBS_Server;Svr;PBS_Server;LOG_ERROR::sync_node_jobs, stray job 21312.tyrone-cluster found on tyrone-node4
04/03/2013 04:12:44;0040;PBS_Server;Svr;tyrone-cluster;Scheduler was sent the command time
04/03/2013 04:12:45;0001;PBS_Server;Svr;PBS_Server;LOG_ERROR::sync_node_jobs, stray job 21190.tyrone-cluster found on tyrone-node6
04/03/2013 04:12:48;0001;PBS_Server;Svr;PBS_Server;LOG_ERROR::sync_node_jobs, stray job 21306.tyrone-cluster found on tyrone-node5
04/03/2013 04:13:18;0001;PBS_Server;Svr;PBS_Server;LOG_ERROR::sync_node_jobs, stray job 21312.tyrone-cluster found on tyrone-node4
04/03/2013 04:13:30;0001;PBS_Server;Svr;PBS_Server;LOG_ERROR::sync_node_jobs, stray job 21190.tyrone-cluster found on tyrone-node6
04/03/2013 04:13:30;0002;PBS_Server;Svr;PBS_Server;Torque Server Version = 3.0.5, loglevel = 0
04/03/2013 04:13:33;0001;PBS_Server;Svr;PBS_Server;LOG_ERROR::sync_node_jobs, stray job 21306.tyrone-cluster found on tyrone-node5
04/03/2013 04:14:03;0001;PBS_Server;Svr;PBS_Server;LOG_ERROR::sync_node_jobs, stray job 21312.tyrone-cluster found on tyrone-node4
04/03/2013 04:14:15;0001;PBS_Server;Svr;PBS_Server;LOG_ERROR::sync_node_jobs, stray job 21190.tyrone-cluster found on tyrone-node6
04/03/2013 04:14:18;0001;PBS_Server;Svr;PBS_Server;LOG_ERROR::sync_node_jobs, stray job 21306.tyrone-cluster found on tyrone-node5
04/03/2013 04:14:48;0001;PBS_Server;Svr;PBS_Server;LOG_ERROR::sync_node_jobs, stray job 21312.tyrone-cluster found on tyrone-node4
04/03/2013 04:15:00;0001;PBS_Server;Svr;PBS_Server;LOG_ERROR::sync_node_jobs, stray job 21190.tyrone-cluster found on tyrone-node6
04/03/2013 04:15:03;0001;PBS_Server;Svr;PBS_Server;LOG_ERROR::sync_node_jobs, stray job 21306.tyrone-cluster found on tyrone-node5
04/03/2013 04:15:33;0001;PBS_Server;Svr;PBS_Server;LOG_ERROR::sync_node_jobs, stray job 21312.tyrone-cluster found on tyrone-node4
04/03/2013 04:15:45;0001;PBS_Server;Svr;PBS_Server;LOG_ERROR::sync_node_jobs, stray job 21190.tyrone-cluster found on tyrone-node6
04/03/2013 04:15:48;0001;PBS_Server;Svr;PBS_Server;LOG_ERROR::sync_node_jobs, stray job 21306.tyrone-cluster found on tyrone-node5
04/03/2013 04:16:18;0001;PBS_Server;Svr;PBS_Server;LOG_ERROR::sync_node_jobs, stray job 21312.tyrone-cluster found on tyrone-node4
04/03/2013 04:16:30;0001;PBS_Server;Svr;PBS_Server;LOG_ERROR::sync_node_jobs, stray job 21190.tyrone-cluster found on tyrone-node6
04/03/2013 04:16:33;0001;PBS_Server;Svr;PBS_Server;LOG_ERROR::sync_node_jobs, stray job 21306.tyrone-cluster found on tyrone-node5
04/03/2013 04:17:03;0001;PBS_Server;Svr;PBS_Server;LOG_ERROR::sync_node_jobs, stray job 21312.tyrone-cluster found on tyrone-node4
04/03/2013 04:17:15;0001;PBS_Server;Svr;PBS_Server;LOG_ERROR::sync_node_jobs, stray job 21190.tyrone-cluster found on tyrone-node6
04/03/2013 04:17:18;0001;PBS_Server;Svr;PBS_Server;LOG_ERROR::sync_node_jobs, stray job 21306.tyrone-cluster found on tyrone-node5
04/03/2013 04:17:48;0001;PBS_Server;Svr;PBS_Server;LOG_ERROR::sync_node_jobs, stray job 21312.tyrone-cluster found on tyrone-node4
04/03/2013 04:18:00;0001;PBS_Server;Svr;PBS_Server;LOG_ERROR::sync_node_jobs, stray job 21190.tyrone-cluster found on tyrone-node6
04/03/2013 04:18:03;0001;PBS_Server;Svr;PBS_Server;LOG_ERROR::sync_node_jobs, stray job 21306.tyrone-cluster found on tyrone-node5
04/03/2013 04:18:30;0002;PBS_Server;Svr;PBS_Server;Torque Server Version = 3.0.5, loglevel = 0
04/03/2013 04:18:33;0001;PBS_Server;Svr;PBS_Server;LOG_ERROR::sync_node_jobs, stray job 21312.tyrone-cluster found on tyrone-node4
04/03/2013 04:18:45;0001;PBS_Server;Svr;PBS_Server;LOG_ERROR::sync_node_jobs, stray job 21190.tyrone-cluster found on tyrone-node6
04/03/2013 04:18:48;0001;PBS_Server;Svr;PBS_Server;LOG_ERROR::sync_node_jobs, stray job 21306.tyrone-cluster found on tyrone-node5
04/03/2013 04:19:18;0001;PBS_Server;Svr;PBS_Server;LOG_ERROR::sync_node_jobs, stray job 21312.tyrone-cluster found on tyrone-node4
04/03/2013 04:19:30;0001;PBS_Server;Svr;PBS_Server;LOG_ERROR::sync_node_jobs, stray job 21190.tyrone-cluster found on tyrone-node6
04/03/2013 04:19:33;0001;PBS_Server;Svr;PBS_Server;LOG_ERROR::sync_node_jobs, stray job 21306.tyrone-cluster found on tyrone-node5
04/03/2013 04:20:03;0001;PBS_Server;Svr;PBS_Server;LOG_ERROR::sync_node_jobs, stray job 21312.tyrone-cluster found on tyrone-node4
04/03/2013 04:20:15;0001;PBS_Server;Svr;PBS_Server;LOG_ERROR::sync_node_jobs, stray job 21190.tyrone-cluster found on tyrone-node6
04/03/2013 04:20:18;0001;PBS_Server;Svr;PBS_Server;LOG_ERROR::sync_node_jobs, stray job 21306.tyrone-cluster found on tyrone-node5
04/03/2013 04:20:48;0001;PBS_Server;Svr;PBS_Server;LOG_ERROR::sync_node_jobs, stray job 21312.tyrone-cluster found on tyrone-node4
04/03/2013 04:21:00;0001;PBS_Server;Svr;PBS_Server;LOG_ERROR::sync_node_jobs, stray job 21190.tyrone-cluster found on tyrone-node6
04/03/2013 04:21:02;0001;PBS_Server;Svr;PBS_Server;LOG_ERROR::sync_node_jobs, stray job 21306.tyrone-cluster found on tyrone-node5
04/03/2013 04:21:32;0001;PBS_Server;Svr;PBS_Server;LOG_ERROR::sync_node_jobs, stray job 21312.tyrone-cluster found on tyrone-node4
04/03/2013 04:21:45;0001;PBS_Server;Svr;PBS_Server;LOG_ERROR::sync_node_jobs, stray job 21190.tyrone-cluster found on tyrone-node6
04/03/2013 04:21:47;0001;PBS_Server;Svr;PBS_Server;LOG_ERROR::sync_node_jobs, stray job 21306.tyrone-cluster found on tyrone-node5
04/03/2013 04:22:17;0001;PBS_Server;Svr;PBS_Server;LOG_ERROR::sync_node_jobs, stray job 21312.tyrone-cluster found on tyrone-node4
04/03/2013 04:22:30;0001;PBS_Server;Svr;PBS_Server;LOG_ERROR::sync_node_jobs, stray job 21190.tyrone-cluster found on tyrone-node6
04/03/2013 04:22:32;0001;PBS_Server;Svr;PBS_Server;LOG_ERROR::sync_node_jobs, stray job 21306.tyrone-cluster found on tyrone-node5
04/03/2013 04:22:44;0040;PBS_Server;Svr;tyrone-cluster;Scheduler was sent the command time
04/03/2013 04:23:02;0001;PBS_Server;Svr;PBS_Server;LOG_ERROR::sync_node_jobs, stray job 21312.tyrone-cluster found on tyrone-node4
04/03/2013 04:23:14;0001;PBS_Server;Svr;PBS_Server;LOG_ERROR::sync_node_jobs, stray job 21190.tyrone-cluster found on tyrone-node6
04/03/2013 04:23:17;0001;PBS_Server;Svr;PBS_Server;LOG_ERROR::sync_node_jobs, stray job 21306.tyrone-cluster found on tyrone-node5
04/03/2013 04:23:30;0002;PBS_Server;Svr;PBS_Server;Torque Server Version = 3.0.5, loglevel = 0
04/03/2013 04:23:48;0001;PBS_Server;Svr;PBS_Server;LOG_ERROR::sync_node_jobs, stray job 21312.tyrone-cluster found on tyrone-node4
04/03/2013 04:24:00;0001;PBS_Server;Svr;PBS_Server;LOG_ERROR::sync_node_jobs, stray job 21190.tyrone-cluster found on tyrone-node6
04/03/2013 04:24:02;0001;PBS_Server;Svr;PBS_Server;LOG_ERROR::sync_node_jobs, stray job 21306.tyrone-cluster found on tyrone-node5
04/03/2013 04:24:33;0001;PBS_Server;Svr;PBS_Server;LOG_ERROR::sync_node_jobs, stray job 21312.tyrone-cluster found on tyrone-node4
04/03/2013 04:24:45;0001;PBS_Server;Svr;PBS_Server;LOG_ERROR::sync_node_jobs, stray job 21190.tyrone-cluster found on tyrone-node6
04/03/2013 04:24:48;0001;PBS_Server;Svr;PBS_Server;LOG_ERROR::sync_node_jobs, stray job 21306.tyrone-cluster found on tyrone-node5
04/03/2013 04:25:18;0001;PBS_Server;Svr;PBS_Server;LOG_ERROR::sync_node_jobs, stray job 21312.tyrone-cluster found on tyrone-node4
04/03/2013 04:25:30;0001;PBS_Server;Svr;PBS_Server;LOG_ERROR::sync_node_jobs, stray job 21190.tyrone-cluster found on tyrone-node6
04/03/2013 04:25:33;0001;PBS_Server;Svr;PBS_Server;LOG_ERROR::sync_node_jobs, stray job 21306.tyrone-cluster found on tyrone-node5
04/03/2013 04:26:03;0001;PBS_Server;Svr;PBS_Server;LOG_ERROR::sync_node_jobs, stray job 21312.tyrone-cluster found on tyrone-node4
04/03/2013 04:26:15;0001;PBS_Server;Svr;PBS_Server;LOG_ERROR::sync_node_jobs, stray job 21190.tyrone-cluster found on tyrone-node6
04/03/2013 04:26:18;0001;PBS_Server;Svr;PBS_Server;LOG_ERROR::sync_node_jobs, stray job 21306.tyrone-cluster found on tyrone-node5
04/03/2013 04:26:48;0001;PBS_Server;Svr;PBS_Server;LOG_ERROR::sync_node_jobs, stray job 21312.tyrone-cluster found on tyrone-node4
04/03/2013 04:27:00;0001;PBS_Server;Svr;PBS_Server;LOG_ERROR::sync_node_jobs, stray job 21190.tyrone-cluster found on tyrone-node6
04/03/2013 04:27:03;0001;PBS_Server;Svr;PBS_Server;LOG_ERROR::sync_node_jobs, stray job 21306.tyrone-cluster found on tyrone-node5
04/03/2013 04:27:33;0001;PBS_Server;Svr;PBS_Server;LOG_ERROR::sync_node_jobs, stray job 21312.tyrone-cluster found on tyrone-node4
04/03/2013 04:27:45;0001;PBS_Server;Svr;PBS_Server;LOG_ERROR::sync_node_jobs, stray job 21190.tyrone-cluster found on tyrone-node6
04/03/2013 04:27:48;0001;PBS_Server;Svr;PBS_Server;LOG_ERROR::sync_node_jobs, stray job 21306.tyrone-cluster found on tyrone-node5
04/03/2013 04:28:18;0001;PBS_Server;Svr;PBS_Server;LOG_ERROR::sync_node_jobs, stray job 21312.tyrone-cluster found on tyrone-node4
04/03/2013 04:28:30;0002;PBS_Server;Svr;PBS_Server;Torque Server Version = 3.0.5, loglevel = 0
04/03/2013 04:28:30;0001;PBS_Server;Svr;PBS_Server;LOG_ERROR::sync_node_jobs, stray job 21190.tyrone-cluster found on tyrone-node6
04/03/2013 04:28:33;0001;PBS_Server;Svr;PBS_Server;LOG_ERROR::sync_node_jobs, stray job 21306.tyrone-cluster found on tyrone-node5
04/03/2013 04:29:03;0001;PBS_Server;Svr;PBS_Server;LOG_ERROR::sync_node_jobs, stray job 21312.tyrone-cluster found on tyrone-node4
04/03/2013 04:29:15;0001;PBS_Server;Svr;PBS_Server;LOG_ERROR::sync_node_jobs, stray job 21190.tyrone-cluster found on tyrone-node6
04/03/2013 04:29:18;0001;PBS_Server;Svr;PBS_Server;LOG_ERROR::sync_node_jobs, stray job 21306.tyrone-cluster found on tyrone-node5
04/03/2013 04:29:48;0001;PBS_Server;Svr;PBS_Server;LOG_ERROR::sync_node_jobs, stray job 21312.tyrone-cluster found on tyrone-node4
04/03/2013 04:30:00;0001;PBS_Server;Svr;PBS_Server;LOG_ERROR::sync_node_jobs, stray job 21190.tyrone-cluster found on tyrone-node6
04/03/2013 04:30:03;0001;PBS_Server;Svr;PBS_Server;LOG_ERROR::sync_node_jobs, stray job 21306.tyrone-cluster found on tyrone-node5
04/03/2013 04:30:33;0001;PBS_Server;Svr;PBS_Server;LOG_ERROR::sync_node_jobs, stray job 21312.tyrone-cluster found on tyrone-node4
04/03/2013 04:30:45;0001;PBS_Server;Svr;PBS_Server;LOG_ERROR::sync_node_jobs, stray job 21190.tyrone-cluster found on tyrone-node6
04/03/2013 04:30:48;0001;PBS_Server;Svr;PBS_Server;LOG_ERROR::sync_node_jobs, stray job 21306.tyrone-cluster found on tyrone-node5
04/03/2013 04:31:17;0001;PBS_Server;Svr;PBS_Server;LOG_ERROR::sync_node_jobs, stray job 21312.tyrone-cluster found on tyrone-node4
04/03/2013 04:31:30;0001;PBS_Server;Svr;PBS_Server;LOG_ERROR::sync_node_jobs, stray job 21190.tyrone-cluster found on tyrone-node6
04/03/2013 04:31:33;0001;PBS_Server;Svr;PBS_Server;LOG_ERROR::sync_node_jobs, stray job 21306.tyrone-cluster found on tyrone-node5
04/03/2013 04:32:02;0001;PBS_Server;Svr;PBS_Server;LOG_ERROR::sync_node_jobs, stray job 21312.tyrone-cluster found on tyrone-node4
04/03/2013 04:32:15;0001;PBS_Server;Svr;PBS_Server;LOG_ERROR::sync_node_jobs, stray job 21190.tyrone-cluster found on tyrone-node6
04/03/2013 04:32:18;0001;PBS_Server;Svr;PBS_Server;LOG_ERROR::sync_node_jobs, stray job 21306.tyrone-cluster found on tyrone-node5
04/03/2013 04:32:44;0040;PBS_Server;Svr;tyrone-cluster;Scheduler was sent the command time
04/03/2013 04:32:47;0001;PBS_Server;Svr;PBS_Server;LOG_ERROR::sync_node_jobs, stray job 21312.tyrone-cluster found on tyrone-node4
04/03/2013 04:33:00;0001;PBS_Server;Svr;PBS_Server;LOG_ERROR::sync_node_jobs, stray job 21190.tyrone-cluster found on tyrone-node6
04/03/2013 04:33:02;0001;PBS_Server;Svr;PBS_Server;LOG_ERROR::sync_node_jobs, stray job 21306.tyrone-cluster found on tyrone-node5
04/03/2013 04:33:30;0002;PBS_Server;Svr;PBS_Server;Torque Server Version = 3.0.5, loglevel = 0
04/03/2013 04:33:32;0001;PBS_Server;Svr;PBS_Server;LOG_ERROR::sync_node_jobs, stray job 21312.tyrone-cluster found on tyrone-node4
04/03/2013 04:33:45;0001;PBS_Server;Svr;PBS_Server;LOG_ERROR::sync_node_jobs, stray job 21190.tyrone-cluster found on tyrone-node6
04/03/2013 04:33:47;0001;PBS_Server;Svr;PBS_Server;LOG_ERROR::sync_node_jobs, stray job 21306.tyrone-cluster found on tyrone-node5
04/03/2013 04:34:17;0001;PBS_Server;Svr;PBS_Server;LOG_ERROR::sync_node_jobs, stray job 21312.tyrone-cluster found on tyrone-node4
04/03/2013 04:34:29;0001;PBS_Server;Svr;PBS_Server;LOG_ERROR::sync_node_jobs, stray job 21190.tyrone-cluster found on tyrone-node6
04/03/2013 04:34:32;0001;PBS_Server;Svr;PBS_Server;LOG_ERROR::sync_node_jobs, stray job 21306.tyrone-cluster found on tyrone-node5
04/03/2013 04:35:02;0001;PBS_Server;Svr;PBS_Server;LOG_ERROR::sync_node_jobs, stray job 21312.tyrone-cluster found on tyrone-node4
04/03/2013 04:35:14;0001;PBS_Server;Svr;PBS_Server;LOG_ERROR::sync_node_jobs, stray job 21190.tyrone-cluster found on tyrone-node6
04/03/2013 04:35:17;0001;PBS_Server;Svr;PBS_Server;LOG_ERROR::sync_node_jobs, stray job 21306.tyrone-cluster found on tyrone-node5
04/03/2013 04:35:48;0001;PBS_Server;Svr;PBS_Server;LOG_ERROR::sync_node_jobs, stray job 21312.tyrone-cluster found on tyrone-node4
04/03/2013 04:35:59;0001;PBS_Server;Svr;PBS_Server;LOG_ERROR::sync_node_jobs, stray job 21190.tyrone-cluster found on tyrone-node6
04/03/2013 04:36:02;0001;PBS_Server;Svr;PBS_Server;LOG_ERROR::sync_node_jobs, stray job 21306.tyrone-cluster found on tyrone-node5
04/03/2013 04:36:33;0001;PBS_Server;Svr;PBS_Server;LOG_ERROR::sync_node_jobs, stray job 21312.tyrone-cluster found on tyrone-node4
04/03/2013 04:36:45;0001;PBS_Server;Svr;PBS_Server;LOG_ERROR::sync_node_jobs, stray job 21190.tyrone-cluster found on tyrone-node6
04/03/2013 04:36:48;0001;PBS_Server;Svr;PBS_Server;LOG_ERROR::sync_node_jobs, stray job 21306.tyrone-cluster found on tyrone-node5
04/03/2013 04:37:18;0001;PBS_Server;Svr;PBS_Server;LOG_ERROR::sync_node_jobs, stray job 21312.tyrone-cluster found on tyrone-node4
04/03/2013 04:37:30;0001;PBS_Server;Svr;PBS_Server;LOG_ERROR::sync_node_jobs, stray job 21190.tyrone-cluster found on tyrone-node6
04/03/2013 04:37:33;0001;PBS_Server;Svr;PBS_Server;LOG_ERROR::sync_node_jobs, stray job 21306.tyrone-cluster found on tyrone-node5
04/03/2013 04:38:03;0001;PBS_Server;Svr;PBS_Server;LOG_ERROR::sync_node_jobs, stray job 21312.tyrone-cluster found on tyrone-node4
04/03/2013 04:38:15;0001;PBS_Server;Svr;PBS_Server;LOG_ERROR::sync_node_jobs, stray job 21190.tyrone-cluster found on tyrone-node6
04/03/2013 04:38:18;0001;PBS_Server;Svr;PBS_Server;LOG_ERROR::sync_node_jobs, stray job 21306.tyrone-cluster found on tyrone-node5
04/03/2013 04:38:30;0002;PBS_Server;Svr;PBS_Server;Torque Server Version = 3.0.5, loglevel = 0
04/03/2013 04:38:48;0001;PBS_Server;Svr;PBS_Server;LOG_ERROR::sync_node_jobs, stray job 21312.tyrone-cluster found on tyrone-node4
04/03/2013 04:39:00;0001;PBS_Server;Svr;PBS_Server;LOG_ERROR::sync_node_jobs, stray job 21190.tyrone-cluster found on tyrone-node6
04/03/2013 04:39:03;0001;PBS_Server;Svr;PBS_Server;LOG_ERROR::sync_node_jobs, stray job 21306.tyrone-cluster found on tyrone-node5
04/03/2013 04:39:33;0001;PBS_Server;Svr;PBS_Server;LOG_ERROR::sync_node_jobs, stray job 21312.tyrone-cluster found on tyrone-node4
04/03/2013 04:39:45;0001;PBS_Server;Svr;PBS_Server;LOG_ERROR::sync_node_jobs, stray job 21190.tyrone-cluster found on tyrone-node6
04/03/2013 04:39:48;0001;PBS_Server;Svr;PBS_Server;LOG_ERROR::sync_node_jobs, stray job 21306.tyrone-cluster found on tyrone-node5
04/03/2013 04:40:18;0001;PBS_Server;Svr;PBS_Server;LOG_ERROR::sync_node_jobs, stray job 21312.tyrone-cluster found on tyrone-node4
04/03/2013 04:40:30;0001;PBS_Server;Svr;PBS_Server;LOG_ERROR::sync_node_jobs, stray job 21190.tyrone-cluster found on tyrone-node6
04/03/2013 04:40:33;0001;PBS_Server;Svr;PBS_Server;LOG_ERROR::sync_node_jobs, stray job 21306.tyrone-cluster found on tyrone-node5
04/03/2013 04:41:02;0001;PBS_Server;Svr;PBS_Server;LOG_ERROR::sync_node_jobs, stray job 21312.tyrone-cluster found on tyrone-node4
04/03/2013 04:41:15;0001;PBS_Server;Svr;PBS_Server;LOG_ERROR::sync_node_jobs, stray job 21190.tyrone-cluster found on tyrone-node6
04/03/2013 04:41:18;0001;PBS_Server;Svr;PBS_Server;LOG_ERROR::sync_node_jobs, stray job 21306.tyrone-cluster found on tyrone-node5
04/03/2013 04:41:47;0001;PBS_Server;Svr;PBS_Server;LOG_ERROR::sync_node_jobs, stray job 21312.tyrone-cluster found on tyrone-node4
04/03/2013 04:42:00;0001;PBS_Server;Svr;PBS_Server;LOG_ERROR::sync_node_jobs, stray job 21190.tyrone-cluster found on tyrone-node6
04/03/2013 04:42:03;0001;PBS_Server;Svr;PBS_Server;LOG_ERROR::sync_node_jobs, stray job 21306.tyrone-cluster found on tyrone-node5
04/03/2013 04:42:32;0001;PBS_Server;Svr;PBS_Server;LOG_ERROR::sync_node_jobs, stray job 21312.tyrone-cluster found on tyrone-node4
04/03/2013 04:42:44;0040;PBS_Server;Svr;tyrone-cluster;Scheduler was sent the command time
04/03/2013 04:42:45;0001;PBS_Server;Svr;PBS_Server;LOG_ERROR::sync_node_jobs, stray job 21190.tyrone-cluster found on tyrone-node6
04/03/2013 04:42:48;0001;PBS_Server;Svr;PBS_Server;LOG_ERROR::sync_node_jobs, stray job 21306.tyrone-cluster found on tyrone-node5
04/03/2013 04:43:17;0001;PBS_Server;Svr;PBS_Server;LOG_ERROR::sync_node_jobs, stray job 21312.tyrone-cluster found on tyrone-node4
04/03/2013 04:43:30;0001;PBS_Server;Svr;PBS_Server;LOG_ERROR::sync_node_jobs, stray job 21190.tyrone-cluster found on tyrone-node6
04/03/2013 04:43:30;0002;PBS_Server;Svr;PBS_Server;Torque Server Version = 3.0.5, loglevel = 0
04/03/2013 04:43:33;0001;PBS_Server;Svr;PBS_Server;LOG_ERROR::sync_node_jobs, stray job 21306.tyrone-cluster found on tyrone-node5
04/03/2013 04:44:02;0001;PBS_Server;Svr;PBS_Server;LOG_ERROR::sync_node_jobs, stray job 21312.tyrone-cluster found on tyrone-node4
04/03/2013 04:44:15;0001;PBS_Server;Svr;PBS_Server;LOG_ERROR::sync_node_jobs, stray job 21190.tyrone-cluster found on tyrone-node6
04/03/2013 04:44:18;0001;PBS_Server;Svr;PBS_Server;LOG_ERROR::sync_node_jobs, stray job 21306.tyrone-cluster found on tyrone-node5
04/03/2013 04:44:47;0001;PBS_Server;Svr;PBS_Server;LOG_ERROR::sync_node_jobs, stray job 21312.tyrone-cluster found on tyrone-node4
04/03/2013 04:45:00;0001;PBS_Server;Svr;PBS_Server;LOG_ERROR::sync_node_jobs, stray job 21190.tyrone-cluster found on tyrone-node6
04/03/2013 04:45:02;0001;PBS_Server;Svr;PBS_Server;LOG_ERROR::sync_node_jobs, stray job 21306.tyrone-cluster found on tyrone-node5
04/03/2013 04:45:32;0001;PBS_Server;Svr;PBS_Server;LOG_ERROR::sync_node_jobs, stray job 21312.tyrone-cluster found on tyrone-node4
04/03/2013 04:45:45;0001;PBS_Server;Svr;PBS_Server;LOG_ERROR::sync_node_jobs, stray job 21190.tyrone-cluster found on tyrone-node6
04/03/2013 04:45:47;0001;PBS_Server;Svr;PBS_Server;LOG_ERROR::sync_node_jobs, stray job 21306.tyrone-cluster found on tyrone-node5
04/03/2013 04:46:17;0001;PBS_Server;Svr;PBS_Server;LOG_ERROR::sync_node_jobs, stray job 21312.tyrone-cluster found on tyrone-node4
04/03/2013 04:46:29;0001;PBS_Server;Svr;PBS_Server;LOG_ERROR::sync_node_jobs, stray job 21190.tyrone-cluster found on tyrone-node6
04/03/2013 04:46:32;0001;PBS_Server;Svr;PBS_Server;LOG_ERROR::sync_node_jobs, stray job 21306.tyrone-cluster found on tyrone-node5
04/03/2013 04:47:02;0001;PBS_Server;Svr;PBS_Server;LOG_ERROR::sync_node_jobs, stray job 21312.tyrone-cluster found on tyrone-node4
04/03/2013 04:47:14;0001;PBS_Server;Svr;PBS_Server;LOG_ERROR::sync_node_jobs, stray job 21190.tyrone-cluster found on tyrone-node6
04/03/2013 04:47:17;0001;PBS_Server;Svr;PBS_Server;LOG_ERROR::sync_node_jobs, stray job 21306.tyrone-cluster found on tyrone-node5
04/03/2013 04:47:47;0001;PBS_Server;Svr;PBS_Server;LOG_ERROR::sync_node_jobs, stray job 21312.tyrone-cluster found on tyrone-node4
04/03/2013 04:47:59;0001;PBS_Server;Svr;PBS_Server;LOG_ERROR::sync_node_jobs, stray job 21190.tyrone-cluster found on tyrone-node6
04/03/2013 04:48:02;0001;PBS_Server;Svr;PBS_Server;LOG_ERROR::sync_node_jobs, stray job 21306.tyrone-cluster found on tyrone-node5
04/03/2013 04:48:30;0002;PBS_Server;Svr;PBS_Server;Torque Server Version = 3.0.5, loglevel = 0
04/03/2013 04:48:33;0001;PBS_Server;Svr;PBS_Server;LOG_ERROR::sync_node_jobs, stray job 21312.tyrone-cluster found on tyrone-node4
04/03/2013 04:48:44;0001;PBS_Server;Svr;PBS_Server;LOG_ERROR::sync_node_jobs, stray job 21190.tyrone-cluster found on tyrone-node6
04/03/2013 04:48:47;0001;PBS_Server;Svr;PBS_Server;LOG_ERROR::sync_node_jobs, stray job 21306.tyrone-cluster found on tyrone-node5
04/03/2013 04:49:18;0001;PBS_Server;Svr;PBS_Server;LOG_ERROR::sync_node_jobs, stray job 21312.tyrone-cluster found on tyrone-node4
04/03/2013 04:49:30;0001;PBS_Server;Svr;PBS_Server;LOG_ERROR::sync_node_jobs, stray job 21190.tyrone-cluster found on tyrone-node6
04/03/2013 04:49:33;0001;PBS_Server;Svr;PBS_Server;LOG_ERROR::sync_node_jobs, stray job 21306.tyrone-cluster found on tyrone-node5
04/03/2013 04:50:03;0001;PBS_Server;Svr;PBS_Server;LOG_ERROR::sync_node_jobs, stray job 21312.tyrone-cluster found on tyrone-node4
04/03/2013 04:50:15;0001;PBS_Server;Svr;PBS_Server;LOG_ERROR::sync_node_jobs, stray job 21190.tyrone-cluster found on tyrone-node6
04/03/2013 04:50:18;0001;PBS_Server;Svr;PBS_Server;LOG_ERROR::sync_node_jobs, stray job 21306.tyrone-cluster found on tyrone-node5
04/03/2013 04:50:48;0001;PBS_Server;Svr;PBS_Server;LOG_ERROR::sync_node_jobs, stray job 21312.tyrone-cluster found on tyrone-node4
04/03/2013 04:51:00;0001;PBS_Server;Svr;PBS_Server;LOG_ERROR::sync_node_jobs, stray job 21190.tyrone-cluster found on tyrone-node6
04/03/2013 04:51:03;0001;PBS_Server;Svr;PBS_Server;LOG_ERROR::sync_node_jobs, stray job 21306.tyrone-cluster found on tyrone-node5
04/03/2013 04:51:32;0001;PBS_Server;Svr;PBS_Server;LOG_ERROR::sync_node_jobs, stray job 21312.tyrone-cluster found on tyrone-node4
04/03/2013 04:51:45;0001;PBS_Server;Svr;PBS_Server;LOG_ERROR::sync_node_jobs, stray job 21190.tyrone-cluster found on tyrone-node6
04/03/2013 04:51:48;0001;PBS_Server;Svr;PBS_Server;LOG_ERROR::sync_node_jobs, stray job 21306.tyrone-cluster found on tyrone-node5
04/03/2013 04:52:17;0001;PBS_Server;Svr;PBS_Server;LOG_ERROR::sync_node_jobs, stray job 21312.tyrone-cluster found on tyrone-node4
04/03/2013 04:52:30;0001;PBS_Server;Svr;PBS_Server;LOG_ERROR::sync_node_jobs, stray job 21190.tyrone-cluster found on tyrone-node6
04/03/2013 04:52:33;0001;PBS_Server;Svr;PBS_Server;LOG_ERROR::sync_node_jobs, stray job 21306.tyrone-cluster found on tyrone-node5
04/03/2013 04:52:44;0040;PBS_Server;Svr;tyrone-cluster;Scheduler was sent the command time
04/03/2013 04:53:02;0001;PBS_Server;Svr;PBS_Server;LOG_ERROR::sync_node_jobs, stray job 21312.tyrone-cluster found on tyrone-node4
04/03/2013 04:53:15;0001;PBS_Server;Svr;PBS_Server;LOG_ERROR::sync_node_jobs, stray job 21190.tyrone-cluster found on tyrone-node6
04/03/2013 04:53:18;0001;PBS_Server;Svr;PBS_Server;LOG_ERROR::sync_node_jobs, stray job 21306.tyrone-cluster found on tyrone-node5
04/03/2013 04:53:30;0002;PBS_Server;Svr;PBS_Server;Torque Server Version = 3.0.5, loglevel = 0
04/03/2013 04:53:47;0001;PBS_Server;Svr;PBS_Server;LOG_ERROR::sync_node_jobs, stray job 21312.tyrone-cluster found on tyrone-node4
04/03/2013 04:54:00;0001;PBS_Server;Svr;PBS_Server;LOG_ERROR::sync_node_jobs, stray job 21190.tyrone-cluster found on tyrone-node6
04/03/2013 04:54:03;0001;PBS_Server;Svr;PBS_Server;LOG_ERROR::sync_node_jobs, stray job 21306.tyrone-cluster found on tyrone-node5
04/03/2013 04:54:32;0001;PBS_Server;Svr;PBS_Server;LOG_ERROR::sync_node_jobs, stray job 21312.tyrone-cluster found on tyrone-node4
04/03/2013 04:54:45;0001;PBS_Server;Svr;PBS_Server;LOG_ERROR::sync_node_jobs, stray job 21190.tyrone-cluster found on tyrone-node6
04/03/2013 04:54:48;0001;PBS_Server;Svr;PBS_Server;LOG_ERROR::sync_node_jobs, stray job 21306.tyrone-cluster found on tyrone-node5
04/03/2013 04:55:17;0001;PBS_Server;Svr;PBS_Server;LOG_ERROR::sync_node_jobs, stray job 21312.tyrone-cluster found on tyrone-node4
04/03/2013 04:55:30;0001;PBS_Server;Svr;PBS_Server;LOG_ERROR::sync_node_jobs, stray job 21190.tyrone-cluster found on tyrone-node6
04/03/2013 04:55:33;0001;PBS_Server;Svr;PBS_Server;LOG_ERROR::sync_node_jobs, stray job 21306.tyrone-cluster found on tyrone-node5
04/03/2013 04:56:02;0001;PBS_Server;Svr;PBS_Server;LOG_ERROR::sync_node_jobs, stray job 21312.tyrone-cluster found on tyrone-node4
04/03/2013 04:56:15;0001;PBS_Server;Svr;PBS_Server;LOG_ERROR::sync_node_jobs, stray job 21190.tyrone-cluster found on tyrone-node6
04/03/2013 04:56:18;0001;PBS_Server;Svr;PBS_Server;LOG_ERROR::sync_node_jobs, stray job 21306.tyrone-cluster found on tyrone-node5
04/03/2013 04:56:47;0001;PBS_Server;Svr;PBS_Server;LOG_ERROR::sync_node_jobs, stray job 21312.tyrone-cluster found on tyrone-node4
04/03/2013 04:57:00;0001;PBS_Server;Svr;PBS_Server;LOG_ERROR::sync_node_jobs, stray job 21190.tyrone-cluster found on tyrone-node6
04/03/2013 04:57:03;0001;PBS_Server;Svr;PBS_Server;LOG_ERROR::sync_node_jobs, stray job 21306.tyrone-cluster found on tyrone-node5
04/03/2013 04:57:32;0001;PBS_Server;Svr;PBS_Server;LOG_ERROR::sync_node_jobs, stray job 21312.tyrone-cluster found on tyrone-node4
04/03/2013 04:57:44;0001;PBS_Server;Svr;PBS_Server;LOG_ERROR::sync_node_jobs, stray job 21190.tyrone-cluster found on tyrone-node6
04/03/2013 04:57:47;0001;PBS_Server;Svr;PBS_Server;LOG_ERROR::sync_node_jobs, stray job 21306.tyrone-cluster found on tyrone-node5
04/03/2013 04:58:17;0001;PBS_Server;Svr;PBS_Server;LOG_ERROR::sync_node_jobs, stray job 21312.tyrone-cluster found on tyrone-node4
04/03/2013 04:58:29;0001;PBS_Server;Svr;PBS_Server;LOG_ERROR::sync_node_jobs, stray job 21190.tyrone-cluster found on tyrone-node6
04/03/2013 04:58:30;0002;PBS_Server;Svr;PBS_Server;Torque Server Version = 3.0.5, loglevel = 0
04/03/2013 04:58:32;0001;PBS_Server;Svr;PBS_Server;LOG_ERROR::sync_node_jobs, stray job 21306.tyrone-cluster found on tyrone-node5
04/03/2013 04:59:02;0001;PBS_Server;Svr;PBS_Server;LOG_ERROR::sync_node_jobs, stray job 21312.tyrone-cluster found on tyrone-node4
04/03/2013 04:59:14;0001;PBS_Server;Svr;PBS_Server;LOG_ERROR::sync_node_jobs, stray job 21190.tyrone-cluster found on tyrone-node6
04/03/2013 04:59:17;0001;PBS_Server;Svr;PBS_Server;LOG_ERROR::sync_node_jobs, stray job 21306.tyrone-cluster found on tyrone-node5
04/03/2013 04:59:47;0001;PBS_Server;Svr;PBS_Server;LOG_ERROR::sync_node_jobs, stray job 21312.tyrone-cluster found on tyrone-node4
04/03/2013 04:59:59;0001;PBS_Server;Svr;PBS_Server;LOG_ERROR::sync_node_jobs, stray job 21190.tyrone-cluster found on tyrone-node6
04/03/2013 05:00:02;0001;PBS_Server;Svr;PBS_Server;LOG_ERROR::sync_node_jobs, stray job 21306.tyrone-cluster found on tyrone-node5
04/03/2013 05:00:31;0001;PBS_Server;Svr;PBS_Server;LOG_ERROR::sync_node_jobs, stray job 21312.tyrone-cluster found on tyrone-node4
04/03/2013 05:00:44;0001;PBS_Server;Svr;PBS_Server;LOG_ERROR::sync_node_jobs, stray job 21190.tyrone-cluster found on tyrone-node6
04/03/2013 05:00:47;0001;PBS_Server;Svr;PBS_Server;LOG_ERROR::sync_node_jobs, stray job 21306.tyrone-cluster found on tyrone-node5
04/03/2013 05:01:17;0001;PBS_Server;Svr;PBS_Server;LOG_ERROR::sync_node_jobs, stray job 21312.tyrone-cluster found on tyrone-node4
04/03/2013 05:01:29;0001;PBS_Server;Svr;PBS_Server;LOG_ERROR::sync_node_jobs, stray job 21190.tyrone-cluster found on tyrone-node6
04/03/2013 05:01:32;0001;PBS_Server;Svr;PBS_Server;LOG_ERROR::sync_node_jobs, stray job 21306.tyrone-cluster found on tyrone-node5
04/03/2013 05:02:02;0001;PBS_Server;Svr;PBS_Server;LOG_ERROR::sync_node_jobs, stray job 21312.tyrone-cluster found on tyrone-node4
04/03/2013 05:02:15;0001;PBS_Server;Svr;PBS_Server;LOG_ERROR::sync_node_jobs, stray job 21190.tyrone-cluster found on tyrone-node6
04/03/2013 05:02:18;0001;PBS_Server;Svr;PBS_Server;LOG_ERROR::sync_node_jobs, stray job 21306.tyrone-cluster found on tyrone-node5
04/03/2013 05:02:44;0040;PBS_Server;Svr;tyrone-cluster;Scheduler was sent the command time
04/03/2013 05:02:47;0001;PBS_Server;Svr;PBS_Server;LOG_ERROR::sync_node_jobs, stray job 21312.tyrone-cluster found on tyrone-node4
04/03/2013 05:03:00;0001;PBS_Server;Svr;PBS_Server;LOG_ERROR::sync_node_jobs, stray job 21190.tyrone-cluster found on tyrone-node6
04/03/2013 05:03:03;0001;PBS_Server;Svr;PBS_Server;LOG_ERROR::sync_node_jobs, stray job 21306.tyrone-cluster found on tyrone-node5
04/03/2013 05:03:30;0002;PBS_Server;Svr;PBS_Server;Torque Server Version = 3.0.5, loglevel = 0
04/03/2013 05:03:32;0001;PBS_Server;Svr;PBS_Server;LOG_ERROR::sync_node_jobs, stray job 21312.tyrone-cluster found on tyrone-node4
04/03/2013 05:03:45;0001;PBS_Server;Svr;PBS_Server;LOG_ERROR::sync_node_jobs, stray job 21190.tyrone-cluster found on tyrone-node6
04/03/2013 05:03:48;0001;PBS_Server;Svr;PBS_Server;LOG_ERROR::sync_node_jobs, stray job 21306.tyrone-cluster found on tyrone-node5
04/03/2013 05:04:17;0001;PBS_Server;Svr;PBS_Server;LOG_ERROR::sync_node_jobs, stray job 21312.tyrone-cluster found on tyrone-node4
04/03/2013 05:04:30;0001;PBS_Server;Svr;PBS_Server;LOG_ERROR::sync_node_jobs, stray job 21190.tyrone-cluster found on tyrone-node6
04/03/2013 05:04:33;0001;PBS_Server;Svr;PBS_Server;LOG_ERROR::sync_node_jobs, stray job 21306.tyrone-cluster found on tyrone-node5
04/03/2013 05:05:02;0001;PBS_Server;Svr;PBS_Server;LOG_ERROR::sync_node_jobs, stray job 21312.tyrone-cluster found on tyrone-node4
04/03/2013 05:05:15;0001;PBS_Server;Svr;PBS_Server;LOG_ERROR::sync_node_jobs, stray job 21190.tyrone-cluster found on tyrone-node6
04/03/2013 05:05:18;0001;PBS_Server;Svr;PBS_Server;LOG_ERROR::sync_node_jobs, stray job 21306.tyrone-cluster found on tyrone-node5
04/03/2013 05:05:47;0001;PBS_Server;Svr;PBS_Server;LOG_ERROR::sync_node_jobs, stray job 21312.tyrone-cluster found on tyrone-node4
04/03/2013 05:06:00;0001;PBS_Server;Svr;PBS_Server;LOG_ERROR::sync_node_jobs, stray job 21190.tyrone-cluster found on tyrone-node6
04/03/2013 05:06:03;0001;PBS_Server;Svr;PBS_Server;LOG_ERROR::sync_node_jobs, stray job 21306.tyrone-cluster found on tyrone-node5
04/03/2013 05:06:32;0001;PBS_Server;Svr;PBS_Server;LOG_ERROR::sync_node_jobs, stray job 21312.tyrone-cluster found on tyrone-node4
04/03/2013 05:06:45;0001;PBS_Server;Svr;PBS_Server;LOG_ERROR::sync_node_jobs, stray job 21190.tyrone-cluster found on tyrone-node6
04/03/2013 05:06:48;0001;PBS_Server;Svr;PBS_Server;LOG_ERROR::sync_node_jobs, stray job 21306.tyrone-cluster found on tyrone-node5
04/03/2013 05:07:17;0001;PBS_Server;Svr;PBS_Server;LOG_ERROR::sync_node_jobs, stray job 21312.tyrone-cluster found on tyrone-node4
04/03/2013 05:07:30;0001;PBS_Server;Svr;PBS_Server;LOG_ERROR::sync_node_jobs, stray job 21190.tyrone-cluster found on tyrone-node6
04/03/2013 05:07:33;0001;PBS_Server;Svr;PBS_Server;LOG_ERROR::sync_node_jobs, stray job 21306.tyrone-cluster found on tyrone-node5
04/03/2013 05:08:02;0001;PBS_Server;Svr;PBS_Server;LOG_ERROR::sync_node_jobs, stray job 21312.tyrone-cluster found on tyrone-node4
04/03/2013 05:08:15;0001;PBS_Server;Svr;PBS_Server;LOG_ERROR::sync_node_jobs, stray job 21190.tyrone-cluster found on tyrone-node6
04/03/2013 05:08:18;0001;PBS_Server;Svr;PBS_Server;LOG_ERROR::sync_node_jobs, stray job 21306.tyrone-cluster found on tyrone-node5
04/03/2013 05:08:30;0002;PBS_Server;Svr;PBS_Server;Torque Server Version = 3.0.5, loglevel = 0
04/03/2013 05:08:47;0001;PBS_Server;Svr;PBS_Server;LOG_ERROR::sync_node_jobs, stray job 21312.tyrone-cluster found on tyrone-node4
04/03/2013 05:09:00;0001;PBS_Server;Svr;PBS_Server;LOG_ERROR::sync_node_jobs, stray job 21190.tyrone-cluster found on tyrone-node6
04/03/2013 05:09:03;0001;PBS_Server;Svr;PBS_Server;LOG_ERROR::sync_node_jobs, stray job 21306.tyrone-cluster found on tyrone-node5
04/03/2013 05:09:32;0001;PBS_Server;Svr;PBS_Server;LOG_ERROR::sync_node_jobs, stray job 21312.tyrone-cluster found on tyrone-node4
04/03/2013 05:09:44;0001;PBS_Server;Svr;PBS_Server;LOG_ERROR::sync_node_jobs, stray job 21190.tyrone-cluster found on tyrone-node6
04/03/2013 05:09:47;0001;PBS_Server;Svr;PBS_Server;LOG_ERROR::sync_node_jobs, stray job 21306.tyrone-cluster found on tyrone-node5
04/03/2013 05:10:16;0001;PBS_Server;Svr;PBS_Server;LOG_ERROR::sync_node_jobs, stray job 21312.tyrone-cluster found on tyrone-node4
04/03/2013 05:10:29;0001;PBS_Server;Svr;PBS_Server;LOG_ERROR::sync_node_jobs, stray job 21190.tyrone-cluster found on tyrone-node6
04/03/2013 05:10:32;0001;PBS_Server;Svr;PBS_Server;LOG_ERROR::sync_node_jobs, stray job 21306.tyrone-cluster found on tyrone-node5
04/03/2013 05:11:01;0001;PBS_Server;Svr;PBS_Server;LOG_ERROR::sync_node_jobs, stray job 21312.tyrone-cluster found on tyrone-node4
04/03/2013 05:11:14;0001;PBS_Server;Svr;PBS_Server;LOG_ERROR::sync_node_jobs, stray job 21190.tyrone-cluster found on tyrone-node6
04/03/2013 05:11:17;0001;PBS_Server;Svr;PBS_Server;LOG_ERROR::sync_node_jobs, stray job 21306.tyrone-cluster found on tyrone-node5
04/03/2013 05:11:46;0001;PBS_Server;Svr;PBS_Server;LOG_ERROR::sync_node_jobs, stray job 21312.tyrone-cluster found on tyrone-node4
04/03/2013 05:11:59;0001;PBS_Server;Svr;PBS_Server;LOG_ERROR::sync_node_jobs, stray job 21190.tyrone-cluster found on tyrone-node6
04/03/2013 05:12:02;0001;PBS_Server;Svr;PBS_Server;LOG_ERROR::sync_node_jobs, stray job 21306.tyrone-cluster found on tyrone-node5
04/03/2013 05:12:31;0001;PBS_Server;Svr;PBS_Server;LOG_ERROR::sync_node_jobs, stray job 21312.tyrone-cluster found on tyrone-node4
04/03/2013 05:12:44;0001;PBS_Server;Svr;PBS_Server;LOG_ERROR::sync_node_jobs, stray job 21190.tyrone-cluster found on tyrone-node6
04/03/2013 05:12:44;0040;PBS_Server;Svr;tyrone-cluster;Scheduler was sent the command time
04/03/2013 05:12:47;0001;PBS_Server;Svr;PBS_Server;LOG_ERROR::sync_node_jobs, stray job 21306.tyrone-cluster found on tyrone-node5
04/03/2013 05:13:17;0001;PBS_Server;Svr;PBS_Server;LOG_ERROR::sync_node_jobs, stray job 21312.tyrone-cluster found on tyrone-node4
04/03/2013 05:13:30;0001;PBS_Server;Svr;PBS_Server;LOG_ERROR::sync_node_jobs, stray job 21190.tyrone-cluster found on tyrone-node6
04/03/2013 05:13:30;0002;PBS_Server;Svr;PBS_Server;Torque Server Version = 3.0.5, loglevel = 0
04/03/2013 05:13:32;0001;PBS_Server;Svr;PBS_Server;LOG_ERROR::sync_node_jobs, stray job 21306.tyrone-cluster found on tyrone-node5
04/03/2013 05:14:02;0001;PBS_Server;Svr;PBS_Server;LOG_ERROR::sync_node_jobs, stray job 21312.tyrone-cluster found on tyrone-node4
04/03/2013 05:14:15;0001;PBS_Server;Svr;PBS_Server;LOG_ERROR::sync_node_jobs, stray job 21190.tyrone-cluster found on tyrone-node6
04/03/2013 05:14:18;0001;PBS_Server;Svr;PBS_Server;LOG_ERROR::sync_node_jobs, stray job 21306.tyrone-cluster found on tyrone-node5
04/03/2013 05:14:47;0001;PBS_Server;Svr;PBS_Server;LOG_ERROR::sync_node_jobs, stray job 21312.tyrone-cluster found on tyrone-node4
04/03/2013 05:15:00;0001;PBS_Server;Svr;PBS_Server;LOG_ERROR::sync_node_jobs, stray job 21190.tyrone-cluster found on tyrone-node6
04/03/2013 05:15:03;0001;PBS_Server;Svr;PBS_Server;LOG_ERROR::sync_node_jobs, stray job 21306.tyrone-cluster found on tyrone-node5
04/03/2013 05:15:32;0001;PBS_Server;Svr;PBS_Server;LOG_ERROR::sync_node_jobs, stray job 21312.tyrone-cluster found on tyrone-node4
04/03/2013 05:15:45;0001;PBS_Server;Svr;PBS_Server;LOG_ERROR::sync_node_jobs, stray job 21190.tyrone-cluster found on tyrone-node6
04/03/2013 05:15:48;0001;PBS_Server;Svr;PBS_Server;LOG_ERROR::sync_node_jobs, stray job 21306.tyrone-cluster found on tyrone-node5
04/03/2013 05:16:17;0001;PBS_Server;Svr;PBS_Server;LOG_ERROR::sync_node_jobs, stray job 21312.tyrone-cluster found on tyrone-node4
04/03/2013 05:16:30;0001;PBS_Server;Svr;PBS_Server;LOG_ERROR::sync_node_jobs, stray job 21190.tyrone-cluster found on tyrone-node6
04/03/2013 05:16:33;0001;PBS_Server;Svr;PBS_Server;LOG_ERROR::sync_node_jobs, stray job 21306.tyrone-cluster found on tyrone-node5
04/03/2013 05:17:02;0001;PBS_Server;Svr;PBS_Server;LOG_ERROR::sync_node_jobs, stray job 21312.tyrone-cluster found on tyrone-node4
04/03/2013 05:17:15;0001;PBS_Server;Svr;PBS_Server;LOG_ERROR::sync_node_jobs, stray job 21190.tyrone-cluster found on tyrone-node6
04/03/2013 05:17:18;0001;PBS_Server;Svr;PBS_Server;LOG_ERROR::sync_node_jobs, stray job 21306.tyrone-cluster found on tyrone-node5
04/03/2013 05:17:47;0001;PBS_Server;Svr;PBS_Server;LOG_ERROR::sync_node_jobs, stray job 21312.tyrone-cluster found on tyrone-node4
04/03/2013 05:18:00;0001;PBS_Server;Svr;PBS_Server;LOG_ERROR::sync_node_jobs, stray job 21190.tyrone-cluster found on tyrone-node6
04/03/2013 05:18:03;0001;PBS_Server;Svr;PBS_Server;LOG_ERROR::sync_node_jobs, stray job 21306.tyrone-cluster found on tyrone-node5
04/03/2013 05:18:30;0002;PBS_Server;Svr;PBS_Server;Torque Server Version = 3.0.5, loglevel = 0
04/03/2013 05:18:32;0001;PBS_Server;Svr;PBS_Server;LOG_ERROR::sync_node_jobs, stray job 21312.tyrone-cluster found on tyrone-node4
04/03/2013 05:18:45;0001;PBS_Server;Svr;PBS_Server;LOG_ERROR::sync_node_jobs, stray job 21190.tyrone-cluster found on tyrone-node6
04/03/2013 05:18:48;0001;PBS_Server;Svr;PBS_Server;LOG_ERROR::sync_node_jobs, stray job 21306.tyrone-cluster found on tyrone-node5
04/03/2013 05:19:17;0001;PBS_Server;Svr;PBS_Server;LOG_ERROR::sync_node_jobs, stray job 21312.tyrone-cluster found on tyrone-node4
04/03/2013 05:19:30;0001;PBS_Server;Svr;PBS_Server;LOG_ERROR::sync_node_jobs, stray job 21190.tyrone-cluster found on tyrone-node6
04/03/2013 05:19:33;0001;PBS_Server;Svr;PBS_Server;LOG_ERROR::sync_node_jobs, stray job 21306.tyrone-cluster found on tyrone-node5
04/03/2013 05:20:01;0001;PBS_Server;Svr;PBS_Server;LOG_ERROR::sync_node_jobs, stray job 21312.tyrone-cluster found on tyrone-node4
04/03/2013 05:20:15;0001;PBS_Server;Svr;PBS_Server;LOG_ERROR::sync_node_jobs, stray job 21190.tyrone-cluster found on tyrone-node6
04/03/2013 05:20:18;0001;PBS_Server;Svr;PBS_Server;LOG_ERROR::sync_node_jobs, stray job 21306.tyrone-cluster found on tyrone-node5
04/03/2013 05:20:46;0001;PBS_Server;Svr;PBS_Server;LOG_ERROR::sync_node_jobs, stray job 21312.tyrone-cluster found on tyrone-node4
04/03/2013 05:20:59;0001;PBS_Server;Svr;PBS_Server;LOG_ERROR::sync_node_jobs, stray job 21190.tyrone-cluster found on tyrone-node6
04/03/2013 05:21:03;0001;PBS_Server;Svr;PBS_Server;LOG_ERROR::sync_node_jobs, stray job 21306.tyrone-cluster found on tyrone-node5
04/03/2013 05:21:31;0001;PBS_Server;Svr;PBS_Server;LOG_ERROR::sync_node_jobs, stray job 21312.tyrone-cluster found on tyrone-node4
04/03/2013 05:21:44;0001;PBS_Server;Svr;PBS_Server;LOG_ERROR::sync_node_jobs, stray job 21190.tyrone-cluster found on tyrone-node6
04/03/2013 05:21:47;0001;PBS_Server;Svr;PBS_Server;LOG_ERROR::sync_node_jobs, stray job 21306.tyrone-cluster found on tyrone-node5
04/03/2013 05:22:16;0001;PBS_Server;Svr;PBS_Server;LOG_ERROR::sync_node_jobs, stray job 21312.tyrone-cluster found on tyrone-node4
04/03/2013 05:22:29;0001;PBS_Server;Svr;PBS_Server;LOG_ERROR::sync_node_jobs, stray job 21190.tyrone-cluster found on tyrone-node6
04/03/2013 05:22:32;0001;PBS_Server;Svr;PBS_Server;LOG_ERROR::sync_node_jobs, stray job 21306.tyrone-cluster found on tyrone-node5
04/03/2013 05:22:44;0040;PBS_Server;Svr;tyrone-cluster;Scheduler was sent the command time
04/03/2013 05:23:01;0001;PBS_Server;Svr;PBS_Server;LOG_ERROR::sync_node_jobs, stray job 21312.tyrone-cluster found on tyrone-node4
04/03/2013 05:23:14;0001;PBS_Server;Svr;PBS_Server;LOG_ERROR::sync_node_jobs, stray job 21190.tyrone-cluster found on tyrone-node6
04/03/2013 05:23:17;0001;PBS_Server;Svr;PBS_Server;LOG_ERROR::sync_node_jobs, stray job 21306.tyrone-cluster found on tyrone-node5
04/03/2013 05:23:30;0002;PBS_Server;Svr;PBS_Server;Torque Server Version = 3.0.5, loglevel = 0
04/03/2013 05:23:46;0001;PBS_Server;Svr;PBS_Server;LOG_ERROR::sync_node_jobs, stray job 21312.tyrone-cluster found on tyrone-node4
04/03/2013 05:23:59;0001;PBS_Server;Svr;PBS_Server;LOG_ERROR::sync_node_jobs, stray job 21190.tyrone-cluster found on tyrone-node6
04/03/2013 05:24:02;0001;PBS_Server;Svr;PBS_Server;LOG_ERROR::sync_node_jobs, stray job 21306.tyrone-cluster found on tyrone-node5
04/03/2013 05:24:31;0001;PBS_Server;Svr;PBS_Server;LOG_ERROR::sync_node_jobs, stray job 21312.tyrone-cluster found on tyrone-node4
04/03/2013 05:24:44;0001;PBS_Server;Svr;PBS_Server;LOG_ERROR::sync_node_jobs, stray job 21190.tyrone-cluster found on tyrone-node6
04/03/2013 05:24:47;0001;PBS_Server;Svr;PBS_Server;LOG_ERROR::sync_node_jobs, stray job 21306.tyrone-cluster found on tyrone-node5
04/03/2013 05:25:16;0001;PBS_Server;Svr;PBS_Server;LOG_ERROR::sync_node_jobs, stray job 21312.tyrone-cluster found on tyrone-node4
04/03/2013 05:25:29;0001;PBS_Server;Svr;PBS_Server;LOG_ERROR::sync_node_jobs, stray job 21190.tyrone-cluster found on tyrone-node6
04/03/2013 05:25:32;0001;PBS_Server;Svr;PBS_Server;LOG_ERROR::sync_node_jobs, stray job 21306.tyrone-cluster found on tyrone-node5
04/03/2013 05:26:02;0001;PBS_Server;Svr;PBS_Server;LOG_ERROR::sync_node_jobs, stray job 21312.tyrone-cluster found on tyrone-node4
04/03/2013 05:26:15;0001;PBS_Server;Svr;PBS_Server;LOG_ERROR::sync_node_jobs, stray job 21190.tyrone-cluster found on tyrone-node6
04/03/2013 05:26:18;0001;PBS_Server;Svr;PBS_Server;LOG_ERROR::sync_node_jobs, stray job 21306.tyrone-cluster found on tyrone-node5
04/03/2013 05:26:47;0001;PBS_Server;Svr;PBS_Server;LOG_ERROR::sync_node_jobs, stray job 21312.tyrone-cluster found on tyrone-node4
04/03/2013 05:27:00;0001;PBS_Server;Svr;PBS_Server;LOG_ERROR::sync_node_jobs, stray job 21190.tyrone-cluster found on tyrone-node6
04/03/2013 05:27:03;0001;PBS_Server;Svr;PBS_Server;LOG_ERROR::sync_node_jobs, stray job 21306.tyrone-cluster found on tyrone-node5
04/03/2013 05:27:32;0001;PBS_Server;Svr;PBS_Server;LOG_ERROR::sync_node_jobs, stray job 21312.tyrone-cluster found on tyrone-node4
04/03/2013 05:27:45;0001;PBS_Server;Svr;PBS_Server;LOG_ERROR::sync_node_jobs, stray job 21190.tyrone-cluster found on tyrone-node6
04/03/2013 05:27:48;0001;PBS_Server;Svr;PBS_Server;LOG_ERROR::sync_node_jobs, stray job 21306.tyrone-cluster found on tyrone-node5
04/03/2013 05:28:17;0001;PBS_Server;Svr;PBS_Server;LOG_ERROR::sync_node_jobs, stray job 21312.tyrone-cluster found on tyrone-node4
04/03/2013 05:28:30;0001;PBS_Server;Svr;PBS_Server;LOG_ERROR::sync_node_jobs, stray job 21190.tyrone-cluster found on tyrone-node6
04/03/2013 05:28:30;0002;PBS_Server;Svr;PBS_Server;Torque Server Version = 3.0.5, loglevel = 0
04/03/2013 05:28:33;0001;PBS_Server;Svr;PBS_Server;LOG_ERROR::sync_node_jobs, stray job 21306.tyrone-cluster found on tyrone-node5
04/03/2013 05:29:02;0001;PBS_Server;Svr;PBS_Server;LOG_ERROR::sync_node_jobs, stray job 21312.tyrone-cluster found on tyrone-node4
04/03/2013 05:29:15;0001;PBS_Server;Svr;PBS_Server;LOG_ERROR::sync_node_jobs, stray job 21190.tyrone-cluster found on tyrone-node6
04/03/2013 05:29:18;0001;PBS_Server;Svr;PBS_Server;LOG_ERROR::sync_node_jobs, stray job 21306.tyrone-cluster found on tyrone-node5
04/03/2013 05:29:47;0001;PBS_Server;Svr;PBS_Server;LOG_ERROR::sync_node_jobs, stray job 21312.tyrone-cluster found on tyrone-node4
04/03/2013 05:30:00;0001;PBS_Server;Svr;PBS_Server;LOG_ERROR::sync_node_jobs, stray job 21190.tyrone-cluster found on tyrone-node6
04/03/2013 05:30:03;0001;PBS_Server;Svr;PBS_Server;LOG_ERROR::sync_node_jobs, stray job 21306.tyrone-cluster found on tyrone-node5
04/03/2013 05:30:31;0001;PBS_Server;Svr;PBS_Server;LOG_ERROR::sync_node_jobs, stray job 21312.tyrone-cluster found on tyrone-node4
04/03/2013 05:30:45;0001;PBS_Server;Svr;PBS_Server;LOG_ERROR::sync_node_jobs, stray job 21190.tyrone-cluster found on tyrone-node6
04/03/2013 05:30:48;0001;PBS_Server;Svr;PBS_Server;LOG_ERROR::sync_node_jobs, stray job 21306.tyrone-cluster found on tyrone-node5
04/03/2013 05:31:16;0001;PBS_Server;Svr;PBS_Server;LOG_ERROR::sync_node_jobs, stray job 21312.tyrone-cluster found on tyrone-node4
04/03/2013 05:31:30;0001;PBS_Server;Svr;PBS_Server;LOG_ERROR::sync_node_jobs, stray job 21190.tyrone-cluster found on tyrone-node6
04/03/2013 05:31:33;0001;PBS_Server;Svr;PBS_Server;LOG_ERROR::sync_node_jobs, stray job 21306.tyrone-cluster found on tyrone-node5
04/03/2013 05:32:01;0001;PBS_Server;Svr;PBS_Server;LOG_ERROR::sync_node_jobs, stray job 21312.tyrone-cluster found on tyrone-node4
04/03/2013 05:32:15;0001;PBS_Server;Svr;PBS_Server;LOG_ERROR::sync_node_jobs, stray job 21190.tyrone-cluster found on tyrone-node6
04/03/2013 05:32:18;0001;PBS_Server;Svr;PBS_Server;LOG_ERROR::sync_node_jobs, stray job 21306.tyrone-cluster found on tyrone-node5
04/03/2013 05:32:44;0040;PBS_Server;Svr;tyrone-cluster;Scheduler was sent the command time
04/03/2013 05:32:46;0001;PBS_Server;Svr;PBS_Server;LOG_ERROR::sync_node_jobs, stray job 21312.tyrone-cluster found on tyrone-node4
04/03/2013 05:32:59;0001;PBS_Server;Svr;PBS_Server;LOG_ERROR::sync_node_jobs, stray job 21190.tyrone-cluster found on tyrone-node6
04/03/2013 05:33:02;0001;PBS_Server;Svr;PBS_Server;LOG_ERROR::sync_node_jobs, stray job 21306.tyrone-cluster found on tyrone-node5
04/03/2013 05:33:30;0002;PBS_Server;Svr;PBS_Server;Torque Server Version = 3.0.5, loglevel = 0
04/03/2013 05:33:31;0001;PBS_Server;Svr;PBS_Server;LOG_ERROR::sync_node_jobs, stray job 21312.tyrone-cluster found on tyrone-node4
04/03/2013 05:33:44;0001;PBS_Server;Svr;PBS_Server;LOG_ERROR::sync_node_jobs, stray job 21190.tyrone-cluster found on tyrone-node6
04/03/2013 05:33:47;0001;PBS_Server;Svr;PBS_Server;LOG_ERROR::sync_node_jobs, stray job 21306.tyrone-cluster found on tyrone-node5
04/03/2013 05:34:16;0001;PBS_Server;Svr;PBS_Server;LOG_ERROR::sync_node_jobs, stray job 21312.tyrone-cluster found on tyrone-node4
04/03/2013 05:34:29;0001;PBS_Server;Svr;PBS_Server;LOG_ERROR::sync_node_jobs, stray job 21190.tyrone-cluster found on tyrone-node6
04/03/2013 05:34:32;0001;PBS_Server;Svr;PBS_Server;LOG_ERROR::sync_node_jobs, stray job 21306.tyrone-cluster found on tyrone-node5
04/03/2013 05:35:01;0001;PBS_Server;Svr;PBS_Server;LOG_ERROR::sync_node_jobs, stray job 21312.tyrone-cluster found on tyrone-node4
04/03/2013 05:35:14;0001;PBS_Server;Svr;PBS_Server;LOG_ERROR::sync_node_jobs, stray job 21190.tyrone-cluster found on tyrone-node6
04/03/2013 05:35:17;0001;PBS_Server;Svr;PBS_Server;LOG_ERROR::sync_node_jobs, stray job 21306.tyrone-cluster found on tyrone-node5
04/03/2013 05:35:46;0001;PBS_Server;Svr;PBS_Server;LOG_ERROR::sync_node_jobs, stray job 21312.tyrone-cluster found on tyrone-node4
04/03/2013 05:35:59;0001;PBS_Server;Svr;PBS_Server;LOG_ERROR::sync_node_jobs, stray job 21190.tyrone-cluster found on tyrone-node6
04/03/2013 05:36:02;0001;PBS_Server;Svr;PBS_Server;LOG_ERROR::sync_node_jobs, stray job 21306.tyrone-cluster found on tyrone-node5
04/03/2013 05:36:31;0001;PBS_Server;Svr;PBS_Server;LOG_ERROR::sync_node_jobs, stray job 21312.tyrone-cluster found on tyrone-node4
04/03/2013 05:36:44;0001;PBS_Server;Svr;PBS_Server;LOG_ERROR::sync_node_jobs, stray job 21190.tyrone-cluster found on tyrone-node6
04/03/2013 05:36:47;0001;PBS_Server;Svr;PBS_Server;LOG_ERROR::sync_node_jobs, stray job 21306.tyrone-cluster found on tyrone-node5
04/03/2013 05:37:16;0001;PBS_Server;Svr;PBS_Server;LOG_ERROR::sync_node_jobs, stray job 21312.tyrone-cluster found on tyrone-node4
04/03/2013 05:37:29;0001;PBS_Server;Svr;PBS_Server;LOG_ERROR::sync_node_jobs, stray job 21190.tyrone-cluster found on tyrone-node6
04/03/2013 05:37:32;0001;PBS_Server;Svr;PBS_Server;LOG_ERROR::sync_node_jobs, stray job 21306.tyrone-cluster found on tyrone-node5
04/03/2013 05:38:02;0001;PBS_Server;Svr;PBS_Server;LOG_ERROR::sync_node_jobs, stray job 21312.tyrone-cluster found on tyrone-node4
04/03/2013 05:38:14;0001;PBS_Server;Svr;PBS_Server;LOG_ERROR::sync_node_jobs, stray job 21190.tyrone-cluster found on tyrone-node6
04/03/2013 05:38:17;0001;PBS_Server;Svr;PBS_Server;LOG_ERROR::sync_node_jobs, stray job 21306.tyrone-cluster found on tyrone-node5
04/03/2013 05:38:30;0002;PBS_Server;Svr;PBS_Server;Torque Server Version = 3.0.5, loglevel = 0
04/03/2013 05:38:47;0001;PBS_Server;Svr;PBS_Server;LOG_ERROR::sync_node_jobs, stray job 21312.tyrone-cluster found on tyrone-node4
04/03/2013 05:39:00;0001;PBS_Server;Svr;PBS_Server;LOG_ERROR::sync_node_jobs, stray job 21190.tyrone-cluster found on tyrone-node6
04/03/2013 05:39:03;0001;PBS_Server;Svr;PBS_Server;LOG_ERROR::sync_node_jobs, stray job 21306.tyrone-cluster found on tyrone-node5
04/03/2013 05:39:32;0001;PBS_Server;Svr;PBS_Server;LOG_ERROR::sync_node_jobs, stray job 21312.tyrone-cluster found on tyrone-node4
04/03/2013 05:39:45;0001;PBS_Server;Svr;PBS_Server;LOG_ERROR::sync_node_jobs, stray job 21190.tyrone-cluster found on tyrone-node6
04/03/2013 05:39:48;0001;PBS_Server;Svr;PBS_Server;LOG_ERROR::sync_node_jobs, stray job 21306.tyrone-cluster found on tyrone-node5
04/03/2013 05:40:16;0001;PBS_Server;Svr;PBS_Server;LOG_ERROR::sync_node_jobs, stray job 21312.tyrone-cluster found on tyrone-node4
04/03/2013 05:40:30;0001;PBS_Server;Svr;PBS_Server;LOG_ERROR::sync_node_jobs, stray job 21190.tyrone-cluster found on tyrone-node6
04/03/2013 05:40:33;0001;PBS_Server;Svr;PBS_Server;LOG_ERROR::sync_node_jobs, stray job 21306.tyrone-cluster found on tyrone-node5
04/03/2013 05:41:01;0001;PBS_Server;Svr;PBS_Server;LOG_ERROR::sync_node_jobs, stray job 21312.tyrone-cluster found on tyrone-node4
04/03/2013 05:41:15;0001;PBS_Server;Svr;PBS_Server;LOG_ERROR::sync_node_jobs, stray job 21190.tyrone-cluster found on tyrone-node6
04/03/2013 05:41:18;0001;PBS_Server;Svr;PBS_Server;LOG_ERROR::sync_node_jobs, stray job 21306.tyrone-cluster found on tyrone-node5
04/03/2013 05:41:46;0001;PBS_Server;Svr;PBS_Server;LOG_ERROR::sync_node_jobs, stray job 21312.tyrone-cluster found on tyrone-node4
04/03/2013 05:42:00;0001;PBS_Server;Svr;PBS_Server;LOG_ERROR::sync_node_jobs, stray job 21190.tyrone-cluster found on tyrone-node6
04/03/2013 05:42:03;0001;PBS_Server;Svr;PBS_Server;LOG_ERROR::sync_node_jobs, stray job 21306.tyrone-cluster found on tyrone-node5
04/03/2013 05:42:31;0001;PBS_Server;Svr;PBS_Server;LOG_ERROR::sync_node_jobs, stray job 21312.tyrone-cluster found on tyrone-node4
04/03/2013 05:42:44;0040;PBS_Server;Svr;tyrone-cluster;Scheduler was sent the command time
04/03/2013 05:42:44;0001;PBS_Server;Svr;PBS_Server;LOG_ERROR::sync_node_jobs, stray job 21190.tyrone-cluster found on tyrone-node6
04/03/2013 05:42:48;0001;PBS_Server;Svr;PBS_Server;LOG_ERROR::sync_node_jobs, stray job 21306.tyrone-cluster found on tyrone-node5
04/03/2013 05:43:16;0001;PBS_Server;Svr;PBS_Server;LOG_ERROR::sync_node_jobs, stray job 21312.tyrone-cluster found on tyrone-node4
04/03/2013 05:43:29;0001;PBS_Server;Svr;PBS_Server;LOG_ERROR::sync_node_jobs, stray job 21190.tyrone-cluster found on tyrone-node6
04/03/2013 05:43:30;0002;PBS_Server;Svr;PBS_Server;Torque Server Version = 3.0.5, loglevel = 0
04/03/2013 05:43:33;0001;PBS_Server;Svr;PBS_Server;LOG_ERROR::sync_node_jobs, stray job 21306.tyrone-cluster found on tyrone-node5
04/03/2013 05:44:01;0001;PBS_Server;Svr;PBS_Server;LOG_ERROR::sync_node_jobs, stray job 21312.tyrone-cluster found on tyrone-node4
04/03/2013 05:44:14;0001;PBS_Server;Svr;PBS_Server;LOG_ERROR::sync_node_jobs, stray job 21190.tyrone-cluster found on tyrone-node6
04/03/2013 05:44:18;0001;PBS_Server;Svr;PBS_Server;LOG_ERROR::sync_node_jobs, stray job 21306.tyrone-cluster found on tyrone-node5
04/03/2013 05:44:46;0001;PBS_Server;Svr;PBS_Server;LOG_ERROR::sync_node_jobs, stray job 21312.tyrone-cluster found on tyrone-node4
04/03/2013 05:44:59;0001;PBS_Server;Svr;PBS_Server;LOG_ERROR::sync_node_jobs, stray job 21190.tyrone-cluster found on tyrone-node6
04/03/2013 05:45:03;0001;PBS_Server;Svr;PBS_Server;LOG_ERROR::sync_node_jobs, stray job 21306.tyrone-cluster found on tyrone-node5
04/03/2013 05:45:31;0001;PBS_Server;Svr;PBS_Server;LOG_ERROR::sync_node_jobs, stray job 21312.tyrone-cluster found on tyrone-node4
04/03/2013 05:45:44;0001;PBS_Server;Svr;PBS_Server;LOG_ERROR::sync_node_jobs, stray job 21190.tyrone-cluster found on tyrone-node6
04/03/2013 05:45:47;0001;PBS_Server;Svr;PBS_Server;LOG_ERROR::sync_node_jobs, stray job 21306.tyrone-cluster found on tyrone-node5
04/03/2013 05:46:16;0001;PBS_Server;Svr;PBS_Server;LOG_ERROR::sync_node_jobs, stray job 21312.tyrone-cluster found on tyrone-node4
04/03/2013 05:46:29;0001;PBS_Server;Svr;PBS_Server;LOG_ERROR::sync_node_jobs, stray job 21190.tyrone-cluster found on tyrone-node6
04/03/2013 05:46:32;0001;PBS_Server;Svr;PBS_Server;LOG_ERROR::sync_node_jobs, stray job 21306.tyrone-cluster found on tyrone-node5
04/03/2013 05:47:01;0001;PBS_Server;Svr;PBS_Server;LOG_ERROR::sync_node_jobs, stray job 21312.tyrone-cluster found on tyrone-node4
04/03/2013 05:47:14;0001;PBS_Server;Svr;PBS_Server;LOG_ERROR::sync_node_jobs, stray job 21190.tyrone-cluster found on tyrone-node6
04/03/2013 05:47:17;0001;PBS_Server;Svr;PBS_Server;LOG_ERROR::sync_node_jobs, stray job 21306.tyrone-cluster found on tyrone-node5
04/03/2013 05:47:46;0001;PBS_Server;Svr;PBS_Server;LOG_ERROR::sync_node_jobs, stray job 21312.tyrone-cluster found on tyrone-node4
04/03/2013 05:47:59;0001;PBS_Server;Svr;PBS_Server;LOG_ERROR::sync_node_jobs, stray job 21190.tyrone-cluster found on tyrone-node6
04/03/2013 05:48:02;0001;PBS_Server;Svr;PBS_Server;LOG_ERROR::sync_node_jobs, stray job 21306.tyrone-cluster found on tyrone-node5
04/03/2013 05:48:30;0002;PBS_Server;Svr;PBS_Server;Torque Server Version = 3.0.5, loglevel = 0
04/03/2013 05:48:30;0001;PBS_Server;Svr;PBS_Server;LOG_ERROR::sync_node_jobs, stray job 21312.tyrone-cluster found on tyrone-node4
04/03/2013 05:48:44;0001;PBS_Server;Svr;PBS_Server;LOG_ERROR::sync_node_jobs, stray job 21190.tyrone-cluster found on tyrone-node6
04/03/2013 05:48:47;0001;PBS_Server;Svr;PBS_Server;LOG_ERROR::sync_node_jobs, stray job 21306.tyrone-cluster found on tyrone-node5
04/03/2013 05:49:16;0001;PBS_Server;Svr;PBS_Server;LOG_ERROR::sync_node_jobs, stray job 21312.tyrone-cluster found on tyrone-node4
04/03/2013 05:49:29;0001;PBS_Server;Svr;PBS_Server;LOG_ERROR::sync_node_jobs, stray job 21190.tyrone-cluster found on tyrone-node6
04/03/2013 05:49:32;0001;PBS_Server;Svr;PBS_Server;LOG_ERROR::sync_node_jobs, stray job 21306.tyrone-cluster found on tyrone-node5
04/03/2013 05:50:01;0001;PBS_Server;Svr;PBS_Server;LOG_ERROR::sync_node_jobs, stray job 21312.tyrone-cluster found on tyrone-node4
04/03/2013 05:50:14;0001;PBS_Server;Svr;PBS_Server;LOG_ERROR::sync_node_jobs, stray job 21190.tyrone-cluster found on tyrone-node6
04/03/2013 05:50:17;0001;PBS_Server;Svr;PBS_Server;LOG_ERROR::sync_node_jobs, stray job 21306.tyrone-cluster found on tyrone-node5
04/03/2013 05:50:46;0001;PBS_Server;Svr;PBS_Server;LOG_ERROR::sync_node_jobs, stray job 21312.tyrone-cluster found on tyrone-node4
04/03/2013 05:51:00;0001;PBS_Server;Svr;PBS_Server;LOG_ERROR::sync_node_jobs, stray job 21190.tyrone-cluster found on tyrone-node6
04/03/2013 05:51:02;0001;PBS_Server;Svr;PBS_Server;LOG_ERROR::sync_node_jobs, stray job 21306.tyrone-cluster found on tyrone-node5
04/03/2013 05:51:31;0001;PBS_Server;Svr;PBS_Server;LOG_ERROR::sync_node_jobs, stray job 21312.tyrone-cluster found on tyrone-node4
04/03/2013 05:51:45;0001;PBS_Server;Svr;PBS_Server;LOG_ERROR::sync_node_jobs, stray job 21190.tyrone-cluster found on tyrone-node6
04/03/2013 05:51:48;0001;PBS_Server;Svr;PBS_Server;LOG_ERROR::sync_node_jobs, stray job 21306.tyrone-cluster found on tyrone-node5
04/03/2013 05:52:16;0001;PBS_Server;Svr;PBS_Server;LOG_ERROR::sync_node_jobs, stray job 21312.tyrone-cluster found on tyrone-node4
04/03/2013 05:52:30;0001;PBS_Server;Svr;PBS_Server;LOG_ERROR::sync_node_jobs, stray job 21190.tyrone-cluster found on tyrone-node6
04/03/2013 05:52:33;0001;PBS_Server;Svr;PBS_Server;LOG_ERROR::sync_node_jobs, stray job 21306.tyrone-cluster found on tyrone-node5
04/03/2013 05:52:44;0040;PBS_Server;Svr;tyrone-cluster;Scheduler was sent the command time
04/03/2013 05:53:01;0001;PBS_Server;Svr;PBS_Server;LOG_ERROR::sync_node_jobs, stray job 21312.tyrone-cluster found on tyrone-node4
04/03/2013 05:53:15;0001;PBS_Server;Svr;PBS_Server;LOG_ERROR::sync_node_jobs, stray job 21190.tyrone-cluster found on tyrone-node6
04/03/2013 05:53:18;0001;PBS_Server;Svr;PBS_Server;LOG_ERROR::sync_node_jobs, stray job 21306.tyrone-cluster found on tyrone-node5
04/03/2013 05:53:30;0002;PBS_Server;Svr;PBS_Server;Torque Server Version = 3.0.5, loglevel = 0
04/03/2013 05:53:46;0001;PBS_Server;Svr;PBS_Server;LOG_ERROR::sync_node_jobs, stray job 21312.tyrone-cluster found on tyrone-node4
04/03/2013 05:54:00;0001;PBS_Server;Svr;PBS_Server;LOG_ERROR::sync_node_jobs, stray job 21190.tyrone-cluster found on tyrone-node6
04/03/2013 05:54:03;0001;PBS_Server;Svr;PBS_Server;LOG_ERROR::sync_node_jobs, stray job 21306.tyrone-cluster found on tyrone-node5
04/03/2013 05:54:31;0001;PBS_Server;Svr;PBS_Server;LOG_ERROR::sync_node_jobs, stray job 21312.tyrone-cluster found on tyrone-node4
04/03/2013 05:54:45;0001;PBS_Server;Svr;PBS_Server;LOG_ERROR::sync_node_jobs, stray job 21190.tyrone-cluster found on tyrone-node6
04/03/2013 05:54:48;0001;PBS_Server;Svr;PBS_Server;LOG_ERROR::sync_node_jobs, stray job 21306.tyrone-cluster found on tyrone-node5
04/03/2013 05:55:16;0001;PBS_Server;Svr;PBS_Server;LOG_ERROR::sync_node_jobs, stray job 21312.tyrone-cluster found on tyrone-node4
04/03/2013 05:55:29;0001;PBS_Server;Svr;PBS_Server;LOG_ERROR::sync_node_jobs, stray job 21190.tyrone-cluster found on tyrone-node6
04/03/2013 05:55:33;0001;PBS_Server;Svr;PBS_Server;LOG_ERROR::sync_node_jobs, stray job 21306.tyrone-cluster found on tyrone-node5
04/03/2013 05:56:01;0001;PBS_Server;Svr;PBS_Server;LOG_ERROR::sync_node_jobs, stray job 21312.tyrone-cluster found on tyrone-node4
04/03/2013 05:56:14;0001;PBS_Server;Svr;PBS_Server;LOG_ERROR::sync_node_jobs, stray job 21190.tyrone-cluster found on tyrone-node6
04/03/2013 05:56:18;0001;PBS_Server;Svr;PBS_Server;LOG_ERROR::sync_node_jobs, stray job 21306.tyrone-cluster found on tyrone-node5
04/03/2013 05:56:46;0001;PBS_Server;Svr;PBS_Server;LOG_ERROR::sync_node_jobs, stray job 21312.tyrone-cluster found on tyrone-node4
04/03/2013 05:56:59;0001;PBS_Server;Svr;PBS_Server;LOG_ERROR::sync_node_jobs, stray job 21190.tyrone-cluster found on tyrone-node6
04/03/2013 05:57:03;0001;PBS_Server;Svr;PBS_Server;LOG_ERROR::sync_node_jobs, stray job 21306.tyrone-cluster found on tyrone-node5
04/03/2013 05:57:31;0001;PBS_Server;Svr;PBS_Server;LOG_ERROR::sync_node_jobs, stray job 21312.tyrone-cluster found on tyrone-node4
04/03/2013 05:57:44;0001;PBS_Server;Svr;PBS_Server;LOG_ERROR::sync_node_jobs, stray job 21190.tyrone-cluster found on tyrone-node6
04/03/2013 05:57:47;0001;PBS_Server;Svr;PBS_Server;LOG_ERROR::sync_node_jobs, stray job 21306.tyrone-cluster found on tyrone-node5
04/03/2013 05:58:16;0001;PBS_Server;Svr;PBS_Server;LOG_ERROR::sync_node_jobs, stray job 21312.tyrone-cluster found on tyrone-node4
04/03/2013 05:58:29;0001;PBS_Server;Svr;PBS_Server;LOG_ERROR::sync_node_jobs, stray job 21190.tyrone-cluster found on tyrone-node6
04/03/2013 05:58:30;0002;PBS_Server;Svr;PBS_Server;Torque Server Version = 3.0.5, loglevel = 0
04/03/2013 05:58:32;0001;PBS_Server;Svr;PBS_Server;LOG_ERROR::sync_node_jobs, stray job 21306.tyrone-cluster found on tyrone-node5
04/03/2013 05:59:01;0001;PBS_Server;Svr;PBS_Server;LOG_ERROR::sync_node_jobs, stray job 21312.tyrone-cluster found on tyrone-node4
04/03/2013 05:59:14;0001;PBS_Server;Svr;PBS_Server;LOG_ERROR::sync_node_jobs, stray job 21190.tyrone-cluster found on tyrone-node6
04/03/2013 05:59:17;0001;PBS_Server;Svr;PBS_Server;LOG_ERROR::sync_node_jobs, stray job 21306.tyrone-cluster found on tyrone-node5
04/03/2013 05:59:45;0001;PBS_Server;Svr;PBS_Server;LOG_ERROR::sync_node_jobs, stray job 21312.tyrone-cluster found on tyrone-node4
04/03/2013 05:59:59;0001;PBS_Server;Svr;PBS_Server;LOG_ERROR::sync_node_jobs, stray job 21190.tyrone-cluster found on tyrone-node6
04/03/2013 06:00:02;0001;PBS_Server;Svr;PBS_Server;LOG_ERROR::sync_node_jobs, stray job 21306.tyrone-cluster found on tyrone-node5
04/03/2013 06:00:30;0001;PBS_Server;Svr;PBS_Server;LOG_ERROR::sync_node_jobs, stray job 21312.tyrone-cluster found on tyrone-node4
04/03/2013 06:00:44;0001;PBS_Server;Svr;PBS_Server;LOG_ERROR::sync_node_jobs, stray job 21190.tyrone-cluster found on tyrone-node6
04/03/2013 06:00:47;0001;PBS_Server;Svr;PBS_Server;LOG_ERROR::sync_node_jobs, stray job 21306.tyrone-cluster found on tyrone-node5
04/03/2013 06:01:15;0001;PBS_Server;Svr;PBS_Server;LOG_ERROR::sync_node_jobs, stray job 21312.tyrone-cluster found on tyrone-node4
04/03/2013 06:01:29;0001;PBS_Server;Svr;PBS_Server;LOG_ERROR::sync_node_jobs, stray job 21190.tyrone-cluster found on tyrone-node6
04/03/2013 06:01:32;0001;PBS_Server;Svr;PBS_Server;LOG_ERROR::sync_node_jobs, stray job 21306.tyrone-cluster found on tyrone-node5
04/03/2013 06:02:00;0001;PBS_Server;Svr;PBS_Server;LOG_ERROR::sync_node_jobs, stray job 21312.tyrone-cluster found on tyrone-node4
04/03/2013 06:02:14;0001;PBS_Server;Svr;PBS_Server;LOG_ERROR::sync_node_jobs, stray job 21190.tyrone-cluster found on tyrone-node6
04/03/2013 06:02:17;0001;PBS_Server;Svr;PBS_Server;LOG_ERROR::sync_node_jobs, stray job 21306.tyrone-cluster found on tyrone-node5
04/03/2013 06:02:44;0040;PBS_Server;Svr;tyrone-cluster;Scheduler was sent the command time
04/03/2013 06:02:46;0001;PBS_Server;Svr;PBS_Server;LOG_ERROR::sync_node_jobs, stray job 21312.tyrone-cluster found on tyrone-node4
04/03/2013 06:03:00;0001;PBS_Server;Svr;PBS_Server;LOG_ERROR::sync_node_jobs, stray job 21190.tyrone-cluster found on tyrone-node6
04/03/2013 06:03:03;0001;PBS_Server;Svr;PBS_Server;LOG_ERROR::sync_node_jobs, stray job 21306.tyrone-cluster found on tyrone-node5
04/03/2013 06:03:30;0002;PBS_Server;Svr;PBS_Server;Torque Server Version = 3.0.5, loglevel = 0
04/03/2013 06:03:31;0001;PBS_Server;Svr;PBS_Server;LOG_ERROR::sync_node_jobs, stray job 21312.tyrone-cluster found on tyrone-node4
04/03/2013 06:03:45;0001;PBS_Server;Svr;PBS_Server;LOG_ERROR::sync_node_jobs, stray job 21190.tyrone-cluster found on tyrone-node6
04/03/2013 06:03:48;0001;PBS_Server;Svr;PBS_Server;LOG_ERROR::sync_node_jobs, stray job 21306.tyrone-cluster found on tyrone-node5
04/03/2013 06:04:16;0001;PBS_Server;Svr;PBS_Server;LOG_ERROR::sync_node_jobs, stray job 21312.tyrone-cluster found on tyrone-node4
04/03/2013 06:04:30;0001;PBS_Server;Svr;PBS_Server;LOG_ERROR::sync_node_jobs, stray job 21190.tyrone-cluster found on tyrone-node6
04/03/2013 06:04:33;0001;PBS_Server;Svr;PBS_Server;LOG_ERROR::sync_node_jobs, stray job 21306.tyrone-cluster found on tyrone-node5
04/03/2013 06:05:01;0001;PBS_Server;Svr;PBS_Server;LOG_ERROR::sync_node_jobs, stray job 21312.tyrone-cluster found on tyrone-node4
04/03/2013 06:05:15;0001;PBS_Server;Svr;PBS_Server;LOG_ERROR::sync_node_jobs, stray job 21190.tyrone-cluster found on tyrone-node6
04/03/2013 06:05:18;0001;PBS_Server;Svr;PBS_Server;LOG_ERROR::sync_node_jobs, stray job 21306.tyrone-cluster found on tyrone-node5
04/03/2013 06:05:46;0001;PBS_Server;Svr;PBS_Server;LOG_ERROR::sync_node_jobs, stray job 21312.tyrone-cluster found on tyrone-node4
04/03/2013 06:06:00;0001;PBS_Server;Svr;PBS_Server;LOG_ERROR::sync_node_jobs, stray job 21190.tyrone-cluster found on tyrone-node6
04/03/2013 06:06:03;0001;PBS_Server;Svr;PBS_Server;LOG_ERROR::sync_node_jobs, stray job 21306.tyrone-cluster found on tyrone-node5
04/03/2013 06:06:31;0001;PBS_Server;Svr;PBS_Server;LOG_ERROR::sync_node_jobs, stray job 21312.tyrone-cluster found on tyrone-node4
04/03/2013 06:06:45;0001;PBS_Server;Svr;PBS_Server;LOG_ERROR::sync_node_jobs, stray job 21190.tyrone-cluster found on tyrone-node6
04/03/2013 06:06:48;0001;PBS_Server;Svr;PBS_Server;LOG_ERROR::sync_node_jobs, stray job 21306.tyrone-cluster found on tyrone-node5
04/03/2013 06:07:16;0001;PBS_Server;Svr;PBS_Server;LOG_ERROR::sync_node_jobs, stray job 21312.tyrone-cluster found on tyrone-node4
04/03/2013 06:07:29;0001;PBS_Server;Svr;PBS_Server;LOG_ERROR::sync_node_jobs, stray job 21190.tyrone-cluster found on tyrone-node6
04/03/2013 06:07:33;0001;PBS_Server;Svr;PBS_Server;LOG_ERROR::sync_node_jobs, stray job 21306.tyrone-cluster found on tyrone-node5
04/03/2013 06:08:01;0001;PBS_Server;Svr;PBS_Server;LOG_ERROR::sync_node_jobs, stray job 21312.tyrone-cluster found on tyrone-node4
04/03/2013 06:08:14;0001;PBS_Server;Svr;PBS_Server;LOG_ERROR::sync_node_jobs, stray job 21190.tyrone-cluster found on tyrone-node6
04/03/2013 06:08:18;0001;PBS_Server;Svr;PBS_Server;LOG_ERROR::sync_node_jobs, stray job 21306.tyrone-cluster found on tyrone-node5
04/03/2013 06:08:30;0002;PBS_Server;Svr;PBS_Server;Torque Server Version = 3.0.5, loglevel = 0
04/03/2013 06:08:46;0001;PBS_Server;Svr;PBS_Server;LOG_ERROR::sync_node_jobs, stray job 21312.tyrone-cluster found on tyrone-node4
04/03/2013 06:08:59;0001;PBS_Server;Svr;PBS_Server;LOG_ERROR::sync_node_jobs, stray job 21190.tyrone-cluster found on tyrone-node6
04/03/2013 06:09:03;0001;PBS_Server;Svr;PBS_Server;LOG_ERROR::sync_node_jobs, stray job 21306.tyrone-cluster found on tyrone-node5
04/03/2013 06:09:30;0001;PBS_Server;Svr;PBS_Server;LOG_ERROR::sync_node_jobs, stray job 21312.tyrone-cluster found on tyrone-node4
04/03/2013 06:09:44;0001;PBS_Server;Svr;PBS_Server;LOG_ERROR::sync_node_jobs, stray job 21190.tyrone-cluster found on tyrone-node6
04/03/2013 06:09:47;0001;PBS_Server;Svr;PBS_Server;LOG_ERROR::sync_node_jobs, stray job 21306.tyrone-cluster found on tyrone-node5
04/03/2013 06:10:15;0001;PBS_Server;Svr;PBS_Server;LOG_ERROR::sync_node_jobs, stray job 21312.tyrone-cluster found on tyrone-node4
04/03/2013 06:10:29;0001;PBS_Server;Svr;PBS_Server;LOG_ERROR::sync_node_jobs, stray job 21190.tyrone-cluster found on tyrone-node6
04/03/2013 06:10:32;0001;PBS_Server;Svr;PBS_Server;LOG_ERROR::sync_node_jobs, stray job 21306.tyrone-cluster found on tyrone-node5
04/03/2013 06:11:00;0001;PBS_Server;Svr;PBS_Server;LOG_ERROR::sync_node_jobs, stray job 21312.tyrone-cluster found on tyrone-node4
04/03/2013 06:11:14;0001;PBS_Server;Svr;PBS_Server;LOG_ERROR::sync_node_jobs, stray job 21190.tyrone-cluster found on tyrone-node6
04/03/2013 06:11:17;0001;PBS_Server;Svr;PBS_Server;LOG_ERROR::sync_node_jobs, stray job 21306.tyrone-cluster found on tyrone-node5
04/03/2013 06:11:45;0001;PBS_Server;Svr;PBS_Server;LOG_ERROR::sync_node_jobs, stray job 21312.tyrone-cluster found on tyrone-node4
04/03/2013 06:11:59;0001;PBS_Server;Svr;PBS_Server;LOG_ERROR::sync_node_jobs, stray job 21190.tyrone-cluster found on tyrone-node6
04/03/2013 06:12:02;0001;PBS_Server;Svr;PBS_Server;LOG_ERROR::sync_node_jobs, stray job 21306.tyrone-cluster found on tyrone-node5
04/03/2013 06:12:30;0001;PBS_Server;Svr;PBS_Server;LOG_ERROR::sync_node_jobs, stray job 21312.tyrone-cluster found on tyrone-node4
04/03/2013 06:12:44;0001;PBS_Server;Svr;PBS_Server;LOG_ERROR::sync_node_jobs, stray job 21190.tyrone-cluster found on tyrone-node6
04/03/2013 06:12:44;0040;PBS_Server;Svr;tyrone-cluster;Scheduler was sent the command time
04/03/2013 06:12:47;0001;PBS_Server;Svr;PBS_Server;LOG_ERROR::sync_node_jobs, stray job 21306.tyrone-cluster found on tyrone-node5
04/03/2013 06:13:15;0001;PBS_Server;Svr;PBS_Server;LOG_ERROR::sync_node_jobs, stray job 21312.tyrone-cluster found on tyrone-node4
04/03/2013 06:13:29;0001;PBS_Server;Svr;PBS_Server;LOG_ERROR::sync_node_jobs, stray job 21190.tyrone-cluster found on tyrone-node6
04/03/2013 06:13:30;0002;PBS_Server;Svr;PBS_Server;Torque Server Version = 3.0.5, loglevel = 0
04/03/2013 06:13:32;0001;PBS_Server;Svr;PBS_Server;LOG_ERROR::sync_node_jobs, stray job 21306.tyrone-cluster found on tyrone-node5
04/03/2013 06:14:00;0001;PBS_Server;Svr;PBS_Server;LOG_ERROR::sync_node_jobs, stray job 21312.tyrone-cluster found on tyrone-node4
04/03/2013 06:14:14;0001;PBS_Server;Svr;PBS_Server;LOG_ERROR::sync_node_jobs, stray job 21190.tyrone-cluster found on tyrone-node6
04/03/2013 06:14:17;0001;PBS_Server;Svr;PBS_Server;LOG_ERROR::sync_node_jobs, stray job 21306.tyrone-cluster found on tyrone-node5
04/03/2013 06:14:46;0001;PBS_Server;Svr;PBS_Server;LOG_ERROR::sync_node_jobs, stray job 21312.tyrone-cluster found on tyrone-node4
04/03/2013 06:14:59;0001;PBS_Server;Svr;PBS_Server;LOG_ERROR::sync_node_jobs, stray job 21190.tyrone-cluster found on tyrone-node6
04/03/2013 06:15:02;0001;PBS_Server;Svr;PBS_Server;LOG_ERROR::sync_node_jobs, stray job 21306.tyrone-cluster found on tyrone-node5
04/03/2013 06:15:30;0001;PBS_Server;Svr;PBS_Server;LOG_ERROR::sync_node_jobs, stray job 21312.tyrone-cluster found on tyrone-node4
04/03/2013 06:15:45;0001;PBS_Server;Svr;PBS_Server;LOG_ERROR::sync_node_jobs, stray job 21190.tyrone-cluster found on tyrone-node6
04/03/2013 06:15:48;0001;PBS_Server;Svr;PBS_Server;LOG_ERROR::sync_node_jobs, stray job 21306.tyrone-cluster found on tyrone-node5
04/03/2013 06:16:16;0001;PBS_Server;Svr;PBS_Server;LOG_ERROR::sync_node_jobs, stray job 21312.tyrone-cluster found on tyrone-node4
04/03/2013 06:16:30;0001;PBS_Server;Svr;PBS_Server;LOG_ERROR::sync_node_jobs, stray job 21190.tyrone-cluster found on tyrone-node6
04/03/2013 06:16:33;0001;PBS_Server;Svr;PBS_Server;LOG_ERROR::sync_node_jobs, stray job 21306.tyrone-cluster found on tyrone-node5
04/03/2013 06:17:01;0001;PBS_Server;Svr;PBS_Server;LOG_ERROR::sync_node_jobs, stray job 21312.tyrone-cluster found on tyrone-node4
04/03/2013 06:17:15;0001;PBS_Server;Svr;PBS_Server;LOG_ERROR::sync_node_jobs, stray job 21190.tyrone-cluster found on tyrone-node6
04/03/2013 06:17:18;0001;PBS_Server;Svr;PBS_Server;LOG_ERROR::sync_node_jobs, stray job 21306.tyrone-cluster found on tyrone-node5
04/03/2013 06:17:46;0001;PBS_Server;Svr;PBS_Server;LOG_ERROR::sync_node_jobs, stray job 21312.tyrone-cluster found on tyrone-node4
04/03/2013 06:18:00;0001;PBS_Server;Svr;PBS_Server;LOG_ERROR::sync_node_jobs, stray job 21190.tyrone-cluster found on tyrone-node6
04/03/2013 06:18:03;0001;PBS_Server;Svr;PBS_Server;LOG_ERROR::sync_node_jobs, stray job 21306.tyrone-cluster found on tyrone-node5
04/03/2013 06:18:30;0002;PBS_Server;Svr;PBS_Server;Torque Server Version = 3.0.5, loglevel = 0
04/03/2013 06:18:31;0001;PBS_Server;Svr;PBS_Server;LOG_ERROR::sync_node_jobs, stray job 21312.tyrone-cluster found on tyrone-node4
04/03/2013 06:18:44;0001;PBS_Server;Svr;PBS_Server;LOG_ERROR::sync_node_jobs, stray job 21190.tyrone-cluster found on tyrone-node6
04/03/2013 06:18:48;0001;PBS_Server;Svr;PBS_Server;LOG_ERROR::sync_node_jobs, stray job 21306.tyrone-cluster found on tyrone-node5
04/03/2013 06:19:15;0001;PBS_Server;Svr;PBS_Server;LOG_ERROR::sync_node_jobs, stray job 21312.tyrone-cluster found on tyrone-node4
04/03/2013 06:19:29;0001;PBS_Server;Svr;PBS_Server;LOG_ERROR::sync_node_jobs, stray job 21190.tyrone-cluster found on tyrone-node6
04/03/2013 06:19:33;0001;PBS_Server;Svr;PBS_Server;LOG_ERROR::sync_node_jobs, stray job 21306.tyrone-cluster found on tyrone-node5
04/03/2013 06:20:00;0001;PBS_Server;Svr;PBS_Server;LOG_ERROR::sync_node_jobs, stray job 21312.tyrone-cluster found on tyrone-node4
04/03/2013 06:20:14;0001;PBS_Server;Svr;PBS_Server;LOG_ERROR::sync_node_jobs, stray job 21190.tyrone-cluster found on tyrone-node6
04/03/2013 06:20:18;0001;PBS_Server;Svr;PBS_Server;LOG_ERROR::sync_node_jobs, stray job 21306.tyrone-cluster found on tyrone-node5
04/03/2013 06:20:45;0001;PBS_Server;Svr;PBS_Server;LOG_ERROR::sync_node_jobs, stray job 21312.tyrone-cluster found on tyrone-node4
04/03/2013 06:20:59;0001;PBS_Server;Svr;PBS_Server;LOG_ERROR::sync_node_jobs, stray job 21190.tyrone-cluster found on tyrone-node6
04/03/2013 06:21:03;0001;PBS_Server;Svr;PBS_Server;LOG_ERROR::sync_node_jobs, stray job 21306.tyrone-cluster found on tyrone-node5
04/03/2013 06:21:30;0001;PBS_Server;Svr;PBS_Server;LOG_ERROR::sync_node_jobs, stray job 21312.tyrone-cluster found on tyrone-node4
04/03/2013 06:21:44;0001;PBS_Server;Svr;PBS_Server;LOG_ERROR::sync_node_jobs, stray job 21190.tyrone-cluster found on tyrone-node6
04/03/2013 06:21:48;0001;PBS_Server;Svr;PBS_Server;LOG_ERROR::sync_node_jobs, stray job 21306.tyrone-cluster found on tyrone-node5
04/03/2013 06:22:15;0001;PBS_Server;Svr;PBS_Server;LOG_ERROR::sync_node_jobs, stray job 21312.tyrone-cluster found on tyrone-node4
04/03/2013 06:22:29;0001;PBS_Server;Svr;PBS_Server;LOG_ERROR::sync_node_jobs, stray job 21190.tyrone-cluster found on tyrone-node6
04/03/2013 06:22:32;0001;PBS_Server;Svr;PBS_Server;LOG_ERROR::sync_node_jobs, stray job 21306.tyrone-cluster found on tyrone-node5
04/03/2013 06:22:44;0040;PBS_Server;Svr;tyrone-cluster;Scheduler was sent the command time
04/03/2013 06:23:00;0001;PBS_Server;Svr;PBS_Server;LOG_ERROR::sync_node_jobs, stray job 21312.tyrone-cluster found on tyrone-node4
04/03/2013 06:23:14;0001;PBS_Server;Svr;PBS_Server;LOG_ERROR::sync_node_jobs, stray job 21190.tyrone-cluster found on tyrone-node6
04/03/2013 06:23:17;0001;PBS_Server;Svr;PBS_Server;LOG_ERROR::sync_node_jobs, stray job 21306.tyrone-cluster found on tyrone-node5
04/03/2013 06:23:30;0002;PBS_Server;Svr;PBS_Server;Torque Server Version = 3.0.5, loglevel = 0
04/03/2013 06:23:45;0001;PBS_Server;Svr;PBS_Server;LOG_ERROR::sync_node_jobs, stray job 21312.tyrone-cluster found on tyrone-node4
04/03/2013 06:23:59;0001;PBS_Server;Svr;PBS_Server;LOG_ERROR::sync_node_jobs, stray job 21190.tyrone-cluster found on tyrone-node6
04/03/2013 06:24:02;0001;PBS_Server;Svr;PBS_Server;LOG_ERROR::sync_node_jobs, stray job 21306.tyrone-cluster found on tyrone-node5
04/03/2013 06:24:30;0001;PBS_Server;Svr;PBS_Server;LOG_ERROR::sync_node_jobs, stray job 21312.tyrone-cluster found on tyrone-node4
04/03/2013 06:24:44;0001;PBS_Server;Svr;PBS_Server;LOG_ERROR::sync_node_jobs, stray job 21190.tyrone-cluster found on tyrone-node6
04/03/2013 06:24:47;0001;PBS_Server;Svr;PBS_Server;LOG_ERROR::sync_node_jobs, stray job 21306.tyrone-cluster found on tyrone-node5
04/03/2013 06:25:15;0001;PBS_Server;Svr;PBS_Server;LOG_ERROR::sync_node_jobs, stray job 21312.tyrone-cluster found on tyrone-node4
04/03/2013 06:25:29;0001;PBS_Server;Svr;PBS_Server;LOG_ERROR::sync_node_jobs, stray job 21190.tyrone-cluster found on tyrone-node6
04/03/2013 06:25:32;0001;PBS_Server;Svr;PBS_Server;LOG_ERROR::sync_node_jobs, stray job 21306.tyrone-cluster found on tyrone-node5
04/03/2013 06:26:00;0001;PBS_Server;Svr;PBS_Server;LOG_ERROR::sync_node_jobs, stray job 21312.tyrone-cluster found on tyrone-node4
04/03/2013 06:26:14;0001;PBS_Server;Svr;PBS_Server;LOG_ERROR::sync_node_jobs, stray job 21190.tyrone-cluster found on tyrone-node6
04/03/2013 06:26:17;0001;PBS_Server;Svr;PBS_Server;LOG_ERROR::sync_node_jobs, stray job 21306.tyrone-cluster found on tyrone-node5
04/03/2013 06:26:45;0001;PBS_Server;Svr;PBS_Server;LOG_ERROR::sync_node_jobs, stray job 21312.tyrone-cluster found on tyrone-node4
04/03/2013 06:26:59;0001;PBS_Server;Svr;PBS_Server;LOG_ERROR::sync_node_jobs, stray job 21190.tyrone-cluster found on tyrone-node6
04/03/2013 06:27:02;0001;PBS_Server;Svr;PBS_Server;LOG_ERROR::sync_node_jobs, stray job 21306.tyrone-cluster found on tyrone-node5
04/03/2013 06:27:30;0001;PBS_Server;Svr;PBS_Server;LOG_ERROR::sync_node_jobs, stray job 21312.tyrone-cluster found on tyrone-node4
04/03/2013 06:27:45;0001;PBS_Server;Svr;PBS_Server;LOG_ERROR::sync_node_jobs, stray job 21190.tyrone-cluster found on tyrone-node6
04/03/2013 06:27:48;0001;PBS_Server;Svr;PBS_Server;LOG_ERROR::sync_node_jobs, stray job 21306.tyrone-cluster found on tyrone-node5
04/03/2013 06:28:16;0001;PBS_Server;Svr;PBS_Server;LOG_ERROR::sync_node_jobs, stray job 21312.tyrone-cluster found on tyrone-node4
04/03/2013 06:28:30;0001;PBS_Server;Svr;PBS_Server;LOG_ERROR::sync_node_jobs, stray job 21190.tyrone-cluster found on tyrone-node6
04/03/2013 06:28:30;0002;PBS_Server;Svr;PBS_Server;Torque Server Version = 3.0.5, loglevel = 0
04/03/2013 06:28:33;0001;PBS_Server;Svr;PBS_Server;LOG_ERROR::sync_node_jobs, stray job 21306.tyrone-cluster found on tyrone-node5
04/03/2013 06:29:01;0001;PBS_Server;Svr;PBS_Server;LOG_ERROR::sync_node_jobs, stray job 21312.tyrone-cluster found on tyrone-node4
04/03/2013 06:29:15;0001;PBS_Server;Svr;PBS_Server;LOG_ERROR::sync_node_jobs, stray job 21190.tyrone-cluster found on tyrone-node6
04/03/2013 06:29:18;0001;PBS_Server;Svr;PBS_Server;LOG_ERROR::sync_node_jobs, stray job 21306.tyrone-cluster found on tyrone-node5
04/03/2013 06:29:45;0001;PBS_Server;Svr;PBS_Server;LOG_ERROR::sync_node_jobs, stray job 21312.tyrone-cluster found on tyrone-node4
04/03/2013 06:30:00;0001;PBS_Server;Svr;PBS_Server;LOG_ERROR::sync_node_jobs, stray job 21190.tyrone-cluster found on tyrone-node6
04/03/2013 06:30:03;0001;PBS_Server;Svr;PBS_Server;LOG_ERROR::sync_node_jobs, stray job 21306.tyrone-cluster found on tyrone-node5
04/03/2013 06:30:30;0001;PBS_Server;Svr;PBS_Server;LOG_ERROR::sync_node_jobs, stray job 21312.tyrone-cluster found on tyrone-node4
04/03/2013 06:30:44;0001;PBS_Server;Svr;PBS_Server;LOG_ERROR::sync_node_jobs, stray job 21190.tyrone-cluster found on tyrone-node6
04/03/2013 06:30:48;0001;PBS_Server;Svr;PBS_Server;LOG_ERROR::sync_node_jobs, stray job 21306.tyrone-cluster found on tyrone-node5
04/03/2013 06:31:15;0001;PBS_Server;Svr;PBS_Server;LOG_ERROR::sync_node_jobs, stray job 21312.tyrone-cluster found on tyrone-node4
04/03/2013 06:31:29;0001;PBS_Server;Svr;PBS_Server;LOG_ERROR::sync_node_jobs, stray job 21190.tyrone-cluster found on tyrone-node6
04/03/2013 06:31:33;0001;PBS_Server;Svr;PBS_Server;LOG_ERROR::sync_node_jobs, stray job 21306.tyrone-cluster found on tyrone-node5
04/03/2013 06:32:00;0001;PBS_Server;Svr;PBS_Server;LOG_ERROR::sync_node_jobs, stray job 21312.tyrone-cluster found on tyrone-node4
04/03/2013 06:32:14;0001;PBS_Server;Svr;PBS_Server;LOG_ERROR::sync_node_jobs, stray job 21190.tyrone-cluster found on tyrone-node6
04/03/2013 06:32:18;0001;PBS_Server;Svr;PBS_Server;LOG_ERROR::sync_node_jobs, stray job 21306.tyrone-cluster found on tyrone-node5
04/03/2013 06:32:44;0040;PBS_Server;Svr;tyrone-cluster;Scheduler was sent the command time
04/03/2013 06:32:45;0001;PBS_Server;Svr;PBS_Server;LOG_ERROR::sync_node_jobs, stray job 21312.tyrone-cluster found on tyrone-node4
04/03/2013 06:32:59;0001;PBS_Server;Svr;PBS_Server;LOG_ERROR::sync_node_jobs, stray job 21190.tyrone-cluster found on tyrone-node6
04/03/2013 06:33:03;0001;PBS_Server;Svr;PBS_Server;LOG_ERROR::sync_node_jobs, stray job 21306.tyrone-cluster found on tyrone-node5
04/03/2013 06:33:30;0002;PBS_Server;Svr;PBS_Server;Torque Server Version = 3.0.5, loglevel = 0
04/03/2013 06:33:30;0001;PBS_Server;Svr;PBS_Server;LOG_ERROR::sync_node_jobs, stray job 21312.tyrone-cluster found on tyrone-node4
04/03/2013 06:33:44;0001;PBS_Server;Svr;PBS_Server;LOG_ERROR::sync_node_jobs, stray job 21190.tyrone-cluster found on tyrone-node6
04/03/2013 06:33:47;0001;PBS_Server;Svr;PBS_Server;LOG_ERROR::sync_node_jobs, stray job 21306.tyrone-cluster found on tyrone-node5
04/03/2013 06:34:15;0001;PBS_Server;Svr;PBS_Server;LOG_ERROR::sync_node_jobs, stray job 21312.tyrone-cluster found on tyrone-node4
04/03/2013 06:34:29;0001;PBS_Server;Svr;PBS_Server;LOG_ERROR::sync_node_jobs, stray job 21190.tyrone-cluster found on tyrone-node6
04/03/2013 06:34:32;0001;PBS_Server;Svr;PBS_Server;LOG_ERROR::sync_node_jobs, stray job 21306.tyrone-cluster found on tyrone-node5
04/03/2013 06:35:00;0001;PBS_Server;Svr;PBS_Server;LOG_ERROR::sync_node_jobs, stray job 21312.tyrone-cluster found on tyrone-node4
04/03/2013 06:35:14;0001;PBS_Server;Svr;PBS_Server;LOG_ERROR::sync_node_jobs, stray job 21190.tyrone-cluster found on tyrone-node6
04/03/2013 06:35:17;0001;PBS_Server;Svr;PBS_Server;LOG_ERROR::sync_node_jobs, stray job 21306.tyrone-cluster found on tyrone-node5
04/03/2013 06:35:45;0001;PBS_Server;Svr;PBS_Server;LOG_ERROR::sync_node_jobs, stray job 21312.tyrone-cluster found on tyrone-node4
04/03/2013 06:35:59;0001;PBS_Server;Svr;PBS_Server;LOG_ERROR::sync_node_jobs, stray job 21190.tyrone-cluster found on tyrone-node6
04/03/2013 06:36:02;0001;PBS_Server;Svr;PBS_Server;LOG_ERROR::sync_node_jobs, stray job 21306.tyrone-cluster found on tyrone-node5
04/03/2013 06:36:30;0001;PBS_Server;Svr;PBS_Server;LOG_ERROR::sync_node_jobs, stray job 21312.tyrone-cluster found on tyrone-node4
04/03/2013 06:36:44;0001;PBS_Server;Svr;PBS_Server;LOG_ERROR::sync_node_jobs, stray job 21190.tyrone-cluster found on tyrone-node6
04/03/2013 06:36:47;0001;PBS_Server;Svr;PBS_Server;LOG_ERROR::sync_node_jobs, stray job 21306.tyrone-cluster found on tyrone-node5
04/03/2013 06:37:15;0001;PBS_Server;Svr;PBS_Server;LOG_ERROR::sync_node_jobs, stray job 21312.tyrone-cluster found on tyrone-node4
04/03/2013 06:37:29;0001;PBS_Server;Svr;PBS_Server;LOG_ERROR::sync_node_jobs, stray job 21190.tyrone-cluster found on tyrone-node6
04/03/2013 06:37:32;0001;PBS_Server;Svr;PBS_Server;LOG_ERROR::sync_node_jobs, stray job 21306.tyrone-cluster found on tyrone-node5
04/03/2013 06:38:00;0001;PBS_Server;Svr;PBS_Server;LOG_ERROR::sync_node_jobs, stray job 21312.tyrone-cluster found on tyrone-node4
04/03/2013 06:38:14;0001;PBS_Server;Svr;PBS_Server;LOG_ERROR::sync_node_jobs, stray job 21190.tyrone-cluster found on tyrone-node6
04/03/2013 06:38:17;0001;PBS_Server;Svr;PBS_Server;LOG_ERROR::sync_node_jobs, stray job 21306.tyrone-cluster found on tyrone-node5
04/03/2013 06:38:30;0002;PBS_Server;Svr;PBS_Server;Torque Server Version = 3.0.5, loglevel = 0
04/03/2013 06:38:45;0001;PBS_Server;Svr;PBS_Server;LOG_ERROR::sync_node_jobs, stray job 21312.tyrone-cluster found on tyrone-node4
04/03/2013 06:38:59;0001;PBS_Server;Svr;PBS_Server;LOG_ERROR::sync_node_jobs, stray job 21190.tyrone-cluster found on tyrone-node6
04/03/2013 06:39:02;0001;PBS_Server;Svr;PBS_Server;LOG_ERROR::sync_node_jobs, stray job 21306.tyrone-cluster found on tyrone-node5
04/03/2013 06:39:29;0001;PBS_Server;Svr;PBS_Server;LOG_ERROR::sync_node_jobs, stray job 21312.tyrone-cluster found on tyrone-node4
04/03/2013 06:39:44;0001;PBS_Server;Svr;PBS_Server;LOG_ERROR::sync_node_jobs, stray job 21190.tyrone-cluster found on tyrone-node6
04/03/2013 06:39:47;0001;PBS_Server;Svr;PBS_Server;LOG_ERROR::sync_node_jobs, stray job 21306.tyrone-cluster found on tyrone-node5
04/03/2013 06:40:15;0001;PBS_Server;Svr;PBS_Server;LOG_ERROR::sync_node_jobs, stray job 21312.tyrone-cluster found on tyrone-node4
04/03/2013 06:40:30;0001;PBS_Server;Svr;PBS_Server;LOG_ERROR::sync_node_jobs, stray job 21190.tyrone-cluster found on tyrone-node6
04/03/2013 06:40:33;0001;PBS_Server;Svr;PBS_Server;LOG_ERROR::sync_node_jobs, stray job 21306.tyrone-cluster found on tyrone-node5
04/03/2013 06:41:00;0001;PBS_Server;Svr;PBS_Server;LOG_ERROR::sync_node_jobs, stray job 21312.tyrone-cluster found on tyrone-node4
04/03/2013 06:41:15;0001;PBS_Server;Svr;PBS_Server;LOG_ERROR::sync_node_jobs, stray job 21190.tyrone-cluster found on tyrone-node6
04/03/2013 06:41:18;0001;PBS_Server;Svr;PBS_Server;LOG_ERROR::sync_node_jobs, stray job 21306.tyrone-cluster found on tyrone-node5
04/03/2013 06:41:45;0001;PBS_Server;Svr;PBS_Server;LOG_ERROR::sync_node_jobs, stray job 21312.tyrone-cluster found on tyrone-node4
04/03/2013 06:42:00;0001;PBS_Server;Svr;PBS_Server;LOG_ERROR::sync_node_jobs, stray job 21190.tyrone-cluster found on tyrone-node6
04/03/2013 06:42:03;0001;PBS_Server;Svr;PBS_Server;LOG_ERROR::sync_node_jobs, stray job 21306.tyrone-cluster found on tyrone-node5
04/03/2013 06:42:30;0001;PBS_Server;Svr;PBS_Server;LOG_ERROR::sync_node_jobs, stray job 21312.tyrone-cluster found on tyrone-node4
04/03/2013 06:42:44;0001;PBS_Server;Svr;PBS_Server;LOG_ERROR::sync_node_jobs, stray job 21190.tyrone-cluster found on tyrone-node6
04/03/2013 06:42:44;0040;PBS_Server;Svr;tyrone-cluster;Scheduler was sent the command time
04/03/2013 06:42:48;0001;PBS_Server;Svr;PBS_Server;LOG_ERROR::sync_node_jobs, stray job 21306.tyrone-cluster found on tyrone-node5
04/03/2013 06:43:15;0001;PBS_Server;Svr;PBS_Server;LOG_ERROR::sync_node_jobs, stray job 21312.tyrone-cluster found on tyrone-node4
04/03/2013 06:43:29;0001;PBS_Server;Svr;PBS_Server;LOG_ERROR::sync_node_jobs, stray job 21190.tyrone-cluster found on tyrone-node6
04/03/2013 06:43:30;0002;PBS_Server;Svr;PBS_Server;Torque Server Version = 3.0.5, loglevel = 0
04/03/2013 06:43:33;0001;PBS_Server;Svr;PBS_Server;LOG_ERROR::sync_node_jobs, stray job 21306.tyrone-cluster found on tyrone-node5
04/03/2013 06:44:00;0001;PBS_Server;Svr;PBS_Server;LOG_ERROR::sync_node_jobs, stray job 21312.tyrone-cluster found on tyrone-node4
04/03/2013 06:44:14;0001;PBS_Server;Svr;PBS_Server;LOG_ERROR::sync_node_jobs, stray job 21190.tyrone-cluster found on tyrone-node6
04/03/2013 06:44:18;0001;PBS_Server;Svr;PBS_Server;LOG_ERROR::sync_node_jobs, stray job 21306.tyrone-cluster found on tyrone-node5
04/03/2013 06:44:45;0001;PBS_Server;Svr;PBS_Server;LOG_ERROR::sync_node_jobs, stray job 21312.tyrone-cluster found on tyrone-node4
04/03/2013 06:44:59;0001;PBS_Server;Svr;PBS_Server;LOG_ERROR::sync_node_jobs, stray job 21190.tyrone-cluster found on tyrone-node6
04/03/2013 06:45:03;0001;PBS_Server;Svr;PBS_Server;LOG_ERROR::sync_node_jobs, stray job 21306.tyrone-cluster found on tyrone-node5
04/03/2013 06:45:30;0001;PBS_Server;Svr;PBS_Server;LOG_ERROR::sync_node_jobs, stray job 21312.tyrone-cluster found on tyrone-node4
04/03/2013 06:45:44;0001;PBS_Server;Svr;PBS_Server;LOG_ERROR::sync_node_jobs, stray job 21190.tyrone-cluster found on tyrone-node6
04/03/2013 06:45:48;0001;PBS_Server;Svr;PBS_Server;LOG_ERROR::sync_node_jobs, stray job 21306.tyrone-cluster found on tyrone-node5
04/03/2013 06:46:15;0001;PBS_Server;Svr;PBS_Server;LOG_ERROR::sync_node_jobs, stray job 21312.tyrone-cluster found on tyrone-node4
04/03/2013 06:46:29;0001;PBS_Server;Svr;PBS_Server;LOG_ERROR::sync_node_jobs, stray job 21190.tyrone-cluster found on tyrone-node6
04/03/2013 06:46:32;0001;PBS_Server;Svr;PBS_Server;LOG_ERROR::sync_node_jobs, stray job 21306.tyrone-cluster found on tyrone-node5
04/03/2013 06:47:00;0001;PBS_Server;Svr;PBS_Server;LOG_ERROR::sync_node_jobs, stray job 21312.tyrone-cluster found on tyrone-node4
04/03/2013 06:47:14;0001;PBS_Server;Svr;PBS_Server;LOG_ERROR::sync_node_jobs, stray job 21190.tyrone-cluster found on tyrone-node6
04/03/2013 06:47:17;0001;PBS_Server;Svr;PBS_Server;LOG_ERROR::sync_node_jobs, stray job 21306.tyrone-cluster found on tyrone-node5
04/03/2013 06:47:45;0001;PBS_Server;Svr;PBS_Server;LOG_ERROR::sync_node_jobs, stray job 21312.tyrone-cluster found on tyrone-node4
04/03/2013 06:47:59;0001;PBS_Server;Svr;PBS_Server;LOG_ERROR::sync_node_jobs, stray job 21190.tyrone-cluster found on tyrone-node6
04/03/2013 06:48:02;0001;PBS_Server;Svr;PBS_Server;LOG_ERROR::sync_node_jobs, stray job 21306.tyrone-cluster found on tyrone-node5
04/03/2013 06:48:29;0001;PBS_Server;Svr;PBS_Server;LOG_ERROR::sync_node_jobs, stray job 21312.tyrone-cluster found on tyrone-node4
04/03/2013 06:48:30;0002;PBS_Server;Svr;PBS_Server;Torque Server Version = 3.0.5, loglevel = 0
04/03/2013 06:48:44;0001;PBS_Server;Svr;PBS_Server;LOG_ERROR::sync_node_jobs, stray job 21190.tyrone-cluster found on tyrone-node6
04/03/2013 06:48:47;0001;PBS_Server;Svr;PBS_Server;LOG_ERROR::sync_node_jobs, stray job 21306.tyrone-cluster found on tyrone-node5
04/03/2013 06:49:14;0001;PBS_Server;Svr;PBS_Server;LOG_ERROR::sync_node_jobs, stray job 21312.tyrone-cluster found on tyrone-node4
04/03/2013 06:49:29;0001;PBS_Server;Svr;PBS_Server;LOG_ERROR::sync_node_jobs, stray job 21190.tyrone-cluster found on tyrone-node6
04/03/2013 06:49:32;0001;PBS_Server;Svr;PBS_Server;LOG_ERROR::sync_node_jobs, stray job 21306.tyrone-cluster found on tyrone-node5
04/03/2013 06:49:59;0001;PBS_Server;Svr;PBS_Server;LOG_ERROR::sync_node_jobs, stray job 21312.tyrone-cluster found on tyrone-node4
04/03/2013 06:50:14;0001;PBS_Server;Svr;PBS_Server;LOG_ERROR::sync_node_jobs, stray job 21190.tyrone-cluster found on tyrone-node6
04/03/2013 06:50:17;0001;PBS_Server;Svr;PBS_Server;LOG_ERROR::sync_node_jobs, stray job 21306.tyrone-cluster found on tyrone-node5
04/03/2013 06:50:44;0001;PBS_Server;Svr;PBS_Server;LOG_ERROR::sync_node_jobs, stray job 21312.tyrone-cluster found on tyrone-node4
04/03/2013 06:50:59;0001;PBS_Server;Svr;PBS_Server;LOG_ERROR::sync_node_jobs, stray job 21190.tyrone-cluster found on tyrone-node6
04/03/2013 06:51:02;0001;PBS_Server;Svr;PBS_Server;LOG_ERROR::sync_node_jobs, stray job 21306.tyrone-cluster found on tyrone-node5
04/03/2013 06:51:29;0001;PBS_Server;Svr;PBS_Server;LOG_ERROR::sync_node_jobs, stray job 21312.tyrone-cluster found on tyrone-node4
04/03/2013 06:51:44;0001;PBS_Server;Svr;PBS_Server;LOG_ERROR::sync_node_jobs, stray job 21190.tyrone-cluster found on tyrone-node6
04/03/2013 06:51:47;0001;PBS_Server;Svr;PBS_Server;LOG_ERROR::sync_node_jobs, stray job 21306.tyrone-cluster found on tyrone-node5
04/03/2013 06:52:14;0001;PBS_Server;Svr;PBS_Server;LOG_ERROR::sync_node_jobs, stray job 21312.tyrone-cluster found on tyrone-node4
04/03/2013 06:52:29;0001;PBS_Server;Svr;PBS_Server;LOG_ERROR::sync_node_jobs, stray job 21190.tyrone-cluster found on tyrone-node6
04/03/2013 06:52:32;0001;PBS_Server;Svr;PBS_Server;LOG_ERROR::sync_node_jobs, stray job 21306.tyrone-cluster found on tyrone-node5
04/03/2013 06:52:44;0040;PBS_Server;Svr;tyrone-cluster;Scheduler was sent the command time
04/03/2013 06:53:00;0001;PBS_Server;Svr;PBS_Server;LOG_ERROR::sync_node_jobs, stray job 21312.tyrone-cluster found on tyrone-node4
04/03/2013 06:53:14;0001;PBS_Server;Svr;PBS_Server;LOG_ERROR::sync_node_jobs, stray job 21190.tyrone-cluster found on tyrone-node6
04/03/2013 06:53:18;0001;PBS_Server;Svr;PBS_Server;LOG_ERROR::sync_node_jobs, stray job 21306.tyrone-cluster found on tyrone-node5
04/03/2013 06:53:30;0002;PBS_Server;Svr;PBS_Server;Torque Server Version = 3.0.5, loglevel = 0
04/03/2013 06:53:45;0001;PBS_Server;Svr;PBS_Server;LOG_ERROR::sync_node_jobs, stray job 21312.tyrone-cluster found on tyrone-node4
04/03/2013 06:53:59;0001;PBS_Server;Svr;PBS_Server;LOG_ERROR::sync_node_jobs, stray job 21190.tyrone-cluster found on tyrone-node6
04/03/2013 06:54:03;0001;PBS_Server;Svr;PBS_Server;LOG_ERROR::sync_node_jobs, stray job 21306.tyrone-cluster found on tyrone-node5
04/03/2013 06:54:30;0001;PBS_Server;Svr;PBS_Server;LOG_ERROR::sync_node_jobs, stray job 21312.tyrone-cluster found on tyrone-node4
04/03/2013 06:54:44;0001;PBS_Server;Svr;PBS_Server;LOG_ERROR::sync_node_jobs, stray job 21190.tyrone-cluster found on tyrone-node6
04/03/2013 06:54:48;0001;PBS_Server;Svr;PBS_Server;LOG_ERROR::sync_node_jobs, stray job 21306.tyrone-cluster found on tyrone-node5
04/03/2013 06:55:15;0001;PBS_Server;Svr;PBS_Server;LOG_ERROR::sync_node_jobs, stray job 21312.tyrone-cluster found on tyrone-node4
04/03/2013 06:55:29;0001;PBS_Server;Svr;PBS_Server;LOG_ERROR::sync_node_jobs, stray job 21190.tyrone-cluster found on tyrone-node6
04/03/2013 06:55:33;0001;PBS_Server;Svr;PBS_Server;LOG_ERROR::sync_node_jobs, stray job 21306.tyrone-cluster found on tyrone-node5
04/03/2013 06:56:00;0001;PBS_Server;Svr;PBS_Server;LOG_ERROR::sync_node_jobs, stray job 21312.tyrone-cluster found on tyrone-node4
04/03/2013 06:56:14;0001;PBS_Server;Svr;PBS_Server;LOG_ERROR::sync_node_jobs, stray job 21190.tyrone-cluster found on tyrone-node6
04/03/2013 06:56:18;0001;PBS_Server;Svr;PBS_Server;LOG_ERROR::sync_node_jobs, stray job 21306.tyrone-cluster found on tyrone-node5
04/03/2013 06:56:45;0001;PBS_Server;Svr;PBS_Server;LOG_ERROR::sync_node_jobs, stray job 21312.tyrone-cluster found on tyrone-node4
04/03/2013 06:56:59;0001;PBS_Server;Svr;PBS_Server;LOG_ERROR::sync_node_jobs, stray job 21190.tyrone-cluster found on tyrone-node6
04/03/2013 06:57:03;0001;PBS_Server;Svr;PBS_Server;LOG_ERROR::sync_node_jobs, stray job 21306.tyrone-cluster found on tyrone-node5
04/03/2013 06:57:30;0001;PBS_Server;Svr;PBS_Server;LOG_ERROR::sync_node_jobs, stray job 21312.tyrone-cluster found on tyrone-node4
04/03/2013 06:57:44;0001;PBS_Server;Svr;PBS_Server;LOG_ERROR::sync_node_jobs, stray job 21190.tyrone-cluster found on tyrone-node6
04/03/2013 06:57:48;0001;PBS_Server;Svr;PBS_Server;LOG_ERROR::sync_node_jobs, stray job 21306.tyrone-cluster found on tyrone-node5
04/03/2013 06:58:15;0001;PBS_Server;Svr;PBS_Server;LOG_ERROR::sync_node_jobs, stray job 21312.tyrone-cluster found on tyrone-node4
04/03/2013 06:58:29;0001;PBS_Server;Svr;PBS_Server;LOG_ERROR::sync_node_jobs, stray job 21190.tyrone-cluster found on tyrone-node6
04/03/2013 06:58:30;0002;PBS_Server;Svr;PBS_Server;Torque Server Version = 3.0.5, loglevel = 0
04/03/2013 06:58:32;0001;PBS_Server;Svr;PBS_Server;LOG_ERROR::sync_node_jobs, stray job 21306.tyrone-cluster found on tyrone-node5
04/03/2013 06:58:59;0001;PBS_Server;Svr;PBS_Server;LOG_ERROR::sync_node_jobs, stray job 21312.tyrone-cluster found on tyrone-node4
04/03/2013 06:59:14;0001;PBS_Server;Svr;PBS_Server;LOG_ERROR::sync_node_jobs, stray job 21190.tyrone-cluster found on tyrone-node6
04/03/2013 06:59:17;0001;PBS_Server;Svr;PBS_Server;LOG_ERROR::sync_node_jobs, stray job 21306.tyrone-cluster found on tyrone-node5
04/03/2013 06:59:44;0001;PBS_Server;Svr;PBS_Server;LOG_ERROR::sync_node_jobs, stray job 21312.tyrone-cluster found on tyrone-node4
04/03/2013 06:59:59;0001;PBS_Server;Svr;PBS_Server;LOG_ERROR::sync_node_jobs, stray job 21190.tyrone-cluster found on tyrone-node6
04/03/2013 07:00:02;0001;PBS_Server;Svr;PBS_Server;LOG_ERROR::sync_node_jobs, stray job 21306.tyrone-cluster found on tyrone-node5
04/03/2013 07:00:29;0001;PBS_Server;Svr;PBS_Server;LOG_ERROR::sync_node_jobs, stray job 21312.tyrone-cluster found on tyrone-node4
04/03/2013 07:00:44;0001;PBS_Server;Svr;PBS_Server;LOG_ERROR::sync_node_jobs, stray job 21190.tyrone-cluster found on tyrone-node6
04/03/2013 07:00:47;0001;PBS_Server;Svr;PBS_Server;LOG_ERROR::sync_node_jobs, stray job 21306.tyrone-cluster found on tyrone-node5
04/03/2013 07:01:14;0001;PBS_Server;Svr;PBS_Server;LOG_ERROR::sync_node_jobs, stray job 21312.tyrone-cluster found on tyrone-node4
04/03/2013 07:01:29;0001;PBS_Server;Svr;PBS_Server;LOG_ERROR::sync_node_jobs, stray job 21190.tyrone-cluster found on tyrone-node6
04/03/2013 07:01:32;0001;PBS_Server;Svr;PBS_Server;LOG_ERROR::sync_node_jobs, stray job 21306.tyrone-cluster found on tyrone-node5
04/03/2013 07:01:59;0001;PBS_Server;Svr;PBS_Server;LOG_ERROR::sync_node_jobs, stray job 21312.tyrone-cluster found on tyrone-node4
04/03/2013 07:02:14;0001;PBS_Server;Svr;PBS_Server;LOG_ERROR::sync_node_jobs, stray job 21190.tyrone-cluster found on tyrone-node6
04/03/2013 07:02:17;0001;PBS_Server;Svr;PBS_Server;LOG_ERROR::sync_node_jobs, stray job 21306.tyrone-cluster found on tyrone-node5
04/03/2013 07:02:44;0040;PBS_Server;Svr;tyrone-cluster;Scheduler was sent the command time
04/03/2013 07:02:44;0001;PBS_Server;Svr;PBS_Server;LOG_ERROR::sync_node_jobs, stray job 21312.tyrone-cluster found on tyrone-node4
04/03/2013 07:02:59;0001;PBS_Server;Svr;PBS_Server;LOG_ERROR::sync_node_jobs, stray job 21190.tyrone-cluster found on tyrone-node6
04/03/2013 07:03:02;0001;PBS_Server;Svr;PBS_Server;LOG_ERROR::sync_node_jobs, stray job 21306.tyrone-cluster found on tyrone-node5
04/03/2013 07:03:29;0001;PBS_Server;Svr;PBS_Server;LOG_ERROR::sync_node_jobs, stray job 21312.tyrone-cluster found on tyrone-node4
04/03/2013 07:03:30;0002;PBS_Server;Svr;PBS_Server;Torque Server Version = 3.0.5, loglevel = 0
04/03/2013 07:03:44;0001;PBS_Server;Svr;PBS_Server;LOG_ERROR::sync_node_jobs, stray job 21190.tyrone-cluster found on tyrone-node6
04/03/2013 07:03:47;0001;PBS_Server;Svr;PBS_Server;LOG_ERROR::sync_node_jobs, stray job 21306.tyrone-cluster found on tyrone-node5
04/03/2013 07:04:14;0001;PBS_Server;Svr;PBS_Server;LOG_ERROR::sync_node_jobs, stray job 21312.tyrone-cluster found on tyrone-node4
04/03/2013 07:04:29;0001;PBS_Server;Svr;PBS_Server;LOG_ERROR::sync_node_jobs, stray job 21190.tyrone-cluster found on tyrone-node6
04/03/2013 07:04:32;0001;PBS_Server;Svr;PBS_Server;LOG_ERROR::sync_node_jobs, stray job 21306.tyrone-cluster found on tyrone-node5
04/03/2013 07:04:59;0001;PBS_Server;Svr;PBS_Server;LOG_ERROR::sync_node_jobs, stray job 21312.tyrone-cluster found on tyrone-node4
04/03/2013 07:05:14;0001;PBS_Server;Svr;PBS_Server;LOG_ERROR::sync_node_jobs, stray job 21190.tyrone-cluster found on tyrone-node6
04/03/2013 07:05:18;0001;PBS_Server;Svr;PBS_Server;LOG_ERROR::sync_node_jobs, stray job 21306.tyrone-cluster found on tyrone-node5
04/03/2013 07:05:45;0001;PBS_Server;Svr;PBS_Server;LOG_ERROR::sync_node_jobs, stray job 21312.tyrone-cluster found on tyrone-node4
04/03/2013 07:05:59;0001;PBS_Server;Svr;PBS_Server;LOG_ERROR::sync_node_jobs, stray job 21190.tyrone-cluster found on tyrone-node6
04/03/2013 07:06:03;0001;PBS_Server;Svr;PBS_Server;LOG_ERROR::sync_node_jobs, stray job 21306.tyrone-cluster found on tyrone-node5
04/03/2013 07:06:30;0001;PBS_Server;Svr;PBS_Server;LOG_ERROR::sync_node_jobs, stray job 21312.tyrone-cluster found on tyrone-node4
04/03/2013 07:06:44;0001;PBS_Server;Svr;PBS_Server;LOG_ERROR::sync_node_jobs, stray job 21190.tyrone-cluster found on tyrone-node6
04/03/2013 07:06:48;0001;PBS_Server;Svr;PBS_Server;LOG_ERROR::sync_node_jobs, stray job 21306.tyrone-cluster found on tyrone-node5
04/03/2013 07:07:15;0001;PBS_Server;Svr;PBS_Server;LOG_ERROR::sync_node_jobs, stray job 21312.tyrone-cluster found on tyrone-node4
04/03/2013 07:07:29;0001;PBS_Server;Svr;PBS_Server;LOG_ERROR::sync_node_jobs, stray job 21190.tyrone-cluster found on tyrone-node6
04/03/2013 07:07:33;0001;PBS_Server;Svr;PBS_Server;LOG_ERROR::sync_node_jobs, stray job 21306.tyrone-cluster found on tyrone-node5
04/03/2013 07:08:00;0001;PBS_Server;Svr;PBS_Server;LOG_ERROR::sync_node_jobs, stray job 21312.tyrone-cluster found on tyrone-node4
04/03/2013 07:08:14;0001;PBS_Server;Svr;PBS_Server;LOG_ERROR::sync_node_jobs, stray job 21190.tyrone-cluster found on tyrone-node6
04/03/2013 07:08:18;0001;PBS_Server;Svr;PBS_Server;LOG_ERROR::sync_node_jobs, stray job 21306.tyrone-cluster found on tyrone-node5
04/03/2013 07:08:30;0002;PBS_Server;Svr;PBS_Server;Torque Server Version = 3.0.5, loglevel = 0
04/03/2013 07:08:44;0001;PBS_Server;Svr;PBS_Server;LOG_ERROR::sync_node_jobs, stray job 21312.tyrone-cluster found on tyrone-node4
04/03/2013 07:08:59;0001;PBS_Server;Svr;PBS_Server;LOG_ERROR::sync_node_jobs, stray job 21190.tyrone-cluster found on tyrone-node6
04/03/2013 07:09:03;0001;PBS_Server;Svr;PBS_Server;LOG_ERROR::sync_node_jobs, stray job 21306.tyrone-cluster found on tyrone-node5
04/03/2013 07:09:29;0001;PBS_Server;Svr;PBS_Server;LOG_ERROR::sync_node_jobs, stray job 21312.tyrone-cluster found on tyrone-node4
04/03/2013 07:09:44;0001;PBS_Server;Svr;PBS_Server;LOG_ERROR::sync_node_jobs, stray job 21190.tyrone-cluster found on tyrone-node6
04/03/2013 07:09:48;0001;PBS_Server;Svr;PBS_Server;LOG_ERROR::sync_node_jobs, stray job 21306.tyrone-cluster found on tyrone-node5
04/03/2013 07:10:14;0001;PBS_Server;Svr;PBS_Server;LOG_ERROR::sync_node_jobs, stray job 21312.tyrone-cluster found on tyrone-node4
04/03/2013 07:10:29;0001;PBS_Server;Svr;PBS_Server;LOG_ERROR::sync_node_jobs, stray job 21190.tyrone-cluster found on tyrone-node6
04/03/2013 07:10:32;0001;PBS_Server;Svr;PBS_Server;LOG_ERROR::sync_node_jobs, stray job 21306.tyrone-cluster found on tyrone-node5
04/03/2013 07:10:59;0001;PBS_Server;Svr;PBS_Server;LOG_ERROR::sync_node_jobs, stray job 21312.tyrone-cluster found on tyrone-node4
04/03/2013 07:11:14;0001;PBS_Server;Svr;PBS_Server;LOG_ERROR::sync_node_jobs, stray job 21190.tyrone-cluster found on tyrone-node6
04/03/2013 07:11:17;0001;PBS_Server;Svr;PBS_Server;LOG_ERROR::sync_node_jobs, stray job 21306.tyrone-cluster found on tyrone-node5
04/03/2013 07:11:44;0001;PBS_Server;Svr;PBS_Server;LOG_ERROR::sync_node_jobs, stray job 21312.tyrone-cluster found on tyrone-node4
04/03/2013 07:11:59;0001;PBS_Server;Svr;PBS_Server;LOG_ERROR::sync_node_jobs, stray job 21190.tyrone-cluster found on tyrone-node6
04/03/2013 07:12:02;0001;PBS_Server;Svr;PBS_Server;LOG_ERROR::sync_node_jobs, stray job 21306.tyrone-cluster found on tyrone-node5
04/03/2013 07:12:29;0001;PBS_Server;Svr;PBS_Server;LOG_ERROR::sync_node_jobs, stray job 21312.tyrone-cluster found on tyrone-node4
04/03/2013 07:12:44;0001;PBS_Server;Svr;PBS_Server;LOG_ERROR::sync_node_jobs, stray job 21190.tyrone-cluster found on tyrone-node6
04/03/2013 07:12:44;0040;PBS_Server;Svr;tyrone-cluster;Scheduler was sent the command time
04/03/2013 07:12:47;0001;PBS_Server;Svr;PBS_Server;LOG_ERROR::sync_node_jobs, stray job 21306.tyrone-cluster found on tyrone-node5
04/03/2013 07:13:14;0001;PBS_Server;Svr;PBS_Server;LOG_ERROR::sync_node_jobs, stray job 21312.tyrone-cluster found on tyrone-node4
04/03/2013 07:13:29;0001;PBS_Server;Svr;PBS_Server;LOG_ERROR::sync_node_jobs, stray job 21190.tyrone-cluster found on tyrone-node6
04/03/2013 07:13:30;0002;PBS_Server;Svr;PBS_Server;Torque Server Version = 3.0.5, loglevel = 0
04/03/2013 07:13:32;0001;PBS_Server;Svr;PBS_Server;LOG_ERROR::sync_node_jobs, stray job 21306.tyrone-cluster found on tyrone-node5
04/03/2013 07:13:59;0001;PBS_Server;Svr;PBS_Server;LOG_ERROR::sync_node_jobs, stray job 21312.tyrone-cluster found on tyrone-node4
04/03/2013 07:14:14;0001;PBS_Server;Svr;PBS_Server;LOG_ERROR::sync_node_jobs, stray job 21190.tyrone-cluster found on tyrone-node6
04/03/2013 07:14:17;0001;PBS_Server;Svr;PBS_Server;LOG_ERROR::sync_node_jobs, stray job 21306.tyrone-cluster found on tyrone-node5
04/03/2013 07:14:44;0001;PBS_Server;Svr;PBS_Server;LOG_ERROR::sync_node_jobs, stray job 21312.tyrone-cluster found on tyrone-node4
04/03/2013 07:14:59;0001;PBS_Server;Svr;PBS_Server;LOG_ERROR::sync_node_jobs, stray job 21190.tyrone-cluster found on tyrone-node6
04/03/2013 07:15:02;0001;PBS_Server;Svr;PBS_Server;LOG_ERROR::sync_node_jobs, stray job 21306.tyrone-cluster found on tyrone-node5
04/03/2013 07:15:29;0001;PBS_Server;Svr;PBS_Server;LOG_ERROR::sync_node_jobs, stray job 21312.tyrone-cluster found on tyrone-node4
04/03/2013 07:15:44;0001;PBS_Server;Svr;PBS_Server;LOG_ERROR::sync_node_jobs, stray job 21190.tyrone-cluster found on tyrone-node6
04/03/2013 07:15:47;0001;PBS_Server;Svr;PBS_Server;LOG_ERROR::sync_node_jobs, stray job 21306.tyrone-cluster found on tyrone-node5
04/03/2013 07:16:14;0001;PBS_Server;Svr;PBS_Server;LOG_ERROR::sync_node_jobs, stray job 21312.tyrone-cluster found on tyrone-node4
04/03/2013 07:16:29;0001;PBS_Server;Svr;PBS_Server;LOG_ERROR::sync_node_jobs, stray job 21190.tyrone-cluster found on tyrone-node6
04/03/2013 07:16:32;0001;PBS_Server;Svr;PBS_Server;LOG_ERROR::sync_node_jobs, stray job 21306.tyrone-cluster found on tyrone-node5
04/03/2013 07:16:59;0001;PBS_Server;Svr;PBS_Server;LOG_ERROR::sync_node_jobs, stray job 21312.tyrone-cluster found on tyrone-node4
04/03/2013 07:17:13;0001;PBS_Server;Svr;PBS_Server;LOG_ERROR::sync_node_jobs, stray job 21190.tyrone-cluster found on tyrone-node6
04/03/2013 07:17:17;0001;PBS_Server;Svr;PBS_Server;LOG_ERROR::sync_node_jobs, stray job 21306.tyrone-cluster found on tyrone-node5
04/03/2013 07:17:45;0001;PBS_Server;Svr;PBS_Server;LOG_ERROR::sync_node_jobs, stray job 21312.tyrone-cluster found on tyrone-node4
04/03/2013 07:17:59;0001;PBS_Server;Svr;PBS_Server;LOG_ERROR::sync_node_jobs, stray job 21190.tyrone-cluster found on tyrone-node6
04/03/2013 07:18:03;0001;PBS_Server;Svr;PBS_Server;LOG_ERROR::sync_node_jobs, stray job 21306.tyrone-cluster found on tyrone-node5
04/03/2013 07:18:30;0001;PBS_Server;Svr;PBS_Server;LOG_ERROR::sync_node_jobs, stray job 21312.tyrone-cluster found on tyrone-node4
04/03/2013 07:18:30;0002;PBS_Server;Svr;PBS_Server;Torque Server Version = 3.0.5, loglevel = 0
04/03/2013 07:18:44;0001;PBS_Server;Svr;PBS_Server;LOG_ERROR::sync_node_jobs, stray job 21190.tyrone-cluster found on tyrone-node6
04/03/2013 07:18:48;0001;PBS_Server;Svr;PBS_Server;LOG_ERROR::sync_node_jobs, stray job 21306.tyrone-cluster found on tyrone-node5
04/03/2013 07:19:14;0001;PBS_Server;Svr;PBS_Server;LOG_ERROR::sync_node_jobs, stray job 21312.tyrone-cluster found on tyrone-node4
04/03/2013 07:19:29;0001;PBS_Server;Svr;PBS_Server;LOG_ERROR::sync_node_jobs, stray job 21190.tyrone-cluster found on tyrone-node6
04/03/2013 07:19:33;0001;PBS_Server;Svr;PBS_Server;LOG_ERROR::sync_node_jobs, stray job 21306.tyrone-cluster found on tyrone-node5
04/03/2013 07:19:59;0001;PBS_Server;Svr;PBS_Server;LOG_ERROR::sync_node_jobs, stray job 21312.tyrone-cluster found on tyrone-node4
04/03/2013 07:20:14;0001;PBS_Server;Svr;PBS_Server;LOG_ERROR::sync_node_jobs, stray job 21190.tyrone-cluster found on tyrone-node6
04/03/2013 07:20:18;0001;PBS_Server;Svr;PBS_Server;LOG_ERROR::sync_node_jobs, stray job 21306.tyrone-cluster found on tyrone-node5
04/03/2013 07:20:44;0001;PBS_Server;Svr;PBS_Server;LOG_ERROR::sync_node_jobs, stray job 21312.tyrone-cluster found on tyrone-node4
04/03/2013 07:20:59;0001;PBS_Server;Svr;PBS_Server;LOG_ERROR::sync_node_jobs, stray job 21190.tyrone-cluster found on tyrone-node6
04/03/2013 07:21:03;0001;PBS_Server;Svr;PBS_Server;LOG_ERROR::sync_node_jobs, stray job 21306.tyrone-cluster found on tyrone-node5
04/03/2013 07:21:29;0001;PBS_Server;Svr;PBS_Server;LOG_ERROR::sync_node_jobs, stray job 21312.tyrone-cluster found on tyrone-node4
04/03/2013 07:21:44;0001;PBS_Server;Svr;PBS_Server;LOG_ERROR::sync_node_jobs, stray job 21190.tyrone-cluster found on tyrone-node6
04/03/2013 07:21:48;0001;PBS_Server;Svr;PBS_Server;LOG_ERROR::sync_node_jobs, stray job 21306.tyrone-cluster found on tyrone-node5
04/03/2013 07:22:14;0001;PBS_Server;Svr;PBS_Server;LOG_ERROR::sync_node_jobs, stray job 21312.tyrone-cluster found on tyrone-node4
04/03/2013 07:22:29;0001;PBS_Server;Svr;PBS_Server;LOG_ERROR::sync_node_jobs, stray job 21190.tyrone-cluster found on tyrone-node6
04/03/2013 07:22:32;0001;PBS_Server;Svr;PBS_Server;LOG_ERROR::sync_node_jobs, stray job 21306.tyrone-cluster found on tyrone-node5
04/03/2013 07:22:44;0040;PBS_Server;Svr;tyrone-cluster;Scheduler was sent the command time
04/03/2013 07:22:59;0001;PBS_Server;Svr;PBS_Server;LOG_ERROR::sync_node_jobs, stray job 21312.tyrone-cluster found on tyrone-node4
04/03/2013 07:23:14;0001;PBS_Server;Svr;PBS_Server;LOG_ERROR::sync_node_jobs, stray job 21190.tyrone-cluster found on tyrone-node6
04/03/2013 07:23:17;0001;PBS_Server;Svr;PBS_Server;LOG_ERROR::sync_node_jobs, stray job 21306.tyrone-cluster found on tyrone-node5
04/03/2013 07:23:30;0002;PBS_Server;Svr;PBS_Server;Torque Server Version = 3.0.5, loglevel = 0
04/03/2013 07:23:44;0001;PBS_Server;Svr;PBS_Server;LOG_ERROR::sync_node_jobs, stray job 21312.tyrone-cluster found on tyrone-node4
04/03/2013 07:23:59;0001;PBS_Server;Svr;PBS_Server;LOG_ERROR::sync_node_jobs, stray job 21190.tyrone-cluster found on tyrone-node6
04/03/2013 07:24:02;0001;PBS_Server;Svr;PBS_Server;LOG_ERROR::sync_node_jobs, stray job 21306.tyrone-cluster found on tyrone-node5
04/03/2013 07:24:29;0001;PBS_Server;Svr;PBS_Server;LOG_ERROR::sync_node_jobs, stray job 21312.tyrone-cluster found on tyrone-node4
04/03/2013 07:24:44;0001;PBS_Server;Svr;PBS_Server;LOG_ERROR::sync_node_jobs, stray job 21190.tyrone-cluster found on tyrone-node6
04/03/2013 07:24:47;0001;PBS_Server;Svr;PBS_Server;LOG_ERROR::sync_node_jobs, stray job 21306.tyrone-cluster found on tyrone-node5
04/03/2013 07:25:14;0001;PBS_Server;Svr;PBS_Server;LOG_ERROR::sync_node_jobs, stray job 21312.tyrone-cluster found on tyrone-node4
04/03/2013 07:25:29;0001;PBS_Server;Svr;PBS_Server;LOG_ERROR::sync_node_jobs, stray job 21190.tyrone-cluster found on tyrone-node6
04/03/2013 07:25:32;0001;PBS_Server;Svr;PBS_Server;LOG_ERROR::sync_node_jobs, stray job 21306.tyrone-cluster found on tyrone-node5
04/03/2013 07:25:59;0001;PBS_Server;Svr;PBS_Server;LOG_ERROR::sync_node_jobs, stray job 21312.tyrone-cluster found on tyrone-node4
04/03/2013 07:26:14;0001;PBS_Server;Svr;PBS_Server;LOG_ERROR::sync_node_jobs, stray job 21190.tyrone-cluster found on tyrone-node6
04/03/2013 07:26:17;0001;PBS_Server;Svr;PBS_Server;LOG_ERROR::sync_node_jobs, stray job 21306.tyrone-cluster found on tyrone-node5
04/03/2013 07:26:44;0001;PBS_Server;Svr;PBS_Server;LOG_ERROR::sync_node_jobs, stray job 21312.tyrone-cluster found on tyrone-node4
04/03/2013 07:26:59;0001;PBS_Server;Svr;PBS_Server;LOG_ERROR::sync_node_jobs, stray job 21190.tyrone-cluster found on tyrone-node6
04/03/2013 07:27:02;0001;PBS_Server;Svr;PBS_Server;LOG_ERROR::sync_node_jobs, stray job 21306.tyrone-cluster found on tyrone-node5
04/03/2013 07:27:29;0001;PBS_Server;Svr;PBS_Server;LOG_ERROR::sync_node_jobs, stray job 21312.tyrone-cluster found on tyrone-node4
04/03/2013 07:27:44;0001;PBS_Server;Svr;PBS_Server;LOG_ERROR::sync_node_jobs, stray job 21190.tyrone-cluster found on tyrone-node6
04/03/2013 07:27:47;0001;PBS_Server;Svr;PBS_Server;LOG_ERROR::sync_node_jobs, stray job 21306.tyrone-cluster found on tyrone-node5
04/03/2013 07:28:14;0001;PBS_Server;Svr;PBS_Server;LOG_ERROR::sync_node_jobs, stray job 21312.tyrone-cluster found on tyrone-node4
04/03/2013 07:28:29;0001;PBS_Server;Svr;PBS_Server;LOG_ERROR::sync_node_jobs, stray job 21190.tyrone-cluster found on tyrone-node6
04/03/2013 07:28:30;0002;PBS_Server;Svr;PBS_Server;Torque Server Version = 3.0.5, loglevel = 0
04/03/2013 07:28:32;0001;PBS_Server;Svr;PBS_Server;LOG_ERROR::sync_node_jobs, stray job 21306.tyrone-cluster found on tyrone-node5
04/03/2013 07:28:58;0001;PBS_Server;Svr;PBS_Server;LOG_ERROR::sync_node_jobs, stray job 21312.tyrone-cluster found on tyrone-node4
04/03/2013 07:29:13;0001;PBS_Server;Svr;PBS_Server;LOG_ERROR::sync_node_jobs, stray job 21190.tyrone-cluster found on tyrone-node6
04/03/2013 07:29:17;0001;PBS_Server;Svr;PBS_Server;LOG_ERROR::sync_node_jobs, stray job 21306.tyrone-cluster found on tyrone-node5
04/03/2013 07:29:43;0001;PBS_Server;Svr;PBS_Server;LOG_ERROR::sync_node_jobs, stray job 21312.tyrone-cluster found on tyrone-node4
04/03/2013 07:29:59;0001;PBS_Server;Svr;PBS_Server;LOG_ERROR::sync_node_jobs, stray job 21190.tyrone-cluster found on tyrone-node6
04/03/2013 07:30:02;0001;PBS_Server;Svr;PBS_Server;LOG_ERROR::sync_node_jobs, stray job 21306.tyrone-cluster found on tyrone-node5
04/03/2013 07:30:29;0001;PBS_Server;Svr;PBS_Server;LOG_ERROR::sync_node_jobs, stray job 21312.tyrone-cluster found on tyrone-node4
04/03/2013 07:30:44;0001;PBS_Server;Svr;PBS_Server;LOG_ERROR::sync_node_jobs, stray job 21190.tyrone-cluster found on tyrone-node6
04/03/2013 07:30:48;0001;PBS_Server;Svr;PBS_Server;LOG_ERROR::sync_node_jobs, stray job 21306.tyrone-cluster found on tyrone-node5
04/03/2013 07:31:14;0001;PBS_Server;Svr;PBS_Server;LOG_ERROR::sync_node_jobs, stray job 21312.tyrone-cluster found on tyrone-node4
04/03/2013 07:31:29;0001;PBS_Server;Svr;PBS_Server;LOG_ERROR::sync_node_jobs, stray job 21190.tyrone-cluster found on tyrone-node6
04/03/2013 07:31:33;0001;PBS_Server;Svr;PBS_Server;LOG_ERROR::sync_node_jobs, stray job 21306.tyrone-cluster found on tyrone-node5
04/03/2013 07:31:59;0001;PBS_Server;Svr;PBS_Server;LOG_ERROR::sync_node_jobs, stray job 21312.tyrone-cluster found on tyrone-node4
04/03/2013 07:32:14;0001;PBS_Server;Svr;PBS_Server;LOG_ERROR::sync_node_jobs, stray job 21190.tyrone-cluster found on tyrone-node6
04/03/2013 07:32:18;0001;PBS_Server;Svr;PBS_Server;LOG_ERROR::sync_node_jobs, stray job 21306.tyrone-cluster found on tyrone-node5
04/03/2013 07:32:44;0040;PBS_Server;Svr;tyrone-cluster;Scheduler was sent the command time
04/03/2013 07:32:44;0001;PBS_Server;Svr;PBS_Server;LOG_ERROR::sync_node_jobs, stray job 21312.tyrone-cluster found on tyrone-node4
04/03/2013 07:32:59;0001;PBS_Server;Svr;PBS_Server;LOG_ERROR::sync_node_jobs, stray job 21190.tyrone-cluster found on tyrone-node6
04/03/2013 07:33:03;0001;PBS_Server;Svr;PBS_Server;LOG_ERROR::sync_node_jobs, stray job 21306.tyrone-cluster found on tyrone-node5
04/03/2013 07:33:29;0001;PBS_Server;Svr;PBS_Server;LOG_ERROR::sync_node_jobs, stray job 21312.tyrone-cluster found on tyrone-node4
04/03/2013 07:33:30;0002;PBS_Server;Svr;PBS_Server;Torque Server Version = 3.0.5, loglevel = 0
04/03/2013 07:33:44;0001;PBS_Server;Svr;PBS_Server;LOG_ERROR::sync_node_jobs, stray job 21190.tyrone-cluster found on tyrone-node6
04/03/2013 07:33:48;0001;PBS_Server;Svr;PBS_Server;LOG_ERROR::sync_node_jobs, stray job 21306.tyrone-cluster found on tyrone-node5
04/03/2013 07:34:14;0001;PBS_Server;Svr;PBS_Server;LOG_ERROR::sync_node_jobs, stray job 21312.tyrone-cluster found on tyrone-node4
04/03/2013 07:34:29;0001;PBS_Server;Svr;PBS_Server;LOG_ERROR::sync_node_jobs, stray job 21190.tyrone-cluster found on tyrone-node6
04/03/2013 07:34:32;0001;PBS_Server;Svr;PBS_Server;LOG_ERROR::sync_node_jobs, stray job 21306.tyrone-cluster found on tyrone-node5
04/03/2013 07:34:59;0001;PBS_Server;Svr;PBS_Server;LOG_ERROR::sync_node_jobs, stray job 21312.tyrone-cluster found on tyrone-node4
04/03/2013 07:35:14;0001;PBS_Server;Svr;PBS_Server;LOG_ERROR::sync_node_jobs, stray job 21190.tyrone-cluster found on tyrone-node6
04/03/2013 07:35:17;0001;PBS_Server;Svr;PBS_Server;LOG_ERROR::sync_node_jobs, stray job 21306.tyrone-cluster found on tyrone-node5
04/03/2013 07:35:44;0001;PBS_Server;Svr;PBS_Server;LOG_ERROR::sync_node_jobs, stray job 21312.tyrone-cluster found on tyrone-node4
04/03/2013 07:35:59;0001;PBS_Server;Svr;PBS_Server;LOG_ERROR::sync_node_jobs, stray job 21190.tyrone-cluster found on tyrone-node6
04/03/2013 07:36:02;0001;PBS_Server;Svr;PBS_Server;LOG_ERROR::sync_node_jobs, stray job 21306.tyrone-cluster found on tyrone-node5
04/03/2013 07:36:29;0001;PBS_Server;Svr;PBS_Server;LOG_ERROR::sync_node_jobs, stray job 21312.tyrone-cluster found on tyrone-node4
04/03/2013 07:36:44;0001;PBS_Server;Svr;PBS_Server;LOG_ERROR::sync_node_jobs, stray job 21190.tyrone-cluster found on tyrone-node6
04/03/2013 07:36:47;0001;PBS_Server;Svr;PBS_Server;LOG_ERROR::sync_node_jobs, stray job 21306.tyrone-cluster found on tyrone-node5
04/03/2013 07:37:14;0001;PBS_Server;Svr;PBS_Server;LOG_ERROR::sync_node_jobs, stray job 21312.tyrone-cluster found on tyrone-node4
04/03/2013 07:37:29;0001;PBS_Server;Svr;PBS_Server;LOG_ERROR::sync_node_jobs, stray job 21190.tyrone-cluster found on tyrone-node6
04/03/2013 07:37:32;0001;PBS_Server;Svr;PBS_Server;LOG_ERROR::sync_node_jobs, stray job 21306.tyrone-cluster found on tyrone-node5
04/03/2013 07:37:59;0001;PBS_Server;Svr;PBS_Server;LOG_ERROR::sync_node_jobs, stray job 21312.tyrone-cluster found on tyrone-node4
04/03/2013 07:38:14;0001;PBS_Server;Svr;PBS_Server;LOG_ERROR::sync_node_jobs, stray job 21190.tyrone-cluster found on tyrone-node6
04/03/2013 07:38:17;0001;PBS_Server;Svr;PBS_Server;LOG_ERROR::sync_node_jobs, stray job 21306.tyrone-cluster found on tyrone-node5
04/03/2013 07:38:30;0002;PBS_Server;Svr;PBS_Server;Torque Server Version = 3.0.5, loglevel = 0
04/03/2013 07:38:43;0001;PBS_Server;Svr;PBS_Server;LOG_ERROR::sync_node_jobs, stray job 21312.tyrone-cluster found on tyrone-node4
04/03/2013 07:38:59;0001;PBS_Server;Svr;PBS_Server;LOG_ERROR::sync_node_jobs, stray job 21190.tyrone-cluster found on tyrone-node6
04/03/2013 07:39:02;0001;PBS_Server;Svr;PBS_Server;LOG_ERROR::sync_node_jobs, stray job 21306.tyrone-cluster found on tyrone-node5
04/03/2013 07:39:28;0001;PBS_Server;Svr;PBS_Server;LOG_ERROR::sync_node_jobs, stray job 21312.tyrone-cluster found on tyrone-node4
04/03/2013 07:39:44;0001;PBS_Server;Svr;PBS_Server;LOG_ERROR::sync_node_jobs, stray job 21190.tyrone-cluster found on tyrone-node6
04/03/2013 07:39:47;0001;PBS_Server;Svr;PBS_Server;LOG_ERROR::sync_node_jobs, stray job 21306.tyrone-cluster found on tyrone-node5
04/03/2013 07:40:13;0001;PBS_Server;Svr;PBS_Server;LOG_ERROR::sync_node_jobs, stray job 21312.tyrone-cluster found on tyrone-node4
04/03/2013 07:40:28;0001;PBS_Server;Svr;PBS_Server;LOG_ERROR::sync_node_jobs, stray job 21190.tyrone-cluster found on tyrone-node6
04/03/2013 07:40:32;0001;PBS_Server;Svr;PBS_Server;LOG_ERROR::sync_node_jobs, stray job 21306.tyrone-cluster found on tyrone-node5
04/03/2013 07:40:58;0001;PBS_Server;Svr;PBS_Server;LOG_ERROR::sync_node_jobs, stray job 21312.tyrone-cluster found on tyrone-node4
04/03/2013 07:41:13;0001;PBS_Server;Svr;PBS_Server;LOG_ERROR::sync_node_jobs, stray job 21190.tyrone-cluster found on tyrone-node6
04/03/2013 07:41:17;0001;PBS_Server;Svr;PBS_Server;LOG_ERROR::sync_node_jobs, stray job 21306.tyrone-cluster found on tyrone-node5
04/03/2013 07:41:43;0001;PBS_Server;Svr;PBS_Server;LOG_ERROR::sync_node_jobs, stray job 21312.tyrone-cluster found on tyrone-node4
04/03/2013 07:41:58;0001;PBS_Server;Svr;PBS_Server;LOG_ERROR::sync_node_jobs, stray job 21190.tyrone-cluster found on tyrone-node6
04/03/2013 07:42:02;0001;PBS_Server;Svr;PBS_Server;LOG_ERROR::sync_node_jobs, stray job 21306.tyrone-cluster found on tyrone-node5
04/03/2013 07:42:29;0001;PBS_Server;Svr;PBS_Server;LOG_ERROR::sync_node_jobs, stray job 21312.tyrone-cluster found on tyrone-node4
04/03/2013 07:42:44;0001;PBS_Server;Svr;PBS_Server;LOG_ERROR::sync_node_jobs, stray job 21190.tyrone-cluster found on tyrone-node6
04/03/2013 07:42:44;0040;PBS_Server;Svr;tyrone-cluster;Scheduler was sent the command time
04/03/2013 07:42:48;0001;PBS_Server;Svr;PBS_Server;LOG_ERROR::sync_node_jobs, stray job 21306.tyrone-cluster found on tyrone-node5
04/03/2013 07:43:14;0001;PBS_Server;Svr;PBS_Server;LOG_ERROR::sync_node_jobs, stray job 21312.tyrone-cluster found on tyrone-node4
04/03/2013 07:43:29;0001;PBS_Server;Svr;PBS_Server;LOG_ERROR::sync_node_jobs, stray job 21190.tyrone-cluster found on tyrone-node6
04/03/2013 07:43:30;0002;PBS_Server;Svr;PBS_Server;Torque Server Version = 3.0.5, loglevel = 0
04/03/2013 07:43:33;0001;PBS_Server;Svr;PBS_Server;LOG_ERROR::sync_node_jobs, stray job 21306.tyrone-cluster found on tyrone-node5
04/03/2013 07:43:59;0001;PBS_Server;Svr;PBS_Server;LOG_ERROR::sync_node_jobs, stray job 21312.tyrone-cluster found on tyrone-node4
04/03/2013 07:44:14;0001;PBS_Server;Svr;PBS_Server;LOG_ERROR::sync_node_jobs, stray job 21190.tyrone-cluster found on tyrone-node6
04/03/2013 07:44:18;0001;PBS_Server;Svr;PBS_Server;LOG_ERROR::sync_node_jobs, stray job 21306.tyrone-cluster found on tyrone-node5
04/03/2013 07:44:44;0001;PBS_Server;Svr;PBS_Server;LOG_ERROR::sync_node_jobs, stray job 21312.tyrone-cluster found on tyrone-node4
04/03/2013 07:44:59;0001;PBS_Server;Svr;PBS_Server;LOG_ERROR::sync_node_jobs, stray job 21190.tyrone-cluster found on tyrone-node6
04/03/2013 07:45:03;0001;PBS_Server;Svr;PBS_Server;LOG_ERROR::sync_node_jobs, stray job 21306.tyrone-cluster found on tyrone-node5
04/03/2013 07:45:29;0001;PBS_Server;Svr;PBS_Server;LOG_ERROR::sync_node_jobs, stray job 21312.tyrone-cluster found on tyrone-node4
04/03/2013 07:45:44;0001;PBS_Server;Svr;PBS_Server;LOG_ERROR::sync_node_jobs, stray job 21190.tyrone-cluster found on tyrone-node6
04/03/2013 07:45:48;0001;PBS_Server;Svr;PBS_Server;LOG_ERROR::sync_node_jobs, stray job 21306.tyrone-cluster found on tyrone-node5
04/03/2013 07:46:14;0001;PBS_Server;Svr;PBS_Server;LOG_ERROR::sync_node_jobs, stray job 21312.tyrone-cluster found on tyrone-node4
04/03/2013 07:46:29;0001;PBS_Server;Svr;PBS_Server;LOG_ERROR::sync_node_jobs, stray job 21190.tyrone-cluster found on tyrone-node6
04/03/2013 07:46:32;0001;PBS_Server;Svr;PBS_Server;LOG_ERROR::sync_node_jobs, stray job 21306.tyrone-cluster found on tyrone-node5
04/03/2013 07:46:59;0001;PBS_Server;Svr;PBS_Server;LOG_ERROR::sync_node_jobs, stray job 21312.tyrone-cluster found on tyrone-node4
04/03/2013 07:47:14;0001;PBS_Server;Svr;PBS_Server;LOG_ERROR::sync_node_jobs, stray job 21190.tyrone-cluster found on tyrone-node6
04/03/2013 07:47:17;0001;PBS_Server;Svr;PBS_Server;LOG_ERROR::sync_node_jobs, stray job 21306.tyrone-cluster found on tyrone-node5
04/03/2013 07:47:44;0001;PBS_Server;Svr;PBS_Server;LOG_ERROR::sync_node_jobs, stray job 21312.tyrone-cluster found on tyrone-node4
04/03/2013 07:47:59;0001;PBS_Server;Svr;PBS_Server;LOG_ERROR::sync_node_jobs, stray job 21190.tyrone-cluster found on tyrone-node6
04/03/2013 07:48:02;0001;PBS_Server;Svr;PBS_Server;LOG_ERROR::sync_node_jobs, stray job 21306.tyrone-cluster found on tyrone-node5
04/03/2013 07:48:28;0001;PBS_Server;Svr;PBS_Server;LOG_ERROR::sync_node_jobs, stray job 21312.tyrone-cluster found on tyrone-node4
04/03/2013 07:48:30;0002;PBS_Server;Svr;PBS_Server;Torque Server Version = 3.0.5, loglevel = 0
04/03/2013 07:48:44;0001;PBS_Server;Svr;PBS_Server;LOG_ERROR::sync_node_jobs, stray job 21190.tyrone-cluster found on tyrone-node6
04/03/2013 07:48:47;0001;PBS_Server;Svr;PBS_Server;LOG_ERROR::sync_node_jobs, stray job 21306.tyrone-cluster found on tyrone-node5
04/03/2013 07:49:13;0001;PBS_Server;Svr;PBS_Server;LOG_ERROR::sync_node_jobs, stray job 21312.tyrone-cluster found on tyrone-node4
04/03/2013 07:49:29;0001;PBS_Server;Svr;PBS_Server;LOG_ERROR::sync_node_jobs, stray job 21190.tyrone-cluster found on tyrone-node6
04/03/2013 07:49:32;0001;PBS_Server;Svr;PBS_Server;LOG_ERROR::sync_node_jobs, stray job 21306.tyrone-cluster found on tyrone-node5
04/03/2013 07:49:58;0001;PBS_Server;Svr;PBS_Server;LOG_ERROR::sync_node_jobs, stray job 21312.tyrone-cluster found on tyrone-node4
04/03/2013 07:50:14;0001;PBS_Server;Svr;PBS_Server;LOG_ERROR::sync_node_jobs, stray job 21190.tyrone-cluster found on tyrone-node6
04/03/2013 07:50:17;0001;PBS_Server;Svr;PBS_Server;LOG_ERROR::sync_node_jobs, stray job 21306.tyrone-cluster found on tyrone-node5
04/03/2013 07:50:43;0001;PBS_Server;Svr;PBS_Server;LOG_ERROR::sync_node_jobs, stray job 21312.tyrone-cluster found on tyrone-node4
04/03/2013 07:50:59;0001;PBS_Server;Svr;PBS_Server;LOG_ERROR::sync_node_jobs, stray job 21190.tyrone-cluster found on tyrone-node6
04/03/2013 07:51:02;0001;PBS_Server;Svr;PBS_Server;LOG_ERROR::sync_node_jobs, stray job 21306.tyrone-cluster found on tyrone-node5
04/03/2013 07:51:28;0001;PBS_Server;Svr;PBS_Server;LOG_ERROR::sync_node_jobs, stray job 21312.tyrone-cluster found on tyrone-node4
04/03/2013 07:51:44;0001;PBS_Server;Svr;PBS_Server;LOG_ERROR::sync_node_jobs, stray job 21190.tyrone-cluster found on tyrone-node6
04/03/2013 07:51:47;0001;PBS_Server;Svr;PBS_Server;LOG_ERROR::sync_node_jobs, stray job 21306.tyrone-cluster found on tyrone-node5
04/03/2013 07:52:13;0001;PBS_Server;Svr;PBS_Server;LOG_ERROR::sync_node_jobs, stray job 21312.tyrone-cluster found on tyrone-node4
04/03/2013 07:52:28;0001;PBS_Server;Svr;PBS_Server;LOG_ERROR::sync_node_jobs, stray job 21190.tyrone-cluster found on tyrone-node6
04/03/2013 07:52:32;0001;PBS_Server;Svr;PBS_Server;LOG_ERROR::sync_node_jobs, stray job 21306.tyrone-cluster found on tyrone-node5
04/03/2013 07:52:44;0040;PBS_Server;Svr;tyrone-cluster;Scheduler was sent the command time
04/03/2013 07:52:58;0001;PBS_Server;Svr;PBS_Server;LOG_ERROR::sync_node_jobs, stray job 21312.tyrone-cluster found on tyrone-node4
04/03/2013 07:53:13;0001;PBS_Server;Svr;PBS_Server;LOG_ERROR::sync_node_jobs, stray job 21190.tyrone-cluster found on tyrone-node6
04/03/2013 07:53:17;0001;PBS_Server;Svr;PBS_Server;LOG_ERROR::sync_node_jobs, stray job 21306.tyrone-cluster found on tyrone-node5
04/03/2013 07:53:30;0002;PBS_Server;Svr;PBS_Server;Torque Server Version = 3.0.5, loglevel = 0
04/03/2013 07:53:43;0001;PBS_Server;Svr;PBS_Server;LOG_ERROR::sync_node_jobs, stray job 21312.tyrone-cluster found on tyrone-node4
04/03/2013 07:53:58;0001;PBS_Server;Svr;PBS_Server;LOG_ERROR::sync_node_jobs, stray job 21190.tyrone-cluster found on tyrone-node6
04/03/2013 07:54:02;0001;PBS_Server;Svr;PBS_Server;LOG_ERROR::sync_node_jobs, stray job 21306.tyrone-cluster found on tyrone-node5
04/03/2013 07:54:29;0001;PBS_Server;Svr;PBS_Server;LOG_ERROR::sync_node_jobs, stray job 21312.tyrone-cluster found on tyrone-node4
04/03/2013 07:54:44;0001;PBS_Server;Svr;PBS_Server;LOG_ERROR::sync_node_jobs, stray job 21190.tyrone-cluster found on tyrone-node6
04/03/2013 07:54:48;0001;PBS_Server;Svr;PBS_Server;LOG_ERROR::sync_node_jobs, stray job 21306.tyrone-cluster found on tyrone-node5
04/03/2013 07:55:14;0001;PBS_Server;Svr;PBS_Server;LOG_ERROR::sync_node_jobs, stray job 21312.tyrone-cluster found on tyrone-node4
04/03/2013 07:55:29;0001;PBS_Server;Svr;PBS_Server;LOG_ERROR::sync_node_jobs, stray job 21190.tyrone-cluster found on tyrone-node6
04/03/2013 07:55:33;0001;PBS_Server;Svr;PBS_Server;LOG_ERROR::sync_node_jobs, stray job 21306.tyrone-cluster found on tyrone-node5
04/03/2013 07:55:59;0001;PBS_Server;Svr;PBS_Server;LOG_ERROR::sync_node_jobs, stray job 21312.tyrone-cluster found on tyrone-node4
04/03/2013 07:56:14;0001;PBS_Server;Svr;PBS_Server;LOG_ERROR::sync_node_jobs, stray job 21190.tyrone-cluster found on tyrone-node6
04/03/2013 07:56:18;0001;PBS_Server;Svr;PBS_Server;LOG_ERROR::sync_node_jobs, stray job 21306.tyrone-cluster found on tyrone-node5
04/03/2013 07:56:44;0001;PBS_Server;Svr;PBS_Server;LOG_ERROR::sync_node_jobs, stray job 21312.tyrone-cluster found on tyrone-node4
04/03/2013 07:56:59;0001;PBS_Server;Svr;PBS_Server;LOG_ERROR::sync_node_jobs, stray job 21190.tyrone-cluster found on tyrone-node6
04/03/2013 07:57:03;0001;PBS_Server;Svr;PBS_Server;LOG_ERROR::sync_node_jobs, stray job 21306.tyrone-cluster found on tyrone-node5
04/03/2013 07:57:29;0001;PBS_Server;Svr;PBS_Server;LOG_ERROR::sync_node_jobs, stray job 21312.tyrone-cluster found on tyrone-node4
04/03/2013 07:57:44;0001;PBS_Server;Svr;PBS_Server;LOG_ERROR::sync_node_jobs, stray job 21190.tyrone-cluster found on tyrone-node6
04/03/2013 07:57:48;0001;PBS_Server;Svr;PBS_Server;LOG_ERROR::sync_node_jobs, stray job 21306.tyrone-cluster found on tyrone-node5
04/03/2013 07:58:13;0001;PBS_Server;Svr;PBS_Server;LOG_ERROR::sync_node_jobs, stray job 21312.tyrone-cluster found on tyrone-node4
04/03/2013 07:58:29;0001;PBS_Server;Svr;PBS_Server;LOG_ERROR::sync_node_jobs, stray job 21190.tyrone-cluster found on tyrone-node6
04/03/2013 07:58:30;0002;PBS_Server;Svr;PBS_Server;Torque Server Version = 3.0.5, loglevel = 0
04/03/2013 07:58:33;0001;PBS_Server;Svr;PBS_Server;LOG_ERROR::sync_node_jobs, stray job 21306.tyrone-cluster found on tyrone-node5
04/03/2013 07:58:58;0001;PBS_Server;Svr;PBS_Server;LOG_ERROR::sync_node_jobs, stray job 21312.tyrone-cluster found on tyrone-node4
04/03/2013 07:59:14;0001;PBS_Server;Svr;PBS_Server;LOG_ERROR::sync_node_jobs, stray job 21190.tyrone-cluster found on tyrone-node6
04/03/2013 07:59:17;0001;PBS_Server;Svr;PBS_Server;LOG_ERROR::sync_node_jobs, stray job 21306.tyrone-cluster found on tyrone-node5
04/03/2013 07:59:43;0001;PBS_Server;Svr;PBS_Server;LOG_ERROR::sync_node_jobs, stray job 21312.tyrone-cluster found on tyrone-node4
04/03/2013 07:59:59;0001;PBS_Server;Svr;PBS_Server;LOG_ERROR::sync_node_jobs, stray job 21190.tyrone-cluster found on tyrone-node6
04/03/2013 08:00:02;0001;PBS_Server;Svr;PBS_Server;LOG_ERROR::sync_node_jobs, stray job 21306.tyrone-cluster found on tyrone-node5
04/03/2013 08:00:28;0001;PBS_Server;Svr;PBS_Server;LOG_ERROR::sync_node_jobs, stray job 21312.tyrone-cluster found on tyrone-node4
04/03/2013 08:00:44;0001;PBS_Server;Svr;PBS_Server;LOG_ERROR::sync_node_jobs, stray job 21190.tyrone-cluster found on tyrone-node6
04/03/2013 08:00:47;0001;PBS_Server;Svr;PBS_Server;LOG_ERROR::sync_node_jobs, stray job 21306.tyrone-cluster found on tyrone-node5
04/03/2013 08:01:13;0001;PBS_Server;Svr;PBS_Server;LOG_ERROR::sync_node_jobs, stray job 21312.tyrone-cluster found on tyrone-node4
04/03/2013 08:01:29;0001;PBS_Server;Svr;PBS_Server;LOG_ERROR::sync_node_jobs, stray job 21190.tyrone-cluster found on tyrone-node6
04/03/2013 08:01:32;0001;PBS_Server;Svr;PBS_Server;LOG_ERROR::sync_node_jobs, stray job 21306.tyrone-cluster found on tyrone-node5
04/03/2013 08:01:58;0001;PBS_Server;Svr;PBS_Server;LOG_ERROR::sync_node_jobs, stray job 21312.tyrone-cluster found on tyrone-node4
04/03/2013 08:02:14;0001;PBS_Server;Svr;PBS_Server;LOG_ERROR::sync_node_jobs, stray job 21190.tyrone-cluster found on tyrone-node6
04/03/2013 08:02:17;0001;PBS_Server;Svr;PBS_Server;LOG_ERROR::sync_node_jobs, stray job 21306.tyrone-cluster found on tyrone-node5
04/03/2013 08:02:43;0001;PBS_Server;Svr;PBS_Server;LOG_ERROR::sync_node_jobs, stray job 21312.tyrone-cluster found on tyrone-node4
04/03/2013 08:02:44;0040;PBS_Server;Svr;tyrone-cluster;Scheduler was sent the command time
04/03/2013 08:02:58;0001;PBS_Server;Svr;PBS_Server;LOG_ERROR::sync_node_jobs, stray job 21190.tyrone-cluster found on tyrone-node6
04/03/2013 08:03:02;0001;PBS_Server;Svr;PBS_Server;LOG_ERROR::sync_node_jobs, stray job 21306.tyrone-cluster found on tyrone-node5
04/03/2013 08:03:28;0001;PBS_Server;Svr;PBS_Server;LOG_ERROR::sync_node_jobs, stray job 21312.tyrone-cluster found on tyrone-node4
04/03/2013 08:03:30;0002;PBS_Server;Svr;PBS_Server;Torque Server Version = 3.0.5, loglevel = 0
04/03/2013 08:03:43;0001;PBS_Server;Svr;PBS_Server;LOG_ERROR::sync_node_jobs, stray job 21190.tyrone-cluster found on tyrone-node6
04/03/2013 08:03:47;0001;PBS_Server;Svr;PBS_Server;LOG_ERROR::sync_node_jobs, stray job 21306.tyrone-cluster found on tyrone-node5
04/03/2013 08:04:13;0001;PBS_Server;Svr;PBS_Server;LOG_ERROR::sync_node_jobs, stray job 21312.tyrone-cluster found on tyrone-node4
04/03/2013 08:04:28;0001;PBS_Server;Svr;PBS_Server;LOG_ERROR::sync_node_jobs, stray job 21190.tyrone-cluster found on tyrone-node6
04/03/2013 08:04:32;0001;PBS_Server;Svr;PBS_Server;LOG_ERROR::sync_node_jobs, stray job 21306.tyrone-cluster found on tyrone-node5
04/03/2013 08:04:58;0001;PBS_Server;Svr;PBS_Server;LOG_ERROR::sync_node_jobs, stray job 21312.tyrone-cluster found on tyrone-node4
04/03/2013 08:05:13;0001;PBS_Server;Svr;PBS_Server;LOG_ERROR::sync_node_jobs, stray job 21190.tyrone-cluster found on tyrone-node6
04/03/2013 08:05:17;0001;PBS_Server;Svr;PBS_Server;LOG_ERROR::sync_node_jobs, stray job 21306.tyrone-cluster found on tyrone-node5
04/03/2013 08:05:43;0001;PBS_Server;Svr;PBS_Server;LOG_ERROR::sync_node_jobs, stray job 21312.tyrone-cluster found on tyrone-node4
04/03/2013 08:05:58;0001;PBS_Server;Svr;PBS_Server;LOG_ERROR::sync_node_jobs, stray job 21190.tyrone-cluster found on tyrone-node6
04/03/2013 08:06:02;0001;PBS_Server;Svr;PBS_Server;LOG_ERROR::sync_node_jobs, stray job 21306.tyrone-cluster found on tyrone-node5
04/03/2013 08:06:28;0001;PBS_Server;Svr;PBS_Server;LOG_ERROR::sync_node_jobs, stray job 21312.tyrone-cluster found on tyrone-node4
04/03/2013 08:06:44;0001;PBS_Server;Svr;PBS_Server;LOG_ERROR::sync_node_jobs, stray job 21190.tyrone-cluster found on tyrone-node6
04/03/2013 08:06:47;0001;PBS_Server;Svr;PBS_Server;LOG_ERROR::sync_node_jobs, stray job 21306.tyrone-cluster found on tyrone-node5
04/03/2013 08:07:14;0001;PBS_Server;Svr;PBS_Server;LOG_ERROR::sync_node_jobs, stray job 21312.tyrone-cluster found on tyrone-node4
04/03/2013 08:07:29;0001;PBS_Server;Svr;PBS_Server;LOG_ERROR::sync_node_jobs, stray job 21190.tyrone-cluster found on tyrone-node6
04/03/2013 08:07:33;0001;PBS_Server;Svr;PBS_Server;LOG_ERROR::sync_node_jobs, stray job 21306.tyrone-cluster found on tyrone-node5
04/03/2013 08:07:59;0001;PBS_Server;Svr;PBS_Server;LOG_ERROR::sync_node_jobs, stray job 21312.tyrone-cluster found on tyrone-node4
04/03/2013 08:08:14;0001;PBS_Server;Svr;PBS_Server;LOG_ERROR::sync_node_jobs, stray job 21190.tyrone-cluster found on tyrone-node6
04/03/2013 08:08:18;0001;PBS_Server;Svr;PBS_Server;LOG_ERROR::sync_node_jobs, stray job 21306.tyrone-cluster found on tyrone-node5
04/03/2013 08:08:30;0002;PBS_Server;Svr;PBS_Server;Torque Server Version = 3.0.5, loglevel = 0
04/03/2013 08:08:43;0001;PBS_Server;Svr;PBS_Server;LOG_ERROR::sync_node_jobs, stray job 21312.tyrone-cluster found on tyrone-node4
04/03/2013 08:08:59;0001;PBS_Server;Svr;PBS_Server;LOG_ERROR::sync_node_jobs, stray job 21190.tyrone-cluster found on tyrone-node6
04/03/2013 08:09:03;0001;PBS_Server;Svr;PBS_Server;LOG_ERROR::sync_node_jobs, stray job 21306.tyrone-cluster found on tyrone-node5
04/03/2013 08:09:28;0001;PBS_Server;Svr;PBS_Server;LOG_ERROR::sync_node_jobs, stray job 21312.tyrone-cluster found on tyrone-node4
04/03/2013 08:09:44;0001;PBS_Server;Svr;PBS_Server;LOG_ERROR::sync_node_jobs, stray job 21190.tyrone-cluster found on tyrone-node6
04/03/2013 08:09:48;0001;PBS_Server;Svr;PBS_Server;LOG_ERROR::sync_node_jobs, stray job 21306.tyrone-cluster found on tyrone-node5
04/03/2013 08:10:13;0001;PBS_Server;Svr;PBS_Server;LOG_ERROR::sync_node_jobs, stray job 21312.tyrone-cluster found on tyrone-node4
04/03/2013 08:10:29;0001;PBS_Server;Svr;PBS_Server;LOG_ERROR::sync_node_jobs, stray job 21190.tyrone-cluster found on tyrone-node6
04/03/2013 08:10:33;0001;PBS_Server;Svr;PBS_Server;LOG_ERROR::sync_node_jobs, stray job 21306.tyrone-cluster found on tyrone-node5
04/03/2013 08:10:58;0001;PBS_Server;Svr;PBS_Server;LOG_ERROR::sync_node_jobs, stray job 21312.tyrone-cluster found on tyrone-node4
04/03/2013 08:11:14;0001;PBS_Server;Svr;PBS_Server;LOG_ERROR::sync_node_jobs, stray job 21190.tyrone-cluster found on tyrone-node6
04/03/2013 08:11:17;0001;PBS_Server;Svr;PBS_Server;LOG_ERROR::sync_node_jobs, stray job 21306.tyrone-cluster found on tyrone-node5
04/03/2013 08:11:43;0001;PBS_Server;Svr;PBS_Server;LOG_ERROR::sync_node_jobs, stray job 21312.tyrone-cluster found on tyrone-node4
04/03/2013 08:11:59;0001;PBS_Server;Svr;PBS_Server;LOG_ERROR::sync_node_jobs, stray job 21190.tyrone-cluster found on tyrone-node6
04/03/2013 08:12:02;0001;PBS_Server;Svr;PBS_Server;LOG_ERROR::sync_node_jobs, stray job 21306.tyrone-cluster found on tyrone-node5
04/03/2013 08:12:28;0001;PBS_Server;Svr;PBS_Server;LOG_ERROR::sync_node_jobs, stray job 21312.tyrone-cluster found on tyrone-node4
04/03/2013 08:12:44;0001;PBS_Server;Svr;PBS_Server;LOG_ERROR::sync_node_jobs, stray job 21190.tyrone-cluster found on tyrone-node6
04/03/2013 08:12:44;0040;PBS_Server;Svr;tyrone-cluster;Scheduler was sent the command time
04/03/2013 08:12:47;0001;PBS_Server;Svr;PBS_Server;LOG_ERROR::sync_node_jobs, stray job 21306.tyrone-cluster found on tyrone-node5
04/03/2013 08:13:13;0001;PBS_Server;Svr;PBS_Server;LOG_ERROR::sync_node_jobs, stray job 21312.tyrone-cluster found on tyrone-node4
04/03/2013 08:13:29;0001;PBS_Server;Svr;PBS_Server;LOG_ERROR::sync_node_jobs, stray job 21190.tyrone-cluster found on tyrone-node6
04/03/2013 08:13:30;0002;PBS_Server;Svr;PBS_Server;Torque Server Version = 3.0.5, loglevel = 0
04/03/2013 08:13:32;0001;PBS_Server;Svr;PBS_Server;LOG_ERROR::sync_node_jobs, stray job 21306.tyrone-cluster found on tyrone-node5
04/03/2013 08:13:58;0001;PBS_Server;Svr;PBS_Server;LOG_ERROR::sync_node_jobs, stray job 21312.tyrone-cluster found on tyrone-node4
04/03/2013 08:14:14;0001;PBS_Server;Svr;PBS_Server;LOG_ERROR::sync_node_jobs, stray job 21190.tyrone-cluster found on tyrone-node6
04/03/2013 08:14:17;0001;PBS_Server;Svr;PBS_Server;LOG_ERROR::sync_node_jobs, stray job 21306.tyrone-cluster found on tyrone-node5
04/03/2013 08:14:43;0001;PBS_Server;Svr;PBS_Server;LOG_ERROR::sync_node_jobs, stray job 21312.tyrone-cluster found on tyrone-node4
04/03/2013 08:14:58;0001;PBS_Server;Svr;PBS_Server;LOG_ERROR::sync_node_jobs, stray job 21190.tyrone-cluster found on tyrone-node6
04/03/2013 08:15:02;0001;PBS_Server;Svr;PBS_Server;LOG_ERROR::sync_node_jobs, stray job 21306.tyrone-cluster found on tyrone-node5
04/03/2013 08:15:28;0001;PBS_Server;Svr;PBS_Server;LOG_ERROR::sync_node_jobs, stray job 21312.tyrone-cluster found on tyrone-node4
04/03/2013 08:15:43;0001;PBS_Server;Svr;PBS_Server;LOG_ERROR::sync_node_jobs, stray job 21190.tyrone-cluster found on tyrone-node6
04/03/2013 08:15:47;0001;PBS_Server;Svr;PBS_Server;LOG_ERROR::sync_node_jobs, stray job 21306.tyrone-cluster found on tyrone-node5
04/03/2013 08:16:13;0001;PBS_Server;Svr;PBS_Server;LOG_ERROR::sync_node_jobs, stray job 21312.tyrone-cluster found on tyrone-node4
04/03/2013 08:16:28;0001;PBS_Server;Svr;PBS_Server;LOG_ERROR::sync_node_jobs, stray job 21190.tyrone-cluster found on tyrone-node6
04/03/2013 08:16:32;0001;PBS_Server;Svr;PBS_Server;LOG_ERROR::sync_node_jobs, stray job 21306.tyrone-cluster found on tyrone-node5
04/03/2013 08:16:58;0001;PBS_Server;Svr;PBS_Server;LOG_ERROR::sync_node_jobs, stray job 21312.tyrone-cluster found on tyrone-node4
04/03/2013 08:17:13;0001;PBS_Server;Svr;PBS_Server;LOG_ERROR::sync_node_jobs, stray job 21190.tyrone-cluster found on tyrone-node6
04/03/2013 08:17:17;0001;PBS_Server;Svr;PBS_Server;LOG_ERROR::sync_node_jobs, stray job 21306.tyrone-cluster found on tyrone-node5
04/03/2013 08:17:43;0001;PBS_Server;Svr;PBS_Server;LOG_ERROR::sync_node_jobs, stray job 21312.tyrone-cluster found on tyrone-node4
04/03/2013 08:17:58;0001;PBS_Server;Svr;PBS_Server;LOG_ERROR::sync_node_jobs, stray job 21190.tyrone-cluster found on tyrone-node6
04/03/2013 08:18:02;0001;PBS_Server;Svr;PBS_Server;LOG_ERROR::sync_node_jobs, stray job 21306.tyrone-cluster found on tyrone-node5
04/03/2013 08:18:27;0001;PBS_Server;Svr;PBS_Server;LOG_ERROR::sync_node_jobs, stray job 21312.tyrone-cluster found on tyrone-node4
04/03/2013 08:18:30;0002;PBS_Server;Svr;PBS_Server;Torque Server Version = 3.0.5, loglevel = 0
04/03/2013 08:18:43;0001;PBS_Server;Svr;PBS_Server;LOG_ERROR::sync_node_jobs, stray job 21190.tyrone-cluster found on tyrone-node6
04/03/2013 08:18:47;0001;PBS_Server;Svr;PBS_Server;LOG_ERROR::sync_node_jobs, stray job 21306.tyrone-cluster found on tyrone-node5
04/03/2013 08:19:12;0001;PBS_Server;Svr;PBS_Server;LOG_ERROR::sync_node_jobs, stray job 21312.tyrone-cluster found on tyrone-node4
04/03/2013 08:19:29;0001;PBS_Server;Svr;PBS_Server;LOG_ERROR::sync_node_jobs, stray job 21190.tyrone-cluster found on tyrone-node6
04/03/2013 08:19:33;0001;PBS_Server;Svr;PBS_Server;LOG_ERROR::sync_node_jobs, stray job 21306.tyrone-cluster found on tyrone-node5
04/03/2013 08:19:58;0001;PBS_Server;Svr;PBS_Server;LOG_ERROR::sync_node_jobs, stray job 21312.tyrone-cluster found on tyrone-node4
04/03/2013 08:20:14;0001;PBS_Server;Svr;PBS_Server;LOG_ERROR::sync_node_jobs, stray job 21190.tyrone-cluster found on tyrone-node6
04/03/2013 08:20:18;0001;PBS_Server;Svr;PBS_Server;LOG_ERROR::sync_node_jobs, stray job 21306.tyrone-cluster found on tyrone-node5
04/03/2013 08:20:43;0001;PBS_Server;Svr;PBS_Server;LOG_ERROR::sync_node_jobs, stray job 21312.tyrone-cluster found on tyrone-node4
04/03/2013 08:20:59;0001;PBS_Server;Svr;PBS_Server;LOG_ERROR::sync_node_jobs, stray job 21190.tyrone-cluster found on tyrone-node6
04/03/2013 08:21:03;0001;PBS_Server;Svr;PBS_Server;LOG_ERROR::sync_node_jobs, stray job 21306.tyrone-cluster found on tyrone-node5
04/03/2013 08:21:28;0001;PBS_Server;Svr;PBS_Server;LOG_ERROR::sync_node_jobs, stray job 21312.tyrone-cluster found on tyrone-node4
04/03/2013 08:21:44;0001;PBS_Server;Svr;PBS_Server;LOG_ERROR::sync_node_jobs, stray job 21190.tyrone-cluster found on tyrone-node6
04/03/2013 08:21:48;0001;PBS_Server;Svr;PBS_Server;LOG_ERROR::sync_node_jobs, stray job 21306.tyrone-cluster found on tyrone-node5
04/03/2013 08:22:13;0001;PBS_Server;Svr;PBS_Server;LOG_ERROR::sync_node_jobs, stray job 21312.tyrone-cluster found on tyrone-node4
04/03/2013 08:22:29;0001;PBS_Server;Svr;PBS_Server;LOG_ERROR::sync_node_jobs, stray job 21190.tyrone-cluster found on tyrone-node6
04/03/2013 08:22:33;0001;PBS_Server;Svr;PBS_Server;LOG_ERROR::sync_node_jobs, stray job 21306.tyrone-cluster found on tyrone-node5
04/03/2013 08:22:44;0040;PBS_Server;Svr;tyrone-cluster;Scheduler was sent the command time
04/03/2013 08:22:58;0001;PBS_Server;Svr;PBS_Server;LOG_ERROR::sync_node_jobs, stray job 21312.tyrone-cluster found on tyrone-node4
04/03/2013 08:23:14;0001;PBS_Server;Svr;PBS_Server;LOG_ERROR::sync_node_jobs, stray job 21190.tyrone-cluster found on tyrone-node6
04/03/2013 08:23:17;0001;PBS_Server;Svr;PBS_Server;LOG_ERROR::sync_node_jobs, stray job 21306.tyrone-cluster found on tyrone-node5
04/03/2013 08:23:30;0002;PBS_Server;Svr;PBS_Server;Torque Server Version = 3.0.5, loglevel = 0
04/03/2013 08:23:43;0001;PBS_Server;Svr;PBS_Server;LOG_ERROR::sync_node_jobs, stray job 21312.tyrone-cluster found on tyrone-node4
04/03/2013 08:23:59;0001;PBS_Server;Svr;PBS_Server;LOG_ERROR::sync_node_jobs, stray job 21190.tyrone-cluster found on tyrone-node6
04/03/2013 08:24:02;0001;PBS_Server;Svr;PBS_Server;LOG_ERROR::sync_node_jobs, stray job 21306.tyrone-cluster found on tyrone-node5
04/03/2013 08:24:28;0001;PBS_Server;Svr;PBS_Server;LOG_ERROR::sync_node_jobs, stray job 21312.tyrone-cluster found on tyrone-node4
04/03/2013 08:24:44;0001;PBS_Server;Svr;PBS_Server;LOG_ERROR::sync_node_jobs, stray job 21190.tyrone-cluster found on tyrone-node6
04/03/2013 08:24:47;0001;PBS_Server;Svr;PBS_Server;LOG_ERROR::sync_node_jobs, stray job 21306.tyrone-cluster found on tyrone-node5
04/03/2013 08:25:13;0001;PBS_Server;Svr;PBS_Server;LOG_ERROR::sync_node_jobs, stray job 21312.tyrone-cluster found on tyrone-node4
04/03/2013 08:25:29;0001;PBS_Server;Svr;PBS_Server;LOG_ERROR::sync_node_jobs, stray job 21190.tyrone-cluster found on tyrone-node6
04/03/2013 08:25:32;0001;PBS_Server;Svr;PBS_Server;LOG_ERROR::sync_node_jobs, stray job 21306.tyrone-cluster found on tyrone-node5
04/03/2013 08:25:58;0001;PBS_Server;Svr;PBS_Server;LOG_ERROR::sync_node_jobs, stray job 21312.tyrone-cluster found on tyrone-node4
04/03/2013 08:26:14;0001;PBS_Server;Svr;PBS_Server;LOG_ERROR::sync_node_jobs, stray job 21190.tyrone-cluster found on tyrone-node6
04/03/2013 08:26:17;0001;PBS_Server;Svr;PBS_Server;LOG_ERROR::sync_node_jobs, stray job 21306.tyrone-cluster found on tyrone-node5
04/03/2013 08:26:43;0001;PBS_Server;Svr;PBS_Server;LOG_ERROR::sync_node_jobs, stray job 21312.tyrone-cluster found on tyrone-node4
04/03/2013 08:26:58;0001;PBS_Server;Svr;PBS_Server;LOG_ERROR::sync_node_jobs, stray job 21190.tyrone-cluster found on tyrone-node6
04/03/2013 08:27:02;0001;PBS_Server;Svr;PBS_Server;LOG_ERROR::sync_node_jobs, stray job 21306.tyrone-cluster found on tyrone-node5
04/03/2013 08:27:28;0001;PBS_Server;Svr;PBS_Server;LOG_ERROR::sync_node_jobs, stray job 21312.tyrone-cluster found on tyrone-node4
04/03/2013 08:27:43;0001;PBS_Server;Svr;PBS_Server;LOG_ERROR::sync_node_jobs, stray job 21190.tyrone-cluster found on tyrone-node6
04/03/2013 08:27:47;0001;PBS_Server;Svr;PBS_Server;LOG_ERROR::sync_node_jobs, stray job 21306.tyrone-cluster found on tyrone-node5
04/03/2013 08:28:12;0001;PBS_Server;Svr;PBS_Server;LOG_ERROR::sync_node_jobs, stray job 21312.tyrone-cluster found on tyrone-node4
04/03/2013 08:28:28;0001;PBS_Server;Svr;PBS_Server;LOG_ERROR::sync_node_jobs, stray job 21190.tyrone-cluster found on tyrone-node6
04/03/2013 08:28:30;0002;PBS_Server;Svr;PBS_Server;Torque Server Version = 3.0.5, loglevel = 0
04/03/2013 08:28:32;0001;PBS_Server;Svr;PBS_Server;LOG_ERROR::sync_node_jobs, stray job 21306.tyrone-cluster found on tyrone-node5
04/03/2013 08:28:57;0001;PBS_Server;Svr;PBS_Server;LOG_ERROR::sync_node_jobs, stray job 21312.tyrone-cluster found on tyrone-node4
04/03/2013 08:29:13;0001;PBS_Server;Svr;PBS_Server;LOG_ERROR::sync_node_jobs, stray job 21190.tyrone-cluster found on tyrone-node6
04/03/2013 08:29:17;0001;PBS_Server;Svr;PBS_Server;LOG_ERROR::sync_node_jobs, stray job 21306.tyrone-cluster found on tyrone-node5
04/03/2013 08:29:42;0001;PBS_Server;Svr;PBS_Server;LOG_ERROR::sync_node_jobs, stray job 21312.tyrone-cluster found on tyrone-node4
04/03/2013 08:29:58;0001;PBS_Server;Svr;PBS_Server;LOG_ERROR::sync_node_jobs, stray job 21190.tyrone-cluster found on tyrone-node6
04/03/2013 08:30:02;0001;PBS_Server;Svr;PBS_Server;LOG_ERROR::sync_node_jobs, stray job 21306.tyrone-cluster found on tyrone-node5
04/03/2013 08:30:27;0001;PBS_Server;Svr;PBS_Server;LOG_ERROR::sync_node_jobs, stray job 21312.tyrone-cluster found on tyrone-node4
04/03/2013 08:30:43;0001;PBS_Server;Svr;PBS_Server;LOG_ERROR::sync_node_jobs, stray job 21190.tyrone-cluster found on tyrone-node6
04/03/2013 08:30:47;0001;PBS_Server;Svr;PBS_Server;LOG_ERROR::sync_node_jobs, stray job 21306.tyrone-cluster found on tyrone-node5
04/03/2013 08:31:12;0001;PBS_Server;Svr;PBS_Server;LOG_ERROR::sync_node_jobs, stray job 21312.tyrone-cluster found on tyrone-node4
04/03/2013 08:31:29;0001;PBS_Server;Svr;PBS_Server;LOG_ERROR::sync_node_jobs, stray job 21190.tyrone-cluster found on tyrone-node6
04/03/2013 08:31:32;0001;PBS_Server;Svr;PBS_Server;LOG_ERROR::sync_node_jobs, stray job 21306.tyrone-cluster found on tyrone-node5
04/03/2013 08:31:58;0001;PBS_Server;Svr;PBS_Server;LOG_ERROR::sync_node_jobs, stray job 21312.tyrone-cluster found on tyrone-node4
04/03/2013 08:32:14;0001;PBS_Server;Svr;PBS_Server;LOG_ERROR::sync_node_jobs, stray job 21190.tyrone-cluster found on tyrone-node6
04/03/2013 08:32:18;0001;PBS_Server;Svr;PBS_Server;LOG_ERROR::sync_node_jobs, stray job 21306.tyrone-cluster found on tyrone-node5
04/03/2013 08:32:43;0001;PBS_Server;Svr;PBS_Server;LOG_ERROR::sync_node_jobs, stray job 21312.tyrone-cluster found on tyrone-node4
04/03/2013 08:32:44;0040;PBS_Server;Svr;tyrone-cluster;Scheduler was sent the command time
04/03/2013 08:32:59;0001;PBS_Server;Svr;PBS_Server;LOG_ERROR::sync_node_jobs, stray job 21190.tyrone-cluster found on tyrone-node6
04/03/2013 08:33:03;0001;PBS_Server;Svr;PBS_Server;LOG_ERROR::sync_node_jobs, stray job 21306.tyrone-cluster found on tyrone-node5
04/03/2013 08:33:28;0001;PBS_Server;Svr;PBS_Server;LOG_ERROR::sync_node_jobs, stray job 21312.tyrone-cluster found on tyrone-node4
04/03/2013 08:33:30;0002;PBS_Server;Svr;PBS_Server;Torque Server Version = 3.0.5, loglevel = 0
04/03/2013 08:33:44;0001;PBS_Server;Svr;PBS_Server;LOG_ERROR::sync_node_jobs, stray job 21190.tyrone-cluster found on tyrone-node6
04/03/2013 08:33:48;0001;PBS_Server;Svr;PBS_Server;LOG_ERROR::sync_node_jobs, stray job 21306.tyrone-cluster found on tyrone-node5
04/03/2013 08:34:13;0001;PBS_Server;Svr;PBS_Server;LOG_ERROR::sync_node_jobs, stray job 21312.tyrone-cluster found on tyrone-node4
04/03/2013 08:34:29;0001;PBS_Server;Svr;PBS_Server;LOG_ERROR::sync_node_jobs, stray job 21190.tyrone-cluster found on tyrone-node6
04/03/2013 08:34:33;0001;PBS_Server;Svr;PBS_Server;LOG_ERROR::sync_node_jobs, stray job 21306.tyrone-cluster found on tyrone-node5
04/03/2013 08:34:58;0001;PBS_Server;Svr;PBS_Server;LOG_ERROR::sync_node_jobs, stray job 21312.tyrone-cluster found on tyrone-node4
04/03/2013 08:35:14;0001;PBS_Server;Svr;PBS_Server;LOG_ERROR::sync_node_jobs, stray job 21190.tyrone-cluster found on tyrone-node6
04/03/2013 08:35:17;0001;PBS_Server;Svr;PBS_Server;LOG_ERROR::sync_node_jobs, stray job 21306.tyrone-cluster found on tyrone-node5
04/03/2013 08:35:43;0001;PBS_Server;Svr;PBS_Server;LOG_ERROR::sync_node_jobs, stray job 21312.tyrone-cluster found on tyrone-node4
04/03/2013 08:35:59;0001;PBS_Server;Svr;PBS_Server;LOG_ERROR::sync_node_jobs, stray job 21190.tyrone-cluster found on tyrone-node6
04/03/2013 08:36:02;0001;PBS_Server;Svr;PBS_Server;LOG_ERROR::sync_node_jobs, stray job 21306.tyrone-cluster found on tyrone-node5
04/03/2013 08:36:28;0001;PBS_Server;Svr;PBS_Server;LOG_ERROR::sync_node_jobs, stray job 21312.tyrone-cluster found on tyrone-node4
04/03/2013 08:36:44;0001;PBS_Server;Svr;PBS_Server;LOG_ERROR::sync_node_jobs, stray job 21190.tyrone-cluster found on tyrone-node6
04/03/2013 08:36:47;0001;PBS_Server;Svr;PBS_Server;LOG_ERROR::sync_node_jobs, stray job 21306.tyrone-cluster found on tyrone-node5
04/03/2013 08:37:13;0001;PBS_Server;Svr;PBS_Server;LOG_ERROR::sync_node_jobs, stray job 21312.tyrone-cluster found on tyrone-node4
04/03/2013 08:37:29;0001;PBS_Server;Svr;PBS_Server;LOG_ERROR::sync_node_jobs, stray job 21190.tyrone-cluster found on tyrone-node6
04/03/2013 08:37:32;0001;PBS_Server;Svr;PBS_Server;LOG_ERROR::sync_node_jobs, stray job 21306.tyrone-cluster found on tyrone-node5
04/03/2013 08:37:57;0001;PBS_Server;Svr;PBS_Server;LOG_ERROR::sync_node_jobs, stray job 21312.tyrone-cluster found on tyrone-node4
04/03/2013 08:38:14;0001;PBS_Server;Svr;PBS_Server;LOG_ERROR::sync_node_jobs, stray job 21190.tyrone-cluster found on tyrone-node6
04/03/2013 08:38:17;0001;PBS_Server;Svr;PBS_Server;LOG_ERROR::sync_node_jobs, stray job 21306.tyrone-cluster found on tyrone-node5
04/03/2013 08:38:30;0002;PBS_Server;Svr;PBS_Server;Torque Server Version = 3.0.5, loglevel = 0
04/03/2013 08:38:42;0001;PBS_Server;Svr;PBS_Server;LOG_ERROR::sync_node_jobs, stray job 21312.tyrone-cluster found on tyrone-node4
04/03/2013 08:38:58;0001;PBS_Server;Svr;PBS_Server;LOG_ERROR::sync_node_jobs, stray job 21190.tyrone-cluster found on tyrone-node6
04/03/2013 08:39:02;0001;PBS_Server;Svr;PBS_Server;LOG_ERROR::sync_node_jobs, stray job 21306.tyrone-cluster found on tyrone-node5
04/03/2013 08:39:27;0001;PBS_Server;Svr;PBS_Server;LOG_ERROR::sync_node_jobs, stray job 21312.tyrone-cluster found on tyrone-node4
04/03/2013 08:39:43;0001;PBS_Server;Svr;PBS_Server;LOG_ERROR::sync_node_jobs, stray job 21190.tyrone-cluster found on tyrone-node6
04/03/2013 08:39:47;0001;PBS_Server;Svr;PBS_Server;LOG_ERROR::sync_node_jobs, stray job 21306.tyrone-cluster found on tyrone-node5
04/03/2013 08:40:12;0001;PBS_Server;Svr;PBS_Server;LOG_ERROR::sync_node_jobs, stray job 21312.tyrone-cluster found on tyrone-node4
04/03/2013 08:40:28;0001;PBS_Server;Svr;PBS_Server;LOG_ERROR::sync_node_jobs, stray job 21190.tyrone-cluster found on tyrone-node6
04/03/2013 08:40:32;0001;PBS_Server;Svr;PBS_Server;LOG_ERROR::sync_node_jobs, stray job 21306.tyrone-cluster found on tyrone-node5
04/03/2013 08:40:57;0001;PBS_Server;Svr;PBS_Server;LOG_ERROR::sync_node_jobs, stray job 21312.tyrone-cluster found on tyrone-node4
04/03/2013 08:41:13;0001;PBS_Server;Svr;PBS_Server;LOG_ERROR::sync_node_jobs, stray job 21190.tyrone-cluster found on tyrone-node6
04/03/2013 08:41:17;0001;PBS_Server;Svr;PBS_Server;LOG_ERROR::sync_node_jobs, stray job 21306.tyrone-cluster found on tyrone-node5
04/03/2013 08:41:42;0001;PBS_Server;Svr;PBS_Server;LOG_ERROR::sync_node_jobs, stray job 21312.tyrone-cluster found on tyrone-node4
04/03/2013 08:41:58;0001;PBS_Server;Svr;PBS_Server;LOG_ERROR::sync_node_jobs, stray job 21190.tyrone-cluster found on tyrone-node6
04/03/2013 08:42:02;0001;PBS_Server;Svr;PBS_Server;LOG_ERROR::sync_node_jobs, stray job 21306.tyrone-cluster found on tyrone-node5
04/03/2013 08:42:27;0001;PBS_Server;Svr;PBS_Server;LOG_ERROR::sync_node_jobs, stray job 21312.tyrone-cluster found on tyrone-node4
04/03/2013 08:42:43;0001;PBS_Server;Svr;PBS_Server;LOG_ERROR::sync_node_jobs, stray job 21190.tyrone-cluster found on tyrone-node6
04/03/2013 08:42:44;0040;PBS_Server;Svr;tyrone-cluster;Scheduler was sent the command time
04/03/2013 08:42:47;0001;PBS_Server;Svr;PBS_Server;LOG_ERROR::sync_node_jobs, stray job 21306.tyrone-cluster found on tyrone-node5
04/03/2013 08:43:12;0001;PBS_Server;Svr;PBS_Server;LOG_ERROR::sync_node_jobs, stray job 21312.tyrone-cluster found on tyrone-node4
04/03/2013 08:43:29;0001;PBS_Server;Svr;PBS_Server;LOG_ERROR::sync_node_jobs, stray job 21190.tyrone-cluster found on tyrone-node6
04/03/2013 08:43:30;0002;PBS_Server;Svr;PBS_Server;Torque Server Version = 3.0.5, loglevel = 0
04/03/2013 08:43:32;0001;PBS_Server;Svr;PBS_Server;LOG_ERROR::sync_node_jobs, stray job 21306.tyrone-cluster found on tyrone-node5
04/03/2013 08:43:58;0001;PBS_Server;Svr;PBS_Server;LOG_ERROR::sync_node_jobs, stray job 21312.tyrone-cluster found on tyrone-node4
04/03/2013 08:44:14;0001;PBS_Server;Svr;PBS_Server;LOG_ERROR::sync_node_jobs, stray job 21190.tyrone-cluster found on tyrone-node6
04/03/2013 08:44:18;0001;PBS_Server;Svr;PBS_Server;LOG_ERROR::sync_node_jobs, stray job 21306.tyrone-cluster found on tyrone-node5
04/03/2013 08:44:43;0001;PBS_Server;Svr;PBS_Server;LOG_ERROR::sync_node_jobs, stray job 21312.tyrone-cluster found on tyrone-node4
04/03/2013 08:44:59;0001;PBS_Server;Svr;PBS_Server;LOG_ERROR::sync_node_jobs, stray job 21190.tyrone-cluster found on tyrone-node6
04/03/2013 08:45:03;0001;PBS_Server;Svr;PBS_Server;LOG_ERROR::sync_node_jobs, stray job 21306.tyrone-cluster found on tyrone-node5
04/03/2013 08:45:28;0001;PBS_Server;Svr;PBS_Server;LOG_ERROR::sync_node_jobs, stray job 21312.tyrone-cluster found on tyrone-node4
04/03/2013 08:45:44;0001;PBS_Server;Svr;PBS_Server;LOG_ERROR::sync_node_jobs, stray job 21190.tyrone-cluster found on tyrone-node6
04/03/2013 08:45:48;0001;PBS_Server;Svr;PBS_Server;LOG_ERROR::sync_node_jobs, stray job 21306.tyrone-cluster found on tyrone-node5
04/03/2013 08:46:13;0001;PBS_Server;Svr;PBS_Server;LOG_ERROR::sync_node_jobs, stray job 21312.tyrone-cluster found on tyrone-node4
04/03/2013 08:46:29;0001;PBS_Server;Svr;PBS_Server;LOG_ERROR::sync_node_jobs, stray job 21190.tyrone-cluster found on tyrone-node6
04/03/2013 08:46:33;0001;PBS_Server;Svr;PBS_Server;LOG_ERROR::sync_node_jobs, stray job 21306.tyrone-cluster found on tyrone-node5
04/03/2013 08:46:58;0001;PBS_Server;Svr;PBS_Server;LOG_ERROR::sync_node_jobs, stray job 21312.tyrone-cluster found on tyrone-node4
04/03/2013 08:47:14;0001;PBS_Server;Svr;PBS_Server;LOG_ERROR::sync_node_jobs, stray job 21190.tyrone-cluster found on tyrone-node6
04/03/2013 08:47:17;0001;PBS_Server;Svr;PBS_Server;LOG_ERROR::sync_node_jobs, stray job 21306.tyrone-cluster found on tyrone-node5
04/03/2013 08:47:42;0001;PBS_Server;Svr;PBS_Server;LOG_ERROR::sync_node_jobs, stray job 21312.tyrone-cluster found on tyrone-node4
04/03/2013 08:47:59;0001;PBS_Server;Svr;PBS_Server;LOG_ERROR::sync_node_jobs, stray job 21190.tyrone-cluster found on tyrone-node6
04/03/2013 08:48:02;0001;PBS_Server;Svr;PBS_Server;LOG_ERROR::sync_node_jobs, stray job 21306.tyrone-cluster found on tyrone-node5
04/03/2013 08:48:27;0001;PBS_Server;Svr;PBS_Server;LOG_ERROR::sync_node_jobs, stray job 21312.tyrone-cluster found on tyrone-node4
04/03/2013 08:48:30;0002;PBS_Server;Svr;PBS_Server;Torque Server Version = 3.0.5, loglevel = 0
04/03/2013 08:48:44;0001;PBS_Server;Svr;PBS_Server;LOG_ERROR::sync_node_jobs, stray job 21190.tyrone-cluster found on tyrone-node6
04/03/2013 08:48:47;0001;PBS_Server;Svr;PBS_Server;LOG_ERROR::sync_node_jobs, stray job 21306.tyrone-cluster found on tyrone-node5
04/03/2013 08:49:12;0001;PBS_Server;Svr;PBS_Server;LOG_ERROR::sync_node_jobs, stray job 21312.tyrone-cluster found on tyrone-node4
04/03/2013 08:49:29;0001;PBS_Server;Svr;PBS_Server;LOG_ERROR::sync_node_jobs, stray job 21190.tyrone-cluster found on tyrone-node6
04/03/2013 08:49:32;0001;PBS_Server;Svr;PBS_Server;LOG_ERROR::sync_node_jobs, stray job 21306.tyrone-cluster found on tyrone-node5
04/03/2013 08:49:57;0001;PBS_Server;Svr;PBS_Server;LOG_ERROR::sync_node_jobs, stray job 21312.tyrone-cluster found on tyrone-node4
04/03/2013 08:50:13;0001;PBS_Server;Svr;PBS_Server;LOG_ERROR::sync_node_jobs, stray job 21190.tyrone-cluster found on tyrone-node6
04/03/2013 08:50:17;0001;PBS_Server;Svr;PBS_Server;LOG_ERROR::sync_node_jobs, stray job 21306.tyrone-cluster found on tyrone-node5
04/03/2013 08:50:42;0001;PBS_Server;Svr;PBS_Server;LOG_ERROR::sync_node_jobs, stray job 21312.tyrone-cluster found on tyrone-node4
04/03/2013 08:50:58;0001;PBS_Server;Svr;PBS_Server;LOG_ERROR::sync_node_jobs, stray job 21190.tyrone-cluster found on tyrone-node6
04/03/2013 08:51:02;0001;PBS_Server;Svr;PBS_Server;LOG_ERROR::sync_node_jobs, stray job 21306.tyrone-cluster found on tyrone-node5
04/03/2013 08:51:27;0001;PBS_Server;Svr;PBS_Server;LOG_ERROR::sync_node_jobs, stray job 21312.tyrone-cluster found on tyrone-node4
04/03/2013 08:51:43;0001;PBS_Server;Svr;PBS_Server;LOG_ERROR::sync_node_jobs, stray job 21190.tyrone-cluster found on tyrone-node6
04/03/2013 08:51:47;0001;PBS_Server;Svr;PBS_Server;LOG_ERROR::sync_node_jobs, stray job 21306.tyrone-cluster found on tyrone-node5
04/03/2013 08:52:12;0001;PBS_Server;Svr;PBS_Server;LOG_ERROR::sync_node_jobs, stray job 21312.tyrone-cluster found on tyrone-node4
04/03/2013 08:52:28;0001;PBS_Server;Svr;PBS_Server;LOG_ERROR::sync_node_jobs, stray job 21190.tyrone-cluster found on tyrone-node6
04/03/2013 08:52:32;0001;PBS_Server;Svr;PBS_Server;LOG_ERROR::sync_node_jobs, stray job 21306.tyrone-cluster found on tyrone-node5
04/03/2013 08:52:44;0040;PBS_Server;Svr;tyrone-cluster;Scheduler was sent the command time
04/03/2013 08:52:57;0001;PBS_Server;Svr;PBS_Server;LOG_ERROR::sync_node_jobs, stray job 21312.tyrone-cluster found on tyrone-node4
04/03/2013 08:53:13;0001;PBS_Server;Svr;PBS_Server;LOG_ERROR::sync_node_jobs, stray job 21190.tyrone-cluster found on tyrone-node6
04/03/2013 08:53:17;0001;PBS_Server;Svr;PBS_Server;LOG_ERROR::sync_node_jobs, stray job 21306.tyrone-cluster found on tyrone-node5
04/03/2013 08:53:30;0002;PBS_Server;Svr;PBS_Server;Torque Server Version = 3.0.5, loglevel = 0
04/03/2013 08:53:42;0001;PBS_Server;Svr;PBS_Server;LOG_ERROR::sync_node_jobs, stray job 21312.tyrone-cluster found on tyrone-node4
04/03/2013 08:53:58;0001;PBS_Server;Svr;PBS_Server;LOG_ERROR::sync_node_jobs, stray job 21190.tyrone-cluster found on tyrone-node6
04/03/2013 08:54:02;0001;PBS_Server;Svr;PBS_Server;LOG_ERROR::sync_node_jobs, stray job 21306.tyrone-cluster found on tyrone-node5
04/03/2013 08:54:27;0001;PBS_Server;Svr;PBS_Server;LOG_ERROR::sync_node_jobs, stray job 21312.tyrone-cluster found on tyrone-node4
04/03/2013 08:54:43;0001;PBS_Server;Svr;PBS_Server;LOG_ERROR::sync_node_jobs, stray job 21190.tyrone-cluster found on tyrone-node6
04/03/2013 08:54:47;0001;PBS_Server;Svr;PBS_Server;LOG_ERROR::sync_node_jobs, stray job 21306.tyrone-cluster found on tyrone-node5
04/03/2013 08:55:12;0001;PBS_Server;Svr;PBS_Server;LOG_ERROR::sync_node_jobs, stray job 21312.tyrone-cluster found on tyrone-node4
04/03/2013 08:55:28;0001;PBS_Server;Svr;PBS_Server;LOG_ERROR::sync_node_jobs, stray job 21190.tyrone-cluster found on tyrone-node6
04/03/2013 08:55:32;0001;PBS_Server;Svr;PBS_Server;LOG_ERROR::sync_node_jobs, stray job 21306.tyrone-cluster found on tyrone-node5
04/03/2013 08:55:57;0001;PBS_Server;Svr;PBS_Server;LOG_ERROR::sync_node_jobs, stray job 21312.tyrone-cluster found on tyrone-node4
04/03/2013 08:56:14;0001;PBS_Server;Svr;PBS_Server;LOG_ERROR::sync_node_jobs, stray job 21190.tyrone-cluster found on tyrone-node6
04/03/2013 08:56:18;0001;PBS_Server;Svr;PBS_Server;LOG_ERROR::sync_node_jobs, stray job 21306.tyrone-cluster found on tyrone-node5
04/03/2013 08:56:43;0001;PBS_Server;Svr;PBS_Server;LOG_ERROR::sync_node_jobs, stray job 21312.tyrone-cluster found on tyrone-node4
04/03/2013 08:56:59;0001;PBS_Server;Svr;PBS_Server;LOG_ERROR::sync_node_jobs, stray job 21190.tyrone-cluster found on tyrone-node6
04/03/2013 08:57:03;0001;PBS_Server;Svr;PBS_Server;LOG_ERROR::sync_node_jobs, stray job 21306.tyrone-cluster found on tyrone-node5
04/03/2013 08:57:27;0001;PBS_Server;Svr;PBS_Server;LOG_ERROR::sync_node_jobs, stray job 21312.tyrone-cluster found on tyrone-node4
04/03/2013 08:57:44;0001;PBS_Server;Svr;PBS_Server;LOG_ERROR::sync_node_jobs, stray job 21190.tyrone-cluster found on tyrone-node6
04/03/2013 08:57:48;0001;PBS_Server;Svr;PBS_Server;LOG_ERROR::sync_node_jobs, stray job 21306.tyrone-cluster found on tyrone-node5
04/03/2013 08:58:12;0001;PBS_Server;Svr;PBS_Server;LOG_ERROR::sync_node_jobs, stray job 21312.tyrone-cluster found on tyrone-node4
04/03/2013 08:58:29;0001;PBS_Server;Svr;PBS_Server;LOG_ERROR::sync_node_jobs, stray job 21190.tyrone-cluster found on tyrone-node6
04/03/2013 08:58:30;0002;PBS_Server;Svr;PBS_Server;Torque Server Version = 3.0.5, loglevel = 0
04/03/2013 08:58:33;0001;PBS_Server;Svr;PBS_Server;LOG_ERROR::sync_node_jobs, stray job 21306.tyrone-cluster found on tyrone-node5
04/03/2013 08:58:57;0001;PBS_Server;Svr;PBS_Server;LOG_ERROR::sync_node_jobs, stray job 21312.tyrone-cluster found on tyrone-node4
04/03/2013 08:59:14;0001;PBS_Server;Svr;PBS_Server;LOG_ERROR::sync_node_jobs, stray job 21190.tyrone-cluster found on tyrone-node6
04/03/2013 08:59:17;0001;PBS_Server;Svr;PBS_Server;LOG_ERROR::sync_node_jobs, stray job 21306.tyrone-cluster found on tyrone-node5
04/03/2013 08:59:42;0001;PBS_Server;Svr;PBS_Server;LOG_ERROR::sync_node_jobs, stray job 21312.tyrone-cluster found on tyrone-node4
04/03/2013 08:59:59;0001;PBS_Server;Svr;PBS_Server;LOG_ERROR::sync_node_jobs, stray job 21190.tyrone-cluster found on tyrone-node6
04/03/2013 09:00:02;0001;PBS_Server;Svr;PBS_Server;LOG_ERROR::sync_node_jobs, stray job 21306.tyrone-cluster found on tyrone-node5
04/03/2013 09:00:27;0001;PBS_Server;Svr;PBS_Server;LOG_ERROR::sync_node_jobs, stray job 21312.tyrone-cluster found on tyrone-node4
04/03/2013 09:00:44;0001;PBS_Server;Svr;PBS_Server;LOG_ERROR::sync_node_jobs, stray job 21190.tyrone-cluster found on tyrone-node6
04/03/2013 09:00:47;0001;PBS_Server;Svr;PBS_Server;LOG_ERROR::sync_node_jobs, stray job 21306.tyrone-cluster found on tyrone-node5
04/03/2013 09:01:12;0001;PBS_Server;Svr;PBS_Server;LOG_ERROR::sync_node_jobs, stray job 21312.tyrone-cluster found on tyrone-node4
04/03/2013 09:01:18;0100;PBS_Server;Job;21331.tyrone-cluster;enqueuing into batch, state 1 hop 1
04/03/2013 09:01:18;0100;PBS_Server;Job;21331.tyrone-cluster;dequeuing from batch, state QUEUED
04/03/2013 09:01:18;0100;PBS_Server;Job;21331.tyrone-cluster;enqueuing into qp32, state 1 hop 1
04/03/2013 09:01:18;0008;PBS_Server;Job;21331.tyrone-cluster;Job Queued at request of ipcmthen@tyrone-cluster, owner = ipcmthen@tyrone-cluster, job name = tyrn1, queue = qp32
04/03/2013 09:01:18;0040;PBS_Server;Svr;tyrone-cluster;Scheduler was sent the command new
04/03/2013 09:01:18;0008;PBS_Server;Job;21331.tyrone-cluster;Job Modified at request of Scheduler@tyrone-cluster
04/03/2013 09:01:18;0008;PBS_Server;Job;21331.tyrone-cluster;Job Run at request of Scheduler@tyrone-cluster
04/03/2013 09:01:18;0040;PBS_Server;Svr;tyrone-cluster;Scheduler was sent the command recyc
04/03/2013 09:01:18;000d;PBS_Server;Job;21331.tyrone-cluster;Not sending email: User does not want mail of this type.
04/03/2013 09:01:28;0001;PBS_Server;Svr;PBS_Server;LOG_ERROR::sync_node_jobs, stray job 21190.tyrone-cluster found on tyrone-node6
04/03/2013 09:01:32;0001;PBS_Server;Svr;PBS_Server;LOG_ERROR::sync_node_jobs, stray job 21306.tyrone-cluster found on tyrone-node5
04/03/2013 09:01:34;0100;PBS_Server;Job;21332.tyrone-cluster;enqueuing into batch, state 1 hop 1
04/03/2013 09:01:34;0100;PBS_Server;Job;21332.tyrone-cluster;dequeuing from batch, state QUEUED
04/03/2013 09:01:34;0100;PBS_Server;Job;21332.tyrone-cluster;enqueuing into qp32, state 1 hop 1
04/03/2013 09:01:34;0008;PBS_Server;Job;21332.tyrone-cluster;Job Queued at request of ipcmthen@tyrone-cluster, owner = ipcmthen@tyrone-cluster, job name = tyrn3, queue = qp32
04/03/2013 09:01:34;0040;PBS_Server;Svr;tyrone-cluster;Scheduler was sent the command new
04/03/2013 09:01:34;0008;PBS_Server;Job;21332.tyrone-cluster;Job Modified at request of Scheduler@tyrone-cluster
04/03/2013 09:01:34;0008;PBS_Server;Job;21332.tyrone-cluster;Job Run at request of Scheduler@tyrone-cluster
04/03/2013 09:01:34;0040;PBS_Server;Svr;tyrone-cluster;Scheduler was sent the command recyc
04/03/2013 09:01:34;000d;PBS_Server;Job;21332.tyrone-cluster;Not sending email: User does not want mail of this type.
04/03/2013 09:01:53;0001;PBS_Server;Svr;PBS_Server;LOG_ERROR::sync_node_jobs, stray job 21332.tyrone-cluster found on tyrone-node8
04/03/2013 09:01:57;0001;PBS_Server;Svr;PBS_Server;LOG_ERROR::sync_node_jobs, stray job 21312.tyrone-cluster found on tyrone-node4
04/03/2013 09:02:14;0001;PBS_Server;Svr;PBS_Server;LOG_ERROR::sync_node_jobs, stray job 21190.tyrone-cluster found on tyrone-node6
04/03/2013 09:02:17;0001;PBS_Server;Svr;PBS_Server;LOG_ERROR::sync_node_jobs, stray job 21306.tyrone-cluster found on tyrone-node5
04/03/2013 09:02:38;0001;PBS_Server;Svr;PBS_Server;LOG_ERROR::sync_node_jobs, stray job 21332.tyrone-cluster found on tyrone-node8
04/03/2013 09:02:42;0001;PBS_Server;Svr;PBS_Server;LOG_ERROR::sync_node_jobs, stray job 21312.tyrone-cluster found on tyrone-node4
04/03/2013 09:02:54;0100;PBS_Server;Job;21333.tyrone-cluster;enqueuing into batch, state 1 hop 1
04/03/2013 09:02:54;0100;PBS_Server;Job;21333.tyrone-cluster;dequeuing from batch, state QUEUED
04/03/2013 09:02:54;0100;PBS_Server;Job;21333.tyrone-cluster;enqueuing into qp32, state 1 hop 1
04/03/2013 09:02:54;0008;PBS_Server;Job;21333.tyrone-cluster;Job Queued at request of ipcmraja@tyrone-cluster, owner = ipcmraja@tyrone-cluster, job name = mitra1, queue = qp32
04/03/2013 09:02:54;0040;PBS_Server;Svr;tyrone-cluster;Scheduler was sent the command new
04/03/2013 09:02:54;0008;PBS_Server;Job;21333.tyrone-cluster;Job Modified at request of Scheduler@tyrone-cluster
04/03/2013 09:02:54;0008;PBS_Server;Job;21333.tyrone-cluster;Job Run at request of Scheduler@tyrone-cluster
04/03/2013 09:02:54;0040;PBS_Server;Svr;tyrone-cluster;Scheduler was sent the command recyc
04/03/2013 09:02:54;000d;PBS_Server;Job;21333.tyrone-cluster;Not sending email: User does not want mail of this type.
04/03/2013 09:02:59;0001;PBS_Server;Svr;PBS_Server;LOG_ERROR::sync_node_jobs, stray job 21190.tyrone-cluster found on tyrone-node6
04/03/2013 09:03:03;0001;PBS_Server;Svr;PBS_Server;LOG_ERROR::sync_node_jobs, stray job 21306.tyrone-cluster found on tyrone-node5
04/03/2013 09:03:23;0001;PBS_Server;Svr;PBS_Server;LOG_ERROR::sync_node_jobs, stray job 21332.tyrone-cluster found on tyrone-node8
04/03/2013 09:03:25;0001;PBS_Server;Svr;PBS_Server;LOG_ERROR::sync_node_jobs, stray job 21333.tyrone-cluster found on tyrone-node10
04/03/2013 09:03:27;0001;PBS_Server;Svr;PBS_Server;LOG_ERROR::sync_node_jobs, stray job 21312.tyrone-cluster found on tyrone-node4
04/03/2013 09:03:30;0002;PBS_Server;Svr;PBS_Server;Torque Server Version = 3.0.5, loglevel = 0
04/03/2013 09:03:44;0001;PBS_Server;Svr;PBS_Server;LOG_ERROR::sync_node_jobs, stray job 21190.tyrone-cluster found on tyrone-node6
04/03/2013 09:03:47;0001;PBS_Server;Svr;PBS_Server;LOG_ERROR::sync_node_jobs, stray job 21306.tyrone-cluster found on tyrone-node5
04/03/2013 09:04:08;0001;PBS_Server;Svr;PBS_Server;LOG_ERROR::sync_node_jobs, stray job 21332.tyrone-cluster found on tyrone-node8
04/03/2013 09:04:10;0001;PBS_Server;Svr;PBS_Server;LOG_ERROR::sync_node_jobs, stray job 21333.tyrone-cluster found on tyrone-node10
04/03/2013 09:04:12;0001;PBS_Server;Svr;PBS_Server;LOG_ERROR::sync_node_jobs, stray job 21312.tyrone-cluster found on tyrone-node4
04/03/2013 09:04:29;0001;PBS_Server;Svr;PBS_Server;LOG_ERROR::sync_node_jobs, stray job 21190.tyrone-cluster found on tyrone-node6
04/03/2013 09:04:32;0001;PBS_Server;Svr;PBS_Server;LOG_ERROR::sync_node_jobs, stray job 21306.tyrone-cluster found on tyrone-node5
04/03/2013 09:04:53;0001;PBS_Server;Svr;PBS_Server;LOG_ERROR::sync_node_jobs, stray job 21332.tyrone-cluster found on tyrone-node8
04/03/2013 09:04:55;0001;PBS_Server;Svr;PBS_Server;LOG_ERROR::sync_node_jobs, stray job 21333.tyrone-cluster found on tyrone-node10
04/03/2013 09:04:57;0001;PBS_Server;Svr;PBS_Server;LOG_ERROR::sync_node_jobs, stray job 21312.tyrone-cluster found on tyrone-node4
04/03/2013 09:05:14;0001;PBS_Server;Svr;PBS_Server;LOG_ERROR::sync_node_jobs, stray job 21190.tyrone-cluster found on tyrone-node6
04/03/2013 09:05:17;0001;PBS_Server;Svr;PBS_Server;LOG_ERROR::sync_node_jobs, stray job 21306.tyrone-cluster found on tyrone-node5
04/03/2013 09:05:31;0100;PBS_Server;Job;21334.tyrone-cluster;enqueuing into batch, state 1 hop 1
04/03/2013 09:05:31;0100;PBS_Server;Job;21334.tyrone-cluster;dequeuing from batch, state QUEUED
04/03/2013 09:05:31;0100;PBS_Server;Job;21334.tyrone-cluster;enqueuing into qp32, state 1 hop 1
04/03/2013 09:05:31;0008;PBS_Server;Job;21334.tyrone-cluster;Job Queued at request of ipcanup@tyrone-cluster, owner = ipcanup@tyrone-cluster, job name = anup1, queue = qp32
04/03/2013 09:05:31;0040;PBS_Server;Svr;tyrone-cluster;Scheduler was sent the command new
04/03/2013 09:05:31;0008;PBS_Server;Job;21334.tyrone-cluster;Job Modified at request of Scheduler@tyrone-cluster
04/03/2013 09:05:31;0008;PBS_Server;Job;21334.tyrone-cluster;Job Run at request of Scheduler@tyrone-cluster
04/03/2013 09:05:31;0040;PBS_Server;Svr;tyrone-cluster;Scheduler was sent the command recyc
04/03/2013 09:05:31;000d;PBS_Server;Job;21334.tyrone-cluster;Not sending email: User does not want mail of this type.
04/03/2013 09:05:38;0001;PBS_Server;Svr;PBS_Server;LOG_ERROR::sync_node_jobs, stray job 21332.tyrone-cluster found on tyrone-node8
04/03/2013 09:05:40;0001;PBS_Server;Svr;PBS_Server;LOG_ERROR::sync_node_jobs, stray job 21333.tyrone-cluster found on tyrone-node10
04/03/2013 09:05:42;0001;PBS_Server;Svr;PBS_Server;LOG_ERROR::sync_node_jobs, stray job 21312.tyrone-cluster found on tyrone-node4
04/03/2013 09:05:43;0001;PBS_Server;Svr;PBS_Server;LOG_ERROR::sync_node_jobs, stray job 21334.tyrone-cluster found on tyrone-node14
04/03/2013 09:05:59;0001;PBS_Server;Svr;PBS_Server;LOG_ERROR::sync_node_jobs, stray job 21190.tyrone-cluster found on tyrone-node6
04/03/2013 09:06:02;0001;PBS_Server;Svr;PBS_Server;LOG_ERROR::sync_node_jobs, stray job 21306.tyrone-cluster found on tyrone-node5
04/03/2013 09:06:23;0001;PBS_Server;Svr;PBS_Server;LOG_ERROR::sync_node_jobs, stray job 21332.tyrone-cluster found on tyrone-node8
04/03/2013 09:06:25;0001;PBS_Server;Svr;PBS_Server;LOG_ERROR::sync_node_jobs, stray job 21333.tyrone-cluster found on tyrone-node10
04/03/2013 09:06:27;0001;PBS_Server;Svr;PBS_Server;LOG_ERROR::sync_node_jobs, stray job 21312.tyrone-cluster found on tyrone-node4
04/03/2013 09:06:29;0001;PBS_Server;Svr;PBS_Server;LOG_ERROR::sync_node_jobs, stray job 21334.tyrone-cluster found on tyrone-node14
04/03/2013 09:06:43;0001;PBS_Server;Svr;PBS_Server;LOG_ERROR::sync_node_jobs, stray job 21190.tyrone-cluster found on tyrone-node6
04/03/2013 09:06:47;0001;PBS_Server;Svr;PBS_Server;LOG_ERROR::sync_node_jobs, stray job 21306.tyrone-cluster found on tyrone-node5
04/03/2013 09:07:08;0001;PBS_Server;Svr;PBS_Server;LOG_ERROR::sync_node_jobs, stray job 21332.tyrone-cluster found on tyrone-node8
04/03/2013 09:07:10;0001;PBS_Server;Svr;PBS_Server;LOG_ERROR::sync_node_jobs, stray job 21333.tyrone-cluster found on tyrone-node10
04/03/2013 09:07:12;0001;PBS_Server;Svr;PBS_Server;LOG_ERROR::sync_node_jobs, stray job 21312.tyrone-cluster found on tyrone-node4
04/03/2013 09:07:14;0001;PBS_Server;Svr;PBS_Server;LOG_ERROR::sync_node_jobs, stray job 21334.tyrone-cluster found on tyrone-node14
04/03/2013 09:07:19;000d;PBS_Server;Job;21331.tyrone-cluster;Not sending email: User does not want mail of this type.
04/03/2013 09:07:19;0010;PBS_Server;Job;21331.tyrone-cluster;Exit_status=1 resources_used.cput=00:00:04 resources_used.mem=4740kb resources_used.vmem=333804kb resources_used.walltime=00:06:00
04/03/2013 09:07:19;0008;PBS_Server;Job;NULL;on_job_exit valid pjob: 0x2063e10 (substate=50)
04/03/2013 09:07:19;0008;PBS_Server;Job;NULL;on_job_exit valid pjob: 0x2063e10 (substate=51)
04/03/2013 09:07:28;0001;PBS_Server;Svr;PBS_Server;LOG_ERROR::sync_node_jobs, stray job 21190.tyrone-cluster found on tyrone-node6
04/03/2013 09:07:29;0008;PBS_Server;Job;NULL;on_job_exit valid pjob: 0x2063e10 (substate=51)
04/03/2013 09:07:29;0008;PBS_Server;Job;NULL;on_job_exit valid pjob: 0x2063e10 (substate=53)
04/03/2013 09:07:29;0100;PBS_Server;Job;21331.tyrone-cluster;dequeuing from qp32, state COMPLETE
04/03/2013 09:07:29;0040;PBS_Server;Svr;tyrone-cluster;Scheduler was sent the command term
04/03/2013 09:07:33;0001;PBS_Server;Svr;PBS_Server;LOG_ERROR::sync_node_jobs, stray job 21306.tyrone-cluster found on tyrone-node5
04/03/2013 09:07:53;0001;PBS_Server;Svr;PBS_Server;LOG_ERROR::sync_node_jobs, stray job 21332.tyrone-cluster found on tyrone-node8
04/03/2013 09:07:55;0001;PBS_Server;Svr;PBS_Server;LOG_ERROR::sync_node_jobs, stray job 21333.tyrone-cluster found on tyrone-node10
04/03/2013 09:07:57;0001;PBS_Server;Svr;PBS_Server;LOG_ERROR::sync_node_jobs, stray job 21312.tyrone-cluster found on tyrone-node4
04/03/2013 09:07:59;0001;PBS_Server;Svr;PBS_Server;LOG_ERROR::sync_node_jobs, stray job 21334.tyrone-cluster found on tyrone-node14
04/03/2013 09:08:14;0001;PBS_Server;Svr;PBS_Server;LOG_ERROR::sync_node_jobs, stray job 21190.tyrone-cluster found on tyrone-node6
04/03/2013 09:08:17;0001;PBS_Server;Svr;PBS_Server;LOG_ERROR::sync_node_jobs, stray job 21306.tyrone-cluster found on tyrone-node5
04/03/2013 09:08:30;0002;PBS_Server;Svr;PBS_Server;Torque Server Version = 3.0.5, loglevel = 0
04/03/2013 09:08:38;0001;PBS_Server;Svr;PBS_Server;LOG_ERROR::sync_node_jobs, stray job 21332.tyrone-cluster found on tyrone-node8
04/03/2013 09:08:40;0001;PBS_Server;Svr;PBS_Server;LOG_ERROR::sync_node_jobs, stray job 21333.tyrone-cluster found on tyrone-node10
04/03/2013 09:08:42;0001;PBS_Server;Svr;PBS_Server;LOG_ERROR::sync_node_jobs, stray job 21312.tyrone-cluster found on tyrone-node4
04/03/2013 09:08:44;0001;PBS_Server;Svr;PBS_Server;LOG_ERROR::sync_node_jobs, stray job 21334.tyrone-cluster found on tyrone-node14
04/03/2013 09:08:59;0001;PBS_Server;Svr;PBS_Server;LOG_ERROR::sync_node_jobs, stray job 21190.tyrone-cluster found on tyrone-node6
04/03/2013 09:09:02;0001;PBS_Server;Svr;PBS_Server;LOG_ERROR::sync_node_jobs, stray job 21306.tyrone-cluster found on tyrone-node5
04/03/2013 09:09:16;000d;PBS_Server;Job;21334.tyrone-cluster;Not sending email: User does not want mail of this type.
04/03/2013 09:09:16;0010;PBS_Server;Job;21334.tyrone-cluster;Exit_status=1 resources_used.cput=00:00:03 resources_used.mem=4660kb resources_used.vmem=333740kb resources_used.walltime=00:03:45
04/03/2013 09:09:16;0008;PBS_Server;Job;NULL;on_job_exit valid pjob: 0x2140720 (substate=50)
04/03/2013 09:09:16;0008;PBS_Server;Job;NULL;on_job_exit valid pjob: 0x2140720 (substate=51)
04/03/2013 09:09:23;0001;PBS_Server;Svr;PBS_Server;LOG_ERROR::sync_node_jobs, stray job 21332.tyrone-cluster found on tyrone-node8
04/03/2013 09:09:25;0001;PBS_Server;Svr;PBS_Server;LOG_ERROR::sync_node_jobs, stray job 21333.tyrone-cluster found on tyrone-node10
04/03/2013 09:09:27;0001;PBS_Server;Svr;PBS_Server;LOG_ERROR::sync_node_jobs, stray job 21312.tyrone-cluster found on tyrone-node4
04/03/2013 09:09:29;0001;PBS_Server;Svr;PBS_Server;LOG_ERROR::sync_node_jobs, stray job 21334.tyrone-cluster found on tyrone-node14
04/03/2013 09:09:31;0008;PBS_Server;Job;NULL;on_job_exit valid pjob: 0x2140720 (substate=51)
04/03/2013 09:09:31;0008;PBS_Server;Job;NULL;on_job_exit valid pjob: 0x2140720 (substate=53)
04/03/2013 09:09:31;0100;PBS_Server;Job;21334.tyrone-cluster;dequeuing from qp32, state COMPLETE
04/03/2013 09:09:31;0040;PBS_Server;Svr;tyrone-cluster;Scheduler was sent the command term
04/03/2013 09:09:44;0001;PBS_Server;Svr;PBS_Server;LOG_ERROR::sync_node_jobs, stray job 21190.tyrone-cluster found on tyrone-node6
04/03/2013 09:09:48;0001;PBS_Server;Svr;PBS_Server;LOG_ERROR::sync_node_jobs, stray job 21306.tyrone-cluster found on tyrone-node5
04/03/2013 09:10:08;0001;PBS_Server;Svr;PBS_Server;LOG_ERROR::sync_node_jobs, stray job 21332.tyrone-cluster found on tyrone-node8
04/03/2013 09:10:10;0001;PBS_Server;Svr;PBS_Server;LOG_ERROR::sync_node_jobs, stray job 21333.tyrone-cluster found on tyrone-node10
04/03/2013 09:10:12;0001;PBS_Server;Svr;PBS_Server;LOG_ERROR::sync_node_jobs, stray job 21312.tyrone-cluster found on tyrone-node4
04/03/2013 09:10:23;0100;PBS_Server;Job;21335.tyrone-cluster;enqueuing into batch, state 1 hop 1
04/03/2013 09:10:23;0100;PBS_Server;Job;21335.tyrone-cluster;dequeuing from batch, state QUEUED
04/03/2013 09:10:23;0100;PBS_Server;Job;21335.tyrone-cluster;enqueuing into qp32, state 1 hop 1
04/03/2013 09:10:23;0008;PBS_Server;Job;21335.tyrone-cluster;Job Queued at request of mrcpndey@tyrone-cluster, owner = mrcpndey@tyrone-cluster, job name = thiol, queue = qp32
04/03/2013 09:10:23;0040;PBS_Server;Svr;tyrone-cluster;Scheduler was sent the command new
04/03/2013 09:10:23;0008;PBS_Server;Job;21335.tyrone-cluster;Job Modified at request of Scheduler@tyrone-cluster
04/03/2013 09:10:23;0008;PBS_Server;Job;21335.tyrone-cluster;Job Run at request of Scheduler@tyrone-cluster
04/03/2013 09:10:24;0040;PBS_Server;Svr;tyrone-cluster;Scheduler was sent the command recyc
04/03/2013 09:10:24;000d;PBS_Server;Job;21335.tyrone-cluster;Not sending email: User does not want mail of this type.
04/03/2013 09:10:28;0001;PBS_Server;Svr;PBS_Server;LOG_ERROR::sync_node_jobs, stray job 21190.tyrone-cluster found on tyrone-node6
04/03/2013 09:10:32;0001;PBS_Server;Svr;PBS_Server;LOG_ERROR::sync_node_jobs, stray job 21306.tyrone-cluster found on tyrone-node5
04/03/2013 09:10:53;0001;PBS_Server;Svr;PBS_Server;LOG_ERROR::sync_node_jobs, stray job 21332.tyrone-cluster found on tyrone-node8
04/03/2013 09:10:55;0001;PBS_Server;Svr;PBS_Server;LOG_ERROR::sync_node_jobs, stray job 21333.tyrone-cluster found on tyrone-node10
04/03/2013 09:10:56;0001;PBS_Server;Svr;PBS_Server;LOG_ERROR::sync_node_jobs, stray job 21312.tyrone-cluster found on tyrone-node4
04/03/2013 09:11:13;0001;PBS_Server;Svr;PBS_Server;LOG_ERROR::sync_node_jobs, stray job 21190.tyrone-cluster found on tyrone-node6
04/03/2013 09:11:18;0001;PBS_Server;Svr;PBS_Server;LOG_ERROR::sync_node_jobs, stray job 21306.tyrone-cluster found on tyrone-node5
04/03/2013 09:11:28;000d;PBS_Server;Job;21333.tyrone-cluster;Not sending email: User does not want mail of this type.
04/03/2013 09:11:28;0010;PBS_Server;Job;21333.tyrone-cluster;Exit_status=1 resources_used.cput=00:00:03 resources_used.mem=4520kb resources_used.vmem=333564kb resources_used.walltime=00:08:34
04/03/2013 09:11:28;0008;PBS_Server;Job;NULL;on_job_exit valid pjob: 0x1fa2f10 (substate=50)
04/03/2013 09:11:28;0008;PBS_Server;Job;NULL;on_job_exit valid pjob: 0x1fa2f10 (substate=51)
04/03/2013 09:11:37;0008;PBS_Server;Job;NULL;on_job_exit valid pjob: 0x1fa2f10 (substate=51)
04/03/2013 09:11:37;000d;PBS_Server;Job;21333.tyrone-cluster;Post job file processing error; job 21333.tyrone-cluster on host tyrone-node5/31+tyrone-node5/30+tyrone-node5/29+tyrone-node5/28+tyrone-node5/27+tyrone-node5/26+tyrone-node5/25+tyrone-node5/24+tyrone-node5/23+tyrone-node5/22+tyrone-node5/21+tyrone-node5/20+tyrone-node5/19+tyrone-node5/18+tyrone-node5/17+tyrone-node5/16+tyrone-node5/15+tyrone-node5/14+tyrone-node5/13+tyrone-node5/12+tyrone-node5/11+tyrone-node5/10+tyrone-node5/9+tyrone-node5/8+tyrone-node5/7+tyrone-node5/6+tyrone-node5/5+tyrone-node5/4+tyrone-node5/3+tyrone-node5/2+tyrone-node5/1+tyrone-node5/0
04/03/2013 09:11:37;0008;PBS_Server;Job;NULL;on_job_exit valid pjob: 0x1fa2f10 (substate=53)
04/03/2013 09:11:37;0100;PBS_Server;Job;21333.tyrone-cluster;dequeuing from qp32, state COMPLETE
04/03/2013 09:11:37;0040;PBS_Server;Svr;tyrone-cluster;Scheduler was sent the command term
04/03/2013 09:11:38;0001;PBS_Server;Svr;PBS_Server;LOG_ERROR::sync_node_jobs, stray job 21332.tyrone-cluster found on tyrone-node8
04/03/2013 09:11:42;0001;PBS_Server;Svr;PBS_Server;LOG_ERROR::sync_node_jobs, stray job 21312.tyrone-cluster found on tyrone-node4
04/03/2013 09:11:59;0001;PBS_Server;Svr;PBS_Server;LOG_ERROR::sync_node_jobs, stray job 21190.tyrone-cluster found on tyrone-node6
04/03/2013 09:12:02;0001;PBS_Server;Svr;PBS_Server;LOG_ERROR::sync_node_jobs, stray job 21306.tyrone-cluster found on tyrone-node5
04/03/2013 09:12:23;0001;PBS_Server;Svr;PBS_Server;LOG_ERROR::sync_node_jobs, stray job 21332.tyrone-cluster found on tyrone-node8
04/03/2013 09:12:27;0001;PBS_Server;Svr;PBS_Server;LOG_ERROR::sync_node_jobs, stray job 21312.tyrone-cluster found on tyrone-node4
04/03/2013 09:12:44;0001;PBS_Server;Svr;PBS_Server;LOG_ERROR::sync_node_jobs, stray job 21190.tyrone-cluster found on tyrone-node6
04/03/2013 09:12:47;0001;PBS_Server;Svr;PBS_Server;LOG_ERROR::sync_node_jobs, stray job 21306.tyrone-cluster found on tyrone-node5
04/03/2013 09:13:08;0001;PBS_Server;Svr;PBS_Server;LOG_ERROR::sync_node_jobs, stray job 21332.tyrone-cluster found on tyrone-node8
04/03/2013 09:13:12;0001;PBS_Server;Svr;PBS_Server;LOG_ERROR::sync_node_jobs, stray job 21312.tyrone-cluster found on tyrone-node4
04/03/2013 09:13:28;0001;PBS_Server;Svr;PBS_Server;LOG_ERROR::sync_node_jobs, stray job 21190.tyrone-cluster found on tyrone-node6
04/03/2013 09:13:30;0002;PBS_Server;Svr;PBS_Server;Torque Server Version = 3.0.5, loglevel = 0
04/03/2013 09:13:32;0001;PBS_Server;Svr;PBS_Server;LOG_ERROR::sync_node_jobs, stray job 21306.tyrone-cluster found on tyrone-node5
04/03/2013 09:13:53;0001;PBS_Server;Svr;PBS_Server;LOG_ERROR::sync_node_jobs, stray job 21332.tyrone-cluster found on tyrone-node8
04/03/2013 09:13:57;0001;PBS_Server;Svr;PBS_Server;LOG_ERROR::sync_node_jobs, stray job 21312.tyrone-cluster found on tyrone-node4
04/03/2013 09:14:13;0001;PBS_Server;Svr;PBS_Server;LOG_ERROR::sync_node_jobs, stray job 21190.tyrone-cluster found on tyrone-node6
04/03/2013 09:14:17;0001;PBS_Server;Svr;PBS_Server;LOG_ERROR::sync_node_jobs, stray job 21306.tyrone-cluster found on tyrone-node5
04/03/2013 09:14:38;0001;PBS_Server;Svr;PBS_Server;LOG_ERROR::sync_node_jobs, stray job 21332.tyrone-cluster found on tyrone-node8
04/03/2013 09:14:42;0001;PBS_Server;Svr;PBS_Server;LOG_ERROR::sync_node_jobs, stray job 21312.tyrone-cluster found on tyrone-node4
04/03/2013 09:14:58;0001;PBS_Server;Svr;PBS_Server;LOG_ERROR::sync_node_jobs, stray job 21190.tyrone-cluster found on tyrone-node6
04/03/2013 09:15:02;0001;PBS_Server;Svr;PBS_Server;LOG_ERROR::sync_node_jobs, stray job 21306.tyrone-cluster found on tyrone-node5
04/03/2013 09:15:23;0001;PBS_Server;Svr;PBS_Server;LOG_ERROR::sync_node_jobs, stray job 21332.tyrone-cluster found on tyrone-node8
04/03/2013 09:15:27;0001;PBS_Server;Svr;PBS_Server;LOG_ERROR::sync_node_jobs, stray job 21312.tyrone-cluster found on tyrone-node4
04/03/2013 09:15:43;0001;PBS_Server;Svr;PBS_Server;LOG_ERROR::sync_node_jobs, stray job 21190.tyrone-cluster found on tyrone-node6
04/03/2013 09:15:47;0001;PBS_Server;Svr;PBS_Server;LOG_ERROR::sync_node_jobs, stray job 21306.tyrone-cluster found on tyrone-node5
04/03/2013 09:16:08;0001;PBS_Server;Svr;PBS_Server;LOG_ERROR::sync_node_jobs, stray job 21332.tyrone-cluster found on tyrone-node8
04/03/2013 09:16:12;0001;PBS_Server;Svr;PBS_Server;LOG_ERROR::sync_node_jobs, stray job 21312.tyrone-cluster found on tyrone-node4
04/03/2013 09:16:28;0001;PBS_Server;Svr;PBS_Server;LOG_ERROR::sync_node_jobs, stray job 21190.tyrone-cluster found on tyrone-node6
04/03/2013 09:16:32;0001;PBS_Server;Svr;PBS_Server;LOG_ERROR::sync_node_jobs, stray job 21306.tyrone-cluster found on tyrone-node5
04/03/2013 09:16:40;000d;PBS_Server;Job;21332.tyrone-cluster;Not sending email: User does not want mail of this type.
04/03/2013 09:16:40;0010;PBS_Server;Job;21332.tyrone-cluster;Exit_status=1 resources_used.cput=00:00:03 resources_used.mem=3596kb resources_used.vmem=222472kb resources_used.walltime=00:15:06
04/03/2013 09:16:40;0008;PBS_Server;Job;NULL;on_job_exit valid pjob: 0x2051580 (substate=50)
04/03/2013 09:16:40;0008;PBS_Server;Job;NULL;on_job_exit valid pjob: 0x2051580 (substate=51)
04/03/2013 09:16:47;0008;PBS_Server;Job;NULL;on_job_exit valid pjob: 0x2051580 (substate=51)
04/03/2013 09:16:47;0008;PBS_Server;Job;NULL;on_job_exit valid pjob: 0x2051580 (substate=53)
04/03/2013 09:16:47;0100;PBS_Server;Job;21332.tyrone-cluster;dequeuing from qp32, state COMPLETE
04/03/2013 09:16:47;0040;PBS_Server;Svr;tyrone-cluster;Scheduler was sent the command term
04/03/2013 09:16:56;0001;PBS_Server;Svr;PBS_Server;LOG_ERROR::sync_node_jobs, stray job 21312.tyrone-cluster found on tyrone-node4
04/03/2013 09:17:13;0001;PBS_Server;Svr;PBS_Server;LOG_ERROR::sync_node_jobs, stray job 21190.tyrone-cluster found on tyrone-node6
04/03/2013 09:17:17;0001;PBS_Server;Svr;PBS_Server;LOG_ERROR::sync_node_jobs, stray job 21306.tyrone-cluster found on tyrone-node5
04/03/2013 09:17:41;0001;PBS_Server;Svr;PBS_Server;LOG_ERROR::sync_node_jobs, stray job 21312.tyrone-cluster found on tyrone-node4
04/03/2013 09:17:58;0001;PBS_Server;Svr;PBS_Server;LOG_ERROR::sync_node_jobs, stray job 21190.tyrone-cluster found on tyrone-node6
04/03/2013 09:18:02;0001;PBS_Server;Svr;PBS_Server;LOG_ERROR::sync_node_jobs, stray job 21306.tyrone-cluster found on tyrone-node5
04/03/2013 09:18:27;0001;PBS_Server;Svr;PBS_Server;LOG_ERROR::sync_node_jobs, stray job 21312.tyrone-cluster found on tyrone-node4
04/03/2013 09:18:30;0002;PBS_Server;Svr;PBS_Server;Torque Server Version = 3.0.5, loglevel = 0
04/03/2013 09:18:44;0001;PBS_Server;Svr;PBS_Server;LOG_ERROR::sync_node_jobs, stray job 21190.tyrone-cluster found on tyrone-node6
04/03/2013 09:18:47;0001;PBS_Server;Svr;PBS_Server;LOG_ERROR::sync_node_jobs, stray job 21306.tyrone-cluster found on tyrone-node5
04/03/2013 09:19:12;0001;PBS_Server;Svr;PBS_Server;LOG_ERROR::sync_node_jobs, stray job 21312.tyrone-cluster found on tyrone-node4
04/03/2013 09:19:29;0001;PBS_Server;Svr;PBS_Server;LOG_ERROR::sync_node_jobs, stray job 21190.tyrone-cluster found on tyrone-node6
04/03/2013 09:19:33;0001;PBS_Server;Svr;PBS_Server;LOG_ERROR::sync_node_jobs, stray job 21306.tyrone-cluster found on tyrone-node5
04/03/2013 09:19:57;0001;PBS_Server;Svr;PBS_Server;LOG_ERROR::sync_node_jobs, stray job 21312.tyrone-cluster found on tyrone-node4
04/03/2013 09:20:14;0001;PBS_Server;Svr;PBS_Server;LOG_ERROR::sync_node_jobs, stray job 21190.tyrone-cluster found on tyrone-node6
04/03/2013 09:20:18;0001;PBS_Server;Svr;PBS_Server;LOG_ERROR::sync_node_jobs, stray job 21306.tyrone-cluster found on tyrone-node5
04/03/2013 09:20:42;0001;PBS_Server;Svr;PBS_Server;LOG_ERROR::sync_node_jobs, stray job 21312.tyrone-cluster found on tyrone-node4
04/03/2013 09:20:59;0001;PBS_Server;Svr;PBS_Server;LOG_ERROR::sync_node_jobs, stray job 21190.tyrone-cluster found on tyrone-node6
04/03/2013 09:21:03;0001;PBS_Server;Svr;PBS_Server;LOG_ERROR::sync_node_jobs, stray job 21306.tyrone-cluster found on tyrone-node5
04/03/2013 09:21:27;0001;PBS_Server;Svr;PBS_Server;LOG_ERROR::sync_node_jobs, stray job 21312.tyrone-cluster found on tyrone-node4
04/03/2013 09:21:44;0001;PBS_Server;Svr;PBS_Server;LOG_ERROR::sync_node_jobs, stray job 21190.tyrone-cluster found on tyrone-node6
04/03/2013 09:21:47;0001;PBS_Server;Svr;PBS_Server;LOG_ERROR::sync_node_jobs, stray job 21306.tyrone-cluster found on tyrone-node5
04/03/2013 09:22:12;0001;PBS_Server;Svr;PBS_Server;LOG_ERROR::sync_node_jobs, stray job 21312.tyrone-cluster found on tyrone-node4
04/03/2013 09:22:28;0001;PBS_Server;Svr;PBS_Server;LOG_ERROR::sync_node_jobs, stray job 21190.tyrone-cluster found on tyrone-node6
04/03/2013 09:22:32;0001;PBS_Server;Svr;PBS_Server;LOG_ERROR::sync_node_jobs, stray job 21306.tyrone-cluster found on tyrone-node5
04/03/2013 09:22:57;0001;PBS_Server;Svr;PBS_Server;LOG_ERROR::sync_node_jobs, stray job 21312.tyrone-cluster found on tyrone-node4
04/03/2013 09:23:13;0001;PBS_Server;Svr;PBS_Server;LOG_ERROR::sync_node_jobs, stray job 21190.tyrone-cluster found on tyrone-node6
04/03/2013 09:23:17;0001;PBS_Server;Svr;PBS_Server;LOG_ERROR::sync_node_jobs, stray job 21306.tyrone-cluster found on tyrone-node5
04/03/2013 09:23:30;0002;PBS_Server;Svr;PBS_Server;Torque Server Version = 3.0.5, loglevel = 0
04/03/2013 09:23:42;0001;PBS_Server;Svr;PBS_Server;LOG_ERROR::sync_node_jobs, stray job 21312.tyrone-cluster found on tyrone-node4
04/03/2013 09:23:58;0001;PBS_Server;Svr;PBS_Server;LOG_ERROR::sync_node_jobs, stray job 21190.tyrone-cluster found on tyrone-node6
04/03/2013 09:24:02;0001;PBS_Server;Svr;PBS_Server;LOG_ERROR::sync_node_jobs, stray job 21306.tyrone-cluster found on tyrone-node5
04/03/2013 09:24:27;0001;PBS_Server;Svr;PBS_Server;LOG_ERROR::sync_node_jobs, stray job 21312.tyrone-cluster found on tyrone-node4
04/03/2013 09:24:43;0001;PBS_Server;Svr;PBS_Server;LOG_ERROR::sync_node_jobs, stray job 21190.tyrone-cluster found on tyrone-node6
04/03/2013 09:24:44;0100;PBS_Server;Job;21336.tyrone-cluster;enqueuing into batch, state 1 hop 1
04/03/2013 09:24:44;0100;PBS_Server;Job;21336.tyrone-cluster;dequeuing from batch, state QUEUED
04/03/2013 09:24:44;0100;PBS_Server;Job;21336.tyrone-cluster;enqueuing into idqueue, state 1 hop 1
04/03/2013 09:24:44;0008;PBS_Server;Job;21336.tyrone-cluster;Job Queued at request of asebala@tyrone-cluster, owner = asebala@tyrone-cluster, job name = test, queue = idqueue
04/03/2013 09:24:44;0040;PBS_Server;Svr;tyrone-cluster;Scheduler was sent the command new
04/03/2013 09:24:44;0008;PBS_Server;Job;21336.tyrone-cluster;Job Modified at request of Scheduler@tyrone-cluster
04/03/2013 09:24:44;0008;PBS_Server;Job;21336.tyrone-cluster;Job Run at request of Scheduler@tyrone-cluster
04/03/2013 09:24:44;0040;PBS_Server;Svr;tyrone-cluster;Scheduler was sent the command recyc
04/03/2013 09:24:44;000d;PBS_Server;Job;21336.tyrone-cluster;Not sending email: User does not want mail of this type.
04/03/2013 09:24:47;000d;PBS_Server;Job;21336.tyrone-cluster;Not sending email: User does not want mail of this type.
04/03/2013 09:24:47;0010;PBS_Server;Job;21336.tyrone-cluster;Exit_status=1 resources_used.cput=00:00:00 resources_used.mem=0kb resources_used.vmem=0kb resources_used.walltime=00:00:03
04/03/2013 09:24:47;0008;PBS_Server;Job;NULL;on_job_exit valid pjob: 0x2051580 (substate=50)
04/03/2013 09:24:47;0008;PBS_Server;Job;NULL;on_job_exit valid pjob: 0x2051580 (substate=51)
04/03/2013 09:24:47;0008;PBS_Server;Job;NULL;on_job_exit valid pjob: 0x2051580 (substate=51)
04/03/2013 09:24:47;0008;PBS_Server;Job;NULL;on_job_exit valid pjob: 0x2051580 (substate=53)
04/03/2013 09:24:47;0100;PBS_Server;Job;21336.tyrone-cluster;dequeuing from idqueue, state COMPLETE
04/03/2013 09:24:47;0040;PBS_Server;Svr;tyrone-cluster;Scheduler was sent the command term
04/03/2013 09:24:47;0001;PBS_Server;Svr;PBS_Server;LOG_ERROR::sync_node_jobs, stray job 21306.tyrone-cluster found on tyrone-node5
04/03/2013 09:25:12;0001;PBS_Server;Svr;PBS_Server;LOG_ERROR::sync_node_jobs, stray job 21312.tyrone-cluster found on tyrone-node4
04/03/2013 09:25:28;0001;PBS_Server;Svr;PBS_Server;LOG_ERROR::sync_node_jobs, stray job 21190.tyrone-cluster found on tyrone-node6
04/03/2013 09:25:32;0001;PBS_Server;Svr;PBS_Server;LOG_ERROR::sync_node_jobs, stray job 21306.tyrone-cluster found on tyrone-node5
04/03/2013 09:25:57;0001;PBS_Server;Svr;PBS_Server;LOG_ERROR::sync_node_jobs, stray job 21312.tyrone-cluster found on tyrone-node4
04/03/2013 09:26:14;0001;PBS_Server;Svr;PBS_Server;LOG_ERROR::sync_node_jobs, stray job 21190.tyrone-cluster found on tyrone-node6
04/03/2013 09:26:17;0001;PBS_Server;Svr;PBS_Server;LOG_ERROR::sync_node_jobs, stray job 21306.tyrone-cluster found on tyrone-node5
04/03/2013 09:26:42;0001;PBS_Server;Svr;PBS_Server;LOG_ERROR::sync_node_jobs, stray job 21312.tyrone-cluster found on tyrone-node4
04/03/2013 09:26:58;0001;PBS_Server;Svr;PBS_Server;LOG_ERROR::sync_node_jobs, stray job 21190.tyrone-cluster found on tyrone-node6
04/03/2013 09:27:02;0001;PBS_Server;Svr;PBS_Server;LOG_ERROR::sync_node_jobs, stray job 21306.tyrone-cluster found on tyrone-node5
04/03/2013 09:27:27;0001;PBS_Server;Svr;PBS_Server;LOG_ERROR::sync_node_jobs, stray job 21312.tyrone-cluster found on tyrone-node4
04/03/2013 09:27:43;0001;PBS_Server;Svr;PBS_Server;LOG_ERROR::sync_node_jobs, stray job 21190.tyrone-cluster found on tyrone-node6
04/03/2013 09:27:47;0001;PBS_Server;Svr;PBS_Server;LOG_ERROR::sync_node_jobs, stray job 21306.tyrone-cluster found on tyrone-node5
04/03/2013 09:28:11;0001;PBS_Server;Svr;PBS_Server;LOG_ERROR::sync_node_jobs, stray job 21312.tyrone-cluster found on tyrone-node4
04/03/2013 09:28:28;0001;PBS_Server;Svr;PBS_Server;LOG_ERROR::sync_node_jobs, stray job 21190.tyrone-cluster found on tyrone-node6
04/03/2013 09:28:30;0002;PBS_Server;Svr;PBS_Server;Torque Server Version = 3.0.5, loglevel = 0
04/03/2013 09:28:32;0001;PBS_Server;Svr;PBS_Server;LOG_ERROR::sync_node_jobs, stray job 21306.tyrone-cluster found on tyrone-node5
04/03/2013 09:28:56;0001;PBS_Server;Svr;PBS_Server;LOG_ERROR::sync_node_jobs, stray job 21312.tyrone-cluster found on tyrone-node4
04/03/2013 09:29:13;0001;PBS_Server;Svr;PBS_Server;LOG_ERROR::sync_node_jobs, stray job 21190.tyrone-cluster found on tyrone-node6
04/03/2013 09:29:17;0001;PBS_Server;Svr;PBS_Server;LOG_ERROR::sync_node_jobs, stray job 21306.tyrone-cluster found on tyrone-node5
04/03/2013 09:29:31;0100;PBS_Server;Job;21337.tyrone-cluster;enqueuing into batch, state 1 hop 1
04/03/2013 09:29:31;0100;PBS_Server;Job;21337.tyrone-cluster;dequeuing from batch, state QUEUED
04/03/2013 09:29:31;0100;PBS_Server;Job;21337.tyrone-cluster;enqueuing into qp32, state 1 hop 1
04/03/2013 09:29:31;0008;PBS_Server;Job;21337.tyrone-cluster;Job Queued at request of nisaadi@tyrone-cluster, owner = nisaadi@tyrone-cluster, job name = gr-di-O-run5, queue = qp32
04/03/2013 09:29:31;0040;PBS_Server;Svr;tyrone-cluster;Scheduler was sent the command new
04/03/2013 09:29:31;0008;PBS_Server;Job;21337.tyrone-cluster;Job Modified at request of Scheduler@tyrone-cluster
04/03/2013 09:29:31;0008;PBS_Server;Job;21337.tyrone-cluster;Job Run at request of Scheduler@tyrone-cluster
04/03/2013 09:29:31;0040;PBS_Server;Svr;tyrone-cluster;Scheduler was sent the command recyc
04/03/2013 09:29:31;000d;PBS_Server;Job;21337.tyrone-cluster;Not sending email: User does not want mail of this type.
04/03/2013 09:29:38;0001;PBS_Server;Svr;PBS_Server;LOG_ERROR::sync_node_jobs, stray job 21337.tyrone-cluster found on tyrone-node8
04/03/2013 09:29:41;0001;PBS_Server;Svr;PBS_Server;LOG_ERROR::sync_node_jobs, stray job 21312.tyrone-cluster found on tyrone-node4
04/03/2013 09:29:58;0001;PBS_Server;Svr;PBS_Server;LOG_ERROR::sync_node_jobs, stray job 21190.tyrone-cluster found on tyrone-node6
04/03/2013 09:30:02;0001;PBS_Server;Svr;PBS_Server;LOG_ERROR::sync_node_jobs, stray job 21306.tyrone-cluster found on tyrone-node5
04/03/2013 09:30:23;0001;PBS_Server;Svr;PBS_Server;LOG_ERROR::sync_node_jobs, stray job 21337.tyrone-cluster found on tyrone-node8
04/03/2013 09:30:26;0001;PBS_Server;Svr;PBS_Server;LOG_ERROR::sync_node_jobs, stray job 21312.tyrone-cluster found on tyrone-node4
04/03/2013 09:30:43;0001;PBS_Server;Svr;PBS_Server;LOG_ERROR::sync_node_jobs, stray job 21190.tyrone-cluster found on tyrone-node6
04/03/2013 09:30:47;0001;PBS_Server;Svr;PBS_Server;LOG_ERROR::sync_node_jobs, stray job 21306.tyrone-cluster found on tyrone-node5
04/03/2013 09:30:48;0100;PBS_Server;Job;21338.tyrone-cluster;enqueuing into batch, state 1 hop 1
04/03/2013 09:30:48;0100;PBS_Server;Job;21338.tyrone-cluster;dequeuing from batch, state QUEUED
04/03/2013 09:30:48;0100;PBS_Server;Job;21338.tyrone-cluster;enqueuing into qp32, state 1 hop 1
04/03/2013 09:30:48;0008;PBS_Server;Job;21338.tyrone-cluster;Job Queued at request of nisaadi@tyrone-cluster, owner = nisaadi@tyrone-cluster, job name = 1layers-OHli, queue = qp32
04/03/2013 09:30:48;0040;PBS_Server;Svr;tyrone-cluster;Scheduler was sent the command new
04/03/2013 09:30:48;0008;PBS_Server;Job;21338.tyrone-cluster;Job Modified at request of Scheduler@tyrone-cluster
04/03/2013 09:30:48;0008;PBS_Server;Job;21338.tyrone-cluster;Job Run at request of Scheduler@tyrone-cluster
04/03/2013 09:30:49;000d;PBS_Server;Job;21338.tyrone-cluster;Not sending email: User does not want mail of this type.
04/03/2013 09:30:49;0040;PBS_Server;Svr;tyrone-cluster;Scheduler was sent the command recyc
04/03/2013 09:31:08;0001;PBS_Server;Svr;PBS_Server;LOG_ERROR::sync_node_jobs, stray job 21337.tyrone-cluster found on tyrone-node8
04/03/2013 09:31:10;0001;PBS_Server;Svr;PBS_Server;LOG_ERROR::sync_node_jobs, stray job 21338.tyrone-cluster found on tyrone-node10
04/03/2013 09:31:11;0001;PBS_Server;Svr;PBS_Server;LOG_ERROR::sync_node_jobs, stray job 21312.tyrone-cluster found on tyrone-node4
04/03/2013 09:31:28;0001;PBS_Server;Svr;PBS_Server;LOG_ERROR::sync_node_jobs, stray job 21190.tyrone-cluster found on tyrone-node6
04/03/2013 09:31:32;0001;PBS_Server;Svr;PBS_Server;LOG_ERROR::sync_node_jobs, stray job 21306.tyrone-cluster found on tyrone-node5
04/03/2013 09:31:54;0001;PBS_Server;Svr;PBS_Server;LOG_ERROR::sync_node_jobs, stray job 21337.tyrone-cluster found on tyrone-node8
04/03/2013 09:31:55;0001;PBS_Server;Svr;PBS_Server;LOG_ERROR::sync_node_jobs, stray job 21338.tyrone-cluster found on tyrone-node10
04/03/2013 09:31:57;0001;PBS_Server;Svr;PBS_Server;LOG_ERROR::sync_node_jobs, stray job 21312.tyrone-cluster found on tyrone-node4
04/03/2013 09:32:13;0001;PBS_Server;Svr;PBS_Server;LOG_ERROR::sync_node_jobs, stray job 21190.tyrone-cluster found on tyrone-node6
04/03/2013 09:32:17;0001;PBS_Server;Svr;PBS_Server;LOG_ERROR::sync_node_jobs, stray job 21306.tyrone-cluster found on tyrone-node5
04/03/2013 09:32:20;0100;PBS_Server;Job;21339.tyrone-cluster;enqueuing into batch, state 1 hop 1
04/03/2013 09:32:20;0100;PBS_Server;Job;21339.tyrone-cluster;dequeuing from batch, state QUEUED
04/03/2013 09:32:20;0100;PBS_Server;Job;21339.tyrone-cluster;enqueuing into idqueue, state 1 hop 1
04/03/2013 09:32:20;0008;PBS_Server;Job;21339.tyrone-cluster;Job Queued at request of mrcaks@tyrone-cluster, owner = mrcaks@tyrone-cluster, job name = Al, queue = idqueue
04/03/2013 09:32:20;0040;PBS_Server;Svr;tyrone-cluster;Scheduler was sent the command new
04/03/2013 09:32:24;0008;PBS_Server;Job;21339.tyrone-cluster;Job Modified at request of Scheduler@tyrone-cluster
04/03/2013 09:32:24;0008;PBS_Server;Job;21339.tyrone-cluster;Job Run at request of Scheduler@tyrone-cluster
04/03/2013 09:32:24;0040;PBS_Server;Svr;tyrone-cluster;Scheduler was sent the command recyc
04/03/2013 09:32:24;000d;PBS_Server;Job;21339.tyrone-cluster;Not sending email: User does not want mail of this type.
04/03/2013 09:32:38;0001;PBS_Server;Svr;PBS_Server;LOG_ERROR::sync_node_jobs, stray job 21337.tyrone-cluster found on tyrone-node8
04/03/2013 09:32:40;0001;PBS_Server;Svr;PBS_Server;LOG_ERROR::sync_node_jobs, stray job 21338.tyrone-cluster found on tyrone-node10
04/03/2013 09:32:41;0001;PBS_Server;Svr;PBS_Server;LOG_ERROR::sync_node_jobs, stray job 21312.tyrone-cluster found on tyrone-node4
04/03/2013 09:32:52;0100;PBS_Server;Job;21340.tyrone-cluster;enqueuing into batch, state 1 hop 1
04/03/2013 09:32:52;0100;PBS_Server;Job;21340.tyrone-cluster;dequeuing from batch, state QUEUED
04/03/2013 09:32:52;0100;PBS_Server;Job;21340.tyrone-cluster;enqueuing into qp64, state 1 hop 1
04/03/2013 09:32:52;0008;PBS_Server;Job;21340.tyrone-cluster;Job Queued at request of mrcpndey@tyrone-cluster, owner = mrcpndey@tyrone-cluster, job name = fcc-Li-diff, queue = qp64
04/03/2013 09:32:52;0040;PBS_Server;Svr;tyrone-cluster;Scheduler was sent the command new
04/03/2013 09:32:53;0008;PBS_Server;Job;21339.tyrone-cluster;Job deleted at request of mrcaks@tyrone-cluster
04/03/2013 09:32:53;0008;PBS_Server;Job;21339.tyrone-cluster;Job sent signal SIGTERM on delete
04/03/2013 09:32:53;000d;PBS_Server;Job;21339.tyrone-cluster;Not sending email: User does not want mail of this type.
04/03/2013 09:32:53;0010;PBS_Server;Job;21339.tyrone-cluster;Exit_status=143 resources_used.cput=00:13:53 resources_used.mem=929472kb resources_used.vmem=22313692kb resources_used.walltime=00:00:29
04/03/2013 09:32:53;0008;PBS_Server;Job;NULL;on_job_exit valid pjob: 0x2140720 (substate=50)
04/03/2013 09:32:53;0008;PBS_Server;Job;NULL;on_job_exit valid pjob: 0x2140720 (substate=51)
04/03/2013 09:32:53;0008;PBS_Server;Job;NULL;on_job_exit valid pjob: 0x2140720 (substate=51)
04/03/2013 09:32:53;0008;PBS_Server;Job;NULL;on_job_exit valid pjob: 0x2140720 (substate=53)
04/03/2013 09:32:53;0100;PBS_Server;Job;21339.tyrone-cluster;dequeuing from idqueue, state COMPLETE
04/03/2013 09:32:56;0008;PBS_Server;Job;21340.tyrone-cluster;Job Modified at request of Scheduler@tyrone-cluster
04/03/2013 09:32:56;0008;PBS_Server;Job;21340.tyrone-cluster;Job Run at request of Scheduler@tyrone-cluster
04/03/2013 09:32:56;0040;PBS_Server;Svr;tyrone-cluster;Scheduler was sent the command recyc
04/03/2013 09:32:56;000d;PBS_Server;Job;21340.tyrone-cluster;Not sending email: User does not want mail of this type.
04/03/2013 09:32:58;0001;PBS_Server;Svr;PBS_Server;LOG_ERROR::sync_node_jobs, stray job 21190.tyrone-cluster found on tyrone-node6
04/03/2013 09:33:02;0100;PBS_Server;Job;21341.tyrone-cluster;enqueuing into batch, state 1 hop 1
04/03/2013 09:33:02;0100;PBS_Server;Job;21341.tyrone-cluster;dequeuing from batch, state QUEUED
04/03/2013 09:33:02;0100;PBS_Server;Job;21341.tyrone-cluster;enqueuing into idqueue, state 1 hop 1
04/03/2013 09:33:02;0008;PBS_Server;Job;21341.tyrone-cluster;Job Queued at request of mrcaks@tyrone-cluster, owner = mrcaks@tyrone-cluster, job name = Al, queue = idqueue
04/03/2013 09:33:02;0040;PBS_Server;Svr;tyrone-cluster;Scheduler was sent the command new
04/03/2013 09:33:02;0001;PBS_Server;Svr;PBS_Server;LOG_ERROR::sync_node_jobs, stray job 21306.tyrone-cluster found on tyrone-node5
04/03/2013 09:33:06;0008;PBS_Server;Job;21341.tyrone-cluster;Job Modified at request of Scheduler@tyrone-cluster
04/03/2013 09:33:06;0008;PBS_Server;Job;21341.tyrone-cluster;Job Run at request of Scheduler@tyrone-cluster
04/03/2013 09:33:06;0040;PBS_Server;Svr;tyrone-cluster;Scheduler was sent the command recyc
04/03/2013 09:33:06;000d;PBS_Server;Job;21341.tyrone-cluster;Not sending email: User does not want mail of this type.
04/03/2013 09:33:23;0001;PBS_Server;Svr;PBS_Server;LOG_ERROR::sync_node_jobs, stray job 21337.tyrone-cluster found on tyrone-node8
04/03/2013 09:33:25;0001;PBS_Server;Svr;PBS_Server;LOG_ERROR::sync_node_jobs, stray job 21338.tyrone-cluster found on tyrone-node10
04/03/2013 09:33:26;0001;PBS_Server;Svr;PBS_Server;LOG_ERROR::sync_node_jobs, stray job 21312.tyrone-cluster found on tyrone-node4
04/03/2013 09:33:30;0002;PBS_Server;Svr;PBS_Server;Torque Server Version = 3.0.5, loglevel = 0
04/03/2013 09:33:43;0001;PBS_Server;Svr;PBS_Server;LOG_ERROR::sync_node_jobs, stray job 21190.tyrone-cluster found on tyrone-node6
04/03/2013 09:33:47;0001;PBS_Server;Svr;PBS_Server;LOG_ERROR::sync_node_jobs, stray job 21306.tyrone-cluster found on tyrone-node5
04/03/2013 09:33:51;000d;PBS_Server;Job;21142.tyrone-cluster;Not sending email: User does not want mail of this type.
04/03/2013 09:33:51;0010;PBS_Server;Job;21142.tyrone-cluster;Exit_status=143 resources_used.cput=181:09:28 resources_used.mem=1471528kb resources_used.vmem=9841952kb resources_used.walltime=24:02:38
04/03/2013 09:33:51;0008;PBS_Server;Job;NULL;on_job_exit valid pjob: 0x1fbec90 (substate=50)
04/03/2013 09:33:51;0008;PBS_Server;Job;NULL;on_job_exit valid pjob: 0x1fbec90 (substate=51)
04/03/2013 09:33:55;0008;PBS_Server;Job;NULL;on_job_exit valid pjob: 0x1fbec90 (substate=51)
04/03/2013 09:33:55;000d;PBS_Server;Job;21142.tyrone-cluster;Post job file processing error; job 21142.tyrone-cluster on host tyrone-node2/31+tyrone-node2/30+tyrone-node2/29+tyrone-node2/28+tyrone-node2/27+tyrone-node2/26+tyrone-node2/25+tyrone-node2/24+tyrone-node2/23+tyrone-node2/22+tyrone-node2/21+tyrone-node2/20+tyrone-node2/19+tyrone-node2/18+tyrone-node2/17+tyrone-node2/16+tyrone-node2/15+tyrone-node2/14+tyrone-node2/13+tyrone-node2/12+tyrone-node2/11+tyrone-node2/10+tyrone-node2/9+tyrone-node2/8+tyrone-node2/7+tyrone-node2/6+tyrone-node2/5+tyrone-node2/4+tyrone-node2/3+tyrone-node2/2+tyrone-node2/1+tyrone-node2/0
04/03/2013 09:33:55;0008;PBS_Server;Job;NULL;on_job_exit valid pjob: 0x1fbec90 (substate=53)
04/03/2013 09:33:55;0100;PBS_Server;Job;21142.tyrone-cluster;dequeuing from qp32, state COMPLETE
04/03/2013 09:33:55;0040;PBS_Server;Svr;tyrone-cluster;Scheduler was sent the command term
04/03/2013 09:34:08;0001;PBS_Server;Svr;PBS_Server;LOG_ERROR::sync_node_jobs, stray job 21337.tyrone-cluster found on tyrone-node8
04/03/2013 09:34:09;0008;PBS_Server;Job;21341.tyrone-cluster;Job deleted at request of mrcaks@tyrone-cluster
04/03/2013 09:34:09;0008;PBS_Server;Job;21341.tyrone-cluster;Job sent signal SIGTERM on delete
04/03/2013 09:34:10;000d;PBS_Server;Job;21341.tyrone-cluster;Not sending email: User does not want mail of this type.
04/03/2013 09:34:10;0010;PBS_Server;Job;21341.tyrone-cluster;Exit_status=143 resources_used.cput=00:14:01 resources_used.mem=11863104kb resources_used.vmem=19034500kb resources_used.walltime=00:01:04
04/03/2013 09:34:10;0008;PBS_Server;Job;NULL;on_job_exit valid pjob: 0x2140720 (substate=50)
04/03/2013 09:34:10;0008;PBS_Server;Job;NULL;on_job_exit valid pjob: 0x2140720 (substate=51)
04/03/2013 09:34:10;0008;PBS_Server;Job;NULL;on_job_exit valid pjob: 0x2140720 (substate=51)
04/03/2013 09:34:10;0008;PBS_Server;Job;NULL;on_job_exit valid pjob: 0x2140720 (substate=53)
04/03/2013 09:34:10;0100;PBS_Server;Job;21341.tyrone-cluster;dequeuing from idqueue, state COMPLETE
04/03/2013 09:34:10;0040;PBS_Server;Svr;tyrone-cluster;Scheduler was sent the command term
04/03/2013 09:34:10;0001;PBS_Server;Svr;PBS_Server;LOG_ERROR::sync_node_jobs, stray job 21338.tyrone-cluster found on tyrone-node10
04/03/2013 09:34:12;0001;PBS_Server;Svr;PBS_Server;LOG_ERROR::sync_node_jobs, stray job 21312.tyrone-cluster found on tyrone-node4
04/03/2013 09:34:12;0100;PBS_Server;Job;21342.tyrone-cluster;enqueuing into batch, state 1 hop 1
04/03/2013 09:34:12;0100;PBS_Server;Job;21342.tyrone-cluster;dequeuing from batch, state QUEUED
04/03/2013 09:34:12;0100;PBS_Server;Job;21342.tyrone-cluster;enqueuing into idqueue, state 1 hop 1
04/03/2013 09:34:12;0008;PBS_Server;Job;21342.tyrone-cluster;Job Queued at request of mrcaks@tyrone-cluster, owner = mrcaks@tyrone-cluster, job name = Al, queue = idqueue
04/03/2013 09:34:12;0040;PBS_Server;Svr;tyrone-cluster;Scheduler was sent the command new
04/03/2013 09:34:12;0008;PBS_Server;Job;21342.tyrone-cluster;Job Modified at request of Scheduler@tyrone-cluster
04/03/2013 09:34:12;0008;PBS_Server;Job;21342.tyrone-cluster;Job Run at request of Scheduler@tyrone-cluster
04/03/2013 09:34:12;0040;PBS_Server;Svr;tyrone-cluster;Scheduler was sent the command recyc
04/03/2013 09:34:12;000d;PBS_Server;Job;21342.tyrone-cluster;Not sending email: User does not want mail of this type.
04/03/2013 09:34:28;0001;PBS_Server;Svr;PBS_Server;LOG_ERROR::sync_node_jobs, stray job 21190.tyrone-cluster found on tyrone-node6
04/03/2013 09:34:32;0001;PBS_Server;Svr;PBS_Server;LOG_ERROR::sync_node_jobs, stray job 21306.tyrone-cluster found on tyrone-node5
04/03/2013 09:34:53;0001;PBS_Server;Svr;PBS_Server;LOG_ERROR::sync_node_jobs, stray job 21337.tyrone-cluster found on tyrone-node8
04/03/2013 09:34:55;0001;PBS_Server;Svr;PBS_Server;LOG_ERROR::sync_node_jobs, stray job 21338.tyrone-cluster found on tyrone-node10
04/03/2013 09:34:56;0001;PBS_Server;Svr;PBS_Server;LOG_ERROR::sync_node_jobs, stray job 21312.tyrone-cluster found on tyrone-node4
04/03/2013 09:35:13;0001;PBS_Server;Svr;PBS_Server;LOG_ERROR::sync_node_jobs, stray job 21190.tyrone-cluster found on tyrone-node6
04/03/2013 09:35:17;0001;PBS_Server;Svr;PBS_Server;LOG_ERROR::sync_node_jobs, stray job 21306.tyrone-cluster found on tyrone-node5
04/03/2013 09:35:38;0001;PBS_Server;Svr;PBS_Server;LOG_ERROR::sync_node_jobs, stray job 21337.tyrone-cluster found on tyrone-node8
04/03/2013 09:35:40;0001;PBS_Server;Svr;PBS_Server;LOG_ERROR::sync_node_jobs, stray job 21338.tyrone-cluster found on tyrone-node10
04/03/2013 09:35:41;0001;PBS_Server;Svr;PBS_Server;LOG_ERROR::sync_node_jobs, stray job 21312.tyrone-cluster found on tyrone-node4
04/03/2013 09:35:58;0001;PBS_Server;Svr;PBS_Server;LOG_ERROR::sync_node_jobs, stray job 21190.tyrone-cluster found on tyrone-node6
04/03/2013 09:36:02;0001;PBS_Server;Svr;PBS_Server;LOG_ERROR::sync_node_jobs, stray job 21306.tyrone-cluster found on tyrone-node5
04/03/2013 09:36:23;0001;PBS_Server;Svr;PBS_Server;LOG_ERROR::sync_node_jobs, stray job 21337.tyrone-cluster found on tyrone-node8
04/03/2013 09:36:25;0001;PBS_Server;Svr;PBS_Server;LOG_ERROR::sync_node_jobs, stray job 21338.tyrone-cluster found on tyrone-node10
04/03/2013 09:36:26;0001;PBS_Server;Svr;PBS_Server;LOG_ERROR::sync_node_jobs, stray job 21312.tyrone-cluster found on tyrone-node4
04/03/2013 09:36:29;000d;PBS_Server;Job;21338.tyrone-cluster;Not sending email: User does not want mail of this type.
04/03/2013 09:36:29;0010;PBS_Server;Job;21338.tyrone-cluster;Exit_status=0 resources_used.cput=00:00:15 resources_used.mem=3104kb resources_used.vmem=217356kb resources_used.walltime=00:05:41
04/03/2013 09:36:29;0008;PBS_Server;Job;NULL;on_job_exit valid pjob: 0x1fa2f10 (substate=50)
04/03/2013 09:36:29;0008;PBS_Server;Job;NULL;on_job_exit valid pjob: 0x1fa2f10 (substate=51)
04/03/2013 09:36:30;0008;PBS_Server;Job;NULL;on_job_exit valid pjob: 0x1fa2f10 (substate=51)
04/03/2013 09:36:30;0008;PBS_Server;Job;NULL;on_job_exit valid pjob: 0x1fa2f10 (substate=53)
04/03/2013 09:36:30;0100;PBS_Server;Job;21338.tyrone-cluster;dequeuing from qp32, state COMPLETE
04/03/2013 09:36:30;0040;PBS_Server;Svr;tyrone-cluster;Scheduler was sent the command term
04/03/2013 09:36:39;000d;PBS_Server;Job;21337.tyrone-cluster;Not sending email: User does not want mail of this type.
04/03/2013 09:36:39;0010;PBS_Server;Job;21337.tyrone-cluster;Exit_status=0 resources_used.cput=00:00:20 resources_used.mem=3104kb resources_used.vmem=217356kb resources_used.walltime=00:07:07
04/03/2013 09:36:39;0008;PBS_Server;Job;NULL;on_job_exit valid pjob: 0x2051580 (substate=50)
04/03/2013 09:36:39;0008;PBS_Server;Job;NULL;on_job_exit valid pjob: 0x2051580 (substate=51)
04/03/2013 09:36:40;0008;PBS_Server;Job;NULL;on_job_exit valid pjob: 0x2051580 (substate=51)
04/03/2013 09:36:40;0008;PBS_Server;Job;NULL;on_job_exit valid pjob: 0x2051580 (substate=53)
04/03/2013 09:36:40;0100;PBS_Server;Job;21337.tyrone-cluster;dequeuing from qp32, state COMPLETE
04/03/2013 09:36:40;0040;PBS_Server;Svr;tyrone-cluster;Scheduler was sent the command term
04/03/2013 09:36:43;0001;PBS_Server;Svr;PBS_Server;LOG_ERROR::sync_node_jobs, stray job 21190.tyrone-cluster found on tyrone-node6
04/03/2013 09:36:47;0001;PBS_Server;Svr;PBS_Server;LOG_ERROR::sync_node_jobs, stray job 21306.tyrone-cluster found on tyrone-node5
04/03/2013 09:37:11;0001;PBS_Server;Svr;PBS_Server;LOG_ERROR::sync_node_jobs, stray job 21312.tyrone-cluster found on tyrone-node4
04/03/2013 09:37:28;0001;PBS_Server;Svr;PBS_Server;LOG_ERROR::sync_node_jobs, stray job 21190.tyrone-cluster found on tyrone-node6
04/03/2013 09:37:32;0001;PBS_Server;Svr;PBS_Server;LOG_ERROR::sync_node_jobs, stray job 21306.tyrone-cluster found on tyrone-node5
04/03/2013 09:37:56;0001;PBS_Server;Svr;PBS_Server;LOG_ERROR::sync_node_jobs, stray job 21312.tyrone-cluster found on tyrone-node4
04/03/2013 09:37:56;000d;PBS_Server;Job;21340.tyrone-cluster;Not sending email: User does not want mail of this type.
04/03/2013 09:37:56;0010;PBS_Server;Job;21340.tyrone-cluster;Exit_status=0 resources_used.cput=01:11:32 resources_used.mem=874336kb resources_used.vmem=37083512kb resources_used.walltime=00:05:00
04/03/2013 09:37:56;0008;PBS_Server;Job;NULL;on_job_exit valid pjob: 0x1fa81b0 (substate=50)
04/03/2013 09:37:56;0008;PBS_Server;Job;NULL;on_job_exit valid pjob: 0x1fa81b0 (substate=51)
04/03/2013 09:37:56;0008;PBS_Server;Job;NULL;on_job_exit valid pjob: 0x1fa81b0 (substate=51)
04/03/2013 09:37:56;0008;PBS_Server;Job;NULL;on_job_exit valid pjob: 0x1fa81b0 (substate=53)
04/03/2013 09:37:56;0100;PBS_Server;Job;21340.tyrone-cluster;dequeuing from qp64, state COMPLETE
04/03/2013 09:37:56;0040;PBS_Server;Svr;tyrone-cluster;Scheduler was sent the command term
04/03/2013 09:38:13;0001;PBS_Server;Svr;PBS_Server;LOG_ERROR::sync_node_jobs, stray job 21190.tyrone-cluster found on tyrone-node6
04/03/2013 09:38:17;0001;PBS_Server;Svr;PBS_Server;LOG_ERROR::sync_node_jobs, stray job 21306.tyrone-cluster found on tyrone-node5
04/03/2013 09:38:30;0002;PBS_Server;Svr;PBS_Server;Torque Server Version = 3.0.5, loglevel = 0
04/03/2013 09:38:41;0001;PBS_Server;Svr;PBS_Server;LOG_ERROR::sync_node_jobs, stray job 21312.tyrone-cluster found on tyrone-node4
04/03/2013 09:38:57;0100;PBS_Server;Job;21343.tyrone-cluster;enqueuing into batch, state 1 hop 1
04/03/2013 09:38:57;0100;PBS_Server;Job;21343.tyrone-cluster;dequeuing from batch, state QUEUED
04/03/2013 09:38:57;0100;PBS_Server;Job;21343.tyrone-cluster;enqueuing into qp32, state 1 hop 1
04/03/2013 09:38:57;0008;PBS_Server;Job;21343.tyrone-cluster;Job Queued at request of nisaadi@tyrone-cluster, owner = nisaadi@tyrone-cluster, job name = 1layers-OHli, queue = qp32
04/03/2013 09:38:57;0040;PBS_Server;Svr;tyrone-cluster;Scheduler was sent the command new
04/03/2013 09:38:57;0008;PBS_Server;Job;21343.tyrone-cluster;Job Modified at request of Scheduler@tyrone-cluster
04/03/2013 09:38:57;0008;PBS_Server;Job;21343.tyrone-cluster;Job Run at request of Scheduler@tyrone-cluster
04/03/2013 09:38:57;0040;PBS_Server;Svr;tyrone-cluster;Scheduler was sent the command recyc
04/03/2013 09:38:57;000d;PBS_Server;Job;21343.tyrone-cluster;Not sending email: User does not want mail of this type.
04/03/2013 09:38:58;0001;PBS_Server;Svr;PBS_Server;LOG_ERROR::sync_node_jobs, stray job 21190.tyrone-cluster found on tyrone-node6
04/03/2013 09:39:02;0001;PBS_Server;Svr;PBS_Server;LOG_ERROR::sync_node_jobs, stray job 21306.tyrone-cluster found on tyrone-node5
04/03/2013 09:39:26;0001;PBS_Server;Svr;PBS_Server;LOG_ERROR::sync_node_jobs, stray job 21312.tyrone-cluster found on tyrone-node4
04/03/2013 09:39:43;0001;PBS_Server;Svr;PBS_Server;LOG_ERROR::sync_node_jobs, stray job 21190.tyrone-cluster found on tyrone-node6
04/03/2013 09:39:47;0001;PBS_Server;Svr;PBS_Server;LOG_ERROR::sync_node_jobs, stray job 21306.tyrone-cluster found on tyrone-node5
04/03/2013 09:40:11;0001;PBS_Server;Svr;PBS_Server;LOG_ERROR::sync_node_jobs, stray job 21312.tyrone-cluster found on tyrone-node4
04/03/2013 09:40:28;0001;PBS_Server;Svr;PBS_Server;LOG_ERROR::sync_node_jobs, stray job 21190.tyrone-cluster found on tyrone-node6
04/03/2013 09:40:32;0001;PBS_Server;Svr;PBS_Server;LOG_ERROR::sync_node_jobs, stray job 21306.tyrone-cluster found on tyrone-node5
04/03/2013 09:40:51;0100;PBS_Server;Job;21344.tyrone-cluster;enqueuing into batch, state 1 hop 1
04/03/2013 09:40:51;0100;PBS_Server;Job;21344.tyrone-cluster;dequeuing from batch, state QUEUED
04/03/2013 09:40:51;0100;PBS_Server;Job;21344.tyrone-cluster;enqueuing into qp32, state 1 hop 1
04/03/2013 09:40:51;0008;PBS_Server;Job;21344.tyrone-cluster;Job Queued at request of mrcaks@tyrone-cluster, owner = mrcaks@tyrone-cluster, job name = Fe_pyridine_84, queue = qp32
04/03/2013 09:40:51;0040;PBS_Server;Svr;tyrone-cluster;Scheduler was sent the command new
04/03/2013 09:40:51;0008;PBS_Server;Job;21344.tyrone-cluster;Job Modified at request of Scheduler@tyrone-cluster
04/03/2013 09:40:51;0008;PBS_Server;Job;21344.tyrone-cluster;Job Run at request of Scheduler@tyrone-cluster
04/03/2013 09:40:52;0040;PBS_Server;Svr;tyrone-cluster;Scheduler was sent the command recyc
04/03/2013 09:40:52;000d;PBS_Server;Job;21344.tyrone-cluster;Not sending email: User does not want mail of this type.
04/03/2013 09:40:53;0001;PBS_Server;Svr;PBS_Server;LOG_ERROR::sync_node_jobs, stray job 21344.tyrone-cluster found on tyrone-node8
04/03/2013 09:40:56;0001;PBS_Server;Svr;PBS_Server;LOG_ERROR::sync_node_jobs, stray job 21312.tyrone-cluster found on tyrone-node4
04/03/2013 09:41:13;0001;PBS_Server;Svr;PBS_Server;LOG_ERROR::sync_node_jobs, stray job 21190.tyrone-cluster found on tyrone-node6
04/03/2013 09:41:17;0001;PBS_Server;Svr;PBS_Server;LOG_ERROR::sync_node_jobs, stray job 21306.tyrone-cluster found on tyrone-node5
04/03/2013 09:41:38;0001;PBS_Server;Svr;PBS_Server;LOG_ERROR::sync_node_jobs, stray job 21344.tyrone-cluster found on tyrone-node8
04/03/2013 09:41:41;0001;PBS_Server;Svr;PBS_Server;LOG_ERROR::sync_node_jobs, stray job 21312.tyrone-cluster found on tyrone-node4
04/03/2013 09:41:58;0001;PBS_Server;Svr;PBS_Server;LOG_ERROR::sync_node_jobs, stray job 21190.tyrone-cluster found on tyrone-node6
04/03/2013 09:42:02;0001;PBS_Server;Svr;PBS_Server;LOG_ERROR::sync_node_jobs, stray job 21306.tyrone-cluster found on tyrone-node5
04/03/2013 09:42:23;0001;PBS_Server;Svr;PBS_Server;LOG_ERROR::sync_node_jobs, stray job 21344.tyrone-cluster found on tyrone-node8
04/03/2013 09:42:26;0001;PBS_Server;Svr;PBS_Server;LOG_ERROR::sync_node_jobs, stray job 21312.tyrone-cluster found on tyrone-node4
04/03/2013 09:42:43;0001;PBS_Server;Svr;PBS_Server;LOG_ERROR::sync_node_jobs, stray job 21190.tyrone-cluster found on tyrone-node6
04/03/2013 09:42:47;0001;PBS_Server;Svr;PBS_Server;LOG_ERROR::sync_node_jobs, stray job 21306.tyrone-cluster found on tyrone-node5
04/03/2013 09:43:08;0001;PBS_Server;Svr;PBS_Server;LOG_ERROR::sync_node_jobs, stray job 21344.tyrone-cluster found on tyrone-node8
04/03/2013 09:43:12;0001;PBS_Server;Svr;PBS_Server;LOG_ERROR::sync_node_jobs, stray job 21312.tyrone-cluster found on tyrone-node4
04/03/2013 09:43:28;0001;PBS_Server;Svr;PBS_Server;LOG_ERROR::sync_node_jobs, stray job 21190.tyrone-cluster found on tyrone-node6
04/03/2013 09:43:30;0002;PBS_Server;Svr;PBS_Server;Torque Server Version = 3.0.5, loglevel = 0
04/03/2013 09:43:32;0001;PBS_Server;Svr;PBS_Server;LOG_ERROR::sync_node_jobs, stray job 21306.tyrone-cluster found on tyrone-node5
04/03/2013 09:43:43;0001;PBS_Server;Svr;PBS_Server;LOG_ERROR::stream_eof, connection to tyrone-node7 is no longer valid, connection may have been closed remotely, remote service may be down, or message may be corrupt (End of File).  setting node state to down
04/03/2013 09:43:45;000d;PBS_Server;Job;21149.tyrone-cluster;Not sending email: User does not want mail of this type.
04/03/2013 09:43:45;0010;PBS_Server;Job;21149.tyrone-cluster;Exit_status=143 resources_used.cput=441:41:51 resources_used.mem=1428248kb resources_used.vmem=9815016kb resources_used.walltime=24:02:36
04/03/2013 09:43:45;0008;PBS_Server;Job;NULL;on_job_exit valid pjob: 0x2056bf0 (substate=50)
04/03/2013 09:43:45;0008;PBS_Server;Job;NULL;on_job_exit valid pjob: 0x2056bf0 (substate=51)
04/03/2013 09:43:49;0008;PBS_Server;Job;NULL;on_job_exit valid pjob: 0x2056bf0 (substate=51)
04/03/2013 09:43:49;000d;PBS_Server;Job;21149.tyrone-cluster;Post job file processing error; job 21149.tyrone-cluster on host tyrone-node7/31+tyrone-node7/30+tyrone-node7/29+tyrone-node7/28+tyrone-node7/27+tyrone-node7/26+tyrone-node7/25+tyrone-node7/24+tyrone-node7/23+tyrone-node7/22+tyrone-node7/21+tyrone-node7/20+tyrone-node7/19+tyrone-node7/18+tyrone-node7/17+tyrone-node7/16+tyrone-node7/15+tyrone-node7/14+tyrone-node7/13+tyrone-node7/12+tyrone-node7/11+tyrone-node7/10+tyrone-node7/9+tyrone-node7/8+tyrone-node7/7+tyrone-node7/6+tyrone-node7/5+tyrone-node7/4+tyrone-node7/3+tyrone-node7/2+tyrone-node7/1+tyrone-node7/0
04/03/2013 09:43:49;0008;PBS_Server;Job;NULL;on_job_exit valid pjob: 0x2056bf0 (substate=53)
04/03/2013 09:43:49;0100;PBS_Server;Job;21149.tyrone-cluster;dequeuing from qp32, state COMPLETE
04/03/2013 09:43:49;0040;PBS_Server;Svr;tyrone-cluster;Scheduler was sent the command term
04/03/2013 09:43:53;0001;PBS_Server;Svr;PBS_Server;LOG_ERROR::sync_node_jobs, stray job 21344.tyrone-cluster found on tyrone-node8
04/03/2013 09:43:56;0001;PBS_Server;Svr;PBS_Server;LOG_ERROR::sync_node_jobs, stray job 21312.tyrone-cluster found on tyrone-node4
04/03/2013 09:44:13;0001;PBS_Server;Svr;PBS_Server;LOG_ERROR::sync_node_jobs, stray job 21190.tyrone-cluster found on tyrone-node6
04/03/2013 09:44:17;0001;PBS_Server;Svr;PBS_Server;LOG_ERROR::sync_node_jobs, stray job 21306.tyrone-cluster found on tyrone-node5
04/03/2013 09:44:38;0001;PBS_Server;Svr;PBS_Server;LOG_ERROR::sync_node_jobs, stray job 21344.tyrone-cluster found on tyrone-node8
04/03/2013 09:44:41;0001;PBS_Server;Svr;PBS_Server;LOG_ERROR::sync_node_jobs, stray job 21312.tyrone-cluster found on tyrone-node4
04/03/2013 09:44:58;0001;PBS_Server;Svr;PBS_Server;LOG_ERROR::sync_node_jobs, stray job 21190.tyrone-cluster found on tyrone-node6
04/03/2013 09:45:02;0001;PBS_Server;Svr;PBS_Server;LOG_ERROR::sync_node_jobs, stray job 21306.tyrone-cluster found on tyrone-node5
04/03/2013 09:45:23;0001;PBS_Server;Svr;PBS_Server;LOG_ERROR::sync_node_jobs, stray job 21344.tyrone-cluster found on tyrone-node8
04/03/2013 09:45:26;0001;PBS_Server;Svr;PBS_Server;LOG_ERROR::sync_node_jobs, stray job 21312.tyrone-cluster found on tyrone-node4
04/03/2013 09:45:43;0001;PBS_Server;Svr;PBS_Server;LOG_ERROR::sync_node_jobs, stray job 21190.tyrone-cluster found on tyrone-node6
04/03/2013 09:45:47;0001;PBS_Server;Svr;PBS_Server;LOG_ERROR::sync_node_jobs, stray job 21306.tyrone-cluster found on tyrone-node5
04/03/2013 09:46:08;0001;PBS_Server;Svr;PBS_Server;LOG_ERROR::sync_node_jobs, stray job 21344.tyrone-cluster found on tyrone-node8
04/03/2013 09:46:11;0001;PBS_Server;Svr;PBS_Server;LOG_ERROR::sync_node_jobs, stray job 21312.tyrone-cluster found on tyrone-node4
04/03/2013 09:46:29;0001;PBS_Server;Svr;PBS_Server;LOG_ERROR::sync_node_jobs, stray job 21190.tyrone-cluster found on tyrone-node6
04/03/2013 09:46:33;0001;PBS_Server;Svr;PBS_Server;LOG_ERROR::sync_node_jobs, stray job 21306.tyrone-cluster found on tyrone-node5
04/03/2013 09:46:39;000d;PBS_Server;Job;21344.tyrone-cluster;Not sending email: User does not want mail of this type.
04/03/2013 09:46:39;0010;PBS_Server;Job;21344.tyrone-cluster;Exit_status=0 resources_used.cput=00:00:09 resources_used.mem=2968kb resources_used.vmem=217252kb resources_used.walltime=00:05:48
04/03/2013 09:46:39;0008;PBS_Server;Job;NULL;on_job_exit valid pjob: 0x1fa2f10 (substate=50)
04/03/2013 09:46:39;0008;PBS_Server;Job;NULL;on_job_exit valid pjob: 0x1fa2f10 (substate=51)
04/03/2013 09:46:41;0008;PBS_Server;Job;NULL;on_job_exit valid pjob: 0x1fa2f10 (substate=51)
04/03/2013 09:46:41;0008;PBS_Server;Job;NULL;on_job_exit valid pjob: 0x1fa2f10 (substate=53)
04/03/2013 09:46:41;0100;PBS_Server;Job;21344.tyrone-cluster;dequeuing from qp32, state COMPLETE
04/03/2013 09:46:41;0040;PBS_Server;Svr;tyrone-cluster;Scheduler was sent the command term
04/03/2013 09:46:56;0001;PBS_Server;Svr;PBS_Server;LOG_ERROR::sync_node_jobs, stray job 21312.tyrone-cluster found on tyrone-node4
04/03/2013 09:47:13;0001;PBS_Server;Svr;PBS_Server;LOG_ERROR::sync_node_jobs, stray job 21190.tyrone-cluster found on tyrone-node6
04/03/2013 09:47:17;0001;PBS_Server;Svr;PBS_Server;LOG_ERROR::sync_node_jobs, stray job 21306.tyrone-cluster found on tyrone-node5
04/03/2013 09:47:41;0001;PBS_Server;Svr;PBS_Server;LOG_ERROR::sync_node_jobs, stray job 21312.tyrone-cluster found on tyrone-node4
04/03/2013 09:47:58;0001;PBS_Server;Svr;PBS_Server;LOG_ERROR::sync_node_jobs, stray job 21190.tyrone-cluster found on tyrone-node6
04/03/2013 09:48:02;0001;PBS_Server;Svr;PBS_Server;LOG_ERROR::sync_node_jobs, stray job 21306.tyrone-cluster found on tyrone-node5
04/03/2013 09:48:26;0001;PBS_Server;Svr;PBS_Server;LOG_ERROR::sync_node_jobs, stray job 21312.tyrone-cluster found on tyrone-node4
04/03/2013 09:48:30;0002;PBS_Server;Svr;PBS_Server;Torque Server Version = 3.0.5, loglevel = 0
04/03/2013 09:48:43;0001;PBS_Server;Svr;PBS_Server;LOG_ERROR::sync_node_jobs, stray job 21190.tyrone-cluster found on tyrone-node6
04/03/2013 09:48:47;0001;PBS_Server;Svr;PBS_Server;LOG_ERROR::sync_node_jobs, stray job 21306.tyrone-cluster found on tyrone-node5
04/03/2013 09:49:11;0001;PBS_Server;Svr;PBS_Server;LOG_ERROR::sync_node_jobs, stray job 21312.tyrone-cluster found on tyrone-node4
04/03/2013 09:49:28;0001;PBS_Server;Svr;PBS_Server;LOG_ERROR::sync_node_jobs, stray job 21190.tyrone-cluster found on tyrone-node6
04/03/2013 09:49:32;0001;PBS_Server;Svr;PBS_Server;LOG_ERROR::sync_node_jobs, stray job 21306.tyrone-cluster found on tyrone-node5
04/03/2013 09:49:56;0001;PBS_Server;Svr;PBS_Server;LOG_ERROR::sync_node_jobs, stray job 21312.tyrone-cluster found on tyrone-node4
04/03/2013 09:50:13;0001;PBS_Server;Svr;PBS_Server;LOG_ERROR::sync_node_jobs, stray job 21190.tyrone-cluster found on tyrone-node6
04/03/2013 09:50:17;0001;PBS_Server;Svr;PBS_Server;LOG_ERROR::sync_node_jobs, stray job 21306.tyrone-cluster found on tyrone-node5
04/03/2013 09:50:23;0100;PBS_Server;Job;21345.tyrone-cluster;enqueuing into batch, state 1 hop 1
04/03/2013 09:50:23;0100;PBS_Server;Job;21345.tyrone-cluster;dequeuing from batch, state QUEUED
04/03/2013 09:50:23;0100;PBS_Server;Job;21345.tyrone-cluster;enqueuing into qp64, state 1 hop 1
04/03/2013 09:50:23;0008;PBS_Server;Job;21345.tyrone-cluster;Job Queued at request of ipcdskp@tyrone-cluster, owner = ipcdskp@tyrone-cluster, job name = n1, queue = qp64
04/03/2013 09:50:23;0040;PBS_Server;Svr;tyrone-cluster;Scheduler was sent the command new
04/03/2013 09:50:23;0008;PBS_Server;Job;21345.tyrone-cluster;Job Modified at request of Scheduler@tyrone-cluster
04/03/2013 09:50:23;0008;PBS_Server;Job;21345.tyrone-cluster;Job Run at request of Scheduler@tyrone-cluster
04/03/2013 09:50:23;0040;PBS_Server;Svr;tyrone-cluster;Scheduler was sent the command recyc
04/03/2013 09:50:23;000d;PBS_Server;Job;21345.tyrone-cluster;Not sending email: User does not want mail of this type.
04/03/2013 09:50:41;0001;PBS_Server;Svr;PBS_Server;LOG_ERROR::sync_node_jobs, stray job 21312.tyrone-cluster found on tyrone-node4
04/03/2013 09:50:58;0001;PBS_Server;Svr;PBS_Server;LOG_ERROR::sync_node_jobs, stray job 21190.tyrone-cluster found on tyrone-node6
04/03/2013 09:51:02;0001;PBS_Server;Svr;PBS_Server;LOG_ERROR::sync_node_jobs, stray job 21306.tyrone-cluster found on tyrone-node5
04/03/2013 09:51:26;0001;PBS_Server;Svr;PBS_Server;LOG_ERROR::sync_node_jobs, stray job 21312.tyrone-cluster found on tyrone-node4
04/03/2013 09:51:43;0001;PBS_Server;Svr;PBS_Server;LOG_ERROR::sync_node_jobs, stray job 21190.tyrone-cluster found on tyrone-node6
04/03/2013 09:51:47;0001;PBS_Server;Svr;PBS_Server;LOG_ERROR::sync_node_jobs, stray job 21306.tyrone-cluster found on tyrone-node5
04/03/2013 09:52:11;0001;PBS_Server;Svr;PBS_Server;LOG_ERROR::sync_node_jobs, stray job 21312.tyrone-cluster found on tyrone-node4
04/03/2013 09:52:28;0001;PBS_Server;Svr;PBS_Server;LOG_ERROR::sync_node_jobs, stray job 21190.tyrone-cluster found on tyrone-node6
04/03/2013 09:52:32;0001;PBS_Server;Svr;PBS_Server;LOG_ERROR::sync_node_jobs, stray job 21306.tyrone-cluster found on tyrone-node5
04/03/2013 09:52:56;0001;PBS_Server;Svr;PBS_Server;LOG_ERROR::sync_node_jobs, stray job 21312.tyrone-cluster found on tyrone-node4
04/03/2013 09:53:13;0001;PBS_Server;Svr;PBS_Server;LOG_ERROR::sync_node_jobs, stray job 21190.tyrone-cluster found on tyrone-node6
04/03/2013 09:53:17;0001;PBS_Server;Svr;PBS_Server;LOG_ERROR::sync_node_jobs, stray job 21306.tyrone-cluster found on tyrone-node5
04/03/2013 09:53:30;0002;PBS_Server;Svr;PBS_Server;Torque Server Version = 3.0.5, loglevel = 0
