03/26/2013 00:03:29;0002;PBS_Server;Svr;Log;Log opened
03/26/2013 00:03:29;0002;PBS_Server;Svr;PBS_Server;Torque Server Version = 3.0.5, loglevel = 0
03/26/2013 00:07:10;0040;PBS_Server;Svr;tyrone-cluster;Scheduler was sent the command time
03/26/2013 00:08:29;0002;PBS_Server;Svr;PBS_Server;Torque Server Version = 3.0.5, loglevel = 0
03/26/2013 00:13:29;0002;PBS_Server;Svr;PBS_Server;Torque Server Version = 3.0.5, loglevel = 0
03/26/2013 00:17:10;0040;PBS_Server;Svr;tyrone-cluster;Scheduler was sent the command time
03/26/2013 00:18:29;0002;PBS_Server;Svr;PBS_Server;Torque Server Version = 3.0.5, loglevel = 0
03/26/2013 00:23:29;0002;PBS_Server;Svr;PBS_Server;Torque Server Version = 3.0.5, loglevel = 0
03/26/2013 00:24:39;000d;PBS_Server;Job;20432.tyrone-cluster;Not sending email: User does not want mail of this type.
03/26/2013 00:24:39;0002;PBS_Server;Svr;Act;Account file /var/spool/torque/server_priv/accounting/20130326 opened
03/26/2013 00:24:39;0010;PBS_Server;Job;20432.tyrone-cluster;Exit_status=1 resources_used.cput=90:33:16 resources_used.mem=2011376kb resources_used.vmem=8191228kb resources_used.walltime=02:58:57
03/26/2013 00:24:39;0008;PBS_Server;Job;NULL;on_job_exit valid pjob: 0x2e39a70 (substate=50)
03/26/2013 00:24:39;0008;PBS_Server;Job;NULL;on_job_exit valid pjob: 0x2e39a70 (substate=51)
03/26/2013 00:24:39;0008;PBS_Server;Job;NULL;on_job_exit valid pjob: 0x2e39a70 (substate=51)
03/26/2013 00:24:39;0008;PBS_Server;Job;NULL;on_job_exit valid pjob: 0x2e39a70 (substate=53)
03/26/2013 00:24:39;0100;PBS_Server;Job;20432.tyrone-cluster;dequeuing from qp32, state COMPLETE
03/26/2013 00:24:39;0040;PBS_Server;Svr;tyrone-cluster;Scheduler was sent the command term
03/26/2013 00:28:29;0002;PBS_Server;Svr;PBS_Server;Torque Server Version = 3.0.5, loglevel = 0
03/26/2013 00:33:29;0002;PBS_Server;Svr;PBS_Server;Torque Server Version = 3.0.5, loglevel = 0
03/26/2013 00:34:39;0040;PBS_Server;Svr;tyrone-cluster;Scheduler was sent the command time
03/26/2013 00:38:29;0002;PBS_Server;Svr;PBS_Server;Torque Server Version = 3.0.5, loglevel = 0
03/26/2013 00:43:29;0002;PBS_Server;Svr;PBS_Server;Torque Server Version = 3.0.5, loglevel = 0
03/26/2013 00:44:39;0040;PBS_Server;Svr;tyrone-cluster;Scheduler was sent the command time
03/26/2013 00:48:29;0002;PBS_Server;Svr;PBS_Server;Torque Server Version = 3.0.5, loglevel = 0
03/26/2013 00:53:29;0002;PBS_Server;Svr;PBS_Server;Torque Server Version = 3.0.5, loglevel = 0
03/26/2013 00:54:39;0040;PBS_Server;Svr;tyrone-cluster;Scheduler was sent the command time
03/26/2013 00:58:29;0002;PBS_Server;Svr;PBS_Server;Torque Server Version = 3.0.5, loglevel = 0
03/26/2013 01:03:29;0002;PBS_Server;Svr;PBS_Server;Torque Server Version = 3.0.5, loglevel = 0
03/26/2013 01:04:39;0040;PBS_Server;Svr;tyrone-cluster;Scheduler was sent the command time
03/26/2013 01:08:29;0002;PBS_Server;Svr;PBS_Server;Torque Server Version = 3.0.5, loglevel = 0
03/26/2013 01:09:33;000d;PBS_Server;Job;20367.tyrone-cluster;Not sending email: User does not want mail of this type.
03/26/2013 01:09:33;0010;PBS_Server;Job;20367.tyrone-cluster;Exit_status=0 resources_used.cput=712:01:30 resources_used.mem=2138920kb resources_used.vmem=35903520kb resources_used.walltime=11:08:58
03/26/2013 01:09:33;0008;PBS_Server;Job;NULL;on_job_exit valid pjob: 0x2e37f20 (substate=50)
03/26/2013 01:09:33;0008;PBS_Server;Job;NULL;on_job_exit valid pjob: 0x2e37f20 (substate=51)
03/26/2013 01:09:33;0008;PBS_Server;Job;NULL;on_job_exit valid pjob: 0x2e37f20 (substate=51)
03/26/2013 01:09:33;0008;PBS_Server;Job;NULL;on_job_exit valid pjob: 0x2e37f20 (substate=53)
03/26/2013 01:09:33;0100;PBS_Server;Job;20367.tyrone-cluster;dequeuing from qp64, state COMPLETE
03/26/2013 01:09:33;0040;PBS_Server;Svr;tyrone-cluster;Scheduler was sent the command term
03/26/2013 01:09:33;0008;PBS_Server;Job;20417.tyrone-cluster;Job Modified at request of Scheduler@tyrone-cluster
03/26/2013 01:09:33;0008;PBS_Server;Job;20417.tyrone-cluster;Job Run at request of Scheduler@tyrone-cluster
03/26/2013 01:09:34;0040;PBS_Server;Svr;tyrone-cluster;Scheduler was sent the command recyc
03/26/2013 01:09:34;000d;PBS_Server;Job;20417.tyrone-cluster;Not sending email: User does not want mail of this type.
03/26/2013 01:13:29;0002;PBS_Server;Svr;PBS_Server;Torque Server Version = 3.0.5, loglevel = 0
03/26/2013 01:18:29;0002;PBS_Server;Svr;PBS_Server;Torque Server Version = 3.0.5, loglevel = 0
03/26/2013 01:19:34;0040;PBS_Server;Svr;tyrone-cluster;Scheduler was sent the command time
03/26/2013 01:23:29;0002;PBS_Server;Svr;PBS_Server;Torque Server Version = 3.0.5, loglevel = 0
03/26/2013 01:28:29;0002;PBS_Server;Svr;PBS_Server;Torque Server Version = 3.0.5, loglevel = 0
03/26/2013 01:29:34;0040;PBS_Server;Svr;tyrone-cluster;Scheduler was sent the command time
03/26/2013 01:29:54;000d;PBS_Server;Job;20431.tyrone-cluster;Not sending email: User does not want mail of this type.
03/26/2013 01:29:54;0010;PBS_Server;Job;20431.tyrone-cluster;Exit_status=0 resources_used.cput=130:54:11 resources_used.mem=1497688kb resources_used.vmem=5200348kb resources_used.walltime=04:06:31
03/26/2013 01:29:54;0008;PBS_Server;Job;NULL;on_job_exit valid pjob: 0x2e5e0f0 (substate=50)
03/26/2013 01:29:54;0008;PBS_Server;Job;NULL;on_job_exit valid pjob: 0x2e5e0f0 (substate=51)
03/26/2013 01:29:54;0008;PBS_Server;Job;NULL;on_job_exit valid pjob: 0x2e5e0f0 (substate=51)
03/26/2013 01:29:54;0008;PBS_Server;Job;NULL;on_job_exit valid pjob: 0x2e5e0f0 (substate=53)
03/26/2013 01:29:54;0100;PBS_Server;Job;20431.tyrone-cluster;dequeuing from qp32, state COMPLETE
03/26/2013 01:29:54;0040;PBS_Server;Svr;tyrone-cluster;Scheduler was sent the command term
03/26/2013 01:33:29;0002;PBS_Server;Svr;PBS_Server;Torque Server Version = 3.0.5, loglevel = 0
03/26/2013 01:35:49;000d;PBS_Server;Job;20433.tyrone-cluster;Not sending email: User does not want mail of this type.
03/26/2013 01:35:49;0010;PBS_Server;Job;20433.tyrone-cluster;Exit_status=0 resources_used.cput=32:25:58 resources_used.mem=959672kb resources_used.vmem=1690756kb resources_used.walltime=04:03:47
03/26/2013 01:35:49;0008;PBS_Server;Job;NULL;on_job_exit valid pjob: 0x2e3bf70 (substate=50)
03/26/2013 01:35:49;0008;PBS_Server;Job;NULL;on_job_exit valid pjob: 0x2e3bf70 (substate=51)
03/26/2013 01:35:49;0008;PBS_Server;Job;NULL;on_job_exit valid pjob: 0x2e3bf70 (substate=51)
03/26/2013 01:35:49;0008;PBS_Server;Job;NULL;on_job_exit valid pjob: 0x2e3bf70 (substate=53)
03/26/2013 01:35:49;0100;PBS_Server;Job;20433.tyrone-cluster;dequeuing from qp32, state COMPLETE
03/26/2013 01:35:49;0040;PBS_Server;Svr;tyrone-cluster;Scheduler was sent the command term
03/26/2013 01:38:29;0002;PBS_Server;Svr;PBS_Server;Torque Server Version = 3.0.5, loglevel = 0
03/26/2013 01:43:29;0002;PBS_Server;Svr;PBS_Server;Torque Server Version = 3.0.5, loglevel = 0
03/26/2013 01:45:49;0040;PBS_Server;Svr;tyrone-cluster;Scheduler was sent the command time
03/26/2013 01:48:29;0002;PBS_Server;Svr;PBS_Server;Torque Server Version = 3.0.5, loglevel = 0
03/26/2013 01:53:29;0002;PBS_Server;Svr;PBS_Server;Torque Server Version = 3.0.5, loglevel = 0
03/26/2013 01:55:08;000d;PBS_Server;Job;20417.tyrone-cluster;Not sending email: User does not want mail of this type.
03/26/2013 01:55:08;0010;PBS_Server;Job;20417.tyrone-cluster;Exit_status=0 resources_used.cput=48:04:56 resources_used.mem=4344320kb resources_used.vmem=41297840kb resources_used.walltime=00:45:35
03/26/2013 01:55:08;0008;PBS_Server;Job;NULL;on_job_exit valid pjob: 0x2e64c40 (substate=50)
03/26/2013 01:55:08;0008;PBS_Server;Job;NULL;on_job_exit valid pjob: 0x2e64c40 (substate=51)
03/26/2013 01:55:08;0008;PBS_Server;Job;NULL;on_job_exit valid pjob: 0x2e64c40 (substate=51)
03/26/2013 01:55:08;0008;PBS_Server;Job;NULL;on_job_exit valid pjob: 0x2e64c40 (substate=53)
03/26/2013 01:55:08;0100;PBS_Server;Job;20417.tyrone-cluster;dequeuing from qp64, state COMPLETE
03/26/2013 01:55:08;0040;PBS_Server;Svr;tyrone-cluster;Scheduler was sent the command term
03/26/2013 01:55:08;0008;PBS_Server;Job;20418.tyrone-cluster;Job Modified at request of Scheduler@tyrone-cluster
03/26/2013 01:55:08;0008;PBS_Server;Job;20418.tyrone-cluster;Job Run at request of Scheduler@tyrone-cluster
03/26/2013 01:55:08;0040;PBS_Server;Svr;tyrone-cluster;Scheduler was sent the command recyc
03/26/2013 01:55:08;000d;PBS_Server;Job;20418.tyrone-cluster;Not sending email: User does not want mail of this type.
03/26/2013 01:57:07;000d;PBS_Server;Job;20427.tyrone-cluster;Not sending email: User does not want mail of this type.
03/26/2013 01:57:07;0010;PBS_Server;Job;20427.tyrone-cluster;Exit_status=0 resources_used.cput=199:51:52 resources_used.mem=1653972kb resources_used.vmem=8190528kb resources_used.walltime=06:50:28
03/26/2013 01:57:07;0008;PBS_Server;Job;NULL;on_job_exit valid pjob: 0x2ec13f0 (substate=50)
03/26/2013 01:57:07;0008;PBS_Server;Job;NULL;on_job_exit valid pjob: 0x2ec13f0 (substate=51)
03/26/2013 01:57:07;0008;PBS_Server;Job;NULL;on_job_exit valid pjob: 0x2ec13f0 (substate=51)
03/26/2013 01:57:07;0008;PBS_Server;Job;NULL;on_job_exit valid pjob: 0x2ec13f0 (substate=53)
03/26/2013 01:57:07;0100;PBS_Server;Job;20427.tyrone-cluster;dequeuing from qp32, state COMPLETE
03/26/2013 01:57:07;0040;PBS_Server;Svr;tyrone-cluster;Scheduler was sent the command term
03/26/2013 01:58:29;0002;PBS_Server;Svr;PBS_Server;Torque Server Version = 3.0.5, loglevel = 0
03/26/2013 02:03:29;0002;PBS_Server;Svr;PBS_Server;Torque Server Version = 3.0.5, loglevel = 0
03/26/2013 02:07:07;0040;PBS_Server;Svr;tyrone-cluster;Scheduler was sent the command time
03/26/2013 02:08:29;0002;PBS_Server;Svr;PBS_Server;Torque Server Version = 3.0.5, loglevel = 0
03/26/2013 02:13:29;0002;PBS_Server;Svr;PBS_Server;Torque Server Version = 3.0.5, loglevel = 0
03/26/2013 02:17:07;0040;PBS_Server;Svr;tyrone-cluster;Scheduler was sent the command time
03/26/2013 02:18:29;0002;PBS_Server;Svr;PBS_Server;Torque Server Version = 3.0.5, loglevel = 0
03/26/2013 02:23:29;0002;PBS_Server;Svr;PBS_Server;Torque Server Version = 3.0.5, loglevel = 0
03/26/2013 02:27:07;0040;PBS_Server;Svr;tyrone-cluster;Scheduler was sent the command time
03/26/2013 02:28:29;0002;PBS_Server;Svr;PBS_Server;Torque Server Version = 3.0.5, loglevel = 0
03/26/2013 02:29:55;000d;PBS_Server;Job;20422.tyrone-cluster;Not sending email: User does not want mail of this type.
03/26/2013 02:29:55;0010;PBS_Server;Job;20422.tyrone-cluster;Exit_status=255 resources_used.cput=293:16:41 resources_used.mem=2301168kb resources_used.vmem=36060844kb resources_used.walltime=04:35:11
03/26/2013 02:29:55;0008;PBS_Server;Job;NULL;on_job_exit valid pjob: 0x2f5fd20 (substate=50)
03/26/2013 02:29:55;0008;PBS_Server;Job;NULL;on_job_exit valid pjob: 0x2f5fd20 (substate=51)
03/26/2013 02:30:00;0008;PBS_Server;Job;NULL;on_job_exit valid pjob: 0x2f5fd20 (substate=51)
03/26/2013 02:30:00;000d;PBS_Server;Job;20422.tyrone-cluster;Post job file processing error; job 20422.tyrone-cluster on host tyrone-node14/63+tyrone-node14/62+tyrone-node14/61+tyrone-node14/60+tyrone-node14/59+tyrone-node14/58+tyrone-node14/57+tyrone-node14/56+tyrone-node14/55+tyrone-node14/54+tyrone-node14/53+tyrone-node14/52+tyrone-node14/51+tyrone-node14/50+tyrone-node14/49+tyrone-node14/48+tyrone-node14/47+tyrone-node14/46+tyrone-node14/45+tyrone-node14/44+tyrone-node14/43+tyrone-node14/42+tyrone-node14/41+tyrone-node14/40+tyrone-node14/39+tyrone-node14/38+tyrone-node14/37+tyrone-node14/36+tyrone-node14/35+tyrone-node14/34+tyrone-node14/33+tyrone-node14/32+tyrone-node14/31+tyrone-node14/30+tyrone-node14/29+tyrone-node14/28+tyrone-node14/27+tyrone-node14/26+tyrone-node14/25+tyrone-node14/24+tyrone-node14/23+tyrone-node14/22+tyrone-node14/21+tyrone-node14/20+tyrone-node14/19+tyrone-node14/18+tyrone-node14/17+tyrone-node14/16+tyrone-node14/15+tyrone-node14/14+tyrone-node14/13+tyrone-node14/12+tyrone-node14/11+tyrone-node14/10+tyrone-node14/9+tyrone-node14/8+tyrone-node14/7+tyrone-node14/6+tyrone-node14/5+tyrone-node14/4+tyrone-node14/3+tyrone-node14/2+tyrone-node14/1+tyrone-node14/0
03/26/2013 02:30:00;0008;PBS_Server;Job;NULL;on_job_exit valid pjob: 0x2f5fd20 (substate=53)
03/26/2013 02:30:00;0100;PBS_Server;Job;20422.tyrone-cluster;dequeuing from qp64, state COMPLETE
03/26/2013 02:30:00;0040;PBS_Server;Svr;tyrone-cluster;Scheduler was sent the command term
03/26/2013 02:30:00;0008;PBS_Server;Job;20430.tyrone-cluster;Job Modified at request of Scheduler@tyrone-cluster
03/26/2013 02:30:00;0008;PBS_Server;Job;20430.tyrone-cluster;Job Run at request of Scheduler@tyrone-cluster
03/26/2013 02:30:00;0040;PBS_Server;Svr;tyrone-cluster;Scheduler was sent the command recyc
03/26/2013 02:30:00;000d;PBS_Server;Job;20430.tyrone-cluster;Not sending email: User does not want mail of this type.
03/26/2013 02:32:15;000d;PBS_Server;Job;20430.tyrone-cluster;Not sending email: User does not want mail of this type.
03/26/2013 02:32:15;0010;PBS_Server;Job;20430.tyrone-cluster;Exit_status=0 resources_used.cput=02:18:16 resources_used.mem=6548504kb resources_used.vmem=40456564kb resources_used.walltime=00:02:16
03/26/2013 02:32:15;0008;PBS_Server;Job;NULL;on_job_exit valid pjob: 0x2f6d060 (substate=50)
03/26/2013 02:32:15;0008;PBS_Server;Job;NULL;on_job_exit valid pjob: 0x2f6d060 (substate=51)
03/26/2013 02:32:15;0008;PBS_Server;Job;NULL;on_job_exit valid pjob: 0x2f6d060 (substate=51)
03/26/2013 02:32:15;0008;PBS_Server;Job;NULL;on_job_exit valid pjob: 0x2f6d060 (substate=53)
03/26/2013 02:32:15;0100;PBS_Server;Job;20430.tyrone-cluster;dequeuing from qp64, state COMPLETE
03/26/2013 02:32:15;0040;PBS_Server;Svr;tyrone-cluster;Scheduler was sent the command term
03/26/2013 02:32:15;0008;PBS_Server;Job;20442.tyrone-cluster;Job Modified at request of Scheduler@tyrone-cluster
03/26/2013 02:32:15;0008;PBS_Server;Job;20442.tyrone-cluster;Job Run at request of Scheduler@tyrone-cluster
03/26/2013 02:32:15;0040;PBS_Server;Svr;tyrone-cluster;Scheduler was sent the command recyc
03/26/2013 02:32:15;000d;PBS_Server;Job;20442.tyrone-cluster;Not sending email: User does not want mail of this type.
03/26/2013 02:33:29;0002;PBS_Server;Svr;PBS_Server;Torque Server Version = 3.0.5, loglevel = 0
03/26/2013 02:38:29;0002;PBS_Server;Svr;PBS_Server;Torque Server Version = 3.0.5, loglevel = 0
03/26/2013 02:42:15;0040;PBS_Server;Svr;tyrone-cluster;Scheduler was sent the command time
03/26/2013 02:43:29;0002;PBS_Server;Svr;PBS_Server;Torque Server Version = 3.0.5, loglevel = 0
03/26/2013 02:48:29;0002;PBS_Server;Svr;PBS_Server;Torque Server Version = 3.0.5, loglevel = 0
03/26/2013 02:52:15;0040;PBS_Server;Svr;tyrone-cluster;Scheduler was sent the command time
03/26/2013 02:53:29;0002;PBS_Server;Svr;PBS_Server;Torque Server Version = 3.0.5, loglevel = 0
03/26/2013 02:58:29;0002;PBS_Server;Svr;PBS_Server;Torque Server Version = 3.0.5, loglevel = 0
03/26/2013 03:02:15;0040;PBS_Server;Svr;tyrone-cluster;Scheduler was sent the command time
03/26/2013 03:03:29;0002;PBS_Server;Svr;PBS_Server;Torque Server Version = 3.0.5, loglevel = 0
03/26/2013 03:08:29;0002;PBS_Server;Svr;PBS_Server;Torque Server Version = 3.0.5, loglevel = 0
03/26/2013 03:12:15;0040;PBS_Server;Svr;tyrone-cluster;Scheduler was sent the command time
03/26/2013 03:13:29;0002;PBS_Server;Svr;PBS_Server;Torque Server Version = 3.0.5, loglevel = 0
03/26/2013 03:18:29;0002;PBS_Server;Svr;PBS_Server;Torque Server Version = 3.0.5, loglevel = 0
03/26/2013 03:22:15;0040;PBS_Server;Svr;tyrone-cluster;Scheduler was sent the command time
03/26/2013 03:23:29;0002;PBS_Server;Svr;PBS_Server;Torque Server Version = 3.0.5, loglevel = 0
03/26/2013 03:26:42;000d;PBS_Server;Job;20418.tyrone-cluster;Not sending email: User does not want mail of this type.
03/26/2013 03:26:42;0010;PBS_Server;Job;20418.tyrone-cluster;Exit_status=0 resources_used.cput=96:50:36 resources_used.mem=4895700kb resources_used.vmem=41850688kb resources_used.walltime=01:31:34
03/26/2013 03:26:42;0008;PBS_Server;Job;NULL;on_job_exit valid pjob: 0x2e75510 (substate=50)
03/26/2013 03:26:42;0008;PBS_Server;Job;NULL;on_job_exit valid pjob: 0x2e75510 (substate=51)
03/26/2013 03:26:42;0008;PBS_Server;Job;NULL;on_job_exit valid pjob: 0x2e75510 (substate=51)
03/26/2013 03:26:42;0008;PBS_Server;Job;NULL;on_job_exit valid pjob: 0x2e75510 (substate=53)
03/26/2013 03:26:42;0100;PBS_Server;Job;20418.tyrone-cluster;dequeuing from qp64, state COMPLETE
03/26/2013 03:26:42;0040;PBS_Server;Svr;tyrone-cluster;Scheduler was sent the command term
03/26/2013 03:26:42;0008;PBS_Server;Job;20443.tyrone-cluster;Job Modified at request of Scheduler@tyrone-cluster
03/26/2013 03:26:42;0008;PBS_Server;Job;20443.tyrone-cluster;Job Run at request of Scheduler@tyrone-cluster
03/26/2013 03:26:42;0040;PBS_Server;Svr;tyrone-cluster;Scheduler was sent the command recyc
03/26/2013 03:26:42;000d;PBS_Server;Job;20443.tyrone-cluster;Not sending email: User does not want mail of this type.
03/26/2013 03:28:29;0002;PBS_Server;Svr;PBS_Server;Torque Server Version = 3.0.5, loglevel = 0
03/26/2013 03:29:58;000d;PBS_Server;Job;20363.tyrone-cluster;Not sending email: User does not want mail of this type.
03/26/2013 03:29:58;0010;PBS_Server;Job;20363.tyrone-cluster;Exit_status=1 resources_used.cput=989:57:26 resources_used.mem=3218356kb resources_used.vmem=10551144kb resources_used.walltime=17:22:05
03/26/2013 03:29:58;0008;PBS_Server;Job;NULL;on_job_exit valid pjob: 0x2e413e0 (substate=50)
03/26/2013 03:29:58;0008;PBS_Server;Job;NULL;on_job_exit valid pjob: 0x2e413e0 (substate=51)
03/26/2013 03:29:59;0008;PBS_Server;Job;NULL;on_job_exit valid pjob: 0x2e413e0 (substate=51)
03/26/2013 03:29:59;0008;PBS_Server;Job;NULL;on_job_exit valid pjob: 0x2e413e0 (substate=53)
03/26/2013 03:29:59;0100;PBS_Server;Job;20363.tyrone-cluster;dequeuing from qp64, state COMPLETE
03/26/2013 03:29:59;0040;PBS_Server;Svr;tyrone-cluster;Scheduler was sent the command term
03/26/2013 03:33:29;0002;PBS_Server;Svr;PBS_Server;Torque Server Version = 3.0.5, loglevel = 0
03/26/2013 03:38:29;0002;PBS_Server;Svr;PBS_Server;Torque Server Version = 3.0.5, loglevel = 0
03/26/2013 03:39:59;0040;PBS_Server;Svr;tyrone-cluster;Scheduler was sent the command time
03/26/2013 03:43:29;0002;PBS_Server;Svr;PBS_Server;Torque Server Version = 3.0.5, loglevel = 0
03/26/2013 03:48:29;0002;PBS_Server;Svr;PBS_Server;Torque Server Version = 3.0.5, loglevel = 0
03/26/2013 03:49:59;0040;PBS_Server;Svr;tyrone-cluster;Scheduler was sent the command time
03/26/2013 03:53:29;0002;PBS_Server;Svr;PBS_Server;Torque Server Version = 3.0.5, loglevel = 0
03/26/2013 03:58:29;0002;PBS_Server;Svr;PBS_Server;Torque Server Version = 3.0.5, loglevel = 0
03/26/2013 03:59:59;0040;PBS_Server;Svr;tyrone-cluster;Scheduler was sent the command time
03/26/2013 04:00:08;000d;PBS_Server;Job;20436.tyrone-cluster;Not sending email: User does not want mail of this type.
03/26/2013 04:00:08;0010;PBS_Server;Job;20436.tyrone-cluster;Exit_status=0 resources_used.cput=180:33:03 resources_used.mem=4385204kb resources_used.vmem=8233388kb resources_used.walltime=06:08:10
03/26/2013 04:00:08;0008;PBS_Server;Job;NULL;on_job_exit valid pjob: 0x2e6b4e0 (substate=50)
03/26/2013 04:00:08;0008;PBS_Server;Job;NULL;on_job_exit valid pjob: 0x2e6b4e0 (substate=51)
03/26/2013 04:00:08;0008;PBS_Server;Job;NULL;on_job_exit valid pjob: 0x2e6b4e0 (substate=51)
03/26/2013 04:00:08;0008;PBS_Server;Job;NULL;on_job_exit valid pjob: 0x2e6b4e0 (substate=53)
03/26/2013 04:00:08;0100;PBS_Server;Job;20436.tyrone-cluster;dequeuing from qp32, state COMPLETE
03/26/2013 04:00:08;0040;PBS_Server;Svr;tyrone-cluster;Scheduler was sent the command term
03/26/2013 04:03:29;0002;PBS_Server;Svr;PBS_Server;Torque Server Version = 3.0.5, loglevel = 0
03/26/2013 04:08:29;0002;PBS_Server;Svr;PBS_Server;Torque Server Version = 3.0.5, loglevel = 0
03/26/2013 04:10:08;0040;PBS_Server;Svr;tyrone-cluster;Scheduler was sent the command time
03/26/2013 04:13:29;0002;PBS_Server;Svr;PBS_Server;Torque Server Version = 3.0.5, loglevel = 0
03/26/2013 04:18:29;0002;PBS_Server;Svr;PBS_Server;Torque Server Version = 3.0.5, loglevel = 0
03/26/2013 04:20:08;0040;PBS_Server;Svr;tyrone-cluster;Scheduler was sent the command time
03/26/2013 04:23:29;0002;PBS_Server;Svr;PBS_Server;Torque Server Version = 3.0.5, loglevel = 0
03/26/2013 04:28:29;0002;PBS_Server;Svr;PBS_Server;Torque Server Version = 3.0.5, loglevel = 0
03/26/2013 04:30:08;0040;PBS_Server;Svr;tyrone-cluster;Scheduler was sent the command time
03/26/2013 04:33:29;0002;PBS_Server;Svr;PBS_Server;Torque Server Version = 3.0.5, loglevel = 0
03/26/2013 04:38:29;0002;PBS_Server;Svr;PBS_Server;Torque Server Version = 3.0.5, loglevel = 0
03/26/2013 04:40:08;0040;PBS_Server;Svr;tyrone-cluster;Scheduler was sent the command time
03/26/2013 04:43:29;0002;PBS_Server;Svr;PBS_Server;Torque Server Version = 3.0.5, loglevel = 0
03/26/2013 04:48:29;0002;PBS_Server;Svr;PBS_Server;Torque Server Version = 3.0.5, loglevel = 0
03/26/2013 04:50:08;0040;PBS_Server;Svr;tyrone-cluster;Scheduler was sent the command time
03/26/2013 04:53:29;0002;PBS_Server;Svr;PBS_Server;Torque Server Version = 3.0.5, loglevel = 0
03/26/2013 04:58:29;0002;PBS_Server;Svr;PBS_Server;Torque Server Version = 3.0.5, loglevel = 0
03/26/2013 05:00:08;0040;PBS_Server;Svr;tyrone-cluster;Scheduler was sent the command time
03/26/2013 05:03:29;0002;PBS_Server;Svr;PBS_Server;Torque Server Version = 3.0.5, loglevel = 0
03/26/2013 05:08:29;0002;PBS_Server;Svr;PBS_Server;Torque Server Version = 3.0.5, loglevel = 0
03/26/2013 05:10:08;0040;PBS_Server;Svr;tyrone-cluster;Scheduler was sent the command time
03/26/2013 05:13:29;0002;PBS_Server;Svr;PBS_Server;Torque Server Version = 3.0.5, loglevel = 0
03/26/2013 05:18:29;0002;PBS_Server;Svr;PBS_Server;Torque Server Version = 3.0.5, loglevel = 0
03/26/2013 05:20:08;0040;PBS_Server;Svr;tyrone-cluster;Scheduler was sent the command time
03/26/2013 05:23:29;0002;PBS_Server;Svr;PBS_Server;Torque Server Version = 3.0.5, loglevel = 0
03/26/2013 05:28:29;0002;PBS_Server;Svr;PBS_Server;Torque Server Version = 3.0.5, loglevel = 0
03/26/2013 05:30:08;0040;PBS_Server;Svr;tyrone-cluster;Scheduler was sent the command time
03/26/2013 05:33:29;0002;PBS_Server;Svr;PBS_Server;Torque Server Version = 3.0.5, loglevel = 0
03/26/2013 05:38:29;0002;PBS_Server;Svr;PBS_Server;Torque Server Version = 3.0.5, loglevel = 0
03/26/2013 05:40:08;0040;PBS_Server;Svr;tyrone-cluster;Scheduler was sent the command time
03/26/2013 05:43:29;0002;PBS_Server;Svr;PBS_Server;Torque Server Version = 3.0.5, loglevel = 0
03/26/2013 05:48:29;0002;PBS_Server;Svr;PBS_Server;Torque Server Version = 3.0.5, loglevel = 0
03/26/2013 05:50:08;0040;PBS_Server;Svr;tyrone-cluster;Scheduler was sent the command time
03/26/2013 05:53:29;0002;PBS_Server;Svr;PBS_Server;Torque Server Version = 3.0.5, loglevel = 0
03/26/2013 05:58:29;0002;PBS_Server;Svr;PBS_Server;Torque Server Version = 3.0.5, loglevel = 0
03/26/2013 06:00:08;0040;PBS_Server;Svr;tyrone-cluster;Scheduler was sent the command time
03/26/2013 06:03:29;0002;PBS_Server;Svr;PBS_Server;Torque Server Version = 3.0.5, loglevel = 0
03/26/2013 06:08:29;0002;PBS_Server;Svr;PBS_Server;Torque Server Version = 3.0.5, loglevel = 0
03/26/2013 06:10:08;0040;PBS_Server;Svr;tyrone-cluster;Scheduler was sent the command time
03/26/2013 06:13:29;0002;PBS_Server;Svr;PBS_Server;Torque Server Version = 3.0.5, loglevel = 0
03/26/2013 06:18:29;0002;PBS_Server;Svr;PBS_Server;Torque Server Version = 3.0.5, loglevel = 0
03/26/2013 06:20:08;0040;PBS_Server;Svr;tyrone-cluster;Scheduler was sent the command time
03/26/2013 06:23:29;0002;PBS_Server;Svr;PBS_Server;Torque Server Version = 3.0.5, loglevel = 0
03/26/2013 06:28:29;0002;PBS_Server;Svr;PBS_Server;Torque Server Version = 3.0.5, loglevel = 0
03/26/2013 06:30:08;0040;PBS_Server;Svr;tyrone-cluster;Scheduler was sent the command time
03/26/2013 06:33:29;0002;PBS_Server;Svr;PBS_Server;Torque Server Version = 3.0.5, loglevel = 0
03/26/2013 06:34:40;000d;PBS_Server;Job;20362.tyrone-cluster;Not sending email: User does not want mail of this type.
03/26/2013 06:34:40;0010;PBS_Server;Job;20362.tyrone-cluster;Exit_status=0 resources_used.cput=1312:14:51 resources_used.mem=2814992kb resources_used.vmem=10550452kb resources_used.walltime=20:39:18
03/26/2013 06:34:40;0008;PBS_Server;Job;NULL;on_job_exit valid pjob: 0x2e6d080 (substate=50)
03/26/2013 06:34:40;0008;PBS_Server;Job;NULL;on_job_exit valid pjob: 0x2e6d080 (substate=51)
03/26/2013 06:34:40;0008;PBS_Server;Job;NULL;on_job_exit valid pjob: 0x2e6d080 (substate=51)
03/26/2013 06:34:40;0008;PBS_Server;Job;NULL;on_job_exit valid pjob: 0x2e6d080 (substate=53)
03/26/2013 06:34:40;0100;PBS_Server;Job;20362.tyrone-cluster;dequeuing from qp64, state COMPLETE
03/26/2013 06:34:40;0040;PBS_Server;Svr;tyrone-cluster;Scheduler was sent the command term
03/26/2013 06:38:29;0002;PBS_Server;Svr;PBS_Server;Torque Server Version = 3.0.5, loglevel = 0
03/26/2013 06:43:29;0002;PBS_Server;Svr;PBS_Server;Torque Server Version = 3.0.5, loglevel = 0
03/26/2013 06:44:40;0040;PBS_Server;Svr;tyrone-cluster;Scheduler was sent the command time
03/26/2013 06:48:29;0002;PBS_Server;Svr;PBS_Server;Torque Server Version = 3.0.5, loglevel = 0
03/26/2013 06:53:29;0002;PBS_Server;Svr;PBS_Server;Torque Server Version = 3.0.5, loglevel = 0
03/26/2013 06:54:40;0040;PBS_Server;Svr;tyrone-cluster;Scheduler was sent the command time
03/26/2013 06:58:29;0002;PBS_Server;Svr;PBS_Server;Torque Server Version = 3.0.5, loglevel = 0
03/26/2013 07:03:29;0002;PBS_Server;Svr;PBS_Server;Torque Server Version = 3.0.5, loglevel = 0
03/26/2013 07:04:40;0040;PBS_Server;Svr;tyrone-cluster;Scheduler was sent the command time
03/26/2013 07:08:29;0002;PBS_Server;Svr;PBS_Server;Torque Server Version = 3.0.5, loglevel = 0
03/26/2013 07:13:29;0002;PBS_Server;Svr;PBS_Server;Torque Server Version = 3.0.5, loglevel = 0
03/26/2013 07:14:40;0040;PBS_Server;Svr;tyrone-cluster;Scheduler was sent the command time
03/26/2013 07:18:29;0002;PBS_Server;Svr;PBS_Server;Torque Server Version = 3.0.5, loglevel = 0
03/26/2013 07:23:29;0002;PBS_Server;Svr;PBS_Server;Torque Server Version = 3.0.5, loglevel = 0
03/26/2013 07:24:40;0040;PBS_Server;Svr;tyrone-cluster;Scheduler was sent the command time
03/26/2013 07:28:29;0002;PBS_Server;Svr;PBS_Server;Torque Server Version = 3.0.5, loglevel = 0
03/26/2013 07:33:29;0002;PBS_Server;Svr;PBS_Server;Torque Server Version = 3.0.5, loglevel = 0
03/26/2013 07:34:27;0100;PBS_Server;Job;20445.tyrone-cluster;enqueuing into batch, state 1 hop 1
03/26/2013 07:34:27;0100;PBS_Server;Job;20445.tyrone-cluster;dequeuing from batch, state QUEUED
03/26/2013 07:34:27;0100;PBS_Server;Job;20445.tyrone-cluster;enqueuing into qp32, state 1 hop 1
03/26/2013 07:34:27;0008;PBS_Server;Job;20445.tyrone-cluster;Job Queued at request of metposhi@tyrone-cluster, owner = metposhi@tyrone-cluster, job name = poshit1, queue = qp32
03/26/2013 07:34:27;0040;PBS_Server;Svr;tyrone-cluster;Scheduler was sent the command new
03/26/2013 07:34:27;0008;PBS_Server;Job;20445.tyrone-cluster;Job Modified at request of Scheduler@tyrone-cluster
03/26/2013 07:34:27;0008;PBS_Server;Job;20445.tyrone-cluster;Job Run at request of Scheduler@tyrone-cluster
03/26/2013 07:34:27;0040;PBS_Server;Svr;tyrone-cluster;Scheduler was sent the command recyc
03/26/2013 07:34:27;000d;PBS_Server;Job;20445.tyrone-cluster;Not sending email: User does not want mail of this type.
03/26/2013 07:36:40;0100;PBS_Server;Job;20446.tyrone-cluster;enqueuing into batch, state 1 hop 1
03/26/2013 07:36:40;0100;PBS_Server;Job;20446.tyrone-cluster;dequeuing from batch, state QUEUED
03/26/2013 07:36:40;0100;PBS_Server;Job;20446.tyrone-cluster;enqueuing into qp32, state 1 hop 1
03/26/2013 07:36:40;0008;PBS_Server;Job;20446.tyrone-cluster;Job Queued at request of metposhi@tyrone-cluster, owner = metposhi@tyrone-cluster, job name = poshit1, queue = qp32
03/26/2013 07:36:40;0040;PBS_Server;Svr;tyrone-cluster;Scheduler was sent the command new
03/26/2013 07:36:40;0008;PBS_Server;Job;20446.tyrone-cluster;Job Modified at request of Scheduler@tyrone-cluster
03/26/2013 07:36:46;0008;PBS_Server;Job;20445.tyrone-cluster;Job deleted at request of metposhi@tyrone-cluster
03/26/2013 07:36:46;0008;PBS_Server;Job;20445.tyrone-cluster;Job sent signal SIGTERM on delete
03/26/2013 07:36:48;0008;PBS_Server;Job;20445.tyrone-cluster;Job sent signal SIGKILL on delete
03/26/2013 07:36:49;000d;PBS_Server;Job;20445.tyrone-cluster;Not sending email: User does not want mail of this type.
03/26/2013 07:36:49;0010;PBS_Server;Job;20445.tyrone-cluster;Exit_status=143 resources_used.cput=01:09:33 resources_used.mem=1417328kb resources_used.vmem=9829476kb resources_used.walltime=00:02:22
03/26/2013 07:36:49;0008;PBS_Server;Job;NULL;on_job_exit valid pjob: 0x2e37f20 (substate=50)
03/26/2013 07:36:49;0008;PBS_Server;Job;NULL;on_job_exit valid pjob: 0x2e37f20 (substate=51)
03/26/2013 07:36:54;0008;PBS_Server;Job;NULL;on_job_exit valid pjob: 0x2e37f20 (substate=51)
03/26/2013 07:36:54;000d;PBS_Server;Job;20445.tyrone-cluster;Post job file processing error; job 20445.tyrone-cluster on host tyrone-node1/31+tyrone-node1/30+tyrone-node1/29+tyrone-node1/28+tyrone-node1/27+tyrone-node1/26+tyrone-node1/25+tyrone-node1/24+tyrone-node1/23+tyrone-node1/22+tyrone-node1/21+tyrone-node1/20+tyrone-node1/19+tyrone-node1/18+tyrone-node1/17+tyrone-node1/16+tyrone-node1/15+tyrone-node1/14+tyrone-node1/13+tyrone-node1/12+tyrone-node1/11+tyrone-node1/10+tyrone-node1/9+tyrone-node1/8+tyrone-node1/7+tyrone-node1/6+tyrone-node1/5+tyrone-node1/4+tyrone-node1/3+tyrone-node1/2+tyrone-node1/1+tyrone-node1/0
03/26/2013 07:36:54;0008;PBS_Server;Job;NULL;on_job_exit valid pjob: 0x2e37f20 (substate=53)
03/26/2013 07:36:54;0100;PBS_Server;Job;20445.tyrone-cluster;dequeuing from qp32, state COMPLETE
03/26/2013 07:36:54;0040;PBS_Server;Svr;tyrone-cluster;Scheduler was sent the command term
03/26/2013 07:36:54;0008;PBS_Server;Job;20446.tyrone-cluster;Job Modified at request of Scheduler@tyrone-cluster
03/26/2013 07:36:54;0008;PBS_Server;Job;20446.tyrone-cluster;Job Run at request of Scheduler@tyrone-cluster
03/26/2013 07:36:54;0040;PBS_Server;Svr;tyrone-cluster;Scheduler was sent the command recyc
03/26/2013 07:36:54;000d;PBS_Server;Job;20446.tyrone-cluster;Not sending email: User does not want mail of this type.
03/26/2013 07:37:12;0100;PBS_Server;Job;20447.tyrone-cluster;enqueuing into batch, state 1 hop 1
03/26/2013 07:37:12;0100;PBS_Server;Job;20447.tyrone-cluster;dequeuing from batch, state QUEUED
03/26/2013 07:37:12;0100;PBS_Server;Job;20447.tyrone-cluster;enqueuing into qp32, state 1 hop 1
03/26/2013 07:37:12;0008;PBS_Server;Job;20447.tyrone-cluster;Job Queued at request of metposhi@tyrone-cluster, owner = metposhi@tyrone-cluster, job name = poshit1, queue = qp32
03/26/2013 07:37:12;0040;PBS_Server;Svr;tyrone-cluster;Scheduler was sent the command new
03/26/2013 07:37:12;0008;PBS_Server;Job;20447.tyrone-cluster;Job Modified at request of Scheduler@tyrone-cluster
03/26/2013 07:37:44;0100;PBS_Server;Job;20448.tyrone-cluster;enqueuing into batch, state 1 hop 1
03/26/2013 07:37:44;0008;PBS_Server;Job;20448.tyrone-cluster;Job Queued at request of metposhi@tyrone-cluster, owner = metposhi@tyrone-cluster, job name = poshit1, queue = batch
03/26/2013 07:37:44;0040;PBS_Server;Svr;tyrone-cluster;Scheduler was sent the command new
03/26/2013 07:37:44;0008;PBS_Server;Job;20448.tyrone-cluster;Job Modified at request of Scheduler@tyrone-cluster
03/26/2013 07:38:15;0040;PBS_Server;Svr;tyrone-cluster;Scheduler was sent the command new
03/26/2013 07:38:29;0002;PBS_Server;Svr;PBS_Server;Torque Server Version = 3.0.5, loglevel = 0
03/26/2013 07:38:44;0040;PBS_Server;Svr;tyrone-cluster;Scheduler was sent the command new
03/26/2013 07:39:21;0040;PBS_Server;Svr;tyrone-cluster;Scheduler was sent the command new
03/26/2013 07:39:56;0040;PBS_Server;Svr;tyrone-cluster;Scheduler was sent the command new
03/26/2013 07:40:25;0040;PBS_Server;Svr;tyrone-cluster;Scheduler was sent the command new
03/26/2013 07:40:56;0040;PBS_Server;Svr;tyrone-cluster;Scheduler was sent the command new
03/26/2013 07:41:27;0040;PBS_Server;Svr;tyrone-cluster;Scheduler was sent the command new
03/26/2013 07:41:39;0100;PBS_Server;Job;20449.tyrone-cluster;enqueuing into batch, state 1 hop 1
03/26/2013 07:41:39;0100;PBS_Server;Job;20449.tyrone-cluster;dequeuing from batch, state QUEUED
03/26/2013 07:41:39;0100;PBS_Server;Job;20449.tyrone-cluster;enqueuing into qp32, state 1 hop 1
03/26/2013 07:41:39;0008;PBS_Server;Job;20449.tyrone-cluster;Job Queued at request of metvura@tyrone-cluster, owner = metvura@tyrone-cluster, job name = vura1, queue = qp32
03/26/2013 07:41:39;0040;PBS_Server;Svr;tyrone-cluster;Scheduler was sent the command new
03/26/2013 07:41:39;0008;PBS_Server;Job;20449.tyrone-cluster;Job Modified at request of Scheduler@tyrone-cluster
03/26/2013 07:41:39;0008;PBS_Server;Job;20449.tyrone-cluster;Job Run at request of Scheduler@tyrone-cluster
03/26/2013 07:41:40;0040;PBS_Server;Svr;tyrone-cluster;Scheduler was sent the command recyc
03/26/2013 07:41:40;000d;PBS_Server;Job;20449.tyrone-cluster;Not sending email: User does not want mail of this type.
03/26/2013 07:41:40;000d;PBS_Server;Job;20449.tyrone-cluster;Not sending email: User does not want mail of this type.
03/26/2013 07:41:40;0010;PBS_Server;Job;20449.tyrone-cluster;Exit_status=1 resources_used.cput=00:00:00 resources_used.mem=0kb resources_used.vmem=0kb resources_used.walltime=00:00:01
03/26/2013 07:41:40;0008;PBS_Server;Job;NULL;on_job_exit valid pjob: 0x2e39a70 (substate=50)
03/26/2013 07:41:40;0008;PBS_Server;Job;NULL;on_job_exit valid pjob: 0x2e39a70 (substate=51)
03/26/2013 07:41:45;0008;PBS_Server;Job;NULL;on_job_exit valid pjob: 0x2e39a70 (substate=51)
03/26/2013 07:41:45;000d;PBS_Server;Job;20449.tyrone-cluster;Post job file processing error; job 20449.tyrone-cluster on host tyrone-node2/31+tyrone-node2/30+tyrone-node2/29+tyrone-node2/28+tyrone-node2/27+tyrone-node2/26+tyrone-node2/25+tyrone-node2/24+tyrone-node2/23+tyrone-node2/22+tyrone-node2/21+tyrone-node2/20+tyrone-node2/19+tyrone-node2/18+tyrone-node2/17+tyrone-node2/16+tyrone-node2/15+tyrone-node2/14+tyrone-node2/13+tyrone-node2/12+tyrone-node2/11+tyrone-node2/10+tyrone-node2/9+tyrone-node2/8+tyrone-node2/7+tyrone-node2/6+tyrone-node2/5+tyrone-node2/4+tyrone-node2/3+tyrone-node2/2+tyrone-node2/1+tyrone-node2/0
03/26/2013 07:41:45;0008;PBS_Server;Job;NULL;on_job_exit valid pjob: 0x2e39a70 (substate=53)
03/26/2013 07:41:45;0100;PBS_Server;Job;20449.tyrone-cluster;dequeuing from qp32, state COMPLETE
03/26/2013 07:41:45;0040;PBS_Server;Svr;tyrone-cluster;Scheduler was sent the command term
03/26/2013 07:41:57;0040;PBS_Server;Svr;tyrone-cluster;Scheduler was sent the command new
03/26/2013 07:42:10;0100;PBS_Server;Job;20450.tyrone-cluster;enqueuing into batch, state 1 hop 1
03/26/2013 07:42:10;0100;PBS_Server;Job;20450.tyrone-cluster;dequeuing from batch, state QUEUED
03/26/2013 07:42:10;0100;PBS_Server;Job;20450.tyrone-cluster;enqueuing into qp32, state 1 hop 1
03/26/2013 07:42:10;0008;PBS_Server;Job;20450.tyrone-cluster;Job Queued at request of metvura@tyrone-cluster, owner = metvura@tyrone-cluster, job name = vura1, queue = qp32
03/26/2013 07:42:10;0040;PBS_Server;Svr;tyrone-cluster;Scheduler was sent the command new
03/26/2013 07:42:10;0008;PBS_Server;Job;20450.tyrone-cluster;Job Modified at request of Scheduler@tyrone-cluster
03/26/2013 07:42:10;0008;PBS_Server;Job;20450.tyrone-cluster;Job Run at request of Scheduler@tyrone-cluster
03/26/2013 07:42:10;0040;PBS_Server;Svr;tyrone-cluster;Scheduler was sent the command recyc
03/26/2013 07:42:10;000d;PBS_Server;Job;20450.tyrone-cluster;Not sending email: User does not want mail of this type.
03/26/2013 07:42:27;0040;PBS_Server;Svr;tyrone-cluster;Scheduler was sent the command new
03/26/2013 07:42:37;0008;PBS_Server;Job;20448.tyrone-cluster;Job deleted at request of metposhi@tyrone-cluster
03/26/2013 07:42:37;0008;PBS_Server;Job;NULL;on_job_exit valid pjob: 0x2e3bf70 (substate=59)
03/26/2013 07:42:37;0100;PBS_Server;Job;20448.tyrone-cluster;dequeuing from batch, state COMPLETE
03/26/2013 07:42:37;0040;PBS_Server;Svr;tyrone-cluster;Scheduler was sent the command term
03/26/2013 07:43:29;0002;PBS_Server;Svr;PBS_Server;Torque Server Version = 3.0.5, loglevel = 0
03/26/2013 07:45:55;0100;PBS_Server;Job;20451.tyrone-cluster;enqueuing into batch, state 1 hop 1
03/26/2013 07:45:55;0100;PBS_Server;Job;20451.tyrone-cluster;dequeuing from batch, state QUEUED
03/26/2013 07:45:55;0100;PBS_Server;Job;20451.tyrone-cluster;enqueuing into qp32, state 1 hop 1
03/26/2013 07:45:55;0008;PBS_Server;Job;20451.tyrone-cluster;Job Queued at request of metvura@tyrone-cluster, owner = metvura@tyrone-cluster, job name = vura1, queue = qp32
03/26/2013 07:45:55;0040;PBS_Server;Svr;tyrone-cluster;Scheduler was sent the command new
03/26/2013 07:45:55;0008;PBS_Server;Job;20451.tyrone-cluster;Job Modified at request of Scheduler@tyrone-cluster
03/26/2013 07:45:55;0008;PBS_Server;Job;20451.tyrone-cluster;Job Run at request of Scheduler@tyrone-cluster
03/26/2013 07:45:55;0040;PBS_Server;Svr;tyrone-cluster;Scheduler was sent the command recyc
03/26/2013 07:45:55;000d;PBS_Server;Job;20451.tyrone-cluster;Not sending email: User does not want mail of this type.
03/26/2013 07:47:16;0008;PBS_Server;Job;20447.tyrone-cluster;Job deleted at request of metposhi@tyrone-cluster
03/26/2013 07:47:16;0008;PBS_Server;Job;NULL;on_job_exit valid pjob: 0x2e413e0 (substate=59)
03/26/2013 07:47:16;0100;PBS_Server;Job;20447.tyrone-cluster;dequeuing from qp32, state COMPLETE
03/26/2013 07:47:16;0040;PBS_Server;Svr;tyrone-cluster;Scheduler was sent the command term
03/26/2013 07:48:29;0002;PBS_Server;Svr;PBS_Server;Torque Server Version = 3.0.5, loglevel = 0
03/26/2013 07:53:29;0002;PBS_Server;Svr;PBS_Server;Torque Server Version = 3.0.5, loglevel = 0
03/26/2013 07:57:16;0040;PBS_Server;Svr;tyrone-cluster;Scheduler was sent the command time
03/26/2013 07:58:29;0002;PBS_Server;Svr;PBS_Server;Torque Server Version = 3.0.5, loglevel = 0
03/26/2013 08:03:29;0002;PBS_Server;Svr;PBS_Server;Torque Server Version = 3.0.5, loglevel = 0
03/26/2013 08:07:16;0040;PBS_Server;Svr;tyrone-cluster;Scheduler was sent the command time
03/26/2013 08:08:29;0002;PBS_Server;Svr;PBS_Server;Torque Server Version = 3.0.5, loglevel = 0
03/26/2013 08:13:29;0002;PBS_Server;Svr;PBS_Server;Torque Server Version = 3.0.5, loglevel = 0
03/26/2013 08:17:16;0040;PBS_Server;Svr;tyrone-cluster;Scheduler was sent the command time
03/26/2013 08:18:29;0002;PBS_Server;Svr;PBS_Server;Torque Server Version = 3.0.5, loglevel = 0
03/26/2013 08:23:29;0002;PBS_Server;Svr;PBS_Server;Torque Server Version = 3.0.5, loglevel = 0
03/26/2013 08:27:16;0040;PBS_Server;Svr;tyrone-cluster;Scheduler was sent the command time
03/26/2013 08:28:29;0002;PBS_Server;Svr;PBS_Server;Torque Server Version = 3.0.5, loglevel = 0
03/26/2013 08:32:23;000d;PBS_Server;Job;20451.tyrone-cluster;Not sending email: User does not want mail of this type.
03/26/2013 08:32:23;0010;PBS_Server;Job;20451.tyrone-cluster;Exit_status=0 resources_used.cput=24:11:22 resources_used.mem=1463156kb resources_used.vmem=9845532kb resources_used.walltime=00:46:28
03/26/2013 08:32:23;0008;PBS_Server;Job;NULL;on_job_exit valid pjob: 0x2e3bf70 (substate=50)
03/26/2013 08:32:23;0008;PBS_Server;Job;NULL;on_job_exit valid pjob: 0x2e3bf70 (substate=51)
03/26/2013 08:32:28;0008;PBS_Server;Job;NULL;on_job_exit valid pjob: 0x2e3bf70 (substate=51)
03/26/2013 08:32:28;000d;PBS_Server;Job;20451.tyrone-cluster;Post job file processing error; job 20451.tyrone-cluster on host tyrone-node3/31+tyrone-node3/30+tyrone-node3/29+tyrone-node3/28+tyrone-node3/27+tyrone-node3/26+tyrone-node3/25+tyrone-node3/24+tyrone-node3/23+tyrone-node3/22+tyrone-node3/21+tyrone-node3/20+tyrone-node3/19+tyrone-node3/18+tyrone-node3/17+tyrone-node3/16+tyrone-node3/15+tyrone-node3/14+tyrone-node3/13+tyrone-node3/12+tyrone-node3/11+tyrone-node3/10+tyrone-node3/9+tyrone-node3/8+tyrone-node3/7+tyrone-node3/6+tyrone-node3/5+tyrone-node3/4+tyrone-node3/3+tyrone-node3/2+tyrone-node3/1+tyrone-node3/0
03/26/2013 08:32:28;0008;PBS_Server;Job;NULL;on_job_exit valid pjob: 0x2e3bf70 (substate=53)
03/26/2013 08:32:28;0100;PBS_Server;Job;20451.tyrone-cluster;dequeuing from qp32, state COMPLETE
03/26/2013 08:32:28;0040;PBS_Server;Svr;tyrone-cluster;Scheduler was sent the command term
03/26/2013 08:33:29;0002;PBS_Server;Svr;PBS_Server;Torque Server Version = 3.0.5, loglevel = 0
03/26/2013 08:38:29;0002;PBS_Server;Svr;PBS_Server;Torque Server Version = 3.0.5, loglevel = 0
03/26/2013 08:42:28;0040;PBS_Server;Svr;tyrone-cluster;Scheduler was sent the command time
03/26/2013 08:43:29;0002;PBS_Server;Svr;PBS_Server;Torque Server Version = 3.0.5, loglevel = 0
03/26/2013 08:48:29;0002;PBS_Server;Svr;PBS_Server;Torque Server Version = 3.0.5, loglevel = 0
03/26/2013 08:52:28;0040;PBS_Server;Svr;tyrone-cluster;Scheduler was sent the command time
03/26/2013 08:53:29;0002;PBS_Server;Svr;PBS_Server;Torque Server Version = 3.0.5, loglevel = 0
03/26/2013 08:58:29;0002;PBS_Server;Svr;PBS_Server;Torque Server Version = 3.0.5, loglevel = 0
03/26/2013 09:02:28;0040;PBS_Server;Svr;tyrone-cluster;Scheduler was sent the command time
03/26/2013 09:03:29;0002;PBS_Server;Svr;PBS_Server;Torque Server Version = 3.0.5, loglevel = 0
03/26/2013 09:04:16;0100;PBS_Server;Job;20452.tyrone-cluster;enqueuing into batch, state 1 hop 1
03/26/2013 09:04:16;0100;PBS_Server;Job;20452.tyrone-cluster;dequeuing from batch, state QUEUED
03/26/2013 09:04:16;0100;PBS_Server;Job;20452.tyrone-cluster;enqueuing into qp32, state 1 hop 1
03/26/2013 09:04:16;0008;PBS_Server;Job;20452.tyrone-cluster;Job Queued at request of ipcdskp@tyrone-cluster, owner = ipcdskp@tyrone-cluster, job name = n12, queue = qp32
03/26/2013 09:04:16;0040;PBS_Server;Svr;tyrone-cluster;Scheduler was sent the command new
03/26/2013 09:04:16;0008;PBS_Server;Job;20452.tyrone-cluster;Job Modified at request of Scheduler@tyrone-cluster
03/26/2013 09:04:16;0008;PBS_Server;Job;20452.tyrone-cluster;Job Run at request of Scheduler@tyrone-cluster
03/26/2013 09:04:17;0040;PBS_Server;Svr;tyrone-cluster;Scheduler was sent the command recyc
03/26/2013 09:04:17;000d;PBS_Server;Job;20452.tyrone-cluster;Not sending email: User does not want mail of this type.
03/26/2013 09:06:06;0008;PBS_Server;Job;20452.tyrone-cluster;Job deleted at request of ipcdskp@tyrone-cluster
03/26/2013 09:06:06;0008;PBS_Server;Job;20452.tyrone-cluster;Job sent signal SIGTERM on delete
03/26/2013 09:06:08;0008;PBS_Server;Job;20452.tyrone-cluster;Job sent signal SIGKILL on delete
03/26/2013 09:06:12;000d;PBS_Server;Job;20452.tyrone-cluster;Not sending email: User does not want mail of this type.
03/26/2013 09:06:12;0010;PBS_Server;Job;20452.tyrone-cluster;Exit_status=143 resources_used.cput=00:54:59 resources_used.mem=1379252kb resources_used.vmem=8192208kb resources_used.walltime=00:01:55
03/26/2013 09:06:12;0008;PBS_Server;Job;NULL;on_job_exit valid pjob: 0x2e3bf70 (substate=50)
03/26/2013 09:06:12;0008;PBS_Server;Job;NULL;on_job_exit valid pjob: 0x2e3bf70 (substate=51)
03/26/2013 09:06:12;0008;PBS_Server;Job;NULL;on_job_exit valid pjob: 0x2e3bf70 (substate=51)
03/26/2013 09:06:12;0008;PBS_Server;Job;NULL;on_job_exit valid pjob: 0x2e3bf70 (substate=53)
03/26/2013 09:06:12;0100;PBS_Server;Job;20452.tyrone-cluster;dequeuing from qp32, state COMPLETE
03/26/2013 09:06:12;0040;PBS_Server;Svr;tyrone-cluster;Scheduler was sent the command term
03/26/2013 09:06:53;0100;PBS_Server;Job;20453.tyrone-cluster;enqueuing into batch, state 1 hop 1
03/26/2013 09:06:53;0100;PBS_Server;Job;20453.tyrone-cluster;dequeuing from batch, state QUEUED
03/26/2013 09:06:53;0100;PBS_Server;Job;20453.tyrone-cluster;enqueuing into qp32, state 1 hop 1
03/26/2013 09:06:53;0008;PBS_Server;Job;20453.tyrone-cluster;Job Queued at request of ipcdskp@tyrone-cluster, owner = ipcdskp@tyrone-cluster, job name = n12, queue = qp32
03/26/2013 09:06:53;0040;PBS_Server;Svr;tyrone-cluster;Scheduler was sent the command new
03/26/2013 09:06:53;0008;PBS_Server;Job;20453.tyrone-cluster;Job Modified at request of Scheduler@tyrone-cluster
03/26/2013 09:06:53;0008;PBS_Server;Job;20453.tyrone-cluster;Job Run at request of Scheduler@tyrone-cluster
03/26/2013 09:06:54;0040;PBS_Server;Svr;tyrone-cluster;Scheduler was sent the command recyc
03/26/2013 09:06:54;000d;PBS_Server;Job;20453.tyrone-cluster;Not sending email: User does not want mail of this type.
03/26/2013 09:08:29;0002;PBS_Server;Svr;PBS_Server;Torque Server Version = 3.0.5, loglevel = 0
03/26/2013 09:13:29;0002;PBS_Server;Svr;PBS_Server;Torque Server Version = 3.0.5, loglevel = 0
03/26/2013 09:16:54;0040;PBS_Server;Svr;tyrone-cluster;Scheduler was sent the command time
03/26/2013 09:18:29;0002;PBS_Server;Svr;PBS_Server;Torque Server Version = 3.0.5, loglevel = 0
03/26/2013 09:23:29;0002;PBS_Server;Svr;PBS_Server;Torque Server Version = 3.0.5, loglevel = 0
03/26/2013 09:26:54;0040;PBS_Server;Svr;tyrone-cluster;Scheduler was sent the command time
03/26/2013 09:27:06;0100;PBS_Server;Job;20454.tyrone-cluster;enqueuing into batch, state 1 hop 1
03/26/2013 09:27:06;0100;PBS_Server;Job;20454.tyrone-cluster;dequeuing from batch, state QUEUED
03/26/2013 09:27:06;0100;PBS_Server;Job;20454.tyrone-cluster;enqueuing into qp64, state 1 hop 1
03/26/2013 09:27:06;0008;PBS_Server;Job;20454.tyrone-cluster;Job Queued at request of csdrjain@tyrone-cluster, owner = csdrjain@tyrone-cluster, job name = n10, queue = qp64
03/26/2013 09:27:06;0040;PBS_Server;Svr;tyrone-cluster;Scheduler was sent the command new
03/26/2013 09:27:06;0008;PBS_Server;Job;20454.tyrone-cluster;Job Modified at request of Scheduler@tyrone-cluster
03/26/2013 09:27:06;0008;PBS_Server;Job;20454.tyrone-cluster;Job Run at request of Scheduler@tyrone-cluster
03/26/2013 09:27:07;0040;PBS_Server;Svr;tyrone-cluster;Scheduler was sent the command recyc
03/26/2013 09:27:07;000d;PBS_Server;Job;20454.tyrone-cluster;Not sending email: User does not want mail of this type.
03/26/2013 09:28:29;0002;PBS_Server;Svr;PBS_Server;Torque Server Version = 3.0.5, loglevel = 0
03/26/2013 09:33:29;0002;PBS_Server;Svr;PBS_Server;Torque Server Version = 3.0.5, loglevel = 0
03/26/2013 09:37:07;0040;PBS_Server;Svr;tyrone-cluster;Scheduler was sent the command time
03/26/2013 09:38:29;0002;PBS_Server;Svr;PBS_Server;Torque Server Version = 3.0.5, loglevel = 0
03/26/2013 09:43:29;0002;PBS_Server;Svr;PBS_Server;Torque Server Version = 3.0.5, loglevel = 0
03/26/2013 09:47:07;0040;PBS_Server;Svr;tyrone-cluster;Scheduler was sent the command time
03/26/2013 09:48:29;0002;PBS_Server;Svr;PBS_Server;Torque Server Version = 3.0.5, loglevel = 0
03/26/2013 09:53:29;0002;PBS_Server;Svr;PBS_Server;Torque Server Version = 3.0.5, loglevel = 0
03/26/2013 09:56:00;000d;PBS_Server;Job;20454.tyrone-cluster;Not sending email: User does not want mail of this type.
03/26/2013 09:56:00;0010;PBS_Server;Job;20454.tyrone-cluster;Exit_status=1 resources_used.cput=30:36:17 resources_used.mem=2874660kb resources_used.vmem=10547880kb resources_used.walltime=00:28:53
03/26/2013 09:56:00;0008;PBS_Server;Job;NULL;on_job_exit valid pjob: 0x2e3bf70 (substate=50)
03/26/2013 09:56:00;0008;PBS_Server;Job;NULL;on_job_exit valid pjob: 0x2e3bf70 (substate=51)
03/26/2013 09:56:00;0008;PBS_Server;Job;NULL;on_job_exit valid pjob: 0x2e3bf70 (substate=51)
03/26/2013 09:56:00;0008;PBS_Server;Job;NULL;on_job_exit valid pjob: 0x2e3bf70 (substate=53)
03/26/2013 09:56:00;0100;PBS_Server;Job;20454.tyrone-cluster;dequeuing from qp64, state COMPLETE
03/26/2013 09:56:00;0040;PBS_Server;Svr;tyrone-cluster;Scheduler was sent the command term
03/26/2013 09:58:29;0002;PBS_Server;Svr;PBS_Server;Torque Server Version = 3.0.5, loglevel = 0
03/26/2013 10:02:28;0100;PBS_Server;Job;20455.tyrone-cluster;enqueuing into batch, state 1 hop 1
03/26/2013 10:02:28;0100;PBS_Server;Job;20455.tyrone-cluster;dequeuing from batch, state QUEUED
03/26/2013 10:02:28;0100;PBS_Server;Job;20455.tyrone-cluster;enqueuing into qp64, state 1 hop 1
03/26/2013 10:02:28;0008;PBS_Server;Job;20455.tyrone-cluster;Job Queued at request of ipcdskp@tyrone-cluster, owner = ipcdskp@tyrone-cluster, job name = n13, queue = qp64
03/26/2013 10:02:28;0040;PBS_Server;Svr;tyrone-cluster;Scheduler was sent the command new
03/26/2013 10:02:28;0008;PBS_Server;Job;20455.tyrone-cluster;Job Modified at request of Scheduler@tyrone-cluster
03/26/2013 10:02:28;0008;PBS_Server;Job;20455.tyrone-cluster;Job Run at request of Scheduler@tyrone-cluster
03/26/2013 10:02:28;0040;PBS_Server;Svr;tyrone-cluster;Scheduler was sent the command recyc
03/26/2013 10:02:28;000d;PBS_Server;Job;20455.tyrone-cluster;Not sending email: User does not want mail of this type.
03/26/2013 10:03:29;0002;PBS_Server;Svr;PBS_Server;Torque Server Version = 3.0.5, loglevel = 0
03/26/2013 10:06:41;0100;PBS_Server;Job;20456.tyrone-cluster;enqueuing into batch, state 1 hop 1
03/26/2013 10:06:41;0100;PBS_Server;Job;20456.tyrone-cluster;dequeuing from batch, state QUEUED
03/26/2013 10:06:41;0100;PBS_Server;Job;20456.tyrone-cluster;enqueuing into qp64, state 1 hop 1
03/26/2013 10:06:41;0008;PBS_Server;Job;20456.tyrone-cluster;Job Queued at request of mbumasha@tyrone-cluster, owner = mbumasha@tyrone-cluster, job name = mlecdig5-22-03-13, queue = qp64
03/26/2013 10:06:41;0040;PBS_Server;Svr;tyrone-cluster;Scheduler was sent the command new
03/26/2013 10:06:41;0008;PBS_Server;Job;20456.tyrone-cluster;Job Modified at request of Scheduler@tyrone-cluster
03/26/2013 10:06:41;0008;PBS_Server;Job;20456.tyrone-cluster;Job Run at request of Scheduler@tyrone-cluster
03/26/2013 10:06:41;0040;PBS_Server;Svr;tyrone-cluster;Scheduler was sent the command recyc
03/26/2013 10:06:41;000d;PBS_Server;Job;20456.tyrone-cluster;Not sending email: User does not want mail of this type.
03/26/2013 10:07:30;000d;PBS_Server;Job;20444.tyrone-cluster;Not sending email: User does not want mail of this type.
03/26/2013 10:07:30;0010;PBS_Server;Job;20444.tyrone-cluster;Exit_status=0 resources_used.cput=320:20:22 resources_used.mem=1957748kb resources_used.vmem=10383136kb resources_used.walltime=10:30:20
03/26/2013 10:07:30;0008;PBS_Server;Job;NULL;on_job_exit valid pjob: 0x2ec6dc0 (substate=50)
03/26/2013 10:07:30;0008;PBS_Server;Job;NULL;on_job_exit valid pjob: 0x2ec6dc0 (substate=51)
03/26/2013 10:07:34;0008;PBS_Server;Job;NULL;on_job_exit valid pjob: 0x2ec6dc0 (substate=51)
03/26/2013 10:07:34;000d;PBS_Server;Job;20444.tyrone-cluster;Post job file processing error; job 20444.tyrone-cluster on host tyrone-node6/31+tyrone-node6/30+tyrone-node6/29+tyrone-node6/28+tyrone-node6/27+tyrone-node6/26+tyrone-node6/25+tyrone-node6/24+tyrone-node6/23+tyrone-node6/22+tyrone-node6/21+tyrone-node6/20+tyrone-node6/19+tyrone-node6/18+tyrone-node6/17+tyrone-node6/16+tyrone-node6/15+tyrone-node6/14+tyrone-node6/13+tyrone-node6/12+tyrone-node6/11+tyrone-node6/10+tyrone-node6/9+tyrone-node6/8+tyrone-node6/7+tyrone-node6/6+tyrone-node6/5+tyrone-node6/4+tyrone-node6/3+tyrone-node6/2+tyrone-node6/1+tyrone-node6/0
03/26/2013 10:07:34;0008;PBS_Server;Job;NULL;on_job_exit valid pjob: 0x2ec6dc0 (substate=53)
03/26/2013 10:07:34;0100;PBS_Server;Job;20444.tyrone-cluster;dequeuing from qp32, state COMPLETE
03/26/2013 10:07:34;0040;PBS_Server;Svr;tyrone-cluster;Scheduler was sent the command term
03/26/2013 10:08:29;0002;PBS_Server;Svr;PBS_Server;Torque Server Version = 3.0.5, loglevel = 0
03/26/2013 10:09:29;0100;PBS_Server;Job;20457.tyrone-cluster;enqueuing into batch, state 1 hop 1
03/26/2013 10:09:29;0100;PBS_Server;Job;20457.tyrone-cluster;dequeuing from batch, state QUEUED
03/26/2013 10:09:29;0100;PBS_Server;Job;20457.tyrone-cluster;enqueuing into qp64, state 1 hop 1
03/26/2013 10:09:29;0008;PBS_Server;Job;20457.tyrone-cluster;Job Queued at request of mbuteja@tyrone-cluster, owner = mbuteja@tyrone-cluster, job name = Mlectrg5-21-03-13, queue = qp64
03/26/2013 10:09:29;0040;PBS_Server;Svr;tyrone-cluster;Scheduler was sent the command new
03/26/2013 10:09:29;0008;PBS_Server;Job;20457.tyrone-cluster;Job Modified at request of Scheduler@tyrone-cluster
03/26/2013 10:13:29;0002;PBS_Server;Svr;PBS_Server;Torque Server Version = 3.0.5, loglevel = 0
03/26/2013 10:14:16;0100;PBS_Server;Job;20458.tyrone-cluster;enqueuing into batch, state 1 hop 1
03/26/2013 10:14:16;0100;PBS_Server;Job;20458.tyrone-cluster;dequeuing from batch, state QUEUED
03/26/2013 10:14:16;0100;PBS_Server;Job;20458.tyrone-cluster;enqueuing into qp64, state 1 hop 1
03/26/2013 10:14:16;0008;PBS_Server;Job;20458.tyrone-cluster;Job Queued at request of mbuavdhs@tyrone-cluster, owner = mbuavdhs@tyrone-cluster, job name = Mlecmog5-25-03-13, queue = qp64
03/26/2013 10:14:16;0040;PBS_Server;Svr;tyrone-cluster;Scheduler was sent the command new
03/26/2013 10:14:16;0008;PBS_Server;Job;20458.tyrone-cluster;Job Modified at request of Scheduler@tyrone-cluster
03/26/2013 10:18:29;0002;PBS_Server;Svr;PBS_Server;Torque Server Version = 3.0.5, loglevel = 0
03/26/2013 10:23:29;0002;PBS_Server;Svr;PBS_Server;Torque Server Version = 3.0.5, loglevel = 0
03/26/2013 10:24:16;0040;PBS_Server;Svr;tyrone-cluster;Scheduler was sent the command time
03/26/2013 10:28:29;0002;PBS_Server;Svr;PBS_Server;Torque Server Version = 3.0.5, loglevel = 0
03/26/2013 10:29:48;0100;PBS_Server;Job;20459.tyrone-cluster;enqueuing into batch, state 1 hop 1
03/26/2013 10:29:48;0100;PBS_Server;Job;20459.tyrone-cluster;dequeuing from batch, state QUEUED
03/26/2013 10:29:48;0100;PBS_Server;Job;20459.tyrone-cluster;enqueuing into qp32, state 1 hop 1
03/26/2013 10:29:48;0008;PBS_Server;Job;20459.tyrone-cluster;Job Queued at request of metvura@tyrone-cluster, owner = metvura@tyrone-cluster, job name = vura1, queue = qp32
03/26/2013 10:29:48;0040;PBS_Server;Svr;tyrone-cluster;Scheduler was sent the command new
03/26/2013 10:29:49;0008;PBS_Server;Job;20459.tyrone-cluster;Job Modified at request of Scheduler@tyrone-cluster
03/26/2013 10:29:49;0008;PBS_Server;Job;20459.tyrone-cluster;Job Run at request of Scheduler@tyrone-cluster
03/26/2013 10:29:49;0040;PBS_Server;Svr;tyrone-cluster;Scheduler was sent the command recyc
03/26/2013 10:29:49;000d;PBS_Server;Job;20459.tyrone-cluster;Not sending email: User does not want mail of this type.
03/26/2013 10:29:56;0100;PBS_Server;Job;20460.tyrone-cluster;enqueuing into batch, state 1 hop 1
03/26/2013 10:29:56;0100;PBS_Server;Job;20460.tyrone-cluster;dequeuing from batch, state QUEUED
03/26/2013 10:29:56;0100;PBS_Server;Job;20460.tyrone-cluster;enqueuing into idqueue, state 1 hop 1
03/26/2013 10:29:56;0008;PBS_Server;Job;20460.tyrone-cluster;Job Queued at request of metvura@tyrone-cluster, owner = metvura@tyrone-cluster, job name = vura1, queue = idqueue
03/26/2013 10:29:56;0040;PBS_Server;Svr;tyrone-cluster;Scheduler was sent the command new
03/26/2013 10:29:56;0008;PBS_Server;Job;20460.tyrone-cluster;Job Modified at request of Scheduler@tyrone-cluster
03/26/2013 10:29:56;0008;PBS_Server;Job;20460.tyrone-cluster;Job Run at request of Scheduler@tyrone-cluster
03/26/2013 10:29:56;0040;PBS_Server;Svr;tyrone-cluster;Scheduler was sent the command recyc
03/26/2013 10:29:56;000d;PBS_Server;Job;20460.tyrone-cluster;Not sending email: User does not want mail of this type.
03/26/2013 10:32:10;000d;PBS_Server;Job;20459.tyrone-cluster;Not sending email: User does not want mail of this type.
03/26/2013 10:32:10;0010;PBS_Server;Job;20459.tyrone-cluster;Exit_status=0 resources_used.cput=01:08:54 resources_used.mem=1381240kb resources_used.vmem=9779844kb resources_used.walltime=00:02:21
03/26/2013 10:32:10;0008;PBS_Server;Job;NULL;on_job_exit valid pjob: 0x2e74200 (substate=50)
03/26/2013 10:32:10;0008;PBS_Server;Job;NULL;on_job_exit valid pjob: 0x2e74200 (substate=51)
03/26/2013 10:32:14;0008;PBS_Server;Job;NULL;on_job_exit valid pjob: 0x2e74200 (substate=51)
03/26/2013 10:32:14;000d;PBS_Server;Job;20459.tyrone-cluster;Post job file processing error; job 20459.tyrone-cluster on host tyrone-node4/31+tyrone-node4/30+tyrone-node4/29+tyrone-node4/28+tyrone-node4/27+tyrone-node4/26+tyrone-node4/25+tyrone-node4/24+tyrone-node4/23+tyrone-node4/22+tyrone-node4/21+tyrone-node4/20+tyrone-node4/19+tyrone-node4/18+tyrone-node4/17+tyrone-node4/16+tyrone-node4/15+tyrone-node4/14+tyrone-node4/13+tyrone-node4/12+tyrone-node4/11+tyrone-node4/10+tyrone-node4/9+tyrone-node4/8+tyrone-node4/7+tyrone-node4/6+tyrone-node4/5+tyrone-node4/4+tyrone-node4/3+tyrone-node4/2+tyrone-node4/1+tyrone-node4/0
03/26/2013 10:32:14;0008;PBS_Server;Job;NULL;on_job_exit valid pjob: 0x2e74200 (substate=53)
03/26/2013 10:32:14;0100;PBS_Server;Job;20459.tyrone-cluster;dequeuing from qp32, state COMPLETE
03/26/2013 10:32:14;0040;PBS_Server;Svr;tyrone-cluster;Scheduler was sent the command term
03/26/2013 10:33:29;0002;PBS_Server;Svr;PBS_Server;Torque Server Version = 3.0.5, loglevel = 0
03/26/2013 10:34:00;000d;PBS_Server;Job;20460.tyrone-cluster;Not sending email: User does not want mail of this type.
03/26/2013 10:34:00;0010;PBS_Server;Job;20460.tyrone-cluster;Exit_status=0 resources_used.cput=02:04:39 resources_used.mem=1380284kb resources_used.vmem=9796044kb resources_used.walltime=00:04:04
03/26/2013 10:34:00;0008;PBS_Server;Job;NULL;on_job_exit valid pjob: 0x2e64c40 (substate=50)
03/26/2013 10:34:00;0008;PBS_Server;Job;NULL;on_job_exit valid pjob: 0x2e64c40 (substate=51)
03/26/2013 10:34:00;0008;PBS_Server;Job;NULL;on_job_exit valid pjob: 0x2e64c40 (substate=51)
03/26/2013 10:34:00;0008;PBS_Server;Job;NULL;on_job_exit valid pjob: 0x2e64c40 (substate=53)
03/26/2013 10:34:00;0100;PBS_Server;Job;20460.tyrone-cluster;dequeuing from idqueue, state COMPLETE
03/26/2013 10:34:00;0040;PBS_Server;Svr;tyrone-cluster;Scheduler was sent the command term
03/26/2013 10:37:00;0100;PBS_Server;Job;20461.tyrone-cluster;enqueuing into batch, state 1 hop 1
03/26/2013 10:37:00;0100;PBS_Server;Job;20461.tyrone-cluster;dequeuing from batch, state QUEUED
03/26/2013 10:37:00;0100;PBS_Server;Job;20461.tyrone-cluster;enqueuing into qp32, state 1 hop 1
03/26/2013 10:37:00;0008;PBS_Server;Job;20461.tyrone-cluster;Job Queued at request of metvura@tyrone-cluster, owner = metvura@tyrone-cluster, job name = vura1, queue = qp32
03/26/2013 10:37:00;0040;PBS_Server;Svr;tyrone-cluster;Scheduler was sent the command new
03/26/2013 10:37:00;0008;PBS_Server;Job;20461.tyrone-cluster;Job Modified at request of Scheduler@tyrone-cluster
03/26/2013 10:37:00;0008;PBS_Server;Job;20461.tyrone-cluster;Job Run at request of Scheduler@tyrone-cluster
03/26/2013 10:37:00;0040;PBS_Server;Svr;tyrone-cluster;Scheduler was sent the command recyc
03/26/2013 10:37:00;000d;PBS_Server;Job;20461.tyrone-cluster;Not sending email: User does not want mail of this type.
03/26/2013 10:38:06;0100;PBS_Server;Job;20462.tyrone-cluster;enqueuing into batch, state 1 hop 1
03/26/2013 10:38:06;0100;PBS_Server;Job;20462.tyrone-cluster;dequeuing from batch, state QUEUED
03/26/2013 10:38:06;0100;PBS_Server;Job;20462.tyrone-cluster;enqueuing into qp32, state 1 hop 1
03/26/2013 10:38:06;0008;PBS_Server;Job;20462.tyrone-cluster;Job Queued at request of metvura@tyrone-cluster, owner = metvura@tyrone-cluster, job name = vura1, queue = qp32
03/26/2013 10:38:06;0040;PBS_Server;Svr;tyrone-cluster;Scheduler was sent the command new
03/26/2013 10:38:06;0008;PBS_Server;Job;20462.tyrone-cluster;Job Modified at request of Scheduler@tyrone-cluster
03/26/2013 10:38:29;0002;PBS_Server;Svr;PBS_Server;Torque Server Version = 3.0.5, loglevel = 0
03/26/2013 10:43:29;0002;PBS_Server;Svr;PBS_Server;Torque Server Version = 3.0.5, loglevel = 0
03/26/2013 10:48:06;0040;PBS_Server;Svr;tyrone-cluster;Scheduler was sent the command time
03/26/2013 10:48:29;0002;PBS_Server;Svr;PBS_Server;Torque Server Version = 3.0.5, loglevel = 0
03/26/2013 10:49:24;0100;PBS_Server;Job;20463.tyrone-cluster;enqueuing into batch, state 1 hop 1
03/26/2013 10:49:24;0100;PBS_Server;Job;20463.tyrone-cluster;dequeuing from batch, state QUEUED
03/26/2013 10:49:24;0100;PBS_Server;Job;20463.tyrone-cluster;enqueuing into qp32, state 1 hop 1
03/26/2013 10:49:24;0008;PBS_Server;Job;20463.tyrone-cluster;Job Queued at request of metposhi@tyrone-cluster, owner = metposhi@tyrone-cluster, job name = poshit1, queue = qp32
03/26/2013 10:49:24;0040;PBS_Server;Svr;tyrone-cluster;Scheduler was sent the command new
03/26/2013 10:49:24;0008;PBS_Server;Job;20463.tyrone-cluster;Job Modified at request of Scheduler@tyrone-cluster
03/26/2013 10:49:24;0008;PBS_Server;Job;20463.tyrone-cluster;Job Run at request of Scheduler@tyrone-cluster
03/26/2013 10:49:24;0040;PBS_Server;Svr;tyrone-cluster;Scheduler was sent the command recyc
03/26/2013 10:49:24;000d;PBS_Server;Job;20463.tyrone-cluster;Not sending email: User does not want mail of this type.
03/26/2013 10:53:29;0002;PBS_Server;Svr;PBS_Server;Torque Server Version = 3.0.5, loglevel = 0
03/26/2013 10:57:34;000d;PBS_Server;Job;20463.tyrone-cluster;Not sending email: User does not want mail of this type.
03/26/2013 10:57:34;0010;PBS_Server;Job;20463.tyrone-cluster;Exit_status=0 resources_used.cput=04:02:49 resources_used.mem=1395036kb resources_used.vmem=9791448kb resources_used.walltime=00:08:10
03/26/2013 10:57:34;0008;PBS_Server;Job;NULL;on_job_exit valid pjob: 0x2e75510 (substate=50)
03/26/2013 10:57:34;0008;PBS_Server;Job;NULL;on_job_exit valid pjob: 0x2e75510 (substate=51)
03/26/2013 10:57:38;0008;PBS_Server;Job;NULL;on_job_exit valid pjob: 0x2e75510 (substate=51)
03/26/2013 10:57:38;000d;PBS_Server;Job;20463.tyrone-cluster;Post job file processing error; job 20463.tyrone-cluster on host tyrone-node5/31+tyrone-node5/30+tyrone-node5/29+tyrone-node5/28+tyrone-node5/27+tyrone-node5/26+tyrone-node5/25+tyrone-node5/24+tyrone-node5/23+tyrone-node5/22+tyrone-node5/21+tyrone-node5/20+tyrone-node5/19+tyrone-node5/18+tyrone-node5/17+tyrone-node5/16+tyrone-node5/15+tyrone-node5/14+tyrone-node5/13+tyrone-node5/12+tyrone-node5/11+tyrone-node5/10+tyrone-node5/9+tyrone-node5/8+tyrone-node5/7+tyrone-node5/6+tyrone-node5/5+tyrone-node5/4+tyrone-node5/3+tyrone-node5/2+tyrone-node5/1+tyrone-node5/0
03/26/2013 10:57:38;0008;PBS_Server;Job;NULL;on_job_exit valid pjob: 0x2e75510 (substate=53)
03/26/2013 10:57:38;0100;PBS_Server;Job;20463.tyrone-cluster;dequeuing from qp32, state COMPLETE
03/26/2013 10:57:38;0040;PBS_Server;Svr;tyrone-cluster;Scheduler was sent the command term
03/26/2013 10:58:29;0002;PBS_Server;Svr;PBS_Server;Torque Server Version = 3.0.5, loglevel = 0
03/26/2013 11:01:51;0100;PBS_Server;Job;20464.tyrone-cluster;enqueuing into batch, state 1 hop 1
03/26/2013 11:01:51;0100;PBS_Server;Job;20464.tyrone-cluster;dequeuing from batch, state QUEUED
03/26/2013 11:01:51;0100;PBS_Server;Job;20464.tyrone-cluster;enqueuing into qp32, state 1 hop 1
03/26/2013 11:01:51;0008;PBS_Server;Job;20464.tyrone-cluster;Job Queued at request of metposhi@tyrone-cluster, owner = metposhi@tyrone-cluster, job name = poshit1, queue = qp32
03/26/2013 11:01:51;0040;PBS_Server;Svr;tyrone-cluster;Scheduler was sent the command new
03/26/2013 11:01:51;0008;PBS_Server;Job;20464.tyrone-cluster;Job Modified at request of Scheduler@tyrone-cluster
03/26/2013 11:01:51;0008;PBS_Server;Job;20464.tyrone-cluster;Job Run at request of Scheduler@tyrone-cluster
03/26/2013 11:01:51;0040;PBS_Server;Svr;tyrone-cluster;Scheduler was sent the command recyc
03/26/2013 11:01:51;000d;PBS_Server;Job;20464.tyrone-cluster;Not sending email: User does not want mail of this type.
03/26/2013 11:03:29;0002;PBS_Server;Svr;PBS_Server;Torque Server Version = 3.0.5, loglevel = 0
03/26/2013 11:08:29;0002;PBS_Server;Svr;PBS_Server;Torque Server Version = 3.0.5, loglevel = 0
03/26/2013 11:11:51;0040;PBS_Server;Svr;tyrone-cluster;Scheduler was sent the command time
03/26/2013 11:12:26;0100;PBS_Server;Job;20465.tyrone-cluster;enqueuing into batch, state 1 hop 1
03/26/2013 11:12:26;0100;PBS_Server;Job;20465.tyrone-cluster;dequeuing from batch, state QUEUED
03/26/2013 11:12:26;0100;PBS_Server;Job;20465.tyrone-cluster;enqueuing into idqueue, state 1 hop 1
03/26/2013 11:12:26;0008;PBS_Server;Job;20465.tyrone-cluster;Job Queued at request of metvura@tyrone-cluster, owner = metvura@tyrone-cluster, job name = vura1, queue = idqueue
03/26/2013 11:12:26;0040;PBS_Server;Svr;tyrone-cluster;Scheduler was sent the command new
03/26/2013 11:12:26;0008;PBS_Server;Job;20465.tyrone-cluster;Job Modified at request of Scheduler@tyrone-cluster
03/26/2013 11:12:26;0008;PBS_Server;Job;20465.tyrone-cluster;Job Run at request of Scheduler@tyrone-cluster
03/26/2013 11:12:27;0040;PBS_Server;Svr;tyrone-cluster;Scheduler was sent the command recyc
03/26/2013 11:12:27;000d;PBS_Server;Job;20465.tyrone-cluster;Not sending email: User does not want mail of this type.
03/26/2013 11:13:29;0002;PBS_Server;Svr;PBS_Server;Torque Server Version = 3.0.5, loglevel = 0
03/26/2013 11:16:53;000d;PBS_Server;Job;20465.tyrone-cluster;Not sending email: User does not want mail of this type.
03/26/2013 11:16:53;0010;PBS_Server;Job;20465.tyrone-cluster;Exit_status=0 resources_used.cput=02:11:46 resources_used.mem=1371632kb resources_used.vmem=9789792kb resources_used.walltime=00:04:27
03/26/2013 11:16:53;0008;PBS_Server;Job;NULL;on_job_exit valid pjob: 0x2ec13f0 (substate=50)
03/26/2013 11:16:53;0008;PBS_Server;Job;NULL;on_job_exit valid pjob: 0x2ec13f0 (substate=51)
03/26/2013 11:16:53;0008;PBS_Server;Job;NULL;on_job_exit valid pjob: 0x2ec13f0 (substate=51)
03/26/2013 11:16:53;0008;PBS_Server;Job;NULL;on_job_exit valid pjob: 0x2ec13f0 (substate=53)
03/26/2013 11:16:53;0100;PBS_Server;Job;20465.tyrone-cluster;dequeuing from idqueue, state COMPLETE
03/26/2013 11:16:53;0040;PBS_Server;Svr;tyrone-cluster;Scheduler was sent the command term
03/26/2013 11:18:29;0002;PBS_Server;Svr;PBS_Server;Torque Server Version = 3.0.5, loglevel = 0
03/26/2013 11:20:50;0100;PBS_Server;Job;20466.tyrone-cluster;enqueuing into batch, state 1 hop 1
03/26/2013 11:20:50;0100;PBS_Server;Job;20466.tyrone-cluster;dequeuing from batch, state QUEUED
03/26/2013 11:20:50;0100;PBS_Server;Job;20466.tyrone-cluster;enqueuing into qp32, state 1 hop 1
03/26/2013 11:20:50;0008;PBS_Server;Job;20466.tyrone-cluster;Job Queued at request of asealama@tyrone-cluster, owner = asealama@tyrone-cluster, job name = jobname, queue = qp32
03/26/2013 11:20:50;0040;PBS_Server;Svr;tyrone-cluster;Scheduler was sent the command new
03/26/2013 11:20:50;0008;PBS_Server;Job;20466.tyrone-cluster;Job Modified at request of Scheduler@tyrone-cluster
03/26/2013 11:20:50;0008;PBS_Server;Job;20466.tyrone-cluster;Job Run at request of Scheduler@tyrone-cluster
03/26/2013 11:20:50;0040;PBS_Server;Svr;tyrone-cluster;Scheduler was sent the command recyc
03/26/2013 11:20:50;000d;PBS_Server;Job;20466.tyrone-cluster;Not sending email: User does not want mail of this type.
03/26/2013 11:21:00;000d;PBS_Server;Job;20466.tyrone-cluster;Not sending email: User does not want mail of this type.
03/26/2013 11:21:00;0010;PBS_Server;Job;20466.tyrone-cluster;Exit_status=0 resources_used.cput=00:00:02 resources_used.mem=0kb resources_used.vmem=0kb resources_used.walltime=00:00:10
03/26/2013 11:21:00;0008;PBS_Server;Job;NULL;on_job_exit valid pjob: 0x2ec13f0 (substate=50)
03/26/2013 11:21:00;0008;PBS_Server;Job;NULL;on_job_exit valid pjob: 0x2ec13f0 (substate=51)
03/26/2013 11:21:00;0008;PBS_Server;Job;NULL;on_job_exit valid pjob: 0x2ec13f0 (substate=51)
03/26/2013 11:21:00;0008;PBS_Server;Job;NULL;on_job_exit valid pjob: 0x2ec13f0 (substate=53)
03/26/2013 11:21:00;0100;PBS_Server;Job;20466.tyrone-cluster;dequeuing from qp32, state COMPLETE
03/26/2013 11:21:00;0040;PBS_Server;Svr;tyrone-cluster;Scheduler was sent the command term
03/26/2013 11:21:57;0100;PBS_Server;Job;20467.tyrone-cluster;enqueuing into batch, state 1 hop 1
03/26/2013 11:21:57;0008;PBS_Server;Job;20467.tyrone-cluster;Job Queued at request of metvura@tyrone-cluster, owner = metvura@tyrone-cluster, job name = vura1, queue = batch
03/26/2013 11:21:57;0040;PBS_Server;Svr;tyrone-cluster;Scheduler was sent the command new
03/26/2013 11:21:57;0008;PBS_Server;Job;20467.tyrone-cluster;Job Modified at request of Scheduler@tyrone-cluster
03/26/2013 11:22:07;0008;PBS_Server;Job;20467.tyrone-cluster;Job deleted at request of metvura@tyrone-cluster
03/26/2013 11:22:07;0008;PBS_Server;Job;NULL;on_job_exit valid pjob: 0x2ec13f0 (substate=59)
03/26/2013 11:22:07;0100;PBS_Server;Job;20467.tyrone-cluster;dequeuing from batch, state COMPLETE
03/26/2013 11:22:07;0040;PBS_Server;Svr;tyrone-cluster;Scheduler was sent the command term
03/26/2013 11:22:39;0100;PBS_Server;Job;20468.tyrone-cluster;enqueuing into batch, state 1 hop 1
03/26/2013 11:22:39;0100;PBS_Server;Job;20468.tyrone-cluster;dequeuing from batch, state QUEUED
03/26/2013 11:22:39;0100;PBS_Server;Job;20468.tyrone-cluster;enqueuing into idqueue, state 1 hop 1
03/26/2013 11:22:39;0008;PBS_Server;Job;20468.tyrone-cluster;Job Queued at request of mrcaks@tyrone-cluster, owner = mrcaks@tyrone-cluster, job name = Sc_B6_5_7H2, queue = idqueue
03/26/2013 11:22:39;0040;PBS_Server;Svr;tyrone-cluster;Scheduler was sent the command new
03/26/2013 11:22:39;0008;PBS_Server;Job;20468.tyrone-cluster;Job Modified at request of Scheduler@tyrone-cluster
03/26/2013 11:22:39;0008;PBS_Server;Job;20468.tyrone-cluster;Job Run at request of Scheduler@tyrone-cluster
03/26/2013 11:22:39;0040;PBS_Server;Svr;tyrone-cluster;Scheduler was sent the command recyc
03/26/2013 11:22:39;000d;PBS_Server;Job;20468.tyrone-cluster;Not sending email: User does not want mail of this type.
03/26/2013 11:23:29;0002;PBS_Server;Svr;PBS_Server;Torque Server Version = 3.0.5, loglevel = 0
03/26/2013 11:28:29;0002;PBS_Server;Svr;PBS_Server;Torque Server Version = 3.0.5, loglevel = 0
03/26/2013 11:32:38;0100;PBS_Server;Job;20469.tyrone-cluster;enqueuing into batch, state 1 hop 1
03/26/2013 11:32:38;0008;PBS_Server;Job;20469.tyrone-cluster;Job Queued at request of metvura@tyrone-cluster, owner = metvura@tyrone-cluster, job name = vura1, queue = batch
03/26/2013 11:32:38;0040;PBS_Server;Svr;tyrone-cluster;Scheduler was sent the command new
03/26/2013 11:32:38;0008;PBS_Server;Job;20469.tyrone-cluster;Job Modified at request of Scheduler@tyrone-cluster
03/26/2013 11:33:09;0040;PBS_Server;Svr;tyrone-cluster;Scheduler was sent the command new
03/26/2013 11:33:29;0002;PBS_Server;Svr;PBS_Server;Torque Server Version = 3.0.5, loglevel = 0
03/26/2013 11:33:40;0040;PBS_Server;Svr;tyrone-cluster;Scheduler was sent the command new
03/26/2013 11:34:10;0040;PBS_Server;Svr;tyrone-cluster;Scheduler was sent the command new
03/26/2013 11:34:42;0040;PBS_Server;Svr;tyrone-cluster;Scheduler was sent the command new
03/26/2013 11:35:13;0040;PBS_Server;Svr;tyrone-cluster;Scheduler was sent the command new
03/26/2013 11:35:45;0040;PBS_Server;Svr;tyrone-cluster;Scheduler was sent the command new
03/26/2013 11:36:05;0100;PBS_Server;Job;20470.tyrone-cluster;enqueuing into batch, state 1 hop 1
03/26/2013 11:36:05;0100;PBS_Server;Job;20470.tyrone-cluster;dequeuing from batch, state QUEUED
03/26/2013 11:36:05;0100;PBS_Server;Job;20470.tyrone-cluster;enqueuing into idqueue, state 1 hop 1
03/26/2013 11:36:05;0008;PBS_Server;Job;20470.tyrone-cluster;Job Queued at request of mrcaks@tyrone-cluster, owner = mrcaks@tyrone-cluster, job name = Bader_Sc_B6, queue = idqueue
03/26/2013 11:36:05;0040;PBS_Server;Svr;tyrone-cluster;Scheduler was sent the command new
03/26/2013 11:36:05;0008;PBS_Server;Job;20470.tyrone-cluster;Job Modified at request of Scheduler@tyrone-cluster
03/26/2013 11:36:05;0008;PBS_Server;Job;20470.tyrone-cluster;Job Run at request of Scheduler@tyrone-cluster
03/26/2013 11:36:05;0040;PBS_Server;Svr;tyrone-cluster;Scheduler was sent the command recyc
03/26/2013 11:36:05;000d;PBS_Server;Job;20470.tyrone-cluster;Not sending email: User does not want mail of this type.
03/26/2013 11:36:13;0040;PBS_Server;Svr;tyrone-cluster;Scheduler was sent the command new
03/26/2013 11:36:46;0040;PBS_Server;Svr;tyrone-cluster;Scheduler was sent the command new
03/26/2013 11:37:15;0040;PBS_Server;Svr;tyrone-cluster;Scheduler was sent the command new
03/26/2013 11:37:36;0100;PBS_Server;Job;20471.tyrone-cluster;enqueuing into batch, state 1 hop 1
03/26/2013 11:37:36;0100;PBS_Server;Job;20471.tyrone-cluster;dequeuing from batch, state QUEUED
03/26/2013 11:37:36;0100;PBS_Server;Job;20471.tyrone-cluster;enqueuing into idqueue, state 1 hop 1
03/26/2013 11:37:36;0008;PBS_Server;Job;20471.tyrone-cluster;Job Queued at request of mrcaks@tyrone-cluster, owner = mrcaks@tyrone-cluster, job name = Bader_Sc_B5_N, queue = idqueue
03/26/2013 11:37:36;0040;PBS_Server;Svr;tyrone-cluster;Scheduler was sent the command new
03/26/2013 11:37:36;0008;PBS_Server;Job;20471.tyrone-cluster;Job Modified at request of Scheduler@tyrone-cluster
03/26/2013 11:37:45;0040;PBS_Server;Svr;tyrone-cluster;Scheduler was sent the command new
03/26/2013 11:38:18;0040;PBS_Server;Svr;tyrone-cluster;Scheduler was sent the command new
03/26/2013 11:38:29;0002;PBS_Server;Svr;PBS_Server;Torque Server Version = 3.0.5, loglevel = 0
03/26/2013 11:38:37;0100;PBS_Server;Job;20472.tyrone-cluster;enqueuing into batch, state 1 hop 1
03/26/2013 11:38:37;0100;PBS_Server;Job;20472.tyrone-cluster;dequeuing from batch, state QUEUED
03/26/2013 11:38:37;0100;PBS_Server;Job;20472.tyrone-cluster;enqueuing into idqueue, state 1 hop 1
03/26/2013 11:38:37;0008;PBS_Server;Job;20472.tyrone-cluster;Job Queued at request of mrcaks@tyrone-cluster, owner = mrcaks@tyrone-cluster, job name = Bader_Sc_B5_P, queue = idqueue
03/26/2013 11:38:37;0040;PBS_Server;Svr;tyrone-cluster;Scheduler was sent the command new
03/26/2013 11:38:37;0008;PBS_Server;Job;20472.tyrone-cluster;Job Modified at request of Scheduler@tyrone-cluster
03/26/2013 11:38:46;0040;PBS_Server;Svr;tyrone-cluster;Scheduler was sent the command new
03/26/2013 11:39:10;0100;PBS_Server;Job;20473.tyrone-cluster;enqueuing into batch, state 1 hop 1
03/26/2013 11:39:10;0100;PBS_Server;Job;20473.tyrone-cluster;dequeuing from batch, state QUEUED
03/26/2013 11:39:10;0100;PBS_Server;Job;20473.tyrone-cluster;enqueuing into idqueue, state 1 hop 1
03/26/2013 11:39:10;0008;PBS_Server;Job;20473.tyrone-cluster;Job Queued at request of mrcaks@tyrone-cluster, owner = mrcaks@tyrone-cluster, job name = Bader_Sc_B5_S, queue = idqueue
03/26/2013 11:39:10;0040;PBS_Server;Svr;tyrone-cluster;Scheduler was sent the command new
03/26/2013 11:39:10;0008;PBS_Server;Job;20473.tyrone-cluster;Job Modified at request of Scheduler@tyrone-cluster
03/26/2013 11:39:22;0040;PBS_Server;Svr;tyrone-cluster;Scheduler was sent the command new
03/26/2013 11:39:53;0040;PBS_Server;Svr;tyrone-cluster;Scheduler was sent the command new
03/26/2013 11:40:23;0040;PBS_Server;Svr;tyrone-cluster;Scheduler was sent the command new
03/26/2013 11:40:55;0040;PBS_Server;Svr;tyrone-cluster;Scheduler was sent the command new
03/26/2013 11:41:28;0040;PBS_Server;Svr;tyrone-cluster;Scheduler was sent the command new
03/26/2013 11:42:01;0040;PBS_Server;Svr;tyrone-cluster;Scheduler was sent the command new
03/26/2013 11:42:30;0040;PBS_Server;Svr;tyrone-cluster;Scheduler was sent the command new
03/26/2013 11:43:00;0040;PBS_Server;Svr;tyrone-cluster;Scheduler was sent the command new
03/26/2013 11:43:29;0002;PBS_Server;Svr;PBS_Server;Torque Server Version = 3.0.5, loglevel = 0
03/26/2013 11:43:33;0040;PBS_Server;Svr;tyrone-cluster;Scheduler was sent the command new
03/26/2013 11:44:01;0040;PBS_Server;Svr;tyrone-cluster;Scheduler was sent the command new
03/26/2013 11:44:37;0040;PBS_Server;Svr;tyrone-cluster;Scheduler was sent the command new
03/26/2013 11:45:09;0040;PBS_Server;Svr;tyrone-cluster;Scheduler was sent the command new
03/26/2013 11:45:38;0040;PBS_Server;Svr;tyrone-cluster;Scheduler was sent the command new
03/26/2013 11:45:54;0100;PBS_Server;Job;20474.tyrone-cluster;enqueuing into batch, state 1 hop 1
03/26/2013 11:45:54;0100;PBS_Server;Job;20474.tyrone-cluster;dequeuing from batch, state QUEUED
03/26/2013 11:45:54;0100;PBS_Server;Job;20474.tyrone-cluster;enqueuing into qp32, state 1 hop 1
03/26/2013 11:45:54;0008;PBS_Server;Job;20474.tyrone-cluster;Job Queued at request of asealama@tyrone-cluster, owner = asealama@tyrone-cluster, job name = jobname, queue = qp32
03/26/2013 11:45:54;0040;PBS_Server;Svr;tyrone-cluster;Scheduler was sent the command new
03/26/2013 11:45:55;0008;PBS_Server;Job;20474.tyrone-cluster;Job Modified at request of Scheduler@tyrone-cluster
03/26/2013 11:45:55;0008;PBS_Server;Job;20474.tyrone-cluster;Job Run at request of Scheduler@tyrone-cluster
03/26/2013 11:45:55;0040;PBS_Server;Svr;tyrone-cluster;Scheduler was sent the command recyc
03/26/2013 11:45:55;000d;PBS_Server;Job;20474.tyrone-cluster;Not sending email: User does not want mail of this type.
03/26/2013 11:46:10;0040;PBS_Server;Svr;tyrone-cluster;Scheduler was sent the command new
03/26/2013 11:46:43;0040;PBS_Server;Svr;tyrone-cluster;Scheduler was sent the command new
03/26/2013 11:47:16;0040;PBS_Server;Svr;tyrone-cluster;Scheduler was sent the command new
03/26/2013 11:47:45;0040;PBS_Server;Svr;tyrone-cluster;Scheduler was sent the command new
03/26/2013 11:48:15;0040;PBS_Server;Svr;tyrone-cluster;Scheduler was sent the command new
03/26/2013 11:48:29;0002;PBS_Server;Svr;PBS_Server;Torque Server Version = 3.0.5, loglevel = 0
03/26/2013 11:48:48;0040;PBS_Server;Svr;tyrone-cluster;Scheduler was sent the command new
03/26/2013 11:49:16;0040;PBS_Server;Svr;tyrone-cluster;Scheduler was sent the command new
03/26/2013 11:49:52;0040;PBS_Server;Svr;tyrone-cluster;Scheduler was sent the command new
03/26/2013 11:50:23;0040;PBS_Server;Svr;tyrone-cluster;Scheduler was sent the command new
03/26/2013 11:50:53;0040;PBS_Server;Svr;tyrone-cluster;Scheduler was sent the command new
03/26/2013 11:51:25;0040;PBS_Server;Svr;tyrone-cluster;Scheduler was sent the command new
03/26/2013 11:51:58;0040;PBS_Server;Svr;tyrone-cluster;Scheduler was sent the command new
03/26/2013 11:52:28;0040;PBS_Server;Svr;tyrone-cluster;Scheduler was sent the command new
03/26/2013 11:53:00;0040;PBS_Server;Svr;tyrone-cluster;Scheduler was sent the command new
03/26/2013 11:53:28;0040;PBS_Server;Svr;tyrone-cluster;Scheduler was sent the command new
03/26/2013 11:53:29;0002;PBS_Server;Svr;PBS_Server;Torque Server Version = 3.0.5, loglevel = 0
03/26/2013 11:54:01;0040;PBS_Server;Svr;tyrone-cluster;Scheduler was sent the command new
03/26/2013 11:54:30;0040;PBS_Server;Svr;tyrone-cluster;Scheduler was sent the command new
03/26/2013 11:55:00;0040;PBS_Server;Svr;tyrone-cluster;Scheduler was sent the command new
03/26/2013 11:55:33;0040;PBS_Server;Svr;tyrone-cluster;Scheduler was sent the command new
03/26/2013 11:56:01;0040;PBS_Server;Svr;tyrone-cluster;Scheduler was sent the command new
03/26/2013 11:56:37;0040;PBS_Server;Svr;tyrone-cluster;Scheduler was sent the command new
03/26/2013 11:57:08;0040;PBS_Server;Svr;tyrone-cluster;Scheduler was sent the command new
03/26/2013 11:57:38;0040;PBS_Server;Svr;tyrone-cluster;Scheduler was sent the command new
03/26/2013 11:58:10;0040;PBS_Server;Svr;tyrone-cluster;Scheduler was sent the command new
03/26/2013 11:58:29;0002;PBS_Server;Svr;PBS_Server;Torque Server Version = 3.0.5, loglevel = 0
03/26/2013 11:58:43;0040;PBS_Server;Svr;tyrone-cluster;Scheduler was sent the command new
03/26/2013 11:59:16;0040;PBS_Server;Svr;tyrone-cluster;Scheduler was sent the command new
03/26/2013 11:59:45;0040;PBS_Server;Svr;tyrone-cluster;Scheduler was sent the command new
03/26/2013 12:00:15;0040;PBS_Server;Svr;tyrone-cluster;Scheduler was sent the command new
03/26/2013 12:00:48;0040;PBS_Server;Svr;tyrone-cluster;Scheduler was sent the command new
03/26/2013 12:01:16;0040;PBS_Server;Svr;tyrone-cluster;Scheduler was sent the command new
03/26/2013 12:01:52;0040;PBS_Server;Svr;tyrone-cluster;Scheduler was sent the command new
03/26/2013 12:02:23;0040;PBS_Server;Svr;tyrone-cluster;Scheduler was sent the command new
03/26/2013 12:02:53;0040;PBS_Server;Svr;tyrone-cluster;Scheduler was sent the command new
03/26/2013 12:03:25;0040;PBS_Server;Svr;tyrone-cluster;Scheduler was sent the command new
03/26/2013 12:03:29;0002;PBS_Server;Svr;PBS_Server;Torque Server Version = 3.0.5, loglevel = 0
03/26/2013 12:03:54;0040;PBS_Server;Svr;tyrone-cluster;Scheduler was sent the command new
03/26/2013 12:04:25;0040;PBS_Server;Svr;tyrone-cluster;Scheduler was sent the command new
03/26/2013 12:04:55;0040;PBS_Server;Svr;tyrone-cluster;Scheduler was sent the command new
03/26/2013 12:05:05;0100;PBS_Server;Job;20475.tyrone-cluster;enqueuing into batch, state 1 hop 1
03/26/2013 12:05:05;0100;PBS_Server;Job;20475.tyrone-cluster;dequeuing from batch, state QUEUED
03/26/2013 12:05:05;0100;PBS_Server;Job;20475.tyrone-cluster;enqueuing into qp64, state 1 hop 1
03/26/2013 12:05:05;0008;PBS_Server;Job;20475.tyrone-cluster;Job Queued at request of mrcpndey@tyrone-cluster, owner = mrcpndey@tyrone-cluster, job name = GO-3, queue = qp64
03/26/2013 12:05:05;0040;PBS_Server;Svr;tyrone-cluster;Scheduler was sent the command new
03/26/2013 12:05:05;0008;PBS_Server;Job;20475.tyrone-cluster;Job Modified at request of Scheduler@tyrone-cluster
03/26/2013 12:05:07;0100;PBS_Server;Job;20476.tyrone-cluster;enqueuing into batch, state 1 hop 1
03/26/2013 12:05:07;0100;PBS_Server;Job;20476.tyrone-cluster;dequeuing from batch, state QUEUED
03/26/2013 12:05:07;0100;PBS_Server;Job;20476.tyrone-cluster;enqueuing into qp64, state 1 hop 1
03/26/2013 12:05:07;0008;PBS_Server;Job;20476.tyrone-cluster;Job Queued at request of mrcpndey@tyrone-cluster, owner = mrcpndey@tyrone-cluster, job name = GO-4, queue = qp64
03/26/2013 12:05:07;0040;PBS_Server;Svr;tyrone-cluster;Scheduler was sent the command new
03/26/2013 12:05:07;0008;PBS_Server;Job;20476.tyrone-cluster;Job Modified at request of Scheduler@tyrone-cluster
03/26/2013 12:05:09;0100;PBS_Server;Job;20477.tyrone-cluster;enqueuing into batch, state 1 hop 1
03/26/2013 12:05:09;0100;PBS_Server;Job;20477.tyrone-cluster;dequeuing from batch, state QUEUED
03/26/2013 12:05:09;0100;PBS_Server;Job;20477.tyrone-cluster;enqueuing into qp64, state 1 hop 1
03/26/2013 12:05:09;0008;PBS_Server;Job;20477.tyrone-cluster;Job Queued at request of mrcpndey@tyrone-cluster, owner = mrcpndey@tyrone-cluster, job name = GO-5, queue = qp64
03/26/2013 12:05:09;0040;PBS_Server;Svr;tyrone-cluster;Scheduler was sent the command new
03/26/2013 12:05:09;0008;PBS_Server;Job;20477.tyrone-cluster;Job Modified at request of Scheduler@tyrone-cluster
03/26/2013 12:05:10;0100;PBS_Server;Job;20478.tyrone-cluster;enqueuing into batch, state 1 hop 1
03/26/2013 12:05:10;0008;PBS_Server;Job;20478.tyrone-cluster;Job Queued at request of mrcpndey@tyrone-cluster, owner = mrcpndey@tyrone-cluster, job name = GO-7, queue = batch
03/26/2013 12:05:10;0040;PBS_Server;Svr;tyrone-cluster;Scheduler was sent the command new
03/26/2013 12:05:10;0008;PBS_Server;Job;20478.tyrone-cluster;Job Modified at request of Scheduler@tyrone-cluster
03/26/2013 12:05:28;0040;PBS_Server;Svr;tyrone-cluster;Scheduler was sent the command new
03/26/2013 12:05:40;0040;PBS_Server;Svr;tyrone-cluster;Scheduler was sent the command new
03/26/2013 12:06:01;0040;PBS_Server;Svr;tyrone-cluster;Scheduler was sent the command new
03/26/2013 12:06:13;0040;PBS_Server;Svr;tyrone-cluster;Scheduler was sent the command new
03/26/2013 12:06:30;0040;PBS_Server;Svr;tyrone-cluster;Scheduler was sent the command new
03/26/2013 12:06:46;0040;PBS_Server;Svr;tyrone-cluster;Scheduler was sent the command new
03/26/2013 12:07:00;0040;PBS_Server;Svr;tyrone-cluster;Scheduler was sent the command new
03/26/2013 12:07:15;0040;PBS_Server;Svr;tyrone-cluster;Scheduler was sent the command new
03/26/2013 12:07:33;0040;PBS_Server;Svr;tyrone-cluster;Scheduler was sent the command new
03/26/2013 12:07:45;0040;PBS_Server;Svr;tyrone-cluster;Scheduler was sent the command new
03/26/2013 12:08:01;0040;PBS_Server;Svr;tyrone-cluster;Scheduler was sent the command new
03/26/2013 12:08:18;0040;PBS_Server;Svr;tyrone-cluster;Scheduler was sent the command new
03/26/2013 12:08:29;0002;PBS_Server;Svr;PBS_Server;Torque Server Version = 3.0.5, loglevel = 0
03/26/2013 12:08:37;0040;PBS_Server;Svr;tyrone-cluster;Scheduler was sent the command new
03/26/2013 12:08:46;0040;PBS_Server;Svr;tyrone-cluster;Scheduler was sent the command new
03/26/2013 12:09:08;0040;PBS_Server;Svr;tyrone-cluster;Scheduler was sent the command new
03/26/2013 12:09:22;0040;PBS_Server;Svr;tyrone-cluster;Scheduler was sent the command new
03/26/2013 12:09:23;000d;PBS_Server;Job;20470.tyrone-cluster;Not sending email: User does not want mail of this type.
03/26/2013 12:09:23;0010;PBS_Server;Job;20470.tyrone-cluster;Exit_status=0 resources_used.cput=08:50:37 resources_used.mem=17153084kb resources_used.vmem=36932692kb resources_used.walltime=00:33:18
03/26/2013 12:09:23;0008;PBS_Server;Job;NULL;on_job_exit valid pjob: 0x2e788e0 (substate=50)
03/26/2013 12:09:23;0008;PBS_Server;Job;NULL;on_job_exit valid pjob: 0x2e788e0 (substate=51)
03/26/2013 12:09:23;0008;PBS_Server;Job;NULL;on_job_exit valid pjob: 0x2e788e0 (substate=51)
03/26/2013 12:09:23;0008;PBS_Server;Job;NULL;on_job_exit valid pjob: 0x2e788e0 (substate=53)
03/26/2013 12:09:23;0100;PBS_Server;Job;20470.tyrone-cluster;dequeuing from idqueue, state COMPLETE
03/26/2013 12:09:23;0040;PBS_Server;Svr;tyrone-cluster;Scheduler was sent the command term
03/26/2013 12:09:23;0008;PBS_Server;Job;20471.tyrone-cluster;Job Modified at request of Scheduler@tyrone-cluster
03/26/2013 12:09:23;0008;PBS_Server;Job;20471.tyrone-cluster;Job Run at request of Scheduler@tyrone-cluster
03/26/2013 12:09:24;0040;PBS_Server;Svr;tyrone-cluster;Scheduler was sent the command recyc
03/26/2013 12:09:24;000d;PBS_Server;Job;20471.tyrone-cluster;Not sending email: User does not want mail of this type.
03/26/2013 12:09:38;0040;PBS_Server;Svr;tyrone-cluster;Scheduler was sent the command new
03/26/2013 12:09:53;0040;PBS_Server;Svr;tyrone-cluster;Scheduler was sent the command new
03/26/2013 12:10:10;0040;PBS_Server;Svr;tyrone-cluster;Scheduler was sent the command new
03/26/2013 12:10:23;0040;PBS_Server;Svr;tyrone-cluster;Scheduler was sent the command new
03/26/2013 12:10:44;0040;PBS_Server;Svr;tyrone-cluster;Scheduler was sent the command new
03/26/2013 12:10:55;0040;PBS_Server;Svr;tyrone-cluster;Scheduler was sent the command new
03/26/2013 12:11:18;0040;PBS_Server;Svr;tyrone-cluster;Scheduler was sent the command new
03/26/2013 12:11:28;0040;PBS_Server;Svr;tyrone-cluster;Scheduler was sent the command new
03/26/2013 12:11:46;0040;PBS_Server;Svr;tyrone-cluster;Scheduler was sent the command new
03/26/2013 12:11:58;0040;PBS_Server;Svr;tyrone-cluster;Scheduler was sent the command new
03/26/2013 12:12:22;0040;PBS_Server;Svr;tyrone-cluster;Scheduler was sent the command new
03/26/2013 12:12:30;0040;PBS_Server;Svr;tyrone-cluster;Scheduler was sent the command new
03/26/2013 12:12:53;0040;PBS_Server;Svr;tyrone-cluster;Scheduler was sent the command new
03/26/2013 12:13:00;0040;PBS_Server;Svr;tyrone-cluster;Scheduler was sent the command new
03/26/2013 12:13:23;0040;PBS_Server;Svr;tyrone-cluster;Scheduler was sent the command new
03/26/2013 12:13:29;0002;PBS_Server;Svr;PBS_Server;Torque Server Version = 3.0.5, loglevel = 0
03/26/2013 12:13:32;0040;PBS_Server;Svr;tyrone-cluster;Scheduler was sent the command new
03/26/2013 12:13:55;0040;PBS_Server;Svr;tyrone-cluster;Scheduler was sent the command new
03/26/2013 12:14:00;0040;PBS_Server;Svr;tyrone-cluster;Scheduler was sent the command new
03/26/2013 12:14:28;0040;PBS_Server;Svr;tyrone-cluster;Scheduler was sent the command new
03/26/2013 12:14:30;0040;PBS_Server;Svr;tyrone-cluster;Scheduler was sent the command new
03/26/2013 12:14:58;0040;PBS_Server;Svr;tyrone-cluster;Scheduler was sent the command new
03/26/2013 12:15:03;0040;PBS_Server;Svr;tyrone-cluster;Scheduler was sent the command new
03/26/2013 12:15:30;0040;PBS_Server;Svr;tyrone-cluster;Scheduler was sent the command new
03/26/2013 12:15:31;0040;PBS_Server;Svr;tyrone-cluster;Scheduler was sent the command new
03/26/2013 12:16:00;0040;PBS_Server;Svr;tyrone-cluster;Scheduler was sent the command new
03/26/2013 12:16:07;0040;PBS_Server;Svr;tyrone-cluster;Scheduler was sent the command new
03/26/2013 12:16:32;0040;PBS_Server;Svr;tyrone-cluster;Scheduler was sent the command new
03/26/2013 12:16:38;0040;PBS_Server;Svr;tyrone-cluster;Scheduler was sent the command new
03/26/2013 12:17:00;0040;PBS_Server;Svr;tyrone-cluster;Scheduler was sent the command new
03/26/2013 12:17:08;0040;PBS_Server;Svr;tyrone-cluster;Scheduler was sent the command new
03/26/2013 12:17:30;0040;PBS_Server;Svr;tyrone-cluster;Scheduler was sent the command new
03/26/2013 12:17:40;0040;PBS_Server;Svr;tyrone-cluster;Scheduler was sent the command new
03/26/2013 12:18:03;0040;PBS_Server;Svr;tyrone-cluster;Scheduler was sent the command new
03/26/2013 12:18:13;0040;PBS_Server;Svr;tyrone-cluster;Scheduler was sent the command new
03/26/2013 12:18:29;0002;PBS_Server;Svr;PBS_Server;Torque Server Version = 3.0.5, loglevel = 0
03/26/2013 12:18:31;0040;PBS_Server;Svr;tyrone-cluster;Scheduler was sent the command new
03/26/2013 12:18:43;0040;PBS_Server;Svr;tyrone-cluster;Scheduler was sent the command new
03/26/2013 12:19:07;0040;PBS_Server;Svr;tyrone-cluster;Scheduler was sent the command new
03/26/2013 12:19:15;0040;PBS_Server;Svr;tyrone-cluster;Scheduler was sent the command new
03/26/2013 12:19:38;0040;PBS_Server;Svr;tyrone-cluster;Scheduler was sent the command new
03/26/2013 12:19:45;0040;PBS_Server;Svr;tyrone-cluster;Scheduler was sent the command new
03/26/2013 12:20:08;0040;PBS_Server;Svr;tyrone-cluster;Scheduler was sent the command new
03/26/2013 12:20:18;0040;PBS_Server;Svr;tyrone-cluster;Scheduler was sent the command new
03/26/2013 12:20:40;0040;PBS_Server;Svr;tyrone-cluster;Scheduler was sent the command new
03/26/2013 12:20:45;0040;PBS_Server;Svr;tyrone-cluster;Scheduler was sent the command new
03/26/2013 12:21:13;0040;PBS_Server;Svr;tyrone-cluster;Scheduler was sent the command new
03/26/2013 12:21:15;0040;PBS_Server;Svr;tyrone-cluster;Scheduler was sent the command new
03/26/2013 12:21:43;0040;PBS_Server;Svr;tyrone-cluster;Scheduler was sent the command new
03/26/2013 12:21:47;0040;PBS_Server;Svr;tyrone-cluster;Scheduler was sent the command new
03/26/2013 12:22:15;0040;PBS_Server;Svr;tyrone-cluster;Scheduler was sent the command new
03/26/2013 12:22:45;0040;PBS_Server;Svr;tyrone-cluster;Scheduler was sent the command new
03/26/2013 12:23:17;0040;PBS_Server;Svr;tyrone-cluster;Scheduler was sent the command new
03/26/2013 12:23:29;0002;PBS_Server;Svr;PBS_Server;Torque Server Version = 3.0.5, loglevel = 0
03/26/2013 12:23:45;0040;PBS_Server;Svr;tyrone-cluster;Scheduler was sent the command new
03/26/2013 12:24:15;0040;PBS_Server;Svr;tyrone-cluster;Scheduler was sent the command new
03/26/2013 12:24:48;0040;PBS_Server;Svr;tyrone-cluster;Scheduler was sent the command new
03/26/2013 12:25:16;0040;PBS_Server;Svr;tyrone-cluster;Scheduler was sent the command new
03/26/2013 12:25:52;0040;PBS_Server;Svr;tyrone-cluster;Scheduler was sent the command new
03/26/2013 12:25:53;000d;PBS_Server;Job;20450.tyrone-cluster;Not sending email: User does not want mail of this type.
03/26/2013 12:25:53;0010;PBS_Server;Job;20450.tyrone-cluster;Exit_status=0 resources_used.cput=144:30:18 resources_used.mem=1473856kb resources_used.vmem=9856632kb resources_used.walltime=04:43:46
03/26/2013 12:25:53;0008;PBS_Server;Job;NULL;on_job_exit valid pjob: 0x2e37f20 (substate=50)
03/26/2013 12:25:53;0008;PBS_Server;Job;NULL;on_job_exit valid pjob: 0x2e37f20 (substate=51)
03/26/2013 12:25:58;0008;PBS_Server;Job;NULL;on_job_exit valid pjob: 0x2e37f20 (substate=51)
03/26/2013 12:25:58;000d;PBS_Server;Job;20450.tyrone-cluster;Post job file processing error; job 20450.tyrone-cluster on host tyrone-node2/31+tyrone-node2/30+tyrone-node2/29+tyrone-node2/28+tyrone-node2/27+tyrone-node2/26+tyrone-node2/25+tyrone-node2/24+tyrone-node2/23+tyrone-node2/22+tyrone-node2/21+tyrone-node2/20+tyrone-node2/19+tyrone-node2/18+tyrone-node2/17+tyrone-node2/16+tyrone-node2/15+tyrone-node2/14+tyrone-node2/13+tyrone-node2/12+tyrone-node2/11+tyrone-node2/10+tyrone-node2/9+tyrone-node2/8+tyrone-node2/7+tyrone-node2/6+tyrone-node2/5+tyrone-node2/4+tyrone-node2/3+tyrone-node2/2+tyrone-node2/1+tyrone-node2/0
03/26/2013 12:25:58;0008;PBS_Server;Job;NULL;on_job_exit valid pjob: 0x2e37f20 (substate=53)
03/26/2013 12:25:58;0100;PBS_Server;Job;20450.tyrone-cluster;dequeuing from qp32, state COMPLETE
03/26/2013 12:25:58;0040;PBS_Server;Svr;tyrone-cluster;Scheduler was sent the command term
03/26/2013 12:25:58;0008;PBS_Server;Job;20462.tyrone-cluster;Job Modified at request of Scheduler@tyrone-cluster
03/26/2013 12:25:58;0008;PBS_Server;Job;20462.tyrone-cluster;Job Run at request of Scheduler@tyrone-cluster
03/26/2013 12:25:58;0040;PBS_Server;Svr;tyrone-cluster;Scheduler was sent the command recyc
03/26/2013 12:25:58;000d;PBS_Server;Job;20462.tyrone-cluster;Not sending email: User does not want mail of this type.
03/26/2013 12:26:21;0100;PBS_Server;Job;20469.tyrone-cluster;dequeuing from batch, state QUEUED
03/26/2013 12:26:21;0100;PBS_Server;Job;20469.tyrone-cluster;enqueuing into qp32, state 1 hop 1
03/26/2013 12:26:24;0040;PBS_Server;Svr;tyrone-cluster;Scheduler was sent the command new
03/26/2013 12:26:24;0008;PBS_Server;Job;20469.tyrone-cluster;Job Modified at request of Scheduler@tyrone-cluster
03/26/2013 12:26:53;0040;PBS_Server;Svr;tyrone-cluster;Scheduler was sent the command new
03/26/2013 12:27:25;0040;PBS_Server;Svr;tyrone-cluster;Scheduler was sent the command new
03/26/2013 12:27:58;0040;PBS_Server;Svr;tyrone-cluster;Scheduler was sent the command new
03/26/2013 12:28:28;0040;PBS_Server;Svr;tyrone-cluster;Scheduler was sent the command new
03/26/2013 12:28:29;0002;PBS_Server;Svr;PBS_Server;Torque Server Version = 3.0.5, loglevel = 0
03/26/2013 12:29:00;0040;PBS_Server;Svr;tyrone-cluster;Scheduler was sent the command new
03/26/2013 12:29:30;0040;PBS_Server;Svr;tyrone-cluster;Scheduler was sent the command new
03/26/2013 12:30:03;0040;PBS_Server;Svr;tyrone-cluster;Scheduler was sent the command new
03/26/2013 12:30:30;0040;PBS_Server;Svr;tyrone-cluster;Scheduler was sent the command new
03/26/2013 12:31:00;0040;PBS_Server;Svr;tyrone-cluster;Scheduler was sent the command new
03/26/2013 12:31:32;0040;PBS_Server;Svr;tyrone-cluster;Scheduler was sent the command new
03/26/2013 12:32:00;0040;PBS_Server;Svr;tyrone-cluster;Scheduler was sent the command new
03/26/2013 12:32:02;000d;PBS_Server;Job;20471.tyrone-cluster;Not sending email: User does not want mail of this type.
03/26/2013 12:32:02;0010;PBS_Server;Job;20471.tyrone-cluster;Exit_status=0 resources_used.cput=05:57:07 resources_used.mem=10825724kb resources_used.vmem=19828628kb resources_used.walltime=00:22:39
03/26/2013 12:32:02;0008;PBS_Server;Job;NULL;on_job_exit valid pjob: 0x2e71070 (substate=50)
03/26/2013 12:32:02;0008;PBS_Server;Job;NULL;on_job_exit valid pjob: 0x2e71070 (substate=51)
03/26/2013 12:32:02;0008;PBS_Server;Job;NULL;on_job_exit valid pjob: 0x2e71070 (substate=51)
03/26/2013 12:32:02;0008;PBS_Server;Job;NULL;on_job_exit valid pjob: 0x2e71070 (substate=53)
03/26/2013 12:32:02;0100;PBS_Server;Job;20471.tyrone-cluster;dequeuing from idqueue, state COMPLETE
03/26/2013 12:32:02;0040;PBS_Server;Svr;tyrone-cluster;Scheduler was sent the command term
03/26/2013 12:32:02;0008;PBS_Server;Job;20472.tyrone-cluster;Job Modified at request of Scheduler@tyrone-cluster
03/26/2013 12:32:02;0008;PBS_Server;Job;20472.tyrone-cluster;Job Run at request of Scheduler@tyrone-cluster
03/26/2013 12:32:03;0040;PBS_Server;Svr;tyrone-cluster;Scheduler was sent the command recyc
03/26/2013 12:32:03;000d;PBS_Server;Job;20472.tyrone-cluster;Not sending email: User does not want mail of this type.
03/26/2013 12:32:30;0040;PBS_Server;Svr;tyrone-cluster;Scheduler was sent the command new
03/26/2013 12:33:00;0040;PBS_Server;Svr;tyrone-cluster;Scheduler was sent the command new
03/26/2013 12:33:29;0002;PBS_Server;Svr;PBS_Server;Torque Server Version = 3.0.5, loglevel = 0
03/26/2013 12:33:30;0040;PBS_Server;Svr;tyrone-cluster;Scheduler was sent the command new
03/26/2013 12:34:00;0040;PBS_Server;Svr;tyrone-cluster;Scheduler was sent the command new
03/26/2013 12:34:30;0040;PBS_Server;Svr;tyrone-cluster;Scheduler was sent the command new
03/26/2013 12:35:00;0040;PBS_Server;Svr;tyrone-cluster;Scheduler was sent the command new
03/26/2013 12:35:30;0040;PBS_Server;Svr;tyrone-cluster;Scheduler was sent the command new
03/26/2013 12:36:00;0040;PBS_Server;Svr;tyrone-cluster;Scheduler was sent the command new
03/26/2013 12:36:30;0040;PBS_Server;Svr;tyrone-cluster;Scheduler was sent the command new
03/26/2013 12:37:00;0040;PBS_Server;Svr;tyrone-cluster;Scheduler was sent the command new
03/26/2013 12:37:30;0040;PBS_Server;Svr;tyrone-cluster;Scheduler was sent the command new
03/26/2013 12:38:00;0040;PBS_Server;Svr;tyrone-cluster;Scheduler was sent the command new
03/26/2013 12:38:29;0002;PBS_Server;Svr;PBS_Server;Torque Server Version = 3.0.5, loglevel = 0
03/26/2013 12:38:30;0040;PBS_Server;Svr;tyrone-cluster;Scheduler was sent the command new
03/26/2013 12:39:00;0040;PBS_Server;Svr;tyrone-cluster;Scheduler was sent the command new
03/26/2013 12:39:30;0040;PBS_Server;Svr;tyrone-cluster;Scheduler was sent the command new
03/26/2013 12:40:00;0040;PBS_Server;Svr;tyrone-cluster;Scheduler was sent the command new
03/26/2013 12:40:30;0040;PBS_Server;Svr;tyrone-cluster;Scheduler was sent the command new
03/26/2013 12:41:00;0040;PBS_Server;Svr;tyrone-cluster;Scheduler was sent the command new
03/26/2013 12:41:30;0040;PBS_Server;Svr;tyrone-cluster;Scheduler was sent the command new
03/26/2013 12:42:00;0040;PBS_Server;Svr;tyrone-cluster;Scheduler was sent the command new
03/26/2013 12:42:30;0040;PBS_Server;Svr;tyrone-cluster;Scheduler was sent the command new
03/26/2013 12:43:00;0040;PBS_Server;Svr;tyrone-cluster;Scheduler was sent the command new
03/26/2013 12:43:29;0002;PBS_Server;Svr;PBS_Server;Torque Server Version = 3.0.5, loglevel = 0
03/26/2013 12:43:30;0040;PBS_Server;Svr;tyrone-cluster;Scheduler was sent the command new
03/26/2013 12:44:00;0040;PBS_Server;Svr;tyrone-cluster;Scheduler was sent the command new
03/26/2013 12:44:30;0040;PBS_Server;Svr;tyrone-cluster;Scheduler was sent the command new
03/26/2013 12:45:00;0040;PBS_Server;Svr;tyrone-cluster;Scheduler was sent the command new
03/26/2013 12:45:30;0040;PBS_Server;Svr;tyrone-cluster;Scheduler was sent the command new
03/26/2013 12:46:00;0040;PBS_Server;Svr;tyrone-cluster;Scheduler was sent the command new
03/26/2013 12:46:30;0040;PBS_Server;Svr;tyrone-cluster;Scheduler was sent the command new
03/26/2013 12:47:00;0040;PBS_Server;Svr;tyrone-cluster;Scheduler was sent the command new
03/26/2013 12:47:30;0040;PBS_Server;Svr;tyrone-cluster;Scheduler was sent the command new
03/26/2013 12:48:00;0040;PBS_Server;Svr;tyrone-cluster;Scheduler was sent the command new
03/26/2013 12:48:29;0002;PBS_Server;Svr;PBS_Server;Torque Server Version = 3.0.5, loglevel = 0
03/26/2013 12:48:30;0040;PBS_Server;Svr;tyrone-cluster;Scheduler was sent the command new
03/26/2013 12:49:00;0040;PBS_Server;Svr;tyrone-cluster;Scheduler was sent the command new
03/26/2013 12:49:30;0040;PBS_Server;Svr;tyrone-cluster;Scheduler was sent the command new
03/26/2013 12:50:00;0040;PBS_Server;Svr;tyrone-cluster;Scheduler was sent the command new
03/26/2013 12:50:17;000d;PBS_Server;Job;20472.tyrone-cluster;Not sending email: User does not want mail of this type.
03/26/2013 12:50:17;0010;PBS_Server;Job;20472.tyrone-cluster;Exit_status=0 resources_used.cput=04:49:39 resources_used.mem=10667888kb resources_used.vmem=19591332kb resources_used.walltime=00:18:15
03/26/2013 12:50:17;0008;PBS_Server;Job;NULL;on_job_exit valid pjob: 0x2e3d8d0 (substate=50)
03/26/2013 12:50:17;0008;PBS_Server;Job;NULL;on_job_exit valid pjob: 0x2e3d8d0 (substate=51)
03/26/2013 12:50:17;0008;PBS_Server;Job;NULL;on_job_exit valid pjob: 0x2e3d8d0 (substate=51)
03/26/2013 12:50:17;0008;PBS_Server;Job;NULL;on_job_exit valid pjob: 0x2e3d8d0 (substate=53)
03/26/2013 12:50:17;0100;PBS_Server;Job;20472.tyrone-cluster;dequeuing from idqueue, state COMPLETE
03/26/2013 12:50:17;0040;PBS_Server;Svr;tyrone-cluster;Scheduler was sent the command term
03/26/2013 12:50:18;0008;PBS_Server;Job;20473.tyrone-cluster;Job Modified at request of Scheduler@tyrone-cluster
03/26/2013 12:50:18;0008;PBS_Server;Job;20473.tyrone-cluster;Job Run at request of Scheduler@tyrone-cluster
03/26/2013 12:50:18;0040;PBS_Server;Svr;tyrone-cluster;Scheduler was sent the command recyc
03/26/2013 12:50:18;000d;PBS_Server;Job;20473.tyrone-cluster;Not sending email: User does not want mail of this type.
03/26/2013 12:50:30;0040;PBS_Server;Svr;tyrone-cluster;Scheduler was sent the command new
03/26/2013 12:51:02;0040;PBS_Server;Svr;tyrone-cluster;Scheduler was sent the command new
03/26/2013 12:51:30;0040;PBS_Server;Svr;tyrone-cluster;Scheduler was sent the command new
03/26/2013 12:52:00;0040;PBS_Server;Svr;tyrone-cluster;Scheduler was sent the command new
03/26/2013 12:52:32;0040;PBS_Server;Svr;tyrone-cluster;Scheduler was sent the command new
03/26/2013 12:53:00;0040;PBS_Server;Svr;tyrone-cluster;Scheduler was sent the command new
03/26/2013 12:53:29;0002;PBS_Server;Svr;PBS_Server;Torque Server Version = 3.0.5, loglevel = 0
03/26/2013 12:53:30;0040;PBS_Server;Svr;tyrone-cluster;Scheduler was sent the command new
03/26/2013 12:54:02;0040;PBS_Server;Svr;tyrone-cluster;Scheduler was sent the command new
03/26/2013 12:54:30;0040;PBS_Server;Svr;tyrone-cluster;Scheduler was sent the command new
03/26/2013 12:55:00;0040;PBS_Server;Svr;tyrone-cluster;Scheduler was sent the command new
03/26/2013 12:55:32;0040;PBS_Server;Svr;tyrone-cluster;Scheduler was sent the command new
03/26/2013 12:56:00;0040;PBS_Server;Svr;tyrone-cluster;Scheduler was sent the command new
03/26/2013 12:56:30;0040;PBS_Server;Svr;tyrone-cluster;Scheduler was sent the command new
03/26/2013 12:57:02;0040;PBS_Server;Svr;tyrone-cluster;Scheduler was sent the command new
03/26/2013 12:57:30;0040;PBS_Server;Svr;tyrone-cluster;Scheduler was sent the command new
03/26/2013 12:58:00;0040;PBS_Server;Svr;tyrone-cluster;Scheduler was sent the command new
03/26/2013 12:58:29;0002;PBS_Server;Svr;PBS_Server;Torque Server Version = 3.0.5, loglevel = 0
03/26/2013 12:58:32;0040;PBS_Server;Svr;tyrone-cluster;Scheduler was sent the command new
03/26/2013 12:59:00;0040;PBS_Server;Svr;tyrone-cluster;Scheduler was sent the command new
03/26/2013 12:59:30;0040;PBS_Server;Svr;tyrone-cluster;Scheduler was sent the command new
03/26/2013 13:00:02;0040;PBS_Server;Svr;tyrone-cluster;Scheduler was sent the command new
03/26/2013 13:00:30;0040;PBS_Server;Svr;tyrone-cluster;Scheduler was sent the command new
03/26/2013 13:01:00;0040;PBS_Server;Svr;tyrone-cluster;Scheduler was sent the command new
03/26/2013 13:01:32;0040;PBS_Server;Svr;tyrone-cluster;Scheduler was sent the command new
03/26/2013 13:02:00;0040;PBS_Server;Svr;tyrone-cluster;Scheduler was sent the command new
03/26/2013 13:02:30;0040;PBS_Server;Svr;tyrone-cluster;Scheduler was sent the command new
03/26/2013 13:03:02;0040;PBS_Server;Svr;tyrone-cluster;Scheduler was sent the command new
03/26/2013 13:03:29;0002;PBS_Server;Svr;PBS_Server;Torque Server Version = 3.0.5, loglevel = 0
03/26/2013 13:03:30;0040;PBS_Server;Svr;tyrone-cluster;Scheduler was sent the command new
03/26/2013 13:04:00;0040;PBS_Server;Svr;tyrone-cluster;Scheduler was sent the command new
03/26/2013 13:04:32;0040;PBS_Server;Svr;tyrone-cluster;Scheduler was sent the command new
03/26/2013 13:05:00;0040;PBS_Server;Svr;tyrone-cluster;Scheduler was sent the command new
03/26/2013 13:05:30;0040;PBS_Server;Svr;tyrone-cluster;Scheduler was sent the command new
03/26/2013 13:06:02;0040;PBS_Server;Svr;tyrone-cluster;Scheduler was sent the command new
03/26/2013 13:06:30;0040;PBS_Server;Svr;tyrone-cluster;Scheduler was sent the command new
03/26/2013 13:07:00;0040;PBS_Server;Svr;tyrone-cluster;Scheduler was sent the command new
03/26/2013 13:07:32;0040;PBS_Server;Svr;tyrone-cluster;Scheduler was sent the command new
03/26/2013 13:08:00;0040;PBS_Server;Svr;tyrone-cluster;Scheduler was sent the command new
03/26/2013 13:08:29;0002;PBS_Server;Svr;PBS_Server;Torque Server Version = 3.0.5, loglevel = 0
03/26/2013 13:08:30;0040;PBS_Server;Svr;tyrone-cluster;Scheduler was sent the command new
03/26/2013 13:09:02;0040;PBS_Server;Svr;tyrone-cluster;Scheduler was sent the command new
03/26/2013 13:09:33;0040;PBS_Server;Svr;tyrone-cluster;Scheduler was sent the command new
03/26/2013 13:10:07;0040;PBS_Server;Svr;tyrone-cluster;Scheduler was sent the command new
03/26/2013 13:10:39;0040;PBS_Server;Svr;tyrone-cluster;Scheduler was sent the command new
03/26/2013 13:10:57;000d;PBS_Server;Job;20473.tyrone-cluster;Not sending email: User does not want mail of this type.
03/26/2013 13:10:57;0010;PBS_Server;Job;20473.tyrone-cluster;Exit_status=0 resources_used.cput=05:24:44 resources_used.mem=10664248kb resources_used.vmem=19591308kb resources_used.walltime=00:20:39
03/26/2013 13:10:57;0008;PBS_Server;Job;NULL;on_job_exit valid pjob: 0x2e46bf0 (substate=50)
03/26/2013 13:10:57;0008;PBS_Server;Job;NULL;on_job_exit valid pjob: 0x2e46bf0 (substate=51)
03/26/2013 13:10:57;0008;PBS_Server;Job;NULL;on_job_exit valid pjob: 0x2e46bf0 (substate=51)
03/26/2013 13:10:57;0008;PBS_Server;Job;NULL;on_job_exit valid pjob: 0x2e46bf0 (substate=53)
03/26/2013 13:10:57;0100;PBS_Server;Job;20473.tyrone-cluster;dequeuing from idqueue, state COMPLETE
03/26/2013 13:10:57;0040;PBS_Server;Svr;tyrone-cluster;Scheduler was sent the command term
03/26/2013 13:11:08;0040;PBS_Server;Svr;tyrone-cluster;Scheduler was sent the command new
03/26/2013 13:11:40;0040;PBS_Server;Svr;tyrone-cluster;Scheduler was sent the command new
03/26/2013 13:12:13;0040;PBS_Server;Svr;tyrone-cluster;Scheduler was sent the command new
03/26/2013 13:12:31;000d;PBS_Server;Job;20461.tyrone-cluster;Not sending email: User does not want mail of this type.
03/26/2013 13:12:31;0010;PBS_Server;Job;20461.tyrone-cluster;Exit_status=0 resources_used.cput=63:53:44 resources_used.mem=2038388kb resources_used.vmem=10430364kb resources_used.walltime=02:35:31
03/26/2013 13:12:31;0008;PBS_Server;Job;NULL;on_job_exit valid pjob: 0x2e74200 (substate=50)
03/26/2013 13:12:31;0008;PBS_Server;Job;NULL;on_job_exit valid pjob: 0x2e74200 (substate=51)
03/26/2013 13:12:35;0008;PBS_Server;Job;NULL;on_job_exit valid pjob: 0x2e74200 (substate=51)
03/26/2013 13:12:35;000d;PBS_Server;Job;20461.tyrone-cluster;Post job file processing error; job 20461.tyrone-cluster on host tyrone-node4/31+tyrone-node4/30+tyrone-node4/29+tyrone-node4/28+tyrone-node4/27+tyrone-node4/26+tyrone-node4/25+tyrone-node4/24+tyrone-node4/23+tyrone-node4/22+tyrone-node4/21+tyrone-node4/20+tyrone-node4/19+tyrone-node4/18+tyrone-node4/17+tyrone-node4/16+tyrone-node4/15+tyrone-node4/14+tyrone-node4/13+tyrone-node4/12+tyrone-node4/11+tyrone-node4/10+tyrone-node4/9+tyrone-node4/8+tyrone-node4/7+tyrone-node4/6+tyrone-node4/5+tyrone-node4/4+tyrone-node4/3+tyrone-node4/2+tyrone-node4/1+tyrone-node4/0
03/26/2013 13:12:35;0008;PBS_Server;Job;NULL;on_job_exit valid pjob: 0x2e74200 (substate=53)
03/26/2013 13:12:35;0100;PBS_Server;Job;20461.tyrone-cluster;dequeuing from qp32, state COMPLETE
03/26/2013 13:12:35;0040;PBS_Server;Svr;tyrone-cluster;Scheduler was sent the command term
03/26/2013 13:12:35;0008;PBS_Server;Job;20469.tyrone-cluster;Job Modified at request of Scheduler@tyrone-cluster
03/26/2013 13:12:35;0008;PBS_Server;Job;20469.tyrone-cluster;Job Run at request of Scheduler@tyrone-cluster
03/26/2013 13:12:36;0040;PBS_Server;Svr;tyrone-cluster;Scheduler was sent the command recyc
03/26/2013 13:12:36;000d;PBS_Server;Job;20469.tyrone-cluster;Not sending email: User does not want mail of this type.
03/26/2013 13:12:45;0040;PBS_Server;Svr;tyrone-cluster;Scheduler was sent the command new
03/26/2013 13:13:15;0040;PBS_Server;Svr;tyrone-cluster;Scheduler was sent the command new
03/26/2013 13:13:29;0002;PBS_Server;Svr;PBS_Server;Torque Server Version = 3.0.5, loglevel = 0
03/26/2013 13:13:44;0040;PBS_Server;Svr;tyrone-cluster;Scheduler was sent the command new
03/26/2013 13:14:18;0040;PBS_Server;Svr;tyrone-cluster;Scheduler was sent the command new
03/26/2013 13:14:45;0040;PBS_Server;Svr;tyrone-cluster;Scheduler was sent the command new
03/26/2013 13:15:15;0040;PBS_Server;Svr;tyrone-cluster;Scheduler was sent the command new
03/26/2013 13:15:47;0040;PBS_Server;Svr;tyrone-cluster;Scheduler was sent the command new
03/26/2013 13:16:15;0040;PBS_Server;Svr;tyrone-cluster;Scheduler was sent the command new
03/26/2013 13:16:45;0040;PBS_Server;Svr;tyrone-cluster;Scheduler was sent the command new
03/26/2013 13:17:17;0040;PBS_Server;Svr;tyrone-cluster;Scheduler was sent the command new
03/26/2013 13:17:45;0040;PBS_Server;Svr;tyrone-cluster;Scheduler was sent the command new
03/26/2013 13:18:15;0040;PBS_Server;Svr;tyrone-cluster;Scheduler was sent the command new
03/26/2013 13:18:29;0002;PBS_Server;Svr;PBS_Server;Torque Server Version = 3.0.5, loglevel = 0
03/26/2013 13:18:47;0040;PBS_Server;Svr;tyrone-cluster;Scheduler was sent the command new
03/26/2013 13:19:15;0040;PBS_Server;Svr;tyrone-cluster;Scheduler was sent the command new
03/26/2013 13:19:45;0040;PBS_Server;Svr;tyrone-cluster;Scheduler was sent the command new
03/26/2013 13:20:18;0040;PBS_Server;Svr;tyrone-cluster;Scheduler was sent the command new
03/26/2013 13:20:48;0040;PBS_Server;Svr;tyrone-cluster;Scheduler was sent the command new
03/26/2013 13:21:22;0040;PBS_Server;Svr;tyrone-cluster;Scheduler was sent the command new
03/26/2013 13:21:54;0040;PBS_Server;Svr;tyrone-cluster;Scheduler was sent the command new
03/26/2013 13:22:23;0040;PBS_Server;Svr;tyrone-cluster;Scheduler was sent the command new
03/26/2013 13:22:56;0040;PBS_Server;Svr;tyrone-cluster;Scheduler was sent the command new
03/26/2013 13:23:22;000d;PBS_Server;Job;20468.tyrone-cluster;Not sending email: User does not want mail of this type.
03/26/2013 13:23:22;0010;PBS_Server;Job;20468.tyrone-cluster;Exit_status=143 resources_used.cput=36:07:21 resources_used.mem=10272228kb resources_used.vmem=21147976kb resources_used.walltime=02:00:43
03/26/2013 13:23:22;0008;PBS_Server;Job;NULL;on_job_exit valid pjob: 0x2ec13f0 (substate=50)
03/26/2013 13:23:22;0008;PBS_Server;Job;NULL;on_job_exit valid pjob: 0x2ec13f0 (substate=51)
03/26/2013 13:23:23;0008;PBS_Server;Job;NULL;on_job_exit valid pjob: 0x2ec13f0 (substate=51)
03/26/2013 13:23:23;0008;PBS_Server;Job;NULL;on_job_exit valid pjob: 0x2ec13f0 (substate=53)
03/26/2013 13:23:23;0100;PBS_Server;Job;20468.tyrone-cluster;dequeuing from idqueue, state COMPLETE
03/26/2013 13:23:23;0040;PBS_Server;Svr;tyrone-cluster;Scheduler was sent the command term
03/26/2013 13:23:27;0040;PBS_Server;Svr;tyrone-cluster;Scheduler was sent the command new
03/26/2013 13:23:29;0002;PBS_Server;Svr;PBS_Server;Torque Server Version = 3.0.5, loglevel = 0
03/26/2013 13:23:56;0040;PBS_Server;Svr;tyrone-cluster;Scheduler was sent the command new
03/26/2013 13:24:27;0040;PBS_Server;Svr;tyrone-cluster;Scheduler was sent the command new
03/26/2013 13:24:57;0040;PBS_Server;Svr;tyrone-cluster;Scheduler was sent the command new
03/26/2013 13:25:28;0040;PBS_Server;Svr;tyrone-cluster;Scheduler was sent the command new
03/26/2013 13:25:57;0040;PBS_Server;Svr;tyrone-cluster;Scheduler was sent the command new
03/26/2013 13:26:27;0040;PBS_Server;Svr;tyrone-cluster;Scheduler was sent the command new
03/26/2013 13:26:50;000d;PBS_Server;Job;20474.tyrone-cluster;Not sending email: User does not want mail of this type.
03/26/2013 13:26:50;0010;PBS_Server;Job;20474.tyrone-cluster;Exit_status=0 resources_used.cput=13:21:18 resources_used.mem=557056kb resources_used.vmem=1295960kb resources_used.walltime=01:40:55
03/26/2013 13:26:50;0008;PBS_Server;Job;NULL;on_job_exit valid pjob: 0x2f47310 (substate=50)
03/26/2013 13:26:50;0008;PBS_Server;Job;NULL;on_job_exit valid pjob: 0x2f47310 (substate=51)
03/26/2013 13:26:50;0008;PBS_Server;Job;NULL;on_job_exit valid pjob: 0x2f47310 (substate=51)
03/26/2013 13:26:50;0008;PBS_Server;Job;NULL;on_job_exit valid pjob: 0x2f47310 (substate=53)
03/26/2013 13:26:50;0100;PBS_Server;Job;20474.tyrone-cluster;dequeuing from qp32, state COMPLETE
03/26/2013 13:26:50;0040;PBS_Server;Svr;tyrone-cluster;Scheduler was sent the command term
03/26/2013 13:26:58;0040;PBS_Server;Svr;tyrone-cluster;Scheduler was sent the command new
03/26/2013 13:27:27;0040;PBS_Server;Svr;tyrone-cluster;Scheduler was sent the command new
03/26/2013 13:27:57;0040;PBS_Server;Svr;tyrone-cluster;Scheduler was sent the command new
03/26/2013 13:28:28;0040;PBS_Server;Svr;tyrone-cluster;Scheduler was sent the command new
03/26/2013 13:28:29;0002;PBS_Server;Svr;PBS_Server;Torque Server Version = 3.0.5, loglevel = 0
03/26/2013 13:28:57;0040;PBS_Server;Svr;tyrone-cluster;Scheduler was sent the command new
03/26/2013 13:29:27;0040;PBS_Server;Svr;tyrone-cluster;Scheduler was sent the command new
03/26/2013 13:29:58;0040;PBS_Server;Svr;tyrone-cluster;Scheduler was sent the command new
03/26/2013 13:30:27;0040;PBS_Server;Svr;tyrone-cluster;Scheduler was sent the command new
03/26/2013 13:30:57;0040;PBS_Server;Svr;tyrone-cluster;Scheduler was sent the command new
03/26/2013 13:31:28;0040;PBS_Server;Svr;tyrone-cluster;Scheduler was sent the command new
03/26/2013 13:31:57;0040;PBS_Server;Svr;tyrone-cluster;Scheduler was sent the command new
03/26/2013 13:32:27;0040;PBS_Server;Svr;tyrone-cluster;Scheduler was sent the command new
03/26/2013 13:32:58;0040;PBS_Server;Svr;tyrone-cluster;Scheduler was sent the command new
03/26/2013 13:33:27;0040;PBS_Server;Svr;tyrone-cluster;Scheduler was sent the command new
03/26/2013 13:33:29;0002;PBS_Server;Svr;PBS_Server;Torque Server Version = 3.0.5, loglevel = 0
03/26/2013 13:33:57;0040;PBS_Server;Svr;tyrone-cluster;Scheduler was sent the command new
03/26/2013 13:34:28;0040;PBS_Server;Svr;tyrone-cluster;Scheduler was sent the command new
03/26/2013 13:34:57;0040;PBS_Server;Svr;tyrone-cluster;Scheduler was sent the command new
03/26/2013 13:35:27;0040;PBS_Server;Svr;tyrone-cluster;Scheduler was sent the command new
03/26/2013 13:35:58;0040;PBS_Server;Svr;tyrone-cluster;Scheduler was sent the command new
03/26/2013 13:36:27;0040;PBS_Server;Svr;tyrone-cluster;Scheduler was sent the command new
03/26/2013 13:36:57;0040;PBS_Server;Svr;tyrone-cluster;Scheduler was sent the command new
03/26/2013 13:37:28;0040;PBS_Server;Svr;tyrone-cluster;Scheduler was sent the command new
03/26/2013 13:37:57;0040;PBS_Server;Svr;tyrone-cluster;Scheduler was sent the command new
03/26/2013 13:38:27;0040;PBS_Server;Svr;tyrone-cluster;Scheduler was sent the command new
03/26/2013 13:38:29;0002;PBS_Server;Svr;PBS_Server;Torque Server Version = 3.0.5, loglevel = 0
03/26/2013 13:38:58;0040;PBS_Server;Svr;tyrone-cluster;Scheduler was sent the command new
03/26/2013 13:39:27;0040;PBS_Server;Svr;tyrone-cluster;Scheduler was sent the command new
03/26/2013 13:39:57;0040;PBS_Server;Svr;tyrone-cluster;Scheduler was sent the command new
03/26/2013 13:40:28;0040;PBS_Server;Svr;tyrone-cluster;Scheduler was sent the command new
03/26/2013 13:40:57;0040;PBS_Server;Svr;tyrone-cluster;Scheduler was sent the command new
03/26/2013 13:41:27;0040;PBS_Server;Svr;tyrone-cluster;Scheduler was sent the command new
03/26/2013 13:41:58;0040;PBS_Server;Svr;tyrone-cluster;Scheduler was sent the command new
03/26/2013 13:42:27;0040;PBS_Server;Svr;tyrone-cluster;Scheduler was sent the command new
03/26/2013 13:42:57;0040;PBS_Server;Svr;tyrone-cluster;Scheduler was sent the command new
03/26/2013 13:43:28;0040;PBS_Server;Svr;tyrone-cluster;Scheduler was sent the command new
03/26/2013 13:43:29;0002;PBS_Server;Svr;PBS_Server;Torque Server Version = 3.0.5, loglevel = 0
03/26/2013 13:43:57;0040;PBS_Server;Svr;tyrone-cluster;Scheduler was sent the command new
03/26/2013 13:44:27;0040;PBS_Server;Svr;tyrone-cluster;Scheduler was sent the command new
03/26/2013 13:44:58;0040;PBS_Server;Svr;tyrone-cluster;Scheduler was sent the command new
03/26/2013 13:45:27;0040;PBS_Server;Svr;tyrone-cluster;Scheduler was sent the command new
03/26/2013 13:45:57;0040;PBS_Server;Svr;tyrone-cluster;Scheduler was sent the command new
03/26/2013 13:46:28;0040;PBS_Server;Svr;tyrone-cluster;Scheduler was sent the command new
03/26/2013 13:46:57;0040;PBS_Server;Svr;tyrone-cluster;Scheduler was sent the command new
03/26/2013 13:47:27;0040;PBS_Server;Svr;tyrone-cluster;Scheduler was sent the command new
03/26/2013 13:47:58;0040;PBS_Server;Svr;tyrone-cluster;Scheduler was sent the command new
03/26/2013 13:48:27;0040;PBS_Server;Svr;tyrone-cluster;Scheduler was sent the command new
03/26/2013 13:48:29;0002;PBS_Server;Svr;PBS_Server;Torque Server Version = 3.0.5, loglevel = 0
03/26/2013 13:48:57;0040;PBS_Server;Svr;tyrone-cluster;Scheduler was sent the command new
03/26/2013 13:49:28;0040;PBS_Server;Svr;tyrone-cluster;Scheduler was sent the command new
03/26/2013 13:49:57;0040;PBS_Server;Svr;tyrone-cluster;Scheduler was sent the command new
03/26/2013 13:50:27;0040;PBS_Server;Svr;tyrone-cluster;Scheduler was sent the command new
03/26/2013 13:50:58;0040;PBS_Server;Svr;tyrone-cluster;Scheduler was sent the command new
03/26/2013 13:51:27;0040;PBS_Server;Svr;tyrone-cluster;Scheduler was sent the command new
03/26/2013 13:51:57;0040;PBS_Server;Svr;tyrone-cluster;Scheduler was sent the command new
03/26/2013 13:52:28;0040;PBS_Server;Svr;tyrone-cluster;Scheduler was sent the command new
03/26/2013 13:52:57;0040;PBS_Server;Svr;tyrone-cluster;Scheduler was sent the command new
03/26/2013 13:53:27;0040;PBS_Server;Svr;tyrone-cluster;Scheduler was sent the command new
03/26/2013 13:53:29;0002;PBS_Server;Svr;PBS_Server;Torque Server Version = 3.0.5, loglevel = 0
03/26/2013 13:53:58;0040;PBS_Server;Svr;tyrone-cluster;Scheduler was sent the command new
03/26/2013 13:54:27;0040;PBS_Server;Svr;tyrone-cluster;Scheduler was sent the command new
03/26/2013 13:54:57;0040;PBS_Server;Svr;tyrone-cluster;Scheduler was sent the command new
03/26/2013 13:55:28;0040;PBS_Server;Svr;tyrone-cluster;Scheduler was sent the command new
03/26/2013 13:55:57;0040;PBS_Server;Svr;tyrone-cluster;Scheduler was sent the command new
03/26/2013 13:56:27;0040;PBS_Server;Svr;tyrone-cluster;Scheduler was sent the command new
03/26/2013 13:56:58;0040;PBS_Server;Svr;tyrone-cluster;Scheduler was sent the command new
03/26/2013 13:57:27;0040;PBS_Server;Svr;tyrone-cluster;Scheduler was sent the command new
03/26/2013 13:57:57;0040;PBS_Server;Svr;tyrone-cluster;Scheduler was sent the command new
03/26/2013 13:58:28;0040;PBS_Server;Svr;tyrone-cluster;Scheduler was sent the command new
03/26/2013 13:58:29;0002;PBS_Server;Svr;PBS_Server;Torque Server Version = 3.0.5, loglevel = 0
03/26/2013 13:58:57;0040;PBS_Server;Svr;tyrone-cluster;Scheduler was sent the command new
03/26/2013 13:59:27;0040;PBS_Server;Svr;tyrone-cluster;Scheduler was sent the command new
03/26/2013 13:59:58;0040;PBS_Server;Svr;tyrone-cluster;Scheduler was sent the command new
03/26/2013 14:00:27;0040;PBS_Server;Svr;tyrone-cluster;Scheduler was sent the command new
03/26/2013 14:00:57;0040;PBS_Server;Svr;tyrone-cluster;Scheduler was sent the command new
03/26/2013 14:01:28;0040;PBS_Server;Svr;tyrone-cluster;Scheduler was sent the command new
03/26/2013 14:01:57;0040;PBS_Server;Svr;tyrone-cluster;Scheduler was sent the command new
03/26/2013 14:02:27;0040;PBS_Server;Svr;tyrone-cluster;Scheduler was sent the command new
03/26/2013 14:02:58;0040;PBS_Server;Svr;tyrone-cluster;Scheduler was sent the command new
03/26/2013 14:03:27;0040;PBS_Server;Svr;tyrone-cluster;Scheduler was sent the command new
03/26/2013 14:03:29;0002;PBS_Server;Svr;PBS_Server;Torque Server Version = 3.0.5, loglevel = 0
03/26/2013 14:03:57;0040;PBS_Server;Svr;tyrone-cluster;Scheduler was sent the command new
03/26/2013 14:04:28;0040;PBS_Server;Svr;tyrone-cluster;Scheduler was sent the command new
03/26/2013 14:04:57;0040;PBS_Server;Svr;tyrone-cluster;Scheduler was sent the command new
03/26/2013 14:05:27;0040;PBS_Server;Svr;tyrone-cluster;Scheduler was sent the command new
03/26/2013 14:05:58;0040;PBS_Server;Svr;tyrone-cluster;Scheduler was sent the command new
03/26/2013 14:06:27;0040;PBS_Server;Svr;tyrone-cluster;Scheduler was sent the command new
03/26/2013 14:06:57;0040;PBS_Server;Svr;tyrone-cluster;Scheduler was sent the command new
03/26/2013 14:07:28;0040;PBS_Server;Svr;tyrone-cluster;Scheduler was sent the command new
03/26/2013 14:07:57;0040;PBS_Server;Svr;tyrone-cluster;Scheduler was sent the command new
03/26/2013 14:08:27;0040;PBS_Server;Svr;tyrone-cluster;Scheduler was sent the command new
03/26/2013 14:08:29;0002;PBS_Server;Svr;PBS_Server;Torque Server Version = 3.0.5, loglevel = 0
03/26/2013 14:08:58;0040;PBS_Server;Svr;tyrone-cluster;Scheduler was sent the command new
03/26/2013 14:09:27;0040;PBS_Server;Svr;tyrone-cluster;Scheduler was sent the command new
03/26/2013 14:09:57;0040;PBS_Server;Svr;tyrone-cluster;Scheduler was sent the command new
03/26/2013 14:10:28;0040;PBS_Server;Svr;tyrone-cluster;Scheduler was sent the command new
03/26/2013 14:10:57;0040;PBS_Server;Svr;tyrone-cluster;Scheduler was sent the command new
03/26/2013 14:11:27;0040;PBS_Server;Svr;tyrone-cluster;Scheduler was sent the command new
03/26/2013 14:11:58;0040;PBS_Server;Svr;tyrone-cluster;Scheduler was sent the command new
03/26/2013 14:12:27;0040;PBS_Server;Svr;tyrone-cluster;Scheduler was sent the command new
03/26/2013 14:12:57;0040;PBS_Server;Svr;tyrone-cluster;Scheduler was sent the command new
03/26/2013 14:13:28;0040;PBS_Server;Svr;tyrone-cluster;Scheduler was sent the command new
03/26/2013 14:13:29;0002;PBS_Server;Svr;PBS_Server;Torque Server Version = 3.0.5, loglevel = 0
03/26/2013 14:13:57;0040;PBS_Server;Svr;tyrone-cluster;Scheduler was sent the command new
03/26/2013 14:14:27;0040;PBS_Server;Svr;tyrone-cluster;Scheduler was sent the command new
03/26/2013 14:14:58;0040;PBS_Server;Svr;tyrone-cluster;Scheduler was sent the command new
03/26/2013 14:15:27;0040;PBS_Server;Svr;tyrone-cluster;Scheduler was sent the command new
03/26/2013 14:15:57;0040;PBS_Server;Svr;tyrone-cluster;Scheduler was sent the command new
03/26/2013 14:16:28;0040;PBS_Server;Svr;tyrone-cluster;Scheduler was sent the command new
03/26/2013 14:16:57;0040;PBS_Server;Svr;tyrone-cluster;Scheduler was sent the command new
03/26/2013 14:17:27;0040;PBS_Server;Svr;tyrone-cluster;Scheduler was sent the command new
03/26/2013 14:17:58;0040;PBS_Server;Svr;tyrone-cluster;Scheduler was sent the command new
03/26/2013 14:18:27;0040;PBS_Server;Svr;tyrone-cluster;Scheduler was sent the command new
03/26/2013 14:18:29;0002;PBS_Server;Svr;PBS_Server;Torque Server Version = 3.0.5, loglevel = 0
03/26/2013 14:18:57;0040;PBS_Server;Svr;tyrone-cluster;Scheduler was sent the command new
03/26/2013 14:19:28;0040;PBS_Server;Svr;tyrone-cluster;Scheduler was sent the command new
03/26/2013 14:19:57;0040;PBS_Server;Svr;tyrone-cluster;Scheduler was sent the command new
03/26/2013 14:20:27;0040;PBS_Server;Svr;tyrone-cluster;Scheduler was sent the command new
03/26/2013 14:20:58;0040;PBS_Server;Svr;tyrone-cluster;Scheduler was sent the command new
03/26/2013 14:21:27;0040;PBS_Server;Svr;tyrone-cluster;Scheduler was sent the command new
03/26/2013 14:21:57;0040;PBS_Server;Svr;tyrone-cluster;Scheduler was sent the command new
03/26/2013 14:22:28;0040;PBS_Server;Svr;tyrone-cluster;Scheduler was sent the command new
03/26/2013 14:22:47;000d;PBS_Server;Job;20446.tyrone-cluster;Not sending email: User does not want mail of this type.
03/26/2013 14:22:47;0010;PBS_Server;Job;20446.tyrone-cluster;Exit_status=0 resources_used.cput=205:57:02 resources_used.mem=1469468kb resources_used.vmem=9852904kb resources_used.walltime=06:45:59
03/26/2013 14:22:47;0008;PBS_Server;Job;NULL;on_job_exit valid pjob: 0x2e6b4e0 (substate=50)
03/26/2013 14:22:47;0008;PBS_Server;Job;NULL;on_job_exit valid pjob: 0x2e6b4e0 (substate=51)
03/26/2013 14:22:51;0008;PBS_Server;Job;NULL;on_job_exit valid pjob: 0x2e6b4e0 (substate=51)
03/26/2013 14:22:51;000d;PBS_Server;Job;20446.tyrone-cluster;Post job file processing error; job 20446.tyrone-cluster on host tyrone-node1/31+tyrone-node1/30+tyrone-node1/29+tyrone-node1/28+tyrone-node1/27+tyrone-node1/26+tyrone-node1/25+tyrone-node1/24+tyrone-node1/23+tyrone-node1/22+tyrone-node1/21+tyrone-node1/20+tyrone-node1/19+tyrone-node1/18+tyrone-node1/17+tyrone-node1/16+tyrone-node1/15+tyrone-node1/14+tyrone-node1/13+tyrone-node1/12+tyrone-node1/11+tyrone-node1/10+tyrone-node1/9+tyrone-node1/8+tyrone-node1/7+tyrone-node1/6+tyrone-node1/5+tyrone-node1/4+tyrone-node1/3+tyrone-node1/2+tyrone-node1/1+tyrone-node1/0
03/26/2013 14:22:51;0008;PBS_Server;Job;NULL;on_job_exit valid pjob: 0x2e6b4e0 (substate=53)
03/26/2013 14:22:51;0100;PBS_Server;Job;20446.tyrone-cluster;dequeuing from qp32, state COMPLETE
03/26/2013 14:22:51;0040;PBS_Server;Svr;tyrone-cluster;Scheduler was sent the command term
03/26/2013 14:22:57;0040;PBS_Server;Svr;tyrone-cluster;Scheduler was sent the command new
03/26/2013 14:23:27;0040;PBS_Server;Svr;tyrone-cluster;Scheduler was sent the command new
03/26/2013 14:23:29;0002;PBS_Server;Svr;PBS_Server;Torque Server Version = 3.0.5, loglevel = 0
03/26/2013 14:23:58;0040;PBS_Server;Svr;tyrone-cluster;Scheduler was sent the command new
03/26/2013 14:24:27;0040;PBS_Server;Svr;tyrone-cluster;Scheduler was sent the command new
03/26/2013 14:24:57;0040;PBS_Server;Svr;tyrone-cluster;Scheduler was sent the command new
03/26/2013 14:25:28;0040;PBS_Server;Svr;tyrone-cluster;Scheduler was sent the command new
03/26/2013 14:25:57;0040;PBS_Server;Svr;tyrone-cluster;Scheduler was sent the command new
03/26/2013 14:26:27;0040;PBS_Server;Svr;tyrone-cluster;Scheduler was sent the command new
03/26/2013 14:26:58;0040;PBS_Server;Svr;tyrone-cluster;Scheduler was sent the command new
03/26/2013 14:27:27;0040;PBS_Server;Svr;tyrone-cluster;Scheduler was sent the command new
03/26/2013 14:27:57;0040;PBS_Server;Svr;tyrone-cluster;Scheduler was sent the command new
03/26/2013 14:28:28;0040;PBS_Server;Svr;tyrone-cluster;Scheduler was sent the command new
03/26/2013 14:28:29;0002;PBS_Server;Svr;PBS_Server;Torque Server Version = 3.0.5, loglevel = 0
03/26/2013 14:28:57;0040;PBS_Server;Svr;tyrone-cluster;Scheduler was sent the command new
03/26/2013 14:29:27;0040;PBS_Server;Svr;tyrone-cluster;Scheduler was sent the command new
03/26/2013 14:29:58;0040;PBS_Server;Svr;tyrone-cluster;Scheduler was sent the command new
03/26/2013 14:30:27;0040;PBS_Server;Svr;tyrone-cluster;Scheduler was sent the command new
03/26/2013 14:30:57;0040;PBS_Server;Svr;tyrone-cluster;Scheduler was sent the command new
03/26/2013 14:31:28;0040;PBS_Server;Svr;tyrone-cluster;Scheduler was sent the command new
03/26/2013 14:31:57;0040;PBS_Server;Svr;tyrone-cluster;Scheduler was sent the command new
03/26/2013 14:32:27;0040;PBS_Server;Svr;tyrone-cluster;Scheduler was sent the command new
03/26/2013 14:32:58;0040;PBS_Server;Svr;tyrone-cluster;Scheduler was sent the command new
03/26/2013 14:33:27;0040;PBS_Server;Svr;tyrone-cluster;Scheduler was sent the command new
03/26/2013 14:33:29;0002;PBS_Server;Svr;PBS_Server;Torque Server Version = 3.0.5, loglevel = 0
03/26/2013 14:33:57;0040;PBS_Server;Svr;tyrone-cluster;Scheduler was sent the command new
03/26/2013 14:34:28;0040;PBS_Server;Svr;tyrone-cluster;Scheduler was sent the command new
03/26/2013 14:34:57;0040;PBS_Server;Svr;tyrone-cluster;Scheduler was sent the command new
03/26/2013 14:35:27;0040;PBS_Server;Svr;tyrone-cluster;Scheduler was sent the command new
03/26/2013 14:35:58;0040;PBS_Server;Svr;tyrone-cluster;Scheduler was sent the command new
03/26/2013 14:36:27;0040;PBS_Server;Svr;tyrone-cluster;Scheduler was sent the command new
03/26/2013 14:36:57;0040;PBS_Server;Svr;tyrone-cluster;Scheduler was sent the command new
03/26/2013 14:37:28;0040;PBS_Server;Svr;tyrone-cluster;Scheduler was sent the command new
03/26/2013 14:37:57;0040;PBS_Server;Svr;tyrone-cluster;Scheduler was sent the command new
03/26/2013 14:38:27;0040;PBS_Server;Svr;tyrone-cluster;Scheduler was sent the command new
03/26/2013 14:38:29;0002;PBS_Server;Svr;PBS_Server;Torque Server Version = 3.0.5, loglevel = 0
03/26/2013 14:38:58;0040;PBS_Server;Svr;tyrone-cluster;Scheduler was sent the command new
03/26/2013 14:39:27;0040;PBS_Server;Svr;tyrone-cluster;Scheduler was sent the command new
03/26/2013 14:39:57;0040;PBS_Server;Svr;tyrone-cluster;Scheduler was sent the command new
03/26/2013 14:40:28;0040;PBS_Server;Svr;tyrone-cluster;Scheduler was sent the command new
03/26/2013 14:40:57;0040;PBS_Server;Svr;tyrone-cluster;Scheduler was sent the command new
03/26/2013 14:41:27;0040;PBS_Server;Svr;tyrone-cluster;Scheduler was sent the command new
03/26/2013 14:41:58;0040;PBS_Server;Svr;tyrone-cluster;Scheduler was sent the command new
03/26/2013 14:42:27;0040;PBS_Server;Svr;tyrone-cluster;Scheduler was sent the command new
03/26/2013 14:42:42;0100;PBS_Server;Job;20479.tyrone-cluster;enqueuing into batch, state 1 hop 1
03/26/2013 14:42:42;0100;PBS_Server;Job;20479.tyrone-cluster;dequeuing from batch, state QUEUED
03/26/2013 14:42:42;0100;PBS_Server;Job;20479.tyrone-cluster;enqueuing into qp64, state 1 hop 1
03/26/2013 14:42:42;0008;PBS_Server;Job;20479.tyrone-cluster;Job Queued at request of mbumasha@tyrone-cluster, owner = mbumasha@tyrone-cluster, job name = mlecdig5-22-03-13, queue = qp64
03/26/2013 14:42:42;0040;PBS_Server;Svr;tyrone-cluster;Scheduler was sent the command new
03/26/2013 14:42:42;0008;PBS_Server;Job;20479.tyrone-cluster;Job Modified at request of Scheduler@tyrone-cluster
03/26/2013 14:42:57;0040;PBS_Server;Svr;tyrone-cluster;Scheduler was sent the command new
03/26/2013 14:43:28;0040;PBS_Server;Svr;tyrone-cluster;Scheduler was sent the command new
03/26/2013 14:43:29;0002;PBS_Server;Svr;PBS_Server;Torque Server Version = 3.0.5, loglevel = 0
03/26/2013 14:43:57;0040;PBS_Server;Svr;tyrone-cluster;Scheduler was sent the command new
03/26/2013 14:44:27;0040;PBS_Server;Svr;tyrone-cluster;Scheduler was sent the command new
03/26/2013 14:44:27;0100;PBS_Server;Job;20480.tyrone-cluster;enqueuing into batch, state 1 hop 1
03/26/2013 14:44:27;0100;PBS_Server;Job;20480.tyrone-cluster;dequeuing from batch, state QUEUED
03/26/2013 14:44:27;0100;PBS_Server;Job;20480.tyrone-cluster;enqueuing into qp32, state 1 hop 1
03/26/2013 14:44:27;0008;PBS_Server;Job;20480.tyrone-cluster;Job Queued at request of metposhi@tyrone-cluster, owner = metposhi@tyrone-cluster, job name = poshit1, queue = qp32
03/26/2013 14:44:27;0008;PBS_Server;Job;20480.tyrone-cluster;Job Modified at request of Scheduler@tyrone-cluster
03/26/2013 14:44:27;0008;PBS_Server;Job;20480.tyrone-cluster;Job Run at request of Scheduler@tyrone-cluster
03/26/2013 14:44:27;0040;PBS_Server;Svr;tyrone-cluster;Scheduler was sent the command recyc
03/26/2013 14:44:27;000d;PBS_Server;Job;20480.tyrone-cluster;Not sending email: User does not want mail of this type.
03/26/2013 14:44:33;000d;PBS_Server;Job;20480.tyrone-cluster;Not sending email: User does not want mail of this type.
03/26/2013 14:44:33;0010;PBS_Server;Job;20480.tyrone-cluster;Exit_status=0 resources_used.cput=00:00:36 resources_used.mem=0kb resources_used.vmem=0kb resources_used.walltime=00:00:06
03/26/2013 14:44:33;0008;PBS_Server;Job;NULL;on_job_exit valid pjob: 0x2e37f20 (substate=50)
03/26/2013 14:44:33;0008;PBS_Server;Job;NULL;on_job_exit valid pjob: 0x2e37f20 (substate=51)
03/26/2013 14:44:38;0008;PBS_Server;Job;NULL;on_job_exit valid pjob: 0x2e37f20 (substate=51)
03/26/2013 14:44:38;000d;PBS_Server;Job;20480.tyrone-cluster;Post job file processing error; job 20480.tyrone-cluster on host tyrone-node1/31+tyrone-node1/30+tyrone-node1/29+tyrone-node1/28+tyrone-node1/27+tyrone-node1/26+tyrone-node1/25+tyrone-node1/24+tyrone-node1/23+tyrone-node1/22+tyrone-node1/21+tyrone-node1/20+tyrone-node1/19+tyrone-node1/18+tyrone-node1/17+tyrone-node1/16+tyrone-node1/15+tyrone-node1/14+tyrone-node1/13+tyrone-node1/12+tyrone-node1/11+tyrone-node1/10+tyrone-node1/9+tyrone-node1/8+tyrone-node1/7+tyrone-node1/6+tyrone-node1/5+tyrone-node1/4+tyrone-node1/3+tyrone-node1/2+tyrone-node1/1+tyrone-node1/0
03/26/2013 14:44:38;0008;PBS_Server;Job;NULL;on_job_exit valid pjob: 0x2e37f20 (substate=53)
03/26/2013 14:44:38;0100;PBS_Server;Job;20480.tyrone-cluster;dequeuing from qp32, state COMPLETE
03/26/2013 14:44:38;0040;PBS_Server;Svr;tyrone-cluster;Scheduler was sent the command term
03/26/2013 14:44:58;0040;PBS_Server;Svr;tyrone-cluster;Scheduler was sent the command new
03/26/2013 14:45:27;0040;PBS_Server;Svr;tyrone-cluster;Scheduler was sent the command new
03/26/2013 14:45:57;0040;PBS_Server;Svr;tyrone-cluster;Scheduler was sent the command new
03/26/2013 14:46:28;0040;PBS_Server;Svr;tyrone-cluster;Scheduler was sent the command new
03/26/2013 14:46:41;0100;PBS_Server;Job;20481.tyrone-cluster;enqueuing into batch, state 1 hop 1
03/26/2013 14:46:41;0100;PBS_Server;Job;20481.tyrone-cluster;dequeuing from batch, state QUEUED
03/26/2013 14:46:41;0100;PBS_Server;Job;20481.tyrone-cluster;enqueuing into qp32, state 1 hop 1
03/26/2013 14:46:41;0008;PBS_Server;Job;20481.tyrone-cluster;Job Queued at request of metposhi@tyrone-cluster, owner = metposhi@tyrone-cluster, job name = poshit1, queue = qp32
03/26/2013 14:46:41;0040;PBS_Server;Svr;tyrone-cluster;Scheduler was sent the command new
03/26/2013 14:46:42;0008;PBS_Server;Job;20481.tyrone-cluster;Job Modified at request of Scheduler@tyrone-cluster
03/26/2013 14:46:42;0008;PBS_Server;Job;20481.tyrone-cluster;Job Run at request of Scheduler@tyrone-cluster
03/26/2013 14:46:42;0040;PBS_Server;Svr;tyrone-cluster;Scheduler was sent the command recyc
03/26/2013 14:46:42;000d;PBS_Server;Job;20481.tyrone-cluster;Not sending email: User does not want mail of this type.
03/26/2013 14:46:57;0040;PBS_Server;Svr;tyrone-cluster;Scheduler was sent the command new
03/26/2013 14:47:27;0040;PBS_Server;Svr;tyrone-cluster;Scheduler was sent the command new
03/26/2013 14:47:58;0040;PBS_Server;Svr;tyrone-cluster;Scheduler was sent the command new
03/26/2013 14:48:27;0040;PBS_Server;Svr;tyrone-cluster;Scheduler was sent the command new
03/26/2013 14:48:29;0002;PBS_Server;Svr;PBS_Server;Torque Server Version = 3.0.5, loglevel = 0
03/26/2013 14:48:45;0100;PBS_Server;Job;20482.tyrone-cluster;enqueuing into batch, state 1 hop 1
03/26/2013 14:48:45;0100;PBS_Server;Job;20482.tyrone-cluster;dequeuing from batch, state QUEUED
03/26/2013 14:48:45;0100;PBS_Server;Job;20482.tyrone-cluster;enqueuing into qp32, state 1 hop 1
03/26/2013 14:48:45;0008;PBS_Server;Job;20482.tyrone-cluster;Job Queued at request of metposhi@tyrone-cluster, owner = metposhi@tyrone-cluster, job name = poshit1, queue = qp32
03/26/2013 14:48:45;0040;PBS_Server;Svr;tyrone-cluster;Scheduler was sent the command new
03/26/2013 14:48:45;0008;PBS_Server;Job;20482.tyrone-cluster;Job Modified at request of Scheduler@tyrone-cluster
03/26/2013 14:48:57;0040;PBS_Server;Svr;tyrone-cluster;Scheduler was sent the command new
03/26/2013 14:49:28;0040;PBS_Server;Svr;tyrone-cluster;Scheduler was sent the command new
03/26/2013 14:49:57;0040;PBS_Server;Svr;tyrone-cluster;Scheduler was sent the command new
03/26/2013 14:50:27;0040;PBS_Server;Svr;tyrone-cluster;Scheduler was sent the command new
03/26/2013 14:50:58;0040;PBS_Server;Svr;tyrone-cluster;Scheduler was sent the command new
03/26/2013 14:51:27;0040;PBS_Server;Svr;tyrone-cluster;Scheduler was sent the command new
03/26/2013 14:51:57;0040;PBS_Server;Svr;tyrone-cluster;Scheduler was sent the command new
03/26/2013 14:52:28;0040;PBS_Server;Svr;tyrone-cluster;Scheduler was sent the command new
03/26/2013 14:52:57;0040;PBS_Server;Svr;tyrone-cluster;Scheduler was sent the command new
03/26/2013 14:53:27;0040;PBS_Server;Svr;tyrone-cluster;Scheduler was sent the command new
03/26/2013 14:53:29;0002;PBS_Server;Svr;PBS_Server;Torque Server Version = 3.0.5, loglevel = 0
03/26/2013 14:53:58;0040;PBS_Server;Svr;tyrone-cluster;Scheduler was sent the command new
03/26/2013 14:54:27;0040;PBS_Server;Svr;tyrone-cluster;Scheduler was sent the command new
03/26/2013 14:54:57;0040;PBS_Server;Svr;tyrone-cluster;Scheduler was sent the command new
03/26/2013 14:55:28;0040;PBS_Server;Svr;tyrone-cluster;Scheduler was sent the command new
03/26/2013 14:55:57;0040;PBS_Server;Svr;tyrone-cluster;Scheduler was sent the command new
03/26/2013 14:56:27;0040;PBS_Server;Svr;tyrone-cluster;Scheduler was sent the command new
03/26/2013 14:56:58;0040;PBS_Server;Svr;tyrone-cluster;Scheduler was sent the command new
03/26/2013 14:57:08;0100;PBS_Server;Job;20483.tyrone-cluster;enqueuing into batch, state 1 hop 1
03/26/2013 14:57:08;0100;PBS_Server;Job;20483.tyrone-cluster;dequeuing from batch, state QUEUED
03/26/2013 14:57:08;0100;PBS_Server;Job;20483.tyrone-cluster;enqueuing into idqueue, state 1 hop 1
03/26/2013 14:57:08;0008;PBS_Server;Job;20483.tyrone-cluster;Job Queued at request of metvura@tyrone-cluster, owner = metvura@tyrone-cluster, job name = vura1, queue = idqueue
03/26/2013 14:57:08;0040;PBS_Server;Svr;tyrone-cluster;Scheduler was sent the command new
03/26/2013 14:57:08;0008;PBS_Server;Job;20483.tyrone-cluster;Job Modified at request of Scheduler@tyrone-cluster
03/26/2013 14:57:08;0008;PBS_Server;Job;20483.tyrone-cluster;Job Run at request of Scheduler@tyrone-cluster
03/26/2013 14:57:08;0040;PBS_Server;Svr;tyrone-cluster;Scheduler was sent the command recyc
03/26/2013 14:57:08;000d;PBS_Server;Job;20483.tyrone-cluster;Not sending email: User does not want mail of this type.
03/26/2013 14:57:27;0040;PBS_Server;Svr;tyrone-cluster;Scheduler was sent the command new
03/26/2013 14:57:57;0040;PBS_Server;Svr;tyrone-cluster;Scheduler was sent the command new
03/26/2013 14:58:28;0040;PBS_Server;Svr;tyrone-cluster;Scheduler was sent the command new
03/26/2013 14:58:29;0002;PBS_Server;Svr;PBS_Server;Torque Server Version = 3.0.5, loglevel = 0
03/26/2013 14:58:57;0040;PBS_Server;Svr;tyrone-cluster;Scheduler was sent the command new
03/26/2013 14:59:27;0040;PBS_Server;Svr;tyrone-cluster;Scheduler was sent the command new
03/26/2013 14:59:43;0100;PBS_Server;Job;20484.tyrone-cluster;enqueuing into batch, state 1 hop 1
03/26/2013 14:59:43;0100;PBS_Server;Job;20484.tyrone-cluster;dequeuing from batch, state QUEUED
03/26/2013 14:59:43;0100;PBS_Server;Job;20484.tyrone-cluster;enqueuing into qp32, state 1 hop 1
03/26/2013 14:59:43;0008;PBS_Server;Job;20484.tyrone-cluster;Job Queued at request of metvura@tyrone-cluster, owner = metvura@tyrone-cluster, job name = vura1, queue = qp32
03/26/2013 14:59:43;0040;PBS_Server;Svr;tyrone-cluster;Scheduler was sent the command new
03/26/2013 14:59:43;0008;PBS_Server;Job;20484.tyrone-cluster;Job Modified at request of Scheduler@tyrone-cluster
03/26/2013 14:59:58;0040;PBS_Server;Svr;tyrone-cluster;Scheduler was sent the command new
03/26/2013 15:00:27;0040;PBS_Server;Svr;tyrone-cluster;Scheduler was sent the command new
03/26/2013 15:00:57;0040;PBS_Server;Svr;tyrone-cluster;Scheduler was sent the command new
03/26/2013 15:01:28;0040;PBS_Server;Svr;tyrone-cluster;Scheduler was sent the command new
03/26/2013 15:01:57;0040;PBS_Server;Svr;tyrone-cluster;Scheduler was sent the command new
03/26/2013 15:02:27;0040;PBS_Server;Svr;tyrone-cluster;Scheduler was sent the command new
03/26/2013 15:02:58;0040;PBS_Server;Svr;tyrone-cluster;Scheduler was sent the command new
03/26/2013 15:03:27;0040;PBS_Server;Svr;tyrone-cluster;Scheduler was sent the command new
03/26/2013 15:03:29;0002;PBS_Server;Svr;PBS_Server;Torque Server Version = 3.0.5, loglevel = 0
03/26/2013 15:03:42;000d;PBS_Server;Job;20481.tyrone-cluster;Not sending email: User does not want mail of this type.
03/26/2013 15:03:42;0010;PBS_Server;Job;20481.tyrone-cluster;Exit_status=0 resources_used.cput=08:37:38 resources_used.mem=1417356kb resources_used.vmem=9810780kb resources_used.walltime=00:17:00
03/26/2013 15:03:42;0008;PBS_Server;Job;NULL;on_job_exit valid pjob: 0x2e37f20 (substate=50)
03/26/2013 15:03:42;0008;PBS_Server;Job;NULL;on_job_exit valid pjob: 0x2e37f20 (substate=51)
03/26/2013 15:03:46;0008;PBS_Server;Job;NULL;on_job_exit valid pjob: 0x2e37f20 (substate=51)
03/26/2013 15:03:46;000d;PBS_Server;Job;20481.tyrone-cluster;Post job file processing error; job 20481.tyrone-cluster on host tyrone-node1/31+tyrone-node1/30+tyrone-node1/29+tyrone-node1/28+tyrone-node1/27+tyrone-node1/26+tyrone-node1/25+tyrone-node1/24+tyrone-node1/23+tyrone-node1/22+tyrone-node1/21+tyrone-node1/20+tyrone-node1/19+tyrone-node1/18+tyrone-node1/17+tyrone-node1/16+tyrone-node1/15+tyrone-node1/14+tyrone-node1/13+tyrone-node1/12+tyrone-node1/11+tyrone-node1/10+tyrone-node1/9+tyrone-node1/8+tyrone-node1/7+tyrone-node1/6+tyrone-node1/5+tyrone-node1/4+tyrone-node1/3+tyrone-node1/2+tyrone-node1/1+tyrone-node1/0
03/26/2013 15:03:46;0008;PBS_Server;Job;NULL;on_job_exit valid pjob: 0x2e37f20 (substate=53)
03/26/2013 15:03:46;0100;PBS_Server;Job;20481.tyrone-cluster;dequeuing from qp32, state COMPLETE
03/26/2013 15:03:46;0040;PBS_Server;Svr;tyrone-cluster;Scheduler was sent the command term
03/26/2013 15:03:46;0008;PBS_Server;Job;20482.tyrone-cluster;Job Modified at request of Scheduler@tyrone-cluster
03/26/2013 15:03:46;0008;PBS_Server;Job;20482.tyrone-cluster;Job Run at request of Scheduler@tyrone-cluster
03/26/2013 15:03:47;0040;PBS_Server;Svr;tyrone-cluster;Scheduler was sent the command recyc
03/26/2013 15:03:47;000d;PBS_Server;Job;20482.tyrone-cluster;Not sending email: User does not want mail of this type.
03/26/2013 15:03:57;0040;PBS_Server;Svr;tyrone-cluster;Scheduler was sent the command new
03/26/2013 15:04:28;0040;PBS_Server;Svr;tyrone-cluster;Scheduler was sent the command new
03/26/2013 15:04:57;0040;PBS_Server;Svr;tyrone-cluster;Scheduler was sent the command new
03/26/2013 15:05:27;0040;PBS_Server;Svr;tyrone-cluster;Scheduler was sent the command new
03/26/2013 15:05:58;0040;PBS_Server;Svr;tyrone-cluster;Scheduler was sent the command new
03/26/2013 15:06:27;0040;PBS_Server;Svr;tyrone-cluster;Scheduler was sent the command new
03/26/2013 15:06:57;0040;PBS_Server;Svr;tyrone-cluster;Scheduler was sent the command new
03/26/2013 15:07:28;0040;PBS_Server;Svr;tyrone-cluster;Scheduler was sent the command new
03/26/2013 15:07:57;0040;PBS_Server;Svr;tyrone-cluster;Scheduler was sent the command new
03/26/2013 15:08:27;0040;PBS_Server;Svr;tyrone-cluster;Scheduler was sent the command new
03/26/2013 15:08:29;0002;PBS_Server;Svr;PBS_Server;Torque Server Version = 3.0.5, loglevel = 0
03/26/2013 15:08:58;0040;PBS_Server;Svr;tyrone-cluster;Scheduler was sent the command new
03/26/2013 15:09:27;0040;PBS_Server;Svr;tyrone-cluster;Scheduler was sent the command new
03/26/2013 15:09:57;0040;PBS_Server;Svr;tyrone-cluster;Scheduler was sent the command new
03/26/2013 15:10:28;0040;PBS_Server;Svr;tyrone-cluster;Scheduler was sent the command new
03/26/2013 15:10:57;0040;PBS_Server;Svr;tyrone-cluster;Scheduler was sent the command new
03/26/2013 15:11:27;0040;PBS_Server;Svr;tyrone-cluster;Scheduler was sent the command new
03/26/2013 15:11:33;000d;PBS_Server;Job;20453.tyrone-cluster;Not sending email: User does not want mail of this type.
03/26/2013 15:11:33;0010;PBS_Server;Job;20453.tyrone-cluster;Exit_status=0 resources_used.cput=171:04:48 resources_used.mem=4478340kb resources_used.vmem=8354516kb resources_used.walltime=06:04:38
03/26/2013 15:11:33;0008;PBS_Server;Job;NULL;on_job_exit valid pjob: 0x2e413e0 (substate=50)
03/26/2013 15:11:33;0008;PBS_Server;Job;NULL;on_job_exit valid pjob: 0x2e413e0 (substate=51)
03/26/2013 15:11:33;0008;PBS_Server;Job;NULL;on_job_exit valid pjob: 0x2e413e0 (substate=51)
03/26/2013 15:11:33;0008;PBS_Server;Job;NULL;on_job_exit valid pjob: 0x2e413e0 (substate=53)
03/26/2013 15:11:33;0100;PBS_Server;Job;20453.tyrone-cluster;dequeuing from qp32, state COMPLETE
03/26/2013 15:11:33;0040;PBS_Server;Svr;tyrone-cluster;Scheduler was sent the command term
03/26/2013 15:11:58;0040;PBS_Server;Svr;tyrone-cluster;Scheduler was sent the command new
03/26/2013 15:12:27;0040;PBS_Server;Svr;tyrone-cluster;Scheduler was sent the command new
03/26/2013 15:12:32;000d;PBS_Server;Job;20368.tyrone-cluster;Not sending email: User does not want mail of this type.
03/26/2013 15:12:32;0010;PBS_Server;Job;20368.tyrone-cluster;Exit_status=143 resources_used.cput=1535:32:45 resources_used.mem=2084984kb resources_used.vmem=35848484kb resources_used.walltime=24:00:40
03/26/2013 15:12:32;0008;PBS_Server;Job;NULL;on_job_exit valid pjob: 0x2e56040 (substate=50)
03/26/2013 15:12:32;0008;PBS_Server;Job;NULL;on_job_exit valid pjob: 0x2e56040 (substate=51)
03/26/2013 15:12:36;0008;PBS_Server;Job;NULL;on_job_exit valid pjob: 0x2e56040 (substate=51)
03/26/2013 15:12:36;000d;PBS_Server;Job;20368.tyrone-cluster;Post job file processing error; job 20368.tyrone-cluster on host tyrone-node10/63+tyrone-node10/62+tyrone-node10/61+tyrone-node10/60+tyrone-node10/59+tyrone-node10/58+tyrone-node10/57+tyrone-node10/56+tyrone-node10/55+tyrone-node10/54+tyrone-node10/53+tyrone-node10/52+tyrone-node10/51+tyrone-node10/50+tyrone-node10/49+tyrone-node10/48+tyrone-node10/47+tyrone-node10/46+tyrone-node10/45+tyrone-node10/44+tyrone-node10/43+tyrone-node10/42+tyrone-node10/41+tyrone-node10/40+tyrone-node10/39+tyrone-node10/38+tyrone-node10/37+tyrone-node10/36+tyrone-node10/35+tyrone-node10/34+tyrone-node10/33+tyrone-node10/32+tyrone-node10/31+tyrone-node10/30+tyrone-node10/29+tyrone-node10/28+tyrone-node10/27+tyrone-node10/26+tyrone-node10/25+tyrone-node10/24+tyrone-node10/23+tyrone-node10/22+tyrone-node10/21+tyrone-node10/20+tyrone-node10/19+tyrone-node10/18+tyrone-node10/17+tyrone-node10/16+tyrone-node10/15+tyrone-node10/14+tyrone-node10/13+tyrone-node10/12+tyrone-node10/11+tyrone-node10/10+tyrone-node10/9+tyrone-node10/8+tyrone-node10/7+tyrone-node10/6+tyrone-node10/5+tyrone-node10/4+tyrone-node10/3+tyrone-node10/2+tyrone-node10/1+tyrone-node10/0
03/26/2013 15:12:36;0008;PBS_Server;Job;NULL;on_job_exit valid pjob: 0x2e56040 (substate=53)
03/26/2013 15:12:36;0100;PBS_Server;Job;20368.tyrone-cluster;dequeuing from qp64, state COMPLETE
03/26/2013 15:12:36;0040;PBS_Server;Svr;tyrone-cluster;Scheduler was sent the command term
03/26/2013 15:12:36;0008;PBS_Server;Job;20457.tyrone-cluster;Job Modified at request of Scheduler@tyrone-cluster
03/26/2013 15:12:36;0008;PBS_Server;Job;20457.tyrone-cluster;Job Run at request of Scheduler@tyrone-cluster
03/26/2013 15:12:36;0040;PBS_Server;Svr;tyrone-cluster;Scheduler was sent the command recyc
03/26/2013 15:12:36;000d;PBS_Server;Job;20457.tyrone-cluster;Not sending email: User does not want mail of this type.
03/26/2013 15:12:57;0040;PBS_Server;Svr;tyrone-cluster;Scheduler was sent the command new
03/26/2013 15:13:28;0040;PBS_Server;Svr;tyrone-cluster;Scheduler was sent the command new
03/26/2013 15:13:29;0002;PBS_Server;Svr;PBS_Server;Torque Server Version = 3.0.5, loglevel = 0
03/26/2013 15:13:57;0040;PBS_Server;Svr;tyrone-cluster;Scheduler was sent the command new
03/26/2013 15:14:27;0040;PBS_Server;Svr;tyrone-cluster;Scheduler was sent the command new
03/26/2013 15:14:58;0040;PBS_Server;Svr;tyrone-cluster;Scheduler was sent the command new
03/26/2013 15:15:27;0040;PBS_Server;Svr;tyrone-cluster;Scheduler was sent the command new
03/26/2013 15:15:57;0040;PBS_Server;Svr;tyrone-cluster;Scheduler was sent the command new
03/26/2013 15:16:28;0040;PBS_Server;Svr;tyrone-cluster;Scheduler was sent the command new
03/26/2013 15:16:30;000d;PBS_Server;Job;20456.tyrone-cluster;Not sending email: User does not want mail of this type.
03/26/2013 15:16:30;0010;PBS_Server;Job;20456.tyrone-cluster;Exit_status=0 resources_used.cput=329:17:34 resources_used.mem=2122792kb resources_used.vmem=35896968kb resources_used.walltime=05:09:50
03/26/2013 15:16:30;0008;PBS_Server;Job;NULL;on_job_exit valid pjob: 0x2e3bf70 (substate=50)
03/26/2013 15:16:30;0008;PBS_Server;Job;NULL;on_job_exit valid pjob: 0x2e3bf70 (substate=51)
03/26/2013 15:16:35;0008;PBS_Server;Job;NULL;on_job_exit valid pjob: 0x2e3bf70 (substate=51)
03/26/2013 15:16:35;0008;PBS_Server;Job;NULL;on_job_exit valid pjob: 0x2e3bf70 (substate=53)
03/26/2013 15:16:35;0100;PBS_Server;Job;20456.tyrone-cluster;dequeuing from qp64, state COMPLETE
03/26/2013 15:16:35;0040;PBS_Server;Svr;tyrone-cluster;Scheduler was sent the command term
03/26/2013 15:16:35;0008;PBS_Server;Job;20458.tyrone-cluster;Job Modified at request of Scheduler@tyrone-cluster
03/26/2013 15:16:35;0008;PBS_Server;Job;20458.tyrone-cluster;Job Run at request of Scheduler@tyrone-cluster
03/26/2013 15:16:35;0040;PBS_Server;Svr;tyrone-cluster;Scheduler was sent the command recyc
03/26/2013 15:16:35;000d;PBS_Server;Job;20458.tyrone-cluster;Not sending email: User does not want mail of this type.
03/26/2013 15:16:57;0040;PBS_Server;Svr;tyrone-cluster;Scheduler was sent the command new
03/26/2013 15:17:27;0040;PBS_Server;Svr;tyrone-cluster;Scheduler was sent the command new
03/26/2013 15:17:58;0040;PBS_Server;Svr;tyrone-cluster;Scheduler was sent the command new
03/26/2013 15:18:27;0040;PBS_Server;Svr;tyrone-cluster;Scheduler was sent the command new
03/26/2013 15:18:29;0002;PBS_Server;Svr;PBS_Server;Torque Server Version = 3.0.5, loglevel = 0
03/26/2013 15:18:57;0040;PBS_Server;Svr;tyrone-cluster;Scheduler was sent the command new
03/26/2013 15:19:28;0040;PBS_Server;Svr;tyrone-cluster;Scheduler was sent the command new
03/26/2013 15:19:57;0040;PBS_Server;Svr;tyrone-cluster;Scheduler was sent the command new
03/26/2013 15:20:27;0040;PBS_Server;Svr;tyrone-cluster;Scheduler was sent the command new
03/26/2013 15:20:58;0040;PBS_Server;Svr;tyrone-cluster;Scheduler was sent the command new
03/26/2013 15:21:27;0040;PBS_Server;Svr;tyrone-cluster;Scheduler was sent the command new
03/26/2013 15:21:57;0040;PBS_Server;Svr;tyrone-cluster;Scheduler was sent the command new
03/26/2013 15:22:28;0040;PBS_Server;Svr;tyrone-cluster;Scheduler was sent the command new
03/26/2013 15:22:57;0040;PBS_Server;Svr;tyrone-cluster;Scheduler was sent the command new
03/26/2013 15:23:27;0040;PBS_Server;Svr;tyrone-cluster;Scheduler was sent the command new
03/26/2013 15:23:29;0002;PBS_Server;Svr;PBS_Server;Torque Server Version = 3.0.5, loglevel = 0
03/26/2013 15:23:58;0040;PBS_Server;Svr;tyrone-cluster;Scheduler was sent the command new
03/26/2013 15:24:27;0040;PBS_Server;Svr;tyrone-cluster;Scheduler was sent the command new
03/26/2013 15:24:57;0040;PBS_Server;Svr;tyrone-cluster;Scheduler was sent the command new
03/26/2013 15:25:28;0040;PBS_Server;Svr;tyrone-cluster;Scheduler was sent the command new
03/26/2013 15:25:57;0040;PBS_Server;Svr;tyrone-cluster;Scheduler was sent the command new
03/26/2013 15:26:27;0040;PBS_Server;Svr;tyrone-cluster;Scheduler was sent the command new
03/26/2013 15:26:58;0040;PBS_Server;Svr;tyrone-cluster;Scheduler was sent the command new
03/26/2013 15:27:27;0040;PBS_Server;Svr;tyrone-cluster;Scheduler was sent the command new
03/26/2013 15:27:57;0040;PBS_Server;Svr;tyrone-cluster;Scheduler was sent the command new
03/26/2013 15:28:28;0040;PBS_Server;Svr;tyrone-cluster;Scheduler was sent the command new
03/26/2013 15:28:29;0002;PBS_Server;Svr;PBS_Server;Torque Server Version = 3.0.5, loglevel = 0
03/26/2013 15:28:57;0040;PBS_Server;Svr;tyrone-cluster;Scheduler was sent the command new
03/26/2013 15:29:27;0040;PBS_Server;Svr;tyrone-cluster;Scheduler was sent the command new
03/26/2013 15:29:58;0040;PBS_Server;Svr;tyrone-cluster;Scheduler was sent the command new
03/26/2013 15:30:27;0040;PBS_Server;Svr;tyrone-cluster;Scheduler was sent the command new
03/26/2013 15:30:57;0040;PBS_Server;Svr;tyrone-cluster;Scheduler was sent the command new
03/26/2013 15:31:07;0100;PBS_Server;Job;20485.tyrone-cluster;enqueuing into batch, state 1 hop 1
03/26/2013 15:31:07;0100;PBS_Server;Job;20485.tyrone-cluster;dequeuing from batch, state QUEUED
03/26/2013 15:31:07;0100;PBS_Server;Job;20485.tyrone-cluster;enqueuing into qp64, state 1 hop 1
03/26/2013 15:31:07;0008;PBS_Server;Job;20485.tyrone-cluster;Job Queued at request of mbumasha@tyrone-cluster, owner = mbumasha@tyrone-cluster, job name = mlecdig5-22-03-13, queue = qp64
03/26/2013 15:31:07;0040;PBS_Server;Svr;tyrone-cluster;Scheduler was sent the command new
03/26/2013 15:31:08;0008;PBS_Server;Job;20485.tyrone-cluster;Job Modified at request of Scheduler@tyrone-cluster
03/26/2013 15:31:28;0040;PBS_Server;Svr;tyrone-cluster;Scheduler was sent the command new
03/26/2013 15:31:28;0008;PBS_Server;Job;20479.tyrone-cluster;Job deleted at request of mbumasha@tyrone-cluster
03/26/2013 15:31:28;0008;PBS_Server;Job;NULL;on_job_exit valid pjob: 0x2e6b4e0 (substate=59)
03/26/2013 15:31:28;0100;PBS_Server;Job;20479.tyrone-cluster;dequeuing from qp64, state COMPLETE
03/26/2013 15:31:57;0040;PBS_Server;Svr;tyrone-cluster;Scheduler was sent the command new
03/26/2013 15:32:27;0040;PBS_Server;Svr;tyrone-cluster;Scheduler was sent the command new
03/26/2013 15:32:58;0040;PBS_Server;Svr;tyrone-cluster;Scheduler was sent the command new
03/26/2013 15:33:27;0040;PBS_Server;Svr;tyrone-cluster;Scheduler was sent the command new
03/26/2013 15:33:29;0002;PBS_Server;Svr;PBS_Server;Torque Server Version = 3.0.5, loglevel = 0
03/26/2013 15:33:57;0040;PBS_Server;Svr;tyrone-cluster;Scheduler was sent the command new
03/26/2013 15:34:28;0040;PBS_Server;Svr;tyrone-cluster;Scheduler was sent the command new
03/26/2013 15:34:57;0040;PBS_Server;Svr;tyrone-cluster;Scheduler was sent the command new
03/26/2013 15:35:27;0040;PBS_Server;Svr;tyrone-cluster;Scheduler was sent the command new
03/26/2013 15:35:58;0040;PBS_Server;Svr;tyrone-cluster;Scheduler was sent the command new
03/26/2013 15:36:27;0040;PBS_Server;Svr;tyrone-cluster;Scheduler was sent the command new
03/26/2013 15:36:57;0040;PBS_Server;Svr;tyrone-cluster;Scheduler was sent the command new
03/26/2013 15:37:28;0040;PBS_Server;Svr;tyrone-cluster;Scheduler was sent the command new
03/26/2013 15:37:57;0040;PBS_Server;Svr;tyrone-cluster;Scheduler was sent the command new
03/26/2013 15:38:27;0040;PBS_Server;Svr;tyrone-cluster;Scheduler was sent the command new
03/26/2013 15:38:29;0002;PBS_Server;Svr;PBS_Server;Torque Server Version = 3.0.5, loglevel = 0
03/26/2013 15:38:58;0040;PBS_Server;Svr;tyrone-cluster;Scheduler was sent the command new
03/26/2013 15:39:27;0040;PBS_Server;Svr;tyrone-cluster;Scheduler was sent the command new
03/26/2013 15:39:57;0040;PBS_Server;Svr;tyrone-cluster;Scheduler was sent the command new
03/26/2013 15:40:28;0040;PBS_Server;Svr;tyrone-cluster;Scheduler was sent the command new
03/26/2013 15:40:57;0040;PBS_Server;Svr;tyrone-cluster;Scheduler was sent the command new
03/26/2013 15:41:27;0040;PBS_Server;Svr;tyrone-cluster;Scheduler was sent the command new
03/26/2013 15:41:58;0040;PBS_Server;Svr;tyrone-cluster;Scheduler was sent the command new
03/26/2013 15:42:27;0040;PBS_Server;Svr;tyrone-cluster;Scheduler was sent the command new
03/26/2013 15:42:57;0040;PBS_Server;Svr;tyrone-cluster;Scheduler was sent the command new
03/26/2013 15:43:23;000d;PBS_Server;Job;20443.tyrone-cluster;Not sending email: User does not want mail of this type.
03/26/2013 15:43:23;0010;PBS_Server;Job;20443.tyrone-cluster;Exit_status=1 resources_used.cput=742:39:00 resources_used.mem=4344188kb resources_used.vmem=10553060kb resources_used.walltime=12:16:46
03/26/2013 15:43:23;0008;PBS_Server;Job;NULL;on_job_exit valid pjob: 0x2f622f0 (substate=50)
03/26/2013 15:43:23;0008;PBS_Server;Job;NULL;on_job_exit valid pjob: 0x2f622f0 (substate=51)
03/26/2013 15:43:23;0008;PBS_Server;Job;NULL;on_job_exit valid pjob: 0x2f622f0 (substate=51)
03/26/2013 15:43:23;0008;PBS_Server;Job;NULL;on_job_exit valid pjob: 0x2f622f0 (substate=53)
03/26/2013 15:43:23;0100;PBS_Server;Job;20443.tyrone-cluster;dequeuing from qp64, state COMPLETE
03/26/2013 15:43:23;0040;PBS_Server;Svr;tyrone-cluster;Scheduler was sent the command term
03/26/2013 15:43:23;0008;PBS_Server;Job;20475.tyrone-cluster;Job Modified at request of Scheduler@tyrone-cluster
03/26/2013 15:43:23;0008;PBS_Server;Job;20475.tyrone-cluster;Job Run at request of Scheduler@tyrone-cluster
03/26/2013 15:43:23;0040;PBS_Server;Svr;tyrone-cluster;Scheduler was sent the command recyc
03/26/2013 15:43:23;000d;PBS_Server;Job;20475.tyrone-cluster;Not sending email: User does not want mail of this type.
03/26/2013 15:43:28;0040;PBS_Server;Svr;tyrone-cluster;Scheduler was sent the command new
03/26/2013 15:43:29;0002;PBS_Server;Svr;PBS_Server;Torque Server Version = 3.0.5, loglevel = 0
03/26/2013 15:43:57;0040;PBS_Server;Svr;tyrone-cluster;Scheduler was sent the command new
03/26/2013 15:44:27;0040;PBS_Server;Svr;tyrone-cluster;Scheduler was sent the command new
03/26/2013 15:44:58;0040;PBS_Server;Svr;tyrone-cluster;Scheduler was sent the command new
03/26/2013 15:45:27;0040;PBS_Server;Svr;tyrone-cluster;Scheduler was sent the command new
03/26/2013 15:45:57;0040;PBS_Server;Svr;tyrone-cluster;Scheduler was sent the command new
03/26/2013 15:46:28;0040;PBS_Server;Svr;tyrone-cluster;Scheduler was sent the command new
03/26/2013 15:46:57;0040;PBS_Server;Svr;tyrone-cluster;Scheduler was sent the command new
03/26/2013 15:47:27;0040;PBS_Server;Svr;tyrone-cluster;Scheduler was sent the command new
03/26/2013 15:47:58;0040;PBS_Server;Svr;tyrone-cluster;Scheduler was sent the command new
03/26/2013 15:48:27;0040;PBS_Server;Svr;tyrone-cluster;Scheduler was sent the command new
03/26/2013 15:48:29;0002;PBS_Server;Svr;PBS_Server;Torque Server Version = 3.0.5, loglevel = 0
03/26/2013 15:48:57;0040;PBS_Server;Svr;tyrone-cluster;Scheduler was sent the command new
03/26/2013 15:49:28;0040;PBS_Server;Svr;tyrone-cluster;Scheduler was sent the command new
03/26/2013 15:49:57;0040;PBS_Server;Svr;tyrone-cluster;Scheduler was sent the command new
03/26/2013 15:50:27;0040;PBS_Server;Svr;tyrone-cluster;Scheduler was sent the command new
03/26/2013 15:50:58;0040;PBS_Server;Svr;tyrone-cluster;Scheduler was sent the command new
03/26/2013 15:51:27;0040;PBS_Server;Svr;tyrone-cluster;Scheduler was sent the command new
03/26/2013 15:51:47;000d;PBS_Server;Job;20475.tyrone-cluster;Not sending email: User does not want mail of this type.
03/26/2013 15:51:47;0010;PBS_Server;Job;20475.tyrone-cluster;Exit_status=0 resources_used.cput=08:48:20 resources_used.mem=7427572kb resources_used.vmem=40681940kb resources_used.walltime=00:08:24
03/26/2013 15:51:47;0008;PBS_Server;Job;NULL;on_job_exit valid pjob: 0x2ec4080 (substate=50)
03/26/2013 15:51:47;0008;PBS_Server;Job;NULL;on_job_exit valid pjob: 0x2ec4080 (substate=51)
03/26/2013 15:51:47;0008;PBS_Server;Job;NULL;on_job_exit valid pjob: 0x2ec4080 (substate=51)
03/26/2013 15:51:47;0008;PBS_Server;Job;NULL;on_job_exit valid pjob: 0x2ec4080 (substate=53)
03/26/2013 15:51:47;0100;PBS_Server;Job;20475.tyrone-cluster;dequeuing from qp64, state COMPLETE
03/26/2013 15:51:47;0040;PBS_Server;Svr;tyrone-cluster;Scheduler was sent the command term
03/26/2013 15:51:47;0008;PBS_Server;Job;20476.tyrone-cluster;Job Modified at request of Scheduler@tyrone-cluster
03/26/2013 15:51:47;0008;PBS_Server;Job;20476.tyrone-cluster;Job Run at request of Scheduler@tyrone-cluster
03/26/2013 15:51:47;0040;PBS_Server;Svr;tyrone-cluster;Scheduler was sent the command recyc
03/26/2013 15:51:47;000d;PBS_Server;Job;20476.tyrone-cluster;Not sending email: User does not want mail of this type.
03/26/2013 15:51:57;0100;PBS_Server;Job;20478.tyrone-cluster;dequeuing from batch, state QUEUED
03/26/2013 15:51:57;0100;PBS_Server;Job;20478.tyrone-cluster;enqueuing into qp64, state 1 hop 1
03/26/2013 15:51:57;0040;PBS_Server;Svr;tyrone-cluster;Scheduler was sent the command new
03/26/2013 15:51:57;0008;PBS_Server;Job;20478.tyrone-cluster;Job Modified at request of Scheduler@tyrone-cluster
03/26/2013 15:53:29;0002;PBS_Server;Svr;PBS_Server;Torque Server Version = 3.0.5, loglevel = 0
03/26/2013 15:58:29;0002;PBS_Server;Svr;PBS_Server;Torque Server Version = 3.0.5, loglevel = 0
03/26/2013 15:59:13;0100;PBS_Server;Job;20486.tyrone-cluster;enqueuing into batch, state 1 hop 1
03/26/2013 15:59:13;0100;PBS_Server;Job;20486.tyrone-cluster;dequeuing from batch, state QUEUED
03/26/2013 15:59:13;0100;PBS_Server;Job;20486.tyrone-cluster;enqueuing into idqueue, state 1 hop 1
03/26/2013 15:59:13;0008;PBS_Server;Job;20486.tyrone-cluster;Job Queued at request of mrcaks@tyrone-cluster, owner = mrcaks@tyrone-cluster, job name = borane_1C, queue = idqueue
03/26/2013 15:59:13;0040;PBS_Server;Svr;tyrone-cluster;Scheduler was sent the command new
03/26/2013 15:59:14;0008;PBS_Server;Job;20486.tyrone-cluster;Job Modified at request of Scheduler@tyrone-cluster
03/26/2013 15:59:14;0008;PBS_Server;Job;20486.tyrone-cluster;Job Run at request of Scheduler@tyrone-cluster
03/26/2013 15:59:14;0040;PBS_Server;Svr;tyrone-cluster;Scheduler was sent the command recyc
03/26/2013 15:59:14;000d;PBS_Server;Job;20486.tyrone-cluster;Not sending email: User does not want mail of this type.
03/26/2013 15:59:43;0100;PBS_Server;Job;20487.tyrone-cluster;enqueuing into batch, state 1 hop 1
03/26/2013 15:59:43;0100;PBS_Server;Job;20487.tyrone-cluster;dequeuing from batch, state QUEUED
03/26/2013 15:59:43;0100;PBS_Server;Job;20487.tyrone-cluster;enqueuing into idqueue, state 1 hop 1
03/26/2013 15:59:43;0008;PBS_Server;Job;20487.tyrone-cluster;Job Queued at request of phymjain@tyrone-cluster, owner = phymjain@tyrone-cluster, job name = Sisimple, queue = idqueue
03/26/2013 15:59:43;0040;PBS_Server;Svr;tyrone-cluster;Scheduler was sent the command new
03/26/2013 15:59:43;0008;PBS_Server;Job;20487.tyrone-cluster;Job Modified at request of Scheduler@tyrone-cluster
03/26/2013 15:59:43;0008;PBS_Server;Job;20487.tyrone-cluster;Job Run at request of Scheduler@tyrone-cluster
03/26/2013 15:59:44;0040;PBS_Server;Svr;tyrone-cluster;Scheduler was sent the command recyc
03/26/2013 15:59:44;000d;PBS_Server;Job;20487.tyrone-cluster;Not sending email: User does not want mail of this type.
03/26/2013 15:59:45;0100;PBS_Server;Job;20488.tyrone-cluster;enqueuing into batch, state 1 hop 1
03/26/2013 15:59:45;0100;PBS_Server;Job;20488.tyrone-cluster;dequeuing from batch, state QUEUED
03/26/2013 15:59:45;0100;PBS_Server;Job;20488.tyrone-cluster;enqueuing into idqueue, state 1 hop 1
03/26/2013 15:59:45;0008;PBS_Server;Job;20488.tyrone-cluster;Job Queued at request of mrcaks@tyrone-cluster, owner = mrcaks@tyrone-cluster, job name = borane_2C, queue = idqueue
03/26/2013 15:59:45;0040;PBS_Server;Svr;tyrone-cluster;Scheduler was sent the command new
03/26/2013 15:59:45;0008;PBS_Server;Job;20488.tyrone-cluster;Job Modified at request of Scheduler@tyrone-cluster
03/26/2013 15:59:46;000d;PBS_Server;Job;20487.tyrone-cluster;Not sending email: User does not want mail of this type.
03/26/2013 15:59:46;0010;PBS_Server;Job;20487.tyrone-cluster;Exit_status=0 resources_used.cput=00:00:10 resources_used.mem=0kb resources_used.vmem=0kb resources_used.walltime=00:00:03
03/26/2013 15:59:46;0008;PBS_Server;Job;NULL;on_job_exit valid pjob: 0x2ec4080 (substate=50)
03/26/2013 15:59:46;0008;PBS_Server;Job;NULL;on_job_exit valid pjob: 0x2ec4080 (substate=51)
03/26/2013 15:59:46;0008;PBS_Server;Job;NULL;on_job_exit valid pjob: 0x2ec4080 (substate=51)
03/26/2013 15:59:46;0008;PBS_Server;Job;NULL;on_job_exit valid pjob: 0x2ec4080 (substate=53)
03/26/2013 15:59:46;0100;PBS_Server;Job;20487.tyrone-cluster;dequeuing from idqueue, state COMPLETE
03/26/2013 15:59:46;0040;PBS_Server;Svr;tyrone-cluster;Scheduler was sent the command term
03/26/2013 15:59:46;0008;PBS_Server;Job;20488.tyrone-cluster;Job Modified at request of Scheduler@tyrone-cluster
03/26/2013 15:59:46;0008;PBS_Server;Job;20488.tyrone-cluster;Job Run at request of Scheduler@tyrone-cluster
03/26/2013 15:59:47;0040;PBS_Server;Svr;tyrone-cluster;Scheduler was sent the command recyc
03/26/2013 15:59:47;000d;PBS_Server;Job;20488.tyrone-cluster;Not sending email: User does not want mail of this type.
03/26/2013 16:00:36;0100;PBS_Server;Job;20489.tyrone-cluster;enqueuing into batch, state 1 hop 1
03/26/2013 16:00:36;0100;PBS_Server;Job;20489.tyrone-cluster;dequeuing from batch, state QUEUED
03/26/2013 16:00:36;0100;PBS_Server;Job;20489.tyrone-cluster;enqueuing into idqueue, state 1 hop 1
03/26/2013 16:00:36;0008;PBS_Server;Job;20489.tyrone-cluster;Job Queued at request of mrcaks@tyrone-cluster, owner = mrcaks@tyrone-cluster, job name = borane_3C, queue = idqueue
03/26/2013 16:00:36;0040;PBS_Server;Svr;tyrone-cluster;Scheduler was sent the command new
03/26/2013 16:00:36;0008;PBS_Server;Job;20489.tyrone-cluster;Job Modified at request of Scheduler@tyrone-cluster
03/26/2013 16:01:13;0100;PBS_Server;Job;20490.tyrone-cluster;enqueuing into batch, state 1 hop 1
03/26/2013 16:01:13;0100;PBS_Server;Job;20490.tyrone-cluster;dequeuing from batch, state QUEUED
03/26/2013 16:01:13;0100;PBS_Server;Job;20490.tyrone-cluster;enqueuing into idqueue, state 1 hop 1
03/26/2013 16:01:13;0008;PBS_Server;Job;20490.tyrone-cluster;Job Queued at request of phymjain@tyrone-cluster, owner = phymjain@tyrone-cluster, job name = ParaN6Medium, queue = idqueue
03/26/2013 16:01:13;0040;PBS_Server;Svr;tyrone-cluster;Scheduler was sent the command new
03/26/2013 16:01:13;0008;PBS_Server;Job;20490.tyrone-cluster;Job Modified at request of Scheduler@tyrone-cluster
03/26/2013 16:01:15;000d;PBS_Server;Job;20476.tyrone-cluster;Not sending email: User does not want mail of this type.
03/26/2013 16:01:15;0010;PBS_Server;Job;20476.tyrone-cluster;Exit_status=0 resources_used.cput=09:57:19 resources_used.mem=7919472kb resources_used.vmem=40985748kb resources_used.walltime=00:09:28
03/26/2013 16:01:15;0008;PBS_Server;Job;NULL;on_job_exit valid pjob: 0x2ec5340 (substate=50)
03/26/2013 16:01:15;0008;PBS_Server;Job;NULL;on_job_exit valid pjob: 0x2ec5340 (substate=51)
03/26/2013 16:01:15;0008;PBS_Server;Job;NULL;on_job_exit valid pjob: 0x2ec5340 (substate=51)
03/26/2013 16:01:15;0008;PBS_Server;Job;NULL;on_job_exit valid pjob: 0x2ec5340 (substate=53)
03/26/2013 16:01:15;0100;PBS_Server;Job;20476.tyrone-cluster;dequeuing from qp64, state COMPLETE
03/26/2013 16:01:15;0040;PBS_Server;Svr;tyrone-cluster;Scheduler was sent the command term
03/26/2013 16:01:15;0008;PBS_Server;Job;20477.tyrone-cluster;Job Modified at request of Scheduler@tyrone-cluster
03/26/2013 16:01:15;0008;PBS_Server;Job;20477.tyrone-cluster;Job Run at request of Scheduler@tyrone-cluster
03/26/2013 16:01:15;0040;PBS_Server;Svr;tyrone-cluster;Scheduler was sent the command recyc
03/26/2013 16:01:15;000d;PBS_Server;Job;20477.tyrone-cluster;Not sending email: User does not want mail of this type.
03/26/2013 16:01:20;0100;PBS_Server;Job;20491.tyrone-cluster;enqueuing into batch, state 1 hop 1
03/26/2013 16:01:20;0100;PBS_Server;Job;20491.tyrone-cluster;dequeuing from batch, state QUEUED
03/26/2013 16:01:20;0100;PBS_Server;Job;20491.tyrone-cluster;enqueuing into idqueue, state 1 hop 1
03/26/2013 16:01:20;0008;PBS_Server;Job;20491.tyrone-cluster;Job Queued at request of mrcaks@tyrone-cluster, owner = mrcaks@tyrone-cluster, job name = borane_4C, queue = idqueue
03/26/2013 16:01:20;0040;PBS_Server;Svr;tyrone-cluster;Scheduler was sent the command new
03/26/2013 16:01:20;0008;PBS_Server;Job;20491.tyrone-cluster;Job Modified at request of Scheduler@tyrone-cluster
03/26/2013 16:03:29;0002;PBS_Server;Svr;PBS_Server;Torque Server Version = 3.0.5, loglevel = 0
03/26/2013 16:05:33;0100;PBS_Server;Job;20492.tyrone-cluster;enqueuing into batch, state 1 hop 1
03/26/2013 16:05:33;0100;PBS_Server;Job;20492.tyrone-cluster;dequeuing from batch, state QUEUED
03/26/2013 16:05:33;0100;PBS_Server;Job;20492.tyrone-cluster;enqueuing into qp64, state 1 hop 1
03/26/2013 16:05:33;0008;PBS_Server;Job;20492.tyrone-cluster;Job Queued at request of mbumasha@tyrone-cluster, owner = mbumasha@tyrone-cluster, job name = mlecdig4-22-03-13, queue = qp64
03/26/2013 16:05:33;0040;PBS_Server;Svr;tyrone-cluster;Scheduler was sent the command new
03/26/2013 16:05:33;0008;PBS_Server;Job;20492.tyrone-cluster;Job Modified at request of Scheduler@tyrone-cluster
03/26/2013 16:08:29;0002;PBS_Server;Svr;PBS_Server;Torque Server Version = 3.0.5, loglevel = 0
03/26/2013 16:13:29;0002;PBS_Server;Svr;PBS_Server;Torque Server Version = 3.0.5, loglevel = 0
03/26/2013 16:15:33;0040;PBS_Server;Svr;tyrone-cluster;Scheduler was sent the command time
03/26/2013 16:18:29;0002;PBS_Server;Svr;PBS_Server;Torque Server Version = 3.0.5, loglevel = 0
03/26/2013 16:20:07;0100;PBS_Server;Job;20493.tyrone-cluster;enqueuing into batch, state 1 hop 1
03/26/2013 16:20:07;0100;PBS_Server;Job;20493.tyrone-cluster;dequeuing from batch, state QUEUED
03/26/2013 16:20:07;0100;PBS_Server;Job;20493.tyrone-cluster;enqueuing into qp32, state 1 hop 1
03/26/2013 16:20:07;0008;PBS_Server;Job;20493.tyrone-cluster;Job Queued at request of asealama@tyrone-cluster, owner = asealama@tyrone-cluster, job name = jobname, queue = qp32
03/26/2013 16:20:07;0040;PBS_Server;Svr;tyrone-cluster;Scheduler was sent the command new
03/26/2013 16:20:07;0008;PBS_Server;Job;20493.tyrone-cluster;Job Modified at request of Scheduler@tyrone-cluster
03/26/2013 16:20:07;0008;PBS_Server;Job;20493.tyrone-cluster;Job Run at request of Scheduler@tyrone-cluster
03/26/2013 16:20:08;0040;PBS_Server;Svr;tyrone-cluster;Scheduler was sent the command recyc
03/26/2013 16:20:08;000d;PBS_Server;Job;20493.tyrone-cluster;Not sending email: User does not want mail of this type.
03/26/2013 16:20:16;000d;PBS_Server;Job;20493.tyrone-cluster;Not sending email: User does not want mail of this type.
03/26/2013 16:20:16;0010;PBS_Server;Job;20493.tyrone-cluster;Exit_status=0 resources_used.cput=00:00:02 resources_used.mem=0kb resources_used.vmem=0kb resources_used.walltime=00:00:09
03/26/2013 16:20:16;0008;PBS_Server;Job;NULL;on_job_exit valid pjob: 0x2ec13f0 (substate=50)
03/26/2013 16:20:16;0008;PBS_Server;Job;NULL;on_job_exit valid pjob: 0x2ec13f0 (substate=51)
03/26/2013 16:20:16;0008;PBS_Server;Job;NULL;on_job_exit valid pjob: 0x2ec13f0 (substate=51)
03/26/2013 16:20:16;0008;PBS_Server;Job;NULL;on_job_exit valid pjob: 0x2ec13f0 (substate=53)
03/26/2013 16:20:16;0100;PBS_Server;Job;20493.tyrone-cluster;dequeuing from qp32, state COMPLETE
03/26/2013 16:20:16;0040;PBS_Server;Svr;tyrone-cluster;Scheduler was sent the command term
03/26/2013 16:23:29;0002;PBS_Server;Svr;PBS_Server;Torque Server Version = 3.0.5, loglevel = 0
03/26/2013 16:24:17;000d;PBS_Server;Job;20477.tyrone-cluster;Not sending email: User does not want mail of this type.
03/26/2013 16:24:17;0010;PBS_Server;Job;20477.tyrone-cluster;Exit_status=0 resources_used.cput=24:15:08 resources_used.mem=4341888kb resources_used.vmem=41298680kb resources_used.walltime=00:23:02
03/26/2013 16:24:17;0008;PBS_Server;Job;NULL;on_job_exit valid pjob: 0x2f6f550 (substate=50)
03/26/2013 16:24:17;0008;PBS_Server;Job;NULL;on_job_exit valid pjob: 0x2f6f550 (substate=51)
03/26/2013 16:24:17;0008;PBS_Server;Job;NULL;on_job_exit valid pjob: 0x2f6f550 (substate=51)
03/26/2013 16:24:17;0008;PBS_Server;Job;NULL;on_job_exit valid pjob: 0x2f6f550 (substate=53)
03/26/2013 16:24:17;0100;PBS_Server;Job;20477.tyrone-cluster;dequeuing from qp64, state COMPLETE
03/26/2013 16:24:17;0040;PBS_Server;Svr;tyrone-cluster;Scheduler was sent the command term
03/26/2013 16:24:17;0008;PBS_Server;Job;20485.tyrone-cluster;Job Modified at request of Scheduler@tyrone-cluster
03/26/2013 16:24:17;0008;PBS_Server;Job;20485.tyrone-cluster;Job Run at request of Scheduler@tyrone-cluster
03/26/2013 16:24:17;0040;PBS_Server;Svr;tyrone-cluster;Scheduler was sent the command recyc
03/26/2013 16:24:17;000d;PBS_Server;Job;20485.tyrone-cluster;Not sending email: User does not want mail of this type.
03/26/2013 16:25:32;0100;PBS_Server;Job;20494.tyrone-cluster;enqueuing into batch, state 1 hop 1
03/26/2013 16:25:32;0100;PBS_Server;Job;20494.tyrone-cluster;dequeuing from batch, state QUEUED
03/26/2013 16:25:32;0100;PBS_Server;Job;20494.tyrone-cluster;enqueuing into qp64, state 1 hop 1
03/26/2013 16:25:32;0008;PBS_Server;Job;20494.tyrone-cluster;Job Queued at request of asealama@tyrone-node9, owner = asealama@tyrone-node9, job name = jobname, queue = qp64
03/26/2013 16:25:32;0040;PBS_Server;Svr;tyrone-cluster;Scheduler was sent the command new
03/26/2013 16:25:32;0008;PBS_Server;Job;20494.tyrone-cluster;Job Modified at request of Scheduler@tyrone-cluster
03/26/2013 16:28:29;0002;PBS_Server;Svr;PBS_Server;Torque Server Version = 3.0.5, loglevel = 0
03/26/2013 16:31:13;0100;PBS_Server;Job;20495.tyrone-cluster;enqueuing into batch, state 1 hop 1
03/26/2013 16:31:13;0100;PBS_Server;Job;20495.tyrone-cluster;dequeuing from batch, state QUEUED
03/26/2013 16:31:13;0100;PBS_Server;Job;20495.tyrone-cluster;enqueuing into qp128, state 1 hop 1
03/26/2013 16:31:13;0008;PBS_Server;Job;20495.tyrone-cluster;Job Queued at request of phymjain@tyrone-cluster, owner = phymjain@tyrone-cluster, job name = ParaN6Medium, queue = qp128
03/26/2013 16:31:13;0040;PBS_Server;Svr;tyrone-cluster;Scheduler was sent the command new
03/26/2013 16:31:13;0008;PBS_Server;Job;20495.tyrone-cluster;Job Modified at request of Scheduler@tyrone-cluster
03/26/2013 16:31:13;0008;PBS_Server;Job;20495.tyrone-cluster;Job Run at request of Scheduler@tyrone-cluster
03/26/2013 16:31:13;0040;PBS_Server;Svr;tyrone-cluster;Scheduler was sent the command recyc
03/26/2013 16:31:20;000d;PBS_Server;Job;20495.tyrone-cluster;Not sending email: User does not want mail of this type.
03/26/2013 16:31:20;0010;PBS_Server;Job;20495.tyrone-cluster;Exit_status=0 resources_used.cput=00:00:00 resources_used.mem=800kb resources_used.vmem=13624kb resources_used.walltime=00:00:07
03/26/2013 16:31:20;0008;PBS_Server;Job;NULL;on_job_exit valid pjob: 0x2ec13f0 (substate=50)
03/26/2013 16:31:20;0008;PBS_Server;Job;NULL;on_job_exit valid pjob: 0x2ec13f0 (substate=51)
03/26/2013 16:31:20;0008;PBS_Server;Job;NULL;on_job_exit valid pjob: 0x2ec13f0 (substate=51)
03/26/2013 16:31:20;0008;PBS_Server;Job;NULL;on_job_exit valid pjob: 0x2ec13f0 (substate=53)
03/26/2013 16:31:20;0100;PBS_Server;Job;20495.tyrone-cluster;dequeuing from qp128, state COMPLETE
03/26/2013 16:31:20;0040;PBS_Server;Svr;tyrone-cluster;Scheduler was sent the command term
03/26/2013 16:31:20;0100;PBS_Server;Job;20496.tyrone-cluster;enqueuing into batch, state 1 hop 1
03/26/2013 16:31:21;0008;PBS_Server;Job;20496.tyrone-cluster;Job rejected by all possible destinations (check syntax, queue resources, ...)
03/26/2013 16:31:21;0100;PBS_Server;Job;20496.tyrone-cluster;dequeuing from batch, state QUEUED
03/26/2013 16:31:21;0080;PBS_Server;Req;req_reject;Reject reply code=15041(Job rejected by all possible destinations (check syntax, queue resources, ...)), aux=0, type=Commit, from phymjain@tyrone-cluster
03/26/2013 16:31:21;0040;PBS_Server;Svr;tyrone-cluster;Scheduler was sent the command term
03/26/2013 16:32:07;0100;PBS_Server;Job;20497.tyrone-cluster;enqueuing into batch, state 1 hop 1
03/26/2013 16:32:07;0008;PBS_Server;Job;20497.tyrone-cluster;Job rejected by all possible destinations (check syntax, queue resources, ...)
03/26/2013 16:32:07;0100;PBS_Server;Job;20497.tyrone-cluster;dequeuing from batch, state QUEUED
03/26/2013 16:32:07;0080;PBS_Server;Req;req_reject;Reject reply code=15041(Job rejected by all possible destinations (check syntax, queue resources, ...)), aux=0, type=Commit, from phymjain@tyrone-cluster
03/26/2013 16:32:07;0040;PBS_Server;Svr;tyrone-cluster;Scheduler was sent the command term
03/26/2013 16:32:31;0100;PBS_Server;Job;20498.tyrone-cluster;enqueuing into batch, state 1 hop 1
03/26/2013 16:32:31;0008;PBS_Server;Job;20498.tyrone-cluster;Job rejected by all possible destinations (check syntax, queue resources, ...)
03/26/2013 16:32:31;0100;PBS_Server;Job;20498.tyrone-cluster;dequeuing from batch, state QUEUED
03/26/2013 16:32:31;0080;PBS_Server;Req;req_reject;Reject reply code=15041(Job rejected by all possible destinations (check syntax, queue resources, ...)), aux=0, type=Commit, from phymjain@tyrone-cluster
03/26/2013 16:32:31;0040;PBS_Server;Svr;tyrone-cluster;Scheduler was sent the command term
03/26/2013 16:33:29;0002;PBS_Server;Svr;PBS_Server;Torque Server Version = 3.0.5, loglevel = 0
03/26/2013 16:34:56;0100;PBS_Server;Job;20499.tyrone-cluster;enqueuing into batch, state 1 hop 1
03/26/2013 16:34:56;0100;PBS_Server;Job;20499.tyrone-cluster;dequeuing from batch, state QUEUED
03/26/2013 16:34:56;0100;PBS_Server;Job;20499.tyrone-cluster;enqueuing into qp128, state 1 hop 1
03/26/2013 16:34:56;0008;PBS_Server;Job;20499.tyrone-cluster;Job Queued at request of phymjain@tyrone-cluster, owner = phymjain@tyrone-cluster, job name = ParaN6Medium, queue = qp128
03/26/2013 16:34:56;0040;PBS_Server;Svr;tyrone-cluster;Scheduler was sent the command new
03/26/2013 16:34:56;0008;PBS_Server;Job;20499.tyrone-cluster;Job Modified at request of Scheduler@tyrone-cluster
03/26/2013 16:34:56;0008;PBS_Server;Job;20499.tyrone-cluster;Job Run at request of Scheduler@tyrone-cluster
03/26/2013 16:34:56;0040;PBS_Server;Svr;tyrone-cluster;Scheduler was sent the command recyc
03/26/2013 16:35:03;000d;PBS_Server;Job;20499.tyrone-cluster;Not sending email: User does not want mail of this type.
03/26/2013 16:35:03;0010;PBS_Server;Job;20499.tyrone-cluster;Exit_status=255 resources_used.cput=00:00:01 resources_used.mem=796kb resources_used.vmem=13624kb resources_used.walltime=00:00:06
03/26/2013 16:35:03;0008;PBS_Server;Job;NULL;on_job_exit valid pjob: 0x2ec13f0 (substate=50)
03/26/2013 16:35:03;0008;PBS_Server;Job;NULL;on_job_exit valid pjob: 0x2ec13f0 (substate=51)
03/26/2013 16:35:03;0008;PBS_Server;Job;NULL;on_job_exit valid pjob: 0x2ec13f0 (substate=51)
03/26/2013 16:35:03;0008;PBS_Server;Job;NULL;on_job_exit valid pjob: 0x2ec13f0 (substate=53)
03/26/2013 16:35:03;0100;PBS_Server;Job;20499.tyrone-cluster;dequeuing from qp128, state COMPLETE
03/26/2013 16:35:03;0040;PBS_Server;Svr;tyrone-cluster;Scheduler was sent the command term
03/26/2013 16:38:29;0002;PBS_Server;Svr;PBS_Server;Torque Server Version = 3.0.5, loglevel = 0
03/26/2013 16:43:29;0002;PBS_Server;Svr;PBS_Server;Torque Server Version = 3.0.5, loglevel = 0
03/26/2013 16:45:03;0040;PBS_Server;Svr;tyrone-cluster;Scheduler was sent the command time
03/26/2013 16:46:28;0100;PBS_Server;Job;20500.tyrone-cluster;enqueuing into batch, state 1 hop 1
03/26/2013 16:46:28;0008;PBS_Server;Job;20500.tyrone-cluster;Job rejected by all possible destinations (check syntax, queue resources, ...)
03/26/2013 16:46:28;0100;PBS_Server;Job;20500.tyrone-cluster;dequeuing from batch, state QUEUED
03/26/2013 16:46:28;0080;PBS_Server;Req;req_reject;Reject reply code=15041(Job rejected by all possible destinations (check syntax, queue resources, ...)), aux=0, type=Commit, from phymjain@tyrone-cluster
03/26/2013 16:46:28;0040;PBS_Server;Svr;tyrone-cluster;Scheduler was sent the command term
03/26/2013 16:48:29;0002;PBS_Server;Svr;PBS_Server;Torque Server Version = 3.0.5, loglevel = 0
03/26/2013 16:49:21;0100;PBS_Server;Job;20501.tyrone-cluster;enqueuing into batch, state 1 hop 1
03/26/2013 16:49:21;0008;PBS_Server;Job;20501.tyrone-cluster;Job rejected by all possible destinations (check syntax, queue resources, ...)
03/26/2013 16:49:21;0100;PBS_Server;Job;20501.tyrone-cluster;dequeuing from batch, state QUEUED
03/26/2013 16:49:21;0080;PBS_Server;Req;req_reject;Reject reply code=15041(Job rejected by all possible destinations (check syntax, queue resources, ...)), aux=0, type=Commit, from phymjain@tyrone-cluster
03/26/2013 16:49:21;0040;PBS_Server;Svr;tyrone-cluster;Scheduler was sent the command term
03/26/2013 16:49:52;0100;PBS_Server;Job;20502.tyrone-cluster;enqueuing into batch, state 1 hop 1
03/26/2013 16:49:52;0008;PBS_Server;Job;20502.tyrone-cluster;Job rejected by all possible destinations (check syntax, queue resources, ...)
03/26/2013 16:49:52;0100;PBS_Server;Job;20502.tyrone-cluster;dequeuing from batch, state QUEUED
03/26/2013 16:49:52;0080;PBS_Server;Req;req_reject;Reject reply code=15041(Job rejected by all possible destinations (check syntax, queue resources, ...)), aux=0, type=Commit, from phymjain@tyrone-cluster
03/26/2013 16:49:52;0040;PBS_Server;Svr;tyrone-cluster;Scheduler was sent the command term
03/26/2013 16:50:54;0100;PBS_Server;Job;20503.tyrone-cluster;enqueuing into batch, state 1 hop 1
03/26/2013 16:50:54;0008;PBS_Server;Job;20503.tyrone-cluster;Job rejected by all possible destinations (check syntax, queue resources, ...)
03/26/2013 16:50:54;0100;PBS_Server;Job;20503.tyrone-cluster;dequeuing from batch, state QUEUED
03/26/2013 16:50:54;0080;PBS_Server;Req;req_reject;Reject reply code=15041(Job rejected by all possible destinations (check syntax, queue resources, ...)), aux=0, type=Commit, from phymjain@tyrone-cluster
03/26/2013 16:50:54;0040;PBS_Server;Svr;tyrone-cluster;Scheduler was sent the command term
03/26/2013 16:51:10;0100;PBS_Server;Job;20504.tyrone-cluster;enqueuing into batch, state 1 hop 1
03/26/2013 16:51:10;0008;PBS_Server;Job;20504.tyrone-cluster;Job rejected by all possible destinations (check syntax, queue resources, ...)
03/26/2013 16:51:10;0100;PBS_Server;Job;20504.tyrone-cluster;dequeuing from batch, state QUEUED
03/26/2013 16:51:10;0080;PBS_Server;Req;req_reject;Reject reply code=15041(Job rejected by all possible destinations (check syntax, queue resources, ...)), aux=0, type=Commit, from phymjain@tyrone-cluster
03/26/2013 16:51:10;0040;PBS_Server;Svr;tyrone-cluster;Scheduler was sent the command term
03/26/2013 16:52:24;0100;PBS_Server;Job;20505.tyrone-cluster;enqueuing into batch, state 1 hop 1
03/26/2013 16:52:24;0008;PBS_Server;Job;20505.tyrone-cluster;Job rejected by all possible destinations (check syntax, queue resources, ...)
03/26/2013 16:52:24;0100;PBS_Server;Job;20505.tyrone-cluster;dequeuing from batch, state QUEUED
03/26/2013 16:52:24;0080;PBS_Server;Req;req_reject;Reject reply code=15041(Job rejected by all possible destinations (check syntax, queue resources, ...)), aux=0, type=Commit, from phymjain@tyrone-cluster
03/26/2013 16:52:24;0040;PBS_Server;Svr;tyrone-cluster;Scheduler was sent the command term
03/26/2013 16:52:50;0100;PBS_Server;Job;20506.tyrone-cluster;enqueuing into batch, state 1 hop 1
03/26/2013 16:52:50;0008;PBS_Server;Job;20506.tyrone-cluster;Job rejected by all possible destinations (check syntax, queue resources, ...)
03/26/2013 16:52:50;0100;PBS_Server;Job;20506.tyrone-cluster;dequeuing from batch, state QUEUED
03/26/2013 16:52:50;0080;PBS_Server;Req;req_reject;Reject reply code=15041(Job rejected by all possible destinations (check syntax, queue resources, ...)), aux=0, type=Commit, from phymjain@tyrone-cluster
03/26/2013 16:52:50;0040;PBS_Server;Svr;tyrone-cluster;Scheduler was sent the command term
03/26/2013 16:53:29;0002;PBS_Server;Svr;PBS_Server;Torque Server Version = 3.0.5, loglevel = 0
03/26/2013 16:53:32;0100;PBS_Server;Job;20507.tyrone-cluster;enqueuing into batch, state 1 hop 1
03/26/2013 16:53:32;0100;PBS_Server;Job;20507.tyrone-cluster;dequeuing from batch, state QUEUED
03/26/2013 16:53:32;0100;PBS_Server;Job;20507.tyrone-cluster;enqueuing into idqueue, state 1 hop 1
03/26/2013 16:53:32;0008;PBS_Server;Job;20507.tyrone-cluster;Job Queued at request of phymjain@tyrone-cluster, owner = phymjain@tyrone-cluster, job name = Sisimple, queue = idqueue
03/26/2013 16:53:32;0040;PBS_Server;Svr;tyrone-cluster;Scheduler was sent the command new
03/26/2013 16:53:32;0008;PBS_Server;Job;20507.tyrone-cluster;Job Modified at request of Scheduler@tyrone-cluster
03/26/2013 16:57:54;000d;PBS_Server;Job;20483.tyrone-cluster;Not sending email: User does not want mail of this type.
03/26/2013 16:57:54;0010;PBS_Server;Job;20483.tyrone-cluster;Exit_status=143 resources_used.cput=23:58:28 resources_used.mem=1350324kb resources_used.vmem=9748636kb resources_used.walltime=02:00:46
03/26/2013 16:57:54;0008;PBS_Server;Job;NULL;on_job_exit valid pjob: 0x2f47310 (substate=50)
03/26/2013 16:57:54;0008;PBS_Server;Job;NULL;on_job_exit valid pjob: 0x2f47310 (substate=51)
03/26/2013 16:57:54;0008;PBS_Server;Job;NULL;on_job_exit valid pjob: 0x2f47310 (substate=51)
03/26/2013 16:57:54;0008;PBS_Server;Job;NULL;on_job_exit valid pjob: 0x2f47310 (substate=53)
03/26/2013 16:57:54;0100;PBS_Server;Job;20483.tyrone-cluster;dequeuing from idqueue, state COMPLETE
03/26/2013 16:57:54;0040;PBS_Server;Svr;tyrone-cluster;Scheduler was sent the command term
03/26/2013 16:57:54;0008;PBS_Server;Job;20490.tyrone-cluster;Job Modified at request of Scheduler@tyrone-cluster
03/26/2013 16:57:54;0008;PBS_Server;Job;20490.tyrone-cluster;Job Run at request of Scheduler@tyrone-cluster
03/26/2013 16:57:54;0040;PBS_Server;Svr;tyrone-cluster;Scheduler was sent the command recyc
03/26/2013 16:57:54;000d;PBS_Server;Job;20490.tyrone-cluster;Not sending email: User does not want mail of this type.
03/26/2013 16:57:58;000d;PBS_Server;Job;20490.tyrone-cluster;Not sending email: User does not want mail of this type.
03/26/2013 16:57:58;0010;PBS_Server;Job;20490.tyrone-cluster;Exit_status=174 resources_used.cput=00:00:17 resources_used.mem=0kb resources_used.vmem=0kb resources_used.walltime=00:00:04
03/26/2013 16:57:58;0008;PBS_Server;Job;NULL;on_job_exit valid pjob: 0x2ec4080 (substate=50)
03/26/2013 16:57:58;0008;PBS_Server;Job;NULL;on_job_exit valid pjob: 0x2ec4080 (substate=51)
03/26/2013 16:57:59;0008;PBS_Server;Job;NULL;on_job_exit valid pjob: 0x2ec4080 (substate=51)
03/26/2013 16:57:59;0008;PBS_Server;Job;NULL;on_job_exit valid pjob: 0x2ec4080 (substate=53)
03/26/2013 16:57:59;0100;PBS_Server;Job;20490.tyrone-cluster;dequeuing from idqueue, state COMPLETE
03/26/2013 16:57:59;0040;PBS_Server;Svr;tyrone-cluster;Scheduler was sent the command term
03/26/2013 16:57:59;0008;PBS_Server;Job;20507.tyrone-cluster;Job Modified at request of Scheduler@tyrone-cluster
03/26/2013 16:57:59;0008;PBS_Server;Job;20507.tyrone-cluster;Job Run at request of Scheduler@tyrone-cluster
03/26/2013 16:57:59;0040;PBS_Server;Svr;tyrone-cluster;Scheduler was sent the command recyc
03/26/2013 16:57:59;000d;PBS_Server;Job;20507.tyrone-cluster;Not sending email: User does not want mail of this type.
03/26/2013 16:58:03;000d;PBS_Server;Job;20507.tyrone-cluster;Not sending email: User does not want mail of this type.
03/26/2013 16:58:03;0010;PBS_Server;Job;20507.tyrone-cluster;Exit_status=0 resources_used.cput=00:00:10 resources_used.mem=0kb resources_used.vmem=0kb resources_used.walltime=00:00:03
03/26/2013 16:58:03;0008;PBS_Server;Job;NULL;on_job_exit valid pjob: 0x2ec13f0 (substate=50)
03/26/2013 16:58:03;0008;PBS_Server;Job;NULL;on_job_exit valid pjob: 0x2ec13f0 (substate=51)
03/26/2013 16:58:03;0008;PBS_Server;Job;NULL;on_job_exit valid pjob: 0x2ec13f0 (substate=51)
03/26/2013 16:58:03;0008;PBS_Server;Job;NULL;on_job_exit valid pjob: 0x2ec13f0 (substate=53)
03/26/2013 16:58:03;0100;PBS_Server;Job;20507.tyrone-cluster;dequeuing from idqueue, state COMPLETE
03/26/2013 16:58:03;0040;PBS_Server;Svr;tyrone-cluster;Scheduler was sent the command term
03/26/2013 16:58:29;0002;PBS_Server;Svr;PBS_Server;Torque Server Version = 3.0.5, loglevel = 0
03/26/2013 17:03:29;0002;PBS_Server;Svr;PBS_Server;Torque Server Version = 3.0.5, loglevel = 0
03/26/2013 17:03:46;000d;PBS_Server;Job;20372.tyrone-cluster;Not sending email: User does not want mail of this type.
03/26/2013 17:03:46;0010;PBS_Server;Job;20372.tyrone-cluster;Exit_status=143 resources_used.cput=768:00:58 resources_used.mem=3089860kb resources_used.vmem=7442808kb resources_used.walltime=24:00:41
03/26/2013 17:03:46;0008;PBS_Server;Job;NULL;on_job_exit valid pjob: 0x2e681a0 (substate=50)
03/26/2013 17:03:46;0008;PBS_Server;Job;NULL;on_job_exit valid pjob: 0x2e681a0 (substate=51)
03/26/2013 17:03:46;0008;PBS_Server;Job;NULL;on_job_exit valid pjob: 0x2e681a0 (substate=51)
03/26/2013 17:03:46;0008;PBS_Server;Job;NULL;on_job_exit valid pjob: 0x2e681a0 (substate=53)
03/26/2013 17:03:46;0100;PBS_Server;Job;20372.tyrone-cluster;dequeuing from qp64, state COMPLETE
03/26/2013 17:03:46;0040;PBS_Server;Svr;tyrone-cluster;Scheduler was sent the command term
03/26/2013 17:03:46;0008;PBS_Server;Job;20478.tyrone-cluster;Job Modified at request of Scheduler@tyrone-cluster
03/26/2013 17:03:46;0008;PBS_Server;Job;20478.tyrone-cluster;Job Run at request of Scheduler@tyrone-cluster
03/26/2013 17:03:46;0040;PBS_Server;Svr;tyrone-cluster;Scheduler was sent the command recyc
03/26/2013 17:03:46;000d;PBS_Server;Job;20478.tyrone-cluster;Not sending email: User does not want mail of this type.
03/26/2013 17:08:23;0100;PBS_Server;Job;20508.tyrone-cluster;enqueuing into batch, state 1 hop 1
03/26/2013 17:08:23;0100;PBS_Server;Job;20508.tyrone-cluster;dequeuing from batch, state QUEUED
03/26/2013 17:08:23;0100;PBS_Server;Job;20508.tyrone-cluster;enqueuing into qp32, state 1 hop 1
03/26/2013 17:08:23;0008;PBS_Server;Job;20508.tyrone-cluster;Job Queued at request of mrcpndey@tyrone-cluster, owner = mrcpndey@tyrone-cluster, job name = thiol, queue = qp32
03/26/2013 17:08:23;0040;PBS_Server;Svr;tyrone-cluster;Scheduler was sent the command new
03/26/2013 17:08:23;0008;PBS_Server;Job;20508.tyrone-cluster;Job Modified at request of Scheduler@tyrone-cluster
03/26/2013 17:08:23;0008;PBS_Server;Job;20508.tyrone-cluster;Job Run at request of Scheduler@tyrone-cluster
03/26/2013 17:08:23;0040;PBS_Server;Svr;tyrone-cluster;Scheduler was sent the command recyc
03/26/2013 17:08:23;000d;PBS_Server;Job;20508.tyrone-cluster;Not sending email: User does not want mail of this type.
03/26/2013 17:08:29;0002;PBS_Server;Svr;PBS_Server;Torque Server Version = 3.0.5, loglevel = 0
03/26/2013 17:13:29;0002;PBS_Server;Svr;PBS_Server;Torque Server Version = 3.0.5, loglevel = 0
03/26/2013 17:18:23;0040;PBS_Server;Svr;tyrone-cluster;Scheduler was sent the command time
03/26/2013 17:18:29;0002;PBS_Server;Svr;PBS_Server;Torque Server Version = 3.0.5, loglevel = 0
03/26/2013 17:21:08;0100;PBS_Server;Job;20509.tyrone-cluster;enqueuing into batch, state 1 hop 1
03/26/2013 17:21:08;0100;PBS_Server;Job;20509.tyrone-cluster;dequeuing from batch, state QUEUED
03/26/2013 17:21:08;0100;PBS_Server;Job;20509.tyrone-cluster;enqueuing into idqueue, state 1 hop 1
03/26/2013 17:21:08;0008;PBS_Server;Job;20509.tyrone-cluster;Job Queued at request of mrcaks@tyrone-cluster, owner = mrcaks@tyrone-cluster, job name = Bader_ScC_B5_0H2, queue = idqueue
03/26/2013 17:21:08;0040;PBS_Server;Svr;tyrone-cluster;Scheduler was sent the command new
03/26/2013 17:21:08;0008;PBS_Server;Job;20509.tyrone-cluster;Job Modified at request of Scheduler@tyrone-cluster
03/26/2013 17:23:29;0002;PBS_Server;Svr;PBS_Server;Torque Server Version = 3.0.5, loglevel = 0
03/26/2013 17:24:20;0008;PBS_Server;Job;20509.tyrone-cluster;Job deleted at request of mrcaks@tyrone-cluster
03/26/2013 17:24:20;0008;PBS_Server;Job;NULL;on_job_exit valid pjob: 0x2e788e0 (substate=59)
03/26/2013 17:24:20;0100;PBS_Server;Job;20509.tyrone-cluster;dequeuing from idqueue, state COMPLETE
03/26/2013 17:24:20;0040;PBS_Server;Svr;tyrone-cluster;Scheduler was sent the command term
03/26/2013 17:24:31;0100;PBS_Server;Job;20510.tyrone-cluster;enqueuing into batch, state 1 hop 1
03/26/2013 17:24:31;0100;PBS_Server;Job;20510.tyrone-cluster;dequeuing from batch, state QUEUED
03/26/2013 17:24:31;0100;PBS_Server;Job;20510.tyrone-cluster;enqueuing into idqueue, state 1 hop 1
03/26/2013 17:24:31;0008;PBS_Server;Job;20510.tyrone-cluster;Job Queued at request of mrcaks@tyrone-cluster, owner = mrcaks@tyrone-cluster, job name = Bader_ScC_B5_0H2, queue = idqueue
03/26/2013 17:24:31;0040;PBS_Server;Svr;tyrone-cluster;Scheduler was sent the command new
03/26/2013 17:24:32;0008;PBS_Server;Job;20510.tyrone-cluster;Job Modified at request of Scheduler@tyrone-cluster
03/26/2013 17:24:36;0100;PBS_Server;Job;20511.tyrone-cluster;enqueuing into batch, state 1 hop 1
03/26/2013 17:24:36;0100;PBS_Server;Job;20511.tyrone-cluster;dequeuing from batch, state QUEUED
03/26/2013 17:24:36;0100;PBS_Server;Job;20511.tyrone-cluster;enqueuing into idqueue, state 1 hop 1
03/26/2013 17:24:36;0008;PBS_Server;Job;20511.tyrone-cluster;Job Queued at request of mrcaks@tyrone-cluster, owner = mrcaks@tyrone-cluster, job name = Bader_ScC_B5_1H2, queue = idqueue
03/26/2013 17:24:36;0040;PBS_Server;Svr;tyrone-cluster;Scheduler was sent the command new
03/26/2013 17:24:36;0008;PBS_Server;Job;20511.tyrone-cluster;Job Modified at request of Scheduler@tyrone-cluster
03/26/2013 17:24:41;0100;PBS_Server;Job;20512.tyrone-cluster;enqueuing into batch, state 1 hop 1
03/26/2013 17:24:41;0100;PBS_Server;Job;20512.tyrone-cluster;dequeuing from batch, state QUEUED
03/26/2013 17:24:41;0100;PBS_Server;Job;20512.tyrone-cluster;enqueuing into idqueue, state 1 hop 1
03/26/2013 17:24:41;0008;PBS_Server;Job;20512.tyrone-cluster;Job Queued at request of mrcaks@tyrone-cluster, owner = mrcaks@tyrone-cluster, job name = Bader_ScC_B5_2H2, queue = idqueue
03/26/2013 17:24:41;0040;PBS_Server;Svr;tyrone-cluster;Scheduler was sent the command new
03/26/2013 17:24:41;0008;PBS_Server;Job;20512.tyrone-cluster;Job Modified at request of Scheduler@tyrone-cluster
03/26/2013 17:24:43;0100;PBS_Server;Job;20513.tyrone-cluster;enqueuing into batch, state 1 hop 1
03/26/2013 17:24:43;0100;PBS_Server;Job;20513.tyrone-cluster;dequeuing from batch, state QUEUED
03/26/2013 17:24:43;0100;PBS_Server;Job;20513.tyrone-cluster;enqueuing into idqueue, state 1 hop 1
03/26/2013 17:24:43;0008;PBS_Server;Job;20513.tyrone-cluster;Job Queued at request of mrcaks@tyrone-cluster, owner = mrcaks@tyrone-cluster, job name = Bader_ScC_B5_3H2, queue = idqueue
03/26/2013 17:24:43;0040;PBS_Server;Svr;tyrone-cluster;Scheduler was sent the command new
03/26/2013 17:24:44;0008;PBS_Server;Job;20513.tyrone-cluster;Job Modified at request of Scheduler@tyrone-cluster
03/26/2013 17:24:46;0100;PBS_Server;Job;20514.tyrone-cluster;enqueuing into batch, state 1 hop 1
03/26/2013 17:24:46;0100;PBS_Server;Job;20514.tyrone-cluster;dequeuing from batch, state QUEUED
03/26/2013 17:24:46;0100;PBS_Server;Job;20514.tyrone-cluster;enqueuing into idqueue, state 1 hop 1
03/26/2013 17:24:46;0008;PBS_Server;Job;20514.tyrone-cluster;Job Queued at request of mrcaks@tyrone-cluster, owner = mrcaks@tyrone-cluster, job name = Bader_ScC_B5_4H2, queue = idqueue
03/26/2013 17:24:46;0040;PBS_Server;Svr;tyrone-cluster;Scheduler was sent the command new
03/26/2013 17:24:47;0008;PBS_Server;Job;20514.tyrone-cluster;Job Modified at request of Scheduler@tyrone-cluster
03/26/2013 17:24:49;0100;PBS_Server;Job;20515.tyrone-cluster;enqueuing into batch, state 1 hop 1
03/26/2013 17:24:49;0100;PBS_Server;Job;20515.tyrone-cluster;dequeuing from batch, state QUEUED
03/26/2013 17:24:49;0100;PBS_Server;Job;20515.tyrone-cluster;enqueuing into idqueue, state 1 hop 1
03/26/2013 17:24:49;0008;PBS_Server;Job;20515.tyrone-cluster;Job Queued at request of mrcaks@tyrone-cluster, owner = mrcaks@tyrone-cluster, job name = Bader_ScC_B5_5H2, queue = idqueue
03/26/2013 17:24:49;0040;PBS_Server;Svr;tyrone-cluster;Scheduler was sent the command new
03/26/2013 17:24:49;0008;PBS_Server;Job;20515.tyrone-cluster;Job Modified at request of Scheduler@tyrone-cluster
03/26/2013 17:28:29;0002;PBS_Server;Svr;PBS_Server;Torque Server Version = 3.0.5, loglevel = 0
03/26/2013 17:29:32;0100;PBS_Server;Job;20516.tyrone-cluster;enqueuing into batch, state 1 hop 1
03/26/2013 17:29:32;0100;PBS_Server;Job;20516.tyrone-cluster;dequeuing from batch, state QUEUED
03/26/2013 17:29:32;0100;PBS_Server;Job;20516.tyrone-cluster;enqueuing into qp64, state 1 hop 1
03/26/2013 17:29:32;0008;PBS_Server;Job;20516.tyrone-cluster;Job Queued at request of mrcpndey@tyrone-cluster, owner = mrcpndey@tyrone-cluster, job name = GO-4, queue = qp64
03/26/2013 17:29:32;0040;PBS_Server;Svr;tyrone-cluster;Scheduler was sent the command new
03/26/2013 17:29:32;0008;PBS_Server;Job;20516.tyrone-cluster;Job Modified at request of Scheduler@tyrone-cluster
03/26/2013 17:29:35;0100;PBS_Server;Job;20517.tyrone-cluster;enqueuing into batch, state 1 hop 1
03/26/2013 17:29:35;0100;PBS_Server;Job;20517.tyrone-cluster;dequeuing from batch, state QUEUED
03/26/2013 17:29:35;0100;PBS_Server;Job;20517.tyrone-cluster;enqueuing into qp64, state 1 hop 1
03/26/2013 17:29:35;0008;PBS_Server;Job;20517.tyrone-cluster;Job Queued at request of mrcpndey@tyrone-cluster, owner = mrcpndey@tyrone-cluster, job name = GO-5, queue = qp64
03/26/2013 17:29:35;0040;PBS_Server;Svr;tyrone-cluster;Scheduler was sent the command new
03/26/2013 17:29:35;0008;PBS_Server;Job;20517.tyrone-cluster;Job Modified at request of Scheduler@tyrone-cluster
03/26/2013 17:33:29;0002;PBS_Server;Svr;PBS_Server;Torque Server Version = 3.0.5, loglevel = 0
03/26/2013 17:38:29;0002;PBS_Server;Svr;PBS_Server;Torque Server Version = 3.0.5, loglevel = 0
03/26/2013 17:39:35;0040;PBS_Server;Svr;tyrone-cluster;Scheduler was sent the command time
03/26/2013 17:43:29;0002;PBS_Server;Svr;PBS_Server;Torque Server Version = 3.0.5, loglevel = 0
03/26/2013 17:48:29;0002;PBS_Server;Svr;PBS_Server;Torque Server Version = 3.0.5, loglevel = 0
03/26/2013 17:49:35;0040;PBS_Server;Svr;tyrone-cluster;Scheduler was sent the command time
03/26/2013 17:49:56;000d;PBS_Server;Job;20469.tyrone-cluster;Not sending email: User does not want mail of this type.
03/26/2013 17:49:56;0010;PBS_Server;Job;20469.tyrone-cluster;Exit_status=9 resources_used.cput=84:11:29 resources_used.mem=2218324kb resources_used.vmem=10653324kb resources_used.walltime=04:37:20
03/26/2013 17:49:56;0008;PBS_Server;Job;NULL;on_job_exit valid pjob: 0x2e59dc0 (substate=50)
03/26/2013 17:49:56;0008;PBS_Server;Job;NULL;on_job_exit valid pjob: 0x2e59dc0 (substate=51)
03/26/2013 17:49:56;0008;PBS_Server;Job;NULL;on_job_exit valid pjob: 0x2e59dc0 (substate=51)
03/26/2013 17:49:56;0008;PBS_Server;Job;NULL;on_job_exit valid pjob: 0x2e59dc0 (substate=53)
03/26/2013 17:49:56;0100;PBS_Server;Job;20469.tyrone-cluster;dequeuing from qp32, state COMPLETE
03/26/2013 17:49:56;0040;PBS_Server;Svr;tyrone-cluster;Scheduler was sent the command term
03/26/2013 17:49:56;0008;PBS_Server;Job;20484.tyrone-cluster;Job Modified at request of Scheduler@tyrone-cluster
03/26/2013 17:49:56;0008;PBS_Server;Job;20484.tyrone-cluster;Job Run at request of Scheduler@tyrone-cluster
03/26/2013 17:49:56;0040;PBS_Server;Svr;tyrone-cluster;Scheduler was sent the command recyc
03/26/2013 17:49:56;000d;PBS_Server;Job;20484.tyrone-cluster;Not sending email: User does not want mail of this type.
03/26/2013 17:50:06;000d;PBS_Server;Job;20484.tyrone-cluster;Not sending email: User does not want mail of this type.
03/26/2013 17:50:06;0010;PBS_Server;Job;20484.tyrone-cluster;Exit_status=0 resources_used.cput=00:01:20 resources_used.mem=0kb resources_used.vmem=0kb resources_used.walltime=00:00:10
03/26/2013 17:50:06;0008;PBS_Server;Job;NULL;on_job_exit valid pjob: 0x2e74200 (substate=50)
03/26/2013 17:50:06;0008;PBS_Server;Job;NULL;on_job_exit valid pjob: 0x2e74200 (substate=51)
03/26/2013 17:50:06;0008;PBS_Server;Job;NULL;on_job_exit valid pjob: 0x2e74200 (substate=51)
03/26/2013 17:50:06;0008;PBS_Server;Job;NULL;on_job_exit valid pjob: 0x2e74200 (substate=53)
03/26/2013 17:50:06;0100;PBS_Server;Job;20484.tyrone-cluster;dequeuing from qp32, state COMPLETE
03/26/2013 17:50:06;0040;PBS_Server;Svr;tyrone-cluster;Scheduler was sent the command term
03/26/2013 17:53:29;0002;PBS_Server;Svr;PBS_Server;Torque Server Version = 3.0.5, loglevel = 0
03/26/2013 17:56:05;000d;PBS_Server;Job;20396.tyrone-cluster;Not sending email: User does not want mail of this type.
03/26/2013 17:56:05;0010;PBS_Server;Job;20396.tyrone-cluster;Exit_status=143 resources_used.cput=1498:27:13 resources_used.mem=4348304kb resources_used.vmem=10560696kb resources_used.walltime=24:00:27
03/26/2013 17:56:05;0008;PBS_Server;Job;NULL;on_job_exit valid pjob: 0x2e57300 (substate=50)
03/26/2013 17:56:05;0008;PBS_Server;Job;NULL;on_job_exit valid pjob: 0x2e57300 (substate=51)
03/26/2013 17:56:06;0008;PBS_Server;Job;NULL;on_job_exit valid pjob: 0x2e57300 (substate=51)
03/26/2013 17:56:06;0008;PBS_Server;Job;NULL;on_job_exit valid pjob: 0x2e57300 (substate=53)
03/26/2013 17:56:06;0100;PBS_Server;Job;20396.tyrone-cluster;dequeuing from qp64, state COMPLETE
03/26/2013 17:56:06;0040;PBS_Server;Svr;tyrone-cluster;Scheduler was sent the command term
03/26/2013 17:56:06;0008;PBS_Server;Job;20492.tyrone-cluster;Job Modified at request of Scheduler@tyrone-cluster
03/26/2013 17:56:06;0008;PBS_Server;Job;20492.tyrone-cluster;Job Run at request of Scheduler@tyrone-cluster
03/26/2013 17:56:06;0040;PBS_Server;Svr;tyrone-cluster;Scheduler was sent the command recyc
03/26/2013 17:56:06;000d;PBS_Server;Job;20492.tyrone-cluster;Not sending email: User does not want mail of this type.
03/26/2013 17:56:41;000d;PBS_Server;Job;20478.tyrone-cluster;Not sending email: User does not want mail of this type.
03/26/2013 17:56:41;0010;PBS_Server;Job;20478.tyrone-cluster;Exit_status=0 resources_used.cput=55:56:49 resources_used.mem=4895012kb resources_used.vmem=41850740kb resources_used.walltime=00:52:57
03/26/2013 17:56:41;0008;PBS_Server;Job;NULL;on_job_exit valid pjob: 0x2f7e490 (substate=50)
03/26/2013 17:56:41;0008;PBS_Server;Job;NULL;on_job_exit valid pjob: 0x2f7e490 (substate=51)
03/26/2013 17:56:41;0008;PBS_Server;Job;NULL;on_job_exit valid pjob: 0x2f7e490 (substate=51)
03/26/2013 17:56:41;0008;PBS_Server;Job;NULL;on_job_exit valid pjob: 0x2f7e490 (substate=53)
03/26/2013 17:56:41;0100;PBS_Server;Job;20478.tyrone-cluster;dequeuing from qp64, state COMPLETE
03/26/2013 17:56:41;0040;PBS_Server;Svr;tyrone-cluster;Scheduler was sent the command term
03/26/2013 17:56:41;0008;PBS_Server;Job;20494.tyrone-cluster;Job Modified at request of Scheduler@tyrone-cluster
03/26/2013 17:56:41;0008;PBS_Server;Job;20494.tyrone-cluster;Job Run at request of Scheduler@tyrone-cluster
03/26/2013 17:56:42;0040;PBS_Server;Svr;tyrone-cluster;Scheduler was sent the command recyc
03/26/2013 17:56:42;000d;PBS_Server;Job;20494.tyrone-cluster;Not sending email: User does not want mail of this type.
03/26/2013 17:56:51;000d;PBS_Server;Job;20494.tyrone-cluster;Not sending email: User does not want mail of this type.
03/26/2013 17:56:51;0010;PBS_Server;Job;20494.tyrone-cluster;Exit_status=0 resources_used.cput=00:00:00 resources_used.mem=0kb resources_used.vmem=0kb resources_used.walltime=00:00:10
03/26/2013 17:56:51;0008;PBS_Server;Job;NULL;on_job_exit valid pjob: 0x2e71070 (substate=50)
03/26/2013 17:56:51;0008;PBS_Server;Job;NULL;on_job_exit valid pjob: 0x2e71070 (substate=51)
03/26/2013 17:56:51;0008;PBS_Server;Job;NULL;on_job_exit valid pjob: 0x2e71070 (substate=51)
03/26/2013 17:56:51;0008;PBS_Server;Job;NULL;on_job_exit valid pjob: 0x2e71070 (substate=53)
03/26/2013 17:56:51;0100;PBS_Server;Job;20494.tyrone-cluster;dequeuing from qp64, state COMPLETE
03/26/2013 17:56:51;0040;PBS_Server;Svr;tyrone-cluster;Scheduler was sent the command term
03/26/2013 17:56:52;0008;PBS_Server;Job;20516.tyrone-cluster;Job Modified at request of Scheduler@tyrone-cluster
03/26/2013 17:56:52;0008;PBS_Server;Job;20516.tyrone-cluster;Job Run at request of Scheduler@tyrone-cluster
03/26/2013 17:56:52;0040;PBS_Server;Svr;tyrone-cluster;Scheduler was sent the command recyc
03/26/2013 17:56:52;000d;PBS_Server;Job;20516.tyrone-cluster;Not sending email: User does not want mail of this type.
03/26/2013 17:57:16;0008;PBS_Server;Job;20486.tyrone-cluster;Job deleted at request of mrcaks@tyrone-cluster
03/26/2013 17:57:16;0008;PBS_Server;Job;20486.tyrone-cluster;Job sent signal SIGTERM on delete
03/26/2013 17:57:16;000d;PBS_Server;Job;20486.tyrone-cluster;Not sending email: User does not want mail of this type.
03/26/2013 17:57:16;0010;PBS_Server;Job;20486.tyrone-cluster;Exit_status=143 resources_used.cput=18:53:31 resources_used.mem=10784536kb resources_used.vmem=22923916kb resources_used.walltime=01:58:02
03/26/2013 17:57:16;0008;PBS_Server;Job;NULL;on_job_exit valid pjob: 0x2f622f0 (substate=50)
03/26/2013 17:57:16;0008;PBS_Server;Job;NULL;on_job_exit valid pjob: 0x2f622f0 (substate=51)
03/26/2013 17:57:16;0008;PBS_Server;Job;NULL;on_job_exit valid pjob: 0x2f622f0 (substate=51)
03/26/2013 17:57:16;0008;PBS_Server;Job;NULL;on_job_exit valid pjob: 0x2f622f0 (substate=53)
03/26/2013 17:57:16;0100;PBS_Server;Job;20486.tyrone-cluster;dequeuing from idqueue, state COMPLETE
03/26/2013 17:57:16;0040;PBS_Server;Svr;tyrone-cluster;Scheduler was sent the command term
03/26/2013 17:57:16;0008;PBS_Server;Job;20489.tyrone-cluster;Job Modified at request of Scheduler@tyrone-cluster
03/26/2013 17:57:16;0008;PBS_Server;Job;20489.tyrone-cluster;Job Run at request of Scheduler@tyrone-cluster
03/26/2013 17:57:17;0040;PBS_Server;Svr;tyrone-cluster;Scheduler was sent the command recyc
03/26/2013 17:57:17;000d;PBS_Server;Job;20489.tyrone-cluster;Not sending email: User does not want mail of this type.
03/26/2013 17:58:00;0100;PBS_Server;Job;20518.tyrone-cluster;enqueuing into batch, state 1 hop 1
03/26/2013 17:58:00;0100;PBS_Server;Job;20518.tyrone-cluster;dequeuing from batch, state QUEUED
03/26/2013 17:58:00;0100;PBS_Server;Job;20518.tyrone-cluster;enqueuing into idqueue, state 1 hop 1
03/26/2013 17:58:00;0008;PBS_Server;Job;20518.tyrone-cluster;Job Queued at request of mrcaks@tyrone-cluster, owner = mrcaks@tyrone-cluster, job name = borane_1C, queue = idqueue
03/26/2013 17:58:00;0040;PBS_Server;Svr;tyrone-cluster;Scheduler was sent the command new
03/26/2013 17:58:00;0008;PBS_Server;Job;20518.tyrone-cluster;Job Modified at request of Scheduler@tyrone-cluster
03/26/2013 17:58:22;0008;PBS_Server;Job;20488.tyrone-cluster;Job deleted at request of mrcaks@tyrone-cluster
03/26/2013 17:58:22;0008;PBS_Server;Job;20488.tyrone-cluster;Job sent signal SIGTERM on delete
03/26/2013 17:58:22;000d;PBS_Server;Job;20488.tyrone-cluster;Not sending email: User does not want mail of this type.
03/26/2013 17:58:22;0010;PBS_Server;Job;20488.tyrone-cluster;Exit_status=143 resources_used.cput=19:02:29 resources_used.mem=10661456kb resources_used.vmem=22728580kb resources_used.walltime=01:58:36
03/26/2013 17:58:22;0008;PBS_Server;Job;NULL;on_job_exit valid pjob: 0x2e56040 (substate=50)
03/26/2013 17:58:22;0008;PBS_Server;Job;NULL;on_job_exit valid pjob: 0x2e56040 (substate=51)
03/26/2013 17:58:23;0008;PBS_Server;Job;NULL;on_job_exit valid pjob: 0x2e56040 (substate=51)
03/26/2013 17:58:23;0008;PBS_Server;Job;NULL;on_job_exit valid pjob: 0x2e56040 (substate=53)
03/26/2013 17:58:23;0100;PBS_Server;Job;20488.tyrone-cluster;dequeuing from idqueue, state COMPLETE
03/26/2013 17:58:23;0040;PBS_Server;Svr;tyrone-cluster;Scheduler was sent the command term
03/26/2013 17:58:23;0008;PBS_Server;Job;20491.tyrone-cluster;Job Modified at request of Scheduler@tyrone-cluster
03/26/2013 17:58:23;0008;PBS_Server;Job;20491.tyrone-cluster;Job Run at request of Scheduler@tyrone-cluster
03/26/2013 17:58:23;0040;PBS_Server;Svr;tyrone-cluster;Scheduler was sent the command recyc
03/26/2013 17:58:23;000d;PBS_Server;Job;20491.tyrone-cluster;Not sending email: User does not want mail of this type.
03/26/2013 17:58:29;0002;PBS_Server;Svr;PBS_Server;Torque Server Version = 3.0.5, loglevel = 0
03/26/2013 17:58:52;0100;PBS_Server;Job;20519.tyrone-cluster;enqueuing into batch, state 1 hop 1
03/26/2013 17:58:52;0100;PBS_Server;Job;20519.tyrone-cluster;dequeuing from batch, state QUEUED
03/26/2013 17:58:52;0100;PBS_Server;Job;20519.tyrone-cluster;enqueuing into idqueue, state 1 hop 1
03/26/2013 17:58:52;0008;PBS_Server;Job;20519.tyrone-cluster;Job Queued at request of mrcaks@tyrone-cluster, owner = mrcaks@tyrone-cluster, job name = borane_2C, queue = idqueue
03/26/2013 17:58:52;0040;PBS_Server;Svr;tyrone-cluster;Scheduler was sent the command new
03/26/2013 17:58:52;0008;PBS_Server;Job;20519.tyrone-cluster;Job Modified at request of Scheduler@tyrone-cluster
03/26/2013 17:59:22;000d;PBS_Server;Job;20516.tyrone-cluster;Not sending email: User does not want mail of this type.
03/26/2013 17:59:22;0010;PBS_Server;Job;20516.tyrone-cluster;Exit_status=0 resources_used.cput=02:36:11 resources_used.mem=7307796kb resources_used.vmem=40985348kb resources_used.walltime=00:02:30
03/26/2013 17:59:22;0008;PBS_Server;Job;NULL;on_job_exit valid pjob: 0x2e448b0 (substate=50)
03/26/2013 17:59:22;0008;PBS_Server;Job;NULL;on_job_exit valid pjob: 0x2e448b0 (substate=51)
03/26/2013 17:59:22;0008;PBS_Server;Job;NULL;on_job_exit valid pjob: 0x2e448b0 (substate=51)
03/26/2013 17:59:22;0008;PBS_Server;Job;NULL;on_job_exit valid pjob: 0x2e448b0 (substate=53)
03/26/2013 17:59:22;0100;PBS_Server;Job;20516.tyrone-cluster;dequeuing from qp64, state COMPLETE
03/26/2013 17:59:22;0040;PBS_Server;Svr;tyrone-cluster;Scheduler was sent the command term
03/26/2013 17:59:22;0008;PBS_Server;Job;20517.tyrone-cluster;Job Modified at request of Scheduler@tyrone-cluster
03/26/2013 17:59:22;0008;PBS_Server;Job;20517.tyrone-cluster;Job Run at request of Scheduler@tyrone-cluster
03/26/2013 17:59:22;0040;PBS_Server;Svr;tyrone-cluster;Scheduler was sent the command recyc
03/26/2013 17:59:22;000d;PBS_Server;Job;20517.tyrone-cluster;Not sending email: User does not want mail of this type.
03/26/2013 17:59:37;0008;PBS_Server;Job;20510.tyrone-cluster;Holds u set at request of mrcaks@tyrone-cluster
03/26/2013 17:59:37;0008;PBS_Server;Job;20511.tyrone-cluster;Holds u set at request of mrcaks@tyrone-cluster
03/26/2013 17:59:37;0008;PBS_Server;Job;20512.tyrone-cluster;Holds u set at request of mrcaks@tyrone-cluster
03/26/2013 17:59:37;0008;PBS_Server;Job;20513.tyrone-cluster;Holds u set at request of mrcaks@tyrone-cluster
03/26/2013 17:59:37;0008;PBS_Server;Job;20514.tyrone-cluster;Holds u set at request of mrcaks@tyrone-cluster
03/26/2013 17:59:37;0008;PBS_Server;Job;20515.tyrone-cluster;Holds u set at request of mrcaks@tyrone-cluster
03/26/2013 17:59:58;0100;PBS_Server;Job;20520.tyrone-cluster;enqueuing into batch, state 1 hop 1
03/26/2013 17:59:58;0100;PBS_Server;Job;20520.tyrone-cluster;dequeuing from batch, state QUEUED
03/26/2013 17:59:58;0100;PBS_Server;Job;20520.tyrone-cluster;enqueuing into idqueue, state 1 hop 1
03/26/2013 17:59:58;0008;PBS_Server;Job;20520.tyrone-cluster;Job Queued at request of phymjain@tyrone-cluster, owner = phymjain@tyrone-cluster, job name = ParaN6Medium, queue = idqueue
03/26/2013 17:59:58;0040;PBS_Server;Svr;tyrone-cluster;Scheduler was sent the command new
03/26/2013 17:59:58;0008;PBS_Server;Job;20520.tyrone-cluster;Job Modified at request of Scheduler@tyrone-cluster
03/26/2013 17:59:58;0008;PBS_Server;Job;20520.tyrone-cluster;Job Run at request of Scheduler@tyrone-cluster
03/26/2013 17:59:58;0040;PBS_Server;Svr;tyrone-cluster;Scheduler was sent the command recyc
03/26/2013 17:59:58;000d;PBS_Server;Job;20520.tyrone-cluster;Not sending email: User does not want mail of this type.
03/26/2013 18:00:02;000d;PBS_Server;Job;20520.tyrone-cluster;Not sending email: User does not want mail of this type.
03/26/2013 18:00:02;0010;PBS_Server;Job;20520.tyrone-cluster;Exit_status=174 resources_used.cput=00:00:23 resources_used.mem=0kb resources_used.vmem=0kb resources_used.walltime=00:00:04
03/26/2013 18:00:02;0008;PBS_Server;Job;NULL;on_job_exit valid pjob: 0x2e74200 (substate=50)
03/26/2013 18:00:02;0008;PBS_Server;Job;NULL;on_job_exit valid pjob: 0x2e74200 (substate=51)
03/26/2013 18:00:02;0008;PBS_Server;Job;NULL;on_job_exit valid pjob: 0x2e74200 (substate=51)
03/26/2013 18:00:02;0008;PBS_Server;Job;NULL;on_job_exit valid pjob: 0x2e74200 (substate=53)
03/26/2013 18:00:02;0100;PBS_Server;Job;20520.tyrone-cluster;dequeuing from idqueue, state COMPLETE
03/26/2013 18:00:02;0040;PBS_Server;Svr;tyrone-cluster;Scheduler was sent the command term
03/26/2013 18:01:11;0100;PBS_Server;Job;20521.tyrone-cluster;enqueuing into batch, state 1 hop 1
03/26/2013 18:01:11;0100;PBS_Server;Job;20521.tyrone-cluster;dequeuing from batch, state QUEUED
03/26/2013 18:01:11;0100;PBS_Server;Job;20521.tyrone-cluster;enqueuing into qp32, state 1 hop 1
03/26/2013 18:01:11;0008;PBS_Server;Job;20521.tyrone-cluster;Job Queued at request of mrcaks@tyrone-cluster, owner = mrcaks@tyrone-cluster, job name = borane_2C, queue = qp32
03/26/2013 18:01:11;0040;PBS_Server;Svr;tyrone-cluster;Scheduler was sent the command new
03/26/2013 18:01:11;0008;PBS_Server;Job;20521.tyrone-cluster;Job Modified at request of Scheduler@tyrone-cluster
03/26/2013 18:01:11;0008;PBS_Server;Job;20521.tyrone-cluster;Job Run at request of Scheduler@tyrone-cluster
03/26/2013 18:01:11;0040;PBS_Server;Svr;tyrone-cluster;Scheduler was sent the command recyc
03/26/2013 18:01:11;000d;PBS_Server;Job;20521.tyrone-cluster;Not sending email: User does not want mail of this type.
03/26/2013 18:01:24;0008;PBS_Server;Job;20519.tyrone-cluster;Job deleted at request of mrcaks@tyrone-cluster
03/26/2013 18:01:24;0008;PBS_Server;Job;NULL;on_job_exit valid pjob: 0x2e71070 (substate=59)
03/26/2013 18:01:24;0100;PBS_Server;Job;20519.tyrone-cluster;dequeuing from idqueue, state COMPLETE
03/26/2013 18:01:24;0040;PBS_Server;Svr;tyrone-cluster;Scheduler was sent the command term
03/26/2013 18:02:01;0100;PBS_Server;Job;20522.tyrone-cluster;enqueuing into batch, state 1 hop 1
03/26/2013 18:02:01;0100;PBS_Server;Job;20522.tyrone-cluster;dequeuing from batch, state QUEUED
03/26/2013 18:02:01;0100;PBS_Server;Job;20522.tyrone-cluster;enqueuing into qp32, state 1 hop 1
03/26/2013 18:02:01;0008;PBS_Server;Job;20522.tyrone-cluster;Job Queued at request of mrcaks@tyrone-cluster, owner = mrcaks@tyrone-cluster, job name = borane_1C, queue = qp32
03/26/2013 18:02:01;0040;PBS_Server;Svr;tyrone-cluster;Scheduler was sent the command new
03/26/2013 18:02:01;0008;PBS_Server;Job;20522.tyrone-cluster;Job Modified at request of Scheduler@tyrone-cluster
03/26/2013 18:02:01;0008;PBS_Server;Job;20522.tyrone-cluster;Job Run at request of Scheduler@tyrone-cluster
03/26/2013 18:02:01;0040;PBS_Server;Svr;tyrone-cluster;Scheduler was sent the command recyc
03/26/2013 18:02:01;000d;PBS_Server;Job;20522.tyrone-cluster;Not sending email: User does not want mail of this type.
03/26/2013 18:02:20;0008;PBS_Server;Job;20510.tyrone-cluster;Holds u released at request of mrcaks@tyrone-cluster
03/26/2013 18:02:20;0040;PBS_Server;Svr;tyrone-cluster;Scheduler was sent the command new
03/26/2013 18:02:20;0008;PBS_Server;Job;20511.tyrone-cluster;Holds u released at request of mrcaks@tyrone-cluster
03/26/2013 18:02:20;0008;PBS_Server;Job;20512.tyrone-cluster;Holds u released at request of mrcaks@tyrone-cluster
03/26/2013 18:02:20;0008;PBS_Server;Job;20513.tyrone-cluster;Holds u released at request of mrcaks@tyrone-cluster
03/26/2013 18:02:20;0008;PBS_Server;Job;20514.tyrone-cluster;Holds u released at request of mrcaks@tyrone-cluster
03/26/2013 18:02:20;0008;PBS_Server;Job;20515.tyrone-cluster;Holds u released at request of mrcaks@tyrone-cluster
03/26/2013 18:02:34;0008;PBS_Server;Job;20518.tyrone-cluster;Job deleted at request of mrcaks@tyrone-cluster
03/26/2013 18:02:34;0008;PBS_Server;Job;NULL;on_job_exit valid pjob: 0x2f622f0 (substate=59)
03/26/2013 18:02:34;0100;PBS_Server;Job;20518.tyrone-cluster;dequeuing from idqueue, state COMPLETE
03/26/2013 18:02:34;0040;PBS_Server;Svr;tyrone-cluster;Scheduler was sent the command term
03/26/2013 18:03:29;0002;PBS_Server;Svr;PBS_Server;Torque Server Version = 3.0.5, loglevel = 0
03/26/2013 18:07:11;0100;PBS_Server;Job;20523.tyrone-cluster;enqueuing into batch, state 1 hop 1
03/26/2013 18:07:12;0100;PBS_Server;Job;20523.tyrone-cluster;dequeuing from batch, state QUEUED
03/26/2013 18:07:12;0100;PBS_Server;Job;20523.tyrone-cluster;enqueuing into idqueue, state 1 hop 1
03/26/2013 18:07:12;0008;PBS_Server;Job;20523.tyrone-cluster;Job Queued at request of phymjain@tyrone-cluster, owner = phymjain@tyrone-cluster, job name = ParaN6Medium, queue = idqueue
03/26/2013 18:07:12;0040;PBS_Server;Svr;tyrone-cluster;Scheduler was sent the command new
03/26/2013 18:07:12;0008;PBS_Server;Job;20523.tyrone-cluster;Job Modified at request of Scheduler@tyrone-cluster
03/26/2013 18:07:12;0008;PBS_Server;Job;20523.tyrone-cluster;Job Run at request of Scheduler@tyrone-cluster
03/26/2013 18:07:13;0040;PBS_Server;Svr;tyrone-cluster;Scheduler was sent the command recyc
03/26/2013 18:07:13;000d;PBS_Server;Job;20523.tyrone-cluster;Not sending email: User does not want mail of this type.
03/26/2013 18:07:17;000d;PBS_Server;Job;20523.tyrone-cluster;Not sending email: User does not want mail of this type.
03/26/2013 18:07:17;0010;PBS_Server;Job;20523.tyrone-cluster;Exit_status=174 resources_used.cput=00:00:17 resources_used.mem=0kb resources_used.vmem=0kb resources_used.walltime=00:00:05
03/26/2013 18:07:17;0008;PBS_Server;Job;NULL;on_job_exit valid pjob: 0x2f622f0 (substate=50)
03/26/2013 18:07:17;0008;PBS_Server;Job;NULL;on_job_exit valid pjob: 0x2f622f0 (substate=51)
03/26/2013 18:07:17;0008;PBS_Server;Job;NULL;on_job_exit valid pjob: 0x2f622f0 (substate=51)
03/26/2013 18:07:17;0008;PBS_Server;Job;NULL;on_job_exit valid pjob: 0x2f622f0 (substate=53)
03/26/2013 18:07:17;0100;PBS_Server;Job;20523.tyrone-cluster;dequeuing from idqueue, state COMPLETE
03/26/2013 18:07:17;0040;PBS_Server;Svr;tyrone-cluster;Scheduler was sent the command term
03/26/2013 18:08:29;0002;PBS_Server;Svr;PBS_Server;Torque Server Version = 3.0.5, loglevel = 0
03/26/2013 18:11:46;000d;PBS_Server;Job;20521.tyrone-cluster;Not sending email: User does not want mail of this type.
03/26/2013 18:11:46;0010;PBS_Server;Job;20521.tyrone-cluster;Exit_status=0 resources_used.cput=05:36:59 resources_used.mem=10483980kb resources_used.vmem=21117324kb resources_used.walltime=00:10:35
03/26/2013 18:11:46;0008;PBS_Server;Job;NULL;on_job_exit valid pjob: 0x2e74200 (substate=50)
03/26/2013 18:11:46;0008;PBS_Server;Job;NULL;on_job_exit valid pjob: 0x2e74200 (substate=51)
03/26/2013 18:11:47;0008;PBS_Server;Job;NULL;on_job_exit valid pjob: 0x2e74200 (substate=51)
03/26/2013 18:11:47;0008;PBS_Server;Job;NULL;on_job_exit valid pjob: 0x2e74200 (substate=53)
03/26/2013 18:11:47;0100;PBS_Server;Job;20521.tyrone-cluster;dequeuing from qp32, state COMPLETE
03/26/2013 18:11:47;0040;PBS_Server;Svr;tyrone-cluster;Scheduler was sent the command term
03/26/2013 18:13:29;0002;PBS_Server;Svr;PBS_Server;Torque Server Version = 3.0.5, loglevel = 0
03/26/2013 18:13:29;0100;PBS_Server;Job;20524.tyrone-cluster;enqueuing into batch, state 1 hop 1
03/26/2013 18:13:29;0100;PBS_Server;Job;20524.tyrone-cluster;dequeuing from batch, state QUEUED
03/26/2013 18:13:29;0100;PBS_Server;Job;20524.tyrone-cluster;enqueuing into idqueue, state 1 hop 1
03/26/2013 18:13:29;0008;PBS_Server;Job;20524.tyrone-cluster;Job Queued at request of mrcaks@tyrone-cluster, owner = mrcaks@tyrone-cluster, job name = Sc_SiH_B5_7H2_15, queue = idqueue
03/26/2013 18:13:29;0040;PBS_Server;Svr;tyrone-cluster;Scheduler was sent the command new
03/26/2013 18:13:29;0008;PBS_Server;Job;20524.tyrone-cluster;Job Modified at request of Scheduler@tyrone-cluster
03/26/2013 18:14:52;0100;PBS_Server;Job;20525.tyrone-cluster;enqueuing into batch, state 1 hop 1
03/26/2013 18:14:52;0100;PBS_Server;Job;20525.tyrone-cluster;dequeuing from batch, state QUEUED
03/26/2013 18:14:52;0100;PBS_Server;Job;20525.tyrone-cluster;enqueuing into idqueue, state 1 hop 1
03/26/2013 18:14:52;0008;PBS_Server;Job;20525.tyrone-cluster;Job Queued at request of phymjain@tyrone-cluster, owner = phymjain@tyrone-cluster, job name = ParaN6Medium, queue = idqueue
03/26/2013 18:14:52;0040;PBS_Server;Svr;tyrone-cluster;Scheduler was sent the command new
03/26/2013 18:14:52;0008;PBS_Server;Job;20525.tyrone-cluster;Job Modified at request of Scheduler@tyrone-cluster
03/26/2013 18:14:52;0008;PBS_Server;Job;20525.tyrone-cluster;Job Run at request of Scheduler@tyrone-cluster
03/26/2013 18:14:52;0040;PBS_Server;Svr;tyrone-cluster;Scheduler was sent the command recyc
03/26/2013 18:14:52;000d;PBS_Server;Job;20525.tyrone-cluster;Not sending email: User does not want mail of this type.
03/26/2013 18:14:55;000d;PBS_Server;Job;20525.tyrone-cluster;Not sending email: User does not want mail of this type.
03/26/2013 18:14:55;0010;PBS_Server;Job;20525.tyrone-cluster;Exit_status=0 resources_used.cput=00:00:17 resources_used.mem=0kb resources_used.vmem=0kb resources_used.walltime=00:00:03
03/26/2013 18:14:55;0008;PBS_Server;Job;NULL;on_job_exit valid pjob: 0x2e74200 (substate=50)
03/26/2013 18:14:55;0008;PBS_Server;Job;NULL;on_job_exit valid pjob: 0x2e74200 (substate=51)
03/26/2013 18:14:55;0008;PBS_Server;Job;NULL;on_job_exit valid pjob: 0x2e74200 (substate=51)
03/26/2013 18:14:55;0008;PBS_Server;Job;NULL;on_job_exit valid pjob: 0x2e74200 (substate=53)
03/26/2013 18:14:55;0100;PBS_Server;Job;20525.tyrone-cluster;dequeuing from idqueue, state COMPLETE
03/26/2013 18:14:55;0040;PBS_Server;Svr;tyrone-cluster;Scheduler was sent the command term
03/26/2013 18:16:55;0100;PBS_Server;Job;20526.tyrone-cluster;enqueuing into batch, state 1 hop 1
03/26/2013 18:16:55;0100;PBS_Server;Job;20526.tyrone-cluster;dequeuing from batch, state QUEUED
03/26/2013 18:16:55;0100;PBS_Server;Job;20526.tyrone-cluster;enqueuing into idqueue, state 1 hop 1
03/26/2013 18:16:55;0008;PBS_Server;Job;20526.tyrone-cluster;Job Queued at request of phymjain@tyrone-cluster, owner = phymjain@tyrone-cluster, job name = ParaN6Medium, queue = idqueue
03/26/2013 18:16:55;0040;PBS_Server;Svr;tyrone-cluster;Scheduler was sent the command new
03/26/2013 18:16:55;0008;PBS_Server;Job;20526.tyrone-cluster;Job Modified at request of Scheduler@tyrone-cluster
03/26/2013 18:16:55;0008;PBS_Server;Job;20526.tyrone-cluster;Job Run at request of Scheduler@tyrone-cluster
03/26/2013 18:16:55;0040;PBS_Server;Svr;tyrone-cluster;Scheduler was sent the command recyc
03/26/2013 18:16:55;000d;PBS_Server;Job;20526.tyrone-cluster;Not sending email: User does not want mail of this type.
03/26/2013 18:16:58;000d;PBS_Server;Job;20526.tyrone-cluster;Not sending email: User does not want mail of this type.
03/26/2013 18:16:58;0010;PBS_Server;Job;20526.tyrone-cluster;Exit_status=0 resources_used.cput=00:00:17 resources_used.mem=0kb resources_used.vmem=0kb resources_used.walltime=00:00:03
03/26/2013 18:16:58;0008;PBS_Server;Job;NULL;on_job_exit valid pjob: 0x2e74200 (substate=50)
03/26/2013 18:16:58;0008;PBS_Server;Job;NULL;on_job_exit valid pjob: 0x2e74200 (substate=51)
03/26/2013 18:16:58;0008;PBS_Server;Job;NULL;on_job_exit valid pjob: 0x2e74200 (substate=51)
03/26/2013 18:16:58;0008;PBS_Server;Job;NULL;on_job_exit valid pjob: 0x2e74200 (substate=53)
03/26/2013 18:16:58;0100;PBS_Server;Job;20526.tyrone-cluster;dequeuing from idqueue, state COMPLETE
03/26/2013 18:16:58;0040;PBS_Server;Svr;tyrone-cluster;Scheduler was sent the command term
03/26/2013 18:17:02;000d;PBS_Server;Job;20522.tyrone-cluster;Not sending email: User does not want mail of this type.
03/26/2013 18:17:02;0010;PBS_Server;Job;20522.tyrone-cluster;Exit_status=0 resources_used.cput=07:54:22 resources_used.mem=10552716kb resources_used.vmem=22894420kb resources_used.walltime=00:15:01
03/26/2013 18:17:02;0008;PBS_Server;Job;NULL;on_job_exit valid pjob: 0x2e71070 (substate=50)
03/26/2013 18:17:02;0008;PBS_Server;Job;NULL;on_job_exit valid pjob: 0x2e71070 (substate=51)
03/26/2013 18:17:03;0008;PBS_Server;Job;NULL;on_job_exit valid pjob: 0x2e71070 (substate=51)
03/26/2013 18:17:03;0008;PBS_Server;Job;NULL;on_job_exit valid pjob: 0x2e71070 (substate=53)
03/26/2013 18:17:03;0100;PBS_Server;Job;20522.tyrone-cluster;dequeuing from qp32, state COMPLETE
03/26/2013 18:17:03;0040;PBS_Server;Svr;tyrone-cluster;Scheduler was sent the command term
03/26/2013 18:18:29;0002;PBS_Server;Svr;PBS_Server;Torque Server Version = 3.0.5, loglevel = 0
03/26/2013 18:18:39;0100;PBS_Server;Job;20527.tyrone-cluster;enqueuing into batch, state 1 hop 1
03/26/2013 18:18:39;0100;PBS_Server;Job;20527.tyrone-cluster;dequeuing from batch, state QUEUED
03/26/2013 18:18:39;0100;PBS_Server;Job;20527.tyrone-cluster;enqueuing into idqueue, state 1 hop 1
03/26/2013 18:18:39;0008;PBS_Server;Job;20527.tyrone-cluster;Job Queued at request of phymjain@tyrone-cluster, owner = phymjain@tyrone-cluster, job name = ParaN6Medium, queue = idqueue
03/26/2013 18:18:39;0040;PBS_Server;Svr;tyrone-cluster;Scheduler was sent the command new
03/26/2013 18:18:39;0008;PBS_Server;Job;20527.tyrone-cluster;Job Modified at request of Scheduler@tyrone-cluster
03/26/2013 18:18:39;0008;PBS_Server;Job;20527.tyrone-cluster;Job Run at request of Scheduler@tyrone-cluster
03/26/2013 18:18:39;0040;PBS_Server;Svr;tyrone-cluster;Scheduler was sent the command recyc
03/26/2013 18:18:39;000d;PBS_Server;Job;20527.tyrone-cluster;Not sending email: User does not want mail of this type.
03/26/2013 18:18:42;000d;PBS_Server;Job;20527.tyrone-cluster;Not sending email: User does not want mail of this type.
03/26/2013 18:18:42;0010;PBS_Server;Job;20527.tyrone-cluster;Exit_status=255 resources_used.cput=00:00:17 resources_used.mem=0kb resources_used.vmem=0kb resources_used.walltime=00:00:03
03/26/2013 18:18:42;0008;PBS_Server;Job;NULL;on_job_exit valid pjob: 0x2e71070 (substate=50)
03/26/2013 18:18:42;0008;PBS_Server;Job;NULL;on_job_exit valid pjob: 0x2e71070 (substate=51)
03/26/2013 18:18:42;0008;PBS_Server;Job;NULL;on_job_exit valid pjob: 0x2e71070 (substate=51)
03/26/2013 18:18:42;0008;PBS_Server;Job;NULL;on_job_exit valid pjob: 0x2e71070 (substate=53)
03/26/2013 18:18:42;0100;PBS_Server;Job;20527.tyrone-cluster;dequeuing from idqueue, state COMPLETE
03/26/2013 18:18:42;0040;PBS_Server;Svr;tyrone-cluster;Scheduler was sent the command term
03/26/2013 18:19:26;000d;PBS_Server;Job;20517.tyrone-cluster;Not sending email: User does not want mail of this type.
03/26/2013 18:19:26;0010;PBS_Server;Job;20517.tyrone-cluster;Exit_status=0 resources_used.cput=21:11:26 resources_used.mem=4334016kb resources_used.vmem=41300640kb resources_used.walltime=00:20:05
03/26/2013 18:19:26;0008;PBS_Server;Job;NULL;on_job_exit valid pjob: 0x2e4d870 (substate=50)
03/26/2013 18:19:26;0008;PBS_Server;Job;NULL;on_job_exit valid pjob: 0x2e4d870 (substate=51)
03/26/2013 18:19:27;0008;PBS_Server;Job;NULL;on_job_exit valid pjob: 0x2e4d870 (substate=51)
03/26/2013 18:19:27;0008;PBS_Server;Job;NULL;on_job_exit valid pjob: 0x2e4d870 (substate=53)
03/26/2013 18:19:27;0100;PBS_Server;Job;20517.tyrone-cluster;dequeuing from qp64, state COMPLETE
03/26/2013 18:19:27;0040;PBS_Server;Svr;tyrone-cluster;Scheduler was sent the command term
03/26/2013 18:20:03;0100;PBS_Server;Job;20528.tyrone-cluster;enqueuing into batch, state 1 hop 1
03/26/2013 18:20:03;0100;PBS_Server;Job;20528.tyrone-cluster;dequeuing from batch, state QUEUED
03/26/2013 18:20:03;0100;PBS_Server;Job;20528.tyrone-cluster;enqueuing into idqueue, state 1 hop 1
03/26/2013 18:20:03;0008;PBS_Server;Job;20528.tyrone-cluster;Job Queued at request of phymjain@tyrone-cluster, owner = phymjain@tyrone-cluster, job name = ParaN6Medium, queue = idqueue
03/26/2013 18:20:03;0040;PBS_Server;Svr;tyrone-cluster;Scheduler was sent the command new
03/26/2013 18:20:03;0008;PBS_Server;Job;20528.tyrone-cluster;Job Modified at request of Scheduler@tyrone-cluster
03/26/2013 18:20:03;0008;PBS_Server;Job;20528.tyrone-cluster;Job Run at request of Scheduler@tyrone-cluster
03/26/2013 18:20:03;0040;PBS_Server;Svr;tyrone-cluster;Scheduler was sent the command recyc
03/26/2013 18:20:03;000d;PBS_Server;Job;20528.tyrone-cluster;Not sending email: User does not want mail of this type.
03/26/2013 18:20:06;000d;PBS_Server;Job;20528.tyrone-cluster;Not sending email: User does not want mail of this type.
03/26/2013 18:20:06;0010;PBS_Server;Job;20528.tyrone-cluster;Exit_status=0 resources_used.cput=00:00:21 resources_used.mem=0kb resources_used.vmem=0kb resources_used.walltime=00:00:03
03/26/2013 18:20:06;0008;PBS_Server;Job;NULL;on_job_exit valid pjob: 0x2e71070 (substate=50)
03/26/2013 18:20:06;0008;PBS_Server;Job;NULL;on_job_exit valid pjob: 0x2e71070 (substate=51)
03/26/2013 18:20:06;0008;PBS_Server;Job;NULL;on_job_exit valid pjob: 0x2e71070 (substate=51)
03/26/2013 18:20:06;0008;PBS_Server;Job;NULL;on_job_exit valid pjob: 0x2e71070 (substate=53)
03/26/2013 18:20:06;0100;PBS_Server;Job;20528.tyrone-cluster;dequeuing from idqueue, state COMPLETE
03/26/2013 18:20:06;0040;PBS_Server;Svr;tyrone-cluster;Scheduler was sent the command term
03/26/2013 18:21:36;0100;PBS_Server;Job;20529.tyrone-cluster;enqueuing into batch, state 1 hop 1
03/26/2013 18:21:36;0100;PBS_Server;Job;20529.tyrone-cluster;dequeuing from batch, state QUEUED
03/26/2013 18:21:36;0100;PBS_Server;Job;20529.tyrone-cluster;enqueuing into idqueue, state 1 hop 1
03/26/2013 18:21:36;0008;PBS_Server;Job;20529.tyrone-cluster;Job Queued at request of phymjain@tyrone-cluster, owner = phymjain@tyrone-cluster, job name = ParaN6Medium, queue = idqueue
03/26/2013 18:21:36;0040;PBS_Server;Svr;tyrone-cluster;Scheduler was sent the command new
03/26/2013 18:21:36;0008;PBS_Server;Job;20529.tyrone-cluster;Job Modified at request of Scheduler@tyrone-cluster
03/26/2013 18:21:36;0008;PBS_Server;Job;20529.tyrone-cluster;Job Run at request of Scheduler@tyrone-cluster
03/26/2013 18:21:36;0040;PBS_Server;Svr;tyrone-cluster;Scheduler was sent the command recyc
03/26/2013 18:21:36;000d;PBS_Server;Job;20529.tyrone-cluster;Not sending email: User does not want mail of this type.
03/26/2013 18:21:39;000d;PBS_Server;Job;20529.tyrone-cluster;Not sending email: User does not want mail of this type.
03/26/2013 18:21:39;0010;PBS_Server;Job;20529.tyrone-cluster;Exit_status=255 resources_used.cput=00:00:17 resources_used.mem=0kb resources_used.vmem=0kb resources_used.walltime=00:00:03
03/26/2013 18:21:39;0008;PBS_Server;Job;NULL;on_job_exit valid pjob: 0x2e71070 (substate=50)
03/26/2013 18:21:39;0008;PBS_Server;Job;NULL;on_job_exit valid pjob: 0x2e71070 (substate=51)
03/26/2013 18:21:39;0008;PBS_Server;Job;NULL;on_job_exit valid pjob: 0x2e71070 (substate=51)
03/26/2013 18:21:39;0008;PBS_Server;Job;NULL;on_job_exit valid pjob: 0x2e71070 (substate=53)
03/26/2013 18:21:39;0100;PBS_Server;Job;20529.tyrone-cluster;dequeuing from idqueue, state COMPLETE
03/26/2013 18:21:39;0040;PBS_Server;Svr;tyrone-cluster;Scheduler was sent the command term
03/26/2013 18:23:29;0002;PBS_Server;Svr;PBS_Server;Torque Server Version = 3.0.5, loglevel = 0
03/26/2013 18:28:29;0002;PBS_Server;Svr;PBS_Server;Torque Server Version = 3.0.5, loglevel = 0
03/26/2013 18:31:39;0040;PBS_Server;Svr;tyrone-cluster;Scheduler was sent the command time
03/26/2013 18:33:29;0002;PBS_Server;Svr;PBS_Server;Torque Server Version = 3.0.5, loglevel = 0
03/26/2013 18:38:29;0002;PBS_Server;Svr;PBS_Server;Torque Server Version = 3.0.5, loglevel = 0
03/26/2013 18:40:20;0100;PBS_Server;Job;20530.tyrone-cluster;enqueuing into batch, state 1 hop 1
03/26/2013 18:40:20;0100;PBS_Server;Job;20530.tyrone-cluster;dequeuing from batch, state QUEUED
03/26/2013 18:40:20;0100;PBS_Server;Job;20530.tyrone-cluster;enqueuing into qp32, state 1 hop 1
03/26/2013 18:40:20;0008;PBS_Server;Job;20530.tyrone-cluster;Job Queued at request of mrcaks@tyrone-cluster, owner = mrcaks@tyrone-cluster, job name = borane_2C_no_upper_B, queue = qp32
03/26/2013 18:40:20;0040;PBS_Server;Svr;tyrone-cluster;Scheduler was sent the command new
03/26/2013 18:40:20;0008;PBS_Server;Job;20530.tyrone-cluster;Job Modified at request of Scheduler@tyrone-cluster
03/26/2013 18:40:20;0008;PBS_Server;Job;20530.tyrone-cluster;Job Run at request of Scheduler@tyrone-cluster
03/26/2013 18:40:21;0040;PBS_Server;Svr;tyrone-cluster;Scheduler was sent the command recyc
03/26/2013 18:40:21;000d;PBS_Server;Job;20530.tyrone-cluster;Not sending email: User does not want mail of this type.
03/26/2013 18:40:44;0008;PBS_Server;Job;20530.tyrone-cluster;Job deleted at request of mrcaks@tyrone-cluster
03/26/2013 18:40:44;0008;PBS_Server;Job;20530.tyrone-cluster;Job sent signal SIGTERM on delete
03/26/2013 18:40:45;000d;PBS_Server;Job;20530.tyrone-cluster;Not sending email: User does not want mail of this type.
03/26/2013 18:40:45;0010;PBS_Server;Job;20530.tyrone-cluster;Exit_status=143 resources_used.cput=00:11:39 resources_used.mem=5314172kb resources_used.vmem=14128684kb resources_used.walltime=00:00:24
03/26/2013 18:40:45;0008;PBS_Server;Job;NULL;on_job_exit valid pjob: 0x2e71070 (substate=50)
03/26/2013 18:40:45;0008;PBS_Server;Job;NULL;on_job_exit valid pjob: 0x2e71070 (substate=51)
03/26/2013 18:40:46;0008;PBS_Server;Job;NULL;on_job_exit valid pjob: 0x2e71070 (substate=51)
03/26/2013 18:40:46;0008;PBS_Server;Job;NULL;on_job_exit valid pjob: 0x2e71070 (substate=53)
03/26/2013 18:40:46;0100;PBS_Server;Job;20530.tyrone-cluster;dequeuing from qp32, state COMPLETE
03/26/2013 18:40:46;0040;PBS_Server;Svr;tyrone-cluster;Scheduler was sent the command term
03/26/2013 18:41:55;0100;PBS_Server;Job;20531.tyrone-cluster;enqueuing into batch, state 1 hop 1
03/26/2013 18:41:55;0100;PBS_Server;Job;20531.tyrone-cluster;dequeuing from batch, state QUEUED
03/26/2013 18:41:55;0100;PBS_Server;Job;20531.tyrone-cluster;enqueuing into qp32, state 1 hop 1
03/26/2013 18:41:55;0008;PBS_Server;Job;20531.tyrone-cluster;Job Queued at request of mrcaks@tyrone-cluster, owner = mrcaks@tyrone-cluster, job name = borane_2C_no_upper_B, queue = qp32
03/26/2013 18:41:55;0040;PBS_Server;Svr;tyrone-cluster;Scheduler was sent the command new
03/26/2013 18:41:55;0008;PBS_Server;Job;20531.tyrone-cluster;Job Modified at request of Scheduler@tyrone-cluster
03/26/2013 18:41:55;0008;PBS_Server;Job;20531.tyrone-cluster;Job Run at request of Scheduler@tyrone-cluster
03/26/2013 18:41:55;0040;PBS_Server;Svr;tyrone-cluster;Scheduler was sent the command recyc
03/26/2013 18:41:55;000d;PBS_Server;Job;20531.tyrone-cluster;Not sending email: User does not want mail of this type.
03/26/2013 18:43:29;0002;PBS_Server;Svr;PBS_Server;Torque Server Version = 3.0.5, loglevel = 0
03/26/2013 18:45:30;0100;PBS_Server;Job;20532.tyrone-cluster;enqueuing into batch, state 1 hop 1
03/26/2013 18:45:30;0100;PBS_Server;Job;20532.tyrone-cluster;dequeuing from batch, state QUEUED
03/26/2013 18:45:30;0100;PBS_Server;Job;20532.tyrone-cluster;enqueuing into qp32, state 1 hop 1
03/26/2013 18:45:30;0008;PBS_Server;Job;20532.tyrone-cluster;Job Queued at request of mrcaks@tyrone-cluster, owner = mrcaks@tyrone-cluster, job name = borane_1C_no_upper_B, queue = qp32
03/26/2013 18:45:30;0040;PBS_Server;Svr;tyrone-cluster;Scheduler was sent the command new
03/26/2013 18:45:30;0008;PBS_Server;Job;20532.tyrone-cluster;Job Modified at request of Scheduler@tyrone-cluster
03/26/2013 18:45:30;0008;PBS_Server;Job;20532.tyrone-cluster;Job Run at request of Scheduler@tyrone-cluster
03/26/2013 18:45:30;0040;PBS_Server;Svr;tyrone-cluster;Scheduler was sent the command recyc
03/26/2013 18:45:30;000d;PBS_Server;Job;20532.tyrone-cluster;Not sending email: User does not want mail of this type.
03/26/2013 18:48:29;0002;PBS_Server;Svr;PBS_Server;Torque Server Version = 3.0.5, loglevel = 0
03/26/2013 18:50:08;0100;PBS_Server;Job;20533.tyrone-cluster;enqueuing into batch, state 1 hop 1
03/26/2013 18:50:08;0100;PBS_Server;Job;20533.tyrone-cluster;dequeuing from batch, state QUEUED
03/26/2013 18:50:08;0100;PBS_Server;Job;20533.tyrone-cluster;enqueuing into qp64, state 1 hop 1
03/26/2013 18:50:08;0008;PBS_Server;Job;20533.tyrone-cluster;Job Queued at request of mrcpndey@tyrone-cluster, owner = mrcpndey@tyrone-cluster, job name = GO-5, queue = qp64
03/26/2013 18:50:08;0040;PBS_Server;Svr;tyrone-cluster;Scheduler was sent the command new
03/26/2013 18:50:08;0008;PBS_Server;Job;20533.tyrone-cluster;Job Modified at request of Scheduler@tyrone-cluster
03/26/2013 18:50:08;0008;PBS_Server;Job;20533.tyrone-cluster;Job Run at request of Scheduler@tyrone-cluster
03/26/2013 18:50:08;0040;PBS_Server;Svr;tyrone-cluster;Scheduler was sent the command recyc
03/26/2013 18:50:08;000d;PBS_Server;Job;20533.tyrone-cluster;Not sending email: User does not want mail of this type.
03/26/2013 18:50:10;0100;PBS_Server;Job;20534.tyrone-cluster;enqueuing into batch, state 1 hop 1
03/26/2013 18:50:10;0100;PBS_Server;Job;20534.tyrone-cluster;dequeuing from batch, state QUEUED
03/26/2013 18:50:10;0100;PBS_Server;Job;20534.tyrone-cluster;enqueuing into qp64, state 1 hop 1
03/26/2013 18:50:10;0008;PBS_Server;Job;20534.tyrone-cluster;Job Queued at request of mrcpndey@tyrone-cluster, owner = mrcpndey@tyrone-cluster, job name = GO-7, queue = qp64
03/26/2013 18:50:10;0040;PBS_Server;Svr;tyrone-cluster;Scheduler was sent the command new
03/26/2013 18:50:10;0008;PBS_Server;Job;20534.tyrone-cluster;Job Modified at request of Scheduler@tyrone-cluster
03/26/2013 18:53:00;0100;PBS_Server;Job;20535.tyrone-cluster;enqueuing into batch, state 1 hop 1
03/26/2013 18:53:00;0100;PBS_Server;Job;20535.tyrone-cluster;dequeuing from batch, state QUEUED
03/26/2013 18:53:00;0100;PBS_Server;Job;20535.tyrone-cluster;enqueuing into idqueue, state 1 hop 1
03/26/2013 18:53:00;0008;PBS_Server;Job;20535.tyrone-cluster;Job Queued at request of mrcaks@tyrone-cluster, owner = mrcaks@tyrone-cluster, job name = borane_3C_no_upper_B, queue = idqueue
03/26/2013 18:53:00;0040;PBS_Server;Svr;tyrone-cluster;Scheduler was sent the command new
03/26/2013 18:53:01;0008;PBS_Server;Job;20535.tyrone-cluster;Job Modified at request of Scheduler@tyrone-cluster
03/26/2013 18:53:12;0008;PBS_Server;Job;20535.tyrone-cluster;Job deleted at request of mrcaks@tyrone-cluster
03/26/2013 18:53:12;0008;PBS_Server;Job;NULL;on_job_exit valid pjob: 0x2e448b0 (substate=59)
03/26/2013 18:53:12;0100;PBS_Server;Job;20535.tyrone-cluster;dequeuing from idqueue, state COMPLETE
03/26/2013 18:53:12;0040;PBS_Server;Svr;tyrone-cluster;Scheduler was sent the command term
03/26/2013 18:53:15;0100;PBS_Server;Job;20536.tyrone-cluster;enqueuing into batch, state 1 hop 1
03/26/2013 18:53:15;0100;PBS_Server;Job;20536.tyrone-cluster;dequeuing from batch, state QUEUED
03/26/2013 18:53:15;0100;PBS_Server;Job;20536.tyrone-cluster;enqueuing into idqueue, state 1 hop 1
03/26/2013 18:53:15;0008;PBS_Server;Job;20536.tyrone-cluster;Job Queued at request of mrcaks@tyrone-cluster, owner = mrcaks@tyrone-cluster, job name = borane_3C_no_upper_B, queue = idqueue
03/26/2013 18:53:15;0040;PBS_Server;Svr;tyrone-cluster;Scheduler was sent the command new
03/26/2013 18:53:15;0008;PBS_Server;Job;20536.tyrone-cluster;Job Modified at request of Scheduler@tyrone-cluster
03/26/2013 18:53:21;0008;PBS_Server;Job;20536.tyrone-cluster;Job deleted at request of mrcaks@tyrone-cluster
03/26/2013 18:53:21;0008;PBS_Server;Job;NULL;on_job_exit valid pjob: 0x2e448b0 (substate=59)
03/26/2013 18:53:21;0100;PBS_Server;Job;20536.tyrone-cluster;dequeuing from idqueue, state COMPLETE
03/26/2013 18:53:21;0040;PBS_Server;Svr;tyrone-cluster;Scheduler was sent the command term
03/26/2013 18:53:29;0002;PBS_Server;Svr;PBS_Server;Torque Server Version = 3.0.5, loglevel = 0
03/26/2013 18:53:47;0100;PBS_Server;Job;20537.tyrone-cluster;enqueuing into batch, state 1 hop 1
03/26/2013 18:53:47;0100;PBS_Server;Job;20537.tyrone-cluster;dequeuing from batch, state QUEUED
03/26/2013 18:53:47;0100;PBS_Server;Job;20537.tyrone-cluster;enqueuing into qp32, state 1 hop 1
03/26/2013 18:53:47;0008;PBS_Server;Job;20537.tyrone-cluster;Job Queued at request of mrcaks@tyrone-cluster, owner = mrcaks@tyrone-cluster, job name = borane_3C_no_upper_B, queue = qp32
03/26/2013 18:53:47;0040;PBS_Server;Svr;tyrone-cluster;Scheduler was sent the command new
03/26/2013 18:53:47;0008;PBS_Server;Job;20537.tyrone-cluster;Job Modified at request of Scheduler@tyrone-cluster
03/26/2013 18:54:00;000d;PBS_Server;Job;20533.tyrone-cluster;Not sending email: User does not want mail of this type.
03/26/2013 18:54:00;0010;PBS_Server;Job;20533.tyrone-cluster;Exit_status=0 resources_used.cput=04:03:45 resources_used.mem=4318892kb resources_used.vmem=41301428kb resources_used.walltime=00:03:53
03/26/2013 18:54:00;0008;PBS_Server;Job;NULL;on_job_exit valid pjob: 0x2f7e3a0 (substate=50)
03/26/2013 18:54:00;0008;PBS_Server;Job;NULL;on_job_exit valid pjob: 0x2f7e3a0 (substate=51)
03/26/2013 18:54:00;0008;PBS_Server;Job;NULL;on_job_exit valid pjob: 0x2f7e3a0 (substate=51)
03/26/2013 18:54:00;0008;PBS_Server;Job;NULL;on_job_exit valid pjob: 0x2f7e3a0 (substate=53)
03/26/2013 18:54:00;0100;PBS_Server;Job;20533.tyrone-cluster;dequeuing from qp64, state COMPLETE
03/26/2013 18:54:00;0040;PBS_Server;Svr;tyrone-cluster;Scheduler was sent the command term
03/26/2013 18:54:00;0008;PBS_Server;Job;20534.tyrone-cluster;Job Modified at request of Scheduler@tyrone-cluster
03/26/2013 18:54:00;0008;PBS_Server;Job;20534.tyrone-cluster;Job Run at request of Scheduler@tyrone-cluster
03/26/2013 18:54:00;0040;PBS_Server;Svr;tyrone-cluster;Scheduler was sent the command recyc
03/26/2013 18:54:00;000d;PBS_Server;Job;20534.tyrone-cluster;Not sending email: User does not want mail of this type.
03/26/2013 18:55:09;000d;PBS_Server;Job;20414.tyrone-cluster;Not sending email: User does not want mail of this type.
03/26/2013 18:55:09;0010;PBS_Server;Job;20414.tyrone-cluster;Exit_status=143 resources_used.cput=1535:48:37 resources_used.mem=3536476kb resources_used.vmem=40307220kb resources_used.walltime=24:00:29
03/26/2013 18:55:09;0008;PBS_Server;Job;NULL;on_job_exit valid pjob: 0x2e7a220 (substate=50)
03/26/2013 18:55:09;0008;PBS_Server;Job;NULL;on_job_exit valid pjob: 0x2e7a220 (substate=51)
03/26/2013 18:55:09;0008;PBS_Server;Job;NULL;on_job_exit valid pjob: 0x2e7a220 (substate=51)
03/26/2013 18:55:09;0008;PBS_Server;Job;NULL;on_job_exit valid pjob: 0x2e7a220 (substate=53)
03/26/2013 18:55:09;0100;PBS_Server;Job;20414.tyrone-cluster;dequeuing from qp64, state COMPLETE
03/26/2013 18:55:09;0040;PBS_Server;Svr;tyrone-cluster;Scheduler was sent the command term
03/26/2013 18:56:32;0100;PBS_Server;Job;20538.tyrone-cluster;enqueuing into batch, state 1 hop 1
03/26/2013 18:56:32;0008;PBS_Server;Job;20538.tyrone-cluster;Job Queued at request of mrcaks@tyrone-cluster, owner = mrcaks@tyrone-cluster, job name = borane_4C_no_upper_B, queue = batch
03/26/2013 18:56:32;0040;PBS_Server;Svr;tyrone-cluster;Scheduler was sent the command new
03/26/2013 18:56:32;0008;PBS_Server;Job;20538.tyrone-cluster;Job Modified at request of Scheduler@tyrone-cluster
03/26/2013 18:57:03;0040;PBS_Server;Svr;tyrone-cluster;Scheduler was sent the command new
03/26/2013 18:57:33;0040;PBS_Server;Svr;tyrone-cluster;Scheduler was sent the command new
03/26/2013 18:58:03;0040;PBS_Server;Svr;tyrone-cluster;Scheduler was sent the command new
03/26/2013 18:58:27;000d;PBS_Server;Job;20531.tyrone-cluster;Not sending email: User does not want mail of this type.
03/26/2013 18:58:27;0010;PBS_Server;Job;20531.tyrone-cluster;Exit_status=0 resources_used.cput=08:47:12 resources_used.mem=10546064kb resources_used.vmem=22537772kb resources_used.walltime=00:16:32
03/26/2013 18:58:27;0008;PBS_Server;Job;NULL;on_job_exit valid pjob: 0x2e71070 (substate=50)
03/26/2013 18:58:27;0008;PBS_Server;Job;NULL;on_job_exit valid pjob: 0x2e71070 (substate=51)
03/26/2013 18:58:28;0008;PBS_Server;Job;NULL;on_job_exit valid pjob: 0x2e71070 (substate=51)
03/26/2013 18:58:28;0008;PBS_Server;Job;NULL;on_job_exit valid pjob: 0x2e71070 (substate=53)
03/26/2013 18:58:28;0100;PBS_Server;Job;20531.tyrone-cluster;dequeuing from qp32, state COMPLETE
03/26/2013 18:58:28;0040;PBS_Server;Svr;tyrone-cluster;Scheduler was sent the command term
03/26/2013 18:58:29;0002;PBS_Server;Svr;PBS_Server;Torque Server Version = 3.0.5, loglevel = 0
03/26/2013 18:58:29;0008;PBS_Server;Job;20537.tyrone-cluster;Job Modified at request of Scheduler@tyrone-cluster
03/26/2013 18:58:29;0008;PBS_Server;Job;20537.tyrone-cluster;Job Run at request of Scheduler@tyrone-cluster
03/26/2013 18:58:29;0040;PBS_Server;Svr;tyrone-cluster;Scheduler was sent the command recyc
03/26/2013 18:58:29;000d;PBS_Server;Job;20537.tyrone-cluster;Not sending email: User does not want mail of this type.
03/26/2013 18:58:33;0100;PBS_Server;Job;20538.tyrone-cluster;dequeuing from batch, state QUEUED
03/26/2013 18:58:33;0100;PBS_Server;Job;20538.tyrone-cluster;enqueuing into qp32, state 1 hop 1
03/26/2013 18:58:35;0040;PBS_Server;Svr;tyrone-cluster;Scheduler was sent the command new
03/26/2013 18:58:35;0008;PBS_Server;Job;20538.tyrone-cluster;Job Modified at request of Scheduler@tyrone-cluster
03/26/2013 19:03:29;0002;PBS_Server;Svr;PBS_Server;Torque Server Version = 3.0.5, loglevel = 0
03/26/2013 19:03:43;000d;PBS_Server;Job;20508.tyrone-cluster;Not sending email: User does not want mail of this type.
03/26/2013 19:03:43;0010;PBS_Server;Job;20508.tyrone-cluster;Exit_status=0 resources_used.cput=61:26:20 resources_used.mem=3941908kb resources_used.vmem=11971036kb resources_used.walltime=01:55:20
03/26/2013 19:03:43;0008;PBS_Server;Job;NULL;on_job_exit valid pjob: 0x2ec13f0 (substate=50)
03/26/2013 19:03:43;0008;PBS_Server;Job;NULL;on_job_exit valid pjob: 0x2ec13f0 (substate=51)
03/26/2013 19:03:47;0008;PBS_Server;Job;NULL;on_job_exit valid pjob: 0x2ec13f0 (substate=51)
03/26/2013 19:03:47;000d;PBS_Server;Job;20508.tyrone-cluster;Post job file processing error; job 20508.tyrone-cluster on host tyrone-node3/31+tyrone-node3/30+tyrone-node3/29+tyrone-node3/28+tyrone-node3/27+tyrone-node3/26+tyrone-node3/25+tyrone-node3/24+tyrone-node3/23+tyrone-node3/22+tyrone-node3/21+tyrone-node3/20+tyrone-node3/19+tyrone-node3/18+tyrone-node3/17+tyrone-node3/16+tyrone-node3/15+tyrone-node3/14+tyrone-node3/13+tyrone-node3/12+tyrone-node3/11+tyrone-node3/10+tyrone-node3/9+tyrone-node3/8+tyrone-node3/7+tyrone-node3/6+tyrone-node3/5+tyrone-node3/4+tyrone-node3/3+tyrone-node3/2+tyrone-node3/1+tyrone-node3/0
03/26/2013 19:03:47;0008;PBS_Server;Job;NULL;on_job_exit valid pjob: 0x2ec13f0 (substate=53)
03/26/2013 19:03:47;0100;PBS_Server;Job;20508.tyrone-cluster;dequeuing from qp32, state COMPLETE
03/26/2013 19:03:47;0040;PBS_Server;Svr;tyrone-cluster;Scheduler was sent the command term
03/26/2013 19:08:29;0002;PBS_Server;Svr;PBS_Server;Torque Server Version = 3.0.5, loglevel = 0
03/26/2013 19:08:39;000d;PBS_Server;Job;20532.tyrone-cluster;Not sending email: User does not want mail of this type.
03/26/2013 19:08:39;0010;PBS_Server;Job;20532.tyrone-cluster;Exit_status=0 resources_used.cput=12:05:59 resources_used.mem=10450616kb resources_used.vmem=22700656kb resources_used.walltime=00:23:09
03/26/2013 19:08:39;0008;PBS_Server;Job;NULL;on_job_exit valid pjob: 0x2e74200 (substate=50)
03/26/2013 19:08:39;0008;PBS_Server;Job;NULL;on_job_exit valid pjob: 0x2e74200 (substate=51)
03/26/2013 19:08:40;0008;PBS_Server;Job;NULL;on_job_exit valid pjob: 0x2e74200 (substate=51)
03/26/2013 19:08:40;0008;PBS_Server;Job;NULL;on_job_exit valid pjob: 0x2e74200 (substate=53)
03/26/2013 19:08:40;0100;PBS_Server;Job;20532.tyrone-cluster;dequeuing from qp32, state COMPLETE
03/26/2013 19:08:40;0040;PBS_Server;Svr;tyrone-cluster;Scheduler was sent the command term
03/26/2013 19:08:40;0008;PBS_Server;Job;20538.tyrone-cluster;Job Modified at request of Scheduler@tyrone-cluster
03/26/2013 19:08:40;0008;PBS_Server;Job;20538.tyrone-cluster;Job Run at request of Scheduler@tyrone-cluster
03/26/2013 19:08:40;0040;PBS_Server;Svr;tyrone-cluster;Scheduler was sent the command recyc
03/26/2013 19:08:40;000d;PBS_Server;Job;20538.tyrone-cluster;Not sending email: User does not want mail of this type.
03/26/2013 19:13:25;000d;PBS_Server;Job;20537.tyrone-cluster;Not sending email: User does not want mail of this type.
03/26/2013 19:13:25;0010;PBS_Server;Job;20537.tyrone-cluster;Exit_status=0 resources_used.cput=07:55:49 resources_used.mem=10473692kb resources_used.vmem=22746340kb resources_used.walltime=00:14:57
03/26/2013 19:13:25;0008;PBS_Server;Job;NULL;on_job_exit valid pjob: 0x2e448b0 (substate=50)
03/26/2013 19:13:25;0008;PBS_Server;Job;NULL;on_job_exit valid pjob: 0x2e448b0 (substate=51)
03/26/2013 19:13:26;0008;PBS_Server;Job;NULL;on_job_exit valid pjob: 0x2e448b0 (substate=51)
03/26/2013 19:13:26;0008;PBS_Server;Job;NULL;on_job_exit valid pjob: 0x2e448b0 (substate=53)
03/26/2013 19:13:26;0100;PBS_Server;Job;20537.tyrone-cluster;dequeuing from qp32, state COMPLETE
03/26/2013 19:13:26;0040;PBS_Server;Svr;tyrone-cluster;Scheduler was sent the command term
03/26/2013 19:13:29;0002;PBS_Server;Svr;PBS_Server;Torque Server Version = 3.0.5, loglevel = 0
03/26/2013 19:15:22;000d;PBS_Server;Job;20485.tyrone-cluster;Not sending email: User does not want mail of this type.
03/26/2013 19:15:22;0010;PBS_Server;Job;20485.tyrone-cluster;Exit_status=0 resources_used.cput=181:52:38 resources_used.mem=2103436kb resources_used.vmem=35897116kb resources_used.walltime=02:51:07
03/26/2013 19:15:22;0008;PBS_Server;Job;NULL;on_job_exit valid pjob: 0x2e413e0 (substate=50)
03/26/2013 19:15:22;0008;PBS_Server;Job;NULL;on_job_exit valid pjob: 0x2e413e0 (substate=51)
03/26/2013 19:15:23;0008;PBS_Server;Job;NULL;on_job_exit valid pjob: 0x2e413e0 (substate=51)
03/26/2013 19:15:23;0008;PBS_Server;Job;NULL;on_job_exit valid pjob: 0x2e413e0 (substate=53)
03/26/2013 19:15:23;0100;PBS_Server;Job;20485.tyrone-cluster;dequeuing from qp64, state COMPLETE
03/26/2013 19:15:23;0040;PBS_Server;Svr;tyrone-cluster;Scheduler was sent the command term
03/26/2013 19:18:29;0002;PBS_Server;Svr;PBS_Server;Torque Server Version = 3.0.5, loglevel = 0
03/26/2013 19:23:17;000d;PBS_Server;Job;20538.tyrone-cluster;Not sending email: User does not want mail of this type.
03/26/2013 19:23:17;0010;PBS_Server;Job;20538.tyrone-cluster;Exit_status=0 resources_used.cput=07:45:08 resources_used.mem=10414408kb resources_used.vmem=22834944kb resources_used.walltime=00:14:37
03/26/2013 19:23:17;0008;PBS_Server;Job;NULL;on_job_exit valid pjob: 0x2e7a220 (substate=50)
03/26/2013 19:23:17;0008;PBS_Server;Job;NULL;on_job_exit valid pjob: 0x2e7a220 (substate=51)
03/26/2013 19:23:18;0008;PBS_Server;Job;NULL;on_job_exit valid pjob: 0x2e7a220 (substate=51)
03/26/2013 19:23:18;0008;PBS_Server;Job;NULL;on_job_exit valid pjob: 0x2e7a220 (substate=53)
03/26/2013 19:23:18;0100;PBS_Server;Job;20538.tyrone-cluster;dequeuing from qp32, state COMPLETE
03/26/2013 19:23:18;0040;PBS_Server;Svr;tyrone-cluster;Scheduler was sent the command term
03/26/2013 19:23:29;0002;PBS_Server;Svr;PBS_Server;Torque Server Version = 3.0.5, loglevel = 0
03/26/2013 19:28:29;0002;PBS_Server;Svr;PBS_Server;Torque Server Version = 3.0.5, loglevel = 0
03/26/2013 19:32:36;000d;PBS_Server;Job;20534.tyrone-cluster;Not sending email: User does not want mail of this type.
03/26/2013 19:32:36;0010;PBS_Server;Job;20534.tyrone-cluster;Exit_status=0 resources_used.cput=40:45:17 resources_used.mem=4896416kb resources_used.vmem=41851020kb resources_used.walltime=00:38:36
03/26/2013 19:32:36;0008;PBS_Server;Job;NULL;on_job_exit valid pjob: 0x2f67920 (substate=50)
03/26/2013 19:32:36;0008;PBS_Server;Job;NULL;on_job_exit valid pjob: 0x2f67920 (substate=51)
03/26/2013 19:32:36;0008;PBS_Server;Job;NULL;on_job_exit valid pjob: 0x2f67920 (substate=51)
03/26/2013 19:32:36;0008;PBS_Server;Job;NULL;on_job_exit valid pjob: 0x2f67920 (substate=53)
03/26/2013 19:32:36;0100;PBS_Server;Job;20534.tyrone-cluster;dequeuing from qp64, state COMPLETE
03/26/2013 19:32:36;0040;PBS_Server;Svr;tyrone-cluster;Scheduler was sent the command term
03/26/2013 19:33:29;0002;PBS_Server;Svr;PBS_Server;Torque Server Version = 3.0.5, loglevel = 0
03/26/2013 19:38:29;0002;PBS_Server;Svr;PBS_Server;Torque Server Version = 3.0.5, loglevel = 0
03/26/2013 19:42:36;0040;PBS_Server;Svr;tyrone-cluster;Scheduler was sent the command time
03/26/2013 19:43:29;0002;PBS_Server;Svr;PBS_Server;Torque Server Version = 3.0.5, loglevel = 0
03/26/2013 19:48:29;0002;PBS_Server;Svr;PBS_Server;Torque Server Version = 3.0.5, loglevel = 0
03/26/2013 19:52:01;000d;PBS_Server;Job;20489.tyrone-cluster;Not sending email: User does not want mail of this type.
03/26/2013 19:52:01;0010;PBS_Server;Job;20489.tyrone-cluster;Exit_status=0 resources_used.cput=30:27:32 resources_used.mem=10633500kb resources_used.vmem=22472316kb resources_used.walltime=01:54:45
03/26/2013 19:52:01;0008;PBS_Server;Job;NULL;on_job_exit valid pjob: 0x2e37f20 (substate=50)
03/26/2013 19:52:01;0008;PBS_Server;Job;NULL;on_job_exit valid pjob: 0x2e37f20 (substate=51)
03/26/2013 19:52:01;0008;PBS_Server;Job;NULL;on_job_exit valid pjob: 0x2e37f20 (substate=51)
03/26/2013 19:52:01;0008;PBS_Server;Job;NULL;on_job_exit valid pjob: 0x2e37f20 (substate=53)
03/26/2013 19:52:01;0100;PBS_Server;Job;20489.tyrone-cluster;dequeuing from idqueue, state COMPLETE
03/26/2013 19:52:01;0040;PBS_Server;Svr;tyrone-cluster;Scheduler was sent the command term
03/26/2013 19:52:01;0008;PBS_Server;Job;20510.tyrone-cluster;Job Modified at request of Scheduler@tyrone-cluster
03/26/2013 19:52:01;0008;PBS_Server;Job;20510.tyrone-cluster;Job Run at request of Scheduler@tyrone-cluster
03/26/2013 19:52:01;0040;PBS_Server;Svr;tyrone-cluster;Scheduler was sent the command recyc
03/26/2013 19:52:01;000d;PBS_Server;Job;20510.tyrone-cluster;Not sending email: User does not want mail of this type.
03/26/2013 19:53:29;0002;PBS_Server;Svr;PBS_Server;Torque Server Version = 3.0.5, loglevel = 0
03/26/2013 19:58:29;0002;PBS_Server;Svr;PBS_Server;Torque Server Version = 3.0.5, loglevel = 0
03/26/2013 19:58:49;000d;PBS_Server;Job;20491.tyrone-cluster;Not sending email: User does not want mail of this type.
03/26/2013 19:58:49;0010;PBS_Server;Job;20491.tyrone-cluster;Exit_status=143 resources_used.cput=31:56:58 resources_used.mem=10725748kb resources_used.vmem=22998500kb resources_used.walltime=02:00:25
03/26/2013 19:58:49;0008;PBS_Server;Job;NULL;on_job_exit valid pjob: 0x2e3bf70 (substate=50)
03/26/2013 19:58:49;0008;PBS_Server;Job;NULL;on_job_exit valid pjob: 0x2e3bf70 (substate=51)
03/26/2013 19:58:49;0008;PBS_Server;Job;NULL;on_job_exit valid pjob: 0x2e3bf70 (substate=51)
03/26/2013 19:58:49;0008;PBS_Server;Job;NULL;on_job_exit valid pjob: 0x2e3bf70 (substate=53)
03/26/2013 19:58:49;0100;PBS_Server;Job;20491.tyrone-cluster;dequeuing from idqueue, state COMPLETE
03/26/2013 19:58:49;0040;PBS_Server;Svr;tyrone-cluster;Scheduler was sent the command term
03/26/2013 19:58:49;0008;PBS_Server;Job;20511.tyrone-cluster;Job Modified at request of Scheduler@tyrone-cluster
03/26/2013 19:58:49;0008;PBS_Server;Job;20511.tyrone-cluster;Job Run at request of Scheduler@tyrone-cluster
03/26/2013 19:58:49;0040;PBS_Server;Svr;tyrone-cluster;Scheduler was sent the command recyc
03/26/2013 19:58:49;000d;PBS_Server;Job;20511.tyrone-cluster;Not sending email: User does not want mail of this type.
03/26/2013 20:03:29;0002;PBS_Server;Svr;PBS_Server;Torque Server Version = 3.0.5, loglevel = 0
03/26/2013 20:07:12;000d;PBS_Server;Job;20510.tyrone-cluster;Not sending email: User does not want mail of this type.
03/26/2013 20:07:12;0010;PBS_Server;Job;20510.tyrone-cluster;Exit_status=0 resources_used.cput=04:06:34 resources_used.mem=11274524kb resources_used.vmem=24715984kb resources_used.walltime=00:15:11
03/26/2013 20:07:12;0008;PBS_Server;Job;NULL;on_job_exit valid pjob: 0x2e788e0 (substate=50)
03/26/2013 20:07:12;0008;PBS_Server;Job;NULL;on_job_exit valid pjob: 0x2e788e0 (substate=51)
03/26/2013 20:07:12;0008;PBS_Server;Job;NULL;on_job_exit valid pjob: 0x2e788e0 (substate=51)
03/26/2013 20:07:12;0008;PBS_Server;Job;NULL;on_job_exit valid pjob: 0x2e788e0 (substate=53)
03/26/2013 20:07:12;0100;PBS_Server;Job;20510.tyrone-cluster;dequeuing from idqueue, state COMPLETE
03/26/2013 20:07:12;0040;PBS_Server;Svr;tyrone-cluster;Scheduler was sent the command term
03/26/2013 20:07:12;0008;PBS_Server;Job;20512.tyrone-cluster;Job Modified at request of Scheduler@tyrone-cluster
03/26/2013 20:07:12;0008;PBS_Server;Job;20512.tyrone-cluster;Job Run at request of Scheduler@tyrone-cluster
03/26/2013 20:07:13;0040;PBS_Server;Svr;tyrone-cluster;Scheduler was sent the command recyc
03/26/2013 20:07:13;000d;PBS_Server;Job;20512.tyrone-cluster;Not sending email: User does not want mail of this type.
03/26/2013 20:08:29;0002;PBS_Server;Svr;PBS_Server;Torque Server Version = 3.0.5, loglevel = 0
03/26/2013 20:09:06;000d;PBS_Server;Job;20511.tyrone-cluster;Not sending email: User does not want mail of this type.
03/26/2013 20:09:06;0010;PBS_Server;Job;20511.tyrone-cluster;Exit_status=0 resources_used.cput=02:44:42 resources_used.mem=8636808kb resources_used.vmem=28219556kb resources_used.walltime=00:10:17
03/26/2013 20:09:06;0008;PBS_Server;Job;NULL;on_job_exit valid pjob: 0x2f41490 (substate=50)
03/26/2013 20:09:06;0008;PBS_Server;Job;NULL;on_job_exit valid pjob: 0x2f41490 (substate=51)
03/26/2013 20:09:06;0008;PBS_Server;Job;NULL;on_job_exit valid pjob: 0x2f41490 (substate=51)
03/26/2013 20:09:06;0008;PBS_Server;Job;NULL;on_job_exit valid pjob: 0x2f41490 (substate=53)
03/26/2013 20:09:06;0100;PBS_Server;Job;20511.tyrone-cluster;dequeuing from idqueue, state COMPLETE
03/26/2013 20:09:06;0040;PBS_Server;Svr;tyrone-cluster;Scheduler was sent the command term
03/26/2013 20:09:06;0008;PBS_Server;Job;20513.tyrone-cluster;Job Modified at request of Scheduler@tyrone-cluster
03/26/2013 20:09:06;0008;PBS_Server;Job;20513.tyrone-cluster;Job Run at request of Scheduler@tyrone-cluster
03/26/2013 20:09:06;0040;PBS_Server;Svr;tyrone-cluster;Scheduler was sent the command recyc
03/26/2013 20:09:06;000d;PBS_Server;Job;20513.tyrone-cluster;Not sending email: User does not want mail of this type.
03/26/2013 20:13:29;0002;PBS_Server;Svr;PBS_Server;Torque Server Version = 3.0.5, loglevel = 0
03/26/2013 20:18:29;0002;PBS_Server;Svr;PBS_Server;Torque Server Version = 3.0.5, loglevel = 0
03/26/2013 20:19:06;0040;PBS_Server;Svr;tyrone-cluster;Scheduler was sent the command time
03/26/2013 20:22:54;000d;PBS_Server;Job;20512.tyrone-cluster;Not sending email: User does not want mail of this type.
03/26/2013 20:22:54;0010;PBS_Server;Job;20512.tyrone-cluster;Exit_status=0 resources_used.cput=04:14:48 resources_used.mem=8801720kb resources_used.vmem=25077068kb resources_used.walltime=00:15:42
03/26/2013 20:22:54;0008;PBS_Server;Job;NULL;on_job_exit valid pjob: 0x2ef9700 (substate=50)
03/26/2013 20:22:54;0008;PBS_Server;Job;NULL;on_job_exit valid pjob: 0x2ef9700 (substate=51)
03/26/2013 20:22:54;0008;PBS_Server;Job;NULL;on_job_exit valid pjob: 0x2ef9700 (substate=51)
03/26/2013 20:22:54;0008;PBS_Server;Job;NULL;on_job_exit valid pjob: 0x2ef9700 (substate=53)
03/26/2013 20:22:54;0100;PBS_Server;Job;20512.tyrone-cluster;dequeuing from idqueue, state COMPLETE
03/26/2013 20:22:54;0040;PBS_Server;Svr;tyrone-cluster;Scheduler was sent the command term
03/26/2013 20:22:55;0008;PBS_Server;Job;20514.tyrone-cluster;Job Modified at request of Scheduler@tyrone-cluster
03/26/2013 20:22:55;0008;PBS_Server;Job;20514.tyrone-cluster;Job Run at request of Scheduler@tyrone-cluster
03/26/2013 20:22:55;0040;PBS_Server;Svr;tyrone-cluster;Scheduler was sent the command recyc
03/26/2013 20:22:55;000d;PBS_Server;Job;20514.tyrone-cluster;Not sending email: User does not want mail of this type.
03/26/2013 20:23:29;0002;PBS_Server;Svr;PBS_Server;Torque Server Version = 3.0.5, loglevel = 0
03/26/2013 20:24:29;000d;PBS_Server;Job;20513.tyrone-cluster;Not sending email: User does not want mail of this type.
03/26/2013 20:24:29;0010;PBS_Server;Job;20513.tyrone-cluster;Exit_status=0 resources_used.cput=04:01:47 resources_used.mem=9152512kb resources_used.vmem=32688076kb resources_used.walltime=00:15:23
03/26/2013 20:24:29;0008;PBS_Server;Job;NULL;on_job_exit valid pjob: 0x2e4bde0 (substate=50)
03/26/2013 20:24:29;0008;PBS_Server;Job;NULL;on_job_exit valid pjob: 0x2e4bde0 (substate=51)
03/26/2013 20:24:29;0008;PBS_Server;Job;NULL;on_job_exit valid pjob: 0x2e4bde0 (substate=51)
03/26/2013 20:24:29;0008;PBS_Server;Job;NULL;on_job_exit valid pjob: 0x2e4bde0 (substate=53)
03/26/2013 20:24:29;0100;PBS_Server;Job;20513.tyrone-cluster;dequeuing from idqueue, state COMPLETE
03/26/2013 20:24:29;0040;PBS_Server;Svr;tyrone-cluster;Scheduler was sent the command term
03/26/2013 20:24:29;0008;PBS_Server;Job;20515.tyrone-cluster;Job Modified at request of Scheduler@tyrone-cluster
03/26/2013 20:24:29;0008;PBS_Server;Job;20515.tyrone-cluster;Job Run at request of Scheduler@tyrone-cluster
03/26/2013 20:24:29;0040;PBS_Server;Svr;tyrone-cluster;Scheduler was sent the command recyc
03/26/2013 20:24:29;000d;PBS_Server;Job;20515.tyrone-cluster;Not sending email: User does not want mail of this type.
03/26/2013 20:28:29;0002;PBS_Server;Svr;PBS_Server;Torque Server Version = 3.0.5, loglevel = 0
03/26/2013 20:33:29;0002;PBS_Server;Svr;PBS_Server;Torque Server Version = 3.0.5, loglevel = 0
03/26/2013 20:34:29;0040;PBS_Server;Svr;tyrone-cluster;Scheduler was sent the command time
03/26/2013 20:38:29;0002;PBS_Server;Svr;PBS_Server;Torque Server Version = 3.0.5, loglevel = 0
03/26/2013 20:43:29;0002;PBS_Server;Svr;PBS_Server;Torque Server Version = 3.0.5, loglevel = 0
03/26/2013 20:44:29;0040;PBS_Server;Svr;tyrone-cluster;Scheduler was sent the command time
03/26/2013 20:46:41;000d;PBS_Server;Job;20514.tyrone-cluster;Not sending email: User does not want mail of this type.
03/26/2013 20:46:41;0010;PBS_Server;Job;20514.tyrone-cluster;Exit_status=0 resources_used.cput=06:18:49 resources_used.mem=9767992kb resources_used.vmem=33466188kb resources_used.walltime=00:23:46
03/26/2013 20:46:41;0008;PBS_Server;Job;NULL;on_job_exit valid pjob: 0x2f47310 (substate=50)
03/26/2013 20:46:41;0008;PBS_Server;Job;NULL;on_job_exit valid pjob: 0x2f47310 (substate=51)
03/26/2013 20:46:41;0008;PBS_Server;Job;NULL;on_job_exit valid pjob: 0x2f47310 (substate=51)
03/26/2013 20:46:41;0008;PBS_Server;Job;NULL;on_job_exit valid pjob: 0x2f47310 (substate=53)
03/26/2013 20:46:41;0100;PBS_Server;Job;20514.tyrone-cluster;dequeuing from idqueue, state COMPLETE
03/26/2013 20:46:41;0040;PBS_Server;Svr;tyrone-cluster;Scheduler was sent the command term
03/26/2013 20:46:41;0008;PBS_Server;Job;20524.tyrone-cluster;Job Modified at request of Scheduler@tyrone-cluster
03/26/2013 20:46:41;0008;PBS_Server;Job;20524.tyrone-cluster;Job Run at request of Scheduler@tyrone-cluster
03/26/2013 20:46:41;0040;PBS_Server;Svr;tyrone-cluster;Scheduler was sent the command recyc
03/26/2013 20:46:41;000d;PBS_Server;Job;20524.tyrone-cluster;Not sending email: User does not want mail of this type.
03/26/2013 20:47:37;000d;PBS_Server;Job;20515.tyrone-cluster;Not sending email: User does not want mail of this type.
03/26/2013 20:47:37;0010;PBS_Server;Job;20515.tyrone-cluster;Exit_status=0 resources_used.cput=06:10:34 resources_used.mem=9848112kb resources_used.vmem=33594956kb resources_used.walltime=00:23:08
03/26/2013 20:47:37;0008;PBS_Server;Job;NULL;on_job_exit valid pjob: 0x2e435f0 (substate=50)
03/26/2013 20:47:37;0008;PBS_Server;Job;NULL;on_job_exit valid pjob: 0x2e435f0 (substate=51)
03/26/2013 20:47:37;0008;PBS_Server;Job;NULL;on_job_exit valid pjob: 0x2e435f0 (substate=51)
03/26/2013 20:47:37;0008;PBS_Server;Job;NULL;on_job_exit valid pjob: 0x2e435f0 (substate=53)
03/26/2013 20:47:37;0100;PBS_Server;Job;20515.tyrone-cluster;dequeuing from idqueue, state COMPLETE
03/26/2013 20:47:37;0040;PBS_Server;Svr;tyrone-cluster;Scheduler was sent the command term
03/26/2013 20:48:29;0002;PBS_Server;Svr;PBS_Server;Torque Server Version = 3.0.5, loglevel = 0
03/26/2013 20:53:29;0002;PBS_Server;Svr;PBS_Server;Torque Server Version = 3.0.5, loglevel = 0
03/26/2013 20:57:37;0040;PBS_Server;Svr;tyrone-cluster;Scheduler was sent the command time
03/26/2013 20:58:29;0002;PBS_Server;Svr;PBS_Server;Torque Server Version = 3.0.5, loglevel = 0
03/26/2013 21:02:50;000d;PBS_Server;Job;20524.tyrone-cluster;Not sending email: User does not want mail of this type.
03/26/2013 21:02:50;0010;PBS_Server;Job;20524.tyrone-cluster;Exit_status=0 resources_used.cput=08:20:44 resources_used.mem=4326776kb resources_used.vmem=12549824kb resources_used.walltime=00:16:09
03/26/2013 21:02:50;0008;PBS_Server;Job;NULL;on_job_exit valid pjob: 0x2f622f0 (substate=50)
03/26/2013 21:02:50;0008;PBS_Server;Job;NULL;on_job_exit valid pjob: 0x2f622f0 (substate=51)
03/26/2013 21:02:50;0008;PBS_Server;Job;NULL;on_job_exit valid pjob: 0x2f622f0 (substate=51)
03/26/2013 21:02:50;0008;PBS_Server;Job;NULL;on_job_exit valid pjob: 0x2f622f0 (substate=53)
03/26/2013 21:02:50;0100;PBS_Server;Job;20524.tyrone-cluster;dequeuing from idqueue, state COMPLETE
03/26/2013 21:02:50;0040;PBS_Server;Svr;tyrone-cluster;Scheduler was sent the command term
03/26/2013 21:03:29;0002;PBS_Server;Svr;PBS_Server;Torque Server Version = 3.0.5, loglevel = 0
03/26/2013 21:08:29;0002;PBS_Server;Svr;PBS_Server;Torque Server Version = 3.0.5, loglevel = 0
03/26/2013 21:12:50;0040;PBS_Server;Svr;tyrone-cluster;Scheduler was sent the command time
03/26/2013 21:13:29;0002;PBS_Server;Svr;PBS_Server;Torque Server Version = 3.0.5, loglevel = 0
03/26/2013 21:18:29;0002;PBS_Server;Svr;PBS_Server;Torque Server Version = 3.0.5, loglevel = 0
03/26/2013 21:22:50;0040;PBS_Server;Svr;tyrone-cluster;Scheduler was sent the command time
03/26/2013 21:23:29;0002;PBS_Server;Svr;PBS_Server;Torque Server Version = 3.0.5, loglevel = 0
03/26/2013 21:28:29;0002;PBS_Server;Svr;PBS_Server;Torque Server Version = 3.0.5, loglevel = 0
03/26/2013 21:32:50;0040;PBS_Server;Svr;tyrone-cluster;Scheduler was sent the command time
03/26/2013 21:33:29;0002;PBS_Server;Svr;PBS_Server;Torque Server Version = 3.0.5, loglevel = 0
03/26/2013 21:38:29;0002;PBS_Server;Svr;PBS_Server;Torque Server Version = 3.0.5, loglevel = 0
03/26/2013 21:42:50;0040;PBS_Server;Svr;tyrone-cluster;Scheduler was sent the command time
03/26/2013 21:43:29;0002;PBS_Server;Svr;PBS_Server;Torque Server Version = 3.0.5, loglevel = 0
03/26/2013 21:48:29;0002;PBS_Server;Svr;PBS_Server;Torque Server Version = 3.0.5, loglevel = 0
03/26/2013 21:52:50;0040;PBS_Server;Svr;tyrone-cluster;Scheduler was sent the command time
03/26/2013 21:53:29;0002;PBS_Server;Svr;PBS_Server;Torque Server Version = 3.0.5, loglevel = 0
03/26/2013 21:56:03;0100;PBS_Server;Job;20539.tyrone-cluster;enqueuing into batch, state 1 hop 1
03/26/2013 21:56:03;0100;PBS_Server;Job;20539.tyrone-cluster;dequeuing from batch, state QUEUED
03/26/2013 21:56:03;0100;PBS_Server;Job;20539.tyrone-cluster;enqueuing into qp64, state 1 hop 1
03/26/2013 21:56:03;0008;PBS_Server;Job;20539.tyrone-cluster;Job Queued at request of asealama@tyrone-node9, owner = asealama@tyrone-node9, job name = jobname, queue = qp64
03/26/2013 21:56:03;0040;PBS_Server;Svr;tyrone-cluster;Scheduler was sent the command new
03/26/2013 21:56:03;0008;PBS_Server;Job;20539.tyrone-cluster;Job Modified at request of Scheduler@tyrone-cluster
03/26/2013 21:56:03;0008;PBS_Server;Job;20539.tyrone-cluster;Job Run at request of Scheduler@tyrone-cluster
03/26/2013 21:56:03;0040;PBS_Server;Svr;tyrone-cluster;Scheduler was sent the command recyc
03/26/2013 21:56:03;000d;PBS_Server;Job;20539.tyrone-cluster;Not sending email: User does not want mail of this type.
03/26/2013 21:56:12;000d;PBS_Server;Job;20539.tyrone-cluster;Not sending email: User does not want mail of this type.
03/26/2013 21:56:12;0010;PBS_Server;Job;20539.tyrone-cluster;Exit_status=0 resources_used.cput=00:00:38 resources_used.mem=63084kb resources_used.vmem=627620kb resources_used.walltime=00:00:09
03/26/2013 21:56:12;0008;PBS_Server;Job;NULL;on_job_exit valid pjob: 0x2f622f0 (substate=50)
03/26/2013 21:56:12;0008;PBS_Server;Job;NULL;on_job_exit valid pjob: 0x2f622f0 (substate=51)
03/26/2013 21:56:12;0008;PBS_Server;Job;NULL;on_job_exit valid pjob: 0x2f622f0 (substate=51)
03/26/2013 21:56:12;0008;PBS_Server;Job;NULL;on_job_exit valid pjob: 0x2f622f0 (substate=53)
03/26/2013 21:56:12;0100;PBS_Server;Job;20539.tyrone-cluster;dequeuing from qp64, state COMPLETE
03/26/2013 21:56:12;0040;PBS_Server;Svr;tyrone-cluster;Scheduler was sent the command term
03/26/2013 21:58:29;0002;PBS_Server;Svr;PBS_Server;Torque Server Version = 3.0.5, loglevel = 0
03/26/2013 22:03:29;0002;PBS_Server;Svr;PBS_Server;Torque Server Version = 3.0.5, loglevel = 0
03/26/2013 22:06:12;0040;PBS_Server;Svr;tyrone-cluster;Scheduler was sent the command time
03/26/2013 22:08:29;0002;PBS_Server;Svr;PBS_Server;Torque Server Version = 3.0.5, loglevel = 0
03/26/2013 22:09:47;000d;PBS_Server;Job;20457.tyrone-cluster;Not sending email: User does not want mail of this type.
03/26/2013 22:09:47;0010;PBS_Server;Job;20457.tyrone-cluster;Exit_status=0 resources_used.cput=444:32:53 resources_used.mem=2320292kb resources_used.vmem=36073540kb resources_used.walltime=06:57:12
03/26/2013 22:09:47;0008;PBS_Server;Job;NULL;on_job_exit valid pjob: 0x2ec6dc0 (substate=50)
03/26/2013 22:09:47;0008;PBS_Server;Job;NULL;on_job_exit valid pjob: 0x2ec6dc0 (substate=51)
03/26/2013 22:09:51;0008;PBS_Server;Job;NULL;on_job_exit valid pjob: 0x2ec6dc0 (substate=51)
03/26/2013 22:09:51;000d;PBS_Server;Job;20457.tyrone-cluster;Post job file processing error; job 20457.tyrone-cluster on host tyrone-node10/63+tyrone-node10/62+tyrone-node10/61+tyrone-node10/60+tyrone-node10/59+tyrone-node10/58+tyrone-node10/57+tyrone-node10/56+tyrone-node10/55+tyrone-node10/54+tyrone-node10/53+tyrone-node10/52+tyrone-node10/51+tyrone-node10/50+tyrone-node10/49+tyrone-node10/48+tyrone-node10/47+tyrone-node10/46+tyrone-node10/45+tyrone-node10/44+tyrone-node10/43+tyrone-node10/42+tyrone-node10/41+tyrone-node10/40+tyrone-node10/39+tyrone-node10/38+tyrone-node10/37+tyrone-node10/36+tyrone-node10/35+tyrone-node10/34+tyrone-node10/33+tyrone-node10/32+tyrone-node10/31+tyrone-node10/30+tyrone-node10/29+tyrone-node10/28+tyrone-node10/27+tyrone-node10/26+tyrone-node10/25+tyrone-node10/24+tyrone-node10/23+tyrone-node10/22+tyrone-node10/21+tyrone-node10/20+tyrone-node10/19+tyrone-node10/18+tyrone-node10/17+tyrone-node10/16+tyrone-node10/15+tyrone-node10/14+tyrone-node10/13+tyrone-node10/12+tyrone-node10/11+tyrone-node10/10+tyrone-node10/9+tyrone-node10/8+tyrone-node10/7+tyrone-node10/6+tyrone-node10/5+tyrone-node10/4+tyrone-node10/3+tyrone-node10/2+tyrone-node10/1+tyrone-node10/0
03/26/2013 22:09:51;0008;PBS_Server;Job;NULL;on_job_exit valid pjob: 0x2ec6dc0 (substate=53)
03/26/2013 22:09:51;0100;PBS_Server;Job;20457.tyrone-cluster;dequeuing from qp64, state COMPLETE
03/26/2013 22:09:51;0040;PBS_Server;Svr;tyrone-cluster;Scheduler was sent the command term
03/26/2013 22:13:29;0002;PBS_Server;Svr;PBS_Server;Torque Server Version = 3.0.5, loglevel = 0
03/26/2013 22:18:29;0002;PBS_Server;Svr;PBS_Server;Torque Server Version = 3.0.5, loglevel = 0
03/26/2013 22:19:51;0040;PBS_Server;Svr;tyrone-cluster;Scheduler was sent the command time
03/26/2013 22:20:19;0100;PBS_Server;Job;20540.tyrone-cluster;enqueuing into batch, state 1 hop 1
03/26/2013 22:20:19;0100;PBS_Server;Job;20540.tyrone-cluster;dequeuing from batch, state QUEUED
03/26/2013 22:20:19;0100;PBS_Server;Job;20540.tyrone-cluster;enqueuing into qp32, state 1 hop 1
03/26/2013 22:20:19;0008;PBS_Server;Job;20540.tyrone-cluster;Job Queued at request of ipcdskp@tyrone-cluster, owner = ipcdskp@tyrone-cluster, job name = n10, queue = qp32
03/26/2013 22:20:19;0040;PBS_Server;Svr;tyrone-cluster;Scheduler was sent the command new
03/26/2013 22:20:19;0008;PBS_Server;Job;20540.tyrone-cluster;Job Modified at request of Scheduler@tyrone-cluster
03/26/2013 22:20:19;0008;PBS_Server;Job;20540.tyrone-cluster;Job Run at request of Scheduler@tyrone-cluster
03/26/2013 22:20:19;0040;PBS_Server;Svr;tyrone-cluster;Scheduler was sent the command recyc
03/26/2013 22:20:19;000d;PBS_Server;Job;20540.tyrone-cluster;Not sending email: User does not want mail of this type.
03/26/2013 22:20:43;0008;PBS_Server;Job;20540.tyrone-cluster;Job deleted at request of ipcdskp@tyrone-cluster
03/26/2013 22:20:43;0008;PBS_Server;Job;20540.tyrone-cluster;Job sent signal SIGTERM on delete
03/26/2013 22:20:44;0008;PBS_Server;Job;20540.tyrone-cluster;Job deleted at request of ipcdskp@tyrone-cluster
03/26/2013 22:20:44;0008;PBS_Server;Job;20540.tyrone-cluster;Job sent signal SIGTERM on delete
03/26/2013 22:20:45;0008;PBS_Server;Job;20540.tyrone-cluster;Job sent signal SIGKILL on delete
03/26/2013 22:20:48;000d;PBS_Server;Job;20540.tyrone-cluster;Not sending email: User does not want mail of this type.
03/26/2013 22:20:48;0010;PBS_Server;Job;20540.tyrone-cluster;Exit_status=143 resources_used.cput=00:11:10 resources_used.mem=274304kb resources_used.vmem=5554492kb resources_used.walltime=00:00:29
03/26/2013 22:20:48;0008;PBS_Server;Job;NULL;on_job_exit valid pjob: 0x2f622f0 (substate=50)
03/26/2013 22:20:48;0008;PBS_Server;Job;NULL;on_job_exit valid pjob: 0x2f622f0 (substate=51)
03/26/2013 22:20:48;0008;PBS_Server;Job;NULL;on_job_exit valid pjob: 0x2f622f0 (substate=51)
03/26/2013 22:20:48;0008;PBS_Server;Job;NULL;on_job_exit valid pjob: 0x2f622f0 (substate=53)
03/26/2013 22:20:48;0100;PBS_Server;Job;20540.tyrone-cluster;dequeuing from qp32, state COMPLETE
03/26/2013 22:20:48;0040;PBS_Server;Svr;tyrone-cluster;Scheduler was sent the command term
03/26/2013 22:22:43;0100;PBS_Server;Job;20541.tyrone-cluster;enqueuing into batch, state 1 hop 1
03/26/2013 22:22:43;0100;PBS_Server;Job;20541.tyrone-cluster;dequeuing from batch, state QUEUED
03/26/2013 22:22:43;0100;PBS_Server;Job;20541.tyrone-cluster;enqueuing into qp64, state 1 hop 1
03/26/2013 22:22:43;0008;PBS_Server;Job;20541.tyrone-cluster;Job Queued at request of ipcdskp@tyrone-cluster, owner = ipcdskp@tyrone-cluster, job name = n10, queue = qp64
03/26/2013 22:22:43;0040;PBS_Server;Svr;tyrone-cluster;Scheduler was sent the command new
03/26/2013 22:22:43;0008;PBS_Server;Job;20541.tyrone-cluster;Job Modified at request of Scheduler@tyrone-cluster
03/26/2013 22:22:43;0008;PBS_Server;Job;20541.tyrone-cluster;Job Run at request of Scheduler@tyrone-cluster
03/26/2013 22:22:44;0040;PBS_Server;Svr;tyrone-cluster;Scheduler was sent the command recyc
03/26/2013 22:22:44;000d;PBS_Server;Job;20541.tyrone-cluster;Not sending email: User does not want mail of this type.
03/26/2013 22:23:00;0008;PBS_Server;Job;20541.tyrone-cluster;Job deleted at request of ipcdskp@tyrone-cluster
03/26/2013 22:23:00;0008;PBS_Server;Job;20541.tyrone-cluster;Job sent signal SIGTERM on delete
03/26/2013 22:23:02;0008;PBS_Server;Job;20541.tyrone-cluster;Job sent signal SIGKILL on delete
03/26/2013 22:23:06;000d;PBS_Server;Job;20541.tyrone-cluster;Not sending email: User does not want mail of this type.
03/26/2013 22:23:06;0010;PBS_Server;Job;20541.tyrone-cluster;Exit_status=143 resources_used.cput=00:15:15 resources_used.mem=215412kb resources_used.vmem=3936512kb resources_used.walltime=00:00:22
03/26/2013 22:23:06;0008;PBS_Server;Job;NULL;on_job_exit valid pjob: 0x2e37f20 (substate=50)
03/26/2013 22:23:06;0008;PBS_Server;Job;NULL;on_job_exit valid pjob: 0x2e37f20 (substate=51)
03/26/2013 22:23:06;0008;PBS_Server;Job;NULL;on_job_exit valid pjob: 0x2e37f20 (substate=51)
03/26/2013 22:23:06;0008;PBS_Server;Job;NULL;on_job_exit valid pjob: 0x2e37f20 (substate=53)
03/26/2013 22:23:06;0100;PBS_Server;Job;20541.tyrone-cluster;dequeuing from qp64, state COMPLETE
03/26/2013 22:23:06;0040;PBS_Server;Svr;tyrone-cluster;Scheduler was sent the command term
03/26/2013 22:23:29;0002;PBS_Server;Svr;PBS_Server;Torque Server Version = 3.0.5, loglevel = 0
03/26/2013 22:28:29;0002;PBS_Server;Svr;PBS_Server;Torque Server Version = 3.0.5, loglevel = 0
03/26/2013 22:33:06;0040;PBS_Server;Svr;tyrone-cluster;Scheduler was sent the command time
03/26/2013 22:33:29;0002;PBS_Server;Svr;PBS_Server;Torque Server Version = 3.0.5, loglevel = 0
03/26/2013 22:38:29;0002;PBS_Server;Svr;PBS_Server;Torque Server Version = 3.0.5, loglevel = 0
03/26/2013 22:43:06;0040;PBS_Server;Svr;tyrone-cluster;Scheduler was sent the command time
03/26/2013 22:43:29;0002;PBS_Server;Svr;PBS_Server;Torque Server Version = 3.0.5, loglevel = 0
03/26/2013 22:48:29;0002;PBS_Server;Svr;PBS_Server;Torque Server Version = 3.0.5, loglevel = 0
03/26/2013 22:53:06;0040;PBS_Server;Svr;tyrone-cluster;Scheduler was sent the command time
03/26/2013 22:53:29;0002;PBS_Server;Svr;PBS_Server;Torque Server Version = 3.0.5, loglevel = 0
03/26/2013 22:58:29;0002;PBS_Server;Svr;PBS_Server;Torque Server Version = 3.0.5, loglevel = 0
03/26/2013 23:03:06;0040;PBS_Server;Svr;tyrone-cluster;Scheduler was sent the command time
03/26/2013 23:03:29;0002;PBS_Server;Svr;PBS_Server;Torque Server Version = 3.0.5, loglevel = 0
03/26/2013 23:08:29;0002;PBS_Server;Svr;PBS_Server;Torque Server Version = 3.0.5, loglevel = 0
03/26/2013 23:13:06;0040;PBS_Server;Svr;tyrone-cluster;Scheduler was sent the command time
03/26/2013 23:13:29;0002;PBS_Server;Svr;PBS_Server;Torque Server Version = 3.0.5, loglevel = 0
03/26/2013 23:17:48;0100;PBS_Server;Job;20542.tyrone-cluster;enqueuing into batch, state 1 hop 1
03/26/2013 23:17:48;0100;PBS_Server;Job;20542.tyrone-cluster;dequeuing from batch, state QUEUED
03/26/2013 23:17:48;0100;PBS_Server;Job;20542.tyrone-cluster;enqueuing into qp32, state 1 hop 1
03/26/2013 23:17:48;0008;PBS_Server;Job;20542.tyrone-cluster;Job Queued at request of nisaadi@tyrone-cluster, owner = nisaadi@tyrone-cluster, job name = sil-disp7, queue = qp32
03/26/2013 23:17:48;0040;PBS_Server;Svr;tyrone-cluster;Scheduler was sent the command new
03/26/2013 23:17:48;0008;PBS_Server;Job;20542.tyrone-cluster;Job Modified at request of Scheduler@tyrone-cluster
03/26/2013 23:17:48;0008;PBS_Server;Job;20542.tyrone-cluster;Job Run at request of Scheduler@tyrone-cluster
03/26/2013 23:17:48;0040;PBS_Server;Svr;tyrone-cluster;Scheduler was sent the command recyc
03/26/2013 23:17:48;000d;PBS_Server;Job;20542.tyrone-cluster;Not sending email: User does not want mail of this type.
03/26/2013 23:18:29;0002;PBS_Server;Svr;PBS_Server;Torque Server Version = 3.0.5, loglevel = 0
03/26/2013 23:23:29;0002;PBS_Server;Svr;PBS_Server;Torque Server Version = 3.0.5, loglevel = 0
03/26/2013 23:27:48;0040;PBS_Server;Svr;tyrone-cluster;Scheduler was sent the command time
03/26/2013 23:28:29;0002;PBS_Server;Svr;PBS_Server;Torque Server Version = 3.0.5, loglevel = 0
03/26/2013 23:33:29;0002;PBS_Server;Svr;PBS_Server;Torque Server Version = 3.0.5, loglevel = 0
03/26/2013 23:37:48;0040;PBS_Server;Svr;tyrone-cluster;Scheduler was sent the command time
03/26/2013 23:38:02;0100;PBS_Server;Job;20543.tyrone-cluster;enqueuing into batch, state 1 hop 1
03/26/2013 23:38:02;0100;PBS_Server;Job;20543.tyrone-cluster;dequeuing from batch, state QUEUED
03/26/2013 23:38:03;0100;PBS_Server;Job;20543.tyrone-cluster;enqueuing into qp64, state 1 hop 1
03/26/2013 23:38:03;0008;PBS_Server;Job;20543.tyrone-cluster;Job Queued at request of csdpalvi@tyrone-cluster, owner = csdpalvi@tyrone-cluster, job name = n11, queue = qp64
03/26/2013 23:38:03;0040;PBS_Server;Svr;tyrone-cluster;Scheduler was sent the command new
03/26/2013 23:38:03;0008;PBS_Server;Job;20543.tyrone-cluster;Job Modified at request of Scheduler@tyrone-cluster
03/26/2013 23:38:03;0008;PBS_Server;Job;20543.tyrone-cluster;Job Run at request of Scheduler@tyrone-cluster
03/26/2013 23:38:03;0040;PBS_Server;Svr;tyrone-cluster;Scheduler was sent the command recyc
03/26/2013 23:38:03;000d;PBS_Server;Job;20543.tyrone-cluster;Not sending email: User does not want mail of this type.
03/26/2013 23:38:29;0002;PBS_Server;Svr;PBS_Server;Torque Server Version = 3.0.5, loglevel = 0
03/26/2013 23:43:29;0002;PBS_Server;Svr;PBS_Server;Torque Server Version = 3.0.5, loglevel = 0
03/26/2013 23:48:03;0040;PBS_Server;Svr;tyrone-cluster;Scheduler was sent the command time
03/26/2013 23:48:29;0002;PBS_Server;Svr;PBS_Server;Torque Server Version = 3.0.5, loglevel = 0
03/26/2013 23:53:29;0002;PBS_Server;Svr;PBS_Server;Torque Server Version = 3.0.5, loglevel = 0
03/26/2013 23:58:03;0040;PBS_Server;Svr;tyrone-cluster;Scheduler was sent the command time
03/26/2013 23:58:29;0002;PBS_Server;Svr;PBS_Server;Torque Server Version = 3.0.5, loglevel = 0
03/27/2013 00:00:52;0002;PBS_Server;Svr;Log;Log closed
