02/18/2014 00:00:27;0002;PBS_Server;Svr;Log;Log opened
02/18/2014 00:00:27;0040;PBS_Server;Svr;tyrone-cluster;Scheduler was sent the command new
02/18/2014 00:00:57;0040;PBS_Server;Svr;tyrone-cluster;Scheduler was sent the command new
02/18/2014 00:01:23;0002;PBS_Server;Svr;PBS_Server;Torque Server Version = 3.0.5, loglevel = 0
02/18/2014 00:01:26;0040;PBS_Server;Svr;tyrone-cluster;Scheduler was sent the command new
02/18/2014 00:01:57;0040;PBS_Server;Svr;tyrone-cluster;Scheduler was sent the command new
02/18/2014 00:02:28;0040;PBS_Server;Svr;tyrone-cluster;Scheduler was sent the command new
02/18/2014 00:02:59;0040;PBS_Server;Svr;tyrone-cluster;Scheduler was sent the command new
02/18/2014 00:03:27;0040;PBS_Server;Svr;tyrone-cluster;Scheduler was sent the command new
02/18/2014 00:03:59;0040;PBS_Server;Svr;tyrone-cluster;Scheduler was sent the command new
02/18/2014 00:04:29;0040;PBS_Server;Svr;tyrone-cluster;Scheduler was sent the command new
02/18/2014 00:04:59;0040;PBS_Server;Svr;tyrone-cluster;Scheduler was sent the command new
02/18/2014 00:05:36;0040;PBS_Server;Svr;tyrone-cluster;Scheduler was sent the command new
02/18/2014 00:06:06;0040;PBS_Server;Svr;tyrone-cluster;Scheduler was sent the command new
02/18/2014 00:06:23;0002;PBS_Server;Svr;PBS_Server;Torque Server Version = 3.0.5, loglevel = 0
02/18/2014 00:06:29;0040;PBS_Server;Svr;tyrone-cluster;Scheduler was sent the command new
02/18/2014 00:07:10;0040;PBS_Server;Svr;tyrone-cluster;Scheduler was sent the command new
02/18/2014 00:07:36;0040;PBS_Server;Svr;tyrone-cluster;Scheduler was sent the command new
02/18/2014 00:08:08;0040;PBS_Server;Svr;tyrone-cluster;Scheduler was sent the command new
02/18/2014 00:08:40;0040;PBS_Server;Svr;tyrone-cluster;Scheduler was sent the command new
02/18/2014 00:09:10;0040;PBS_Server;Svr;tyrone-cluster;Scheduler was sent the command new
02/18/2014 00:09:41;0040;PBS_Server;Svr;tyrone-cluster;Scheduler was sent the command new
02/18/2014 00:10:12;0040;PBS_Server;Svr;tyrone-cluster;Scheduler was sent the command new
02/18/2014 00:10:42;0040;PBS_Server;Svr;tyrone-cluster;Scheduler was sent the command new
02/18/2014 00:11:11;0040;PBS_Server;Svr;tyrone-cluster;Scheduler was sent the command new
02/18/2014 00:11:23;0002;PBS_Server;Svr;PBS_Server;Torque Server Version = 3.0.5, loglevel = 0
02/18/2014 00:11:42;0040;PBS_Server;Svr;tyrone-cluster;Scheduler was sent the command new
02/18/2014 00:12:13;0040;PBS_Server;Svr;tyrone-cluster;Scheduler was sent the command new
02/18/2014 00:12:44;0040;PBS_Server;Svr;tyrone-cluster;Scheduler was sent the command new
02/18/2014 00:13:14;0040;PBS_Server;Svr;tyrone-cluster;Scheduler was sent the command new
02/18/2014 00:13:51;0040;PBS_Server;Svr;tyrone-cluster;Scheduler was sent the command new
02/18/2014 00:14:21;0040;PBS_Server;Svr;tyrone-cluster;Scheduler was sent the command new
02/18/2014 00:14:44;0040;PBS_Server;Svr;tyrone-cluster;Scheduler was sent the command new
02/18/2014 00:15:21;0040;PBS_Server;Svr;tyrone-cluster;Scheduler was sent the command new
02/18/2014 00:15:51;0040;PBS_Server;Svr;tyrone-cluster;Scheduler was sent the command new
02/18/2014 00:16:14;0040;PBS_Server;Svr;tyrone-cluster;Scheduler was sent the command new
02/18/2014 00:16:23;0002;PBS_Server;Svr;PBS_Server;Torque Server Version = 3.0.5, loglevel = 0
02/18/2014 00:16:51;0040;PBS_Server;Svr;tyrone-cluster;Scheduler was sent the command new
02/18/2014 00:17:21;0040;PBS_Server;Svr;tyrone-cluster;Scheduler was sent the command new
02/18/2014 00:17:44;0040;PBS_Server;Svr;tyrone-cluster;Scheduler was sent the command new
02/18/2014 00:18:25;0040;PBS_Server;Svr;tyrone-cluster;Scheduler was sent the command new
02/18/2014 00:18:51;0040;PBS_Server;Svr;tyrone-cluster;Scheduler was sent the command new
02/18/2014 00:19:23;0040;PBS_Server;Svr;tyrone-cluster;Scheduler was sent the command new
02/18/2014 00:19:55;0040;PBS_Server;Svr;tyrone-cluster;Scheduler was sent the command new
02/18/2014 00:20:25;0040;PBS_Server;Svr;tyrone-cluster;Scheduler was sent the command new
02/18/2014 00:20:56;0040;PBS_Server;Svr;tyrone-cluster;Scheduler was sent the command new
02/18/2014 00:21:23;0002;PBS_Server;Svr;PBS_Server;Torque Server Version = 3.0.5, loglevel = 0
02/18/2014 00:21:27;0040;PBS_Server;Svr;tyrone-cluster;Scheduler was sent the command new
02/18/2014 00:21:57;0040;PBS_Server;Svr;tyrone-cluster;Scheduler was sent the command new
02/18/2014 00:22:26;0040;PBS_Server;Svr;tyrone-cluster;Scheduler was sent the command new
02/18/2014 00:22:57;0040;PBS_Server;Svr;tyrone-cluster;Scheduler was sent the command new
02/18/2014 00:23:36;0040;PBS_Server;Svr;tyrone-cluster;Scheduler was sent the command new
02/18/2014 00:24:06;0040;PBS_Server;Svr;tyrone-cluster;Scheduler was sent the command new
02/18/2014 00:24:29;0040;PBS_Server;Svr;tyrone-cluster;Scheduler was sent the command new
02/18/2014 00:25:07;0040;PBS_Server;Svr;tyrone-cluster;Scheduler was sent the command new
02/18/2014 00:25:36;0040;PBS_Server;Svr;tyrone-cluster;Scheduler was sent the command new
02/18/2014 00:25:59;0040;PBS_Server;Svr;tyrone-cluster;Scheduler was sent the command new
02/18/2014 00:26:23;0002;PBS_Server;Svr;PBS_Server;Torque Server Version = 3.0.5, loglevel = 0
02/18/2014 00:26:36;0040;PBS_Server;Svr;tyrone-cluster;Scheduler was sent the command new
02/18/2014 00:27:06;0040;PBS_Server;Svr;tyrone-cluster;Scheduler was sent the command new
02/18/2014 00:27:29;0040;PBS_Server;Svr;tyrone-cluster;Scheduler was sent the command new
02/18/2014 00:28:06;0040;PBS_Server;Svr;tyrone-cluster;Scheduler was sent the command new
02/18/2014 00:28:36;0040;PBS_Server;Svr;tyrone-cluster;Scheduler was sent the command new
02/18/2014 00:28:59;0040;PBS_Server;Svr;tyrone-cluster;Scheduler was sent the command new
02/18/2014 00:29:36;0040;PBS_Server;Svr;tyrone-cluster;Scheduler was sent the command new
02/18/2014 00:30:06;0040;PBS_Server;Svr;tyrone-cluster;Scheduler was sent the command new
02/18/2014 00:30:29;0040;PBS_Server;Svr;tyrone-cluster;Scheduler was sent the command new
02/18/2014 00:31:10;0040;PBS_Server;Svr;tyrone-cluster;Scheduler was sent the command new
02/18/2014 00:31:23;0002;PBS_Server;Svr;PBS_Server;Torque Server Version = 3.0.5, loglevel = 0
02/18/2014 00:31:39;0040;PBS_Server;Svr;tyrone-cluster;Scheduler was sent the command new
02/18/2014 00:32:08;0040;PBS_Server;Svr;tyrone-cluster;Scheduler was sent the command new
02/18/2014 00:32:40;0040;PBS_Server;Svr;tyrone-cluster;Scheduler was sent the command new
02/18/2014 00:33:10;0040;PBS_Server;Svr;tyrone-cluster;Scheduler was sent the command new
02/18/2014 00:33:41;0040;PBS_Server;Svr;tyrone-cluster;Scheduler was sent the command new
02/18/2014 00:34:12;0040;PBS_Server;Svr;tyrone-cluster;Scheduler was sent the command new
02/18/2014 00:34:51;0040;PBS_Server;Svr;tyrone-cluster;Scheduler was sent the command new
02/18/2014 00:35:21;0040;PBS_Server;Svr;tyrone-cluster;Scheduler was sent the command new
02/18/2014 00:35:44;0040;PBS_Server;Svr;tyrone-cluster;Scheduler was sent the command new
02/18/2014 00:36:24;0002;PBS_Server;Svr;PBS_Server;Torque Server Version = 3.0.5, loglevel = 0
02/18/2014 00:36:24;0040;PBS_Server;Svr;tyrone-cluster;Scheduler was sent the command new
02/18/2014 00:36:51;0040;PBS_Server;Svr;tyrone-cluster;Scheduler was sent the command new
02/18/2014 00:37:22;0040;PBS_Server;Svr;tyrone-cluster;Scheduler was sent the command new
02/18/2014 00:37:55;0040;PBS_Server;Svr;tyrone-cluster;Scheduler was sent the command new
02/18/2014 00:38:21;0040;PBS_Server;Svr;tyrone-cluster;Scheduler was sent the command new
02/18/2014 00:38:53;0040;PBS_Server;Svr;tyrone-cluster;Scheduler was sent the command new
02/18/2014 00:39:25;0040;PBS_Server;Svr;tyrone-cluster;Scheduler was sent the command new
02/18/2014 00:39:55;0040;PBS_Server;Svr;tyrone-cluster;Scheduler was sent the command new
02/18/2014 00:40:26;0040;PBS_Server;Svr;tyrone-cluster;Scheduler was sent the command new
02/18/2014 00:40:57;0040;PBS_Server;Svr;tyrone-cluster;Scheduler was sent the command new
02/18/2014 00:41:24;0002;PBS_Server;Svr;PBS_Server;Torque Server Version = 3.0.5, loglevel = 0
02/18/2014 00:41:29;0040;PBS_Server;Svr;tyrone-cluster;Scheduler was sent the command new
02/18/2014 00:41:59;0040;PBS_Server;Svr;tyrone-cluster;Scheduler was sent the command new
02/18/2014 00:42:27;0040;PBS_Server;Svr;tyrone-cluster;Scheduler was sent the command new
02/18/2014 00:42:57;0040;PBS_Server;Svr;tyrone-cluster;Scheduler was sent the command new
02/18/2014 00:43:29;0040;PBS_Server;Svr;tyrone-cluster;Scheduler was sent the command new
02/18/2014 00:43:59;0040;PBS_Server;Svr;tyrone-cluster;Scheduler was sent the command new
02/18/2014 00:44:36;0040;PBS_Server;Svr;tyrone-cluster;Scheduler was sent the command new
02/18/2014 00:45:06;0040;PBS_Server;Svr;tyrone-cluster;Scheduler was sent the command new
02/18/2014 00:45:29;0040;PBS_Server;Svr;tyrone-cluster;Scheduler was sent the command new
02/18/2014 00:46:06;0040;PBS_Server;Svr;tyrone-cluster;Scheduler was sent the command new
02/18/2014 00:46:24;0002;PBS_Server;Svr;PBS_Server;Torque Server Version = 3.0.5, loglevel = 0
02/18/2014 00:46:36;0040;PBS_Server;Svr;tyrone-cluster;Scheduler was sent the command new
02/18/2014 00:46:59;0040;PBS_Server;Svr;tyrone-cluster;Scheduler was sent the command new
02/18/2014 00:47:36;0040;PBS_Server;Svr;tyrone-cluster;Scheduler was sent the command new
02/18/2014 00:48:06;0040;PBS_Server;Svr;tyrone-cluster;Scheduler was sent the command new
02/18/2014 00:48:29;0040;PBS_Server;Svr;tyrone-cluster;Scheduler was sent the command new
02/18/2014 00:49:07;0040;PBS_Server;Svr;tyrone-cluster;Scheduler was sent the command new
02/18/2014 00:49:36;0040;PBS_Server;Svr;tyrone-cluster;Scheduler was sent the command new
02/18/2014 00:49:59;0040;PBS_Server;Svr;tyrone-cluster;Scheduler was sent the command new
02/18/2014 00:50:36;0040;PBS_Server;Svr;tyrone-cluster;Scheduler was sent the command new
02/18/2014 00:51:06;0040;PBS_Server;Svr;tyrone-cluster;Scheduler was sent the command new
02/18/2014 00:51:24;0002;PBS_Server;Svr;PBS_Server;Torque Server Version = 3.0.5, loglevel = 0
02/18/2014 00:51:29;0040;PBS_Server;Svr;tyrone-cluster;Scheduler was sent the command new
02/18/2014 00:52:06;0040;PBS_Server;Svr;tyrone-cluster;Scheduler was sent the command new
02/18/2014 00:52:36;0040;PBS_Server;Svr;tyrone-cluster;Scheduler was sent the command new
02/18/2014 00:52:59;0040;PBS_Server;Svr;tyrone-cluster;Scheduler was sent the command new
02/18/2014 00:53:36;0040;PBS_Server;Svr;tyrone-cluster;Scheduler was sent the command new
02/18/2014 00:54:06;0040;PBS_Server;Svr;tyrone-cluster;Scheduler was sent the command new
02/18/2014 00:54:29;0040;PBS_Server;Svr;tyrone-cluster;Scheduler was sent the command new
02/18/2014 00:55:07;0040;PBS_Server;Svr;tyrone-cluster;Scheduler was sent the command new
02/18/2014 00:55:36;0040;PBS_Server;Svr;tyrone-cluster;Scheduler was sent the command new
02/18/2014 00:56:07;0040;PBS_Server;Svr;tyrone-cluster;Scheduler was sent the command new
02/18/2014 00:56:24;0002;PBS_Server;Svr;PBS_Server;Torque Server Version = 3.0.5, loglevel = 0
02/18/2014 00:56:40;0040;PBS_Server;Svr;tyrone-cluster;Scheduler was sent the command new
02/18/2014 00:57:09;0040;PBS_Server;Svr;tyrone-cluster;Scheduler was sent the command new
02/18/2014 00:57:38;0040;PBS_Server;Svr;tyrone-cluster;Scheduler was sent the command new
02/18/2014 00:58:10;0040;PBS_Server;Svr;tyrone-cluster;Scheduler was sent the command new
02/18/2014 00:58:40;0040;PBS_Server;Svr;tyrone-cluster;Scheduler was sent the command new
02/18/2014 00:59:11;0040;PBS_Server;Svr;tyrone-cluster;Scheduler was sent the command new
02/18/2014 00:59:42;0040;PBS_Server;Svr;tyrone-cluster;Scheduler was sent the command new
02/18/2014 01:00:12;0040;PBS_Server;Svr;tyrone-cluster;Scheduler was sent the command new
02/18/2014 01:00:44;0040;PBS_Server;Svr;tyrone-cluster;Scheduler was sent the command new
02/18/2014 01:01:14;0040;PBS_Server;Svr;tyrone-cluster;Scheduler was sent the command new
02/18/2014 01:01:24;0002;PBS_Server;Svr;PBS_Server;Torque Server Version = 3.0.5, loglevel = 0
02/18/2014 01:01:52;0040;PBS_Server;Svr;tyrone-cluster;Scheduler was sent the command new
02/18/2014 01:02:21;0040;PBS_Server;Svr;tyrone-cluster;Scheduler was sent the command new
02/18/2014 01:02:52;0040;PBS_Server;Svr;tyrone-cluster;Scheduler was sent the command new
02/18/2014 01:03:25;0040;PBS_Server;Svr;tyrone-cluster;Scheduler was sent the command new
02/18/2014 01:03:51;0040;PBS_Server;Svr;tyrone-cluster;Scheduler was sent the command new
02/18/2014 01:04:22;0040;PBS_Server;Svr;tyrone-cluster;Scheduler was sent the command new
02/18/2014 01:04:55;0040;PBS_Server;Svr;tyrone-cluster;Scheduler was sent the command new
02/18/2014 01:05:21;0040;PBS_Server;Svr;tyrone-cluster;Scheduler was sent the command new
02/18/2014 01:05:52;0040;PBS_Server;Svr;tyrone-cluster;Scheduler was sent the command new
02/18/2014 01:06:24;0002;PBS_Server;Svr;PBS_Server;Torque Server Version = 3.0.5, loglevel = 0
02/18/2014 01:06:24;0040;PBS_Server;Svr;tyrone-cluster;Scheduler was sent the command new
02/18/2014 01:06:54;0040;PBS_Server;Svr;tyrone-cluster;Scheduler was sent the command new
02/18/2014 01:07:25;0040;PBS_Server;Svr;tyrone-cluster;Scheduler was sent the command new
02/18/2014 01:07:55;0040;PBS_Server;Svr;tyrone-cluster;Scheduler was sent the command new
02/18/2014 01:08:26;0040;PBS_Server;Svr;tyrone-cluster;Scheduler was sent the command new
02/18/2014 01:08:56;0040;PBS_Server;Svr;tyrone-cluster;Scheduler was sent the command new
02/18/2014 01:09:25;0040;PBS_Server;Svr;tyrone-cluster;Scheduler was sent the command new
02/18/2014 01:09:56;0040;PBS_Server;Svr;tyrone-cluster;Scheduler was sent the command new
02/18/2014 01:10:26;0040;PBS_Server;Svr;tyrone-cluster;Scheduler was sent the command new
02/18/2014 01:10:57;0040;PBS_Server;Svr;tyrone-cluster;Scheduler was sent the command new
02/18/2014 01:11:24;0002;PBS_Server;Svr;PBS_Server;Torque Server Version = 3.0.5, loglevel = 0
02/18/2014 01:11:37;0040;PBS_Server;Svr;tyrone-cluster;Scheduler was sent the command new
02/18/2014 01:12:06;0040;PBS_Server;Svr;tyrone-cluster;Scheduler was sent the command new
02/18/2014 01:12:37;0040;PBS_Server;Svr;tyrone-cluster;Scheduler was sent the command new
02/18/2014 01:13:10;0040;PBS_Server;Svr;tyrone-cluster;Scheduler was sent the command new
02/18/2014 01:13:39;0040;PBS_Server;Svr;tyrone-cluster;Scheduler was sent the command new
02/18/2014 01:14:10;0040;PBS_Server;Svr;tyrone-cluster;Scheduler was sent the command new
02/18/2014 01:14:40;0040;PBS_Server;Svr;tyrone-cluster;Scheduler was sent the command new
02/18/2014 01:15:11;0040;PBS_Server;Svr;tyrone-cluster;Scheduler was sent the command new
02/18/2014 01:15:41;0040;PBS_Server;Svr;tyrone-cluster;Scheduler was sent the command new
02/18/2014 01:16:12;0040;PBS_Server;Svr;tyrone-cluster;Scheduler was sent the command new
02/18/2014 01:16:24;0002;PBS_Server;Svr;PBS_Server;Torque Server Version = 3.0.5, loglevel = 0
02/18/2014 01:16:51;0040;PBS_Server;Svr;tyrone-cluster;Scheduler was sent the command new
02/18/2014 01:17:21;0040;PBS_Server;Svr;tyrone-cluster;Scheduler was sent the command new
02/18/2014 01:17:52;0040;PBS_Server;Svr;tyrone-cluster;Scheduler was sent the command new
02/18/2014 01:18:25;0040;PBS_Server;Svr;tyrone-cluster;Scheduler was sent the command new
02/18/2014 01:18:54;0040;PBS_Server;Svr;tyrone-cluster;Scheduler was sent the command new
02/18/2014 01:19:25;0040;PBS_Server;Svr;tyrone-cluster;Scheduler was sent the command new
02/18/2014 01:19:55;0040;PBS_Server;Svr;tyrone-cluster;Scheduler was sent the command new
02/18/2014 01:20:26;0040;PBS_Server;Svr;tyrone-cluster;Scheduler was sent the command new
02/18/2014 01:20:56;0040;PBS_Server;Svr;tyrone-cluster;Scheduler was sent the command new
02/18/2014 01:21:24;0002;PBS_Server;Svr;PBS_Server;Torque Server Version = 3.0.5, loglevel = 0
02/18/2014 01:21:25;0040;PBS_Server;Svr;tyrone-cluster;Scheduler was sent the command new
02/18/2014 01:21:56;0040;PBS_Server;Svr;tyrone-cluster;Scheduler was sent the command new
02/18/2014 01:22:26;0040;PBS_Server;Svr;tyrone-cluster;Scheduler was sent the command new
02/18/2014 01:22:57;0040;PBS_Server;Svr;tyrone-cluster;Scheduler was sent the command new
02/18/2014 01:23:27;0040;PBS_Server;Svr;tyrone-cluster;Scheduler was sent the command new
02/18/2014 01:23:59;0040;PBS_Server;Svr;tyrone-cluster;Scheduler was sent the command new
02/18/2014 01:24:29;0040;PBS_Server;Svr;tyrone-cluster;Scheduler was sent the command new
02/18/2014 01:25:07;0040;PBS_Server;Svr;tyrone-cluster;Scheduler was sent the command new
02/18/2014 01:25:36;0040;PBS_Server;Svr;tyrone-cluster;Scheduler was sent the command new
02/18/2014 01:26:07;0040;PBS_Server;Svr;tyrone-cluster;Scheduler was sent the command new
02/18/2014 01:26:24;0002;PBS_Server;Svr;PBS_Server;Torque Server Version = 3.0.5, loglevel = 0
02/18/2014 01:26:40;0040;PBS_Server;Svr;tyrone-cluster;Scheduler was sent the command new
02/18/2014 01:27:09;0040;PBS_Server;Svr;tyrone-cluster;Scheduler was sent the command new
02/18/2014 01:27:38;0040;PBS_Server;Svr;tyrone-cluster;Scheduler was sent the command new
02/18/2014 01:28:10;0040;PBS_Server;Svr;tyrone-cluster;Scheduler was sent the command new
02/18/2014 01:28:40;0040;PBS_Server;Svr;tyrone-cluster;Scheduler was sent the command new
02/18/2014 01:29:11;0040;PBS_Server;Svr;tyrone-cluster;Scheduler was sent the command new
02/18/2014 01:29:40;0040;PBS_Server;Svr;tyrone-cluster;Scheduler was sent the command new
02/18/2014 01:30:11;0040;PBS_Server;Svr;tyrone-cluster;Scheduler was sent the command new
02/18/2014 01:30:41;0040;PBS_Server;Svr;tyrone-cluster;Scheduler was sent the command new
02/18/2014 01:31:10;0040;PBS_Server;Svr;tyrone-cluster;Scheduler was sent the command new
02/18/2014 01:31:24;0002;PBS_Server;Svr;PBS_Server;Torque Server Version = 3.0.5, loglevel = 0
02/18/2014 01:31:41;0040;PBS_Server;Svr;tyrone-cluster;Scheduler was sent the command new
02/18/2014 01:32:11;0040;PBS_Server;Svr;tyrone-cluster;Scheduler was sent the command new
02/18/2014 01:32:42;0040;PBS_Server;Svr;tyrone-cluster;Scheduler was sent the command new
02/18/2014 01:33:15;0040;PBS_Server;Svr;tyrone-cluster;Scheduler was sent the command new
02/18/2014 01:33:44;0040;PBS_Server;Svr;tyrone-cluster;Scheduler was sent the command new
02/18/2014 01:34:14;0040;PBS_Server;Svr;tyrone-cluster;Scheduler was sent the command new
02/18/2014 01:34:52;0040;PBS_Server;Svr;tyrone-cluster;Scheduler was sent the command new
02/18/2014 01:35:21;0040;PBS_Server;Svr;tyrone-cluster;Scheduler was sent the command new
02/18/2014 01:35:52;0040;PBS_Server;Svr;tyrone-cluster;Scheduler was sent the command new
02/18/2014 01:36:24;0002;PBS_Server;Svr;PBS_Server;Torque Server Version = 3.0.5, loglevel = 0
02/18/2014 01:36:24;0040;PBS_Server;Svr;tyrone-cluster;Scheduler was sent the command new
02/18/2014 01:36:54;0040;PBS_Server;Svr;tyrone-cluster;Scheduler was sent the command new
02/18/2014 01:37:23;0040;PBS_Server;Svr;tyrone-cluster;Scheduler was sent the command new
02/18/2014 01:37:55;0040;PBS_Server;Svr;tyrone-cluster;Scheduler was sent the command new
02/18/2014 01:38:26;0040;PBS_Server;Svr;tyrone-cluster;Scheduler was sent the command new
02/18/2014 01:38:55;0040;PBS_Server;Svr;tyrone-cluster;Scheduler was sent the command new
02/18/2014 01:39:25;0040;PBS_Server;Svr;tyrone-cluster;Scheduler was sent the command new
02/18/2014 01:39:56;0040;PBS_Server;Svr;tyrone-cluster;Scheduler was sent the command new
02/18/2014 01:40:26;0040;PBS_Server;Svr;tyrone-cluster;Scheduler was sent the command new
02/18/2014 01:40:55;0040;PBS_Server;Svr;tyrone-cluster;Scheduler was sent the command new
02/18/2014 01:41:24;0002;PBS_Server;Svr;PBS_Server;Torque Server Version = 3.0.5, loglevel = 0
02/18/2014 01:41:25;0040;PBS_Server;Svr;tyrone-cluster;Scheduler was sent the command new
02/18/2014 01:41:56;0040;PBS_Server;Svr;tyrone-cluster;Scheduler was sent the command new
02/18/2014 01:42:25;0040;PBS_Server;Svr;tyrone-cluster;Scheduler was sent the command new
02/18/2014 01:42:55;0040;PBS_Server;Svr;tyrone-cluster;Scheduler was sent the command new
02/18/2014 01:43:26;0040;PBS_Server;Svr;tyrone-cluster;Scheduler was sent the command new
02/18/2014 01:43:55;0040;PBS_Server;Svr;tyrone-cluster;Scheduler was sent the command new
02/18/2014 01:44:25;0040;PBS_Server;Svr;tyrone-cluster;Scheduler was sent the command new
02/18/2014 01:44:56;0040;PBS_Server;Svr;tyrone-cluster;Scheduler was sent the command new
02/18/2014 01:45:25;0040;PBS_Server;Svr;tyrone-cluster;Scheduler was sent the command new
02/18/2014 01:45:56;0040;PBS_Server;Svr;tyrone-cluster;Scheduler was sent the command new
02/18/2014 01:46:24;0002;PBS_Server;Svr;PBS_Server;Torque Server Version = 3.0.5, loglevel = 0
02/18/2014 01:46:25;0040;PBS_Server;Svr;tyrone-cluster;Scheduler was sent the command new
02/18/2014 01:46:55;0040;PBS_Server;Svr;tyrone-cluster;Scheduler was sent the command new
02/18/2014 01:47:25;0040;PBS_Server;Svr;tyrone-cluster;Scheduler was sent the command new
02/18/2014 01:47:56;0040;PBS_Server;Svr;tyrone-cluster;Scheduler was sent the command new
02/18/2014 01:48:25;0040;PBS_Server;Svr;tyrone-cluster;Scheduler was sent the command new
02/18/2014 01:48:55;0040;PBS_Server;Svr;tyrone-cluster;Scheduler was sent the command new
02/18/2014 01:49:26;0040;PBS_Server;Svr;tyrone-cluster;Scheduler was sent the command new
02/18/2014 01:49:55;0040;PBS_Server;Svr;tyrone-cluster;Scheduler was sent the command new
02/18/2014 01:50:26;0040;PBS_Server;Svr;tyrone-cluster;Scheduler was sent the command new
02/18/2014 01:50:56;0040;PBS_Server;Svr;tyrone-cluster;Scheduler was sent the command new
02/18/2014 01:51:24;0002;PBS_Server;Svr;PBS_Server;Torque Server Version = 3.0.5, loglevel = 0
02/18/2014 01:51:25;0040;PBS_Server;Svr;tyrone-cluster;Scheduler was sent the command new
02/18/2014 01:51:55;0040;PBS_Server;Svr;tyrone-cluster;Scheduler was sent the command new
02/18/2014 01:52:26;0040;PBS_Server;Svr;tyrone-cluster;Scheduler was sent the command new
02/18/2014 01:52:57;0040;PBS_Server;Svr;tyrone-cluster;Scheduler was sent the command new
02/18/2014 01:53:26;0040;PBS_Server;Svr;tyrone-cluster;Scheduler was sent the command new
02/18/2014 01:53:56;0040;PBS_Server;Svr;tyrone-cluster;Scheduler was sent the command new
02/18/2014 01:54:27;0040;PBS_Server;Svr;tyrone-cluster;Scheduler was sent the command new
02/18/2014 01:54:56;0040;PBS_Server;Svr;tyrone-cluster;Scheduler was sent the command new
02/18/2014 01:55:26;0040;PBS_Server;Svr;tyrone-cluster;Scheduler was sent the command new
02/18/2014 01:55:57;0040;PBS_Server;Svr;tyrone-cluster;Scheduler was sent the command new
02/18/2014 01:56:24;0002;PBS_Server;Svr;PBS_Server;Torque Server Version = 3.0.5, loglevel = 0
02/18/2014 01:56:27;0040;PBS_Server;Svr;tyrone-cluster;Scheduler was sent the command new
02/18/2014 01:56:59;0040;PBS_Server;Svr;tyrone-cluster;Scheduler was sent the command new
02/18/2014 01:57:29;0040;PBS_Server;Svr;tyrone-cluster;Scheduler was sent the command new
02/18/2014 01:58:07;0040;PBS_Server;Svr;tyrone-cluster;Scheduler was sent the command new
02/18/2014 01:58:36;0040;PBS_Server;Svr;tyrone-cluster;Scheduler was sent the command new
02/18/2014 01:59:07;0040;PBS_Server;Svr;tyrone-cluster;Scheduler was sent the command new
02/18/2014 01:59:40;0040;PBS_Server;Svr;tyrone-cluster;Scheduler was sent the command new
02/18/2014 02:00:09;0040;PBS_Server;Svr;tyrone-cluster;Scheduler was sent the command new
02/18/2014 02:00:40;0040;PBS_Server;Svr;tyrone-cluster;Scheduler was sent the command new
02/18/2014 02:01:10;0040;PBS_Server;Svr;tyrone-cluster;Scheduler was sent the command new
02/18/2014 02:01:24;0002;PBS_Server;Svr;PBS_Server;Torque Server Version = 3.0.5, loglevel = 0
02/18/2014 02:01:40;0040;PBS_Server;Svr;tyrone-cluster;Scheduler was sent the command new
02/18/2014 02:02:11;0040;PBS_Server;Svr;tyrone-cluster;Scheduler was sent the command new
02/18/2014 02:02:40;0040;PBS_Server;Svr;tyrone-cluster;Scheduler was sent the command new
02/18/2014 02:03:11;0040;PBS_Server;Svr;tyrone-cluster;Scheduler was sent the command new
02/18/2014 02:03:41;0040;PBS_Server;Svr;tyrone-cluster;Scheduler was sent the command new
02/18/2014 02:04:10;0040;PBS_Server;Svr;tyrone-cluster;Scheduler was sent the command new
02/18/2014 02:04:41;0040;PBS_Server;Svr;tyrone-cluster;Scheduler was sent the command new
02/18/2014 02:05:11;0040;PBS_Server;Svr;tyrone-cluster;Scheduler was sent the command new
02/18/2014 02:05:40;0040;PBS_Server;Svr;tyrone-cluster;Scheduler was sent the command new
02/18/2014 02:06:11;0040;PBS_Server;Svr;tyrone-cluster;Scheduler was sent the command new
02/18/2014 02:06:24;0002;PBS_Server;Svr;PBS_Server;Torque Server Version = 3.0.5, loglevel = 0
02/18/2014 02:06:41;0040;PBS_Server;Svr;tyrone-cluster;Scheduler was sent the command new
02/18/2014 02:07:10;0040;PBS_Server;Svr;tyrone-cluster;Scheduler was sent the command new
02/18/2014 02:07:41;0040;PBS_Server;Svr;tyrone-cluster;Scheduler was sent the command new
02/18/2014 02:08:11;0040;PBS_Server;Svr;tyrone-cluster;Scheduler was sent the command new
02/18/2014 02:08:42;0040;PBS_Server;Svr;tyrone-cluster;Scheduler was sent the command new
02/18/2014 02:09:11;0040;PBS_Server;Svr;tyrone-cluster;Scheduler was sent the command new
02/18/2014 02:09:41;0040;PBS_Server;Svr;tyrone-cluster;Scheduler was sent the command new
02/18/2014 02:10:12;0040;PBS_Server;Svr;tyrone-cluster;Scheduler was sent the command new
02/18/2014 02:10:41;0040;PBS_Server;Svr;tyrone-cluster;Scheduler was sent the command new
02/18/2014 02:10:41;000d;PBS_Server;Job;35079.tyrone-cluster;Not sending email: User does not want mail of this type.
02/18/2014 02:10:41;0002;PBS_Server;Svr;Act;Account file /var/spool/torque/server_priv/accounting/20140218 opened
02/18/2014 02:10:41;0010;PBS_Server;Job;35079.tyrone-cluster;Exit_status=271 resources_used.cput=1534:10:44 resources_used.mem=2589768kb resources_used.vmem=36229828kb resources_used.walltime=24:00:18
02/18/2014 02:10:41;0008;PBS_Server;Job;NULL;on_job_exit valid pjob: 0x1dc4030 (substate=50)
02/18/2014 02:10:41;0008;PBS_Server;Job;NULL;on_job_exit valid pjob: 0x1dc4030 (substate=51)
02/18/2014 02:10:41;0008;PBS_Server;Job;35118.tyrone-cluster;Job Modified at request of Scheduler@tyrone-cluster
02/18/2014 02:10:41;0008;PBS_Server;Job;35059.tyrone-cluster;Job Modified at request of Scheduler@tyrone-cluster
02/18/2014 02:10:41;0008;PBS_Server;Job;35060.tyrone-cluster;Job Modified at request of Scheduler@tyrone-cluster
02/18/2014 02:10:41;0008;PBS_Server;Job;35117.tyrone-cluster;Job Modified at request of Scheduler@tyrone-cluster
02/18/2014 02:10:41;0008;PBS_Server;Job;35145.tyrone-cluster;Job Modified at request of Scheduler@tyrone-cluster
02/18/2014 02:10:58;0008;PBS_Server;Job;NULL;on_job_exit valid pjob: 0x1dc4030 (substate=51)
02/18/2014 02:10:58;0008;PBS_Server;Job;NULL;on_job_exit valid pjob: 0x1dc4030 (substate=53)
02/18/2014 02:10:58;0100;PBS_Server;Job;35079.tyrone-cluster;dequeuing from qp256, state COMPLETE
02/18/2014 02:10:58;0040;PBS_Server;Svr;tyrone-cluster;Scheduler was sent the command term
02/18/2014 02:10:59;0008;PBS_Server;Job;35118.tyrone-cluster;Job Modified at request of Scheduler@tyrone-cluster
02/18/2014 02:10:59;0008;PBS_Server;Job;35118.tyrone-cluster;Job Run at request of Scheduler@tyrone-cluster
02/18/2014 02:10:59;0008;PBS_Server;Job;35059.tyrone-cluster;Job Modified at request of Scheduler@tyrone-cluster
02/18/2014 02:10:59;0008;PBS_Server;Job;35060.tyrone-cluster;Job Modified at request of Scheduler@tyrone-cluster
02/18/2014 02:10:59;0008;PBS_Server;Job;35117.tyrone-cluster;Job Modified at request of Scheduler@tyrone-cluster
02/18/2014 02:10:59;0008;PBS_Server;Job;35145.tyrone-cluster;Job Modified at request of Scheduler@tyrone-cluster
02/18/2014 02:10:59;0040;PBS_Server;Svr;tyrone-cluster;Scheduler was sent the command recyc
02/18/2014 02:11:11;0100;PBS_Server;Job;35140.tyrone-cluster;dequeuing from batch, state QUEUED
02/18/2014 02:11:11;0100;PBS_Server;Job;35140.tyrone-cluster;enqueuing into qp256, state 1 hop 1
02/18/2014 02:11:11;0040;PBS_Server;Svr;tyrone-cluster;Scheduler was sent the command new
02/18/2014 02:11:11;0008;PBS_Server;Job;35140.tyrone-cluster;Job Modified at request of Scheduler@tyrone-cluster
02/18/2014 02:11:24;0002;PBS_Server;Svr;PBS_Server;Torque Server Version = 3.0.5, loglevel = 0
02/18/2014 02:11:35;000d;PBS_Server;Job;35118.tyrone-cluster;Not sending email: User does not want mail of this type.
02/18/2014 02:16:24;0002;PBS_Server;Svr;PBS_Server;Torque Server Version = 3.0.5, loglevel = 0
02/18/2014 02:21:11;0040;PBS_Server;Svr;tyrone-cluster;Scheduler was sent the command time
02/18/2014 02:21:24;0002;PBS_Server;Svr;PBS_Server;Torque Server Version = 3.0.5, loglevel = 0
02/18/2014 02:26:24;0002;PBS_Server;Svr;PBS_Server;Torque Server Version = 3.0.5, loglevel = 0
02/18/2014 02:31:11;0040;PBS_Server;Svr;tyrone-cluster;Scheduler was sent the command time
02/18/2014 02:31:24;0002;PBS_Server;Svr;PBS_Server;Torque Server Version = 3.0.5, loglevel = 0
02/18/2014 02:36:24;0002;PBS_Server;Svr;PBS_Server;Torque Server Version = 3.0.5, loglevel = 0
02/18/2014 02:41:11;0040;PBS_Server;Svr;tyrone-cluster;Scheduler was sent the command time
02/18/2014 02:41:24;0002;PBS_Server;Svr;PBS_Server;Torque Server Version = 3.0.5, loglevel = 0
02/18/2014 02:46:24;0002;PBS_Server;Svr;PBS_Server;Torque Server Version = 3.0.5, loglevel = 0
02/18/2014 02:51:11;0040;PBS_Server;Svr;tyrone-cluster;Scheduler was sent the command time
02/18/2014 02:51:24;0002;PBS_Server;Svr;PBS_Server;Torque Server Version = 3.0.5, loglevel = 0
02/18/2014 02:56:24;0002;PBS_Server;Svr;PBS_Server;Torque Server Version = 3.0.5, loglevel = 0
02/18/2014 03:01:11;0040;PBS_Server;Svr;tyrone-cluster;Scheduler was sent the command time
02/18/2014 03:01:24;0002;PBS_Server;Svr;PBS_Server;Torque Server Version = 3.0.5, loglevel = 0
02/18/2014 03:06:24;0002;PBS_Server;Svr;PBS_Server;Torque Server Version = 3.0.5, loglevel = 0
02/18/2014 03:11:11;0040;PBS_Server;Svr;tyrone-cluster;Scheduler was sent the command time
02/18/2014 03:11:24;0002;PBS_Server;Svr;PBS_Server;Torque Server Version = 3.0.5, loglevel = 0
02/18/2014 03:16:24;0002;PBS_Server;Svr;PBS_Server;Torque Server Version = 3.0.5, loglevel = 0
02/18/2014 03:21:11;0040;PBS_Server;Svr;tyrone-cluster;Scheduler was sent the command time
02/18/2014 03:21:24;0002;PBS_Server;Svr;PBS_Server;Torque Server Version = 3.0.5, loglevel = 0
02/18/2014 03:26:24;0002;PBS_Server;Svr;PBS_Server;Torque Server Version = 3.0.5, loglevel = 0
02/18/2014 03:31:11;0040;PBS_Server;Svr;tyrone-cluster;Scheduler was sent the command time
02/18/2014 03:31:24;0002;PBS_Server;Svr;PBS_Server;Torque Server Version = 3.0.5, loglevel = 0
02/18/2014 03:36:24;0002;PBS_Server;Svr;PBS_Server;Torque Server Version = 3.0.5, loglevel = 0
02/18/2014 03:41:11;0040;PBS_Server;Svr;tyrone-cluster;Scheduler was sent the command time
02/18/2014 03:41:24;0002;PBS_Server;Svr;PBS_Server;Torque Server Version = 3.0.5, loglevel = 0
02/18/2014 03:46:24;0002;PBS_Server;Svr;PBS_Server;Torque Server Version = 3.0.5, loglevel = 0
02/18/2014 03:51:11;0040;PBS_Server;Svr;tyrone-cluster;Scheduler was sent the command time
02/18/2014 03:51:24;0002;PBS_Server;Svr;PBS_Server;Torque Server Version = 3.0.5, loglevel = 0
02/18/2014 03:56:24;0002;PBS_Server;Svr;PBS_Server;Torque Server Version = 3.0.5, loglevel = 0
02/18/2014 04:01:11;0040;PBS_Server;Svr;tyrone-cluster;Scheduler was sent the command time
02/18/2014 04:01:24;0002;PBS_Server;Svr;PBS_Server;Torque Server Version = 3.0.5, loglevel = 0
02/18/2014 04:06:24;0002;PBS_Server;Svr;PBS_Server;Torque Server Version = 3.0.5, loglevel = 0
02/18/2014 04:11:11;0040;PBS_Server;Svr;tyrone-cluster;Scheduler was sent the command time
02/18/2014 04:11:24;0002;PBS_Server;Svr;PBS_Server;Torque Server Version = 3.0.5, loglevel = 0
02/18/2014 04:16:24;0002;PBS_Server;Svr;PBS_Server;Torque Server Version = 3.0.5, loglevel = 0
02/18/2014 04:21:11;0040;PBS_Server;Svr;tyrone-cluster;Scheduler was sent the command time
02/18/2014 04:21:24;0002;PBS_Server;Svr;PBS_Server;Torque Server Version = 3.0.5, loglevel = 0
02/18/2014 04:26:24;0002;PBS_Server;Svr;PBS_Server;Torque Server Version = 3.0.5, loglevel = 0
02/18/2014 04:31:11;0040;PBS_Server;Svr;tyrone-cluster;Scheduler was sent the command time
02/18/2014 04:31:24;0002;PBS_Server;Svr;PBS_Server;Torque Server Version = 3.0.5, loglevel = 0
02/18/2014 04:36:24;0002;PBS_Server;Svr;PBS_Server;Torque Server Version = 3.0.5, loglevel = 0
02/18/2014 04:41:11;0040;PBS_Server;Svr;tyrone-cluster;Scheduler was sent the command time
02/18/2014 04:41:24;0002;PBS_Server;Svr;PBS_Server;Torque Server Version = 3.0.5, loglevel = 0
02/18/2014 04:46:24;0002;PBS_Server;Svr;PBS_Server;Torque Server Version = 3.0.5, loglevel = 0
02/18/2014 04:51:11;0040;PBS_Server;Svr;tyrone-cluster;Scheduler was sent the command time
02/18/2014 04:51:24;0002;PBS_Server;Svr;PBS_Server;Torque Server Version = 3.0.5, loglevel = 0
02/18/2014 04:56:24;0002;PBS_Server;Svr;PBS_Server;Torque Server Version = 3.0.5, loglevel = 0
02/18/2014 05:01:11;0040;PBS_Server;Svr;tyrone-cluster;Scheduler was sent the command time
02/18/2014 05:01:24;0002;PBS_Server;Svr;PBS_Server;Torque Server Version = 3.0.5, loglevel = 0
02/18/2014 05:06:24;0002;PBS_Server;Svr;PBS_Server;Torque Server Version = 3.0.5, loglevel = 0
02/18/2014 05:11:11;0040;PBS_Server;Svr;tyrone-cluster;Scheduler was sent the command time
02/18/2014 05:11:24;0002;PBS_Server;Svr;PBS_Server;Torque Server Version = 3.0.5, loglevel = 0
02/18/2014 05:16:24;0002;PBS_Server;Svr;PBS_Server;Torque Server Version = 3.0.5, loglevel = 0
02/18/2014 05:21:11;0040;PBS_Server;Svr;tyrone-cluster;Scheduler was sent the command time
02/18/2014 05:21:24;0002;PBS_Server;Svr;PBS_Server;Torque Server Version = 3.0.5, loglevel = 0
02/18/2014 05:26:24;0002;PBS_Server;Svr;PBS_Server;Torque Server Version = 3.0.5, loglevel = 0
02/18/2014 05:31:11;0040;PBS_Server;Svr;tyrone-cluster;Scheduler was sent the command time
02/18/2014 05:31:24;0002;PBS_Server;Svr;PBS_Server;Torque Server Version = 3.0.5, loglevel = 0
02/18/2014 05:36:24;0002;PBS_Server;Svr;PBS_Server;Torque Server Version = 3.0.5, loglevel = 0
02/18/2014 05:41:11;0040;PBS_Server;Svr;tyrone-cluster;Scheduler was sent the command time
02/18/2014 05:41:24;0002;PBS_Server;Svr;PBS_Server;Torque Server Version = 3.0.5, loglevel = 0
02/18/2014 05:46:24;0002;PBS_Server;Svr;PBS_Server;Torque Server Version = 3.0.5, loglevel = 0
02/18/2014 05:51:11;0040;PBS_Server;Svr;tyrone-cluster;Scheduler was sent the command time
02/18/2014 05:51:24;0002;PBS_Server;Svr;PBS_Server;Torque Server Version = 3.0.5, loglevel = 0
02/18/2014 05:56:24;0002;PBS_Server;Svr;PBS_Server;Torque Server Version = 3.0.5, loglevel = 0
02/18/2014 06:01:11;0040;PBS_Server;Svr;tyrone-cluster;Scheduler was sent the command time
02/18/2014 06:01:24;0002;PBS_Server;Svr;PBS_Server;Torque Server Version = 3.0.5, loglevel = 0
02/18/2014 06:06:24;0002;PBS_Server;Svr;PBS_Server;Torque Server Version = 3.0.5, loglevel = 0
02/18/2014 06:11:11;0040;PBS_Server;Svr;tyrone-cluster;Scheduler was sent the command time
02/18/2014 06:11:24;0002;PBS_Server;Svr;PBS_Server;Torque Server Version = 3.0.5, loglevel = 0
02/18/2014 06:16:24;0002;PBS_Server;Svr;PBS_Server;Torque Server Version = 3.0.5, loglevel = 0
02/18/2014 06:21:11;0040;PBS_Server;Svr;tyrone-cluster;Scheduler was sent the command time
02/18/2014 06:21:24;0002;PBS_Server;Svr;PBS_Server;Torque Server Version = 3.0.5, loglevel = 0
02/18/2014 06:26:24;0002;PBS_Server;Svr;PBS_Server;Torque Server Version = 3.0.5, loglevel = 0
02/18/2014 06:31:11;0040;PBS_Server;Svr;tyrone-cluster;Scheduler was sent the command time
02/18/2014 06:31:24;0002;PBS_Server;Svr;PBS_Server;Torque Server Version = 3.0.5, loglevel = 0
02/18/2014 06:36:24;0002;PBS_Server;Svr;PBS_Server;Torque Server Version = 3.0.5, loglevel = 0
02/18/2014 06:41:11;0040;PBS_Server;Svr;tyrone-cluster;Scheduler was sent the command time
02/18/2014 06:41:24;0002;PBS_Server;Svr;PBS_Server;Torque Server Version = 3.0.5, loglevel = 0
02/18/2014 06:46:24;0002;PBS_Server;Svr;PBS_Server;Torque Server Version = 3.0.5, loglevel = 0
02/18/2014 06:51:11;0040;PBS_Server;Svr;tyrone-cluster;Scheduler was sent the command time
02/18/2014 06:51:24;0002;PBS_Server;Svr;PBS_Server;Torque Server Version = 3.0.5, loglevel = 0
02/18/2014 06:56:24;0002;PBS_Server;Svr;PBS_Server;Torque Server Version = 3.0.5, loglevel = 0
02/18/2014 07:01:11;0040;PBS_Server;Svr;tyrone-cluster;Scheduler was sent the command time
02/18/2014 07:01:24;0002;PBS_Server;Svr;PBS_Server;Torque Server Version = 3.0.5, loglevel = 0
02/18/2014 07:06:24;0002;PBS_Server;Svr;PBS_Server;Torque Server Version = 3.0.5, loglevel = 0
02/18/2014 07:11:11;0040;PBS_Server;Svr;tyrone-cluster;Scheduler was sent the command time
02/18/2014 07:11:24;0002;PBS_Server;Svr;PBS_Server;Torque Server Version = 3.0.5, loglevel = 0
02/18/2014 07:13:59;000d;PBS_Server;Job;35189.tyrone-cluster;Not sending email: User does not want mail of this type.
02/18/2014 07:13:59;0010;PBS_Server;Job;35189.tyrone-cluster;Exit_status=0 resources_used.cput=313:45:38 resources_used.mem=1718520kb resources_used.vmem=5314964kb resources_used.walltime=09:49:04
02/18/2014 07:13:59;0008;PBS_Server;Job;NULL;on_job_exit valid pjob: 0x1da08a0 (substate=50)
02/18/2014 07:13:59;0008;PBS_Server;Job;NULL;on_job_exit valid pjob: 0x1da08a0 (substate=51)
02/18/2014 07:13:59;0008;PBS_Server;Job;NULL;on_job_exit valid pjob: 0x1da08a0 (substate=51)
02/18/2014 07:13:59;0008;PBS_Server;Job;NULL;on_job_exit valid pjob: 0x1da08a0 (substate=53)
02/18/2014 07:13:59;0100;PBS_Server;Job;35189.tyrone-cluster;dequeuing from qp32, state COMPLETE
02/18/2014 07:13:59;0040;PBS_Server;Svr;tyrone-cluster;Scheduler was sent the command term
02/18/2014 07:13:59;0008;PBS_Server;Job;35190.tyrone-cluster;Job Modified at request of Scheduler@tyrone-cluster
02/18/2014 07:13:59;0008;PBS_Server;Job;35190.tyrone-cluster;Job Run at request of Scheduler@tyrone-cluster
02/18/2014 07:13:59;0040;PBS_Server;Svr;tyrone-cluster;Scheduler was sent the command recyc
02/18/2014 07:13:59;000d;PBS_Server;Job;35190.tyrone-cluster;Not sending email: User does not want mail of this type.
02/18/2014 07:16:24;0002;PBS_Server;Svr;PBS_Server;Torque Server Version = 3.0.5, loglevel = 0
02/18/2014 07:21:24;0002;PBS_Server;Svr;PBS_Server;Torque Server Version = 3.0.5, loglevel = 0
02/18/2014 07:23:59;0040;PBS_Server;Svr;tyrone-cluster;Scheduler was sent the command time
02/18/2014 07:26:24;0002;PBS_Server;Svr;PBS_Server;Torque Server Version = 3.0.5, loglevel = 0
02/18/2014 07:31:24;0002;PBS_Server;Svr;PBS_Server;Torque Server Version = 3.0.5, loglevel = 0
02/18/2014 07:33:59;0040;PBS_Server;Svr;tyrone-cluster;Scheduler was sent the command time
02/18/2014 07:36:24;0002;PBS_Server;Svr;PBS_Server;Torque Server Version = 3.0.5, loglevel = 0
02/18/2014 07:41:24;0002;PBS_Server;Svr;PBS_Server;Torque Server Version = 3.0.5, loglevel = 0
02/18/2014 07:43:59;0040;PBS_Server;Svr;tyrone-cluster;Scheduler was sent the command time
02/18/2014 07:46:24;0002;PBS_Server;Svr;PBS_Server;Torque Server Version = 3.0.5, loglevel = 0
02/18/2014 07:51:24;0002;PBS_Server;Svr;PBS_Server;Torque Server Version = 3.0.5, loglevel = 0
02/18/2014 07:53:59;0040;PBS_Server;Svr;tyrone-cluster;Scheduler was sent the command time
02/18/2014 07:56:24;0002;PBS_Server;Svr;PBS_Server;Torque Server Version = 3.0.5, loglevel = 0
02/18/2014 08:01:24;0002;PBS_Server;Svr;PBS_Server;Torque Server Version = 3.0.5, loglevel = 0
02/18/2014 08:03:59;0040;PBS_Server;Svr;tyrone-cluster;Scheduler was sent the command time
02/18/2014 08:06:24;0002;PBS_Server;Svr;PBS_Server;Torque Server Version = 3.0.5, loglevel = 0
02/18/2014 08:11:24;0002;PBS_Server;Svr;PBS_Server;Torque Server Version = 3.0.5, loglevel = 0
02/18/2014 08:13:59;0040;PBS_Server;Svr;tyrone-cluster;Scheduler was sent the command time
02/18/2014 08:16:24;0002;PBS_Server;Svr;PBS_Server;Torque Server Version = 3.0.5, loglevel = 0
02/18/2014 08:21:24;0002;PBS_Server;Svr;PBS_Server;Torque Server Version = 3.0.5, loglevel = 0
02/18/2014 08:23:59;0040;PBS_Server;Svr;tyrone-cluster;Scheduler was sent the command time
02/18/2014 08:26:24;0002;PBS_Server;Svr;PBS_Server;Torque Server Version = 3.0.5, loglevel = 0
02/18/2014 08:31:24;0002;PBS_Server;Svr;PBS_Server;Torque Server Version = 3.0.5, loglevel = 0
02/18/2014 08:33:59;0040;PBS_Server;Svr;tyrone-cluster;Scheduler was sent the command time
02/18/2014 08:36:24;0002;PBS_Server;Svr;PBS_Server;Torque Server Version = 3.0.5, loglevel = 0
02/18/2014 08:41:24;0002;PBS_Server;Svr;PBS_Server;Torque Server Version = 3.0.5, loglevel = 0
02/18/2014 08:43:59;0040;PBS_Server;Svr;tyrone-cluster;Scheduler was sent the command time
02/18/2014 08:46:24;0002;PBS_Server;Svr;PBS_Server;Torque Server Version = 3.0.5, loglevel = 0
02/18/2014 08:47:28;0100;PBS_Server;Job;35193.tyrone-cluster;enqueuing into batch, state 1 hop 1
02/18/2014 08:47:28;0100;PBS_Server;Job;35193.tyrone-cluster;dequeuing from batch, state QUEUED
02/18/2014 08:47:28;0100;PBS_Server;Job;35193.tyrone-cluster;enqueuing into qp32, state 1 hop 1
02/18/2014 08:47:28;0008;PBS_Server;Job;35193.tyrone-cluster;Job Queued at request of asealama@tyrone-cluster, owner = asealama@tyrone-cluster, job name = jobname, queue = qp32
02/18/2014 08:47:28;0040;PBS_Server;Svr;tyrone-cluster;Scheduler was sent the command new
02/18/2014 08:47:28;0008;PBS_Server;Job;35193.tyrone-cluster;Job Modified at request of Scheduler@tyrone-cluster
02/18/2014 08:51:24;0002;PBS_Server;Svr;PBS_Server;Torque Server Version = 3.0.5, loglevel = 0
02/18/2014 08:56:24;0002;PBS_Server;Svr;PBS_Server;Torque Server Version = 3.0.5, loglevel = 0
02/18/2014 08:57:28;0040;PBS_Server;Svr;tyrone-cluster;Scheduler was sent the command time
02/18/2014 09:01:24;0002;PBS_Server;Svr;PBS_Server;Torque Server Version = 3.0.5, loglevel = 0
02/18/2014 09:06:24;0002;PBS_Server;Svr;PBS_Server;Torque Server Version = 3.0.5, loglevel = 0
02/18/2014 09:07:28;0040;PBS_Server;Svr;tyrone-cluster;Scheduler was sent the command time
02/18/2014 09:10:05;0100;PBS_Server;Job;35194.tyrone-cluster;enqueuing into batch, state 1 hop 1
02/18/2014 09:10:05;0100;PBS_Server;Job;35194.tyrone-cluster;dequeuing from batch, state QUEUED
02/18/2014 09:10:05;0100;PBS_Server;Job;35194.tyrone-cluster;enqueuing into idqueue, state 1 hop 1
02/18/2014 09:10:05;0008;PBS_Server;Job;35194.tyrone-cluster;Job Queued at request of metsomya@tyrone-cluster, owner = metsomya@tyrone-cluster, job name = poshit1, queue = idqueue
02/18/2014 09:10:05;0040;PBS_Server;Svr;tyrone-cluster;Scheduler was sent the command new
02/18/2014 09:10:05;0008;PBS_Server;Job;35194.tyrone-cluster;Job Modified at request of Scheduler@tyrone-cluster
02/18/2014 09:10:05;0008;PBS_Server;Job;35194.tyrone-cluster;Job Run at request of Scheduler@tyrone-cluster
02/18/2014 09:10:05;0040;PBS_Server;Svr;tyrone-cluster;Scheduler was sent the command recyc
02/18/2014 09:10:05;000d;PBS_Server;Job;35194.tyrone-cluster;Not sending email: User does not want mail of this type.
02/18/2014 09:10:10;000d;PBS_Server;Job;35194.tyrone-cluster;Not sending email: User does not want mail of this type.
02/18/2014 09:10:10;0010;PBS_Server;Job;35194.tyrone-cluster;Exit_status=0 resources_used.cput=00:01:46 resources_used.mem=0kb resources_used.vmem=0kb resources_used.walltime=00:00:05
02/18/2014 09:10:10;0008;PBS_Server;Job;NULL;on_job_exit valid pjob: 0x1e14a70 (substate=50)
02/18/2014 09:10:10;0008;PBS_Server;Job;NULL;on_job_exit valid pjob: 0x1e14a70 (substate=51)
02/18/2014 09:10:10;0008;PBS_Server;Job;NULL;on_job_exit valid pjob: 0x1e14a70 (substate=51)
02/18/2014 09:10:10;0008;PBS_Server;Job;NULL;on_job_exit valid pjob: 0x1e14a70 (substate=53)
02/18/2014 09:10:10;0100;PBS_Server;Job;35194.tyrone-cluster;dequeuing from idqueue, state COMPLETE
02/18/2014 09:10:10;0040;PBS_Server;Svr;tyrone-cluster;Scheduler was sent the command term
02/18/2014 09:11:24;0002;PBS_Server;Svr;PBS_Server;Torque Server Version = 3.0.5, loglevel = 0
02/18/2014 09:13:57;0100;PBS_Server;Job;35195.tyrone-cluster;enqueuing into batch, state 1 hop 1
02/18/2014 09:13:57;0100;PBS_Server;Job;35195.tyrone-cluster;dequeuing from batch, state QUEUED
02/18/2014 09:13:57;0100;PBS_Server;Job;35195.tyrone-cluster;enqueuing into idqueue, state 1 hop 1
02/18/2014 09:13:57;0008;PBS_Server;Job;35195.tyrone-cluster;Job Queued at request of metsomya@tyrone-cluster, owner = metsomya@tyrone-cluster, job name = poshit1, queue = idqueue
02/18/2014 09:13:57;0040;PBS_Server;Svr;tyrone-cluster;Scheduler was sent the command new
02/18/2014 09:13:57;0008;PBS_Server;Job;35195.tyrone-cluster;Job Modified at request of Scheduler@tyrone-cluster
02/18/2014 09:13:57;0008;PBS_Server;Job;35195.tyrone-cluster;Job Run at request of Scheduler@tyrone-cluster
02/18/2014 09:13:57;0040;PBS_Server;Svr;tyrone-cluster;Scheduler was sent the command recyc
02/18/2014 09:13:57;000d;PBS_Server;Job;35195.tyrone-cluster;Not sending email: User does not want mail of this type.
02/18/2014 09:14:03;000d;PBS_Server;Job;35195.tyrone-cluster;Not sending email: User does not want mail of this type.
02/18/2014 09:14:03;0010;PBS_Server;Job;35195.tyrone-cluster;Exit_status=0 resources_used.cput=00:02:29 resources_used.mem=0kb resources_used.vmem=0kb resources_used.walltime=00:00:06
02/18/2014 09:14:03;0008;PBS_Server;Job;NULL;on_job_exit valid pjob: 0x1e14a70 (substate=50)
02/18/2014 09:14:03;0008;PBS_Server;Job;NULL;on_job_exit valid pjob: 0x1e14a70 (substate=51)
02/18/2014 09:14:03;0008;PBS_Server;Job;NULL;on_job_exit valid pjob: 0x1e14a70 (substate=51)
02/18/2014 09:14:03;0008;PBS_Server;Job;NULL;on_job_exit valid pjob: 0x1e14a70 (substate=53)
02/18/2014 09:14:03;0100;PBS_Server;Job;35195.tyrone-cluster;dequeuing from idqueue, state COMPLETE
02/18/2014 09:14:03;0040;PBS_Server;Svr;tyrone-cluster;Scheduler was sent the command term
02/18/2014 09:16:24;0002;PBS_Server;Svr;PBS_Server;Torque Server Version = 3.0.5, loglevel = 0
02/18/2014 09:21:24;0002;PBS_Server;Svr;PBS_Server;Torque Server Version = 3.0.5, loglevel = 0
02/18/2014 09:24:03;0040;PBS_Server;Svr;tyrone-cluster;Scheduler was sent the command time
02/18/2014 09:26:24;0002;PBS_Server;Svr;PBS_Server;Torque Server Version = 3.0.5, loglevel = 0
02/18/2014 09:31:24;0002;PBS_Server;Svr;PBS_Server;Torque Server Version = 3.0.5, loglevel = 0
02/18/2014 09:34:03;0040;PBS_Server;Svr;tyrone-cluster;Scheduler was sent the command time
02/18/2014 09:36:24;0002;PBS_Server;Svr;PBS_Server;Torque Server Version = 3.0.5, loglevel = 0
02/18/2014 09:41:24;0002;PBS_Server;Svr;PBS_Server;Torque Server Version = 3.0.5, loglevel = 0
02/18/2014 09:44:03;0040;PBS_Server;Svr;tyrone-cluster;Scheduler was sent the command time
02/18/2014 09:45:29;0100;PBS_Server;Job;35196.tyrone-cluster;enqueuing into batch, state 1 hop 1
02/18/2014 09:45:29;0100;PBS_Server;Job;35196.tyrone-cluster;dequeuing from batch, state QUEUED
02/18/2014 09:45:29;0100;PBS_Server;Job;35196.tyrone-cluster;enqueuing into qp32, state 1 hop 1
02/18/2014 09:45:29;0008;PBS_Server;Job;35196.tyrone-cluster;Job Queued at request of ipcnwrit@tyrone-cluster, owner = ipcnwrit@tyrone-cluster, job name = tyrn.sh, queue = qp32
02/18/2014 09:45:29;0040;PBS_Server;Svr;tyrone-cluster;Scheduler was sent the command new
02/18/2014 09:45:29;0008;PBS_Server;Job;35196.tyrone-cluster;Job Modified at request of Scheduler@tyrone-cluster
02/18/2014 09:45:29;0008;PBS_Server;Job;35196.tyrone-cluster;Job Run at request of Scheduler@tyrone-cluster
02/18/2014 09:45:29;0040;PBS_Server;Svr;tyrone-cluster;Scheduler was sent the command recyc
02/18/2014 09:45:29;000d;PBS_Server;Job;35196.tyrone-cluster;Not sending email: User does not want mail of this type.
02/18/2014 09:45:30;000d;PBS_Server;Job;35196.tyrone-cluster;Not sending email: User does not want mail of this type.
02/18/2014 09:45:30;0010;PBS_Server;Job;35196.tyrone-cluster;Exit_status=0 resources_used.cput=00:00:00 resources_used.mem=0kb resources_used.vmem=0kb resources_used.walltime=00:00:01
02/18/2014 09:45:30;0008;PBS_Server;Job;NULL;on_job_exit valid pjob: 0x1e02e70 (substate=50)
02/18/2014 09:45:30;0008;PBS_Server;Job;NULL;on_job_exit valid pjob: 0x1e02e70 (substate=51)
02/18/2014 09:45:30;0008;PBS_Server;Job;NULL;on_job_exit valid pjob: 0x1e02e70 (substate=51)
02/18/2014 09:45:30;0008;PBS_Server;Job;NULL;on_job_exit valid pjob: 0x1e02e70 (substate=53)
02/18/2014 09:45:30;0100;PBS_Server;Job;35196.tyrone-cluster;dequeuing from qp32, state COMPLETE
02/18/2014 09:45:30;0040;PBS_Server;Svr;tyrone-cluster;Scheduler was sent the command term
02/18/2014 09:45:43;0100;PBS_Server;Job;35197.tyrone-cluster;enqueuing into batch, state 1 hop 1
02/18/2014 09:45:43;0100;PBS_Server;Job;35197.tyrone-cluster;dequeuing from batch, state QUEUED
02/18/2014 09:45:43;0100;PBS_Server;Job;35197.tyrone-cluster;enqueuing into idqueue, state 1 hop 1
02/18/2014 09:45:43;0008;PBS_Server;Job;35197.tyrone-cluster;Job Queued at request of metsomya@tyrone-cluster, owner = metsomya@tyrone-cluster, job name = poshit1, queue = idqueue
02/18/2014 09:45:43;0040;PBS_Server;Svr;tyrone-cluster;Scheduler was sent the command new
02/18/2014 09:45:43;0008;PBS_Server;Job;35197.tyrone-cluster;Job Modified at request of Scheduler@tyrone-cluster
02/18/2014 09:45:43;0008;PBS_Server;Job;35197.tyrone-cluster;Job Run at request of Scheduler@tyrone-cluster
02/18/2014 09:45:43;0040;PBS_Server;Svr;tyrone-cluster;Scheduler was sent the command recyc
02/18/2014 09:45:43;000d;PBS_Server;Job;35197.tyrone-cluster;Not sending email: User does not want mail of this type.
02/18/2014 09:46:01;000d;PBS_Server;Job;35197.tyrone-cluster;Not sending email: User does not want mail of this type.
02/18/2014 09:46:01;0010;PBS_Server;Job;35197.tyrone-cluster;Exit_status=0 resources_used.cput=00:08:48 resources_used.mem=345208kb resources_used.vmem=8473076kb resources_used.walltime=00:00:18
02/18/2014 09:46:01;0008;PBS_Server;Job;NULL;on_job_exit valid pjob: 0x1e14a70 (substate=50)
02/18/2014 09:46:01;0008;PBS_Server;Job;NULL;on_job_exit valid pjob: 0x1e14a70 (substate=51)
02/18/2014 09:46:01;0008;PBS_Server;Job;NULL;on_job_exit valid pjob: 0x1e14a70 (substate=51)
02/18/2014 09:46:01;0008;PBS_Server;Job;NULL;on_job_exit valid pjob: 0x1e14a70 (substate=53)
02/18/2014 09:46:01;0100;PBS_Server;Job;35197.tyrone-cluster;dequeuing from idqueue, state COMPLETE
02/18/2014 09:46:01;0040;PBS_Server;Svr;tyrone-cluster;Scheduler was sent the command term
02/18/2014 09:46:06;0100;PBS_Server;Job;35198.tyrone-cluster;enqueuing into batch, state 1 hop 1
02/18/2014 09:46:06;0100;PBS_Server;Job;35198.tyrone-cluster;dequeuing from batch, state QUEUED
02/18/2014 09:46:06;0100;PBS_Server;Job;35198.tyrone-cluster;enqueuing into idqueue, state 1 hop 1
02/18/2014 09:46:06;0008;PBS_Server;Job;35198.tyrone-cluster;Job Queued at request of metsomya@tyrone-cluster, owner = metsomya@tyrone-cluster, job name = poshit1, queue = idqueue
02/18/2014 09:46:06;0040;PBS_Server;Svr;tyrone-cluster;Scheduler was sent the command new
02/18/2014 09:46:06;0008;PBS_Server;Job;35198.tyrone-cluster;Job Modified at request of Scheduler@tyrone-cluster
02/18/2014 09:46:06;0008;PBS_Server;Job;35198.tyrone-cluster;Job Run at request of Scheduler@tyrone-cluster
02/18/2014 09:46:06;0040;PBS_Server;Svr;tyrone-cluster;Scheduler was sent the command recyc
02/18/2014 09:46:06;000d;PBS_Server;Job;35198.tyrone-cluster;Not sending email: User does not want mail of this type.
02/18/2014 09:46:22;000d;PBS_Server;Job;35198.tyrone-cluster;Not sending email: User does not want mail of this type.
02/18/2014 09:46:22;0010;PBS_Server;Job;35198.tyrone-cluster;Exit_status=0 resources_used.cput=00:08:01 resources_used.mem=0kb resources_used.vmem=0kb resources_used.walltime=00:00:16
02/18/2014 09:46:22;0008;PBS_Server;Job;NULL;on_job_exit valid pjob: 0x1e14a70 (substate=50)
02/18/2014 09:46:22;0008;PBS_Server;Job;NULL;on_job_exit valid pjob: 0x1e14a70 (substate=51)
02/18/2014 09:46:22;0008;PBS_Server;Job;NULL;on_job_exit valid pjob: 0x1e14a70 (substate=51)
02/18/2014 09:46:22;0008;PBS_Server;Job;NULL;on_job_exit valid pjob: 0x1e14a70 (substate=53)
02/18/2014 09:46:22;0100;PBS_Server;Job;35198.tyrone-cluster;dequeuing from idqueue, state COMPLETE
02/18/2014 09:46:22;0040;PBS_Server;Svr;tyrone-cluster;Scheduler was sent the command term
02/18/2014 09:46:24;0002;PBS_Server;Svr;PBS_Server;Torque Server Version = 3.0.5, loglevel = 0
02/18/2014 09:46:42;0100;PBS_Server;Job;35199.tyrone-cluster;enqueuing into batch, state 1 hop 1
02/18/2014 09:46:42;0100;PBS_Server;Job;35199.tyrone-cluster;dequeuing from batch, state QUEUED
02/18/2014 09:46:42;0100;PBS_Server;Job;35199.tyrone-cluster;enqueuing into qp32, state 1 hop 1
02/18/2014 09:46:42;0008;PBS_Server;Job;35199.tyrone-cluster;Job Queued at request of ipcnwrit@tyrone-cluster, owner = ipcnwrit@tyrone-cluster, job name = tyrn.sh, queue = qp32
02/18/2014 09:46:42;0040;PBS_Server;Svr;tyrone-cluster;Scheduler was sent the command new
02/18/2014 09:46:42;0008;PBS_Server;Job;35199.tyrone-cluster;Job Modified at request of Scheduler@tyrone-cluster
02/18/2014 09:46:42;0008;PBS_Server;Job;35199.tyrone-cluster;Job Run at request of Scheduler@tyrone-cluster
02/18/2014 09:46:42;0040;PBS_Server;Svr;tyrone-cluster;Scheduler was sent the command recyc
02/18/2014 09:46:42;000d;PBS_Server;Job;35199.tyrone-cluster;Not sending email: User does not want mail of this type.
02/18/2014 09:47:22;000d;PBS_Server;Job;35199.tyrone-cluster;Not sending email: User does not want mail of this type.
02/18/2014 09:47:22;0010;PBS_Server;Job;35199.tyrone-cluster;Exit_status=0 resources_used.cput=00:00:05 resources_used.mem=17252kb resources_used.vmem=2051504kb resources_used.walltime=00:00:40
02/18/2014 09:47:22;0008;PBS_Server;Job;NULL;on_job_exit valid pjob: 0x1e02e70 (substate=50)
02/18/2014 09:47:22;0008;PBS_Server;Job;NULL;on_job_exit valid pjob: 0x1e02e70 (substate=51)
02/18/2014 09:47:22;0008;PBS_Server;Job;NULL;on_job_exit valid pjob: 0x1e02e70 (substate=51)
02/18/2014 09:47:22;0008;PBS_Server;Job;NULL;on_job_exit valid pjob: 0x1e02e70 (substate=53)
02/18/2014 09:47:22;0100;PBS_Server;Job;35199.tyrone-cluster;dequeuing from qp32, state COMPLETE
02/18/2014 09:47:22;0040;PBS_Server;Svr;tyrone-cluster;Scheduler was sent the command term
02/18/2014 09:51:24;0002;PBS_Server;Svr;PBS_Server;Torque Server Version = 3.0.5, loglevel = 0
02/18/2014 09:52:57;000d;PBS_Server;Job;35142.tyrone-cluster;Not sending email: User does not want mail of this type.
02/18/2014 09:52:57;0010;PBS_Server;Job;35142.tyrone-cluster;Exit_status=143 resources_used.cput=1514:55:15 resources_used.mem=1371980kb resources_used.vmem=34640592kb resources_used.walltime=24:00:31
02/18/2014 09:52:57;0008;PBS_Server;Job;NULL;on_job_exit valid pjob: 0x1dc01e0 (substate=50)
02/18/2014 09:52:57;0008;PBS_Server;Job;NULL;on_job_exit valid pjob: 0x1dc01e0 (substate=51)
02/18/2014 09:53:06;0008;PBS_Server;Job;NULL;on_job_exit valid pjob: 0x1dc01e0 (substate=51)
02/18/2014 09:53:06;000d;PBS_Server;Job;35142.tyrone-cluster;Post job file processing error; job 35142.tyrone-cluster on host tyrone-node14/63+tyrone-node14/62+tyrone-node14/61+tyrone-node14/60+tyrone-node14/59+tyrone-node14/58+tyrone-node14/57+tyrone-node14/56+tyrone-node14/55+tyrone-node14/54+tyrone-node14/53+tyrone-node14/52+tyrone-node14/51+tyrone-node14/50+tyrone-node14/49+tyrone-node14/48+tyrone-node14/47+tyrone-node14/46+tyrone-node14/45+tyrone-node14/44+tyrone-node14/43+tyrone-node14/42+tyrone-node14/41+tyrone-node14/40+tyrone-node14/39+tyrone-node14/38+tyrone-node14/37+tyrone-node14/36+tyrone-node14/35+tyrone-node14/34+tyrone-node14/33+tyrone-node14/32+tyrone-node14/31+tyrone-node14/30+tyrone-node14/29+tyrone-node14/28+tyrone-node14/27+tyrone-node14/26+tyrone-node14/25+tyrone-node14/24+tyrone-node14/23+tyrone-node14/22+tyrone-node14/21+tyrone-node14/20+tyrone-node14/19+tyrone-node14/18+tyrone-node14/17+tyrone-node14/16+tyrone-node14/15+tyrone-node14/14+tyrone-node14/13+tyrone-node14/12+tyrone-node14/11+tyrone-node14/10+tyrone-node14/9+tyrone-node14/8+tyrone-node14/7+tyrone-node14/6+tyrone-node14/5+tyrone-node14/4+tyrone-node14/3+tyrone-node14/2+tyrone-node14/1+tyrone-node14/0
02/18/2014 09:53:06;0008;PBS_Server;Job;NULL;on_job_exit valid pjob: 0x1dc01e0 (substate=53)
02/18/2014 09:53:06;0100;PBS_Server;Job;35142.tyrone-cluster;dequeuing from qp64, state COMPLETE
02/18/2014 09:53:06;0040;PBS_Server;Svr;tyrone-cluster;Scheduler was sent the command term
02/18/2014 09:53:06;0008;PBS_Server;Job;35134.tyrone-cluster;Job Modified at request of Scheduler@tyrone-cluster
02/18/2014 09:53:06;0008;PBS_Server;Job;35151.tyrone-cluster;Job Modified at request of Scheduler@tyrone-cluster
02/18/2014 09:53:06;0008;PBS_Server;Job;35151.tyrone-cluster;Job Run at request of Scheduler@tyrone-cluster
02/18/2014 09:53:06;0040;PBS_Server;Svr;tyrone-cluster;Scheduler was sent the command recyc
02/18/2014 09:53:06;000d;PBS_Server;Job;35151.tyrone-cluster;Not sending email: User does not want mail of this type.
02/18/2014 09:54:26;0100;PBS_Server;Job;35200.tyrone-cluster;enqueuing into batch, state 1 hop 1
02/18/2014 09:54:26;0100;PBS_Server;Job;35200.tyrone-cluster;dequeuing from batch, state QUEUED
02/18/2014 09:54:26;0100;PBS_Server;Job;35200.tyrone-cluster;enqueuing into qp64, state 1 hop 1
02/18/2014 09:54:26;0008;PBS_Server;Job;35200.tyrone-cluster;Job Queued at request of seckavya@tyrone-node9, owner = seckavya@tyrone-node9, job name = Ms1-A-C1, queue = qp64
02/18/2014 09:54:26;0040;PBS_Server;Svr;tyrone-cluster;Scheduler was sent the command new
02/18/2014 09:54:26;0008;PBS_Server;Job;35134.tyrone-cluster;Job Modified at request of Scheduler@tyrone-cluster
02/18/2014 09:54:26;0008;PBS_Server;Job;35200.tyrone-cluster;Job Modified at request of Scheduler@tyrone-cluster
02/18/2014 09:56:24;0002;PBS_Server;Svr;PBS_Server;Torque Server Version = 3.0.5, loglevel = 0
02/18/2014 09:57:06;0100;PBS_Server;Job;35201.tyrone-cluster;enqueuing into batch, state 1 hop 1
02/18/2014 09:57:06;0100;PBS_Server;Job;35201.tyrone-cluster;dequeuing from batch, state QUEUED
02/18/2014 09:57:06;0100;PBS_Server;Job;35201.tyrone-cluster;enqueuing into qp64, state 1 hop 1
02/18/2014 09:57:06;0008;PBS_Server;Job;35201.tyrone-cluster;Job Queued at request of seckavya@tyrone-node9, owner = seckavya@tyrone-node9, job name = Ms1-A-C2, queue = qp64
02/18/2014 09:57:06;0040;PBS_Server;Svr;tyrone-cluster;Scheduler was sent the command new
02/18/2014 09:57:06;0008;PBS_Server;Job;35201.tyrone-cluster;Job Modified at request of Scheduler@tyrone-cluster
02/18/2014 09:58:43;0100;PBS_Server;Job;35202.tyrone-cluster;enqueuing into batch, state 1 hop 1
02/18/2014 09:58:43;0100;PBS_Server;Job;35202.tyrone-cluster;dequeuing from batch, state QUEUED
02/18/2014 09:58:43;0100;PBS_Server;Job;35202.tyrone-cluster;enqueuing into qp64, state 1 hop 1
02/18/2014 09:58:43;0008;PBS_Server;Job;35202.tyrone-cluster;Job Queued at request of seckavya@tyrone-node9, owner = seckavya@tyrone-node9, job name = Ms1-A-C3, queue = qp64
02/18/2014 09:58:43;0040;PBS_Server;Svr;tyrone-cluster;Scheduler was sent the command new
02/18/2014 09:58:43;0008;PBS_Server;Job;35202.tyrone-cluster;Job Modified at request of Scheduler@tyrone-cluster
02/18/2014 09:59:47;0100;PBS_Server;Job;35203.tyrone-cluster;enqueuing into batch, state 1 hop 1
02/18/2014 09:59:49;0008;PBS_Server;Job;35203.tyrone-cluster;Job Queued at request of seckavya@tyrone-node9, owner = seckavya@tyrone-node9, job name = Ms1-A-C4, queue = batch
02/18/2014 09:59:49;0040;PBS_Server;Svr;tyrone-cluster;Scheduler was sent the command new
02/18/2014 09:59:50;0008;PBS_Server;Job;35203.tyrone-cluster;Job Modified at request of Scheduler@tyrone-cluster
02/18/2014 10:00:23;0040;PBS_Server;Svr;tyrone-cluster;Scheduler was sent the command new
02/18/2014 10:00:50;0040;PBS_Server;Svr;tyrone-cluster;Scheduler was sent the command new
02/18/2014 10:01:19;0040;PBS_Server;Svr;tyrone-cluster;Scheduler was sent the command new
02/18/2014 10:01:24;0002;PBS_Server;Svr;PBS_Server;Torque Server Version = 3.0.5, loglevel = 0
02/18/2014 10:01:53;0040;PBS_Server;Svr;tyrone-cluster;Scheduler was sent the command new
02/18/2014 10:02:25;0040;PBS_Server;Svr;tyrone-cluster;Scheduler was sent the command new
02/18/2014 10:02:35;0100;PBS_Server;Job;35204.tyrone-cluster;enqueuing into batch, state 1 hop 1
02/18/2014 10:02:35;0008;PBS_Server;Job;35204.tyrone-cluster;Job Queued at request of seckavya@tyrone-node9, owner = seckavya@tyrone-node9, job name = Ms1-A-C5, queue = batch
02/18/2014 10:02:35;0040;PBS_Server;Svr;tyrone-cluster;Scheduler was sent the command new
02/18/2014 10:02:35;0008;PBS_Server;Job;35204.tyrone-cluster;Job Modified at request of Scheduler@tyrone-cluster
02/18/2014 10:02:57;0040;PBS_Server;Svr;tyrone-cluster;Scheduler was sent the command new
02/18/2014 10:03:10;0040;PBS_Server;Svr;tyrone-cluster;Scheduler was sent the command new
02/18/2014 10:03:26;0040;PBS_Server;Svr;tyrone-cluster;Scheduler was sent the command new
02/18/2014 10:03:36;0040;PBS_Server;Svr;tyrone-cluster;Scheduler was sent the command new
02/18/2014 10:03:59;0040;PBS_Server;Svr;tyrone-cluster;Scheduler was sent the command new
02/18/2014 10:04:08;0040;PBS_Server;Svr;tyrone-cluster;Scheduler was sent the command new
02/18/2014 10:04:26;0040;PBS_Server;Svr;tyrone-cluster;Scheduler was sent the command new
02/18/2014 10:04:39;0040;PBS_Server;Svr;tyrone-cluster;Scheduler was sent the command new
02/18/2014 10:04:56;0040;PBS_Server;Svr;tyrone-cluster;Scheduler was sent the command new
02/18/2014 10:05:11;0040;PBS_Server;Svr;tyrone-cluster;Scheduler was sent the command new
02/18/2014 10:05:29;0040;PBS_Server;Svr;tyrone-cluster;Scheduler was sent the command new
02/18/2014 10:05:43;0040;PBS_Server;Svr;tyrone-cluster;Scheduler was sent the command new
02/18/2014 10:05:56;0040;PBS_Server;Svr;tyrone-cluster;Scheduler was sent the command new
02/18/2014 10:06:16;0040;PBS_Server;Svr;tyrone-cluster;Scheduler was sent the command new
02/18/2014 10:06:22;0100;PBS_Server;Job;35205.tyrone-cluster;enqueuing into batch, state 1 hop 1
02/18/2014 10:06:23;0100;PBS_Server;Job;35205.tyrone-cluster;dequeuing from batch, state QUEUED
02/18/2014 10:06:23;0100;PBS_Server;Job;35205.tyrone-cluster;enqueuing into idqueue, state 1 hop 1
02/18/2014 10:06:23;0008;PBS_Server;Job;35205.tyrone-cluster;Job Queued at request of phynagmp@tyrone-cluster, owner = phynagmp@tyrone-cluster, job name = poshit1, queue = idqueue
02/18/2014 10:06:24;0002;PBS_Server;Svr;PBS_Server;Torque Server Version = 3.0.5, loglevel = 0
02/18/2014 10:06:24;0040;PBS_Server;Svr;tyrone-cluster;Scheduler was sent the command new
02/18/2014 10:06:24;0008;PBS_Server;Job;35205.tyrone-cluster;Job Modified at request of Scheduler@tyrone-cluster
02/18/2014 10:06:24;0008;PBS_Server;Job;35205.tyrone-cluster;Job Run at request of Scheduler@tyrone-cluster
02/18/2014 10:06:26;0040;PBS_Server;Svr;tyrone-cluster;Scheduler was sent the command recyc
02/18/2014 10:06:26;000d;PBS_Server;Job;35205.tyrone-cluster;Not sending email: User does not want mail of this type.
02/18/2014 10:06:37;0100;PBS_Server;Job;35206.tyrone-cluster;enqueuing into batch, state 1 hop 1
02/18/2014 10:06:37;0100;PBS_Server;Job;35206.tyrone-cluster;dequeuing from batch, state QUEUED
02/18/2014 10:06:37;0100;PBS_Server;Job;35206.tyrone-cluster;enqueuing into qp64, state 1 hop 1
02/18/2014 10:06:37;0008;PBS_Server;Job;35206.tyrone-cluster;Job Queued at request of asessija@tyrone-cluster, owner = asessija@tyrone-cluster, job name = vbdn, queue = qp64
02/18/2014 10:06:37;0040;PBS_Server;Svr;tyrone-cluster;Scheduler was sent the command new
02/18/2014 10:06:38;0008;PBS_Server;Job;35206.tyrone-cluster;Job Modified at request of Scheduler@tyrone-cluster
02/18/2014 10:06:44;0040;PBS_Server;Svr;tyrone-cluster;Scheduler was sent the command new
02/18/2014 10:06:46;000d;PBS_Server;Job;35205.tyrone-cluster;Not sending email: User does not want mail of this type.
02/18/2014 10:06:46;0010;PBS_Server;Job;35205.tyrone-cluster;Exit_status=0 resources_used.cput=00:10:01 resources_used.mem=2175228kb resources_used.vmem=12346260kb resources_used.walltime=00:00:22
02/18/2014 10:06:46;0008;PBS_Server;Job;NULL;on_job_exit valid pjob: 0x1e4ee40 (substate=50)
02/18/2014 10:06:46;0008;PBS_Server;Job;NULL;on_job_exit valid pjob: 0x1e4ee40 (substate=51)
02/18/2014 10:06:46;0008;PBS_Server;Job;NULL;on_job_exit valid pjob: 0x1e4ee40 (substate=51)
02/18/2014 10:06:46;0008;PBS_Server;Job;NULL;on_job_exit valid pjob: 0x1e4ee40 (substate=53)
02/18/2014 10:06:46;0100;PBS_Server;Job;35205.tyrone-cluster;dequeuing from idqueue, state COMPLETE
02/18/2014 10:06:46;0040;PBS_Server;Svr;tyrone-cluster;Scheduler was sent the command term
02/18/2014 10:06:49;0100;PBS_Server;Job;35207.tyrone-cluster;enqueuing into batch, state 1 hop 1
02/18/2014 10:06:49;0100;PBS_Server;Job;35207.tyrone-cluster;dequeuing from batch, state QUEUED
02/18/2014 10:06:49;0100;PBS_Server;Job;35207.tyrone-cluster;enqueuing into idqueue, state 1 hop 1
02/18/2014 10:06:49;0008;PBS_Server;Job;35207.tyrone-cluster;Job Queued at request of phynagmp@tyrone-cluster, owner = phynagmp@tyrone-cluster, job name = poshit1, queue = idqueue
02/18/2014 10:06:49;0040;PBS_Server;Svr;tyrone-cluster;Scheduler was sent the command new
02/18/2014 10:06:50;0008;PBS_Server;Job;35207.tyrone-cluster;Job Modified at request of Scheduler@tyrone-cluster
02/18/2014 10:06:50;0008;PBS_Server;Job;35207.tyrone-cluster;Job Run at request of Scheduler@tyrone-cluster
02/18/2014 10:06:50;0040;PBS_Server;Svr;tyrone-cluster;Scheduler was sent the command recyc
02/18/2014 10:06:50;000d;PBS_Server;Job;35207.tyrone-cluster;Not sending email: User does not want mail of this type.
02/18/2014 10:06:59;0040;PBS_Server;Svr;tyrone-cluster;Scheduler was sent the command new
02/18/2014 10:07:07;000d;PBS_Server;Job;35207.tyrone-cluster;Not sending email: User does not want mail of this type.
02/18/2014 10:07:07;0010;PBS_Server;Job;35207.tyrone-cluster;Exit_status=0 resources_used.cput=00:07:59 resources_used.mem=0kb resources_used.vmem=0kb resources_used.walltime=00:00:17
02/18/2014 10:07:07;0008;PBS_Server;Job;NULL;on_job_exit valid pjob: 0x1dbc160 (substate=50)
02/18/2014 10:07:07;0008;PBS_Server;Job;NULL;on_job_exit valid pjob: 0x1dbc160 (substate=51)
02/18/2014 10:07:07;0008;PBS_Server;Job;NULL;on_job_exit valid pjob: 0x1dbc160 (substate=51)
02/18/2014 10:07:07;0008;PBS_Server;Job;NULL;on_job_exit valid pjob: 0x1dbc160 (substate=53)
02/18/2014 10:07:07;0100;PBS_Server;Job;35207.tyrone-cluster;dequeuing from idqueue, state COMPLETE
02/18/2014 10:07:07;0040;PBS_Server;Svr;tyrone-cluster;Scheduler was sent the command term
02/18/2014 10:07:15;0040;PBS_Server;Svr;tyrone-cluster;Scheduler was sent the command new
02/18/2014 10:07:26;0040;PBS_Server;Svr;tyrone-cluster;Scheduler was sent the command new
02/18/2014 10:07:46;0040;PBS_Server;Svr;tyrone-cluster;Scheduler was sent the command new
02/18/2014 10:07:58;0040;PBS_Server;Svr;tyrone-cluster;Scheduler was sent the command new
02/18/2014 10:08:18;0040;PBS_Server;Svr;tyrone-cluster;Scheduler was sent the command new
02/18/2014 10:08:31;0040;PBS_Server;Svr;tyrone-cluster;Scheduler was sent the command new
02/18/2014 10:08:47;0040;PBS_Server;Svr;tyrone-cluster;Scheduler was sent the command new
02/18/2014 10:08:59;0040;PBS_Server;Svr;tyrone-cluster;Scheduler was sent the command new
02/18/2014 10:09:23;0040;PBS_Server;Svr;tyrone-cluster;Scheduler was sent the command new
02/18/2014 10:09:31;0040;PBS_Server;Svr;tyrone-cluster;Scheduler was sent the command new
02/18/2014 10:09:49;0040;PBS_Server;Svr;tyrone-cluster;Scheduler was sent the command new
02/18/2014 10:10:03;0040;PBS_Server;Svr;tyrone-cluster;Scheduler was sent the command new
02/18/2014 10:10:18;0040;PBS_Server;Svr;tyrone-cluster;Scheduler was sent the command new
02/18/2014 10:10:31;0040;PBS_Server;Svr;tyrone-cluster;Scheduler was sent the command new
02/18/2014 10:10:44;0008;PBS_Server;Job;35200.tyrone-cluster;Job deleted at request of seckavya@tyrone-node9
02/18/2014 10:10:44;0008;PBS_Server;Job;NULL;on_job_exit valid pjob: 0x1e02e70 (substate=59)
02/18/2014 10:10:44;0100;PBS_Server;Job;35200.tyrone-cluster;dequeuing from qp64, state COMPLETE
02/18/2014 10:10:44;0040;PBS_Server;Svr;tyrone-cluster;Scheduler was sent the command term
02/18/2014 10:10:48;0100;PBS_Server;Job;35204.tyrone-cluster;dequeuing from batch, state QUEUED
02/18/2014 10:10:48;0100;PBS_Server;Job;35204.tyrone-cluster;enqueuing into qp64, state 1 hop 1
02/18/2014 10:10:51;0040;PBS_Server;Svr;tyrone-cluster;Scheduler was sent the command new
02/18/2014 10:10:51;0008;PBS_Server;Job;35204.tyrone-cluster;Job Modified at request of Scheduler@tyrone-cluster
02/18/2014 10:10:52;0008;PBS_Server;Job;35201.tyrone-cluster;Job deleted at request of seckavya@tyrone-node9
02/18/2014 10:10:52;0008;PBS_Server;Job;NULL;on_job_exit valid pjob: 0x1e14a70 (substate=59)
02/18/2014 10:10:52;0100;PBS_Server;Job;35201.tyrone-cluster;dequeuing from qp64, state COMPLETE
02/18/2014 10:10:52;0040;PBS_Server;Svr;tyrone-cluster;Scheduler was sent the command term
02/18/2014 10:10:58;0008;PBS_Server;Job;35202.tyrone-cluster;Job deleted at request of seckavya@tyrone-node9
02/18/2014 10:10:58;0008;PBS_Server;Job;NULL;on_job_exit valid pjob: 0x1d04560 (substate=59)
02/18/2014 10:10:58;0100;PBS_Server;Job;35202.tyrone-cluster;dequeuing from qp64, state COMPLETE
02/18/2014 10:10:58;0040;PBS_Server;Svr;tyrone-cluster;Scheduler was sent the command term
02/18/2014 10:11:01;0100;PBS_Server;Job;35203.tyrone-cluster;dequeuing from batch, state QUEUED
02/18/2014 10:11:01;0100;PBS_Server;Job;35203.tyrone-cluster;enqueuing into qp64, state 1 hop 1
02/18/2014 10:11:04;0040;PBS_Server;Svr;tyrone-cluster;Scheduler was sent the command new
02/18/2014 10:11:04;0008;PBS_Server;Job;35203.tyrone-cluster;Job Modified at request of Scheduler@tyrone-cluster
02/18/2014 10:11:07;0008;PBS_Server;Job;35203.tyrone-cluster;Job deleted at request of seckavya@tyrone-node9
02/18/2014 10:11:07;0008;PBS_Server;Job;NULL;on_job_exit valid pjob: 0x1dc01e0 (substate=59)
02/18/2014 10:11:07;0100;PBS_Server;Job;35203.tyrone-cluster;dequeuing from qp64, state COMPLETE
02/18/2014 10:11:07;0040;PBS_Server;Svr;tyrone-cluster;Scheduler was sent the command term
02/18/2014 10:11:12;0008;PBS_Server;Job;35204.tyrone-cluster;Job deleted at request of seckavya@tyrone-node9
02/18/2014 10:11:12;0008;PBS_Server;Job;NULL;on_job_exit valid pjob: 0x1d9a650 (substate=59)
02/18/2014 10:11:12;0100;PBS_Server;Job;35204.tyrone-cluster;dequeuing from qp64, state COMPLETE
02/18/2014 10:11:12;0040;PBS_Server;Svr;tyrone-cluster;Scheduler was sent the command term
02/18/2014 10:11:24;0002;PBS_Server;Svr;PBS_Server;Torque Server Version = 3.0.5, loglevel = 0
02/18/2014 10:16:13;0100;PBS_Server;Job;35208.tyrone-cluster;enqueuing into batch, state 1 hop 1
02/18/2014 10:16:13;0100;PBS_Server;Job;35208.tyrone-cluster;dequeuing from batch, state QUEUED
02/18/2014 10:16:13;0100;PBS_Server;Job;35208.tyrone-cluster;enqueuing into qp64, state 1 hop 1
02/18/2014 10:16:13;0008;PBS_Server;Job;35208.tyrone-cluster;Job Queued at request of seckavya@tyrone-node9, owner = seckavya@tyrone-node9, job name = Ms1-A-C1, queue = qp64
02/18/2014 10:16:13;0040;PBS_Server;Svr;tyrone-cluster;Scheduler was sent the command new
02/18/2014 10:16:13;0008;PBS_Server;Job;35208.tyrone-cluster;Job Modified at request of Scheduler@tyrone-cluster
02/18/2014 10:16:24;0002;PBS_Server;Svr;PBS_Server;Torque Server Version = 3.0.5, loglevel = 0
02/18/2014 10:16:24;0100;PBS_Server;Job;35209.tyrone-cluster;enqueuing into batch, state 1 hop 1
02/18/2014 10:16:24;0100;PBS_Server;Job;35209.tyrone-cluster;dequeuing from batch, state QUEUED
02/18/2014 10:16:24;0100;PBS_Server;Job;35209.tyrone-cluster;enqueuing into qp64, state 1 hop 1
02/18/2014 10:16:24;0008;PBS_Server;Job;35209.tyrone-cluster;Job Queued at request of seckavya@tyrone-node9, owner = seckavya@tyrone-node9, job name = Ms1-A-C2, queue = qp64
02/18/2014 10:16:24;0040;PBS_Server;Svr;tyrone-cluster;Scheduler was sent the command new
02/18/2014 10:16:25;0008;PBS_Server;Job;35209.tyrone-cluster;Job Modified at request of Scheduler@tyrone-cluster
02/18/2014 10:17:35;0100;PBS_Server;Job;35210.tyrone-cluster;enqueuing into batch, state 1 hop 1
02/18/2014 10:17:35;0100;PBS_Server;Job;35210.tyrone-cluster;dequeuing from batch, state QUEUED
02/18/2014 10:17:35;0100;PBS_Server;Job;35210.tyrone-cluster;enqueuing into qp64, state 1 hop 1
02/18/2014 10:17:35;0008;PBS_Server;Job;35210.tyrone-cluster;Job Queued at request of seckavya@tyrone-node9, owner = seckavya@tyrone-node9, job name = Ms1-A-C3, queue = qp64
02/18/2014 10:17:35;0040;PBS_Server;Svr;tyrone-cluster;Scheduler was sent the command new
02/18/2014 10:17:35;0008;PBS_Server;Job;35210.tyrone-cluster;Job Modified at request of Scheduler@tyrone-cluster
02/18/2014 10:18:34;0100;PBS_Server;Job;35211.tyrone-cluster;enqueuing into batch, state 1 hop 1
02/18/2014 10:18:34;0008;PBS_Server;Job;35211.tyrone-cluster;Job Queued at request of seckavya@tyrone-node9, owner = seckavya@tyrone-node9, job name = Ms1-A-C4, queue = batch
02/18/2014 10:18:34;0040;PBS_Server;Svr;tyrone-cluster;Scheduler was sent the command new
02/18/2014 10:18:34;0008;PBS_Server;Job;35211.tyrone-cluster;Job Modified at request of Scheduler@tyrone-cluster
02/18/2014 10:19:08;0040;PBS_Server;Svr;tyrone-cluster;Scheduler was sent the command new
02/18/2014 10:19:18;0100;PBS_Server;Job;35212.tyrone-cluster;enqueuing into batch, state 1 hop 1
02/18/2014 10:19:18;0008;PBS_Server;Job;35212.tyrone-cluster;Job Queued at request of seckavya@tyrone-node9, owner = seckavya@tyrone-node9, job name = Ms1-A-C5, queue = batch
02/18/2014 10:19:18;0040;PBS_Server;Svr;tyrone-cluster;Scheduler was sent the command new
02/18/2014 10:19:18;0008;PBS_Server;Job;35212.tyrone-cluster;Job Modified at request of Scheduler@tyrone-cluster
02/18/2014 10:19:35;0040;PBS_Server;Svr;tyrone-cluster;Scheduler was sent the command new
02/18/2014 10:19:53;0040;PBS_Server;Svr;tyrone-cluster;Scheduler was sent the command new
02/18/2014 10:20:04;0040;PBS_Server;Svr;tyrone-cluster;Scheduler was sent the command new
02/18/2014 10:20:19;0040;PBS_Server;Svr;tyrone-cluster;Scheduler was sent the command new
02/18/2014 10:20:38;0040;PBS_Server;Svr;tyrone-cluster;Scheduler was sent the command new
02/18/2014 10:20:49;0040;PBS_Server;Svr;tyrone-cluster;Scheduler was sent the command new
02/18/2014 10:21:09;0040;PBS_Server;Svr;tyrone-cluster;Scheduler was sent the command new
02/18/2014 10:21:23;0040;PBS_Server;Svr;tyrone-cluster;Scheduler was sent the command new
02/18/2014 10:21:24;0002;PBS_Server;Svr;PBS_Server;Torque Server Version = 3.0.5, loglevel = 0
02/18/2014 10:21:41;0040;PBS_Server;Svr;tyrone-cluster;Scheduler was sent the command new
02/18/2014 10:21:54;0040;PBS_Server;Svr;tyrone-cluster;Scheduler was sent the command new
02/18/2014 10:22:13;0040;PBS_Server;Svr;tyrone-cluster;Scheduler was sent the command new
02/18/2014 10:22:26;0040;PBS_Server;Svr;tyrone-cluster;Scheduler was sent the command new
02/18/2014 10:22:45;0040;PBS_Server;Svr;tyrone-cluster;Scheduler was sent the command new
02/18/2014 10:22:55;0040;PBS_Server;Svr;tyrone-cluster;Scheduler was sent the command new
02/18/2014 10:23:14;0040;PBS_Server;Svr;tyrone-cluster;Scheduler was sent the command new
02/18/2014 10:23:29;0040;PBS_Server;Svr;tyrone-cluster;Scheduler was sent the command new
02/18/2014 10:23:45;0040;PBS_Server;Svr;tyrone-cluster;Scheduler was sent the command new
02/18/2014 10:23:56;0040;PBS_Server;Svr;tyrone-cluster;Scheduler was sent the command new
02/18/2014 10:24:17;0040;PBS_Server;Svr;tyrone-cluster;Scheduler was sent the command new
02/18/2014 10:24:28;0040;PBS_Server;Svr;tyrone-cluster;Scheduler was sent the command new
02/18/2014 10:24:46;0040;PBS_Server;Svr;tyrone-cluster;Scheduler was sent the command new
02/18/2014 10:25:01;0040;PBS_Server;Svr;tyrone-cluster;Scheduler was sent the command new
02/18/2014 10:25:17;0040;PBS_Server;Svr;tyrone-cluster;Scheduler was sent the command new
02/18/2014 10:25:29;0040;PBS_Server;Svr;tyrone-cluster;Scheduler was sent the command new
02/18/2014 10:25:48;0040;PBS_Server;Svr;tyrone-cluster;Scheduler was sent the command new
02/18/2014 10:26:00;0040;PBS_Server;Svr;tyrone-cluster;Scheduler was sent the command new
02/18/2014 10:26:16;0040;PBS_Server;Svr;tyrone-cluster;Scheduler was sent the command new
02/18/2014 10:26:24;0002;PBS_Server;Svr;PBS_Server;Torque Server Version = 3.0.5, loglevel = 0
02/18/2014 10:26:31;0040;PBS_Server;Svr;tyrone-cluster;Scheduler was sent the command new
02/18/2014 10:26:49;0040;PBS_Server;Svr;tyrone-cluster;Scheduler was sent the command new
02/18/2014 10:27:01;0040;PBS_Server;Svr;tyrone-cluster;Scheduler was sent the command new
02/18/2014 10:27:18;0040;PBS_Server;Svr;tyrone-cluster;Scheduler was sent the command new
02/18/2014 10:27:18;0100;PBS_Server;Job;35213.tyrone-cluster;enqueuing into batch, state 1 hop 1
02/18/2014 10:27:18;0008;PBS_Server;Job;35213.tyrone-cluster;Job rejected by all possible destinations (check syntax, queue resources, ...)
02/18/2014 10:27:18;0100;PBS_Server;Job;35213.tyrone-cluster;dequeuing from batch, state QUEUED
02/18/2014 10:27:18;0080;PBS_Server;Req;req_reject;Reject reply code=15041(Job rejected by all possible destinations (check syntax, queue resources, ...)), aux=0, type=Commit, from physkc@tyrone-node9
02/18/2014 10:27:20;0100;PBS_Server;Job;35214.tyrone-cluster;enqueuing into batch, state 1 hop 1
02/18/2014 10:27:20;0100;PBS_Server;Job;35214.tyrone-cluster;dequeuing from batch, state QUEUED
02/18/2014 10:27:20;0100;PBS_Server;Job;35214.tyrone-cluster;enqueuing into qp32, state 1 hop 1
02/18/2014 10:27:20;0008;PBS_Server;Job;35214.tyrone-cluster;Job Queued at request of ipcnwrit@tyrone-cluster, owner = ipcnwrit@tyrone-cluster, job name = tyrn.sh, queue = qp32
02/18/2014 10:27:20;0040;PBS_Server;Svr;tyrone-cluster;Scheduler was sent the command new
02/18/2014 10:27:20;0008;PBS_Server;Job;35214.tyrone-cluster;Job Modified at request of Scheduler@tyrone-cluster
02/18/2014 10:27:20;0008;PBS_Server;Job;35214.tyrone-cluster;Job Run at request of Scheduler@tyrone-cluster
02/18/2014 10:27:20;0040;PBS_Server;Svr;tyrone-cluster;Scheduler was sent the command recyc
02/18/2014 10:27:20;000d;PBS_Server;Job;35214.tyrone-cluster;Not sending email: User does not want mail of this type.
02/18/2014 10:27:34;0040;PBS_Server;Svr;tyrone-cluster;Scheduler was sent the command new
02/18/2014 10:27:34;0008;PBS_Server;Job;35193.tyrone-cluster;Job Modified at request of Scheduler@tyrone-cluster
02/18/2014 10:27:43;000d;PBS_Server;Job;35214.tyrone-cluster;Not sending email: User does not want mail of this type.
02/18/2014 10:27:43;0010;PBS_Server;Job;35214.tyrone-cluster;Exit_status=0 resources_used.cput=00:00:12 resources_used.mem=67004kb resources_used.vmem=4372968kb resources_used.walltime=00:00:22
02/18/2014 10:27:43;0008;PBS_Server;Job;NULL;on_job_exit valid pjob: 0x1dc01e0 (substate=50)
02/18/2014 10:27:43;0008;PBS_Server;Job;NULL;on_job_exit valid pjob: 0x1dc01e0 (substate=51)
02/18/2014 10:27:43;0008;PBS_Server;Job;NULL;on_job_exit valid pjob: 0x1dc01e0 (substate=51)
02/18/2014 10:27:43;0008;PBS_Server;Job;NULL;on_job_exit valid pjob: 0x1dc01e0 (substate=53)
02/18/2014 10:27:43;0100;PBS_Server;Job;35214.tyrone-cluster;dequeuing from qp32, state COMPLETE
02/18/2014 10:27:43;0040;PBS_Server;Svr;tyrone-cluster;Scheduler was sent the command term
02/18/2014 10:27:43;0008;PBS_Server;Job;35193.tyrone-cluster;Job Modified at request of Scheduler@tyrone-cluster
02/18/2014 10:27:50;0040;PBS_Server;Svr;tyrone-cluster;Scheduler was sent the command new
02/18/2014 10:28:02;0040;PBS_Server;Svr;tyrone-cluster;Scheduler was sent the command new
02/18/2014 10:28:19;0040;PBS_Server;Svr;tyrone-cluster;Scheduler was sent the command new
02/18/2014 10:28:31;0040;PBS_Server;Svr;tyrone-cluster;Scheduler was sent the command new
02/18/2014 10:28:53;0040;PBS_Server;Svr;tyrone-cluster;Scheduler was sent the command new
02/18/2014 10:28:56;0100;PBS_Server;Job;35215.tyrone-cluster;enqueuing into batch, state 1 hop 1
02/18/2014 10:28:56;0008;PBS_Server;Job;35215.tyrone-cluster;Job rejected by all possible destinations (check syntax, queue resources, ...)
02/18/2014 10:28:56;0100;PBS_Server;Job;35215.tyrone-cluster;dequeuing from batch, state QUEUED
02/18/2014 10:28:56;0080;PBS_Server;Req;req_reject;Reject reply code=15041(Job rejected by all possible destinations (check syntax, queue resources, ...)), aux=0, type=Commit, from physkc@tyrone-node9
02/18/2014 10:28:56;0040;PBS_Server;Svr;tyrone-cluster;Scheduler was sent the command term
02/18/2014 10:29:04;0040;PBS_Server;Svr;tyrone-cluster;Scheduler was sent the command new
02/18/2014 10:29:24;0040;PBS_Server;Svr;tyrone-cluster;Scheduler was sent the command new
02/18/2014 10:29:34;0040;PBS_Server;Svr;tyrone-cluster;Scheduler was sent the command new
02/18/2014 10:29:56;0040;PBS_Server;Svr;tyrone-cluster;Scheduler was sent the command new
02/18/2014 10:30:05;0040;PBS_Server;Svr;tyrone-cluster;Scheduler was sent the command new
02/18/2014 10:30:28;0040;PBS_Server;Svr;tyrone-cluster;Scheduler was sent the command new
02/18/2014 10:30:34;0040;PBS_Server;Svr;tyrone-cluster;Scheduler was sent the command new
02/18/2014 10:30:56;0100;PBS_Server;Job;35216.tyrone-cluster;enqueuing into batch, state 1 hop 1
02/18/2014 10:30:56;0008;PBS_Server;Job;35216.tyrone-cluster;Job rejected by all possible destinations (check syntax, queue resources, ...)
02/18/2014 10:30:56;0100;PBS_Server;Job;35216.tyrone-cluster;dequeuing from batch, state QUEUED
02/18/2014 10:30:56;0080;PBS_Server;Req;req_reject;Reject reply code=15041(Job rejected by all possible destinations (check syntax, queue resources, ...)), aux=0, type=Commit, from physkc@tyrone-node9
02/18/2014 10:30:56;0040;PBS_Server;Svr;tyrone-cluster;Scheduler was sent the command term
02/18/2014 10:31:01;0040;PBS_Server;Svr;tyrone-cluster;Scheduler was sent the command new
02/18/2014 10:31:08;0040;PBS_Server;Svr;tyrone-cluster;Scheduler was sent the command new
02/18/2014 10:31:24;0002;PBS_Server;Svr;PBS_Server;Torque Server Version = 3.0.5, loglevel = 0
02/18/2014 10:31:29;0040;PBS_Server;Svr;tyrone-cluster;Scheduler was sent the command new
02/18/2014 10:31:39;0040;PBS_Server;Svr;tyrone-cluster;Scheduler was sent the command new
02/18/2014 10:32:00;0040;PBS_Server;Svr;tyrone-cluster;Scheduler was sent the command new
02/18/2014 10:32:11;0040;PBS_Server;Svr;tyrone-cluster;Scheduler was sent the command new
02/18/2014 10:32:31;0040;PBS_Server;Svr;tyrone-cluster;Scheduler was sent the command new
02/18/2014 10:32:43;0040;PBS_Server;Svr;tyrone-cluster;Scheduler was sent the command new
02/18/2014 10:33:01;0040;PBS_Server;Svr;tyrone-cluster;Scheduler was sent the command new
02/18/2014 10:33:15;0040;PBS_Server;Svr;tyrone-cluster;Scheduler was sent the command new
02/18/2014 10:33:34;0040;PBS_Server;Svr;tyrone-cluster;Scheduler was sent the command new
02/18/2014 10:33:45;0040;PBS_Server;Svr;tyrone-cluster;Scheduler was sent the command new
02/18/2014 10:34:02;0040;PBS_Server;Svr;tyrone-cluster;Scheduler was sent the command new
02/18/2014 10:34:16;0040;PBS_Server;Svr;tyrone-cluster;Scheduler was sent the command new
02/18/2014 10:34:32;0040;PBS_Server;Svr;tyrone-cluster;Scheduler was sent the command new
02/18/2014 10:34:47;0040;PBS_Server;Svr;tyrone-cluster;Scheduler was sent the command new
02/18/2014 10:35:05;0040;PBS_Server;Svr;tyrone-cluster;Scheduler was sent the command new
02/18/2014 10:35:17;0040;PBS_Server;Svr;tyrone-cluster;Scheduler was sent the command new
02/18/2014 10:35:34;0040;PBS_Server;Svr;tyrone-cluster;Scheduler was sent the command new
02/18/2014 10:35:50;0040;PBS_Server;Svr;tyrone-cluster;Scheduler was sent the command new
02/18/2014 10:36:02;0040;PBS_Server;Svr;tyrone-cluster;Scheduler was sent the command new
02/18/2014 10:36:24;0002;PBS_Server;Svr;PBS_Server;Torque Server Version = 3.0.5, loglevel = 0
02/18/2014 10:36:24;0040;PBS_Server;Svr;tyrone-cluster;Scheduler was sent the command new
02/18/2014 10:36:35;0040;PBS_Server;Svr;tyrone-cluster;Scheduler was sent the command new
02/18/2014 10:36:54;0040;PBS_Server;Svr;tyrone-cluster;Scheduler was sent the command new
02/18/2014 10:37:09;0040;PBS_Server;Svr;tyrone-cluster;Scheduler was sent the command new
02/18/2014 10:37:27;0040;PBS_Server;Svr;tyrone-cluster;Scheduler was sent the command new
02/18/2014 10:37:40;0040;PBS_Server;Svr;tyrone-cluster;Scheduler was sent the command new
02/18/2014 10:37:58;0040;PBS_Server;Svr;tyrone-cluster;Scheduler was sent the command new
02/18/2014 10:38:12;0040;PBS_Server;Svr;tyrone-cluster;Scheduler was sent the command new
02/18/2014 10:38:31;0040;PBS_Server;Svr;tyrone-cluster;Scheduler was sent the command new
02/18/2014 10:38:43;0040;PBS_Server;Svr;tyrone-cluster;Scheduler was sent the command new
02/18/2014 10:39:00;0040;PBS_Server;Svr;tyrone-cluster;Scheduler was sent the command new
02/18/2014 10:39:16;0040;PBS_Server;Svr;tyrone-cluster;Scheduler was sent the command new
02/18/2014 10:39:31;0040;PBS_Server;Svr;tyrone-cluster;Scheduler was sent the command new
02/18/2014 10:39:45;0040;PBS_Server;Svr;tyrone-cluster;Scheduler was sent the command new
02/18/2014 10:40:01;0040;PBS_Server;Svr;tyrone-cluster;Scheduler was sent the command new
02/18/2014 10:40:16;0040;PBS_Server;Svr;tyrone-cluster;Scheduler was sent the command new
02/18/2014 10:40:32;0040;PBS_Server;Svr;tyrone-cluster;Scheduler was sent the command new
02/18/2014 10:40:48;0040;PBS_Server;Svr;tyrone-cluster;Scheduler was sent the command new
02/18/2014 10:41:05;0040;PBS_Server;Svr;tyrone-cluster;Scheduler was sent the command new
02/18/2014 10:41:17;0040;PBS_Server;Svr;tyrone-cluster;Scheduler was sent the command new
02/18/2014 10:41:24;0002;PBS_Server;Svr;PBS_Server;Torque Server Version = 3.0.5, loglevel = 0
02/18/2014 10:41:34;0040;PBS_Server;Svr;tyrone-cluster;Scheduler was sent the command new
02/18/2014 10:41:50;0040;PBS_Server;Svr;tyrone-cluster;Scheduler was sent the command new
02/18/2014 10:42:02;0040;PBS_Server;Svr;tyrone-cluster;Scheduler was sent the command new
02/18/2014 10:42:19;0040;PBS_Server;Svr;tyrone-cluster;Scheduler was sent the command new
02/18/2014 10:42:35;0040;PBS_Server;Svr;tyrone-cluster;Scheduler was sent the command new
02/18/2014 10:42:47;0040;PBS_Server;Svr;tyrone-cluster;Scheduler was sent the command new
02/18/2014 10:43:09;0040;PBS_Server;Svr;tyrone-cluster;Scheduler was sent the command new
02/18/2014 10:43:20;0040;PBS_Server;Svr;tyrone-cluster;Scheduler was sent the command new
02/18/2014 10:43:39;0040;PBS_Server;Svr;tyrone-cluster;Scheduler was sent the command new
02/18/2014 10:43:54;0040;PBS_Server;Svr;tyrone-cluster;Scheduler was sent the command new
02/18/2014 10:44:12;0040;PBS_Server;Svr;tyrone-cluster;Scheduler was sent the command new
02/18/2014 10:44:25;0040;PBS_Server;Svr;tyrone-cluster;Scheduler was sent the command new
02/18/2014 10:44:43;0040;PBS_Server;Svr;tyrone-cluster;Scheduler was sent the command new
02/18/2014 10:44:57;0040;PBS_Server;Svr;tyrone-cluster;Scheduler was sent the command new
02/18/2014 10:45:16;0040;PBS_Server;Svr;tyrone-cluster;Scheduler was sent the command new
02/18/2014 10:45:28;0040;PBS_Server;Svr;tyrone-cluster;Scheduler was sent the command new
02/18/2014 10:45:45;0040;PBS_Server;Svr;tyrone-cluster;Scheduler was sent the command new
02/18/2014 10:46:01;0040;PBS_Server;Svr;tyrone-cluster;Scheduler was sent the command new
02/18/2014 10:46:16;0040;PBS_Server;Svr;tyrone-cluster;Scheduler was sent the command new
02/18/2014 10:46:24;0002;PBS_Server;Svr;PBS_Server;Torque Server Version = 3.0.5, loglevel = 0
02/18/2014 10:46:30;0040;PBS_Server;Svr;tyrone-cluster;Scheduler was sent the command new
02/18/2014 10:46:46;0040;PBS_Server;Svr;tyrone-cluster;Scheduler was sent the command new
02/18/2014 10:47:01;0040;PBS_Server;Svr;tyrone-cluster;Scheduler was sent the command new
02/18/2014 10:47:17;0040;PBS_Server;Svr;tyrone-cluster;Scheduler was sent the command new
02/18/2014 10:47:33;0040;PBS_Server;Svr;tyrone-cluster;Scheduler was sent the command new
02/18/2014 10:47:50;0040;PBS_Server;Svr;tyrone-cluster;Scheduler was sent the command new
02/18/2014 10:48:02;0040;PBS_Server;Svr;tyrone-cluster;Scheduler was sent the command new
02/18/2014 10:48:19;0040;PBS_Server;Svr;tyrone-cluster;Scheduler was sent the command new
02/18/2014 10:48:35;0040;PBS_Server;Svr;tyrone-cluster;Scheduler was sent the command new
02/18/2014 10:48:47;0040;PBS_Server;Svr;tyrone-cluster;Scheduler was sent the command new
02/18/2014 10:49:04;0040;PBS_Server;Svr;tyrone-cluster;Scheduler was sent the command new
02/18/2014 10:49:20;0040;PBS_Server;Svr;tyrone-cluster;Scheduler was sent the command new
02/18/2014 10:49:32;0040;PBS_Server;Svr;tyrone-cluster;Scheduler was sent the command new
02/18/2014 10:49:54;0040;PBS_Server;Svr;tyrone-cluster;Scheduler was sent the command new
02/18/2014 10:50:05;0040;PBS_Server;Svr;tyrone-cluster;Scheduler was sent the command new
02/18/2014 10:50:24;0040;PBS_Server;Svr;tyrone-cluster;Scheduler was sent the command new
02/18/2014 10:50:39;0040;PBS_Server;Svr;tyrone-cluster;Scheduler was sent the command new
02/18/2014 10:50:57;0040;PBS_Server;Svr;tyrone-cluster;Scheduler was sent the command new
02/18/2014 10:51:10;0040;PBS_Server;Svr;tyrone-cluster;Scheduler was sent the command new
02/18/2014 10:51:24;0002;PBS_Server;Svr;PBS_Server;Torque Server Version = 3.0.5, loglevel = 0
02/18/2014 10:51:28;0040;PBS_Server;Svr;tyrone-cluster;Scheduler was sent the command new
02/18/2014 10:51:42;0040;PBS_Server;Svr;tyrone-cluster;Scheduler was sent the command new
02/18/2014 10:52:01;0040;PBS_Server;Svr;tyrone-cluster;Scheduler was sent the command new
02/18/2014 10:52:13;0040;PBS_Server;Svr;tyrone-cluster;Scheduler was sent the command new
02/18/2014 10:52:30;0040;PBS_Server;Svr;tyrone-cluster;Scheduler was sent the command new
02/18/2014 10:52:46;0040;PBS_Server;Svr;tyrone-cluster;Scheduler was sent the command new
02/18/2014 10:53:01;0040;PBS_Server;Svr;tyrone-cluster;Scheduler was sent the command new
02/18/2014 10:53:15;0040;PBS_Server;Svr;tyrone-cluster;Scheduler was sent the command new
02/18/2014 10:53:31;0040;PBS_Server;Svr;tyrone-cluster;Scheduler was sent the command new
02/18/2014 10:53:46;0040;PBS_Server;Svr;tyrone-cluster;Scheduler was sent the command new
02/18/2014 10:54:02;0040;PBS_Server;Svr;tyrone-cluster;Scheduler was sent the command new
02/18/2014 10:54:18;0040;PBS_Server;Svr;tyrone-cluster;Scheduler was sent the command new
02/18/2014 10:54:36;0040;PBS_Server;Svr;tyrone-cluster;Scheduler was sent the command new
02/18/2014 10:54:47;0040;PBS_Server;Svr;tyrone-cluster;Scheduler was sent the command new
02/18/2014 10:55:09;0040;PBS_Server;Svr;tyrone-cluster;Scheduler was sent the command new
02/18/2014 10:55:20;0040;PBS_Server;Svr;tyrone-cluster;Scheduler was sent the command new
02/18/2014 10:55:40;0040;PBS_Server;Svr;tyrone-cluster;Scheduler was sent the command new
02/18/2014 10:55:49;0040;PBS_Server;Svr;tyrone-cluster;Scheduler was sent the command new
02/18/2014 10:56:12;0040;PBS_Server;Svr;tyrone-cluster;Scheduler was sent the command new
02/18/2014 10:56:17;0040;PBS_Server;Svr;tyrone-cluster;Scheduler was sent the command new
02/18/2014 10:56:24;0002;PBS_Server;Svr;PBS_Server;Torque Server Version = 3.0.5, loglevel = 0
02/18/2014 10:56:43;0040;PBS_Server;Svr;tyrone-cluster;Scheduler was sent the command new
02/18/2014 10:56:50;0040;PBS_Server;Svr;tyrone-cluster;Scheduler was sent the command new
02/18/2014 10:57:15;0040;PBS_Server;Svr;tyrone-cluster;Scheduler was sent the command new
02/18/2014 10:57:24;0040;PBS_Server;Svr;tyrone-cluster;Scheduler was sent the command new
02/18/2014 10:57:40;0100;PBS_Server;Job;35217.tyrone-cluster;enqueuing into batch, state 1 hop 1
02/18/2014 10:57:40;0100;PBS_Server;Job;35217.tyrone-cluster;dequeuing from batch, state QUEUED
02/18/2014 10:57:40;0100;PBS_Server;Job;35217.tyrone-cluster;enqueuing into qp256, state 1 hop 1
02/18/2014 10:57:40;0008;PBS_Server;Job;35217.tyrone-cluster;Job Queued at request of ipcanupb@tyrone-cluster, owner = ipcanupb@tyrone-cluster, job name = ts12, queue = qp256
02/18/2014 10:57:40;0040;PBS_Server;Svr;tyrone-cluster;Scheduler was sent the command new
02/18/2014 10:57:41;0008;PBS_Server;Job;35217.tyrone-cluster;Job Modified at request of Scheduler@tyrone-cluster
02/18/2014 10:57:45;0040;PBS_Server;Svr;tyrone-cluster;Scheduler was sent the command new
02/18/2014 10:57:53;0040;PBS_Server;Svr;tyrone-cluster;Scheduler was sent the command new
02/18/2014 10:58:16;0040;PBS_Server;Svr;tyrone-cluster;Scheduler was sent the command new
02/18/2014 10:58:27;0040;PBS_Server;Svr;tyrone-cluster;Scheduler was sent the command new
02/18/2014 10:58:49;0040;PBS_Server;Svr;tyrone-cluster;Scheduler was sent the command new
02/18/2014 10:58:58;0040;PBS_Server;Svr;tyrone-cluster;Scheduler was sent the command new
02/18/2014 10:59:17;0040;PBS_Server;Svr;tyrone-cluster;Scheduler was sent the command new
02/18/2014 10:59:31;0040;PBS_Server;Svr;tyrone-cluster;Scheduler was sent the command new
02/18/2014 10:59:50;0040;PBS_Server;Svr;tyrone-cluster;Scheduler was sent the command new
02/18/2014 11:00:00;0040;PBS_Server;Svr;tyrone-cluster;Scheduler was sent the command new
02/18/2014 11:00:19;0040;PBS_Server;Svr;tyrone-cluster;Scheduler was sent the command new
02/18/2014 11:00:31;0040;PBS_Server;Svr;tyrone-cluster;Scheduler was sent the command new
02/18/2014 11:00:47;0040;PBS_Server;Svr;tyrone-cluster;Scheduler was sent the command new
02/18/2014 11:01:01;0040;PBS_Server;Svr;tyrone-cluster;Scheduler was sent the command new
02/18/2014 11:01:20;0040;PBS_Server;Svr;tyrone-cluster;Scheduler was sent the command new
02/18/2014 11:01:24;0002;PBS_Server;Svr;PBS_Server;Torque Server Version = 3.0.5, loglevel = 0
02/18/2014 11:01:32;0040;PBS_Server;Svr;tyrone-cluster;Scheduler was sent the command new
02/18/2014 11:01:54;0040;PBS_Server;Svr;tyrone-cluster;Scheduler was sent the command new
02/18/2014 11:02:05;0040;PBS_Server;Svr;tyrone-cluster;Scheduler was sent the command new
02/18/2014 11:02:24;0040;PBS_Server;Svr;tyrone-cluster;Scheduler was sent the command new
02/18/2014 11:02:34;0040;PBS_Server;Svr;tyrone-cluster;Scheduler was sent the command new
02/18/2014 11:02:57;0040;PBS_Server;Svr;tyrone-cluster;Scheduler was sent the command new
02/18/2014 11:03:02;0040;PBS_Server;Svr;tyrone-cluster;Scheduler was sent the command new
02/18/2014 11:03:28;0040;PBS_Server;Svr;tyrone-cluster;Scheduler was sent the command new
02/18/2014 11:03:28;0100;PBS_Server;Job;35218.tyrone-cluster;enqueuing into batch, state 1 hop 1
02/18/2014 11:03:28;0008;PBS_Server;Job;35218.tyrone-cluster;Job Queued at request of icrsanch@tyrone-cluster, owner = icrsanch@tyrone-cluster, job name = job256, queue = batch
02/18/2014 11:03:28;0008;PBS_Server;Job;35218.tyrone-cluster;Job Modified at request of Scheduler@tyrone-cluster
02/18/2014 11:03:34;0040;PBS_Server;Svr;tyrone-cluster;Scheduler was sent the command new
02/18/2014 11:03:34;0100;PBS_Server;Job;35219.tyrone-cluster;enqueuing into batch, state 1 hop 1
02/18/2014 11:03:34;0008;PBS_Server;Job;35219.tyrone-cluster;Job Queued at request of icrsanch@tyrone-cluster, owner = icrsanch@tyrone-cluster, job name = job256, queue = batch
02/18/2014 11:03:34;0008;PBS_Server;Job;35219.tyrone-cluster;Job Modified at request of Scheduler@tyrone-cluster
02/18/2014 11:03:38;0100;PBS_Server;Job;35220.tyrone-cluster;enqueuing into batch, state 1 hop 1
02/18/2014 11:03:38;0008;PBS_Server;Job;35220.tyrone-cluster;Job Queued at request of icrsanch@tyrone-cluster, owner = icrsanch@tyrone-cluster, job name = job256, queue = batch
02/18/2014 11:03:38;0040;PBS_Server;Svr;tyrone-cluster;Scheduler was sent the command new
02/18/2014 11:03:38;0008;PBS_Server;Job;35220.tyrone-cluster;Job Modified at request of Scheduler@tyrone-cluster
02/18/2014 11:03:42;0100;PBS_Server;Job;35221.tyrone-cluster;enqueuing into batch, state 1 hop 1
02/18/2014 11:03:42;0008;PBS_Server;Job;35221.tyrone-cluster;Job Queued at request of icrsanch@tyrone-cluster, owner = icrsanch@tyrone-cluster, job name = job256, queue = batch
02/18/2014 11:03:42;0040;PBS_Server;Svr;tyrone-cluster;Scheduler was sent the command new
02/18/2014 11:03:42;0008;PBS_Server;Job;35221.tyrone-cluster;Job Modified at request of Scheduler@tyrone-cluster
02/18/2014 11:04:01;0040;PBS_Server;Svr;tyrone-cluster;Scheduler was sent the command new
02/18/2014 11:04:09;0040;PBS_Server;Svr;tyrone-cluster;Scheduler was sent the command new
02/18/2014 11:04:13;0040;PBS_Server;Svr;tyrone-cluster;Scheduler was sent the command new
02/18/2014 11:04:30;0040;PBS_Server;Svr;tyrone-cluster;Scheduler was sent the command new
02/18/2014 11:04:35;0040;PBS_Server;Svr;tyrone-cluster;Scheduler was sent the command new
02/18/2014 11:04:40;0040;PBS_Server;Svr;tyrone-cluster;Scheduler was sent the command new
02/18/2014 11:04:46;0040;PBS_Server;Svr;tyrone-cluster;Scheduler was sent the command new
02/18/2014 11:05:01;0040;PBS_Server;Svr;tyrone-cluster;Scheduler was sent the command new
02/18/2014 11:05:05;0040;PBS_Server;Svr;tyrone-cluster;Scheduler was sent the command new
02/18/2014 11:05:12;0040;PBS_Server;Svr;tyrone-cluster;Scheduler was sent the command new
02/18/2014 11:05:14;0040;PBS_Server;Svr;tyrone-cluster;Scheduler was sent the command new
02/18/2014 11:05:32;0040;PBS_Server;Svr;tyrone-cluster;Scheduler was sent the command new
02/18/2014 11:05:37;0040;PBS_Server;Svr;tyrone-cluster;Scheduler was sent the command new
02/18/2014 11:05:41;0040;PBS_Server;Svr;tyrone-cluster;Scheduler was sent the command new
02/18/2014 11:05:46;0040;PBS_Server;Svr;tyrone-cluster;Scheduler was sent the command new
02/18/2014 11:06:02;0040;PBS_Server;Svr;tyrone-cluster;Scheduler was sent the command new
02/18/2014 11:06:09;0040;PBS_Server;Svr;tyrone-cluster;Scheduler was sent the command new
02/18/2014 11:06:16;0040;PBS_Server;Svr;tyrone-cluster;Scheduler was sent the command new
02/18/2014 11:06:24;0002;PBS_Server;Svr;PBS_Server;Torque Server Version = 3.0.5, loglevel = 0
02/18/2014 11:06:35;0040;PBS_Server;Svr;tyrone-cluster;Scheduler was sent the command new
02/18/2014 11:06:42;0040;PBS_Server;Svr;tyrone-cluster;Scheduler was sent the command new
02/18/2014 11:06:45;0040;PBS_Server;Svr;tyrone-cluster;Scheduler was sent the command new
02/18/2014 11:07:09;0040;PBS_Server;Svr;tyrone-cluster;Scheduler was sent the command new
02/18/2014 11:07:13;0040;PBS_Server;Svr;tyrone-cluster;Scheduler was sent the command new
02/18/2014 11:07:16;0040;PBS_Server;Svr;tyrone-cluster;Scheduler was sent the command new
02/18/2014 11:07:40;0040;PBS_Server;Svr;tyrone-cluster;Scheduler was sent the command new
02/18/2014 11:07:46;0040;PBS_Server;Svr;tyrone-cluster;Scheduler was sent the command new
02/18/2014 11:08:10;0040;PBS_Server;Svr;tyrone-cluster;Scheduler was sent the command new
02/18/2014 11:08:15;0040;PBS_Server;Svr;tyrone-cluster;Scheduler was sent the command new
02/18/2014 11:08:17;0040;PBS_Server;Svr;tyrone-cluster;Scheduler was sent the command new
02/18/2014 11:08:43;0040;PBS_Server;Svr;tyrone-cluster;Scheduler was sent the command new
02/18/2014 11:08:46;0040;PBS_Server;Svr;tyrone-cluster;Scheduler was sent the command new
02/18/2014 11:08:50;0040;PBS_Server;Svr;tyrone-cluster;Scheduler was sent the command new
02/18/2014 11:09:15;0040;PBS_Server;Svr;tyrone-cluster;Scheduler was sent the command new
02/18/2014 11:09:24;0040;PBS_Server;Svr;tyrone-cluster;Scheduler was sent the command new
02/18/2014 11:09:45;0040;PBS_Server;Svr;tyrone-cluster;Scheduler was sent the command new
02/18/2014 11:09:47;0040;PBS_Server;Svr;tyrone-cluster;Scheduler was sent the command new
02/18/2014 11:09:54;0040;PBS_Server;Svr;tyrone-cluster;Scheduler was sent the command new
02/18/2014 11:10:06;000d;PBS_Server;Job;35146.tyrone-cluster;Not sending email: User does not want mail of this type.
02/18/2014 11:10:06;0010;PBS_Server;Job;35146.tyrone-cluster;Exit_status=143 resources_used.cput=1530:11:34 resources_used.mem=13515300kb resources_used.vmem=47438652kb resources_used.walltime=24:00:14
02/18/2014 11:10:06;0008;PBS_Server;Job;NULL;on_job_exit valid pjob: 0x1e25d70 (substate=50)
02/18/2014 11:10:06;0008;PBS_Server;Job;NULL;on_job_exit valid pjob: 0x1e25d70 (substate=51)
02/18/2014 11:10:13;0008;PBS_Server;Job;NULL;on_job_exit valid pjob: 0x1e25d70 (substate=51)
02/18/2014 11:10:13;0008;PBS_Server;Job;NULL;on_job_exit valid pjob: 0x1e25d70 (substate=53)
02/18/2014 11:10:13;0100;PBS_Server;Job;35146.tyrone-cluster;dequeuing from qp64, state COMPLETE
02/18/2014 11:10:13;0040;PBS_Server;Svr;tyrone-cluster;Scheduler was sent the command term
02/18/2014 11:10:13;0008;PBS_Server;Job;35134.tyrone-cluster;Job Modified at request of Scheduler@tyrone-cluster
02/18/2014 11:10:13;0008;PBS_Server;Job;35152.tyrone-cluster;Job Modified at request of Scheduler@tyrone-cluster
02/18/2014 11:10:13;0008;PBS_Server;Job;35152.tyrone-cluster;Job Run at request of Scheduler@tyrone-cluster
02/18/2014 11:10:13;0040;PBS_Server;Svr;tyrone-cluster;Scheduler was sent the command recyc
02/18/2014 11:10:13;000d;PBS_Server;Job;35152.tyrone-cluster;Not sending email: User does not want mail of this type.
02/18/2014 11:10:16;0040;PBS_Server;Svr;tyrone-cluster;Scheduler was sent the command new
02/18/2014 11:10:17;0008;PBS_Server;Job;35134.tyrone-cluster;Job Modified at request of Scheduler@tyrone-cluster
02/18/2014 11:10:25;0040;PBS_Server;Svr;tyrone-cluster;Scheduler was sent the command new
02/18/2014 11:10:25;000d;PBS_Server;Job;35152.tyrone-cluster;Not sending email: User does not want mail of this type.
02/18/2014 11:10:25;0010;PBS_Server;Job;35152.tyrone-cluster;Exit_status=255 resources_used.cput=00:09:51 resources_used.mem=0kb resources_used.vmem=0kb resources_used.walltime=00:00:12
02/18/2014 11:10:25;0008;PBS_Server;Job;NULL;on_job_exit valid pjob: 0x1e4a5e0 (substate=50)
02/18/2014 11:10:25;0008;PBS_Server;Job;NULL;on_job_exit valid pjob: 0x1e4a5e0 (substate=51)
02/18/2014 11:10:25;0008;PBS_Server;Job;35134.tyrone-cluster;Job Modified at request of Scheduler@tyrone-cluster
02/18/2014 11:10:25;0008;PBS_Server;Job;35153.tyrone-cluster;Job Modified at request of Scheduler@tyrone-cluster
02/18/2014 11:10:25;0008;PBS_Server;Job;35184.tyrone-cluster;Job Modified at request of Scheduler@tyrone-cluster
02/18/2014 11:10:25;0008;PBS_Server;Job;35135.tyrone-cluster;Job Modified at request of Scheduler@tyrone-cluster
02/18/2014 11:10:25;0008;PBS_Server;Job;35206.tyrone-cluster;Job Modified at request of Scheduler@tyrone-cluster
02/18/2014 11:10:25;0008;PBS_Server;Job;35208.tyrone-cluster;Job Modified at request of Scheduler@tyrone-cluster
02/18/2014 11:10:25;0008;PBS_Server;Job;35209.tyrone-cluster;Job Modified at request of Scheduler@tyrone-cluster
02/18/2014 11:10:25;0008;PBS_Server;Job;35210.tyrone-cluster;Job Modified at request of Scheduler@tyrone-cluster
02/18/2014 11:10:29;0008;PBS_Server;Job;NULL;on_job_exit valid pjob: 0x1e4a5e0 (substate=51)
02/18/2014 11:10:29;000d;PBS_Server;Job;35152.tyrone-cluster;Post job file processing error; job 35152.tyrone-cluster on host tyrone-node16/63+tyrone-node16/62+tyrone-node16/61+tyrone-node16/60+tyrone-node16/59+tyrone-node16/58+tyrone-node16/57+tyrone-node16/56+tyrone-node16/55+tyrone-node16/54+tyrone-node16/53+tyrone-node16/52+tyrone-node16/51+tyrone-node16/50+tyrone-node16/49+tyrone-node16/48+tyrone-node16/47+tyrone-node16/46+tyrone-node16/45+tyrone-node16/44+tyrone-node16/43+tyrone-node16/42+tyrone-node16/41+tyrone-node16/40+tyrone-node16/39+tyrone-node16/38+tyrone-node16/37+tyrone-node16/36+tyrone-node16/35+tyrone-node16/34+tyrone-node16/33+tyrone-node16/32+tyrone-node16/31+tyrone-node16/30+tyrone-node16/29+tyrone-node16/28+tyrone-node16/27+tyrone-node16/26+tyrone-node16/25+tyrone-node16/24+tyrone-node16/23+tyrone-node16/22+tyrone-node16/21+tyrone-node16/20+tyrone-node16/19+tyrone-node16/18+tyrone-node16/17+tyrone-node16/16+tyrone-node16/15+tyrone-node16/14+tyrone-node16/13+tyrone-node16/12+tyrone-node16/11+tyrone-node16/10+tyrone-node16/9+tyrone-node16/8+tyrone-node16/7+tyrone-node16/6+tyrone-node16/5+tyrone-node16/4+tyrone-node16/3+tyrone-node16/2+tyrone-node16/1+tyrone-node16/0
02/18/2014 11:10:29;0008;PBS_Server;Job;NULL;on_job_exit valid pjob: 0x1e4a5e0 (substate=53)
02/18/2014 11:10:29;0100;PBS_Server;Job;35152.tyrone-cluster;dequeuing from qp64, state COMPLETE
02/18/2014 11:10:29;0040;PBS_Server;Svr;tyrone-cluster;Scheduler was sent the command term
02/18/2014 11:10:29;0008;PBS_Server;Job;35153.tyrone-cluster;Job Modified at request of Scheduler@tyrone-cluster
02/18/2014 11:10:29;0008;PBS_Server;Job;35153.tyrone-cluster;Job Run at request of Scheduler@tyrone-cluster
02/18/2014 11:10:30;0008;PBS_Server;Job;35184.tyrone-cluster;Job Modified at request of Scheduler@tyrone-cluster
02/18/2014 11:10:30;0008;PBS_Server;Job;35135.tyrone-cluster;Job Modified at request of Scheduler@tyrone-cluster
02/18/2014 11:10:30;0008;PBS_Server;Job;35206.tyrone-cluster;Job Modified at request of Scheduler@tyrone-cluster
02/18/2014 11:10:30;0008;PBS_Server;Job;35208.tyrone-cluster;Job Modified at request of Scheduler@tyrone-cluster
02/18/2014 11:10:30;0008;PBS_Server;Job;35209.tyrone-cluster;Job Modified at request of Scheduler@tyrone-cluster
02/18/2014 11:10:30;0008;PBS_Server;Job;35210.tyrone-cluster;Job Modified at request of Scheduler@tyrone-cluster
02/18/2014 11:10:30;0040;PBS_Server;Svr;tyrone-cluster;Scheduler was sent the command recyc
02/18/2014 11:10:31;000d;PBS_Server;Job;35153.tyrone-cluster;Not sending email: User does not want mail of this type.
02/18/2014 11:10:47;0040;PBS_Server;Svr;tyrone-cluster;Scheduler was sent the command new
02/18/2014 11:10:47;0008;PBS_Server;Job;35134.tyrone-cluster;Job Modified at request of Scheduler@tyrone-cluster
02/18/2014 11:10:58;0040;PBS_Server;Svr;tyrone-cluster;Scheduler was sent the command new
02/18/2014 11:11:17;0040;PBS_Server;Svr;tyrone-cluster;Scheduler was sent the command new
02/18/2014 11:11:24;0002;PBS_Server;Svr;PBS_Server;Torque Server Version = 3.0.5, loglevel = 0
02/18/2014 11:11:31;0040;PBS_Server;Svr;tyrone-cluster;Scheduler was sent the command new
02/18/2014 11:11:50;0040;PBS_Server;Svr;tyrone-cluster;Scheduler was sent the command new
02/18/2014 11:12:00;0040;PBS_Server;Svr;tyrone-cluster;Scheduler was sent the command new
02/18/2014 11:12:23;0040;PBS_Server;Svr;tyrone-cluster;Scheduler was sent the command new
02/18/2014 11:12:31;0040;PBS_Server;Svr;tyrone-cluster;Scheduler was sent the command new
02/18/2014 11:12:50;0040;PBS_Server;Svr;tyrone-cluster;Scheduler was sent the command new
02/18/2014 11:13:02;0040;PBS_Server;Svr;tyrone-cluster;Scheduler was sent the command new
02/18/2014 11:13:20;0040;PBS_Server;Svr;tyrone-cluster;Scheduler was sent the command new
02/18/2014 11:13:32;0040;PBS_Server;Svr;tyrone-cluster;Scheduler was sent the command new
02/18/2014 11:13:54;0040;PBS_Server;Svr;tyrone-cluster;Scheduler was sent the command new
02/18/2014 11:14:05;0040;PBS_Server;Svr;tyrone-cluster;Scheduler was sent the command new
02/18/2014 11:14:25;0040;PBS_Server;Svr;tyrone-cluster;Scheduler was sent the command new
02/18/2014 11:14:39;0040;PBS_Server;Svr;tyrone-cluster;Scheduler was sent the command new
02/18/2014 11:14:57;0040;PBS_Server;Svr;tyrone-cluster;Scheduler was sent the command new
02/18/2014 11:15:10;0040;PBS_Server;Svr;tyrone-cluster;Scheduler was sent the command new
02/18/2014 11:15:28;0040;PBS_Server;Svr;tyrone-cluster;Scheduler was sent the command new
02/18/2014 11:15:42;0040;PBS_Server;Svr;tyrone-cluster;Scheduler was sent the command new
02/18/2014 11:16:01;0040;PBS_Server;Svr;tyrone-cluster;Scheduler was sent the command new
02/18/2014 11:16:13;0040;PBS_Server;Svr;tyrone-cluster;Scheduler was sent the command new
02/18/2014 11:16:24;0002;PBS_Server;Svr;PBS_Server;Torque Server Version = 3.0.5, loglevel = 0
02/18/2014 11:16:30;0040;PBS_Server;Svr;tyrone-cluster;Scheduler was sent the command new
02/18/2014 11:16:46;0040;PBS_Server;Svr;tyrone-cluster;Scheduler was sent the command new
02/18/2014 11:17:01;0040;PBS_Server;Svr;tyrone-cluster;Scheduler was sent the command new
02/18/2014 11:17:15;0040;PBS_Server;Svr;tyrone-cluster;Scheduler was sent the command new
02/18/2014 11:17:32;0040;PBS_Server;Svr;tyrone-cluster;Scheduler was sent the command new
02/18/2014 11:17:46;0040;PBS_Server;Svr;tyrone-cluster;Scheduler was sent the command new
02/18/2014 11:18:02;0040;PBS_Server;Svr;tyrone-cluster;Scheduler was sent the command new
02/18/2014 11:18:17;0040;PBS_Server;Svr;tyrone-cluster;Scheduler was sent the command new
02/18/2014 11:18:35;0040;PBS_Server;Svr;tyrone-cluster;Scheduler was sent the command new
02/18/2014 11:18:47;0040;PBS_Server;Svr;tyrone-cluster;Scheduler was sent the command new
02/18/2014 11:19:04;0040;PBS_Server;Svr;tyrone-cluster;Scheduler was sent the command new
02/18/2014 11:19:20;0040;PBS_Server;Svr;tyrone-cluster;Scheduler was sent the command new
02/18/2014 11:19:32;0040;PBS_Server;Svr;tyrone-cluster;Scheduler was sent the command new
02/18/2014 11:19:54;0040;PBS_Server;Svr;tyrone-cluster;Scheduler was sent the command new
02/18/2014 11:20:05;0040;PBS_Server;Svr;tyrone-cluster;Scheduler was sent the command new
02/18/2014 11:20:25;0040;PBS_Server;Svr;tyrone-cluster;Scheduler was sent the command new
02/18/2014 11:20:39;0040;PBS_Server;Svr;tyrone-cluster;Scheduler was sent the command new
02/18/2014 11:20:57;0040;PBS_Server;Svr;tyrone-cluster;Scheduler was sent the command new
02/18/2014 11:21:10;0040;PBS_Server;Svr;tyrone-cluster;Scheduler was sent the command new
02/18/2014 11:21:24;0002;PBS_Server;Svr;PBS_Server;Torque Server Version = 3.0.5, loglevel = 0
02/18/2014 11:21:28;0040;PBS_Server;Svr;tyrone-cluster;Scheduler was sent the command new
02/18/2014 11:21:42;0040;PBS_Server;Svr;tyrone-cluster;Scheduler was sent the command new
02/18/2014 11:22:02;0040;PBS_Server;Svr;tyrone-cluster;Scheduler was sent the command new
02/18/2014 11:22:13;0040;PBS_Server;Svr;tyrone-cluster;Scheduler was sent the command new
02/18/2014 11:22:30;0040;PBS_Server;Svr;tyrone-cluster;Scheduler was sent the command new
02/18/2014 11:22:40;0100;PBS_Server;Job;35222.tyrone-cluster;enqueuing into batch, state 1 hop 1
02/18/2014 11:22:40;0100;PBS_Server;Job;35222.tyrone-cluster;dequeuing from batch, state QUEUED
02/18/2014 11:22:40;0100;PBS_Server;Job;35222.tyrone-cluster;enqueuing into qp32, state 1 hop 1
02/18/2014 11:22:40;0008;PBS_Server;Job;35222.tyrone-cluster;Job Queued at request of ipcdskp@tyrone-cluster, owner = ipcdskp@tyrone-cluster, job name = n11, queue = qp32
02/18/2014 11:22:40;0040;PBS_Server;Svr;tyrone-cluster;Scheduler was sent the command new
02/18/2014 11:22:40;0008;PBS_Server;Job;35222.tyrone-cluster;Job Modified at request of Scheduler@tyrone-cluster
02/18/2014 11:22:40;0008;PBS_Server;Job;35222.tyrone-cluster;Job Run at request of Scheduler@tyrone-cluster
02/18/2014 11:22:40;0040;PBS_Server;Svr;tyrone-cluster;Scheduler was sent the command recyc
02/18/2014 11:22:40;000d;PBS_Server;Job;35222.tyrone-cluster;Not sending email: User does not want mail of this type.
02/18/2014 11:22:47;0040;PBS_Server;Svr;tyrone-cluster;Scheduler was sent the command new
02/18/2014 11:22:47;0008;PBS_Server;Job;35193.tyrone-cluster;Job Modified at request of Scheduler@tyrone-cluster
02/18/2014 11:23:01;0040;PBS_Server;Svr;tyrone-cluster;Scheduler was sent the command new
02/18/2014 11:23:15;0040;PBS_Server;Svr;tyrone-cluster;Scheduler was sent the command new
02/18/2014 11:23:32;0040;PBS_Server;Svr;tyrone-cluster;Scheduler was sent the command new
02/18/2014 11:23:46;0040;PBS_Server;Svr;tyrone-cluster;Scheduler was sent the command new
02/18/2014 11:24:02;0040;PBS_Server;Svr;tyrone-cluster;Scheduler was sent the command new
02/18/2014 11:24:17;0040;PBS_Server;Svr;tyrone-cluster;Scheduler was sent the command new
02/18/2014 11:24:35;0040;PBS_Server;Svr;tyrone-cluster;Scheduler was sent the command new
02/18/2014 11:24:47;0040;PBS_Server;Svr;tyrone-cluster;Scheduler was sent the command new
02/18/2014 11:25:02;0040;PBS_Server;Svr;tyrone-cluster;Scheduler was sent the command new
02/18/2014 11:25:20;0040;PBS_Server;Svr;tyrone-cluster;Scheduler was sent the command new
02/18/2014 11:25:32;0040;PBS_Server;Svr;tyrone-cluster;Scheduler was sent the command new
02/18/2014 11:25:47;0040;PBS_Server;Svr;tyrone-cluster;Scheduler was sent the command new
02/18/2014 11:26:05;0040;PBS_Server;Svr;tyrone-cluster;Scheduler was sent the command new
02/18/2014 11:26:17;0040;PBS_Server;Svr;tyrone-cluster;Scheduler was sent the command new
02/18/2014 11:26:24;0002;PBS_Server;Svr;PBS_Server;Torque Server Version = 3.0.5, loglevel = 0
02/18/2014 11:26:39;0040;PBS_Server;Svr;tyrone-cluster;Scheduler was sent the command new
02/18/2014 11:26:50;0040;PBS_Server;Svr;tyrone-cluster;Scheduler was sent the command new
02/18/2014 11:27:10;0040;PBS_Server;Svr;tyrone-cluster;Scheduler was sent the command new
02/18/2014 11:27:24;0040;PBS_Server;Svr;tyrone-cluster;Scheduler was sent the command new
02/18/2014 11:27:42;0040;PBS_Server;Svr;tyrone-cluster;Scheduler was sent the command new
02/18/2014 11:27:55;0040;PBS_Server;Svr;tyrone-cluster;Scheduler was sent the command new
02/18/2014 11:28:13;0040;PBS_Server;Svr;tyrone-cluster;Scheduler was sent the command new
02/18/2014 11:28:27;0040;PBS_Server;Svr;tyrone-cluster;Scheduler was sent the command new
02/18/2014 11:28:47;0040;PBS_Server;Svr;tyrone-cluster;Scheduler was sent the command new
02/18/2014 11:28:58;0040;PBS_Server;Svr;tyrone-cluster;Scheduler was sent the command new
02/18/2014 11:29:15;0040;PBS_Server;Svr;tyrone-cluster;Scheduler was sent the command new
02/18/2014 11:29:32;0040;PBS_Server;Svr;tyrone-cluster;Scheduler was sent the command new
02/18/2014 11:29:46;0040;PBS_Server;Svr;tyrone-cluster;Scheduler was sent the command new
02/18/2014 11:30:00;0040;PBS_Server;Svr;tyrone-cluster;Scheduler was sent the command new
02/18/2014 11:30:17;0040;PBS_Server;Svr;tyrone-cluster;Scheduler was sent the command new
02/18/2014 11:30:31;0040;PBS_Server;Svr;tyrone-cluster;Scheduler was sent the command new
02/18/2014 11:30:47;0040;PBS_Server;Svr;tyrone-cluster;Scheduler was sent the command new
02/18/2014 11:31:02;0040;PBS_Server;Svr;tyrone-cluster;Scheduler was sent the command new
02/18/2014 11:31:20;0040;PBS_Server;Svr;tyrone-cluster;Scheduler was sent the command new
02/18/2014 11:31:24;0002;PBS_Server;Svr;PBS_Server;Torque Server Version = 3.0.5, loglevel = 0
02/18/2014 11:31:32;0040;PBS_Server;Svr;tyrone-cluster;Scheduler was sent the command new
02/18/2014 11:31:47;0040;PBS_Server;Svr;tyrone-cluster;Scheduler was sent the command new
02/18/2014 11:32:05;0040;PBS_Server;Svr;tyrone-cluster;Scheduler was sent the command new
02/18/2014 11:32:17;0040;PBS_Server;Svr;tyrone-cluster;Scheduler was sent the command new
02/18/2014 11:32:39;0040;PBS_Server;Svr;tyrone-cluster;Scheduler was sent the command new
02/18/2014 11:32:50;0040;PBS_Server;Svr;tyrone-cluster;Scheduler was sent the command new
02/18/2014 11:33:06;0040;PBS_Server;Svr;tyrone-cluster;Scheduler was sent the command new
02/18/2014 11:33:17;0040;PBS_Server;Svr;tyrone-cluster;Scheduler was sent the command new
02/18/2014 11:33:35;0040;PBS_Server;Svr;tyrone-cluster;Scheduler was sent the command new
02/18/2014 11:33:47;0040;PBS_Server;Svr;tyrone-cluster;Scheduler was sent the command new
02/18/2014 11:34:09;0040;PBS_Server;Svr;tyrone-cluster;Scheduler was sent the command new
02/18/2014 11:34:20;0040;PBS_Server;Svr;tyrone-cluster;Scheduler was sent the command new
02/18/2014 11:34:39;0040;PBS_Server;Svr;tyrone-cluster;Scheduler was sent the command new
02/18/2014 11:34:47;0040;PBS_Server;Svr;tyrone-cluster;Scheduler was sent the command new
02/18/2014 11:35:11;0040;PBS_Server;Svr;tyrone-cluster;Scheduler was sent the command new
02/18/2014 11:35:17;0040;PBS_Server;Svr;tyrone-cluster;Scheduler was sent the command new
02/18/2014 11:35:39;0040;PBS_Server;Svr;tyrone-cluster;Scheduler was sent the command new
02/18/2014 11:35:50;0040;PBS_Server;Svr;tyrone-cluster;Scheduler was sent the command new
02/18/2014 11:36:10;0040;PBS_Server;Svr;tyrone-cluster;Scheduler was sent the command new
02/18/2014 11:36:17;0040;PBS_Server;Svr;tyrone-cluster;Scheduler was sent the command new
02/18/2014 11:36:24;0002;PBS_Server;Svr;PBS_Server;Torque Server Version = 3.0.5, loglevel = 0
02/18/2014 11:36:42;0040;PBS_Server;Svr;tyrone-cluster;Scheduler was sent the command new
02/18/2014 11:36:47;0040;PBS_Server;Svr;tyrone-cluster;Scheduler was sent the command new
02/18/2014 11:37:13;0040;PBS_Server;Svr;tyrone-cluster;Scheduler was sent the command new
02/18/2014 11:37:20;0040;PBS_Server;Svr;tyrone-cluster;Scheduler was sent the command new
02/18/2014 11:37:47;0040;PBS_Server;Svr;tyrone-cluster;Scheduler was sent the command new
02/18/2014 11:38:15;0040;PBS_Server;Svr;tyrone-cluster;Scheduler was sent the command new
02/18/2014 11:38:17;0040;PBS_Server;Svr;tyrone-cluster;Scheduler was sent the command new
02/18/2014 11:38:46;0040;PBS_Server;Svr;tyrone-cluster;Scheduler was sent the command new
02/18/2014 11:39:17;0040;PBS_Server;Svr;tyrone-cluster;Scheduler was sent the command new
02/18/2014 11:39:47;0040;PBS_Server;Svr;tyrone-cluster;Scheduler was sent the command new
02/18/2014 11:40:20;0040;PBS_Server;Svr;tyrone-cluster;Scheduler was sent the command new
02/18/2014 11:40:47;0040;PBS_Server;Svr;tyrone-cluster;Scheduler was sent the command new
02/18/2014 11:41:12;0100;PBS_Server;Job;35223.tyrone-cluster;enqueuing into batch, state 1 hop 1
02/18/2014 11:41:12;0008;PBS_Server;Job;35223.tyrone-cluster;Job Queued at request of icrsanch@tyrone-cluster, owner = icrsanch@tyrone-cluster, job name = job256, queue = batch
02/18/2014 11:41:12;0040;PBS_Server;Svr;tyrone-cluster;Scheduler was sent the command new
02/18/2014 11:41:13;0008;PBS_Server;Job;35223.tyrone-cluster;Job Modified at request of Scheduler@tyrone-cluster
02/18/2014 11:41:17;0040;PBS_Server;Svr;tyrone-cluster;Scheduler was sent the command new
02/18/2014 11:41:24;0002;PBS_Server;Svr;PBS_Server;Torque Server Version = 3.0.5, loglevel = 0
02/18/2014 11:41:43;0040;PBS_Server;Svr;tyrone-cluster;Scheduler was sent the command new
02/18/2014 11:41:50;0040;PBS_Server;Svr;tyrone-cluster;Scheduler was sent the command new
02/18/2014 11:42:17;0040;PBS_Server;Svr;tyrone-cluster;Scheduler was sent the command new
02/18/2014 11:42:45;0040;PBS_Server;Svr;tyrone-cluster;Scheduler was sent the command new
02/18/2014 11:42:47;0040;PBS_Server;Svr;tyrone-cluster;Scheduler was sent the command new
02/18/2014 11:42:53;0100;PBS_Server;Job;35224.tyrone-cluster;enqueuing into batch, state 1 hop 1
02/18/2014 11:42:53;0008;PBS_Server;Job;35224.tyrone-cluster;Job Queued at request of icrsanch@tyrone-cluster, owner = icrsanch@tyrone-cluster, job name = job256, queue = batch
02/18/2014 11:42:53;0040;PBS_Server;Svr;tyrone-cluster;Scheduler was sent the command new
02/18/2014 11:42:53;0008;PBS_Server;Job;35224.tyrone-cluster;Job Modified at request of Scheduler@tyrone-cluster
02/18/2014 11:43:16;0040;PBS_Server;Svr;tyrone-cluster;Scheduler was sent the command new
02/18/2014 11:43:20;0040;PBS_Server;Svr;tyrone-cluster;Scheduler was sent the command new
02/18/2014 11:43:24;0040;PBS_Server;Svr;tyrone-cluster;Scheduler was sent the command new
02/18/2014 11:43:47;0040;PBS_Server;Svr;tyrone-cluster;Scheduler was sent the command new
02/18/2014 11:43:54;0040;PBS_Server;Svr;tyrone-cluster;Scheduler was sent the command new
02/18/2014 11:44:17;0040;PBS_Server;Svr;tyrone-cluster;Scheduler was sent the command new
02/18/2014 11:44:24;0040;PBS_Server;Svr;tyrone-cluster;Scheduler was sent the command new
02/18/2014 11:44:50;0040;PBS_Server;Svr;tyrone-cluster;Scheduler was sent the command new
02/18/2014 11:44:56;0040;PBS_Server;Svr;tyrone-cluster;Scheduler was sent the command new
02/18/2014 11:45:24;0040;PBS_Server;Svr;tyrone-cluster;Scheduler was sent the command new
02/18/2014 11:45:28;0040;PBS_Server;Svr;tyrone-cluster;Scheduler was sent the command new
02/18/2014 11:45:51;0040;PBS_Server;Svr;tyrone-cluster;Scheduler was sent the command new
02/18/2014 11:46:02;0040;PBS_Server;Svr;tyrone-cluster;Scheduler was sent the command new
02/18/2014 11:46:20;0040;PBS_Server;Svr;tyrone-cluster;Scheduler was sent the command new
02/18/2014 11:46:24;0002;PBS_Server;Svr;PBS_Server;Torque Server Version = 3.0.5, loglevel = 0
02/18/2014 11:46:30;0040;PBS_Server;Svr;tyrone-cluster;Scheduler was sent the command new
02/18/2014 11:46:54;0040;PBS_Server;Svr;tyrone-cluster;Scheduler was sent the command new
02/18/2014 11:47:01;0040;PBS_Server;Svr;tyrone-cluster;Scheduler was sent the command new
02/18/2014 11:47:25;0040;PBS_Server;Svr;tyrone-cluster;Scheduler was sent the command new
02/18/2014 11:47:32;0040;PBS_Server;Svr;tyrone-cluster;Scheduler was sent the command new
02/18/2014 11:47:56;0040;PBS_Server;Svr;tyrone-cluster;Scheduler was sent the command new
02/18/2014 11:48:02;0040;PBS_Server;Svr;tyrone-cluster;Scheduler was sent the command new
02/18/2014 11:48:24;0040;PBS_Server;Svr;tyrone-cluster;Scheduler was sent the command new
02/18/2014 11:48:35;0040;PBS_Server;Svr;tyrone-cluster;Scheduler was sent the command new
02/18/2014 11:48:54;0040;PBS_Server;Svr;tyrone-cluster;Scheduler was sent the command new
02/18/2014 11:49:02;0040;PBS_Server;Svr;tyrone-cluster;Scheduler was sent the command new
02/18/2014 11:49:27;0040;PBS_Server;Svr;tyrone-cluster;Scheduler was sent the command new
02/18/2014 11:49:32;0040;PBS_Server;Svr;tyrone-cluster;Scheduler was sent the command new
02/18/2014 11:49:58;0040;PBS_Server;Svr;tyrone-cluster;Scheduler was sent the command new
02/18/2014 11:50:05;0040;PBS_Server;Svr;tyrone-cluster;Scheduler was sent the command new
02/18/2014 11:50:32;0040;PBS_Server;Svr;tyrone-cluster;Scheduler was sent the command new
02/18/2014 11:50:39;0040;PBS_Server;Svr;tyrone-cluster;Scheduler was sent the command new
02/18/2014 11:51:00;0040;PBS_Server;Svr;tyrone-cluster;Scheduler was sent the command new
02/18/2014 11:51:05;0040;PBS_Server;Svr;tyrone-cluster;Scheduler was sent the command new
02/18/2014 11:51:24;0002;PBS_Server;Svr;PBS_Server;Torque Server Version = 3.0.5, loglevel = 0
02/18/2014 11:51:31;0040;PBS_Server;Svr;tyrone-cluster;Scheduler was sent the command new
02/18/2014 11:51:35;0040;PBS_Server;Svr;tyrone-cluster;Scheduler was sent the command new
02/18/2014 11:52:03;0040;PBS_Server;Svr;tyrone-cluster;Scheduler was sent the command new
02/18/2014 11:52:09;0040;PBS_Server;Svr;tyrone-cluster;Scheduler was sent the command new
02/18/2014 11:52:32;0040;PBS_Server;Svr;tyrone-cluster;Scheduler was sent the command new
02/18/2014 11:52:35;0040;PBS_Server;Svr;tyrone-cluster;Scheduler was sent the command new
02/18/2014 11:52:42;0100;PBS_Server;Job;35225.tyrone-cluster;enqueuing into batch, state 1 hop 1
02/18/2014 11:52:42;0008;PBS_Server;Job;35225.tyrone-cluster;Job Queued at request of icrsanch@tyrone-cluster, owner = icrsanch@tyrone-cluster, job name = job256, queue = batch
02/18/2014 11:52:42;0040;PBS_Server;Svr;tyrone-cluster;Scheduler was sent the command new
02/18/2014 11:52:43;0008;PBS_Server;Job;35225.tyrone-cluster;Job Modified at request of Scheduler@tyrone-cluster
02/18/2014 11:53:05;0040;PBS_Server;Svr;tyrone-cluster;Scheduler was sent the command new
02/18/2014 11:53:10;0008;PBS_Server;Job;35223.tyrone-cluster;Job deleted at request of icrsanch@tyrone-cluster
02/18/2014 11:53:10;0008;PBS_Server;Job;NULL;on_job_exit valid pjob: 0x1dc8db0 (substate=59)
02/18/2014 11:53:10;0100;PBS_Server;Job;35223.tyrone-cluster;dequeuing from batch, state COMPLETE
02/18/2014 11:53:10;0040;PBS_Server;Svr;tyrone-cluster;Scheduler was sent the command term
02/18/2014 11:53:12;0040;PBS_Server;Svr;tyrone-cluster;Scheduler was sent the command new
02/18/2014 11:53:25;0008;PBS_Server;Job;35224.tyrone-cluster;Job deleted at request of icrsanch@tyrone-cluster
02/18/2014 11:53:25;0008;PBS_Server;Job;NULL;on_job_exit valid pjob: 0x1daf7c0 (substate=59)
02/18/2014 11:53:25;0100;PBS_Server;Job;35224.tyrone-cluster;dequeuing from batch, state COMPLETE
02/18/2014 11:53:25;0040;PBS_Server;Svr;tyrone-cluster;Scheduler was sent the command term
02/18/2014 11:53:32;0040;PBS_Server;Svr;tyrone-cluster;Scheduler was sent the command new
02/18/2014 11:53:43;0040;PBS_Server;Svr;tyrone-cluster;Scheduler was sent the command new
02/18/2014 11:54:02;0040;PBS_Server;Svr;tyrone-cluster;Scheduler was sent the command new
02/18/2014 11:54:17;0040;PBS_Server;Svr;tyrone-cluster;Scheduler was sent the command new
02/18/2014 11:54:35;0040;PBS_Server;Svr;tyrone-cluster;Scheduler was sent the command new
02/18/2014 11:54:35;0100;PBS_Server;Job;35226.tyrone-cluster;enqueuing into batch, state 1 hop 1
02/18/2014 11:54:35;0008;PBS_Server;Job;35226.tyrone-cluster;Job Queued at request of icrsanch@tyrone-cluster, owner = icrsanch@tyrone-cluster, job name = job256, queue = batch
02/18/2014 11:54:35;0008;PBS_Server;Job;35226.tyrone-cluster;Job Modified at request of Scheduler@tyrone-cluster
02/18/2014 11:54:45;0040;PBS_Server;Svr;tyrone-cluster;Scheduler was sent the command new
02/18/2014 11:55:09;0040;PBS_Server;Svr;tyrone-cluster;Scheduler was sent the command new
02/18/2014 11:55:16;0040;PBS_Server;Svr;tyrone-cluster;Scheduler was sent the command new
02/18/2014 11:55:40;0040;PBS_Server;Svr;tyrone-cluster;Scheduler was sent the command new
02/18/2014 11:55:48;0040;PBS_Server;Svr;tyrone-cluster;Scheduler was sent the command new
02/18/2014 11:56:09;0040;PBS_Server;Svr;tyrone-cluster;Scheduler was sent the command new
02/18/2014 11:56:17;0040;PBS_Server;Svr;tyrone-cluster;Scheduler was sent the command new
02/18/2014 11:56:24;0002;PBS_Server;Svr;PBS_Server;Torque Server Version = 3.0.5, loglevel = 0
02/18/2014 11:56:39;0040;PBS_Server;Svr;tyrone-cluster;Scheduler was sent the command new
02/18/2014 11:56:50;0040;PBS_Server;Svr;tyrone-cluster;Scheduler was sent the command new
02/18/2014 11:57:09;0040;PBS_Server;Svr;tyrone-cluster;Scheduler was sent the command new
02/18/2014 11:57:17;0040;PBS_Server;Svr;tyrone-cluster;Scheduler was sent the command new
02/18/2014 11:57:42;0040;PBS_Server;Svr;tyrone-cluster;Scheduler was sent the command new
02/18/2014 11:57:47;0040;PBS_Server;Svr;tyrone-cluster;Scheduler was sent the command new
02/18/2014 11:58:13;0040;PBS_Server;Svr;tyrone-cluster;Scheduler was sent the command new
02/18/2014 11:58:20;0040;PBS_Server;Svr;tyrone-cluster;Scheduler was sent the command new
02/18/2014 11:58:48;0040;PBS_Server;Svr;tyrone-cluster;Scheduler was sent the command new
02/18/2014 11:59:15;0040;PBS_Server;Svr;tyrone-cluster;Scheduler was sent the command new
02/18/2014 11:59:21;0040;PBS_Server;Svr;tyrone-cluster;Scheduler was sent the command new
02/18/2014 11:59:46;0040;PBS_Server;Svr;tyrone-cluster;Scheduler was sent the command new
02/18/2014 11:59:50;0040;PBS_Server;Svr;tyrone-cluster;Scheduler was sent the command new
02/18/2014 12:00:17;0040;PBS_Server;Svr;tyrone-cluster;Scheduler was sent the command new
02/18/2014 12:00:24;0040;PBS_Server;Svr;tyrone-cluster;Scheduler was sent the command new
02/18/2014 12:00:47;0040;PBS_Server;Svr;tyrone-cluster;Scheduler was sent the command new
02/18/2014 12:00:55;0040;PBS_Server;Svr;tyrone-cluster;Scheduler was sent the command new
02/18/2014 12:01:20;0040;PBS_Server;Svr;tyrone-cluster;Scheduler was sent the command new
02/18/2014 12:01:24;0002;PBS_Server;Svr;PBS_Server;Torque Server Version = 3.0.5, loglevel = 0
02/18/2014 12:01:24;0040;PBS_Server;Svr;tyrone-cluster;Scheduler was sent the command new
02/18/2014 12:01:48;0040;PBS_Server;Svr;tyrone-cluster;Scheduler was sent the command new
02/18/2014 12:01:53;000d;PBS_Server;Job;35148.tyrone-cluster;Not sending email: User does not want mail of this type.
02/18/2014 12:01:53;0010;PBS_Server;Job;35148.tyrone-cluster;Exit_status=143 resources_used.cput=166:41:13 resources_used.mem=457288kb resources_used.vmem=2909500kb resources_used.walltime=24:00:43
02/18/2014 12:01:53;0008;PBS_Server;Job;NULL;on_job_exit valid pjob: 0x1e2f5a0 (substate=50)
02/18/2014 12:01:53;0008;PBS_Server;Job;NULL;on_job_exit valid pjob: 0x1e2f5a0 (substate=51)
02/18/2014 12:01:53;0008;PBS_Server;Job;NULL;on_job_exit valid pjob: 0x1e2f5a0 (substate=51)
02/18/2014 12:01:53;0008;PBS_Server;Job;NULL;on_job_exit valid pjob: 0x1e2f5a0 (substate=53)
02/18/2014 12:01:53;0100;PBS_Server;Job;35148.tyrone-cluster;dequeuing from qp32, state COMPLETE
02/18/2014 12:01:53;0040;PBS_Server;Svr;tyrone-cluster;Scheduler was sent the command term
02/18/2014 12:01:54;0008;PBS_Server;Job;35193.tyrone-cluster;Job Modified at request of Scheduler@tyrone-cluster
02/18/2014 12:02:18;0040;PBS_Server;Svr;tyrone-cluster;Scheduler was sent the command new
02/18/2014 12:02:25;0040;PBS_Server;Svr;tyrone-cluster;Scheduler was sent the command new
02/18/2014 12:02:50;0040;PBS_Server;Svr;tyrone-cluster;Scheduler was sent the command new
02/18/2014 12:02:54;0040;PBS_Server;Svr;tyrone-cluster;Scheduler was sent the command new
02/18/2014 12:03:24;0040;PBS_Server;Svr;tyrone-cluster;Scheduler was sent the command new
02/18/2014 12:03:51;0040;PBS_Server;Svr;tyrone-cluster;Scheduler was sent the command new
02/18/2014 12:03:54;0040;PBS_Server;Svr;tyrone-cluster;Scheduler was sent the command new
02/18/2014 12:04:20;0040;PBS_Server;Svr;tyrone-cluster;Scheduler was sent the command new
02/18/2014 12:04:26;0040;PBS_Server;Svr;tyrone-cluster;Scheduler was sent the command new
02/18/2014 12:04:50;0040;PBS_Server;Svr;tyrone-cluster;Scheduler was sent the command new
02/18/2014 12:04:54;0040;PBS_Server;Svr;tyrone-cluster;Scheduler was sent the command new
02/18/2014 12:05:21;0040;PBS_Server;Svr;tyrone-cluster;Scheduler was sent the command new
02/18/2014 12:05:24;0040;PBS_Server;Svr;tyrone-cluster;Scheduler was sent the command new
02/18/2014 12:05:50;0040;PBS_Server;Svr;tyrone-cluster;Scheduler was sent the command new
02/18/2014 12:05:56;0040;PBS_Server;Svr;tyrone-cluster;Scheduler was sent the command new
02/18/2014 12:06:24;0002;PBS_Server;Svr;PBS_Server;Torque Server Version = 3.0.5, loglevel = 0
02/18/2014 12:06:24;0040;PBS_Server;Svr;tyrone-cluster;Scheduler was sent the command new
02/18/2014 12:06:55;0040;PBS_Server;Svr;tyrone-cluster;Scheduler was sent the command new
02/18/2014 12:07:24;0040;PBS_Server;Svr;tyrone-cluster;Scheduler was sent the command new
02/18/2014 12:07:54;0040;PBS_Server;Svr;tyrone-cluster;Scheduler was sent the command new
02/18/2014 12:08:25;0040;PBS_Server;Svr;tyrone-cluster;Scheduler was sent the command new
02/18/2014 12:08:54;0040;PBS_Server;Svr;tyrone-cluster;Scheduler was sent the command new
02/18/2014 12:09:24;0040;PBS_Server;Svr;tyrone-cluster;Scheduler was sent the command new
02/18/2014 12:09:54;0040;PBS_Server;Svr;tyrone-cluster;Scheduler was sent the command new
02/18/2014 12:10:24;0040;PBS_Server;Svr;tyrone-cluster;Scheduler was sent the command new
02/18/2014 12:10:54;0040;PBS_Server;Svr;tyrone-cluster;Scheduler was sent the command new
02/18/2014 12:11:24;0002;PBS_Server;Svr;PBS_Server;Torque Server Version = 3.0.5, loglevel = 0
02/18/2014 12:11:25;0040;PBS_Server;Svr;tyrone-cluster;Scheduler was sent the command new
02/18/2014 12:11:54;0040;PBS_Server;Svr;tyrone-cluster;Scheduler was sent the command new
02/18/2014 12:12:24;0040;PBS_Server;Svr;tyrone-cluster;Scheduler was sent the command new
02/18/2014 12:12:55;0040;PBS_Server;Svr;tyrone-cluster;Scheduler was sent the command new
02/18/2014 12:13:23;0100;PBS_Server;Job;35227.tyrone-cluster;enqueuing into batch, state 1 hop 1
02/18/2014 12:13:23;0008;PBS_Server;Job;35227.tyrone-cluster;Job Queued at request of icrsanch@tyrone-cluster, owner = icrsanch@tyrone-cluster, job name = job256, queue = batch
02/18/2014 12:13:23;0040;PBS_Server;Svr;tyrone-cluster;Scheduler was sent the command new
02/18/2014 12:13:23;0008;PBS_Server;Job;35227.tyrone-cluster;Job Modified at request of Scheduler@tyrone-cluster
02/18/2014 12:13:24;0040;PBS_Server;Svr;tyrone-cluster;Scheduler was sent the command new
02/18/2014 12:13:37;0100;PBS_Server;Job;35228.tyrone-cluster;enqueuing into batch, state 1 hop 1
02/18/2014 12:13:37;0008;PBS_Server;Job;35228.tyrone-cluster;Job Queued at request of icrsanch@tyrone-cluster, owner = icrsanch@tyrone-cluster, job name = job256, queue = batch
02/18/2014 12:13:37;0040;PBS_Server;Svr;tyrone-cluster;Scheduler was sent the command new
02/18/2014 12:13:37;0008;PBS_Server;Job;35228.tyrone-cluster;Job Modified at request of Scheduler@tyrone-cluster
02/18/2014 12:13:54;0040;PBS_Server;Svr;tyrone-cluster;Scheduler was sent the command new
02/18/2014 12:14:09;0040;PBS_Server;Svr;tyrone-cluster;Scheduler was sent the command new
02/18/2014 12:14:25;0040;PBS_Server;Svr;tyrone-cluster;Scheduler was sent the command new
02/18/2014 12:14:39;0040;PBS_Server;Svr;tyrone-cluster;Scheduler was sent the command new
02/18/2014 12:14:57;0040;PBS_Server;Svr;tyrone-cluster;Scheduler was sent the command new
02/18/2014 12:15:09;0040;PBS_Server;Svr;tyrone-cluster;Scheduler was sent the command new
02/18/2014 12:15:29;0040;PBS_Server;Svr;tyrone-cluster;Scheduler was sent the command new
02/18/2014 12:15:39;0040;PBS_Server;Svr;tyrone-cluster;Scheduler was sent the command new
02/18/2014 12:15:51;0100;PBS_Server;Job;35229.tyrone-cluster;enqueuing into batch, state 1 hop 1
02/18/2014 12:15:51;0100;PBS_Server;Job;35229.tyrone-cluster;dequeuing from batch, state QUEUED
02/18/2014 12:15:51;0100;PBS_Server;Job;35229.tyrone-cluster;enqueuing into qp32, state 1 hop 1
02/18/2014 12:15:51;0008;PBS_Server;Job;35229.tyrone-cluster;Job Queued at request of csdshiku@tyrone-cluster, owner = csdshiku@tyrone-cluster, job name = script32.sh, queue = qp32
02/18/2014 12:15:51;0040;PBS_Server;Svr;tyrone-cluster;Scheduler was sent the command new
02/18/2014 12:15:51;0008;PBS_Server;Job;35229.tyrone-cluster;Job Modified at request of Scheduler@tyrone-cluster
02/18/2014 12:15:51;0008;PBS_Server;Job;35229.tyrone-cluster;Job Run at request of Scheduler@tyrone-cluster
02/18/2014 12:15:51;0040;PBS_Server;Svr;tyrone-cluster;Scheduler was sent the command recyc
02/18/2014 12:15:51;000d;PBS_Server;Job;35229.tyrone-cluster;Not sending email: User does not want mail of this type.
02/18/2014 12:16:03;0040;PBS_Server;Svr;tyrone-cluster;Scheduler was sent the command new
02/18/2014 12:16:03;0008;PBS_Server;Job;35193.tyrone-cluster;Job Modified at request of Scheduler@tyrone-cluster
02/18/2014 12:16:09;0040;PBS_Server;Svr;tyrone-cluster;Scheduler was sent the command new
02/18/2014 12:16:24;0002;PBS_Server;Svr;PBS_Server;Torque Server Version = 3.0.5, loglevel = 0
02/18/2014 12:16:30;0040;PBS_Server;Svr;tyrone-cluster;Scheduler was sent the command new
02/18/2014 12:16:39;0040;PBS_Server;Svr;tyrone-cluster;Scheduler was sent the command new
02/18/2014 12:17:01;0040;PBS_Server;Svr;tyrone-cluster;Scheduler was sent the command new
02/18/2014 12:17:12;0040;PBS_Server;Svr;tyrone-cluster;Scheduler was sent the command new
02/18/2014 12:17:33;0040;PBS_Server;Svr;tyrone-cluster;Scheduler was sent the command new
02/18/2014 12:17:44;0040;PBS_Server;Svr;tyrone-cluster;Scheduler was sent the command new
02/18/2014 12:18:06;0040;PBS_Server;Svr;tyrone-cluster;Scheduler was sent the command new
02/18/2014 12:18:18;0040;PBS_Server;Svr;tyrone-cluster;Scheduler was sent the command new
02/18/2014 12:18:35;0040;PBS_Server;Svr;tyrone-cluster;Scheduler was sent the command new
02/18/2014 12:18:45;0040;PBS_Server;Svr;tyrone-cluster;Scheduler was sent the command new
02/18/2014 12:19:09;0040;PBS_Server;Svr;tyrone-cluster;Scheduler was sent the command new
02/18/2014 12:19:16;0040;PBS_Server;Svr;tyrone-cluster;Scheduler was sent the command new
02/18/2014 12:19:35;0040;PBS_Server;Svr;tyrone-cluster;Scheduler was sent the command new
02/18/2014 12:19:47;0040;PBS_Server;Svr;tyrone-cluster;Scheduler was sent the command new
02/18/2014 12:20:05;0040;PBS_Server;Svr;tyrone-cluster;Scheduler was sent the command new
02/18/2014 12:20:17;0040;PBS_Server;Svr;tyrone-cluster;Scheduler was sent the command new
02/18/2014 12:20:39;0040;PBS_Server;Svr;tyrone-cluster;Scheduler was sent the command new
02/18/2014 12:20:50;0040;PBS_Server;Svr;tyrone-cluster;Scheduler was sent the command new
02/18/2014 12:21:06;0040;PBS_Server;Svr;tyrone-cluster;Scheduler was sent the command new
02/18/2014 12:21:17;0040;PBS_Server;Svr;tyrone-cluster;Scheduler was sent the command new
02/18/2014 12:21:24;0002;PBS_Server;Svr;PBS_Server;Torque Server Version = 3.0.5, loglevel = 0
02/18/2014 12:21:39;0040;PBS_Server;Svr;tyrone-cluster;Scheduler was sent the command new
02/18/2014 12:21:44;000d;PBS_Server;Job;35150.tyrone-cluster;Not sending email: User does not want mail of this type.
02/18/2014 12:21:44;0010;PBS_Server;Job;35150.tyrone-cluster;Exit_status=143 resources_used.cput=1536:11:27 resources_used.mem=1349820kb resources_used.vmem=35022904kb resources_used.walltime=24:00:42
02/18/2014 12:21:44;0008;PBS_Server;Job;NULL;on_job_exit valid pjob: 0x1e584e0 (substate=50)
02/18/2014 12:21:44;0008;PBS_Server;Job;NULL;on_job_exit valid pjob: 0x1e584e0 (substate=51)
02/18/2014 12:21:45;0008;PBS_Server;Job;NULL;on_job_exit valid pjob: 0x1e584e0 (substate=51)
02/18/2014 12:21:45;0008;PBS_Server;Job;NULL;on_job_exit valid pjob: 0x1e584e0 (substate=53)
02/18/2014 12:21:45;0100;PBS_Server;Job;35150.tyrone-cluster;dequeuing from qp64, state COMPLETE
02/18/2014 12:21:45;0040;PBS_Server;Svr;tyrone-cluster;Scheduler was sent the command term
02/18/2014 12:21:45;0008;PBS_Server;Job;35134.tyrone-cluster;Job Modified at request of Scheduler@tyrone-cluster
02/18/2014 12:21:45;0008;PBS_Server;Job;35184.tyrone-cluster;Job Modified at request of Scheduler@tyrone-cluster
02/18/2014 12:21:45;0008;PBS_Server;Job;35184.tyrone-cluster;Job Run at request of Scheduler@tyrone-cluster
02/18/2014 12:21:45;0040;PBS_Server;Svr;tyrone-cluster;Scheduler was sent the command recyc
02/18/2014 12:21:45;000d;PBS_Server;Job;35184.tyrone-cluster;Not sending email: User does not want mail of this type.
02/18/2014 12:21:47;0040;PBS_Server;Svr;tyrone-cluster;Scheduler was sent the command new
02/18/2014 12:21:47;0008;PBS_Server;Job;35134.tyrone-cluster;Job Modified at request of Scheduler@tyrone-cluster
02/18/2014 12:21:53;000d;PBS_Server;Job;35184.tyrone-cluster;Not sending email: User does not want mail of this type.
02/18/2014 12:21:53;0010;PBS_Server;Job;35184.tyrone-cluster;Exit_status=0 resources_used.cput=00:00:00 resources_used.mem=0kb resources_used.vmem=0kb resources_used.walltime=00:00:08
02/18/2014 12:21:53;0008;PBS_Server;Job;NULL;on_job_exit valid pjob: 0x1e1b0a0 (substate=50)
02/18/2014 12:21:53;0008;PBS_Server;Job;NULL;on_job_exit valid pjob: 0x1e1b0a0 (substate=51)
02/18/2014 12:21:53;0008;PBS_Server;Job;NULL;on_job_exit valid pjob: 0x1e1b0a0 (substate=51)
02/18/2014 12:21:53;0008;PBS_Server;Job;NULL;on_job_exit valid pjob: 0x1e1b0a0 (substate=53)
02/18/2014 12:21:53;0100;PBS_Server;Job;35184.tyrone-cluster;dequeuing from qp64, state COMPLETE
02/18/2014 12:21:53;0040;PBS_Server;Svr;tyrone-cluster;Scheduler was sent the command term
02/18/2014 12:21:53;0008;PBS_Server;Job;35134.tyrone-cluster;Job Modified at request of Scheduler@tyrone-cluster
02/18/2014 12:21:53;0008;PBS_Server;Job;35135.tyrone-cluster;Job Modified at request of Scheduler@tyrone-cluster
02/18/2014 12:21:53;0008;PBS_Server;Job;35206.tyrone-cluster;Job Modified at request of Scheduler@tyrone-cluster
02/18/2014 12:21:53;0008;PBS_Server;Job;35206.tyrone-cluster;Job Run at request of Scheduler@tyrone-cluster
02/18/2014 12:21:53;0040;PBS_Server;Svr;tyrone-cluster;Scheduler was sent the command recyc
02/18/2014 12:21:53;000d;PBS_Server;Job;35206.tyrone-cluster;Not sending email: User does not want mail of this type.
02/18/2014 12:22:09;0040;PBS_Server;Svr;tyrone-cluster;Scheduler was sent the command new
02/18/2014 12:22:10;0008;PBS_Server;Job;35134.tyrone-cluster;Job Modified at request of Scheduler@tyrone-cluster
02/18/2014 12:22:10;0008;PBS_Server;Job;35135.tyrone-cluster;Job Modified at request of Scheduler@tyrone-cluster
02/18/2014 12:22:20;0040;PBS_Server;Svr;tyrone-cluster;Scheduler was sent the command new
02/18/2014 12:22:40;0040;PBS_Server;Svr;tyrone-cluster;Scheduler was sent the command new
02/18/2014 12:22:48;0040;PBS_Server;Svr;tyrone-cluster;Scheduler was sent the command new
02/18/2014 12:23:09;0040;PBS_Server;Svr;tyrone-cluster;Scheduler was sent the command new
02/18/2014 12:23:21;0040;PBS_Server;Svr;tyrone-cluster;Scheduler was sent the command new
02/18/2014 12:23:39;0040;PBS_Server;Svr;tyrone-cluster;Scheduler was sent the command new
02/18/2014 12:23:54;0040;PBS_Server;Svr;tyrone-cluster;Scheduler was sent the command new
02/18/2014 12:24:09;0040;PBS_Server;Svr;tyrone-cluster;Scheduler was sent the command new
02/18/2014 12:24:24;0040;PBS_Server;Svr;tyrone-cluster;Scheduler was sent the command new
02/18/2014 12:24:39;0040;PBS_Server;Svr;tyrone-cluster;Scheduler was sent the command new
02/18/2014 12:24:55;0040;PBS_Server;Svr;tyrone-cluster;Scheduler was sent the command new
02/18/2014 12:25:09;0040;PBS_Server;Svr;tyrone-cluster;Scheduler was sent the command new
02/18/2014 12:25:27;0040;PBS_Server;Svr;tyrone-cluster;Scheduler was sent the command new
02/18/2014 12:25:39;0040;PBS_Server;Svr;tyrone-cluster;Scheduler was sent the command new
02/18/2014 12:25:59;0040;PBS_Server;Svr;tyrone-cluster;Scheduler was sent the command new
02/18/2014 12:26:09;0040;PBS_Server;Svr;tyrone-cluster;Scheduler was sent the command new
02/18/2014 12:26:24;0002;PBS_Server;Svr;PBS_Server;Torque Server Version = 3.0.5, loglevel = 0
02/18/2014 12:26:32;0040;PBS_Server;Svr;tyrone-cluster;Scheduler was sent the command new
02/18/2014 12:26:39;0040;PBS_Server;Svr;tyrone-cluster;Scheduler was sent the command new
02/18/2014 12:27:00;0040;PBS_Server;Svr;tyrone-cluster;Scheduler was sent the command new
02/18/2014 12:27:10;0040;PBS_Server;Svr;tyrone-cluster;Scheduler was sent the command new
02/18/2014 12:27:29;0040;PBS_Server;Svr;tyrone-cluster;Scheduler was sent the command new
02/18/2014 12:27:39;0040;PBS_Server;Svr;tyrone-cluster;Scheduler was sent the command new
02/18/2014 12:28:02;0040;PBS_Server;Svr;tyrone-cluster;Scheduler was sent the command new
02/18/2014 12:28:09;0040;PBS_Server;Svr;tyrone-cluster;Scheduler was sent the command new
02/18/2014 12:28:32;0040;PBS_Server;Svr;tyrone-cluster;Scheduler was sent the command new
02/18/2014 12:28:40;0040;PBS_Server;Svr;tyrone-cluster;Scheduler was sent the command new
02/18/2014 12:29:01;0040;PBS_Server;Svr;tyrone-cluster;Scheduler was sent the command new
02/18/2014 12:29:12;0040;PBS_Server;Svr;tyrone-cluster;Scheduler was sent the command new
02/18/2014 12:29:35;0040;PBS_Server;Svr;tyrone-cluster;Scheduler was sent the command new
02/18/2014 12:29:44;0040;PBS_Server;Svr;tyrone-cluster;Scheduler was sent the command new
02/18/2014 12:30:06;0040;PBS_Server;Svr;tyrone-cluster;Scheduler was sent the command new
02/18/2014 12:30:17;0040;PBS_Server;Svr;tyrone-cluster;Scheduler was sent the command new
02/18/2014 12:30:35;0040;PBS_Server;Svr;tyrone-cluster;Scheduler was sent the command new
02/18/2014 12:30:47;0040;PBS_Server;Svr;tyrone-cluster;Scheduler was sent the command new
02/18/2014 12:31:07;0040;PBS_Server;Svr;tyrone-cluster;Scheduler was sent the command new
02/18/2014 12:31:16;0040;PBS_Server;Svr;tyrone-cluster;Scheduler was sent the command new
02/18/2014 12:31:24;0002;PBS_Server;Svr;PBS_Server;Torque Server Version = 3.0.5, loglevel = 0
02/18/2014 12:31:36;0040;PBS_Server;Svr;tyrone-cluster;Scheduler was sent the command new
02/18/2014 12:31:48;0040;PBS_Server;Svr;tyrone-cluster;Scheduler was sent the command new
02/18/2014 12:32:09;0040;PBS_Server;Svr;tyrone-cluster;Scheduler was sent the command new
02/18/2014 12:32:21;0040;PBS_Server;Svr;tyrone-cluster;Scheduler was sent the command new
02/18/2014 12:32:39;0040;PBS_Server;Svr;tyrone-cluster;Scheduler was sent the command new
02/18/2014 12:32:54;0040;PBS_Server;Svr;tyrone-cluster;Scheduler was sent the command new
02/18/2014 12:33:09;0040;PBS_Server;Svr;tyrone-cluster;Scheduler was sent the command new
02/18/2014 12:33:24;0040;PBS_Server;Svr;tyrone-cluster;Scheduler was sent the command new
02/18/2014 12:33:40;0040;PBS_Server;Svr;tyrone-cluster;Scheduler was sent the command new
02/18/2014 12:33:55;0040;PBS_Server;Svr;tyrone-cluster;Scheduler was sent the command new
02/18/2014 12:34:00;0080;PBS_Server;Job;53094.tyrone-cluster;Unknown Job Id
02/18/2014 12:34:00;0080;PBS_Server;Req;req_reject;Reject reply code=15001(Unknown Job Id), aux=0, type=DeleteJob, from chevadh@tyrone-node5
02/18/2014 12:34:00;0080;PBS_Server;Req;req_reject;Reject reply code=15001(Unknown Job Id), aux=0, type=LocateJob, from chevadh@tyrone-node5
02/18/2014 12:34:09;0040;PBS_Server;Svr;tyrone-cluster;Scheduler was sent the command new
02/18/2014 12:34:24;0040;PBS_Server;Svr;tyrone-cluster;Scheduler was sent the command new
02/18/2014 12:34:40;0040;PBS_Server;Svr;tyrone-cluster;Scheduler was sent the command new
02/18/2014 12:34:54;0040;PBS_Server;Svr;tyrone-cluster;Scheduler was sent the command new
02/18/2014 12:35:10;0040;PBS_Server;Svr;tyrone-cluster;Scheduler was sent the command new
02/18/2014 12:35:25;0040;PBS_Server;Svr;tyrone-cluster;Scheduler was sent the command new
02/18/2014 12:35:39;0040;PBS_Server;Svr;tyrone-cluster;Scheduler was sent the command new
02/18/2014 12:35:54;0040;PBS_Server;Svr;tyrone-cluster;Scheduler was sent the command new
02/18/2014 12:36:09;0040;PBS_Server;Svr;tyrone-cluster;Scheduler was sent the command new
02/18/2014 12:36:24;0002;PBS_Server;Svr;PBS_Server;Torque Server Version = 3.0.5, loglevel = 0
02/18/2014 12:36:24;0040;PBS_Server;Svr;tyrone-cluster;Scheduler was sent the command new
02/18/2014 12:36:41;0040;PBS_Server;Svr;tyrone-cluster;Scheduler was sent the command new
02/18/2014 12:36:55;0040;PBS_Server;Svr;tyrone-cluster;Scheduler was sent the command new
02/18/2014 12:37:09;0040;PBS_Server;Svr;tyrone-cluster;Scheduler was sent the command new
02/18/2014 12:37:27;0040;PBS_Server;Svr;tyrone-cluster;Scheduler was sent the command new
02/18/2014 12:37:39;0040;PBS_Server;Svr;tyrone-cluster;Scheduler was sent the command new
02/18/2014 12:37:59;0040;PBS_Server;Svr;tyrone-cluster;Scheduler was sent the command new
02/18/2014 12:38:09;0040;PBS_Server;Svr;tyrone-cluster;Scheduler was sent the command new
02/18/2014 12:38:33;0040;PBS_Server;Svr;tyrone-cluster;Scheduler was sent the command new
02/18/2014 12:38:39;0040;PBS_Server;Svr;tyrone-cluster;Scheduler was sent the command new
02/18/2014 12:39:02;0040;PBS_Server;Svr;tyrone-cluster;Scheduler was sent the command new
02/18/2014 12:39:10;0040;PBS_Server;Svr;tyrone-cluster;Scheduler was sent the command new
02/18/2014 12:39:31;0040;PBS_Server;Svr;tyrone-cluster;Scheduler was sent the command new
02/18/2014 12:39:41;0040;PBS_Server;Svr;tyrone-cluster;Scheduler was sent the command new
02/18/2014 12:40:03;0040;PBS_Server;Svr;tyrone-cluster;Scheduler was sent the command new
02/18/2014 12:40:09;0040;PBS_Server;Svr;tyrone-cluster;Scheduler was sent the command new
02/18/2014 12:40:36;0040;PBS_Server;Svr;tyrone-cluster;Scheduler was sent the command new
02/18/2014 12:40:39;0040;PBS_Server;Svr;tyrone-cluster;Scheduler was sent the command new
02/18/2014 12:41:09;0040;PBS_Server;Svr;tyrone-cluster;Scheduler was sent the command new
02/18/2014 12:41:24;0002;PBS_Server;Svr;PBS_Server;Torque Server Version = 3.0.5, loglevel = 0
02/18/2014 12:41:39;0040;PBS_Server;Svr;tyrone-cluster;Scheduler was sent the command new
02/18/2014 12:42:10;0040;PBS_Server;Svr;tyrone-cluster;Scheduler was sent the command new
02/18/2014 12:42:41;0040;PBS_Server;Svr;tyrone-cluster;Scheduler was sent the command new
02/18/2014 12:43:13;0040;PBS_Server;Svr;tyrone-cluster;Scheduler was sent the command new
02/18/2014 12:43:40;0040;PBS_Server;Svr;tyrone-cluster;Scheduler was sent the command new
02/18/2014 12:44:12;0040;PBS_Server;Svr;tyrone-cluster;Scheduler was sent the command new
02/18/2014 12:44:44;0040;PBS_Server;Svr;tyrone-cluster;Scheduler was sent the command new
02/18/2014 12:45:18;0040;PBS_Server;Svr;tyrone-cluster;Scheduler was sent the command new
02/18/2014 12:45:47;0040;PBS_Server;Svr;tyrone-cluster;Scheduler was sent the command new
02/18/2014 12:45:54;0100;PBS_Server;Job;35230.tyrone-cluster;enqueuing into batch, state 1 hop 1
02/18/2014 12:45:54;0100;PBS_Server;Job;35230.tyrone-cluster;dequeuing from batch, state QUEUED
02/18/2014 12:45:54;0100;PBS_Server;Job;35230.tyrone-cluster;enqueuing into idqueue, state 1 hop 1
02/18/2014 12:45:54;0008;PBS_Server;Job;35230.tyrone-cluster;Job Queued at request of metsomya@tyrone-cluster, owner = metsomya@tyrone-cluster, job name = poshit1, queue = idqueue
02/18/2014 12:45:54;0040;PBS_Server;Svr;tyrone-cluster;Scheduler was sent the command new
02/18/2014 12:45:54;0008;PBS_Server;Job;35230.tyrone-cluster;Job Modified at request of Scheduler@tyrone-cluster
02/18/2014 12:45:54;0008;PBS_Server;Job;35230.tyrone-cluster;Job Run at request of Scheduler@tyrone-cluster
02/18/2014 12:45:54;0040;PBS_Server;Svr;tyrone-cluster;Scheduler was sent the command recyc
02/18/2014 12:45:54;000d;PBS_Server;Job;35230.tyrone-cluster;Not sending email: User does not want mail of this type.
02/18/2014 12:46:16;0040;PBS_Server;Svr;tyrone-cluster;Scheduler was sent the command new
02/18/2014 12:46:24;0002;PBS_Server;Svr;PBS_Server;Torque Server Version = 3.0.5, loglevel = 0
02/18/2014 12:46:48;0040;PBS_Server;Svr;tyrone-cluster;Scheduler was sent the command new
02/18/2014 12:46:55;000d;PBS_Server;Job;35230.tyrone-cluster;Not sending email: User does not want mail of this type.
02/18/2014 12:46:55;0010;PBS_Server;Job;35230.tyrone-cluster;Exit_status=0 resources_used.cput=00:26:36 resources_used.mem=853892kb resources_used.vmem=10100728kb resources_used.walltime=00:01:01
02/18/2014 12:46:55;0008;PBS_Server;Job;NULL;on_job_exit valid pjob: 0x1e584e0 (substate=50)
02/18/2014 12:46:55;0008;PBS_Server;Job;NULL;on_job_exit valid pjob: 0x1e584e0 (substate=51)
02/18/2014 12:46:56;0008;PBS_Server;Job;NULL;on_job_exit valid pjob: 0x1e584e0 (substate=51)
02/18/2014 12:46:56;0008;PBS_Server;Job;NULL;on_job_exit valid pjob: 0x1e584e0 (substate=53)
02/18/2014 12:46:56;0100;PBS_Server;Job;35230.tyrone-cluster;dequeuing from idqueue, state COMPLETE
02/18/2014 12:46:56;0040;PBS_Server;Svr;tyrone-cluster;Scheduler was sent the command term
02/18/2014 12:47:21;0040;PBS_Server;Svr;tyrone-cluster;Scheduler was sent the command new
02/18/2014 12:47:54;0040;PBS_Server;Svr;tyrone-cluster;Scheduler was sent the command new
02/18/2014 12:48:24;0040;PBS_Server;Svr;tyrone-cluster;Scheduler was sent the command new
02/18/2014 12:48:55;0040;PBS_Server;Svr;tyrone-cluster;Scheduler was sent the command new
02/18/2014 12:48:55;0100;PBS_Server;Job;35231.tyrone-cluster;enqueuing into batch, state 1 hop 1
02/18/2014 12:48:55;0100;PBS_Server;Job;35231.tyrone-cluster;dequeuing from batch, state QUEUED
02/18/2014 12:48:55;0100;PBS_Server;Job;35231.tyrone-cluster;enqueuing into idqueue, state 1 hop 1
02/18/2014 12:48:55;0008;PBS_Server;Job;35231.tyrone-cluster;Job Queued at request of metsomya@tyrone-cluster, owner = metsomya@tyrone-cluster, job name = poshit1, queue = idqueue
02/18/2014 12:48:55;0040;PBS_Server;Svr;tyrone-cluster;Scheduler was sent the command new
02/18/2014 12:48:55;0008;PBS_Server;Job;35231.tyrone-cluster;Job Modified at request of Scheduler@tyrone-cluster
02/18/2014 12:48:55;0008;PBS_Server;Job;35231.tyrone-cluster;Job Run at request of Scheduler@tyrone-cluster
02/18/2014 12:48:55;0040;PBS_Server;Svr;tyrone-cluster;Scheduler was sent the command recyc
02/18/2014 12:48:55;000d;PBS_Server;Job;35231.tyrone-cluster;Not sending email: User does not want mail of this type.
02/18/2014 12:49:27;0040;PBS_Server;Svr;tyrone-cluster;Scheduler was sent the command new
02/18/2014 12:49:59;0040;PBS_Server;Svr;tyrone-cluster;Scheduler was sent the command new
02/18/2014 12:50:29;0040;PBS_Server;Svr;tyrone-cluster;Scheduler was sent the command new
02/18/2014 12:50:57;000d;PBS_Server;Job;35231.tyrone-cluster;Not sending email: User does not want mail of this type.
02/18/2014 12:50:57;0010;PBS_Server;Job;35231.tyrone-cluster;Exit_status=0 resources_used.cput=00:45:08 resources_used.mem=1294984kb resources_used.vmem=10247948kb resources_used.walltime=00:02:02
02/18/2014 12:50:57;0008;PBS_Server;Job;NULL;on_job_exit valid pjob: 0x1e584e0 (substate=50)
02/18/2014 12:50:57;0008;PBS_Server;Job;NULL;on_job_exit valid pjob: 0x1e584e0 (substate=51)
02/18/2014 12:50:58;0008;PBS_Server;Job;NULL;on_job_exit valid pjob: 0x1e584e0 (substate=51)
02/18/2014 12:50:58;0008;PBS_Server;Job;NULL;on_job_exit valid pjob: 0x1e584e0 (substate=53)
02/18/2014 12:50:58;0100;PBS_Server;Job;35231.tyrone-cluster;dequeuing from idqueue, state COMPLETE
02/18/2014 12:50:58;0040;PBS_Server;Svr;tyrone-cluster;Scheduler was sent the command term
02/18/2014 12:51:24;0002;PBS_Server;Svr;PBS_Server;Torque Server Version = 3.0.5, loglevel = 0
02/18/2014 12:51:29;0040;PBS_Server;Svr;tyrone-cluster;Scheduler was sent the command new
02/18/2014 12:52:02;0040;PBS_Server;Svr;tyrone-cluster;Scheduler was sent the command new
02/18/2014 12:52:30;0040;PBS_Server;Svr;tyrone-cluster;Scheduler was sent the command new
02/18/2014 12:52:59;0040;PBS_Server;Svr;tyrone-cluster;Scheduler was sent the command new
02/18/2014 12:53:33;0040;PBS_Server;Svr;tyrone-cluster;Scheduler was sent the command new
02/18/2014 12:54:00;0040;PBS_Server;Svr;tyrone-cluster;Scheduler was sent the command new
02/18/2014 12:54:31;0040;PBS_Server;Svr;tyrone-cluster;Scheduler was sent the command new
02/18/2014 12:54:54;0100;PBS_Server;Job;35232.tyrone-cluster;enqueuing into batch, state 1 hop 1
02/18/2014 12:54:54;0100;PBS_Server;Job;35232.tyrone-cluster;dequeuing from batch, state QUEUED
02/18/2014 12:54:54;0100;PBS_Server;Job;35232.tyrone-cluster;enqueuing into idqueue, state 1 hop 1
02/18/2014 12:54:54;0008;PBS_Server;Job;35232.tyrone-cluster;Job Queued at request of metsomya@tyrone-cluster, owner = metsomya@tyrone-cluster, job name = poshit1, queue = idqueue
02/18/2014 12:54:54;0040;PBS_Server;Svr;tyrone-cluster;Scheduler was sent the command new
02/18/2014 12:54:54;0008;PBS_Server;Job;35232.tyrone-cluster;Job Modified at request of Scheduler@tyrone-cluster
02/18/2014 12:54:54;0008;PBS_Server;Job;35232.tyrone-cluster;Job Run at request of Scheduler@tyrone-cluster
02/18/2014 12:54:54;0040;PBS_Server;Svr;tyrone-cluster;Scheduler was sent the command recyc
02/18/2014 12:54:54;000d;PBS_Server;Job;35232.tyrone-cluster;Not sending email: User does not want mail of this type.
02/18/2014 12:55:02;0040;PBS_Server;Svr;tyrone-cluster;Scheduler was sent the command new
02/18/2014 12:55:32;0040;PBS_Server;Svr;tyrone-cluster;Scheduler was sent the command new
02/18/2014 12:56:05;0040;PBS_Server;Svr;tyrone-cluster;Scheduler was sent the command new
02/18/2014 12:56:24;0002;PBS_Server;Svr;PBS_Server;Torque Server Version = 3.0.5, loglevel = 0
02/18/2014 12:56:33;0040;PBS_Server;Svr;tyrone-cluster;Scheduler was sent the command new
02/18/2014 12:57:02;0040;PBS_Server;Svr;tyrone-cluster;Scheduler was sent the command new
02/18/2014 12:57:11;000d;PBS_Server;Job;35232.tyrone-cluster;Not sending email: User does not want mail of this type.
02/18/2014 12:57:11;0010;PBS_Server;Job;35232.tyrone-cluster;Exit_status=0 resources_used.cput=01:06:42 resources_used.mem=2320144kb resources_used.vmem=13120720kb resources_used.walltime=00:02:17
02/18/2014 12:57:11;0008;PBS_Server;Job;NULL;on_job_exit valid pjob: 0x1e584e0 (substate=50)
02/18/2014 12:57:11;0008;PBS_Server;Job;NULL;on_job_exit valid pjob: 0x1e584e0 (substate=51)
02/18/2014 12:57:11;0008;PBS_Server;Job;NULL;on_job_exit valid pjob: 0x1e584e0 (substate=51)
02/18/2014 12:57:11;0008;PBS_Server;Job;NULL;on_job_exit valid pjob: 0x1e584e0 (substate=53)
02/18/2014 12:57:11;0100;PBS_Server;Job;35232.tyrone-cluster;dequeuing from idqueue, state COMPLETE
02/18/2014 12:57:11;0040;PBS_Server;Svr;tyrone-cluster;Scheduler was sent the command term
02/18/2014 12:57:35;0040;PBS_Server;Svr;tyrone-cluster;Scheduler was sent the command new
02/18/2014 12:58:03;0040;PBS_Server;Svr;tyrone-cluster;Scheduler was sent the command new
02/18/2014 12:58:36;0040;PBS_Server;Svr;tyrone-cluster;Scheduler was sent the command new
02/18/2014 12:59:10;0040;PBS_Server;Svr;tyrone-cluster;Scheduler was sent the command new
02/18/2014 12:59:39;0040;PBS_Server;Svr;tyrone-cluster;Scheduler was sent the command new
02/18/2014 13:00:09;0040;PBS_Server;Svr;tyrone-cluster;Scheduler was sent the command new
02/18/2014 13:00:39;0040;PBS_Server;Svr;tyrone-cluster;Scheduler was sent the command new
02/18/2014 13:01:09;0040;PBS_Server;Svr;tyrone-cluster;Scheduler was sent the command new
02/18/2014 13:01:24;0002;PBS_Server;Svr;PBS_Server;Torque Server Version = 3.0.5, loglevel = 0
02/18/2014 13:01:40;0040;PBS_Server;Svr;tyrone-cluster;Scheduler was sent the command new
02/18/2014 13:02:10;0040;PBS_Server;Svr;tyrone-cluster;Scheduler was sent the command new
02/18/2014 13:02:39;0040;PBS_Server;Svr;tyrone-cluster;Scheduler was sent the command new
02/18/2014 13:03:09;0040;PBS_Server;Svr;tyrone-cluster;Scheduler was sent the command new
02/18/2014 13:03:40;0040;PBS_Server;Svr;tyrone-cluster;Scheduler was sent the command new
02/18/2014 13:04:09;0040;PBS_Server;Svr;tyrone-cluster;Scheduler was sent the command new
02/18/2014 13:04:40;0040;PBS_Server;Svr;tyrone-cluster;Scheduler was sent the command new
02/18/2014 13:05:11;0040;PBS_Server;Svr;tyrone-cluster;Scheduler was sent the command new
02/18/2014 13:05:39;0040;PBS_Server;Svr;tyrone-cluster;Scheduler was sent the command new
02/18/2014 13:06:10;0040;PBS_Server;Svr;tyrone-cluster;Scheduler was sent the command new
02/18/2014 13:06:24;0002;PBS_Server;Svr;PBS_Server;Torque Server Version = 3.0.5, loglevel = 0
02/18/2014 13:06:40;0040;PBS_Server;Svr;tyrone-cluster;Scheduler was sent the command new
02/18/2014 13:07:09;0040;PBS_Server;Svr;tyrone-cluster;Scheduler was sent the command new
02/18/2014 13:07:39;0040;PBS_Server;Svr;tyrone-cluster;Scheduler was sent the command new
02/18/2014 13:08:10;0040;PBS_Server;Svr;tyrone-cluster;Scheduler was sent the command new
02/18/2014 13:08:39;0040;PBS_Server;Svr;tyrone-cluster;Scheduler was sent the command new
02/18/2014 13:09:10;0040;PBS_Server;Svr;tyrone-cluster;Scheduler was sent the command new
02/18/2014 13:09:41;0040;PBS_Server;Svr;tyrone-cluster;Scheduler was sent the command new
02/18/2014 13:10:10;0040;PBS_Server;Svr;tyrone-cluster;Scheduler was sent the command new
02/18/2014 13:10:40;0040;PBS_Server;Svr;tyrone-cluster;Scheduler was sent the command new
02/18/2014 13:11:11;0040;PBS_Server;Svr;tyrone-cluster;Scheduler was sent the command new
02/18/2014 13:11:24;0002;PBS_Server;Svr;PBS_Server;Torque Server Version = 3.0.5, loglevel = 0
02/18/2014 13:11:43;0040;PBS_Server;Svr;tyrone-cluster;Scheduler was sent the command new
02/18/2014 13:12:18;0040;PBS_Server;Svr;tyrone-cluster;Scheduler was sent the command new
02/18/2014 13:12:45;0040;PBS_Server;Svr;tyrone-cluster;Scheduler was sent the command new
02/18/2014 13:13:16;0040;PBS_Server;Svr;tyrone-cluster;Scheduler was sent the command new
02/18/2014 13:13:48;0040;PBS_Server;Svr;tyrone-cluster;Scheduler was sent the command new
02/18/2014 13:14:17;0040;PBS_Server;Svr;tyrone-cluster;Scheduler was sent the command new
02/18/2014 13:14:46;0040;PBS_Server;Svr;tyrone-cluster;Scheduler was sent the command new
02/18/2014 13:15:18;0040;PBS_Server;Svr;tyrone-cluster;Scheduler was sent the command new
02/18/2014 13:15:51;0040;PBS_Server;Svr;tyrone-cluster;Scheduler was sent the command new
02/18/2014 13:16:24;0002;PBS_Server;Svr;PBS_Server;Torque Server Version = 3.0.5, loglevel = 0
02/18/2014 13:16:25;0040;PBS_Server;Svr;tyrone-cluster;Scheduler was sent the command new
02/18/2014 13:16:54;0040;PBS_Server;Svr;tyrone-cluster;Scheduler was sent the command new
02/18/2014 13:17:25;0040;PBS_Server;Svr;tyrone-cluster;Scheduler was sent the command new
02/18/2014 13:17:55;0040;PBS_Server;Svr;tyrone-cluster;Scheduler was sent the command new
02/18/2014 13:18:24;0040;PBS_Server;Svr;tyrone-cluster;Scheduler was sent the command new
02/18/2014 13:18:54;0040;PBS_Server;Svr;tyrone-cluster;Scheduler was sent the command new
02/18/2014 13:19:24;0040;PBS_Server;Svr;tyrone-cluster;Scheduler was sent the command new
02/18/2014 13:19:54;0040;PBS_Server;Svr;tyrone-cluster;Scheduler was sent the command new
02/18/2014 13:20:25;0040;PBS_Server;Svr;tyrone-cluster;Scheduler was sent the command new
02/18/2014 13:20:56;0040;PBS_Server;Svr;tyrone-cluster;Scheduler was sent the command new
02/18/2014 13:21:24;0002;PBS_Server;Svr;PBS_Server;Torque Server Version = 3.0.5, loglevel = 0
02/18/2014 13:21:26;0040;PBS_Server;Svr;tyrone-cluster;Scheduler was sent the command new
02/18/2014 13:21:55;0040;PBS_Server;Svr;tyrone-cluster;Scheduler was sent the command new
02/18/2014 13:22:26;0040;PBS_Server;Svr;tyrone-cluster;Scheduler was sent the command new
02/18/2014 13:22:58;0040;PBS_Server;Svr;tyrone-cluster;Scheduler was sent the command new
02/18/2014 13:23:33;0040;PBS_Server;Svr;tyrone-cluster;Scheduler was sent the command new
02/18/2014 13:24:00;0040;PBS_Server;Svr;tyrone-cluster;Scheduler was sent the command new
02/18/2014 13:24:30;0040;PBS_Server;Svr;tyrone-cluster;Scheduler was sent the command new
02/18/2014 13:25:03;0040;PBS_Server;Svr;tyrone-cluster;Scheduler was sent the command new
02/18/2014 13:25:30;0040;PBS_Server;Svr;tyrone-cluster;Scheduler was sent the command new
02/18/2014 13:26:01;0040;PBS_Server;Svr;tyrone-cluster;Scheduler was sent the command new
02/18/2014 13:26:24;0002;PBS_Server;Svr;PBS_Server;Torque Server Version = 3.0.5, loglevel = 0
02/18/2014 13:26:33;0040;PBS_Server;Svr;tyrone-cluster;Scheduler was sent the command new
02/18/2014 13:27:06;0040;PBS_Server;Svr;tyrone-cluster;Scheduler was sent the command new
02/18/2014 13:27:40;0040;PBS_Server;Svr;tyrone-cluster;Scheduler was sent the command new
02/18/2014 13:28:09;0040;PBS_Server;Svr;tyrone-cluster;Scheduler was sent the command new
02/18/2014 13:28:27;0100;PBS_Server;Job;35233.tyrone-cluster;enqueuing into batch, state 1 hop 1
02/18/2014 13:28:27;0100;PBS_Server;Job;35233.tyrone-cluster;dequeuing from batch, state QUEUED
02/18/2014 13:28:27;0100;PBS_Server;Job;35233.tyrone-cluster;enqueuing into idqueue, state 1 hop 1
02/18/2014 13:28:27;0008;PBS_Server;Job;35233.tyrone-cluster;Job Queued at request of metsomya@tyrone-cluster, owner = metsomya@tyrone-cluster, job name = poshit1, queue = idqueue
02/18/2014 13:28:27;0040;PBS_Server;Svr;tyrone-cluster;Scheduler was sent the command new
02/18/2014 13:28:27;0008;PBS_Server;Job;35233.tyrone-cluster;Job Modified at request of Scheduler@tyrone-cluster
02/18/2014 13:28:27;0008;PBS_Server;Job;35233.tyrone-cluster;Job Run at request of Scheduler@tyrone-cluster
02/18/2014 13:28:27;0040;PBS_Server;Svr;tyrone-cluster;Scheduler was sent the command recyc
02/18/2014 13:28:27;000d;PBS_Server;Job;35233.tyrone-cluster;Not sending email: User does not want mail of this type.
02/18/2014 13:28:39;0040;PBS_Server;Svr;tyrone-cluster;Scheduler was sent the command new
02/18/2014 13:28:43;000d;PBS_Server;Job;35233.tyrone-cluster;Not sending email: User does not want mail of this type.
02/18/2014 13:28:43;0010;PBS_Server;Job;35233.tyrone-cluster;Exit_status=0 resources_used.cput=00:01:52 resources_used.mem=1428kb resources_used.vmem=110776kb resources_used.walltime=00:00:16
02/18/2014 13:28:43;0008;PBS_Server;Job;NULL;on_job_exit valid pjob: 0x1e584e0 (substate=50)
02/18/2014 13:28:43;0008;PBS_Server;Job;NULL;on_job_exit valid pjob: 0x1e584e0 (substate=51)
02/18/2014 13:28:43;0008;PBS_Server;Job;NULL;on_job_exit valid pjob: 0x1e584e0 (substate=51)
02/18/2014 13:28:43;0008;PBS_Server;Job;NULL;on_job_exit valid pjob: 0x1e584e0 (substate=53)
02/18/2014 13:28:43;0100;PBS_Server;Job;35233.tyrone-cluster;dequeuing from idqueue, state COMPLETE
02/18/2014 13:28:43;0040;PBS_Server;Svr;tyrone-cluster;Scheduler was sent the command term
02/18/2014 13:29:10;0040;PBS_Server;Svr;tyrone-cluster;Scheduler was sent the command new
02/18/2014 13:29:39;0040;PBS_Server;Svr;tyrone-cluster;Scheduler was sent the command new
02/18/2014 13:30:10;0040;PBS_Server;Svr;tyrone-cluster;Scheduler was sent the command new
02/18/2014 13:30:39;0040;PBS_Server;Svr;tyrone-cluster;Scheduler was sent the command new
02/18/2014 13:31:10;0040;PBS_Server;Svr;tyrone-cluster;Scheduler was sent the command new
02/18/2014 13:31:24;0002;PBS_Server;Svr;PBS_Server;Torque Server Version = 3.0.5, loglevel = 0
02/18/2014 13:31:40;0040;PBS_Server;Svr;tyrone-cluster;Scheduler was sent the command new
02/18/2014 13:32:11;0040;PBS_Server;Svr;tyrone-cluster;Scheduler was sent the command new
02/18/2014 13:32:44;0040;PBS_Server;Svr;tyrone-cluster;Scheduler was sent the command new
02/18/2014 13:33:18;0040;PBS_Server;Svr;tyrone-cluster;Scheduler was sent the command new
02/18/2014 13:33:45;0040;PBS_Server;Svr;tyrone-cluster;Scheduler was sent the command new
02/18/2014 13:34:14;0040;PBS_Server;Svr;tyrone-cluster;Scheduler was sent the command new
02/18/2014 13:34:48;0040;PBS_Server;Svr;tyrone-cluster;Scheduler was sent the command new
02/18/2014 13:35:15;0040;PBS_Server;Svr;tyrone-cluster;Scheduler was sent the command new
02/18/2014 13:35:44;0040;PBS_Server;Svr;tyrone-cluster;Scheduler was sent the command new
02/18/2014 13:36:18;0040;PBS_Server;Svr;tyrone-cluster;Scheduler was sent the command new
02/18/2014 13:36:24;0002;PBS_Server;Svr;PBS_Server;Torque Server Version = 3.0.5, loglevel = 0
02/18/2014 13:36:51;0040;PBS_Server;Svr;tyrone-cluster;Scheduler was sent the command new
02/18/2014 13:37:25;0040;PBS_Server;Svr;tyrone-cluster;Scheduler was sent the command new
02/18/2014 13:37:54;0040;PBS_Server;Svr;tyrone-cluster;Scheduler was sent the command new
02/18/2014 13:38:25;0040;PBS_Server;Svr;tyrone-cluster;Scheduler was sent the command new
02/18/2014 13:38:56;0040;PBS_Server;Svr;tyrone-cluster;Scheduler was sent the command new
02/18/2014 13:39:29;0040;PBS_Server;Svr;tyrone-cluster;Scheduler was sent the command new
02/18/2014 13:40:03;0040;PBS_Server;Svr;tyrone-cluster;Scheduler was sent the command new
02/18/2014 13:40:30;0040;PBS_Server;Svr;tyrone-cluster;Scheduler was sent the command new
02/18/2014 13:41:01;0040;PBS_Server;Svr;tyrone-cluster;Scheduler was sent the command new
02/18/2014 13:41:24;0002;PBS_Server;Svr;PBS_Server;Torque Server Version = 3.0.5, loglevel = 0
02/18/2014 13:41:33;0040;PBS_Server;Svr;tyrone-cluster;Scheduler was sent the command new
02/18/2014 13:42:00;0040;PBS_Server;Svr;tyrone-cluster;Scheduler was sent the command new
02/18/2014 13:42:31;0040;PBS_Server;Svr;tyrone-cluster;Scheduler was sent the command new
02/18/2014 13:43:03;0040;PBS_Server;Svr;tyrone-cluster;Scheduler was sent the command new
02/18/2014 13:43:36;0040;PBS_Server;Svr;tyrone-cluster;Scheduler was sent the command new
02/18/2014 13:44:10;0040;PBS_Server;Svr;tyrone-cluster;Scheduler was sent the command new
02/18/2014 13:44:39;0040;PBS_Server;Svr;tyrone-cluster;Scheduler was sent the command new
02/18/2014 13:45:09;0040;PBS_Server;Svr;tyrone-cluster;Scheduler was sent the command new
02/18/2014 13:45:40;0040;PBS_Server;Svr;tyrone-cluster;Scheduler was sent the command new
02/18/2014 13:46:09;0040;PBS_Server;Svr;tyrone-cluster;Scheduler was sent the command new
02/18/2014 13:46:24;0002;PBS_Server;Svr;PBS_Server;Torque Server Version = 3.0.5, loglevel = 0
02/18/2014 13:46:40;0040;PBS_Server;Svr;tyrone-cluster;Scheduler was sent the command new
02/18/2014 13:47:10;0040;PBS_Server;Svr;tyrone-cluster;Scheduler was sent the command new
02/18/2014 13:47:39;0040;PBS_Server;Svr;tyrone-cluster;Scheduler was sent the command new
02/18/2014 13:48:10;0040;PBS_Server;Svr;tyrone-cluster;Scheduler was sent the command new
02/18/2014 13:48:40;0040;PBS_Server;Svr;tyrone-cluster;Scheduler was sent the command new
02/18/2014 13:49:09;0040;PBS_Server;Svr;tyrone-cluster;Scheduler was sent the command new
02/18/2014 13:49:39;0040;PBS_Server;Svr;tyrone-cluster;Scheduler was sent the command new
02/18/2014 13:50:10;0040;PBS_Server;Svr;tyrone-cluster;Scheduler was sent the command new
02/18/2014 13:50:39;0040;PBS_Server;Svr;tyrone-cluster;Scheduler was sent the command new
02/18/2014 13:51:10;0040;PBS_Server;Svr;tyrone-cluster;Scheduler was sent the command new
02/18/2014 13:51:24;0002;PBS_Server;Svr;PBS_Server;Torque Server Version = 3.0.5, loglevel = 0
02/18/2014 13:51:41;0040;PBS_Server;Svr;tyrone-cluster;Scheduler was sent the command new
02/18/2014 13:52:09;0040;PBS_Server;Svr;tyrone-cluster;Scheduler was sent the command new
02/18/2014 13:52:39;0040;PBS_Server;Svr;tyrone-cluster;Scheduler was sent the command new
02/18/2014 13:53:10;0040;PBS_Server;Svr;tyrone-cluster;Scheduler was sent the command new
02/18/2014 13:53:39;0040;PBS_Server;Svr;tyrone-cluster;Scheduler was sent the command new
02/18/2014 13:54:09;0040;PBS_Server;Svr;tyrone-cluster;Scheduler was sent the command new
02/18/2014 13:54:40;0040;PBS_Server;Svr;tyrone-cluster;Scheduler was sent the command new
02/18/2014 13:55:09;0040;PBS_Server;Svr;tyrone-cluster;Scheduler was sent the command new
02/18/2014 13:55:40;0040;PBS_Server;Svr;tyrone-cluster;Scheduler was sent the command new
02/18/2014 13:56:11;0040;PBS_Server;Svr;tyrone-cluster;Scheduler was sent the command new
02/18/2014 13:56:24;0002;PBS_Server;Svr;PBS_Server;Torque Server Version = 3.0.5, loglevel = 0
02/18/2014 13:56:39;0040;PBS_Server;Svr;tyrone-cluster;Scheduler was sent the command new
02/18/2014 13:57:09;0040;PBS_Server;Svr;tyrone-cluster;Scheduler was sent the command new
02/18/2014 13:57:40;0040;PBS_Server;Svr;tyrone-cluster;Scheduler was sent the command new
02/18/2014 13:58:09;0040;PBS_Server;Svr;tyrone-cluster;Scheduler was sent the command new
02/18/2014 13:58:40;0040;PBS_Server;Svr;tyrone-cluster;Scheduler was sent the command new
02/18/2014 13:59:10;0040;PBS_Server;Svr;tyrone-cluster;Scheduler was sent the command new
02/18/2014 13:59:39;0040;PBS_Server;Svr;tyrone-cluster;Scheduler was sent the command new
02/18/2014 14:00:10;0040;PBS_Server;Svr;tyrone-cluster;Scheduler was sent the command new
02/18/2014 14:00:41;0040;PBS_Server;Svr;tyrone-cluster;Scheduler was sent the command new
02/18/2014 14:01:09;0040;PBS_Server;Svr;tyrone-cluster;Scheduler was sent the command new
02/18/2014 14:01:24;0002;PBS_Server;Svr;PBS_Server;Torque Server Version = 3.0.5, loglevel = 0
02/18/2014 14:01:39;0040;PBS_Server;Svr;tyrone-cluster;Scheduler was sent the command new
02/18/2014 14:02:10;0040;PBS_Server;Svr;tyrone-cluster;Scheduler was sent the command new
02/18/2014 14:02:39;0040;PBS_Server;Svr;tyrone-cluster;Scheduler was sent the command new
02/18/2014 14:03:10;0040;PBS_Server;Svr;tyrone-cluster;Scheduler was sent the command new
02/18/2014 14:03:40;0040;PBS_Server;Svr;tyrone-cluster;Scheduler was sent the command new
02/18/2014 14:04:09;0040;PBS_Server;Svr;tyrone-cluster;Scheduler was sent the command new
02/18/2014 14:04:40;0040;PBS_Server;Svr;tyrone-cluster;Scheduler was sent the command new
02/18/2014 14:05:11;0040;PBS_Server;Svr;tyrone-cluster;Scheduler was sent the command new
02/18/2014 14:05:39;0040;PBS_Server;Svr;tyrone-cluster;Scheduler was sent the command new
02/18/2014 14:06:09;0040;PBS_Server;Svr;tyrone-cluster;Scheduler was sent the command new
02/18/2014 14:06:24;0002;PBS_Server;Svr;PBS_Server;Torque Server Version = 3.0.5, loglevel = 0
02/18/2014 14:06:40;0040;PBS_Server;Svr;tyrone-cluster;Scheduler was sent the command new
02/18/2014 14:07:09;0040;PBS_Server;Svr;tyrone-cluster;Scheduler was sent the command new
02/18/2014 14:07:40;0040;PBS_Server;Svr;tyrone-cluster;Scheduler was sent the command new
02/18/2014 14:08:11;0040;PBS_Server;Svr;tyrone-cluster;Scheduler was sent the command new
02/18/2014 14:08:39;0040;PBS_Server;Svr;tyrone-cluster;Scheduler was sent the command new
02/18/2014 14:09:09;0040;PBS_Server;Svr;tyrone-cluster;Scheduler was sent the command new
02/18/2014 14:09:40;0040;PBS_Server;Svr;tyrone-cluster;Scheduler was sent the command new
02/18/2014 14:10:09;0040;PBS_Server;Svr;tyrone-cluster;Scheduler was sent the command new
02/18/2014 14:10:40;0040;PBS_Server;Svr;tyrone-cluster;Scheduler was sent the command new
02/18/2014 14:11:11;0040;PBS_Server;Svr;tyrone-cluster;Scheduler was sent the command new
02/18/2014 14:11:24;0002;PBS_Server;Svr;PBS_Server;Torque Server Version = 3.0.5, loglevel = 0
02/18/2014 14:11:39;0040;PBS_Server;Svr;tyrone-cluster;Scheduler was sent the command new
02/18/2014 14:12:09;0040;PBS_Server;Svr;tyrone-cluster;Scheduler was sent the command new
02/18/2014 14:12:40;0040;PBS_Server;Svr;tyrone-cluster;Scheduler was sent the command new
02/18/2014 14:13:09;0040;PBS_Server;Svr;tyrone-cluster;Scheduler was sent the command new
02/18/2014 14:13:40;0040;PBS_Server;Svr;tyrone-cluster;Scheduler was sent the command new
02/18/2014 14:14:10;0040;PBS_Server;Svr;tyrone-cluster;Scheduler was sent the command new
02/18/2014 14:14:39;0040;PBS_Server;Svr;tyrone-cluster;Scheduler was sent the command new
02/18/2014 14:15:10;0040;PBS_Server;Svr;tyrone-cluster;Scheduler was sent the command new
02/18/2014 14:15:41;0040;PBS_Server;Svr;tyrone-cluster;Scheduler was sent the command new
02/18/2014 14:16:09;0040;PBS_Server;Svr;tyrone-cluster;Scheduler was sent the command new
02/18/2014 14:16:24;0002;PBS_Server;Svr;PBS_Server;Torque Server Version = 3.0.5, loglevel = 0
02/18/2014 14:16:39;0040;PBS_Server;Svr;tyrone-cluster;Scheduler was sent the command new
02/18/2014 14:17:11;0040;PBS_Server;Svr;tyrone-cluster;Scheduler was sent the command new
02/18/2014 14:17:39;0040;PBS_Server;Svr;tyrone-cluster;Scheduler was sent the command new
02/18/2014 14:18:09;0040;PBS_Server;Svr;tyrone-cluster;Scheduler was sent the command new
02/18/2014 14:18:40;0040;PBS_Server;Svr;tyrone-cluster;Scheduler was sent the command new
02/18/2014 14:19:09;0040;PBS_Server;Svr;tyrone-cluster;Scheduler was sent the command new
02/18/2014 14:19:40;0040;PBS_Server;Svr;tyrone-cluster;Scheduler was sent the command new
02/18/2014 14:20:11;0040;PBS_Server;Svr;tyrone-cluster;Scheduler was sent the command new
02/18/2014 14:20:39;0040;PBS_Server;Svr;tyrone-cluster;Scheduler was sent the command new
02/18/2014 14:21:09;0040;PBS_Server;Svr;tyrone-cluster;Scheduler was sent the command new
02/18/2014 14:21:21;000d;PBS_Server;Job;35118.tyrone-cluster;Not sending email: User does not want mail of this type.
02/18/2014 14:21:21;0010;PBS_Server;Job;35118.tyrone-cluster;Exit_status=0 resources_used.cput=752:10:18 resources_used.mem=15583048kb resources_used.vmem=51429248kb resources_used.walltime=12:10:16
02/18/2014 14:21:21;0008;PBS_Server;Job;NULL;on_job_exit valid pjob: 0x1df19b0 (substate=50)
02/18/2014 14:21:21;0008;PBS_Server;Job;NULL;on_job_exit valid pjob: 0x1df19b0 (substate=51)
02/18/2014 14:21:21;0008;PBS_Server;Job;NULL;on_job_exit valid pjob: 0x1df19b0 (substate=51)
02/18/2014 14:21:21;0008;PBS_Server;Job;NULL;on_job_exit valid pjob: 0x1df19b0 (substate=53)
02/18/2014 14:21:21;0100;PBS_Server;Job;35118.tyrone-cluster;dequeuing from qp256, state COMPLETE
02/18/2014 14:21:21;0040;PBS_Server;Svr;tyrone-cluster;Scheduler was sent the command term
02/18/2014 14:21:21;0008;PBS_Server;Job;35059.tyrone-cluster;Job Modified at request of Scheduler@tyrone-cluster
02/18/2014 14:21:21;0008;PBS_Server;Job;35059.tyrone-cluster;Job Run at request of Scheduler@tyrone-cluster
02/18/2014 14:21:22;000d;PBS_Server;Job;35059.tyrone-cluster;Not sending email: User does not want mail of this type.
02/18/2014 14:21:22;0040;PBS_Server;Svr;tyrone-cluster;Scheduler was sent the command recyc
02/18/2014 14:21:24;0002;PBS_Server;Svr;PBS_Server;Torque Server Version = 3.0.5, loglevel = 0
02/18/2014 14:21:40;0040;PBS_Server;Svr;tyrone-cluster;Scheduler was sent the command new
02/18/2014 14:22:13;0040;PBS_Server;Svr;tyrone-cluster;Scheduler was sent the command new
02/18/2014 14:22:49;0040;PBS_Server;Svr;tyrone-cluster;Scheduler was sent the command new
02/18/2014 14:23:17;0040;PBS_Server;Svr;tyrone-cluster;Scheduler was sent the command new
02/18/2014 14:23:46;0040;PBS_Server;Svr;tyrone-cluster;Scheduler was sent the command new
02/18/2014 14:24:19;0040;PBS_Server;Svr;tyrone-cluster;Scheduler was sent the command new
02/18/2014 14:24:47;0040;PBS_Server;Svr;tyrone-cluster;Scheduler was sent the command new
02/18/2014 14:25:16;0040;PBS_Server;Svr;tyrone-cluster;Scheduler was sent the command new
02/18/2014 14:25:51;0040;PBS_Server;Svr;tyrone-cluster;Scheduler was sent the command new
02/18/2014 14:26:21;0040;PBS_Server;Svr;tyrone-cluster;Scheduler was sent the command new
02/18/2014 14:26:24;0002;PBS_Server;Svr;PBS_Server;Torque Server Version = 3.0.5, loglevel = 0
02/18/2014 14:26:55;0040;PBS_Server;Svr;tyrone-cluster;Scheduler was sent the command new
02/18/2014 14:27:29;0040;PBS_Server;Svr;tyrone-cluster;Scheduler was sent the command new
02/18/2014 14:28:03;0040;PBS_Server;Svr;tyrone-cluster;Scheduler was sent the command new
02/18/2014 14:28:30;0040;PBS_Server;Svr;tyrone-cluster;Scheduler was sent the command new
02/18/2014 14:29:01;0040;PBS_Server;Svr;tyrone-cluster;Scheduler was sent the command new
02/18/2014 14:29:34;0040;PBS_Server;Svr;tyrone-cluster;Scheduler was sent the command new
02/18/2014 14:30:02;0040;PBS_Server;Svr;tyrone-cluster;Scheduler was sent the command new
02/18/2014 14:30:31;0040;PBS_Server;Svr;tyrone-cluster;Scheduler was sent the command new
02/18/2014 14:31:04;0040;PBS_Server;Svr;tyrone-cluster;Scheduler was sent the command new
02/18/2014 14:31:24;0002;PBS_Server;Svr;PBS_Server;Torque Server Version = 3.0.5, loglevel = 0
02/18/2014 14:31:36;0040;PBS_Server;Svr;tyrone-cluster;Scheduler was sent the command new
02/18/2014 14:32:11;0040;PBS_Server;Svr;tyrone-cluster;Scheduler was sent the command new
02/18/2014 14:32:44;0040;PBS_Server;Svr;tyrone-cluster;Scheduler was sent the command new
02/18/2014 14:33:16;0040;PBS_Server;Svr;tyrone-cluster;Scheduler was sent the command new
02/18/2014 14:33:45;0040;PBS_Server;Svr;tyrone-cluster;Scheduler was sent the command new
02/18/2014 14:34:17;0040;PBS_Server;Svr;tyrone-cluster;Scheduler was sent the command new
02/18/2014 14:34:49;0040;PBS_Server;Svr;tyrone-cluster;Scheduler was sent the command new
02/18/2014 14:35:21;0040;PBS_Server;Svr;tyrone-cluster;Scheduler was sent the command new
02/18/2014 14:35:52;0040;PBS_Server;Svr;tyrone-cluster;Scheduler was sent the command new
02/18/2014 14:36:22;0040;PBS_Server;Svr;tyrone-cluster;Scheduler was sent the command new
02/18/2014 14:36:24;0002;PBS_Server;Svr;PBS_Server;Torque Server Version = 3.0.5, loglevel = 0
02/18/2014 14:36:30;000d;PBS_Server;Job;35059.tyrone-cluster;Not sending email: User does not want mail of this type.
02/18/2014 14:36:30;0010;PBS_Server;Job;35059.tyrone-cluster;Exit_status=0 resources_used.cput=00:04:33 resources_used.mem=234632kb resources_used.vmem=3160700kb resources_used.walltime=00:15:09
02/18/2014 14:36:30;0008;PBS_Server;Job;NULL;on_job_exit valid pjob: 0x1df9bc0 (substate=50)
02/18/2014 14:36:30;0008;PBS_Server;Job;NULL;on_job_exit valid pjob: 0x1df9bc0 (substate=51)
02/18/2014 14:36:31;0008;PBS_Server;Job;NULL;on_job_exit valid pjob: 0x1df9bc0 (substate=51)
02/18/2014 14:36:31;0008;PBS_Server;Job;NULL;on_job_exit valid pjob: 0x1df9bc0 (substate=53)
02/18/2014 14:36:31;0100;PBS_Server;Job;35059.tyrone-cluster;dequeuing from qp256, state COMPLETE
02/18/2014 14:36:31;0040;PBS_Server;Svr;tyrone-cluster;Scheduler was sent the command term
02/18/2014 14:36:31;0008;PBS_Server;Job;35060.tyrone-cluster;Job Modified at request of Scheduler@tyrone-cluster
02/18/2014 14:36:31;0008;PBS_Server;Job;35060.tyrone-cluster;Job Run at request of Scheduler@tyrone-cluster
02/18/2014 14:36:31;0040;PBS_Server;Svr;tyrone-cluster;Scheduler was sent the command recyc
02/18/2014 14:36:52;0100;PBS_Server;Job;35218.tyrone-cluster;dequeuing from batch, state QUEUED
02/18/2014 14:36:52;0100;PBS_Server;Job;35218.tyrone-cluster;enqueuing into qp256, state 1 hop 1
02/18/2014 14:36:53;0040;PBS_Server;Svr;tyrone-cluster;Scheduler was sent the command new
02/18/2014 14:36:53;0008;PBS_Server;Job;35218.tyrone-cluster;Job Modified at request of Scheduler@tyrone-cluster
02/18/2014 14:36:56;000d;PBS_Server;Job;35060.tyrone-cluster;Not sending email: User does not want mail of this type.
02/18/2014 14:37:26;0040;PBS_Server;Svr;tyrone-cluster;Scheduler was sent the command new
02/18/2014 14:37:59;0040;PBS_Server;Svr;tyrone-cluster;Scheduler was sent the command new
02/18/2014 14:38:34;0040;PBS_Server;Svr;tyrone-cluster;Scheduler was sent the command new
02/18/2014 14:39:00;0040;PBS_Server;Svr;tyrone-cluster;Scheduler was sent the command new
02/18/2014 14:39:29;0040;PBS_Server;Svr;tyrone-cluster;Scheduler was sent the command new
02/18/2014 14:39:53;0100;PBS_Server;Job;35234.tyrone-cluster;enqueuing into batch, state 1 hop 1
02/18/2014 14:39:53;0100;PBS_Server;Job;35234.tyrone-cluster;dequeuing from batch, state QUEUED
02/18/2014 14:39:53;0100;PBS_Server;Job;35234.tyrone-cluster;enqueuing into qp64, state 1 hop 1
02/18/2014 14:39:53;0008;PBS_Server;Job;35234.tyrone-cluster;Job Queued at request of csdshiku@tyrone-cluster, owner = csdshiku@tyrone-cluster, job name = script64.sh, queue = qp64
02/18/2014 14:39:53;0040;PBS_Server;Svr;tyrone-cluster;Scheduler was sent the command new
02/18/2014 14:39:53;0008;PBS_Server;Job;35234.tyrone-cluster;Job Modified at request of Scheduler@tyrone-cluster
02/18/2014 14:40:03;0040;PBS_Server;Svr;tyrone-cluster;Scheduler was sent the command new
02/18/2014 14:40:28;0008;PBS_Server;Job;35234.tyrone-cluster;Job deleted at request of csdshiku@tyrone-cluster
02/18/2014 14:40:28;0008;PBS_Server;Job;NULL;on_job_exit valid pjob: 0x1e1b0a0 (substate=59)
02/18/2014 14:40:28;0100;PBS_Server;Job;35234.tyrone-cluster;dequeuing from qp64, state COMPLETE
02/18/2014 14:40:28;0040;PBS_Server;Svr;tyrone-cluster;Scheduler was sent the command term
02/18/2014 14:40:30;0040;PBS_Server;Svr;tyrone-cluster;Scheduler was sent the command new
02/18/2014 14:40:59;0040;PBS_Server;Svr;tyrone-cluster;Scheduler was sent the command new
02/18/2014 14:41:24;0002;PBS_Server;Svr;PBS_Server;Torque Server Version = 3.0.5, loglevel = 0
02/18/2014 14:41:33;0040;PBS_Server;Svr;tyrone-cluster;Scheduler was sent the command new
02/18/2014 14:41:51;0100;PBS_Server;Job;35235.tyrone-cluster;enqueuing into batch, state 1 hop 1
02/18/2014 14:41:51;0100;PBS_Server;Job;35235.tyrone-cluster;dequeuing from batch, state QUEUED
02/18/2014 14:41:51;0100;PBS_Server;Job;35235.tyrone-cluster;enqueuing into qp64, state 1 hop 1
02/18/2014 14:41:51;0008;PBS_Server;Job;35235.tyrone-cluster;Job Queued at request of csdshiku@tyrone-cluster, owner = csdshiku@tyrone-cluster, job name = script64.sh, queue = qp64
02/18/2014 14:41:51;0040;PBS_Server;Svr;tyrone-cluster;Scheduler was sent the command new
02/18/2014 14:41:52;0008;PBS_Server;Job;35235.tyrone-cluster;Job Modified at request of Scheduler@tyrone-cluster
02/18/2014 14:42:00;0040;PBS_Server;Svr;tyrone-cluster;Scheduler was sent the command new
02/18/2014 14:42:31;0040;PBS_Server;Svr;tyrone-cluster;Scheduler was sent the command new
02/18/2014 14:43:04;0040;PBS_Server;Svr;tyrone-cluster;Scheduler was sent the command new
02/18/2014 14:43:32;0040;PBS_Server;Svr;tyrone-cluster;Scheduler was sent the command new
02/18/2014 14:44:01;0040;PBS_Server;Svr;tyrone-cluster;Scheduler was sent the command new
02/18/2014 14:44:34;0040;PBS_Server;Svr;tyrone-cluster;Scheduler was sent the command new
02/18/2014 14:45:06;0040;PBS_Server;Svr;tyrone-cluster;Scheduler was sent the command new
02/18/2014 14:45:41;0040;PBS_Server;Svr;tyrone-cluster;Scheduler was sent the command new
02/18/2014 14:46:14;0040;PBS_Server;Svr;tyrone-cluster;Scheduler was sent the command new
02/18/2014 14:46:24;0002;PBS_Server;Svr;PBS_Server;Torque Server Version = 3.0.5, loglevel = 0
02/18/2014 14:46:48;0040;PBS_Server;Svr;tyrone-cluster;Scheduler was sent the command new
02/18/2014 14:47:15;0040;PBS_Server;Svr;tyrone-cluster;Scheduler was sent the command new
02/18/2014 14:47:45;0040;PBS_Server;Svr;tyrone-cluster;Scheduler was sent the command new
02/18/2014 14:48:19;0040;PBS_Server;Svr;tyrone-cluster;Scheduler was sent the command new
02/18/2014 14:48:51;0040;PBS_Server;Svr;tyrone-cluster;Scheduler was sent the command new
02/18/2014 14:49:26;0040;PBS_Server;Svr;tyrone-cluster;Scheduler was sent the command new
02/18/2014 14:49:59;0040;PBS_Server;Svr;tyrone-cluster;Scheduler was sent the command new
02/18/2014 14:50:28;0040;PBS_Server;Svr;tyrone-cluster;Scheduler was sent the command new
02/18/2014 14:50:59;0040;PBS_Server;Svr;tyrone-cluster;Scheduler was sent the command new
02/18/2014 14:51:24;0002;PBS_Server;Svr;PBS_Server;Torque Server Version = 3.0.5, loglevel = 0
02/18/2014 14:51:30;0040;PBS_Server;Svr;tyrone-cluster;Scheduler was sent the command new
02/18/2014 14:52:03;0040;PBS_Server;Svr;tyrone-cluster;Scheduler was sent the command new
02/18/2014 14:52:29;0040;PBS_Server;Svr;tyrone-cluster;Scheduler was sent the command new
02/18/2014 14:52:49;000d;PBS_Server;Job;35060.tyrone-cluster;Not sending email: User does not want mail of this type.
02/18/2014 14:52:49;0010;PBS_Server;Job;35060.tyrone-cluster;Exit_status=0 resources_used.cput=00:04:24 resources_used.mem=199748kb resources_used.vmem=3160700kb resources_used.walltime=00:16:18
02/18/2014 14:52:49;0008;PBS_Server;Job;NULL;on_job_exit valid pjob: 0x1d9ec20 (substate=50)
02/18/2014 14:52:49;0008;PBS_Server;Job;NULL;on_job_exit valid pjob: 0x1d9ec20 (substate=51)
02/18/2014 14:52:49;0008;PBS_Server;Job;NULL;on_job_exit valid pjob: 0x1d9ec20 (substate=51)
02/18/2014 14:52:49;0008;PBS_Server;Job;NULL;on_job_exit valid pjob: 0x1d9ec20 (substate=53)
02/18/2014 14:52:49;0100;PBS_Server;Job;35060.tyrone-cluster;dequeuing from qp256, state COMPLETE
02/18/2014 14:52:49;0040;PBS_Server;Svr;tyrone-cluster;Scheduler was sent the command term
02/18/2014 14:52:49;0008;PBS_Server;Job;35117.tyrone-cluster;Job Modified at request of Scheduler@tyrone-cluster
02/18/2014 14:52:49;0008;PBS_Server;Job;35117.tyrone-cluster;Job Run at request of Scheduler@tyrone-cluster
02/18/2014 14:52:49;0040;PBS_Server;Svr;tyrone-cluster;Scheduler was sent the command recyc
02/18/2014 14:52:59;0100;PBS_Server;Job;35219.tyrone-cluster;dequeuing from batch, state QUEUED
02/18/2014 14:52:59;0100;PBS_Server;Job;35219.tyrone-cluster;enqueuing into qp256, state 1 hop 1
02/18/2014 14:53:00;0040;PBS_Server;Svr;tyrone-cluster;Scheduler was sent the command new
02/18/2014 14:53:01;0008;PBS_Server;Job;35219.tyrone-cluster;Job Modified at request of Scheduler@tyrone-cluster
02/18/2014 14:53:34;0040;PBS_Server;Svr;tyrone-cluster;Scheduler was sent the command new
02/18/2014 14:53:37;000d;PBS_Server;Job;35117.tyrone-cluster;Not sending email: User does not want mail of this type.
02/18/2014 14:54:00;0040;PBS_Server;Svr;tyrone-cluster;Scheduler was sent the command new
02/18/2014 14:54:30;0040;PBS_Server;Svr;tyrone-cluster;Scheduler was sent the command new
02/18/2014 14:55:04;0040;PBS_Server;Svr;tyrone-cluster;Scheduler was sent the command new
02/18/2014 14:55:36;0040;PBS_Server;Svr;tyrone-cluster;Scheduler was sent the command new
02/18/2014 14:56:11;0040;PBS_Server;Svr;tyrone-cluster;Scheduler was sent the command new
02/18/2014 14:56:24;0002;PBS_Server;Svr;PBS_Server;Torque Server Version = 3.0.5, loglevel = 0
02/18/2014 14:56:44;0040;PBS_Server;Svr;tyrone-cluster;Scheduler was sent the command new
02/18/2014 14:57:19;0040;PBS_Server;Svr;tyrone-cluster;Scheduler was sent the command new
02/18/2014 14:57:45;0040;PBS_Server;Svr;tyrone-cluster;Scheduler was sent the command new
02/18/2014 14:58:16;0040;PBS_Server;Svr;tyrone-cluster;Scheduler was sent the command new
02/18/2014 14:58:49;0040;PBS_Server;Svr;tyrone-cluster;Scheduler was sent the command new
02/18/2014 14:59:21;0040;PBS_Server;Svr;tyrone-cluster;Scheduler was sent the command new
02/18/2014 14:59:56;0040;PBS_Server;Svr;tyrone-cluster;Scheduler was sent the command new
02/18/2014 15:00:30;0040;PBS_Server;Svr;tyrone-cluster;Scheduler was sent the command new
02/18/2014 15:01:04;0040;PBS_Server;Svr;tyrone-cluster;Scheduler was sent the command new
02/18/2014 15:01:24;0002;PBS_Server;Svr;PBS_Server;Torque Server Version = 3.0.5, loglevel = 0
02/18/2014 15:01:30;0040;PBS_Server;Svr;tyrone-cluster;Scheduler was sent the command new
02/18/2014 15:02:01;0040;PBS_Server;Svr;tyrone-cluster;Scheduler was sent the command new
02/18/2014 15:02:34;0040;PBS_Server;Svr;tyrone-cluster;Scheduler was sent the command new
02/18/2014 15:03:06;0040;PBS_Server;Svr;tyrone-cluster;Scheduler was sent the command new
02/18/2014 15:03:41;0040;PBS_Server;Svr;tyrone-cluster;Scheduler was sent the command new
02/18/2014 15:04:14;0040;PBS_Server;Svr;tyrone-cluster;Scheduler was sent the command new
02/18/2014 15:04:49;0040;PBS_Server;Svr;tyrone-cluster;Scheduler was sent the command new
02/18/2014 15:05:15;0040;PBS_Server;Svr;tyrone-cluster;Scheduler was sent the command new
02/18/2014 15:05:46;0040;PBS_Server;Svr;tyrone-cluster;Scheduler was sent the command new
02/18/2014 15:06:19;0040;PBS_Server;Svr;tyrone-cluster;Scheduler was sent the command new
02/18/2014 15:06:24;0002;PBS_Server;Svr;PBS_Server;Torque Server Version = 3.0.5, loglevel = 0
02/18/2014 15:06:51;0040;PBS_Server;Svr;tyrone-cluster;Scheduler was sent the command new
02/18/2014 15:07:26;0040;PBS_Server;Svr;tyrone-cluster;Scheduler was sent the command new
02/18/2014 15:07:59;0040;PBS_Server;Svr;tyrone-cluster;Scheduler was sent the command new
02/18/2014 15:08:34;0040;PBS_Server;Svr;tyrone-cluster;Scheduler was sent the command new
02/18/2014 15:09:00;0040;PBS_Server;Svr;tyrone-cluster;Scheduler was sent the command new
02/18/2014 15:09:31;0040;PBS_Server;Svr;tyrone-cluster;Scheduler was sent the command new
02/18/2014 15:10:04;0040;PBS_Server;Svr;tyrone-cluster;Scheduler was sent the command new
02/18/2014 15:10:30;0040;PBS_Server;Svr;tyrone-cluster;Scheduler was sent the command new
02/18/2014 15:11:01;0040;PBS_Server;Svr;tyrone-cluster;Scheduler was sent the command new
02/18/2014 15:11:24;0002;PBS_Server;Svr;PBS_Server;Torque Server Version = 3.0.5, loglevel = 0
02/18/2014 15:11:34;0040;PBS_Server;Svr;tyrone-cluster;Scheduler was sent the command new
02/18/2014 15:12:06;0040;PBS_Server;Svr;tyrone-cluster;Scheduler was sent the command new
02/18/2014 15:12:41;0040;PBS_Server;Svr;tyrone-cluster;Scheduler was sent the command new
02/18/2014 15:13:15;0040;PBS_Server;Svr;tyrone-cluster;Scheduler was sent the command new
02/18/2014 15:13:49;0040;PBS_Server;Svr;tyrone-cluster;Scheduler was sent the command new
02/18/2014 15:14:15;0040;PBS_Server;Svr;tyrone-cluster;Scheduler was sent the command new
02/18/2014 15:14:46;0040;PBS_Server;Svr;tyrone-cluster;Scheduler was sent the command new
02/18/2014 15:15:19;0040;PBS_Server;Svr;tyrone-cluster;Scheduler was sent the command new
02/18/2014 15:15:45;0040;PBS_Server;Svr;tyrone-cluster;Scheduler was sent the command new
02/18/2014 15:16:16;0040;PBS_Server;Svr;tyrone-cluster;Scheduler was sent the command new
02/18/2014 15:16:24;0002;PBS_Server;Svr;PBS_Server;Torque Server Version = 3.0.5, loglevel = 0
02/18/2014 15:16:49;0040;PBS_Server;Svr;tyrone-cluster;Scheduler was sent the command new
02/18/2014 15:17:21;0040;PBS_Server;Svr;tyrone-cluster;Scheduler was sent the command new
02/18/2014 15:17:56;0040;PBS_Server;Svr;tyrone-cluster;Scheduler was sent the command new
02/18/2014 15:18:30;0040;PBS_Server;Svr;tyrone-cluster;Scheduler was sent the command new
02/18/2014 15:19:04;0040;PBS_Server;Svr;tyrone-cluster;Scheduler was sent the command new
02/18/2014 15:19:30;0040;PBS_Server;Svr;tyrone-cluster;Scheduler was sent the command new
02/18/2014 15:20:01;0040;PBS_Server;Svr;tyrone-cluster;Scheduler was sent the command new
02/18/2014 15:20:34;0040;PBS_Server;Svr;tyrone-cluster;Scheduler was sent the command new
02/18/2014 15:21:00;0040;PBS_Server;Svr;tyrone-cluster;Scheduler was sent the command new
02/18/2014 15:21:24;0002;PBS_Server;Svr;PBS_Server;Torque Server Version = 3.0.5, loglevel = 0
02/18/2014 15:21:31;0040;PBS_Server;Svr;tyrone-cluster;Scheduler was sent the command new
02/18/2014 15:22:04;0040;PBS_Server;Svr;tyrone-cluster;Scheduler was sent the command new
02/18/2014 15:22:30;0040;PBS_Server;Svr;tyrone-cluster;Scheduler was sent the command new
02/18/2014 15:23:00;0040;PBS_Server;Svr;tyrone-cluster;Scheduler was sent the command new
02/18/2014 15:23:37;0040;PBS_Server;Svr;tyrone-cluster;Scheduler was sent the command new
02/18/2014 15:24:06;0040;PBS_Server;Svr;tyrone-cluster;Scheduler was sent the command new
02/18/2014 15:24:41;0040;PBS_Server;Svr;tyrone-cluster;Scheduler was sent the command new
02/18/2014 15:25:15;0040;PBS_Server;Svr;tyrone-cluster;Scheduler was sent the command new
02/18/2014 15:25:49;0040;PBS_Server;Svr;tyrone-cluster;Scheduler was sent the command new
02/18/2014 15:26:15;0040;PBS_Server;Svr;tyrone-cluster;Scheduler was sent the command new
02/18/2014 15:26:24;0002;PBS_Server;Svr;PBS_Server;Torque Server Version = 3.0.5, loglevel = 0
02/18/2014 15:26:46;0040;PBS_Server;Svr;tyrone-cluster;Scheduler was sent the command new
02/18/2014 15:27:19;0040;PBS_Server;Svr;tyrone-cluster;Scheduler was sent the command new
02/18/2014 15:27:51;0040;PBS_Server;Svr;tyrone-cluster;Scheduler was sent the command new
02/18/2014 15:28:26;0040;PBS_Server;Svr;tyrone-cluster;Scheduler was sent the command new
02/18/2014 15:28:57;0040;PBS_Server;Svr;tyrone-cluster;Scheduler was sent the command new
02/18/2014 15:29:25;0040;PBS_Server;Svr;tyrone-cluster;Scheduler was sent the command new
02/18/2014 15:29:57;0040;PBS_Server;Svr;tyrone-cluster;Scheduler was sent the command new
02/18/2014 15:30:30;0040;PBS_Server;Svr;tyrone-cluster;Scheduler was sent the command new
02/18/2014 15:31:04;0040;PBS_Server;Svr;tyrone-cluster;Scheduler was sent the command new
02/18/2014 15:31:24;0002;PBS_Server;Svr;PBS_Server;Torque Server Version = 3.0.5, loglevel = 0
02/18/2014 15:31:30;0040;PBS_Server;Svr;tyrone-cluster;Scheduler was sent the command new
02/18/2014 15:32:01;0040;PBS_Server;Svr;tyrone-cluster;Scheduler was sent the command new
02/18/2014 15:32:34;0040;PBS_Server;Svr;tyrone-cluster;Scheduler was sent the command new
02/18/2014 15:33:00;0040;PBS_Server;Svr;tyrone-cluster;Scheduler was sent the command new
02/18/2014 15:33:31;0040;PBS_Server;Svr;tyrone-cluster;Scheduler was sent the command new
02/18/2014 15:34:04;0040;PBS_Server;Svr;tyrone-cluster;Scheduler was sent the command new
02/18/2014 15:34:36;0040;PBS_Server;Svr;tyrone-cluster;Scheduler was sent the command new
02/18/2014 15:35:09;0040;PBS_Server;Svr;tyrone-cluster;Scheduler was sent the command new
02/18/2014 15:35:37;0040;PBS_Server;Svr;tyrone-cluster;Scheduler was sent the command new
02/18/2014 15:36:09;0040;PBS_Server;Svr;tyrone-cluster;Scheduler was sent the command new
02/18/2014 15:36:24;0002;PBS_Server;Svr;PBS_Server;Torque Server Version = 3.0.5, loglevel = 0
02/18/2014 15:36:41;0040;PBS_Server;Svr;tyrone-cluster;Scheduler was sent the command new
02/18/2014 15:37:15;0040;PBS_Server;Svr;tyrone-cluster;Scheduler was sent the command new
02/18/2014 15:37:49;0040;PBS_Server;Svr;tyrone-cluster;Scheduler was sent the command new
02/18/2014 15:38:12;0100;PBS_Server;Job;35236.tyrone-cluster;enqueuing into batch, state 1 hop 1
02/18/2014 15:38:12;0008;PBS_Server;Job;35236.tyrone-cluster;Job rejected by all possible destinations (check syntax, queue resources, ...)
02/18/2014 15:38:12;0100;PBS_Server;Job;35236.tyrone-cluster;dequeuing from batch, state QUEUED
02/18/2014 15:38:12;0080;PBS_Server;Req;req_reject;Reject reply code=15041(Job rejected by all possible destinations (check syntax, queue resources, ...)), aux=0, type=Commit, from physkc@tyrone-node9
02/18/2014 15:38:12;0040;PBS_Server;Svr;tyrone-cluster;Scheduler was sent the command term
02/18/2014 15:38:15;0040;PBS_Server;Svr;tyrone-cluster;Scheduler was sent the command new
02/18/2014 15:38:46;0040;PBS_Server;Svr;tyrone-cluster;Scheduler was sent the command new
02/18/2014 15:39:19;0040;PBS_Server;Svr;tyrone-cluster;Scheduler was sent the command new
02/18/2014 15:39:45;0040;PBS_Server;Svr;tyrone-cluster;Scheduler was sent the command new
02/18/2014 15:40:16;0040;PBS_Server;Svr;tyrone-cluster;Scheduler was sent the command new
02/18/2014 15:40:49;0040;PBS_Server;Svr;tyrone-cluster;Scheduler was sent the command new
02/18/2014 15:40:50;0100;PBS_Server;Job;35237.tyrone-cluster;enqueuing into batch, state 1 hop 1
02/18/2014 15:40:50;0008;PBS_Server;Job;35237.tyrone-cluster;Job rejected by all possible destinations (check syntax, queue resources, ...)
02/18/2014 15:40:50;0100;PBS_Server;Job;35237.tyrone-cluster;dequeuing from batch, state QUEUED
02/18/2014 15:40:50;0080;PBS_Server;Req;req_reject;Reject reply code=15041(Job rejected by all possible destinations (check syntax, queue resources, ...)), aux=0, type=Commit, from physkc@tyrone-node9
02/18/2014 15:40:50;0040;PBS_Server;Svr;tyrone-cluster;Scheduler was sent the command term
02/18/2014 15:41:21;0040;PBS_Server;Svr;tyrone-cluster;Scheduler was sent the command new
02/18/2014 15:41:24;0002;PBS_Server;Svr;PBS_Server;Torque Server Version = 3.0.5, loglevel = 0
02/18/2014 15:41:56;0040;PBS_Server;Svr;tyrone-cluster;Scheduler was sent the command new
02/18/2014 15:42:29;0040;PBS_Server;Svr;tyrone-cluster;Scheduler was sent the command new
02/18/2014 15:43:04;0040;PBS_Server;Svr;tyrone-cluster;Scheduler was sent the command new
02/18/2014 15:43:30;0040;PBS_Server;Svr;tyrone-cluster;Scheduler was sent the command new
02/18/2014 15:43:30;0100;PBS_Server;Job;35238.tyrone-cluster;enqueuing into batch, state 1 hop 1
02/18/2014 15:43:30;0008;PBS_Server;Job;35238.tyrone-cluster;Job rejected by all possible destinations (check syntax, queue resources, ...)
02/18/2014 15:43:30;0100;PBS_Server;Job;35238.tyrone-cluster;dequeuing from batch, state QUEUED
02/18/2014 15:43:30;0080;PBS_Server;Req;req_reject;Reject reply code=15041(Job rejected by all possible destinations (check syntax, queue resources, ...)), aux=0, type=Commit, from root@tyrone-cluster
02/18/2014 15:43:30;0040;PBS_Server;Svr;tyrone-cluster;Scheduler was sent the command term
02/18/2014 15:44:01;0040;PBS_Server;Svr;tyrone-cluster;Scheduler was sent the command new
02/18/2014 15:44:28;0100;PBS_Server;Job;35239.tyrone-cluster;enqueuing into batch, state 1 hop 1
02/18/2014 15:44:28;0100;PBS_Server;Job;35239.tyrone-cluster;dequeuing from batch, state QUEUED
02/18/2014 15:44:28;0100;PBS_Server;Job;35239.tyrone-cluster;enqueuing into qp64, state 1 hop 1
02/18/2014 15:44:28;0008;PBS_Server;Job;35239.tyrone-cluster;Job Queued at request of csdshiku@tyrone-cluster, owner = csdshiku@tyrone-cluster, job name = script64.sh, queue = qp64
02/18/2014 15:44:28;0040;PBS_Server;Svr;tyrone-cluster;Scheduler was sent the command new
02/18/2014 15:44:28;0008;PBS_Server;Job;35239.tyrone-cluster;Job Modified at request of Scheduler@tyrone-cluster
02/18/2014 15:44:34;0040;PBS_Server;Svr;tyrone-cluster;Scheduler was sent the command new
02/18/2014 15:45:06;0040;PBS_Server;Svr;tyrone-cluster;Scheduler was sent the command new
02/18/2014 15:45:41;0040;PBS_Server;Svr;tyrone-cluster;Scheduler was sent the command new
02/18/2014 15:46:14;0040;PBS_Server;Svr;tyrone-cluster;Scheduler was sent the command new
02/18/2014 15:46:24;0002;PBS_Server;Svr;PBS_Server;Torque Server Version = 3.0.5, loglevel = 0
02/18/2014 15:46:50;0040;PBS_Server;Svr;tyrone-cluster;Scheduler was sent the command new
02/18/2014 15:47:15;0040;PBS_Server;Svr;tyrone-cluster;Scheduler was sent the command new
02/18/2014 15:47:46;0040;PBS_Server;Svr;tyrone-cluster;Scheduler was sent the command new
02/18/2014 15:48:19;0040;PBS_Server;Svr;tyrone-cluster;Scheduler was sent the command new
02/18/2014 15:48:51;0040;PBS_Server;Svr;tyrone-cluster;Scheduler was sent the command new
02/18/2014 15:49:15;0100;PBS_Server;Job;35240.tyrone-cluster;enqueuing into batch, state 1 hop 1
02/18/2014 15:49:15;0008;PBS_Server;Job;35240.tyrone-cluster;Job rejected by all possible destinations (check syntax, queue resources, ...)
02/18/2014 15:49:15;0100;PBS_Server;Job;35240.tyrone-cluster;dequeuing from batch, state QUEUED
02/18/2014 15:49:15;0080;PBS_Server;Req;req_reject;Reject reply code=15041(Job rejected by all possible destinations (check syntax, queue resources, ...)), aux=0, type=Commit, from physkc@tyrone-node9
02/18/2014 15:49:15;0040;PBS_Server;Svr;tyrone-cluster;Scheduler was sent the command term
02/18/2014 15:49:26;0040;PBS_Server;Svr;tyrone-cluster;Scheduler was sent the command new
02/18/2014 15:49:59;0040;PBS_Server;Svr;tyrone-cluster;Scheduler was sent the command new
02/18/2014 15:50:34;0040;PBS_Server;Svr;tyrone-cluster;Scheduler was sent the command new
02/18/2014 15:51:01;0040;PBS_Server;Svr;tyrone-cluster;Scheduler was sent the command new
02/18/2014 15:51:24;0002;PBS_Server;Svr;PBS_Server;Torque Server Version = 3.0.5, loglevel = 0
02/18/2014 15:51:31;0040;PBS_Server;Svr;tyrone-cluster;Scheduler was sent the command new
02/18/2014 15:52:04;0040;PBS_Server;Svr;tyrone-cluster;Scheduler was sent the command new
02/18/2014 15:52:36;0040;PBS_Server;Svr;tyrone-cluster;Scheduler was sent the command new
02/18/2014 15:53:11;0040;PBS_Server;Svr;tyrone-cluster;Scheduler was sent the command new
02/18/2014 15:53:44;0040;PBS_Server;Svr;tyrone-cluster;Scheduler was sent the command new
02/18/2014 15:54:20;0040;PBS_Server;Svr;tyrone-cluster;Scheduler was sent the command new
02/18/2014 15:54:45;0040;PBS_Server;Svr;tyrone-cluster;Scheduler was sent the command new
02/18/2014 15:55:16;0040;PBS_Server;Svr;tyrone-cluster;Scheduler was sent the command new
02/18/2014 15:55:49;0040;PBS_Server;Svr;tyrone-cluster;Scheduler was sent the command new
02/18/2014 15:56:21;0040;PBS_Server;Svr;tyrone-cluster;Scheduler was sent the command new
02/18/2014 15:56:24;0002;PBS_Server;Svr;PBS_Server;Torque Server Version = 3.0.5, loglevel = 0
02/18/2014 15:56:56;0040;PBS_Server;Svr;tyrone-cluster;Scheduler was sent the command new
02/18/2014 15:57:30;0040;PBS_Server;Svr;tyrone-cluster;Scheduler was sent the command new
02/18/2014 15:58:04;0040;PBS_Server;Svr;tyrone-cluster;Scheduler was sent the command new
02/18/2014 15:58:30;0040;PBS_Server;Svr;tyrone-cluster;Scheduler was sent the command new
02/18/2014 15:59:01;0040;PBS_Server;Svr;tyrone-cluster;Scheduler was sent the command new
02/18/2014 15:59:34;0040;PBS_Server;Svr;tyrone-cluster;Scheduler was sent the command new
02/18/2014 16:00:06;0040;PBS_Server;Svr;tyrone-cluster;Scheduler was sent the command new
02/18/2014 16:00:41;0040;PBS_Server;Svr;tyrone-cluster;Scheduler was sent the command new
02/18/2014 16:01:15;0040;PBS_Server;Svr;tyrone-cluster;Scheduler was sent the command new
02/18/2014 16:01:24;0002;PBS_Server;Svr;PBS_Server;Torque Server Version = 3.0.5, loglevel = 0
02/18/2014 16:01:47;0040;PBS_Server;Svr;tyrone-cluster;Scheduler was sent the command new
02/18/2014 16:02:16;0040;PBS_Server;Svr;tyrone-cluster;Scheduler was sent the command new
02/18/2014 16:02:46;0040;PBS_Server;Svr;tyrone-cluster;Scheduler was sent the command new
02/18/2014 16:03:19;0040;PBS_Server;Svr;tyrone-cluster;Scheduler was sent the command new
02/18/2014 16:03:20;0100;PBS_Server;Job;35241.tyrone-cluster;enqueuing into batch, state 1 hop 1
02/18/2014 16:03:20;0008;PBS_Server;Job;35241.tyrone-cluster;Job Queued at request of seckavya@tyrone-node9, owner = seckavya@tyrone-node9, job name = Ms1-A-C6, queue = batch
02/18/2014 16:03:20;0040;PBS_Server;Svr;tyrone-cluster;Scheduler was sent the command new
02/18/2014 16:03:20;0008;PBS_Server;Job;35241.tyrone-cluster;Job Modified at request of Scheduler@tyrone-cluster
02/18/2014 16:03:51;0040;PBS_Server;Svr;tyrone-cluster;Scheduler was sent the command new
02/18/2014 16:04:26;0040;PBS_Server;Svr;tyrone-cluster;Scheduler was sent the command new
02/18/2014 16:04:59;0040;PBS_Server;Svr;tyrone-cluster;Scheduler was sent the command new
02/18/2014 16:05:26;0100;PBS_Server;Job;35242.tyrone-cluster;enqueuing into batch, state 1 hop 1
02/18/2014 16:05:26;0008;PBS_Server;Job;35242.tyrone-cluster;Job rejected by all possible destinations (check syntax, queue resources, ...)
02/18/2014 16:05:26;0100;PBS_Server;Job;35242.tyrone-cluster;dequeuing from batch, state QUEUED
02/18/2014 16:05:26;0080;PBS_Server;Req;req_reject;Reject reply code=15041(Job rejected by all possible destinations (check syntax, queue resources, ...)), aux=0, type=Commit, from physkc@tyrone-node9
02/18/2014 16:05:26;0040;PBS_Server;Svr;tyrone-cluster;Scheduler was sent the command term
02/18/2014 16:05:34;0040;PBS_Server;Svr;tyrone-cluster;Scheduler was sent the command new
02/18/2014 16:06:00;0040;PBS_Server;Svr;tyrone-cluster;Scheduler was sent the command new
02/18/2014 16:06:24;0002;PBS_Server;Svr;PBS_Server;Torque Server Version = 3.0.5, loglevel = 0
02/18/2014 16:06:31;0040;PBS_Server;Svr;tyrone-cluster;Scheduler was sent the command new
02/18/2014 16:07:05;0040;PBS_Server;Svr;tyrone-cluster;Scheduler was sent the command new
02/18/2014 16:07:36;0040;PBS_Server;Svr;tyrone-cluster;Scheduler was sent the command new
02/18/2014 16:08:11;0040;PBS_Server;Svr;tyrone-cluster;Scheduler was sent the command new
02/18/2014 16:08:44;0040;PBS_Server;Svr;tyrone-cluster;Scheduler was sent the command new
02/18/2014 16:09:19;0040;PBS_Server;Svr;tyrone-cluster;Scheduler was sent the command new
02/18/2014 16:09:46;0040;PBS_Server;Svr;tyrone-cluster;Scheduler was sent the command new
02/18/2014 16:10:16;0040;PBS_Server;Svr;tyrone-cluster;Scheduler was sent the command new
02/18/2014 16:10:49;0040;PBS_Server;Svr;tyrone-cluster;Scheduler was sent the command new
02/18/2014 16:11:18;0100;PBS_Server;Job;35243.tyrone-cluster;enqueuing into batch, state 1 hop 1
02/18/2014 16:11:18;0100;PBS_Server;Job;35243.tyrone-cluster;dequeuing from batch, state QUEUED
02/18/2014 16:11:18;0100;PBS_Server;Job;35243.tyrone-cluster;enqueuing into idqueue, state 1 hop 1
02/18/2014 16:11:18;0008;PBS_Server;Job;35243.tyrone-cluster;Job Queued at request of metsomya@tyrone-cluster, owner = metsomya@tyrone-cluster, job name = poshit1, queue = idqueue
02/18/2014 16:11:18;0040;PBS_Server;Svr;tyrone-cluster;Scheduler was sent the command new
02/18/2014 16:11:18;0008;PBS_Server;Job;35243.tyrone-cluster;Job Modified at request of Scheduler@tyrone-cluster
02/18/2014 16:11:18;0008;PBS_Server;Job;35243.tyrone-cluster;Job Run at request of Scheduler@tyrone-cluster
02/18/2014 16:11:18;0040;PBS_Server;Svr;tyrone-cluster;Scheduler was sent the command recyc
02/18/2014 16:11:18;000d;PBS_Server;Job;35243.tyrone-cluster;Not sending email: User does not want mail of this type.
02/18/2014 16:11:19;0040;PBS_Server;Svr;tyrone-cluster;Scheduler was sent the command new
02/18/2014 16:11:24;0002;PBS_Server;Svr;PBS_Server;Torque Server Version = 3.0.5, loglevel = 0
02/18/2014 16:11:50;0040;PBS_Server;Svr;tyrone-cluster;Scheduler was sent the command new
02/18/2014 16:11:51;000d;PBS_Server;Job;35243.tyrone-cluster;Not sending email: User does not want mail of this type.
02/18/2014 16:11:51;0010;PBS_Server;Job;35243.tyrone-cluster;Exit_status=0 resources_used.cput=00:13:43 resources_used.mem=0kb resources_used.vmem=0kb resources_used.walltime=00:00:33
02/18/2014 16:11:51;0008;PBS_Server;Job;NULL;on_job_exit valid pjob: 0x1dfc540 (substate=50)
02/18/2014 16:11:51;0008;PBS_Server;Job;NULL;on_job_exit valid pjob: 0x1dfc540 (substate=51)
02/18/2014 16:11:52;0008;PBS_Server;Job;NULL;on_job_exit valid pjob: 0x1dfc540 (substate=51)
02/18/2014 16:11:52;0008;PBS_Server;Job;NULL;on_job_exit valid pjob: 0x1dfc540 (substate=53)
02/18/2014 16:11:52;0100;PBS_Server;Job;35243.tyrone-cluster;dequeuing from idqueue, state COMPLETE
02/18/2014 16:11:52;0040;PBS_Server;Svr;tyrone-cluster;Scheduler was sent the command term
02/18/2014 16:12:22;0040;PBS_Server;Svr;tyrone-cluster;Scheduler was sent the command new
02/18/2014 16:12:51;0040;PBS_Server;Svr;tyrone-cluster;Scheduler was sent the command new
02/18/2014 16:13:26;0040;PBS_Server;Svr;tyrone-cluster;Scheduler was sent the command new
02/18/2014 16:13:38;0100;PBS_Server;Job;35244.tyrone-cluster;enqueuing into batch, state 1 hop 1
02/18/2014 16:13:38;0100;PBS_Server;Job;35244.tyrone-cluster;dequeuing from batch, state QUEUED
02/18/2014 16:13:38;0100;PBS_Server;Job;35244.tyrone-cluster;enqueuing into idqueue, state 1 hop 1
02/18/2014 16:13:38;0008;PBS_Server;Job;35244.tyrone-cluster;Job Queued at request of metsomya@tyrone-cluster, owner = metsomya@tyrone-cluster, job name = poshit1, queue = idqueue
02/18/2014 16:13:38;0040;PBS_Server;Svr;tyrone-cluster;Scheduler was sent the command new
02/18/2014 16:13:38;0008;PBS_Server;Job;35244.tyrone-cluster;Job Modified at request of Scheduler@tyrone-cluster
02/18/2014 16:13:38;0008;PBS_Server;Job;35244.tyrone-cluster;Job Run at request of Scheduler@tyrone-cluster
02/18/2014 16:13:38;0040;PBS_Server;Svr;tyrone-cluster;Scheduler was sent the command recyc
02/18/2014 16:13:38;000d;PBS_Server;Job;35244.tyrone-cluster;Not sending email: User does not want mail of this type.
02/18/2014 16:13:40;0100;PBS_Server;Job;35245.tyrone-cluster;enqueuing into batch, state 1 hop 1
02/18/2014 16:13:40;0008;PBS_Server;Job;35245.tyrone-cluster;Job rejected by all possible destinations (check syntax, queue resources, ...)
02/18/2014 16:13:40;0100;PBS_Server;Job;35245.tyrone-cluster;dequeuing from batch, state QUEUED
02/18/2014 16:13:40;0080;PBS_Server;Req;req_reject;Reject reply code=15041(Job rejected by all possible destinations (check syntax, queue resources, ...)), aux=0, type=Commit, from physkc@tyrone-node9
02/18/2014 16:13:40;0040;PBS_Server;Svr;tyrone-cluster;Scheduler was sent the command term
02/18/2014 16:13:58;0040;PBS_Server;Svr;tyrone-cluster;Scheduler was sent the command new
02/18/2014 16:14:10;000d;PBS_Server;Job;35244.tyrone-cluster;Not sending email: User does not want mail of this type.
02/18/2014 16:14:10;0010;PBS_Server;Job;35244.tyrone-cluster;Exit_status=0 resources_used.cput=00:09:59 resources_used.mem=0kb resources_used.vmem=0kb resources_used.walltime=00:00:32
02/18/2014 16:14:10;0008;PBS_Server;Job;NULL;on_job_exit valid pjob: 0x1dfc540 (substate=50)
02/18/2014 16:14:10;0008;PBS_Server;Job;NULL;on_job_exit valid pjob: 0x1dfc540 (substate=51)
02/18/2014 16:14:12;0008;PBS_Server;Job;NULL;on_job_exit valid pjob: 0x1dfc540 (substate=51)
02/18/2014 16:14:12;0008;PBS_Server;Job;NULL;on_job_exit valid pjob: 0x1dfc540 (substate=53)
02/18/2014 16:14:12;0100;PBS_Server;Job;35244.tyrone-cluster;dequeuing from idqueue, state COMPLETE
02/18/2014 16:14:12;0040;PBS_Server;Svr;tyrone-cluster;Scheduler was sent the command term
02/18/2014 16:14:25;0040;PBS_Server;Svr;tyrone-cluster;Scheduler was sent the command new
02/18/2014 16:14:57;0040;PBS_Server;Svr;tyrone-cluster;Scheduler was sent the command new
02/18/2014 16:15:29;0040;PBS_Server;Svr;tyrone-cluster;Scheduler was sent the command new
02/18/2014 16:16:04;0040;PBS_Server;Svr;tyrone-cluster;Scheduler was sent the command new
02/18/2014 16:16:24;0002;PBS_Server;Svr;PBS_Server;Torque Server Version = 3.0.5, loglevel = 0
02/18/2014 16:16:30;0040;PBS_Server;Svr;tyrone-cluster;Scheduler was sent the command new
02/18/2014 16:17:01;0040;PBS_Server;Svr;tyrone-cluster;Scheduler was sent the command new
02/18/2014 16:17:34;0040;PBS_Server;Svr;tyrone-cluster;Scheduler was sent the command new
02/18/2014 16:18:06;0040;PBS_Server;Svr;tyrone-cluster;Scheduler was sent the command new
02/18/2014 16:18:41;0040;PBS_Server;Svr;tyrone-cluster;Scheduler was sent the command new
02/18/2014 16:19:15;0040;PBS_Server;Svr;tyrone-cluster;Scheduler was sent the command new
02/18/2014 16:19:50;0040;PBS_Server;Svr;tyrone-cluster;Scheduler was sent the command new
02/18/2014 16:20:16;0040;PBS_Server;Svr;tyrone-cluster;Scheduler was sent the command new
02/18/2014 16:20:46;0040;PBS_Server;Svr;tyrone-cluster;Scheduler was sent the command new
02/18/2014 16:21:20;0040;PBS_Server;Svr;tyrone-cluster;Scheduler was sent the command new
02/18/2014 16:21:24;0002;PBS_Server;Svr;PBS_Server;Torque Server Version = 3.0.5, loglevel = 0
02/18/2014 16:21:51;0040;PBS_Server;Svr;tyrone-cluster;Scheduler was sent the command new
02/18/2014 16:22:26;0040;PBS_Server;Svr;tyrone-cluster;Scheduler was sent the command new
02/18/2014 16:22:59;0040;PBS_Server;Svr;tyrone-cluster;Scheduler was sent the command new
02/18/2014 16:23:34;0040;PBS_Server;Svr;tyrone-cluster;Scheduler was sent the command new
02/18/2014 16:24:00;0040;PBS_Server;Svr;tyrone-cluster;Scheduler was sent the command new
02/18/2014 16:24:31;0040;PBS_Server;Svr;tyrone-cluster;Scheduler was sent the command new
02/18/2014 16:25:05;0040;PBS_Server;Svr;tyrone-cluster;Scheduler was sent the command new
02/18/2014 16:25:36;0040;PBS_Server;Svr;tyrone-cluster;Scheduler was sent the command new
02/18/2014 16:26:11;0040;PBS_Server;Svr;tyrone-cluster;Scheduler was sent the command new
02/18/2014 16:26:24;0002;PBS_Server;Svr;PBS_Server;Torque Server Version = 3.0.5, loglevel = 0
02/18/2014 16:26:31;0100;PBS_Server;Job;35246.tyrone-cluster;enqueuing into batch, state 1 hop 1
02/18/2014 16:26:31;0008;PBS_Server;Job;35246.tyrone-cluster;Job rejected by all possible destinations (check syntax, queue resources, ...)
02/18/2014 16:26:31;0100;PBS_Server;Job;35246.tyrone-cluster;dequeuing from batch, state QUEUED
02/18/2014 16:26:31;0080;PBS_Server;Req;req_reject;Reject reply code=15041(Job rejected by all possible destinations (check syntax, queue resources, ...)), aux=0, type=Commit, from physkc@tyrone-node9
02/18/2014 16:26:31;0040;PBS_Server;Svr;tyrone-cluster;Scheduler was sent the command term
02/18/2014 16:26:44;0040;PBS_Server;Svr;tyrone-cluster;Scheduler was sent the command new
02/18/2014 16:27:19;0040;PBS_Server;Svr;tyrone-cluster;Scheduler was sent the command new
02/18/2014 16:27:46;0040;PBS_Server;Svr;tyrone-cluster;Scheduler was sent the command new
02/18/2014 16:28:16;0040;PBS_Server;Svr;tyrone-cluster;Scheduler was sent the command new
02/18/2014 16:28:49;0040;PBS_Server;Svr;tyrone-cluster;Scheduler was sent the command new
02/18/2014 16:29:21;0040;PBS_Server;Svr;tyrone-cluster;Scheduler was sent the command new
02/18/2014 16:29:55;0040;PBS_Server;Svr;tyrone-cluster;Scheduler was sent the command new
02/18/2014 16:30:30;0040;PBS_Server;Svr;tyrone-cluster;Scheduler was sent the command new
02/18/2014 16:31:04;0040;PBS_Server;Svr;tyrone-cluster;Scheduler was sent the command new
02/18/2014 16:31:24;0002;PBS_Server;Svr;PBS_Server;Torque Server Version = 3.0.5, loglevel = 0
02/18/2014 16:31:31;0040;PBS_Server;Svr;tyrone-cluster;Scheduler was sent the command new
02/18/2014 16:31:43;0100;PBS_Server;Job;35247.tyrone-cluster;enqueuing into batch, state 1 hop 1
02/18/2014 16:31:43;0008;PBS_Server;Job;35247.tyrone-cluster;Job Queued at request of icrsanch@tyrone-cluster, owner = icrsanch@tyrone-cluster, job name = job256, queue = batch
02/18/2014 16:31:43;0040;PBS_Server;Svr;tyrone-cluster;Scheduler was sent the command new
02/18/2014 16:31:43;0008;PBS_Server;Job;35247.tyrone-cluster;Job Modified at request of Scheduler@tyrone-cluster
02/18/2014 16:31:50;0100;PBS_Server;Job;35248.tyrone-cluster;enqueuing into batch, state 1 hop 1
02/18/2014 16:31:50;0008;PBS_Server;Job;35248.tyrone-cluster;Job Queued at request of icrsanch@tyrone-cluster, owner = icrsanch@tyrone-cluster, job name = job256, queue = batch
02/18/2014 16:31:50;0040;PBS_Server;Svr;tyrone-cluster;Scheduler was sent the command new
02/18/2014 16:31:50;0008;PBS_Server;Job;35248.tyrone-cluster;Job Modified at request of Scheduler@tyrone-cluster
02/18/2014 16:32:01;0040;PBS_Server;Svr;tyrone-cluster;Scheduler was sent the command new
02/18/2014 16:32:15;0040;PBS_Server;Svr;tyrone-cluster;Scheduler was sent the command new
02/18/2014 16:32:21;0040;PBS_Server;Svr;tyrone-cluster;Scheduler was sent the command new
02/18/2014 16:32:34;0040;PBS_Server;Svr;tyrone-cluster;Scheduler was sent the command new
02/18/2014 16:32:46;0040;PBS_Server;Svr;tyrone-cluster;Scheduler was sent the command new
02/18/2014 16:32:56;0040;PBS_Server;Svr;tyrone-cluster;Scheduler was sent the command new
02/18/2014 16:33:06;0040;PBS_Server;Svr;tyrone-cluster;Scheduler was sent the command new
02/18/2014 16:33:20;0040;PBS_Server;Svr;tyrone-cluster;Scheduler was sent the command new
02/18/2014 16:33:30;0040;PBS_Server;Svr;tyrone-cluster;Scheduler was sent the command new
02/18/2014 16:33:40;0040;PBS_Server;Svr;tyrone-cluster;Scheduler was sent the command new
02/18/2014 16:33:51;0040;PBS_Server;Svr;tyrone-cluster;Scheduler was sent the command new
02/18/2014 16:34:04;0040;PBS_Server;Svr;tyrone-cluster;Scheduler was sent the command new
02/18/2014 16:34:15;0040;PBS_Server;Svr;tyrone-cluster;Scheduler was sent the command new
02/18/2014 16:34:26;0040;PBS_Server;Svr;tyrone-cluster;Scheduler was sent the command new
02/18/2014 16:34:31;0040;PBS_Server;Svr;tyrone-cluster;Scheduler was sent the command new
02/18/2014 16:34:50;0040;PBS_Server;Svr;tyrone-cluster;Scheduler was sent the command new
02/18/2014 16:35:00;0040;PBS_Server;Svr;tyrone-cluster;Scheduler was sent the command new
02/18/2014 16:35:15;0040;PBS_Server;Svr;tyrone-cluster;Scheduler was sent the command new
02/18/2014 16:35:34;0040;PBS_Server;Svr;tyrone-cluster;Scheduler was sent the command new
02/18/2014 16:35:46;0040;PBS_Server;Svr;tyrone-cluster;Scheduler was sent the command new
02/18/2014 16:36:01;0040;PBS_Server;Svr;tyrone-cluster;Scheduler was sent the command new
02/18/2014 16:36:06;0040;PBS_Server;Svr;tyrone-cluster;Scheduler was sent the command new
02/18/2014 16:36:20;0040;PBS_Server;Svr;tyrone-cluster;Scheduler was sent the command new
02/18/2014 16:36:24;0002;PBS_Server;Svr;PBS_Server;Torque Server Version = 3.0.5, loglevel = 0
02/18/2014 16:36:31;0040;PBS_Server;Svr;tyrone-cluster;Scheduler was sent the command new
02/18/2014 16:36:41;0040;PBS_Server;Svr;tyrone-cluster;Scheduler was sent the command new
02/18/2014 16:36:51;0040;PBS_Server;Svr;tyrone-cluster;Scheduler was sent the command new
02/18/2014 16:37:04;0040;PBS_Server;Svr;tyrone-cluster;Scheduler was sent the command new
02/18/2014 16:37:14;0040;PBS_Server;Svr;tyrone-cluster;Scheduler was sent the command new
02/18/2014 16:37:26;0040;PBS_Server;Svr;tyrone-cluster;Scheduler was sent the command new
02/18/2014 16:37:36;0040;PBS_Server;Svr;tyrone-cluster;Scheduler was sent the command new
02/18/2014 16:37:50;0040;PBS_Server;Svr;tyrone-cluster;Scheduler was sent the command new
02/18/2014 16:38:00;0040;PBS_Server;Svr;tyrone-cluster;Scheduler was sent the command new
02/18/2014 16:38:11;0040;PBS_Server;Svr;tyrone-cluster;Scheduler was sent the command new
02/18/2014 16:38:16;0040;PBS_Server;Svr;tyrone-cluster;Scheduler was sent the command new
02/18/2014 16:38:34;0040;PBS_Server;Svr;tyrone-cluster;Scheduler was sent the command new
02/18/2014 16:38:44;0040;PBS_Server;Svr;tyrone-cluster;Scheduler was sent the command new
02/18/2014 16:38:46;0040;PBS_Server;Svr;tyrone-cluster;Scheduler was sent the command new
02/18/2014 16:39:01;0040;PBS_Server;Svr;tyrone-cluster;Scheduler was sent the command new
02/18/2014 16:39:20;0040;PBS_Server;Svr;tyrone-cluster;Scheduler was sent the command new
02/18/2014 16:39:31;0040;PBS_Server;Svr;tyrone-cluster;Scheduler was sent the command new
02/18/2014 16:39:45;0040;PBS_Server;Svr;tyrone-cluster;Scheduler was sent the command new
02/18/2014 16:39:51;0040;PBS_Server;Svr;tyrone-cluster;Scheduler was sent the command new
02/18/2014 16:40:05;0040;PBS_Server;Svr;tyrone-cluster;Scheduler was sent the command new
02/18/2014 16:40:16;0040;PBS_Server;Svr;tyrone-cluster;Scheduler was sent the command new
02/18/2014 16:40:26;0040;PBS_Server;Svr;tyrone-cluster;Scheduler was sent the command new
02/18/2014 16:40:36;0040;PBS_Server;Svr;tyrone-cluster;Scheduler was sent the command new
02/18/2014 16:40:49;0040;PBS_Server;Svr;tyrone-cluster;Scheduler was sent the command new
02/18/2014 16:41:00;0040;PBS_Server;Svr;tyrone-cluster;Scheduler was sent the command new
02/18/2014 16:41:11;0040;PBS_Server;Svr;tyrone-cluster;Scheduler was sent the command new
02/18/2014 16:41:21;0040;PBS_Server;Svr;tyrone-cluster;Scheduler was sent the command new
02/18/2014 16:41:24;0002;PBS_Server;Svr;PBS_Server;Torque Server Version = 3.0.5, loglevel = 0
02/18/2014 16:41:34;0040;PBS_Server;Svr;tyrone-cluster;Scheduler was sent the command new
02/18/2014 16:41:44;0040;PBS_Server;Svr;tyrone-cluster;Scheduler was sent the command new
02/18/2014 16:41:56;0040;PBS_Server;Svr;tyrone-cluster;Scheduler was sent the command new
02/18/2014 16:42:00;0040;PBS_Server;Svr;tyrone-cluster;Scheduler was sent the command new
02/18/2014 16:42:20;0040;PBS_Server;Svr;tyrone-cluster;Scheduler was sent the command new
02/18/2014 16:42:30;0040;PBS_Server;Svr;tyrone-cluster;Scheduler was sent the command new
02/18/2014 16:42:46;0040;PBS_Server;Svr;tyrone-cluster;Scheduler was sent the command new
02/18/2014 16:43:04;0040;PBS_Server;Svr;tyrone-cluster;Scheduler was sent the command new
02/18/2014 16:43:16;0040;PBS_Server;Svr;tyrone-cluster;Scheduler was sent the command new
02/18/2014 16:43:31;0040;PBS_Server;Svr;tyrone-cluster;Scheduler was sent the command new
02/18/2014 16:43:36;0040;PBS_Server;Svr;tyrone-cluster;Scheduler was sent the command new
02/18/2014 16:43:50;0040;PBS_Server;Svr;tyrone-cluster;Scheduler was sent the command new
02/18/2014 16:44:01;0040;PBS_Server;Svr;tyrone-cluster;Scheduler was sent the command new
02/18/2014 16:44:11;0040;PBS_Server;Svr;tyrone-cluster;Scheduler was sent the command new
02/18/2014 16:44:21;0040;PBS_Server;Svr;tyrone-cluster;Scheduler was sent the command new
02/18/2014 16:44:35;0040;PBS_Server;Svr;tyrone-cluster;Scheduler was sent the command new
02/18/2014 16:44:45;0040;PBS_Server;Svr;tyrone-cluster;Scheduler was sent the command new
02/18/2014 16:44:56;0040;PBS_Server;Svr;tyrone-cluster;Scheduler was sent the command new
02/18/2014 16:45:06;0040;PBS_Server;Svr;tyrone-cluster;Scheduler was sent the command new
02/18/2014 16:45:19;0040;PBS_Server;Svr;tyrone-cluster;Scheduler was sent the command new
02/18/2014 16:45:29;0040;PBS_Server;Svr;tyrone-cluster;Scheduler was sent the command new
02/18/2014 16:45:41;0040;PBS_Server;Svr;tyrone-cluster;Scheduler was sent the command new
02/18/2014 16:45:45;0040;PBS_Server;Svr;tyrone-cluster;Scheduler was sent the command new
02/18/2014 16:46:05;0040;PBS_Server;Svr;tyrone-cluster;Scheduler was sent the command new
02/18/2014 16:46:15;0040;PBS_Server;Svr;tyrone-cluster;Scheduler was sent the command new
02/18/2014 16:46:24;0002;PBS_Server;Svr;PBS_Server;Torque Server Version = 3.0.5, loglevel = 0
02/18/2014 16:46:31;0040;PBS_Server;Svr;tyrone-cluster;Scheduler was sent the command new
02/18/2014 16:46:46;0040;PBS_Server;Svr;tyrone-cluster;Scheduler was sent the command new
02/18/2014 16:47:01;0040;PBS_Server;Svr;tyrone-cluster;Scheduler was sent the command new
02/18/2014 16:47:16;0040;PBS_Server;Svr;tyrone-cluster;Scheduler was sent the command new
02/18/2014 16:47:35;0040;PBS_Server;Svr;tyrone-cluster;Scheduler was sent the command new
02/18/2014 16:47:46;0040;PBS_Server;Svr;tyrone-cluster;Scheduler was sent the command new
02/18/2014 16:48:06;0040;PBS_Server;Svr;tyrone-cluster;Scheduler was sent the command new
02/18/2014 16:48:20;0040;PBS_Server;Svr;tyrone-cluster;Scheduler was sent the command new
02/18/2014 16:48:41;0040;PBS_Server;Svr;tyrone-cluster;Scheduler was sent the command new
02/18/2014 16:48:51;0040;PBS_Server;Svr;tyrone-cluster;Scheduler was sent the command new
02/18/2014 16:49:15;0040;PBS_Server;Svr;tyrone-cluster;Scheduler was sent the command new
02/18/2014 16:49:26;0040;PBS_Server;Svr;tyrone-cluster;Scheduler was sent the command new
02/18/2014 16:49:49;0040;PBS_Server;Svr;tyrone-cluster;Scheduler was sent the command new
02/18/2014 16:49:58;0040;PBS_Server;Svr;tyrone-cluster;Scheduler was sent the command new
02/18/2014 16:50:16;0040;PBS_Server;Svr;tyrone-cluster;Scheduler was sent the command new
02/18/2014 16:50:24;0040;PBS_Server;Svr;tyrone-cluster;Scheduler was sent the command new
02/18/2014 16:50:46;0040;PBS_Server;Svr;tyrone-cluster;Scheduler was sent the command new
02/18/2014 16:50:56;0040;PBS_Server;Svr;tyrone-cluster;Scheduler was sent the command new
02/18/2014 16:51:19;0040;PBS_Server;Svr;tyrone-cluster;Scheduler was sent the command new
02/18/2014 16:51:24;0002;PBS_Server;Svr;PBS_Server;Torque Server Version = 3.0.5, loglevel = 0
02/18/2014 16:51:25;0040;PBS_Server;Svr;tyrone-cluster;Scheduler was sent the command new
02/18/2014 16:51:51;0040;PBS_Server;Svr;tyrone-cluster;Scheduler was sent the command new
02/18/2014 16:51:54;0040;PBS_Server;Svr;tyrone-cluster;Scheduler was sent the command new
02/18/2014 16:52:26;0040;PBS_Server;Svr;tyrone-cluster;Scheduler was sent the command new
02/18/2014 16:52:59;0040;PBS_Server;Svr;tyrone-cluster;Scheduler was sent the command new
02/18/2014 16:53:34;0040;PBS_Server;Svr;tyrone-cluster;Scheduler was sent the command new
02/18/2014 16:54:01;0040;PBS_Server;Svr;tyrone-cluster;Scheduler was sent the command new
02/18/2014 16:54:31;0040;PBS_Server;Svr;tyrone-cluster;Scheduler was sent the command new
02/18/2014 16:55:05;0040;PBS_Server;Svr;tyrone-cluster;Scheduler was sent the command new
02/18/2014 16:55:37;0040;PBS_Server;Svr;tyrone-cluster;Scheduler was sent the command new
02/18/2014 16:56:11;0040;PBS_Server;Svr;tyrone-cluster;Scheduler was sent the command new
02/18/2014 16:56:24;0002;PBS_Server;Svr;PBS_Server;Torque Server Version = 3.0.5, loglevel = 0
02/18/2014 16:56:45;0040;PBS_Server;Svr;tyrone-cluster;Scheduler was sent the command new
02/18/2014 16:57:20;0040;PBS_Server;Svr;tyrone-cluster;Scheduler was sent the command new
02/18/2014 16:57:46;0040;PBS_Server;Svr;tyrone-cluster;Scheduler was sent the command new
02/18/2014 16:58:16;0040;PBS_Server;Svr;tyrone-cluster;Scheduler was sent the command new
02/18/2014 16:58:49;0040;PBS_Server;Svr;tyrone-cluster;Scheduler was sent the command new
02/18/2014 16:59:21;0040;PBS_Server;Svr;tyrone-cluster;Scheduler was sent the command new
02/18/2014 16:59:56;0040;PBS_Server;Svr;tyrone-cluster;Scheduler was sent the command new
02/18/2014 17:00:30;0040;PBS_Server;Svr;tyrone-cluster;Scheduler was sent the command new
02/18/2014 17:01:05;0040;PBS_Server;Svr;tyrone-cluster;Scheduler was sent the command new
02/18/2014 17:01:24;0002;PBS_Server;Svr;PBS_Server;Torque Server Version = 3.0.5, loglevel = 0
02/18/2014 17:01:30;0040;PBS_Server;Svr;tyrone-cluster;Scheduler was sent the command new
02/18/2014 17:02:01;0040;PBS_Server;Svr;tyrone-cluster;Scheduler was sent the command new
02/18/2014 17:02:35;0040;PBS_Server;Svr;tyrone-cluster;Scheduler was sent the command new
02/18/2014 17:03:06;0040;PBS_Server;Svr;tyrone-cluster;Scheduler was sent the command new
02/18/2014 17:03:41;0040;PBS_Server;Svr;tyrone-cluster;Scheduler was sent the command new
02/18/2014 17:04:14;0040;PBS_Server;Svr;tyrone-cluster;Scheduler was sent the command new
02/18/2014 17:04:50;0040;PBS_Server;Svr;tyrone-cluster;Scheduler was sent the command new
02/18/2014 17:05:16;0040;PBS_Server;Svr;tyrone-cluster;Scheduler was sent the command new
02/18/2014 17:05:46;0040;PBS_Server;Svr;tyrone-cluster;Scheduler was sent the command new
02/18/2014 17:06:20;0040;PBS_Server;Svr;tyrone-cluster;Scheduler was sent the command new
02/18/2014 17:06:24;0002;PBS_Server;Svr;PBS_Server;Torque Server Version = 3.0.5, loglevel = 0
02/18/2014 17:06:51;0040;PBS_Server;Svr;tyrone-cluster;Scheduler was sent the command new
02/18/2014 17:07:26;0040;PBS_Server;Svr;tyrone-cluster;Scheduler was sent the command new
02/18/2014 17:07:59;0040;PBS_Server;Svr;tyrone-cluster;Scheduler was sent the command new
02/18/2014 17:08:35;0040;PBS_Server;Svr;tyrone-cluster;Scheduler was sent the command new
02/18/2014 17:09:01;0040;PBS_Server;Svr;tyrone-cluster;Scheduler was sent the command new
02/18/2014 17:09:31;0040;PBS_Server;Svr;tyrone-cluster;Scheduler was sent the command new
02/18/2014 17:10:05;0040;PBS_Server;Svr;tyrone-cluster;Scheduler was sent the command new
02/18/2014 17:10:36;0040;PBS_Server;Svr;tyrone-cluster;Scheduler was sent the command new
02/18/2014 17:11:11;0040;PBS_Server;Svr;tyrone-cluster;Scheduler was sent the command new
02/18/2014 17:11:24;0002;PBS_Server;Svr;PBS_Server;Torque Server Version = 3.0.5, loglevel = 0
02/18/2014 17:11:44;0040;PBS_Server;Svr;tyrone-cluster;Scheduler was sent the command new
02/18/2014 17:12:09;0040;PBS_Server;Svr;tyrone-cluster;Scheduler was sent the command new
02/18/2014 17:12:41;0040;PBS_Server;Svr;tyrone-cluster;Scheduler was sent the command new
02/18/2014 17:13:14;0040;PBS_Server;Svr;tyrone-cluster;Scheduler was sent the command new
02/18/2014 17:13:39;0040;PBS_Server;Svr;tyrone-cluster;Scheduler was sent the command new
02/18/2014 17:14:11;0040;PBS_Server;Svr;tyrone-cluster;Scheduler was sent the command new
02/18/2014 17:14:45;0040;PBS_Server;Svr;tyrone-cluster;Scheduler was sent the command new
02/18/2014 17:15:20;0040;PBS_Server;Svr;tyrone-cluster;Scheduler was sent the command new
02/18/2014 17:15:45;0040;PBS_Server;Svr;tyrone-cluster;Scheduler was sent the command new
02/18/2014 17:16:14;0040;PBS_Server;Svr;tyrone-cluster;Scheduler was sent the command new
02/18/2014 17:16:24;0002;PBS_Server;Svr;PBS_Server;Torque Server Version = 3.0.5, loglevel = 0
02/18/2014 17:16:50;0040;PBS_Server;Svr;tyrone-cluster;Scheduler was sent the command new
02/18/2014 17:17:15;0040;PBS_Server;Svr;tyrone-cluster;Scheduler was sent the command new
02/18/2014 17:17:45;0040;PBS_Server;Svr;tyrone-cluster;Scheduler was sent the command new
02/18/2014 17:18:20;0040;PBS_Server;Svr;tyrone-cluster;Scheduler was sent the command new
02/18/2014 17:18:45;0040;PBS_Server;Svr;tyrone-cluster;Scheduler was sent the command new
02/18/2014 17:19:15;0040;PBS_Server;Svr;tyrone-cluster;Scheduler was sent the command new
02/18/2014 17:19:49;0040;PBS_Server;Svr;tyrone-cluster;Scheduler was sent the command new
02/18/2014 17:20:15;0040;PBS_Server;Svr;tyrone-cluster;Scheduler was sent the command new
02/18/2014 17:20:45;0040;PBS_Server;Svr;tyrone-cluster;Scheduler was sent the command new
02/18/2014 17:21:20;0040;PBS_Server;Svr;tyrone-cluster;Scheduler was sent the command new
02/18/2014 17:21:24;0002;PBS_Server;Svr;PBS_Server;Torque Server Version = 3.0.5, loglevel = 0
02/18/2014 17:21:45;0040;PBS_Server;Svr;tyrone-cluster;Scheduler was sent the command new
02/18/2014 17:22:15;0040;PBS_Server;Svr;tyrone-cluster;Scheduler was sent the command new
02/18/2014 17:22:50;0040;PBS_Server;Svr;tyrone-cluster;Scheduler was sent the command new
02/18/2014 17:23:15;0040;PBS_Server;Svr;tyrone-cluster;Scheduler was sent the command new
02/18/2014 17:23:45;0040;PBS_Server;Svr;tyrone-cluster;Scheduler was sent the command new
02/18/2014 17:24:20;0040;PBS_Server;Svr;tyrone-cluster;Scheduler was sent the command new
02/18/2014 17:24:45;0040;PBS_Server;Svr;tyrone-cluster;Scheduler was sent the command new
02/18/2014 17:25:14;0040;PBS_Server;Svr;tyrone-cluster;Scheduler was sent the command new
02/18/2014 17:25:50;0040;PBS_Server;Svr;tyrone-cluster;Scheduler was sent the command new
02/18/2014 17:26:15;0040;PBS_Server;Svr;tyrone-cluster;Scheduler was sent the command new
02/18/2014 17:26:24;0002;PBS_Server;Svr;PBS_Server;Torque Server Version = 3.0.5, loglevel = 0
02/18/2014 17:26:45;0040;PBS_Server;Svr;tyrone-cluster;Scheduler was sent the command new
02/18/2014 17:27:20;0040;PBS_Server;Svr;tyrone-cluster;Scheduler was sent the command new
02/18/2014 17:27:45;0040;PBS_Server;Svr;tyrone-cluster;Scheduler was sent the command new
02/18/2014 17:28:14;0040;PBS_Server;Svr;tyrone-cluster;Scheduler was sent the command new
02/18/2014 17:28:50;0040;PBS_Server;Svr;tyrone-cluster;Scheduler was sent the command new
02/18/2014 17:29:15;0040;PBS_Server;Svr;tyrone-cluster;Scheduler was sent the command new
02/18/2014 17:29:46;0040;PBS_Server;Svr;tyrone-cluster;Scheduler was sent the command new
02/18/2014 17:30:20;0040;PBS_Server;Svr;tyrone-cluster;Scheduler was sent the command new
02/18/2014 17:30:51;0040;PBS_Server;Svr;tyrone-cluster;Scheduler was sent the command new
02/18/2014 17:31:24;0002;PBS_Server;Svr;PBS_Server;Torque Server Version = 3.0.5, loglevel = 0
02/18/2014 17:31:25;0040;PBS_Server;Svr;tyrone-cluster;Scheduler was sent the command new
02/18/2014 17:31:59;0040;PBS_Server;Svr;tyrone-cluster;Scheduler was sent the command new
02/18/2014 17:32:25;0040;PBS_Server;Svr;tyrone-cluster;Scheduler was sent the command new
02/18/2014 17:32:56;0040;PBS_Server;Svr;tyrone-cluster;Scheduler was sent the command new
02/18/2014 17:33:30;0040;PBS_Server;Svr;tyrone-cluster;Scheduler was sent the command new
02/18/2014 17:34:05;0040;PBS_Server;Svr;tyrone-cluster;Scheduler was sent the command new
02/18/2014 17:34:36;0040;PBS_Server;Svr;tyrone-cluster;Scheduler was sent the command new
02/18/2014 17:35:11;0040;PBS_Server;Svr;tyrone-cluster;Scheduler was sent the command new
02/18/2014 17:35:44;0040;PBS_Server;Svr;tyrone-cluster;Scheduler was sent the command new
02/18/2014 17:36:09;0040;PBS_Server;Svr;tyrone-cluster;Scheduler was sent the command new
02/18/2014 17:36:24;0002;PBS_Server;Svr;PBS_Server;Torque Server Version = 3.0.5, loglevel = 0
02/18/2014 17:36:41;0040;PBS_Server;Svr;tyrone-cluster;Scheduler was sent the command new
02/18/2014 17:37:14;0040;PBS_Server;Svr;tyrone-cluster;Scheduler was sent the command new
02/18/2014 17:37:40;0040;PBS_Server;Svr;tyrone-cluster;Scheduler was sent the command new
02/18/2014 17:38:12;0040;PBS_Server;Svr;tyrone-cluster;Scheduler was sent the command new
02/18/2014 17:38:45;0040;PBS_Server;Svr;tyrone-cluster;Scheduler was sent the command new
02/18/2014 17:39:20;0040;PBS_Server;Svr;tyrone-cluster;Scheduler was sent the command new
02/18/2014 17:39:51;0040;PBS_Server;Svr;tyrone-cluster;Scheduler was sent the command new
02/18/2014 17:40:26;0040;PBS_Server;Svr;tyrone-cluster;Scheduler was sent the command new
02/18/2014 17:40:59;0040;PBS_Server;Svr;tyrone-cluster;Scheduler was sent the command new
02/18/2014 17:41:24;0002;PBS_Server;Svr;PBS_Server;Torque Server Version = 3.0.5, loglevel = 0
02/18/2014 17:41:25;0040;PBS_Server;Svr;tyrone-cluster;Scheduler was sent the command new
02/18/2014 17:41:56;0040;PBS_Server;Svr;tyrone-cluster;Scheduler was sent the command new
02/18/2014 17:42:30;0040;PBS_Server;Svr;tyrone-cluster;Scheduler was sent the command new
02/18/2014 17:43:05;0040;PBS_Server;Svr;tyrone-cluster;Scheduler was sent the command new
02/18/2014 17:43:36;0040;PBS_Server;Svr;tyrone-cluster;Scheduler was sent the command new
02/18/2014 17:44:11;0040;PBS_Server;Svr;tyrone-cluster;Scheduler was sent the command new
02/18/2014 17:44:45;0040;PBS_Server;Svr;tyrone-cluster;Scheduler was sent the command new
02/18/2014 17:45:20;0040;PBS_Server;Svr;tyrone-cluster;Scheduler was sent the command new
02/18/2014 17:45:45;0040;PBS_Server;Svr;tyrone-cluster;Scheduler was sent the command new
02/18/2014 17:46:14;0040;PBS_Server;Svr;tyrone-cluster;Scheduler was sent the command new
02/18/2014 17:46:24;0002;PBS_Server;Svr;PBS_Server;Torque Server Version = 3.0.5, loglevel = 0
02/18/2014 17:46:50;0040;PBS_Server;Svr;tyrone-cluster;Scheduler was sent the command new
02/18/2014 17:47:15;0040;PBS_Server;Svr;tyrone-cluster;Scheduler was sent the command new
02/18/2014 17:47:46;0040;PBS_Server;Svr;tyrone-cluster;Scheduler was sent the command new
02/18/2014 17:48:20;0040;PBS_Server;Svr;tyrone-cluster;Scheduler was sent the command new
02/18/2014 17:48:51;0040;PBS_Server;Svr;tyrone-cluster;Scheduler was sent the command new
02/18/2014 17:49:26;0040;PBS_Server;Svr;tyrone-cluster;Scheduler was sent the command new
02/18/2014 17:50:00;0040;PBS_Server;Svr;tyrone-cluster;Scheduler was sent the command new
02/18/2014 17:50:24;0040;PBS_Server;Svr;tyrone-cluster;Scheduler was sent the command new
02/18/2014 17:50:56;0040;PBS_Server;Svr;tyrone-cluster;Scheduler was sent the command new
02/18/2014 17:51:24;0002;PBS_Server;Svr;PBS_Server;Torque Server Version = 3.0.5, loglevel = 0
02/18/2014 17:51:24;0040;PBS_Server;Svr;tyrone-cluster;Scheduler was sent the command new
02/18/2014 17:51:54;0040;PBS_Server;Svr;tyrone-cluster;Scheduler was sent the command new
02/18/2014 17:52:26;0040;PBS_Server;Svr;tyrone-cluster;Scheduler was sent the command new
02/18/2014 17:53:00;0040;PBS_Server;Svr;tyrone-cluster;Scheduler was sent the command new
02/18/2014 17:53:24;0040;PBS_Server;Svr;tyrone-cluster;Scheduler was sent the command new
02/18/2014 17:53:55;0040;PBS_Server;Svr;tyrone-cluster;Scheduler was sent the command new
02/18/2014 17:54:29;0040;PBS_Server;Svr;tyrone-cluster;Scheduler was sent the command new
02/18/2014 17:54:54;0040;PBS_Server;Svr;tyrone-cluster;Scheduler was sent the command new
02/18/2014 17:55:26;0040;PBS_Server;Svr;tyrone-cluster;Scheduler was sent the command new
02/18/2014 17:55:54;0040;PBS_Server;Svr;tyrone-cluster;Scheduler was sent the command new
02/18/2014 17:56:24;0002;PBS_Server;Svr;PBS_Server;Torque Server Version = 3.0.5, loglevel = 0
02/18/2014 17:56:24;0040;PBS_Server;Svr;tyrone-cluster;Scheduler was sent the command new
02/18/2014 17:56:56;0040;PBS_Server;Svr;tyrone-cluster;Scheduler was sent the command new
02/18/2014 17:57:29;0040;PBS_Server;Svr;tyrone-cluster;Scheduler was sent the command new
02/18/2014 17:57:55;0040;PBS_Server;Svr;tyrone-cluster;Scheduler was sent the command new
02/18/2014 17:58:26;0040;PBS_Server;Svr;tyrone-cluster;Scheduler was sent the command new
02/18/2014 17:58:55;0040;PBS_Server;Svr;tyrone-cluster;Scheduler was sent the command new
02/18/2014 17:59:25;0040;PBS_Server;Svr;tyrone-cluster;Scheduler was sent the command new
02/18/2014 17:59:56;0040;PBS_Server;Svr;tyrone-cluster;Scheduler was sent the command new
02/18/2014 18:00:30;0040;PBS_Server;Svr;tyrone-cluster;Scheduler was sent the command new
02/18/2014 18:01:05;0040;PBS_Server;Svr;tyrone-cluster;Scheduler was sent the command new
02/18/2014 18:01:24;0002;PBS_Server;Svr;PBS_Server;Torque Server Version = 3.0.5, loglevel = 0
02/18/2014 18:01:36;0040;PBS_Server;Svr;tyrone-cluster;Scheduler was sent the command new
02/18/2014 18:02:05;0040;PBS_Server;Svr;tyrone-cluster;Scheduler was sent the command new
02/18/2014 18:02:35;0040;PBS_Server;Svr;tyrone-cluster;Scheduler was sent the command new
02/18/2014 18:03:08;0040;PBS_Server;Svr;tyrone-cluster;Scheduler was sent the command new
02/18/2014 18:03:41;0040;PBS_Server;Svr;tyrone-cluster;Scheduler was sent the command new
02/18/2014 18:04:09;0040;PBS_Server;Svr;tyrone-cluster;Scheduler was sent the command new
02/18/2014 18:04:39;0040;PBS_Server;Svr;tyrone-cluster;Scheduler was sent the command new
02/18/2014 18:05:11;0040;PBS_Server;Svr;tyrone-cluster;Scheduler was sent the command new
02/18/2014 18:05:45;0040;PBS_Server;Svr;tyrone-cluster;Scheduler was sent the command new
02/18/2014 18:06:09;0040;PBS_Server;Svr;tyrone-cluster;Scheduler was sent the command new
02/18/2014 18:06:24;0002;PBS_Server;Svr;PBS_Server;Torque Server Version = 3.0.5, loglevel = 0
02/18/2014 18:06:41;0040;PBS_Server;Svr;tyrone-cluster;Scheduler was sent the command new
02/18/2014 18:07:14;0040;PBS_Server;Svr;tyrone-cluster;Scheduler was sent the command new
02/18/2014 18:07:39;0040;PBS_Server;Svr;tyrone-cluster;Scheduler was sent the command new
02/18/2014 18:08:11;0040;PBS_Server;Svr;tyrone-cluster;Scheduler was sent the command new
02/18/2014 18:08:45;0040;PBS_Server;Svr;tyrone-cluster;Scheduler was sent the command new
02/18/2014 18:09:09;0040;PBS_Server;Svr;tyrone-cluster;Scheduler was sent the command new
02/18/2014 18:09:41;0040;PBS_Server;Svr;tyrone-cluster;Scheduler was sent the command new
02/18/2014 18:10:14;0040;PBS_Server;Svr;tyrone-cluster;Scheduler was sent the command new
02/18/2014 18:10:40;0040;PBS_Server;Svr;tyrone-cluster;Scheduler was sent the command new
02/18/2014 18:11:12;0040;PBS_Server;Svr;tyrone-cluster;Scheduler was sent the command new
02/18/2014 18:11:24;0002;PBS_Server;Svr;PBS_Server;Torque Server Version = 3.0.5, loglevel = 0
02/18/2014 18:11:45;0040;PBS_Server;Svr;tyrone-cluster;Scheduler was sent the command new
02/18/2014 18:12:20;0040;PBS_Server;Svr;tyrone-cluster;Scheduler was sent the command new
02/18/2014 18:12:51;0040;PBS_Server;Svr;tyrone-cluster;Scheduler was sent the command new
02/18/2014 18:13:26;0040;PBS_Server;Svr;tyrone-cluster;Scheduler was sent the command new
02/18/2014 18:13:55;0040;PBS_Server;Svr;tyrone-cluster;Scheduler was sent the command new
02/18/2014 18:14:25;0040;PBS_Server;Svr;tyrone-cluster;Scheduler was sent the command new
02/18/2014 18:14:57;0040;PBS_Server;Svr;tyrone-cluster;Scheduler was sent the command new
02/18/2014 18:15:30;0040;PBS_Server;Svr;tyrone-cluster;Scheduler was sent the command new
02/18/2014 18:16:06;0040;PBS_Server;Svr;tyrone-cluster;Scheduler was sent the command new
02/18/2014 18:16:24;0002;PBS_Server;Svr;PBS_Server;Torque Server Version = 3.0.5, loglevel = 0
02/18/2014 18:16:30;0040;PBS_Server;Svr;tyrone-cluster;Scheduler was sent the command new
02/18/2014 18:17:00;0040;PBS_Server;Svr;tyrone-cluster;Scheduler was sent the command new
02/18/2014 18:17:35;0040;PBS_Server;Svr;tyrone-cluster;Scheduler was sent the command new
02/18/2014 18:18:06;0040;PBS_Server;Svr;tyrone-cluster;Scheduler was sent the command new
02/18/2014 18:18:41;0040;PBS_Server;Svr;tyrone-cluster;Scheduler was sent the command new
02/18/2014 18:19:15;0040;PBS_Server;Svr;tyrone-cluster;Scheduler was sent the command new
02/18/2014 18:19:50;0040;PBS_Server;Svr;tyrone-cluster;Scheduler was sent the command new
02/18/2014 18:20:21;0040;PBS_Server;Svr;tyrone-cluster;Scheduler was sent the command new
02/18/2014 18:20:56;0040;PBS_Server;Svr;tyrone-cluster;Scheduler was sent the command new
02/18/2014 18:21:24;0002;PBS_Server;Svr;PBS_Server;Torque Server Version = 3.0.5, loglevel = 0
02/18/2014 18:21:25;0040;PBS_Server;Svr;tyrone-cluster;Scheduler was sent the command new
02/18/2014 18:21:55;0040;PBS_Server;Svr;tyrone-cluster;Scheduler was sent the command new
02/18/2014 18:22:27;0040;PBS_Server;Svr;tyrone-cluster;Scheduler was sent the command new
02/18/2014 18:23:00;0040;PBS_Server;Svr;tyrone-cluster;Scheduler was sent the command new
02/18/2014 18:23:35;0040;PBS_Server;Svr;tyrone-cluster;Scheduler was sent the command new
02/18/2014 18:24:06;0040;PBS_Server;Svr;tyrone-cluster;Scheduler was sent the command new
02/18/2014 18:24:41;0040;PBS_Server;Svr;tyrone-cluster;Scheduler was sent the command new
02/18/2014 18:25:15;0040;PBS_Server;Svr;tyrone-cluster;Scheduler was sent the command new
02/18/2014 18:25:39;0040;PBS_Server;Svr;tyrone-cluster;Scheduler was sent the command new
02/18/2014 18:26:11;0040;PBS_Server;Svr;tyrone-cluster;Scheduler was sent the command new
02/18/2014 18:26:24;0002;PBS_Server;Svr;PBS_Server;Torque Server Version = 3.0.5, loglevel = 0
02/18/2014 18:26:44;0040;PBS_Server;Svr;tyrone-cluster;Scheduler was sent the command new
02/18/2014 18:27:10;0040;PBS_Server;Svr;tyrone-cluster;Scheduler was sent the command new
02/18/2014 18:27:41;0040;PBS_Server;Svr;tyrone-cluster;Scheduler was sent the command new
02/18/2014 18:28:15;0040;PBS_Server;Svr;tyrone-cluster;Scheduler was sent the command new
02/18/2014 18:28:40;0040;PBS_Server;Svr;tyrone-cluster;Scheduler was sent the command new
02/18/2014 18:29:12;0040;PBS_Server;Svr;tyrone-cluster;Scheduler was sent the command new
02/18/2014 18:29:45;0040;PBS_Server;Svr;tyrone-cluster;Scheduler was sent the command new
02/18/2014 18:30:21;0040;PBS_Server;Svr;tyrone-cluster;Scheduler was sent the command new
02/18/2014 18:30:51;0040;PBS_Server;Svr;tyrone-cluster;Scheduler was sent the command new
02/18/2014 18:31:24;0002;PBS_Server;Svr;PBS_Server;Torque Server Version = 3.0.5, loglevel = 0
02/18/2014 18:31:25;0040;PBS_Server;Svr;tyrone-cluster;Scheduler was sent the command new
02/18/2014 18:32:00;0040;PBS_Server;Svr;tyrone-cluster;Scheduler was sent the command new
02/18/2014 18:32:25;0040;PBS_Server;Svr;tyrone-cluster;Scheduler was sent the command new
02/18/2014 18:32:57;0040;PBS_Server;Svr;tyrone-cluster;Scheduler was sent the command new
02/18/2014 18:33:30;0040;PBS_Server;Svr;tyrone-cluster;Scheduler was sent the command new
02/18/2014 18:34:06;0040;PBS_Server;Svr;tyrone-cluster;Scheduler was sent the command new
02/18/2014 18:34:21;0100;PBS_Server;Job;35249.tyrone-cluster;enqueuing into batch, state 1 hop 1
02/18/2014 18:34:21;0100;PBS_Server;Job;35249.tyrone-cluster;dequeuing from batch, state QUEUED
02/18/2014 18:34:21;0100;PBS_Server;Job;35249.tyrone-cluster;enqueuing into qp64, state 1 hop 1
02/18/2014 18:34:21;0008;PBS_Server;Job;35249.tyrone-cluster;Job Queued at request of mbunisha@tyrone-cluster, owner = mbunisha@tyrone-cluster, job name = mlecg2m9nsa-2-12-02-14, queue = qp64
02/18/2014 18:34:21;0040;PBS_Server;Svr;tyrone-cluster;Scheduler was sent the command new
02/18/2014 18:34:21;0008;PBS_Server;Job;35249.tyrone-cluster;Job Modified at request of Scheduler@tyrone-cluster
02/18/2014 18:34:36;0040;PBS_Server;Svr;tyrone-cluster;Scheduler was sent the command new
02/18/2014 18:35:11;0040;PBS_Server;Svr;tyrone-cluster;Scheduler was sent the command new
02/18/2014 18:35:44;0040;PBS_Server;Svr;tyrone-cluster;Scheduler was sent the command new
02/18/2014 18:36:09;0040;PBS_Server;Svr;tyrone-cluster;Scheduler was sent the command new
02/18/2014 18:36:24;0002;PBS_Server;Svr;PBS_Server;Torque Server Version = 3.0.5, loglevel = 0
02/18/2014 18:36:41;0040;PBS_Server;Svr;tyrone-cluster;Scheduler was sent the command new
02/18/2014 18:37:15;0040;PBS_Server;Svr;tyrone-cluster;Scheduler was sent the command new
02/18/2014 18:37:40;0040;PBS_Server;Svr;tyrone-cluster;Scheduler was sent the command new
02/18/2014 18:38:12;0040;PBS_Server;Svr;tyrone-cluster;Scheduler was sent the command new
02/18/2014 18:38:45;0040;PBS_Server;Svr;tyrone-cluster;Scheduler was sent the command new
02/18/2014 18:39:21;0040;PBS_Server;Svr;tyrone-cluster;Scheduler was sent the command new
02/18/2014 18:39:51;0040;PBS_Server;Svr;tyrone-cluster;Scheduler was sent the command new
02/18/2014 18:40:22;0040;PBS_Server;Svr;tyrone-cluster;Scheduler was sent the command new
02/18/2014 18:40:47;0100;PBS_Server;Job;35250.tyrone-cluster;enqueuing into batch, state 1 hop 1
02/18/2014 18:40:47;0100;PBS_Server;Job;35250.tyrone-cluster;dequeuing from batch, state QUEUED
02/18/2014 18:40:47;0100;PBS_Server;Job;35250.tyrone-cluster;enqueuing into qp32, state 1 hop 1
02/18/2014 18:40:47;0008;PBS_Server;Job;35250.tyrone-cluster;Job Queued at request of mbunisha@tyrone-cluster, owner = mbunisha@tyrone-cluster, job name = 4gky-man9-18-02-14, queue = qp32
02/18/2014 18:40:47;0040;PBS_Server;Svr;tyrone-cluster;Scheduler was sent the command new
02/18/2014 18:40:47;0008;PBS_Server;Job;35250.tyrone-cluster;Job Modified at request of Scheduler@tyrone-cluster
02/18/2014 18:40:52;0040;PBS_Server;Svr;tyrone-cluster;Scheduler was sent the command new
02/18/2014 18:41:23;0040;PBS_Server;Svr;tyrone-cluster;Scheduler was sent the command new
02/18/2014 18:41:24;0002;PBS_Server;Svr;PBS_Server;Torque Server Version = 3.0.5, loglevel = 0
02/18/2014 18:41:56;0040;PBS_Server;Svr;tyrone-cluster;Scheduler was sent the command new
02/18/2014 18:42:30;0040;PBS_Server;Svr;tyrone-cluster;Scheduler was sent the command new
02/18/2014 18:42:55;0040;PBS_Server;Svr;tyrone-cluster;Scheduler was sent the command new
02/18/2014 18:43:27;0040;PBS_Server;Svr;tyrone-cluster;Scheduler was sent the command new
02/18/2014 18:43:30;0100;PBS_Server;Job;35251.tyrone-cluster;enqueuing into batch, state 1 hop 1
02/18/2014 18:43:30;0100;PBS_Server;Job;35251.tyrone-cluster;dequeuing from batch, state QUEUED
02/18/2014 18:43:30;0100;PBS_Server;Job;35251.tyrone-cluster;enqueuing into qp64, state 1 hop 1
02/18/2014 18:43:30;0008;PBS_Server;Job;35251.tyrone-cluster;Job Queued at request of mbumasha@tyrone-cluster, owner = mbumasha@tyrone-cluster, job name = mlecg2m7c-12-02-14, queue = qp64
02/18/2014 18:43:30;0040;PBS_Server;Svr;tyrone-cluster;Scheduler was sent the command new
02/18/2014 18:43:30;0008;PBS_Server;Job;35251.tyrone-cluster;Job Modified at request of Scheduler@tyrone-cluster
02/18/2014 18:44:00;0040;PBS_Server;Svr;tyrone-cluster;Scheduler was sent the command new
02/18/2014 18:44:35;0040;PBS_Server;Svr;tyrone-cluster;Scheduler was sent the command new
02/18/2014 18:45:06;0040;PBS_Server;Svr;tyrone-cluster;Scheduler was sent the command new
02/18/2014 18:45:41;0040;PBS_Server;Svr;tyrone-cluster;Scheduler was sent the command new
02/18/2014 18:46:15;0040;PBS_Server;Svr;tyrone-cluster;Scheduler was sent the command new
02/18/2014 18:46:24;0002;PBS_Server;Svr;PBS_Server;Torque Server Version = 3.0.5, loglevel = 0
02/18/2014 18:46:40;0040;PBS_Server;Svr;tyrone-cluster;Scheduler was sent the command new
02/18/2014 18:47:11;0040;PBS_Server;Svr;tyrone-cluster;Scheduler was sent the command new
02/18/2014 18:47:45;0040;PBS_Server;Svr;tyrone-cluster;Scheduler was sent the command new
02/18/2014 18:48:10;0040;PBS_Server;Svr;tyrone-cluster;Scheduler was sent the command new
02/18/2014 18:48:42;0040;PBS_Server;Svr;tyrone-cluster;Scheduler was sent the command new
02/18/2014 18:49:15;0040;PBS_Server;Svr;tyrone-cluster;Scheduler was sent the command new
02/18/2014 18:49:43;0100;PBS_Server;Job;35252.tyrone-cluster;enqueuing into batch, state 1 hop 1
02/18/2014 18:49:43;0100;PBS_Server;Job;35252.tyrone-cluster;dequeuing from batch, state QUEUED
02/18/2014 18:49:43;0100;PBS_Server;Job;35252.tyrone-cluster;enqueuing into qp32, state 1 hop 1
02/18/2014 18:49:43;0008;PBS_Server;Job;35252.tyrone-cluster;Job Queued at request of mbunisha@tyrone-cluster, owner = mbunisha@tyrone-cluster, job name = 4gky-man9-18-02-14, queue = qp32
02/18/2014 18:49:43;0040;PBS_Server;Svr;tyrone-cluster;Scheduler was sent the command new
02/18/2014 18:49:43;0008;PBS_Server;Job;35252.tyrone-cluster;Job Modified at request of Scheduler@tyrone-cluster
02/18/2014 18:49:47;0040;PBS_Server;Svr;tyrone-cluster;Scheduler was sent the command new
02/18/2014 18:50:17;0040;PBS_Server;Svr;tyrone-cluster;Scheduler was sent the command new
02/18/2014 18:50:47;0040;PBS_Server;Svr;tyrone-cluster;Scheduler was sent the command new
02/18/2014 18:51:20;0040;PBS_Server;Svr;tyrone-cluster;Scheduler was sent the command new
02/18/2014 18:51:24;0002;PBS_Server;Svr;PBS_Server;Torque Server Version = 3.0.5, loglevel = 0
02/18/2014 18:51:51;0040;PBS_Server;Svr;tyrone-cluster;Scheduler was sent the command new
02/18/2014 18:52:26;0040;PBS_Server;Svr;tyrone-cluster;Scheduler was sent the command new
02/18/2014 18:53:00;0040;PBS_Server;Svr;tyrone-cluster;Scheduler was sent the command new
02/18/2014 18:53:25;0040;PBS_Server;Svr;tyrone-cluster;Scheduler was sent the command new
02/18/2014 18:53:56;0040;PBS_Server;Svr;tyrone-cluster;Scheduler was sent the command new
02/18/2014 18:54:19;0100;PBS_Server;Job;35253.tyrone-cluster;enqueuing into batch, state 1 hop 1
02/18/2014 18:54:19;0100;PBS_Server;Job;35253.tyrone-cluster;dequeuing from batch, state QUEUED
02/18/2014 18:54:19;0100;PBS_Server;Job;35253.tyrone-cluster;enqueuing into qp64, state 1 hop 1
02/18/2014 18:54:19;0008;PBS_Server;Job;35253.tyrone-cluster;Job Queued at request of mbumasha@tyrone-cluster, owner = mbumasha@tyrone-cluster, job name = mlecg2m7c-12-02-14, queue = qp64
02/18/2014 18:54:19;0040;PBS_Server;Svr;tyrone-cluster;Scheduler was sent the command new
02/18/2014 18:54:20;0008;PBS_Server;Job;35253.tyrone-cluster;Job Modified at request of Scheduler@tyrone-cluster
02/18/2014 18:54:29;0040;PBS_Server;Svr;tyrone-cluster;Scheduler was sent the command new
02/18/2014 18:54:31;0008;PBS_Server;Job;35251.tyrone-cluster;Job deleted at request of mbumasha@tyrone-cluster
02/18/2014 18:54:31;0008;PBS_Server;Job;NULL;on_job_exit valid pjob: 0x1ec3290 (substate=59)
02/18/2014 18:54:31;0100;PBS_Server;Job;35251.tyrone-cluster;dequeuing from qp64, state COMPLETE
02/18/2014 18:54:31;0040;PBS_Server;Svr;tyrone-cluster;Scheduler was sent the command term
02/18/2014 18:54:55;0040;PBS_Server;Svr;tyrone-cluster;Scheduler was sent the command new
02/18/2014 18:55:27;0040;PBS_Server;Svr;tyrone-cluster;Scheduler was sent the command new
02/18/2014 18:56:01;0040;PBS_Server;Svr;tyrone-cluster;Scheduler was sent the command new
02/18/2014 18:56:24;0002;PBS_Server;Svr;PBS_Server;Torque Server Version = 3.0.5, loglevel = 0
02/18/2014 18:56:32;0040;PBS_Server;Svr;tyrone-cluster;Scheduler was sent the command new
02/18/2014 18:56:45;0008;PBS_Server;Job;35250.tyrone-cluster;Job deleted at request of mbunisha@tyrone-cluster
02/18/2014 18:56:45;0008;PBS_Server;Job;NULL;on_job_exit valid pjob: 0x1ec1fd0 (substate=59)
02/18/2014 18:56:45;0100;PBS_Server;Job;35250.tyrone-cluster;dequeuing from qp32, state COMPLETE
02/18/2014 18:56:45;0040;PBS_Server;Svr;tyrone-cluster;Scheduler was sent the command term
02/18/2014 18:57:02;0040;PBS_Server;Svr;tyrone-cluster;Scheduler was sent the command new
02/18/2014 18:57:03;0008;PBS_Server;Job;35252.tyrone-cluster;Job deleted at request of mbunisha@tyrone-cluster
02/18/2014 18:57:03;0008;PBS_Server;Job;NULL;on_job_exit valid pjob: 0x1ec8450 (substate=59)
02/18/2014 18:57:03;0100;PBS_Server;Job;35252.tyrone-cluster;dequeuing from qp32, state COMPLETE
02/18/2014 18:57:03;0040;PBS_Server;Svr;tyrone-cluster;Scheduler was sent the command term
02/18/2014 18:57:33;0040;PBS_Server;Svr;tyrone-cluster;Scheduler was sent the command new
02/18/2014 18:57:54;0100;PBS_Server;Job;35254.tyrone-cluster;enqueuing into batch, state 1 hop 1
02/18/2014 18:57:54;0100;PBS_Server;Job;35254.tyrone-cluster;dequeuing from batch, state QUEUED
02/18/2014 18:57:54;0100;PBS_Server;Job;35254.tyrone-cluster;enqueuing into qp32, state 1 hop 1
02/18/2014 18:57:54;0008;PBS_Server;Job;35254.tyrone-cluster;Job Queued at request of mbumasha@tyrone-cluster, owner = mbumasha@tyrone-cluster, job name = 2dur-man9-18-02-14, queue = qp32
02/18/2014 18:57:54;0040;PBS_Server;Svr;tyrone-cluster;Scheduler was sent the command new
02/18/2014 18:57:55;0008;PBS_Server;Job;35254.tyrone-cluster;Job Modified at request of Scheduler@tyrone-cluster
02/18/2014 18:58:06;0040;PBS_Server;Svr;tyrone-cluster;Scheduler was sent the command new
02/18/2014 18:58:23;0100;PBS_Server;Job;35255.tyrone-cluster;enqueuing into batch, state 1 hop 1
02/18/2014 18:58:23;0100;PBS_Server;Job;35255.tyrone-cluster;dequeuing from batch, state QUEUED
02/18/2014 18:58:23;0100;PBS_Server;Job;35255.tyrone-cluster;enqueuing into qp64, state 1 hop 1
02/18/2014 18:58:23;0008;PBS_Server;Job;35255.tyrone-cluster;Job Queued at request of mbuteja@tyrone-cluster, owner = mbuteja@tyrone-cluster, job name = mlecg2modnsa-10-02-14, queue = qp64
02/18/2014 18:58:23;0040;PBS_Server;Svr;tyrone-cluster;Scheduler was sent the command new
02/18/2014 18:58:23;0008;PBS_Server;Job;35255.tyrone-cluster;Job Modified at request of Scheduler@tyrone-cluster
02/18/2014 18:58:36;0040;PBS_Server;Svr;tyrone-cluster;Scheduler was sent the command new
02/18/2014 18:59:11;0040;PBS_Server;Svr;tyrone-cluster;Scheduler was sent the command new
02/18/2014 18:59:45;0040;PBS_Server;Svr;tyrone-cluster;Scheduler was sent the command new
02/18/2014 19:00:10;0040;PBS_Server;Svr;tyrone-cluster;Scheduler was sent the command new
02/18/2014 19:00:41;0040;PBS_Server;Svr;tyrone-cluster;Scheduler was sent the command new
02/18/2014 19:01:15;0040;PBS_Server;Svr;tyrone-cluster;Scheduler was sent the command new
02/18/2014 19:01:24;0002;PBS_Server;Svr;PBS_Server;Torque Server Version = 3.0.5, loglevel = 0
02/18/2014 19:01:40;0040;PBS_Server;Svr;tyrone-cluster;Scheduler was sent the command new
02/18/2014 19:02:00;0100;PBS_Server;Job;35256.tyrone-cluster;enqueuing into batch, state 1 hop 1
02/18/2014 19:02:00;0100;PBS_Server;Job;35256.tyrone-cluster;dequeuing from batch, state QUEUED
02/18/2014 19:02:00;0100;PBS_Server;Job;35256.tyrone-cluster;enqueuing into qp32, state 1 hop 1
02/18/2014 19:02:00;0008;PBS_Server;Job;35256.tyrone-cluster;Job Queued at request of mbunisha@tyrone-cluster, owner = mbunisha@tyrone-cluster, job name = 4gky-man9-18-02-14, queue = qp32
02/18/2014 19:02:00;0040;PBS_Server;Svr;tyrone-cluster;Scheduler was sent the command new
02/18/2014 19:02:00;0008;PBS_Server;Job;35256.tyrone-cluster;Job Modified at request of Scheduler@tyrone-cluster
02/18/2014 19:02:12;0040;PBS_Server;Svr;tyrone-cluster;Scheduler was sent the command new
02/18/2014 19:02:46;0040;PBS_Server;Svr;tyrone-cluster;Scheduler was sent the command new
02/18/2014 19:03:21;0040;PBS_Server;Svr;tyrone-cluster;Scheduler was sent the command new
02/18/2014 19:03:51;0040;PBS_Server;Svr;tyrone-cluster;Scheduler was sent the command new
02/18/2014 19:04:26;0040;PBS_Server;Svr;tyrone-cluster;Scheduler was sent the command new
02/18/2014 19:05:00;0040;PBS_Server;Svr;tyrone-cluster;Scheduler was sent the command new
02/18/2014 19:05:24;0040;PBS_Server;Svr;tyrone-cluster;Scheduler was sent the command new
02/18/2014 19:05:56;0040;PBS_Server;Svr;tyrone-cluster;Scheduler was sent the command new
02/18/2014 19:06:24;0002;PBS_Server;Svr;PBS_Server;Torque Server Version = 3.0.5, loglevel = 0
02/18/2014 19:06:25;0040;PBS_Server;Svr;tyrone-cluster;Scheduler was sent the command new
02/18/2014 19:06:54;0040;PBS_Server;Svr;tyrone-cluster;Scheduler was sent the command new
02/18/2014 19:07:26;0040;PBS_Server;Svr;tyrone-cluster;Scheduler was sent the command new
02/18/2014 19:08:00;0040;PBS_Server;Svr;tyrone-cluster;Scheduler was sent the command new
02/18/2014 19:08:06;0008;PBS_Server;Job;35153.tyrone-cluster;Job deleted at request of mbuteja@tyrone-cluster
02/18/2014 19:08:06;0008;PBS_Server;Job;35153.tyrone-cluster;Job sent signal SIGTERM on delete
02/18/2014 19:08:06;000d;PBS_Server;Job;35153.tyrone-cluster;Not sending email: User does not want mail of this type.
02/18/2014 19:08:06;0010;PBS_Server;Job;35153.tyrone-cluster;Exit_status=143 resources_used.cput=509:11:02 resources_used.mem=2117348kb resources_used.vmem=35875204kb resources_used.walltime=07:57:31
02/18/2014 19:08:06;0008;PBS_Server;Job;NULL;on_job_exit valid pjob: 0x1d9d2b0 (substate=50)
02/18/2014 19:08:06;0008;PBS_Server;Job;NULL;on_job_exit valid pjob: 0x1d9d2b0 (substate=51)
02/18/2014 19:08:11;0008;PBS_Server;Job;NULL;on_job_exit valid pjob: 0x1d9d2b0 (substate=51)
02/18/2014 19:08:11;000d;PBS_Server;Job;35153.tyrone-cluster;Post job file processing error; job 35153.tyrone-cluster on host tyrone-node16/63+tyrone-node16/62+tyrone-node16/61+tyrone-node16/60+tyrone-node16/59+tyrone-node16/58+tyrone-node16/57+tyrone-node16/56+tyrone-node16/55+tyrone-node16/54+tyrone-node16/53+tyrone-node16/52+tyrone-node16/51+tyrone-node16/50+tyrone-node16/49+tyrone-node16/48+tyrone-node16/47+tyrone-node16/46+tyrone-node16/45+tyrone-node16/44+tyrone-node16/43+tyrone-node16/42+tyrone-node16/41+tyrone-node16/40+tyrone-node16/39+tyrone-node16/38+tyrone-node16/37+tyrone-node16/36+tyrone-node16/35+tyrone-node16/34+tyrone-node16/33+tyrone-node16/32+tyrone-node16/31+tyrone-node16/30+tyrone-node16/29+tyrone-node16/28+tyrone-node16/27+tyrone-node16/26+tyrone-node16/25+tyrone-node16/24+tyrone-node16/23+tyrone-node16/22+tyrone-node16/21+tyrone-node16/20+tyrone-node16/19+tyrone-node16/18+tyrone-node16/17+tyrone-node16/16+tyrone-node16/15+tyrone-node16/14+tyrone-node16/13+tyrone-node16/12+tyrone-node16/11+tyrone-node16/10+tyrone-node16/9+tyrone-node16/8+tyrone-node16/7+tyrone-node16/6+tyrone-node16/5+tyrone-node16/4+tyrone-node16/3+tyrone-node16/2+tyrone-node16/1+tyrone-node16/0
02/18/2014 19:08:11;0008;PBS_Server;Job;NULL;on_job_exit valid pjob: 0x1d9d2b0 (substate=53)
02/18/2014 19:08:11;0100;PBS_Server;Job;35153.tyrone-cluster;dequeuing from qp64, state COMPLETE
02/18/2014 19:08:11;0040;PBS_Server;Svr;tyrone-cluster;Scheduler was sent the command term
02/18/2014 19:08:11;0008;PBS_Server;Job;35134.tyrone-cluster;Job Modified at request of Scheduler@tyrone-cluster
02/18/2014 19:08:11;0008;PBS_Server;Job;35135.tyrone-cluster;Job Modified at request of Scheduler@tyrone-cluster
02/18/2014 19:08:11;0008;PBS_Server;Job;35208.tyrone-cluster;Job Modified at request of Scheduler@tyrone-cluster
02/18/2014 19:08:11;0008;PBS_Server;Job;35208.tyrone-cluster;Job Run at request of Scheduler@tyrone-cluster
02/18/2014 19:08:12;0040;PBS_Server;Svr;tyrone-cluster;Scheduler was sent the command recyc
02/18/2014 19:08:12;000d;PBS_Server;Job;35208.tyrone-cluster;Not sending email: User does not want mail of this type.
02/18/2014 19:08:25;0040;PBS_Server;Svr;tyrone-cluster;Scheduler was sent the command new
02/18/2014 19:08:26;0008;PBS_Server;Job;35134.tyrone-cluster;Job Modified at request of Scheduler@tyrone-cluster
02/18/2014 19:08:26;0008;PBS_Server;Job;35135.tyrone-cluster;Job Modified at request of Scheduler@tyrone-cluster
02/18/2014 19:08:56;0040;PBS_Server;Svr;tyrone-cluster;Scheduler was sent the command new
02/18/2014 19:09:28;0040;PBS_Server;Svr;tyrone-cluster;Scheduler was sent the command new
02/18/2014 19:09:55;0040;PBS_Server;Svr;tyrone-cluster;Scheduler was sent the command new
02/18/2014 19:10:27;0040;PBS_Server;Svr;tyrone-cluster;Scheduler was sent the command new
02/18/2014 19:10:58;0040;PBS_Server;Svr;tyrone-cluster;Scheduler was sent the command new
02/18/2014 19:11:22;0100;PBS_Server;Job;35257.tyrone-cluster;enqueuing into batch, state 1 hop 1
02/18/2014 19:11:22;0100;PBS_Server;Job;35257.tyrone-cluster;dequeuing from batch, state QUEUED
02/18/2014 19:11:22;0100;PBS_Server;Job;35257.tyrone-cluster;enqueuing into qp64, state 1 hop 1
02/18/2014 19:11:22;0008;PBS_Server;Job;35257.tyrone-cluster;Job Queued at request of mbuavdhs@tyrone-cluster, owner = mbuavdhs@tyrone-cluster, job name = mlecg2m8b-2-12-02-14, queue = qp64
02/18/2014 19:11:22;0040;PBS_Server;Svr;tyrone-cluster;Scheduler was sent the command new
02/18/2014 19:11:22;0008;PBS_Server;Job;35257.tyrone-cluster;Job Modified at request of Scheduler@tyrone-cluster
02/18/2014 19:11:24;0002;PBS_Server;Svr;PBS_Server;Torque Server Version = 3.0.5, loglevel = 0
02/18/2014 19:11:36;0040;PBS_Server;Svr;tyrone-cluster;Scheduler was sent the command new
02/18/2014 19:11:37;0100;PBS_Server;Job;35258.tyrone-cluster;enqueuing into batch, state 1 hop 1
02/18/2014 19:11:37;0100;PBS_Server;Job;35258.tyrone-cluster;dequeuing from batch, state QUEUED
02/18/2014 19:11:37;0100;PBS_Server;Job;35258.tyrone-cluster;enqueuing into qp64, state 1 hop 1
02/18/2014 19:11:37;0008;PBS_Server;Job;35258.tyrone-cluster;Job Queued at request of mbuavdhs@tyrone-cluster, owner = mbuavdhs@tyrone-cluster, job name = mlecg2m8b-2-12-02-14, queue = qp64
02/18/2014 19:11:37;0040;PBS_Server;Svr;tyrone-cluster;Scheduler was sent the command new
02/18/2014 19:11:37;0008;PBS_Server;Job;35258.tyrone-cluster;Job Modified at request of Scheduler@tyrone-cluster
02/18/2014 19:12:02;0040;PBS_Server;Svr;tyrone-cluster;Scheduler was sent the command new
02/18/2014 19:12:31;0040;PBS_Server;Svr;tyrone-cluster;Scheduler was sent the command new
02/18/2014 19:13:06;0040;PBS_Server;Svr;tyrone-cluster;Scheduler was sent the command new
02/18/2014 19:13:39;0040;PBS_Server;Svr;tyrone-cluster;Scheduler was sent the command new
02/18/2014 19:14:11;0040;PBS_Server;Svr;tyrone-cluster;Scheduler was sent the command new
02/18/2014 19:14:43;0040;PBS_Server;Svr;tyrone-cluster;Scheduler was sent the command new
02/18/2014 19:15:10;0040;PBS_Server;Svr;tyrone-cluster;Scheduler was sent the command new
02/18/2014 19:15:41;0040;PBS_Server;Svr;tyrone-cluster;Scheduler was sent the command new
02/18/2014 19:16:13;0040;PBS_Server;Svr;tyrone-cluster;Scheduler was sent the command new
02/18/2014 19:16:24;0002;PBS_Server;Svr;PBS_Server;Torque Server Version = 3.0.5, loglevel = 0
02/18/2014 19:16:40;0040;PBS_Server;Svr;tyrone-cluster;Scheduler was sent the command new
02/18/2014 19:17:12;0040;PBS_Server;Svr;tyrone-cluster;Scheduler was sent the command new
02/18/2014 19:17:43;0040;PBS_Server;Svr;tyrone-cluster;Scheduler was sent the command new
02/18/2014 19:18:21;0040;PBS_Server;Svr;tyrone-cluster;Scheduler was sent the command new
02/18/2014 19:18:47;0040;PBS_Server;Svr;tyrone-cluster;Scheduler was sent the command new
02/18/2014 19:19:16;0040;PBS_Server;Svr;tyrone-cluster;Scheduler was sent the command new
02/18/2014 19:19:51;0040;PBS_Server;Svr;tyrone-cluster;Scheduler was sent the command new
02/18/2014 19:20:24;0040;PBS_Server;Svr;tyrone-cluster;Scheduler was sent the command new
02/18/2014 19:20:56;0040;PBS_Server;Svr;tyrone-cluster;Scheduler was sent the command new
02/18/2014 19:21:24;0002;PBS_Server;Svr;PBS_Server;Torque Server Version = 3.0.5, loglevel = 0
02/18/2014 19:21:25;0040;PBS_Server;Svr;tyrone-cluster;Scheduler was sent the command new
02/18/2014 19:21:54;0040;PBS_Server;Svr;tyrone-cluster;Scheduler was sent the command new
02/18/2014 19:22:26;0040;PBS_Server;Svr;tyrone-cluster;Scheduler was sent the command new
02/18/2014 19:22:58;0040;PBS_Server;Svr;tyrone-cluster;Scheduler was sent the command new
02/18/2014 19:23:25;0040;PBS_Server;Svr;tyrone-cluster;Scheduler was sent the command new
02/18/2014 19:23:56;0040;PBS_Server;Svr;tyrone-cluster;Scheduler was sent the command new
02/18/2014 19:24:28;0040;PBS_Server;Svr;tyrone-cluster;Scheduler was sent the command new
02/18/2014 19:24:55;0040;PBS_Server;Svr;tyrone-cluster;Scheduler was sent the command new
02/18/2014 19:25:26;0040;PBS_Server;Svr;tyrone-cluster;Scheduler was sent the command new
02/18/2014 19:25:58;0040;PBS_Server;Svr;tyrone-cluster;Scheduler was sent the command new
02/18/2014 19:26:24;0002;PBS_Server;Svr;PBS_Server;Torque Server Version = 3.0.5, loglevel = 0
02/18/2014 19:26:25;0040;PBS_Server;Svr;tyrone-cluster;Scheduler was sent the command new
02/18/2014 19:26:56;0040;PBS_Server;Svr;tyrone-cluster;Scheduler was sent the command new
02/18/2014 19:27:28;0040;PBS_Server;Svr;tyrone-cluster;Scheduler was sent the command new
02/18/2014 19:27:55;0040;PBS_Server;Svr;tyrone-cluster;Scheduler was sent the command new
02/18/2014 19:28:27;0040;PBS_Server;Svr;tyrone-cluster;Scheduler was sent the command new
02/18/2014 19:28:58;0040;PBS_Server;Svr;tyrone-cluster;Scheduler was sent the command new
02/18/2014 19:29:36;0040;PBS_Server;Svr;tyrone-cluster;Scheduler was sent the command new
02/18/2014 19:30:02;0040;PBS_Server;Svr;tyrone-cluster;Scheduler was sent the command new
02/18/2014 19:30:31;0040;PBS_Server;Svr;tyrone-cluster;Scheduler was sent the command new
02/18/2014 19:31:06;0040;PBS_Server;Svr;tyrone-cluster;Scheduler was sent the command new
02/18/2014 19:31:24;0002;PBS_Server;Svr;PBS_Server;Torque Server Version = 3.0.5, loglevel = 0
02/18/2014 19:31:39;0040;PBS_Server;Svr;tyrone-cluster;Scheduler was sent the command new
02/18/2014 19:32:11;0040;PBS_Server;Svr;tyrone-cluster;Scheduler was sent the command new
02/18/2014 19:32:43;0040;PBS_Server;Svr;tyrone-cluster;Scheduler was sent the command new
02/18/2014 19:33:10;0040;PBS_Server;Svr;tyrone-cluster;Scheduler was sent the command new
02/18/2014 19:33:41;0040;PBS_Server;Svr;tyrone-cluster;Scheduler was sent the command new
02/18/2014 19:34:13;0040;PBS_Server;Svr;tyrone-cluster;Scheduler was sent the command new
02/18/2014 19:34:40;0040;PBS_Server;Svr;tyrone-cluster;Scheduler was sent the command new
02/18/2014 19:35:12;0040;PBS_Server;Svr;tyrone-cluster;Scheduler was sent the command new
02/18/2014 19:35:43;0040;PBS_Server;Svr;tyrone-cluster;Scheduler was sent the command new
02/18/2014 19:36:21;0040;PBS_Server;Svr;tyrone-cluster;Scheduler was sent the command new
02/18/2014 19:36:24;0002;PBS_Server;Svr;PBS_Server;Torque Server Version = 3.0.5, loglevel = 0
02/18/2014 19:36:47;0040;PBS_Server;Svr;tyrone-cluster;Scheduler was sent the command new
02/18/2014 19:37:16;0040;PBS_Server;Svr;tyrone-cluster;Scheduler was sent the command new
02/18/2014 19:37:51;0040;PBS_Server;Svr;tyrone-cluster;Scheduler was sent the command new
02/18/2014 19:38:24;0040;PBS_Server;Svr;tyrone-cluster;Scheduler was sent the command new
02/18/2014 19:38:55;0040;PBS_Server;Svr;tyrone-cluster;Scheduler was sent the command new
02/18/2014 19:39:28;0040;PBS_Server;Svr;tyrone-cluster;Scheduler was sent the command new
02/18/2014 19:39:59;0040;PBS_Server;Svr;tyrone-cluster;Scheduler was sent the command new
02/18/2014 19:40:28;0040;PBS_Server;Svr;tyrone-cluster;Scheduler was sent the command new
02/18/2014 19:40:58;0040;PBS_Server;Svr;tyrone-cluster;Scheduler was sent the command new
02/18/2014 19:41:24;0002;PBS_Server;Svr;PBS_Server;Torque Server Version = 3.0.5, loglevel = 0
02/18/2014 19:41:36;0040;PBS_Server;Svr;tyrone-cluster;Scheduler was sent the command new
02/18/2014 19:42:02;0040;PBS_Server;Svr;tyrone-cluster;Scheduler was sent the command new
02/18/2014 19:42:31;0040;PBS_Server;Svr;tyrone-cluster;Scheduler was sent the command new
02/18/2014 19:43:06;0040;PBS_Server;Svr;tyrone-cluster;Scheduler was sent the command new
02/18/2014 19:43:39;0040;PBS_Server;Svr;tyrone-cluster;Scheduler was sent the command new
02/18/2014 19:44:11;0040;PBS_Server;Svr;tyrone-cluster;Scheduler was sent the command new
02/18/2014 19:44:43;0040;PBS_Server;Svr;tyrone-cluster;Scheduler was sent the command new
02/18/2014 19:45:10;0040;PBS_Server;Svr;tyrone-cluster;Scheduler was sent the command new
02/18/2014 19:45:41;0040;PBS_Server;Svr;tyrone-cluster;Scheduler was sent the command new
02/18/2014 19:46:13;0040;PBS_Server;Svr;tyrone-cluster;Scheduler was sent the command new
02/18/2014 19:46:24;0002;PBS_Server;Svr;PBS_Server;Torque Server Version = 3.0.5, loglevel = 0
02/18/2014 19:46:44;0040;PBS_Server;Svr;tyrone-cluster;Scheduler was sent the command new
02/18/2014 19:47:16;0040;PBS_Server;Svr;tyrone-cluster;Scheduler was sent the command new
02/18/2014 19:47:43;0040;PBS_Server;Svr;tyrone-cluster;Scheduler was sent the command new
02/18/2014 19:48:22;0040;PBS_Server;Svr;tyrone-cluster;Scheduler was sent the command new
02/18/2014 19:48:47;0040;PBS_Server;Svr;tyrone-cluster;Scheduler was sent the command new
02/18/2014 19:49:16;0040;PBS_Server;Svr;tyrone-cluster;Scheduler was sent the command new
02/18/2014 19:49:51;0040;PBS_Server;Svr;tyrone-cluster;Scheduler was sent the command new
02/18/2014 19:50:24;0040;PBS_Server;Svr;tyrone-cluster;Scheduler was sent the command new
02/18/2014 19:50:56;0040;PBS_Server;Svr;tyrone-cluster;Scheduler was sent the command new
02/18/2014 19:51:24;0002;PBS_Server;Svr;PBS_Server;Torque Server Version = 3.0.5, loglevel = 0
02/18/2014 19:51:25;0040;PBS_Server;Svr;tyrone-cluster;Scheduler was sent the command new
02/18/2014 19:51:55;0040;PBS_Server;Svr;tyrone-cluster;Scheduler was sent the command new
02/18/2014 19:52:26;0040;PBS_Server;Svr;tyrone-cluster;Scheduler was sent the command new
02/18/2014 19:52:58;0040;PBS_Server;Svr;tyrone-cluster;Scheduler was sent the command new
02/18/2014 19:53:29;0040;PBS_Server;Svr;tyrone-cluster;Scheduler was sent the command new
02/18/2014 19:53:58;0040;PBS_Server;Svr;tyrone-cluster;Scheduler was sent the command new
02/18/2014 19:54:28;0040;PBS_Server;Svr;tyrone-cluster;Scheduler was sent the command new
02/18/2014 19:55:06;0040;PBS_Server;Svr;tyrone-cluster;Scheduler was sent the command new
02/18/2014 19:55:32;0040;PBS_Server;Svr;tyrone-cluster;Scheduler was sent the command new
02/18/2014 19:56:03;0040;PBS_Server;Svr;tyrone-cluster;Scheduler was sent the command new
02/18/2014 19:56:24;0002;PBS_Server;Svr;PBS_Server;Torque Server Version = 3.0.5, loglevel = 0
02/18/2014 19:56:36;0040;PBS_Server;Svr;tyrone-cluster;Scheduler was sent the command new
02/18/2014 19:57:09;0040;PBS_Server;Svr;tyrone-cluster;Scheduler was sent the command new
02/18/2014 19:57:41;0040;PBS_Server;Svr;tyrone-cluster;Scheduler was sent the command new
02/18/2014 19:58:13;0040;PBS_Server;Svr;tyrone-cluster;Scheduler was sent the command new
02/18/2014 19:58:40;0040;PBS_Server;Svr;tyrone-cluster;Scheduler was sent the command new
02/18/2014 19:59:11;0040;PBS_Server;Svr;tyrone-cluster;Scheduler was sent the command new
02/18/2014 19:59:43;0040;PBS_Server;Svr;tyrone-cluster;Scheduler was sent the command new
02/18/2014 20:00:14;0040;PBS_Server;Svr;tyrone-cluster;Scheduler was sent the command new
02/18/2014 20:00:43;0040;PBS_Server;Svr;tyrone-cluster;Scheduler was sent the command new
02/18/2014 20:01:13;0040;PBS_Server;Svr;tyrone-cluster;Scheduler was sent the command new
02/18/2014 20:01:24;0002;PBS_Server;Svr;PBS_Server;Torque Server Version = 3.0.5, loglevel = 0
02/18/2014 20:01:51;0040;PBS_Server;Svr;tyrone-cluster;Scheduler was sent the command new
02/18/2014 20:02:17;0040;PBS_Server;Svr;tyrone-cluster;Scheduler was sent the command new
02/18/2014 20:02:46;0040;PBS_Server;Svr;tyrone-cluster;Scheduler was sent the command new
02/18/2014 20:03:22;0040;PBS_Server;Svr;tyrone-cluster;Scheduler was sent the command new
02/18/2014 20:03:54;0040;PBS_Server;Svr;tyrone-cluster;Scheduler was sent the command new
02/18/2014 20:04:26;0040;PBS_Server;Svr;tyrone-cluster;Scheduler was sent the command new
02/18/2014 20:04:58;0040;PBS_Server;Svr;tyrone-cluster;Scheduler was sent the command new
02/18/2014 20:05:28;0040;PBS_Server;Svr;tyrone-cluster;Scheduler was sent the command new
02/18/2014 20:05:58;0040;PBS_Server;Svr;tyrone-cluster;Scheduler was sent the command new
02/18/2014 20:06:24;0002;PBS_Server;Svr;PBS_Server;Torque Server Version = 3.0.5, loglevel = 0
02/18/2014 20:06:28;0040;PBS_Server;Svr;tyrone-cluster;Scheduler was sent the command new
02/18/2014 20:06:59;0040;PBS_Server;Svr;tyrone-cluster;Scheduler was sent the command new
02/18/2014 20:07:28;0040;PBS_Server;Svr;tyrone-cluster;Scheduler was sent the command new
02/18/2014 20:07:58;0040;PBS_Server;Svr;tyrone-cluster;Scheduler was sent the command new
02/18/2014 20:08:29;0040;PBS_Server;Svr;tyrone-cluster;Scheduler was sent the command new
02/18/2014 20:09:02;0040;PBS_Server;Svr;tyrone-cluster;Scheduler was sent the command new
02/18/2014 20:09:28;0040;PBS_Server;Svr;tyrone-cluster;Scheduler was sent the command new
02/18/2014 20:10:06;0040;PBS_Server;Svr;tyrone-cluster;Scheduler was sent the command new
02/18/2014 20:10:32;0040;PBS_Server;Svr;tyrone-cluster;Scheduler was sent the command new
02/18/2014 20:11:01;0040;PBS_Server;Svr;tyrone-cluster;Scheduler was sent the command new
02/18/2014 20:11:24;0002;PBS_Server;Svr;PBS_Server;Torque Server Version = 3.0.5, loglevel = 0
02/18/2014 20:11:37;0040;PBS_Server;Svr;tyrone-cluster;Scheduler was sent the command new
02/18/2014 20:12:09;0040;PBS_Server;Svr;tyrone-cluster;Scheduler was sent the command new
02/18/2014 20:12:41;0040;PBS_Server;Svr;tyrone-cluster;Scheduler was sent the command new
02/18/2014 20:13:13;0040;PBS_Server;Svr;tyrone-cluster;Scheduler was sent the command new
02/18/2014 20:13:44;0040;PBS_Server;Svr;tyrone-cluster;Scheduler was sent the command new
02/18/2014 20:14:17;0040;PBS_Server;Svr;tyrone-cluster;Scheduler was sent the command new
02/18/2014 20:14:43;0040;PBS_Server;Svr;tyrone-cluster;Scheduler was sent the command new
02/18/2014 20:15:21;0040;PBS_Server;Svr;tyrone-cluster;Scheduler was sent the command new
02/18/2014 20:15:47;0040;PBS_Server;Svr;tyrone-cluster;Scheduler was sent the command new
02/18/2014 20:16:16;0040;PBS_Server;Svr;tyrone-cluster;Scheduler was sent the command new
02/18/2014 20:16:24;0002;PBS_Server;Svr;PBS_Server;Torque Server Version = 3.0.5, loglevel = 0
02/18/2014 20:16:51;0040;PBS_Server;Svr;tyrone-cluster;Scheduler was sent the command new
02/18/2014 20:17:24;0040;PBS_Server;Svr;tyrone-cluster;Scheduler was sent the command new
02/18/2014 20:17:56;0040;PBS_Server;Svr;tyrone-cluster;Scheduler was sent the command new
02/18/2014 20:18:28;0040;PBS_Server;Svr;tyrone-cluster;Scheduler was sent the command new
02/18/2014 20:18:59;0040;PBS_Server;Svr;tyrone-cluster;Scheduler was sent the command new
02/18/2014 20:19:28;0040;PBS_Server;Svr;tyrone-cluster;Scheduler was sent the command new
02/18/2014 20:19:58;0040;PBS_Server;Svr;tyrone-cluster;Scheduler was sent the command new
02/18/2014 20:20:29;0040;PBS_Server;Svr;tyrone-cluster;Scheduler was sent the command new
02/18/2014 20:20:58;0040;PBS_Server;Svr;tyrone-cluster;Scheduler was sent the command new
02/18/2014 20:21:24;0002;PBS_Server;Svr;PBS_Server;Torque Server Version = 3.0.5, loglevel = 0
02/18/2014 20:21:28;0040;PBS_Server;Svr;tyrone-cluster;Scheduler was sent the command new
02/18/2014 20:21:59;0040;PBS_Server;Svr;tyrone-cluster;Scheduler was sent the command new
02/18/2014 20:22:32;0040;PBS_Server;Svr;tyrone-cluster;Scheduler was sent the command new
02/18/2014 20:22:58;0040;PBS_Server;Svr;tyrone-cluster;Scheduler was sent the command new
02/18/2014 20:23:36;0040;PBS_Server;Svr;tyrone-cluster;Scheduler was sent the command new
02/18/2014 20:24:02;0040;PBS_Server;Svr;tyrone-cluster;Scheduler was sent the command new
02/18/2014 20:24:31;0040;PBS_Server;Svr;tyrone-cluster;Scheduler was sent the command new
02/18/2014 20:25:07;0040;PBS_Server;Svr;tyrone-cluster;Scheduler was sent the command new
02/18/2014 20:25:16;0100;PBS_Server;Job;35259.tyrone-cluster;enqueuing into batch, state 1 hop 1
02/18/2014 20:25:16;0008;PBS_Server;Job;35259.tyrone-cluster;Job rejected by all possible destinations (check syntax, queue resources, ...)
02/18/2014 20:25:16;0100;PBS_Server;Job;35259.tyrone-cluster;dequeuing from batch, state QUEUED
02/18/2014 20:25:16;0080;PBS_Server;Req;req_reject;Reject reply code=15041(Job rejected by all possible destinations (check syntax, queue resources, ...)), aux=0, type=Commit, from physkc@tyrone-node9
02/18/2014 20:25:16;0040;PBS_Server;Svr;tyrone-cluster;Scheduler was sent the command term
02/18/2014 20:25:39;0040;PBS_Server;Svr;tyrone-cluster;Scheduler was sent the command new
02/18/2014 20:26:11;0040;PBS_Server;Svr;tyrone-cluster;Scheduler was sent the command new
02/18/2014 20:26:24;0002;PBS_Server;Svr;PBS_Server;Torque Server Version = 3.0.5, loglevel = 0
02/18/2014 20:26:43;0040;PBS_Server;Svr;tyrone-cluster;Scheduler was sent the command new
02/18/2014 20:27:14;0040;PBS_Server;Svr;tyrone-cluster;Scheduler was sent the command new
02/18/2014 20:27:47;0040;PBS_Server;Svr;tyrone-cluster;Scheduler was sent the command new
02/18/2014 20:28:13;0040;PBS_Server;Svr;tyrone-cluster;Scheduler was sent the command new
02/18/2014 20:28:44;0040;PBS_Server;Svr;tyrone-cluster;Scheduler was sent the command new
02/18/2014 20:29:17;0040;PBS_Server;Svr;tyrone-cluster;Scheduler was sent the command new
02/18/2014 20:29:43;0040;PBS_Server;Svr;tyrone-cluster;Scheduler was sent the command new
02/18/2014 20:30:15;0040;PBS_Server;Svr;tyrone-cluster;Scheduler was sent the command new
02/18/2014 20:30:47;0040;PBS_Server;Svr;tyrone-cluster;Scheduler was sent the command new
02/18/2014 20:31:17;0040;PBS_Server;Svr;tyrone-cluster;Scheduler was sent the command new
02/18/2014 20:31:24;0002;PBS_Server;Svr;PBS_Server;Torque Server Version = 3.0.5, loglevel = 0
02/18/2014 20:31:52;0040;PBS_Server;Svr;tyrone-cluster;Scheduler was sent the command new
02/18/2014 20:32:24;0040;PBS_Server;Svr;tyrone-cluster;Scheduler was sent the command new
02/18/2014 20:32:56;0040;PBS_Server;Svr;tyrone-cluster;Scheduler was sent the command new
02/18/2014 20:33:28;0040;PBS_Server;Svr;tyrone-cluster;Scheduler was sent the command new
02/18/2014 20:33:59;0040;PBS_Server;Svr;tyrone-cluster;Scheduler was sent the command new
02/18/2014 20:34:33;0040;PBS_Server;Svr;tyrone-cluster;Scheduler was sent the command new
02/18/2014 20:34:58;0040;PBS_Server;Svr;tyrone-cluster;Scheduler was sent the command new
02/18/2014 20:35:30;0040;PBS_Server;Svr;tyrone-cluster;Scheduler was sent the command new
02/18/2014 20:36:01;0040;PBS_Server;Svr;tyrone-cluster;Scheduler was sent the command new
02/18/2014 20:36:24;0002;PBS_Server;Svr;PBS_Server;Torque Server Version = 3.0.5, loglevel = 0
02/18/2014 20:36:28;0040;PBS_Server;Svr;tyrone-cluster;Scheduler was sent the command new
02/18/2014 20:37:00;0040;PBS_Server;Svr;tyrone-cluster;Scheduler was sent the command new
02/18/2014 20:37:32;0040;PBS_Server;Svr;tyrone-cluster;Scheduler was sent the command new
02/18/2014 20:38:03;0040;PBS_Server;Svr;tyrone-cluster;Scheduler was sent the command new
02/18/2014 20:38:36;0040;PBS_Server;Svr;tyrone-cluster;Scheduler was sent the command new
02/18/2014 20:39:09;0040;PBS_Server;Svr;tyrone-cluster;Scheduler was sent the command new
02/18/2014 20:39:41;0040;PBS_Server;Svr;tyrone-cluster;Scheduler was sent the command new
02/18/2014 20:40:13;0040;PBS_Server;Svr;tyrone-cluster;Scheduler was sent the command new
02/18/2014 20:40:45;0040;PBS_Server;Svr;tyrone-cluster;Scheduler was sent the command new
02/18/2014 20:41:17;0040;PBS_Server;Svr;tyrone-cluster;Scheduler was sent the command new
02/18/2014 20:41:24;0002;PBS_Server;Svr;PBS_Server;Torque Server Version = 3.0.5, loglevel = 0
02/18/2014 20:41:43;0040;PBS_Server;Svr;tyrone-cluster;Scheduler was sent the command new
02/18/2014 20:42:15;0040;PBS_Server;Svr;tyrone-cluster;Scheduler was sent the command new
02/18/2014 20:42:47;0040;PBS_Server;Svr;tyrone-cluster;Scheduler was sent the command new
02/18/2014 20:43:17;0040;PBS_Server;Svr;tyrone-cluster;Scheduler was sent the command new
02/18/2014 20:43:52;0040;PBS_Server;Svr;tyrone-cluster;Scheduler was sent the command new
02/18/2014 20:44:24;0040;PBS_Server;Svr;tyrone-cluster;Scheduler was sent the command new
02/18/2014 20:44:56;0040;PBS_Server;Svr;tyrone-cluster;Scheduler was sent the command new
02/18/2014 20:45:28;0040;PBS_Server;Svr;tyrone-cluster;Scheduler was sent the command new
02/18/2014 20:46:00;0040;PBS_Server;Svr;tyrone-cluster;Scheduler was sent the command new
02/18/2014 20:46:24;0002;PBS_Server;Svr;PBS_Server;Torque Server Version = 3.0.5, loglevel = 0
02/18/2014 20:46:32;0040;PBS_Server;Svr;tyrone-cluster;Scheduler was sent the command new
02/18/2014 20:46:58;0040;PBS_Server;Svr;tyrone-cluster;Scheduler was sent the command new
02/18/2014 20:47:30;0040;PBS_Server;Svr;tyrone-cluster;Scheduler was sent the command new
02/18/2014 20:48:02;0040;PBS_Server;Svr;tyrone-cluster;Scheduler was sent the command new
02/18/2014 20:48:32;0040;PBS_Server;Svr;tyrone-cluster;Scheduler was sent the command new
02/18/2014 20:49:07;0040;PBS_Server;Svr;tyrone-cluster;Scheduler was sent the command new
02/18/2014 20:49:39;0040;PBS_Server;Svr;tyrone-cluster;Scheduler was sent the command new
02/18/2014 20:50:11;0040;PBS_Server;Svr;tyrone-cluster;Scheduler was sent the command new
02/18/2014 20:50:43;0040;PBS_Server;Svr;tyrone-cluster;Scheduler was sent the command new
02/18/2014 20:51:15;0040;PBS_Server;Svr;tyrone-cluster;Scheduler was sent the command new
02/18/2014 20:51:24;0002;PBS_Server;Svr;PBS_Server;Torque Server Version = 3.0.5, loglevel = 0
02/18/2014 20:51:47;0040;PBS_Server;Svr;tyrone-cluster;Scheduler was sent the command new
02/18/2014 20:52:18;0040;PBS_Server;Svr;tyrone-cluster;Scheduler was sent the command new
02/18/2014 20:52:51;0040;PBS_Server;Svr;tyrone-cluster;Scheduler was sent the command new
02/18/2014 20:53:24;0040;PBS_Server;Svr;tyrone-cluster;Scheduler was sent the command new
02/18/2014 20:53:30;000d;PBS_Server;Job;35188.tyrone-cluster;Not sending email: User does not want mail of this type.
02/18/2014 20:53:30;0010;PBS_Server;Job;35188.tyrone-cluster;Exit_status=0 resources_used.cput=407:04:30 resources_used.mem=294000kb resources_used.vmem=1100340kb resources_used.walltime=24:00:27
02/18/2014 20:53:30;0008;PBS_Server;Job;NULL;on_job_exit valid pjob: 0x1dea340 (substate=50)
02/18/2014 20:53:30;0008;PBS_Server;Job;NULL;on_job_exit valid pjob: 0x1dea340 (substate=51)
02/18/2014 20:53:30;0008;PBS_Server;Job;NULL;on_job_exit valid pjob: 0x1dea340 (substate=51)
02/18/2014 20:53:30;0008;PBS_Server;Job;NULL;on_job_exit valid pjob: 0x1dea340 (substate=53)
02/18/2014 20:53:30;0100;PBS_Server;Job;35188.tyrone-cluster;dequeuing from qp32, state COMPLETE
02/18/2014 20:53:30;0040;PBS_Server;Svr;tyrone-cluster;Scheduler was sent the command term
02/18/2014 20:53:30;0008;PBS_Server;Job;35193.tyrone-cluster;Job Modified at request of Scheduler@tyrone-cluster
02/18/2014 20:53:30;0008;PBS_Server;Job;35254.tyrone-cluster;Job Modified at request of Scheduler@tyrone-cluster
02/18/2014 20:53:30;0008;PBS_Server;Job;35254.tyrone-cluster;Job Run at request of Scheduler@tyrone-cluster
02/18/2014 20:53:30;0040;PBS_Server;Svr;tyrone-cluster;Scheduler was sent the command recyc
02/18/2014 20:53:30;000d;PBS_Server;Job;35254.tyrone-cluster;Not sending email: User does not want mail of this type.
02/18/2014 20:53:39;000d;PBS_Server;Job;35254.tyrone-cluster;Not sending email: User does not want mail of this type.
02/18/2014 20:53:39;0010;PBS_Server;Job;35254.tyrone-cluster;Exit_status=255 resources_used.cput=00:00:53 resources_used.mem=0kb resources_used.vmem=0kb resources_used.walltime=00:00:09
02/18/2014 20:53:39;0008;PBS_Server;Job;NULL;on_job_exit valid pjob: 0x1ec48f0 (substate=50)
02/18/2014 20:53:39;0008;PBS_Server;Job;NULL;on_job_exit valid pjob: 0x1ec48f0 (substate=51)
02/18/2014 20:53:40;0008;PBS_Server;Job;NULL;on_job_exit valid pjob: 0x1ec48f0 (substate=51)
02/18/2014 20:53:40;0008;PBS_Server;Job;NULL;on_job_exit valid pjob: 0x1ec48f0 (substate=53)
02/18/2014 20:53:40;0100;PBS_Server;Job;35254.tyrone-cluster;dequeuing from qp32, state COMPLETE
02/18/2014 20:53:40;0040;PBS_Server;Svr;tyrone-cluster;Scheduler was sent the command term
02/18/2014 20:53:40;0008;PBS_Server;Job;35256.tyrone-cluster;Job Modified at request of Scheduler@tyrone-cluster
02/18/2014 20:53:40;0008;PBS_Server;Job;35256.tyrone-cluster;Job Run at request of Scheduler@tyrone-cluster
02/18/2014 20:53:40;0040;PBS_Server;Svr;tyrone-cluster;Scheduler was sent the command recyc
02/18/2014 20:53:40;000d;PBS_Server;Job;35256.tyrone-cluster;Not sending email: User does not want mail of this type.
02/18/2014 20:53:44;000d;PBS_Server;Job;35256.tyrone-cluster;Not sending email: User does not want mail of this type.
02/18/2014 20:53:44;0010;PBS_Server;Job;35256.tyrone-cluster;Exit_status=255 resources_used.cput=00:01:02 resources_used.mem=0kb resources_used.vmem=0kb resources_used.walltime=00:00:04
02/18/2014 20:53:44;0008;PBS_Server;Job;NULL;on_job_exit valid pjob: 0x1ec3450 (substate=50)
02/18/2014 20:53:44;0008;PBS_Server;Job;NULL;on_job_exit valid pjob: 0x1ec3450 (substate=51)
02/18/2014 20:53:48;0008;PBS_Server;Job;NULL;on_job_exit valid pjob: 0x1ec3450 (substate=51)
02/18/2014 20:53:48;000d;PBS_Server;Job;35256.tyrone-cluster;Post job file processing error; job 35256.tyrone-cluster on host tyrone-node2/31+tyrone-node2/30+tyrone-node2/29+tyrone-node2/28+tyrone-node2/27+tyrone-node2/26+tyrone-node2/25+tyrone-node2/24+tyrone-node2/23+tyrone-node2/22+tyrone-node2/21+tyrone-node2/20+tyrone-node2/19+tyrone-node2/18+tyrone-node2/17+tyrone-node2/16+tyrone-node2/15+tyrone-node2/14+tyrone-node2/13+tyrone-node2/12+tyrone-node2/11+tyrone-node2/10+tyrone-node2/9+tyrone-node2/8+tyrone-node2/7+tyrone-node2/6+tyrone-node2/5+tyrone-node2/4+tyrone-node2/3+tyrone-node2/2+tyrone-node2/1+tyrone-node2/0
02/18/2014 20:53:48;0008;PBS_Server;Job;NULL;on_job_exit valid pjob: 0x1ec3450 (substate=53)
02/18/2014 20:53:48;0100;PBS_Server;Job;35256.tyrone-cluster;dequeuing from qp32, state COMPLETE
02/18/2014 20:53:48;0040;PBS_Server;Svr;tyrone-cluster;Scheduler was sent the command term
02/18/2014 20:53:55;0040;PBS_Server;Svr;tyrone-cluster;Scheduler was sent the command new
02/18/2014 20:54:28;0040;PBS_Server;Svr;tyrone-cluster;Scheduler was sent the command new
02/18/2014 20:55:00;0040;PBS_Server;Svr;tyrone-cluster;Scheduler was sent the command new
02/18/2014 20:55:32;0040;PBS_Server;Svr;tyrone-cluster;Scheduler was sent the command new
02/18/2014 20:56:03;0040;PBS_Server;Svr;tyrone-cluster;Scheduler was sent the command new
02/18/2014 20:56:24;0002;PBS_Server;Svr;PBS_Server;Torque Server Version = 3.0.5, loglevel = 0
02/18/2014 20:56:37;0040;PBS_Server;Svr;tyrone-cluster;Scheduler was sent the command new
02/18/2014 20:57:09;0040;PBS_Server;Svr;tyrone-cluster;Scheduler was sent the command new
02/18/2014 20:57:41;0040;PBS_Server;Svr;tyrone-cluster;Scheduler was sent the command new
02/18/2014 20:58:13;0040;PBS_Server;Svr;tyrone-cluster;Scheduler was sent the command new
02/18/2014 20:58:45;0040;PBS_Server;Svr;tyrone-cluster;Scheduler was sent the command new
02/18/2014 20:59:17;0040;PBS_Server;Svr;tyrone-cluster;Scheduler was sent the command new
02/18/2014 20:59:47;0040;PBS_Server;Svr;tyrone-cluster;Scheduler was sent the command new
02/18/2014 21:00:22;0040;PBS_Server;Svr;tyrone-cluster;Scheduler was sent the command new
02/18/2014 21:00:54;0040;PBS_Server;Svr;tyrone-cluster;Scheduler was sent the command new
02/18/2014 21:01:24;0002;PBS_Server;Svr;PBS_Server;Torque Server Version = 3.0.5, loglevel = 0
02/18/2014 21:01:25;0040;PBS_Server;Svr;tyrone-cluster;Scheduler was sent the command new
02/18/2014 21:01:58;0040;PBS_Server;Svr;tyrone-cluster;Scheduler was sent the command new
02/18/2014 21:02:30;0040;PBS_Server;Svr;tyrone-cluster;Scheduler was sent the command new
02/18/2014 21:03:02;0040;PBS_Server;Svr;tyrone-cluster;Scheduler was sent the command new
02/18/2014 21:03:33;0040;PBS_Server;Svr;tyrone-cluster;Scheduler was sent the command new
02/18/2014 21:04:07;0040;PBS_Server;Svr;tyrone-cluster;Scheduler was sent the command new
02/18/2014 21:04:39;0040;PBS_Server;Svr;tyrone-cluster;Scheduler was sent the command new
02/18/2014 21:05:11;0040;PBS_Server;Svr;tyrone-cluster;Scheduler was sent the command new
02/18/2014 21:05:43;0040;PBS_Server;Svr;tyrone-cluster;Scheduler was sent the command new
02/18/2014 21:06:15;0040;PBS_Server;Svr;tyrone-cluster;Scheduler was sent the command new
02/18/2014 21:06:24;0002;PBS_Server;Svr;PBS_Server;Torque Server Version = 3.0.5, loglevel = 0
02/18/2014 21:06:47;0040;PBS_Server;Svr;tyrone-cluster;Scheduler was sent the command new
02/18/2014 21:07:18;0040;PBS_Server;Svr;tyrone-cluster;Scheduler was sent the command new
02/18/2014 21:07:52;0040;PBS_Server;Svr;tyrone-cluster;Scheduler was sent the command new
02/18/2014 21:08:24;0040;PBS_Server;Svr;tyrone-cluster;Scheduler was sent the command new
02/18/2014 21:08:55;0040;PBS_Server;Svr;tyrone-cluster;Scheduler was sent the command new
02/18/2014 21:09:28;0040;PBS_Server;Svr;tyrone-cluster;Scheduler was sent the command new
02/18/2014 21:10:00;0040;PBS_Server;Svr;tyrone-cluster;Scheduler was sent the command new
02/18/2014 21:10:32;0040;PBS_Server;Svr;tyrone-cluster;Scheduler was sent the command new
02/18/2014 21:11:03;0040;PBS_Server;Svr;tyrone-cluster;Scheduler was sent the command new
02/18/2014 21:11:24;0002;PBS_Server;Svr;PBS_Server;Torque Server Version = 3.0.5, loglevel = 0
02/18/2014 21:11:38;0040;PBS_Server;Svr;tyrone-cluster;Scheduler was sent the command new
02/18/2014 21:12:09;0040;PBS_Server;Svr;tyrone-cluster;Scheduler was sent the command new
02/18/2014 21:12:41;0040;PBS_Server;Svr;tyrone-cluster;Scheduler was sent the command new
02/18/2014 21:13:15;0040;PBS_Server;Svr;tyrone-cluster;Scheduler was sent the command new
02/18/2014 21:13:45;0040;PBS_Server;Svr;tyrone-cluster;Scheduler was sent the command new
02/18/2014 21:14:17;0040;PBS_Server;Svr;tyrone-cluster;Scheduler was sent the command new
02/18/2014 21:14:48;0040;PBS_Server;Svr;tyrone-cluster;Scheduler was sent the command new
02/18/2014 21:15:22;0040;PBS_Server;Svr;tyrone-cluster;Scheduler was sent the command new
02/18/2014 21:15:54;0040;PBS_Server;Svr;tyrone-cluster;Scheduler was sent the command new
02/18/2014 21:16:24;0002;PBS_Server;Svr;PBS_Server;Torque Server Version = 3.0.5, loglevel = 0
02/18/2014 21:16:25;0040;PBS_Server;Svr;tyrone-cluster;Scheduler was sent the command new
02/18/2014 21:16:58;0040;PBS_Server;Svr;tyrone-cluster;Scheduler was sent the command new
02/18/2014 21:17:25;0040;PBS_Server;Svr;tyrone-cluster;Scheduler was sent the command new
02/18/2014 21:17:56;0040;PBS_Server;Svr;tyrone-cluster;Scheduler was sent the command new
02/18/2014 21:18:28;0040;PBS_Server;Svr;tyrone-cluster;Scheduler was sent the command new
02/18/2014 21:19:00;0040;PBS_Server;Svr;tyrone-cluster;Scheduler was sent the command new
02/18/2014 21:19:32;0040;PBS_Server;Svr;tyrone-cluster;Scheduler was sent the command new
02/18/2014 21:20:02;0040;PBS_Server;Svr;tyrone-cluster;Scheduler was sent the command new
02/18/2014 21:20:37;0040;PBS_Server;Svr;tyrone-cluster;Scheduler was sent the command new
02/18/2014 21:21:09;0040;PBS_Server;Svr;tyrone-cluster;Scheduler was sent the command new
02/18/2014 21:21:24;0002;PBS_Server;Svr;PBS_Server;Torque Server Version = 3.0.5, loglevel = 0
02/18/2014 21:21:41;0040;PBS_Server;Svr;tyrone-cluster;Scheduler was sent the command new
02/18/2014 21:22:13;0040;PBS_Server;Svr;tyrone-cluster;Scheduler was sent the command new
02/18/2014 21:22:44;0040;PBS_Server;Svr;tyrone-cluster;Scheduler was sent the command new
02/18/2014 21:23:20;0040;PBS_Server;Svr;tyrone-cluster;Scheduler was sent the command new
02/18/2014 21:23:50;0040;PBS_Server;Svr;tyrone-cluster;Scheduler was sent the command new
02/18/2014 21:24:22;0040;PBS_Server;Svr;tyrone-cluster;Scheduler was sent the command new
02/18/2014 21:24:54;0040;PBS_Server;Svr;tyrone-cluster;Scheduler was sent the command new
02/18/2014 21:25:26;0040;PBS_Server;Svr;tyrone-cluster;Scheduler was sent the command new
02/18/2014 21:25:58;0040;PBS_Server;Svr;tyrone-cluster;Scheduler was sent the command new
02/18/2014 21:26:04;0100;PBS_Server;Job;35260.tyrone-cluster;enqueuing into batch, state 1 hop 1
02/18/2014 21:26:07;0008;PBS_Server;Job;35260.tyrone-cluster;Job rejected by all possible destinations (check syntax, queue resources, ...)
02/18/2014 21:26:07;0100;PBS_Server;Job;35260.tyrone-cluster;dequeuing from batch, state QUEUED
02/18/2014 21:26:07;0080;PBS_Server;Req;req_reject;Reject reply code=15041(Job rejected by all possible destinations (check syntax, queue resources, ...)), aux=0, type=Commit, from physkc@tyrone-node9
02/18/2014 21:26:07;0040;PBS_Server;Svr;tyrone-cluster;Scheduler was sent the command term
02/18/2014 21:26:24;0002;PBS_Server;Svr;PBS_Server;Torque Server Version = 3.0.5, loglevel = 0
02/18/2014 21:26:30;0040;PBS_Server;Svr;tyrone-cluster;Scheduler was sent the command new
02/18/2014 21:27:02;0040;PBS_Server;Svr;tyrone-cluster;Scheduler was sent the command new
02/18/2014 21:27:33;0040;PBS_Server;Svr;tyrone-cluster;Scheduler was sent the command new
02/18/2014 21:28:07;0040;PBS_Server;Svr;tyrone-cluster;Scheduler was sent the command new
02/18/2014 21:28:39;0040;PBS_Server;Svr;tyrone-cluster;Scheduler was sent the command new
02/18/2014 21:29:11;0040;PBS_Server;Svr;tyrone-cluster;Scheduler was sent the command new
02/18/2014 21:29:43;0040;PBS_Server;Svr;tyrone-cluster;Scheduler was sent the command new
02/18/2014 21:30:14;0040;PBS_Server;Svr;tyrone-cluster;Scheduler was sent the command new
02/18/2014 21:30:47;0040;PBS_Server;Svr;tyrone-cluster;Scheduler was sent the command new
02/18/2014 21:31:18;0040;PBS_Server;Svr;tyrone-cluster;Scheduler was sent the command new
02/18/2014 21:31:24;0002;PBS_Server;Svr;PBS_Server;Torque Server Version = 3.0.5, loglevel = 0
02/18/2014 21:31:52;0040;PBS_Server;Svr;tyrone-cluster;Scheduler was sent the command new
02/18/2014 21:32:24;0040;PBS_Server;Svr;tyrone-cluster;Scheduler was sent the command new
02/18/2014 21:32:56;0040;PBS_Server;Svr;tyrone-cluster;Scheduler was sent the command new
02/18/2014 21:33:28;0040;PBS_Server;Svr;tyrone-cluster;Scheduler was sent the command new
02/18/2014 21:34:00;0040;PBS_Server;Svr;tyrone-cluster;Scheduler was sent the command new
02/18/2014 21:34:32;0040;PBS_Server;Svr;tyrone-cluster;Scheduler was sent the command new
02/18/2014 21:35:03;0040;PBS_Server;Svr;tyrone-cluster;Scheduler was sent the command new
02/18/2014 21:35:37;0040;PBS_Server;Svr;tyrone-cluster;Scheduler was sent the command new
02/18/2014 21:36:09;0040;PBS_Server;Svr;tyrone-cluster;Scheduler was sent the command new
02/18/2014 21:36:24;0002;PBS_Server;Svr;PBS_Server;Torque Server Version = 3.0.5, loglevel = 0
02/18/2014 21:36:41;0040;PBS_Server;Svr;tyrone-cluster;Scheduler was sent the command new
02/18/2014 21:37:13;0040;PBS_Server;Svr;tyrone-cluster;Scheduler was sent the command new
02/18/2014 21:37:45;0040;PBS_Server;Svr;tyrone-cluster;Scheduler was sent the command new
02/18/2014 21:38:17;0040;PBS_Server;Svr;tyrone-cluster;Scheduler was sent the command new
02/18/2014 21:38:48;0040;PBS_Server;Svr;tyrone-cluster;Scheduler was sent the command new
02/18/2014 21:39:22;0040;PBS_Server;Svr;tyrone-cluster;Scheduler was sent the command new
02/18/2014 21:39:54;0040;PBS_Server;Svr;tyrone-cluster;Scheduler was sent the command new
02/18/2014 21:40:26;0040;PBS_Server;Svr;tyrone-cluster;Scheduler was sent the command new
02/18/2014 21:40:58;0040;PBS_Server;Svr;tyrone-cluster;Scheduler was sent the command new
02/18/2014 21:41:24;0002;PBS_Server;Svr;PBS_Server;Torque Server Version = 3.0.5, loglevel = 0
02/18/2014 21:41:30;0040;PBS_Server;Svr;tyrone-cluster;Scheduler was sent the command new
02/18/2014 21:42:02;0040;PBS_Server;Svr;tyrone-cluster;Scheduler was sent the command new
02/18/2014 21:42:33;0040;PBS_Server;Svr;tyrone-cluster;Scheduler was sent the command new
02/18/2014 21:43:07;0040;PBS_Server;Svr;tyrone-cluster;Scheduler was sent the command new
02/18/2014 21:43:39;0040;PBS_Server;Svr;tyrone-cluster;Scheduler was sent the command new
02/18/2014 21:44:11;0040;PBS_Server;Svr;tyrone-cluster;Scheduler was sent the command new
02/18/2014 21:44:43;0040;PBS_Server;Svr;tyrone-cluster;Scheduler was sent the command new
02/18/2014 21:45:15;0040;PBS_Server;Svr;tyrone-cluster;Scheduler was sent the command new
02/18/2014 21:45:47;0040;PBS_Server;Svr;tyrone-cluster;Scheduler was sent the command new
02/18/2014 21:46:18;0040;PBS_Server;Svr;tyrone-cluster;Scheduler was sent the command new
02/18/2014 21:46:24;0002;PBS_Server;Svr;PBS_Server;Torque Server Version = 3.0.5, loglevel = 0
02/18/2014 21:46:52;0040;PBS_Server;Svr;tyrone-cluster;Scheduler was sent the command new
02/18/2014 21:47:24;0040;PBS_Server;Svr;tyrone-cluster;Scheduler was sent the command new
02/18/2014 21:47:56;0040;PBS_Server;Svr;tyrone-cluster;Scheduler was sent the command new
02/18/2014 21:48:28;0040;PBS_Server;Svr;tyrone-cluster;Scheduler was sent the command new
02/18/2014 21:48:59;0040;PBS_Server;Svr;tyrone-cluster;Scheduler was sent the command new
02/18/2014 21:49:32;0040;PBS_Server;Svr;tyrone-cluster;Scheduler was sent the command new
02/18/2014 21:50:03;0040;PBS_Server;Svr;tyrone-cluster;Scheduler was sent the command new
02/18/2014 21:50:37;0040;PBS_Server;Svr;tyrone-cluster;Scheduler was sent the command new
02/18/2014 21:51:09;0040;PBS_Server;Svr;tyrone-cluster;Scheduler was sent the command new
02/18/2014 21:51:24;0002;PBS_Server;Svr;PBS_Server;Torque Server Version = 3.0.5, loglevel = 0
02/18/2014 21:51:41;0040;PBS_Server;Svr;tyrone-cluster;Scheduler was sent the command new
02/18/2014 21:52:13;0040;PBS_Server;Svr;tyrone-cluster;Scheduler was sent the command new
02/18/2014 21:52:45;0040;PBS_Server;Svr;tyrone-cluster;Scheduler was sent the command new
02/18/2014 21:53:17;0040;PBS_Server;Svr;tyrone-cluster;Scheduler was sent the command new
02/18/2014 21:53:48;0040;PBS_Server;Svr;tyrone-cluster;Scheduler was sent the command new
02/18/2014 21:54:22;0040;PBS_Server;Svr;tyrone-cluster;Scheduler was sent the command new
02/18/2014 21:54:54;0040;PBS_Server;Svr;tyrone-cluster;Scheduler was sent the command new
02/18/2014 21:55:26;0040;PBS_Server;Svr;tyrone-cluster;Scheduler was sent the command new
02/18/2014 21:55:58;0040;PBS_Server;Svr;tyrone-cluster;Scheduler was sent the command new
02/18/2014 21:56:24;0002;PBS_Server;Svr;PBS_Server;Torque Server Version = 3.0.5, loglevel = 0
02/18/2014 21:56:30;0040;PBS_Server;Svr;tyrone-cluster;Scheduler was sent the command new
02/18/2014 21:57:02;0040;PBS_Server;Svr;tyrone-cluster;Scheduler was sent the command new
02/18/2014 21:57:33;0040;PBS_Server;Svr;tyrone-cluster;Scheduler was sent the command new
02/18/2014 21:58:07;0040;PBS_Server;Svr;tyrone-cluster;Scheduler was sent the command new
02/18/2014 21:58:39;0040;PBS_Server;Svr;tyrone-cluster;Scheduler was sent the command new
02/18/2014 21:59:11;0040;PBS_Server;Svr;tyrone-cluster;Scheduler was sent the command new
02/18/2014 21:59:43;0040;PBS_Server;Svr;tyrone-cluster;Scheduler was sent the command new
02/18/2014 22:00:15;0040;PBS_Server;Svr;tyrone-cluster;Scheduler was sent the command new
02/18/2014 22:00:47;0040;PBS_Server;Svr;tyrone-cluster;Scheduler was sent the command new
02/18/2014 22:01:18;0040;PBS_Server;Svr;tyrone-cluster;Scheduler was sent the command new
02/18/2014 22:01:24;0002;PBS_Server;Svr;PBS_Server;Torque Server Version = 3.0.5, loglevel = 0
02/18/2014 22:01:52;0040;PBS_Server;Svr;tyrone-cluster;Scheduler was sent the command new
02/18/2014 22:02:24;0040;PBS_Server;Svr;tyrone-cluster;Scheduler was sent the command new
02/18/2014 22:02:56;0040;PBS_Server;Svr;tyrone-cluster;Scheduler was sent the command new
02/18/2014 22:03:28;0040;PBS_Server;Svr;tyrone-cluster;Scheduler was sent the command new
02/18/2014 22:04:00;0040;PBS_Server;Svr;tyrone-cluster;Scheduler was sent the command new
02/18/2014 22:04:32;0040;PBS_Server;Svr;tyrone-cluster;Scheduler was sent the command new
02/18/2014 22:05:03;0040;PBS_Server;Svr;tyrone-cluster;Scheduler was sent the command new
02/18/2014 22:05:37;0040;PBS_Server;Svr;tyrone-cluster;Scheduler was sent the command new
02/18/2014 22:06:09;0040;PBS_Server;Svr;tyrone-cluster;Scheduler was sent the command new
02/18/2014 22:06:24;0002;PBS_Server;Svr;PBS_Server;Torque Server Version = 3.0.5, loglevel = 0
02/18/2014 22:06:41;0040;PBS_Server;Svr;tyrone-cluster;Scheduler was sent the command new
02/18/2014 22:07:13;0040;PBS_Server;Svr;tyrone-cluster;Scheduler was sent the command new
02/18/2014 22:07:45;0040;PBS_Server;Svr;tyrone-cluster;Scheduler was sent the command new
02/18/2014 22:08:17;0040;PBS_Server;Svr;tyrone-cluster;Scheduler was sent the command new
02/18/2014 22:08:48;0040;PBS_Server;Svr;tyrone-cluster;Scheduler was sent the command new
02/18/2014 22:09:22;0040;PBS_Server;Svr;tyrone-cluster;Scheduler was sent the command new
02/18/2014 22:09:54;0040;PBS_Server;Svr;tyrone-cluster;Scheduler was sent the command new
02/18/2014 22:10:26;0040;PBS_Server;Svr;tyrone-cluster;Scheduler was sent the command new
02/18/2014 22:10:58;0040;PBS_Server;Svr;tyrone-cluster;Scheduler was sent the command new
02/18/2014 22:11:24;0002;PBS_Server;Svr;PBS_Server;Torque Server Version = 3.0.5, loglevel = 0
02/18/2014 22:11:30;0040;PBS_Server;Svr;tyrone-cluster;Scheduler was sent the command new
02/18/2014 22:12:02;0040;PBS_Server;Svr;tyrone-cluster;Scheduler was sent the command new
02/18/2014 22:12:33;0040;PBS_Server;Svr;tyrone-cluster;Scheduler was sent the command new
02/18/2014 22:13:07;0040;PBS_Server;Svr;tyrone-cluster;Scheduler was sent the command new
02/18/2014 22:13:40;0040;PBS_Server;Svr;tyrone-cluster;Scheduler was sent the command new
02/18/2014 22:14:11;0040;PBS_Server;Svr;tyrone-cluster;Scheduler was sent the command new
02/18/2014 22:14:43;0040;PBS_Server;Svr;tyrone-cluster;Scheduler was sent the command new
02/18/2014 22:15:15;0040;PBS_Server;Svr;tyrone-cluster;Scheduler was sent the command new
02/18/2014 22:15:38;0100;PBS_Server;Job;35261.tyrone-cluster;enqueuing into batch, state 1 hop 1
02/18/2014 22:15:38;0008;PBS_Server;Job;35261.tyrone-cluster;Job rejected by all possible destinations (check syntax, queue resources, ...)
02/18/2014 22:15:38;0100;PBS_Server;Job;35261.tyrone-cluster;dequeuing from batch, state QUEUED
02/18/2014 22:15:38;0080;PBS_Server;Req;req_reject;Reject reply code=15041(Job rejected by all possible destinations (check syntax, queue resources, ...)), aux=0, type=Commit, from physkc@tyrone-node9
02/18/2014 22:15:38;0040;PBS_Server;Svr;tyrone-cluster;Scheduler was sent the command term
02/18/2014 22:15:47;0040;PBS_Server;Svr;tyrone-cluster;Scheduler was sent the command new
02/18/2014 22:16:18;0040;PBS_Server;Svr;tyrone-cluster;Scheduler was sent the command new
02/18/2014 22:16:24;0002;PBS_Server;Svr;PBS_Server;Torque Server Version = 3.0.5, loglevel = 0
02/18/2014 22:16:53;0040;PBS_Server;Svr;tyrone-cluster;Scheduler was sent the command new
02/18/2014 22:17:24;0040;PBS_Server;Svr;tyrone-cluster;Scheduler was sent the command new
02/18/2014 22:17:56;0040;PBS_Server;Svr;tyrone-cluster;Scheduler was sent the command new
02/18/2014 22:18:28;0040;PBS_Server;Svr;tyrone-cluster;Scheduler was sent the command new
02/18/2014 22:19:00;0040;PBS_Server;Svr;tyrone-cluster;Scheduler was sent the command new
02/18/2014 22:19:32;0040;PBS_Server;Svr;tyrone-cluster;Scheduler was sent the command new
02/18/2014 22:20:03;0040;PBS_Server;Svr;tyrone-cluster;Scheduler was sent the command new
02/18/2014 22:20:37;0040;PBS_Server;Svr;tyrone-cluster;Scheduler was sent the command new
02/18/2014 22:21:09;0040;PBS_Server;Svr;tyrone-cluster;Scheduler was sent the command new
02/18/2014 22:21:24;0002;PBS_Server;Svr;PBS_Server;Torque Server Version = 3.0.5, loglevel = 0
02/18/2014 22:21:41;0040;PBS_Server;Svr;tyrone-cluster;Scheduler was sent the command new
02/18/2014 22:22:13;0040;PBS_Server;Svr;tyrone-cluster;Scheduler was sent the command new
02/18/2014 22:22:45;0040;PBS_Server;Svr;tyrone-cluster;Scheduler was sent the command new
02/18/2014 22:23:17;0040;PBS_Server;Svr;tyrone-cluster;Scheduler was sent the command new
02/18/2014 22:23:48;0040;PBS_Server;Svr;tyrone-cluster;Scheduler was sent the command new
02/18/2014 22:24:22;0040;PBS_Server;Svr;tyrone-cluster;Scheduler was sent the command new
02/18/2014 22:24:54;0040;PBS_Server;Svr;tyrone-cluster;Scheduler was sent the command new
02/18/2014 22:25:26;0040;PBS_Server;Svr;tyrone-cluster;Scheduler was sent the command new
02/18/2014 22:25:58;0040;PBS_Server;Svr;tyrone-cluster;Scheduler was sent the command new
02/18/2014 22:26:24;0002;PBS_Server;Svr;PBS_Server;Torque Server Version = 3.0.5, loglevel = 0
02/18/2014 22:26:30;0040;PBS_Server;Svr;tyrone-cluster;Scheduler was sent the command new
02/18/2014 22:27:02;0040;PBS_Server;Svr;tyrone-cluster;Scheduler was sent the command new
02/18/2014 22:27:33;0040;PBS_Server;Svr;tyrone-cluster;Scheduler was sent the command new
02/18/2014 22:28:07;0040;PBS_Server;Svr;tyrone-cluster;Scheduler was sent the command new
02/18/2014 22:28:39;0040;PBS_Server;Svr;tyrone-cluster;Scheduler was sent the command new
02/18/2014 22:29:11;0040;PBS_Server;Svr;tyrone-cluster;Scheduler was sent the command new
02/18/2014 22:29:43;0040;PBS_Server;Svr;tyrone-cluster;Scheduler was sent the command new
02/18/2014 22:30:15;0040;PBS_Server;Svr;tyrone-cluster;Scheduler was sent the command new
02/18/2014 22:30:47;0040;PBS_Server;Svr;tyrone-cluster;Scheduler was sent the command new
02/18/2014 22:31:18;0040;PBS_Server;Svr;tyrone-cluster;Scheduler was sent the command new
02/18/2014 22:31:24;0002;PBS_Server;Svr;PBS_Server;Torque Server Version = 3.0.5, loglevel = 0
02/18/2014 22:31:52;0040;PBS_Server;Svr;tyrone-cluster;Scheduler was sent the command new
02/18/2014 22:32:24;0040;PBS_Server;Svr;tyrone-cluster;Scheduler was sent the command new
02/18/2014 22:32:56;0040;PBS_Server;Svr;tyrone-cluster;Scheduler was sent the command new
02/18/2014 22:33:28;0040;PBS_Server;Svr;tyrone-cluster;Scheduler was sent the command new
02/18/2014 22:34:00;0040;PBS_Server;Svr;tyrone-cluster;Scheduler was sent the command new
02/18/2014 22:34:32;0040;PBS_Server;Svr;tyrone-cluster;Scheduler was sent the command new
02/18/2014 22:35:03;0040;PBS_Server;Svr;tyrone-cluster;Scheduler was sent the command new
02/18/2014 22:35:37;0040;PBS_Server;Svr;tyrone-cluster;Scheduler was sent the command new
02/18/2014 22:36:09;0040;PBS_Server;Svr;tyrone-cluster;Scheduler was sent the command new
02/18/2014 22:36:24;0002;PBS_Server;Svr;PBS_Server;Torque Server Version = 3.0.5, loglevel = 0
02/18/2014 22:36:41;0040;PBS_Server;Svr;tyrone-cluster;Scheduler was sent the command new
02/18/2014 22:37:13;0040;PBS_Server;Svr;tyrone-cluster;Scheduler was sent the command new
02/18/2014 22:37:45;0040;PBS_Server;Svr;tyrone-cluster;Scheduler was sent the command new
02/18/2014 22:38:17;0040;PBS_Server;Svr;tyrone-cluster;Scheduler was sent the command new
02/18/2014 22:38:48;0040;PBS_Server;Svr;tyrone-cluster;Scheduler was sent the command new
02/18/2014 22:39:22;0040;PBS_Server;Svr;tyrone-cluster;Scheduler was sent the command new
02/18/2014 22:39:54;0040;PBS_Server;Svr;tyrone-cluster;Scheduler was sent the command new
02/18/2014 22:40:26;0040;PBS_Server;Svr;tyrone-cluster;Scheduler was sent the command new
02/18/2014 22:40:58;0040;PBS_Server;Svr;tyrone-cluster;Scheduler was sent the command new
02/18/2014 22:41:24;0002;PBS_Server;Svr;PBS_Server;Torque Server Version = 3.0.5, loglevel = 0
02/18/2014 22:41:30;0040;PBS_Server;Svr;tyrone-cluster;Scheduler was sent the command new
02/18/2014 22:42:02;0040;PBS_Server;Svr;tyrone-cluster;Scheduler was sent the command new
02/18/2014 22:42:33;0040;PBS_Server;Svr;tyrone-cluster;Scheduler was sent the command new
02/18/2014 22:43:07;0040;PBS_Server;Svr;tyrone-cluster;Scheduler was sent the command new
02/18/2014 22:43:39;0040;PBS_Server;Svr;tyrone-cluster;Scheduler was sent the command new
02/18/2014 22:44:11;0040;PBS_Server;Svr;tyrone-cluster;Scheduler was sent the command new
02/18/2014 22:44:43;0040;PBS_Server;Svr;tyrone-cluster;Scheduler was sent the command new
02/18/2014 22:45:15;0040;PBS_Server;Svr;tyrone-cluster;Scheduler was sent the command new
02/18/2014 22:45:47;0040;PBS_Server;Svr;tyrone-cluster;Scheduler was sent the command new
02/18/2014 22:46:19;0040;PBS_Server;Svr;tyrone-cluster;Scheduler was sent the command new
02/18/2014 22:46:24;0002;PBS_Server;Svr;PBS_Server;Torque Server Version = 3.0.5, loglevel = 0
02/18/2014 22:46:52;0040;PBS_Server;Svr;tyrone-cluster;Scheduler was sent the command new
02/18/2014 22:47:24;0040;PBS_Server;Svr;tyrone-cluster;Scheduler was sent the command new
02/18/2014 22:47:56;0040;PBS_Server;Svr;tyrone-cluster;Scheduler was sent the command new
02/18/2014 22:48:28;0040;PBS_Server;Svr;tyrone-cluster;Scheduler was sent the command new
02/18/2014 22:49:00;0040;PBS_Server;Svr;tyrone-cluster;Scheduler was sent the command new
02/18/2014 22:49:32;0040;PBS_Server;Svr;tyrone-cluster;Scheduler was sent the command new
02/18/2014 22:50:04;0040;PBS_Server;Svr;tyrone-cluster;Scheduler was sent the command new
02/18/2014 22:50:37;0040;PBS_Server;Svr;tyrone-cluster;Scheduler was sent the command new
02/18/2014 22:51:09;0040;PBS_Server;Svr;tyrone-cluster;Scheduler was sent the command new
02/18/2014 22:51:24;0002;PBS_Server;Svr;PBS_Server;Torque Server Version = 3.0.5, loglevel = 0
02/18/2014 22:51:41;0040;PBS_Server;Svr;tyrone-cluster;Scheduler was sent the command new
02/18/2014 22:52:13;0040;PBS_Server;Svr;tyrone-cluster;Scheduler was sent the command new
02/18/2014 22:52:46;0040;PBS_Server;Svr;tyrone-cluster;Scheduler was sent the command new
02/18/2014 22:52:55;000d;PBS_Server;Job;35116.tyrone-cluster;Not sending email: User does not want mail of this type.
02/18/2014 22:52:55;0010;PBS_Server;Job;35116.tyrone-cluster;Exit_status=271 resources_used.cput=1535:51:45 resources_used.mem=2308940kb resources_used.vmem=35347244kb resources_used.walltime=24:00:46
02/18/2014 22:52:55;0008;PBS_Server;Job;NULL;on_job_exit valid pjob: 0x1e62070 (substate=50)
02/18/2014 22:52:55;0008;PBS_Server;Job;NULL;on_job_exit valid pjob: 0x1e62070 (substate=51)
02/18/2014 22:52:55;0008;PBS_Server;Job;NULL;on_job_exit valid pjob: 0x1e62070 (substate=51)
02/18/2014 22:52:55;0008;PBS_Server;Job;NULL;on_job_exit valid pjob: 0x1e62070 (substate=53)
02/18/2014 22:52:55;0100;PBS_Server;Job;35116.tyrone-cluster;dequeuing from qp64, state COMPLETE
02/18/2014 22:52:55;0040;PBS_Server;Svr;tyrone-cluster;Scheduler was sent the command term
02/18/2014 22:52:55;0008;PBS_Server;Job;35134.tyrone-cluster;Job Modified at request of Scheduler@tyrone-cluster
02/18/2014 22:52:55;0008;PBS_Server;Job;35134.tyrone-cluster;Job Run at request of Scheduler@tyrone-cluster
02/18/2014 22:52:55;0040;PBS_Server;Svr;tyrone-cluster;Scheduler was sent the command recyc
02/18/2014 22:52:55;000d;PBS_Server;Job;35134.tyrone-cluster;Not sending email: User does not want mail of this type.
02/18/2014 22:53:17;0040;PBS_Server;Svr;tyrone-cluster;Scheduler was sent the command new
02/18/2014 22:53:50;0040;PBS_Server;Svr;tyrone-cluster;Scheduler was sent the command new
02/18/2014 22:54:21;0040;PBS_Server;Svr;tyrone-cluster;Scheduler was sent the command new
02/18/2014 22:54:54;0040;PBS_Server;Svr;tyrone-cluster;Scheduler was sent the command new
02/18/2014 22:55:26;0040;PBS_Server;Svr;tyrone-cluster;Scheduler was sent the command new
02/18/2014 22:55:58;0040;PBS_Server;Svr;tyrone-cluster;Scheduler was sent the command new
02/18/2014 22:56:25;0002;PBS_Server;Svr;PBS_Server;Torque Server Version = 3.0.5, loglevel = 0
02/18/2014 22:56:30;0040;PBS_Server;Svr;tyrone-cluster;Scheduler was sent the command new
02/18/2014 22:57:02;0040;PBS_Server;Svr;tyrone-cluster;Scheduler was sent the command new
02/18/2014 22:57:33;0040;PBS_Server;Svr;tyrone-cluster;Scheduler was sent the command new
02/18/2014 22:58:06;0040;PBS_Server;Svr;tyrone-cluster;Scheduler was sent the command new
02/18/2014 22:58:39;0040;PBS_Server;Svr;tyrone-cluster;Scheduler was sent the command new
02/18/2014 22:59:11;0040;PBS_Server;Svr;tyrone-cluster;Scheduler was sent the command new
02/18/2014 22:59:43;0040;PBS_Server;Svr;tyrone-cluster;Scheduler was sent the command new
02/18/2014 23:00:15;0040;PBS_Server;Svr;tyrone-cluster;Scheduler was sent the command new
02/18/2014 23:00:47;0040;PBS_Server;Svr;tyrone-cluster;Scheduler was sent the command new
02/18/2014 23:01:18;0040;PBS_Server;Svr;tyrone-cluster;Scheduler was sent the command new
02/18/2014 23:01:25;0002;PBS_Server;Svr;PBS_Server;Torque Server Version = 3.0.5, loglevel = 0
02/18/2014 23:01:51;0040;PBS_Server;Svr;tyrone-cluster;Scheduler was sent the command new
02/18/2014 23:02:24;0040;PBS_Server;Svr;tyrone-cluster;Scheduler was sent the command new
02/18/2014 23:02:56;0040;PBS_Server;Svr;tyrone-cluster;Scheduler was sent the command new
02/18/2014 23:03:28;0040;PBS_Server;Svr;tyrone-cluster;Scheduler was sent the command new
02/18/2014 23:04:00;0040;PBS_Server;Svr;tyrone-cluster;Scheduler was sent the command new
02/18/2014 23:04:32;0040;PBS_Server;Svr;tyrone-cluster;Scheduler was sent the command new
02/18/2014 23:05:03;0040;PBS_Server;Svr;tyrone-cluster;Scheduler was sent the command new
02/18/2014 23:05:36;0040;PBS_Server;Svr;tyrone-cluster;Scheduler was sent the command new
02/18/2014 23:06:09;0040;PBS_Server;Svr;tyrone-cluster;Scheduler was sent the command new
02/18/2014 23:06:25;0002;PBS_Server;Svr;PBS_Server;Torque Server Version = 3.0.5, loglevel = 0
02/18/2014 23:06:41;0040;PBS_Server;Svr;tyrone-cluster;Scheduler was sent the command new
02/18/2014 23:07:13;0040;PBS_Server;Svr;tyrone-cluster;Scheduler was sent the command new
02/18/2014 23:07:46;0040;PBS_Server;Svr;tyrone-cluster;Scheduler was sent the command new
02/18/2014 23:08:17;0040;PBS_Server;Svr;tyrone-cluster;Scheduler was sent the command new
02/18/2014 23:08:49;0040;PBS_Server;Svr;tyrone-cluster;Scheduler was sent the command new
02/18/2014 23:09:21;0040;PBS_Server;Svr;tyrone-cluster;Scheduler was sent the command new
02/18/2014 23:09:54;0040;PBS_Server;Svr;tyrone-cluster;Scheduler was sent the command new
02/18/2014 23:10:26;0040;PBS_Server;Svr;tyrone-cluster;Scheduler was sent the command new
02/18/2014 23:10:58;0040;PBS_Server;Svr;tyrone-cluster;Scheduler was sent the command new
02/18/2014 23:11:25;0002;PBS_Server;Svr;PBS_Server;Torque Server Version = 3.0.5, loglevel = 0
02/18/2014 23:11:31;0040;PBS_Server;Svr;tyrone-cluster;Scheduler was sent the command new
02/18/2014 23:12:02;0040;PBS_Server;Svr;tyrone-cluster;Scheduler was sent the command new
02/18/2014 23:12:35;0040;PBS_Server;Svr;tyrone-cluster;Scheduler was sent the command new
02/18/2014 23:13:06;0040;PBS_Server;Svr;tyrone-cluster;Scheduler was sent the command new
02/18/2014 23:13:39;0040;PBS_Server;Svr;tyrone-cluster;Scheduler was sent the command new
02/18/2014 23:14:11;0040;PBS_Server;Svr;tyrone-cluster;Scheduler was sent the command new
02/18/2014 23:14:43;0040;PBS_Server;Svr;tyrone-cluster;Scheduler was sent the command new
02/18/2014 23:15:15;0040;PBS_Server;Svr;tyrone-cluster;Scheduler was sent the command new
02/18/2014 23:15:32;000d;PBS_Server;Job;35190.tyrone-cluster;Not sending email: User does not want mail of this type.
02/18/2014 23:15:32;0010;PBS_Server;Job;35190.tyrone-cluster;Exit_status=0 resources_used.cput=511:51:14 resources_used.mem=1903912kb resources_used.vmem=5643520kb resources_used.walltime=16:01:32
02/18/2014 23:15:32;0008;PBS_Server;Job;NULL;on_job_exit valid pjob: 0x1da6be0 (substate=50)
02/18/2014 23:15:32;0008;PBS_Server;Job;NULL;on_job_exit valid pjob: 0x1da6be0 (substate=51)
02/18/2014 23:15:32;0008;PBS_Server;Job;NULL;on_job_exit valid pjob: 0x1da6be0 (substate=51)
02/18/2014 23:15:32;0008;PBS_Server;Job;NULL;on_job_exit valid pjob: 0x1da6be0 (substate=53)
02/18/2014 23:15:32;0100;PBS_Server;Job;35190.tyrone-cluster;dequeuing from qp32, state COMPLETE
02/18/2014 23:15:32;0040;PBS_Server;Svr;tyrone-cluster;Scheduler was sent the command term
02/18/2014 23:15:33;0008;PBS_Server;Job;35193.tyrone-cluster;Job Modified at request of Scheduler@tyrone-cluster
02/18/2014 23:15:33;0008;PBS_Server;Job;35193.tyrone-cluster;Job Run at request of Scheduler@tyrone-cluster
02/18/2014 23:15:33;0040;PBS_Server;Svr;tyrone-cluster;Scheduler was sent the command recyc
02/18/2014 23:15:33;000d;PBS_Server;Job;35193.tyrone-cluster;Not sending email: User does not want mail of this type.
02/18/2014 23:15:47;0040;PBS_Server;Svr;tyrone-cluster;Scheduler was sent the command new
02/18/2014 23:16:18;0040;PBS_Server;Svr;tyrone-cluster;Scheduler was sent the command new
02/18/2014 23:16:25;0002;PBS_Server;Svr;PBS_Server;Torque Server Version = 3.0.5, loglevel = 0
02/18/2014 23:16:51;0040;PBS_Server;Svr;tyrone-cluster;Scheduler was sent the command new
02/18/2014 23:17:24;0040;PBS_Server;Svr;tyrone-cluster;Scheduler was sent the command new
02/18/2014 23:17:56;0040;PBS_Server;Svr;tyrone-cluster;Scheduler was sent the command new
02/18/2014 23:18:28;0040;PBS_Server;Svr;tyrone-cluster;Scheduler was sent the command new
02/18/2014 23:19:01;0040;PBS_Server;Svr;tyrone-cluster;Scheduler was sent the command new
02/18/2014 23:19:32;0040;PBS_Server;Svr;tyrone-cluster;Scheduler was sent the command new
02/18/2014 23:20:04;0040;PBS_Server;Svr;tyrone-cluster;Scheduler was sent the command new
02/18/2014 23:20:36;0040;PBS_Server;Svr;tyrone-cluster;Scheduler was sent the command new
02/18/2014 23:21:09;0040;PBS_Server;Svr;tyrone-cluster;Scheduler was sent the command new
02/18/2014 23:21:25;0002;PBS_Server;Svr;PBS_Server;Torque Server Version = 3.0.5, loglevel = 0
02/18/2014 23:21:41;0040;PBS_Server;Svr;tyrone-cluster;Scheduler was sent the command new
02/18/2014 23:22:13;0040;PBS_Server;Svr;tyrone-cluster;Scheduler was sent the command new
02/18/2014 23:22:46;0040;PBS_Server;Svr;tyrone-cluster;Scheduler was sent the command new
02/18/2014 23:23:17;0040;PBS_Server;Svr;tyrone-cluster;Scheduler was sent the command new
02/18/2014 23:23:50;0040;PBS_Server;Svr;tyrone-cluster;Scheduler was sent the command new
02/18/2014 23:24:21;0040;PBS_Server;Svr;tyrone-cluster;Scheduler was sent the command new
02/18/2014 23:24:54;0040;PBS_Server;Svr;tyrone-cluster;Scheduler was sent the command new
02/18/2014 23:25:26;0040;PBS_Server;Svr;tyrone-cluster;Scheduler was sent the command new
02/18/2014 23:25:57;0040;PBS_Server;Svr;tyrone-cluster;Scheduler was sent the command new
02/18/2014 23:26:24;0040;PBS_Server;Svr;tyrone-cluster;Scheduler was sent the command new
02/18/2014 23:26:25;0002;PBS_Server;Svr;PBS_Server;Torque Server Version = 3.0.5, loglevel = 0
02/18/2014 23:26:56;0040;PBS_Server;Svr;tyrone-cluster;Scheduler was sent the command new
02/18/2014 23:27:28;0040;PBS_Server;Svr;tyrone-cluster;Scheduler was sent the command new
02/18/2014 23:28:01;0040;PBS_Server;Svr;tyrone-cluster;Scheduler was sent the command new
02/18/2014 23:28:32;0040;PBS_Server;Svr;tyrone-cluster;Scheduler was sent the command new
02/18/2014 23:29:05;0040;PBS_Server;Svr;tyrone-cluster;Scheduler was sent the command new
02/18/2014 23:29:36;0040;PBS_Server;Svr;tyrone-cluster;Scheduler was sent the command new
02/18/2014 23:30:09;0040;PBS_Server;Svr;tyrone-cluster;Scheduler was sent the command new
02/18/2014 23:30:41;0040;PBS_Server;Svr;tyrone-cluster;Scheduler was sent the command new
02/18/2014 23:31:13;0040;PBS_Server;Svr;tyrone-cluster;Scheduler was sent the command new
02/18/2014 23:31:25;0002;PBS_Server;Svr;PBS_Server;Torque Server Version = 3.0.5, loglevel = 0
02/18/2014 23:31:46;0040;PBS_Server;Svr;tyrone-cluster;Scheduler was sent the command new
02/18/2014 23:32:17;0040;PBS_Server;Svr;tyrone-cluster;Scheduler was sent the command new
02/18/2014 23:32:50;0040;PBS_Server;Svr;tyrone-cluster;Scheduler was sent the command new
02/18/2014 23:33:21;0040;PBS_Server;Svr;tyrone-cluster;Scheduler was sent the command new
02/18/2014 23:33:54;0040;PBS_Server;Svr;tyrone-cluster;Scheduler was sent the command new
02/18/2014 23:34:26;0040;PBS_Server;Svr;tyrone-cluster;Scheduler was sent the command new
02/18/2014 23:34:58;0040;PBS_Server;Svr;tyrone-cluster;Scheduler was sent the command new
02/18/2014 23:35:31;0040;PBS_Server;Svr;tyrone-cluster;Scheduler was sent the command new
02/18/2014 23:36:02;0040;PBS_Server;Svr;tyrone-cluster;Scheduler was sent the command new
02/18/2014 23:36:25;0002;PBS_Server;Svr;PBS_Server;Torque Server Version = 3.0.5, loglevel = 0
02/18/2014 23:36:35;0040;PBS_Server;Svr;tyrone-cluster;Scheduler was sent the command new
02/18/2014 23:37:06;0040;PBS_Server;Svr;tyrone-cluster;Scheduler was sent the command new
02/18/2014 23:37:39;0040;PBS_Server;Svr;tyrone-cluster;Scheduler was sent the command new
02/18/2014 23:38:11;0040;PBS_Server;Svr;tyrone-cluster;Scheduler was sent the command new
02/18/2014 23:38:43;0040;PBS_Server;Svr;tyrone-cluster;Scheduler was sent the command new
02/18/2014 23:39:09;0040;PBS_Server;Svr;tyrone-cluster;Scheduler was sent the command new
02/18/2014 23:39:41;0040;PBS_Server;Svr;tyrone-cluster;Scheduler was sent the command new
02/18/2014 23:40:13;0040;PBS_Server;Svr;tyrone-cluster;Scheduler was sent the command new
02/18/2014 23:40:46;0040;PBS_Server;Svr;tyrone-cluster;Scheduler was sent the command new
02/18/2014 23:41:17;0040;PBS_Server;Svr;tyrone-cluster;Scheduler was sent the command new
02/18/2014 23:41:25;0002;PBS_Server;Svr;PBS_Server;Torque Server Version = 3.0.5, loglevel = 0
02/18/2014 23:41:48;0040;PBS_Server;Svr;tyrone-cluster;Scheduler was sent the command new
02/18/2014 23:42:21;0040;PBS_Server;Svr;tyrone-cluster;Scheduler was sent the command new
02/18/2014 23:42:47;0040;PBS_Server;Svr;tyrone-cluster;Scheduler was sent the command new
02/18/2014 23:43:20;0040;PBS_Server;Svr;tyrone-cluster;Scheduler was sent the command new
02/18/2014 23:43:51;0040;PBS_Server;Svr;tyrone-cluster;Scheduler was sent the command new
02/18/2014 23:44:24;0040;PBS_Server;Svr;tyrone-cluster;Scheduler was sent the command new
02/18/2014 23:44:56;0040;PBS_Server;Svr;tyrone-cluster;Scheduler was sent the command new
02/18/2014 23:45:28;0040;PBS_Server;Svr;tyrone-cluster;Scheduler was sent the command new
02/18/2014 23:45:55;0040;PBS_Server;Svr;tyrone-cluster;Scheduler was sent the command new
02/18/2014 23:46:25;0002;PBS_Server;Svr;PBS_Server;Torque Server Version = 3.0.5, loglevel = 0
02/18/2014 23:46:25;0040;PBS_Server;Svr;tyrone-cluster;Scheduler was sent the command new
02/18/2014 23:46:58;0040;PBS_Server;Svr;tyrone-cluster;Scheduler was sent the command new
02/18/2014 23:47:31;0040;PBS_Server;Svr;tyrone-cluster;Scheduler was sent the command new
02/18/2014 23:48:02;0040;PBS_Server;Svr;tyrone-cluster;Scheduler was sent the command new
02/18/2014 23:48:35;0040;PBS_Server;Svr;tyrone-cluster;Scheduler was sent the command new
02/18/2014 23:49:06;0040;PBS_Server;Svr;tyrone-cluster;Scheduler was sent the command new
02/18/2014 23:49:39;0040;PBS_Server;Svr;tyrone-cluster;Scheduler was sent the command new
02/18/2014 23:50:11;0040;PBS_Server;Svr;tyrone-cluster;Scheduler was sent the command new
02/18/2014 23:50:43;0040;PBS_Server;Svr;tyrone-cluster;Scheduler was sent the command new
02/18/2014 23:51:17;0040;PBS_Server;Svr;tyrone-cluster;Scheduler was sent the command new
02/18/2014 23:51:25;0002;PBS_Server;Svr;PBS_Server;Torque Server Version = 3.0.5, loglevel = 0
02/18/2014 23:51:47;0040;PBS_Server;Svr;tyrone-cluster;Scheduler was sent the command new
02/18/2014 23:52:20;0040;PBS_Server;Svr;tyrone-cluster;Scheduler was sent the command new
02/18/2014 23:52:51;0040;PBS_Server;Svr;tyrone-cluster;Scheduler was sent the command new
02/18/2014 23:53:24;0040;PBS_Server;Svr;tyrone-cluster;Scheduler was sent the command new
02/18/2014 23:53:55;0040;PBS_Server;Svr;tyrone-cluster;Scheduler was sent the command new
02/18/2014 23:54:28;0040;PBS_Server;Svr;tyrone-cluster;Scheduler was sent the command new
02/18/2014 23:55:02;0040;PBS_Server;Svr;tyrone-cluster;Scheduler was sent the command new
02/18/2014 23:55:32;0040;PBS_Server;Svr;tyrone-cluster;Scheduler was sent the command new
02/18/2014 23:56:05;0040;PBS_Server;Svr;tyrone-cluster;Scheduler was sent the command new
02/18/2014 23:56:25;0002;PBS_Server;Svr;PBS_Server;Torque Server Version = 3.0.5, loglevel = 0
02/18/2014 23:56:36;0040;PBS_Server;Svr;tyrone-cluster;Scheduler was sent the command new
02/18/2014 23:57:09;0040;PBS_Server;Svr;tyrone-cluster;Scheduler was sent the command new
02/18/2014 23:57:41;0040;PBS_Server;Svr;tyrone-cluster;Scheduler was sent the command new
02/18/2014 23:58:09;0040;PBS_Server;Svr;tyrone-cluster;Scheduler was sent the command new
02/18/2014 23:58:39;0040;PBS_Server;Svr;tyrone-cluster;Scheduler was sent the command new
02/18/2014 23:59:11;0040;PBS_Server;Svr;tyrone-cluster;Scheduler was sent the command new
02/18/2014 23:59:43;0040;PBS_Server;Svr;tyrone-cluster;Scheduler was sent the command new
02/19/2014 00:00:16;0002;PBS_Server;Svr;Log;Log closed
