06/03/2014 00:00:22;0002;PBS_Server;Svr;Log;Log opened
06/03/2014 00:00:22;000d;PBS_Server;Job;39211.tyrone-cluster;Not sending email: User does not want mail of this type.
06/03/2014 00:00:57;0002;PBS_Server;Svr;PBS_Server;Torque Server Version = 3.0.5, loglevel = 0
06/03/2014 00:05:57;0002;PBS_Server;Svr;PBS_Server;Torque Server Version = 3.0.5, loglevel = 0
06/03/2014 00:09:16;0040;PBS_Server;Svr;tyrone-cluster;Scheduler was sent the command time
06/03/2014 00:10:57;0002;PBS_Server;Svr;PBS_Server;Torque Server Version = 3.0.5, loglevel = 0
06/03/2014 00:15:57;0002;PBS_Server;Svr;PBS_Server;Torque Server Version = 3.0.5, loglevel = 0
06/03/2014 00:19:16;0040;PBS_Server;Svr;tyrone-cluster;Scheduler was sent the command time
06/03/2014 00:20:57;0002;PBS_Server;Svr;PBS_Server;Torque Server Version = 3.0.5, loglevel = 0
06/03/2014 00:25:57;0002;PBS_Server;Svr;PBS_Server;Torque Server Version = 3.0.5, loglevel = 0
06/03/2014 00:29:16;0040;PBS_Server;Svr;tyrone-cluster;Scheduler was sent the command time
06/03/2014 00:30:57;0002;PBS_Server;Svr;PBS_Server;Torque Server Version = 3.0.5, loglevel = 0
06/03/2014 00:35:57;0002;PBS_Server;Svr;PBS_Server;Torque Server Version = 3.0.5, loglevel = 0
06/03/2014 00:39:16;0040;PBS_Server;Svr;tyrone-cluster;Scheduler was sent the command time
06/03/2014 00:40:57;0002;PBS_Server;Svr;PBS_Server;Torque Server Version = 3.0.5, loglevel = 0
06/03/2014 00:45:57;0002;PBS_Server;Svr;PBS_Server;Torque Server Version = 3.0.5, loglevel = 0
06/03/2014 00:49:16;0040;PBS_Server;Svr;tyrone-cluster;Scheduler was sent the command time
06/03/2014 00:50:57;0002;PBS_Server;Svr;PBS_Server;Torque Server Version = 3.0.5, loglevel = 0
06/03/2014 00:55:57;0002;PBS_Server;Svr;PBS_Server;Torque Server Version = 3.0.5, loglevel = 0
06/03/2014 00:59:16;0040;PBS_Server;Svr;tyrone-cluster;Scheduler was sent the command time
06/03/2014 01:00:57;0002;PBS_Server;Svr;PBS_Server;Torque Server Version = 3.0.5, loglevel = 0
06/03/2014 01:05:57;0002;PBS_Server;Svr;PBS_Server;Torque Server Version = 3.0.5, loglevel = 0
06/03/2014 01:09:16;0040;PBS_Server;Svr;tyrone-cluster;Scheduler was sent the command time
06/03/2014 01:10:57;0002;PBS_Server;Svr;PBS_Server;Torque Server Version = 3.0.5, loglevel = 0
06/03/2014 01:15:57;0002;PBS_Server;Svr;PBS_Server;Torque Server Version = 3.0.5, loglevel = 0
06/03/2014 01:19:16;0040;PBS_Server;Svr;tyrone-cluster;Scheduler was sent the command time
06/03/2014 01:20:57;0002;PBS_Server;Svr;PBS_Server;Torque Server Version = 3.0.5, loglevel = 0
06/03/2014 01:25:57;0002;PBS_Server;Svr;PBS_Server;Torque Server Version = 3.0.5, loglevel = 0
06/03/2014 01:29:16;0040;PBS_Server;Svr;tyrone-cluster;Scheduler was sent the command time
06/03/2014 01:30:57;0002;PBS_Server;Svr;PBS_Server;Torque Server Version = 3.0.5, loglevel = 0
06/03/2014 01:35:57;0002;PBS_Server;Svr;PBS_Server;Torque Server Version = 3.0.5, loglevel = 0
06/03/2014 01:39:16;0040;PBS_Server;Svr;tyrone-cluster;Scheduler was sent the command time
06/03/2014 01:40:57;0002;PBS_Server;Svr;PBS_Server;Torque Server Version = 3.0.5, loglevel = 0
06/03/2014 01:45:57;0002;PBS_Server;Svr;PBS_Server;Torque Server Version = 3.0.5, loglevel = 0
06/03/2014 01:49:16;0040;PBS_Server;Svr;tyrone-cluster;Scheduler was sent the command time
06/03/2014 01:50:57;0002;PBS_Server;Svr;PBS_Server;Torque Server Version = 3.0.5, loglevel = 0
06/03/2014 01:55:57;0002;PBS_Server;Svr;PBS_Server;Torque Server Version = 3.0.5, loglevel = 0
06/03/2014 01:59:16;0040;PBS_Server;Svr;tyrone-cluster;Scheduler was sent the command time
06/03/2014 02:00:57;0002;PBS_Server;Svr;PBS_Server;Torque Server Version = 3.0.5, loglevel = 0
06/03/2014 02:05:57;0002;PBS_Server;Svr;PBS_Server;Torque Server Version = 3.0.5, loglevel = 0
06/03/2014 02:09:16;0040;PBS_Server;Svr;tyrone-cluster;Scheduler was sent the command time
06/03/2014 02:10:57;0002;PBS_Server;Svr;PBS_Server;Torque Server Version = 3.0.5, loglevel = 0
06/03/2014 02:15:57;0002;PBS_Server;Svr;PBS_Server;Torque Server Version = 3.0.5, loglevel = 0
06/03/2014 02:19:16;0040;PBS_Server;Svr;tyrone-cluster;Scheduler was sent the command time
06/03/2014 02:20:57;0002;PBS_Server;Svr;PBS_Server;Torque Server Version = 3.0.5, loglevel = 0
06/03/2014 02:25:57;0002;PBS_Server;Svr;PBS_Server;Torque Server Version = 3.0.5, loglevel = 0
06/03/2014 02:29:16;0040;PBS_Server;Svr;tyrone-cluster;Scheduler was sent the command time
06/03/2014 02:30:57;0002;PBS_Server;Svr;PBS_Server;Torque Server Version = 3.0.5, loglevel = 0
06/03/2014 02:31:53;000d;PBS_Server;Job;39264.tyrone-cluster;Not sending email: User does not want mail of this type.
06/03/2014 02:31:53;0002;PBS_Server;Svr;Act;Account file /var/spool/torque/server_priv/accounting/20140603 opened
06/03/2014 02:31:53;0010;PBS_Server;Job;39264.tyrone-cluster;Exit_status=143 resources_used.cput=758:49:07 resources_used.mem=18733032kb resources_used.vmem=21997100kb resources_used.walltime=24:00:21
06/03/2014 02:31:53;0008;PBS_Server;Job;NULL;on_job_exit valid pjob: 0x1789fc0 (substate=50)
06/03/2014 02:31:53;0008;PBS_Server;Job;NULL;on_job_exit valid pjob: 0x1789fc0 (substate=51)
06/03/2014 02:32:01;0008;PBS_Server;Job;NULL;on_job_exit valid pjob: 0x1789fc0 (substate=51)
06/03/2014 02:32:01;000d;PBS_Server;Job;39264.tyrone-cluster;Post job file processing error; job 39264.tyrone-cluster on host tyrone-node7/31+tyrone-node7/30+tyrone-node7/29+tyrone-node7/28+tyrone-node7/27+tyrone-node7/26+tyrone-node7/25+tyrone-node7/24+tyrone-node7/23+tyrone-node7/22+tyrone-node7/21+tyrone-node7/20+tyrone-node7/19+tyrone-node7/18+tyrone-node7/17+tyrone-node7/16+tyrone-node7/15+tyrone-node7/14+tyrone-node7/13+tyrone-node7/12+tyrone-node7/11+tyrone-node7/10+tyrone-node7/9+tyrone-node7/8+tyrone-node7/7+tyrone-node7/6+tyrone-node7/5+tyrone-node7/4+tyrone-node7/3+tyrone-node7/2+tyrone-node7/1+tyrone-node7/0
06/03/2014 02:32:01;0008;PBS_Server;Job;NULL;on_job_exit valid pjob: 0x1789fc0 (substate=53)
06/03/2014 02:32:01;0100;PBS_Server;Job;39264.tyrone-cluster;dequeuing from qp32, state COMPLETE
06/03/2014 02:32:01;0040;PBS_Server;Svr;tyrone-cluster;Scheduler was sent the command term
06/03/2014 02:32:01;0008;PBS_Server;Job;39301.tyrone-cluster;Job Modified at request of Scheduler@tyrone-cluster
06/03/2014 02:32:01;0008;PBS_Server;Job;39301.tyrone-cluster;Job Run at request of Scheduler@tyrone-cluster
06/03/2014 02:32:01;0040;PBS_Server;Svr;tyrone-cluster;Scheduler was sent the command recyc
06/03/2014 02:32:01;000d;PBS_Server;Job;39301.tyrone-cluster;Not sending email: User does not want mail of this type.
06/03/2014 02:35:57;0002;PBS_Server;Svr;PBS_Server;Torque Server Version = 3.0.5, loglevel = 0
06/03/2014 02:40:57;0002;PBS_Server;Svr;PBS_Server;Torque Server Version = 3.0.5, loglevel = 0
06/03/2014 02:42:01;0040;PBS_Server;Svr;tyrone-cluster;Scheduler was sent the command time
06/03/2014 02:45:57;0002;PBS_Server;Svr;PBS_Server;Torque Server Version = 3.0.5, loglevel = 0
06/03/2014 02:50:57;0002;PBS_Server;Svr;PBS_Server;Torque Server Version = 3.0.5, loglevel = 0
06/03/2014 02:52:01;0040;PBS_Server;Svr;tyrone-cluster;Scheduler was sent the command time
06/03/2014 02:55:57;0002;PBS_Server;Svr;PBS_Server;Torque Server Version = 3.0.5, loglevel = 0
06/03/2014 02:57:54;000d;PBS_Server;Job;39287.tyrone-cluster;Not sending email: User does not want mail of this type.
06/03/2014 02:57:54;0010;PBS_Server;Job;39287.tyrone-cluster;Exit_status=0 resources_used.cput=20:53:57 resources_used.mem=2721508kb resources_used.vmem=3081380kb resources_used.walltime=10:25:25
06/03/2014 02:57:54;0008;PBS_Server;Job;NULL;on_job_exit valid pjob: 0x17a61b0 (substate=50)
06/03/2014 02:57:54;0008;PBS_Server;Job;NULL;on_job_exit valid pjob: 0x17a61b0 (substate=51)
06/03/2014 02:58:02;0008;PBS_Server;Job;NULL;on_job_exit valid pjob: 0x17a61b0 (substate=51)
06/03/2014 02:58:02;000d;PBS_Server;Job;39287.tyrone-cluster;Post job file processing error; job 39287.tyrone-cluster on host tyrone-node2/31+tyrone-node2/30+tyrone-node2/29+tyrone-node2/28+tyrone-node2/27+tyrone-node2/26+tyrone-node2/25+tyrone-node2/24+tyrone-node2/23+tyrone-node2/22+tyrone-node2/21+tyrone-node2/20+tyrone-node2/19+tyrone-node2/18+tyrone-node2/17+tyrone-node2/16+tyrone-node2/15+tyrone-node2/14+tyrone-node2/13+tyrone-node2/12+tyrone-node2/11+tyrone-node2/10+tyrone-node2/9+tyrone-node2/8+tyrone-node2/7+tyrone-node2/6+tyrone-node2/5+tyrone-node2/4+tyrone-node2/3+tyrone-node2/2+tyrone-node2/1+tyrone-node2/0
06/03/2014 02:58:02;0008;PBS_Server;Job;NULL;on_job_exit valid pjob: 0x17a61b0 (substate=53)
06/03/2014 02:58:02;0100;PBS_Server;Job;39287.tyrone-cluster;dequeuing from qp32, state COMPLETE
06/03/2014 02:58:02;0040;PBS_Server;Svr;tyrone-cluster;Scheduler was sent the command term
06/03/2014 03:00:57;0002;PBS_Server;Svr;PBS_Server;Torque Server Version = 3.0.5, loglevel = 0
06/03/2014 03:05:57;0002;PBS_Server;Svr;PBS_Server;Torque Server Version = 3.0.5, loglevel = 0
06/03/2014 03:08:02;0040;PBS_Server;Svr;tyrone-cluster;Scheduler was sent the command time
06/03/2014 03:10:57;0002;PBS_Server;Svr;PBS_Server;Torque Server Version = 3.0.5, loglevel = 0
06/03/2014 03:15:57;0002;PBS_Server;Svr;PBS_Server;Torque Server Version = 3.0.5, loglevel = 0
06/03/2014 03:18:02;0040;PBS_Server;Svr;tyrone-cluster;Scheduler was sent the command time
06/03/2014 03:20:57;0002;PBS_Server;Svr;PBS_Server;Torque Server Version = 3.0.5, loglevel = 0
06/03/2014 03:25:57;0002;PBS_Server;Svr;PBS_Server;Torque Server Version = 3.0.5, loglevel = 0
06/03/2014 03:28:02;0040;PBS_Server;Svr;tyrone-cluster;Scheduler was sent the command time
06/03/2014 03:30:57;0002;PBS_Server;Svr;PBS_Server;Torque Server Version = 3.0.5, loglevel = 0
06/03/2014 03:35:57;0002;PBS_Server;Svr;PBS_Server;Torque Server Version = 3.0.5, loglevel = 0
06/03/2014 03:38:02;0040;PBS_Server;Svr;tyrone-cluster;Scheduler was sent the command time
06/03/2014 03:40:57;0002;PBS_Server;Svr;PBS_Server;Torque Server Version = 3.0.5, loglevel = 0
06/03/2014 03:45:57;0002;PBS_Server;Svr;PBS_Server;Torque Server Version = 3.0.5, loglevel = 0
06/03/2014 03:48:02;0040;PBS_Server;Svr;tyrone-cluster;Scheduler was sent the command time
06/03/2014 03:50:57;0002;PBS_Server;Svr;PBS_Server;Torque Server Version = 3.0.5, loglevel = 0
06/03/2014 03:55:57;0002;PBS_Server;Svr;PBS_Server;Torque Server Version = 3.0.5, loglevel = 0
06/03/2014 03:58:02;0040;PBS_Server;Svr;tyrone-cluster;Scheduler was sent the command time
06/03/2014 04:00:57;0002;PBS_Server;Svr;PBS_Server;Torque Server Version = 3.0.5, loglevel = 0
06/03/2014 04:05:57;0002;PBS_Server;Svr;PBS_Server;Torque Server Version = 3.0.5, loglevel = 0
06/03/2014 04:08:02;0040;PBS_Server;Svr;tyrone-cluster;Scheduler was sent the command time
06/03/2014 04:10:57;0002;PBS_Server;Svr;PBS_Server;Torque Server Version = 3.0.5, loglevel = 0
06/03/2014 04:15:57;0002;PBS_Server;Svr;PBS_Server;Torque Server Version = 3.0.5, loglevel = 0
06/03/2014 04:18:02;0040;PBS_Server;Svr;tyrone-cluster;Scheduler was sent the command time
06/03/2014 04:20:57;0002;PBS_Server;Svr;PBS_Server;Torque Server Version = 3.0.5, loglevel = 0
06/03/2014 04:25:57;0002;PBS_Server;Svr;PBS_Server;Torque Server Version = 3.0.5, loglevel = 0
06/03/2014 04:28:02;0040;PBS_Server;Svr;tyrone-cluster;Scheduler was sent the command time
06/03/2014 04:30:57;0002;PBS_Server;Svr;PBS_Server;Torque Server Version = 3.0.5, loglevel = 0
06/03/2014 04:35:57;0002;PBS_Server;Svr;PBS_Server;Torque Server Version = 3.0.5, loglevel = 0
06/03/2014 04:38:02;0040;PBS_Server;Svr;tyrone-cluster;Scheduler was sent the command time
06/03/2014 04:40:57;0002;PBS_Server;Svr;PBS_Server;Torque Server Version = 3.0.5, loglevel = 0
06/03/2014 04:45:57;0002;PBS_Server;Svr;PBS_Server;Torque Server Version = 3.0.5, loglevel = 0
06/03/2014 04:48:02;0040;PBS_Server;Svr;tyrone-cluster;Scheduler was sent the command time
06/03/2014 04:50:57;0002;PBS_Server;Svr;PBS_Server;Torque Server Version = 3.0.5, loglevel = 0
06/03/2014 04:55:57;0002;PBS_Server;Svr;PBS_Server;Torque Server Version = 3.0.5, loglevel = 0
06/03/2014 04:58:02;0040;PBS_Server;Svr;tyrone-cluster;Scheduler was sent the command time
06/03/2014 05:00:57;0002;PBS_Server;Svr;PBS_Server;Torque Server Version = 3.0.5, loglevel = 0
06/03/2014 05:05:57;0002;PBS_Server;Svr;PBS_Server;Torque Server Version = 3.0.5, loglevel = 0
06/03/2014 05:08:02;0040;PBS_Server;Svr;tyrone-cluster;Scheduler was sent the command time
06/03/2014 05:10:57;0002;PBS_Server;Svr;PBS_Server;Torque Server Version = 3.0.5, loglevel = 0
06/03/2014 05:15:57;0002;PBS_Server;Svr;PBS_Server;Torque Server Version = 3.0.5, loglevel = 0
06/03/2014 05:18:02;0040;PBS_Server;Svr;tyrone-cluster;Scheduler was sent the command time
06/03/2014 05:20:57;0002;PBS_Server;Svr;PBS_Server;Torque Server Version = 3.0.5, loglevel = 0
06/03/2014 05:25:57;0002;PBS_Server;Svr;PBS_Server;Torque Server Version = 3.0.5, loglevel = 0
06/03/2014 05:28:02;0040;PBS_Server;Svr;tyrone-cluster;Scheduler was sent the command time
06/03/2014 05:30:57;0002;PBS_Server;Svr;PBS_Server;Torque Server Version = 3.0.5, loglevel = 0
06/03/2014 05:35:57;0002;PBS_Server;Svr;PBS_Server;Torque Server Version = 3.0.5, loglevel = 0
06/03/2014 05:38:02;0040;PBS_Server;Svr;tyrone-cluster;Scheduler was sent the command time
06/03/2014 05:40:57;0002;PBS_Server;Svr;PBS_Server;Torque Server Version = 3.0.5, loglevel = 0
06/03/2014 05:45:57;0002;PBS_Server;Svr;PBS_Server;Torque Server Version = 3.0.5, loglevel = 0
06/03/2014 05:48:02;0040;PBS_Server;Svr;tyrone-cluster;Scheduler was sent the command time
06/03/2014 05:50:57;0002;PBS_Server;Svr;PBS_Server;Torque Server Version = 3.0.5, loglevel = 0
06/03/2014 05:55:57;0002;PBS_Server;Svr;PBS_Server;Torque Server Version = 3.0.5, loglevel = 0
06/03/2014 05:58:02;0040;PBS_Server;Svr;tyrone-cluster;Scheduler was sent the command time
06/03/2014 06:00:57;0002;PBS_Server;Svr;PBS_Server;Torque Server Version = 3.0.5, loglevel = 0
06/03/2014 06:05:57;0002;PBS_Server;Svr;PBS_Server;Torque Server Version = 3.0.5, loglevel = 0
06/03/2014 06:08:02;0040;PBS_Server;Svr;tyrone-cluster;Scheduler was sent the command time
06/03/2014 06:10:57;0002;PBS_Server;Svr;PBS_Server;Torque Server Version = 3.0.5, loglevel = 0
06/03/2014 06:15:57;0002;PBS_Server;Svr;PBS_Server;Torque Server Version = 3.0.5, loglevel = 0
06/03/2014 06:18:02;0040;PBS_Server;Svr;tyrone-cluster;Scheduler was sent the command time
06/03/2014 06:20:57;0002;PBS_Server;Svr;PBS_Server;Torque Server Version = 3.0.5, loglevel = 0
06/03/2014 06:25:57;0002;PBS_Server;Svr;PBS_Server;Torque Server Version = 3.0.5, loglevel = 0
06/03/2014 06:28:02;0040;PBS_Server;Svr;tyrone-cluster;Scheduler was sent the command time
06/03/2014 06:30:57;0002;PBS_Server;Svr;PBS_Server;Torque Server Version = 3.0.5, loglevel = 0
06/03/2014 06:35:57;0002;PBS_Server;Svr;PBS_Server;Torque Server Version = 3.0.5, loglevel = 0
06/03/2014 06:38:02;0040;PBS_Server;Svr;tyrone-cluster;Scheduler was sent the command time
06/03/2014 06:40:57;0002;PBS_Server;Svr;PBS_Server;Torque Server Version = 3.0.5, loglevel = 0
06/03/2014 06:45:57;0002;PBS_Server;Svr;PBS_Server;Torque Server Version = 3.0.5, loglevel = 0
06/03/2014 06:48:02;0040;PBS_Server;Svr;tyrone-cluster;Scheduler was sent the command time
06/03/2014 06:50:57;0002;PBS_Server;Svr;PBS_Server;Torque Server Version = 3.0.5, loglevel = 0
06/03/2014 06:55:57;0002;PBS_Server;Svr;PBS_Server;Torque Server Version = 3.0.5, loglevel = 0
06/03/2014 06:58:02;0040;PBS_Server;Svr;tyrone-cluster;Scheduler was sent the command time
06/03/2014 07:00:57;0002;PBS_Server;Svr;PBS_Server;Torque Server Version = 3.0.5, loglevel = 0
06/03/2014 07:05:57;0002;PBS_Server;Svr;PBS_Server;Torque Server Version = 3.0.5, loglevel = 0
06/03/2014 07:08:02;0040;PBS_Server;Svr;tyrone-cluster;Scheduler was sent the command time
06/03/2014 07:10:57;0002;PBS_Server;Svr;PBS_Server;Torque Server Version = 3.0.5, loglevel = 0
06/03/2014 07:15:57;0002;PBS_Server;Svr;PBS_Server;Torque Server Version = 3.0.5, loglevel = 0
06/03/2014 07:18:02;0040;PBS_Server;Svr;tyrone-cluster;Scheduler was sent the command time
06/03/2014 07:20:57;0002;PBS_Server;Svr;PBS_Server;Torque Server Version = 3.0.5, loglevel = 0
06/03/2014 07:24:07;000d;PBS_Server;Job;39301.tyrone-cluster;Not sending email: User does not want mail of this type.
06/03/2014 07:24:07;0010;PBS_Server;Job;39301.tyrone-cluster;Exit_status=1 resources_used.cput=38:37:19 resources_used.mem=3246420kb resources_used.vmem=14992120kb resources_used.walltime=04:52:06
06/03/2014 07:24:07;0008;PBS_Server;Job;NULL;on_job_exit valid pjob: 0x1782bb0 (substate=50)
06/03/2014 07:24:07;0008;PBS_Server;Job;NULL;on_job_exit valid pjob: 0x1782bb0 (substate=51)
06/03/2014 07:24:15;0008;PBS_Server;Job;NULL;on_job_exit valid pjob: 0x1782bb0 (substate=51)
06/03/2014 07:24:15;000d;PBS_Server;Job;39301.tyrone-cluster;Post job file processing error; job 39301.tyrone-cluster on host tyrone-node7/31+tyrone-node7/30+tyrone-node7/29+tyrone-node7/28+tyrone-node7/27+tyrone-node7/26+tyrone-node7/25+tyrone-node7/24+tyrone-node7/23+tyrone-node7/22+tyrone-node7/21+tyrone-node7/20+tyrone-node7/19+tyrone-node7/18+tyrone-node7/17+tyrone-node7/16+tyrone-node7/15+tyrone-node7/14+tyrone-node7/13+tyrone-node7/12+tyrone-node7/11+tyrone-node7/10+tyrone-node7/9+tyrone-node7/8+tyrone-node7/7+tyrone-node7/6+tyrone-node7/5+tyrone-node7/4+tyrone-node7/3+tyrone-node7/2+tyrone-node7/1+tyrone-node7/0
06/03/2014 07:24:15;0008;PBS_Server;Job;NULL;on_job_exit valid pjob: 0x1782bb0 (substate=53)
06/03/2014 07:24:15;0100;PBS_Server;Job;39301.tyrone-cluster;dequeuing from qp32, state COMPLETE
06/03/2014 07:24:15;0040;PBS_Server;Svr;tyrone-cluster;Scheduler was sent the command term
06/03/2014 07:25:57;0002;PBS_Server;Svr;PBS_Server;Torque Server Version = 3.0.5, loglevel = 0
06/03/2014 07:28:52;000d;PBS_Server;Job;39272.tyrone-cluster;Not sending email: User does not want mail of this type.
06/03/2014 07:28:52;0010;PBS_Server;Job;39272.tyrone-cluster;Exit_status=0 resources_used.cput=480:51:13 resources_used.mem=74167448kb resources_used.vmem=111022480kb resources_used.walltime=07:31:25
06/03/2014 07:28:52;0008;PBS_Server;Job;NULL;on_job_exit valid pjob: 0x1713730 (substate=50)
06/03/2014 07:28:52;0008;PBS_Server;Job;NULL;on_job_exit valid pjob: 0x1713730 (substate=51)
06/03/2014 07:28:57;0008;PBS_Server;Job;NULL;on_job_exit valid pjob: 0x1713730 (substate=51)
06/03/2014 07:28:57;0008;PBS_Server;Job;NULL;on_job_exit valid pjob: 0x1713730 (substate=53)
06/03/2014 07:28:57;0100;PBS_Server;Job;39272.tyrone-cluster;dequeuing from qp256, state COMPLETE
06/03/2014 07:28:57;0040;PBS_Server;Svr;tyrone-cluster;Scheduler was sent the command term
06/03/2014 07:28:57;0008;PBS_Server;Job;39292.tyrone-cluster;Job Modified at request of Scheduler@tyrone-cluster
06/03/2014 07:30:57;0002;PBS_Server;Svr;PBS_Server;Torque Server Version = 3.0.5, loglevel = 0
06/03/2014 07:35:57;0002;PBS_Server;Svr;PBS_Server;Torque Server Version = 3.0.5, loglevel = 0
06/03/2014 07:38:57;0040;PBS_Server;Svr;tyrone-cluster;Scheduler was sent the command time
06/03/2014 07:40:57;0002;PBS_Server;Svr;PBS_Server;Torque Server Version = 3.0.5, loglevel = 0
06/03/2014 07:45:57;0002;PBS_Server;Svr;PBS_Server;Torque Server Version = 3.0.5, loglevel = 0
06/03/2014 07:48:57;0040;PBS_Server;Svr;tyrone-cluster;Scheduler was sent the command time
06/03/2014 07:50:57;0002;PBS_Server;Svr;PBS_Server;Torque Server Version = 3.0.5, loglevel = 0
06/03/2014 07:55:57;0002;PBS_Server;Svr;PBS_Server;Torque Server Version = 3.0.5, loglevel = 0
06/03/2014 07:58:57;0040;PBS_Server;Svr;tyrone-cluster;Scheduler was sent the command time
06/03/2014 08:00:57;0002;PBS_Server;Svr;PBS_Server;Torque Server Version = 3.0.5, loglevel = 0
06/03/2014 08:05:57;0002;PBS_Server;Svr;PBS_Server;Torque Server Version = 3.0.5, loglevel = 0
06/03/2014 08:08:57;0040;PBS_Server;Svr;tyrone-cluster;Scheduler was sent the command time
06/03/2014 08:10:57;0002;PBS_Server;Svr;PBS_Server;Torque Server Version = 3.0.5, loglevel = 0
06/03/2014 08:15:57;0002;PBS_Server;Svr;PBS_Server;Torque Server Version = 3.0.5, loglevel = 0
06/03/2014 08:18:57;0040;PBS_Server;Svr;tyrone-cluster;Scheduler was sent the command time
06/03/2014 08:20:57;0002;PBS_Server;Svr;PBS_Server;Torque Server Version = 3.0.5, loglevel = 0
06/03/2014 08:25:57;0002;PBS_Server;Svr;PBS_Server;Torque Server Version = 3.0.5, loglevel = 0
06/03/2014 08:28:57;0040;PBS_Server;Svr;tyrone-cluster;Scheduler was sent the command time
06/03/2014 08:30:57;0002;PBS_Server;Svr;PBS_Server;Torque Server Version = 3.0.5, loglevel = 0
06/03/2014 08:35:57;0002;PBS_Server;Svr;PBS_Server;Torque Server Version = 3.0.5, loglevel = 0
06/03/2014 08:38:57;0040;PBS_Server;Svr;tyrone-cluster;Scheduler was sent the command time
06/03/2014 08:40:57;0002;PBS_Server;Svr;PBS_Server;Torque Server Version = 3.0.5, loglevel = 0
06/03/2014 08:45:57;0002;PBS_Server;Svr;PBS_Server;Torque Server Version = 3.0.5, loglevel = 0
06/03/2014 08:48:57;0040;PBS_Server;Svr;tyrone-cluster;Scheduler was sent the command time
06/03/2014 08:50:57;0002;PBS_Server;Svr;PBS_Server;Torque Server Version = 3.0.5, loglevel = 0
06/03/2014 08:55:57;0002;PBS_Server;Svr;PBS_Server;Torque Server Version = 3.0.5, loglevel = 0
06/03/2014 08:58:57;0040;PBS_Server;Svr;tyrone-cluster;Scheduler was sent the command time
06/03/2014 09:00:57;0002;PBS_Server;Svr;PBS_Server;Torque Server Version = 3.0.5, loglevel = 0
06/03/2014 09:05:57;0002;PBS_Server;Svr;PBS_Server;Torque Server Version = 3.0.5, loglevel = 0
06/03/2014 09:08:57;0040;PBS_Server;Svr;tyrone-cluster;Scheduler was sent the command time
06/03/2014 09:10:57;0002;PBS_Server;Svr;PBS_Server;Torque Server Version = 3.0.5, loglevel = 0
06/03/2014 09:15:57;0002;PBS_Server;Svr;PBS_Server;Torque Server Version = 3.0.5, loglevel = 0
06/03/2014 09:18:57;0040;PBS_Server;Svr;tyrone-cluster;Scheduler was sent the command time
06/03/2014 09:20:57;0002;PBS_Server;Svr;PBS_Server;Torque Server Version = 3.0.5, loglevel = 0
06/03/2014 09:25:57;0002;PBS_Server;Svr;PBS_Server;Torque Server Version = 3.0.5, loglevel = 0
06/03/2014 09:27:44;0100;PBS_Server;Job;39305.tyrone-cluster;enqueuing into batch, state 1 hop 1
06/03/2014 09:27:44;0100;PBS_Server;Job;39305.tyrone-cluster;dequeuing from batch, state QUEUED
06/03/2014 09:27:44;0100;PBS_Server;Job;39305.tyrone-cluster;enqueuing into qp32, state 1 hop 1
06/03/2014 09:27:44;0008;PBS_Server;Job;39305.tyrone-cluster;Job Queued at request of secpsm@tyrone-cluster, owner = secpsm@tyrone-cluster, job name = job32, queue = qp32
06/03/2014 09:27:44;0040;PBS_Server;Svr;tyrone-cluster;Scheduler was sent the command new
06/03/2014 09:27:44;0008;PBS_Server;Job;39305.tyrone-cluster;Job Modified at request of Scheduler@tyrone-cluster
06/03/2014 09:27:44;0008;PBS_Server;Job;39305.tyrone-cluster;Job Run at request of Scheduler@tyrone-cluster
06/03/2014 09:27:44;0040;PBS_Server;Svr;tyrone-cluster;Scheduler was sent the command recyc
06/03/2014 09:27:44;000d;PBS_Server;Job;39305.tyrone-cluster;Not sending email: User does not want mail of this type.
06/03/2014 09:30:57;0002;PBS_Server;Svr;PBS_Server;Torque Server Version = 3.0.5, loglevel = 0
06/03/2014 09:35:57;0002;PBS_Server;Svr;PBS_Server;Torque Server Version = 3.0.5, loglevel = 0
06/03/2014 09:37:44;0040;PBS_Server;Svr;tyrone-cluster;Scheduler was sent the command time
06/03/2014 09:40:57;0002;PBS_Server;Svr;PBS_Server;Torque Server Version = 3.0.5, loglevel = 0
06/03/2014 09:45:57;0002;PBS_Server;Svr;PBS_Server;Torque Server Version = 3.0.5, loglevel = 0
06/03/2014 09:47:44;0040;PBS_Server;Svr;tyrone-cluster;Scheduler was sent the command time
06/03/2014 09:50:57;0002;PBS_Server;Svr;PBS_Server;Torque Server Version = 3.0.5, loglevel = 0
06/03/2014 09:55:57;0002;PBS_Server;Svr;PBS_Server;Torque Server Version = 3.0.5, loglevel = 0
06/03/2014 09:56:42;0100;PBS_Server;Job;39306.tyrone-cluster;enqueuing into batch, state 1 hop 1
06/03/2014 09:56:42;0100;PBS_Server;Job;39306.tyrone-cluster;dequeuing from batch, state QUEUED
06/03/2014 09:56:42;0100;PBS_Server;Job;39306.tyrone-cluster;enqueuing into qp64, state 1 hop 1
06/03/2014 09:56:42;0008;PBS_Server;Job;39306.tyrone-cluster;Job Queued at request of aseabwit@tyrone-cluster, owner = aseabwit@tyrone-cluster, job name = TBLDNS, queue = qp64
06/03/2014 09:56:42;0040;PBS_Server;Svr;tyrone-cluster;Scheduler was sent the command new
06/03/2014 09:56:42;0008;PBS_Server;Job;39306.tyrone-cluster;Job Modified at request of Scheduler@tyrone-cluster
06/03/2014 10:00:57;0002;PBS_Server;Svr;PBS_Server;Torque Server Version = 3.0.5, loglevel = 0
06/03/2014 10:05:57;0002;PBS_Server;Svr;PBS_Server;Torque Server Version = 3.0.5, loglevel = 0
06/03/2014 10:06:42;0040;PBS_Server;Svr;tyrone-cluster;Scheduler was sent the command time
06/03/2014 10:10:57;0002;PBS_Server;Svr;PBS_Server;Torque Server Version = 3.0.5, loglevel = 0
06/03/2014 10:15:57;0002;PBS_Server;Svr;PBS_Server;Torque Server Version = 3.0.5, loglevel = 0
06/03/2014 10:16:42;0040;PBS_Server;Svr;tyrone-cluster;Scheduler was sent the command time
06/03/2014 10:20:57;0002;PBS_Server;Svr;PBS_Server;Torque Server Version = 3.0.5, loglevel = 0
06/03/2014 10:25:57;0002;PBS_Server;Svr;PBS_Server;Torque Server Version = 3.0.5, loglevel = 0
06/03/2014 10:26:42;0040;PBS_Server;Svr;tyrone-cluster;Scheduler was sent the command time
06/03/2014 10:30:57;0002;PBS_Server;Svr;PBS_Server;Torque Server Version = 3.0.5, loglevel = 0
06/03/2014 10:35:57;0002;PBS_Server;Svr;PBS_Server;Torque Server Version = 3.0.5, loglevel = 0
06/03/2014 10:36:42;0040;PBS_Server;Svr;tyrone-cluster;Scheduler was sent the command time
06/03/2014 10:40:57;0002;PBS_Server;Svr;PBS_Server;Torque Server Version = 3.0.5, loglevel = 0
06/03/2014 10:43:13;0100;PBS_Server;Job;39307.tyrone-cluster;enqueuing into batch, state 1 hop 1
06/03/2014 10:43:13;0100;PBS_Server;Job;39307.tyrone-cluster;dequeuing from batch, state QUEUED
06/03/2014 10:43:13;0100;PBS_Server;Job;39307.tyrone-cluster;enqueuing into qp256, state 1 hop 1
06/03/2014 10:43:13;0008;PBS_Server;Job;39307.tyrone-cluster;Job Queued at request of secbadar@tyrone-cluster, owner = secbadar@tyrone-cluster, job name = job1286USGS, queue = qp256
06/03/2014 10:43:13;0040;PBS_Server;Svr;tyrone-cluster;Scheduler was sent the command new
06/03/2014 10:43:14;0008;PBS_Server;Job;39307.tyrone-cluster;Job Modified at request of Scheduler@tyrone-cluster
06/03/2014 10:43:14;0008;PBS_Server;Job;39307.tyrone-cluster;Job Run at request of Scheduler@tyrone-cluster
06/03/2014 10:43:14;0040;PBS_Server;Svr;tyrone-cluster;Scheduler was sent the command recyc
06/03/2014 10:43:22;000d;PBS_Server;Job;39307.tyrone-cluster;Not sending email: User does not want mail of this type.
06/03/2014 10:43:40;0100;PBS_Server;Job;39308.tyrone-cluster;enqueuing into batch, state 1 hop 1
06/03/2014 10:43:40;0100;PBS_Server;Job;39308.tyrone-cluster;dequeuing from batch, state QUEUED
06/03/2014 10:43:40;0100;PBS_Server;Job;39308.tyrone-cluster;enqueuing into qp256, state 1 hop 1
06/03/2014 10:43:40;0008;PBS_Server;Job;39308.tyrone-cluster;Job Queued at request of secbadar@tyrone-cluster, owner = secbadar@tyrone-cluster, job name = jobpMpi6USGS, queue = qp256
06/03/2014 10:43:40;0040;PBS_Server;Svr;tyrone-cluster;Scheduler was sent the command new
06/03/2014 10:43:40;0008;PBS_Server;Job;39292.tyrone-cluster;Job Modified at request of Scheduler@tyrone-cluster
06/03/2014 10:43:40;0008;PBS_Server;Job;39308.tyrone-cluster;Job Modified at request of Scheduler@tyrone-cluster
06/03/2014 10:43:56;000d;PBS_Server;Job;39241.tyrone-cluster;Not sending email: User does not want mail of this type.
06/03/2014 10:43:56;0010;PBS_Server;Job;39241.tyrone-cluster;Exit_status=271 resources_used.cput=1535:24:42 resources_used.mem=2602032kb resources_used.vmem=36275028kb resources_used.walltime=24:00:41
06/03/2014 10:43:56;0008;PBS_Server;Job;NULL;on_job_exit valid pjob: 0x1724940 (substate=50)
06/03/2014 10:43:56;0008;PBS_Server;Job;NULL;on_job_exit valid pjob: 0x1724940 (substate=51)
06/03/2014 10:43:57;0008;PBS_Server;Job;NULL;on_job_exit valid pjob: 0x1724940 (substate=51)
06/03/2014 10:43:57;0008;PBS_Server;Job;NULL;on_job_exit valid pjob: 0x1724940 (substate=53)
06/03/2014 10:43:57;0100;PBS_Server;Job;39241.tyrone-cluster;dequeuing from qp256, state COMPLETE
06/03/2014 10:43:57;0040;PBS_Server;Svr;tyrone-cluster;Scheduler was sent the command term
06/03/2014 10:43:57;0008;PBS_Server;Job;39292.tyrone-cluster;Job Modified at request of Scheduler@tyrone-cluster
06/03/2014 10:43:57;0008;PBS_Server;Job;39292.tyrone-cluster;Job Run at request of Scheduler@tyrone-cluster
06/03/2014 10:43:57;0040;PBS_Server;Svr;tyrone-cluster;Scheduler was sent the command recyc
06/03/2014 10:44:24;000d;PBS_Server;Job;39292.tyrone-cluster;Not sending email: User does not want mail of this type.
06/03/2014 10:45:57;0002;PBS_Server;Svr;PBS_Server;Torque Server Version = 3.0.5, loglevel = 0
06/03/2014 10:50:28;0008;PBS_Server;Job;39307.tyrone-cluster;Job deleted at request of secbadar@tyrone-cluster
06/03/2014 10:50:28;0008;PBS_Server;Job;39307.tyrone-cluster;Job sent signal SIGTERM on delete
06/03/2014 10:50:29;000d;PBS_Server;Job;39307.tyrone-cluster;Not sending email: User does not want mail of this type.
06/03/2014 10:50:29;0010;PBS_Server;Job;39307.tyrone-cluster;Exit_status=143 resources_used.cput=00:20:50 resources_used.mem=40824996kb resources_used.vmem=54329012kb resources_used.walltime=00:07:15
06/03/2014 10:50:29;0008;PBS_Server;Job;NULL;on_job_exit valid pjob: 0x17a61b0 (substate=50)
06/03/2014 10:50:29;0008;PBS_Server;Job;NULL;on_job_exit valid pjob: 0x17a61b0 (substate=51)
06/03/2014 10:50:29;0008;PBS_Server;Job;NULL;on_job_exit valid pjob: 0x17a61b0 (substate=51)
06/03/2014 10:50:29;0008;PBS_Server;Job;NULL;on_job_exit valid pjob: 0x17a61b0 (substate=53)
06/03/2014 10:50:29;0100;PBS_Server;Job;39307.tyrone-cluster;dequeuing from qp256, state COMPLETE
06/03/2014 10:50:29;0040;PBS_Server;Svr;tyrone-cluster;Scheduler was sent the command term
06/03/2014 10:50:29;0008;PBS_Server;Job;39308.tyrone-cluster;Job Modified at request of Scheduler@tyrone-cluster
06/03/2014 10:50:29;0008;PBS_Server;Job;39308.tyrone-cluster;Job Run at request of Scheduler@tyrone-cluster
06/03/2014 10:50:29;0040;PBS_Server;Svr;tyrone-cluster;Scheduler was sent the command recyc
06/03/2014 10:50:54;000d;PBS_Server;Job;39308.tyrone-cluster;Not sending email: User does not want mail of this type.
06/03/2014 10:50:57;0002;PBS_Server;Svr;PBS_Server;Torque Server Version = 3.0.5, loglevel = 0
06/03/2014 10:54:15;0100;PBS_Server;Job;39309.tyrone-cluster;enqueuing into batch, state 1 hop 1
06/03/2014 10:54:15;0100;PBS_Server;Job;39309.tyrone-cluster;dequeuing from batch, state QUEUED
06/03/2014 10:54:15;0100;PBS_Server;Job;39309.tyrone-cluster;enqueuing into qp256, state 1 hop 1
06/03/2014 10:54:15;0008;PBS_Server;Job;39309.tyrone-cluster;Job Queued at request of secbadar@tyrone-cluster, owner = secbadar@tyrone-cluster, job name = job1286USGS, queue = qp256
06/03/2014 10:54:15;0040;PBS_Server;Svr;tyrone-cluster;Scheduler was sent the command new
06/03/2014 10:54:15;0008;PBS_Server;Job;39309.tyrone-cluster;Job Modified at request of Scheduler@tyrone-cluster
06/03/2014 10:54:26;0008;PBS_Server;Job;39309.tyrone-cluster;Job deleted at request of secbadar@tyrone-cluster
06/03/2014 10:54:26;0008;PBS_Server;Job;NULL;on_job_exit valid pjob: 0x17a61b0 (substate=59)
06/03/2014 10:54:26;0100;PBS_Server;Job;39309.tyrone-cluster;dequeuing from qp256, state COMPLETE
06/03/2014 10:54:26;0040;PBS_Server;Svr;tyrone-cluster;Scheduler was sent the command term
06/03/2014 10:54:30;0100;PBS_Server;Job;39310.tyrone-cluster;enqueuing into batch, state 1 hop 1
06/03/2014 10:54:30;0100;PBS_Server;Job;39310.tyrone-cluster;dequeuing from batch, state QUEUED
06/03/2014 10:54:30;0100;PBS_Server;Job;39310.tyrone-cluster;enqueuing into qp256, state 1 hop 1
06/03/2014 10:54:30;0008;PBS_Server;Job;39310.tyrone-cluster;Job Queued at request of secbadar@tyrone-cluster, owner = secbadar@tyrone-cluster, job name = job1286USGS, queue = qp256
06/03/2014 10:54:30;0040;PBS_Server;Svr;tyrone-cluster;Scheduler was sent the command new
06/03/2014 10:54:30;0008;PBS_Server;Job;39310.tyrone-cluster;Job Modified at request of Scheduler@tyrone-cluster
06/03/2014 10:54:35;0008;PBS_Server;Job;39310.tyrone-cluster;Job deleted at request of secbadar@tyrone-cluster
06/03/2014 10:54:35;0008;PBS_Server;Job;NULL;on_job_exit valid pjob: 0x17a61b0 (substate=59)
06/03/2014 10:54:35;0100;PBS_Server;Job;39310.tyrone-cluster;dequeuing from qp256, state COMPLETE
06/03/2014 10:54:35;0040;PBS_Server;Svr;tyrone-cluster;Scheduler was sent the command term
06/03/2014 10:55:08;0100;PBS_Server;Job;39311.tyrone-cluster;enqueuing into batch, state 1 hop 1
06/03/2014 10:55:08;0100;PBS_Server;Job;39311.tyrone-cluster;dequeuing from batch, state QUEUED
06/03/2014 10:55:08;0100;PBS_Server;Job;39311.tyrone-cluster;enqueuing into qp256, state 1 hop 1
06/03/2014 10:55:08;0008;PBS_Server;Job;39311.tyrone-cluster;Job Queued at request of secbadar@tyrone-cluster, owner = secbadar@tyrone-cluster, job name = job1286USGS, queue = qp256
06/03/2014 10:55:08;0040;PBS_Server;Svr;tyrone-cluster;Scheduler was sent the command new
06/03/2014 10:55:08;0008;PBS_Server;Job;39311.tyrone-cluster;Job Modified at request of Scheduler@tyrone-cluster
06/03/2014 10:55:15;0008;PBS_Server;Job;39308.tyrone-cluster;Job deleted at request of secbadar@tyrone-cluster
06/03/2014 10:55:15;0008;PBS_Server;Job;39308.tyrone-cluster;Job sent signal SIGTERM on delete
06/03/2014 10:55:15;000d;PBS_Server;Job;39308.tyrone-cluster;Not sending email: User does not want mail of this type.
06/03/2014 10:55:15;0010;PBS_Server;Job;39308.tyrone-cluster;Exit_status=143 resources_used.cput=00:12:16 resources_used.mem=36396224kb resources_used.vmem=48544268kb resources_used.walltime=00:04:47
06/03/2014 10:55:15;0008;PBS_Server;Job;NULL;on_job_exit valid pjob: 0x1788aa0 (substate=50)
06/03/2014 10:55:15;0008;PBS_Server;Job;NULL;on_job_exit valid pjob: 0x1788aa0 (substate=51)
06/03/2014 10:55:15;0008;PBS_Server;Job;NULL;on_job_exit valid pjob: 0x1788aa0 (substate=51)
06/03/2014 10:55:15;0008;PBS_Server;Job;NULL;on_job_exit valid pjob: 0x1788aa0 (substate=53)
06/03/2014 10:55:15;0100;PBS_Server;Job;39308.tyrone-cluster;dequeuing from qp256, state COMPLETE
06/03/2014 10:55:15;0040;PBS_Server;Svr;tyrone-cluster;Scheduler was sent the command term
06/03/2014 10:55:15;0008;PBS_Server;Job;39311.tyrone-cluster;Job Modified at request of Scheduler@tyrone-cluster
06/03/2014 10:55:15;0008;PBS_Server;Job;39311.tyrone-cluster;Job Run at request of Scheduler@tyrone-cluster
06/03/2014 10:55:16;0040;PBS_Server;Svr;tyrone-cluster;Scheduler was sent the command recyc
06/03/2014 10:55:30;000d;PBS_Server;Job;39311.tyrone-cluster;Not sending email: User does not want mail of this type.
06/03/2014 10:55:57;0002;PBS_Server;Svr;PBS_Server;Torque Server Version = 3.0.5, loglevel = 0
06/03/2014 10:56:48;0008;PBS_Server;Job;39311.tyrone-cluster;Job deleted at request of secbadar@tyrone-cluster
06/03/2014 10:56:48;0008;PBS_Server;Job;39311.tyrone-cluster;Job sent signal SIGTERM on delete
06/03/2014 10:56:49;000d;PBS_Server;Job;39311.tyrone-cluster;Not sending email: User does not want mail of this type.
06/03/2014 10:56:49;0010;PBS_Server;Job;39311.tyrone-cluster;Exit_status=143 resources_used.cput=00:00:01 resources_used.mem=100344kb resources_used.vmem=3205624kb resources_used.walltime=00:01:33
06/03/2014 10:56:49;0008;PBS_Server;Job;NULL;on_job_exit valid pjob: 0x1711f00 (substate=50)
06/03/2014 10:56:49;0008;PBS_Server;Job;NULL;on_job_exit valid pjob: 0x1711f00 (substate=51)
06/03/2014 10:56:49;0008;PBS_Server;Job;NULL;on_job_exit valid pjob: 0x1711f00 (substate=51)
06/03/2014 10:56:49;0008;PBS_Server;Job;NULL;on_job_exit valid pjob: 0x1711f00 (substate=53)
06/03/2014 10:56:49;0100;PBS_Server;Job;39311.tyrone-cluster;dequeuing from qp256, state COMPLETE
06/03/2014 10:56:49;0040;PBS_Server;Svr;tyrone-cluster;Scheduler was sent the command term
06/03/2014 10:59:39;0100;PBS_Server;Job;39312.tyrone-cluster;enqueuing into batch, state 1 hop 1
06/03/2014 10:59:39;0100;PBS_Server;Job;39312.tyrone-cluster;dequeuing from batch, state QUEUED
06/03/2014 10:59:39;0100;PBS_Server;Job;39312.tyrone-cluster;enqueuing into qp256, state 1 hop 1
06/03/2014 10:59:39;0008;PBS_Server;Job;39312.tyrone-cluster;Job Queued at request of mbuanuv@tyrone-node9, owner = mbuanuv@tyrone-node9, job name = Ms4-A-C18, queue = qp256
06/03/2014 10:59:39;0040;PBS_Server;Svr;tyrone-cluster;Scheduler was sent the command new
06/03/2014 10:59:39;0008;PBS_Server;Job;39312.tyrone-cluster;Job Modified at request of Scheduler@tyrone-cluster
06/03/2014 11:00:47;0100;PBS_Server;Job;39313.tyrone-cluster;enqueuing into batch, state 1 hop 1
06/03/2014 11:00:47;0008;PBS_Server;Job;39313.tyrone-cluster;Job Queued at request of mbuanuv@tyrone-node9, owner = mbuanuv@tyrone-node9, job name = Ms4-A-C19, queue = batch
06/03/2014 11:00:47;0040;PBS_Server;Svr;tyrone-cluster;Scheduler was sent the command new
06/03/2014 11:00:47;0008;PBS_Server;Job;39313.tyrone-cluster;Job Modified at request of Scheduler@tyrone-cluster
06/03/2014 11:00:57;0002;PBS_Server;Svr;PBS_Server;Torque Server Version = 3.0.5, loglevel = 0
06/03/2014 11:01:18;0040;PBS_Server;Svr;tyrone-cluster;Scheduler was sent the command new
06/03/2014 11:01:44;0100;PBS_Server;Job;39314.tyrone-cluster;enqueuing into batch, state 1 hop 1
06/03/2014 11:01:44;0008;PBS_Server;Job;39314.tyrone-cluster;Job Queued at request of mbuanuv@tyrone-node9, owner = mbuanuv@tyrone-node9, job name = Ms4-A-C20, queue = batch
06/03/2014 11:01:44;0040;PBS_Server;Svr;tyrone-cluster;Scheduler was sent the command new
06/03/2014 11:01:44;0008;PBS_Server;Job;39314.tyrone-cluster;Job Modified at request of Scheduler@tyrone-cluster
06/03/2014 11:01:50;0040;PBS_Server;Svr;tyrone-cluster;Scheduler was sent the command new
06/03/2014 11:02:22;0040;PBS_Server;Svr;tyrone-cluster;Scheduler was sent the command new
06/03/2014 11:02:46;0040;PBS_Server;Svr;tyrone-cluster;Scheduler was sent the command new
06/03/2014 11:02:55;0040;PBS_Server;Svr;tyrone-cluster;Scheduler was sent the command new
06/03/2014 11:03:20;0040;PBS_Server;Svr;tyrone-cluster;Scheduler was sent the command new
06/03/2014 11:03:29;0040;PBS_Server;Svr;tyrone-cluster;Scheduler was sent the command new
06/03/2014 11:03:52;0040;PBS_Server;Svr;tyrone-cluster;Scheduler was sent the command new
06/03/2014 11:04:05;0040;PBS_Server;Svr;tyrone-cluster;Scheduler was sent the command new
06/03/2014 11:04:25;0040;PBS_Server;Svr;tyrone-cluster;Scheduler was sent the command new
06/03/2014 11:04:37;0040;PBS_Server;Svr;tyrone-cluster;Scheduler was sent the command new
06/03/2014 11:04:56;0040;PBS_Server;Svr;tyrone-cluster;Scheduler was sent the command new
06/03/2014 11:05:10;0040;PBS_Server;Svr;tyrone-cluster;Scheduler was sent the command new
06/03/2014 11:05:35;0040;PBS_Server;Svr;tyrone-cluster;Scheduler was sent the command new
06/03/2014 11:05:40;0040;PBS_Server;Svr;tyrone-cluster;Scheduler was sent the command new
06/03/2014 11:05:57;0002;PBS_Server;Svr;PBS_Server;Torque Server Version = 3.0.5, loglevel = 0
06/03/2014 11:06:07;0040;PBS_Server;Svr;tyrone-cluster;Scheduler was sent the command new
06/03/2014 11:06:20;0040;PBS_Server;Svr;tyrone-cluster;Scheduler was sent the command new
06/03/2014 11:06:40;0040;PBS_Server;Svr;tyrone-cluster;Scheduler was sent the command new
06/03/2014 11:06:52;0040;PBS_Server;Svr;tyrone-cluster;Scheduler was sent the command new
06/03/2014 11:07:11;0040;PBS_Server;Svr;tyrone-cluster;Scheduler was sent the command new
06/03/2014 11:07:25;0040;PBS_Server;Svr;tyrone-cluster;Scheduler was sent the command new
06/03/2014 11:07:49;0040;PBS_Server;Svr;tyrone-cluster;Scheduler was sent the command new
06/03/2014 11:07:49;0100;PBS_Server;Job;39315.tyrone-cluster;enqueuing into batch, state 1 hop 1
06/03/2014 11:07:49;0100;PBS_Server;Job;39315.tyrone-cluster;dequeuing from batch, state QUEUED
06/03/2014 11:07:49;0100;PBS_Server;Job;39315.tyrone-cluster;enqueuing into qp256, state 1 hop 1
06/03/2014 11:07:49;0008;PBS_Server;Job;39315.tyrone-cluster;Job Queued at request of aserajsh@tyrone-cluster, owner = aserajsh@tyrone-cluster, job name = fixed_n, queue = qp256
06/03/2014 11:07:49;0008;PBS_Server;Job;39315.tyrone-cluster;Job Modified at request of Scheduler@tyrone-cluster
06/03/2014 11:07:49;0008;PBS_Server;Job;39315.tyrone-cluster;Job Run at request of Scheduler@tyrone-cluster
06/03/2014 11:07:49;0040;PBS_Server;Svr;tyrone-cluster;Scheduler was sent the command recyc
06/03/2014 11:07:51;000d;PBS_Server;Job;39315.tyrone-cluster;Not sending email: User does not want mail of this type.
06/03/2014 11:07:51;0010;PBS_Server;Job;39315.tyrone-cluster;Exit_status=1 resources_used.cput=00:00:00 resources_used.mem=804kb resources_used.vmem=13624kb resources_used.walltime=00:00:01
06/03/2014 11:07:51;0008;PBS_Server;Job;NULL;on_job_exit valid pjob: 0x17a61b0 (substate=50)
06/03/2014 11:07:51;0008;PBS_Server;Job;NULL;on_job_exit valid pjob: 0x17a61b0 (substate=51)
06/03/2014 11:07:56;0040;PBS_Server;Svr;tyrone-cluster;Scheduler was sent the command new
06/03/2014 11:07:59;0008;PBS_Server;Job;NULL;on_job_exit valid pjob: 0x17a61b0 (substate=51)
06/03/2014 11:07:59;000d;PBS_Server;Job;39315.tyrone-cluster;Post job file processing error; job 39315.tyrone-cluster on host tyrone-node16/63+tyrone-node16/62+tyrone-node16/61+tyrone-node16/60+tyrone-node16/59+tyrone-node16/58+tyrone-node16/57+tyrone-node16/56+tyrone-node16/55+tyrone-node16/54+tyrone-node16/53+tyrone-node16/52+tyrone-node16/51+tyrone-node16/50+tyrone-node16/49+tyrone-node16/48+tyrone-node16/47+tyrone-node16/46+tyrone-node16/45+tyrone-node16/44+tyrone-node16/43+tyrone-node16/42+tyrone-node16/41+tyrone-node16/40+tyrone-node16/39+tyrone-node16/38+tyrone-node16/37+tyrone-node16/36+tyrone-node16/35+tyrone-node16/34+tyrone-node16/33+tyrone-node16/32+tyrone-node16/31+tyrone-node16/30+tyrone-node16/29+tyrone-node16/28+tyrone-node16/27+tyrone-node16/26+tyrone-node16/25+tyrone-node16/24+tyrone-node16/23+tyrone-node16/22+tyrone-node16/21+tyrone-node16/20+tyrone-node16/19+tyrone-node16/18+tyrone-node16/17+tyrone-node16/16+tyrone-node16/15+tyrone-node16/14+tyrone-node16/13+tyrone-node16/12+tyrone-node16/11+tyrone-node16/10+tyrone-node16/9+tyrone-node16/8+tyrone-node16/7+tyrone-node16/6+tyrone-node16/5+tyrone-node16/4+tyrone-node16/3+tyrone-node16/2+tyrone-node16/1+tyrone-node16/0+tyrone-node15/63+tyrone-node15/62+tyrone-node15/61+tyrone-node15/60+tyrone-node15/59+tyrone-node15/58+tyrone-node15/57+tyrone-node15/56+tyrone-node15/55+tyrone-node15/54+tyrone-node15/53+tyrone-node15/52+tyrone-node15/51+tyrone-node15/50+tyrone-node15/49+tyrone-node15/48+tyrone-node15/47+tyrone-node15/46+tyrone-node15/45+tyrone-node15/44+tyrone-node15/43+tyrone-node15/42+tyrone-node15/41+tyrone-node15/40+tyrone-node15/39+tyrone-node15/38+tyrone-node15/37+tyrone-node15/36+tyrone-node15/35+tyrone-node15/34+tyrone-node15/33+tyrone-node15/32+tyrone-node15/31+tyrone-node15/30+tyrone-node15/29+tyrone-node15/28+tyrone-node15/27+tyrone-node15/26+tyrone-node15/25+tyrone-node15/24+tyrone-node15/23+tyrone-node15/22+tyrone-node15/21+tyrone-node15/20+tyrone-node15/19+tyrone-node15/18+tyrone-node15/17+tyrone-node15/16+tyrone-node15/15+tyrone-node15/14+tyrone-node15/13+tyrone-node15/12+tyrone-node15/11+tyrone-node15/10+tyrone-node15/9+tyrone-node15/8+tyrone-node15/7+tyrone-node15/6+tyrone-node15/5+tyrone-node15/4+tyrone-node15/3+tyrone-node15/2+tyrone-node15/1+tyrone-node15/0+tyrone-node14/63+tyrone-node14/62+tyrone-node14/61+tyrone-node14/60+tyrone-node14/59+tyrone-node14/58+tyrone-node14/57+tyrone-node14/56+tyrone-node14/55+tyrone-node14/54+tyrone-node14/53+tyrone-node14/52+tyrone-node14/51+tyrone-node14/50+tyrone-node14/49+tyrone-node14/48+tyrone-node14/47+tyrone-node14/46+tyrone-node14/45+tyrone-node14/44+tyrone-node14/43+tyrone-node14/42+tyrone-node14/41+tyrone-node14/40+tyrone-node14/39+tyrone-node14/38+tyrone-node14/37+tyrone-node14/36+tyrone-node14/35+tyrone-node14/34+tyrone-node14/33+tyrone-node14/32+tyrone-node14/31+tyrone-node14/30+tyrone-node14/29+tyrone-node14/28+tyrone-node14/27+tyrone-node14/26+tyrone-node14/25+tyrone-node14/24+tyrone-node14/23+tyrone-node14/22+tyrone-node14/21+tyrone-node14/20+tyrone-node14/19+tyrone-node14/18+tyrone-node14/17+tyrone-node14/16+tyrone-node14/15+tyrone-node14/14+tyrone-node14/13+tyrone-node14/12+tyrone-node14/11+tyrone-node14/10+tyrone-node14/9+tyrone-node14/8+tyrone-node14/7+tyrone-node14/6+tyrone-node14/5+tyrone-node14/4+tyrone-node14/3+tyrone-node14/2+tyrone-node14/1+tyrone-node14/0+tyrone-node13/63+tyrone-node13/62+tyrone-node13/61+tyrone-node13/60+tyrone-node13/59+tyrone-node13/58+tyrone-node13/57+tyrone-node13/56+tyrone-node13/55+tyrone-node13/54+tyrone-node13/53+tyrone-node13/52+tyrone-node13/51+tyrone-node13/50+tyrone-node13/49+tyrone-node13/48+tyrone-node13/47+tyrone-node13/46+tyrone-node13/45+tyrone-node13/44+tyrone-node13/43+tyrone-node13/42+tyrone-node13/41+tyrone-node13/40+tyrone-node13/39+tyrone-node13/38+tyrone-node13/37+tyrone-node13/36+tyrone-node13/35+tyrone-node13/34+tyrone-node13/33+tyrone-node13/32+tyrone-node13/31+tyrone-node13/30+tyrone-node13/29+tyrone-node13/28+tyrone-node13/27+tyrone-node13/26+tyrone-node13/25+tyrone-node13/24+tyrone-node13/23+tyrone-node13/22+tyrone-node13/21+tyrone-node13/20+tyrone-node13/19+tyrone-node13/18+tyrone-node13/17+tyrone-node13/16+tyrone-node13/15+tyrone-node13/14+tyrone-node13/13+tyrone-node13/12+tyrone-node13/11+tyrone-node13/10+tyrone-node13/9+tyrone-node13/8+tyrone-node13/7+tyrone-node13/6+tyrone-node13/5+tyrone-node13/4+tyrone-node13/3+tyrone-node13/2+tyrone-node13/1+tyrone-node13/0
06/03/2014 11:07:59;0008;PBS_Server;Job;NULL;on_job_exit valid pjob: 0x17a61b0 (substate=53)
06/03/2014 11:07:59;0100;PBS_Server;Job;39315.tyrone-cluster;dequeuing from qp256, state COMPLETE
06/03/2014 11:07:59;0040;PBS_Server;Svr;tyrone-cluster;Scheduler was sent the command term
06/03/2014 11:08:22;0040;PBS_Server;Svr;tyrone-cluster;Scheduler was sent the command new
06/03/2014 11:08:27;0040;PBS_Server;Svr;tyrone-cluster;Scheduler was sent the command new
06/03/2014 11:08:55;0040;PBS_Server;Svr;tyrone-cluster;Scheduler was sent the command new
06/03/2014 11:08:56;0040;PBS_Server;Svr;tyrone-cluster;Scheduler was sent the command new
06/03/2014 11:09:13;0100;PBS_Server;Job;39316.tyrone-cluster;enqueuing into batch, state 1 hop 1
06/03/2014 11:09:13;0100;PBS_Server;Job;39316.tyrone-cluster;dequeuing from batch, state QUEUED
06/03/2014 11:09:13;0100;PBS_Server;Job;39316.tyrone-cluster;enqueuing into qp128, state 1 hop 1
06/03/2014 11:09:13;0008;PBS_Server;Job;39316.tyrone-cluster;Job Queued at request of ciesita@tyrone-cluster, owner = ciesita@tyrone-cluster, job name = Ec1-A-C24, queue = qp128
06/03/2014 11:09:13;0040;PBS_Server;Svr;tyrone-cluster;Scheduler was sent the command new
06/03/2014 11:09:14;0008;PBS_Server;Job;39316.tyrone-cluster;Job Modified at request of Scheduler@tyrone-cluster
06/03/2014 11:09:26;0040;PBS_Server;Svr;tyrone-cluster;Scheduler was sent the command new
06/03/2014 11:09:28;0008;PBS_Server;Job;39291.tyrone-cluster;Job deleted at request of ciesita@tyrone-cluster
06/03/2014 11:09:28;0008;PBS_Server;Job;39291.tyrone-cluster;Job sent signal SIGTERM on delete
06/03/2014 11:09:30;0008;PBS_Server;Job;39291.tyrone-cluster;Job sent signal SIGKILL on delete
06/03/2014 11:09:38;000d;PBS_Server;Job;39291.tyrone-cluster;Not sending email: User does not want mail of this type.
06/03/2014 11:09:38;0010;PBS_Server;Job;39291.tyrone-cluster;Exit_status=271 resources_used.cput=605:11:15 resources_used.mem=1314188kb resources_used.vmem=7886060kb resources_used.walltime=18:56:07
06/03/2014 11:09:38;0008;PBS_Server;Job;NULL;on_job_exit valid pjob: 0x177dbb0 (substate=50)
06/03/2014 11:09:38;0008;PBS_Server;Job;NULL;on_job_exit valid pjob: 0x177dbb0 (substate=51)
06/03/2014 11:09:42;0080;PBS_Server;Job;39291.tyrone-cluster;Request invalid for state of job EXITING
06/03/2014 11:09:42;0080;PBS_Server;Req;req_reject;Reject reply code=15018(Request invalid for state of job MSG=invalid state for job - EXITING), aux=0, type=DeleteJob, from ciesita@tyrone-cluster
06/03/2014 11:09:43;0008;PBS_Server;Job;NULL;on_job_exit valid pjob: 0x177dbb0 (substate=51)
06/03/2014 11:09:43;000d;PBS_Server;Job;39291.tyrone-cluster;Post job file processing error; job 39291.tyrone-cluster on host tyrone-node8/31+tyrone-node8/30+tyrone-node8/29+tyrone-node8/28+tyrone-node8/27+tyrone-node8/26+tyrone-node8/25+tyrone-node8/24+tyrone-node8/23+tyrone-node8/22+tyrone-node8/21+tyrone-node8/20+tyrone-node8/19+tyrone-node8/18+tyrone-node8/17+tyrone-node8/16+tyrone-node8/15+tyrone-node8/14+tyrone-node8/13+tyrone-node8/12+tyrone-node8/11+tyrone-node8/10+tyrone-node8/9+tyrone-node8/8+tyrone-node8/7+tyrone-node8/6+tyrone-node8/5+tyrone-node8/4+tyrone-node8/3+tyrone-node8/2+tyrone-node8/1+tyrone-node8/0+tyrone-node5/31+tyrone-node5/30+tyrone-node5/29+tyrone-node5/28+tyrone-node5/27+tyrone-node5/26+tyrone-node5/25+tyrone-node5/24+tyrone-node5/23+tyrone-node5/22+tyrone-node5/21+tyrone-node5/20+tyrone-node5/19+tyrone-node5/18+tyrone-node5/17+tyrone-node5/16+tyrone-node5/15+tyrone-node5/14+tyrone-node5/13+tyrone-node5/12+tyrone-node5/11+tyrone-node5/10+tyrone-node5/9+tyrone-node5/8+tyrone-node5/7+tyrone-node5/6+tyrone-node5/5+tyrone-node5/4+tyrone-node5/3+tyrone-node5/2+tyrone-node5/1+tyrone-node5/0+tyrone-node4/31+tyrone-node4/30+tyrone-node4/29+tyrone-node4/28+tyrone-node4/27+tyrone-node4/26+tyrone-node4/25+tyrone-node4/24+tyrone-node4/23+tyrone-node4/22+tyrone-node4/21+tyrone-node4/20+tyrone-node4/19+tyrone-node4/18+tyrone-node4/17+tyrone-node4/16+tyrone-node4/15+tyrone-node4/14+tyrone-node4/13+tyrone-node4/12+tyrone-node4/11+tyrone-node4/10+tyrone-node4/9+tyrone-node4/8+tyrone-node4/7+tyrone-node4/6+tyrone-node4/5+tyrone-node4/4+tyrone-node4/3+tyrone-node4/2+tyrone-node4/1+tyrone-node4/0+tyrone-node3/31+tyrone-node3/30+tyrone-node3/29+tyrone-node3/28+tyrone-node3/27+tyrone-node3/26+tyrone-node3/25+tyrone-node3/24+tyrone-node3/23+tyrone-node3/22+tyrone-node3/21+tyrone-node3/20+tyrone-node3/19+tyrone-node3/18+tyrone-node3/17+tyrone-node3/16+tyrone-node3/15+tyrone-node3/14+tyrone-node3/13+tyrone-node3/12+tyrone-node3/11+tyrone-node3/10+tyrone-node3/9+tyrone-node3/8+tyrone-node3/7+tyrone-node3/6+tyrone-node3/5+tyrone-node3/4+tyrone-node3/3+tyrone-node3/2+tyrone-node3/1+tyrone-node3/0
06/03/2014 11:09:43;0008;PBS_Server;Job;NULL;on_job_exit valid pjob: 0x177dbb0 (substate=53)
06/03/2014 11:09:43;0100;PBS_Server;Job;39291.tyrone-cluster;dequeuing from qp128, state COMPLETE
06/03/2014 11:09:43;0040;PBS_Server;Svr;tyrone-cluster;Scheduler was sent the command term
06/03/2014 11:09:43;0008;PBS_Server;Job;39316.tyrone-cluster;Job Modified at request of Scheduler@tyrone-cluster
06/03/2014 11:09:43;0008;PBS_Server;Job;39316.tyrone-cluster;Job Run at request of Scheduler@tyrone-cluster
06/03/2014 11:09:43;0040;PBS_Server;Svr;tyrone-cluster;Scheduler was sent the command recyc
06/03/2014 11:09:54;0040;PBS_Server;Svr;tyrone-cluster;Scheduler was sent the command new
06/03/2014 11:10:06;0040;PBS_Server;Svr;tyrone-cluster;Scheduler was sent the command new
06/03/2014 11:10:25;0040;PBS_Server;Svr;tyrone-cluster;Scheduler was sent the command new
06/03/2014 11:10:38;000d;PBS_Server;Job;39316.tyrone-cluster;Not sending email: User does not want mail of this type.
06/03/2014 11:10:38;0040;PBS_Server;Svr;tyrone-cluster;Scheduler was sent the command new
06/03/2014 11:10:55;0040;PBS_Server;Svr;tyrone-cluster;Scheduler was sent the command new
06/03/2014 11:10:57;0002;PBS_Server;Svr;PBS_Server;Torque Server Version = 3.0.5, loglevel = 0
06/03/2014 11:11:10;0040;PBS_Server;Svr;tyrone-cluster;Scheduler was sent the command new
06/03/2014 11:11:16;0100;PBS_Server;Job;39317.tyrone-cluster;enqueuing into batch, state 1 hop 1
06/03/2014 11:11:16;0100;PBS_Server;Job;39317.tyrone-cluster;dequeuing from batch, state QUEUED
06/03/2014 11:11:16;0100;PBS_Server;Job;39317.tyrone-cluster;enqueuing into qp256, state 1 hop 1
06/03/2014 11:11:16;0008;PBS_Server;Job;39317.tyrone-cluster;Job Queued at request of secbadar@tyrone-cluster, owner = secbadar@tyrone-cluster, job name = job1286USD, queue = qp256
06/03/2014 11:11:16;0040;PBS_Server;Svr;tyrone-cluster;Scheduler was sent the command new
06/03/2014 11:11:16;0008;PBS_Server;Job;39317.tyrone-cluster;Job Modified at request of Scheduler@tyrone-cluster
06/03/2014 11:11:16;0008;PBS_Server;Job;39317.tyrone-cluster;Job Run at request of Scheduler@tyrone-cluster
06/03/2014 11:11:16;0040;PBS_Server;Svr;tyrone-cluster;Scheduler was sent the command recyc
06/03/2014 11:11:37;0040;PBS_Server;Svr;tyrone-cluster;Scheduler was sent the command new
06/03/2014 11:11:37;0008;PBS_Server;Job;39312.tyrone-cluster;Job Modified at request of Scheduler@tyrone-cluster
06/03/2014 11:11:41;0040;PBS_Server;Svr;tyrone-cluster;Scheduler was sent the command new
06/03/2014 11:12:08;0040;PBS_Server;Svr;tyrone-cluster;Scheduler was sent the command new
06/03/2014 11:12:10;000d;PBS_Server;Job;39317.tyrone-cluster;Not sending email: User does not want mail of this type.
06/03/2014 11:12:10;0040;PBS_Server;Svr;tyrone-cluster;Scheduler was sent the command new
06/03/2014 11:12:40;0040;PBS_Server;Svr;tyrone-cluster;Scheduler was sent the command new
06/03/2014 11:12:45;0100;PBS_Server;Job;39318.tyrone-cluster;enqueuing into batch, state 1 hop 1
06/03/2014 11:12:45;0100;PBS_Server;Job;39318.tyrone-cluster;dequeuing from batch, state QUEUED
06/03/2014 11:12:45;0100;PBS_Server;Job;39318.tyrone-cluster;enqueuing into qp256, state 1 hop 1
06/03/2014 11:12:45;0008;PBS_Server;Job;39318.tyrone-cluster;Job Queued at request of secbadar@tyrone-cluster, owner = secbadar@tyrone-cluster, job name = job1286USD, queue = qp256
06/03/2014 11:12:45;0040;PBS_Server;Svr;tyrone-cluster;Scheduler was sent the command new
06/03/2014 11:12:45;0008;PBS_Server;Job;39318.tyrone-cluster;Job Modified at request of Scheduler@tyrone-cluster
06/03/2014 11:13:11;0040;PBS_Server;Svr;tyrone-cluster;Scheduler was sent the command new
06/03/2014 11:13:26;0100;PBS_Server;Job;39319.tyrone-cluster;enqueuing into batch, state 1 hop 1
06/03/2014 11:13:26;0100;PBS_Server;Job;39319.tyrone-cluster;dequeuing from batch, state QUEUED
06/03/2014 11:13:26;0100;PBS_Server;Job;39319.tyrone-cluster;enqueuing into qp256, state 1 hop 1
06/03/2014 11:13:26;0008;PBS_Server;Job;39319.tyrone-cluster;Job Queued at request of aserajsh@tyrone-cluster, owner = aserajsh@tyrone-cluster, job name = fixed_n, queue = qp256
06/03/2014 11:13:26;0040;PBS_Server;Svr;tyrone-cluster;Scheduler was sent the command new
06/03/2014 11:13:26;0008;PBS_Server;Job;39319.tyrone-cluster;Job Modified at request of Scheduler@tyrone-cluster
06/03/2014 11:13:40;0040;PBS_Server;Svr;tyrone-cluster;Scheduler was sent the command new
06/03/2014 11:14:10;0040;PBS_Server;Svr;tyrone-cluster;Scheduler was sent the command new
06/03/2014 11:14:44;0040;PBS_Server;Svr;tyrone-cluster;Scheduler was sent the command new
06/03/2014 11:15:10;0040;PBS_Server;Svr;tyrone-cluster;Scheduler was sent the command new
06/03/2014 11:15:40;0040;PBS_Server;Svr;tyrone-cluster;Scheduler was sent the command new
06/03/2014 11:15:57;0002;PBS_Server;Svr;PBS_Server;Torque Server Version = 3.0.5, loglevel = 0
06/03/2014 11:16:10;0040;PBS_Server;Svr;tyrone-cluster;Scheduler was sent the command new
06/03/2014 11:16:40;0040;PBS_Server;Svr;tyrone-cluster;Scheduler was sent the command new
06/03/2014 11:17:10;0040;PBS_Server;Svr;tyrone-cluster;Scheduler was sent the command new
06/03/2014 11:17:41;0040;PBS_Server;Svr;tyrone-cluster;Scheduler was sent the command new
06/03/2014 11:18:10;0040;PBS_Server;Svr;tyrone-cluster;Scheduler was sent the command new
06/03/2014 11:18:40;0040;PBS_Server;Svr;tyrone-cluster;Scheduler was sent the command new
06/03/2014 11:19:14;0040;PBS_Server;Svr;tyrone-cluster;Scheduler was sent the command new
06/03/2014 11:19:40;0040;PBS_Server;Svr;tyrone-cluster;Scheduler was sent the command new
06/03/2014 11:20:10;0040;PBS_Server;Svr;tyrone-cluster;Scheduler was sent the command new
06/03/2014 11:20:40;0040;PBS_Server;Svr;tyrone-cluster;Scheduler was sent the command new
06/03/2014 11:20:57;0002;PBS_Server;Svr;PBS_Server;Torque Server Version = 3.0.5, loglevel = 0
06/03/2014 11:21:10;0040;PBS_Server;Svr;tyrone-cluster;Scheduler was sent the command new
06/03/2014 11:21:40;0040;PBS_Server;Svr;tyrone-cluster;Scheduler was sent the command new
06/03/2014 11:22:11;0040;PBS_Server;Svr;tyrone-cluster;Scheduler was sent the command new
06/03/2014 11:22:40;0040;PBS_Server;Svr;tyrone-cluster;Scheduler was sent the command new
06/03/2014 11:23:10;0040;PBS_Server;Svr;tyrone-cluster;Scheduler was sent the command new
06/03/2014 11:23:44;0040;PBS_Server;Svr;tyrone-cluster;Scheduler was sent the command new
06/03/2014 11:24:21;0040;PBS_Server;Svr;tyrone-cluster;Scheduler was sent the command new
06/03/2014 11:24:53;0040;PBS_Server;Svr;tyrone-cluster;Scheduler was sent the command new
06/03/2014 11:25:25;0040;PBS_Server;Svr;tyrone-cluster;Scheduler was sent the command new
06/03/2014 11:25:56;0040;PBS_Server;Svr;tyrone-cluster;Scheduler was sent the command new
06/03/2014 11:25:57;0002;PBS_Server;Svr;PBS_Server;Torque Server Version = 3.0.5, loglevel = 0
06/03/2014 11:26:20;000d;PBS_Server;Job;39317.tyrone-cluster;Not sending email: User does not want mail of this type.
06/03/2014 11:26:20;0010;PBS_Server;Job;39317.tyrone-cluster;Exit_status=0 resources_used.cput=00:24:21 resources_used.mem=40847080kb resources_used.vmem=54329624kb resources_used.walltime=00:15:04
06/03/2014 11:26:20;0008;PBS_Server;Job;NULL;on_job_exit valid pjob: 0x177dbb0 (substate=50)
06/03/2014 11:26:20;0008;PBS_Server;Job;NULL;on_job_exit valid pjob: 0x177dbb0 (substate=51)
06/03/2014 11:26:20;0008;PBS_Server;Job;NULL;on_job_exit valid pjob: 0x177dbb0 (substate=51)
06/03/2014 11:26:20;0008;PBS_Server;Job;NULL;on_job_exit valid pjob: 0x177dbb0 (substate=53)
06/03/2014 11:26:20;0100;PBS_Server;Job;39317.tyrone-cluster;dequeuing from qp256, state COMPLETE
06/03/2014 11:26:20;0040;PBS_Server;Svr;tyrone-cluster;Scheduler was sent the command term
06/03/2014 11:26:20;0008;PBS_Server;Job;39312.tyrone-cluster;Job Modified at request of Scheduler@tyrone-cluster
06/03/2014 11:26:20;0008;PBS_Server;Job;39318.tyrone-cluster;Job Modified at request of Scheduler@tyrone-cluster
06/03/2014 11:26:20;0008;PBS_Server;Job;39318.tyrone-cluster;Job Run at request of Scheduler@tyrone-cluster
06/03/2014 11:26:20;0040;PBS_Server;Svr;tyrone-cluster;Scheduler was sent the command recyc
06/03/2014 11:26:36;0040;PBS_Server;Svr;tyrone-cluster;Scheduler was sent the command new
06/03/2014 11:26:36;0008;PBS_Server;Job;39312.tyrone-cluster;Job Modified at request of Scheduler@tyrone-cluster
06/03/2014 11:27:08;0040;PBS_Server;Svr;tyrone-cluster;Scheduler was sent the command new
06/03/2014 11:27:12;000d;PBS_Server;Job;39318.tyrone-cluster;Not sending email: User does not want mail of this type.
06/03/2014 11:27:40;0040;PBS_Server;Svr;tyrone-cluster;Scheduler was sent the command new
06/03/2014 11:28:14;0040;PBS_Server;Svr;tyrone-cluster;Scheduler was sent the command new
06/03/2014 11:28:42;0040;PBS_Server;Svr;tyrone-cluster;Scheduler was sent the command new
06/03/2014 11:29:23;0040;PBS_Server;Svr;tyrone-cluster;Scheduler was sent the command new
06/03/2014 11:29:46;0040;PBS_Server;Svr;tyrone-cluster;Scheduler was sent the command new
06/03/2014 11:30:21;0040;PBS_Server;Svr;tyrone-cluster;Scheduler was sent the command new
06/03/2014 11:30:53;0040;PBS_Server;Svr;tyrone-cluster;Scheduler was sent the command new
06/03/2014 11:30:57;0002;PBS_Server;Svr;PBS_Server;Torque Server Version = 3.0.5, loglevel = 0
06/03/2014 11:31:25;0040;PBS_Server;Svr;tyrone-cluster;Scheduler was sent the command new
06/03/2014 11:31:56;0040;PBS_Server;Svr;tyrone-cluster;Scheduler was sent the command new
06/03/2014 11:32:27;0040;PBS_Server;Svr;tyrone-cluster;Scheduler was sent the command new
06/03/2014 11:33:08;0040;PBS_Server;Svr;tyrone-cluster;Scheduler was sent the command new
06/03/2014 11:33:31;0040;PBS_Server;Svr;tyrone-cluster;Scheduler was sent the command new
06/03/2014 11:34:06;0040;PBS_Server;Svr;tyrone-cluster;Scheduler was sent the command new
06/03/2014 11:34:38;0040;PBS_Server;Svr;tyrone-cluster;Scheduler was sent the command new
06/03/2014 11:35:10;0040;PBS_Server;Svr;tyrone-cluster;Scheduler was sent the command new
06/03/2014 11:35:41;0040;PBS_Server;Svr;tyrone-cluster;Scheduler was sent the command new
06/03/2014 11:35:57;0002;PBS_Server;Svr;PBS_Server;Torque Server Version = 3.0.5, loglevel = 0
06/03/2014 11:36:09;0040;PBS_Server;Svr;tyrone-cluster;Scheduler was sent the command new
06/03/2014 11:36:22;0100;PBS_Server;Job;39320.tyrone-cluster;enqueuing into batch, state 1 hop 1
06/03/2014 11:36:22;0100;PBS_Server;Job;39320.tyrone-cluster;dequeuing from batch, state QUEUED
06/03/2014 11:36:22;0100;PBS_Server;Job;39320.tyrone-cluster;enqueuing into qp256, state 1 hop 1
06/03/2014 11:36:22;0008;PBS_Server;Job;39320.tyrone-cluster;Job Queued at request of secbadar@tyrone-cluster, owner = secbadar@tyrone-cluster, job name = job1286USp, queue = qp256
06/03/2014 11:36:22;0040;PBS_Server;Svr;tyrone-cluster;Scheduler was sent the command new
06/03/2014 11:36:22;0008;PBS_Server;Job;39320.tyrone-cluster;Job Modified at request of Scheduler@tyrone-cluster
06/03/2014 11:36:40;0040;PBS_Server;Svr;tyrone-cluster;Scheduler was sent the command new
06/03/2014 11:37:11;0040;PBS_Server;Svr;tyrone-cluster;Scheduler was sent the command new
06/03/2014 11:37:39;0040;PBS_Server;Svr;tyrone-cluster;Scheduler was sent the command new
06/03/2014 11:38:10;0040;PBS_Server;Svr;tyrone-cluster;Scheduler was sent the command new
06/03/2014 11:38:44;0040;PBS_Server;Svr;tyrone-cluster;Scheduler was sent the command new
06/03/2014 11:39:00;000d;PBS_Server;Job;39318.tyrone-cluster;Not sending email: User does not want mail of this type.
06/03/2014 11:39:00;0010;PBS_Server;Job;39318.tyrone-cluster;Exit_status=0 resources_used.cput=00:21:29 resources_used.mem=40770268kb resources_used.vmem=54415540kb resources_used.walltime=00:12:39
06/03/2014 11:39:00;0008;PBS_Server;Job;NULL;on_job_exit valid pjob: 0x1724940 (substate=50)
06/03/2014 11:39:00;0008;PBS_Server;Job;NULL;on_job_exit valid pjob: 0x1724940 (substate=51)
06/03/2014 11:39:00;0008;PBS_Server;Job;NULL;on_job_exit valid pjob: 0x1724940 (substate=51)
06/03/2014 11:39:00;0008;PBS_Server;Job;NULL;on_job_exit valid pjob: 0x1724940 (substate=53)
06/03/2014 11:39:00;0100;PBS_Server;Job;39318.tyrone-cluster;dequeuing from qp256, state COMPLETE
06/03/2014 11:39:00;0040;PBS_Server;Svr;tyrone-cluster;Scheduler was sent the command term
06/03/2014 11:39:00;0008;PBS_Server;Job;39312.tyrone-cluster;Job Modified at request of Scheduler@tyrone-cluster
06/03/2014 11:39:00;0008;PBS_Server;Job;39319.tyrone-cluster;Job Modified at request of Scheduler@tyrone-cluster
06/03/2014 11:39:00;0008;PBS_Server;Job;39319.tyrone-cluster;Job Run at request of Scheduler@tyrone-cluster
06/03/2014 11:39:00;0040;PBS_Server;Svr;tyrone-cluster;Scheduler was sent the command recyc
06/03/2014 11:39:01;000d;PBS_Server;Job;39319.tyrone-cluster;Not sending email: User does not want mail of this type.
06/03/2014 11:39:01;0010;PBS_Server;Job;39319.tyrone-cluster;Exit_status=1 resources_used.cput=00:00:00 resources_used.mem=800kb resources_used.vmem=13624kb resources_used.walltime=00:00:01
06/03/2014 11:39:01;0008;PBS_Server;Job;NULL;on_job_exit valid pjob: 0x1713730 (substate=50)
06/03/2014 11:39:01;0008;PBS_Server;Job;NULL;on_job_exit valid pjob: 0x1713730 (substate=51)
06/03/2014 11:39:09;0008;PBS_Server;Job;NULL;on_job_exit valid pjob: 0x1713730 (substate=51)
06/03/2014 11:39:09;000d;PBS_Server;Job;39319.tyrone-cluster;Post job file processing error; job 39319.tyrone-cluster on host tyrone-node16/63+tyrone-node16/62+tyrone-node16/61+tyrone-node16/60+tyrone-node16/59+tyrone-node16/58+tyrone-node16/57+tyrone-node16/56+tyrone-node16/55+tyrone-node16/54+tyrone-node16/53+tyrone-node16/52+tyrone-node16/51+tyrone-node16/50+tyrone-node16/49+tyrone-node16/48+tyrone-node16/47+tyrone-node16/46+tyrone-node16/45+tyrone-node16/44+tyrone-node16/43+tyrone-node16/42+tyrone-node16/41+tyrone-node16/40+tyrone-node16/39+tyrone-node16/38+tyrone-node16/37+tyrone-node16/36+tyrone-node16/35+tyrone-node16/34+tyrone-node16/33+tyrone-node16/32+tyrone-node16/31+tyrone-node16/30+tyrone-node16/29+tyrone-node16/28+tyrone-node16/27+tyrone-node16/26+tyrone-node16/25+tyrone-node16/24+tyrone-node16/23+tyrone-node16/22+tyrone-node16/21+tyrone-node16/20+tyrone-node16/19+tyrone-node16/18+tyrone-node16/17+tyrone-node16/16+tyrone-node16/15+tyrone-node16/14+tyrone-node16/13+tyrone-node16/12+tyrone-node16/11+tyrone-node16/10+tyrone-node16/9+tyrone-node16/8+tyrone-node16/7+tyrone-node16/6+tyrone-node16/5+tyrone-node16/4+tyrone-node16/3+tyrone-node16/2+tyrone-node16/1+tyrone-node16/0+tyrone-node15/63+tyrone-node15/62+tyrone-node15/61+tyrone-node15/60+tyrone-node15/59+tyrone-node15/58+tyrone-node15/57+tyrone-node15/56+tyrone-node15/55+tyrone-node15/54+tyrone-node15/53+tyrone-node15/52+tyrone-node15/51+tyrone-node15/50+tyrone-node15/49+tyrone-node15/48+tyrone-node15/47+tyrone-node15/46+tyrone-node15/45+tyrone-node15/44+tyrone-node15/43+tyrone-node15/42+tyrone-node15/41+tyrone-node15/40+tyrone-node15/39+tyrone-node15/38+tyrone-node15/37+tyrone-node15/36+tyrone-node15/35+tyrone-node15/34+tyrone-node15/33+tyrone-node15/32+tyrone-node15/31+tyrone-node15/30+tyrone-node15/29+tyrone-node15/28+tyrone-node15/27+tyrone-node15/26+tyrone-node15/25+tyrone-node15/24+tyrone-node15/23+tyrone-node15/22+tyrone-node15/21+tyrone-node15/20+tyrone-node15/19+tyrone-node15/18+tyrone-node15/17+tyrone-node15/16+tyrone-node15/15+tyrone-node15/14+tyrone-node15/13+tyrone-node15/12+tyrone-node15/11+tyrone-node15/10+tyrone-node15/9+tyrone-node15/8+tyrone-node15/7+tyrone-node15/6+tyrone-node15/5+tyrone-node15/4+tyrone-node15/3+tyrone-node15/2+tyrone-node15/1+tyrone-node15/0+tyrone-node14/63+tyrone-node14/62+tyrone-node14/61+tyrone-node14/60+tyrone-node14/59+tyrone-node14/58+tyrone-node14/57+tyrone-node14/56+tyrone-node14/55+tyrone-node14/54+tyrone-node14/53+tyrone-node14/52+tyrone-node14/51+tyrone-node14/50+tyrone-node14/49+tyrone-node14/48+tyrone-node14/47+tyrone-node14/46+tyrone-node14/45+tyrone-node14/44+tyrone-node14/43+tyrone-node14/42+tyrone-node14/41+tyrone-node14/40+tyrone-node14/39+tyrone-node14/38+tyrone-node14/37+tyrone-node14/36+tyrone-node14/35+tyrone-node14/34+tyrone-node14/33+tyrone-node14/32+tyrone-node14/31+tyrone-node14/30+tyrone-node14/29+tyrone-node14/28+tyrone-node14/27+tyrone-node14/26+tyrone-node14/25+tyrone-node14/24+tyrone-node14/23+tyrone-node14/22+tyrone-node14/21+tyrone-node14/20+tyrone-node14/19+tyrone-node14/18+tyrone-node14/17+tyrone-node14/16+tyrone-node14/15+tyrone-node14/14+tyrone-node14/13+tyrone-node14/12+tyrone-node14/11+tyrone-node14/10+tyrone-node14/9+tyrone-node14/8+tyrone-node14/7+tyrone-node14/6+tyrone-node14/5+tyrone-node14/4+tyrone-node14/3+tyrone-node14/2+tyrone-node14/1+tyrone-node14/0+tyrone-node13/63+tyrone-node13/62+tyrone-node13/61+tyrone-node13/60+tyrone-node13/59+tyrone-node13/58+tyrone-node13/57+tyrone-node13/56+tyrone-node13/55+tyrone-node13/54+tyrone-node13/53+tyrone-node13/52+tyrone-node13/51+tyrone-node13/50+tyrone-node13/49+tyrone-node13/48+tyrone-node13/47+tyrone-node13/46+tyrone-node13/45+tyrone-node13/44+tyrone-node13/43+tyrone-node13/42+tyrone-node13/41+tyrone-node13/40+tyrone-node13/39+tyrone-node13/38+tyrone-node13/37+tyrone-node13/36+tyrone-node13/35+tyrone-node13/34+tyrone-node13/33+tyrone-node13/32+tyrone-node13/31+tyrone-node13/30+tyrone-node13/29+tyrone-node13/28+tyrone-node13/27+tyrone-node13/26+tyrone-node13/25+tyrone-node13/24+tyrone-node13/23+tyrone-node13/22+tyrone-node13/21+tyrone-node13/20+tyrone-node13/19+tyrone-node13/18+tyrone-node13/17+tyrone-node13/16+tyrone-node13/15+tyrone-node13/14+tyrone-node13/13+tyrone-node13/12+tyrone-node13/11+tyrone-node13/10+tyrone-node13/9+tyrone-node13/8+tyrone-node13/7+tyrone-node13/6+tyrone-node13/5+tyrone-node13/4+tyrone-node13/3+tyrone-node13/2+tyrone-node13/1+tyrone-node13/0
06/03/2014 11:39:09;0008;PBS_Server;Job;NULL;on_job_exit valid pjob: 0x1713730 (substate=53)
06/03/2014 11:39:09;0100;PBS_Server;Job;39319.tyrone-cluster;dequeuing from qp256, state COMPLETE
06/03/2014 11:39:09;0040;PBS_Server;Svr;tyrone-cluster;Scheduler was sent the command term
06/03/2014 11:39:10;0008;PBS_Server;Job;39320.tyrone-cluster;Job Modified at request of Scheduler@tyrone-cluster
06/03/2014 11:39:10;0008;PBS_Server;Job;39320.tyrone-cluster;Job Run at request of Scheduler@tyrone-cluster
06/03/2014 11:39:10;0040;PBS_Server;Svr;tyrone-cluster;Scheduler was sent the command recyc
06/03/2014 11:39:22;0040;PBS_Server;Svr;tyrone-cluster;Scheduler was sent the command new
06/03/2014 11:39:22;0008;PBS_Server;Job;39312.tyrone-cluster;Job Modified at request of Scheduler@tyrone-cluster
06/03/2014 11:39:42;0100;PBS_Server;Job;39321.tyrone-cluster;enqueuing into batch, state 1 hop 1
06/03/2014 11:39:42;0100;PBS_Server;Job;39321.tyrone-cluster;dequeuing from batch, state QUEUED
06/03/2014 11:39:42;0100;PBS_Server;Job;39321.tyrone-cluster;enqueuing into qp256, state 1 hop 1
06/03/2014 11:39:42;0008;PBS_Server;Job;39321.tyrone-cluster;Job Queued at request of secbadar@tyrone-cluster, owner = secbadar@tyrone-cluster, job name = job646USGp, queue = qp256
06/03/2014 11:39:42;0040;PBS_Server;Svr;tyrone-cluster;Scheduler was sent the command new
06/03/2014 11:39:42;0008;PBS_Server;Job;39321.tyrone-cluster;Job Modified at request of Scheduler@tyrone-cluster
06/03/2014 11:39:52;0040;PBS_Server;Svr;tyrone-cluster;Scheduler was sent the command new
06/03/2014 11:40:01;000d;PBS_Server;Job;39320.tyrone-cluster;Not sending email: User does not want mail of this type.
06/03/2014 11:40:25;0040;PBS_Server;Svr;tyrone-cluster;Scheduler was sent the command new
06/03/2014 11:40:57;0002;PBS_Server;Svr;PBS_Server;Torque Server Version = 3.0.5, loglevel = 0
06/03/2014 11:40:57;0040;PBS_Server;Svr;tyrone-cluster;Scheduler was sent the command new
06/03/2014 11:41:31;0040;PBS_Server;Svr;tyrone-cluster;Scheduler was sent the command new
06/03/2014 11:41:38;0100;PBS_Server;Job;39322.tyrone-cluster;enqueuing into batch, state 1 hop 1
06/03/2014 11:41:38;0008;PBS_Server;Job;39322.tyrone-cluster;Job Queued at request of secbadar@tyrone-cluster, owner = secbadar@tyrone-cluster, job name = job646USGp, queue = batch
06/03/2014 11:41:38;0040;PBS_Server;Svr;tyrone-cluster;Scheduler was sent the command new
06/03/2014 11:41:38;0008;PBS_Server;Job;39322.tyrone-cluster;Job Modified at request of Scheduler@tyrone-cluster
06/03/2014 11:41:43;0008;PBS_Server;Job;39322.tyrone-cluster;Job deleted at request of secbadar@tyrone-cluster
06/03/2014 11:41:43;0008;PBS_Server;Job;NULL;on_job_exit valid pjob: 0x1713730 (substate=59)
06/03/2014 11:41:43;0100;PBS_Server;Job;39322.tyrone-cluster;dequeuing from batch, state COMPLETE
06/03/2014 11:41:43;0040;PBS_Server;Svr;tyrone-cluster;Scheduler was sent the command term
06/03/2014 11:42:08;0040;PBS_Server;Svr;tyrone-cluster;Scheduler was sent the command new
06/03/2014 11:42:14;000d;PBS_Server;Job;39320.tyrone-cluster;Not sending email: User does not want mail of this type.
06/03/2014 11:42:14;0010;PBS_Server;Job;39320.tyrone-cluster;Exit_status=255 resources_used.cput=00:00:00 resources_used.mem=183432kb resources_used.vmem=6970556kb resources_used.walltime=00:03:04
06/03/2014 11:42:14;0008;PBS_Server;Job;NULL;on_job_exit valid pjob: 0x177dbb0 (substate=50)
06/03/2014 11:42:14;0008;PBS_Server;Job;NULL;on_job_exit valid pjob: 0x177dbb0 (substate=51)
06/03/2014 11:42:14;0008;PBS_Server;Job;NULL;on_job_exit valid pjob: 0x177dbb0 (substate=51)
06/03/2014 11:42:14;0008;PBS_Server;Job;NULL;on_job_exit valid pjob: 0x177dbb0 (substate=53)
06/03/2014 11:42:14;0100;PBS_Server;Job;39320.tyrone-cluster;dequeuing from qp256, state COMPLETE
06/03/2014 11:42:14;0040;PBS_Server;Svr;tyrone-cluster;Scheduler was sent the command term
06/03/2014 11:42:14;0008;PBS_Server;Job;39312.tyrone-cluster;Job Modified at request of Scheduler@tyrone-cluster
06/03/2014 11:42:14;0008;PBS_Server;Job;39321.tyrone-cluster;Job Modified at request of Scheduler@tyrone-cluster
06/03/2014 11:42:14;0008;PBS_Server;Job;39321.tyrone-cluster;Job Run at request of Scheduler@tyrone-cluster
06/03/2014 11:42:14;0040;PBS_Server;Svr;tyrone-cluster;Scheduler was sent the command recyc
06/03/2014 11:42:40;0040;PBS_Server;Svr;tyrone-cluster;Scheduler was sent the command new
06/03/2014 11:42:40;0008;PBS_Server;Job;39312.tyrone-cluster;Job Modified at request of Scheduler@tyrone-cluster
06/03/2014 11:42:48;0100;PBS_Server;Job;39323.tyrone-cluster;enqueuing into batch, state 1 hop 1
06/03/2014 11:42:48;0100;PBS_Server;Job;39323.tyrone-cluster;dequeuing from batch, state QUEUED
06/03/2014 11:42:48;0100;PBS_Server;Job;39323.tyrone-cluster;enqueuing into qp256, state 1 hop 1
06/03/2014 11:42:48;0008;PBS_Server;Job;39323.tyrone-cluster;Job Queued at request of secbadar@tyrone-cluster, owner = secbadar@tyrone-cluster, job name = jobpMpi6USGp, queue = qp256
06/03/2014 11:42:48;0040;PBS_Server;Svr;tyrone-cluster;Scheduler was sent the command new
06/03/2014 11:42:48;0008;PBS_Server;Job;39323.tyrone-cluster;Job Modified at request of Scheduler@tyrone-cluster
06/03/2014 11:43:03;000d;PBS_Server;Job;39321.tyrone-cluster;Not sending email: User does not want mail of this type.
06/03/2014 11:43:11;0040;PBS_Server;Svr;tyrone-cluster;Scheduler was sent the command new
06/03/2014 11:43:48;0040;PBS_Server;Svr;tyrone-cluster;Scheduler was sent the command new
06/03/2014 11:44:23;0040;PBS_Server;Svr;tyrone-cluster;Scheduler was sent the command new
06/03/2014 11:44:41;0008;PBS_Server;Job;39323.tyrone-cluster;Job deleted at request of secbadar@tyrone-cluster
06/03/2014 11:44:41;0008;PBS_Server;Job;NULL;on_job_exit valid pjob: 0x177dbb0 (substate=59)
06/03/2014 11:44:41;0100;PBS_Server;Job;39323.tyrone-cluster;dequeuing from qp256, state COMPLETE
06/03/2014 11:44:41;0040;PBS_Server;Svr;tyrone-cluster;Scheduler was sent the command term
06/03/2014 11:44:47;000d;PBS_Server;Job;39321.tyrone-cluster;Not sending email: User does not want mail of this type.
06/03/2014 11:44:47;0010;PBS_Server;Job;39321.tyrone-cluster;Exit_status=0 resources_used.cput=00:00:00 resources_used.mem=100804kb resources_used.vmem=3207004kb resources_used.walltime=00:02:33
06/03/2014 11:44:47;0008;PBS_Server;Job;NULL;on_job_exit valid pjob: 0x1724940 (substate=50)
06/03/2014 11:44:47;0008;PBS_Server;Job;NULL;on_job_exit valid pjob: 0x1724940 (substate=51)
06/03/2014 11:44:47;0008;PBS_Server;Job;NULL;on_job_exit valid pjob: 0x1724940 (substate=51)
06/03/2014 11:44:47;0008;PBS_Server;Job;NULL;on_job_exit valid pjob: 0x1724940 (substate=53)
06/03/2014 11:44:47;0100;PBS_Server;Job;39321.tyrone-cluster;dequeuing from qp256, state COMPLETE
06/03/2014 11:44:47;0040;PBS_Server;Svr;tyrone-cluster;Scheduler was sent the command term
06/03/2014 11:44:47;0008;PBS_Server;Job;39312.tyrone-cluster;Job Modified at request of Scheduler@tyrone-cluster
06/03/2014 11:44:55;0040;PBS_Server;Svr;tyrone-cluster;Scheduler was sent the command new
06/03/2014 11:45:28;0040;PBS_Server;Svr;tyrone-cluster;Scheduler was sent the command new
06/03/2014 11:45:57;0002;PBS_Server;Svr;PBS_Server;Torque Server Version = 3.0.5, loglevel = 0
06/03/2014 11:45:57;0040;PBS_Server;Svr;tyrone-cluster;Scheduler was sent the command new
06/03/2014 11:46:26;0040;PBS_Server;Svr;tyrone-cluster;Scheduler was sent the command new
06/03/2014 11:46:59;0040;PBS_Server;Svr;tyrone-cluster;Scheduler was sent the command new
06/03/2014 11:47:13;0100;PBS_Server;Job;39324.tyrone-cluster;enqueuing into batch, state 1 hop 1
06/03/2014 11:47:13;0100;PBS_Server;Job;39324.tyrone-cluster;dequeuing from batch, state QUEUED
06/03/2014 11:47:13;0100;PBS_Server;Job;39324.tyrone-cluster;enqueuing into qp256, state 1 hop 1
06/03/2014 11:47:13;0008;PBS_Server;Job;39324.tyrone-cluster;Job Queued at request of secbadar@tyrone-cluster, owner = secbadar@tyrone-cluster, job name = job1286USp, queue = qp256
06/03/2014 11:47:13;0040;PBS_Server;Svr;tyrone-cluster;Scheduler was sent the command new
06/03/2014 11:47:13;0008;PBS_Server;Job;39324.tyrone-cluster;Job Modified at request of Scheduler@tyrone-cluster
06/03/2014 11:47:13;0008;PBS_Server;Job;39324.tyrone-cluster;Job Run at request of Scheduler@tyrone-cluster
06/03/2014 11:47:13;0040;PBS_Server;Svr;tyrone-cluster;Scheduler was sent the command recyc
06/03/2014 11:47:19;0100;PBS_Server;Job;39325.tyrone-cluster;enqueuing into batch, state 1 hop 1
06/03/2014 11:47:19;0100;PBS_Server;Job;39325.tyrone-cluster;dequeuing from batch, state QUEUED
06/03/2014 11:47:19;0100;PBS_Server;Job;39325.tyrone-cluster;enqueuing into qp256, state 1 hop 1
06/03/2014 11:47:19;0008;PBS_Server;Job;39325.tyrone-cluster;Job Queued at request of secbadar@tyrone-cluster, owner = secbadar@tyrone-cluster, job name = job646USGp, queue = qp256
06/03/2014 11:47:19;0040;PBS_Server;Svr;tyrone-cluster;Scheduler was sent the command new
06/03/2014 11:47:19;0008;PBS_Server;Job;39312.tyrone-cluster;Job Modified at request of Scheduler@tyrone-cluster
06/03/2014 11:47:19;0008;PBS_Server;Job;39325.tyrone-cluster;Job Modified at request of Scheduler@tyrone-cluster
06/03/2014 11:47:28;0040;PBS_Server;Svr;tyrone-cluster;Scheduler was sent the command new
06/03/2014 11:48:01;0040;PBS_Server;Svr;tyrone-cluster;Scheduler was sent the command new
06/03/2014 11:48:23;000d;PBS_Server;Job;39324.tyrone-cluster;Not sending email: User does not want mail of this type.
06/03/2014 11:48:31;0040;PBS_Server;Svr;tyrone-cluster;Scheduler was sent the command new
06/03/2014 11:49:06;0040;PBS_Server;Svr;tyrone-cluster;Scheduler was sent the command new
06/03/2014 11:49:38;0040;PBS_Server;Svr;tyrone-cluster;Scheduler was sent the command new
06/03/2014 11:50:08;0040;PBS_Server;Svr;tyrone-cluster;Scheduler was sent the command new
06/03/2014 11:50:38;0040;PBS_Server;Svr;tyrone-cluster;Scheduler was sent the command new
06/03/2014 11:50:51;0100;PBS_Server;Job;39326.tyrone-cluster;enqueuing into batch, state 1 hop 1
06/03/2014 11:50:51;0008;PBS_Server;Job;39326.tyrone-cluster;Job Queued at request of secbadar@tyrone-cluster, owner = secbadar@tyrone-cluster, job name = job1285USGp, queue = batch
06/03/2014 11:50:51;0040;PBS_Server;Svr;tyrone-cluster;Scheduler was sent the command new
06/03/2014 11:50:51;0008;PBS_Server;Job;39326.tyrone-cluster;Job Modified at request of Scheduler@tyrone-cluster
06/03/2014 11:50:57;0002;PBS_Server;Svr;PBS_Server;Torque Server Version = 3.0.5, loglevel = 0
06/03/2014 11:51:08;0040;PBS_Server;Svr;tyrone-cluster;Scheduler was sent the command new
06/03/2014 11:51:22;0040;PBS_Server;Svr;tyrone-cluster;Scheduler was sent the command new
06/03/2014 11:51:40;0040;PBS_Server;Svr;tyrone-cluster;Scheduler was sent the command new
06/03/2014 11:51:51;0040;PBS_Server;Svr;tyrone-cluster;Scheduler was sent the command new
06/03/2014 11:52:13;0040;PBS_Server;Svr;tyrone-cluster;Scheduler was sent the command new
06/03/2014 11:52:26;0040;PBS_Server;Svr;tyrone-cluster;Scheduler was sent the command new
06/03/2014 11:52:51;0040;PBS_Server;Svr;tyrone-cluster;Scheduler was sent the command new
06/03/2014 11:52:55;0040;PBS_Server;Svr;tyrone-cluster;Scheduler was sent the command new
06/03/2014 11:52:55;000d;PBS_Server;Job;39324.tyrone-cluster;Not sending email: User does not want mail of this type.
06/03/2014 11:52:55;0010;PBS_Server;Job;39324.tyrone-cluster;Exit_status=0 resources_used.cput=00:13:52 resources_used.mem=40832136kb resources_used.vmem=54329620kb resources_used.walltime=00:05:42
06/03/2014 11:52:55;0008;PBS_Server;Job;NULL;on_job_exit valid pjob: 0x177dbb0 (substate=50)
06/03/2014 11:52:55;0008;PBS_Server;Job;NULL;on_job_exit valid pjob: 0x177dbb0 (substate=51)
06/03/2014 11:52:55;0008;PBS_Server;Job;39312.tyrone-cluster;Job Modified at request of Scheduler@tyrone-cluster
06/03/2014 11:52:55;0008;PBS_Server;Job;39325.tyrone-cluster;Job Modified at request of Scheduler@tyrone-cluster
06/03/2014 11:52:55;0008;PBS_Server;Job;NULL;on_job_exit valid pjob: 0x177dbb0 (substate=51)
06/03/2014 11:52:55;0008;PBS_Server;Job;NULL;on_job_exit valid pjob: 0x177dbb0 (substate=53)
06/03/2014 11:52:55;0100;PBS_Server;Job;39324.tyrone-cluster;dequeuing from qp256, state COMPLETE
06/03/2014 11:52:55;0040;PBS_Server;Svr;tyrone-cluster;Scheduler was sent the command term
06/03/2014 11:52:55;0008;PBS_Server;Job;39325.tyrone-cluster;Job Modified at request of Scheduler@tyrone-cluster
06/03/2014 11:52:55;0008;PBS_Server;Job;39325.tyrone-cluster;Job Run at request of Scheduler@tyrone-cluster
06/03/2014 11:52:55;0040;PBS_Server;Svr;tyrone-cluster;Scheduler was sent the command recyc
06/03/2014 11:53:23;0040;PBS_Server;Svr;tyrone-cluster;Scheduler was sent the command new
06/03/2014 11:53:23;0008;PBS_Server;Job;39312.tyrone-cluster;Job Modified at request of Scheduler@tyrone-cluster
06/03/2014 11:53:26;0100;PBS_Server;Job;39326.tyrone-cluster;dequeuing from batch, state QUEUED
06/03/2014 11:53:26;0100;PBS_Server;Job;39326.tyrone-cluster;enqueuing into qp256, state 1 hop 1
06/03/2014 11:53:36;0040;PBS_Server;Svr;tyrone-cluster;Scheduler was sent the command new
06/03/2014 11:53:36;0008;PBS_Server;Job;39326.tyrone-cluster;Job Modified at request of Scheduler@tyrone-cluster
06/03/2014 11:53:40;000d;PBS_Server;Job;39325.tyrone-cluster;Not sending email: User does not want mail of this type.
06/03/2014 11:53:55;0040;PBS_Server;Svr;tyrone-cluster;Scheduler was sent the command new
06/03/2014 11:54:25;0040;PBS_Server;Svr;tyrone-cluster;Scheduler was sent the command new
06/03/2014 11:55:06;0040;PBS_Server;Svr;tyrone-cluster;Scheduler was sent the command new
06/03/2014 11:55:38;0040;PBS_Server;Svr;tyrone-cluster;Scheduler was sent the command new
06/03/2014 11:55:57;0002;PBS_Server;Svr;PBS_Server;Torque Server Version = 3.0.5, loglevel = 0
06/03/2014 11:56:11;0040;PBS_Server;Svr;tyrone-cluster;Scheduler was sent the command new
06/03/2014 11:56:40;0040;PBS_Server;Svr;tyrone-cluster;Scheduler was sent the command new
06/03/2014 11:56:53;0100;PBS_Server;Job;39327.tyrone-cluster;enqueuing into batch, state 1 hop 1
06/03/2014 11:56:53;0100;PBS_Server;Job;39327.tyrone-cluster;dequeuing from batch, state QUEUED
06/03/2014 11:56:53;0100;PBS_Server;Job;39327.tyrone-cluster;enqueuing into idqueue, state 1 hop 1
06/03/2014 11:56:53;0008;PBS_Server;Job;39327.tyrone-cluster;Job Queued at request of secpka@tyrone-cluster, owner = secpka@tyrone-cluster, job name = jobname, queue = idqueue
06/03/2014 11:56:53;0040;PBS_Server;Svr;tyrone-cluster;Scheduler was sent the command new
06/03/2014 11:56:54;0008;PBS_Server;Job;39327.tyrone-cluster;Job Modified at request of Scheduler@tyrone-cluster
06/03/2014 11:56:54;0008;PBS_Server;Job;39327.tyrone-cluster;Job Run at request of Scheduler@tyrone-cluster
06/03/2014 11:56:54;0040;PBS_Server;Svr;tyrone-cluster;Scheduler was sent the command recyc
06/03/2014 11:56:54;000d;PBS_Server;Job;39327.tyrone-cluster;Not sending email: User does not want mail of this type.
06/03/2014 11:57:18;0040;PBS_Server;Svr;tyrone-cluster;Scheduler was sent the command new
06/03/2014 11:57:51;0040;PBS_Server;Svr;tyrone-cluster;Scheduler was sent the command new
06/03/2014 11:57:51;000d;PBS_Server;Job;39325.tyrone-cluster;Not sending email: User does not want mail of this type.
06/03/2014 11:57:51;0010;PBS_Server;Job;39325.tyrone-cluster;Exit_status=0 resources_used.cput=00:08:28 resources_used.mem=9547088kb resources_used.vmem=11596224kb resources_used.walltime=00:04:56
06/03/2014 11:57:51;0008;PBS_Server;Job;NULL;on_job_exit valid pjob: 0x1724940 (substate=50)
06/03/2014 11:57:51;0008;PBS_Server;Job;NULL;on_job_exit valid pjob: 0x1724940 (substate=51)
06/03/2014 11:57:51;0008;PBS_Server;Job;NULL;on_job_exit valid pjob: 0x1724940 (substate=51)
06/03/2014 11:57:51;0008;PBS_Server;Job;NULL;on_job_exit valid pjob: 0x1724940 (substate=53)
06/03/2014 11:57:51;0100;PBS_Server;Job;39325.tyrone-cluster;dequeuing from qp256, state COMPLETE
06/03/2014 11:57:51;0008;PBS_Server;Job;39312.tyrone-cluster;Job Modified at request of Scheduler@tyrone-cluster
06/03/2014 11:57:51;0008;PBS_Server;Job;39326.tyrone-cluster;Job Modified at request of Scheduler@tyrone-cluster
06/03/2014 11:57:51;0008;PBS_Server;Job;39326.tyrone-cluster;Job Run at request of Scheduler@tyrone-cluster
06/03/2014 11:57:51;0040;PBS_Server;Svr;tyrone-cluster;Scheduler was sent the command recyc
06/03/2014 11:58:25;0040;PBS_Server;Svr;tyrone-cluster;Scheduler was sent the command new
06/03/2014 11:58:25;0008;PBS_Server;Job;39312.tyrone-cluster;Job Modified at request of Scheduler@tyrone-cluster
06/03/2014 11:58:55;0040;PBS_Server;Svr;tyrone-cluster;Scheduler was sent the command new
06/03/2014 11:58:57;000d;PBS_Server;Job;39326.tyrone-cluster;Not sending email: User does not want mail of this type.
06/03/2014 11:59:25;0040;PBS_Server;Svr;tyrone-cluster;Scheduler was sent the command new
06/03/2014 11:59:56;0040;PBS_Server;Svr;tyrone-cluster;Scheduler was sent the command new
06/03/2014 12:00:26;0040;PBS_Server;Svr;tyrone-cluster;Scheduler was sent the command new
06/03/2014 12:00:57;0002;PBS_Server;Svr;PBS_Server;Torque Server Version = 3.0.5, loglevel = 0
06/03/2014 12:00:57;0040;PBS_Server;Svr;tyrone-cluster;Scheduler was sent the command new
06/03/2014 12:01:29;0040;PBS_Server;Svr;tyrone-cluster;Scheduler was sent the command new
06/03/2014 12:01:57;0040;PBS_Server;Svr;tyrone-cluster;Scheduler was sent the command new
06/03/2014 12:02:32;0040;PBS_Server;Svr;tyrone-cluster;Scheduler was sent the command new
06/03/2014 12:02:32;0100;PBS_Server;Job;39328.tyrone-cluster;enqueuing into batch, state 1 hop 1
06/03/2014 12:02:32;0100;PBS_Server;Job;39328.tyrone-cluster;dequeuing from batch, state QUEUED
06/03/2014 12:02:32;0100;PBS_Server;Job;39328.tyrone-cluster;enqueuing into qp256, state 1 hop 1
06/03/2014 12:02:32;0008;PBS_Server;Job;39328.tyrone-cluster;Job Queued at request of secbadar@tyrone-cluster, owner = secbadar@tyrone-cluster, job name = job1286USp, queue = qp256
06/03/2014 12:02:32;0008;PBS_Server;Job;39328.tyrone-cluster;Job Modified at request of Scheduler@tyrone-cluster
06/03/2014 12:02:40;0008;PBS_Server;Job;39326.tyrone-cluster;Job deleted at request of secbadar@tyrone-cluster
06/03/2014 12:02:40;0008;PBS_Server;Job;39326.tyrone-cluster;Job sent signal SIGTERM on delete
06/03/2014 12:02:40;000d;PBS_Server;Job;39326.tyrone-cluster;Not sending email: User does not want mail of this type.
06/03/2014 12:02:40;0010;PBS_Server;Job;39326.tyrone-cluster;Exit_status=143 resources_used.cput=00:13:55 resources_used.mem=1520636kb resources_used.vmem=3466608kb resources_used.walltime=00:04:49
06/03/2014 12:02:40;0008;PBS_Server;Job;NULL;on_job_exit valid pjob: 0x1713730 (substate=50)
06/03/2014 12:02:40;0008;PBS_Server;Job;NULL;on_job_exit valid pjob: 0x1713730 (substate=51)
06/03/2014 12:02:40;0008;PBS_Server;Job;NULL;on_job_exit valid pjob: 0x1713730 (substate=51)
06/03/2014 12:02:40;0008;PBS_Server;Job;NULL;on_job_exit valid pjob: 0x1713730 (substate=53)
06/03/2014 12:02:40;0100;PBS_Server;Job;39326.tyrone-cluster;dequeuing from qp256, state COMPLETE
06/03/2014 12:02:40;0040;PBS_Server;Svr;tyrone-cluster;Scheduler was sent the command term
06/03/2014 12:02:40;0008;PBS_Server;Job;39312.tyrone-cluster;Job Modified at request of Scheduler@tyrone-cluster
06/03/2014 12:02:40;0008;PBS_Server;Job;39328.tyrone-cluster;Job Modified at request of Scheduler@tyrone-cluster
06/03/2014 12:02:40;0008;PBS_Server;Job;39328.tyrone-cluster;Job Run at request of Scheduler@tyrone-cluster
06/03/2014 12:02:40;0040;PBS_Server;Svr;tyrone-cluster;Scheduler was sent the command recyc
06/03/2014 12:02:45;0100;PBS_Server;Job;39329.tyrone-cluster;enqueuing into batch, state 1 hop 1
06/03/2014 12:02:45;0100;PBS_Server;Job;39329.tyrone-cluster;dequeuing from batch, state QUEUED
06/03/2014 12:02:45;0100;PBS_Server;Job;39329.tyrone-cluster;enqueuing into qp256, state 1 hop 1
06/03/2014 12:02:45;0008;PBS_Server;Job;39329.tyrone-cluster;Job Queued at request of secbadar@tyrone-cluster, owner = secbadar@tyrone-cluster, job name = job646USGp, queue = qp256
06/03/2014 12:02:45;0040;PBS_Server;Svr;tyrone-cluster;Scheduler was sent the command new
06/03/2014 12:02:45;0008;PBS_Server;Job;39312.tyrone-cluster;Job Modified at request of Scheduler@tyrone-cluster
06/03/2014 12:02:45;0008;PBS_Server;Job;39329.tyrone-cluster;Job Modified at request of Scheduler@tyrone-cluster
06/03/2014 12:02:47;000d;PBS_Server;Job;39328.tyrone-cluster;Not sending email: User does not want mail of this type.
06/03/2014 12:03:08;0040;PBS_Server;Svr;tyrone-cluster;Scheduler was sent the command new
06/03/2014 12:03:40;0040;PBS_Server;Svr;tyrone-cluster;Scheduler was sent the command new
06/03/2014 12:04:09;0100;PBS_Server;Job;39330.tyrone-cluster;enqueuing into batch, state 1 hop 1
06/03/2014 12:04:09;0008;PBS_Server;Job;39330.tyrone-cluster;Job Queued at request of secbadar@tyrone-cluster, owner = secbadar@tyrone-cluster, job name = job1285USGp, queue = batch
06/03/2014 12:04:09;0040;PBS_Server;Svr;tyrone-cluster;Scheduler was sent the command new
06/03/2014 12:04:09;0008;PBS_Server;Job;39330.tyrone-cluster;Job Modified at request of Scheduler@tyrone-cluster
06/03/2014 12:04:11;0040;PBS_Server;Svr;tyrone-cluster;Scheduler was sent the command new
06/03/2014 12:04:39;0040;PBS_Server;Svr;tyrone-cluster;Scheduler was sent the command new
06/03/2014 12:04:51;0040;PBS_Server;Svr;tyrone-cluster;Scheduler was sent the command new
06/03/2014 12:05:10;0040;PBS_Server;Svr;tyrone-cluster;Scheduler was sent the command new
06/03/2014 12:05:23;0040;PBS_Server;Svr;tyrone-cluster;Scheduler was sent the command new
06/03/2014 12:05:41;0040;PBS_Server;Svr;tyrone-cluster;Scheduler was sent the command new
06/03/2014 12:05:56;0040;PBS_Server;Svr;tyrone-cluster;Scheduler was sent the command new
06/03/2014 12:05:57;0002;PBS_Server;Svr;PBS_Server;Torque Server Version = 3.0.5, loglevel = 0
06/03/2014 12:06:21;0040;PBS_Server;Svr;tyrone-cluster;Scheduler was sent the command new
06/03/2014 12:06:28;0040;PBS_Server;Svr;tyrone-cluster;Scheduler was sent the command new
06/03/2014 12:06:53;0040;PBS_Server;Svr;tyrone-cluster;Scheduler was sent the command new
06/03/2014 12:07:06;0040;PBS_Server;Svr;tyrone-cluster;Scheduler was sent the command new
06/03/2014 12:07:25;0040;PBS_Server;Svr;tyrone-cluster;Scheduler was sent the command new
06/03/2014 12:07:38;0040;PBS_Server;Svr;tyrone-cluster;Scheduler was sent the command new
06/03/2014 12:07:58;0040;PBS_Server;Svr;tyrone-cluster;Scheduler was sent the command new
06/03/2014 12:08:10;0040;PBS_Server;Svr;tyrone-cluster;Scheduler was sent the command new
06/03/2014 12:08:17;000d;PBS_Server;Job;39328.tyrone-cluster;Not sending email: User does not want mail of this type.
06/03/2014 12:08:17;0010;PBS_Server;Job;39328.tyrone-cluster;Exit_status=0 resources_used.cput=00:08:23 resources_used.mem=14507216kb resources_used.vmem=19103988kb resources_used.walltime=00:05:36
06/03/2014 12:08:17;0008;PBS_Server;Job;NULL;on_job_exit valid pjob: 0x1724940 (substate=50)
06/03/2014 12:08:17;0008;PBS_Server;Job;NULL;on_job_exit valid pjob: 0x1724940 (substate=51)
06/03/2014 12:08:17;0008;PBS_Server;Job;NULL;on_job_exit valid pjob: 0x1724940 (substate=51)
06/03/2014 12:08:17;0008;PBS_Server;Job;NULL;on_job_exit valid pjob: 0x1724940 (substate=53)
06/03/2014 12:08:17;0100;PBS_Server;Job;39328.tyrone-cluster;dequeuing from qp256, state COMPLETE
06/03/2014 12:08:17;0040;PBS_Server;Svr;tyrone-cluster;Scheduler was sent the command term
06/03/2014 12:08:17;0008;PBS_Server;Job;39312.tyrone-cluster;Job Modified at request of Scheduler@tyrone-cluster
06/03/2014 12:08:17;0008;PBS_Server;Job;39329.tyrone-cluster;Job Modified at request of Scheduler@tyrone-cluster
06/03/2014 12:08:17;0008;PBS_Server;Job;39329.tyrone-cluster;Job Run at request of Scheduler@tyrone-cluster
06/03/2014 12:08:17;0040;PBS_Server;Svr;tyrone-cluster;Scheduler was sent the command recyc
06/03/2014 12:08:26;0100;PBS_Server;Job;39330.tyrone-cluster;dequeuing from batch, state QUEUED
06/03/2014 12:08:26;0100;PBS_Server;Job;39330.tyrone-cluster;enqueuing into qp256, state 1 hop 1
06/03/2014 12:08:36;0040;PBS_Server;Svr;tyrone-cluster;Scheduler was sent the command new
06/03/2014 12:08:36;0008;PBS_Server;Job;39312.tyrone-cluster;Job Modified at request of Scheduler@tyrone-cluster
06/03/2014 12:08:36;0008;PBS_Server;Job;39330.tyrone-cluster;Job Modified at request of Scheduler@tyrone-cluster
06/03/2014 12:08:41;0040;PBS_Server;Svr;tyrone-cluster;Scheduler was sent the command new
06/03/2014 12:08:48;000d;PBS_Server;Job;39329.tyrone-cluster;Not sending email: User does not want mail of this type.
06/03/2014 12:09:20;0040;PBS_Server;Svr;tyrone-cluster;Scheduler was sent the command new
06/03/2014 12:09:20;000d;PBS_Server;Job;39327.tyrone-cluster;Not sending email: User does not want mail of this type.
06/03/2014 12:09:20;0010;PBS_Server;Job;39327.tyrone-cluster;Exit_status=0 resources_used.cput=01:51:50 resources_used.mem=130408kb resources_used.vmem=970624kb resources_used.walltime=00:12:26
06/03/2014 12:09:20;0008;PBS_Server;Job;NULL;on_job_exit valid pjob: 0x177dbb0 (substate=50)
06/03/2014 12:09:20;0008;PBS_Server;Job;NULL;on_job_exit valid pjob: 0x177dbb0 (substate=51)
06/03/2014 12:09:20;0008;PBS_Server;Job;NULL;on_job_exit valid pjob: 0x177dbb0 (substate=51)
06/03/2014 12:09:20;0008;PBS_Server;Job;NULL;on_job_exit valid pjob: 0x177dbb0 (substate=53)
06/03/2014 12:09:20;0100;PBS_Server;Job;39327.tyrone-cluster;dequeuing from idqueue, state COMPLETE
06/03/2014 12:09:20;0040;PBS_Server;Svr;tyrone-cluster;Scheduler was sent the command term
06/03/2014 12:09:53;0040;PBS_Server;Svr;tyrone-cluster;Scheduler was sent the command new
06/03/2014 12:10:25;0040;PBS_Server;Svr;tyrone-cluster;Scheduler was sent the command new
06/03/2014 12:10:55;0040;PBS_Server;Svr;tyrone-cluster;Scheduler was sent the command new
06/03/2014 12:10:57;0002;PBS_Server;Svr;PBS_Server;Torque Server Version = 3.0.5, loglevel = 0
06/03/2014 12:11:24;0040;PBS_Server;Svr;tyrone-cluster;Scheduler was sent the command new
06/03/2014 12:11:56;0040;PBS_Server;Svr;tyrone-cluster;Scheduler was sent the command new
06/03/2014 12:12:26;0040;PBS_Server;Svr;tyrone-cluster;Scheduler was sent the command new
06/03/2014 12:13:06;0040;PBS_Server;Svr;tyrone-cluster;Scheduler was sent the command new
06/03/2014 12:13:06;000d;PBS_Server;Job;39329.tyrone-cluster;Not sending email: User does not want mail of this type.
06/03/2014 12:13:06;0010;PBS_Server;Job;39329.tyrone-cluster;Exit_status=0 resources_used.cput=00:08:19 resources_used.mem=20436468kb resources_used.vmem=25811788kb resources_used.walltime=00:04:49
06/03/2014 12:13:06;0008;PBS_Server;Job;NULL;on_job_exit valid pjob: 0x1713730 (substate=50)
06/03/2014 12:13:06;0008;PBS_Server;Job;NULL;on_job_exit valid pjob: 0x1713730 (substate=51)
06/03/2014 12:13:06;0008;PBS_Server;Job;NULL;on_job_exit valid pjob: 0x1713730 (substate=51)
06/03/2014 12:13:06;0008;PBS_Server;Job;NULL;on_job_exit valid pjob: 0x1713730 (substate=53)
06/03/2014 12:13:06;0100;PBS_Server;Job;39329.tyrone-cluster;dequeuing from qp256, state COMPLETE
06/03/2014 12:13:06;0008;PBS_Server;Job;39312.tyrone-cluster;Job Modified at request of Scheduler@tyrone-cluster
06/03/2014 12:13:06;0008;PBS_Server;Job;39330.tyrone-cluster;Job Modified at request of Scheduler@tyrone-cluster
06/03/2014 12:13:06;0008;PBS_Server;Job;39330.tyrone-cluster;Job Run at request of Scheduler@tyrone-cluster
06/03/2014 12:13:06;0040;PBS_Server;Svr;tyrone-cluster;Scheduler was sent the command recyc
06/03/2014 12:13:20;000d;PBS_Server;Job;39330.tyrone-cluster;Not sending email: User does not want mail of this type.
06/03/2014 12:13:38;0040;PBS_Server;Svr;tyrone-cluster;Scheduler was sent the command new
06/03/2014 12:13:38;0008;PBS_Server;Job;39312.tyrone-cluster;Job Modified at request of Scheduler@tyrone-cluster
06/03/2014 12:14:11;0040;PBS_Server;Svr;tyrone-cluster;Scheduler was sent the command new
06/03/2014 12:14:44;0040;PBS_Server;Svr;tyrone-cluster;Scheduler was sent the command new
06/03/2014 12:14:46;0100;PBS_Server;Job;39331.tyrone-cluster;enqueuing into batch, state 1 hop 1
06/03/2014 12:14:46;0100;PBS_Server;Job;39331.tyrone-cluster;dequeuing from batch, state QUEUED
06/03/2014 12:14:46;0100;PBS_Server;Job;39331.tyrone-cluster;enqueuing into idqueue, state 1 hop 1
06/03/2014 12:14:46;0008;PBS_Server;Job;39331.tyrone-cluster;Job Queued at request of secpka@tyrone-cluster, owner = secpka@tyrone-cluster, job name = jobname, queue = idqueue
06/03/2014 12:14:46;0040;PBS_Server;Svr;tyrone-cluster;Scheduler was sent the command new
06/03/2014 12:14:46;0008;PBS_Server;Job;39331.tyrone-cluster;Job Modified at request of Scheduler@tyrone-cluster
06/03/2014 12:14:46;0008;PBS_Server;Job;39331.tyrone-cluster;Job Run at request of Scheduler@tyrone-cluster
06/03/2014 12:14:46;0040;PBS_Server;Svr;tyrone-cluster;Scheduler was sent the command recyc
06/03/2014 12:14:46;000d;PBS_Server;Job;39331.tyrone-cluster;Not sending email: User does not want mail of this type.
06/03/2014 12:14:47;000d;PBS_Server;Job;39331.tyrone-cluster;Not sending email: User does not want mail of this type.
06/03/2014 12:14:47;0010;PBS_Server;Job;39331.tyrone-cluster;Exit_status=0 resources_used.cput=00:00:01 resources_used.mem=0kb resources_used.vmem=0kb resources_used.walltime=00:00:00
06/03/2014 12:14:47;0008;PBS_Server;Job;NULL;on_job_exit valid pjob: 0x177dbb0 (substate=50)
06/03/2014 12:14:47;0008;PBS_Server;Job;NULL;on_job_exit valid pjob: 0x177dbb0 (substate=51)
06/03/2014 12:14:47;0008;PBS_Server;Job;NULL;on_job_exit valid pjob: 0x177dbb0 (substate=51)
06/03/2014 12:14:47;0008;PBS_Server;Job;NULL;on_job_exit valid pjob: 0x177dbb0 (substate=53)
06/03/2014 12:14:47;0100;PBS_Server;Job;39331.tyrone-cluster;dequeuing from idqueue, state COMPLETE
06/03/2014 12:14:47;0040;PBS_Server;Svr;tyrone-cluster;Scheduler was sent the command term
06/03/2014 12:15:21;0040;PBS_Server;Svr;tyrone-cluster;Scheduler was sent the command new
06/03/2014 12:15:44;0100;PBS_Server;Job;39332.tyrone-cluster;enqueuing into batch, state 1 hop 1
06/03/2014 12:15:44;0100;PBS_Server;Job;39332.tyrone-cluster;dequeuing from batch, state QUEUED
06/03/2014 12:15:44;0100;PBS_Server;Job;39332.tyrone-cluster;enqueuing into qp256, state 1 hop 1
06/03/2014 12:15:44;0008;PBS_Server;Job;39332.tyrone-cluster;Job Queued at request of secbadar@tyrone-cluster, owner = secbadar@tyrone-cluster, job name = job646USGp, queue = qp256
06/03/2014 12:15:44;0040;PBS_Server;Svr;tyrone-cluster;Scheduler was sent the command new
06/03/2014 12:15:44;0008;PBS_Server;Job;39332.tyrone-cluster;Job Modified at request of Scheduler@tyrone-cluster
06/03/2014 12:15:52;0040;PBS_Server;Svr;tyrone-cluster;Scheduler was sent the command new
06/03/2014 12:15:57;0002;PBS_Server;Svr;PBS_Server;Torque Server Version = 3.0.5, loglevel = 0
06/03/2014 12:16:25;0040;PBS_Server;Svr;tyrone-cluster;Scheduler was sent the command new
06/03/2014 12:16:32;0100;PBS_Server;Job;39333.tyrone-cluster;enqueuing into batch, state 1 hop 1
06/03/2014 12:16:32;0100;PBS_Server;Job;39333.tyrone-cluster;dequeuing from batch, state QUEUED
06/03/2014 12:16:32;0100;PBS_Server;Job;39333.tyrone-cluster;enqueuing into idqueue, state 1 hop 1
06/03/2014 12:16:32;0008;PBS_Server;Job;39333.tyrone-cluster;Job Queued at request of secpka@tyrone-cluster, owner = secpka@tyrone-cluster, job name = jobname, queue = idqueue
06/03/2014 12:16:32;0040;PBS_Server;Svr;tyrone-cluster;Scheduler was sent the command new
06/03/2014 12:16:32;0008;PBS_Server;Job;39333.tyrone-cluster;Job Modified at request of Scheduler@tyrone-cluster
06/03/2014 12:16:32;0008;PBS_Server;Job;39333.tyrone-cluster;Job Run at request of Scheduler@tyrone-cluster
06/03/2014 12:16:32;0040;PBS_Server;Svr;tyrone-cluster;Scheduler was sent the command recyc
06/03/2014 12:16:32;000d;PBS_Server;Job;39333.tyrone-cluster;Not sending email: User does not want mail of this type.
06/03/2014 12:16:40;000d;PBS_Server;Job;39333.tyrone-cluster;Not sending email: User does not want mail of this type.
06/03/2014 12:16:40;0010;PBS_Server;Job;39333.tyrone-cluster;Exit_status=0 resources_used.cput=00:01:09 resources_used.mem=125128kb resources_used.vmem=970624kb resources_used.walltime=00:00:08
06/03/2014 12:16:40;0008;PBS_Server;Job;NULL;on_job_exit valid pjob: 0x1724940 (substate=50)
06/03/2014 12:16:40;0008;PBS_Server;Job;NULL;on_job_exit valid pjob: 0x1724940 (substate=51)
06/03/2014 12:16:40;0008;PBS_Server;Job;NULL;on_job_exit valid pjob: 0x1724940 (substate=51)
06/03/2014 12:16:40;0008;PBS_Server;Job;NULL;on_job_exit valid pjob: 0x1724940 (substate=53)
06/03/2014 12:16:40;0100;PBS_Server;Job;39333.tyrone-cluster;dequeuing from idqueue, state COMPLETE
06/03/2014 12:16:40;0040;PBS_Server;Svr;tyrone-cluster;Scheduler was sent the command term
06/03/2014 12:16:52;0040;PBS_Server;Svr;tyrone-cluster;Scheduler was sent the command new
06/03/2014 12:17:23;0040;PBS_Server;Svr;tyrone-cluster;Scheduler was sent the command new
06/03/2014 12:17:56;0040;PBS_Server;Svr;tyrone-cluster;Scheduler was sent the command new
06/03/2014 12:18:26;0040;PBS_Server;Svr;tyrone-cluster;Scheduler was sent the command new
06/03/2014 12:18:53;0100;PBS_Server;Job;39334.tyrone-cluster;enqueuing into batch, state 1 hop 1
06/03/2014 12:18:53;0100;PBS_Server;Job;39334.tyrone-cluster;dequeuing from batch, state QUEUED
06/03/2014 12:18:53;0100;PBS_Server;Job;39334.tyrone-cluster;enqueuing into idqueue, state 1 hop 1
06/03/2014 12:18:53;0008;PBS_Server;Job;39334.tyrone-cluster;Job Queued at request of secpka@tyrone-cluster, owner = secpka@tyrone-cluster, job name = jobname, queue = idqueue
06/03/2014 12:18:53;0040;PBS_Server;Svr;tyrone-cluster;Scheduler was sent the command new
06/03/2014 12:18:53;0008;PBS_Server;Job;39334.tyrone-cluster;Job Modified at request of Scheduler@tyrone-cluster
06/03/2014 12:18:53;0008;PBS_Server;Job;39334.tyrone-cluster;Job Run at request of Scheduler@tyrone-cluster
06/03/2014 12:18:53;0040;PBS_Server;Svr;tyrone-cluster;Scheduler was sent the command recyc
06/03/2014 12:18:53;000d;PBS_Server;Job;39334.tyrone-cluster;Not sending email: User does not want mail of this type.
06/03/2014 12:18:57;0040;PBS_Server;Svr;tyrone-cluster;Scheduler was sent the command new
06/03/2014 12:18:59;000d;PBS_Server;Job;39334.tyrone-cluster;Not sending email: User does not want mail of this type.
06/03/2014 12:18:59;0010;PBS_Server;Job;39334.tyrone-cluster;Exit_status=0 resources_used.cput=00:00:46 resources_used.mem=125004kb resources_used.vmem=970624kb resources_used.walltime=00:00:06
06/03/2014 12:18:59;0008;PBS_Server;Job;NULL;on_job_exit valid pjob: 0x1724940 (substate=50)
06/03/2014 12:18:59;0008;PBS_Server;Job;NULL;on_job_exit valid pjob: 0x1724940 (substate=51)
06/03/2014 12:18:59;0008;PBS_Server;Job;NULL;on_job_exit valid pjob: 0x1724940 (substate=51)
06/03/2014 12:18:59;0008;PBS_Server;Job;NULL;on_job_exit valid pjob: 0x1724940 (substate=53)
06/03/2014 12:18:59;0100;PBS_Server;Job;39334.tyrone-cluster;dequeuing from idqueue, state COMPLETE
06/03/2014 12:18:59;0040;PBS_Server;Svr;tyrone-cluster;Scheduler was sent the command term
06/03/2014 12:19:29;0040;PBS_Server;Svr;tyrone-cluster;Scheduler was sent the command new
06/03/2014 12:20:01;0040;PBS_Server;Svr;tyrone-cluster;Scheduler was sent the command new
06/03/2014 12:20:07;0100;PBS_Server;Job;39335.tyrone-cluster;enqueuing into batch, state 1 hop 1
06/03/2014 12:20:07;0100;PBS_Server;Job;39335.tyrone-cluster;dequeuing from batch, state QUEUED
06/03/2014 12:20:07;0100;PBS_Server;Job;39335.tyrone-cluster;enqueuing into idqueue, state 1 hop 1
06/03/2014 12:20:07;0008;PBS_Server;Job;39335.tyrone-cluster;Job Queued at request of secpka@tyrone-cluster, owner = secpka@tyrone-cluster, job name = jobname, queue = idqueue
06/03/2014 12:20:07;0040;PBS_Server;Svr;tyrone-cluster;Scheduler was sent the command new
06/03/2014 12:20:07;0008;PBS_Server;Job;39335.tyrone-cluster;Job Modified at request of Scheduler@tyrone-cluster
06/03/2014 12:20:07;0008;PBS_Server;Job;39335.tyrone-cluster;Job Run at request of Scheduler@tyrone-cluster
06/03/2014 12:20:07;0040;PBS_Server;Svr;tyrone-cluster;Scheduler was sent the command recyc
06/03/2014 12:20:07;000d;PBS_Server;Job;39335.tyrone-cluster;Not sending email: User does not want mail of this type.
06/03/2014 12:20:10;000d;PBS_Server;Job;39335.tyrone-cluster;Not sending email: User does not want mail of this type.
06/03/2014 12:20:10;0010;PBS_Server;Job;39335.tyrone-cluster;Exit_status=0 resources_used.cput=00:00:23 resources_used.mem=0kb resources_used.vmem=0kb resources_used.walltime=00:00:03
06/03/2014 12:20:10;0008;PBS_Server;Job;NULL;on_job_exit valid pjob: 0x1724940 (substate=50)
06/03/2014 12:20:10;0008;PBS_Server;Job;NULL;on_job_exit valid pjob: 0x1724940 (substate=51)
06/03/2014 12:20:10;0008;PBS_Server;Job;NULL;on_job_exit valid pjob: 0x1724940 (substate=51)
06/03/2014 12:20:10;0008;PBS_Server;Job;NULL;on_job_exit valid pjob: 0x1724940 (substate=53)
06/03/2014 12:20:10;0100;PBS_Server;Job;39335.tyrone-cluster;dequeuing from idqueue, state COMPLETE
06/03/2014 12:20:10;0040;PBS_Server;Svr;tyrone-cluster;Scheduler was sent the command term
06/03/2014 12:20:36;0040;PBS_Server;Svr;tyrone-cluster;Scheduler was sent the command new
06/03/2014 12:20:57;0002;PBS_Server;Svr;PBS_Server;Torque Server Version = 3.0.5, loglevel = 0
06/03/2014 12:21:08;0040;PBS_Server;Svr;tyrone-cluster;Scheduler was sent the command new
06/03/2014 12:21:41;0040;PBS_Server;Svr;tyrone-cluster;Scheduler was sent the command new
06/03/2014 12:22:11;0040;PBS_Server;Svr;tyrone-cluster;Scheduler was sent the command new
06/03/2014 12:22:35;0100;PBS_Server;Job;39336.tyrone-cluster;enqueuing into batch, state 1 hop 1
06/03/2014 12:22:35;0008;PBS_Server;Job;39336.tyrone-cluster;Job Queued at request of secbadar@tyrone-cluster, owner = secbadar@tyrone-cluster, job name = job128Uns, queue = batch
06/03/2014 12:22:35;0040;PBS_Server;Svr;tyrone-cluster;Scheduler was sent the command new
06/03/2014 12:22:35;0008;PBS_Server;Job;39336.tyrone-cluster;Job Modified at request of Scheduler@tyrone-cluster
06/03/2014 12:22:51;0040;PBS_Server;Svr;tyrone-cluster;Scheduler was sent the command new
06/03/2014 12:23:03;0008;PBS_Server;Job;39330.tyrone-cluster;Job deleted at request of secbadar@tyrone-cluster
06/03/2014 12:23:03;0008;PBS_Server;Job;39330.tyrone-cluster;Job sent signal SIGTERM on delete
06/03/2014 12:23:03;000d;PBS_Server;Job;39330.tyrone-cluster;Not sending email: User does not want mail of this type.
06/03/2014 12:23:03;0010;PBS_Server;Job;39330.tyrone-cluster;Exit_status=143 resources_used.cput=00:24:52 resources_used.mem=5606700kb resources_used.vmem=16231656kb resources_used.walltime=00:09:58
06/03/2014 12:23:03;0008;PBS_Server;Job;NULL;on_job_exit valid pjob: 0x1791590 (substate=50)
06/03/2014 12:23:03;0008;PBS_Server;Job;NULL;on_job_exit valid pjob: 0x1791590 (substate=51)
06/03/2014 12:23:03;0008;PBS_Server;Job;NULL;on_job_exit valid pjob: 0x1791590 (substate=51)
06/03/2014 12:23:03;0008;PBS_Server;Job;NULL;on_job_exit valid pjob: 0x1791590 (substate=53)
06/03/2014 12:23:03;0100;PBS_Server;Job;39330.tyrone-cluster;dequeuing from qp256, state COMPLETE
06/03/2014 12:23:03;0040;PBS_Server;Svr;tyrone-cluster;Scheduler was sent the command term
06/03/2014 12:23:03;0008;PBS_Server;Job;39312.tyrone-cluster;Job Modified at request of Scheduler@tyrone-cluster
06/03/2014 12:23:03;0008;PBS_Server;Job;39332.tyrone-cluster;Job Modified at request of Scheduler@tyrone-cluster
06/03/2014 12:23:03;0008;PBS_Server;Job;39332.tyrone-cluster;Job Run at request of Scheduler@tyrone-cluster
06/03/2014 12:23:03;0040;PBS_Server;Svr;tyrone-cluster;Scheduler was sent the command recyc
06/03/2014 12:23:05;0100;PBS_Server;Job;39336.tyrone-cluster;dequeuing from batch, state QUEUED
06/03/2014 12:23:05;0100;PBS_Server;Job;39336.tyrone-cluster;enqueuing into qp256, state 1 hop 1
06/03/2014 12:23:09;0040;PBS_Server;Svr;tyrone-cluster;Scheduler was sent the command new
06/03/2014 12:23:09;0008;PBS_Server;Job;39312.tyrone-cluster;Job Modified at request of Scheduler@tyrone-cluster
06/03/2014 12:23:09;0008;PBS_Server;Job;39336.tyrone-cluster;Job Modified at request of Scheduler@tyrone-cluster
06/03/2014 12:23:23;0040;PBS_Server;Svr;tyrone-cluster;Scheduler was sent the command new
06/03/2014 12:23:54;000d;PBS_Server;Job;39332.tyrone-cluster;Not sending email: User does not want mail of this type.
06/03/2014 12:23:54;0040;PBS_Server;Svr;tyrone-cluster;Scheduler was sent the command new
06/03/2014 12:24:26;0040;PBS_Server;Svr;tyrone-cluster;Scheduler was sent the command new
06/03/2014 12:25:07;0040;PBS_Server;Svr;tyrone-cluster;Scheduler was sent the command new
06/03/2014 12:25:38;0040;PBS_Server;Svr;tyrone-cluster;Scheduler was sent the command new
06/03/2014 12:25:48;0100;PBS_Server;Job;39337.tyrone-cluster;enqueuing into batch, state 1 hop 1
06/03/2014 12:25:48;0100;PBS_Server;Job;39337.tyrone-cluster;dequeuing from batch, state QUEUED
06/03/2014 12:25:48;0100;PBS_Server;Job;39337.tyrone-cluster;enqueuing into idqueue, state 1 hop 1
06/03/2014 12:25:48;0008;PBS_Server;Job;39337.tyrone-cluster;Job Queued at request of secpka@tyrone-cluster, owner = secpka@tyrone-cluster, job name = jobname, queue = idqueue
06/03/2014 12:25:48;0040;PBS_Server;Svr;tyrone-cluster;Scheduler was sent the command new
06/03/2014 12:25:48;0008;PBS_Server;Job;39337.tyrone-cluster;Job Modified at request of Scheduler@tyrone-cluster
06/03/2014 12:25:48;0008;PBS_Server;Job;39337.tyrone-cluster;Job Run at request of Scheduler@tyrone-cluster
06/03/2014 12:25:48;0040;PBS_Server;Svr;tyrone-cluster;Scheduler was sent the command recyc
06/03/2014 12:25:48;000d;PBS_Server;Job;39337.tyrone-cluster;Not sending email: User does not want mail of this type.
06/03/2014 12:25:57;0002;PBS_Server;Svr;PBS_Server;Torque Server Version = 3.0.5, loglevel = 0
06/03/2014 12:26:09;0040;PBS_Server;Svr;tyrone-cluster;Scheduler was sent the command new
06/03/2014 12:26:31;0100;PBS_Server;Job;39338.tyrone-cluster;enqueuing into batch, state 1 hop 1
06/03/2014 12:26:31;0008;PBS_Server;Job;39338.tyrone-cluster;Job Queued at request of secbadar@tyrone-cluster, owner = secbadar@tyrone-cluster, job name = jobpMpiGp, queue = batch
06/03/2014 12:26:31;0040;PBS_Server;Svr;tyrone-cluster;Scheduler was sent the command new
06/03/2014 12:26:31;0008;PBS_Server;Job;39338.tyrone-cluster;Job Modified at request of Scheduler@tyrone-cluster
06/03/2014 12:26:39;0040;PBS_Server;Svr;tyrone-cluster;Scheduler was sent the command new
06/03/2014 12:26:45;0100;PBS_Server;Job;39339.tyrone-cluster;enqueuing into batch, state 1 hop 1
06/03/2014 12:26:45;0008;PBS_Server;Job;39339.tyrone-cluster;Job Queued at request of secbadar@tyrone-cluster, owner = secbadar@tyrone-cluster, job name = job1285USGp, queue = batch
06/03/2014 12:26:45;0040;PBS_Server;Svr;tyrone-cluster;Scheduler was sent the command new
06/03/2014 12:26:45;0008;PBS_Server;Job;39339.tyrone-cluster;Job Modified at request of Scheduler@tyrone-cluster
06/03/2014 12:27:04;0040;PBS_Server;Svr;tyrone-cluster;Scheduler was sent the command new
06/03/2014 12:27:05;0100;PBS_Server;Job;39340.tyrone-cluster;enqueuing into batch, state 1 hop 1
06/03/2014 12:27:05;0008;PBS_Server;Job;39340.tyrone-cluster;Job Queued at request of secbadar@tyrone-cluster, owner = secbadar@tyrone-cluster, job name = job645USGp, queue = batch
06/03/2014 12:27:05;0040;PBS_Server;Svr;tyrone-cluster;Scheduler was sent the command new
06/03/2014 12:27:05;0008;PBS_Server;Job;39340.tyrone-cluster;Job Modified at request of Scheduler@tyrone-cluster
06/03/2014 12:27:06;0100;PBS_Server;Job;39341.tyrone-cluster;enqueuing into batch, state 1 hop 1
06/03/2014 12:27:06;0100;PBS_Server;Job;39341.tyrone-cluster;dequeuing from batch, state QUEUED
06/03/2014 12:27:06;0100;PBS_Server;Job;39341.tyrone-cluster;enqueuing into idqueue, state 1 hop 1
06/03/2014 12:27:06;0008;PBS_Server;Job;39341.tyrone-cluster;Job Queued at request of secpka@tyrone-cluster, owner = secpka@tyrone-cluster, job name = jobname, queue = idqueue
06/03/2014 12:27:06;0040;PBS_Server;Svr;tyrone-cluster;Scheduler was sent the command new
06/03/2014 12:27:06;0008;PBS_Server;Job;39341.tyrone-cluster;Job Modified at request of Scheduler@tyrone-cluster
06/03/2014 12:27:09;0040;PBS_Server;Svr;tyrone-cluster;Scheduler was sent the command new
06/03/2014 12:27:21;0040;PBS_Server;Svr;tyrone-cluster;Scheduler was sent the command new
06/03/2014 12:27:34;0040;PBS_Server;Svr;tyrone-cluster;Scheduler was sent the command new
06/03/2014 12:27:38;0040;PBS_Server;Svr;tyrone-cluster;Scheduler was sent the command new
06/03/2014 12:27:39;0040;PBS_Server;Svr;tyrone-cluster;Scheduler was sent the command new
06/03/2014 12:27:53;0040;PBS_Server;Svr;tyrone-cluster;Scheduler was sent the command new
06/03/2014 12:28:07;0040;PBS_Server;Svr;tyrone-cluster;Scheduler was sent the command new
06/03/2014 12:28:11;0040;PBS_Server;Svr;tyrone-cluster;Scheduler was sent the command new
06/03/2014 12:28:13;000d;PBS_Server;Job;39332.tyrone-cluster;Not sending email: User does not want mail of this type.
06/03/2014 12:28:13;0010;PBS_Server;Job;39332.tyrone-cluster;Exit_status=0 resources_used.cput=00:08:34 resources_used.mem=5118880kb resources_used.vmem=6632540kb resources_used.walltime=00:05:10
06/03/2014 12:28:13;0008;PBS_Server;Job;NULL;on_job_exit valid pjob: 0x177dbb0 (substate=50)
06/03/2014 12:28:13;0008;PBS_Server;Job;NULL;on_job_exit valid pjob: 0x177dbb0 (substate=51)
06/03/2014 12:28:13;0008;PBS_Server;Job;NULL;on_job_exit valid pjob: 0x177dbb0 (substate=51)
06/03/2014 12:28:13;0008;PBS_Server;Job;NULL;on_job_exit valid pjob: 0x177dbb0 (substate=53)
06/03/2014 12:28:13;0100;PBS_Server;Job;39332.tyrone-cluster;dequeuing from qp256, state COMPLETE
06/03/2014 12:28:13;0040;PBS_Server;Svr;tyrone-cluster;Scheduler was sent the command term
06/03/2014 12:28:13;0008;PBS_Server;Job;39312.tyrone-cluster;Job Modified at request of Scheduler@tyrone-cluster
06/03/2014 12:28:13;0008;PBS_Server;Job;39336.tyrone-cluster;Job Modified at request of Scheduler@tyrone-cluster
06/03/2014 12:28:13;0008;PBS_Server;Job;39336.tyrone-cluster;Job Run at request of Scheduler@tyrone-cluster
06/03/2014 12:28:13;0040;PBS_Server;Svr;tyrone-cluster;Scheduler was sent the command recyc
06/03/2014 12:28:16;000d;PBS_Server;Job;39336.tyrone-cluster;Not sending email: User does not want mail of this type.
06/03/2014 12:28:16;0010;PBS_Server;Job;39336.tyrone-cluster;Exit_status=255 resources_used.cput=00:00:00 resources_used.mem=800kb resources_used.vmem=13624kb resources_used.walltime=00:00:03
06/03/2014 12:28:16;0008;PBS_Server;Job;NULL;on_job_exit valid pjob: 0x1724940 (substate=50)
06/03/2014 12:28:16;0008;PBS_Server;Job;NULL;on_job_exit valid pjob: 0x1724940 (substate=51)
06/03/2014 12:28:16;0008;PBS_Server;Job;NULL;on_job_exit valid pjob: 0x1724940 (substate=51)
06/03/2014 12:28:16;0008;PBS_Server;Job;NULL;on_job_exit valid pjob: 0x1724940 (substate=53)
06/03/2014 12:28:16;0100;PBS_Server;Job;39336.tyrone-cluster;dequeuing from qp256, state COMPLETE
06/03/2014 12:28:16;0040;PBS_Server;Svr;tyrone-cluster;Scheduler was sent the command term
06/03/2014 12:28:24;0100;PBS_Server;Job;39339.tyrone-cluster;dequeuing from batch, state QUEUED
06/03/2014 12:28:24;0100;PBS_Server;Job;39339.tyrone-cluster;enqueuing into qp256, state 1 hop 1
06/03/2014 12:28:25;0040;PBS_Server;Svr;tyrone-cluster;Scheduler was sent the command new
06/03/2014 12:28:26;0008;PBS_Server;Job;39339.tyrone-cluster;Job Modified at request of Scheduler@tyrone-cluster
06/03/2014 12:28:26;0008;PBS_Server;Job;39339.tyrone-cluster;Job Run at request of Scheduler@tyrone-cluster
06/03/2014 12:28:26;0040;PBS_Server;Svr;tyrone-cluster;Scheduler was sent the command recyc
06/03/2014 12:28:38;0100;PBS_Server;Job;39338.tyrone-cluster;dequeuing from batch, state QUEUED
06/03/2014 12:28:38;0100;PBS_Server;Job;39338.tyrone-cluster;enqueuing into qp256, state 1 hop 1
06/03/2014 12:28:38;0040;PBS_Server;Svr;tyrone-cluster;Scheduler was sent the command new
06/03/2014 12:28:38;0008;PBS_Server;Job;39312.tyrone-cluster;Job Modified at request of Scheduler@tyrone-cluster
06/03/2014 12:28:38;0008;PBS_Server;Job;39338.tyrone-cluster;Job Modified at request of Scheduler@tyrone-cluster
06/03/2014 12:28:39;0040;PBS_Server;Svr;tyrone-cluster;Scheduler was sent the command new
06/03/2014 12:29:11;0040;PBS_Server;Svr;tyrone-cluster;Scheduler was sent the command new
06/03/2014 12:29:25;000d;PBS_Server;Job;39339.tyrone-cluster;Not sending email: User does not want mail of this type.
06/03/2014 12:29:41;0040;PBS_Server;Svr;tyrone-cluster;Scheduler was sent the command new
06/03/2014 12:29:58;0100;PBS_Server;Job;39342.tyrone-cluster;enqueuing into batch, state 1 hop 1
06/03/2014 12:29:58;0008;PBS_Server;Job;39342.tyrone-cluster;Job Queued at request of secbadar@tyrone-cluster, owner = secbadar@tyrone-cluster, job name = jobpMpiUns, queue = batch
06/03/2014 12:29:58;0040;PBS_Server;Svr;tyrone-cluster;Scheduler was sent the command new
06/03/2014 12:29:58;0008;PBS_Server;Job;39342.tyrone-cluster;Job Modified at request of Scheduler@tyrone-cluster
06/03/2014 12:30:01;0100;PBS_Server;Job;39343.tyrone-cluster;enqueuing into batch, state 1 hop 1
06/03/2014 12:30:01;0008;PBS_Server;Job;39343.tyrone-cluster;Job Queued at request of secbadar@tyrone-cluster, owner = secbadar@tyrone-cluster, job name = job128Uns, queue = batch
06/03/2014 12:30:01;0040;PBS_Server;Svr;tyrone-cluster;Scheduler was sent the command new
06/03/2014 12:30:02;0008;PBS_Server;Job;39343.tyrone-cluster;Job Modified at request of Scheduler@tyrone-cluster
06/03/2014 12:30:10;0040;PBS_Server;Svr;tyrone-cluster;Scheduler was sent the command new
06/03/2014 12:30:31;0040;PBS_Server;Svr;tyrone-cluster;Scheduler was sent the command new
06/03/2014 12:30:40;0040;PBS_Server;Svr;tyrone-cluster;Scheduler was sent the command new
06/03/2014 12:30:46;0008;PBS_Server;Job;39337.tyrone-cluster;Job deleted at request of secpka@tyrone-cluster
06/03/2014 12:30:46;0008;PBS_Server;Job;39337.tyrone-cluster;Job sent signal SIGTERM on delete
06/03/2014 12:30:47;000d;PBS_Server;Job;39337.tyrone-cluster;Not sending email: User does not want mail of this type.
06/03/2014 12:30:47;0010;PBS_Server;Job;39337.tyrone-cluster;Exit_status=143 resources_used.cput=00:39:00 resources_used.mem=131764kb resources_used.vmem=970624kb resources_used.walltime=00:04:59
06/03/2014 12:30:47;0008;PBS_Server;Job;NULL;on_job_exit valid pjob: 0x177bea0 (substate=50)
06/03/2014 12:30:47;0008;PBS_Server;Job;NULL;on_job_exit valid pjob: 0x177bea0 (substate=51)
06/03/2014 12:30:47;0008;PBS_Server;Job;NULL;on_job_exit valid pjob: 0x177bea0 (substate=51)
06/03/2014 12:30:47;0008;PBS_Server;Job;NULL;on_job_exit valid pjob: 0x177bea0 (substate=53)
06/03/2014 12:30:47;0100;PBS_Server;Job;39337.tyrone-cluster;dequeuing from idqueue, state COMPLETE
06/03/2014 12:30:47;0040;PBS_Server;Svr;tyrone-cluster;Scheduler was sent the command term
06/03/2014 12:30:47;0008;PBS_Server;Job;39341.tyrone-cluster;Job Modified at request of Scheduler@tyrone-cluster
06/03/2014 12:30:47;0008;PBS_Server;Job;39341.tyrone-cluster;Job Run at request of Scheduler@tyrone-cluster
06/03/2014 12:30:47;0040;PBS_Server;Svr;tyrone-cluster;Scheduler was sent the command recyc
06/03/2014 12:30:47;000d;PBS_Server;Job;39341.tyrone-cluster;Not sending email: User does not want mail of this type.
06/03/2014 12:30:48;000d;PBS_Server;Job;39341.tyrone-cluster;Not sending email: User does not want mail of this type.
06/03/2014 12:30:48;0010;PBS_Server;Job;39341.tyrone-cluster;Exit_status=0 resources_used.cput=00:00:02 resources_used.mem=0kb resources_used.vmem=0kb resources_used.walltime=00:00:01
06/03/2014 12:30:48;0008;PBS_Server;Job;NULL;on_job_exit valid pjob: 0x17a1940 (substate=50)
06/03/2014 12:30:48;0008;PBS_Server;Job;NULL;on_job_exit valid pjob: 0x17a1940 (substate=51)
06/03/2014 12:30:48;0008;PBS_Server;Job;NULL;on_job_exit valid pjob: 0x17a1940 (substate=51)
06/03/2014 12:30:48;0008;PBS_Server;Job;NULL;on_job_exit valid pjob: 0x17a1940 (substate=53)
06/03/2014 12:30:48;0100;PBS_Server;Job;39341.tyrone-cluster;dequeuing from idqueue, state COMPLETE
06/03/2014 12:30:48;0040;PBS_Server;Svr;tyrone-cluster;Scheduler was sent the command term
06/03/2014 12:30:57;0002;PBS_Server;Svr;PBS_Server;Torque Server Version = 3.0.5, loglevel = 0
06/03/2014 12:31:07;0040;PBS_Server;Svr;tyrone-cluster;Scheduler was sent the command new
06/03/2014 12:31:10;0040;PBS_Server;Svr;tyrone-cluster;Scheduler was sent the command new
06/03/2014 12:31:38;0040;PBS_Server;Svr;tyrone-cluster;Scheduler was sent the command new
06/03/2014 12:31:40;0040;PBS_Server;Svr;tyrone-cluster;Scheduler was sent the command new
06/03/2014 12:32:10;0040;PBS_Server;Svr;tyrone-cluster;Scheduler was sent the command new
06/03/2014 12:32:40;0040;PBS_Server;Svr;tyrone-cluster;Scheduler was sent the command new
06/03/2014 12:32:48;0100;PBS_Server;Job;39344.tyrone-cluster;enqueuing into batch, state 1 hop 1
06/03/2014 12:32:48;0100;PBS_Server;Job;39344.tyrone-cluster;dequeuing from batch, state QUEUED
06/03/2014 12:32:48;0100;PBS_Server;Job;39344.tyrone-cluster;enqueuing into idqueue, state 1 hop 1
06/03/2014 12:32:48;0008;PBS_Server;Job;39344.tyrone-cluster;Job Queued at request of secpka@tyrone-cluster, owner = secpka@tyrone-cluster, job name = jobname, queue = idqueue
06/03/2014 12:32:48;0040;PBS_Server;Svr;tyrone-cluster;Scheduler was sent the command new
06/03/2014 12:32:49;0008;PBS_Server;Job;39344.tyrone-cluster;Job Modified at request of Scheduler@tyrone-cluster
06/03/2014 12:32:49;0008;PBS_Server;Job;39344.tyrone-cluster;Job Run at request of Scheduler@tyrone-cluster
06/03/2014 12:32:49;0040;PBS_Server;Svr;tyrone-cluster;Scheduler was sent the command recyc
06/03/2014 12:32:49;000d;PBS_Server;Job;39344.tyrone-cluster;Not sending email: User does not want mail of this type.
06/03/2014 12:32:56;000d;PBS_Server;Job;39344.tyrone-cluster;Not sending email: User does not want mail of this type.
06/03/2014 12:32:56;0010;PBS_Server;Job;39344.tyrone-cluster;Exit_status=0 resources_used.cput=00:00:58 resources_used.mem=0kb resources_used.vmem=0kb resources_used.walltime=00:00:07
06/03/2014 12:32:56;0008;PBS_Server;Job;NULL;on_job_exit valid pjob: 0x177bea0 (substate=50)
06/03/2014 12:32:56;0008;PBS_Server;Job;NULL;on_job_exit valid pjob: 0x177bea0 (substate=51)
06/03/2014 12:32:56;0008;PBS_Server;Job;NULL;on_job_exit valid pjob: 0x177bea0 (substate=51)
06/03/2014 12:32:56;0008;PBS_Server;Job;NULL;on_job_exit valid pjob: 0x177bea0 (substate=53)
06/03/2014 12:32:56;0100;PBS_Server;Job;39344.tyrone-cluster;dequeuing from idqueue, state COMPLETE
06/03/2014 12:32:56;0040;PBS_Server;Svr;tyrone-cluster;Scheduler was sent the command term
06/03/2014 12:33:09;0040;PBS_Server;Svr;tyrone-cluster;Scheduler was sent the command new
06/03/2014 12:33:10;0040;PBS_Server;Svr;tyrone-cluster;Scheduler was sent the command new
06/03/2014 12:33:41;0040;PBS_Server;Svr;tyrone-cluster;Scheduler was sent the command new
06/03/2014 12:34:14;0040;PBS_Server;Svr;tyrone-cluster;Scheduler was sent the command new
06/03/2014 12:34:40;0040;PBS_Server;Svr;tyrone-cluster;Scheduler was sent the command new
06/03/2014 12:35:10;0040;PBS_Server;Svr;tyrone-cluster;Scheduler was sent the command new
06/03/2014 12:35:44;0040;PBS_Server;Svr;tyrone-cluster;Scheduler was sent the command new
06/03/2014 12:35:57;0002;PBS_Server;Svr;PBS_Server;Torque Server Version = 3.0.5, loglevel = 0
06/03/2014 12:36:10;0040;PBS_Server;Svr;tyrone-cluster;Scheduler was sent the command new
06/03/2014 12:36:41;0040;PBS_Server;Svr;tyrone-cluster;Scheduler was sent the command new
06/03/2014 12:37:11;0040;PBS_Server;Svr;tyrone-cluster;Scheduler was sent the command new
06/03/2014 12:37:40;0040;PBS_Server;Svr;tyrone-cluster;Scheduler was sent the command new
06/03/2014 12:38:11;0040;PBS_Server;Svr;tyrone-cluster;Scheduler was sent the command new
06/03/2014 12:38:44;0040;PBS_Server;Svr;tyrone-cluster;Scheduler was sent the command new
06/03/2014 12:39:10;0040;PBS_Server;Svr;tyrone-cluster;Scheduler was sent the command new
06/03/2014 12:39:41;0040;PBS_Server;Svr;tyrone-cluster;Scheduler was sent the command new
06/03/2014 12:40:13;0040;PBS_Server;Svr;tyrone-cluster;Scheduler was sent the command new
06/03/2014 12:40:40;0040;PBS_Server;Svr;tyrone-cluster;Scheduler was sent the command new
06/03/2014 12:40:57;0002;PBS_Server;Svr;PBS_Server;Torque Server Version = 3.0.5, loglevel = 0
06/03/2014 12:41:10;0040;PBS_Server;Svr;tyrone-cluster;Scheduler was sent the command new
06/03/2014 12:41:44;0040;PBS_Server;Svr;tyrone-cluster;Scheduler was sent the command new
06/03/2014 12:42:10;0040;PBS_Server;Svr;tyrone-cluster;Scheduler was sent the command new
06/03/2014 12:42:41;0040;PBS_Server;Svr;tyrone-cluster;Scheduler was sent the command new
06/03/2014 12:43:10;0080;PBS_Server;Req;dis_request_read;req header bad, dis error 7 (Premature end of message), type=Connect
06/03/2014 12:43:10;0080;PBS_Server;Req;req_reject;Reject reply code=15058(Bad DIS based Request Protocol MSG=cannot decode message), aux=0, type=Connect, from @
06/03/2014 12:43:10;0040;PBS_Server;Svr;tyrone-cluster;Scheduler was sent the command new
06/03/2014 12:43:40;0040;PBS_Server;Svr;tyrone-cluster;Scheduler was sent the command new
06/03/2014 12:44:11;0040;PBS_Server;Svr;tyrone-cluster;Scheduler was sent the command new
06/03/2014 12:44:44;0040;PBS_Server;Svr;tyrone-cluster;Scheduler was sent the command new
06/03/2014 12:45:10;0040;PBS_Server;Svr;tyrone-cluster;Scheduler was sent the command new
06/03/2014 12:45:41;0040;PBS_Server;Svr;tyrone-cluster;Scheduler was sent the command new
06/03/2014 12:45:57;0002;PBS_Server;Svr;PBS_Server;Torque Server Version = 3.0.5, loglevel = 0
06/03/2014 12:46:13;0040;PBS_Server;Svr;tyrone-cluster;Scheduler was sent the command new
06/03/2014 12:46:40;0040;PBS_Server;Svr;tyrone-cluster;Scheduler was sent the command new
06/03/2014 12:47:10;0040;PBS_Server;Svr;tyrone-cluster;Scheduler was sent the command new
06/03/2014 12:47:40;0040;PBS_Server;Svr;tyrone-cluster;Scheduler was sent the command new
06/03/2014 12:48:10;0040;PBS_Server;Svr;tyrone-cluster;Scheduler was sent the command new
06/03/2014 12:48:41;0040;PBS_Server;Svr;tyrone-cluster;Scheduler was sent the command new
06/03/2014 12:49:13;0040;PBS_Server;Svr;tyrone-cluster;Scheduler was sent the command new
06/03/2014 12:49:40;0040;PBS_Server;Svr;tyrone-cluster;Scheduler was sent the command new
06/03/2014 12:50:10;0040;PBS_Server;Svr;tyrone-cluster;Scheduler was sent the command new
06/03/2014 12:50:41;0040;PBS_Server;Svr;tyrone-cluster;Scheduler was sent the command new
06/03/2014 12:50:57;0002;PBS_Server;Svr;PBS_Server;Torque Server Version = 3.0.5, loglevel = 0
06/03/2014 12:51:10;0040;PBS_Server;Svr;tyrone-cluster;Scheduler was sent the command new
06/03/2014 12:51:41;0040;PBS_Server;Svr;tyrone-cluster;Scheduler was sent the command new
06/03/2014 12:52:14;0040;PBS_Server;Svr;tyrone-cluster;Scheduler was sent the command new
06/03/2014 12:52:40;0040;PBS_Server;Svr;tyrone-cluster;Scheduler was sent the command new
06/03/2014 12:53:10;0040;PBS_Server;Svr;tyrone-cluster;Scheduler was sent the command new
06/03/2014 12:53:43;0040;PBS_Server;Svr;tyrone-cluster;Scheduler was sent the command new
06/03/2014 12:54:10;0040;PBS_Server;Svr;tyrone-cluster;Scheduler was sent the command new
06/03/2014 12:54:40;0040;PBS_Server;Svr;tyrone-cluster;Scheduler was sent the command new
06/03/2014 12:55:10;0040;PBS_Server;Svr;tyrone-cluster;Scheduler was sent the command new
06/03/2014 12:55:40;0040;PBS_Server;Svr;tyrone-cluster;Scheduler was sent the command new
06/03/2014 12:55:57;0002;PBS_Server;Svr;PBS_Server;Torque Server Version = 3.0.5, loglevel = 0
06/03/2014 12:56:11;0040;PBS_Server;Svr;tyrone-cluster;Scheduler was sent the command new
06/03/2014 12:56:40;0040;PBS_Server;Svr;tyrone-cluster;Scheduler was sent the command new
06/03/2014 12:57:10;0040;PBS_Server;Svr;tyrone-cluster;Scheduler was sent the command new
06/03/2014 12:57:41;0040;PBS_Server;Svr;tyrone-cluster;Scheduler was sent the command new
06/03/2014 12:58:14;0040;PBS_Server;Svr;tyrone-cluster;Scheduler was sent the command new
06/03/2014 12:58:40;0040;PBS_Server;Svr;tyrone-cluster;Scheduler was sent the command new
06/03/2014 12:59:11;0040;PBS_Server;Svr;tyrone-cluster;Scheduler was sent the command new
06/03/2014 12:59:43;0040;PBS_Server;Svr;tyrone-cluster;Scheduler was sent the command new
06/03/2014 13:00:10;0040;PBS_Server;Svr;tyrone-cluster;Scheduler was sent the command new
06/03/2014 13:00:40;0040;PBS_Server;Svr;tyrone-cluster;Scheduler was sent the command new
06/03/2014 13:00:57;0002;PBS_Server;Svr;PBS_Server;Torque Server Version = 3.0.5, loglevel = 0
06/03/2014 13:01:10;0040;PBS_Server;Svr;tyrone-cluster;Scheduler was sent the command new
06/03/2014 13:01:40;0040;PBS_Server;Svr;tyrone-cluster;Scheduler was sent the command new
06/03/2014 13:02:11;0040;PBS_Server;Svr;tyrone-cluster;Scheduler was sent the command new
06/03/2014 13:02:44;0040;PBS_Server;Svr;tyrone-cluster;Scheduler was sent the command new
06/03/2014 13:03:10;0040;PBS_Server;Svr;tyrone-cluster;Scheduler was sent the command new
06/03/2014 13:03:40;0040;PBS_Server;Svr;tyrone-cluster;Scheduler was sent the command new
06/03/2014 13:04:13;0040;PBS_Server;Svr;tyrone-cluster;Scheduler was sent the command new
06/03/2014 13:04:40;0040;PBS_Server;Svr;tyrone-cluster;Scheduler was sent the command new
06/03/2014 13:05:11;0040;PBS_Server;Svr;tyrone-cluster;Scheduler was sent the command new
06/03/2014 13:05:46;0040;PBS_Server;Svr;tyrone-cluster;Scheduler was sent the command new
06/03/2014 13:05:57;0002;PBS_Server;Svr;PBS_Server;Torque Server Version = 3.0.5, loglevel = 0
06/03/2014 13:06:22;0040;PBS_Server;Svr;tyrone-cluster;Scheduler was sent the command new
06/03/2014 13:06:53;0040;PBS_Server;Svr;tyrone-cluster;Scheduler was sent the command new
06/03/2014 13:07:26;0040;PBS_Server;Svr;tyrone-cluster;Scheduler was sent the command new
06/03/2014 13:07:59;0040;PBS_Server;Svr;tyrone-cluster;Scheduler was sent the command new
06/03/2014 13:08:25;0040;PBS_Server;Svr;tyrone-cluster;Scheduler was sent the command new
06/03/2014 13:08:55;0040;PBS_Server;Svr;tyrone-cluster;Scheduler was sent the command new
06/03/2014 13:09:28;0040;PBS_Server;Svr;tyrone-cluster;Scheduler was sent the command new
06/03/2014 13:09:55;0040;PBS_Server;Svr;tyrone-cluster;Scheduler was sent the command new
06/03/2014 13:10:26;0040;PBS_Server;Svr;tyrone-cluster;Scheduler was sent the command new
06/03/2014 13:10:56;0040;PBS_Server;Svr;tyrone-cluster;Scheduler was sent the command new
06/03/2014 13:10:57;0002;PBS_Server;Svr;PBS_Server;Torque Server Version = 3.0.5, loglevel = 0
06/03/2014 13:11:25;0040;PBS_Server;Svr;tyrone-cluster;Scheduler was sent the command new
06/03/2014 13:11:56;0040;PBS_Server;Svr;tyrone-cluster;Scheduler was sent the command new
06/03/2014 13:12:29;0040;PBS_Server;Svr;tyrone-cluster;Scheduler was sent the command new
06/03/2014 13:12:55;0040;PBS_Server;Svr;tyrone-cluster;Scheduler was sent the command new
06/03/2014 13:13:25;0040;PBS_Server;Svr;tyrone-cluster;Scheduler was sent the command new
06/03/2014 13:13:58;0040;PBS_Server;Svr;tyrone-cluster;Scheduler was sent the command new
06/03/2014 13:14:25;0040;PBS_Server;Svr;tyrone-cluster;Scheduler was sent the command new
06/03/2014 13:14:56;0040;PBS_Server;Svr;tyrone-cluster;Scheduler was sent the command new
06/03/2014 13:15:29;0040;PBS_Server;Svr;tyrone-cluster;Scheduler was sent the command new
06/03/2014 13:15:55;0040;PBS_Server;Svr;tyrone-cluster;Scheduler was sent the command new
06/03/2014 13:15:57;0002;PBS_Server;Svr;PBS_Server;Torque Server Version = 3.0.5, loglevel = 0
06/03/2014 13:16:25;0040;PBS_Server;Svr;tyrone-cluster;Scheduler was sent the command new
06/03/2014 13:16:58;0040;PBS_Server;Svr;tyrone-cluster;Scheduler was sent the command new
06/03/2014 13:17:25;0040;PBS_Server;Svr;tyrone-cluster;Scheduler was sent the command new
06/03/2014 13:17:56;0040;PBS_Server;Svr;tyrone-cluster;Scheduler was sent the command new
06/03/2014 13:18:28;0040;PBS_Server;Svr;tyrone-cluster;Scheduler was sent the command new
06/03/2014 13:19:07;0040;PBS_Server;Svr;tyrone-cluster;Scheduler was sent the command new
06/03/2014 13:19:38;0040;PBS_Server;Svr;tyrone-cluster;Scheduler was sent the command new
06/03/2014 13:20:11;0040;PBS_Server;Svr;tyrone-cluster;Scheduler was sent the command new
06/03/2014 13:20:44;0040;PBS_Server;Svr;tyrone-cluster;Scheduler was sent the command new
06/03/2014 13:20:57;0002;PBS_Server;Svr;PBS_Server;Torque Server Version = 3.0.5, loglevel = 0
06/03/2014 13:21:10;0040;PBS_Server;Svr;tyrone-cluster;Scheduler was sent the command new
06/03/2014 13:21:40;0040;PBS_Server;Svr;tyrone-cluster;Scheduler was sent the command new
06/03/2014 13:22:16;0040;PBS_Server;Svr;tyrone-cluster;Scheduler was sent the command new
06/03/2014 13:22:51;0040;PBS_Server;Svr;tyrone-cluster;Scheduler was sent the command new
06/03/2014 13:23:23;0040;PBS_Server;Svr;tyrone-cluster;Scheduler was sent the command new
06/03/2014 13:23:56;0040;PBS_Server;Svr;tyrone-cluster;Scheduler was sent the command new
06/03/2014 13:24:29;0040;PBS_Server;Svr;tyrone-cluster;Scheduler was sent the command new
06/03/2014 13:24:55;0040;PBS_Server;Svr;tyrone-cluster;Scheduler was sent the command new
06/03/2014 13:25:25;0040;PBS_Server;Svr;tyrone-cluster;Scheduler was sent the command new
06/03/2014 13:25:57;0002;PBS_Server;Svr;PBS_Server;Torque Server Version = 3.0.5, loglevel = 0
06/03/2014 13:25:57;0040;PBS_Server;Svr;tyrone-cluster;Scheduler was sent the command new
06/03/2014 13:26:36;0040;PBS_Server;Svr;tyrone-cluster;Scheduler was sent the command new
06/03/2014 13:27:08;0040;PBS_Server;Svr;tyrone-cluster;Scheduler was sent the command new
06/03/2014 13:27:41;0040;PBS_Server;Svr;tyrone-cluster;Scheduler was sent the command new
06/03/2014 13:28:14;0040;PBS_Server;Svr;tyrone-cluster;Scheduler was sent the command new
06/03/2014 13:28:40;0040;PBS_Server;Svr;tyrone-cluster;Scheduler was sent the command new
06/03/2014 13:29:10;0040;PBS_Server;Svr;tyrone-cluster;Scheduler was sent the command new
06/03/2014 13:29:43;0040;PBS_Server;Svr;tyrone-cluster;Scheduler was sent the command new
06/03/2014 13:30:10;0040;PBS_Server;Svr;tyrone-cluster;Scheduler was sent the command new
06/03/2014 13:30:41;0040;PBS_Server;Svr;tyrone-cluster;Scheduler was sent the command new
06/03/2014 13:30:57;0002;PBS_Server;Svr;PBS_Server;Torque Server Version = 3.0.5, loglevel = 0
06/03/2014 13:31:10;0040;PBS_Server;Svr;tyrone-cluster;Scheduler was sent the command new
06/03/2014 13:31:40;0040;PBS_Server;Svr;tyrone-cluster;Scheduler was sent the command new
06/03/2014 13:32:11;0040;PBS_Server;Svr;tyrone-cluster;Scheduler was sent the command new
06/03/2014 13:32:25;0100;PBS_Server;Job;39345.tyrone-cluster;enqueuing into batch, state 1 hop 1
06/03/2014 13:32:25;0100;PBS_Server;Job;39345.tyrone-cluster;dequeuing from batch, state QUEUED
06/03/2014 13:32:25;0100;PBS_Server;Job;39345.tyrone-cluster;enqueuing into qp32, state 1 hop 1
06/03/2014 13:32:25;0008;PBS_Server;Job;39345.tyrone-cluster;Job Queued at request of secanoop@tyrone-cluster, owner = secanoop@tyrone-cluster, job name = jobname, queue = qp32
06/03/2014 13:32:25;0040;PBS_Server;Svr;tyrone-cluster;Scheduler was sent the command new
06/03/2014 13:32:25;0008;PBS_Server;Job;39345.tyrone-cluster;Job Modified at request of Scheduler@tyrone-cluster
06/03/2014 13:32:25;0008;PBS_Server;Job;39345.tyrone-cluster;Job Run at request of Scheduler@tyrone-cluster
06/03/2014 13:32:25;0040;PBS_Server;Svr;tyrone-cluster;Scheduler was sent the command recyc
06/03/2014 13:32:25;000d;PBS_Server;Job;39345.tyrone-cluster;Not sending email: User does not want mail of this type.
06/03/2014 13:32:26;000d;PBS_Server;Job;39345.tyrone-cluster;Not sending email: User does not want mail of this type.
06/03/2014 13:32:26;0010;PBS_Server;Job;39345.tyrone-cluster;Exit_status=0 resources_used.cput=00:00:15 resources_used.mem=0kb resources_used.vmem=0kb resources_used.walltime=00:00:01
06/03/2014 13:32:26;0008;PBS_Server;Job;NULL;on_job_exit valid pjob: 0x177bea0 (substate=50)
06/03/2014 13:32:26;0008;PBS_Server;Job;NULL;on_job_exit valid pjob: 0x177bea0 (substate=51)
06/03/2014 13:32:26;0008;PBS_Server;Job;NULL;on_job_exit valid pjob: 0x177bea0 (substate=51)
06/03/2014 13:32:26;0008;PBS_Server;Job;NULL;on_job_exit valid pjob: 0x177bea0 (substate=53)
06/03/2014 13:32:26;0100;PBS_Server;Job;39345.tyrone-cluster;dequeuing from qp32, state COMPLETE
06/03/2014 13:32:26;0040;PBS_Server;Svr;tyrone-cluster;Scheduler was sent the command term
06/03/2014 13:32:46;0040;PBS_Server;Svr;tyrone-cluster;Scheduler was sent the command new
06/03/2014 13:33:21;0040;PBS_Server;Svr;tyrone-cluster;Scheduler was sent the command new
06/03/2014 13:33:53;0040;PBS_Server;Svr;tyrone-cluster;Scheduler was sent the command new
06/03/2014 13:34:26;0040;PBS_Server;Svr;tyrone-cluster;Scheduler was sent the command new
06/03/2014 13:34:59;0040;PBS_Server;Svr;tyrone-cluster;Scheduler was sent the command new
06/03/2014 13:35:25;0040;PBS_Server;Svr;tyrone-cluster;Scheduler was sent the command new
06/03/2014 13:35:55;0040;PBS_Server;Svr;tyrone-cluster;Scheduler was sent the command new
06/03/2014 13:35:57;0002;PBS_Server;Svr;PBS_Server;Torque Server Version = 3.0.5, loglevel = 0
06/03/2014 13:36:29;0040;PBS_Server;Svr;tyrone-cluster;Scheduler was sent the command new
06/03/2014 13:37:07;0040;PBS_Server;Svr;tyrone-cluster;Scheduler was sent the command new
06/03/2014 13:37:38;0040;PBS_Server;Svr;tyrone-cluster;Scheduler was sent the command new
06/03/2014 13:38:10;0040;PBS_Server;Svr;tyrone-cluster;Scheduler was sent the command new
06/03/2014 13:38:46;0040;PBS_Server;Svr;tyrone-cluster;Scheduler was sent the command new
06/03/2014 13:39:21;0040;PBS_Server;Svr;tyrone-cluster;Scheduler was sent the command new
06/03/2014 13:39:53;0040;PBS_Server;Svr;tyrone-cluster;Scheduler was sent the command new
06/03/2014 13:40:26;0040;PBS_Server;Svr;tyrone-cluster;Scheduler was sent the command new
06/03/2014 13:40:56;0040;PBS_Server;Svr;tyrone-cluster;Scheduler was sent the command new
06/03/2014 13:40:57;0002;PBS_Server;Svr;PBS_Server;Torque Server Version = 3.0.5, loglevel = 0
06/03/2014 13:41:25;0040;PBS_Server;Svr;tyrone-cluster;Scheduler was sent the command new
06/03/2014 13:41:55;0040;PBS_Server;Svr;tyrone-cluster;Scheduler was sent the command new
06/03/2014 13:42:31;0040;PBS_Server;Svr;tyrone-cluster;Scheduler was sent the command new
06/03/2014 13:43:06;0040;PBS_Server;Svr;tyrone-cluster;Scheduler was sent the command new
06/03/2014 13:43:38;0040;PBS_Server;Svr;tyrone-cluster;Scheduler was sent the command new
06/03/2014 13:44:11;0040;PBS_Server;Svr;tyrone-cluster;Scheduler was sent the command new
06/03/2014 13:44:46;0040;PBS_Server;Svr;tyrone-cluster;Scheduler was sent the command new
06/03/2014 13:45:22;0040;PBS_Server;Svr;tyrone-cluster;Scheduler was sent the command new
06/03/2014 13:45:53;0040;PBS_Server;Svr;tyrone-cluster;Scheduler was sent the command new
06/03/2014 13:45:57;0002;PBS_Server;Svr;PBS_Server;Torque Server Version = 3.0.5, loglevel = 0
06/03/2014 13:46:26;0040;PBS_Server;Svr;tyrone-cluster;Scheduler was sent the command new
06/03/2014 13:47:01;0040;PBS_Server;Svr;tyrone-cluster;Scheduler was sent the command new
06/03/2014 13:47:37;0040;PBS_Server;Svr;tyrone-cluster;Scheduler was sent the command new
06/03/2014 13:48:08;0040;PBS_Server;Svr;tyrone-cluster;Scheduler was sent the command new
06/03/2014 13:48:41;0040;PBS_Server;Svr;tyrone-cluster;Scheduler was sent the command new
06/03/2014 13:49:16;0040;PBS_Server;Svr;tyrone-cluster;Scheduler was sent the command new
06/03/2014 13:49:52;0040;PBS_Server;Svr;tyrone-cluster;Scheduler was sent the command new
06/03/2014 13:50:23;0040;PBS_Server;Svr;tyrone-cluster;Scheduler was sent the command new
06/03/2014 13:50:55;0040;PBS_Server;Svr;tyrone-cluster;Scheduler was sent the command new
06/03/2014 13:50:57;0002;PBS_Server;Svr;PBS_Server;Torque Server Version = 3.0.5, loglevel = 0
06/03/2014 13:51:24;0040;PBS_Server;Svr;tyrone-cluster;Scheduler was sent the command new
06/03/2014 13:51:54;0040;PBS_Server;Svr;tyrone-cluster;Scheduler was sent the command new
06/03/2014 13:52:26;0040;PBS_Server;Svr;tyrone-cluster;Scheduler was sent the command new
06/03/2014 13:53:01;0040;PBS_Server;Svr;tyrone-cluster;Scheduler was sent the command new
06/03/2014 13:53:37;0040;PBS_Server;Svr;tyrone-cluster;Scheduler was sent the command new
06/03/2014 13:54:08;0040;PBS_Server;Svr;tyrone-cluster;Scheduler was sent the command new
06/03/2014 13:54:40;0040;PBS_Server;Svr;tyrone-cluster;Scheduler was sent the command new
06/03/2014 13:55:09;0040;PBS_Server;Svr;tyrone-cluster;Scheduler was sent the command new
06/03/2014 13:55:39;0040;PBS_Server;Svr;tyrone-cluster;Scheduler was sent the command new
06/03/2014 13:55:57;0002;PBS_Server;Svr;PBS_Server;Torque Server Version = 3.0.5, loglevel = 0
06/03/2014 13:56:11;0040;PBS_Server;Svr;tyrone-cluster;Scheduler was sent the command new
06/03/2014 13:56:44;0040;PBS_Server;Svr;tyrone-cluster;Scheduler was sent the command new
06/03/2014 13:57:10;0040;PBS_Server;Svr;tyrone-cluster;Scheduler was sent the command new
06/03/2014 13:57:40;0040;PBS_Server;Svr;tyrone-cluster;Scheduler was sent the command new
06/03/2014 13:58:16;0040;PBS_Server;Svr;tyrone-cluster;Scheduler was sent the command new
06/03/2014 13:58:52;0040;PBS_Server;Svr;tyrone-cluster;Scheduler was sent the command new
06/03/2014 13:59:23;0040;PBS_Server;Svr;tyrone-cluster;Scheduler was sent the command new
06/03/2014 13:59:55;0040;PBS_Server;Svr;tyrone-cluster;Scheduler was sent the command new
06/03/2014 14:00:06;0008;PBS_Server;Job;39339.tyrone-cluster;Job deleted at request of secbadar@tyrone-cluster
06/03/2014 14:00:06;0008;PBS_Server;Job;39339.tyrone-cluster;Job sent signal SIGTERM on delete
06/03/2014 14:00:07;000d;PBS_Server;Job;39339.tyrone-cluster;Not sending email: User does not want mail of this type.
06/03/2014 14:00:07;0010;PBS_Server;Job;39339.tyrone-cluster;Exit_status=143 resources_used.cput=03:07:44 resources_used.mem=496584kb resources_used.vmem=1297948kb resources_used.walltime=01:31:42
06/03/2014 14:00:07;0008;PBS_Server;Job;NULL;on_job_exit valid pjob: 0x17bf730 (substate=50)
06/03/2014 14:00:07;0008;PBS_Server;Job;NULL;on_job_exit valid pjob: 0x17bf730 (substate=51)
06/03/2014 14:00:07;0008;PBS_Server;Job;NULL;on_job_exit valid pjob: 0x17bf730 (substate=51)
06/03/2014 14:00:07;0008;PBS_Server;Job;NULL;on_job_exit valid pjob: 0x17bf730 (substate=53)
06/03/2014 14:00:07;0100;PBS_Server;Job;39339.tyrone-cluster;dequeuing from qp256, state COMPLETE
06/03/2014 14:00:07;0040;PBS_Server;Svr;tyrone-cluster;Scheduler was sent the command term
06/03/2014 14:00:07;0008;PBS_Server;Job;39312.tyrone-cluster;Job Modified at request of Scheduler@tyrone-cluster
06/03/2014 14:00:07;0008;PBS_Server;Job;39338.tyrone-cluster;Job Modified at request of Scheduler@tyrone-cluster
06/03/2014 14:00:07;0008;PBS_Server;Job;39338.tyrone-cluster;Job Run at request of Scheduler@tyrone-cluster
06/03/2014 14:00:07;0040;PBS_Server;Svr;tyrone-cluster;Scheduler was sent the command recyc
06/03/2014 14:00:24;0008;PBS_Server;Job;39340.tyrone-cluster;Job rejected by all possible destinations (check syntax, queue resources, ...)
06/03/2014 14:00:24;0100;PBS_Server;Job;39340.tyrone-cluster;dequeuing from batch, state EXITING
06/03/2014 14:00:24;0100;PBS_Server;Job;39342.tyrone-cluster;dequeuing from batch, state QUEUED
06/03/2014 14:00:24;0100;PBS_Server;Job;39342.tyrone-cluster;enqueuing into qp256, state 1 hop 1
06/03/2014 14:00:24;0040;PBS_Server;Svr;tyrone-cluster;Scheduler was sent the command new
06/03/2014 14:00:24;0008;PBS_Server;Job;39312.tyrone-cluster;Job Modified at request of Scheduler@tyrone-cluster
06/03/2014 14:00:24;0008;PBS_Server;Job;39342.tyrone-cluster;Job Modified at request of Scheduler@tyrone-cluster
06/03/2014 14:00:54;0040;PBS_Server;Svr;tyrone-cluster;Scheduler was sent the command new
06/03/2014 14:00:56;000d;PBS_Server;Job;39338.tyrone-cluster;Not sending email: User does not want mail of this type.
06/03/2014 14:00:57;0002;PBS_Server;Svr;PBS_Server;Torque Server Version = 3.0.5, loglevel = 0
06/03/2014 14:01:26;0040;PBS_Server;Svr;tyrone-cluster;Scheduler was sent the command new
06/03/2014 14:02:01;0040;PBS_Server;Svr;tyrone-cluster;Scheduler was sent the command new
06/03/2014 14:02:37;0040;PBS_Server;Svr;tyrone-cluster;Scheduler was sent the command new
06/03/2014 14:02:38;000d;PBS_Server;Job;39338.tyrone-cluster;Not sending email: User does not want mail of this type.
06/03/2014 14:02:38;0010;PBS_Server;Job;39338.tyrone-cluster;Exit_status=0 resources_used.cput=00:09:34 resources_used.mem=3776076kb resources_used.vmem=7948412kb resources_used.walltime=00:02:31
06/03/2014 14:02:38;0008;PBS_Server;Job;NULL;on_job_exit valid pjob: 0x1713730 (substate=50)
06/03/2014 14:02:38;0008;PBS_Server;Job;NULL;on_job_exit valid pjob: 0x1713730 (substate=51)
06/03/2014 14:02:38;0008;PBS_Server;Job;NULL;on_job_exit valid pjob: 0x1713730 (substate=51)
06/03/2014 14:02:38;0008;PBS_Server;Job;NULL;on_job_exit valid pjob: 0x1713730 (substate=53)
06/03/2014 14:02:38;0100;PBS_Server;Job;39338.tyrone-cluster;dequeuing from qp256, state COMPLETE
06/03/2014 14:02:38;0040;PBS_Server;Svr;tyrone-cluster;Scheduler was sent the command term
06/03/2014 14:02:38;0008;PBS_Server;Job;39312.tyrone-cluster;Job Modified at request of Scheduler@tyrone-cluster
06/03/2014 14:02:38;0008;PBS_Server;Job;39342.tyrone-cluster;Job Modified at request of Scheduler@tyrone-cluster
06/03/2014 14:02:38;0008;PBS_Server;Job;39342.tyrone-cluster;Job Run at request of Scheduler@tyrone-cluster
06/03/2014 14:02:38;0040;PBS_Server;Svr;tyrone-cluster;Scheduler was sent the command recyc
06/03/2014 14:02:41;000d;PBS_Server;Job;39342.tyrone-cluster;Not sending email: User does not want mail of this type.
06/03/2014 14:02:41;0010;PBS_Server;Job;39342.tyrone-cluster;Exit_status=127 resources_used.cput=00:00:00 resources_used.mem=15596kb resources_used.vmem=461748kb resources_used.walltime=00:00:03
06/03/2014 14:02:41;0008;PBS_Server;Job;NULL;on_job_exit valid pjob: 0x177dbb0 (substate=50)
06/03/2014 14:02:41;0008;PBS_Server;Job;NULL;on_job_exit valid pjob: 0x177dbb0 (substate=51)
06/03/2014 14:02:41;0008;PBS_Server;Job;NULL;on_job_exit valid pjob: 0x177dbb0 (substate=51)
06/03/2014 14:02:41;0008;PBS_Server;Job;NULL;on_job_exit valid pjob: 0x177dbb0 (substate=53)
06/03/2014 14:02:41;0100;PBS_Server;Job;39342.tyrone-cluster;dequeuing from qp256, state COMPLETE
06/03/2014 14:02:41;0040;PBS_Server;Svr;tyrone-cluster;Scheduler was sent the command term
06/03/2014 14:03:08;0100;PBS_Server;Job;39343.tyrone-cluster;dequeuing from batch, state QUEUED
06/03/2014 14:03:08;0100;PBS_Server;Job;39343.tyrone-cluster;enqueuing into qp256, state 1 hop 1
06/03/2014 14:03:08;0040;PBS_Server;Svr;tyrone-cluster;Scheduler was sent the command new
06/03/2014 14:03:09;0008;PBS_Server;Job;39343.tyrone-cluster;Job Modified at request of Scheduler@tyrone-cluster
06/03/2014 14:03:09;0008;PBS_Server;Job;39343.tyrone-cluster;Job Run at request of Scheduler@tyrone-cluster
06/03/2014 14:03:09;0040;PBS_Server;Svr;tyrone-cluster;Scheduler was sent the command recyc
06/03/2014 14:03:16;000d;PBS_Server;Job;39343.tyrone-cluster;Not sending email: User does not want mail of this type.
06/03/2014 14:03:16;0010;PBS_Server;Job;39343.tyrone-cluster;Exit_status=255 resources_used.cput=00:00:15 resources_used.mem=796kb resources_used.vmem=13624kb resources_used.walltime=00:00:07
06/03/2014 14:03:16;0008;PBS_Server;Job;NULL;on_job_exit valid pjob: 0x17bd870 (substate=50)
06/03/2014 14:03:16;0008;PBS_Server;Job;NULL;on_job_exit valid pjob: 0x17bd870 (substate=51)
06/03/2014 14:03:16;0008;PBS_Server;Job;NULL;on_job_exit valid pjob: 0x17bd870 (substate=51)
06/03/2014 14:03:16;0008;PBS_Server;Job;NULL;on_job_exit valid pjob: 0x17bd870 (substate=53)
06/03/2014 14:03:16;0100;PBS_Server;Job;39343.tyrone-cluster;dequeuing from qp256, state COMPLETE
06/03/2014 14:03:16;0040;PBS_Server;Svr;tyrone-cluster;Scheduler was sent the command term
06/03/2014 14:03:41;0040;PBS_Server;Svr;tyrone-cluster;Scheduler was sent the command new
06/03/2014 14:04:16;0040;PBS_Server;Svr;tyrone-cluster;Scheduler was sent the command new
06/03/2014 14:04:52;0040;PBS_Server;Svr;tyrone-cluster;Scheduler was sent the command new
06/03/2014 14:05:23;0040;PBS_Server;Svr;tyrone-cluster;Scheduler was sent the command new
06/03/2014 14:05:56;0040;PBS_Server;Svr;tyrone-cluster;Scheduler was sent the command new
06/03/2014 14:05:57;0002;PBS_Server;Svr;PBS_Server;Torque Server Version = 3.0.5, loglevel = 0
06/03/2014 14:06:31;0040;PBS_Server;Svr;tyrone-cluster;Scheduler was sent the command new
06/03/2014 14:07:07;0040;PBS_Server;Svr;tyrone-cluster;Scheduler was sent the command new
06/03/2014 14:07:38;0040;PBS_Server;Svr;tyrone-cluster;Scheduler was sent the command new
06/03/2014 14:08:10;0040;PBS_Server;Svr;tyrone-cluster;Scheduler was sent the command new
06/03/2014 14:08:39;0040;PBS_Server;Svr;tyrone-cluster;Scheduler was sent the command new
06/03/2014 14:09:09;0040;PBS_Server;Svr;tyrone-cluster;Scheduler was sent the command new
06/03/2014 14:09:41;0040;PBS_Server;Svr;tyrone-cluster;Scheduler was sent the command new
06/03/2014 14:10:17;0040;PBS_Server;Svr;tyrone-cluster;Scheduler was sent the command new
06/03/2014 14:10:52;0040;PBS_Server;Svr;tyrone-cluster;Scheduler was sent the command new
06/03/2014 14:10:57;0002;PBS_Server;Svr;PBS_Server;Torque Server Version = 3.0.5, loglevel = 0
06/03/2014 14:11:24;0040;PBS_Server;Svr;tyrone-cluster;Scheduler was sent the command new
06/03/2014 14:11:55;0040;PBS_Server;Svr;tyrone-cluster;Scheduler was sent the command new
06/03/2014 14:12:32;0040;PBS_Server;Svr;tyrone-cluster;Scheduler was sent the command new
06/03/2014 14:13:07;0040;PBS_Server;Svr;tyrone-cluster;Scheduler was sent the command new
06/03/2014 14:13:39;0040;PBS_Server;Svr;tyrone-cluster;Scheduler was sent the command new
06/03/2014 14:14:10;0040;PBS_Server;Svr;tyrone-cluster;Scheduler was sent the command new
06/03/2014 14:14:43;0040;PBS_Server;Svr;tyrone-cluster;Scheduler was sent the command new
06/03/2014 14:15:09;0040;PBS_Server;Svr;tyrone-cluster;Scheduler was sent the command new
06/03/2014 14:15:41;0040;PBS_Server;Svr;tyrone-cluster;Scheduler was sent the command new
06/03/2014 14:15:57;0002;PBS_Server;Svr;PBS_Server;Torque Server Version = 3.0.5, loglevel = 0
06/03/2014 14:16:17;0040;PBS_Server;Svr;tyrone-cluster;Scheduler was sent the command new
06/03/2014 14:16:52;0040;PBS_Server;Svr;tyrone-cluster;Scheduler was sent the command new
06/03/2014 14:17:24;0040;PBS_Server;Svr;tyrone-cluster;Scheduler was sent the command new
06/03/2014 14:17:55;0040;PBS_Server;Svr;tyrone-cluster;Scheduler was sent the command new
06/03/2014 14:18:28;0040;PBS_Server;Svr;tyrone-cluster;Scheduler was sent the command new
06/03/2014 14:19:07;0040;PBS_Server;Svr;tyrone-cluster;Scheduler was sent the command new
06/03/2014 14:19:39;0040;PBS_Server;Svr;tyrone-cluster;Scheduler was sent the command new
06/03/2014 14:20:11;0040;PBS_Server;Svr;tyrone-cluster;Scheduler was sent the command new
06/03/2014 14:20:47;0040;PBS_Server;Svr;tyrone-cluster;Scheduler was sent the command new
06/03/2014 14:20:57;0002;PBS_Server;Svr;PBS_Server;Torque Server Version = 3.0.5, loglevel = 0
06/03/2014 14:21:22;0040;PBS_Server;Svr;tyrone-cluster;Scheduler was sent the command new
06/03/2014 14:21:54;0040;PBS_Server;Svr;tyrone-cluster;Scheduler was sent the command new
06/03/2014 14:22:25;0040;PBS_Server;Svr;tyrone-cluster;Scheduler was sent the command new
06/03/2014 14:23:02;0040;PBS_Server;Svr;tyrone-cluster;Scheduler was sent the command new
06/03/2014 14:23:37;0040;PBS_Server;Svr;tyrone-cluster;Scheduler was sent the command new
06/03/2014 14:24:09;0040;PBS_Server;Svr;tyrone-cluster;Scheduler was sent the command new
06/03/2014 14:24:40;0040;PBS_Server;Svr;tyrone-cluster;Scheduler was sent the command new
06/03/2014 14:25:14;0040;PBS_Server;Svr;tyrone-cluster;Scheduler was sent the command new
06/03/2014 14:25:39;0040;PBS_Server;Svr;tyrone-cluster;Scheduler was sent the command new
06/03/2014 14:25:57;0002;PBS_Server;Svr;PBS_Server;Torque Server Version = 3.0.5, loglevel = 0
06/03/2014 14:26:11;0040;PBS_Server;Svr;tyrone-cluster;Scheduler was sent the command new
06/03/2014 14:26:47;0040;PBS_Server;Svr;tyrone-cluster;Scheduler was sent the command new
06/03/2014 14:27:22;0040;PBS_Server;Svr;tyrone-cluster;Scheduler was sent the command new
06/03/2014 14:27:54;0040;PBS_Server;Svr;tyrone-cluster;Scheduler was sent the command new
06/03/2014 14:28:25;0040;PBS_Server;Svr;tyrone-cluster;Scheduler was sent the command new
06/03/2014 14:29:02;0040;PBS_Server;Svr;tyrone-cluster;Scheduler was sent the command new
06/03/2014 14:29:37;0040;PBS_Server;Svr;tyrone-cluster;Scheduler was sent the command new
06/03/2014 14:30:09;0040;PBS_Server;Svr;tyrone-cluster;Scheduler was sent the command new
06/03/2014 14:30:41;0040;PBS_Server;Svr;tyrone-cluster;Scheduler was sent the command new
06/03/2014 14:30:57;0002;PBS_Server;Svr;PBS_Server;Torque Server Version = 3.0.5, loglevel = 0
06/03/2014 14:31:17;0040;PBS_Server;Svr;tyrone-cluster;Scheduler was sent the command new
06/03/2014 14:31:52;0040;PBS_Server;Svr;tyrone-cluster;Scheduler was sent the command new
06/03/2014 14:32:24;0040;PBS_Server;Svr;tyrone-cluster;Scheduler was sent the command new
06/03/2014 14:32:55;0040;PBS_Server;Svr;tyrone-cluster;Scheduler was sent the command new
06/03/2014 14:33:28;0040;PBS_Server;Svr;tyrone-cluster;Scheduler was sent the command new
06/03/2014 14:34:07;0040;PBS_Server;Svr;tyrone-cluster;Scheduler was sent the command new
06/03/2014 14:34:39;0040;PBS_Server;Svr;tyrone-cluster;Scheduler was sent the command new
06/03/2014 14:35:10;0040;PBS_Server;Svr;tyrone-cluster;Scheduler was sent the command new
06/03/2014 14:35:39;0040;PBS_Server;Svr;tyrone-cluster;Scheduler was sent the command new
06/03/2014 14:35:57;0002;PBS_Server;Svr;PBS_Server;Torque Server Version = 3.0.5, loglevel = 0
06/03/2014 14:36:09;0040;PBS_Server;Svr;tyrone-cluster;Scheduler was sent the command new
06/03/2014 14:36:41;0040;PBS_Server;Svr;tyrone-cluster;Scheduler was sent the command new
06/03/2014 14:37:17;0040;PBS_Server;Svr;tyrone-cluster;Scheduler was sent the command new
06/03/2014 14:37:52;0040;PBS_Server;Svr;tyrone-cluster;Scheduler was sent the command new
06/03/2014 14:38:24;0040;PBS_Server;Svr;tyrone-cluster;Scheduler was sent the command new
06/03/2014 14:38:55;0040;PBS_Server;Svr;tyrone-cluster;Scheduler was sent the command new
06/03/2014 14:39:32;0040;PBS_Server;Svr;tyrone-cluster;Scheduler was sent the command new
06/03/2014 14:40:07;0040;PBS_Server;Svr;tyrone-cluster;Scheduler was sent the command new
06/03/2014 14:40:39;0040;PBS_Server;Svr;tyrone-cluster;Scheduler was sent the command new
06/03/2014 14:40:57;0002;PBS_Server;Svr;PBS_Server;Torque Server Version = 3.0.5, loglevel = 0
06/03/2014 14:41:10;0040;PBS_Server;Svr;tyrone-cluster;Scheduler was sent the command new
06/03/2014 14:41:39;0040;PBS_Server;Svr;tyrone-cluster;Scheduler was sent the command new
06/03/2014 14:42:09;0040;PBS_Server;Svr;tyrone-cluster;Scheduler was sent the command new
06/03/2014 14:42:41;0040;PBS_Server;Svr;tyrone-cluster;Scheduler was sent the command new
06/03/2014 14:43:17;0040;PBS_Server;Svr;tyrone-cluster;Scheduler was sent the command new
06/03/2014 14:43:52;0040;PBS_Server;Svr;tyrone-cluster;Scheduler was sent the command new
06/03/2014 14:44:24;0040;PBS_Server;Svr;tyrone-cluster;Scheduler was sent the command new
06/03/2014 14:44:55;0040;PBS_Server;Svr;tyrone-cluster;Scheduler was sent the command new
06/03/2014 14:45:32;0040;PBS_Server;Svr;tyrone-cluster;Scheduler was sent the command new
06/03/2014 14:45:57;0002;PBS_Server;Svr;PBS_Server;Torque Server Version = 3.0.5, loglevel = 0
06/03/2014 14:46:07;0040;PBS_Server;Svr;tyrone-cluster;Scheduler was sent the command new
06/03/2014 14:46:07;0008;PBS_Server;Job;39305.tyrone-cluster;Job deleted at request of secpsm@tyrone-cluster
06/03/2014 14:46:07;0008;PBS_Server;Job;39305.tyrone-cluster;Job sent signal SIGTERM on delete
06/03/2014 14:46:08;000d;PBS_Server;Job;39305.tyrone-cluster;Not sending email: User does not want mail of this type.
06/03/2014 14:46:08;0010;PBS_Server;Job;39305.tyrone-cluster;Exit_status=143 resources_used.cput=10:37:42 resources_used.mem=2749372kb resources_used.vmem=3107164kb resources_used.walltime=05:18:19
06/03/2014 14:46:08;0008;PBS_Server;Job;NULL;on_job_exit valid pjob: 0x1789fc0 (substate=50)
06/03/2014 14:46:08;0008;PBS_Server;Job;NULL;on_job_exit valid pjob: 0x1789fc0 (substate=51)
06/03/2014 14:46:16;0008;PBS_Server;Job;NULL;on_job_exit valid pjob: 0x1789fc0 (substate=51)
06/03/2014 14:46:16;000d;PBS_Server;Job;39305.tyrone-cluster;Post job file processing error; job 39305.tyrone-cluster on host tyrone-node2/31+tyrone-node2/30+tyrone-node2/29+tyrone-node2/28+tyrone-node2/27+tyrone-node2/26+tyrone-node2/25+tyrone-node2/24+tyrone-node2/23+tyrone-node2/22+tyrone-node2/21+tyrone-node2/20+tyrone-node2/19+tyrone-node2/18+tyrone-node2/17+tyrone-node2/16+tyrone-node2/15+tyrone-node2/14+tyrone-node2/13+tyrone-node2/12+tyrone-node2/11+tyrone-node2/10+tyrone-node2/9+tyrone-node2/8+tyrone-node2/7+tyrone-node2/6+tyrone-node2/5+tyrone-node2/4+tyrone-node2/3+tyrone-node2/2+tyrone-node2/1+tyrone-node2/0
06/03/2014 14:46:16;0008;PBS_Server;Job;NULL;on_job_exit valid pjob: 0x1789fc0 (substate=53)
06/03/2014 14:46:16;0100;PBS_Server;Job;39305.tyrone-cluster;dequeuing from qp32, state COMPLETE
06/03/2014 14:46:16;0040;PBS_Server;Svr;tyrone-cluster;Scheduler was sent the command term
06/03/2014 14:46:39;0040;PBS_Server;Svr;tyrone-cluster;Scheduler was sent the command new
06/03/2014 14:47:10;0040;PBS_Server;Svr;tyrone-cluster;Scheduler was sent the command new
06/03/2014 14:47:28;0100;PBS_Server;Job;39346.tyrone-cluster;enqueuing into batch, state 1 hop 1
06/03/2014 14:47:28;0100;PBS_Server;Job;39346.tyrone-cluster;dequeuing from batch, state QUEUED
06/03/2014 14:47:28;0100;PBS_Server;Job;39346.tyrone-cluster;enqueuing into qp32, state 1 hop 1
06/03/2014 14:47:28;0008;PBS_Server;Job;39346.tyrone-cluster;Job Queued at request of secpsm@tyrone-cluster, owner = secpsm@tyrone-cluster, job name = job32, queue = qp32
06/03/2014 14:47:28;0040;PBS_Server;Svr;tyrone-cluster;Scheduler was sent the command new
06/03/2014 14:47:28;0008;PBS_Server;Job;39346.tyrone-cluster;Job Modified at request of Scheduler@tyrone-cluster
06/03/2014 14:47:28;0008;PBS_Server;Job;39346.tyrone-cluster;Job Run at request of Scheduler@tyrone-cluster
06/03/2014 14:47:28;0040;PBS_Server;Svr;tyrone-cluster;Scheduler was sent the command recyc
06/03/2014 14:47:28;000d;PBS_Server;Job;39346.tyrone-cluster;Not sending email: User does not want mail of this type.
06/03/2014 14:47:47;0040;PBS_Server;Svr;tyrone-cluster;Scheduler was sent the command new
06/03/2014 14:48:22;0040;PBS_Server;Svr;tyrone-cluster;Scheduler was sent the command new
06/03/2014 14:48:54;0040;PBS_Server;Svr;tyrone-cluster;Scheduler was sent the command new
06/03/2014 14:49:25;0040;PBS_Server;Svr;tyrone-cluster;Scheduler was sent the command new
06/03/2014 14:49:55;0040;PBS_Server;Svr;tyrone-cluster;Scheduler was sent the command new
06/03/2014 14:50:05;0008;PBS_Server;Job;39346.tyrone-cluster;Job deleted at request of secpsm@tyrone-cluster
06/03/2014 14:50:05;0008;PBS_Server;Job;39346.tyrone-cluster;Job sent signal SIGTERM on delete
06/03/2014 14:50:07;0008;PBS_Server;Job;39346.tyrone-cluster;Job sent signal SIGKILL on delete
06/03/2014 14:50:07;000d;PBS_Server;Job;39346.tyrone-cluster;Not sending email: User does not want mail of this type.
06/03/2014 14:50:07;0010;PBS_Server;Job;39346.tyrone-cluster;Exit_status=143 resources_used.cput=00:16:08 resources_used.mem=4010644kb resources_used.vmem=7774780kb resources_used.walltime=00:02:39
06/03/2014 14:50:07;0008;PBS_Server;Job;NULL;on_job_exit valid pjob: 0x1789fc0 (substate=50)
06/03/2014 14:50:07;0008;PBS_Server;Job;NULL;on_job_exit valid pjob: 0x1789fc0 (substate=51)
06/03/2014 14:50:16;0008;PBS_Server;Job;NULL;on_job_exit valid pjob: 0x1789fc0 (substate=51)
06/03/2014 14:50:16;000d;PBS_Server;Job;39346.tyrone-cluster;Post job file processing error; job 39346.tyrone-cluster on host tyrone-node2/31+tyrone-node2/30+tyrone-node2/29+tyrone-node2/28+tyrone-node2/27+tyrone-node2/26+tyrone-node2/25+tyrone-node2/24+tyrone-node2/23+tyrone-node2/22+tyrone-node2/21+tyrone-node2/20+tyrone-node2/19+tyrone-node2/18+tyrone-node2/17+tyrone-node2/16+tyrone-node2/15+tyrone-node2/14+tyrone-node2/13+tyrone-node2/12+tyrone-node2/11+tyrone-node2/10+tyrone-node2/9+tyrone-node2/8+tyrone-node2/7+tyrone-node2/6+tyrone-node2/5+tyrone-node2/4+tyrone-node2/3+tyrone-node2/2+tyrone-node2/1+tyrone-node2/0
06/03/2014 14:50:16;0008;PBS_Server;Job;NULL;on_job_exit valid pjob: 0x1789fc0 (substate=53)
06/03/2014 14:50:16;0100;PBS_Server;Job;39346.tyrone-cluster;dequeuing from qp32, state COMPLETE
06/03/2014 14:50:16;0040;PBS_Server;Svr;tyrone-cluster;Scheduler was sent the command term
06/03/2014 14:50:25;0040;PBS_Server;Svr;tyrone-cluster;Scheduler was sent the command new
06/03/2014 14:50:56;0040;PBS_Server;Svr;tyrone-cluster;Scheduler was sent the command new
06/03/2014 14:50:57;0002;PBS_Server;Svr;PBS_Server;Torque Server Version = 3.0.5, loglevel = 0
06/03/2014 14:51:32;0040;PBS_Server;Svr;tyrone-cluster;Scheduler was sent the command new
06/03/2014 14:52:07;0040;PBS_Server;Svr;tyrone-cluster;Scheduler was sent the command new
06/03/2014 14:52:39;0040;PBS_Server;Svr;tyrone-cluster;Scheduler was sent the command new
06/03/2014 14:53:10;0040;PBS_Server;Svr;tyrone-cluster;Scheduler was sent the command new
06/03/2014 14:53:47;0040;PBS_Server;Svr;tyrone-cluster;Scheduler was sent the command new
06/03/2014 14:54:21;0040;PBS_Server;Svr;tyrone-cluster;Scheduler was sent the command new
06/03/2014 14:54:54;0040;PBS_Server;Svr;tyrone-cluster;Scheduler was sent the command new
06/03/2014 14:55:26;0040;PBS_Server;Svr;tyrone-cluster;Scheduler was sent the command new
06/03/2014 14:55:52;0100;PBS_Server;Job;39347.tyrone-cluster;enqueuing into batch, state 1 hop 1
06/03/2014 14:55:52;0100;PBS_Server;Job;39347.tyrone-cluster;dequeuing from batch, state QUEUED
06/03/2014 14:55:52;0100;PBS_Server;Job;39347.tyrone-cluster;enqueuing into qp32, state 1 hop 1
06/03/2014 14:55:52;0008;PBS_Server;Job;39347.tyrone-cluster;Job Queued at request of secpsm@tyrone-cluster, owner = secpsm@tyrone-cluster, job name = job32, queue = qp32
06/03/2014 14:55:52;0040;PBS_Server;Svr;tyrone-cluster;Scheduler was sent the command new
06/03/2014 14:55:52;0008;PBS_Server;Job;39347.tyrone-cluster;Job Modified at request of Scheduler@tyrone-cluster
06/03/2014 14:55:52;0008;PBS_Server;Job;39347.tyrone-cluster;Job Run at request of Scheduler@tyrone-cluster
06/03/2014 14:55:52;0040;PBS_Server;Svr;tyrone-cluster;Scheduler was sent the command recyc
06/03/2014 14:55:52;000d;PBS_Server;Job;39347.tyrone-cluster;Not sending email: User does not want mail of this type.
06/03/2014 14:55:57;0002;PBS_Server;Svr;PBS_Server;Torque Server Version = 3.0.5, loglevel = 0
06/03/2014 14:55:57;0040;PBS_Server;Svr;tyrone-cluster;Scheduler was sent the command new
06/03/2014 14:56:37;0040;PBS_Server;Svr;tyrone-cluster;Scheduler was sent the command new
06/03/2014 14:57:09;0040;PBS_Server;Svr;tyrone-cluster;Scheduler was sent the command new
06/03/2014 14:57:40;0040;PBS_Server;Svr;tyrone-cluster;Scheduler was sent the command new
06/03/2014 14:58:17;0040;PBS_Server;Svr;tyrone-cluster;Scheduler was sent the command new
06/03/2014 14:58:52;0040;PBS_Server;Svr;tyrone-cluster;Scheduler was sent the command new
06/03/2014 14:59:24;0040;PBS_Server;Svr;tyrone-cluster;Scheduler was sent the command new
06/03/2014 14:59:55;0040;PBS_Server;Svr;tyrone-cluster;Scheduler was sent the command new
06/03/2014 15:00:24;0040;PBS_Server;Svr;tyrone-cluster;Scheduler was sent the command new
06/03/2014 15:00:54;0040;PBS_Server;Svr;tyrone-cluster;Scheduler was sent the command new
06/03/2014 15:00:54;0100;PBS_Server;Job;39348.tyrone-cluster;enqueuing into batch, state 1 hop 1
06/03/2014 15:00:54;0008;PBS_Server;Job;39348.tyrone-cluster;Job rejected by all possible destinations (check syntax, queue resources, ...)
06/03/2014 15:00:54;0100;PBS_Server;Job;39348.tyrone-cluster;dequeuing from batch, state QUEUED
06/03/2014 15:00:54;0080;PBS_Server;Req;req_reject;Reject reply code=15041(Job rejected by all possible destinations (check syntax, queue resources, ...)), aux=0, type=Commit, from secbadar@tyrone-cluster
06/03/2014 15:00:57;0002;PBS_Server;Svr;PBS_Server;Torque Server Version = 3.0.5, loglevel = 0
06/03/2014 15:01:15;0100;PBS_Server;Job;39349.tyrone-cluster;enqueuing into batch, state 1 hop 1
06/03/2014 15:01:15;0008;PBS_Server;Job;39349.tyrone-cluster;Job rejected by all possible destinations (check syntax, queue resources, ...)
06/03/2014 15:01:15;0100;PBS_Server;Job;39349.tyrone-cluster;dequeuing from batch, state QUEUED
06/03/2014 15:01:15;0080;PBS_Server;Req;req_reject;Reject reply code=15041(Job rejected by all possible destinations (check syntax, queue resources, ...)), aux=0, type=Commit, from secbadar@tyrone-cluster
06/03/2014 15:01:15;0040;PBS_Server;Svr;tyrone-cluster;Scheduler was sent the command term
06/03/2014 15:01:20;0100;PBS_Server;Job;39350.tyrone-cluster;enqueuing into batch, state 1 hop 1
06/03/2014 15:01:20;0100;PBS_Server;Job;39350.tyrone-cluster;dequeuing from batch, state QUEUED
06/03/2014 15:01:20;0100;PBS_Server;Job;39350.tyrone-cluster;enqueuing into qp256, state 1 hop 1
06/03/2014 15:01:20;0008;PBS_Server;Job;39350.tyrone-cluster;Job Queued at request of secbadar@tyrone-cluster, owner = secbadar@tyrone-cluster, job name = job1285USGp, queue = qp256
06/03/2014 15:01:20;0040;PBS_Server;Svr;tyrone-cluster;Scheduler was sent the command new
06/03/2014 15:01:20;0008;PBS_Server;Job;39350.tyrone-cluster;Job Modified at request of Scheduler@tyrone-cluster
06/03/2014 15:01:20;0008;PBS_Server;Job;39350.tyrone-cluster;Job Run at request of Scheduler@tyrone-cluster
06/03/2014 15:01:20;0040;PBS_Server;Svr;tyrone-cluster;Scheduler was sent the command recyc
06/03/2014 15:01:25;0040;PBS_Server;Svr;tyrone-cluster;Scheduler was sent the command new
06/03/2014 15:01:25;0008;PBS_Server;Job;39312.tyrone-cluster;Job Modified at request of Scheduler@tyrone-cluster
06/03/2014 15:01:41;0100;PBS_Server;Job;39351.tyrone-cluster;enqueuing into batch, state 1 hop 1
06/03/2014 15:01:41;0100;PBS_Server;Job;39351.tyrone-cluster;dequeuing from batch, state QUEUED
06/03/2014 15:01:41;0100;PBS_Server;Job;39351.tyrone-cluster;enqueuing into qp32, state 1 hop 1
06/03/2014 15:01:41;0008;PBS_Server;Job;39351.tyrone-cluster;Job Queued at request of secanoop@tyrone-cluster, owner = secanoop@tyrone-cluster, job name = jobname, queue = qp32
06/03/2014 15:01:41;0040;PBS_Server;Svr;tyrone-cluster;Scheduler was sent the command new
06/03/2014 15:01:41;0008;PBS_Server;Job;39351.tyrone-cluster;Job Modified at request of Scheduler@tyrone-cluster
06/03/2014 15:01:41;0008;PBS_Server;Job;39351.tyrone-cluster;Job Run at request of Scheduler@tyrone-cluster
06/03/2014 15:01:41;0040;PBS_Server;Svr;tyrone-cluster;Scheduler was sent the command recyc
06/03/2014 15:01:41;000d;PBS_Server;Job;39351.tyrone-cluster;Not sending email: User does not want mail of this type.
06/03/2014 15:01:42;000d;PBS_Server;Job;39351.tyrone-cluster;Not sending email: User does not want mail of this type.
06/03/2014 15:01:42;0010;PBS_Server;Job;39351.tyrone-cluster;Exit_status=0 resources_used.cput=00:00:17 resources_used.mem=0kb resources_used.vmem=0kb resources_used.walltime=00:00:01
06/03/2014 15:01:42;0008;PBS_Server;Job;NULL;on_job_exit valid pjob: 0x1724940 (substate=50)
06/03/2014 15:01:42;0008;PBS_Server;Job;NULL;on_job_exit valid pjob: 0x1724940 (substate=51)
06/03/2014 15:01:42;0008;PBS_Server;Job;NULL;on_job_exit valid pjob: 0x1724940 (substate=51)
06/03/2014 15:01:42;0008;PBS_Server;Job;NULL;on_job_exit valid pjob: 0x1724940 (substate=53)
06/03/2014 15:01:42;0100;PBS_Server;Job;39351.tyrone-cluster;dequeuing from qp32, state COMPLETE
06/03/2014 15:01:42;0040;PBS_Server;Svr;tyrone-cluster;Scheduler was sent the command term
06/03/2014 15:02:02;0040;PBS_Server;Svr;tyrone-cluster;Scheduler was sent the command new
06/03/2014 15:02:36;0040;PBS_Server;Svr;tyrone-cluster;Scheduler was sent the command new
06/03/2014 15:02:43;000d;PBS_Server;Job;39350.tyrone-cluster;Not sending email: User does not want mail of this type.
06/03/2014 15:03:09;0040;PBS_Server;Svr;tyrone-cluster;Scheduler was sent the command new
06/03/2014 15:03:35;0100;PBS_Server;Job;39352.tyrone-cluster;enqueuing into batch, state 1 hop 1
06/03/2014 15:03:35;0008;PBS_Server;Job;39352.tyrone-cluster;Job rejected by all possible destinations (check syntax, queue resources, ...)
06/03/2014 15:03:35;0100;PBS_Server;Job;39352.tyrone-cluster;dequeuing from batch, state QUEUED
06/03/2014 15:03:35;0080;PBS_Server;Req;req_reject;Reject reply code=15041(Job rejected by all possible destinations (check syntax, queue resources, ...)), aux=0, type=Commit, from secbadar@tyrone-cluster
06/03/2014 15:03:35;0040;PBS_Server;Svr;tyrone-cluster;Scheduler was sent the command term
06/03/2014 15:03:40;0040;PBS_Server;Svr;tyrone-cluster;Scheduler was sent the command new
06/03/2014 15:04:13;0040;PBS_Server;Svr;tyrone-cluster;Scheduler was sent the command new
06/03/2014 15:04:27;0100;PBS_Server;Job;39353.tyrone-cluster;enqueuing into batch, state 1 hop 1
06/03/2014 15:04:27;0100;PBS_Server;Job;39353.tyrone-cluster;dequeuing from batch, state QUEUED
06/03/2014 15:04:27;0100;PBS_Server;Job;39353.tyrone-cluster;enqueuing into qp256, state 1 hop 1
06/03/2014 15:04:27;0008;PBS_Server;Job;39353.tyrone-cluster;Job Queued at request of secbadar@tyrone-cluster, owner = secbadar@tyrone-cluster, job name = job645USGp, queue = qp256
06/03/2014 15:04:27;0040;PBS_Server;Svr;tyrone-cluster;Scheduler was sent the command new
06/03/2014 15:04:28;0008;PBS_Server;Job;39353.tyrone-cluster;Job Modified at request of Scheduler@tyrone-cluster
06/03/2014 15:04:44;0040;PBS_Server;Svr;tyrone-cluster;Scheduler was sent the command new
06/03/2014 15:04:47;0008;PBS_Server;Job;39347.tyrone-cluster;Job deleted at request of secpsm@tyrone-cluster
06/03/2014 15:04:47;0008;PBS_Server;Job;39347.tyrone-cluster;Job sent signal SIGTERM on delete
06/03/2014 15:04:47;000d;PBS_Server;Job;39347.tyrone-cluster;Not sending email: User does not want mail of this type.
06/03/2014 15:04:47;0010;PBS_Server;Job;39347.tyrone-cluster;Exit_status=143 resources_used.cput=04:41:58 resources_used.mem=5099684kb resources_used.vmem=8719580kb resources_used.walltime=00:08:55
06/03/2014 15:04:47;0008;PBS_Server;Job;NULL;on_job_exit valid pjob: 0x177dbb0 (substate=50)
06/03/2014 15:04:47;0008;PBS_Server;Job;NULL;on_job_exit valid pjob: 0x177dbb0 (substate=51)
06/03/2014 15:04:55;0008;PBS_Server;Job;NULL;on_job_exit valid pjob: 0x177dbb0 (substate=51)
06/03/2014 15:04:55;000d;PBS_Server;Job;39347.tyrone-cluster;Post job file processing error; job 39347.tyrone-cluster on host tyrone-node2/31+tyrone-node2/30+tyrone-node2/29+tyrone-node2/28+tyrone-node2/27+tyrone-node2/26+tyrone-node2/25+tyrone-node2/24+tyrone-node2/23+tyrone-node2/22+tyrone-node2/21+tyrone-node2/20+tyrone-node2/19+tyrone-node2/18+tyrone-node2/17+tyrone-node2/16+tyrone-node2/15+tyrone-node2/14+tyrone-node2/13+tyrone-node2/12+tyrone-node2/11+tyrone-node2/10+tyrone-node2/9+tyrone-node2/8+tyrone-node2/7+tyrone-node2/6+tyrone-node2/5+tyrone-node2/4+tyrone-node2/3+tyrone-node2/2+tyrone-node2/1+tyrone-node2/0
06/03/2014 15:04:55;0008;PBS_Server;Job;NULL;on_job_exit valid pjob: 0x177dbb0 (substate=53)
06/03/2014 15:04:55;0100;PBS_Server;Job;39347.tyrone-cluster;dequeuing from qp32, state COMPLETE
06/03/2014 15:04:55;0040;PBS_Server;Svr;tyrone-cluster;Scheduler was sent the command term
06/03/2014 15:05:24;0040;PBS_Server;Svr;tyrone-cluster;Scheduler was sent the command new
06/03/2014 15:05:43;0100;PBS_Server;Job;39354.tyrone-cluster;enqueuing into batch, state 1 hop 1
06/03/2014 15:05:43;0100;PBS_Server;Job;39354.tyrone-cluster;dequeuing from batch, state QUEUED
06/03/2014 15:05:43;0100;PBS_Server;Job;39354.tyrone-cluster;enqueuing into qp32, state 1 hop 1
06/03/2014 15:05:43;0008;PBS_Server;Job;39354.tyrone-cluster;Job Queued at request of secpsm@tyrone-cluster, owner = secpsm@tyrone-cluster, job name = job32, queue = qp32
06/03/2014 15:05:43;0040;PBS_Server;Svr;tyrone-cluster;Scheduler was sent the command new
06/03/2014 15:05:43;0008;PBS_Server;Job;39354.tyrone-cluster;Job Modified at request of Scheduler@tyrone-cluster
06/03/2014 15:05:43;0008;PBS_Server;Job;39354.tyrone-cluster;Job Run at request of Scheduler@tyrone-cluster
06/03/2014 15:05:43;0040;PBS_Server;Svr;tyrone-cluster;Scheduler was sent the command recyc
06/03/2014 15:05:43;000d;PBS_Server;Job;39354.tyrone-cluster;Not sending email: User does not want mail of this type.
06/03/2014 15:05:46;0040;PBS_Server;Svr;tyrone-cluster;Scheduler was sent the command new
06/03/2014 15:05:57;0002;PBS_Server;Svr;PBS_Server;Torque Server Version = 3.0.5, loglevel = 0
06/03/2014 15:05:59;000d;PBS_Server;Job;39354.tyrone-cluster;Not sending email: User does not want mail of this type.
06/03/2014 15:05:59;0010;PBS_Server;Job;39354.tyrone-cluster;Exit_status=0 resources_used.cput=00:05:27 resources_used.mem=4884kb resources_used.vmem=42516kb resources_used.walltime=00:00:16
06/03/2014 15:05:59;0008;PBS_Server;Job;NULL;on_job_exit valid pjob: 0x177dbb0 (substate=50)
06/03/2014 15:05:59;0008;PBS_Server;Job;NULL;on_job_exit valid pjob: 0x177dbb0 (substate=51)
06/03/2014 15:06:08;0008;PBS_Server;Job;NULL;on_job_exit valid pjob: 0x177dbb0 (substate=51)
06/03/2014 15:06:08;000d;PBS_Server;Job;39354.tyrone-cluster;Post job file processing error; job 39354.tyrone-cluster on host tyrone-node2/31+tyrone-node2/30+tyrone-node2/29+tyrone-node2/28+tyrone-node2/27+tyrone-node2/26+tyrone-node2/25+tyrone-node2/24+tyrone-node2/23+tyrone-node2/22+tyrone-node2/21+tyrone-node2/20+tyrone-node2/19+tyrone-node2/18+tyrone-node2/17+tyrone-node2/16+tyrone-node2/15+tyrone-node2/14+tyrone-node2/13+tyrone-node2/12+tyrone-node2/11+tyrone-node2/10+tyrone-node2/9+tyrone-node2/8+tyrone-node2/7+tyrone-node2/6+tyrone-node2/5+tyrone-node2/4+tyrone-node2/3+tyrone-node2/2+tyrone-node2/1+tyrone-node2/0
06/03/2014 15:06:08;0008;PBS_Server;Job;NULL;on_job_exit valid pjob: 0x177dbb0 (substate=53)
06/03/2014 15:06:08;0100;PBS_Server;Job;39354.tyrone-cluster;dequeuing from qp32, state COMPLETE
06/03/2014 15:06:08;0040;PBS_Server;Svr;tyrone-cluster;Scheduler was sent the command term
06/03/2014 15:06:21;0040;PBS_Server;Svr;tyrone-cluster;Scheduler was sent the command new
06/03/2014 15:06:54;0040;PBS_Server;Svr;tyrone-cluster;Scheduler was sent the command new
06/03/2014 15:07:01;0100;PBS_Server;Job;39355.tyrone-cluster;enqueuing into batch, state 1 hop 1
06/03/2014 15:07:01;0100;PBS_Server;Job;39355.tyrone-cluster;dequeuing from batch, state QUEUED
06/03/2014 15:07:01;0100;PBS_Server;Job;39355.tyrone-cluster;enqueuing into qp32, state 1 hop 1
06/03/2014 15:07:01;0008;PBS_Server;Job;39355.tyrone-cluster;Job Queued at request of secpsm@tyrone-cluster, owner = secpsm@tyrone-cluster, job name = job32, queue = qp32
06/03/2014 15:07:01;0040;PBS_Server;Svr;tyrone-cluster;Scheduler was sent the command new
06/03/2014 15:07:01;0008;PBS_Server;Job;39355.tyrone-cluster;Job Modified at request of Scheduler@tyrone-cluster
06/03/2014 15:07:01;0008;PBS_Server;Job;39355.tyrone-cluster;Job Run at request of Scheduler@tyrone-cluster
06/03/2014 15:07:01;0040;PBS_Server;Svr;tyrone-cluster;Scheduler was sent the command recyc
06/03/2014 15:07:01;000d;PBS_Server;Job;39355.tyrone-cluster;Not sending email: User does not want mail of this type.
06/03/2014 15:07:25;0040;PBS_Server;Svr;tyrone-cluster;Scheduler was sent the command new
06/03/2014 15:07:58;0040;PBS_Server;Svr;tyrone-cluster;Scheduler was sent the command new
06/03/2014 15:08:37;0040;PBS_Server;Svr;tyrone-cluster;Scheduler was sent the command new
06/03/2014 15:09:09;0040;PBS_Server;Svr;tyrone-cluster;Scheduler was sent the command new
06/03/2014 15:09:41;0040;PBS_Server;Svr;tyrone-cluster;Scheduler was sent the command new
06/03/2014 15:10:13;0040;PBS_Server;Svr;tyrone-cluster;Scheduler was sent the command new
06/03/2014 15:10:51;0040;PBS_Server;Svr;tyrone-cluster;Scheduler was sent the command new
06/03/2014 15:10:57;0002;PBS_Server;Svr;PBS_Server;Torque Server Version = 3.0.5, loglevel = 0
06/03/2014 15:11:24;0040;PBS_Server;Svr;tyrone-cluster;Scheduler was sent the command new
06/03/2014 15:11:55;0040;PBS_Server;Svr;tyrone-cluster;Scheduler was sent the command new
06/03/2014 15:12:28;0040;PBS_Server;Svr;tyrone-cluster;Scheduler was sent the command new
06/03/2014 15:13:07;0040;PBS_Server;Svr;tyrone-cluster;Scheduler was sent the command new
06/03/2014 15:13:39;0040;PBS_Server;Svr;tyrone-cluster;Scheduler was sent the command new
06/03/2014 15:14:11;0040;PBS_Server;Svr;tyrone-cluster;Scheduler was sent the command new
06/03/2014 15:14:43;0040;PBS_Server;Svr;tyrone-cluster;Scheduler was sent the command new
06/03/2014 15:14:48;0100;PBS_Server;Job;39356.tyrone-cluster;enqueuing into batch, state 1 hop 1
06/03/2014 15:14:48;0100;PBS_Server;Job;39356.tyrone-cluster;dequeuing from batch, state QUEUED
06/03/2014 15:14:48;0100;PBS_Server;Job;39356.tyrone-cluster;enqueuing into qp32, state 1 hop 1
06/03/2014 15:14:48;0008;PBS_Server;Job;39356.tyrone-cluster;Job Queued at request of secanoop@tyrone-cluster, owner = secanoop@tyrone-cluster, job name = jobname, queue = qp32
06/03/2014 15:14:48;0040;PBS_Server;Svr;tyrone-cluster;Scheduler was sent the command new
06/03/2014 15:14:48;0008;PBS_Server;Job;39356.tyrone-cluster;Job Modified at request of Scheduler@tyrone-cluster
06/03/2014 15:14:48;0008;PBS_Server;Job;39356.tyrone-cluster;Job Run at request of Scheduler@tyrone-cluster
06/03/2014 15:14:48;0040;PBS_Server;Svr;tyrone-cluster;Scheduler was sent the command recyc
06/03/2014 15:14:48;000d;PBS_Server;Job;39356.tyrone-cluster;Not sending email: User does not want mail of this type.
06/03/2014 15:14:49;000d;PBS_Server;Job;39356.tyrone-cluster;Not sending email: User does not want mail of this type.
06/03/2014 15:14:49;0010;PBS_Server;Job;39356.tyrone-cluster;Exit_status=0 resources_used.cput=00:00:19 resources_used.mem=0kb resources_used.vmem=0kb resources_used.walltime=00:00:01
06/03/2014 15:14:49;0008;PBS_Server;Job;NULL;on_job_exit valid pjob: 0x1791590 (substate=50)
06/03/2014 15:14:49;0008;PBS_Server;Job;NULL;on_job_exit valid pjob: 0x1791590 (substate=51)
06/03/2014 15:14:49;0008;PBS_Server;Job;NULL;on_job_exit valid pjob: 0x1791590 (substate=51)
06/03/2014 15:14:49;0008;PBS_Server;Job;NULL;on_job_exit valid pjob: 0x1791590 (substate=53)
06/03/2014 15:14:49;0100;PBS_Server;Job;39356.tyrone-cluster;dequeuing from qp32, state COMPLETE
06/03/2014 15:14:49;0040;PBS_Server;Svr;tyrone-cluster;Scheduler was sent the command term
06/03/2014 15:15:06;000d;PBS_Server;Job;39211.tyrone-cluster;Not sending email: User does not want mail of this type.
06/03/2014 15:15:06;0010;PBS_Server;Job;39211.tyrone-cluster;Exit_status=0 resources_used.cput=486:52:34 resources_used.mem=1162020kb resources_used.vmem=7434448kb resources_used.walltime=15:15:52
06/03/2014 15:15:06;0008;PBS_Server;Job;NULL;on_job_exit valid pjob: 0x1720110 (substate=50)
06/03/2014 15:15:06;0008;PBS_Server;Job;NULL;on_job_exit valid pjob: 0x1720110 (substate=51)
06/03/2014 15:15:15;0008;PBS_Server;Job;NULL;on_job_exit valid pjob: 0x1720110 (substate=51)
06/03/2014 15:15:15;000d;PBS_Server;Job;39211.tyrone-cluster;Post job file processing error; job 39211.tyrone-cluster on host tyrone-node6/31+tyrone-node6/30+tyrone-node6/29+tyrone-node6/28+tyrone-node6/27+tyrone-node6/26+tyrone-node6/25+tyrone-node6/24+tyrone-node6/23+tyrone-node6/22+tyrone-node6/21+tyrone-node6/20+tyrone-node6/19+tyrone-node6/18+tyrone-node6/17+tyrone-node6/16+tyrone-node6/15+tyrone-node6/14+tyrone-node6/13+tyrone-node6/12+tyrone-node6/11+tyrone-node6/10+tyrone-node6/9+tyrone-node6/8+tyrone-node6/7+tyrone-node6/6+tyrone-node6/5+tyrone-node6/4+tyrone-node6/3+tyrone-node6/2+tyrone-node6/1+tyrone-node6/0+tyrone-node1/31+tyrone-node1/30+tyrone-node1/29+tyrone-node1/28+tyrone-node1/27+tyrone-node1/26+tyrone-node1/25+tyrone-node1/24+tyrone-node1/23+tyrone-node1/22+tyrone-node1/21+tyrone-node1/20+tyrone-node1/19+tyrone-node1/18+tyrone-node1/17+tyrone-node1/16+tyrone-node1/15+tyrone-node1/14+tyrone-node1/13+tyrone-node1/12+tyrone-node1/11+tyrone-node1/10+tyrone-node1/9+tyrone-node1/8+tyrone-node1/7+tyrone-node1/6+tyrone-node1/5+tyrone-node1/4+tyrone-node1/3+tyrone-node1/2+tyrone-node1/1+tyrone-node1/0
06/03/2014 15:15:15;0008;PBS_Server;Job;NULL;on_job_exit valid pjob: 0x1720110 (substate=53)
06/03/2014 15:15:15;0100;PBS_Server;Job;39211.tyrone-cluster;dequeuing from qp64, state COMPLETE
06/03/2014 15:15:15;0040;PBS_Server;Svr;tyrone-cluster;Scheduler was sent the command term
06/03/2014 15:15:15;0008;PBS_Server;Job;39253.tyrone-cluster;Job Modified at request of Scheduler@tyrone-cluster
06/03/2014 15:15:15;0008;PBS_Server;Job;39253.tyrone-cluster;Job Run at request of Scheduler@tyrone-cluster
06/03/2014 15:15:15;0040;PBS_Server;Svr;tyrone-cluster;Scheduler was sent the command recyc
06/03/2014 15:15:51;0040;PBS_Server;Svr;tyrone-cluster;Scheduler was sent the command new
06/03/2014 15:15:57;0002;PBS_Server;Svr;PBS_Server;Torque Server Version = 3.0.5, loglevel = 0
06/03/2014 15:16:06;000d;PBS_Server;Job;39253.tyrone-cluster;Not sending email: User does not want mail of this type.
06/03/2014 15:16:18;0040;PBS_Server;Svr;tyrone-cluster;Scheduler was sent the command new
06/03/2014 15:16:51;0040;PBS_Server;Svr;tyrone-cluster;Scheduler was sent the command new
06/03/2014 15:17:24;0040;PBS_Server;Svr;tyrone-cluster;Scheduler was sent the command new
06/03/2014 15:17:56;0040;PBS_Server;Svr;tyrone-cluster;Scheduler was sent the command new
06/03/2014 15:18:28;0040;PBS_Server;Svr;tyrone-cluster;Scheduler was sent the command new
06/03/2014 15:19:06;0040;PBS_Server;Svr;tyrone-cluster;Scheduler was sent the command new
06/03/2014 15:19:39;0040;PBS_Server;Svr;tyrone-cluster;Scheduler was sent the command new
06/03/2014 15:20:10;0040;PBS_Server;Svr;tyrone-cluster;Scheduler was sent the command new
06/03/2014 15:20:43;0040;PBS_Server;Svr;tyrone-cluster;Scheduler was sent the command new
06/03/2014 15:20:57;0002;PBS_Server;Svr;PBS_Server;Torque Server Version = 3.0.5, loglevel = 0
06/03/2014 15:21:09;0040;PBS_Server;Svr;tyrone-cluster;Scheduler was sent the command new
06/03/2014 15:21:41;0040;PBS_Server;Svr;tyrone-cluster;Scheduler was sent the command new
06/03/2014 15:22:13;0040;PBS_Server;Svr;tyrone-cluster;Scheduler was sent the command new
06/03/2014 15:22:51;0040;PBS_Server;Svr;tyrone-cluster;Scheduler was sent the command new
06/03/2014 15:23:24;0040;PBS_Server;Svr;tyrone-cluster;Scheduler was sent the command new
06/03/2014 15:23:55;0040;PBS_Server;Svr;tyrone-cluster;Scheduler was sent the command new
06/03/2014 15:24:28;0040;PBS_Server;Svr;tyrone-cluster;Scheduler was sent the command new
06/03/2014 15:25:06;0040;PBS_Server;Svr;tyrone-cluster;Scheduler was sent the command new
06/03/2014 15:25:39;0040;PBS_Server;Svr;tyrone-cluster;Scheduler was sent the command new
06/03/2014 15:25:57;0002;PBS_Server;Svr;PBS_Server;Torque Server Version = 3.0.5, loglevel = 0
06/03/2014 15:26:10;0040;PBS_Server;Svr;tyrone-cluster;Scheduler was sent the command new
06/03/2014 15:26:43;0040;PBS_Server;Svr;tyrone-cluster;Scheduler was sent the command new
06/03/2014 15:27:09;0040;PBS_Server;Svr;tyrone-cluster;Scheduler was sent the command new
06/03/2014 15:27:41;0040;PBS_Server;Svr;tyrone-cluster;Scheduler was sent the command new
06/03/2014 15:28:13;0040;PBS_Server;Svr;tyrone-cluster;Scheduler was sent the command new
06/03/2014 15:28:51;0040;PBS_Server;Svr;tyrone-cluster;Scheduler was sent the command new
06/03/2014 15:29:24;0040;PBS_Server;Svr;tyrone-cluster;Scheduler was sent the command new
06/03/2014 15:29:55;0040;PBS_Server;Svr;tyrone-cluster;Scheduler was sent the command new
06/03/2014 15:30:28;0040;PBS_Server;Svr;tyrone-cluster;Scheduler was sent the command new
06/03/2014 15:30:57;0002;PBS_Server;Svr;PBS_Server;Torque Server Version = 3.0.5, loglevel = 0
06/03/2014 15:31:06;0040;PBS_Server;Svr;tyrone-cluster;Scheduler was sent the command new
06/03/2014 15:31:39;0040;PBS_Server;Svr;tyrone-cluster;Scheduler was sent the command new
06/03/2014 15:32:11;0040;PBS_Server;Svr;tyrone-cluster;Scheduler was sent the command new
06/03/2014 15:32:43;0040;PBS_Server;Svr;tyrone-cluster;Scheduler was sent the command new
06/03/2014 15:33:21;0040;PBS_Server;Svr;tyrone-cluster;Scheduler was sent the command new
06/03/2014 15:33:54;0040;PBS_Server;Svr;tyrone-cluster;Scheduler was sent the command new
06/03/2014 15:34:27;0040;PBS_Server;Svr;tyrone-cluster;Scheduler was sent the command new
06/03/2014 15:34:58;0040;PBS_Server;Svr;tyrone-cluster;Scheduler was sent the command new
06/03/2014 15:35:36;0040;PBS_Server;Svr;tyrone-cluster;Scheduler was sent the command new
06/03/2014 15:35:57;0002;PBS_Server;Svr;PBS_Server;Torque Server Version = 3.0.5, loglevel = 0
06/03/2014 15:36:09;0040;PBS_Server;Svr;tyrone-cluster;Scheduler was sent the command new
06/03/2014 15:36:29;0008;PBS_Server;Job;39350.tyrone-cluster;Job deleted at request of secbadar@tyrone-cluster
06/03/2014 15:36:29;0008;PBS_Server;Job;39350.tyrone-cluster;Job sent signal SIGTERM on delete
06/03/2014 15:36:29;000d;PBS_Server;Job;39350.tyrone-cluster;Not sending email: User does not want mail of this type.
06/03/2014 15:36:29;0010;PBS_Server;Job;39350.tyrone-cluster;Exit_status=143 resources_used.cput=01:15:54 resources_used.mem=497872kb resources_used.vmem=1297944kb resources_used.walltime=00:35:10
06/03/2014 15:36:29;0008;PBS_Server;Job;NULL;on_job_exit valid pjob: 0x1789fc0 (substate=50)
06/03/2014 15:36:29;0008;PBS_Server;Job;NULL;on_job_exit valid pjob: 0x1789fc0 (substate=51)
06/03/2014 15:36:29;0008;PBS_Server;Job;NULL;on_job_exit valid pjob: 0x1789fc0 (substate=51)
06/03/2014 15:36:29;0008;PBS_Server;Job;NULL;on_job_exit valid pjob: 0x1789fc0 (substate=53)
06/03/2014 15:36:29;0100;PBS_Server;Job;39350.tyrone-cluster;dequeuing from qp256, state COMPLETE
06/03/2014 15:36:29;0040;PBS_Server;Svr;tyrone-cluster;Scheduler was sent the command term
06/03/2014 15:36:29;0008;PBS_Server;Job;39312.tyrone-cluster;Job Modified at request of Scheduler@tyrone-cluster
06/03/2014 15:36:29;0008;PBS_Server;Job;39353.tyrone-cluster;Job Modified at request of Scheduler@tyrone-cluster
06/03/2014 15:36:29;0008;PBS_Server;Job;39353.tyrone-cluster;Job Run at request of Scheduler@tyrone-cluster
06/03/2014 15:36:29;0040;PBS_Server;Svr;tyrone-cluster;Scheduler was sent the command recyc
06/03/2014 15:36:33;000d;PBS_Server;Job;39353.tyrone-cluster;Not sending email: User does not want mail of this type.
06/03/2014 15:36:40;0040;PBS_Server;Svr;tyrone-cluster;Scheduler was sent the command new
06/03/2014 15:36:41;0008;PBS_Server;Job;39312.tyrone-cluster;Job Modified at request of Scheduler@tyrone-cluster
06/03/2014 15:37:13;0040;PBS_Server;Svr;tyrone-cluster;Scheduler was sent the command new
06/03/2014 15:37:39;0040;PBS_Server;Svr;tyrone-cluster;Scheduler was sent the command new
06/03/2014 15:38:10;0040;PBS_Server;Svr;tyrone-cluster;Scheduler was sent the command new
06/03/2014 15:38:47;0040;PBS_Server;Svr;tyrone-cluster;Scheduler was sent the command new
06/03/2014 15:39:17;0040;PBS_Server;Svr;tyrone-cluster;Scheduler was sent the command new
06/03/2014 15:39:54;0040;PBS_Server;Svr;tyrone-cluster;Scheduler was sent the command new
06/03/2014 15:40:26;0040;PBS_Server;Svr;tyrone-cluster;Scheduler was sent the command new
06/03/2014 15:40:57;0002;PBS_Server;Svr;PBS_Server;Torque Server Version = 3.0.5, loglevel = 0
06/03/2014 15:40:57;0040;PBS_Server;Svr;tyrone-cluster;Scheduler was sent the command new
06/03/2014 15:41:36;0040;PBS_Server;Svr;tyrone-cluster;Scheduler was sent the command new
06/03/2014 15:42:09;0040;PBS_Server;Svr;tyrone-cluster;Scheduler was sent the command new
06/03/2014 15:42:41;0040;PBS_Server;Svr;tyrone-cluster;Scheduler was sent the command new
06/03/2014 15:42:55;0100;PBS_Server;Job;39357.tyrone-cluster;enqueuing into batch, state 1 hop 1
06/03/2014 15:42:55;0100;PBS_Server;Job;39357.tyrone-cluster;dequeuing from batch, state QUEUED
06/03/2014 15:42:55;0100;PBS_Server;Job;39357.tyrone-cluster;enqueuing into idqueue, state 1 hop 1
06/03/2014 15:42:55;0008;PBS_Server;Job;39357.tyrone-cluster;Job Queued at request of secpka@tyrone-cluster, owner = secpka@tyrone-cluster, job name = jobname, queue = idqueue
06/03/2014 15:42:55;0040;PBS_Server;Svr;tyrone-cluster;Scheduler was sent the command new
06/03/2014 15:42:55;0008;PBS_Server;Job;39357.tyrone-cluster;Job Modified at request of Scheduler@tyrone-cluster
06/03/2014 15:42:55;0008;PBS_Server;Job;39357.tyrone-cluster;Job Run at request of Scheduler@tyrone-cluster
06/03/2014 15:42:55;0040;PBS_Server;Svr;tyrone-cluster;Scheduler was sent the command recyc
06/03/2014 15:42:56;000d;PBS_Server;Job;39357.tyrone-cluster;Not sending email: User does not want mail of this type.
06/03/2014 15:43:04;000d;PBS_Server;Job;39357.tyrone-cluster;Not sending email: User does not want mail of this type.
06/03/2014 15:43:04;0010;PBS_Server;Job;39357.tyrone-cluster;Exit_status=0 resources_used.cput=00:01:09 resources_used.mem=0kb resources_used.vmem=0kb resources_used.walltime=00:00:09
06/03/2014 15:43:04;0008;PBS_Server;Job;NULL;on_job_exit valid pjob: 0x1791590 (substate=50)
06/03/2014 15:43:04;0008;PBS_Server;Job;NULL;on_job_exit valid pjob: 0x1791590 (substate=51)
06/03/2014 15:43:04;0008;PBS_Server;Job;NULL;on_job_exit valid pjob: 0x1791590 (substate=51)
06/03/2014 15:43:04;0008;PBS_Server;Job;NULL;on_job_exit valid pjob: 0x1791590 (substate=53)
06/03/2014 15:43:04;0100;PBS_Server;Job;39357.tyrone-cluster;dequeuing from idqueue, state COMPLETE
06/03/2014 15:43:04;0040;PBS_Server;Svr;tyrone-cluster;Scheduler was sent the command term
06/03/2014 15:43:17;0040;PBS_Server;Svr;tyrone-cluster;Scheduler was sent the command new
06/03/2014 15:43:51;0040;PBS_Server;Svr;tyrone-cluster;Scheduler was sent the command new
06/03/2014 15:44:24;0040;PBS_Server;Svr;tyrone-cluster;Scheduler was sent the command new
06/03/2014 15:44:55;0040;PBS_Server;Svr;tyrone-cluster;Scheduler was sent the command new
06/03/2014 15:45:06;0100;PBS_Server;Job;39358.tyrone-cluster;enqueuing into batch, state 1 hop 1
06/03/2014 15:45:06;0100;PBS_Server;Job;39358.tyrone-cluster;dequeuing from batch, state QUEUED
06/03/2014 15:45:06;0100;PBS_Server;Job;39358.tyrone-cluster;enqueuing into qp256, state 1 hop 1
06/03/2014 15:45:06;0008;PBS_Server;Job;39358.tyrone-cluster;Job Queued at request of secbadar@tyrone-cluster, owner = secbadar@tyrone-cluster, job name = jobpMpiUns, queue = qp256
06/03/2014 15:45:06;0040;PBS_Server;Svr;tyrone-cluster;Scheduler was sent the command new
06/03/2014 15:45:06;0008;PBS_Server;Job;39358.tyrone-cluster;Job Modified at request of Scheduler@tyrone-cluster
06/03/2014 15:45:28;0040;PBS_Server;Svr;tyrone-cluster;Scheduler was sent the command new
06/03/2014 15:45:54;0040;PBS_Server;Svr;tyrone-cluster;Scheduler was sent the command new
06/03/2014 15:45:57;0002;PBS_Server;Svr;PBS_Server;Torque Server Version = 3.0.5, loglevel = 0
06/03/2014 15:46:25;0040;PBS_Server;Svr;tyrone-cluster;Scheduler was sent the command new
06/03/2014 15:46:57;0040;PBS_Server;Svr;tyrone-cluster;Scheduler was sent the command new
06/03/2014 15:47:36;0040;PBS_Server;Svr;tyrone-cluster;Scheduler was sent the command new
06/03/2014 15:48:09;0040;PBS_Server;Svr;tyrone-cluster;Scheduler was sent the command new
06/03/2014 15:48:26;0100;PBS_Server;Job;39359.tyrone-cluster;enqueuing into batch, state 1 hop 1
06/03/2014 15:48:26;0100;PBS_Server;Job;39359.tyrone-cluster;dequeuing from batch, state QUEUED
06/03/2014 15:48:26;0100;PBS_Server;Job;39359.tyrone-cluster;enqueuing into idqueue, state 1 hop 1
06/03/2014 15:48:26;0008;PBS_Server;Job;39359.tyrone-cluster;Job Queued at request of secpka@tyrone-cluster, owner = secpka@tyrone-cluster, job name = jobname, queue = idqueue
06/03/2014 15:48:26;0040;PBS_Server;Svr;tyrone-cluster;Scheduler was sent the command new
06/03/2014 15:48:27;0008;PBS_Server;Job;39359.tyrone-cluster;Job Modified at request of Scheduler@tyrone-cluster
06/03/2014 15:48:27;0008;PBS_Server;Job;39359.tyrone-cluster;Job Run at request of Scheduler@tyrone-cluster
06/03/2014 15:48:27;0040;PBS_Server;Svr;tyrone-cluster;Scheduler was sent the command recyc
06/03/2014 15:48:27;000d;PBS_Server;Job;39359.tyrone-cluster;Not sending email: User does not want mail of this type.
06/03/2014 15:48:34;000d;PBS_Server;Job;39359.tyrone-cluster;Not sending email: User does not want mail of this type.
06/03/2014 15:48:34;0010;PBS_Server;Job;39359.tyrone-cluster;Exit_status=0 resources_used.cput=00:00:57 resources_used.mem=0kb resources_used.vmem=0kb resources_used.walltime=00:00:06
06/03/2014 15:48:34;0008;PBS_Server;Job;NULL;on_job_exit valid pjob: 0x17999c0 (substate=50)
06/03/2014 15:48:34;0008;PBS_Server;Job;NULL;on_job_exit valid pjob: 0x17999c0 (substate=51)
06/03/2014 15:48:34;0008;PBS_Server;Job;NULL;on_job_exit valid pjob: 0x17999c0 (substate=51)
06/03/2014 15:48:34;0008;PBS_Server;Job;NULL;on_job_exit valid pjob: 0x17999c0 (substate=53)
06/03/2014 15:48:34;0100;PBS_Server;Job;39359.tyrone-cluster;dequeuing from idqueue, state COMPLETE
06/03/2014 15:48:34;0040;PBS_Server;Svr;tyrone-cluster;Scheduler was sent the command term
06/03/2014 15:48:41;0040;PBS_Server;Svr;tyrone-cluster;Scheduler was sent the command new
06/03/2014 15:49:11;0040;PBS_Server;Svr;tyrone-cluster;Scheduler was sent the command new
06/03/2014 15:49:51;0040;PBS_Server;Svr;tyrone-cluster;Scheduler was sent the command new
06/03/2014 15:50:24;0040;PBS_Server;Svr;tyrone-cluster;Scheduler was sent the command new
06/03/2014 15:50:47;0100;PBS_Server;Job;39360.tyrone-cluster;enqueuing into batch, state 1 hop 1
06/03/2014 15:50:47;0100;PBS_Server;Job;39360.tyrone-cluster;dequeuing from batch, state QUEUED
06/03/2014 15:50:47;0100;PBS_Server;Job;39360.tyrone-cluster;enqueuing into idqueue, state 1 hop 1
06/03/2014 15:50:47;0008;PBS_Server;Job;39360.tyrone-cluster;Job Queued at request of secpka@tyrone-cluster, owner = secpka@tyrone-cluster, job name = jobname, queue = idqueue
06/03/2014 15:50:47;0040;PBS_Server;Svr;tyrone-cluster;Scheduler was sent the command new
06/03/2014 15:50:47;0008;PBS_Server;Job;39360.tyrone-cluster;Job Modified at request of Scheduler@tyrone-cluster
06/03/2014 15:50:47;0008;PBS_Server;Job;39360.tyrone-cluster;Job Run at request of Scheduler@tyrone-cluster
06/03/2014 15:50:47;0040;PBS_Server;Svr;tyrone-cluster;Scheduler was sent the command recyc
06/03/2014 15:50:47;000d;PBS_Server;Job;39360.tyrone-cluster;Not sending email: User does not want mail of this type.
06/03/2014 15:50:53;000d;PBS_Server;Job;39360.tyrone-cluster;Not sending email: User does not want mail of this type.
06/03/2014 15:50:53;0010;PBS_Server;Job;39360.tyrone-cluster;Exit_status=0 resources_used.cput=00:00:47 resources_used.mem=0kb resources_used.vmem=0kb resources_used.walltime=00:00:06
06/03/2014 15:50:53;0008;PBS_Server;Job;NULL;on_job_exit valid pjob: 0x17999c0 (substate=50)
06/03/2014 15:50:53;0008;PBS_Server;Job;NULL;on_job_exit valid pjob: 0x17999c0 (substate=51)
06/03/2014 15:50:53;0008;PBS_Server;Job;NULL;on_job_exit valid pjob: 0x17999c0 (substate=51)
06/03/2014 15:50:53;0008;PBS_Server;Job;NULL;on_job_exit valid pjob: 0x17999c0 (substate=53)
06/03/2014 15:50:53;0100;PBS_Server;Job;39360.tyrone-cluster;dequeuing from idqueue, state COMPLETE
06/03/2014 15:50:53;0040;PBS_Server;Svr;tyrone-cluster;Scheduler was sent the command term
06/03/2014 15:50:55;0040;PBS_Server;Svr;tyrone-cluster;Scheduler was sent the command new
06/03/2014 15:50:57;0002;PBS_Server;Svr;PBS_Server;Torque Server Version = 3.0.5, loglevel = 0
06/03/2014 15:51:31;0040;PBS_Server;Svr;tyrone-cluster;Scheduler was sent the command new
06/03/2014 15:52:06;0040;PBS_Server;Svr;tyrone-cluster;Scheduler was sent the command new
06/03/2014 15:52:39;0040;PBS_Server;Svr;tyrone-cluster;Scheduler was sent the command new
06/03/2014 15:53:12;0040;PBS_Server;Svr;tyrone-cluster;Scheduler was sent the command new
06/03/2014 15:53:19;0100;PBS_Server;Job;39361.tyrone-cluster;enqueuing into batch, state 1 hop 1
06/03/2014 15:53:19;0100;PBS_Server;Job;39361.tyrone-cluster;dequeuing from batch, state QUEUED
06/03/2014 15:53:19;0100;PBS_Server;Job;39361.tyrone-cluster;enqueuing into idqueue, state 1 hop 1
06/03/2014 15:53:19;0008;PBS_Server;Job;39361.tyrone-cluster;Job Queued at request of secpka@tyrone-cluster, owner = secpka@tyrone-cluster, job name = jobname, queue = idqueue
06/03/2014 15:53:19;0040;PBS_Server;Svr;tyrone-cluster;Scheduler was sent the command new
06/03/2014 15:53:19;0008;PBS_Server;Job;39361.tyrone-cluster;Job Modified at request of Scheduler@tyrone-cluster
06/03/2014 15:53:19;0008;PBS_Server;Job;39361.tyrone-cluster;Job Run at request of Scheduler@tyrone-cluster
06/03/2014 15:53:19;0040;PBS_Server;Svr;tyrone-cluster;Scheduler was sent the command recyc
06/03/2014 15:53:19;000d;PBS_Server;Job;39361.tyrone-cluster;Not sending email: User does not want mail of this type.
06/03/2014 15:53:23;000d;PBS_Server;Job;39361.tyrone-cluster;Not sending email: User does not want mail of this type.
06/03/2014 15:53:23;0010;PBS_Server;Job;39361.tyrone-cluster;Exit_status=0 resources_used.cput=00:00:35 resources_used.mem=0kb resources_used.vmem=0kb resources_used.walltime=00:00:04
06/03/2014 15:53:23;0008;PBS_Server;Job;NULL;on_job_exit valid pjob: 0x17999c0 (substate=50)
06/03/2014 15:53:23;0008;PBS_Server;Job;NULL;on_job_exit valid pjob: 0x17999c0 (substate=51)
06/03/2014 15:53:23;0008;PBS_Server;Job;NULL;on_job_exit valid pjob: 0x17999c0 (substate=51)
06/03/2014 15:53:23;0008;PBS_Server;Job;NULL;on_job_exit valid pjob: 0x17999c0 (substate=53)
06/03/2014 15:53:23;0100;PBS_Server;Job;39361.tyrone-cluster;dequeuing from idqueue, state COMPLETE
06/03/2014 15:53:23;0040;PBS_Server;Svr;tyrone-cluster;Scheduler was sent the command term
06/03/2014 15:53:38;0100;PBS_Server;Job;39362.tyrone-cluster;enqueuing into batch, state 1 hop 1
06/03/2014 15:53:38;0100;PBS_Server;Job;39362.tyrone-cluster;dequeuing from batch, state QUEUED
06/03/2014 15:53:38;0100;PBS_Server;Job;39362.tyrone-cluster;enqueuing into idqueue, state 1 hop 1
06/03/2014 15:53:38;0008;PBS_Server;Job;39362.tyrone-cluster;Job Queued at request of secpka@tyrone-cluster, owner = secpka@tyrone-cluster, job name = jobname, queue = idqueue
06/03/2014 15:53:38;0040;PBS_Server;Svr;tyrone-cluster;Scheduler was sent the command new
06/03/2014 15:53:38;0008;PBS_Server;Job;39362.tyrone-cluster;Job Modified at request of Scheduler@tyrone-cluster
06/03/2014 15:53:38;0008;PBS_Server;Job;39362.tyrone-cluster;Job Run at request of Scheduler@tyrone-cluster
06/03/2014 15:53:38;0040;PBS_Server;Svr;tyrone-cluster;Scheduler was sent the command recyc
06/03/2014 15:53:38;000d;PBS_Server;Job;39362.tyrone-cluster;Not sending email: User does not want mail of this type.
06/03/2014 15:53:42;0040;PBS_Server;Svr;tyrone-cluster;Scheduler was sent the command new
06/03/2014 15:53:42;000d;PBS_Server;Job;39362.tyrone-cluster;Not sending email: User does not want mail of this type.
06/03/2014 15:53:42;0010;PBS_Server;Job;39362.tyrone-cluster;Exit_status=0 resources_used.cput=00:00:23 resources_used.mem=0kb resources_used.vmem=0kb resources_used.walltime=00:00:04
06/03/2014 15:53:42;0008;PBS_Server;Job;NULL;on_job_exit valid pjob: 0x17999c0 (substate=50)
06/03/2014 15:53:42;0008;PBS_Server;Job;NULL;on_job_exit valid pjob: 0x17999c0 (substate=51)
06/03/2014 15:53:42;0008;PBS_Server;Job;NULL;on_job_exit valid pjob: 0x17999c0 (substate=51)
06/03/2014 15:53:42;0008;PBS_Server;Job;NULL;on_job_exit valid pjob: 0x17999c0 (substate=53)
06/03/2014 15:53:42;0100;PBS_Server;Job;39362.tyrone-cluster;dequeuing from idqueue, state COMPLETE
06/03/2014 15:54:10;0100;PBS_Server;Job;39363.tyrone-cluster;enqueuing into batch, state 1 hop 1
06/03/2014 15:54:10;0100;PBS_Server;Job;39363.tyrone-cluster;dequeuing from batch, state QUEUED
06/03/2014 15:54:10;0100;PBS_Server;Job;39363.tyrone-cluster;enqueuing into idqueue, state 1 hop 1
06/03/2014 15:54:10;0008;PBS_Server;Job;39363.tyrone-cluster;Job Queued at request of secpka@tyrone-cluster, owner = secpka@tyrone-cluster, job name = jobname, queue = idqueue
06/03/2014 15:54:10;0040;PBS_Server;Svr;tyrone-cluster;Scheduler was sent the command new
06/03/2014 15:54:10;0008;PBS_Server;Job;39363.tyrone-cluster;Job Modified at request of Scheduler@tyrone-cluster
06/03/2014 15:54:10;0008;PBS_Server;Job;39363.tyrone-cluster;Job Run at request of Scheduler@tyrone-cluster
06/03/2014 15:54:10;0040;PBS_Server;Svr;tyrone-cluster;Scheduler was sent the command recyc
06/03/2014 15:54:10;000d;PBS_Server;Job;39363.tyrone-cluster;Not sending email: User does not want mail of this type.
06/03/2014 15:54:12;0040;PBS_Server;Svr;tyrone-cluster;Scheduler was sent the command new
06/03/2014 15:54:12;000d;PBS_Server;Job;39363.tyrone-cluster;Not sending email: User does not want mail of this type.
06/03/2014 15:54:12;0010;PBS_Server;Job;39363.tyrone-cluster;Exit_status=0 resources_used.cput=00:00:12 resources_used.mem=0kb resources_used.vmem=0kb resources_used.walltime=00:00:02
06/03/2014 15:54:12;0008;PBS_Server;Job;NULL;on_job_exit valid pjob: 0x17999c0 (substate=50)
06/03/2014 15:54:12;0008;PBS_Server;Job;NULL;on_job_exit valid pjob: 0x17999c0 (substate=51)
06/03/2014 15:54:12;0008;PBS_Server;Job;NULL;on_job_exit valid pjob: 0x17999c0 (substate=51)
06/03/2014 15:54:12;0008;PBS_Server;Job;NULL;on_job_exit valid pjob: 0x17999c0 (substate=53)
06/03/2014 15:54:12;0100;PBS_Server;Job;39363.tyrone-cluster;dequeuing from idqueue, state COMPLETE
06/03/2014 15:54:12;0040;PBS_Server;Svr;tyrone-cluster;Scheduler was sent the command term
06/03/2014 15:54:44;0040;PBS_Server;Svr;tyrone-cluster;Scheduler was sent the command new
06/03/2014 15:55:17;0040;PBS_Server;Svr;tyrone-cluster;Scheduler was sent the command new
06/03/2014 15:55:51;0040;PBS_Server;Svr;tyrone-cluster;Scheduler was sent the command new
06/03/2014 15:55:57;0002;PBS_Server;Svr;PBS_Server;Torque Server Version = 3.0.5, loglevel = 0
06/03/2014 15:56:24;0040;PBS_Server;Svr;tyrone-cluster;Scheduler was sent the command new
06/03/2014 15:56:56;0040;PBS_Server;Svr;tyrone-cluster;Scheduler was sent the command new
06/03/2014 15:57:32;0040;PBS_Server;Svr;tyrone-cluster;Scheduler was sent the command new
06/03/2014 15:57:53;0100;PBS_Server;Job;39364.tyrone-cluster;enqueuing into batch, state 1 hop 1
06/03/2014 15:57:53;0100;PBS_Server;Job;39364.tyrone-cluster;dequeuing from batch, state QUEUED
06/03/2014 15:57:53;0100;PBS_Server;Job;39364.tyrone-cluster;enqueuing into idqueue, state 1 hop 1
06/03/2014 15:57:53;0008;PBS_Server;Job;39364.tyrone-cluster;Job Queued at request of secpka@tyrone-cluster, owner = secpka@tyrone-cluster, job name = jobname, queue = idqueue
06/03/2014 15:57:53;0040;PBS_Server;Svr;tyrone-cluster;Scheduler was sent the command new
06/03/2014 15:57:53;0008;PBS_Server;Job;39364.tyrone-cluster;Job Modified at request of Scheduler@tyrone-cluster
06/03/2014 15:57:53;0008;PBS_Server;Job;39364.tyrone-cluster;Job Run at request of Scheduler@tyrone-cluster
06/03/2014 15:57:54;0040;PBS_Server;Svr;tyrone-cluster;Scheduler was sent the command recyc
06/03/2014 15:57:54;000d;PBS_Server;Job;39364.tyrone-cluster;Not sending email: User does not want mail of this type.
06/03/2014 15:58:06;0040;PBS_Server;Svr;tyrone-cluster;Scheduler was sent the command new
06/03/2014 15:58:06;000d;PBS_Server;Job;39364.tyrone-cluster;Not sending email: User does not want mail of this type.
06/03/2014 15:58:06;0010;PBS_Server;Job;39364.tyrone-cluster;Exit_status=0 resources_used.cput=00:01:43 resources_used.mem=1532kb resources_used.vmem=118980kb resources_used.walltime=00:00:13
06/03/2014 15:58:06;0008;PBS_Server;Job;NULL;on_job_exit valid pjob: 0x17999c0 (substate=50)
06/03/2014 15:58:06;0008;PBS_Server;Job;NULL;on_job_exit valid pjob: 0x17999c0 (substate=51)
06/03/2014 15:58:06;0008;PBS_Server;Job;NULL;on_job_exit valid pjob: 0x17999c0 (substate=51)
06/03/2014 15:58:06;0008;PBS_Server;Job;NULL;on_job_exit valid pjob: 0x17999c0 (substate=53)
06/03/2014 15:58:06;0100;PBS_Server;Job;39364.tyrone-cluster;dequeuing from idqueue, state COMPLETE
06/03/2014 15:58:39;0040;PBS_Server;Svr;tyrone-cluster;Scheduler was sent the command new
06/03/2014 15:59:01;0100;PBS_Server;Job;39365.tyrone-cluster;enqueuing into batch, state 1 hop 1
06/03/2014 15:59:01;0100;PBS_Server;Job;39365.tyrone-cluster;dequeuing from batch, state QUEUED
06/03/2014 15:59:01;0100;PBS_Server;Job;39365.tyrone-cluster;enqueuing into idqueue, state 1 hop 1
06/03/2014 15:59:01;0008;PBS_Server;Job;39365.tyrone-cluster;Job Queued at request of secpka@tyrone-cluster, owner = secpka@tyrone-cluster, job name = jobname, queue = idqueue
06/03/2014 15:59:01;0040;PBS_Server;Svr;tyrone-cluster;Scheduler was sent the command new
06/03/2014 15:59:02;0008;PBS_Server;Job;39365.tyrone-cluster;Job Modified at request of Scheduler@tyrone-cluster
06/03/2014 15:59:02;0008;PBS_Server;Job;39365.tyrone-cluster;Job Run at request of Scheduler@tyrone-cluster
06/03/2014 15:59:02;0040;PBS_Server;Svr;tyrone-cluster;Scheduler was sent the command recyc
06/03/2014 15:59:02;000d;PBS_Server;Job;39365.tyrone-cluster;Not sending email: User does not want mail of this type.
06/03/2014 15:59:11;0040;PBS_Server;Svr;tyrone-cluster;Scheduler was sent the command new
06/03/2014 15:59:12;000d;PBS_Server;Job;39365.tyrone-cluster;Not sending email: User does not want mail of this type.
06/03/2014 15:59:12;0010;PBS_Server;Job;39365.tyrone-cluster;Exit_status=0 resources_used.cput=00:01:32 resources_used.mem=0kb resources_used.vmem=0kb resources_used.walltime=00:00:10
06/03/2014 15:59:12;0008;PBS_Server;Job;NULL;on_job_exit valid pjob: 0x17999c0 (substate=50)
06/03/2014 15:59:12;0008;PBS_Server;Job;NULL;on_job_exit valid pjob: 0x17999c0 (substate=51)
06/03/2014 15:59:12;0008;PBS_Server;Job;NULL;on_job_exit valid pjob: 0x17999c0 (substate=51)
06/03/2014 15:59:12;0008;PBS_Server;Job;NULL;on_job_exit valid pjob: 0x17999c0 (substate=53)
06/03/2014 15:59:12;0100;PBS_Server;Job;39365.tyrone-cluster;dequeuing from idqueue, state COMPLETE
06/03/2014 15:59:12;0040;PBS_Server;Svr;tyrone-cluster;Scheduler was sent the command term
06/03/2014 15:59:46;0040;PBS_Server;Svr;tyrone-cluster;Scheduler was sent the command new
06/03/2014 15:59:46;0008;PBS_Server;Job;39353.tyrone-cluster;Job deleted at request of secbadar@tyrone-cluster
06/03/2014 15:59:46;0008;PBS_Server;Job;39353.tyrone-cluster;Job sent signal SIGTERM on delete
06/03/2014 15:59:46;000d;PBS_Server;Job;39353.tyrone-cluster;Not sending email: User does not want mail of this type.
06/03/2014 15:59:46;0010;PBS_Server;Job;39353.tyrone-cluster;Exit_status=143 resources_used.cput=00:47:41 resources_used.mem=497736kb resources_used.vmem=1297944kb resources_used.walltime=00:23:16
06/03/2014 15:59:46;0008;PBS_Server;Job;NULL;on_job_exit valid pjob: 0x177bea0 (substate=50)
06/03/2014 15:59:46;0008;PBS_Server;Job;NULL;on_job_exit valid pjob: 0x177bea0 (substate=51)
06/03/2014 15:59:46;0008;PBS_Server;Job;NULL;on_job_exit valid pjob: 0x177bea0 (substate=51)
06/03/2014 15:59:46;0008;PBS_Server;Job;NULL;on_job_exit valid pjob: 0x177bea0 (substate=53)
06/03/2014 15:59:46;0100;PBS_Server;Job;39353.tyrone-cluster;dequeuing from qp256, state COMPLETE
06/03/2014 15:59:46;0040;PBS_Server;Svr;tyrone-cluster;Scheduler was sent the command term
06/03/2014 15:59:46;0008;PBS_Server;Job;39312.tyrone-cluster;Job Modified at request of Scheduler@tyrone-cluster
06/03/2014 15:59:46;0008;PBS_Server;Job;39358.tyrone-cluster;Job Modified at request of Scheduler@tyrone-cluster
06/03/2014 15:59:46;0008;PBS_Server;Job;39358.tyrone-cluster;Job Run at request of Scheduler@tyrone-cluster
06/03/2014 15:59:46;0040;PBS_Server;Svr;tyrone-cluster;Scheduler was sent the command recyc
06/03/2014 15:59:58;000d;PBS_Server;Job;39358.tyrone-cluster;Not sending email: User does not want mail of this type.
06/03/2014 16:00:09;0100;PBS_Server;Job;39366.tyrone-cluster;enqueuing into batch, state 1 hop 1
06/03/2014 16:00:09;0100;PBS_Server;Job;39366.tyrone-cluster;dequeuing from batch, state QUEUED
06/03/2014 16:00:09;0100;PBS_Server;Job;39366.tyrone-cluster;enqueuing into idqueue, state 1 hop 1
06/03/2014 16:00:09;0008;PBS_Server;Job;39366.tyrone-cluster;Job Queued at request of secpka@tyrone-cluster, owner = secpka@tyrone-cluster, job name = jobname, queue = idqueue
06/03/2014 16:00:09;0040;PBS_Server;Svr;tyrone-cluster;Scheduler was sent the command new
06/03/2014 16:00:09;0008;PBS_Server;Job;39366.tyrone-cluster;Job Modified at request of Scheduler@tyrone-cluster
06/03/2014 16:00:09;0008;PBS_Server;Job;39366.tyrone-cluster;Job Run at request of Scheduler@tyrone-cluster
06/03/2014 16:00:09;0008;PBS_Server;Job;39312.tyrone-cluster;Job Modified at request of Scheduler@tyrone-cluster
06/03/2014 16:00:09;0040;PBS_Server;Svr;tyrone-cluster;Scheduler was sent the command recyc
06/03/2014 16:00:09;000d;PBS_Server;Job;39366.tyrone-cluster;Not sending email: User does not want mail of this type.
06/03/2014 16:00:19;0040;PBS_Server;Svr;tyrone-cluster;Scheduler was sent the command new
06/03/2014 16:00:19;000d;PBS_Server;Job;39366.tyrone-cluster;Not sending email: User does not want mail of this type.
06/03/2014 16:00:19;0010;PBS_Server;Job;39366.tyrone-cluster;Exit_status=0 resources_used.cput=00:01:20 resources_used.mem=0kb resources_used.vmem=0kb resources_used.walltime=00:00:10
06/03/2014 16:00:19;0008;PBS_Server;Job;NULL;on_job_exit valid pjob: 0x177bea0 (substate=50)
06/03/2014 16:00:19;0008;PBS_Server;Job;NULL;on_job_exit valid pjob: 0x177bea0 (substate=51)
06/03/2014 16:00:19;0008;PBS_Server;Job;NULL;on_job_exit valid pjob: 0x177bea0 (substate=51)
06/03/2014 16:00:19;0008;PBS_Server;Job;NULL;on_job_exit valid pjob: 0x177bea0 (substate=53)
06/03/2014 16:00:19;0100;PBS_Server;Job;39366.tyrone-cluster;dequeuing from idqueue, state COMPLETE
06/03/2014 16:00:19;0040;PBS_Server;Svr;tyrone-cluster;Scheduler was sent the command term
06/03/2014 16:00:54;0040;PBS_Server;Svr;tyrone-cluster;Scheduler was sent the command new
06/03/2014 16:00:57;0002;PBS_Server;Svr;PBS_Server;Torque Server Version = 3.0.5, loglevel = 0
06/03/2014 16:01:21;0040;PBS_Server;Svr;tyrone-cluster;Scheduler was sent the command new
06/03/2014 16:01:51;0040;PBS_Server;Svr;tyrone-cluster;Scheduler was sent the command new
06/03/2014 16:02:24;0040;PBS_Server;Svr;tyrone-cluster;Scheduler was sent the command new
06/03/2014 16:02:55;0040;PBS_Server;Svr;tyrone-cluster;Scheduler was sent the command new
06/03/2014 16:03:28;0040;PBS_Server;Svr;tyrone-cluster;Scheduler was sent the command new
06/03/2014 16:04:06;0040;PBS_Server;Svr;tyrone-cluster;Scheduler was sent the command new
06/03/2014 16:04:39;0040;PBS_Server;Svr;tyrone-cluster;Scheduler was sent the command new
06/03/2014 16:05:11;0040;PBS_Server;Svr;tyrone-cluster;Scheduler was sent the command new
06/03/2014 16:05:47;0040;PBS_Server;Svr;tyrone-cluster;Scheduler was sent the command new
06/03/2014 16:05:57;0002;PBS_Server;Svr;PBS_Server;Torque Server Version = 3.0.5, loglevel = 0
06/03/2014 16:06:21;0040;PBS_Server;Svr;tyrone-cluster;Scheduler was sent the command new
06/03/2014 16:06:54;0040;PBS_Server;Svr;tyrone-cluster;Scheduler was sent the command new
06/03/2014 16:07:23;000d;PBS_Server;Job;39358.tyrone-cluster;Not sending email: User does not want mail of this type.
06/03/2014 16:07:23;0010;PBS_Server;Job;39358.tyrone-cluster;Exit_status=127 resources_used.cput=00:09:04 resources_used.mem=2570460kb resources_used.vmem=4499484kb resources_used.walltime=00:07:37
06/03/2014 16:07:23;0008;PBS_Server;Job;NULL;on_job_exit valid pjob: 0x1791590 (substate=50)
06/03/2014 16:07:23;0008;PBS_Server;Job;NULL;on_job_exit valid pjob: 0x1791590 (substate=51)
06/03/2014 16:07:23;0008;PBS_Server;Job;NULL;on_job_exit valid pjob: 0x1791590 (substate=51)
06/03/2014 16:07:23;0008;PBS_Server;Job;NULL;on_job_exit valid pjob: 0x1791590 (substate=53)
06/03/2014 16:07:23;0100;PBS_Server;Job;39358.tyrone-cluster;dequeuing from qp256, state COMPLETE
06/03/2014 16:07:23;0040;PBS_Server;Svr;tyrone-cluster;Scheduler was sent the command term
06/03/2014 16:07:23;0008;PBS_Server;Job;39312.tyrone-cluster;Job Modified at request of Scheduler@tyrone-cluster
06/03/2014 16:07:25;0040;PBS_Server;Svr;tyrone-cluster;Scheduler was sent the command new
06/03/2014 16:08:02;0040;PBS_Server;Svr;tyrone-cluster;Scheduler was sent the command new
06/03/2014 16:08:36;0040;PBS_Server;Svr;tyrone-cluster;Scheduler was sent the command new
06/03/2014 16:09:09;0040;PBS_Server;Svr;tyrone-cluster;Scheduler was sent the command new
06/03/2014 16:09:41;0040;PBS_Server;Svr;tyrone-cluster;Scheduler was sent the command new
06/03/2014 16:10:17;0040;PBS_Server;Svr;tyrone-cluster;Scheduler was sent the command new
06/03/2014 16:10:51;0040;PBS_Server;Svr;tyrone-cluster;Scheduler was sent the command new
06/03/2014 16:10:57;0002;PBS_Server;Svr;PBS_Server;Torque Server Version = 3.0.5, loglevel = 0
06/03/2014 16:11:14;0100;PBS_Server;Job;39367.tyrone-cluster;enqueuing into batch, state 1 hop 1
06/03/2014 16:11:14;0100;PBS_Server;Job;39367.tyrone-cluster;dequeuing from batch, state QUEUED
06/03/2014 16:11:14;0100;PBS_Server;Job;39367.tyrone-cluster;enqueuing into idqueue, state 1 hop 1
06/03/2014 16:11:14;0008;PBS_Server;Job;39367.tyrone-cluster;Job Queued at request of secpka@tyrone-cluster, owner = secpka@tyrone-cluster, job name = jobname, queue = idqueue
06/03/2014 16:11:14;0040;PBS_Server;Svr;tyrone-cluster;Scheduler was sent the command new
06/03/2014 16:11:14;0008;PBS_Server;Job;39367.tyrone-cluster;Job Modified at request of Scheduler@tyrone-cluster
06/03/2014 16:11:14;0008;PBS_Server;Job;39367.tyrone-cluster;Job Run at request of Scheduler@tyrone-cluster
06/03/2014 16:11:14;0040;PBS_Server;Svr;tyrone-cluster;Scheduler was sent the command recyc
06/03/2014 16:11:14;000d;PBS_Server;Job;39367.tyrone-cluster;Not sending email: User does not want mail of this type.
06/03/2014 16:11:23;0040;PBS_Server;Svr;tyrone-cluster;Scheduler was sent the command new
06/03/2014 16:11:23;000d;PBS_Server;Job;39367.tyrone-cluster;Not sending email: User does not want mail of this type.
06/03/2014 16:11:23;0010;PBS_Server;Job;39367.tyrone-cluster;Exit_status=0 resources_used.cput=00:01:17 resources_used.mem=0kb resources_used.vmem=0kb resources_used.walltime=00:00:09
06/03/2014 16:11:23;0008;PBS_Server;Job;NULL;on_job_exit valid pjob: 0x177bea0 (substate=50)
06/03/2014 16:11:23;0008;PBS_Server;Job;NULL;on_job_exit valid pjob: 0x177bea0 (substate=51)
06/03/2014 16:11:24;0008;PBS_Server;Job;NULL;on_job_exit valid pjob: 0x177bea0 (substate=51)
06/03/2014 16:11:24;0008;PBS_Server;Job;NULL;on_job_exit valid pjob: 0x177bea0 (substate=53)
06/03/2014 16:11:24;0100;PBS_Server;Job;39367.tyrone-cluster;dequeuing from idqueue, state COMPLETE
06/03/2014 16:11:35;0100;PBS_Server;Job;39368.tyrone-cluster;enqueuing into batch, state 1 hop 1
06/03/2014 16:11:35;0100;PBS_Server;Job;39368.tyrone-cluster;dequeuing from batch, state QUEUED
06/03/2014 16:11:35;0100;PBS_Server;Job;39368.tyrone-cluster;enqueuing into idqueue, state 1 hop 1
06/03/2014 16:11:35;0008;PBS_Server;Job;39368.tyrone-cluster;Job Queued at request of secpka@tyrone-cluster, owner = secpka@tyrone-cluster, job name = jobname, queue = idqueue
06/03/2014 16:11:35;0040;PBS_Server;Svr;tyrone-cluster;Scheduler was sent the command new
06/03/2014 16:11:35;0008;PBS_Server;Job;39368.tyrone-cluster;Job Modified at request of Scheduler@tyrone-cluster
06/03/2014 16:11:35;0008;PBS_Server;Job;39368.tyrone-cluster;Job Run at request of Scheduler@tyrone-cluster
06/03/2014 16:11:35;0040;PBS_Server;Svr;tyrone-cluster;Scheduler was sent the command recyc
06/03/2014 16:11:35;000d;PBS_Server;Job;39368.tyrone-cluster;Not sending email: User does not want mail of this type.
06/03/2014 16:11:43;000d;PBS_Server;Job;39368.tyrone-cluster;Not sending email: User does not want mail of this type.
06/03/2014 16:11:43;0010;PBS_Server;Job;39368.tyrone-cluster;Exit_status=0 resources_used.cput=00:01:09 resources_used.mem=0kb resources_used.vmem=0kb resources_used.walltime=00:00:08
06/03/2014 16:11:43;0008;PBS_Server;Job;NULL;on_job_exit valid pjob: 0x177bea0 (substate=50)
06/03/2014 16:11:43;0008;PBS_Server;Job;NULL;on_job_exit valid pjob: 0x177bea0 (substate=51)
06/03/2014 16:11:43;0008;PBS_Server;Job;NULL;on_job_exit valid pjob: 0x177bea0 (substate=51)
06/03/2014 16:11:43;0008;PBS_Server;Job;NULL;on_job_exit valid pjob: 0x177bea0 (substate=53)
06/03/2014 16:11:43;0100;PBS_Server;Job;39368.tyrone-cluster;dequeuing from idqueue, state COMPLETE
06/03/2014 16:11:43;0040;PBS_Server;Svr;tyrone-cluster;Scheduler was sent the command term
06/03/2014 16:11:55;0040;PBS_Server;Svr;tyrone-cluster;Scheduler was sent the command new
06/03/2014 16:12:24;0040;PBS_Server;Svr;tyrone-cluster;Scheduler was sent the command new
06/03/2014 16:12:54;0040;PBS_Server;Svr;tyrone-cluster;Scheduler was sent the command new
06/03/2014 16:13:25;0040;PBS_Server;Svr;tyrone-cluster;Scheduler was sent the command new
06/03/2014 16:13:27;0100;PBS_Server;Job;39369.tyrone-cluster;enqueuing into batch, state 1 hop 1
06/03/2014 16:13:27;0100;PBS_Server;Job;39369.tyrone-cluster;dequeuing from batch, state QUEUED
06/03/2014 16:13:27;0100;PBS_Server;Job;39369.tyrone-cluster;enqueuing into idqueue, state 1 hop 1
06/03/2014 16:13:27;0008;PBS_Server;Job;39369.tyrone-cluster;Job Queued at request of secpka@tyrone-cluster, owner = secpka@tyrone-cluster, job name = jobname, queue = idqueue
06/03/2014 16:13:27;0040;PBS_Server;Svr;tyrone-cluster;Scheduler was sent the command new
06/03/2014 16:13:27;0008;PBS_Server;Job;39369.tyrone-cluster;Job Modified at request of Scheduler@tyrone-cluster
06/03/2014 16:13:27;0008;PBS_Server;Job;39369.tyrone-cluster;Job Run at request of Scheduler@tyrone-cluster
06/03/2014 16:13:27;0040;PBS_Server;Svr;tyrone-cluster;Scheduler was sent the command recyc
06/03/2014 16:13:27;000d;PBS_Server;Job;39369.tyrone-cluster;Not sending email: User does not want mail of this type.
06/03/2014 16:13:34;000d;PBS_Server;Job;39369.tyrone-cluster;Not sending email: User does not want mail of this type.
06/03/2014 16:13:34;0010;PBS_Server;Job;39369.tyrone-cluster;Exit_status=0 resources_used.cput=00:01:00 resources_used.mem=0kb resources_used.vmem=0kb resources_used.walltime=00:00:07
06/03/2014 16:13:34;0008;PBS_Server;Job;NULL;on_job_exit valid pjob: 0x177bea0 (substate=50)
06/03/2014 16:13:34;0008;PBS_Server;Job;NULL;on_job_exit valid pjob: 0x177bea0 (substate=51)
06/03/2014 16:13:34;0008;PBS_Server;Job;NULL;on_job_exit valid pjob: 0x177bea0 (substate=51)
06/03/2014 16:13:34;0008;PBS_Server;Job;NULL;on_job_exit valid pjob: 0x177bea0 (substate=53)
06/03/2014 16:13:34;0100;PBS_Server;Job;39369.tyrone-cluster;dequeuing from idqueue, state COMPLETE
06/03/2014 16:13:34;0040;PBS_Server;Svr;tyrone-cluster;Scheduler was sent the command term
06/03/2014 16:14:02;0040;PBS_Server;Svr;tyrone-cluster;Scheduler was sent the command new
06/03/2014 16:14:36;0040;PBS_Server;Svr;tyrone-cluster;Scheduler was sent the command new
06/03/2014 16:14:37;0100;PBS_Server;Job;39370.tyrone-cluster;enqueuing into batch, state 1 hop 1
06/03/2014 16:14:37;0100;PBS_Server;Job;39370.tyrone-cluster;dequeuing from batch, state QUEUED
06/03/2014 16:14:37;0100;PBS_Server;Job;39370.tyrone-cluster;enqueuing into idqueue, state 1 hop 1
06/03/2014 16:14:37;0008;PBS_Server;Job;39370.tyrone-cluster;Job Queued at request of secpka@tyrone-cluster, owner = secpka@tyrone-cluster, job name = jobname, queue = idqueue
06/03/2014 16:14:37;0040;PBS_Server;Svr;tyrone-cluster;Scheduler was sent the command new
06/03/2014 16:14:37;0008;PBS_Server;Job;39370.tyrone-cluster;Job Modified at request of Scheduler@tyrone-cluster
06/03/2014 16:14:37;0008;PBS_Server;Job;39370.tyrone-cluster;Job Run at request of Scheduler@tyrone-cluster
06/03/2014 16:14:37;0040;PBS_Server;Svr;tyrone-cluster;Scheduler was sent the command recyc
06/03/2014 16:14:37;000d;PBS_Server;Job;39370.tyrone-cluster;Not sending email: User does not want mail of this type.
06/03/2014 16:14:44;000d;PBS_Server;Job;39370.tyrone-cluster;Not sending email: User does not want mail of this type.
06/03/2014 16:14:44;0010;PBS_Server;Job;39370.tyrone-cluster;Exit_status=0 resources_used.cput=00:00:52 resources_used.mem=0kb resources_used.vmem=0kb resources_used.walltime=00:00:07
06/03/2014 16:14:44;0008;PBS_Server;Job;NULL;on_job_exit valid pjob: 0x177bea0 (substate=50)
06/03/2014 16:14:44;0008;PBS_Server;Job;NULL;on_job_exit valid pjob: 0x177bea0 (substate=51)
06/03/2014 16:14:44;0008;PBS_Server;Job;NULL;on_job_exit valid pjob: 0x177bea0 (substate=51)
06/03/2014 16:14:44;0008;PBS_Server;Job;NULL;on_job_exit valid pjob: 0x177bea0 (substate=53)
06/03/2014 16:14:44;0100;PBS_Server;Job;39370.tyrone-cluster;dequeuing from idqueue, state COMPLETE
06/03/2014 16:14:44;0040;PBS_Server;Svr;tyrone-cluster;Scheduler was sent the command term
06/03/2014 16:15:09;0040;PBS_Server;Svr;tyrone-cluster;Scheduler was sent the command new
06/03/2014 16:15:41;0040;PBS_Server;Svr;tyrone-cluster;Scheduler was sent the command new
06/03/2014 16:15:57;0002;PBS_Server;Svr;PBS_Server;Torque Server Version = 3.0.5, loglevel = 0
06/03/2014 16:16:17;0040;PBS_Server;Svr;tyrone-cluster;Scheduler was sent the command new
06/03/2014 16:16:51;0040;PBS_Server;Svr;tyrone-cluster;Scheduler was sent the command new
06/03/2014 16:17:24;0040;PBS_Server;Svr;tyrone-cluster;Scheduler was sent the command new
06/03/2014 16:17:55;0040;PBS_Server;Svr;tyrone-cluster;Scheduler was sent the command new
06/03/2014 16:18:06;0100;PBS_Server;Job;39371.tyrone-cluster;enqueuing into batch, state 1 hop 1
06/03/2014 16:18:06;0100;PBS_Server;Job;39371.tyrone-cluster;dequeuing from batch, state QUEUED
06/03/2014 16:18:06;0100;PBS_Server;Job;39371.tyrone-cluster;enqueuing into idqueue, state 1 hop 1
06/03/2014 16:18:06;0008;PBS_Server;Job;39371.tyrone-cluster;Job Queued at request of secpka@tyrone-cluster, owner = secpka@tyrone-cluster, job name = jobname, queue = idqueue
06/03/2014 16:18:06;0040;PBS_Server;Svr;tyrone-cluster;Scheduler was sent the command new
06/03/2014 16:18:06;0008;PBS_Server;Job;39371.tyrone-cluster;Job Modified at request of Scheduler@tyrone-cluster
06/03/2014 16:18:06;0008;PBS_Server;Job;39371.tyrone-cluster;Job Run at request of Scheduler@tyrone-cluster
06/03/2014 16:18:06;0040;PBS_Server;Svr;tyrone-cluster;Scheduler was sent the command recyc
06/03/2014 16:18:06;000d;PBS_Server;Job;39371.tyrone-cluster;Not sending email: User does not want mail of this type.
06/03/2014 16:18:11;000d;PBS_Server;Job;39371.tyrone-cluster;Not sending email: User does not want mail of this type.
06/03/2014 16:18:11;0010;PBS_Server;Job;39371.tyrone-cluster;Exit_status=0 resources_used.cput=00:00:43 resources_used.mem=124956kb resources_used.vmem=970588kb resources_used.walltime=00:00:05
06/03/2014 16:18:11;0008;PBS_Server;Job;NULL;on_job_exit valid pjob: 0x177bea0 (substate=50)
06/03/2014 16:18:11;0008;PBS_Server;Job;NULL;on_job_exit valid pjob: 0x177bea0 (substate=51)
06/03/2014 16:18:11;0008;PBS_Server;Job;NULL;on_job_exit valid pjob: 0x177bea0 (substate=51)
06/03/2014 16:18:11;0008;PBS_Server;Job;NULL;on_job_exit valid pjob: 0x177bea0 (substate=53)
06/03/2014 16:18:11;0100;PBS_Server;Job;39371.tyrone-cluster;dequeuing from idqueue, state COMPLETE
06/03/2014 16:18:11;0040;PBS_Server;Svr;tyrone-cluster;Scheduler was sent the command term
06/03/2014 16:18:28;0040;PBS_Server;Svr;tyrone-cluster;Scheduler was sent the command new
06/03/2014 16:19:06;0040;PBS_Server;Svr;tyrone-cluster;Scheduler was sent the command new
06/03/2014 16:19:17;0100;PBS_Server;Job;39372.tyrone-cluster;enqueuing into batch, state 1 hop 1
06/03/2014 16:19:17;0100;PBS_Server;Job;39372.tyrone-cluster;dequeuing from batch, state QUEUED
06/03/2014 16:19:17;0100;PBS_Server;Job;39372.tyrone-cluster;enqueuing into idqueue, state 1 hop 1
06/03/2014 16:19:17;0008;PBS_Server;Job;39372.tyrone-cluster;Job Queued at request of secpka@tyrone-cluster, owner = secpka@tyrone-cluster, job name = jobname, queue = idqueue
06/03/2014 16:19:17;0040;PBS_Server;Svr;tyrone-cluster;Scheduler was sent the command new
06/03/2014 16:19:17;0008;PBS_Server;Job;39372.tyrone-cluster;Job Modified at request of Scheduler@tyrone-cluster
06/03/2014 16:19:17;0008;PBS_Server;Job;39372.tyrone-cluster;Job Run at request of Scheduler@tyrone-cluster
06/03/2014 16:19:17;0040;PBS_Server;Svr;tyrone-cluster;Scheduler was sent the command recyc
06/03/2014 16:19:17;000d;PBS_Server;Job;39372.tyrone-cluster;Not sending email: User does not want mail of this type.
06/03/2014 16:19:21;000d;PBS_Server;Job;39372.tyrone-cluster;Not sending email: User does not want mail of this type.
06/03/2014 16:19:21;0010;PBS_Server;Job;39372.tyrone-cluster;Exit_status=0 resources_used.cput=00:00:34 resources_used.mem=0kb resources_used.vmem=0kb resources_used.walltime=00:00:04
06/03/2014 16:19:21;0008;PBS_Server;Job;NULL;on_job_exit valid pjob: 0x177bea0 (substate=50)
06/03/2014 16:19:21;0008;PBS_Server;Job;NULL;on_job_exit valid pjob: 0x177bea0 (substate=51)
06/03/2014 16:19:21;0008;PBS_Server;Job;NULL;on_job_exit valid pjob: 0x177bea0 (substate=51)
06/03/2014 16:19:21;0008;PBS_Server;Job;NULL;on_job_exit valid pjob: 0x177bea0 (substate=53)
06/03/2014 16:19:21;0100;PBS_Server;Job;39372.tyrone-cluster;dequeuing from idqueue, state COMPLETE
06/03/2014 16:19:21;0040;PBS_Server;Svr;tyrone-cluster;Scheduler was sent the command term
06/03/2014 16:19:33;0100;PBS_Server;Job;39373.tyrone-cluster;enqueuing into batch, state 1 hop 1
06/03/2014 16:19:33;0100;PBS_Server;Job;39373.tyrone-cluster;dequeuing from batch, state QUEUED
06/03/2014 16:19:33;0100;PBS_Server;Job;39373.tyrone-cluster;enqueuing into idqueue, state 1 hop 1
06/03/2014 16:19:33;0008;PBS_Server;Job;39373.tyrone-cluster;Job Queued at request of secpka@tyrone-cluster, owner = secpka@tyrone-cluster, job name = jobname, queue = idqueue
06/03/2014 16:19:33;0040;PBS_Server;Svr;tyrone-cluster;Scheduler was sent the command new
06/03/2014 16:19:34;0008;PBS_Server;Job;39373.tyrone-cluster;Job Modified at request of Scheduler@tyrone-cluster
06/03/2014 16:19:34;0008;PBS_Server;Job;39373.tyrone-cluster;Job Run at request of Scheduler@tyrone-cluster
06/03/2014 16:19:34;0040;PBS_Server;Svr;tyrone-cluster;Scheduler was sent the command recyc
06/03/2014 16:19:34;000d;PBS_Server;Job;39373.tyrone-cluster;Not sending email: User does not want mail of this type.
06/03/2014 16:19:37;0040;PBS_Server;Svr;tyrone-cluster;Scheduler was sent the command new
06/03/2014 16:19:37;000d;PBS_Server;Job;39373.tyrone-cluster;Not sending email: User does not want mail of this type.
06/03/2014 16:19:37;0010;PBS_Server;Job;39373.tyrone-cluster;Exit_status=0 resources_used.cput=00:00:26 resources_used.mem=0kb resources_used.vmem=0kb resources_used.walltime=00:00:03
06/03/2014 16:19:37;0008;PBS_Server;Job;NULL;on_job_exit valid pjob: 0x177bea0 (substate=50)
06/03/2014 16:19:37;0008;PBS_Server;Job;NULL;on_job_exit valid pjob: 0x177bea0 (substate=51)
06/03/2014 16:19:37;0008;PBS_Server;Job;NULL;on_job_exit valid pjob: 0x177bea0 (substate=51)
06/03/2014 16:19:37;0008;PBS_Server;Job;NULL;on_job_exit valid pjob: 0x177bea0 (substate=53)
06/03/2014 16:19:37;0100;PBS_Server;Job;39373.tyrone-cluster;dequeuing from idqueue, state COMPLETE
06/03/2014 16:19:37;0040;PBS_Server;Svr;tyrone-cluster;Scheduler was sent the command term
06/03/2014 16:19:39;0100;PBS_Server;Job;39374.tyrone-cluster;enqueuing into batch, state 1 hop 1
06/03/2014 16:19:39;0100;PBS_Server;Job;39374.tyrone-cluster;dequeuing from batch, state QUEUED
06/03/2014 16:19:39;0100;PBS_Server;Job;39374.tyrone-cluster;enqueuing into qp256, state 1 hop 1
06/03/2014 16:19:39;0008;PBS_Server;Job;39374.tyrone-cluster;Job Queued at request of secbadar@tyrone-cluster, owner = secbadar@tyrone-cluster, job name = job128Uns, queue = qp256
06/03/2014 16:19:39;0040;PBS_Server;Svr;tyrone-cluster;Scheduler was sent the command new
06/03/2014 16:19:39;0008;PBS_Server;Job;39374.tyrone-cluster;Job Modified at request of Scheduler@tyrone-cluster
06/03/2014 16:19:39;0008;PBS_Server;Job;39374.tyrone-cluster;Job Run at request of Scheduler@tyrone-cluster
06/03/2014 16:19:39;0040;PBS_Server;Svr;tyrone-cluster;Scheduler was sent the command recyc
06/03/2014 16:19:47;000d;PBS_Server;Job;39374.tyrone-cluster;Not sending email: User does not want mail of this type.
06/03/2014 16:19:47;0010;PBS_Server;Job;39374.tyrone-cluster;Exit_status=255 resources_used.cput=00:00:41 resources_used.mem=800kb resources_used.vmem=13624kb resources_used.walltime=00:00:08
06/03/2014 16:19:47;0008;PBS_Server;Job;NULL;on_job_exit valid pjob: 0x177bea0 (substate=50)
06/03/2014 16:19:47;0008;PBS_Server;Job;NULL;on_job_exit valid pjob: 0x177bea0 (substate=51)
06/03/2014 16:19:47;0008;PBS_Server;Job;NULL;on_job_exit valid pjob: 0x177bea0 (substate=51)
06/03/2014 16:19:47;0008;PBS_Server;Job;NULL;on_job_exit valid pjob: 0x177bea0 (substate=53)
06/03/2014 16:19:47;0100;PBS_Server;Job;39374.tyrone-cluster;dequeuing from qp256, state COMPLETE
06/03/2014 16:19:47;0040;PBS_Server;Svr;tyrone-cluster;Scheduler was sent the command term
06/03/2014 16:19:59;0100;PBS_Server;Job;39375.tyrone-cluster;enqueuing into batch, state 1 hop 1
06/03/2014 16:19:59;0100;PBS_Server;Job;39375.tyrone-cluster;dequeuing from batch, state QUEUED
06/03/2014 16:19:59;0100;PBS_Server;Job;39375.tyrone-cluster;enqueuing into idqueue, state 1 hop 1
06/03/2014 16:19:59;0008;PBS_Server;Job;39375.tyrone-cluster;Job Queued at request of secpka@tyrone-cluster, owner = secpka@tyrone-cluster, job name = jobname, queue = idqueue
06/03/2014 16:19:59;0040;PBS_Server;Svr;tyrone-cluster;Scheduler was sent the command new
06/03/2014 16:19:59;0008;PBS_Server;Job;39375.tyrone-cluster;Job Modified at request of Scheduler@tyrone-cluster
06/03/2014 16:19:59;0008;PBS_Server;Job;39375.tyrone-cluster;Job Run at request of Scheduler@tyrone-cluster
06/03/2014 16:19:59;0040;PBS_Server;Svr;tyrone-cluster;Scheduler was sent the command recyc
06/03/2014 16:19:59;000d;PBS_Server;Job;39375.tyrone-cluster;Not sending email: User does not want mail of this type.
06/03/2014 16:20:01;0100;PBS_Server;Job;39376.tyrone-cluster;enqueuing into batch, state 1 hop 1
06/03/2014 16:20:01;0100;PBS_Server;Job;39376.tyrone-cluster;dequeuing from batch, state QUEUED
06/03/2014 16:20:01;0100;PBS_Server;Job;39376.tyrone-cluster;enqueuing into qp256, state 1 hop 1
06/03/2014 16:20:01;0008;PBS_Server;Job;39376.tyrone-cluster;Job Queued at request of secbadar@tyrone-cluster, owner = secbadar@tyrone-cluster, job name = jobpMpiUns, queue = qp256
06/03/2014 16:20:01;0040;PBS_Server;Svr;tyrone-cluster;Scheduler was sent the command new
06/03/2014 16:20:01;0008;PBS_Server;Job;39376.tyrone-cluster;Job Modified at request of Scheduler@tyrone-cluster
06/03/2014 16:20:01;0008;PBS_Server;Job;39376.tyrone-cluster;Job Run at request of Scheduler@tyrone-cluster
06/03/2014 16:20:01;0040;PBS_Server;Svr;tyrone-cluster;Scheduler was sent the command recyc
06/03/2014 16:20:02;000d;PBS_Server;Job;39375.tyrone-cluster;Not sending email: User does not want mail of this type.
06/03/2014 16:20:02;0010;PBS_Server;Job;39375.tyrone-cluster;Exit_status=0 resources_used.cput=00:00:18 resources_used.mem=0kb resources_used.vmem=0kb resources_used.walltime=00:00:03
06/03/2014 16:20:02;0008;PBS_Server;Job;NULL;on_job_exit valid pjob: 0x177bea0 (substate=50)
06/03/2014 16:20:02;0008;PBS_Server;Job;NULL;on_job_exit valid pjob: 0x177bea0 (substate=51)
06/03/2014 16:20:02;0008;PBS_Server;Job;NULL;on_job_exit valid pjob: 0x177bea0 (substate=51)
06/03/2014 16:20:02;0008;PBS_Server;Job;NULL;on_job_exit valid pjob: 0x177bea0 (substate=53)
06/03/2014 16:20:02;0100;PBS_Server;Job;39375.tyrone-cluster;dequeuing from idqueue, state COMPLETE
06/03/2014 16:20:02;0040;PBS_Server;Svr;tyrone-cluster;Scheduler was sent the command term
06/03/2014 16:20:02;0008;PBS_Server;Job;39312.tyrone-cluster;Job Modified at request of Scheduler@tyrone-cluster
06/03/2014 16:20:04;000d;PBS_Server;Job;39376.tyrone-cluster;Not sending email: User does not want mail of this type.
06/03/2014 16:20:07;0040;PBS_Server;Svr;tyrone-cluster;Scheduler was sent the command new
06/03/2014 16:20:15;0100;PBS_Server;Job;39377.tyrone-cluster;enqueuing into batch, state 1 hop 1
06/03/2014 16:20:15;0100;PBS_Server;Job;39377.tyrone-cluster;dequeuing from batch, state QUEUED
06/03/2014 16:20:15;0100;PBS_Server;Job;39377.tyrone-cluster;enqueuing into idqueue, state 1 hop 1
06/03/2014 16:20:15;0008;PBS_Server;Job;39377.tyrone-cluster;Job Queued at request of secpka@tyrone-cluster, owner = secpka@tyrone-cluster, job name = jobname, queue = idqueue
06/03/2014 16:20:15;0040;PBS_Server;Svr;tyrone-cluster;Scheduler was sent the command new
06/03/2014 16:20:15;0008;PBS_Server;Job;39377.tyrone-cluster;Job Modified at request of Scheduler@tyrone-cluster
06/03/2014 16:20:15;0008;PBS_Server;Job;39377.tyrone-cluster;Job Run at request of Scheduler@tyrone-cluster
06/03/2014 16:20:15;0040;PBS_Server;Svr;tyrone-cluster;Scheduler was sent the command recyc
06/03/2014 16:20:15;000d;PBS_Server;Job;39377.tyrone-cluster;Not sending email: User does not want mail of this type.
06/03/2014 16:20:16;000d;PBS_Server;Job;39377.tyrone-cluster;Not sending email: User does not want mail of this type.
06/03/2014 16:20:16;0010;PBS_Server;Job;39377.tyrone-cluster;Exit_status=0 resources_used.cput=00:00:09 resources_used.mem=0kb resources_used.vmem=0kb resources_used.walltime=00:00:01
06/03/2014 16:20:16;0008;PBS_Server;Job;NULL;on_job_exit valid pjob: 0x177bea0 (substate=50)
06/03/2014 16:20:16;0008;PBS_Server;Job;NULL;on_job_exit valid pjob: 0x177bea0 (substate=51)
06/03/2014 16:20:16;0008;PBS_Server;Job;NULL;on_job_exit valid pjob: 0x177bea0 (substate=51)
06/03/2014 16:20:16;0008;PBS_Server;Job;NULL;on_job_exit valid pjob: 0x177bea0 (substate=53)
06/03/2014 16:20:16;0100;PBS_Server;Job;39377.tyrone-cluster;dequeuing from idqueue, state COMPLETE
06/03/2014 16:20:16;0040;PBS_Server;Svr;tyrone-cluster;Scheduler was sent the command term
06/03/2014 16:20:38;0040;PBS_Server;Svr;tyrone-cluster;Scheduler was sent the command new
06/03/2014 16:20:57;0002;PBS_Server;Svr;PBS_Server;Torque Server Version = 3.0.5, loglevel = 0
06/03/2014 16:21:09;0040;PBS_Server;Svr;tyrone-cluster;Scheduler was sent the command new
06/03/2014 16:21:35;0100;PBS_Server;Job;39378.tyrone-cluster;enqueuing into batch, state 1 hop 1
06/03/2014 16:21:35;0100;PBS_Server;Job;39378.tyrone-cluster;dequeuing from batch, state QUEUED
06/03/2014 16:21:35;0100;PBS_Server;Job;39378.tyrone-cluster;enqueuing into qp256, state 1 hop 1
06/03/2014 16:21:35;0008;PBS_Server;Job;39378.tyrone-cluster;Job Queued at request of secbadar@tyrone-cluster, owner = secbadar@tyrone-cluster, job name = job128Uns, queue = qp256
06/03/2014 16:21:35;0040;PBS_Server;Svr;tyrone-cluster;Scheduler was sent the command new
06/03/2014 16:21:35;0008;PBS_Server;Job;39378.tyrone-cluster;Job Modified at request of Scheduler@tyrone-cluster
06/03/2014 16:21:41;0040;PBS_Server;Svr;tyrone-cluster;Scheduler was sent the command new
06/03/2014 16:22:17;0040;PBS_Server;Svr;tyrone-cluster;Scheduler was sent the command new
06/03/2014 16:22:51;0040;PBS_Server;Svr;tyrone-cluster;Scheduler was sent the command new
06/03/2014 16:23:24;0040;PBS_Server;Svr;tyrone-cluster;Scheduler was sent the command new
06/03/2014 16:23:55;0040;PBS_Server;Svr;tyrone-cluster;Scheduler was sent the command new
06/03/2014 16:24:32;0040;PBS_Server;Svr;tyrone-cluster;Scheduler was sent the command new
06/03/2014 16:25:06;0040;PBS_Server;Svr;tyrone-cluster;Scheduler was sent the command new
06/03/2014 16:25:39;0040;PBS_Server;Svr;tyrone-cluster;Scheduler was sent the command new
06/03/2014 16:25:57;0002;PBS_Server;Svr;PBS_Server;Torque Server Version = 3.0.5, loglevel = 0
06/03/2014 16:26:11;0040;PBS_Server;Svr;tyrone-cluster;Scheduler was sent the command new
06/03/2014 16:26:47;0040;PBS_Server;Svr;tyrone-cluster;Scheduler was sent the command new
06/03/2014 16:27:21;0040;PBS_Server;Svr;tyrone-cluster;Scheduler was sent the command new
06/03/2014 16:27:26;000d;PBS_Server;Job;39376.tyrone-cluster;Not sending email: User does not want mail of this type.
06/03/2014 16:27:26;0010;PBS_Server;Job;39376.tyrone-cluster;Exit_status=127 resources_used.cput=00:09:08 resources_used.mem=2789264kb resources_used.vmem=4855076kb resources_used.walltime=00:07:25
06/03/2014 16:27:26;0008;PBS_Server;Job;NULL;on_job_exit valid pjob: 0x1791590 (substate=50)
06/03/2014 16:27:26;0008;PBS_Server;Job;NULL;on_job_exit valid pjob: 0x1791590 (substate=51)
06/03/2014 16:27:26;0008;PBS_Server;Job;NULL;on_job_exit valid pjob: 0x1791590 (substate=51)
06/03/2014 16:27:26;0008;PBS_Server;Job;NULL;on_job_exit valid pjob: 0x1791590 (substate=53)
06/03/2014 16:27:26;0100;PBS_Server;Job;39376.tyrone-cluster;dequeuing from qp256, state COMPLETE
06/03/2014 16:27:26;0040;PBS_Server;Svr;tyrone-cluster;Scheduler was sent the command term
06/03/2014 16:27:26;0008;PBS_Server;Job;39312.tyrone-cluster;Job Modified at request of Scheduler@tyrone-cluster
06/03/2014 16:27:26;0008;PBS_Server;Job;39378.tyrone-cluster;Job Modified at request of Scheduler@tyrone-cluster
06/03/2014 16:27:26;0008;PBS_Server;Job;39378.tyrone-cluster;Job Run at request of Scheduler@tyrone-cluster
06/03/2014 16:27:26;0040;PBS_Server;Svr;tyrone-cluster;Scheduler was sent the command recyc
06/03/2014 16:27:38;000d;PBS_Server;Job;39378.tyrone-cluster;Not sending email: User does not want mail of this type.
06/03/2014 16:27:54;0040;PBS_Server;Svr;tyrone-cluster;Scheduler was sent the command new
06/03/2014 16:27:54;0008;PBS_Server;Job;39312.tyrone-cluster;Job Modified at request of Scheduler@tyrone-cluster
06/03/2014 16:28:26;0040;PBS_Server;Svr;tyrone-cluster;Scheduler was sent the command new
06/03/2014 16:28:50;000d;PBS_Server;Job;39378.tyrone-cluster;Not sending email: User does not want mail of this type.
06/03/2014 16:28:50;0010;PBS_Server;Job;39378.tyrone-cluster;Exit_status=255 resources_used.cput=00:01:56 resources_used.mem=2791132kb resources_used.vmem=4855076kb resources_used.walltime=00:01:24
06/03/2014 16:28:50;0008;PBS_Server;Job;NULL;on_job_exit valid pjob: 0x177bea0 (substate=50)
06/03/2014 16:28:50;0008;PBS_Server;Job;NULL;on_job_exit valid pjob: 0x177bea0 (substate=51)
06/03/2014 16:28:50;0008;PBS_Server;Job;NULL;on_job_exit valid pjob: 0x177bea0 (substate=51)
06/03/2014 16:28:50;0008;PBS_Server;Job;NULL;on_job_exit valid pjob: 0x177bea0 (substate=53)
06/03/2014 16:28:50;0100;PBS_Server;Job;39378.tyrone-cluster;dequeuing from qp256, state COMPLETE
06/03/2014 16:28:50;0040;PBS_Server;Svr;tyrone-cluster;Scheduler was sent the command term
06/03/2014 16:28:50;0008;PBS_Server;Job;39312.tyrone-cluster;Job Modified at request of Scheduler@tyrone-cluster
06/03/2014 16:29:00;0040;PBS_Server;Svr;tyrone-cluster;Scheduler was sent the command new
06/03/2014 16:29:00;0100;PBS_Server;Job;39379.tyrone-cluster;enqueuing into batch, state 1 hop 1
06/03/2014 16:29:00;0100;PBS_Server;Job;39379.tyrone-cluster;dequeuing from batch, state QUEUED
06/03/2014 16:29:00;0100;PBS_Server;Job;39379.tyrone-cluster;enqueuing into idqueue, state 1 hop 1
06/03/2014 16:29:00;0008;PBS_Server;Job;39379.tyrone-cluster;Job Queued at request of secpka@tyrone-cluster, owner = secpka@tyrone-cluster, job name = jobname, queue = idqueue
06/03/2014 16:29:00;0008;PBS_Server;Job;39379.tyrone-cluster;Job Modified at request of Scheduler@tyrone-cluster
06/03/2014 16:29:00;0008;PBS_Server;Job;39379.tyrone-cluster;Job Run at request of Scheduler@tyrone-cluster
06/03/2014 16:29:00;0040;PBS_Server;Svr;tyrone-cluster;Scheduler was sent the command recyc
06/03/2014 16:29:00;000d;PBS_Server;Job;39379.tyrone-cluster;Not sending email: User does not want mail of this type.
06/03/2014 16:29:01;000d;PBS_Server;Job;39379.tyrone-cluster;Not sending email: User does not want mail of this type.
06/03/2014 16:29:01;0010;PBS_Server;Job;39379.tyrone-cluster;Exit_status=139 resources_used.cput=00:00:05 resources_used.mem=0kb resources_used.vmem=0kb resources_used.walltime=00:00:01
06/03/2014 16:29:01;0008;PBS_Server;Job;NULL;on_job_exit valid pjob: 0x177bea0 (substate=50)
06/03/2014 16:29:01;0008;PBS_Server;Job;NULL;on_job_exit valid pjob: 0x177bea0 (substate=51)
06/03/2014 16:29:01;0008;PBS_Server;Job;NULL;on_job_exit valid pjob: 0x177bea0 (substate=51)
06/03/2014 16:29:01;0008;PBS_Server;Job;NULL;on_job_exit valid pjob: 0x177bea0 (substate=53)
06/03/2014 16:29:01;0100;PBS_Server;Job;39379.tyrone-cluster;dequeuing from idqueue, state COMPLETE
06/03/2014 16:29:01;0040;PBS_Server;Svr;tyrone-cluster;Scheduler was sent the command term
06/03/2014 16:29:18;0100;PBS_Server;Job;39380.tyrone-cluster;enqueuing into batch, state 1 hop 1
06/03/2014 16:29:18;0100;PBS_Server;Job;39380.tyrone-cluster;dequeuing from batch, state QUEUED
06/03/2014 16:29:18;0100;PBS_Server;Job;39380.tyrone-cluster;enqueuing into idqueue, state 1 hop 1
06/03/2014 16:29:18;0008;PBS_Server;Job;39380.tyrone-cluster;Job Queued at request of secpka@tyrone-cluster, owner = secpka@tyrone-cluster, job name = jobname, queue = idqueue
06/03/2014 16:29:18;0040;PBS_Server;Svr;tyrone-cluster;Scheduler was sent the command new
06/03/2014 16:29:18;0008;PBS_Server;Job;39380.tyrone-cluster;Job Modified at request of Scheduler@tyrone-cluster
06/03/2014 16:29:18;0008;PBS_Server;Job;39380.tyrone-cluster;Job Run at request of Scheduler@tyrone-cluster
06/03/2014 16:29:18;0040;PBS_Server;Svr;tyrone-cluster;Scheduler was sent the command recyc
06/03/2014 16:29:18;000d;PBS_Server;Job;39380.tyrone-cluster;Not sending email: User does not want mail of this type.
06/03/2014 16:29:19;000d;PBS_Server;Job;39380.tyrone-cluster;Not sending email: User does not want mail of this type.
06/03/2014 16:29:19;0010;PBS_Server;Job;39380.tyrone-cluster;Exit_status=139 resources_used.cput=00:00:01 resources_used.mem=0kb resources_used.vmem=0kb resources_used.walltime=00:00:01
06/03/2014 16:29:19;0008;PBS_Server;Job;NULL;on_job_exit valid pjob: 0x177bea0 (substate=50)
06/03/2014 16:29:19;0008;PBS_Server;Job;NULL;on_job_exit valid pjob: 0x177bea0 (substate=51)
06/03/2014 16:29:19;0008;PBS_Server;Job;NULL;on_job_exit valid pjob: 0x177bea0 (substate=51)
06/03/2014 16:29:19;0008;PBS_Server;Job;NULL;on_job_exit valid pjob: 0x177bea0 (substate=53)
06/03/2014 16:29:19;0100;PBS_Server;Job;39380.tyrone-cluster;dequeuing from idqueue, state COMPLETE
06/03/2014 16:29:19;0040;PBS_Server;Svr;tyrone-cluster;Scheduler was sent the command term
06/03/2014 16:29:36;0040;PBS_Server;Svr;tyrone-cluster;Scheduler was sent the command new
06/03/2014 16:29:36;0100;PBS_Server;Job;39381.tyrone-cluster;enqueuing into batch, state 1 hop 1
06/03/2014 16:29:36;0100;PBS_Server;Job;39381.tyrone-cluster;dequeuing from batch, state QUEUED
06/03/2014 16:29:36;0100;PBS_Server;Job;39381.tyrone-cluster;enqueuing into idqueue, state 1 hop 1
06/03/2014 16:29:36;0008;PBS_Server;Job;39381.tyrone-cluster;Job Queued at request of secpka@tyrone-cluster, owner = secpka@tyrone-cluster, job name = jobname, queue = idqueue
06/03/2014 16:29:36;0040;PBS_Server;Svr;tyrone-cluster;Scheduler was sent the command new
06/03/2014 16:29:36;0008;PBS_Server;Job;39381.tyrone-cluster;Job Modified at request of Scheduler@tyrone-cluster
06/03/2014 16:29:36;0008;PBS_Server;Job;39381.tyrone-cluster;Job Run at request of Scheduler@tyrone-cluster
06/03/2014 16:29:36;0040;PBS_Server;Svr;tyrone-cluster;Scheduler was sent the command recyc
06/03/2014 16:29:36;000d;PBS_Server;Job;39381.tyrone-cluster;Not sending email: User does not want mail of this type.
06/03/2014 16:29:37;000d;PBS_Server;Job;39381.tyrone-cluster;Not sending email: User does not want mail of this type.
06/03/2014 16:29:37;0010;PBS_Server;Job;39381.tyrone-cluster;Exit_status=139 resources_used.cput=00:00:04 resources_used.mem=0kb resources_used.vmem=0kb resources_used.walltime=00:00:01
06/03/2014 16:29:37;0008;PBS_Server;Job;NULL;on_job_exit valid pjob: 0x177bea0 (substate=50)
06/03/2014 16:29:37;0008;PBS_Server;Job;NULL;on_job_exit valid pjob: 0x177bea0 (substate=51)
06/03/2014 16:29:37;0008;PBS_Server;Job;NULL;on_job_exit valid pjob: 0x177bea0 (substate=51)
06/03/2014 16:29:37;0008;PBS_Server;Job;NULL;on_job_exit valid pjob: 0x177bea0 (substate=53)
06/03/2014 16:29:37;0100;PBS_Server;Job;39381.tyrone-cluster;dequeuing from idqueue, state COMPLETE
06/03/2014 16:29:37;0040;PBS_Server;Svr;tyrone-cluster;Scheduler was sent the command term
06/03/2014 16:30:09;0040;PBS_Server;Svr;tyrone-cluster;Scheduler was sent the command new
06/03/2014 16:30:12;0100;PBS_Server;Job;39382.tyrone-cluster;enqueuing into batch, state 1 hop 1
06/03/2014 16:30:12;0100;PBS_Server;Job;39382.tyrone-cluster;dequeuing from batch, state QUEUED
06/03/2014 16:30:12;0100;PBS_Server;Job;39382.tyrone-cluster;enqueuing into idqueue, state 1 hop 1
06/03/2014 16:30:12;0008;PBS_Server;Job;39382.tyrone-cluster;Job Queued at request of secpka@tyrone-cluster, owner = secpka@tyrone-cluster, job name = jobname, queue = idqueue
06/03/2014 16:30:12;0040;PBS_Server;Svr;tyrone-cluster;Scheduler was sent the command new
06/03/2014 16:30:12;0008;PBS_Server;Job;39382.tyrone-cluster;Job Modified at request of Scheduler@tyrone-cluster
06/03/2014 16:30:12;0008;PBS_Server;Job;39382.tyrone-cluster;Job Run at request of Scheduler@tyrone-cluster
06/03/2014 16:30:12;0040;PBS_Server;Svr;tyrone-cluster;Scheduler was sent the command recyc
06/03/2014 16:30:12;000d;PBS_Server;Job;39382.tyrone-cluster;Not sending email: User does not want mail of this type.
06/03/2014 16:30:13;000d;PBS_Server;Job;39382.tyrone-cluster;Not sending email: User does not want mail of this type.
06/03/2014 16:30:13;0010;PBS_Server;Job;39382.tyrone-cluster;Exit_status=139 resources_used.cput=00:00:04 resources_used.mem=0kb resources_used.vmem=0kb resources_used.walltime=00:00:01
06/03/2014 16:30:13;0008;PBS_Server;Job;NULL;on_job_exit valid pjob: 0x177bea0 (substate=50)
06/03/2014 16:30:13;0008;PBS_Server;Job;NULL;on_job_exit valid pjob: 0x177bea0 (substate=51)
06/03/2014 16:30:13;0008;PBS_Server;Job;NULL;on_job_exit valid pjob: 0x177bea0 (substate=51)
06/03/2014 16:30:13;0008;PBS_Server;Job;NULL;on_job_exit valid pjob: 0x177bea0 (substate=53)
06/03/2014 16:30:13;0100;PBS_Server;Job;39382.tyrone-cluster;dequeuing from idqueue, state COMPLETE
06/03/2014 16:30:13;0040;PBS_Server;Svr;tyrone-cluster;Scheduler was sent the command term
06/03/2014 16:30:24;0100;PBS_Server;Job;39383.tyrone-cluster;enqueuing into batch, state 1 hop 1
06/03/2014 16:30:24;0100;PBS_Server;Job;39383.tyrone-cluster;dequeuing from batch, state QUEUED
06/03/2014 16:30:24;0100;PBS_Server;Job;39383.tyrone-cluster;enqueuing into idqueue, state 1 hop 1
06/03/2014 16:30:24;0008;PBS_Server;Job;39383.tyrone-cluster;Job Queued at request of secpka@tyrone-cluster, owner = secpka@tyrone-cluster, job name = jobname, queue = idqueue
06/03/2014 16:30:24;0040;PBS_Server;Svr;tyrone-cluster;Scheduler was sent the command new
06/03/2014 16:30:24;0008;PBS_Server;Job;39383.tyrone-cluster;Job Modified at request of Scheduler@tyrone-cluster
06/03/2014 16:30:24;0008;PBS_Server;Job;39383.tyrone-cluster;Job Run at request of Scheduler@tyrone-cluster
06/03/2014 16:30:24;0040;PBS_Server;Svr;tyrone-cluster;Scheduler was sent the command recyc
06/03/2014 16:30:24;000d;PBS_Server;Job;39383.tyrone-cluster;Not sending email: User does not want mail of this type.
06/03/2014 16:30:25;000d;PBS_Server;Job;39383.tyrone-cluster;Not sending email: User does not want mail of this type.
06/03/2014 16:30:25;0010;PBS_Server;Job;39383.tyrone-cluster;Exit_status=139 resources_used.cput=00:00:01 resources_used.mem=0kb resources_used.vmem=0kb resources_used.walltime=00:00:00
06/03/2014 16:30:25;0008;PBS_Server;Job;NULL;on_job_exit valid pjob: 0x177bea0 (substate=50)
06/03/2014 16:30:25;0008;PBS_Server;Job;NULL;on_job_exit valid pjob: 0x177bea0 (substate=51)
06/03/2014 16:30:25;0008;PBS_Server;Job;NULL;on_job_exit valid pjob: 0x177bea0 (substate=51)
06/03/2014 16:30:25;0008;PBS_Server;Job;NULL;on_job_exit valid pjob: 0x177bea0 (substate=53)
06/03/2014 16:30:25;0100;PBS_Server;Job;39383.tyrone-cluster;dequeuing from idqueue, state COMPLETE
06/03/2014 16:30:25;0040;PBS_Server;Svr;tyrone-cluster;Scheduler was sent the command term
06/03/2014 16:30:41;0040;PBS_Server;Svr;tyrone-cluster;Scheduler was sent the command new
06/03/2014 16:30:57;0002;PBS_Server;Svr;PBS_Server;Torque Server Version = 3.0.5, loglevel = 0
06/03/2014 16:31:17;0040;PBS_Server;Svr;tyrone-cluster;Scheduler was sent the command new
06/03/2014 16:31:51;0040;PBS_Server;Svr;tyrone-cluster;Scheduler was sent the command new
06/03/2014 16:32:24;0040;PBS_Server;Svr;tyrone-cluster;Scheduler was sent the command new
06/03/2014 16:32:55;0040;PBS_Server;Svr;tyrone-cluster;Scheduler was sent the command new
06/03/2014 16:33:28;0040;PBS_Server;Svr;tyrone-cluster;Scheduler was sent the command new
06/03/2014 16:34:06;0040;PBS_Server;Svr;tyrone-cluster;Scheduler was sent the command new
06/03/2014 16:34:39;0040;PBS_Server;Svr;tyrone-cluster;Scheduler was sent the command new
06/03/2014 16:35:10;0040;PBS_Server;Svr;tyrone-cluster;Scheduler was sent the command new
06/03/2014 16:35:47;0040;PBS_Server;Svr;tyrone-cluster;Scheduler was sent the command new
06/03/2014 16:35:57;0002;PBS_Server;Svr;PBS_Server;Torque Server Version = 3.0.5, loglevel = 0
06/03/2014 16:36:21;0040;PBS_Server;Svr;tyrone-cluster;Scheduler was sent the command new
06/03/2014 16:36:54;0040;PBS_Server;Svr;tyrone-cluster;Scheduler was sent the command new
06/03/2014 16:37:26;0040;PBS_Server;Svr;tyrone-cluster;Scheduler was sent the command new
06/03/2014 16:38:02;0040;PBS_Server;Svr;tyrone-cluster;Scheduler was sent the command new
06/03/2014 16:38:36;0040;PBS_Server;Svr;tyrone-cluster;Scheduler was sent the command new
06/03/2014 16:38:44;0100;PBS_Server;Job;39384.tyrone-cluster;enqueuing into batch, state 1 hop 1
06/03/2014 16:38:44;0100;PBS_Server;Job;39384.tyrone-cluster;dequeuing from batch, state QUEUED
06/03/2014 16:38:44;0100;PBS_Server;Job;39384.tyrone-cluster;enqueuing into qp32, state 1 hop 1
06/03/2014 16:38:44;0008;PBS_Server;Job;39384.tyrone-cluster;Job Queued at request of secbadar@tyrone-cluster, owner = secbadar@tyrone-cluster, job name = job32Guns, queue = qp32
06/03/2014 16:38:44;0040;PBS_Server;Svr;tyrone-cluster;Scheduler was sent the command new
06/03/2014 16:38:44;0008;PBS_Server;Job;39384.tyrone-cluster;Job Modified at request of Scheduler@tyrone-cluster
06/03/2014 16:38:44;0008;PBS_Server;Job;39384.tyrone-cluster;Job Run at request of Scheduler@tyrone-cluster
06/03/2014 16:38:44;0040;PBS_Server;Svr;tyrone-cluster;Scheduler was sent the command recyc
06/03/2014 16:38:44;000d;PBS_Server;Job;39384.tyrone-cluster;Not sending email: User does not want mail of this type.
06/03/2014 16:38:45;000d;PBS_Server;Job;39384.tyrone-cluster;Not sending email: User does not want mail of this type.
06/03/2014 16:38:45;0010;PBS_Server;Job;39384.tyrone-cluster;Exit_status=255 resources_used.cput=00:00:00 resources_used.mem=0kb resources_used.vmem=0kb resources_used.walltime=00:00:01
06/03/2014 16:38:45;0008;PBS_Server;Job;NULL;on_job_exit valid pjob: 0x177bea0 (substate=50)
06/03/2014 16:38:45;0008;PBS_Server;Job;NULL;on_job_exit valid pjob: 0x177bea0 (substate=51)
06/03/2014 16:38:45;0008;PBS_Server;Job;NULL;on_job_exit valid pjob: 0x177bea0 (substate=51)
06/03/2014 16:38:45;0008;PBS_Server;Job;NULL;on_job_exit valid pjob: 0x177bea0 (substate=53)
06/03/2014 16:38:45;0100;PBS_Server;Job;39384.tyrone-cluster;dequeuing from qp32, state COMPLETE
06/03/2014 16:38:45;0040;PBS_Server;Svr;tyrone-cluster;Scheduler was sent the command term
06/03/2014 16:39:09;0040;PBS_Server;Svr;tyrone-cluster;Scheduler was sent the command new
06/03/2014 16:39:34;0100;PBS_Server;Job;39385.tyrone-cluster;enqueuing into batch, state 1 hop 1
06/03/2014 16:39:34;0100;PBS_Server;Job;39385.tyrone-cluster;dequeuing from batch, state QUEUED
06/03/2014 16:39:34;0100;PBS_Server;Job;39385.tyrone-cluster;enqueuing into qp32, state 1 hop 1
06/03/2014 16:39:34;0008;PBS_Server;Job;39385.tyrone-cluster;Job Queued at request of secbadar@tyrone-cluster, owner = secbadar@tyrone-cluster, job name = job32Guns, queue = qp32
06/03/2014 16:39:34;0040;PBS_Server;Svr;tyrone-cluster;Scheduler was sent the command new
06/03/2014 16:39:34;0008;PBS_Server;Job;39385.tyrone-cluster;Job Modified at request of Scheduler@tyrone-cluster
06/03/2014 16:39:34;0008;PBS_Server;Job;39385.tyrone-cluster;Job Run at request of Scheduler@tyrone-cluster
06/03/2014 16:39:34;0040;PBS_Server;Svr;tyrone-cluster;Scheduler was sent the command recyc
06/03/2014 16:39:34;000d;PBS_Server;Job;39385.tyrone-cluster;Not sending email: User does not want mail of this type.
06/03/2014 16:39:40;0040;PBS_Server;Svr;tyrone-cluster;Scheduler was sent the command new
06/03/2014 16:40:17;0040;PBS_Server;Svr;tyrone-cluster;Scheduler was sent the command new
06/03/2014 16:40:51;0040;PBS_Server;Svr;tyrone-cluster;Scheduler was sent the command new
06/03/2014 16:40:57;0002;PBS_Server;Svr;PBS_Server;Torque Server Version = 3.0.5, loglevel = 0
06/03/2014 16:41:22;0040;PBS_Server;Svr;tyrone-cluster;Scheduler was sent the command new
06/03/2014 16:41:52;0040;PBS_Server;Svr;tyrone-cluster;Scheduler was sent the command new
06/03/2014 16:42:22;0040;PBS_Server;Svr;tyrone-cluster;Scheduler was sent the command new
06/03/2014 16:42:52;0040;PBS_Server;Svr;tyrone-cluster;Scheduler was sent the command new
06/03/2014 16:43:22;0040;PBS_Server;Svr;tyrone-cluster;Scheduler was sent the command new
06/03/2014 16:43:52;0040;PBS_Server;Svr;tyrone-cluster;Scheduler was sent the command new
06/03/2014 16:44:14;0100;PBS_Server;Job;39386.tyrone-cluster;enqueuing into batch, state 1 hop 1
06/03/2014 16:44:14;0100;PBS_Server;Job;39386.tyrone-cluster;dequeuing from batch, state QUEUED
06/03/2014 16:44:14;0100;PBS_Server;Job;39386.tyrone-cluster;enqueuing into idqueue, state 1 hop 1
06/03/2014 16:44:14;0008;PBS_Server;Job;39386.tyrone-cluster;Job Queued at request of secpka@tyrone-cluster, owner = secpka@tyrone-cluster, job name = jobname, queue = idqueue
06/03/2014 16:44:14;0040;PBS_Server;Svr;tyrone-cluster;Scheduler was sent the command new
06/03/2014 16:44:14;0008;PBS_Server;Job;39386.tyrone-cluster;Job Modified at request of Scheduler@tyrone-cluster
06/03/2014 16:44:14;0008;PBS_Server;Job;39386.tyrone-cluster;Job Run at request of Scheduler@tyrone-cluster
06/03/2014 16:44:14;0040;PBS_Server;Svr;tyrone-cluster;Scheduler was sent the command recyc
06/03/2014 16:44:14;000d;PBS_Server;Job;39386.tyrone-cluster;Not sending email: User does not want mail of this type.
06/03/2014 16:44:22;0040;PBS_Server;Svr;tyrone-cluster;Scheduler was sent the command new
06/03/2014 16:44:23;000d;PBS_Server;Job;39386.tyrone-cluster;Not sending email: User does not want mail of this type.
06/03/2014 16:44:23;0010;PBS_Server;Job;39386.tyrone-cluster;Exit_status=0 resources_used.cput=00:01:28 resources_used.mem=0kb resources_used.vmem=0kb resources_used.walltime=00:00:09
06/03/2014 16:44:23;0008;PBS_Server;Job;NULL;on_job_exit valid pjob: 0x1791590 (substate=50)
06/03/2014 16:44:23;0008;PBS_Server;Job;NULL;on_job_exit valid pjob: 0x1791590 (substate=51)
06/03/2014 16:44:23;0008;PBS_Server;Job;NULL;on_job_exit valid pjob: 0x1791590 (substate=51)
06/03/2014 16:44:23;0008;PBS_Server;Job;NULL;on_job_exit valid pjob: 0x1791590 (substate=53)
06/03/2014 16:44:23;0100;PBS_Server;Job;39386.tyrone-cluster;dequeuing from idqueue, state COMPLETE
06/03/2014 16:44:23;0040;PBS_Server;Svr;tyrone-cluster;Scheduler was sent the command term
06/03/2014 16:44:52;0040;PBS_Server;Svr;tyrone-cluster;Scheduler was sent the command new
06/03/2014 16:45:19;000d;PBS_Server;Job;39385.tyrone-cluster;Not sending email: User does not want mail of this type.
06/03/2014 16:45:19;0010;PBS_Server;Job;39385.tyrone-cluster;Exit_status=0 resources_used.cput=00:36:43 resources_used.mem=5263380kb resources_used.vmem=8600516kb resources_used.walltime=00:05:44
06/03/2014 16:45:19;0008;PBS_Server;Job;NULL;on_job_exit valid pjob: 0x177bea0 (substate=50)
06/03/2014 16:45:19;0008;PBS_Server;Job;NULL;on_job_exit valid pjob: 0x177bea0 (substate=51)
06/03/2014 16:45:19;0008;PBS_Server;Job;NULL;on_job_exit valid pjob: 0x177bea0 (substate=51)
06/03/2014 16:45:19;0008;PBS_Server;Job;NULL;on_job_exit valid pjob: 0x177bea0 (substate=53)
06/03/2014 16:45:19;0100;PBS_Server;Job;39385.tyrone-cluster;dequeuing from qp32, state COMPLETE
06/03/2014 16:45:19;0040;PBS_Server;Svr;tyrone-cluster;Scheduler was sent the command term
06/03/2014 16:45:22;0040;PBS_Server;Svr;tyrone-cluster;Scheduler was sent the command new
06/03/2014 16:45:54;0040;PBS_Server;Svr;tyrone-cluster;Scheduler was sent the command new
06/03/2014 16:45:57;0002;PBS_Server;Svr;PBS_Server;Torque Server Version = 3.0.5, loglevel = 0
06/03/2014 16:46:18;0100;PBS_Server;Job;39387.tyrone-cluster;enqueuing into batch, state 1 hop 1
06/03/2014 16:46:18;0100;PBS_Server;Job;39387.tyrone-cluster;dequeuing from batch, state QUEUED
06/03/2014 16:46:18;0100;PBS_Server;Job;39387.tyrone-cluster;enqueuing into idqueue, state 1 hop 1
06/03/2014 16:46:18;0008;PBS_Server;Job;39387.tyrone-cluster;Job Queued at request of secpka@tyrone-cluster, owner = secpka@tyrone-cluster, job name = jobname, queue = idqueue
06/03/2014 16:46:18;0040;PBS_Server;Svr;tyrone-cluster;Scheduler was sent the command new
06/03/2014 16:46:18;0008;PBS_Server;Job;39387.tyrone-cluster;Job Modified at request of Scheduler@tyrone-cluster
06/03/2014 16:46:18;0008;PBS_Server;Job;39387.tyrone-cluster;Job Run at request of Scheduler@tyrone-cluster
06/03/2014 16:46:19;0040;PBS_Server;Svr;tyrone-cluster;Scheduler was sent the command recyc
06/03/2014 16:46:19;000d;PBS_Server;Job;39387.tyrone-cluster;Not sending email: User does not want mail of this type.
06/03/2014 16:46:25;0040;PBS_Server;Svr;tyrone-cluster;Scheduler was sent the command new
06/03/2014 16:46:33;000d;PBS_Server;Job;39387.tyrone-cluster;Not sending email: User does not want mail of this type.
06/03/2014 16:46:33;0010;PBS_Server;Job;39387.tyrone-cluster;Exit_status=0 resources_used.cput=00:02:38 resources_used.mem=0kb resources_used.vmem=0kb resources_used.walltime=00:00:15
06/03/2014 16:46:33;0008;PBS_Server;Job;NULL;on_job_exit valid pjob: 0x177bea0 (substate=50)
06/03/2014 16:46:33;0008;PBS_Server;Job;NULL;on_job_exit valid pjob: 0x177bea0 (substate=51)
06/03/2014 16:46:34;0008;PBS_Server;Job;NULL;on_job_exit valid pjob: 0x177bea0 (substate=51)
06/03/2014 16:46:34;0008;PBS_Server;Job;NULL;on_job_exit valid pjob: 0x177bea0 (substate=53)
06/03/2014 16:46:34;0100;PBS_Server;Job;39387.tyrone-cluster;dequeuing from idqueue, state COMPLETE
06/03/2014 16:46:34;0040;PBS_Server;Svr;tyrone-cluster;Scheduler was sent the command term
06/03/2014 16:46:54;0040;PBS_Server;Svr;tyrone-cluster;Scheduler was sent the command new
06/03/2014 16:47:24;0040;PBS_Server;Svr;tyrone-cluster;Scheduler was sent the command new
06/03/2014 16:47:55;0040;PBS_Server;Svr;tyrone-cluster;Scheduler was sent the command new
06/03/2014 16:48:10;0100;PBS_Server;Job;39388.tyrone-cluster;enqueuing into batch, state 1 hop 1
06/03/2014 16:48:10;0100;PBS_Server;Job;39388.tyrone-cluster;dequeuing from batch, state QUEUED
06/03/2014 16:48:10;0100;PBS_Server;Job;39388.tyrone-cluster;enqueuing into idqueue, state 1 hop 1
06/03/2014 16:48:10;0008;PBS_Server;Job;39388.tyrone-cluster;Job Queued at request of secpka@tyrone-cluster, owner = secpka@tyrone-cluster, job name = jobname, queue = idqueue
06/03/2014 16:48:10;0040;PBS_Server;Svr;tyrone-cluster;Scheduler was sent the command new
06/03/2014 16:48:10;0008;PBS_Server;Job;39388.tyrone-cluster;Job Modified at request of Scheduler@tyrone-cluster
06/03/2014 16:48:10;0008;PBS_Server;Job;39388.tyrone-cluster;Job Run at request of Scheduler@tyrone-cluster
06/03/2014 16:48:10;0040;PBS_Server;Svr;tyrone-cluster;Scheduler was sent the command recyc
06/03/2014 16:48:10;000d;PBS_Server;Job;39388.tyrone-cluster;Not sending email: User does not want mail of this type.
06/03/2014 16:48:24;000d;PBS_Server;Job;39388.tyrone-cluster;Not sending email: User does not want mail of this type.
06/03/2014 16:48:24;0010;PBS_Server;Job;39388.tyrone-cluster;Exit_status=0 resources_used.cput=00:02:21 resources_used.mem=0kb resources_used.vmem=0kb resources_used.walltime=00:00:13
06/03/2014 16:48:24;0008;PBS_Server;Job;NULL;on_job_exit valid pjob: 0x177bea0 (substate=50)
06/03/2014 16:48:24;0008;PBS_Server;Job;NULL;on_job_exit valid pjob: 0x177bea0 (substate=51)
06/03/2014 16:48:24;0008;PBS_Server;Job;NULL;on_job_exit valid pjob: 0x177bea0 (substate=51)
06/03/2014 16:48:24;0008;PBS_Server;Job;NULL;on_job_exit valid pjob: 0x177bea0 (substate=53)
06/03/2014 16:48:24;0100;PBS_Server;Job;39388.tyrone-cluster;dequeuing from idqueue, state COMPLETE
06/03/2014 16:48:24;0040;PBS_Server;Svr;tyrone-cluster;Scheduler was sent the command term
06/03/2014 16:48:28;0040;PBS_Server;Svr;tyrone-cluster;Scheduler was sent the command new
06/03/2014 16:49:06;0040;PBS_Server;Svr;tyrone-cluster;Scheduler was sent the command new
06/03/2014 16:49:21;0100;PBS_Server;Job;39389.tyrone-cluster;enqueuing into batch, state 1 hop 1
06/03/2014 16:49:21;0100;PBS_Server;Job;39389.tyrone-cluster;dequeuing from batch, state QUEUED
06/03/2014 16:49:21;0100;PBS_Server;Job;39389.tyrone-cluster;enqueuing into idqueue, state 1 hop 1
06/03/2014 16:49:21;0008;PBS_Server;Job;39389.tyrone-cluster;Job Queued at request of secpka@tyrone-cluster, owner = secpka@tyrone-cluster, job name = jobname, queue = idqueue
06/03/2014 16:49:21;0040;PBS_Server;Svr;tyrone-cluster;Scheduler was sent the command new
06/03/2014 16:49:21;0008;PBS_Server;Job;39389.tyrone-cluster;Job Modified at request of Scheduler@tyrone-cluster
06/03/2014 16:49:21;0008;PBS_Server;Job;39389.tyrone-cluster;Job Run at request of Scheduler@tyrone-cluster
06/03/2014 16:49:21;0040;PBS_Server;Svr;tyrone-cluster;Scheduler was sent the command recyc
06/03/2014 16:49:21;000d;PBS_Server;Job;39389.tyrone-cluster;Not sending email: User does not want mail of this type.
06/03/2014 16:49:33;000d;PBS_Server;Job;39389.tyrone-cluster;Not sending email: User does not want mail of this type.
06/03/2014 16:49:33;0010;PBS_Server;Job;39389.tyrone-cluster;Exit_status=0 resources_used.cput=00:02:04 resources_used.mem=0kb resources_used.vmem=0kb resources_used.walltime=00:00:12
06/03/2014 16:49:33;0008;PBS_Server;Job;NULL;on_job_exit valid pjob: 0x177bea0 (substate=50)
06/03/2014 16:49:33;0008;PBS_Server;Job;NULL;on_job_exit valid pjob: 0x177bea0 (substate=51)
06/03/2014 16:49:33;0008;PBS_Server;Job;NULL;on_job_exit valid pjob: 0x177bea0 (substate=51)
06/03/2014 16:49:33;0008;PBS_Server;Job;NULL;on_job_exit valid pjob: 0x177bea0 (substate=53)
06/03/2014 16:49:33;0100;PBS_Server;Job;39389.tyrone-cluster;dequeuing from idqueue, state COMPLETE
06/03/2014 16:49:33;0040;PBS_Server;Svr;tyrone-cluster;Scheduler was sent the command term
06/03/2014 16:49:39;0040;PBS_Server;Svr;tyrone-cluster;Scheduler was sent the command new
06/03/2014 16:50:08;0100;PBS_Server;Job;39390.tyrone-cluster;enqueuing into batch, state 1 hop 1
06/03/2014 16:50:08;0100;PBS_Server;Job;39390.tyrone-cluster;dequeuing from batch, state QUEUED
06/03/2014 16:50:08;0100;PBS_Server;Job;39390.tyrone-cluster;enqueuing into idqueue, state 1 hop 1
06/03/2014 16:50:08;0008;PBS_Server;Job;39390.tyrone-cluster;Job Queued at request of secpka@tyrone-cluster, owner = secpka@tyrone-cluster, job name = jobname, queue = idqueue
06/03/2014 16:50:08;0040;PBS_Server;Svr;tyrone-cluster;Scheduler was sent the command new
06/03/2014 16:50:08;0008;PBS_Server;Job;39390.tyrone-cluster;Job Modified at request of Scheduler@tyrone-cluster
06/03/2014 16:50:08;0008;PBS_Server;Job;39390.tyrone-cluster;Job Run at request of Scheduler@tyrone-cluster
06/03/2014 16:50:08;0040;PBS_Server;Svr;tyrone-cluster;Scheduler was sent the command recyc
06/03/2014 16:50:08;000d;PBS_Server;Job;39390.tyrone-cluster;Not sending email: User does not want mail of this type.
06/03/2014 16:50:10;0040;PBS_Server;Svr;tyrone-cluster;Scheduler was sent the command new
06/03/2014 16:50:18;000d;PBS_Server;Job;39390.tyrone-cluster;Not sending email: User does not want mail of this type.
06/03/2014 16:50:18;0010;PBS_Server;Job;39390.tyrone-cluster;Exit_status=0 resources_used.cput=00:01:46 resources_used.mem=0kb resources_used.vmem=0kb resources_used.walltime=00:00:10
06/03/2014 16:50:18;0008;PBS_Server;Job;NULL;on_job_exit valid pjob: 0x177bea0 (substate=50)
06/03/2014 16:50:18;0008;PBS_Server;Job;NULL;on_job_exit valid pjob: 0x177bea0 (substate=51)
06/03/2014 16:50:18;0008;PBS_Server;Job;NULL;on_job_exit valid pjob: 0x177bea0 (substate=51)
06/03/2014 16:50:18;0008;PBS_Server;Job;NULL;on_job_exit valid pjob: 0x177bea0 (substate=53)
06/03/2014 16:50:18;0100;PBS_Server;Job;39390.tyrone-cluster;dequeuing from idqueue, state COMPLETE
06/03/2014 16:50:18;0040;PBS_Server;Svr;tyrone-cluster;Scheduler was sent the command term
06/03/2014 16:50:24;0100;PBS_Server;Job;39391.tyrone-cluster;enqueuing into batch, state 1 hop 1
06/03/2014 16:50:24;0100;PBS_Server;Job;39391.tyrone-cluster;dequeuing from batch, state QUEUED
06/03/2014 16:50:24;0100;PBS_Server;Job;39391.tyrone-cluster;enqueuing into idqueue, state 1 hop 1
06/03/2014 16:50:24;0008;PBS_Server;Job;39391.tyrone-cluster;Job Queued at request of secpka@tyrone-cluster, owner = secpka@tyrone-cluster, job name = jobname, queue = idqueue
06/03/2014 16:50:24;0040;PBS_Server;Svr;tyrone-cluster;Scheduler was sent the command new
06/03/2014 16:50:24;0008;PBS_Server;Job;39391.tyrone-cluster;Job Modified at request of Scheduler@tyrone-cluster
06/03/2014 16:50:24;0008;PBS_Server;Job;39391.tyrone-cluster;Job Run at request of Scheduler@tyrone-cluster
06/03/2014 16:50:24;0040;PBS_Server;Svr;tyrone-cluster;Scheduler was sent the command recyc
06/03/2014 16:50:24;000d;PBS_Server;Job;39391.tyrone-cluster;Not sending email: User does not want mail of this type.
06/03/2014 16:50:44;0040;PBS_Server;Svr;tyrone-cluster;Scheduler was sent the command new
06/03/2014 16:50:44;0100;PBS_Server;Job;39392.tyrone-cluster;enqueuing into batch, state 1 hop 1
06/03/2014 16:50:44;0100;PBS_Server;Job;39392.tyrone-cluster;dequeuing from batch, state QUEUED
06/03/2014 16:50:44;0100;PBS_Server;Job;39392.tyrone-cluster;enqueuing into idqueue, state 1 hop 1
06/03/2014 16:50:44;0008;PBS_Server;Job;39392.tyrone-cluster;Job Queued at request of secpka@tyrone-cluster, owner = secpka@tyrone-cluster, job name = jobname, queue = idqueue
06/03/2014 16:50:44;0008;PBS_Server;Job;39392.tyrone-cluster;Job Modified at request of Scheduler@tyrone-cluster
06/03/2014 16:50:52;000d;PBS_Server;Job;39391.tyrone-cluster;Not sending email: User does not want mail of this type.
06/03/2014 16:50:52;0010;PBS_Server;Job;39391.tyrone-cluster;Exit_status=0 resources_used.cput=00:02:49 resources_used.mem=0kb resources_used.vmem=0kb resources_used.walltime=00:00:28
06/03/2014 16:50:52;0008;PBS_Server;Job;NULL;on_job_exit valid pjob: 0x177bea0 (substate=50)
06/03/2014 16:50:52;0008;PBS_Server;Job;NULL;on_job_exit valid pjob: 0x177bea0 (substate=51)
06/03/2014 16:50:52;0008;PBS_Server;Job;NULL;on_job_exit valid pjob: 0x177bea0 (substate=51)
06/03/2014 16:50:52;0008;PBS_Server;Job;NULL;on_job_exit valid pjob: 0x177bea0 (substate=53)
06/03/2014 16:50:52;0100;PBS_Server;Job;39391.tyrone-cluster;dequeuing from idqueue, state COMPLETE
06/03/2014 16:50:52;0040;PBS_Server;Svr;tyrone-cluster;Scheduler was sent the command term
06/03/2014 16:50:52;0008;PBS_Server;Job;39392.tyrone-cluster;Job Modified at request of Scheduler@tyrone-cluster
06/03/2014 16:50:52;0008;PBS_Server;Job;39392.tyrone-cluster;Job Run at request of Scheduler@tyrone-cluster
06/03/2014 16:50:53;0040;PBS_Server;Svr;tyrone-cluster;Scheduler was sent the command recyc
06/03/2014 16:50:53;000d;PBS_Server;Job;39392.tyrone-cluster;Not sending email: User does not want mail of this type.
06/03/2014 16:50:57;0002;PBS_Server;Svr;PBS_Server;Torque Server Version = 3.0.5, loglevel = 0
06/03/2014 16:50:57;0100;PBS_Server;Job;39393.tyrone-cluster;enqueuing into batch, state 1 hop 1
06/03/2014 16:50:57;0100;PBS_Server;Job;39393.tyrone-cluster;dequeuing from batch, state QUEUED
06/03/2014 16:50:57;0100;PBS_Server;Job;39393.tyrone-cluster;enqueuing into idqueue, state 1 hop 1
06/03/2014 16:50:57;0008;PBS_Server;Job;39393.tyrone-cluster;Job Queued at request of secpka@tyrone-cluster, owner = secpka@tyrone-cluster, job name = jobname, queue = idqueue
06/03/2014 16:50:57;0040;PBS_Server;Svr;tyrone-cluster;Scheduler was sent the command new
06/03/2014 16:50:58;0008;PBS_Server;Job;39393.tyrone-cluster;Job Modified at request of Scheduler@tyrone-cluster
06/03/2014 16:51:06;000d;PBS_Server;Job;39392.tyrone-cluster;Not sending email: User does not want mail of this type.
06/03/2014 16:51:06;0010;PBS_Server;Job;39392.tyrone-cluster;Exit_status=0 resources_used.cput=00:01:37 resources_used.mem=0kb resources_used.vmem=0kb resources_used.walltime=00:00:14
06/03/2014 16:51:06;0008;PBS_Server;Job;NULL;on_job_exit valid pjob: 0x1791590 (substate=50)
06/03/2014 16:51:06;0008;PBS_Server;Job;NULL;on_job_exit valid pjob: 0x1791590 (substate=51)
06/03/2014 16:51:07;0008;PBS_Server;Job;NULL;on_job_exit valid pjob: 0x1791590 (substate=51)
06/03/2014 16:51:07;0008;PBS_Server;Job;NULL;on_job_exit valid pjob: 0x1791590 (substate=53)
06/03/2014 16:51:07;0100;PBS_Server;Job;39392.tyrone-cluster;dequeuing from idqueue, state COMPLETE
06/03/2014 16:51:07;0040;PBS_Server;Svr;tyrone-cluster;Scheduler was sent the command term
06/03/2014 16:51:07;0008;PBS_Server;Job;39393.tyrone-cluster;Job Modified at request of Scheduler@tyrone-cluster
06/03/2014 16:51:07;0008;PBS_Server;Job;39393.tyrone-cluster;Job Run at request of Scheduler@tyrone-cluster
06/03/2014 16:51:07;0040;PBS_Server;Svr;tyrone-cluster;Scheduler was sent the command recyc
06/03/2014 16:51:07;000d;PBS_Server;Job;39393.tyrone-cluster;Not sending email: User does not want mail of this type.
06/03/2014 16:51:15;0040;PBS_Server;Svr;tyrone-cluster;Scheduler was sent the command new
06/03/2014 16:51:15;000d;PBS_Server;Job;39393.tyrone-cluster;Not sending email: User does not want mail of this type.
06/03/2014 16:51:15;0010;PBS_Server;Job;39393.tyrone-cluster;Exit_status=0 resources_used.cput=00:00:54 resources_used.mem=153504kb resources_used.vmem=1201592kb resources_used.walltime=00:00:08
06/03/2014 16:51:15;0008;PBS_Server;Job;NULL;on_job_exit valid pjob: 0x177bea0 (substate=50)
06/03/2014 16:51:15;0008;PBS_Server;Job;NULL;on_job_exit valid pjob: 0x177bea0 (substate=51)
06/03/2014 16:51:16;0008;PBS_Server;Job;NULL;on_job_exit valid pjob: 0x177bea0 (substate=51)
06/03/2014 16:51:16;0008;PBS_Server;Job;NULL;on_job_exit valid pjob: 0x177bea0 (substate=53)
06/03/2014 16:51:16;0100;PBS_Server;Job;39393.tyrone-cluster;dequeuing from idqueue, state COMPLETE
06/03/2014 16:51:16;0040;PBS_Server;Svr;tyrone-cluster;Scheduler was sent the command term
06/03/2014 16:51:18;0100;PBS_Server;Job;39394.tyrone-cluster;enqueuing into batch, state 1 hop 1
06/03/2014 16:51:18;0100;PBS_Server;Job;39394.tyrone-cluster;dequeuing from batch, state QUEUED
06/03/2014 16:51:18;0100;PBS_Server;Job;39394.tyrone-cluster;enqueuing into idqueue, state 1 hop 1
06/03/2014 16:51:18;0008;PBS_Server;Job;39394.tyrone-cluster;Job Queued at request of secpka@tyrone-cluster, owner = secpka@tyrone-cluster, job name = jobname, queue = idqueue
06/03/2014 16:51:18;0040;PBS_Server;Svr;tyrone-cluster;Scheduler was sent the command new
06/03/2014 16:51:18;0008;PBS_Server;Job;39394.tyrone-cluster;Job Modified at request of Scheduler@tyrone-cluster
06/03/2014 16:51:18;0008;PBS_Server;Job;39394.tyrone-cluster;Job Run at request of Scheduler@tyrone-cluster
06/03/2014 16:51:18;0040;PBS_Server;Svr;tyrone-cluster;Scheduler was sent the command recyc
06/03/2014 16:51:18;000d;PBS_Server;Job;39394.tyrone-cluster;Not sending email: User does not want mail of this type.
06/03/2014 16:51:22;000d;PBS_Server;Job;39394.tyrone-cluster;Not sending email: User does not want mail of this type.
06/03/2014 16:51:22;0010;PBS_Server;Job;39394.tyrone-cluster;Exit_status=0 resources_used.cput=00:00:36 resources_used.mem=0kb resources_used.vmem=0kb resources_used.walltime=00:00:04
06/03/2014 16:51:22;0008;PBS_Server;Job;NULL;on_job_exit valid pjob: 0x177bea0 (substate=50)
06/03/2014 16:51:22;0008;PBS_Server;Job;NULL;on_job_exit valid pjob: 0x177bea0 (substate=51)
06/03/2014 16:51:22;0008;PBS_Server;Job;NULL;on_job_exit valid pjob: 0x177bea0 (substate=51)
06/03/2014 16:51:22;0008;PBS_Server;Job;NULL;on_job_exit valid pjob: 0x177bea0 (substate=53)
06/03/2014 16:51:22;0100;PBS_Server;Job;39394.tyrone-cluster;dequeuing from idqueue, state COMPLETE
06/03/2014 16:51:22;0040;PBS_Server;Svr;tyrone-cluster;Scheduler was sent the command term
06/03/2014 16:51:54;0040;PBS_Server;Svr;tyrone-cluster;Scheduler was sent the command new
06/03/2014 16:52:18;0040;PBS_Server;Svr;tyrone-cluster;Scheduler was sent the command new
06/03/2014 16:52:51;0040;PBS_Server;Svr;tyrone-cluster;Scheduler was sent the command new
06/03/2014 16:53:17;0100;PBS_Server;Job;39395.tyrone-cluster;enqueuing into batch, state 1 hop 1
06/03/2014 16:53:17;0100;PBS_Server;Job;39395.tyrone-cluster;dequeuing from batch, state QUEUED
06/03/2014 16:53:17;0100;PBS_Server;Job;39395.tyrone-cluster;enqueuing into idqueue, state 1 hop 1
06/03/2014 16:53:17;0008;PBS_Server;Job;39395.tyrone-cluster;Job Queued at request of secpka@tyrone-cluster, owner = secpka@tyrone-cluster, job name = jobname, queue = idqueue
06/03/2014 16:53:17;0040;PBS_Server;Svr;tyrone-cluster;Scheduler was sent the command new
06/03/2014 16:53:17;0008;PBS_Server;Job;39395.tyrone-cluster;Job Modified at request of Scheduler@tyrone-cluster
06/03/2014 16:53:17;0008;PBS_Server;Job;39395.tyrone-cluster;Job Run at request of Scheduler@tyrone-cluster
06/03/2014 16:53:17;0040;PBS_Server;Svr;tyrone-cluster;Scheduler was sent the command recyc
06/03/2014 16:53:17;000d;PBS_Server;Job;39395.tyrone-cluster;Not sending email: User does not want mail of this type.
06/03/2014 16:53:21;0040;PBS_Server;Svr;tyrone-cluster;Scheduler was sent the command new
06/03/2014 16:53:21;000d;PBS_Server;Job;39395.tyrone-cluster;Not sending email: User does not want mail of this type.
06/03/2014 16:53:21;0010;PBS_Server;Job;39395.tyrone-cluster;Exit_status=0 resources_used.cput=00:00:24 resources_used.mem=0kb resources_used.vmem=0kb resources_used.walltime=00:00:04
06/03/2014 16:53:21;0008;PBS_Server;Job;NULL;on_job_exit valid pjob: 0x177bea0 (substate=50)
06/03/2014 16:53:21;0008;PBS_Server;Job;NULL;on_job_exit valid pjob: 0x177bea0 (substate=51)
06/03/2014 16:53:22;0008;PBS_Server;Job;NULL;on_job_exit valid pjob: 0x177bea0 (substate=51)
06/03/2014 16:53:22;0008;PBS_Server;Job;NULL;on_job_exit valid pjob: 0x177bea0 (substate=53)
06/03/2014 16:53:22;0100;PBS_Server;Job;39395.tyrone-cluster;dequeuing from idqueue, state COMPLETE
06/03/2014 16:53:22;0040;PBS_Server;Svr;tyrone-cluster;Scheduler was sent the command term
06/03/2014 16:53:51;0040;PBS_Server;Svr;tyrone-cluster;Scheduler was sent the command new
06/03/2014 16:54:21;0040;PBS_Server;Svr;tyrone-cluster;Scheduler was sent the command new
06/03/2014 16:54:54;0040;PBS_Server;Svr;tyrone-cluster;Scheduler was sent the command new
06/03/2014 16:55:25;0040;PBS_Server;Svr;tyrone-cluster;Scheduler was sent the command new
06/03/2014 16:55:57;0002;PBS_Server;Svr;PBS_Server;Torque Server Version = 3.0.5, loglevel = 0
06/03/2014 16:55:57;0040;PBS_Server;Svr;tyrone-cluster;Scheduler was sent the command new
06/03/2014 16:56:36;0040;PBS_Server;Svr;tyrone-cluster;Scheduler was sent the command new
06/03/2014 16:57:09;0040;PBS_Server;Svr;tyrone-cluster;Scheduler was sent the command new
06/03/2014 16:57:40;0040;PBS_Server;Svr;tyrone-cluster;Scheduler was sent the command new
06/03/2014 16:57:46;0100;PBS_Server;Job;39396.tyrone-cluster;enqueuing into batch, state 1 hop 1
06/03/2014 16:57:46;0100;PBS_Server;Job;39396.tyrone-cluster;dequeuing from batch, state QUEUED
06/03/2014 16:57:46;0100;PBS_Server;Job;39396.tyrone-cluster;enqueuing into idqueue, state 1 hop 1
06/03/2014 16:57:46;0008;PBS_Server;Job;39396.tyrone-cluster;Job Queued at request of secpka@tyrone-cluster, owner = secpka@tyrone-cluster, job name = jobname, queue = idqueue
06/03/2014 16:57:46;0040;PBS_Server;Svr;tyrone-cluster;Scheduler was sent the command new
06/03/2014 16:57:46;0008;PBS_Server;Job;39396.tyrone-cluster;Job Modified at request of Scheduler@tyrone-cluster
06/03/2014 16:57:46;0008;PBS_Server;Job;39396.tyrone-cluster;Job Run at request of Scheduler@tyrone-cluster
06/03/2014 16:57:46;0040;PBS_Server;Svr;tyrone-cluster;Scheduler was sent the command recyc
06/03/2014 16:57:46;000d;PBS_Server;Job;39396.tyrone-cluster;Not sending email: User does not want mail of this type.
06/03/2014 16:57:48;0100;PBS_Server;Job;39397.tyrone-cluster;enqueuing into batch, state 1 hop 1
06/03/2014 16:57:48;0100;PBS_Server;Job;39397.tyrone-cluster;dequeuing from batch, state QUEUED
06/03/2014 16:57:48;0100;PBS_Server;Job;39397.tyrone-cluster;enqueuing into idqueue, state 1 hop 1
06/03/2014 16:57:48;0008;PBS_Server;Job;39397.tyrone-cluster;Job Queued at request of secpka@tyrone-cluster, owner = secpka@tyrone-cluster, job name = jobname, queue = idqueue
06/03/2014 16:57:48;0040;PBS_Server;Svr;tyrone-cluster;Scheduler was sent the command new
06/03/2014 16:57:48;0008;PBS_Server;Job;39397.tyrone-cluster;Job Modified at request of Scheduler@tyrone-cluster
06/03/2014 16:57:55;000d;PBS_Server;Job;39396.tyrone-cluster;Not sending email: User does not want mail of this type.
06/03/2014 16:57:55;0010;PBS_Server;Job;39396.tyrone-cluster;Exit_status=0 resources_used.cput=00:01:29 resources_used.mem=153592kb resources_used.vmem=1201588kb resources_used.walltime=00:00:09
06/03/2014 16:57:55;0008;PBS_Server;Job;NULL;on_job_exit valid pjob: 0x177bea0 (substate=50)
06/03/2014 16:57:55;0008;PBS_Server;Job;NULL;on_job_exit valid pjob: 0x177bea0 (substate=51)
06/03/2014 16:57:55;0008;PBS_Server;Job;NULL;on_job_exit valid pjob: 0x177bea0 (substate=51)
06/03/2014 16:57:55;0008;PBS_Server;Job;NULL;on_job_exit valid pjob: 0x177bea0 (substate=53)
06/03/2014 16:57:55;0100;PBS_Server;Job;39396.tyrone-cluster;dequeuing from idqueue, state COMPLETE
06/03/2014 16:57:55;0040;PBS_Server;Svr;tyrone-cluster;Scheduler was sent the command term
06/03/2014 16:57:55;0008;PBS_Server;Job;39397.tyrone-cluster;Job Modified at request of Scheduler@tyrone-cluster
06/03/2014 16:57:55;0008;PBS_Server;Job;39397.tyrone-cluster;Job Run at request of Scheduler@tyrone-cluster
06/03/2014 16:57:55;0040;PBS_Server;Svr;tyrone-cluster;Scheduler was sent the command recyc
06/03/2014 16:57:55;000d;PBS_Server;Job;39397.tyrone-cluster;Not sending email: User does not want mail of this type.
06/03/2014 16:58:04;000d;PBS_Server;Job;39397.tyrone-cluster;Not sending email: User does not want mail of this type.
06/03/2014 16:58:04;0010;PBS_Server;Job;39397.tyrone-cluster;Exit_status=0 resources_used.cput=00:01:27 resources_used.mem=0kb resources_used.vmem=0kb resources_used.walltime=00:00:09
06/03/2014 16:58:04;0008;PBS_Server;Job;NULL;on_job_exit valid pjob: 0x1791590 (substate=50)
06/03/2014 16:58:04;0008;PBS_Server;Job;NULL;on_job_exit valid pjob: 0x1791590 (substate=51)
06/03/2014 16:58:04;0008;PBS_Server;Job;NULL;on_job_exit valid pjob: 0x1791590 (substate=51)
06/03/2014 16:58:04;0008;PBS_Server;Job;NULL;on_job_exit valid pjob: 0x1791590 (substate=53)
06/03/2014 16:58:04;0100;PBS_Server;Job;39397.tyrone-cluster;dequeuing from idqueue, state COMPLETE
06/03/2014 16:58:04;0040;PBS_Server;Svr;tyrone-cluster;Scheduler was sent the command term
06/03/2014 16:58:09;0040;PBS_Server;Svr;tyrone-cluster;Scheduler was sent the command new
06/03/2014 16:58:39;0040;PBS_Server;Svr;tyrone-cluster;Scheduler was sent the command new
06/03/2014 16:59:10;0040;PBS_Server;Svr;tyrone-cluster;Scheduler was sent the command new
06/03/2014 16:59:46;0040;PBS_Server;Svr;tyrone-cluster;Scheduler was sent the command new
06/03/2014 16:59:46;0100;PBS_Server;Job;39398.tyrone-cluster;enqueuing into batch, state 1 hop 1
06/03/2014 16:59:46;0100;PBS_Server;Job;39398.tyrone-cluster;dequeuing from batch, state QUEUED
06/03/2014 16:59:46;0100;PBS_Server;Job;39398.tyrone-cluster;enqueuing into idqueue, state 1 hop 1
06/03/2014 16:59:46;0008;PBS_Server;Job;39398.tyrone-cluster;Job Queued at request of secpka@tyrone-cluster, owner = secpka@tyrone-cluster, job name = jobname, queue = idqueue
06/03/2014 16:59:46;0008;PBS_Server;Job;39398.tyrone-cluster;Job Modified at request of Scheduler@tyrone-cluster
06/03/2014 16:59:46;0008;PBS_Server;Job;39398.tyrone-cluster;Job Run at request of Scheduler@tyrone-cluster
06/03/2014 16:59:47;0040;PBS_Server;Svr;tyrone-cluster;Scheduler was sent the command recyc
06/03/2014 16:59:47;000d;PBS_Server;Job;39398.tyrone-cluster;Not sending email: User does not want mail of this type.
06/03/2014 16:59:54;000d;PBS_Server;Job;39398.tyrone-cluster;Not sending email: User does not want mail of this type.
06/03/2014 16:59:54;0010;PBS_Server;Job;39398.tyrone-cluster;Exit_status=0 resources_used.cput=00:01:11 resources_used.mem=0kb resources_used.vmem=0kb resources_used.walltime=00:00:07
06/03/2014 16:59:54;0008;PBS_Server;Job;NULL;on_job_exit valid pjob: 0x177bea0 (substate=50)
06/03/2014 16:59:54;0008;PBS_Server;Job;NULL;on_job_exit valid pjob: 0x177bea0 (substate=51)
06/03/2014 16:59:54;0008;PBS_Server;Job;NULL;on_job_exit valid pjob: 0x177bea0 (substate=51)
06/03/2014 16:59:54;0008;PBS_Server;Job;NULL;on_job_exit valid pjob: 0x177bea0 (substate=53)
06/03/2014 16:59:54;0100;PBS_Server;Job;39398.tyrone-cluster;dequeuing from idqueue, state COMPLETE
06/03/2014 16:59:54;0040;PBS_Server;Svr;tyrone-cluster;Scheduler was sent the command term
06/03/2014 17:00:21;0040;PBS_Server;Svr;tyrone-cluster;Scheduler was sent the command new
06/03/2014 17:00:54;0040;PBS_Server;Svr;tyrone-cluster;Scheduler was sent the command new
06/03/2014 17:00:57;0002;PBS_Server;Svr;PBS_Server;Torque Server Version = 3.0.5, loglevel = 0
06/03/2014 17:01:22;0040;PBS_Server;Svr;tyrone-cluster;Scheduler was sent the command new
06/03/2014 17:01:51;0040;PBS_Server;Svr;tyrone-cluster;Scheduler was sent the command new
06/03/2014 17:02:24;0040;PBS_Server;Svr;tyrone-cluster;Scheduler was sent the command new
06/03/2014 17:02:32;0100;PBS_Server;Job;39399.tyrone-cluster;enqueuing into batch, state 1 hop 1
06/03/2014 17:02:32;0100;PBS_Server;Job;39399.tyrone-cluster;dequeuing from batch, state QUEUED
06/03/2014 17:02:32;0100;PBS_Server;Job;39399.tyrone-cluster;enqueuing into idqueue, state 1 hop 1
06/03/2014 17:02:32;0008;PBS_Server;Job;39399.tyrone-cluster;Job Queued at request of secpka@tyrone-cluster, owner = secpka@tyrone-cluster, job name = jobname, queue = idqueue
06/03/2014 17:02:32;0040;PBS_Server;Svr;tyrone-cluster;Scheduler was sent the command new
06/03/2014 17:02:32;0008;PBS_Server;Job;39399.tyrone-cluster;Job Modified at request of Scheduler@tyrone-cluster
06/03/2014 17:02:32;0008;PBS_Server;Job;39399.tyrone-cluster;Job Run at request of Scheduler@tyrone-cluster
06/03/2014 17:02:32;0040;PBS_Server;Svr;tyrone-cluster;Scheduler was sent the command recyc
06/03/2014 17:02:32;000d;PBS_Server;Job;39399.tyrone-cluster;Not sending email: User does not want mail of this type.
06/03/2014 17:02:37;000d;PBS_Server;Job;39399.tyrone-cluster;Not sending email: User does not want mail of this type.
06/03/2014 17:02:37;0010;PBS_Server;Job;39399.tyrone-cluster;Exit_status=0 resources_used.cput=00:00:52 resources_used.mem=0kb resources_used.vmem=0kb resources_used.walltime=00:00:05
06/03/2014 17:02:37;0008;PBS_Server;Job;NULL;on_job_exit valid pjob: 0x177bea0 (substate=50)
06/03/2014 17:02:37;0008;PBS_Server;Job;NULL;on_job_exit valid pjob: 0x177bea0 (substate=51)
06/03/2014 17:02:37;0008;PBS_Server;Job;NULL;on_job_exit valid pjob: 0x177bea0 (substate=51)
06/03/2014 17:02:37;0008;PBS_Server;Job;NULL;on_job_exit valid pjob: 0x177bea0 (substate=53)
06/03/2014 17:02:37;0100;PBS_Server;Job;39399.tyrone-cluster;dequeuing from idqueue, state COMPLETE
06/03/2014 17:02:37;0040;PBS_Server;Svr;tyrone-cluster;Scheduler was sent the command term
06/03/2014 17:02:55;0040;PBS_Server;Svr;tyrone-cluster;Scheduler was sent the command new
06/03/2014 17:03:27;0040;PBS_Server;Svr;tyrone-cluster;Scheduler was sent the command new
06/03/2014 17:04:06;0040;PBS_Server;Svr;tyrone-cluster;Scheduler was sent the command new
06/03/2014 17:04:39;0040;PBS_Server;Svr;tyrone-cluster;Scheduler was sent the command new
06/03/2014 17:05:10;0040;PBS_Server;Svr;tyrone-cluster;Scheduler was sent the command new
06/03/2014 17:05:39;0040;PBS_Server;Svr;tyrone-cluster;Scheduler was sent the command new
06/03/2014 17:05:57;0002;PBS_Server;Svr;PBS_Server;Torque Server Version = 3.0.5, loglevel = 0
06/03/2014 17:06:09;0040;PBS_Server;Svr;tyrone-cluster;Scheduler was sent the command new
06/03/2014 17:06:40;0040;PBS_Server;Svr;tyrone-cluster;Scheduler was sent the command new
06/03/2014 17:07:17;0040;PBS_Server;Svr;tyrone-cluster;Scheduler was sent the command new
06/03/2014 17:07:51;0040;PBS_Server;Svr;tyrone-cluster;Scheduler was sent the command new
06/03/2014 17:08:24;0040;PBS_Server;Svr;tyrone-cluster;Scheduler was sent the command new
06/03/2014 17:08:55;0040;PBS_Server;Svr;tyrone-cluster;Scheduler was sent the command new
06/03/2014 17:09:32;0040;PBS_Server;Svr;tyrone-cluster;Scheduler was sent the command new
06/03/2014 17:10:06;0040;PBS_Server;Svr;tyrone-cluster;Scheduler was sent the command new
06/03/2014 17:10:39;0040;PBS_Server;Svr;tyrone-cluster;Scheduler was sent the command new
06/03/2014 17:10:57;0002;PBS_Server;Svr;PBS_Server;Torque Server Version = 3.0.5, loglevel = 0
06/03/2014 17:11:10;0040;PBS_Server;Svr;tyrone-cluster;Scheduler was sent the command new
06/03/2014 17:11:43;0040;PBS_Server;Svr;tyrone-cluster;Scheduler was sent the command new
06/03/2014 17:12:09;0040;PBS_Server;Svr;tyrone-cluster;Scheduler was sent the command new
06/03/2014 17:12:40;0040;PBS_Server;Svr;tyrone-cluster;Scheduler was sent the command new
06/03/2014 17:13:17;0040;PBS_Server;Svr;tyrone-cluster;Scheduler was sent the command new
06/03/2014 17:13:51;0040;PBS_Server;Svr;tyrone-cluster;Scheduler was sent the command new
06/03/2014 17:14:24;0040;PBS_Server;Svr;tyrone-cluster;Scheduler was sent the command new
06/03/2014 17:14:55;0040;PBS_Server;Svr;tyrone-cluster;Scheduler was sent the command new
06/03/2014 17:15:24;0040;PBS_Server;Svr;tyrone-cluster;Scheduler was sent the command new
06/03/2014 17:15:54;0040;PBS_Server;Svr;tyrone-cluster;Scheduler was sent the command new
06/03/2014 17:15:57;0002;PBS_Server;Svr;PBS_Server;Torque Server Version = 3.0.5, loglevel = 0
06/03/2014 17:16:25;0040;PBS_Server;Svr;tyrone-cluster;Scheduler was sent the command new
06/03/2014 17:16:54;0040;PBS_Server;Svr;tyrone-cluster;Scheduler was sent the command new
06/03/2014 17:17:24;0040;PBS_Server;Svr;tyrone-cluster;Scheduler was sent the command new
06/03/2014 17:17:55;0040;PBS_Server;Svr;tyrone-cluster;Scheduler was sent the command new
06/03/2014 17:17:59;000d;PBS_Server;Job;39355.tyrone-cluster;Not sending email: User does not want mail of this type.
06/03/2014 17:17:59;0010;PBS_Server;Job;39355.tyrone-cluster;Exit_status=0 resources_used.cput=69:44:44 resources_used.mem=5282188kb resources_used.vmem=8769836kb resources_used.walltime=02:10:56
06/03/2014 17:17:59;0008;PBS_Server;Job;NULL;on_job_exit valid pjob: 0x1713730 (substate=50)
06/03/2014 17:17:59;0008;PBS_Server;Job;NULL;on_job_exit valid pjob: 0x1713730 (substate=51)
06/03/2014 17:18:07;0008;PBS_Server;Job;NULL;on_job_exit valid pjob: 0x1713730 (substate=51)
06/03/2014 17:18:07;000d;PBS_Server;Job;39355.tyrone-cluster;Post job file processing error; job 39355.tyrone-cluster on host tyrone-node2/31+tyrone-node2/30+tyrone-node2/29+tyrone-node2/28+tyrone-node2/27+tyrone-node2/26+tyrone-node2/25+tyrone-node2/24+tyrone-node2/23+tyrone-node2/22+tyrone-node2/21+tyrone-node2/20+tyrone-node2/19+tyrone-node2/18+tyrone-node2/17+tyrone-node2/16+tyrone-node2/15+tyrone-node2/14+tyrone-node2/13+tyrone-node2/12+tyrone-node2/11+tyrone-node2/10+tyrone-node2/9+tyrone-node2/8+tyrone-node2/7+tyrone-node2/6+tyrone-node2/5+tyrone-node2/4+tyrone-node2/3+tyrone-node2/2+tyrone-node2/1+tyrone-node2/0
06/03/2014 17:18:07;0008;PBS_Server;Job;NULL;on_job_exit valid pjob: 0x1713730 (substate=53)
06/03/2014 17:18:07;0100;PBS_Server;Job;39355.tyrone-cluster;dequeuing from qp32, state COMPLETE
06/03/2014 17:18:07;0040;PBS_Server;Svr;tyrone-cluster;Scheduler was sent the command term
06/03/2014 17:18:28;0040;PBS_Server;Svr;tyrone-cluster;Scheduler was sent the command new
06/03/2014 17:19:06;0040;PBS_Server;Svr;tyrone-cluster;Scheduler was sent the command new
06/03/2014 17:19:39;0040;PBS_Server;Svr;tyrone-cluster;Scheduler was sent the command new
06/03/2014 17:20:10;0040;PBS_Server;Svr;tyrone-cluster;Scheduler was sent the command new
06/03/2014 17:20:47;0040;PBS_Server;Svr;tyrone-cluster;Scheduler was sent the command new
06/03/2014 17:20:57;0002;PBS_Server;Svr;PBS_Server;Torque Server Version = 3.0.5, loglevel = 0
06/03/2014 17:21:12;0040;PBS_Server;Svr;tyrone-cluster;Scheduler was sent the command new
06/03/2014 17:21:12;0100;PBS_Server;Job;39400.tyrone-cluster;enqueuing into batch, state 1 hop 1
06/03/2014 17:21:12;0100;PBS_Server;Job;39400.tyrone-cluster;dequeuing from batch, state QUEUED
06/03/2014 17:21:12;0100;PBS_Server;Job;39400.tyrone-cluster;enqueuing into qp32, state 1 hop 1
06/03/2014 17:21:12;0008;PBS_Server;Job;39400.tyrone-cluster;Job Queued at request of secbadar@tyrone-cluster, owner = secbadar@tyrone-cluster, job name = job32Guns, queue = qp32
06/03/2014 17:21:12;0008;PBS_Server;Job;39400.tyrone-cluster;Job Modified at request of Scheduler@tyrone-cluster
06/03/2014 17:21:12;0008;PBS_Server;Job;39400.tyrone-cluster;Job Run at request of Scheduler@tyrone-cluster
06/03/2014 17:21:12;0040;PBS_Server;Svr;tyrone-cluster;Scheduler was sent the command recyc
06/03/2014 17:21:12;000d;PBS_Server;Job;39400.tyrone-cluster;Not sending email: User does not want mail of this type.
06/03/2014 17:21:44;0040;PBS_Server;Svr;tyrone-cluster;Scheduler was sent the command new
06/03/2014 17:22:17;0040;PBS_Server;Svr;tyrone-cluster;Scheduler was sent the command new
06/03/2014 17:22:51;0040;PBS_Server;Svr;tyrone-cluster;Scheduler was sent the command new
06/03/2014 17:23:24;0040;PBS_Server;Svr;tyrone-cluster;Scheduler was sent the command new
06/03/2014 17:23:55;0040;PBS_Server;Svr;tyrone-cluster;Scheduler was sent the command new
06/03/2014 17:24:24;0040;PBS_Server;Svr;tyrone-cluster;Scheduler was sent the command new
06/03/2014 17:24:24;000d;PBS_Server;Job;39400.tyrone-cluster;Not sending email: User does not want mail of this type.
06/03/2014 17:24:24;0010;PBS_Server;Job;39400.tyrone-cluster;Exit_status=139 resources_used.cput=00:34:44 resources_used.mem=4668kb resources_used.vmem=57500kb resources_used.walltime=00:03:13
06/03/2014 17:24:24;0008;PBS_Server;Job;NULL;on_job_exit valid pjob: 0x177bea0 (substate=50)
06/03/2014 17:24:24;0008;PBS_Server;Job;NULL;on_job_exit valid pjob: 0x177bea0 (substate=51)
06/03/2014 17:24:24;0008;PBS_Server;Job;NULL;on_job_exit valid pjob: 0x177bea0 (substate=51)
06/03/2014 17:24:24;0008;PBS_Server;Job;NULL;on_job_exit valid pjob: 0x177bea0 (substate=53)
06/03/2014 17:24:24;0100;PBS_Server;Job;39400.tyrone-cluster;dequeuing from qp32, state COMPLETE
06/03/2014 17:24:54;0040;PBS_Server;Svr;tyrone-cluster;Scheduler was sent the command new
06/03/2014 17:25:25;0040;PBS_Server;Svr;tyrone-cluster;Scheduler was sent the command new
06/03/2014 17:25:56;0040;PBS_Server;Svr;tyrone-cluster;Scheduler was sent the command new
06/03/2014 17:25:57;0002;PBS_Server;Svr;PBS_Server;Torque Server Version = 3.0.5, loglevel = 0
06/03/2014 17:26:24;0040;PBS_Server;Svr;tyrone-cluster;Scheduler was sent the command new
06/03/2014 17:26:55;0040;PBS_Server;Svr;tyrone-cluster;Scheduler was sent the command new
06/03/2014 17:27:24;0040;PBS_Server;Svr;tyrone-cluster;Scheduler was sent the command new
06/03/2014 17:27:54;0040;PBS_Server;Svr;tyrone-cluster;Scheduler was sent the command new
06/03/2014 17:28:25;0040;PBS_Server;Svr;tyrone-cluster;Scheduler was sent the command new
06/03/2014 17:29:02;0040;PBS_Server;Svr;tyrone-cluster;Scheduler was sent the command new
06/03/2014 17:29:34;0040;PBS_Server;Svr;tyrone-cluster;Scheduler was sent the command new
06/03/2014 17:30:09;0040;PBS_Server;Svr;tyrone-cluster;Scheduler was sent the command new
06/03/2014 17:30:40;0040;PBS_Server;Svr;tyrone-cluster;Scheduler was sent the command new
06/03/2014 17:30:57;0002;PBS_Server;Svr;PBS_Server;Torque Server Version = 3.0.5, loglevel = 0
06/03/2014 17:31:09;0040;PBS_Server;Svr;tyrone-cluster;Scheduler was sent the command new
06/03/2014 17:31:39;0040;PBS_Server;Svr;tyrone-cluster;Scheduler was sent the command new
06/03/2014 17:32:10;0040;PBS_Server;Svr;tyrone-cluster;Scheduler was sent the command new
06/03/2014 17:32:47;0040;PBS_Server;Svr;tyrone-cluster;Scheduler was sent the command new
06/03/2014 17:33:21;0040;PBS_Server;Svr;tyrone-cluster;Scheduler was sent the command new
06/03/2014 17:33:54;0040;PBS_Server;Svr;tyrone-cluster;Scheduler was sent the command new
06/03/2014 17:34:25;0040;PBS_Server;Svr;tyrone-cluster;Scheduler was sent the command new
06/03/2014 17:35:02;0040;PBS_Server;Svr;tyrone-cluster;Scheduler was sent the command new
06/03/2014 17:35:36;0040;PBS_Server;Svr;tyrone-cluster;Scheduler was sent the command new
06/03/2014 17:35:57;0002;PBS_Server;Svr;PBS_Server;Torque Server Version = 3.0.5, loglevel = 0
06/03/2014 17:36:04;0100;PBS_Server;Job;39401.tyrone-cluster;enqueuing into batch, state 1 hop 1
06/03/2014 17:36:04;0100;PBS_Server;Job;39401.tyrone-cluster;dequeuing from batch, state QUEUED
06/03/2014 17:36:04;0100;PBS_Server;Job;39401.tyrone-cluster;enqueuing into qp32, state 1 hop 1
06/03/2014 17:36:04;0008;PBS_Server;Job;39401.tyrone-cluster;Job Queued at request of secbadar@tyrone-cluster, owner = secbadar@tyrone-cluster, job name = job32Guns, queue = qp32
06/03/2014 17:36:04;0040;PBS_Server;Svr;tyrone-cluster;Scheduler was sent the command new
06/03/2014 17:36:04;0008;PBS_Server;Job;39401.tyrone-cluster;Job Modified at request of Scheduler@tyrone-cluster
06/03/2014 17:36:04;0008;PBS_Server;Job;39401.tyrone-cluster;Job Run at request of Scheduler@tyrone-cluster
06/03/2014 17:36:04;0040;PBS_Server;Svr;tyrone-cluster;Scheduler was sent the command recyc
06/03/2014 17:36:04;000d;PBS_Server;Job;39401.tyrone-cluster;Not sending email: User does not want mail of this type.
06/03/2014 17:36:06;0040;PBS_Server;Svr;tyrone-cluster;Scheduler was sent the command new
06/03/2014 17:36:37;0040;PBS_Server;Svr;tyrone-cluster;Scheduler was sent the command new
06/03/2014 17:37:06;0040;PBS_Server;Svr;tyrone-cluster;Scheduler was sent the command new
06/03/2014 17:37:39;0040;PBS_Server;Svr;tyrone-cluster;Scheduler was sent the command new
06/03/2014 17:38:09;0040;PBS_Server;Svr;tyrone-cluster;Scheduler was sent the command new
06/03/2014 17:38:47;0040;PBS_Server;Svr;tyrone-cluster;Scheduler was sent the command new
06/03/2014 17:39:01;0100;PBS_Server;Job;39402.tyrone-cluster;enqueuing into batch, state 1 hop 1
06/03/2014 17:39:01;0008;PBS_Server;Job;39402.tyrone-cluster;Job Queued at request of secbadar@tyrone-cluster, owner = secbadar@tyrone-cluster, job name = jobpMpiGuns, queue = batch
06/03/2014 17:39:01;0040;PBS_Server;Svr;tyrone-cluster;Scheduler was sent the command new
06/03/2014 17:39:01;0008;PBS_Server;Job;39402.tyrone-cluster;Job Modified at request of Scheduler@tyrone-cluster
06/03/2014 17:39:21;0040;PBS_Server;Svr;tyrone-cluster;Scheduler was sent the command new
06/03/2014 17:39:33;0040;PBS_Server;Svr;tyrone-cluster;Scheduler was sent the command new
06/03/2014 17:39:54;0040;PBS_Server;Svr;tyrone-cluster;Scheduler was sent the command new
06/03/2014 17:40:06;0040;PBS_Server;Svr;tyrone-cluster;Scheduler was sent the command new
06/03/2014 17:40:24;0040;PBS_Server;Svr;tyrone-cluster;Scheduler was sent the command new
06/03/2014 17:40:39;0040;PBS_Server;Svr;tyrone-cluster;Scheduler was sent the command new
06/03/2014 17:40:57;0002;PBS_Server;Svr;PBS_Server;Torque Server Version = 3.0.5, loglevel = 0
06/03/2014 17:40:57;0040;PBS_Server;Svr;tyrone-cluster;Scheduler was sent the command new
06/03/2014 17:41:09;0040;PBS_Server;Svr;tyrone-cluster;Scheduler was sent the command new
06/03/2014 17:41:36;0040;PBS_Server;Svr;tyrone-cluster;Scheduler was sent the command new
06/03/2014 17:41:39;0040;PBS_Server;Svr;tyrone-cluster;Scheduler was sent the command new
06/03/2014 17:41:42;000d;PBS_Server;Job;39401.tyrone-cluster;Not sending email: User does not want mail of this type.
06/03/2014 17:41:42;0010;PBS_Server;Job;39401.tyrone-cluster;Exit_status=0 resources_used.cput=00:42:57 resources_used.mem=4752kb resources_used.vmem=57500kb resources_used.walltime=00:05:38
06/03/2014 17:41:42;0008;PBS_Server;Job;NULL;on_job_exit valid pjob: 0x177bea0 (substate=50)
06/03/2014 17:41:42;0008;PBS_Server;Job;NULL;on_job_exit valid pjob: 0x177bea0 (substate=51)
06/03/2014 17:41:42;0008;PBS_Server;Job;NULL;on_job_exit valid pjob: 0x177bea0 (substate=51)
06/03/2014 17:41:42;0008;PBS_Server;Job;NULL;on_job_exit valid pjob: 0x177bea0 (substate=53)
06/03/2014 17:41:42;0100;PBS_Server;Job;39401.tyrone-cluster;dequeuing from qp32, state COMPLETE
06/03/2014 17:41:42;0040;PBS_Server;Svr;tyrone-cluster;Scheduler was sent the command term
06/03/2014 17:42:09;0100;PBS_Server;Job;39402.tyrone-cluster;dequeuing from batch, state QUEUED
06/03/2014 17:42:09;0100;PBS_Server;Job;39402.tyrone-cluster;enqueuing into qp32, state 1 hop 1
06/03/2014 17:42:09;0040;PBS_Server;Svr;tyrone-cluster;Scheduler was sent the command new
06/03/2014 17:42:09;0008;PBS_Server;Job;39402.tyrone-cluster;Job Modified at request of Scheduler@tyrone-cluster
06/03/2014 17:42:09;0008;PBS_Server;Job;39402.tyrone-cluster;Job Run at request of Scheduler@tyrone-cluster
06/03/2014 17:42:09;0040;PBS_Server;Svr;tyrone-cluster;Scheduler was sent the command recyc
06/03/2014 17:42:09;000d;PBS_Server;Job;39402.tyrone-cluster;Not sending email: User does not want mail of this type.
06/03/2014 17:42:40;0040;PBS_Server;Svr;tyrone-cluster;Scheduler was sent the command new
06/03/2014 17:43:13;0040;PBS_Server;Svr;tyrone-cluster;Scheduler was sent the command new
06/03/2014 17:43:39;0040;PBS_Server;Svr;tyrone-cluster;Scheduler was sent the command new
06/03/2014 17:44:10;0040;PBS_Server;Svr;tyrone-cluster;Scheduler was sent the command new
06/03/2014 17:44:47;0040;PBS_Server;Svr;tyrone-cluster;Scheduler was sent the command new
06/03/2014 17:45:21;0040;PBS_Server;Svr;tyrone-cluster;Scheduler was sent the command new
06/03/2014 17:45:54;0040;PBS_Server;Svr;tyrone-cluster;Scheduler was sent the command new
06/03/2014 17:45:57;0002;PBS_Server;Svr;PBS_Server;Torque Server Version = 3.0.5, loglevel = 0
06/03/2014 17:46:21;0040;PBS_Server;Svr;tyrone-cluster;Scheduler was sent the command new
06/03/2014 17:46:51;0040;PBS_Server;Svr;tyrone-cluster;Scheduler was sent the command new
06/03/2014 17:47:24;0040;PBS_Server;Svr;tyrone-cluster;Scheduler was sent the command new
06/03/2014 17:47:55;0040;PBS_Server;Svr;tyrone-cluster;Scheduler was sent the command new
06/03/2014 17:48:24;0040;PBS_Server;Svr;tyrone-cluster;Scheduler was sent the command new
06/03/2014 17:48:54;0040;PBS_Server;Svr;tyrone-cluster;Scheduler was sent the command new
06/03/2014 17:49:25;0040;PBS_Server;Svr;tyrone-cluster;Scheduler was sent the command new
06/03/2014 17:50:02;0040;PBS_Server;Svr;tyrone-cluster;Scheduler was sent the command new
06/03/2014 17:50:36;0040;PBS_Server;Svr;tyrone-cluster;Scheduler was sent the command new
06/03/2014 17:50:57;0002;PBS_Server;Svr;PBS_Server;Torque Server Version = 3.0.5, loglevel = 0
06/03/2014 17:51:09;0040;PBS_Server;Svr;tyrone-cluster;Scheduler was sent the command new
06/03/2014 17:51:40;0040;PBS_Server;Svr;tyrone-cluster;Scheduler was sent the command new
06/03/2014 17:52:17;0040;PBS_Server;Svr;tyrone-cluster;Scheduler was sent the command new
06/03/2014 17:52:51;0040;PBS_Server;Svr;tyrone-cluster;Scheduler was sent the command new
06/03/2014 17:53:24;0040;PBS_Server;Svr;tyrone-cluster;Scheduler was sent the command new
06/03/2014 17:53:42;000d;PBS_Server;Job;39402.tyrone-cluster;Not sending email: User does not want mail of this type.
06/03/2014 17:53:42;0010;PBS_Server;Job;39402.tyrone-cluster;Exit_status=0 resources_used.cput=00:55:25 resources_used.mem=669988kb resources_used.vmem=847596kb resources_used.walltime=00:11:33
06/03/2014 17:53:42;0008;PBS_Server;Job;NULL;on_job_exit valid pjob: 0x1713730 (substate=50)
06/03/2014 17:53:42;0008;PBS_Server;Job;NULL;on_job_exit valid pjob: 0x1713730 (substate=51)
06/03/2014 17:53:42;0008;PBS_Server;Job;NULL;on_job_exit valid pjob: 0x1713730 (substate=51)
06/03/2014 17:53:42;0008;PBS_Server;Job;NULL;on_job_exit valid pjob: 0x1713730 (substate=53)
06/03/2014 17:53:42;0100;PBS_Server;Job;39402.tyrone-cluster;dequeuing from qp32, state COMPLETE
06/03/2014 17:53:42;0040;PBS_Server;Svr;tyrone-cluster;Scheduler was sent the command term
06/03/2014 17:53:55;0040;PBS_Server;Svr;tyrone-cluster;Scheduler was sent the command new
06/03/2014 17:54:24;0040;PBS_Server;Svr;tyrone-cluster;Scheduler was sent the command new
06/03/2014 17:54:54;0040;PBS_Server;Svr;tyrone-cluster;Scheduler was sent the command new
06/03/2014 17:55:25;0040;PBS_Server;Svr;tyrone-cluster;Scheduler was sent the command new
06/03/2014 17:55:57;0002;PBS_Server;Svr;PBS_Server;Torque Server Version = 3.0.5, loglevel = 0
06/03/2014 17:55:57;0040;PBS_Server;Svr;tyrone-cluster;Scheduler was sent the command new
06/03/2014 17:56:36;0040;PBS_Server;Svr;tyrone-cluster;Scheduler was sent the command new
06/03/2014 17:57:09;0040;PBS_Server;Svr;tyrone-cluster;Scheduler was sent the command new
06/03/2014 17:57:39;0040;PBS_Server;Svr;tyrone-cluster;Scheduler was sent the command new
06/03/2014 17:58:17;0040;PBS_Server;Svr;tyrone-cluster;Scheduler was sent the command new
06/03/2014 17:58:51;0040;PBS_Server;Svr;tyrone-cluster;Scheduler was sent the command new
06/03/2014 17:59:25;0040;PBS_Server;Svr;tyrone-cluster;Scheduler was sent the command new
06/03/2014 17:59:55;0040;PBS_Server;Svr;tyrone-cluster;Scheduler was sent the command new
06/03/2014 18:00:24;0040;PBS_Server;Svr;tyrone-cluster;Scheduler was sent the command new
06/03/2014 18:00:55;0040;PBS_Server;Svr;tyrone-cluster;Scheduler was sent the command new
06/03/2014 18:00:57;0002;PBS_Server;Svr;PBS_Server;Torque Server Version = 3.0.5, loglevel = 0
06/03/2014 18:01:25;0040;PBS_Server;Svr;tyrone-cluster;Scheduler was sent the command new
06/03/2014 18:02:03;0040;PBS_Server;Svr;tyrone-cluster;Scheduler was sent the command new
06/03/2014 18:02:36;0040;PBS_Server;Svr;tyrone-cluster;Scheduler was sent the command new
06/03/2014 18:03:10;0040;PBS_Server;Svr;tyrone-cluster;Scheduler was sent the command new
06/03/2014 18:03:39;0040;PBS_Server;Svr;tyrone-cluster;Scheduler was sent the command new
06/03/2014 18:04:18;0040;PBS_Server;Svr;tyrone-cluster;Scheduler was sent the command new
06/03/2014 18:04:52;0040;PBS_Server;Svr;tyrone-cluster;Scheduler was sent the command new
06/03/2014 18:05:25;0040;PBS_Server;Svr;tyrone-cluster;Scheduler was sent the command new
06/03/2014 18:05:55;0040;PBS_Server;Svr;tyrone-cluster;Scheduler was sent the command new
06/03/2014 18:05:57;0002;PBS_Server;Svr;PBS_Server;Torque Server Version = 3.0.5, loglevel = 0
06/03/2014 18:06:24;0040;PBS_Server;Svr;tyrone-cluster;Scheduler was sent the command new
06/03/2014 18:06:55;0040;PBS_Server;Svr;tyrone-cluster;Scheduler was sent the command new
06/03/2014 18:07:25;0040;PBS_Server;Svr;tyrone-cluster;Scheduler was sent the command new
06/03/2014 18:08:03;0040;PBS_Server;Svr;tyrone-cluster;Scheduler was sent the command new
06/03/2014 18:08:36;0040;PBS_Server;Svr;tyrone-cluster;Scheduler was sent the command new
06/03/2014 18:09:10;0040;PBS_Server;Svr;tyrone-cluster;Scheduler was sent the command new
06/03/2014 18:09:39;0040;PBS_Server;Svr;tyrone-cluster;Scheduler was sent the command new
06/03/2014 18:10:18;0040;PBS_Server;Svr;tyrone-cluster;Scheduler was sent the command new
06/03/2014 18:10:51;0040;PBS_Server;Svr;tyrone-cluster;Scheduler was sent the command new
06/03/2014 18:10:57;0002;PBS_Server;Svr;PBS_Server;Torque Server Version = 3.0.5, loglevel = 0
06/03/2014 18:11:25;0040;PBS_Server;Svr;tyrone-cluster;Scheduler was sent the command new
06/03/2014 18:11:55;0040;PBS_Server;Svr;tyrone-cluster;Scheduler was sent the command new
06/03/2014 18:12:24;0040;PBS_Server;Svr;tyrone-cluster;Scheduler was sent the command new
06/03/2014 18:12:55;0040;PBS_Server;Svr;tyrone-cluster;Scheduler was sent the command new
06/03/2014 18:13:25;0040;PBS_Server;Svr;tyrone-cluster;Scheduler was sent the command new
06/03/2014 18:14:03;0040;PBS_Server;Svr;tyrone-cluster;Scheduler was sent the command new
06/03/2014 18:14:36;0040;PBS_Server;Svr;tyrone-cluster;Scheduler was sent the command new
06/03/2014 18:15:10;0040;PBS_Server;Svr;tyrone-cluster;Scheduler was sent the command new
06/03/2014 18:15:39;0040;PBS_Server;Svr;tyrone-cluster;Scheduler was sent the command new
06/03/2014 18:15:57;0002;PBS_Server;Svr;PBS_Server;Torque Server Version = 3.0.5, loglevel = 0
06/03/2014 18:16:18;0040;PBS_Server;Svr;tyrone-cluster;Scheduler was sent the command new
06/03/2014 18:16:52;0040;PBS_Server;Svr;tyrone-cluster;Scheduler was sent the command new
06/03/2014 18:17:25;0040;PBS_Server;Svr;tyrone-cluster;Scheduler was sent the command new
06/03/2014 18:17:55;0040;PBS_Server;Svr;tyrone-cluster;Scheduler was sent the command new
06/03/2014 18:18:24;0040;PBS_Server;Svr;tyrone-cluster;Scheduler was sent the command new
06/03/2014 18:18:55;0040;PBS_Server;Svr;tyrone-cluster;Scheduler was sent the command new
06/03/2014 18:19:25;0040;PBS_Server;Svr;tyrone-cluster;Scheduler was sent the command new
06/03/2014 18:20:03;0040;PBS_Server;Svr;tyrone-cluster;Scheduler was sent the command new
06/03/2014 18:20:36;0040;PBS_Server;Svr;tyrone-cluster;Scheduler was sent the command new
06/03/2014 18:20:57;0002;PBS_Server;Svr;PBS_Server;Torque Server Version = 3.0.5, loglevel = 0
06/03/2014 18:21:10;0040;PBS_Server;Svr;tyrone-cluster;Scheduler was sent the command new
06/03/2014 18:21:39;0040;PBS_Server;Svr;tyrone-cluster;Scheduler was sent the command new
06/03/2014 18:22:18;0040;PBS_Server;Svr;tyrone-cluster;Scheduler was sent the command new
06/03/2014 18:22:52;0040;PBS_Server;Svr;tyrone-cluster;Scheduler was sent the command new
06/03/2014 18:23:25;0040;PBS_Server;Svr;tyrone-cluster;Scheduler was sent the command new
06/03/2014 18:23:55;0040;PBS_Server;Svr;tyrone-cluster;Scheduler was sent the command new
06/03/2014 18:24:24;0040;PBS_Server;Svr;tyrone-cluster;Scheduler was sent the command new
06/03/2014 18:24:55;0040;PBS_Server;Svr;tyrone-cluster;Scheduler was sent the command new
06/03/2014 18:25:25;0040;PBS_Server;Svr;tyrone-cluster;Scheduler was sent the command new
06/03/2014 18:25:57;0002;PBS_Server;Svr;PBS_Server;Torque Server Version = 3.0.5, loglevel = 0
06/03/2014 18:25:57;0040;PBS_Server;Svr;tyrone-cluster;Scheduler was sent the command new
06/03/2014 18:26:26;0040;PBS_Server;Svr;tyrone-cluster;Scheduler was sent the command new
06/03/2014 18:26:59;0040;PBS_Server;Svr;tyrone-cluster;Scheduler was sent the command new
06/03/2014 18:27:33;0040;PBS_Server;Svr;tyrone-cluster;Scheduler was sent the command new
06/03/2014 18:28:06;0040;PBS_Server;Svr;tyrone-cluster;Scheduler was sent the command new
06/03/2014 18:28:40;0040;PBS_Server;Svr;tyrone-cluster;Scheduler was sent the command new
06/03/2014 18:29:10;0040;PBS_Server;Svr;tyrone-cluster;Scheduler was sent the command new
06/03/2014 18:29:48;0040;PBS_Server;Svr;tyrone-cluster;Scheduler was sent the command new
06/03/2014 18:30:21;0040;PBS_Server;Svr;tyrone-cluster;Scheduler was sent the command new
06/03/2014 18:30:54;0040;PBS_Server;Svr;tyrone-cluster;Scheduler was sent the command new
06/03/2014 18:30:57;0002;PBS_Server;Svr;PBS_Server;Torque Server Version = 3.0.5, loglevel = 0
06/03/2014 18:31:21;0040;PBS_Server;Svr;tyrone-cluster;Scheduler was sent the command new
06/03/2014 18:31:51;0040;PBS_Server;Svr;tyrone-cluster;Scheduler was sent the command new
06/03/2014 18:32:25;0040;PBS_Server;Svr;tyrone-cluster;Scheduler was sent the command new
06/03/2014 18:32:55;0040;PBS_Server;Svr;tyrone-cluster;Scheduler was sent the command new
06/03/2014 18:33:28;0040;PBS_Server;Svr;tyrone-cluster;Scheduler was sent the command new
06/03/2014 18:33:56;0040;PBS_Server;Svr;tyrone-cluster;Scheduler was sent the command new
06/03/2014 18:34:29;0040;PBS_Server;Svr;tyrone-cluster;Scheduler was sent the command new
06/03/2014 18:35:03;0040;PBS_Server;Svr;tyrone-cluster;Scheduler was sent the command new
06/03/2014 18:35:36;0040;PBS_Server;Svr;tyrone-cluster;Scheduler was sent the command new
06/03/2014 18:35:57;0002;PBS_Server;Svr;PBS_Server;Torque Server Version = 3.0.5, loglevel = 0
06/03/2014 18:36:10;0040;PBS_Server;Svr;tyrone-cluster;Scheduler was sent the command new
06/03/2014 18:36:39;0040;PBS_Server;Svr;tyrone-cluster;Scheduler was sent the command new
06/03/2014 18:37:18;0040;PBS_Server;Svr;tyrone-cluster;Scheduler was sent the command new
06/03/2014 18:37:52;0040;PBS_Server;Svr;tyrone-cluster;Scheduler was sent the command new
06/03/2014 18:38:25;0040;PBS_Server;Svr;tyrone-cluster;Scheduler was sent the command new
06/03/2014 18:38:55;0040;PBS_Server;Svr;tyrone-cluster;Scheduler was sent the command new
06/03/2014 18:39:33;0040;PBS_Server;Svr;tyrone-cluster;Scheduler was sent the command new
06/03/2014 18:40:06;0040;PBS_Server;Svr;tyrone-cluster;Scheduler was sent the command new
06/03/2014 18:40:40;0040;PBS_Server;Svr;tyrone-cluster;Scheduler was sent the command new
06/03/2014 18:40:57;0002;PBS_Server;Svr;PBS_Server;Torque Server Version = 3.0.5, loglevel = 0
06/03/2014 18:41:09;0040;PBS_Server;Svr;tyrone-cluster;Scheduler was sent the command new
06/03/2014 18:41:48;0040;PBS_Server;Svr;tyrone-cluster;Scheduler was sent the command new
06/03/2014 18:42:21;0040;PBS_Server;Svr;tyrone-cluster;Scheduler was sent the command new
06/03/2014 18:42:55;0040;PBS_Server;Svr;tyrone-cluster;Scheduler was sent the command new
06/03/2014 18:43:25;0040;PBS_Server;Svr;tyrone-cluster;Scheduler was sent the command new
06/03/2014 18:44:03;0040;PBS_Server;Svr;tyrone-cluster;Scheduler was sent the command new
06/03/2014 18:44:30;0040;PBS_Server;Svr;tyrone-cluster;Scheduler was sent the command new
06/03/2014 18:45:02;0040;PBS_Server;Svr;tyrone-cluster;Scheduler was sent the command new
06/03/2014 18:45:34;0040;PBS_Server;Svr;tyrone-cluster;Scheduler was sent the command new
06/03/2014 18:45:57;0002;PBS_Server;Svr;PBS_Server;Torque Server Version = 3.0.5, loglevel = 0
06/03/2014 18:46:06;0040;PBS_Server;Svr;tyrone-cluster;Scheduler was sent the command new
06/03/2014 18:46:40;0040;PBS_Server;Svr;tyrone-cluster;Scheduler was sent the command new
06/03/2014 18:47:10;0040;PBS_Server;Svr;tyrone-cluster;Scheduler was sent the command new
06/03/2014 18:47:48;0040;PBS_Server;Svr;tyrone-cluster;Scheduler was sent the command new
06/03/2014 18:48:21;0040;PBS_Server;Svr;tyrone-cluster;Scheduler was sent the command new
06/03/2014 18:48:55;0040;PBS_Server;Svr;tyrone-cluster;Scheduler was sent the command new
06/03/2014 18:49:24;0040;PBS_Server;Svr;tyrone-cluster;Scheduler was sent the command new
06/03/2014 18:49:54;0040;PBS_Server;Svr;tyrone-cluster;Scheduler was sent the command new
06/03/2014 18:50:25;0040;PBS_Server;Svr;tyrone-cluster;Scheduler was sent the command new
06/03/2014 18:50:55;0040;PBS_Server;Svr;tyrone-cluster;Scheduler was sent the command new
06/03/2014 18:50:57;0002;PBS_Server;Svr;PBS_Server;Torque Server Version = 3.0.5, loglevel = 0
06/03/2014 18:51:33;0040;PBS_Server;Svr;tyrone-cluster;Scheduler was sent the command new
06/03/2014 18:52:06;0040;PBS_Server;Svr;tyrone-cluster;Scheduler was sent the command new
06/03/2014 18:52:40;0040;PBS_Server;Svr;tyrone-cluster;Scheduler was sent the command new
06/03/2014 18:53:09;0040;PBS_Server;Svr;tyrone-cluster;Scheduler was sent the command new
06/03/2014 18:53:48;0040;PBS_Server;Svr;tyrone-cluster;Scheduler was sent the command new
06/03/2014 18:54:21;0040;PBS_Server;Svr;tyrone-cluster;Scheduler was sent the command new
06/03/2014 18:54:55;0040;PBS_Server;Svr;tyrone-cluster;Scheduler was sent the command new
06/03/2014 18:55:25;0040;PBS_Server;Svr;tyrone-cluster;Scheduler was sent the command new
06/03/2014 18:55:57;0002;PBS_Server;Svr;PBS_Server;Torque Server Version = 3.0.5, loglevel = 0
06/03/2014 18:55:57;0040;PBS_Server;Svr;tyrone-cluster;Scheduler was sent the command new
06/03/2014 18:56:13;0100;PBS_Server;Job;39403.tyrone-cluster;enqueuing into batch, state 1 hop 1
06/03/2014 18:56:13;0100;PBS_Server;Job;39403.tyrone-cluster;dequeuing from batch, state QUEUED
06/03/2014 18:56:13;0100;PBS_Server;Job;39403.tyrone-cluster;enqueuing into qp32, state 1 hop 1
06/03/2014 18:56:13;0008;PBS_Server;Job;39403.tyrone-cluster;Job Queued at request of secbadar@tyrone-cluster, owner = secbadar@tyrone-cluster, job name = jobpMpiGuns, queue = qp32
06/03/2014 18:56:13;0040;PBS_Server;Svr;tyrone-cluster;Scheduler was sent the command new
06/03/2014 18:56:13;0008;PBS_Server;Job;39403.tyrone-cluster;Job Modified at request of Scheduler@tyrone-cluster
06/03/2014 18:56:13;0008;PBS_Server;Job;39403.tyrone-cluster;Job Run at request of Scheduler@tyrone-cluster
06/03/2014 18:56:13;0040;PBS_Server;Svr;tyrone-cluster;Scheduler was sent the command recyc
06/03/2014 18:56:13;000d;PBS_Server;Job;39403.tyrone-cluster;Not sending email: User does not want mail of this type.
06/03/2014 18:56:26;0040;PBS_Server;Svr;tyrone-cluster;Scheduler was sent the command new
06/03/2014 18:56:59;0040;PBS_Server;Svr;tyrone-cluster;Scheduler was sent the command new
06/03/2014 18:57:33;0040;PBS_Server;Svr;tyrone-cluster;Scheduler was sent the command new
06/03/2014 18:58:06;0040;PBS_Server;Svr;tyrone-cluster;Scheduler was sent the command new
06/03/2014 18:58:40;0040;PBS_Server;Svr;tyrone-cluster;Scheduler was sent the command new
06/03/2014 18:59:10;0040;PBS_Server;Svr;tyrone-cluster;Scheduler was sent the command new
06/03/2014 18:59:48;0040;PBS_Server;Svr;tyrone-cluster;Scheduler was sent the command new
06/03/2014 19:00:21;0040;PBS_Server;Svr;tyrone-cluster;Scheduler was sent the command new
06/03/2014 19:00:54;0040;PBS_Server;Svr;tyrone-cluster;Scheduler was sent the command new
06/03/2014 19:00:57;0002;PBS_Server;Svr;PBS_Server;Torque Server Version = 3.0.5, loglevel = 0
06/03/2014 19:01:21;0040;PBS_Server;Svr;tyrone-cluster;Scheduler was sent the command new
06/03/2014 19:01:52;0040;PBS_Server;Svr;tyrone-cluster;Scheduler was sent the command new
06/03/2014 19:02:25;0040;PBS_Server;Svr;tyrone-cluster;Scheduler was sent the command new
06/03/2014 19:02:55;0040;PBS_Server;Svr;tyrone-cluster;Scheduler was sent the command new
06/03/2014 19:03:28;0040;PBS_Server;Svr;tyrone-cluster;Scheduler was sent the command new
06/03/2014 19:03:56;0040;PBS_Server;Svr;tyrone-cluster;Scheduler was sent the command new
06/03/2014 19:04:29;0040;PBS_Server;Svr;tyrone-cluster;Scheduler was sent the command new
06/03/2014 19:05:03;0040;PBS_Server;Svr;tyrone-cluster;Scheduler was sent the command new
06/03/2014 19:05:36;0040;PBS_Server;Svr;tyrone-cluster;Scheduler was sent the command new
06/03/2014 19:05:57;0002;PBS_Server;Svr;PBS_Server;Torque Server Version = 3.0.5, loglevel = 0
06/03/2014 19:06:10;0040;PBS_Server;Svr;tyrone-cluster;Scheduler was sent the command new
06/03/2014 19:06:39;0040;PBS_Server;Svr;tyrone-cluster;Scheduler was sent the command new
06/03/2014 19:07:13;0040;PBS_Server;Svr;tyrone-cluster;Scheduler was sent the command new
06/03/2014 19:07:40;0040;PBS_Server;Svr;tyrone-cluster;Scheduler was sent the command new
06/03/2014 19:07:51;000d;PBS_Server;Job;39403.tyrone-cluster;Not sending email: User does not want mail of this type.
06/03/2014 19:07:51;0010;PBS_Server;Job;39403.tyrone-cluster;Exit_status=0 resources_used.cput=00:55:03 resources_used.mem=670512kb resources_used.vmem=847596kb resources_used.walltime=00:11:37
06/03/2014 19:07:51;0008;PBS_Server;Job;NULL;on_job_exit valid pjob: 0x177bea0 (substate=50)
06/03/2014 19:07:51;0008;PBS_Server;Job;NULL;on_job_exit valid pjob: 0x177bea0 (substate=51)
06/03/2014 19:07:51;0008;PBS_Server;Job;NULL;on_job_exit valid pjob: 0x177bea0 (substate=51)
06/03/2014 19:07:51;0008;PBS_Server;Job;NULL;on_job_exit valid pjob: 0x177bea0 (substate=53)
06/03/2014 19:07:51;0100;PBS_Server;Job;39403.tyrone-cluster;dequeuing from qp32, state COMPLETE
06/03/2014 19:07:51;0040;PBS_Server;Svr;tyrone-cluster;Scheduler was sent the command term
06/03/2014 19:08:10;0040;PBS_Server;Svr;tyrone-cluster;Scheduler was sent the command new
06/03/2014 19:08:48;0040;PBS_Server;Svr;tyrone-cluster;Scheduler was sent the command new
06/03/2014 19:09:21;0040;PBS_Server;Svr;tyrone-cluster;Scheduler was sent the command new
06/03/2014 19:09:55;0040;PBS_Server;Svr;tyrone-cluster;Scheduler was sent the command new
06/03/2014 19:10:24;0040;PBS_Server;Svr;tyrone-cluster;Scheduler was sent the command new
06/03/2014 19:10:57;0002;PBS_Server;Svr;PBS_Server;Torque Server Version = 3.0.5, loglevel = 0
06/03/2014 19:10:57;0040;PBS_Server;Svr;tyrone-cluster;Scheduler was sent the command new
06/03/2014 19:11:26;0040;PBS_Server;Svr;tyrone-cluster;Scheduler was sent the command new
06/03/2014 19:12:00;0040;PBS_Server;Svr;tyrone-cluster;Scheduler was sent the command new
06/03/2014 19:12:34;0040;PBS_Server;Svr;tyrone-cluster;Scheduler was sent the command new
06/03/2014 19:13:06;0040;PBS_Server;Svr;tyrone-cluster;Scheduler was sent the command new
06/03/2014 19:13:40;0040;PBS_Server;Svr;tyrone-cluster;Scheduler was sent the command new
06/03/2014 19:14:10;0040;PBS_Server;Svr;tyrone-cluster;Scheduler was sent the command new
06/03/2014 19:14:48;0040;PBS_Server;Svr;tyrone-cluster;Scheduler was sent the command new
06/03/2014 19:15:20;0040;PBS_Server;Svr;tyrone-cluster;Scheduler was sent the command new
06/03/2014 19:15:54;0040;PBS_Server;Svr;tyrone-cluster;Scheduler was sent the command new
06/03/2014 19:15:57;0002;PBS_Server;Svr;PBS_Server;Torque Server Version = 3.0.5, loglevel = 0
06/03/2014 19:16:22;0040;PBS_Server;Svr;tyrone-cluster;Scheduler was sent the command new
06/03/2014 19:16:51;0040;PBS_Server;Svr;tyrone-cluster;Scheduler was sent the command new
06/03/2014 19:17:25;0040;PBS_Server;Svr;tyrone-cluster;Scheduler was sent the command new
06/03/2014 19:17:55;0040;PBS_Server;Svr;tyrone-cluster;Scheduler was sent the command new
06/03/2014 19:18:27;0040;PBS_Server;Svr;tyrone-cluster;Scheduler was sent the command new
06/03/2014 19:18:56;0040;PBS_Server;Svr;tyrone-cluster;Scheduler was sent the command new
06/03/2014 19:19:30;0040;PBS_Server;Svr;tyrone-cluster;Scheduler was sent the command new
06/03/2014 19:20:03;0040;PBS_Server;Svr;tyrone-cluster;Scheduler was sent the command new
06/03/2014 19:20:35;0040;PBS_Server;Svr;tyrone-cluster;Scheduler was sent the command new
06/03/2014 19:20:57;0002;PBS_Server;Svr;PBS_Server;Torque Server Version = 3.0.5, loglevel = 0
06/03/2014 19:21:10;0040;PBS_Server;Svr;tyrone-cluster;Scheduler was sent the command new
06/03/2014 19:21:40;0040;PBS_Server;Svr;tyrone-cluster;Scheduler was sent the command new
06/03/2014 19:22:18;0040;PBS_Server;Svr;tyrone-cluster;Scheduler was sent the command new
06/03/2014 19:22:51;0040;PBS_Server;Svr;tyrone-cluster;Scheduler was sent the command new
06/03/2014 19:23:25;0040;PBS_Server;Svr;tyrone-cluster;Scheduler was sent the command new
06/03/2014 19:23:55;0040;PBS_Server;Svr;tyrone-cluster;Scheduler was sent the command new
06/03/2014 19:24:33;0040;PBS_Server;Svr;tyrone-cluster;Scheduler was sent the command new
06/03/2014 19:25:05;0040;PBS_Server;Svr;tyrone-cluster;Scheduler was sent the command new
06/03/2014 19:25:40;0040;PBS_Server;Svr;tyrone-cluster;Scheduler was sent the command new
06/03/2014 19:25:57;0002;PBS_Server;Svr;PBS_Server;Torque Server Version = 3.0.5, loglevel = 0
06/03/2014 19:26:10;0040;PBS_Server;Svr;tyrone-cluster;Scheduler was sent the command new
06/03/2014 19:26:48;0040;PBS_Server;Svr;tyrone-cluster;Scheduler was sent the command new
06/03/2014 19:27:21;0040;PBS_Server;Svr;tyrone-cluster;Scheduler was sent the command new
06/03/2014 19:27:55;0040;PBS_Server;Svr;tyrone-cluster;Scheduler was sent the command new
06/03/2014 19:28:25;0040;PBS_Server;Svr;tyrone-cluster;Scheduler was sent the command new
06/03/2014 19:29:03;0040;PBS_Server;Svr;tyrone-cluster;Scheduler was sent the command new
06/03/2014 19:29:35;0040;PBS_Server;Svr;tyrone-cluster;Scheduler was sent the command new
06/03/2014 19:30:10;0040;PBS_Server;Svr;tyrone-cluster;Scheduler was sent the command new
06/03/2014 19:30:39;0040;PBS_Server;Svr;tyrone-cluster;Scheduler was sent the command new
06/03/2014 19:30:57;0002;PBS_Server;Svr;PBS_Server;Torque Server Version = 3.0.5, loglevel = 0
06/03/2014 19:31:13;0040;PBS_Server;Svr;tyrone-cluster;Scheduler was sent the command new
06/03/2014 19:31:40;0040;PBS_Server;Svr;tyrone-cluster;Scheduler was sent the command new
06/03/2014 19:32:10;0040;PBS_Server;Svr;tyrone-cluster;Scheduler was sent the command new
06/03/2014 19:32:48;0040;PBS_Server;Svr;tyrone-cluster;Scheduler was sent the command new
06/03/2014 19:33:20;0040;PBS_Server;Svr;tyrone-cluster;Scheduler was sent the command new
06/03/2014 19:33:55;0040;PBS_Server;Svr;tyrone-cluster;Scheduler was sent the command new
06/03/2014 19:34:25;0040;PBS_Server;Svr;tyrone-cluster;Scheduler was sent the command new
06/03/2014 19:35:03;0040;PBS_Server;Svr;tyrone-cluster;Scheduler was sent the command new
06/03/2014 19:35:36;0040;PBS_Server;Svr;tyrone-cluster;Scheduler was sent the command new
06/03/2014 19:35:57;0002;PBS_Server;Svr;PBS_Server;Torque Server Version = 3.0.5, loglevel = 0
06/03/2014 19:36:10;0040;PBS_Server;Svr;tyrone-cluster;Scheduler was sent the command new
06/03/2014 19:36:40;0040;PBS_Server;Svr;tyrone-cluster;Scheduler was sent the command new
06/03/2014 19:37:18;0040;PBS_Server;Svr;tyrone-cluster;Scheduler was sent the command new
06/03/2014 19:37:50;0040;PBS_Server;Svr;tyrone-cluster;Scheduler was sent the command new
06/03/2014 19:38:25;0040;PBS_Server;Svr;tyrone-cluster;Scheduler was sent the command new
06/03/2014 19:38:55;0040;PBS_Server;Svr;tyrone-cluster;Scheduler was sent the command new
06/03/2014 19:39:33;0040;PBS_Server;Svr;tyrone-cluster;Scheduler was sent the command new
06/03/2014 19:40:06;0040;PBS_Server;Svr;tyrone-cluster;Scheduler was sent the command new
06/03/2014 19:40:40;0040;PBS_Server;Svr;tyrone-cluster;Scheduler was sent the command new
06/03/2014 19:40:57;0002;PBS_Server;Svr;PBS_Server;Torque Server Version = 3.0.5, loglevel = 0
06/03/2014 19:41:10;0040;PBS_Server;Svr;tyrone-cluster;Scheduler was sent the command new
06/03/2014 19:41:48;0040;PBS_Server;Svr;tyrone-cluster;Scheduler was sent the command new
06/03/2014 19:42:20;0040;PBS_Server;Svr;tyrone-cluster;Scheduler was sent the command new
06/03/2014 19:42:55;0040;PBS_Server;Svr;tyrone-cluster;Scheduler was sent the command new
06/03/2014 19:43:25;0040;PBS_Server;Svr;tyrone-cluster;Scheduler was sent the command new
06/03/2014 19:44:03;0040;PBS_Server;Svr;tyrone-cluster;Scheduler was sent the command new
06/03/2014 19:44:27;0040;PBS_Server;Svr;tyrone-cluster;Scheduler was sent the command new
06/03/2014 19:45:00;0040;PBS_Server;Svr;tyrone-cluster;Scheduler was sent the command new
06/03/2014 19:45:33;0040;PBS_Server;Svr;tyrone-cluster;Scheduler was sent the command new
06/03/2014 19:45:57;0002;PBS_Server;Svr;PBS_Server;Torque Server Version = 3.0.5, loglevel = 0
06/03/2014 19:46:06;0040;PBS_Server;Svr;tyrone-cluster;Scheduler was sent the command new
06/03/2014 19:46:30;0040;PBS_Server;Svr;tyrone-cluster;Scheduler was sent the command new
06/03/2014 19:47:03;0040;PBS_Server;Svr;tyrone-cluster;Scheduler was sent the command new
06/03/2014 19:47:35;0040;PBS_Server;Svr;tyrone-cluster;Scheduler was sent the command new
06/03/2014 19:48:10;0040;PBS_Server;Svr;tyrone-cluster;Scheduler was sent the command new
06/03/2014 19:48:40;0040;PBS_Server;Svr;tyrone-cluster;Scheduler was sent the command new
06/03/2014 19:49:18;0040;PBS_Server;Svr;tyrone-cluster;Scheduler was sent the command new
06/03/2014 19:49:50;0040;PBS_Server;Svr;tyrone-cluster;Scheduler was sent the command new
06/03/2014 19:50:25;0040;PBS_Server;Svr;tyrone-cluster;Scheduler was sent the command new
06/03/2014 19:50:55;0040;PBS_Server;Svr;tyrone-cluster;Scheduler was sent the command new
06/03/2014 19:50:57;0002;PBS_Server;Svr;PBS_Server;Torque Server Version = 3.0.5, loglevel = 0
06/03/2014 19:51:28;0040;PBS_Server;Svr;tyrone-cluster;Scheduler was sent the command new
06/03/2014 19:51:55;0040;PBS_Server;Svr;tyrone-cluster;Scheduler was sent the command new
06/03/2014 19:52:25;0040;PBS_Server;Svr;tyrone-cluster;Scheduler was sent the command new
06/03/2014 19:53:03;0040;PBS_Server;Svr;tyrone-cluster;Scheduler was sent the command new
06/03/2014 19:53:35;0040;PBS_Server;Svr;tyrone-cluster;Scheduler was sent the command new
06/03/2014 19:54:10;0040;PBS_Server;Svr;tyrone-cluster;Scheduler was sent the command new
06/03/2014 19:54:40;0040;PBS_Server;Svr;tyrone-cluster;Scheduler was sent the command new
06/03/2014 19:55:18;0040;PBS_Server;Svr;tyrone-cluster;Scheduler was sent the command new
06/03/2014 19:55:51;0040;PBS_Server;Svr;tyrone-cluster;Scheduler was sent the command new
06/03/2014 19:55:57;0002;PBS_Server;Svr;PBS_Server;Torque Server Version = 3.0.5, loglevel = 0
06/03/2014 19:56:25;0040;PBS_Server;Svr;tyrone-cluster;Scheduler was sent the command new
06/03/2014 19:56:55;0040;PBS_Server;Svr;tyrone-cluster;Scheduler was sent the command new
06/03/2014 19:57:33;0040;PBS_Server;Svr;tyrone-cluster;Scheduler was sent the command new
06/03/2014 19:58:05;0040;PBS_Server;Svr;tyrone-cluster;Scheduler was sent the command new
06/03/2014 19:58:40;0040;PBS_Server;Svr;tyrone-cluster;Scheduler was sent the command new
06/03/2014 19:59:10;0040;PBS_Server;Svr;tyrone-cluster;Scheduler was sent the command new
06/03/2014 19:59:42;0040;PBS_Server;Svr;tyrone-cluster;Scheduler was sent the command new
06/03/2014 20:00:10;0040;PBS_Server;Svr;tyrone-cluster;Scheduler was sent the command new
06/03/2014 20:00:40;0040;PBS_Server;Svr;tyrone-cluster;Scheduler was sent the command new
06/03/2014 20:00:57;0002;PBS_Server;Svr;PBS_Server;Torque Server Version = 3.0.5, loglevel = 0
06/03/2014 20:01:09;0040;PBS_Server;Svr;tyrone-cluster;Scheduler was sent the command new
06/03/2014 20:01:40;0040;PBS_Server;Svr;tyrone-cluster;Scheduler was sent the command new
06/03/2014 20:02:10;0040;PBS_Server;Svr;tyrone-cluster;Scheduler was sent the command new
06/03/2014 20:02:48;0040;PBS_Server;Svr;tyrone-cluster;Scheduler was sent the command new
06/03/2014 20:03:20;0040;PBS_Server;Svr;tyrone-cluster;Scheduler was sent the command new
06/03/2014 20:03:55;0040;PBS_Server;Svr;tyrone-cluster;Scheduler was sent the command new
06/03/2014 20:04:25;0040;PBS_Server;Svr;tyrone-cluster;Scheduler was sent the command new
06/03/2014 20:05:03;0040;PBS_Server;Svr;tyrone-cluster;Scheduler was sent the command new
06/03/2014 20:05:36;0040;PBS_Server;Svr;tyrone-cluster;Scheduler was sent the command new
06/03/2014 20:05:57;0002;PBS_Server;Svr;PBS_Server;Torque Server Version = 3.0.5, loglevel = 0
06/03/2014 20:06:10;0040;PBS_Server;Svr;tyrone-cluster;Scheduler was sent the command new
06/03/2014 20:06:40;0040;PBS_Server;Svr;tyrone-cluster;Scheduler was sent the command new
06/03/2014 20:07:18;0040;PBS_Server;Svr;tyrone-cluster;Scheduler was sent the command new
06/03/2014 20:07:50;0040;PBS_Server;Svr;tyrone-cluster;Scheduler was sent the command new
06/03/2014 20:08:25;0040;PBS_Server;Svr;tyrone-cluster;Scheduler was sent the command new
06/03/2014 20:08:55;0040;PBS_Server;Svr;tyrone-cluster;Scheduler was sent the command new
06/03/2014 20:09:33;0040;PBS_Server;Svr;tyrone-cluster;Scheduler was sent the command new
06/03/2014 20:09:57;0040;PBS_Server;Svr;tyrone-cluster;Scheduler was sent the command new
06/03/2014 20:10:30;0040;PBS_Server;Svr;tyrone-cluster;Scheduler was sent the command new
06/03/2014 20:10:57;0002;PBS_Server;Svr;PBS_Server;Torque Server Version = 3.0.5, loglevel = 0
06/03/2014 20:11:04;0040;PBS_Server;Svr;tyrone-cluster;Scheduler was sent the command new
06/03/2014 20:11:35;0040;PBS_Server;Svr;tyrone-cluster;Scheduler was sent the command new
06/03/2014 20:12:10;0040;PBS_Server;Svr;tyrone-cluster;Scheduler was sent the command new
06/03/2014 20:12:40;0040;PBS_Server;Svr;tyrone-cluster;Scheduler was sent the command new
06/03/2014 20:13:18;0040;PBS_Server;Svr;tyrone-cluster;Scheduler was sent the command new
06/03/2014 20:13:50;0040;PBS_Server;Svr;tyrone-cluster;Scheduler was sent the command new
06/03/2014 20:14:25;0040;PBS_Server;Svr;tyrone-cluster;Scheduler was sent the command new
06/03/2014 20:14:55;0040;PBS_Server;Svr;tyrone-cluster;Scheduler was sent the command new
06/03/2014 20:15:24;0040;PBS_Server;Svr;tyrone-cluster;Scheduler was sent the command new
06/03/2014 20:15:55;0040;PBS_Server;Svr;tyrone-cluster;Scheduler was sent the command new
06/03/2014 20:15:57;0002;PBS_Server;Svr;PBS_Server;Torque Server Version = 3.0.5, loglevel = 0
06/03/2014 20:16:25;0040;PBS_Server;Svr;tyrone-cluster;Scheduler was sent the command new
06/03/2014 20:16:54;0040;PBS_Server;Svr;tyrone-cluster;Scheduler was sent the command new
06/03/2014 20:17:25;0040;PBS_Server;Svr;tyrone-cluster;Scheduler was sent the command new
06/03/2014 20:17:55;0040;PBS_Server;Svr;tyrone-cluster;Scheduler was sent the command new
06/03/2014 20:18:27;0040;PBS_Server;Svr;tyrone-cluster;Scheduler was sent the command new
06/03/2014 20:18:56;0040;PBS_Server;Svr;tyrone-cluster;Scheduler was sent the command new
06/03/2014 20:19:30;0040;PBS_Server;Svr;tyrone-cluster;Scheduler was sent the command new
06/03/2014 20:20:03;0040;PBS_Server;Svr;tyrone-cluster;Scheduler was sent the command new
06/03/2014 20:20:36;0040;PBS_Server;Svr;tyrone-cluster;Scheduler was sent the command new
06/03/2014 20:20:57;0002;PBS_Server;Svr;PBS_Server;Torque Server Version = 3.0.5, loglevel = 0
06/03/2014 20:21:10;0040;PBS_Server;Svr;tyrone-cluster;Scheduler was sent the command new
06/03/2014 20:21:40;0040;PBS_Server;Svr;tyrone-cluster;Scheduler was sent the command new
06/03/2014 20:22:09;0040;PBS_Server;Svr;tyrone-cluster;Scheduler was sent the command new
06/03/2014 20:22:40;0040;PBS_Server;Svr;tyrone-cluster;Scheduler was sent the command new
06/03/2014 20:23:10;0040;PBS_Server;Svr;tyrone-cluster;Scheduler was sent the command new
06/03/2014 20:23:48;0040;PBS_Server;Svr;tyrone-cluster;Scheduler was sent the command new
06/03/2014 20:24:20;0040;PBS_Server;Svr;tyrone-cluster;Scheduler was sent the command new
06/03/2014 20:24:55;0040;PBS_Server;Svr;tyrone-cluster;Scheduler was sent the command new
06/03/2014 20:25:25;0040;PBS_Server;Svr;tyrone-cluster;Scheduler was sent the command new
06/03/2014 20:25:56;0040;PBS_Server;Svr;tyrone-cluster;Scheduler was sent the command new
06/03/2014 20:25:57;0002;PBS_Server;Svr;PBS_Server;Torque Server Version = 3.0.5, loglevel = 0
06/03/2014 20:26:25;0040;PBS_Server;Svr;tyrone-cluster;Scheduler was sent the command new
06/03/2014 20:26:55;0040;PBS_Server;Svr;tyrone-cluster;Scheduler was sent the command new
06/03/2014 20:27:24;0040;PBS_Server;Svr;tyrone-cluster;Scheduler was sent the command new
06/03/2014 20:27:55;0040;PBS_Server;Svr;tyrone-cluster;Scheduler was sent the command new
06/03/2014 20:28:25;0040;PBS_Server;Svr;tyrone-cluster;Scheduler was sent the command new
06/03/2014 20:28:54;0040;PBS_Server;Svr;tyrone-cluster;Scheduler was sent the command new
06/03/2014 20:29:25;0040;PBS_Server;Svr;tyrone-cluster;Scheduler was sent the command new
06/03/2014 20:29:55;0040;PBS_Server;Svr;tyrone-cluster;Scheduler was sent the command new
06/03/2014 20:30:33;0040;PBS_Server;Svr;tyrone-cluster;Scheduler was sent the command new
06/03/2014 20:30:57;0002;PBS_Server;Svr;PBS_Server;Torque Server Version = 3.0.5, loglevel = 0
06/03/2014 20:31:05;0040;PBS_Server;Svr;tyrone-cluster;Scheduler was sent the command new
06/03/2014 20:31:30;0040;PBS_Server;Svr;tyrone-cluster;Scheduler was sent the command new
06/03/2014 20:32:03;0040;PBS_Server;Svr;tyrone-cluster;Scheduler was sent the command new
06/03/2014 20:32:35;0040;PBS_Server;Svr;tyrone-cluster;Scheduler was sent the command new
06/03/2014 20:33:10;0040;PBS_Server;Svr;tyrone-cluster;Scheduler was sent the command new
06/03/2014 20:33:40;0040;PBS_Server;Svr;tyrone-cluster;Scheduler was sent the command new
06/03/2014 20:34:09;0040;PBS_Server;Svr;tyrone-cluster;Scheduler was sent the command new
06/03/2014 20:34:40;0040;PBS_Server;Svr;tyrone-cluster;Scheduler was sent the command new
06/03/2014 20:35:10;0040;PBS_Server;Svr;tyrone-cluster;Scheduler was sent the command new
06/03/2014 20:35:48;0040;PBS_Server;Svr;tyrone-cluster;Scheduler was sent the command new
06/03/2014 20:35:57;0002;PBS_Server;Svr;PBS_Server;Torque Server Version = 3.0.5, loglevel = 0
06/03/2014 20:36:21;0040;PBS_Server;Svr;tyrone-cluster;Scheduler was sent the command new
06/03/2014 20:36:55;0040;PBS_Server;Svr;tyrone-cluster;Scheduler was sent the command new
06/03/2014 20:37:25;0040;PBS_Server;Svr;tyrone-cluster;Scheduler was sent the command new
06/03/2014 20:37:54;0040;PBS_Server;Svr;tyrone-cluster;Scheduler was sent the command new
06/03/2014 20:38:25;0040;PBS_Server;Svr;tyrone-cluster;Scheduler was sent the command new
06/03/2014 20:38:55;0040;PBS_Server;Svr;tyrone-cluster;Scheduler was sent the command new
06/03/2014 20:39:24;0040;PBS_Server;Svr;tyrone-cluster;Scheduler was sent the command new
06/03/2014 20:39:55;0040;PBS_Server;Svr;tyrone-cluster;Scheduler was sent the command new
06/03/2014 20:40:25;0040;PBS_Server;Svr;tyrone-cluster;Scheduler was sent the command new
06/03/2014 20:40:57;0002;PBS_Server;Svr;PBS_Server;Torque Server Version = 3.0.5, loglevel = 0
06/03/2014 20:40:57;0040;PBS_Server;Svr;tyrone-cluster;Scheduler was sent the command new
06/03/2014 20:41:26;0040;PBS_Server;Svr;tyrone-cluster;Scheduler was sent the command new
06/03/2014 20:41:58;0040;PBS_Server;Svr;tyrone-cluster;Scheduler was sent the command new
06/03/2014 20:42:33;0040;PBS_Server;Svr;tyrone-cluster;Scheduler was sent the command new
06/03/2014 20:43:05;0040;PBS_Server;Svr;tyrone-cluster;Scheduler was sent the command new
06/03/2014 20:43:40;0040;PBS_Server;Svr;tyrone-cluster;Scheduler was sent the command new
06/03/2014 20:44:09;0040;PBS_Server;Svr;tyrone-cluster;Scheduler was sent the command new
06/03/2014 20:44:42;0040;PBS_Server;Svr;tyrone-cluster;Scheduler was sent the command new
06/03/2014 20:45:10;0040;PBS_Server;Svr;tyrone-cluster;Scheduler was sent the command new
06/03/2014 20:45:40;0040;PBS_Server;Svr;tyrone-cluster;Scheduler was sent the command new
06/03/2014 20:45:57;0002;PBS_Server;Svr;PBS_Server;Torque Server Version = 3.0.5, loglevel = 0
06/03/2014 20:46:09;0040;PBS_Server;Svr;tyrone-cluster;Scheduler was sent the command new
06/03/2014 20:46:40;0040;PBS_Server;Svr;tyrone-cluster;Scheduler was sent the command new
06/03/2014 20:47:10;0040;PBS_Server;Svr;tyrone-cluster;Scheduler was sent the command new
06/03/2014 20:47:39;0040;PBS_Server;Svr;tyrone-cluster;Scheduler was sent the command new
06/03/2014 20:48:10;0040;PBS_Server;Svr;tyrone-cluster;Scheduler was sent the command new
06/03/2014 20:48:40;0040;PBS_Server;Svr;tyrone-cluster;Scheduler was sent the command new
06/03/2014 20:49:09;0040;PBS_Server;Svr;tyrone-cluster;Scheduler was sent the command new
06/03/2014 20:49:40;0040;PBS_Server;Svr;tyrone-cluster;Scheduler was sent the command new
06/03/2014 20:50:10;0040;PBS_Server;Svr;tyrone-cluster;Scheduler was sent the command new
06/03/2014 20:50:48;0040;PBS_Server;Svr;tyrone-cluster;Scheduler was sent the command new
06/03/2014 20:50:57;0002;PBS_Server;Svr;PBS_Server;Torque Server Version = 3.0.5, loglevel = 0
06/03/2014 20:51:20;0040;PBS_Server;Svr;tyrone-cluster;Scheduler was sent the command new
06/03/2014 20:51:55;0040;PBS_Server;Svr;tyrone-cluster;Scheduler was sent the command new
06/03/2014 20:52:25;0040;PBS_Server;Svr;tyrone-cluster;Scheduler was sent the command new
06/03/2014 20:52:54;0040;PBS_Server;Svr;tyrone-cluster;Scheduler was sent the command new
06/03/2014 20:53:25;0040;PBS_Server;Svr;tyrone-cluster;Scheduler was sent the command new
06/03/2014 20:53:55;0040;PBS_Server;Svr;tyrone-cluster;Scheduler was sent the command new
06/03/2014 20:54:27;0040;PBS_Server;Svr;tyrone-cluster;Scheduler was sent the command new
06/03/2014 20:54:55;0040;PBS_Server;Svr;tyrone-cluster;Scheduler was sent the command new
06/03/2014 20:55:25;0040;PBS_Server;Svr;tyrone-cluster;Scheduler was sent the command new
06/03/2014 20:55:56;0040;PBS_Server;Svr;tyrone-cluster;Scheduler was sent the command new
06/03/2014 20:55:57;0002;PBS_Server;Svr;PBS_Server;Torque Server Version = 3.0.5, loglevel = 0
06/03/2014 20:56:25;0040;PBS_Server;Svr;tyrone-cluster;Scheduler was sent the command new
06/03/2014 20:56:55;0040;PBS_Server;Svr;tyrone-cluster;Scheduler was sent the command new
06/03/2014 20:57:24;0040;PBS_Server;Svr;tyrone-cluster;Scheduler was sent the command new
06/03/2014 20:57:55;0040;PBS_Server;Svr;tyrone-cluster;Scheduler was sent the command new
06/03/2014 20:58:25;0040;PBS_Server;Svr;tyrone-cluster;Scheduler was sent the command new
06/03/2014 20:58:54;0040;PBS_Server;Svr;tyrone-cluster;Scheduler was sent the command new
06/03/2014 20:59:25;0040;PBS_Server;Svr;tyrone-cluster;Scheduler was sent the command new
06/03/2014 20:59:54;0040;PBS_Server;Svr;tyrone-cluster;Scheduler was sent the command new
06/03/2014 21:00:33;0040;PBS_Server;Svr;tyrone-cluster;Scheduler was sent the command new
06/03/2014 21:00:57;0002;PBS_Server;Svr;PBS_Server;Torque Server Version = 3.0.5, loglevel = 0
06/03/2014 21:01:04;0040;PBS_Server;Svr;tyrone-cluster;Scheduler was sent the command new
06/03/2014 21:01:29;0040;PBS_Server;Svr;tyrone-cluster;Scheduler was sent the command new
06/03/2014 21:02:04;0040;PBS_Server;Svr;tyrone-cluster;Scheduler was sent the command new
06/03/2014 21:02:35;0040;PBS_Server;Svr;tyrone-cluster;Scheduler was sent the command new
06/03/2014 21:03:10;0040;PBS_Server;Svr;tyrone-cluster;Scheduler was sent the command new
06/03/2014 21:03:40;0040;PBS_Server;Svr;tyrone-cluster;Scheduler was sent the command new
06/03/2014 21:04:18;0040;PBS_Server;Svr;tyrone-cluster;Scheduler was sent the command new
06/03/2014 21:04:50;0040;PBS_Server;Svr;tyrone-cluster;Scheduler was sent the command new
06/03/2014 21:05:25;0040;PBS_Server;Svr;tyrone-cluster;Scheduler was sent the command new
06/03/2014 21:05:55;0040;PBS_Server;Svr;tyrone-cluster;Scheduler was sent the command new
06/03/2014 21:05:57;0002;PBS_Server;Svr;PBS_Server;Torque Server Version = 3.0.5, loglevel = 0
06/03/2014 21:06:33;0040;PBS_Server;Svr;tyrone-cluster;Scheduler was sent the command new
06/03/2014 21:06:50;0100;PBS_Server;Job;39404.tyrone-cluster;enqueuing into batch, state 1 hop 1
06/03/2014 21:06:50;0100;PBS_Server;Job;39404.tyrone-cluster;dequeuing from batch, state QUEUED
06/03/2014 21:06:50;0100;PBS_Server;Job;39404.tyrone-cluster;enqueuing into qp256, state 1 hop 1
06/03/2014 21:06:50;0008;PBS_Server;Job;39404.tyrone-cluster;Job Queued at request of secbadar@tyrone-cluster, owner = secbadar@tyrone-cluster, job name = jobpMpi6USG, queue = qp256
06/03/2014 21:06:50;0040;PBS_Server;Svr;tyrone-cluster;Scheduler was sent the command new
06/03/2014 21:06:50;0008;PBS_Server;Job;39404.tyrone-cluster;Job Modified at request of Scheduler@tyrone-cluster
06/03/2014 21:06:50;0008;PBS_Server;Job;39404.tyrone-cluster;Job Run at request of Scheduler@tyrone-cluster
06/03/2014 21:06:50;0040;PBS_Server;Svr;tyrone-cluster;Scheduler was sent the command recyc
06/03/2014 21:06:56;0040;PBS_Server;Svr;tyrone-cluster;Scheduler was sent the command new
06/03/2014 21:06:56;0008;PBS_Server;Job;39312.tyrone-cluster;Job Modified at request of Scheduler@tyrone-cluster
06/03/2014 21:07:27;0040;PBS_Server;Svr;tyrone-cluster;Scheduler was sent the command new
06/03/2014 21:07:31;000d;PBS_Server;Job;39404.tyrone-cluster;Not sending email: User does not want mail of this type.
06/03/2014 21:08:03;0040;PBS_Server;Svr;tyrone-cluster;Scheduler was sent the command new
06/03/2014 21:08:35;0040;PBS_Server;Svr;tyrone-cluster;Scheduler was sent the command new
06/03/2014 21:09:10;0040;PBS_Server;Svr;tyrone-cluster;Scheduler was sent the command new
06/03/2014 21:09:40;0040;PBS_Server;Svr;tyrone-cluster;Scheduler was sent the command new
06/03/2014 21:10:18;0040;PBS_Server;Svr;tyrone-cluster;Scheduler was sent the command new
06/03/2014 21:10:50;0040;PBS_Server;Svr;tyrone-cluster;Scheduler was sent the command new
06/03/2014 21:10:57;0002;PBS_Server;Svr;PBS_Server;Torque Server Version = 3.0.5, loglevel = 0
06/03/2014 21:11:25;0040;PBS_Server;Svr;tyrone-cluster;Scheduler was sent the command new
06/03/2014 21:11:55;0040;PBS_Server;Svr;tyrone-cluster;Scheduler was sent the command new
06/03/2014 21:12:33;0040;PBS_Server;Svr;tyrone-cluster;Scheduler was sent the command new
06/03/2014 21:13:05;0040;PBS_Server;Svr;tyrone-cluster;Scheduler was sent the command new
06/03/2014 21:13:40;0040;PBS_Server;Svr;tyrone-cluster;Scheduler was sent the command new
06/03/2014 21:14:11;0040;PBS_Server;Svr;tyrone-cluster;Scheduler was sent the command new
06/03/2014 21:14:48;0040;PBS_Server;Svr;tyrone-cluster;Scheduler was sent the command new
06/03/2014 21:15:11;0040;PBS_Server;Svr;tyrone-cluster;Scheduler was sent the command new
06/03/2014 21:15:43;0040;PBS_Server;Svr;tyrone-cluster;Scheduler was sent the command new
06/03/2014 21:15:57;0002;PBS_Server;Svr;PBS_Server;Torque Server Version = 3.0.5, loglevel = 0
06/03/2014 21:16:18;0040;PBS_Server;Svr;tyrone-cluster;Scheduler was sent the command new
06/03/2014 21:16:50;0040;PBS_Server;Svr;tyrone-cluster;Scheduler was sent the command new
06/03/2014 21:17:25;0040;PBS_Server;Svr;tyrone-cluster;Scheduler was sent the command new
06/03/2014 21:17:56;0040;PBS_Server;Svr;tyrone-cluster;Scheduler was sent the command new
06/03/2014 21:18:26;0040;PBS_Server;Svr;tyrone-cluster;Scheduler was sent the command new
06/03/2014 21:18:55;0040;PBS_Server;Svr;tyrone-cluster;Scheduler was sent the command new
06/03/2014 21:19:27;0040;PBS_Server;Svr;tyrone-cluster;Scheduler was sent the command new
06/03/2014 21:19:57;0040;PBS_Server;Svr;tyrone-cluster;Scheduler was sent the command new
06/03/2014 21:20:25;0040;PBS_Server;Svr;tyrone-cluster;Scheduler was sent the command new
06/03/2014 21:20:55;0040;PBS_Server;Svr;tyrone-cluster;Scheduler was sent the command new
06/03/2014 21:20:57;0002;PBS_Server;Svr;PBS_Server;Torque Server Version = 3.0.5, loglevel = 0
06/03/2014 21:21:27;0040;PBS_Server;Svr;tyrone-cluster;Scheduler was sent the command new
06/03/2014 21:21:55;0040;PBS_Server;Svr;tyrone-cluster;Scheduler was sent the command new
06/03/2014 21:22:26;0040;PBS_Server;Svr;tyrone-cluster;Scheduler was sent the command new
06/03/2014 21:23:03;0040;PBS_Server;Svr;tyrone-cluster;Scheduler was sent the command new
06/03/2014 21:23:26;0040;PBS_Server;Svr;tyrone-cluster;Scheduler was sent the command new
06/03/2014 21:23:58;0040;PBS_Server;Svr;tyrone-cluster;Scheduler was sent the command new
06/03/2014 21:24:33;0040;PBS_Server;Svr;tyrone-cluster;Scheduler was sent the command new
06/03/2014 21:25:05;0040;PBS_Server;Svr;tyrone-cluster;Scheduler was sent the command new
06/03/2014 21:25:40;0040;PBS_Server;Svr;tyrone-cluster;Scheduler was sent the command new
06/03/2014 21:25:57;0002;PBS_Server;Svr;PBS_Server;Torque Server Version = 3.0.5, loglevel = 0
06/03/2014 21:26:11;0040;PBS_Server;Svr;tyrone-cluster;Scheduler was sent the command new
06/03/2014 21:26:42;0040;PBS_Server;Svr;tyrone-cluster;Scheduler was sent the command new
06/03/2014 21:27:10;0040;PBS_Server;Svr;tyrone-cluster;Scheduler was sent the command new
06/03/2014 21:27:43;0040;PBS_Server;Svr;tyrone-cluster;Scheduler was sent the command new
06/03/2014 21:28:12;0040;PBS_Server;Svr;tyrone-cluster;Scheduler was sent the command new
06/03/2014 21:28:40;0040;PBS_Server;Svr;tyrone-cluster;Scheduler was sent the command new
06/03/2014 21:29:10;0040;PBS_Server;Svr;tyrone-cluster;Scheduler was sent the command new
06/03/2014 21:29:42;0040;PBS_Server;Svr;tyrone-cluster;Scheduler was sent the command new
06/03/2014 21:30:10;0040;PBS_Server;Svr;tyrone-cluster;Scheduler was sent the command new
06/03/2014 21:30:41;0040;PBS_Server;Svr;tyrone-cluster;Scheduler was sent the command new
06/03/2014 21:30:57;0002;PBS_Server;Svr;PBS_Server;Torque Server Version = 3.0.5, loglevel = 0
06/03/2014 21:31:18;0040;PBS_Server;Svr;tyrone-cluster;Scheduler was sent the command new
06/03/2014 21:31:41;0040;PBS_Server;Svr;tyrone-cluster;Scheduler was sent the command new
06/03/2014 21:32:13;0040;PBS_Server;Svr;tyrone-cluster;Scheduler was sent the command new
06/03/2014 21:32:31;0100;PBS_Server;Job;39405.tyrone-cluster;enqueuing into batch, state 1 hop 1
06/03/2014 21:32:31;0100;PBS_Server;Job;39405.tyrone-cluster;dequeuing from batch, state QUEUED
06/03/2014 21:32:31;0100;PBS_Server;Job;39405.tyrone-cluster;enqueuing into qp256, state 1 hop 1
06/03/2014 21:32:31;0008;PBS_Server;Job;39405.tyrone-cluster;Job Queued at request of secbadar@tyrone-cluster, owner = secbadar@tyrone-cluster, job name = job1286USG, queue = qp256
06/03/2014 21:32:31;0040;PBS_Server;Svr;tyrone-cluster;Scheduler was sent the command new
06/03/2014 21:32:31;0008;PBS_Server;Job;39405.tyrone-cluster;Job Modified at request of Scheduler@tyrone-cluster
06/03/2014 21:32:48;0040;PBS_Server;Svr;tyrone-cluster;Scheduler was sent the command new
06/03/2014 21:33:20;0040;PBS_Server;Svr;tyrone-cluster;Scheduler was sent the command new
06/03/2014 21:33:55;0040;PBS_Server;Svr;tyrone-cluster;Scheduler was sent the command new
06/03/2014 21:34:22;0040;PBS_Server;Svr;tyrone-cluster;Scheduler was sent the command new
06/03/2014 21:34:50;0040;PBS_Server;Svr;tyrone-cluster;Scheduler was sent the command new
06/03/2014 21:35:25;0040;PBS_Server;Svr;tyrone-cluster;Scheduler was sent the command new
06/03/2014 21:35:56;0040;PBS_Server;Svr;tyrone-cluster;Scheduler was sent the command new
06/03/2014 21:35:57;0002;PBS_Server;Svr;PBS_Server;Torque Server Version = 3.0.5, loglevel = 0
06/03/2014 21:36:26;0040;PBS_Server;Svr;tyrone-cluster;Scheduler was sent the command new
06/03/2014 21:36:55;0040;PBS_Server;Svr;tyrone-cluster;Scheduler was sent the command new
06/03/2014 21:37:28;0040;PBS_Server;Svr;tyrone-cluster;Scheduler was sent the command new
06/03/2014 21:38:03;0040;PBS_Server;Svr;tyrone-cluster;Scheduler was sent the command new
06/03/2014 21:38:35;0040;PBS_Server;Svr;tyrone-cluster;Scheduler was sent the command new
06/03/2014 21:39:10;0040;PBS_Server;Svr;tyrone-cluster;Scheduler was sent the command new
06/03/2014 21:39:40;0040;PBS_Server;Svr;tyrone-cluster;Scheduler was sent the command new
06/03/2014 21:40:12;0040;PBS_Server;Svr;tyrone-cluster;Scheduler was sent the command new
06/03/2014 21:40:40;0040;PBS_Server;Svr;tyrone-cluster;Scheduler was sent the command new
06/03/2014 21:40:57;0002;PBS_Server;Svr;PBS_Server;Torque Server Version = 3.0.5, loglevel = 0
06/03/2014 21:41:11;0040;PBS_Server;Svr;tyrone-cluster;Scheduler was sent the command new
06/03/2014 21:41:42;0040;PBS_Server;Svr;tyrone-cluster;Scheduler was sent the command new
06/03/2014 21:41:47;000d;PBS_Server;Job;39404.tyrone-cluster;Not sending email: User does not want mail of this type.
06/03/2014 21:41:47;0010;PBS_Server;Job;39404.tyrone-cluster;Exit_status=0 resources_used.cput=01:06:58 resources_used.mem=7593196kb resources_used.vmem=7967572kb resources_used.walltime=00:34:57
06/03/2014 21:41:47;0008;PBS_Server;Job;NULL;on_job_exit valid pjob: 0x177bea0 (substate=50)
06/03/2014 21:41:47;0008;PBS_Server;Job;NULL;on_job_exit valid pjob: 0x177bea0 (substate=51)
06/03/2014 21:41:47;0008;PBS_Server;Job;NULL;on_job_exit valid pjob: 0x177bea0 (substate=51)
06/03/2014 21:41:47;0008;PBS_Server;Job;NULL;on_job_exit valid pjob: 0x177bea0 (substate=53)
06/03/2014 21:41:47;0100;PBS_Server;Job;39404.tyrone-cluster;dequeuing from qp256, state COMPLETE
06/03/2014 21:41:47;0040;PBS_Server;Svr;tyrone-cluster;Scheduler was sent the command term
06/03/2014 21:41:47;0008;PBS_Server;Job;39312.tyrone-cluster;Job Modified at request of Scheduler@tyrone-cluster
06/03/2014 21:41:47;0008;PBS_Server;Job;39405.tyrone-cluster;Job Modified at request of Scheduler@tyrone-cluster
06/03/2014 21:41:47;0008;PBS_Server;Job;39405.tyrone-cluster;Job Run at request of Scheduler@tyrone-cluster
06/03/2014 21:41:47;0040;PBS_Server;Svr;tyrone-cluster;Scheduler was sent the command recyc
06/03/2014 21:42:03;000d;PBS_Server;Job;39405.tyrone-cluster;Not sending email: User does not want mail of this type.
06/03/2014 21:42:10;0040;PBS_Server;Svr;tyrone-cluster;Scheduler was sent the command new
06/03/2014 21:42:10;0008;PBS_Server;Job;39312.tyrone-cluster;Job Modified at request of Scheduler@tyrone-cluster
06/03/2014 21:42:41;0040;PBS_Server;Svr;tyrone-cluster;Scheduler was sent the command new
06/03/2014 21:43:12;0040;PBS_Server;Svr;tyrone-cluster;Scheduler was sent the command new
06/03/2014 21:43:40;0040;PBS_Server;Svr;tyrone-cluster;Scheduler was sent the command new
06/03/2014 21:44:11;0040;PBS_Server;Svr;tyrone-cluster;Scheduler was sent the command new
06/03/2014 21:44:48;0040;PBS_Server;Svr;tyrone-cluster;Scheduler was sent the command new
06/03/2014 21:45:20;0040;PBS_Server;Svr;tyrone-cluster;Scheduler was sent the command new
06/03/2014 21:45:51;0040;PBS_Server;Svr;tyrone-cluster;Scheduler was sent the command new
06/03/2014 21:45:57;0002;PBS_Server;Svr;PBS_Server;Torque Server Version = 3.0.5, loglevel = 0
06/03/2014 21:46:22;0040;PBS_Server;Svr;tyrone-cluster;Scheduler was sent the command new
06/03/2014 21:46:50;0040;PBS_Server;Svr;tyrone-cluster;Scheduler was sent the command new
06/03/2014 21:47:25;0040;PBS_Server;Svr;tyrone-cluster;Scheduler was sent the command new
06/03/2014 21:47:56;0040;PBS_Server;Svr;tyrone-cluster;Scheduler was sent the command new
06/03/2014 21:48:26;0040;PBS_Server;Svr;tyrone-cluster;Scheduler was sent the command new
06/03/2014 21:48:55;0040;PBS_Server;Svr;tyrone-cluster;Scheduler was sent the command new
06/03/2014 21:49:28;0040;PBS_Server;Svr;tyrone-cluster;Scheduler was sent the command new
06/03/2014 21:49:48;0100;PBS_Server;Job;39406.tyrone-cluster;enqueuing into batch, state 1 hop 1
06/03/2014 21:49:48;0100;PBS_Server;Job;39406.tyrone-cluster;dequeuing from batch, state QUEUED
06/03/2014 21:49:48;0100;PBS_Server;Job;39406.tyrone-cluster;enqueuing into qp256, state 1 hop 1
06/03/2014 21:49:48;0008;PBS_Server;Job;39406.tyrone-cluster;Job Queued at request of secbadar@tyrone-cluster, owner = secbadar@tyrone-cluster, job name = job646USG, queue = qp256
06/03/2014 21:49:48;0040;PBS_Server;Svr;tyrone-cluster;Scheduler was sent the command new
06/03/2014 21:49:48;0008;PBS_Server;Job;39406.tyrone-cluster;Job Modified at request of Scheduler@tyrone-cluster
06/03/2014 21:49:54;0100;PBS_Server;Job;39407.tyrone-cluster;enqueuing into batch, state 1 hop 1
06/03/2014 21:49:54;0008;PBS_Server;Job;39407.tyrone-cluster;Job Queued at request of secbadar@tyrone-cluster, owner = secbadar@tyrone-cluster, job name = jobpMpi6USG, queue = batch
06/03/2014 21:49:54;0040;PBS_Server;Svr;tyrone-cluster;Scheduler was sent the command new
06/03/2014 21:49:54;0008;PBS_Server;Job;39407.tyrone-cluster;Job Modified at request of Scheduler@tyrone-cluster
06/03/2014 21:49:56;0040;PBS_Server;Svr;tyrone-cluster;Scheduler was sent the command new
06/03/2014 21:50:25;0040;PBS_Server;Svr;tyrone-cluster;Scheduler was sent the command new
06/03/2014 21:50:26;0040;PBS_Server;Svr;tyrone-cluster;Scheduler was sent the command new
06/03/2014 21:50:55;0040;PBS_Server;Svr;tyrone-cluster;Scheduler was sent the command new
06/03/2014 21:50:57;0002;PBS_Server;Svr;PBS_Server;Torque Server Version = 3.0.5, loglevel = 0
06/03/2014 21:50:57;0040;PBS_Server;Svr;tyrone-cluster;Scheduler was sent the command new
06/03/2014 21:51:27;0040;PBS_Server;Svr;tyrone-cluster;Scheduler was sent the command new
06/03/2014 21:51:55;0040;PBS_Server;Svr;tyrone-cluster;Scheduler was sent the command new
06/03/2014 21:52:05;0040;PBS_Server;Svr;tyrone-cluster;Scheduler was sent the command new
06/03/2014 21:52:26;0040;PBS_Server;Svr;tyrone-cluster;Scheduler was sent the command new
06/03/2014 21:52:33;0040;PBS_Server;Svr;tyrone-cluster;Scheduler was sent the command new
06/03/2014 21:53:03;0040;PBS_Server;Svr;tyrone-cluster;Scheduler was sent the command new
06/03/2014 21:53:26;0040;PBS_Server;Svr;tyrone-cluster;Scheduler was sent the command new
06/03/2014 21:53:34;0040;PBS_Server;Svr;tyrone-cluster;Scheduler was sent the command new
06/03/2014 21:53:58;0040;PBS_Server;Svr;tyrone-cluster;Scheduler was sent the command new
06/03/2014 21:54:03;0040;PBS_Server;Svr;tyrone-cluster;Scheduler was sent the command new
06/03/2014 21:54:33;0040;PBS_Server;Svr;tyrone-cluster;Scheduler was sent the command new
06/03/2014 21:55:00;0040;PBS_Server;Svr;tyrone-cluster;Scheduler was sent the command new
06/03/2014 21:55:04;0040;PBS_Server;Svr;tyrone-cluster;Scheduler was sent the command new
06/03/2014 21:55:14;0008;PBS_Server;Job;39405.tyrone-cluster;Job deleted at request of secbadar@tyrone-cluster
06/03/2014 21:55:14;0008;PBS_Server;Job;39405.tyrone-cluster;Job sent signal SIGTERM on delete
06/03/2014 21:55:14;000d;PBS_Server;Job;39405.tyrone-cluster;Not sending email: User does not want mail of this type.
06/03/2014 21:55:14;0010;PBS_Server;Job;39405.tyrone-cluster;Exit_status=143 resources_used.cput=00:28:28 resources_used.mem=6232kb resources_used.vmem=266000kb resources_used.walltime=00:13:28
06/03/2014 21:55:14;0008;PBS_Server;Job;NULL;on_job_exit valid pjob: 0x1713730 (substate=50)
06/03/2014 21:55:14;0008;PBS_Server;Job;NULL;on_job_exit valid pjob: 0x1713730 (substate=51)
06/03/2014 21:55:14;0008;PBS_Server;Job;NULL;on_job_exit valid pjob: 0x1713730 (substate=51)
06/03/2014 21:55:14;0008;PBS_Server;Job;NULL;on_job_exit valid pjob: 0x1713730 (substate=53)
06/03/2014 21:55:14;0100;PBS_Server;Job;39405.tyrone-cluster;dequeuing from qp256, state COMPLETE
06/03/2014 21:55:14;0040;PBS_Server;Svr;tyrone-cluster;Scheduler was sent the command term
06/03/2014 21:55:15;0008;PBS_Server;Job;39312.tyrone-cluster;Job Modified at request of Scheduler@tyrone-cluster
06/03/2014 21:55:15;0008;PBS_Server;Job;39406.tyrone-cluster;Job Modified at request of Scheduler@tyrone-cluster
06/03/2014 21:55:15;0008;PBS_Server;Job;39406.tyrone-cluster;Job Run at request of Scheduler@tyrone-cluster
06/03/2014 21:55:15;0040;PBS_Server;Svr;tyrone-cluster;Scheduler was sent the command recyc
06/03/2014 21:55:31;0100;PBS_Server;Job;39407.tyrone-cluster;dequeuing from batch, state QUEUED
06/03/2014 21:55:31;0100;PBS_Server;Job;39407.tyrone-cluster;enqueuing into qp256, state 1 hop 1
06/03/2014 21:55:34;0040;PBS_Server;Svr;tyrone-cluster;Scheduler was sent the command new
06/03/2014 21:55:34;0008;PBS_Server;Job;39312.tyrone-cluster;Job Modified at request of Scheduler@tyrone-cluster
06/03/2014 21:55:34;0008;PBS_Server;Job;39407.tyrone-cluster;Job Modified at request of Scheduler@tyrone-cluster
06/03/2014 21:55:35;000d;PBS_Server;Job;39406.tyrone-cluster;Not sending email: User does not want mail of this type.
06/03/2014 21:55:57;0002;PBS_Server;Svr;PBS_Server;Torque Server Version = 3.0.5, loglevel = 0
06/03/2014 21:56:07;0040;PBS_Server;Svr;tyrone-cluster;Scheduler was sent the command new
06/03/2014 21:56:35;0040;PBS_Server;Svr;tyrone-cluster;Scheduler was sent the command new
06/03/2014 21:56:42;0100;PBS_Server;Job;39408.tyrone-cluster;enqueuing into batch, state 1 hop 1
06/03/2014 21:56:42;0008;PBS_Server;Job;39408.tyrone-cluster;Job Queued at request of secbadar@tyrone-cluster, owner = secbadar@tyrone-cluster, job name = job1286USG, queue = batch
06/03/2014 21:56:42;0040;PBS_Server;Svr;tyrone-cluster;Scheduler was sent the command new
06/03/2014 21:56:42;0008;PBS_Server;Job;39408.tyrone-cluster;Job Modified at request of Scheduler@tyrone-cluster
06/03/2014 21:57:05;0040;PBS_Server;Svr;tyrone-cluster;Scheduler was sent the command new
06/03/2014 21:57:19;0040;PBS_Server;Svr;tyrone-cluster;Scheduler was sent the command new
06/03/2014 21:57:39;0040;PBS_Server;Svr;tyrone-cluster;Scheduler was sent the command new
06/03/2014 21:57:50;0040;PBS_Server;Svr;tyrone-cluster;Scheduler was sent the command new
06/03/2014 21:58:07;0040;PBS_Server;Svr;tyrone-cluster;Scheduler was sent the command new
06/03/2014 21:58:22;0040;PBS_Server;Svr;tyrone-cluster;Scheduler was sent the command new
06/03/2014 21:58:40;0040;PBS_Server;Svr;tyrone-cluster;Scheduler was sent the command new
06/03/2014 21:58:51;0040;PBS_Server;Svr;tyrone-cluster;Scheduler was sent the command new
06/03/2014 21:59:11;0040;PBS_Server;Svr;tyrone-cluster;Scheduler was sent the command new
06/03/2014 21:59:20;0040;PBS_Server;Svr;tyrone-cluster;Scheduler was sent the command new
06/03/2014 21:59:42;0040;PBS_Server;Svr;tyrone-cluster;Scheduler was sent the command new
06/03/2014 21:59:53;0040;PBS_Server;Svr;tyrone-cluster;Scheduler was sent the command new
06/03/2014 22:00:10;0040;PBS_Server;Svr;tyrone-cluster;Scheduler was sent the command new
06/03/2014 22:00:22;0040;PBS_Server;Svr;tyrone-cluster;Scheduler was sent the command new
06/03/2014 22:00:41;0040;PBS_Server;Svr;tyrone-cluster;Scheduler was sent the command new
06/03/2014 22:00:55;0040;PBS_Server;Svr;tyrone-cluster;Scheduler was sent the command new
06/03/2014 22:00:57;0002;PBS_Server;Svr;PBS_Server;Torque Server Version = 3.0.5, loglevel = 0
06/03/2014 22:01:18;0040;PBS_Server;Svr;tyrone-cluster;Scheduler was sent the command new
06/03/2014 22:01:23;0040;PBS_Server;Svr;tyrone-cluster;Scheduler was sent the command new
06/03/2014 22:01:41;0040;PBS_Server;Svr;tyrone-cluster;Scheduler was sent the command new
06/03/2014 22:01:52;0040;PBS_Server;Svr;tyrone-cluster;Scheduler was sent the command new
06/03/2014 22:02:13;0040;PBS_Server;Svr;tyrone-cluster;Scheduler was sent the command new
06/03/2014 22:02:25;0040;PBS_Server;Svr;tyrone-cluster;Scheduler was sent the command new
06/03/2014 22:02:48;0040;PBS_Server;Svr;tyrone-cluster;Scheduler was sent the command new
06/03/2014 22:02:55;0040;PBS_Server;Svr;tyrone-cluster;Scheduler was sent the command new
06/03/2014 22:03:20;0040;PBS_Server;Svr;tyrone-cluster;Scheduler was sent the command new
06/03/2014 22:03:26;0040;PBS_Server;Svr;tyrone-cluster;Scheduler was sent the command new
06/03/2014 22:03:50;0040;PBS_Server;Svr;tyrone-cluster;Scheduler was sent the command new
06/03/2014 22:03:55;0040;PBS_Server;Svr;tyrone-cluster;Scheduler was sent the command new
06/03/2014 22:04:19;0040;PBS_Server;Svr;tyrone-cluster;Scheduler was sent the command new
06/03/2014 22:04:26;0040;PBS_Server;Svr;tyrone-cluster;Scheduler was sent the command new
06/03/2014 22:04:49;0040;PBS_Server;Svr;tyrone-cluster;Scheduler was sent the command new
06/03/2014 22:04:56;0040;PBS_Server;Svr;tyrone-cluster;Scheduler was sent the command new
06/03/2014 22:05:20;0040;PBS_Server;Svr;tyrone-cluster;Scheduler was sent the command new
06/03/2014 22:05:25;0040;PBS_Server;Svr;tyrone-cluster;Scheduler was sent the command new
06/03/2014 22:05:49;0040;PBS_Server;Svr;tyrone-cluster;Scheduler was sent the command new
06/03/2014 22:05:55;0040;PBS_Server;Svr;tyrone-cluster;Scheduler was sent the command new
06/03/2014 22:05:57;0002;PBS_Server;Svr;PBS_Server;Torque Server Version = 3.0.5, loglevel = 0
06/03/2014 22:06:20;0040;PBS_Server;Svr;tyrone-cluster;Scheduler was sent the command new
06/03/2014 22:06:27;0040;PBS_Server;Svr;tyrone-cluster;Scheduler was sent the command new
06/03/2014 22:06:50;0040;PBS_Server;Svr;tyrone-cluster;Scheduler was sent the command new
06/03/2014 22:06:55;0040;PBS_Server;Svr;tyrone-cluster;Scheduler was sent the command new
06/03/2014 22:07:22;0040;PBS_Server;Svr;tyrone-cluster;Scheduler was sent the command new
06/03/2014 22:07:26;0040;PBS_Server;Svr;tyrone-cluster;Scheduler was sent the command new
06/03/2014 22:07:51;0040;PBS_Server;Svr;tyrone-cluster;Scheduler was sent the command new
06/03/2014 22:07:57;0040;PBS_Server;Svr;tyrone-cluster;Scheduler was sent the command new
06/03/2014 22:08:20;0040;PBS_Server;Svr;tyrone-cluster;Scheduler was sent the command new
06/03/2014 22:08:25;0040;PBS_Server;Svr;tyrone-cluster;Scheduler was sent the command new
06/03/2014 22:08:53;0040;PBS_Server;Svr;tyrone-cluster;Scheduler was sent the command new
06/03/2014 22:08:57;0040;PBS_Server;Svr;tyrone-cluster;Scheduler was sent the command new
06/03/2014 22:09:22;0040;PBS_Server;Svr;tyrone-cluster;Scheduler was sent the command new
06/03/2014 22:09:33;0040;PBS_Server;Svr;tyrone-cluster;Scheduler was sent the command new
06/03/2014 22:09:55;0040;PBS_Server;Svr;tyrone-cluster;Scheduler was sent the command new
06/03/2014 22:10:05;0040;PBS_Server;Svr;tyrone-cluster;Scheduler was sent the command new
06/03/2014 22:10:14;000d;PBS_Server;Job;39406.tyrone-cluster;Not sending email: User does not want mail of this type.
06/03/2014 22:10:14;0010;PBS_Server;Job;39406.tyrone-cluster;Exit_status=0 resources_used.cput=00:33:09 resources_used.mem=13840008kb resources_used.vmem=17528188kb resources_used.walltime=00:15:00
06/03/2014 22:10:14;0008;PBS_Server;Job;NULL;on_job_exit valid pjob: 0x177bea0 (substate=50)
06/03/2014 22:10:14;0008;PBS_Server;Job;NULL;on_job_exit valid pjob: 0x177bea0 (substate=51)
06/03/2014 22:10:14;0008;PBS_Server;Job;NULL;on_job_exit valid pjob: 0x177bea0 (substate=51)
06/03/2014 22:10:14;0008;PBS_Server;Job;NULL;on_job_exit valid pjob: 0x177bea0 (substate=53)
06/03/2014 22:10:14;0100;PBS_Server;Job;39406.tyrone-cluster;dequeuing from qp256, state COMPLETE
06/03/2014 22:10:14;0040;PBS_Server;Svr;tyrone-cluster;Scheduler was sent the command term
06/03/2014 22:10:14;0008;PBS_Server;Job;39312.tyrone-cluster;Job Modified at request of Scheduler@tyrone-cluster
06/03/2014 22:10:14;0008;PBS_Server;Job;39407.tyrone-cluster;Job Modified at request of Scheduler@tyrone-cluster
06/03/2014 22:10:14;0008;PBS_Server;Job;39407.tyrone-cluster;Job Run at request of Scheduler@tyrone-cluster
06/03/2014 22:10:14;0040;PBS_Server;Svr;tyrone-cluster;Scheduler was sent the command recyc
06/03/2014 22:10:27;0040;PBS_Server;Svr;tyrone-cluster;Scheduler was sent the command new
06/03/2014 22:10:28;0008;PBS_Server;Job;39312.tyrone-cluster;Job Modified at request of Scheduler@tyrone-cluster
06/03/2014 22:10:37;0100;PBS_Server;Job;39408.tyrone-cluster;dequeuing from batch, state QUEUED
06/03/2014 22:10:37;0100;PBS_Server;Job;39408.tyrone-cluster;enqueuing into qp256, state 1 hop 1
06/03/2014 22:10:37;000d;PBS_Server;Job;39407.tyrone-cluster;Not sending email: User does not want mail of this type.
06/03/2014 22:10:37;0040;PBS_Server;Svr;tyrone-cluster;Scheduler was sent the command new
06/03/2014 22:10:37;0008;PBS_Server;Job;39408.tyrone-cluster;Job Modified at request of Scheduler@tyrone-cluster
06/03/2014 22:10:56;0040;PBS_Server;Svr;tyrone-cluster;Scheduler was sent the command new
06/03/2014 22:10:57;0002;PBS_Server;Svr;PBS_Server;Torque Server Version = 3.0.5, loglevel = 0
06/03/2014 22:11:26;0040;PBS_Server;Svr;tyrone-cluster;Scheduler was sent the command new
06/03/2014 22:11:58;0040;PBS_Server;Svr;tyrone-cluster;Scheduler was sent the command new
06/03/2014 22:12:33;0040;PBS_Server;Svr;tyrone-cluster;Scheduler was sent the command new
06/03/2014 22:13:05;0040;PBS_Server;Svr;tyrone-cluster;Scheduler was sent the command new
06/03/2014 22:13:37;0040;PBS_Server;Svr;tyrone-cluster;Scheduler was sent the command new
06/03/2014 22:14:07;0040;PBS_Server;Svr;tyrone-cluster;Scheduler was sent the command new
06/03/2014 22:14:36;0040;PBS_Server;Svr;tyrone-cluster;Scheduler was sent the command new
06/03/2014 22:15:07;0040;PBS_Server;Svr;tyrone-cluster;Scheduler was sent the command new
06/03/2014 22:15:39;0040;PBS_Server;Svr;tyrone-cluster;Scheduler was sent the command new
06/03/2014 22:15:57;0002;PBS_Server;Svr;PBS_Server;Torque Server Version = 3.0.5, loglevel = 0
06/03/2014 22:16:08;0040;PBS_Server;Svr;tyrone-cluster;Scheduler was sent the command new
06/03/2014 22:16:40;0040;PBS_Server;Svr;tyrone-cluster;Scheduler was sent the command new
06/03/2014 22:17:10;0040;PBS_Server;Svr;tyrone-cluster;Scheduler was sent the command new
06/03/2014 22:17:42;0040;PBS_Server;Svr;tyrone-cluster;Scheduler was sent the command new
06/03/2014 22:18:10;0040;PBS_Server;Svr;tyrone-cluster;Scheduler was sent the command new
06/03/2014 22:18:40;0040;PBS_Server;Svr;tyrone-cluster;Scheduler was sent the command new
06/03/2014 22:19:11;0040;PBS_Server;Svr;tyrone-cluster;Scheduler was sent the command new
06/03/2014 22:19:40;0040;PBS_Server;Svr;tyrone-cluster;Scheduler was sent the command new
06/03/2014 22:20:12;0040;PBS_Server;Svr;tyrone-cluster;Scheduler was sent the command new
06/03/2014 22:20:48;0040;PBS_Server;Svr;tyrone-cluster;Scheduler was sent the command new
06/03/2014 22:20:57;0002;PBS_Server;Svr;PBS_Server;Torque Server Version = 3.0.5, loglevel = 0
06/03/2014 22:21:20;0040;PBS_Server;Svr;tyrone-cluster;Scheduler was sent the command new
06/03/2014 22:21:52;0040;PBS_Server;Svr;tyrone-cluster;Scheduler was sent the command new
06/03/2014 22:22:22;0040;PBS_Server;Svr;tyrone-cluster;Scheduler was sent the command new
06/03/2014 22:22:51;0040;PBS_Server;Svr;tyrone-cluster;Scheduler was sent the command new
06/03/2014 22:23:22;0040;PBS_Server;Svr;tyrone-cluster;Scheduler was sent the command new
06/03/2014 22:23:53;0040;PBS_Server;Svr;tyrone-cluster;Scheduler was sent the command new
06/03/2014 22:24:22;0040;PBS_Server;Svr;tyrone-cluster;Scheduler was sent the command new
06/03/2014 22:24:52;0040;PBS_Server;Svr;tyrone-cluster;Scheduler was sent the command new
06/03/2014 22:25:24;0040;PBS_Server;Svr;tyrone-cluster;Scheduler was sent the command new
06/03/2014 22:25:53;0040;PBS_Server;Svr;tyrone-cluster;Scheduler was sent the command new
06/03/2014 22:25:57;0002;PBS_Server;Svr;PBS_Server;Torque Server Version = 3.0.5, loglevel = 0
06/03/2014 22:26:25;0040;PBS_Server;Svr;tyrone-cluster;Scheduler was sent the command new
06/03/2014 22:26:55;0040;PBS_Server;Svr;tyrone-cluster;Scheduler was sent the command new
06/03/2014 22:27:27;0040;PBS_Server;Svr;tyrone-cluster;Scheduler was sent the command new
06/03/2014 22:27:55;0040;PBS_Server;Svr;tyrone-cluster;Scheduler was sent the command new
06/03/2014 22:28:25;0040;PBS_Server;Svr;tyrone-cluster;Scheduler was sent the command new
06/03/2014 22:28:56;0040;PBS_Server;Svr;tyrone-cluster;Scheduler was sent the command new
06/03/2014 22:29:25;0040;PBS_Server;Svr;tyrone-cluster;Scheduler was sent the command new
06/03/2014 22:29:58;0040;PBS_Server;Svr;tyrone-cluster;Scheduler was sent the command new
06/03/2014 22:30:33;0040;PBS_Server;Svr;tyrone-cluster;Scheduler was sent the command new
06/03/2014 22:30:57;0002;PBS_Server;Svr;PBS_Server;Torque Server Version = 3.0.5, loglevel = 0
06/03/2014 22:31:03;0040;PBS_Server;Svr;tyrone-cluster;Scheduler was sent the command new
06/03/2014 22:31:27;0040;PBS_Server;Svr;tyrone-cluster;Scheduler was sent the command new
06/03/2014 22:32:04;0040;PBS_Server;Svr;tyrone-cluster;Scheduler was sent the command new
06/03/2014 22:32:34;0040;PBS_Server;Svr;tyrone-cluster;Scheduler was sent the command new
06/03/2014 22:33:07;0040;PBS_Server;Svr;tyrone-cluster;Scheduler was sent the command new
06/03/2014 22:33:34;0040;PBS_Server;Svr;tyrone-cluster;Scheduler was sent the command new
06/03/2014 22:34:05;0040;PBS_Server;Svr;tyrone-cluster;Scheduler was sent the command new
06/03/2014 22:34:37;0040;PBS_Server;Svr;tyrone-cluster;Scheduler was sent the command new
06/03/2014 22:35:07;0040;PBS_Server;Svr;tyrone-cluster;Scheduler was sent the command new
06/03/2014 22:35:36;0040;PBS_Server;Svr;tyrone-cluster;Scheduler was sent the command new
06/03/2014 22:35:57;0002;PBS_Server;Svr;PBS_Server;Torque Server Version = 3.0.5, loglevel = 0
06/03/2014 22:36:07;0040;PBS_Server;Svr;tyrone-cluster;Scheduler was sent the command new
06/03/2014 22:36:39;0040;PBS_Server;Svr;tyrone-cluster;Scheduler was sent the command new
06/03/2014 22:37:07;0040;PBS_Server;Svr;tyrone-cluster;Scheduler was sent the command new
06/03/2014 22:37:37;0040;PBS_Server;Svr;tyrone-cluster;Scheduler was sent the command new
06/03/2014 22:38:09;0040;PBS_Server;Svr;tyrone-cluster;Scheduler was sent the command new
06/03/2014 22:38:37;0040;PBS_Server;Svr;tyrone-cluster;Scheduler was sent the command new
06/03/2014 22:39:07;0040;PBS_Server;Svr;tyrone-cluster;Scheduler was sent the command new
06/03/2014 22:39:38;0040;PBS_Server;Svr;tyrone-cluster;Scheduler was sent the command new
06/03/2014 22:40:07;0040;PBS_Server;Svr;tyrone-cluster;Scheduler was sent the command new
06/03/2014 22:40:28;0100;PBS_Server;Job;39409.tyrone-cluster;enqueuing into batch, state 1 hop 1
06/03/2014 22:40:28;0100;PBS_Server;Job;39409.tyrone-cluster;dequeuing from batch, state QUEUED
06/03/2014 22:40:28;0100;PBS_Server;Job;39409.tyrone-cluster;enqueuing into idqueue, state 1 hop 1
06/03/2014 22:40:28;0008;PBS_Server;Job;39409.tyrone-cluster;Job Queued at request of secpka@tyrone-cluster, owner = secpka@tyrone-cluster, job name = jobname, queue = idqueue
06/03/2014 22:40:28;0040;PBS_Server;Svr;tyrone-cluster;Scheduler was sent the command new
06/03/2014 22:40:28;0008;PBS_Server;Job;39409.tyrone-cluster;Job Modified at request of Scheduler@tyrone-cluster
06/03/2014 22:40:28;0008;PBS_Server;Job;39409.tyrone-cluster;Job Run at request of Scheduler@tyrone-cluster
06/03/2014 22:40:28;0040;PBS_Server;Svr;tyrone-cluster;Scheduler was sent the command recyc
06/03/2014 22:40:28;000d;PBS_Server;Job;39409.tyrone-cluster;Not sending email: User does not want mail of this type.
06/03/2014 22:40:37;0040;PBS_Server;Svr;tyrone-cluster;Scheduler was sent the command new
06/03/2014 22:40:40;000d;PBS_Server;Job;39409.tyrone-cluster;Not sending email: User does not want mail of this type.
06/03/2014 22:40:40;0010;PBS_Server;Job;39409.tyrone-cluster;Exit_status=0 resources_used.cput=00:01:57 resources_used.mem=1748kb resources_used.vmem=119176kb resources_used.walltime=00:00:12
06/03/2014 22:40:40;0008;PBS_Server;Job;NULL;on_job_exit valid pjob: 0x177bea0 (substate=50)
06/03/2014 22:40:40;0008;PBS_Server;Job;NULL;on_job_exit valid pjob: 0x177bea0 (substate=51)
06/03/2014 22:40:41;0008;PBS_Server;Job;NULL;on_job_exit valid pjob: 0x177bea0 (substate=51)
06/03/2014 22:40:41;0008;PBS_Server;Job;NULL;on_job_exit valid pjob: 0x177bea0 (substate=53)
06/03/2014 22:40:41;0100;PBS_Server;Job;39409.tyrone-cluster;dequeuing from idqueue, state COMPLETE
06/03/2014 22:40:41;0040;PBS_Server;Svr;tyrone-cluster;Scheduler was sent the command term
06/03/2014 22:40:46;0100;PBS_Server;Job;39410.tyrone-cluster;enqueuing into batch, state 1 hop 1
06/03/2014 22:40:46;0100;PBS_Server;Job;39410.tyrone-cluster;dequeuing from batch, state QUEUED
06/03/2014 22:40:46;0100;PBS_Server;Job;39410.tyrone-cluster;enqueuing into idqueue, state 1 hop 1
06/03/2014 22:40:46;0008;PBS_Server;Job;39410.tyrone-cluster;Job Queued at request of secpka@tyrone-cluster, owner = secpka@tyrone-cluster, job name = jobname, queue = idqueue
06/03/2014 22:40:46;0040;PBS_Server;Svr;tyrone-cluster;Scheduler was sent the command new
06/03/2014 22:40:46;0008;PBS_Server;Job;39410.tyrone-cluster;Job Modified at request of Scheduler@tyrone-cluster
06/03/2014 22:40:46;0008;PBS_Server;Job;39410.tyrone-cluster;Job Run at request of Scheduler@tyrone-cluster
06/03/2014 22:40:46;0040;PBS_Server;Svr;tyrone-cluster;Scheduler was sent the command recyc
06/03/2014 22:40:46;000d;PBS_Server;Job;39410.tyrone-cluster;Not sending email: User does not want mail of this type.
06/03/2014 22:40:55;000d;PBS_Server;Job;39410.tyrone-cluster;Not sending email: User does not want mail of this type.
06/03/2014 22:40:55;0010;PBS_Server;Job;39410.tyrone-cluster;Exit_status=0 resources_used.cput=00:01:39 resources_used.mem=0kb resources_used.vmem=0kb resources_used.walltime=00:00:09
06/03/2014 22:40:55;0008;PBS_Server;Job;NULL;on_job_exit valid pjob: 0x177bea0 (substate=50)
06/03/2014 22:40:55;0008;PBS_Server;Job;NULL;on_job_exit valid pjob: 0x177bea0 (substate=51)
06/03/2014 22:40:56;0008;PBS_Server;Job;NULL;on_job_exit valid pjob: 0x177bea0 (substate=51)
06/03/2014 22:40:56;0008;PBS_Server;Job;NULL;on_job_exit valid pjob: 0x177bea0 (substate=53)
06/03/2014 22:40:56;0100;PBS_Server;Job;39410.tyrone-cluster;dequeuing from idqueue, state COMPLETE
06/03/2014 22:40:56;0040;PBS_Server;Svr;tyrone-cluster;Scheduler was sent the command term
06/03/2014 22:40:57;0002;PBS_Server;Svr;PBS_Server;Torque Server Version = 3.0.5, loglevel = 0
06/03/2014 22:41:00;0100;PBS_Server;Job;39411.tyrone-cluster;enqueuing into batch, state 1 hop 1
06/03/2014 22:41:00;0100;PBS_Server;Job;39411.tyrone-cluster;dequeuing from batch, state QUEUED
06/03/2014 22:41:00;0100;PBS_Server;Job;39411.tyrone-cluster;enqueuing into idqueue, state 1 hop 1
06/03/2014 22:41:00;0008;PBS_Server;Job;39411.tyrone-cluster;Job Queued at request of secpka@tyrone-cluster, owner = secpka@tyrone-cluster, job name = jobname, queue = idqueue
06/03/2014 22:41:00;0040;PBS_Server;Svr;tyrone-cluster;Scheduler was sent the command new
06/03/2014 22:41:00;0008;PBS_Server;Job;39411.tyrone-cluster;Job Modified at request of Scheduler@tyrone-cluster
06/03/2014 22:41:00;0008;PBS_Server;Job;39411.tyrone-cluster;Job Run at request of Scheduler@tyrone-cluster
06/03/2014 22:41:00;0040;PBS_Server;Svr;tyrone-cluster;Scheduler was sent the command recyc
06/03/2014 22:41:00;000d;PBS_Server;Job;39411.tyrone-cluster;Not sending email: User does not want mail of this type.
06/03/2014 22:41:09;0040;PBS_Server;Svr;tyrone-cluster;Scheduler was sent the command new
06/03/2014 22:41:09;000d;PBS_Server;Job;39411.tyrone-cluster;Not sending email: User does not want mail of this type.
06/03/2014 22:41:09;0010;PBS_Server;Job;39411.tyrone-cluster;Exit_status=0 resources_used.cput=00:01:28 resources_used.mem=0kb resources_used.vmem=0kb resources_used.walltime=00:00:09
06/03/2014 22:41:09;0008;PBS_Server;Job;NULL;on_job_exit valid pjob: 0x177bea0 (substate=50)
06/03/2014 22:41:09;0008;PBS_Server;Job;NULL;on_job_exit valid pjob: 0x177bea0 (substate=51)
06/03/2014 22:41:09;0008;PBS_Server;Job;NULL;on_job_exit valid pjob: 0x177bea0 (substate=51)
06/03/2014 22:41:09;0008;PBS_Server;Job;NULL;on_job_exit valid pjob: 0x177bea0 (substate=53)
06/03/2014 22:41:09;0100;PBS_Server;Job;39411.tyrone-cluster;dequeuing from idqueue, state COMPLETE
06/03/2014 22:41:09;0040;PBS_Server;Svr;tyrone-cluster;Scheduler was sent the command term
06/03/2014 22:41:37;0040;PBS_Server;Svr;tyrone-cluster;Scheduler was sent the command new
06/03/2014 22:42:00;0100;PBS_Server;Job;39412.tyrone-cluster;enqueuing into batch, state 1 hop 1
06/03/2014 22:42:00;0100;PBS_Server;Job;39412.tyrone-cluster;dequeuing from batch, state QUEUED
06/03/2014 22:42:00;0100;PBS_Server;Job;39412.tyrone-cluster;enqueuing into idqueue, state 1 hop 1
06/03/2014 22:42:00;0008;PBS_Server;Job;39412.tyrone-cluster;Job Queued at request of secpka@tyrone-cluster, owner = secpka@tyrone-cluster, job name = jobname, queue = idqueue
06/03/2014 22:42:00;0040;PBS_Server;Svr;tyrone-cluster;Scheduler was sent the command new
06/03/2014 22:42:00;0008;PBS_Server;Job;39412.tyrone-cluster;Job Modified at request of Scheduler@tyrone-cluster
06/03/2014 22:42:00;0008;PBS_Server;Job;39412.tyrone-cluster;Job Run at request of Scheduler@tyrone-cluster
06/03/2014 22:42:00;0040;PBS_Server;Svr;tyrone-cluster;Scheduler was sent the command recyc
06/03/2014 22:42:00;000d;PBS_Server;Job;39412.tyrone-cluster;Not sending email: User does not want mail of this type.
06/03/2014 22:42:07;0040;PBS_Server;Svr;tyrone-cluster;Scheduler was sent the command new
06/03/2014 22:42:07;000d;PBS_Server;Job;39412.tyrone-cluster;Not sending email: User does not want mail of this type.
06/03/2014 22:42:07;0010;PBS_Server;Job;39412.tyrone-cluster;Exit_status=0 resources_used.cput=00:01:15 resources_used.mem=0kb resources_used.vmem=0kb resources_used.walltime=00:00:07
06/03/2014 22:42:07;0008;PBS_Server;Job;NULL;on_job_exit valid pjob: 0x177bea0 (substate=50)
06/03/2014 22:42:07;0008;PBS_Server;Job;NULL;on_job_exit valid pjob: 0x177bea0 (substate=51)
06/03/2014 22:42:08;0008;PBS_Server;Job;NULL;on_job_exit valid pjob: 0x177bea0 (substate=51)
06/03/2014 22:42:08;0008;PBS_Server;Job;NULL;on_job_exit valid pjob: 0x177bea0 (substate=53)
06/03/2014 22:42:08;0100;PBS_Server;Job;39412.tyrone-cluster;dequeuing from idqueue, state COMPLETE
06/03/2014 22:42:08;0040;PBS_Server;Svr;tyrone-cluster;Scheduler was sent the command term
06/03/2014 22:42:39;0040;PBS_Server;Svr;tyrone-cluster;Scheduler was sent the command new
06/03/2014 22:42:49;0100;PBS_Server;Job;39413.tyrone-cluster;enqueuing into batch, state 1 hop 1
06/03/2014 22:42:49;0100;PBS_Server;Job;39413.tyrone-cluster;dequeuing from batch, state QUEUED
06/03/2014 22:42:49;0100;PBS_Server;Job;39413.tyrone-cluster;enqueuing into idqueue, state 1 hop 1
06/03/2014 22:42:49;0008;PBS_Server;Job;39413.tyrone-cluster;Job Queued at request of secpka@tyrone-cluster, owner = secpka@tyrone-cluster, job name = jobname, queue = idqueue
06/03/2014 22:42:49;0040;PBS_Server;Svr;tyrone-cluster;Scheduler was sent the command new
06/03/2014 22:42:49;0008;PBS_Server;Job;39413.tyrone-cluster;Job Modified at request of Scheduler@tyrone-cluster
06/03/2014 22:42:49;0008;PBS_Server;Job;39413.tyrone-cluster;Job Run at request of Scheduler@tyrone-cluster
06/03/2014 22:42:49;0040;PBS_Server;Svr;tyrone-cluster;Scheduler was sent the command recyc
06/03/2014 22:42:49;000d;PBS_Server;Job;39413.tyrone-cluster;Not sending email: User does not want mail of this type.
06/03/2014 22:42:56;000d;PBS_Server;Job;39413.tyrone-cluster;Not sending email: User does not want mail of this type.
06/03/2014 22:42:56;0010;PBS_Server;Job;39413.tyrone-cluster;Exit_status=0 resources_used.cput=00:01:01 resources_used.mem=1744kb resources_used.vmem=119176kb resources_used.walltime=00:00:07
06/03/2014 22:42:56;0008;PBS_Server;Job;NULL;on_job_exit valid pjob: 0x177bea0 (substate=50)
06/03/2014 22:42:56;0008;PBS_Server;Job;NULL;on_job_exit valid pjob: 0x177bea0 (substate=51)
06/03/2014 22:42:56;0008;PBS_Server;Job;NULL;on_job_exit valid pjob: 0x177bea0 (substate=51)
06/03/2014 22:42:56;0008;PBS_Server;Job;NULL;on_job_exit valid pjob: 0x177bea0 (substate=53)
06/03/2014 22:42:56;0100;PBS_Server;Job;39413.tyrone-cluster;dequeuing from idqueue, state COMPLETE
06/03/2014 22:42:56;0040;PBS_Server;Svr;tyrone-cluster;Scheduler was sent the command term
06/03/2014 22:43:04;000d;PBS_Server;Job;39407.tyrone-cluster;Not sending email: User does not want mail of this type.
06/03/2014 22:43:04;0010;PBS_Server;Job;39407.tyrone-cluster;Exit_status=0 resources_used.cput=01:03:39 resources_used.mem=7593200kb resources_used.vmem=12267032kb resources_used.walltime=00:32:51
06/03/2014 22:43:04;0008;PBS_Server;Job;NULL;on_job_exit valid pjob: 0x1791590 (substate=50)
06/03/2014 22:43:04;0008;PBS_Server;Job;NULL;on_job_exit valid pjob: 0x1791590 (substate=51)
06/03/2014 22:43:04;0008;PBS_Server;Job;NULL;on_job_exit valid pjob: 0x1791590 (substate=51)
06/03/2014 22:43:04;0008;PBS_Server;Job;NULL;on_job_exit valid pjob: 0x1791590 (substate=53)
06/03/2014 22:43:04;0100;PBS_Server;Job;39407.tyrone-cluster;dequeuing from qp256, state COMPLETE
06/03/2014 22:43:04;0040;PBS_Server;Svr;tyrone-cluster;Scheduler was sent the command term
06/03/2014 22:43:05;0008;PBS_Server;Job;39312.tyrone-cluster;Job Modified at request of Scheduler@tyrone-cluster
06/03/2014 22:43:05;0008;PBS_Server;Job;39408.tyrone-cluster;Job Modified at request of Scheduler@tyrone-cluster
06/03/2014 22:43:05;0008;PBS_Server;Job;39408.tyrone-cluster;Job Run at request of Scheduler@tyrone-cluster
06/03/2014 22:43:05;0040;PBS_Server;Svr;tyrone-cluster;Scheduler was sent the command recyc
06/03/2014 22:43:07;0040;PBS_Server;Svr;tyrone-cluster;Scheduler was sent the command new
06/03/2014 22:43:07;0008;PBS_Server;Job;39312.tyrone-cluster;Job Modified at request of Scheduler@tyrone-cluster
06/03/2014 22:43:35;0100;PBS_Server;Job;39414.tyrone-cluster;enqueuing into batch, state 1 hop 1
06/03/2014 22:43:35;0100;PBS_Server;Job;39414.tyrone-cluster;dequeuing from batch, state QUEUED
06/03/2014 22:43:35;0100;PBS_Server;Job;39414.tyrone-cluster;enqueuing into idqueue, state 1 hop 1
06/03/2014 22:43:35;0008;PBS_Server;Job;39414.tyrone-cluster;Job Queued at request of secpka@tyrone-cluster, owner = secpka@tyrone-cluster, job name = jobname, queue = idqueue
06/03/2014 22:43:35;0040;PBS_Server;Svr;tyrone-cluster;Scheduler was sent the command new
06/03/2014 22:43:35;0008;PBS_Server;Job;39414.tyrone-cluster;Job Modified at request of Scheduler@tyrone-cluster
06/03/2014 22:43:35;0008;PBS_Server;Job;39414.tyrone-cluster;Job Run at request of Scheduler@tyrone-cluster
06/03/2014 22:43:35;0040;PBS_Server;Svr;tyrone-cluster;Scheduler was sent the command recyc
06/03/2014 22:43:35;000d;PBS_Server;Job;39414.tyrone-cluster;Not sending email: User does not want mail of this type.
06/03/2014 22:43:39;000d;PBS_Server;Job;39408.tyrone-cluster;Not sending email: User does not want mail of this type.
06/03/2014 22:43:39;0040;PBS_Server;Svr;tyrone-cluster;Scheduler was sent the command new
06/03/2014 22:43:41;000d;PBS_Server;Job;39414.tyrone-cluster;Not sending email: User does not want mail of this type.
06/03/2014 22:43:41;0010;PBS_Server;Job;39414.tyrone-cluster;Exit_status=0 resources_used.cput=00:00:50 resources_used.mem=0kb resources_used.vmem=0kb resources_used.walltime=00:00:06
06/03/2014 22:43:41;0008;PBS_Server;Job;NULL;on_job_exit valid pjob: 0x177bea0 (substate=50)
06/03/2014 22:43:41;0008;PBS_Server;Job;NULL;on_job_exit valid pjob: 0x177bea0 (substate=51)
06/03/2014 22:43:41;0008;PBS_Server;Job;NULL;on_job_exit valid pjob: 0x177bea0 (substate=51)
06/03/2014 22:43:41;0008;PBS_Server;Job;NULL;on_job_exit valid pjob: 0x177bea0 (substate=53)
06/03/2014 22:43:41;0100;PBS_Server;Job;39414.tyrone-cluster;dequeuing from idqueue, state COMPLETE
06/03/2014 22:43:41;0040;PBS_Server;Svr;tyrone-cluster;Scheduler was sent the command term
06/03/2014 22:44:10;0040;PBS_Server;Svr;tyrone-cluster;Scheduler was sent the command new
06/03/2014 22:44:40;0040;PBS_Server;Svr;tyrone-cluster;Scheduler was sent the command new
06/03/2014 22:45:09;0040;PBS_Server;Svr;tyrone-cluster;Scheduler was sent the command new
06/03/2014 22:45:40;0040;PBS_Server;Svr;tyrone-cluster;Scheduler was sent the command new
06/03/2014 22:45:57;0002;PBS_Server;Svr;PBS_Server;Torque Server Version = 3.0.5, loglevel = 0
06/03/2014 22:46:10;0040;PBS_Server;Svr;tyrone-cluster;Scheduler was sent the command new
06/03/2014 22:46:39;0040;PBS_Server;Svr;tyrone-cluster;Scheduler was sent the command new
06/03/2014 22:47:09;0040;PBS_Server;Svr;tyrone-cluster;Scheduler was sent the command new
06/03/2014 22:47:40;0040;PBS_Server;Svr;tyrone-cluster;Scheduler was sent the command new
06/03/2014 22:48:09;0040;PBS_Server;Svr;tyrone-cluster;Scheduler was sent the command new
06/03/2014 22:48:40;0040;PBS_Server;Svr;tyrone-cluster;Scheduler was sent the command new
06/03/2014 22:49:09;0040;PBS_Server;Svr;tyrone-cluster;Scheduler was sent the command new
06/03/2014 22:49:39;0040;PBS_Server;Svr;tyrone-cluster;Scheduler was sent the command new
06/03/2014 22:50:03;0100;PBS_Server;Job;39415.tyrone-cluster;enqueuing into batch, state 1 hop 1
06/03/2014 22:50:03;0100;PBS_Server;Job;39415.tyrone-cluster;dequeuing from batch, state QUEUED
06/03/2014 22:50:03;0100;PBS_Server;Job;39415.tyrone-cluster;enqueuing into idqueue, state 1 hop 1
06/03/2014 22:50:03;0008;PBS_Server;Job;39415.tyrone-cluster;Job Queued at request of secpka@tyrone-cluster, owner = secpka@tyrone-cluster, job name = jobname, queue = idqueue
06/03/2014 22:50:03;0040;PBS_Server;Svr;tyrone-cluster;Scheduler was sent the command new
06/03/2014 22:50:03;0008;PBS_Server;Job;39415.tyrone-cluster;Job Modified at request of Scheduler@tyrone-cluster
06/03/2014 22:50:03;0008;PBS_Server;Job;39415.tyrone-cluster;Job Run at request of Scheduler@tyrone-cluster
06/03/2014 22:50:03;0040;PBS_Server;Svr;tyrone-cluster;Scheduler was sent the command recyc
06/03/2014 22:50:03;000d;PBS_Server;Job;39415.tyrone-cluster;Not sending email: User does not want mail of this type.
06/03/2014 22:50:07;000d;PBS_Server;Job;39415.tyrone-cluster;Not sending email: User does not want mail of this type.
06/03/2014 22:50:07;0010;PBS_Server;Job;39415.tyrone-cluster;Exit_status=0 resources_used.cput=00:00:39 resources_used.mem=0kb resources_used.vmem=0kb resources_used.walltime=00:00:04
06/03/2014 22:50:07;0008;PBS_Server;Job;NULL;on_job_exit valid pjob: 0x177bea0 (substate=50)
06/03/2014 22:50:07;0008;PBS_Server;Job;NULL;on_job_exit valid pjob: 0x177bea0 (substate=51)
06/03/2014 22:50:07;0008;PBS_Server;Job;NULL;on_job_exit valid pjob: 0x177bea0 (substate=51)
06/03/2014 22:50:07;0008;PBS_Server;Job;NULL;on_job_exit valid pjob: 0x177bea0 (substate=53)
06/03/2014 22:50:07;0100;PBS_Server;Job;39415.tyrone-cluster;dequeuing from idqueue, state COMPLETE
06/03/2014 22:50:07;0040;PBS_Server;Svr;tyrone-cluster;Scheduler was sent the command term
06/03/2014 22:50:09;0040;PBS_Server;Svr;tyrone-cluster;Scheduler was sent the command new
06/03/2014 22:50:21;0100;PBS_Server;Job;39416.tyrone-cluster;enqueuing into batch, state 1 hop 1
06/03/2014 22:50:21;0100;PBS_Server;Job;39416.tyrone-cluster;dequeuing from batch, state QUEUED
06/03/2014 22:50:21;0100;PBS_Server;Job;39416.tyrone-cluster;enqueuing into idqueue, state 1 hop 1
06/03/2014 22:50:21;0008;PBS_Server;Job;39416.tyrone-cluster;Job Queued at request of secpka@tyrone-cluster, owner = secpka@tyrone-cluster, job name = jobname, queue = idqueue
06/03/2014 22:50:21;0040;PBS_Server;Svr;tyrone-cluster;Scheduler was sent the command new
06/03/2014 22:50:21;0008;PBS_Server;Job;39416.tyrone-cluster;Job Modified at request of Scheduler@tyrone-cluster
06/03/2014 22:50:21;0008;PBS_Server;Job;39416.tyrone-cluster;Job Run at request of Scheduler@tyrone-cluster
06/03/2014 22:50:21;0040;PBS_Server;Svr;tyrone-cluster;Scheduler was sent the command recyc
06/03/2014 22:50:21;000d;PBS_Server;Job;39416.tyrone-cluster;Not sending email: User does not want mail of this type.
06/03/2014 22:50:23;000d;PBS_Server;Job;39416.tyrone-cluster;Not sending email: User does not want mail of this type.
06/03/2014 22:50:23;0010;PBS_Server;Job;39416.tyrone-cluster;Exit_status=0 resources_used.cput=00:00:25 resources_used.mem=0kb resources_used.vmem=0kb resources_used.walltime=00:00:02
06/03/2014 22:50:23;0008;PBS_Server;Job;NULL;on_job_exit valid pjob: 0x177bea0 (substate=50)
06/03/2014 22:50:23;0008;PBS_Server;Job;NULL;on_job_exit valid pjob: 0x177bea0 (substate=51)
06/03/2014 22:50:23;0008;PBS_Server;Job;NULL;on_job_exit valid pjob: 0x177bea0 (substate=51)
06/03/2014 22:50:23;0008;PBS_Server;Job;NULL;on_job_exit valid pjob: 0x177bea0 (substate=53)
06/03/2014 22:50:23;0100;PBS_Server;Job;39416.tyrone-cluster;dequeuing from idqueue, state COMPLETE
06/03/2014 22:50:23;0040;PBS_Server;Svr;tyrone-cluster;Scheduler was sent the command term
06/03/2014 22:50:31;0100;PBS_Server;Job;39417.tyrone-cluster;enqueuing into batch, state 1 hop 1
06/03/2014 22:50:31;0100;PBS_Server;Job;39417.tyrone-cluster;dequeuing from batch, state QUEUED
06/03/2014 22:50:31;0100;PBS_Server;Job;39417.tyrone-cluster;enqueuing into idqueue, state 1 hop 1
06/03/2014 22:50:31;0008;PBS_Server;Job;39417.tyrone-cluster;Job Queued at request of secpka@tyrone-cluster, owner = secpka@tyrone-cluster, job name = jobname, queue = idqueue
06/03/2014 22:50:31;0040;PBS_Server;Svr;tyrone-cluster;Scheduler was sent the command new
06/03/2014 22:50:31;0008;PBS_Server;Job;39417.tyrone-cluster;Job Modified at request of Scheduler@tyrone-cluster
06/03/2014 22:50:31;0008;PBS_Server;Job;39417.tyrone-cluster;Job Run at request of Scheduler@tyrone-cluster
06/03/2014 22:50:31;0040;PBS_Server;Svr;tyrone-cluster;Scheduler was sent the command recyc
06/03/2014 22:50:31;000d;PBS_Server;Job;39417.tyrone-cluster;Not sending email: User does not want mail of this type.
06/03/2014 22:50:33;000d;PBS_Server;Job;39417.tyrone-cluster;Not sending email: User does not want mail of this type.
06/03/2014 22:50:33;0010;PBS_Server;Job;39417.tyrone-cluster;Exit_status=0 resources_used.cput=00:00:13 resources_used.mem=0kb resources_used.vmem=0kb resources_used.walltime=00:00:02
06/03/2014 22:50:33;0008;PBS_Server;Job;NULL;on_job_exit valid pjob: 0x177bea0 (substate=50)
06/03/2014 22:50:33;0008;PBS_Server;Job;NULL;on_job_exit valid pjob: 0x177bea0 (substate=51)
06/03/2014 22:50:33;0008;PBS_Server;Job;NULL;on_job_exit valid pjob: 0x177bea0 (substate=51)
06/03/2014 22:50:33;0008;PBS_Server;Job;NULL;on_job_exit valid pjob: 0x177bea0 (substate=53)
06/03/2014 22:50:33;0100;PBS_Server;Job;39417.tyrone-cluster;dequeuing from idqueue, state COMPLETE
06/03/2014 22:50:33;0040;PBS_Server;Svr;tyrone-cluster;Scheduler was sent the command term
06/03/2014 22:50:40;0040;PBS_Server;Svr;tyrone-cluster;Scheduler was sent the command new
06/03/2014 22:50:57;0002;PBS_Server;Svr;PBS_Server;Torque Server Version = 3.0.5, loglevel = 0
06/03/2014 22:51:09;0040;PBS_Server;Svr;tyrone-cluster;Scheduler was sent the command new
06/03/2014 22:51:39;0040;PBS_Server;Svr;tyrone-cluster;Scheduler was sent the command new
06/03/2014 22:52:10;0040;PBS_Server;Svr;tyrone-cluster;Scheduler was sent the command new
06/03/2014 22:52:39;0040;PBS_Server;Svr;tyrone-cluster;Scheduler was sent the command new
06/03/2014 22:53:10;0040;PBS_Server;Svr;tyrone-cluster;Scheduler was sent the command new
06/03/2014 22:53:39;0040;PBS_Server;Svr;tyrone-cluster;Scheduler was sent the command new
06/03/2014 22:54:09;0040;PBS_Server;Svr;tyrone-cluster;Scheduler was sent the command new
06/03/2014 22:54:40;0040;PBS_Server;Svr;tyrone-cluster;Scheduler was sent the command new
06/03/2014 22:55:10;0040;PBS_Server;Svr;tyrone-cluster;Scheduler was sent the command new
06/03/2014 22:55:39;0040;PBS_Server;Svr;tyrone-cluster;Scheduler was sent the command new
06/03/2014 22:55:57;0002;PBS_Server;Svr;PBS_Server;Torque Server Version = 3.0.5, loglevel = 0
06/03/2014 22:56:09;0040;PBS_Server;Svr;tyrone-cluster;Scheduler was sent the command new
06/03/2014 22:56:40;0040;PBS_Server;Svr;tyrone-cluster;Scheduler was sent the command new
06/03/2014 22:57:09;0040;PBS_Server;Svr;tyrone-cluster;Scheduler was sent the command new
06/03/2014 22:57:11;000d;PBS_Server;Job;39408.tyrone-cluster;Not sending email: User does not want mail of this type.
06/03/2014 22:57:11;0010;PBS_Server;Job;39408.tyrone-cluster;Exit_status=0 resources_used.cput=00:36:10 resources_used.mem=20441496kb resources_used.vmem=25811428kb resources_used.walltime=00:14:06
06/03/2014 22:57:11;0008;PBS_Server;Job;NULL;on_job_exit valid pjob: 0x1713730 (substate=50)
06/03/2014 22:57:11;0008;PBS_Server;Job;NULL;on_job_exit valid pjob: 0x1713730 (substate=51)
06/03/2014 22:57:11;0008;PBS_Server;Job;NULL;on_job_exit valid pjob: 0x1713730 (substate=51)
06/03/2014 22:57:11;0008;PBS_Server;Job;NULL;on_job_exit valid pjob: 0x1713730 (substate=53)
06/03/2014 22:57:11;0100;PBS_Server;Job;39408.tyrone-cluster;dequeuing from qp256, state COMPLETE
06/03/2014 22:57:11;0040;PBS_Server;Svr;tyrone-cluster;Scheduler was sent the command term
06/03/2014 22:57:11;0008;PBS_Server;Job;39312.tyrone-cluster;Job Modified at request of Scheduler@tyrone-cluster
06/03/2014 22:57:40;0040;PBS_Server;Svr;tyrone-cluster;Scheduler was sent the command new
06/03/2014 22:58:10;0040;PBS_Server;Svr;tyrone-cluster;Scheduler was sent the command new
06/03/2014 22:58:40;0040;PBS_Server;Svr;tyrone-cluster;Scheduler was sent the command new
06/03/2014 22:59:10;0040;PBS_Server;Svr;tyrone-cluster;Scheduler was sent the command new
06/03/2014 22:59:41;0040;PBS_Server;Svr;tyrone-cluster;Scheduler was sent the command new
06/03/2014 23:00:10;0040;PBS_Server;Svr;tyrone-cluster;Scheduler was sent the command new
06/03/2014 23:00:41;0040;PBS_Server;Svr;tyrone-cluster;Scheduler was sent the command new
06/03/2014 23:00:57;0002;PBS_Server;Svr;PBS_Server;Torque Server Version = 3.0.5, loglevel = 0
06/03/2014 23:01:12;0040;PBS_Server;Svr;tyrone-cluster;Scheduler was sent the command new
06/03/2014 23:01:40;0040;PBS_Server;Svr;tyrone-cluster;Scheduler was sent the command new
06/03/2014 23:02:10;0040;PBS_Server;Svr;tyrone-cluster;Scheduler was sent the command new
06/03/2014 23:02:42;0040;PBS_Server;Svr;tyrone-cluster;Scheduler was sent the command new
06/03/2014 23:03:10;0040;PBS_Server;Svr;tyrone-cluster;Scheduler was sent the command new
06/03/2014 23:03:40;0040;PBS_Server;Svr;tyrone-cluster;Scheduler was sent the command new
06/03/2014 23:04:11;0040;PBS_Server;Svr;tyrone-cluster;Scheduler was sent the command new
06/03/2014 23:04:40;0040;PBS_Server;Svr;tyrone-cluster;Scheduler was sent the command new
06/03/2014 23:05:11;0040;PBS_Server;Svr;tyrone-cluster;Scheduler was sent the command new
06/03/2014 23:05:42;0040;PBS_Server;Svr;tyrone-cluster;Scheduler was sent the command new
06/03/2014 23:05:57;0002;PBS_Server;Svr;PBS_Server;Torque Server Version = 3.0.5, loglevel = 0
06/03/2014 23:06:10;0040;PBS_Server;Svr;tyrone-cluster;Scheduler was sent the command new
06/03/2014 23:06:37;0100;PBS_Server;Job;39418.tyrone-cluster;enqueuing into batch, state 1 hop 1
06/03/2014 23:06:37;0100;PBS_Server;Job;39418.tyrone-cluster;dequeuing from batch, state QUEUED
06/03/2014 23:06:37;0100;PBS_Server;Job;39418.tyrone-cluster;enqueuing into qp32, state 1 hop 1
06/03/2014 23:06:37;0008;PBS_Server;Job;39418.tyrone-cluster;Job Queued at request of secbadar@tyrone-cluster, owner = secbadar@tyrone-cluster, job name = job32G, queue = qp32
06/03/2014 23:06:37;0040;PBS_Server;Svr;tyrone-cluster;Scheduler was sent the command new
06/03/2014 23:06:37;0008;PBS_Server;Job;39418.tyrone-cluster;Job Modified at request of Scheduler@tyrone-cluster
06/03/2014 23:06:37;0008;PBS_Server;Job;39418.tyrone-cluster;Job Run at request of Scheduler@tyrone-cluster
06/03/2014 23:06:37;0040;PBS_Server;Svr;tyrone-cluster;Scheduler was sent the command recyc
06/03/2014 23:06:37;000d;PBS_Server;Job;39418.tyrone-cluster;Not sending email: User does not want mail of this type.
06/03/2014 23:06:42;0040;PBS_Server;Svr;tyrone-cluster;Scheduler was sent the command new
06/03/2014 23:07:12;0040;PBS_Server;Svr;tyrone-cluster;Scheduler was sent the command new
06/03/2014 23:07:40;0040;PBS_Server;Svr;tyrone-cluster;Scheduler was sent the command new
06/03/2014 23:08:10;0040;PBS_Server;Svr;tyrone-cluster;Scheduler was sent the command new
06/03/2014 23:08:42;0040;PBS_Server;Svr;tyrone-cluster;Scheduler was sent the command new
06/03/2014 23:09:10;0040;PBS_Server;Svr;tyrone-cluster;Scheduler was sent the command new
06/03/2014 23:09:40;0040;PBS_Server;Svr;tyrone-cluster;Scheduler was sent the command new
06/03/2014 23:10:11;0040;PBS_Server;Svr;tyrone-cluster;Scheduler was sent the command new
06/03/2014 23:10:40;0040;PBS_Server;Svr;tyrone-cluster;Scheduler was sent the command new
06/03/2014 23:10:57;0002;PBS_Server;Svr;PBS_Server;Torque Server Version = 3.0.5, loglevel = 0
06/03/2014 23:11:10;0040;PBS_Server;Svr;tyrone-cluster;Scheduler was sent the command new
06/03/2014 23:11:23;0100;PBS_Server;Job;39419.tyrone-cluster;enqueuing into batch, state 1 hop 1
06/03/2014 23:11:23;0100;PBS_Server;Job;39419.tyrone-cluster;dequeuing from batch, state QUEUED
06/03/2014 23:11:23;0100;PBS_Server;Job;39419.tyrone-cluster;enqueuing into qp256, state 1 hop 1
06/03/2014 23:11:23;0008;PBS_Server;Job;39419.tyrone-cluster;Job Queued at request of secbadar@tyrone-cluster, owner = secbadar@tyrone-cluster, job name = job1286USG, queue = qp256
06/03/2014 23:11:23;0040;PBS_Server;Svr;tyrone-cluster;Scheduler was sent the command new
06/03/2014 23:11:23;0008;PBS_Server;Job;39419.tyrone-cluster;Job Modified at request of Scheduler@tyrone-cluster
06/03/2014 23:11:23;0008;PBS_Server;Job;39419.tyrone-cluster;Job Run at request of Scheduler@tyrone-cluster
06/03/2014 23:11:23;0040;PBS_Server;Svr;tyrone-cluster;Scheduler was sent the command recyc
06/03/2014 23:11:42;0040;PBS_Server;Svr;tyrone-cluster;Scheduler was sent the command new
06/03/2014 23:11:42;0008;PBS_Server;Job;39312.tyrone-cluster;Job Modified at request of Scheduler@tyrone-cluster
06/03/2014 23:12:10;0040;PBS_Server;Svr;tyrone-cluster;Scheduler was sent the command new
06/03/2014 23:12:24;0100;PBS_Server;Job;39420.tyrone-cluster;enqueuing into batch, state 1 hop 1
06/03/2014 23:12:24;0100;PBS_Server;Job;39420.tyrone-cluster;dequeuing from batch, state QUEUED
06/03/2014 23:12:24;0100;PBS_Server;Job;39420.tyrone-cluster;enqueuing into qp256, state 1 hop 1
06/03/2014 23:12:24;0008;PBS_Server;Job;39420.tyrone-cluster;Job Queued at request of secbadar@tyrone-cluster, owner = secbadar@tyrone-cluster, job name = job646USG, queue = qp256
06/03/2014 23:12:24;0040;PBS_Server;Svr;tyrone-cluster;Scheduler was sent the command new
06/03/2014 23:12:24;0008;PBS_Server;Job;39420.tyrone-cluster;Job Modified at request of Scheduler@tyrone-cluster
06/03/2014 23:12:31;000d;PBS_Server;Job;39419.tyrone-cluster;Not sending email: User does not want mail of this type.
06/03/2014 23:12:40;0040;PBS_Server;Svr;tyrone-cluster;Scheduler was sent the command new
06/03/2014 23:13:11;0040;PBS_Server;Svr;tyrone-cluster;Scheduler was sent the command new
06/03/2014 23:13:40;0040;PBS_Server;Svr;tyrone-cluster;Scheduler was sent the command new
06/03/2014 23:14:10;0040;PBS_Server;Svr;tyrone-cluster;Scheduler was sent the command new
06/03/2014 23:14:41;0040;PBS_Server;Svr;tyrone-cluster;Scheduler was sent the command new
06/03/2014 23:15:10;0040;PBS_Server;Svr;tyrone-cluster;Scheduler was sent the command new
06/03/2014 23:15:40;0040;PBS_Server;Svr;tyrone-cluster;Scheduler was sent the command new
06/03/2014 23:15:57;0002;PBS_Server;Svr;PBS_Server;Torque Server Version = 3.0.5, loglevel = 0
06/03/2014 23:16:11;0040;PBS_Server;Svr;tyrone-cluster;Scheduler was sent the command new
06/03/2014 23:16:40;0040;PBS_Server;Svr;tyrone-cluster;Scheduler was sent the command new
06/03/2014 23:17:10;0040;PBS_Server;Svr;tyrone-cluster;Scheduler was sent the command new
06/03/2014 23:17:41;0040;PBS_Server;Svr;tyrone-cluster;Scheduler was sent the command new
06/03/2014 23:18:10;0040;PBS_Server;Svr;tyrone-cluster;Scheduler was sent the command new
06/03/2014 23:18:40;0040;PBS_Server;Svr;tyrone-cluster;Scheduler was sent the command new
06/03/2014 23:19:12;0040;PBS_Server;Svr;tyrone-cluster;Scheduler was sent the command new
06/03/2014 23:19:40;0040;PBS_Server;Svr;tyrone-cluster;Scheduler was sent the command new
06/03/2014 23:20:10;0040;PBS_Server;Svr;tyrone-cluster;Scheduler was sent the command new
06/03/2014 23:20:41;0040;PBS_Server;Svr;tyrone-cluster;Scheduler was sent the command new
06/03/2014 23:20:57;0002;PBS_Server;Svr;PBS_Server;Torque Server Version = 3.0.5, loglevel = 0
06/03/2014 23:21:10;0040;PBS_Server;Svr;tyrone-cluster;Scheduler was sent the command new
06/03/2014 23:21:42;0040;PBS_Server;Svr;tyrone-cluster;Scheduler was sent the command new
06/03/2014 23:22:12;0040;PBS_Server;Svr;tyrone-cluster;Scheduler was sent the command new
06/03/2014 23:22:40;0040;PBS_Server;Svr;tyrone-cluster;Scheduler was sent the command new
06/03/2014 23:23:10;0040;PBS_Server;Svr;tyrone-cluster;Scheduler was sent the command new
