09/19/2014 00:02:39;0002;PBS_Server;Svr;Log;Log opened
09/19/2014 00:02:39;0002;PBS_Server;Svr;PBS_Server;Torque Server Version = 3.0.5, loglevel = 0
09/19/2014 00:07:39;0002;PBS_Server;Svr;PBS_Server;Torque Server Version = 3.0.5, loglevel = 0
09/19/2014 00:09:14;0040;PBS_Server;Svr;tyrone-cluster;Scheduler was sent the command time
09/19/2014 00:10:30;0100;PBS_Server;Job;42528.tyrone-cluster;enqueuing into batch, state 1 hop 1
09/19/2014 00:10:30;0002;PBS_Server;Svr;Act;Account file /var/spool/torque/server_priv/accounting/20140919 opened
09/19/2014 00:10:30;0100;PBS_Server;Job;42528.tyrone-cluster;dequeuing from batch, state QUEUED
09/19/2014 00:10:30;0100;PBS_Server;Job;42528.tyrone-cluster;enqueuing into qp64, state 1 hop 1
09/19/2014 00:10:30;0008;PBS_Server;Job;42528.tyrone-cluster;Job Queued at request of chevadh@tyrone-cluster, owner = chevadh@tyrone-cluster, job name = jobname, queue = qp64
09/19/2014 00:10:30;0040;PBS_Server;Svr;tyrone-cluster;Scheduler was sent the command new
09/19/2014 00:10:30;0008;PBS_Server;Job;42528.tyrone-cluster;Job Modified at request of Scheduler@tyrone-cluster
09/19/2014 00:11:52;0100;PBS_Server;Job;42529.tyrone-cluster;enqueuing into batch, state 1 hop 1
09/19/2014 00:11:52;0008;PBS_Server;Job;42529.tyrone-cluster;Job Queued at request of chevadh@tyrone-cluster, owner = chevadh@tyrone-cluster, job name = jobname, queue = batch
09/19/2014 00:11:52;0040;PBS_Server;Svr;tyrone-cluster;Scheduler was sent the command new
09/19/2014 00:11:52;0008;PBS_Server;Job;42529.tyrone-cluster;Job Modified at request of Scheduler@tyrone-cluster
09/19/2014 00:11:53;0100;PBS_Server;Job;42530.tyrone-cluster;enqueuing into batch, state 1 hop 1
09/19/2014 00:11:53;0008;PBS_Server;Job;42530.tyrone-cluster;Job Queued at request of chevadh@tyrone-cluster, owner = chevadh@tyrone-cluster, job name = jobname, queue = batch
09/19/2014 00:11:53;0040;PBS_Server;Svr;tyrone-cluster;Scheduler was sent the command new
09/19/2014 00:11:53;0008;PBS_Server;Job;42530.tyrone-cluster;Job Modified at request of Scheduler@tyrone-cluster
09/19/2014 00:12:25;0040;PBS_Server;Svr;tyrone-cluster;Scheduler was sent the command new
09/19/2014 00:12:39;0002;PBS_Server;Svr;PBS_Server;Torque Server Version = 3.0.5, loglevel = 0
09/19/2014 00:12:57;0040;PBS_Server;Svr;tyrone-cluster;Scheduler was sent the command new
09/19/2014 00:13:31;0040;PBS_Server;Svr;tyrone-cluster;Scheduler was sent the command new
09/19/2014 00:14:00;0040;PBS_Server;Svr;tyrone-cluster;Scheduler was sent the command new
09/19/2014 00:14:34;0040;PBS_Server;Svr;tyrone-cluster;Scheduler was sent the command new
09/19/2014 00:15:03;0040;PBS_Server;Svr;tyrone-cluster;Scheduler was sent the command new
09/19/2014 00:15:34;0040;PBS_Server;Svr;tyrone-cluster;Scheduler was sent the command new
09/19/2014 00:16:04;0040;PBS_Server;Svr;tyrone-cluster;Scheduler was sent the command new
09/19/2014 00:16:42;0040;PBS_Server;Svr;tyrone-cluster;Scheduler was sent the command new
09/19/2014 00:17:16;0040;PBS_Server;Svr;tyrone-cluster;Scheduler was sent the command new
09/19/2014 00:17:39;0002;PBS_Server;Svr;PBS_Server;Torque Server Version = 3.0.5, loglevel = 0
09/19/2014 00:17:49;0040;PBS_Server;Svr;tyrone-cluster;Scheduler was sent the command new
09/19/2014 00:18:19;0040;PBS_Server;Svr;tyrone-cluster;Scheduler was sent the command new
09/19/2014 00:18:48;0040;PBS_Server;Svr;tyrone-cluster;Scheduler was sent the command new
09/19/2014 00:19:19;0040;PBS_Server;Svr;tyrone-cluster;Scheduler was sent the command new
09/19/2014 00:19:49;0040;PBS_Server;Svr;tyrone-cluster;Scheduler was sent the command new
09/19/2014 00:20:18;0040;PBS_Server;Svr;tyrone-cluster;Scheduler was sent the command new
09/19/2014 00:20:49;0040;PBS_Server;Svr;tyrone-cluster;Scheduler was sent the command new
09/19/2014 00:21:19;0040;PBS_Server;Svr;tyrone-cluster;Scheduler was sent the command new
09/19/2014 00:21:48;0040;PBS_Server;Svr;tyrone-cluster;Scheduler was sent the command new
09/19/2014 00:22:19;0040;PBS_Server;Svr;tyrone-cluster;Scheduler was sent the command new
09/19/2014 00:22:39;0002;PBS_Server;Svr;PBS_Server;Torque Server Version = 3.0.5, loglevel = 0
09/19/2014 00:22:49;0040;PBS_Server;Svr;tyrone-cluster;Scheduler was sent the command new
09/19/2014 00:23:27;0040;PBS_Server;Svr;tyrone-cluster;Scheduler was sent the command new
09/19/2014 00:24:01;0040;PBS_Server;Svr;tyrone-cluster;Scheduler was sent the command new
09/19/2014 00:24:33;0040;PBS_Server;Svr;tyrone-cluster;Scheduler was sent the command new
09/19/2014 00:25:04;0040;PBS_Server;Svr;tyrone-cluster;Scheduler was sent the command new
09/19/2014 00:25:33;0040;PBS_Server;Svr;tyrone-cluster;Scheduler was sent the command new
09/19/2014 00:26:04;0040;PBS_Server;Svr;tyrone-cluster;Scheduler was sent the command new
09/19/2014 00:26:34;0040;PBS_Server;Svr;tyrone-cluster;Scheduler was sent the command new
09/19/2014 00:27:12;0040;PBS_Server;Svr;tyrone-cluster;Scheduler was sent the command new
09/19/2014 00:27:39;0002;PBS_Server;Svr;PBS_Server;Torque Server Version = 3.0.5, loglevel = 0
09/19/2014 00:27:45;0040;PBS_Server;Svr;tyrone-cluster;Scheduler was sent the command new
09/19/2014 00:28:13;0040;PBS_Server;Svr;tyrone-cluster;Scheduler was sent the command new
09/19/2014 00:28:42;0040;PBS_Server;Svr;tyrone-cluster;Scheduler was sent the command new
09/19/2014 00:29:16;0040;PBS_Server;Svr;tyrone-cluster;Scheduler was sent the command new
09/19/2014 00:29:48;0040;PBS_Server;Svr;tyrone-cluster;Scheduler was sent the command new
09/19/2014 00:30:15;0100;PBS_Server;Job;42531.tyrone-cluster;enqueuing into batch, state 1 hop 1
09/19/2014 00:30:15;0100;PBS_Server;Job;42531.tyrone-cluster;dequeuing from batch, state QUEUED
09/19/2014 00:30:15;0100;PBS_Server;Job;42531.tyrone-cluster;enqueuing into qp256, state 1 hop 1
09/19/2014 00:30:15;0008;PBS_Server;Job;42531.tyrone-cluster;Job Queued at request of chemraja@tyrone-cluster, owner = chemraja@tyrone-cluster, job name = run, queue = qp256
09/19/2014 00:30:15;0040;PBS_Server;Svr;tyrone-cluster;Scheduler was sent the command new
09/19/2014 00:30:15;0008;PBS_Server;Job;42531.tyrone-cluster;Job Modified at request of Scheduler@tyrone-cluster
09/19/2014 00:30:17;0040;PBS_Server;Svr;tyrone-cluster;Scheduler was sent the command new
09/19/2014 00:30:47;0040;PBS_Server;Svr;tyrone-cluster;Scheduler was sent the command new
09/19/2014 00:31:10;0008;PBS_Server;Job;42445.tyrone-cluster;Job deleted at request of asepk@tyrone-cluster
09/19/2014 00:31:10;0008;PBS_Server;Job;42445.tyrone-cluster;Job sent signal SIGTERM on delete
09/19/2014 00:31:11;000d;PBS_Server;Job;42445.tyrone-cluster;Not sending email: User does not want mail of this type.
09/19/2014 00:31:11;0010;PBS_Server;Job;42445.tyrone-cluster;Exit_status=143 resources_used.cput=461:11:15 resources_used.mem=1108788kb resources_used.vmem=7164004kb resources_used.walltime=21:40:49
09/19/2014 00:31:11;0008;PBS_Server;Job;NULL;on_job_exit valid pjob: 0x2cd6fe0 (substate=50)
09/19/2014 00:31:11;0008;PBS_Server;Job;NULL;on_job_exit valid pjob: 0x2cd6fe0 (substate=51)
09/19/2014 00:31:19;0040;PBS_Server;Svr;tyrone-cluster;Scheduler was sent the command new
09/19/2014 00:31:19;0008;PBS_Server;Job;42484.tyrone-cluster;Job Modified at request of Scheduler@tyrone-cluster
09/19/2014 00:31:19;0008;PBS_Server;Job;42496.tyrone-cluster;Job Modified at request of Scheduler@tyrone-cluster
09/19/2014 00:31:19;0008;PBS_Server;Job;NULL;on_job_exit valid pjob: 0x2cd6fe0 (substate=51)
09/19/2014 00:31:19;000d;PBS_Server;Job;42445.tyrone-cluster;Post job file processing error; job 42445.tyrone-cluster on host tyrone-node1/31+tyrone-node1/30+tyrone-node1/29+tyrone-node1/28+tyrone-node1/27+tyrone-node1/26+tyrone-node1/25+tyrone-node1/24+tyrone-node1/23+tyrone-node1/22+tyrone-node1/21+tyrone-node1/20+tyrone-node1/19+tyrone-node1/18+tyrone-node1/17+tyrone-node1/16+tyrone-node1/15+tyrone-node1/14+tyrone-node1/13+tyrone-node1/12+tyrone-node1/11+tyrone-node1/10+tyrone-node1/9+tyrone-node1/8+tyrone-node1/7+tyrone-node1/6+tyrone-node1/5+tyrone-node1/4+tyrone-node1/3+tyrone-node1/2+tyrone-node1/1+tyrone-node1/0
09/19/2014 00:31:19;0008;PBS_Server;Job;NULL;on_job_exit valid pjob: 0x2cd6fe0 (substate=53)
09/19/2014 00:31:19;0100;PBS_Server;Job;42445.tyrone-cluster;dequeuing from qp32, state COMPLETE
09/19/2014 00:31:19;0040;PBS_Server;Svr;tyrone-cluster;Scheduler was sent the command term
09/19/2014 00:31:20;0008;PBS_Server;Job;42484.tyrone-cluster;Job Modified at request of Scheduler@tyrone-cluster
09/19/2014 00:31:20;0008;PBS_Server;Job;42484.tyrone-cluster;Job Run at request of Scheduler@tyrone-cluster
09/19/2014 00:31:20;0008;PBS_Server;Job;42496.tyrone-cluster;Job Modified at request of Scheduler@tyrone-cluster
09/19/2014 00:31:20;0040;PBS_Server;Svr;tyrone-cluster;Scheduler was sent the command recyc
09/19/2014 00:31:20;000d;PBS_Server;Job;42484.tyrone-cluster;Not sending email: User does not want mail of this type.
09/19/2014 00:31:49;0040;PBS_Server;Svr;tyrone-cluster;Scheduler was sent the command new
09/19/2014 00:32:18;0040;PBS_Server;Svr;tyrone-cluster;Scheduler was sent the command new
09/19/2014 00:32:39;0002;PBS_Server;Svr;PBS_Server;Torque Server Version = 3.0.5, loglevel = 0
09/19/2014 00:32:50;0040;PBS_Server;Svr;tyrone-cluster;Scheduler was sent the command new
09/19/2014 00:33:19;0040;PBS_Server;Svr;tyrone-cluster;Scheduler was sent the command new
09/19/2014 00:33:48;0040;PBS_Server;Svr;tyrone-cluster;Scheduler was sent the command new
09/19/2014 00:34:20;0040;PBS_Server;Svr;tyrone-cluster;Scheduler was sent the command new
09/19/2014 00:34:49;0040;PBS_Server;Svr;tyrone-cluster;Scheduler was sent the command new
09/19/2014 00:35:18;0040;PBS_Server;Svr;tyrone-cluster;Scheduler was sent the command new
09/19/2014 00:35:42;000d;PBS_Server;Job;42508.tyrone-cluster;Not sending email: User does not want mail of this type.
09/19/2014 00:35:42;0010;PBS_Server;Job;42508.tyrone-cluster;Exit_status=143 resources_used.cput=63:44:50 resources_used.mem=410888kb resources_used.vmem=12107772kb resources_used.walltime=02:00:49
09/19/2014 00:35:42;0008;PBS_Server;Job;NULL;on_job_exit valid pjob: 0x2ce9a70 (substate=50)
09/19/2014 00:35:42;0008;PBS_Server;Job;NULL;on_job_exit valid pjob: 0x2ce9a70 (substate=51)
09/19/2014 00:35:42;0008;PBS_Server;Job;NULL;on_job_exit valid pjob: 0x2ce9a70 (substate=51)
09/19/2014 00:35:42;0008;PBS_Server;Job;NULL;on_job_exit valid pjob: 0x2ce9a70 (substate=53)
09/19/2014 00:35:42;0100;PBS_Server;Job;42508.tyrone-cluster;dequeuing from idqueue, state COMPLETE
09/19/2014 00:35:42;0040;PBS_Server;Svr;tyrone-cluster;Scheduler was sent the command term
09/19/2014 00:35:42;0008;PBS_Server;Job;42509.tyrone-cluster;Job Modified at request of Scheduler@tyrone-cluster
09/19/2014 00:35:42;0008;PBS_Server;Job;42509.tyrone-cluster;Job Run at request of Scheduler@tyrone-cluster
09/19/2014 00:35:42;0040;PBS_Server;Svr;tyrone-cluster;Scheduler was sent the command recyc
09/19/2014 00:35:42;000d;PBS_Server;Job;42509.tyrone-cluster;Not sending email: User does not want mail of this type.
09/19/2014 00:35:50;0040;PBS_Server;Svr;tyrone-cluster;Scheduler was sent the command new
09/19/2014 00:36:19;0040;PBS_Server;Svr;tyrone-cluster;Scheduler was sent the command new
09/19/2014 00:36:48;0040;PBS_Server;Svr;tyrone-cluster;Scheduler was sent the command new
09/19/2014 00:37:20;0040;PBS_Server;Svr;tyrone-cluster;Scheduler was sent the command new
09/19/2014 00:37:39;0002;PBS_Server;Svr;PBS_Server;Torque Server Version = 3.0.5, loglevel = 0
09/19/2014 00:37:49;0040;PBS_Server;Svr;tyrone-cluster;Scheduler was sent the command new
09/19/2014 00:37:49;0100;PBS_Server;Job;42532.tyrone-cluster;enqueuing into batch, state 1 hop 1
09/19/2014 00:37:49;0100;PBS_Server;Job;42532.tyrone-cluster;dequeuing from batch, state QUEUED
09/19/2014 00:37:49;0100;PBS_Server;Job;42532.tyrone-cluster;enqueuing into qp32, state 1 hop 1
09/19/2014 00:37:49;0008;PBS_Server;Job;42532.tyrone-cluster;Job Queued at request of asepk@tyrone-cluster, owner = asepk@tyrone-cluster, job name = TURBDN_32, queue = qp32
09/19/2014 00:37:49;0008;PBS_Server;Job;42532.tyrone-cluster;Job Modified at request of Scheduler@tyrone-cluster
09/19/2014 00:38:14;000d;PBS_Server;Job;42520.tyrone-cluster;Not sending email: User does not want mail of this type.
09/19/2014 00:38:14;0010;PBS_Server;Job;42520.tyrone-cluster;Exit_status=1 resources_used.cput=00:59:08 resources_used.mem=159396kb resources_used.vmem=1979064kb resources_used.walltime=01:05:43
09/19/2014 00:38:14;0008;PBS_Server;Job;NULL;on_job_exit valid pjob: 0x2cee4a0 (substate=50)
09/19/2014 00:38:14;0008;PBS_Server;Job;NULL;on_job_exit valid pjob: 0x2cee4a0 (substate=51)
09/19/2014 00:38:14;0008;PBS_Server;Job;NULL;on_job_exit valid pjob: 0x2cee4a0 (substate=51)
09/19/2014 00:38:14;0008;PBS_Server;Job;NULL;on_job_exit valid pjob: 0x2cee4a0 (substate=53)
09/19/2014 00:38:14;0100;PBS_Server;Job;42520.tyrone-cluster;dequeuing from qp128, state COMPLETE
09/19/2014 00:38:14;0040;PBS_Server;Svr;tyrone-cluster;Scheduler was sent the command term
09/19/2014 00:38:18;0040;PBS_Server;Svr;tyrone-cluster;Scheduler was sent the command new
09/19/2014 00:38:50;0040;PBS_Server;Svr;tyrone-cluster;Scheduler was sent the command new
09/19/2014 00:39:19;0040;PBS_Server;Svr;tyrone-cluster;Scheduler was sent the command new
09/19/2014 00:39:57;0040;PBS_Server;Svr;tyrone-cluster;Scheduler was sent the command new
09/19/2014 00:40:31;0040;PBS_Server;Svr;tyrone-cluster;Scheduler was sent the command new
09/19/2014 00:41:03;0040;PBS_Server;Svr;tyrone-cluster;Scheduler was sent the command new
09/19/2014 00:41:34;0040;PBS_Server;Svr;tyrone-cluster;Scheduler was sent the command new
09/19/2014 00:42:03;0040;PBS_Server;Svr;tyrone-cluster;Scheduler was sent the command new
09/19/2014 00:42:35;0040;PBS_Server;Svr;tyrone-cluster;Scheduler was sent the command new
09/19/2014 00:42:39;0002;PBS_Server;Svr;PBS_Server;Torque Server Version = 3.0.5, loglevel = 0
09/19/2014 00:43:04;0040;PBS_Server;Svr;tyrone-cluster;Scheduler was sent the command new
09/19/2014 00:43:42;0040;PBS_Server;Svr;tyrone-cluster;Scheduler was sent the command new
09/19/2014 00:44:16;0040;PBS_Server;Svr;tyrone-cluster;Scheduler was sent the command new
09/19/2014 00:44:46;0040;PBS_Server;Svr;tyrone-cluster;Scheduler was sent the command new
09/19/2014 00:45:19;0040;PBS_Server;Svr;tyrone-cluster;Scheduler was sent the command new
09/19/2014 00:45:48;0040;PBS_Server;Svr;tyrone-cluster;Scheduler was sent the command new
09/19/2014 00:46:20;0040;PBS_Server;Svr;tyrone-cluster;Scheduler was sent the command new
09/19/2014 00:46:37;000d;PBS_Server;Job;42519.tyrone-cluster;Not sending email: User does not want mail of this type.
09/19/2014 00:46:37;0010;PBS_Server;Job;42519.tyrone-cluster;Exit_status=1 resources_used.cput=02:40:59 resources_used.mem=124396kb resources_used.vmem=1978932kb resources_used.walltime=02:44:31
09/19/2014 00:46:37;0008;PBS_Server;Job;NULL;on_job_exit valid pjob: 0x2db2a70 (substate=50)
09/19/2014 00:46:37;0008;PBS_Server;Job;NULL;on_job_exit valid pjob: 0x2db2a70 (substate=51)
09/19/2014 00:46:37;0008;PBS_Server;Job;NULL;on_job_exit valid pjob: 0x2db2a70 (substate=51)
09/19/2014 00:46:37;0008;PBS_Server;Job;NULL;on_job_exit valid pjob: 0x2db2a70 (substate=53)
09/19/2014 00:46:37;0100;PBS_Server;Job;42519.tyrone-cluster;dequeuing from qp256, state COMPLETE
09/19/2014 00:46:37;0040;PBS_Server;Svr;tyrone-cluster;Scheduler was sent the command term
09/19/2014 00:46:37;0008;PBS_Server;Job;42531.tyrone-cluster;Job Modified at request of Scheduler@tyrone-cluster
09/19/2014 00:46:37;0008;PBS_Server;Job;42531.tyrone-cluster;Job Run at request of Scheduler@tyrone-cluster
09/19/2014 00:46:37;0040;PBS_Server;Svr;tyrone-cluster;Scheduler was sent the command recyc
09/19/2014 00:46:49;0040;PBS_Server;Svr;tyrone-cluster;Scheduler was sent the command new
09/19/2014 00:47:27;0040;PBS_Server;Svr;tyrone-cluster;Scheduler was sent the command new
09/19/2014 00:47:30;000d;PBS_Server;Job;42531.tyrone-cluster;Not sending email: User does not want mail of this type.
09/19/2014 00:47:39;0002;PBS_Server;Svr;PBS_Server;Torque Server Version = 3.0.5, loglevel = 0
09/19/2014 00:48:01;0040;PBS_Server;Svr;tyrone-cluster;Scheduler was sent the command new
09/19/2014 00:48:33;0040;PBS_Server;Svr;tyrone-cluster;Scheduler was sent the command new
09/19/2014 00:49:01;0008;PBS_Server;Job;42532.tyrone-cluster;Job deleted at request of asepk@tyrone-cluster
09/19/2014 00:49:01;0008;PBS_Server;Job;NULL;on_job_exit valid pjob: 0x2ce9a70 (substate=59)
09/19/2014 00:49:01;0100;PBS_Server;Job;42532.tyrone-cluster;dequeuing from qp32, state COMPLETE
09/19/2014 00:49:01;0040;PBS_Server;Svr;tyrone-cluster;Scheduler was sent the command term
09/19/2014 00:49:16;0100;PBS_Server;Job;42533.tyrone-cluster;enqueuing into batch, state 1 hop 1
09/19/2014 00:49:16;0100;PBS_Server;Job;42533.tyrone-cluster;dequeuing from batch, state QUEUED
09/19/2014 00:49:16;0100;PBS_Server;Job;42533.tyrone-cluster;enqueuing into qp32, state 1 hop 1
09/19/2014 00:49:16;0008;PBS_Server;Job;42533.tyrone-cluster;Job Queued at request of asepk@tyrone-cluster, owner = asepk@tyrone-cluster, job name = TURBDN_32, queue = qp32
09/19/2014 00:49:16;0040;PBS_Server;Svr;tyrone-cluster;Scheduler was sent the command new
09/19/2014 00:49:16;0008;PBS_Server;Job;42533.tyrone-cluster;Job Modified at request of Scheduler@tyrone-cluster
09/19/2014 00:49:31;0040;PBS_Server;Svr;tyrone-cluster;Scheduler was sent the command new
09/19/2014 00:50:03;0040;PBS_Server;Svr;tyrone-cluster;Scheduler was sent the command new
09/19/2014 00:50:34;0040;PBS_Server;Svr;tyrone-cluster;Scheduler was sent the command new
09/19/2014 00:51:03;0040;PBS_Server;Svr;tyrone-cluster;Scheduler was sent the command new
09/19/2014 00:51:35;0040;PBS_Server;Svr;tyrone-cluster;Scheduler was sent the command new
09/19/2014 00:52:04;0040;PBS_Server;Svr;tyrone-cluster;Scheduler was sent the command new
09/19/2014 00:52:39;0002;PBS_Server;Svr;PBS_Server;Torque Server Version = 3.0.5, loglevel = 0
09/19/2014 00:52:41;0040;PBS_Server;Svr;tyrone-cluster;Scheduler was sent the command new
09/19/2014 00:53:16;0040;PBS_Server;Svr;tyrone-cluster;Scheduler was sent the command new
09/19/2014 00:53:44;0040;PBS_Server;Svr;tyrone-cluster;Scheduler was sent the command new
09/19/2014 00:54:15;0040;PBS_Server;Svr;tyrone-cluster;Scheduler was sent the command new
09/19/2014 00:54:46;0040;PBS_Server;Svr;tyrone-cluster;Scheduler was sent the command new
09/19/2014 00:55:18;0040;PBS_Server;Svr;tyrone-cluster;Scheduler was sent the command new
09/19/2014 00:55:49;0040;PBS_Server;Svr;tyrone-cluster;Scheduler was sent the command new
09/19/2014 00:56:18;0040;PBS_Server;Svr;tyrone-cluster;Scheduler was sent the command new
09/19/2014 00:56:49;0040;PBS_Server;Svr;tyrone-cluster;Scheduler was sent the command new
09/19/2014 00:57:19;0040;PBS_Server;Svr;tyrone-cluster;Scheduler was sent the command new
09/19/2014 00:57:39;0002;PBS_Server;Svr;PBS_Server;Torque Server Version = 3.0.5, loglevel = 0
09/19/2014 00:57:57;0040;PBS_Server;Svr;tyrone-cluster;Scheduler was sent the command new
09/19/2014 00:58:31;0040;PBS_Server;Svr;tyrone-cluster;Scheduler was sent the command new
09/19/2014 00:59:03;0040;PBS_Server;Svr;tyrone-cluster;Scheduler was sent the command new
09/19/2014 00:59:33;0040;PBS_Server;Svr;tyrone-cluster;Scheduler was sent the command new
09/19/2014 01:00:03;0040;PBS_Server;Svr;tyrone-cluster;Scheduler was sent the command new
09/19/2014 01:00:34;0040;PBS_Server;Svr;tyrone-cluster;Scheduler was sent the command new
09/19/2014 01:01:04;0040;PBS_Server;Svr;tyrone-cluster;Scheduler was sent the command new
09/19/2014 01:01:42;0040;PBS_Server;Svr;tyrone-cluster;Scheduler was sent the command new
09/19/2014 01:02:16;0040;PBS_Server;Svr;tyrone-cluster;Scheduler was sent the command new
09/19/2014 01:02:39;0002;PBS_Server;Svr;PBS_Server;Torque Server Version = 3.0.5, loglevel = 0
09/19/2014 01:02:44;0040;PBS_Server;Svr;tyrone-cluster;Scheduler was sent the command new
09/19/2014 01:03:15;0040;PBS_Server;Svr;tyrone-cluster;Scheduler was sent the command new
09/19/2014 01:03:46;0040;PBS_Server;Svr;tyrone-cluster;Scheduler was sent the command new
09/19/2014 01:04:18;0040;PBS_Server;Svr;tyrone-cluster;Scheduler was sent the command new
09/19/2014 01:04:49;0040;PBS_Server;Svr;tyrone-cluster;Scheduler was sent the command new
09/19/2014 01:05:18;0040;PBS_Server;Svr;tyrone-cluster;Scheduler was sent the command new
09/19/2014 01:05:50;0040;PBS_Server;Svr;tyrone-cluster;Scheduler was sent the command new
09/19/2014 01:06:19;0040;PBS_Server;Svr;tyrone-cluster;Scheduler was sent the command new
09/19/2014 01:06:48;0040;PBS_Server;Svr;tyrone-cluster;Scheduler was sent the command new
09/19/2014 01:07:20;0040;PBS_Server;Svr;tyrone-cluster;Scheduler was sent the command new
09/19/2014 01:07:39;0002;PBS_Server;Svr;PBS_Server;Torque Server Version = 3.0.5, loglevel = 0
09/19/2014 01:07:49;0040;PBS_Server;Svr;tyrone-cluster;Scheduler was sent the command new
09/19/2014 01:08:27;0040;PBS_Server;Svr;tyrone-cluster;Scheduler was sent the command new
09/19/2014 01:09:01;0040;PBS_Server;Svr;tyrone-cluster;Scheduler was sent the command new
09/19/2014 01:09:30;0040;PBS_Server;Svr;tyrone-cluster;Scheduler was sent the command new
09/19/2014 01:10:00;0040;PBS_Server;Svr;tyrone-cluster;Scheduler was sent the command new
09/19/2014 01:10:31;0040;PBS_Server;Svr;tyrone-cluster;Scheduler was sent the command new
09/19/2014 01:11:01;0040;PBS_Server;Svr;tyrone-cluster;Scheduler was sent the command new
09/19/2014 01:11:30;0040;PBS_Server;Svr;tyrone-cluster;Scheduler was sent the command new
09/19/2014 01:12:01;0040;PBS_Server;Svr;tyrone-cluster;Scheduler was sent the command new
09/19/2014 01:12:31;0040;PBS_Server;Svr;tyrone-cluster;Scheduler was sent the command new
09/19/2014 01:12:39;0002;PBS_Server;Svr;PBS_Server;Torque Server Version = 3.0.5, loglevel = 0
09/19/2014 01:13:04;0040;PBS_Server;Svr;tyrone-cluster;Scheduler was sent the command new
09/19/2014 01:13:32;0040;PBS_Server;Svr;tyrone-cluster;Scheduler was sent the command new
09/19/2014 01:14:05;0040;PBS_Server;Svr;tyrone-cluster;Scheduler was sent the command new
09/19/2014 01:14:33;0040;PBS_Server;Svr;tyrone-cluster;Scheduler was sent the command new
09/19/2014 01:15:04;0040;PBS_Server;Svr;tyrone-cluster;Scheduler was sent the command new
09/19/2014 01:15:35;0040;PBS_Server;Svr;tyrone-cluster;Scheduler was sent the command new
09/19/2014 01:16:05;0040;PBS_Server;Svr;tyrone-cluster;Scheduler was sent the command new
09/19/2014 01:16:42;0040;PBS_Server;Svr;tyrone-cluster;Scheduler was sent the command new
09/19/2014 01:17:17;0040;PBS_Server;Svr;tyrone-cluster;Scheduler was sent the command new
09/19/2014 01:17:39;0002;PBS_Server;Svr;PBS_Server;Torque Server Version = 3.0.5, loglevel = 0
09/19/2014 01:17:45;0040;PBS_Server;Svr;tyrone-cluster;Scheduler was sent the command new
09/19/2014 01:18:16;0040;PBS_Server;Svr;tyrone-cluster;Scheduler was sent the command new
09/19/2014 01:18:47;0040;PBS_Server;Svr;tyrone-cluster;Scheduler was sent the command new
09/19/2014 01:19:20;0040;PBS_Server;Svr;tyrone-cluster;Scheduler was sent the command new
09/19/2014 01:19:49;0040;PBS_Server;Svr;tyrone-cluster;Scheduler was sent the command new
09/19/2014 01:20:17;0040;PBS_Server;Svr;tyrone-cluster;Scheduler was sent the command new
09/19/2014 01:20:50;0040;PBS_Server;Svr;tyrone-cluster;Scheduler was sent the command new
09/19/2014 01:21:20;0040;PBS_Server;Svr;tyrone-cluster;Scheduler was sent the command new
09/19/2014 01:21:49;0040;PBS_Server;Svr;tyrone-cluster;Scheduler was sent the command new
09/19/2014 01:22:20;0040;PBS_Server;Svr;tyrone-cluster;Scheduler was sent the command new
09/19/2014 01:22:39;0002;PBS_Server;Svr;PBS_Server;Torque Server Version = 3.0.5, loglevel = 0
09/19/2014 01:22:50;0040;PBS_Server;Svr;tyrone-cluster;Scheduler was sent the command new
09/19/2014 01:23:20;0040;PBS_Server;Svr;tyrone-cluster;Scheduler was sent the command new
09/19/2014 01:23:51;0040;PBS_Server;Svr;tyrone-cluster;Scheduler was sent the command new
09/19/2014 01:24:20;0040;PBS_Server;Svr;tyrone-cluster;Scheduler was sent the command new
09/19/2014 01:24:50;0040;PBS_Server;Svr;tyrone-cluster;Scheduler was sent the command new
09/19/2014 01:25:21;0040;PBS_Server;Svr;tyrone-cluster;Scheduler was sent the command new
09/19/2014 01:25:50;0040;PBS_Server;Svr;tyrone-cluster;Scheduler was sent the command new
09/19/2014 01:26:20;0040;PBS_Server;Svr;tyrone-cluster;Scheduler was sent the command new
09/19/2014 01:26:51;0040;PBS_Server;Svr;tyrone-cluster;Scheduler was sent the command new
09/19/2014 01:27:20;0040;PBS_Server;Svr;tyrone-cluster;Scheduler was sent the command new
09/19/2014 01:27:39;0002;PBS_Server;Svr;PBS_Server;Torque Server Version = 3.0.5, loglevel = 0
09/19/2014 01:27:50;0040;PBS_Server;Svr;tyrone-cluster;Scheduler was sent the command new
09/19/2014 01:28:22;0040;PBS_Server;Svr;tyrone-cluster;Scheduler was sent the command new
09/19/2014 01:28:51;0040;PBS_Server;Svr;tyrone-cluster;Scheduler was sent the command new
09/19/2014 01:29:27;0040;PBS_Server;Svr;tyrone-cluster;Scheduler was sent the command new
09/19/2014 01:30:03;0040;PBS_Server;Svr;tyrone-cluster;Scheduler was sent the command new
09/19/2014 01:30:31;0040;PBS_Server;Svr;tyrone-cluster;Scheduler was sent the command new
09/19/2014 01:31:02;0040;PBS_Server;Svr;tyrone-cluster;Scheduler was sent the command new
09/19/2014 01:31:33;0040;PBS_Server;Svr;tyrone-cluster;Scheduler was sent the command new
09/19/2014 01:32:05;0040;PBS_Server;Svr;tyrone-cluster;Scheduler was sent the command new
09/19/2014 01:32:35;0040;PBS_Server;Svr;tyrone-cluster;Scheduler was sent the command new
09/19/2014 01:32:39;0002;PBS_Server;Svr;PBS_Server;Torque Server Version = 3.0.5, loglevel = 0
09/19/2014 01:33:03;0040;PBS_Server;Svr;tyrone-cluster;Scheduler was sent the command new
09/19/2014 01:33:35;0040;PBS_Server;Svr;tyrone-cluster;Scheduler was sent the command new
09/19/2014 01:34:05;0040;PBS_Server;Svr;tyrone-cluster;Scheduler was sent the command new
09/19/2014 01:34:35;0040;PBS_Server;Svr;tyrone-cluster;Scheduler was sent the command new
09/19/2014 01:35:06;0040;PBS_Server;Svr;tyrone-cluster;Scheduler was sent the command new
09/19/2014 01:35:35;0040;PBS_Server;Svr;tyrone-cluster;Scheduler was sent the command new
09/19/2014 01:36:05;0040;PBS_Server;Svr;tyrone-cluster;Scheduler was sent the command new
09/19/2014 01:36:35;0040;PBS_Server;Svr;tyrone-cluster;Scheduler was sent the command new
09/19/2014 01:37:05;0040;PBS_Server;Svr;tyrone-cluster;Scheduler was sent the command new
09/19/2014 01:37:35;0040;PBS_Server;Svr;tyrone-cluster;Scheduler was sent the command new
09/19/2014 01:37:39;0002;PBS_Server;Svr;PBS_Server;Torque Server Version = 3.0.5, loglevel = 0
09/19/2014 01:38:06;0040;PBS_Server;Svr;tyrone-cluster;Scheduler was sent the command new
09/19/2014 01:38:35;0040;PBS_Server;Svr;tyrone-cluster;Scheduler was sent the command new
09/19/2014 01:39:05;0040;PBS_Server;Svr;tyrone-cluster;Scheduler was sent the command new
09/19/2014 01:39:36;0040;PBS_Server;Svr;tyrone-cluster;Scheduler was sent the command new
09/19/2014 01:40:05;0040;PBS_Server;Svr;tyrone-cluster;Scheduler was sent the command new
09/19/2014 01:40:35;0040;PBS_Server;Svr;tyrone-cluster;Scheduler was sent the command new
09/19/2014 01:41:07;0040;PBS_Server;Svr;tyrone-cluster;Scheduler was sent the command new
09/19/2014 01:41:35;0040;PBS_Server;Svr;tyrone-cluster;Scheduler was sent the command new
09/19/2014 01:41:38;000d;PBS_Server;Job;42531.tyrone-cluster;Not sending email: User does not want mail of this type.
09/19/2014 01:41:38;0010;PBS_Server;Job;42531.tyrone-cluster;Exit_status=1 resources_used.cput=00:52:31 resources_used.mem=176128kb resources_used.vmem=1978844kb resources_used.walltime=00:55:00
09/19/2014 01:41:38;0008;PBS_Server;Job;NULL;on_job_exit valid pjob: 0x2dc4790 (substate=50)
09/19/2014 01:41:38;0008;PBS_Server;Job;NULL;on_job_exit valid pjob: 0x2dc4790 (substate=51)
09/19/2014 01:41:38;0008;PBS_Server;Job;NULL;on_job_exit valid pjob: 0x2dc4790 (substate=51)
09/19/2014 01:41:38;0008;PBS_Server;Job;NULL;on_job_exit valid pjob: 0x2dc4790 (substate=53)
09/19/2014 01:41:38;0100;PBS_Server;Job;42531.tyrone-cluster;dequeuing from qp256, state COMPLETE
09/19/2014 01:42:05;0040;PBS_Server;Svr;tyrone-cluster;Scheduler was sent the command new
09/19/2014 01:42:35;0040;PBS_Server;Svr;tyrone-cluster;Scheduler was sent the command new
09/19/2014 01:42:39;0002;PBS_Server;Svr;PBS_Server;Torque Server Version = 3.0.5, loglevel = 0
09/19/2014 01:43:05;0040;PBS_Server;Svr;tyrone-cluster;Scheduler was sent the command new
09/19/2014 01:43:35;0040;PBS_Server;Svr;tyrone-cluster;Scheduler was sent the command new
09/19/2014 01:44:05;0040;PBS_Server;Svr;tyrone-cluster;Scheduler was sent the command new
09/19/2014 01:44:35;0040;PBS_Server;Svr;tyrone-cluster;Scheduler was sent the command new
09/19/2014 01:45:05;0040;PBS_Server;Svr;tyrone-cluster;Scheduler was sent the command new
09/19/2014 01:45:35;0040;PBS_Server;Svr;tyrone-cluster;Scheduler was sent the command new
09/19/2014 01:46:05;0040;PBS_Server;Svr;tyrone-cluster;Scheduler was sent the command new
09/19/2014 01:46:35;0040;PBS_Server;Svr;tyrone-cluster;Scheduler was sent the command new
09/19/2014 01:47:05;0040;PBS_Server;Svr;tyrone-cluster;Scheduler was sent the command new
09/19/2014 01:47:35;0040;PBS_Server;Svr;tyrone-cluster;Scheduler was sent the command new
09/19/2014 01:47:39;0002;PBS_Server;Svr;PBS_Server;Torque Server Version = 3.0.5, loglevel = 0
09/19/2014 01:48:05;0040;PBS_Server;Svr;tyrone-cluster;Scheduler was sent the command new
09/19/2014 01:48:36;0040;PBS_Server;Svr;tyrone-cluster;Scheduler was sent the command new
09/19/2014 01:49:05;0040;PBS_Server;Svr;tyrone-cluster;Scheduler was sent the command new
09/19/2014 01:49:35;0040;PBS_Server;Svr;tyrone-cluster;Scheduler was sent the command new
09/19/2014 01:50:05;0040;PBS_Server;Svr;tyrone-cluster;Scheduler was sent the command new
09/19/2014 01:50:36;0040;PBS_Server;Svr;tyrone-cluster;Scheduler was sent the command new
09/19/2014 01:51:05;0040;PBS_Server;Svr;tyrone-cluster;Scheduler was sent the command new
09/19/2014 01:51:35;0040;PBS_Server;Svr;tyrone-cluster;Scheduler was sent the command new
09/19/2014 01:52:05;0040;PBS_Server;Svr;tyrone-cluster;Scheduler was sent the command new
09/19/2014 01:52:35;0040;PBS_Server;Svr;tyrone-cluster;Scheduler was sent the command new
09/19/2014 01:52:39;0002;PBS_Server;Svr;PBS_Server;Torque Server Version = 3.0.5, loglevel = 0
09/19/2014 01:53:05;0040;PBS_Server;Svr;tyrone-cluster;Scheduler was sent the command new
09/19/2014 01:53:36;0040;PBS_Server;Svr;tyrone-cluster;Scheduler was sent the command new
09/19/2014 01:54:05;0040;PBS_Server;Svr;tyrone-cluster;Scheduler was sent the command new
09/19/2014 01:54:35;0040;PBS_Server;Svr;tyrone-cluster;Scheduler was sent the command new
09/19/2014 01:55:05;0040;PBS_Server;Svr;tyrone-cluster;Scheduler was sent the command new
09/19/2014 01:55:35;0040;PBS_Server;Svr;tyrone-cluster;Scheduler was sent the command new
09/19/2014 01:56:05;0040;PBS_Server;Svr;tyrone-cluster;Scheduler was sent the command new
09/19/2014 01:56:36;0040;PBS_Server;Svr;tyrone-cluster;Scheduler was sent the command new
09/19/2014 01:57:05;0040;PBS_Server;Svr;tyrone-cluster;Scheduler was sent the command new
09/19/2014 01:57:35;0040;PBS_Server;Svr;tyrone-cluster;Scheduler was sent the command new
09/19/2014 01:57:39;0002;PBS_Server;Svr;PBS_Server;Torque Server Version = 3.0.5, loglevel = 0
09/19/2014 01:58:05;0040;PBS_Server;Svr;tyrone-cluster;Scheduler was sent the command new
09/19/2014 01:58:37;0040;PBS_Server;Svr;tyrone-cluster;Scheduler was sent the command new
09/19/2014 01:59:08;0040;PBS_Server;Svr;tyrone-cluster;Scheduler was sent the command new
09/19/2014 01:59:38;0040;PBS_Server;Svr;tyrone-cluster;Scheduler was sent the command new
09/19/2014 02:00:11;0040;PBS_Server;Svr;tyrone-cluster;Scheduler was sent the command new
09/19/2014 02:00:48;0040;PBS_Server;Svr;tyrone-cluster;Scheduler was sent the command new
09/19/2014 02:01:16;0040;PBS_Server;Svr;tyrone-cluster;Scheduler was sent the command new
09/19/2014 02:01:48;0040;PBS_Server;Svr;tyrone-cluster;Scheduler was sent the command new
09/19/2014 02:02:18;0040;PBS_Server;Svr;tyrone-cluster;Scheduler was sent the command new
09/19/2014 02:02:39;0002;PBS_Server;Svr;PBS_Server;Torque Server Version = 3.0.5, loglevel = 0
09/19/2014 02:02:50;0040;PBS_Server;Svr;tyrone-cluster;Scheduler was sent the command new
09/19/2014 02:03:20;0040;PBS_Server;Svr;tyrone-cluster;Scheduler was sent the command new
09/19/2014 02:03:48;0040;PBS_Server;Svr;tyrone-cluster;Scheduler was sent the command new
09/19/2014 02:04:20;0040;PBS_Server;Svr;tyrone-cluster;Scheduler was sent the command new
09/19/2014 02:04:51;0040;PBS_Server;Svr;tyrone-cluster;Scheduler was sent the command new
09/19/2014 02:05:21;0040;PBS_Server;Svr;tyrone-cluster;Scheduler was sent the command new
09/19/2014 02:05:53;0040;PBS_Server;Svr;tyrone-cluster;Scheduler was sent the command new
09/19/2014 02:06:22;0040;PBS_Server;Svr;tyrone-cluster;Scheduler was sent the command new
09/19/2014 02:06:56;0040;PBS_Server;Svr;tyrone-cluster;Scheduler was sent the command new
09/19/2014 02:07:31;0040;PBS_Server;Svr;tyrone-cluster;Scheduler was sent the command new
09/19/2014 02:07:39;0002;PBS_Server;Svr;PBS_Server;Torque Server Version = 3.0.5, loglevel = 0
09/19/2014 02:08:02;0040;PBS_Server;Svr;tyrone-cluster;Scheduler was sent the command new
09/19/2014 02:08:33;0040;PBS_Server;Svr;tyrone-cluster;Scheduler was sent the command new
09/19/2014 02:09:04;0040;PBS_Server;Svr;tyrone-cluster;Scheduler was sent the command new
09/19/2014 02:09:35;0040;PBS_Server;Svr;tyrone-cluster;Scheduler was sent the command new
09/19/2014 02:10:05;0040;PBS_Server;Svr;tyrone-cluster;Scheduler was sent the command new
09/19/2014 02:10:36;0040;PBS_Server;Svr;tyrone-cluster;Scheduler was sent the command new
09/19/2014 02:11:08;0040;PBS_Server;Svr;tyrone-cluster;Scheduler was sent the command new
09/19/2014 02:11:37;0040;PBS_Server;Svr;tyrone-cluster;Scheduler was sent the command new
09/19/2014 02:12:11;0040;PBS_Server;Svr;tyrone-cluster;Scheduler was sent the command new
09/19/2014 02:12:39;0002;PBS_Server;Svr;PBS_Server;Torque Server Version = 3.0.5, loglevel = 0
09/19/2014 02:12:44;0040;PBS_Server;Svr;tyrone-cluster;Scheduler was sent the command new
09/19/2014 02:13:15;0040;PBS_Server;Svr;tyrone-cluster;Scheduler was sent the command new
09/19/2014 02:13:48;0040;PBS_Server;Svr;tyrone-cluster;Scheduler was sent the command new
09/19/2014 02:14:19;0040;PBS_Server;Svr;tyrone-cluster;Scheduler was sent the command new
09/19/2014 02:14:50;0040;PBS_Server;Svr;tyrone-cluster;Scheduler was sent the command new
09/19/2014 02:15:20;0040;PBS_Server;Svr;tyrone-cluster;Scheduler was sent the command new
09/19/2014 02:15:51;0040;PBS_Server;Svr;tyrone-cluster;Scheduler was sent the command new
09/19/2014 02:16:23;0040;PBS_Server;Svr;tyrone-cluster;Scheduler was sent the command new
09/19/2014 02:16:52;0040;PBS_Server;Svr;tyrone-cluster;Scheduler was sent the command new
09/19/2014 02:17:26;0040;PBS_Server;Svr;tyrone-cluster;Scheduler was sent the command new
09/19/2014 02:17:39;0002;PBS_Server;Svr;PBS_Server;Torque Server Version = 3.0.5, loglevel = 0
09/19/2014 02:18:04;0040;PBS_Server;Svr;tyrone-cluster;Scheduler was sent the command new
09/19/2014 02:18:32;0040;PBS_Server;Svr;tyrone-cluster;Scheduler was sent the command new
09/19/2014 02:19:02;0040;PBS_Server;Svr;tyrone-cluster;Scheduler was sent the command new
09/19/2014 02:19:34;0040;PBS_Server;Svr;tyrone-cluster;Scheduler was sent the command new
09/19/2014 02:20:05;0040;PBS_Server;Svr;tyrone-cluster;Scheduler was sent the command new
09/19/2014 02:20:37;0040;PBS_Server;Svr;tyrone-cluster;Scheduler was sent the command new
09/19/2014 02:21:06;0040;PBS_Server;Svr;tyrone-cluster;Scheduler was sent the command new
09/19/2014 02:21:37;0040;PBS_Server;Svr;tyrone-cluster;Scheduler was sent the command new
09/19/2014 02:22:07;0040;PBS_Server;Svr;tyrone-cluster;Scheduler was sent the command new
09/19/2014 02:22:39;0002;PBS_Server;Svr;PBS_Server;Torque Server Version = 3.0.5, loglevel = 0
09/19/2014 02:22:40;0040;PBS_Server;Svr;tyrone-cluster;Scheduler was sent the command new
09/19/2014 02:23:19;0040;PBS_Server;Svr;tyrone-cluster;Scheduler was sent the command new
09/19/2014 02:23:47;0040;PBS_Server;Svr;tyrone-cluster;Scheduler was sent the command new
09/19/2014 02:24:17;0040;PBS_Server;Svr;tyrone-cluster;Scheduler was sent the command new
09/19/2014 02:24:49;0040;PBS_Server;Svr;tyrone-cluster;Scheduler was sent the command new
09/19/2014 02:25:20;0040;PBS_Server;Svr;tyrone-cluster;Scheduler was sent the command new
09/19/2014 02:25:50;0040;PBS_Server;Svr;tyrone-cluster;Scheduler was sent the command new
09/19/2014 02:26:19;0040;PBS_Server;Svr;tyrone-cluster;Scheduler was sent the command new
09/19/2014 02:26:50;0040;PBS_Server;Svr;tyrone-cluster;Scheduler was sent the command new
09/19/2014 02:27:22;0040;PBS_Server;Svr;tyrone-cluster;Scheduler was sent the command new
09/19/2014 02:27:39;0002;PBS_Server;Svr;PBS_Server;Torque Server Version = 3.0.5, loglevel = 0
09/19/2014 02:27:51;0040;PBS_Server;Svr;tyrone-cluster;Scheduler was sent the command new
09/19/2014 02:28:23;0040;PBS_Server;Svr;tyrone-cluster;Scheduler was sent the command new
09/19/2014 02:28:52;0040;PBS_Server;Svr;tyrone-cluster;Scheduler was sent the command new
09/19/2014 02:29:26;0040;PBS_Server;Svr;tyrone-cluster;Scheduler was sent the command new
09/19/2014 02:30:04;0040;PBS_Server;Svr;tyrone-cluster;Scheduler was sent the command new
09/19/2014 02:30:32;0040;PBS_Server;Svr;tyrone-cluster;Scheduler was sent the command new
09/19/2014 02:31:02;0040;PBS_Server;Svr;tyrone-cluster;Scheduler was sent the command new
09/19/2014 02:31:34;0040;PBS_Server;Svr;tyrone-cluster;Scheduler was sent the command new
09/19/2014 02:32:05;0040;PBS_Server;Svr;tyrone-cluster;Scheduler was sent the command new
09/19/2014 02:32:36;0040;PBS_Server;Svr;tyrone-cluster;Scheduler was sent the command new
09/19/2014 02:32:39;0002;PBS_Server;Svr;PBS_Server;Torque Server Version = 3.0.5, loglevel = 0
09/19/2014 02:33:06;0040;PBS_Server;Svr;tyrone-cluster;Scheduler was sent the command new
09/19/2014 02:33:38;0040;PBS_Server;Svr;tyrone-cluster;Scheduler was sent the command new
09/19/2014 02:34:07;0040;PBS_Server;Svr;tyrone-cluster;Scheduler was sent the command new
09/19/2014 02:34:36;0040;PBS_Server;Svr;tyrone-cluster;Scheduler was sent the command new
09/19/2014 02:35:07;0040;PBS_Server;Svr;tyrone-cluster;Scheduler was sent the command new
09/19/2014 02:35:37;0040;PBS_Server;Svr;tyrone-cluster;Scheduler was sent the command new
09/19/2014 02:36:06;0040;PBS_Server;Svr;tyrone-cluster;Scheduler was sent the command new
09/19/2014 02:36:22;000d;PBS_Server;Job;42509.tyrone-cluster;Not sending email: User does not want mail of this type.
09/19/2014 02:36:22;0010;PBS_Server;Job;42509.tyrone-cluster;Exit_status=143 resources_used.cput=63:36:30 resources_used.mem=434616kb resources_used.vmem=12107920kb resources_used.walltime=02:00:40
09/19/2014 02:36:22;0008;PBS_Server;Job;NULL;on_job_exit valid pjob: 0x2dfb870 (substate=50)
09/19/2014 02:36:22;0008;PBS_Server;Job;NULL;on_job_exit valid pjob: 0x2dfb870 (substate=51)
09/19/2014 02:36:25;0008;PBS_Server;Job;NULL;on_job_exit valid pjob: 0x2dfb870 (substate=51)
09/19/2014 02:36:25;0008;PBS_Server;Job;NULL;on_job_exit valid pjob: 0x2dfb870 (substate=53)
09/19/2014 02:36:25;0100;PBS_Server;Job;42509.tyrone-cluster;dequeuing from idqueue, state COMPLETE
09/19/2014 02:36:25;0040;PBS_Server;Svr;tyrone-cluster;Scheduler was sent the command term
09/19/2014 02:36:26;0008;PBS_Server;Job;42510.tyrone-cluster;Job Modified at request of Scheduler@tyrone-cluster
09/19/2014 02:36:26;0008;PBS_Server;Job;42510.tyrone-cluster;Job Run at request of Scheduler@tyrone-cluster
09/19/2014 02:36:26;0040;PBS_Server;Svr;tyrone-cluster;Scheduler was sent the command recyc
09/19/2014 02:36:26;000d;PBS_Server;Job;42510.tyrone-cluster;Not sending email: User does not want mail of this type.
09/19/2014 02:36:38;0040;PBS_Server;Svr;tyrone-cluster;Scheduler was sent the command new
09/19/2014 02:37:07;0040;PBS_Server;Svr;tyrone-cluster;Scheduler was sent the command new
09/19/2014 02:37:39;0002;PBS_Server;Svr;PBS_Server;Torque Server Version = 3.0.5, loglevel = 0
09/19/2014 02:37:40;0040;PBS_Server;Svr;tyrone-cluster;Scheduler was sent the command new
09/19/2014 02:38:19;0040;PBS_Server;Svr;tyrone-cluster;Scheduler was sent the command new
09/19/2014 02:38:47;0040;PBS_Server;Svr;tyrone-cluster;Scheduler was sent the command new
09/19/2014 02:39:17;0040;PBS_Server;Svr;tyrone-cluster;Scheduler was sent the command new
09/19/2014 02:39:49;0040;PBS_Server;Svr;tyrone-cluster;Scheduler was sent the command new
09/19/2014 02:40:20;0040;PBS_Server;Svr;tyrone-cluster;Scheduler was sent the command new
09/19/2014 02:40:50;0040;PBS_Server;Svr;tyrone-cluster;Scheduler was sent the command new
09/19/2014 02:41:19;0040;PBS_Server;Svr;tyrone-cluster;Scheduler was sent the command new
09/19/2014 02:41:50;0040;PBS_Server;Svr;tyrone-cluster;Scheduler was sent the command new
09/19/2014 02:42:20;0040;PBS_Server;Svr;tyrone-cluster;Scheduler was sent the command new
09/19/2014 02:42:39;0002;PBS_Server;Svr;PBS_Server;Torque Server Version = 3.0.5, loglevel = 0
09/19/2014 02:42:49;0040;PBS_Server;Svr;tyrone-cluster;Scheduler was sent the command new
09/19/2014 02:43:20;0040;PBS_Server;Svr;tyrone-cluster;Scheduler was sent the command new
09/19/2014 02:43:51;0040;PBS_Server;Svr;tyrone-cluster;Scheduler was sent the command new
09/19/2014 02:44:21;0040;PBS_Server;Svr;tyrone-cluster;Scheduler was sent the command new
09/19/2014 02:44:58;0040;PBS_Server;Svr;tyrone-cluster;Scheduler was sent the command new
09/19/2014 02:45:22;0040;PBS_Server;Svr;tyrone-cluster;Scheduler was sent the command new
09/19/2014 02:45:56;0040;PBS_Server;Svr;tyrone-cluster;Scheduler was sent the command new
09/19/2014 02:46:34;0040;PBS_Server;Svr;tyrone-cluster;Scheduler was sent the command new
09/19/2014 02:47:02;0040;PBS_Server;Svr;tyrone-cluster;Scheduler was sent the command new
09/19/2014 02:47:31;0040;PBS_Server;Svr;tyrone-cluster;Scheduler was sent the command new
09/19/2014 02:47:39;0002;PBS_Server;Svr;PBS_Server;Torque Server Version = 3.0.5, loglevel = 0
09/19/2014 02:48:04;0040;PBS_Server;Svr;tyrone-cluster;Scheduler was sent the command new
09/19/2014 02:48:35;0040;PBS_Server;Svr;tyrone-cluster;Scheduler was sent the command new
09/19/2014 02:49:06;0040;PBS_Server;Svr;tyrone-cluster;Scheduler was sent the command new
09/19/2014 02:49:36;0040;PBS_Server;Svr;tyrone-cluster;Scheduler was sent the command new
09/19/2014 02:50:12;0040;PBS_Server;Svr;tyrone-cluster;Scheduler was sent the command new
09/19/2014 02:50:37;0040;PBS_Server;Svr;tyrone-cluster;Scheduler was sent the command new
09/19/2014 02:51:11;0040;PBS_Server;Svr;tyrone-cluster;Scheduler was sent the command new
09/19/2014 02:51:49;0040;PBS_Server;Svr;tyrone-cluster;Scheduler was sent the command new
09/19/2014 02:52:17;0040;PBS_Server;Svr;tyrone-cluster;Scheduler was sent the command new
09/19/2014 02:52:39;0002;PBS_Server;Svr;PBS_Server;Torque Server Version = 3.0.5, loglevel = 0
09/19/2014 02:52:47;0040;PBS_Server;Svr;tyrone-cluster;Scheduler was sent the command new
09/19/2014 02:53:19;0040;PBS_Server;Svr;tyrone-cluster;Scheduler was sent the command new
09/19/2014 02:53:50;0040;PBS_Server;Svr;tyrone-cluster;Scheduler was sent the command new
09/19/2014 02:54:21;0040;PBS_Server;Svr;tyrone-cluster;Scheduler was sent the command new
09/19/2014 02:54:51;0040;PBS_Server;Svr;tyrone-cluster;Scheduler was sent the command new
09/19/2014 02:55:28;0040;PBS_Server;Svr;tyrone-cluster;Scheduler was sent the command new
09/19/2014 02:55:54;0040;PBS_Server;Svr;tyrone-cluster;Scheduler was sent the command new
09/19/2014 02:56:25;0040;PBS_Server;Svr;tyrone-cluster;Scheduler was sent the command new
09/19/2014 02:57:04;0040;PBS_Server;Svr;tyrone-cluster;Scheduler was sent the command new
09/19/2014 02:57:31;0040;PBS_Server;Svr;tyrone-cluster;Scheduler was sent the command new
09/19/2014 02:57:39;0002;PBS_Server;Svr;PBS_Server;Torque Server Version = 3.0.5, loglevel = 0
09/19/2014 02:58:02;0040;PBS_Server;Svr;tyrone-cluster;Scheduler was sent the command new
09/19/2014 02:58:34;0040;PBS_Server;Svr;tyrone-cluster;Scheduler was sent the command new
09/19/2014 02:59:05;0040;PBS_Server;Svr;tyrone-cluster;Scheduler was sent the command new
09/19/2014 02:59:35;0040;PBS_Server;Svr;tyrone-cluster;Scheduler was sent the command new
09/19/2014 03:00:04;0040;PBS_Server;Svr;tyrone-cluster;Scheduler was sent the command new
09/19/2014 03:00:35;0040;PBS_Server;Svr;tyrone-cluster;Scheduler was sent the command new
09/19/2014 03:01:05;0040;PBS_Server;Svr;tyrone-cluster;Scheduler was sent the command new
09/19/2014 03:01:36;0040;PBS_Server;Svr;tyrone-cluster;Scheduler was sent the command new
09/19/2014 03:02:08;0040;PBS_Server;Svr;tyrone-cluster;Scheduler was sent the command new
09/19/2014 03:02:37;0040;PBS_Server;Svr;tyrone-cluster;Scheduler was sent the command new
09/19/2014 03:02:39;0002;PBS_Server;Svr;PBS_Server;Torque Server Version = 3.0.5, loglevel = 0
09/19/2014 03:03:06;0040;PBS_Server;Svr;tyrone-cluster;Scheduler was sent the command new
09/19/2014 03:03:38;0040;PBS_Server;Svr;tyrone-cluster;Scheduler was sent the command new
09/19/2014 03:04:07;0040;PBS_Server;Svr;tyrone-cluster;Scheduler was sent the command new
09/19/2014 03:04:36;0040;PBS_Server;Svr;tyrone-cluster;Scheduler was sent the command new
09/19/2014 03:05:08;0040;PBS_Server;Svr;tyrone-cluster;Scheduler was sent the command new
09/19/2014 03:05:37;0040;PBS_Server;Svr;tyrone-cluster;Scheduler was sent the command new
09/19/2014 03:06:06;0040;PBS_Server;Svr;tyrone-cluster;Scheduler was sent the command new
09/19/2014 03:06:43;0040;PBS_Server;Svr;tyrone-cluster;Scheduler was sent the command new
09/19/2014 03:07:10;0040;PBS_Server;Svr;tyrone-cluster;Scheduler was sent the command new
09/19/2014 03:07:39;0002;PBS_Server;Svr;PBS_Server;Torque Server Version = 3.0.5, loglevel = 0
09/19/2014 03:07:40;0040;PBS_Server;Svr;tyrone-cluster;Scheduler was sent the command new
09/19/2014 03:08:19;0040;PBS_Server;Svr;tyrone-cluster;Scheduler was sent the command new
09/19/2014 03:08:47;0040;PBS_Server;Svr;tyrone-cluster;Scheduler was sent the command new
09/19/2014 03:09:17;0040;PBS_Server;Svr;tyrone-cluster;Scheduler was sent the command new
09/19/2014 03:09:49;0040;PBS_Server;Svr;tyrone-cluster;Scheduler was sent the command new
09/19/2014 03:10:20;0040;PBS_Server;Svr;tyrone-cluster;Scheduler was sent the command new
09/19/2014 03:10:50;0040;PBS_Server;Svr;tyrone-cluster;Scheduler was sent the command new
09/19/2014 03:11:19;0040;PBS_Server;Svr;tyrone-cluster;Scheduler was sent the command new
09/19/2014 03:11:50;0040;PBS_Server;Svr;tyrone-cluster;Scheduler was sent the command new
09/19/2014 03:12:20;0040;PBS_Server;Svr;tyrone-cluster;Scheduler was sent the command new
09/19/2014 03:12:39;0002;PBS_Server;Svr;PBS_Server;Torque Server Version = 3.0.5, loglevel = 0
09/19/2014 03:12:49;0040;PBS_Server;Svr;tyrone-cluster;Scheduler was sent the command new
09/19/2014 03:13:20;0040;PBS_Server;Svr;tyrone-cluster;Scheduler was sent the command new
09/19/2014 03:13:50;0040;PBS_Server;Svr;tyrone-cluster;Scheduler was sent the command new
09/19/2014 03:14:21;0040;PBS_Server;Svr;tyrone-cluster;Scheduler was sent the command new
09/19/2014 03:14:58;0040;PBS_Server;Svr;tyrone-cluster;Scheduler was sent the command new
09/19/2014 03:15:23;0040;PBS_Server;Svr;tyrone-cluster;Scheduler was sent the command new
09/19/2014 03:15:56;0040;PBS_Server;Svr;tyrone-cluster;Scheduler was sent the command new
09/19/2014 03:16:34;0040;PBS_Server;Svr;tyrone-cluster;Scheduler was sent the command new
09/19/2014 03:17:02;0040;PBS_Server;Svr;tyrone-cluster;Scheduler was sent the command new
09/19/2014 03:17:31;0040;PBS_Server;Svr;tyrone-cluster;Scheduler was sent the command new
09/19/2014 03:17:39;0002;PBS_Server;Svr;PBS_Server;Torque Server Version = 3.0.5, loglevel = 0
09/19/2014 03:18:04;0040;PBS_Server;Svr;tyrone-cluster;Scheduler was sent the command new
09/19/2014 03:18:34;0040;PBS_Server;Svr;tyrone-cluster;Scheduler was sent the command new
09/19/2014 03:19:05;0040;PBS_Server;Svr;tyrone-cluster;Scheduler was sent the command new
09/19/2014 03:19:34;0040;PBS_Server;Svr;tyrone-cluster;Scheduler was sent the command new
09/19/2014 03:20:05;0040;PBS_Server;Svr;tyrone-cluster;Scheduler was sent the command new
09/19/2014 03:20:35;0040;PBS_Server;Svr;tyrone-cluster;Scheduler was sent the command new
09/19/2014 03:21:06;0040;PBS_Server;Svr;tyrone-cluster;Scheduler was sent the command new
09/19/2014 03:21:43;0040;PBS_Server;Svr;tyrone-cluster;Scheduler was sent the command new
09/19/2014 03:22:07;0040;PBS_Server;Svr;tyrone-cluster;Scheduler was sent the command new
09/19/2014 03:22:39;0002;PBS_Server;Svr;PBS_Server;Torque Server Version = 3.0.5, loglevel = 0
09/19/2014 03:22:41;0040;PBS_Server;Svr;tyrone-cluster;Scheduler was sent the command new
09/19/2014 03:23:19;0040;PBS_Server;Svr;tyrone-cluster;Scheduler was sent the command new
09/19/2014 03:23:47;0040;PBS_Server;Svr;tyrone-cluster;Scheduler was sent the command new
09/19/2014 03:24:16;0040;PBS_Server;Svr;tyrone-cluster;Scheduler was sent the command new
09/19/2014 03:24:49;0040;PBS_Server;Svr;tyrone-cluster;Scheduler was sent the command new
09/19/2014 03:25:19;0040;PBS_Server;Svr;tyrone-cluster;Scheduler was sent the command new
09/19/2014 03:25:50;0040;PBS_Server;Svr;tyrone-cluster;Scheduler was sent the command new
09/19/2014 03:26:19;0040;PBS_Server;Svr;tyrone-cluster;Scheduler was sent the command new
09/19/2014 03:26:50;0040;PBS_Server;Svr;tyrone-cluster;Scheduler was sent the command new
09/19/2014 03:27:20;0040;PBS_Server;Svr;tyrone-cluster;Scheduler was sent the command new
09/19/2014 03:27:39;0002;PBS_Server;Svr;PBS_Server;Torque Server Version = 3.0.5, loglevel = 0
09/19/2014 03:27:49;0040;PBS_Server;Svr;tyrone-cluster;Scheduler was sent the command new
09/19/2014 03:28:20;0040;PBS_Server;Svr;tyrone-cluster;Scheduler was sent the command new
09/19/2014 03:28:50;0040;PBS_Server;Svr;tyrone-cluster;Scheduler was sent the command new
09/19/2014 03:29:21;0040;PBS_Server;Svr;tyrone-cluster;Scheduler was sent the command new
09/19/2014 03:29:58;0040;PBS_Server;Svr;tyrone-cluster;Scheduler was sent the command new
09/19/2014 03:30:22;0040;PBS_Server;Svr;tyrone-cluster;Scheduler was sent the command new
09/19/2014 03:30:55;0040;PBS_Server;Svr;tyrone-cluster;Scheduler was sent the command new
09/19/2014 03:31:34;0040;PBS_Server;Svr;tyrone-cluster;Scheduler was sent the command new
09/19/2014 03:32:02;0040;PBS_Server;Svr;tyrone-cluster;Scheduler was sent the command new
09/19/2014 03:32:31;0040;PBS_Server;Svr;tyrone-cluster;Scheduler was sent the command new
09/19/2014 03:32:39;0002;PBS_Server;Svr;PBS_Server;Torque Server Version = 3.0.5, loglevel = 0
09/19/2014 03:33:04;0040;PBS_Server;Svr;tyrone-cluster;Scheduler was sent the command new
09/19/2014 03:33:35;0040;PBS_Server;Svr;tyrone-cluster;Scheduler was sent the command new
09/19/2014 03:34:05;0040;PBS_Server;Svr;tyrone-cluster;Scheduler was sent the command new
09/19/2014 03:34:36;0040;PBS_Server;Svr;tyrone-cluster;Scheduler was sent the command new
09/19/2014 03:35:12;0040;PBS_Server;Svr;tyrone-cluster;Scheduler was sent the command new
09/19/2014 03:35:37;0040;PBS_Server;Svr;tyrone-cluster;Scheduler was sent the command new
09/19/2014 03:36:11;0040;PBS_Server;Svr;tyrone-cluster;Scheduler was sent the command new
09/19/2014 03:36:49;0040;PBS_Server;Svr;tyrone-cluster;Scheduler was sent the command new
09/19/2014 03:37:16;0040;PBS_Server;Svr;tyrone-cluster;Scheduler was sent the command new
09/19/2014 03:37:39;0002;PBS_Server;Svr;PBS_Server;Torque Server Version = 3.0.5, loglevel = 0
09/19/2014 03:37:48;0040;PBS_Server;Svr;tyrone-cluster;Scheduler was sent the command new
09/19/2014 03:38:19;0040;PBS_Server;Svr;tyrone-cluster;Scheduler was sent the command new
09/19/2014 03:38:50;0040;PBS_Server;Svr;tyrone-cluster;Scheduler was sent the command new
09/19/2014 03:39:20;0040;PBS_Server;Svr;tyrone-cluster;Scheduler was sent the command new
09/19/2014 03:39:49;0040;PBS_Server;Svr;tyrone-cluster;Scheduler was sent the command new
09/19/2014 03:40:20;0040;PBS_Server;Svr;tyrone-cluster;Scheduler was sent the command new
09/19/2014 03:40:50;0040;PBS_Server;Svr;tyrone-cluster;Scheduler was sent the command new
09/19/2014 03:41:19;0040;PBS_Server;Svr;tyrone-cluster;Scheduler was sent the command new
09/19/2014 03:41:49;0040;PBS_Server;Svr;tyrone-cluster;Scheduler was sent the command new
09/19/2014 03:42:19;0040;PBS_Server;Svr;tyrone-cluster;Scheduler was sent the command new
09/19/2014 03:42:40;0002;PBS_Server;Svr;PBS_Server;Torque Server Version = 3.0.5, loglevel = 0
09/19/2014 03:42:50;0040;PBS_Server;Svr;tyrone-cluster;Scheduler was sent the command new
09/19/2014 03:43:19;0040;PBS_Server;Svr;tyrone-cluster;Scheduler was sent the command new
09/19/2014 03:43:50;0040;PBS_Server;Svr;tyrone-cluster;Scheduler was sent the command new
09/19/2014 03:44:21;0040;PBS_Server;Svr;tyrone-cluster;Scheduler was sent the command new
09/19/2014 03:44:57;0040;PBS_Server;Svr;tyrone-cluster;Scheduler was sent the command new
09/19/2014 03:45:22;0040;PBS_Server;Svr;tyrone-cluster;Scheduler was sent the command new
09/19/2014 03:45:56;0040;PBS_Server;Svr;tyrone-cluster;Scheduler was sent the command new
09/19/2014 03:46:34;0040;PBS_Server;Svr;tyrone-cluster;Scheduler was sent the command new
09/19/2014 03:47:02;0040;PBS_Server;Svr;tyrone-cluster;Scheduler was sent the command new
09/19/2014 03:47:33;0040;PBS_Server;Svr;tyrone-cluster;Scheduler was sent the command new
09/19/2014 03:47:40;0002;PBS_Server;Svr;PBS_Server;Torque Server Version = 3.0.5, loglevel = 0
09/19/2014 03:48:04;0040;PBS_Server;Svr;tyrone-cluster;Scheduler was sent the command new
09/19/2014 03:48:34;0040;PBS_Server;Svr;tyrone-cluster;Scheduler was sent the command new
09/19/2014 03:49:05;0040;PBS_Server;Svr;tyrone-cluster;Scheduler was sent the command new
09/19/2014 03:49:36;0040;PBS_Server;Svr;tyrone-cluster;Scheduler was sent the command new
09/19/2014 03:50:12;0040;PBS_Server;Svr;tyrone-cluster;Scheduler was sent the command new
09/19/2014 03:50:39;0040;PBS_Server;Svr;tyrone-cluster;Scheduler was sent the command new
09/19/2014 03:51:15;0040;PBS_Server;Svr;tyrone-cluster;Scheduler was sent the command new
09/19/2014 03:51:49;0040;PBS_Server;Svr;tyrone-cluster;Scheduler was sent the command new
09/19/2014 03:52:16;0040;PBS_Server;Svr;tyrone-cluster;Scheduler was sent the command new
09/19/2014 03:52:40;0002;PBS_Server;Svr;PBS_Server;Torque Server Version = 3.0.5, loglevel = 0
09/19/2014 03:52:46;0040;PBS_Server;Svr;tyrone-cluster;Scheduler was sent the command new
09/19/2014 03:53:19;0040;PBS_Server;Svr;tyrone-cluster;Scheduler was sent the command new
09/19/2014 03:53:50;0040;PBS_Server;Svr;tyrone-cluster;Scheduler was sent the command new
09/19/2014 03:54:20;0040;PBS_Server;Svr;tyrone-cluster;Scheduler was sent the command new
09/19/2014 03:54:49;0040;PBS_Server;Svr;tyrone-cluster;Scheduler was sent the command new
09/19/2014 03:55:20;0040;PBS_Server;Svr;tyrone-cluster;Scheduler was sent the command new
09/19/2014 03:55:50;0040;PBS_Server;Svr;tyrone-cluster;Scheduler was sent the command new
09/19/2014 03:56:20;0040;PBS_Server;Svr;tyrone-cluster;Scheduler was sent the command new
09/19/2014 03:56:50;0040;PBS_Server;Svr;tyrone-cluster;Scheduler was sent the command new
09/19/2014 03:57:20;0040;PBS_Server;Svr;tyrone-cluster;Scheduler was sent the command new
09/19/2014 03:57:40;0002;PBS_Server;Svr;PBS_Server;Torque Server Version = 3.0.5, loglevel = 0
09/19/2014 03:57:49;0040;PBS_Server;Svr;tyrone-cluster;Scheduler was sent the command new
09/19/2014 03:58:19;0040;PBS_Server;Svr;tyrone-cluster;Scheduler was sent the command new
09/19/2014 03:58:50;0040;PBS_Server;Svr;tyrone-cluster;Scheduler was sent the command new
09/19/2014 03:59:20;0040;PBS_Server;Svr;tyrone-cluster;Scheduler was sent the command new
09/19/2014 03:59:53;0040;PBS_Server;Svr;tyrone-cluster;Scheduler was sent the command new
09/19/2014 04:00:22;0040;PBS_Server;Svr;tyrone-cluster;Scheduler was sent the command new
09/19/2014 04:00:51;0040;PBS_Server;Svr;tyrone-cluster;Scheduler was sent the command new
09/19/2014 04:01:28;0040;PBS_Server;Svr;tyrone-cluster;Scheduler was sent the command new
09/19/2014 04:01:54;0040;PBS_Server;Svr;tyrone-cluster;Scheduler was sent the command new
09/19/2014 04:02:25;0040;PBS_Server;Svr;tyrone-cluster;Scheduler was sent the command new
09/19/2014 04:02:40;0002;PBS_Server;Svr;PBS_Server;Torque Server Version = 3.0.5, loglevel = 0
09/19/2014 04:03:04;0040;PBS_Server;Svr;tyrone-cluster;Scheduler was sent the command new
09/19/2014 04:03:31;0040;PBS_Server;Svr;tyrone-cluster;Scheduler was sent the command new
09/19/2014 04:04:01;0040;PBS_Server;Svr;tyrone-cluster;Scheduler was sent the command new
09/19/2014 04:04:34;0040;PBS_Server;Svr;tyrone-cluster;Scheduler was sent the command new
09/19/2014 04:05:04;0040;PBS_Server;Svr;tyrone-cluster;Scheduler was sent the command new
09/19/2014 04:05:35;0040;PBS_Server;Svr;tyrone-cluster;Scheduler was sent the command new
09/19/2014 04:06:04;0040;PBS_Server;Svr;tyrone-cluster;Scheduler was sent the command new
09/19/2014 04:06:34;0040;PBS_Server;Svr;tyrone-cluster;Scheduler was sent the command new
09/19/2014 04:07:05;0040;PBS_Server;Svr;tyrone-cluster;Scheduler was sent the command new
09/19/2014 04:07:34;0040;PBS_Server;Svr;tyrone-cluster;Scheduler was sent the command new
09/19/2014 04:07:40;0002;PBS_Server;Svr;PBS_Server;Torque Server Version = 3.0.5, loglevel = 0
09/19/2014 04:08:05;0040;PBS_Server;Svr;tyrone-cluster;Scheduler was sent the command new
09/19/2014 04:08:35;0040;PBS_Server;Svr;tyrone-cluster;Scheduler was sent the command new
09/19/2014 04:09:04;0040;PBS_Server;Svr;tyrone-cluster;Scheduler was sent the command new
09/19/2014 04:09:35;0040;PBS_Server;Svr;tyrone-cluster;Scheduler was sent the command new
09/19/2014 04:10:05;0040;PBS_Server;Svr;tyrone-cluster;Scheduler was sent the command new
09/19/2014 04:10:34;0040;PBS_Server;Svr;tyrone-cluster;Scheduler was sent the command new
09/19/2014 04:11:04;0040;PBS_Server;Svr;tyrone-cluster;Scheduler was sent the command new
09/19/2014 04:11:37;0040;PBS_Server;Svr;tyrone-cluster;Scheduler was sent the command new
09/19/2014 04:12:06;0040;PBS_Server;Svr;tyrone-cluster;Scheduler was sent the command new
09/19/2014 04:12:40;0002;PBS_Server;Svr;PBS_Server;Torque Server Version = 3.0.5, loglevel = 0
09/19/2014 04:12:40;0040;PBS_Server;Svr;tyrone-cluster;Scheduler was sent the command new
09/19/2014 04:13:09;0040;PBS_Server;Svr;tyrone-cluster;Scheduler was sent the command new
09/19/2014 04:13:44;0040;PBS_Server;Svr;tyrone-cluster;Scheduler was sent the command new
09/19/2014 04:14:19;0040;PBS_Server;Svr;tyrone-cluster;Scheduler was sent the command new
09/19/2014 04:14:46;0040;PBS_Server;Svr;tyrone-cluster;Scheduler was sent the command new
09/19/2014 04:15:15;0040;PBS_Server;Svr;tyrone-cluster;Scheduler was sent the command new
09/19/2014 04:15:49;0040;PBS_Server;Svr;tyrone-cluster;Scheduler was sent the command new
09/19/2014 04:16:20;0040;PBS_Server;Svr;tyrone-cluster;Scheduler was sent the command new
09/19/2014 04:16:50;0040;PBS_Server;Svr;tyrone-cluster;Scheduler was sent the command new
09/19/2014 04:17:21;0040;PBS_Server;Svr;tyrone-cluster;Scheduler was sent the command new
09/19/2014 04:17:40;0002;PBS_Server;Svr;PBS_Server;Torque Server Version = 3.0.5, loglevel = 0
09/19/2014 04:17:57;0040;PBS_Server;Svr;tyrone-cluster;Scheduler was sent the command new
09/19/2014 04:18:22;0040;PBS_Server;Svr;tyrone-cluster;Scheduler was sent the command new
09/19/2014 04:18:55;0040;PBS_Server;Svr;tyrone-cluster;Scheduler was sent the command new
09/19/2014 04:19:35;0040;PBS_Server;Svr;tyrone-cluster;Scheduler was sent the command new
09/19/2014 04:20:01;0040;PBS_Server;Svr;tyrone-cluster;Scheduler was sent the command new
09/19/2014 04:20:30;0040;PBS_Server;Svr;tyrone-cluster;Scheduler was sent the command new
09/19/2014 04:21:04;0040;PBS_Server;Svr;tyrone-cluster;Scheduler was sent the command new
09/19/2014 04:21:35;0040;PBS_Server;Svr;tyrone-cluster;Scheduler was sent the command new
09/19/2014 04:22:05;0040;PBS_Server;Svr;tyrone-cluster;Scheduler was sent the command new
09/19/2014 04:22:36;0040;PBS_Server;Svr;tyrone-cluster;Scheduler was sent the command new
09/19/2014 04:22:40;0002;PBS_Server;Svr;PBS_Server;Torque Server Version = 3.0.5, loglevel = 0
09/19/2014 04:23:12;0040;PBS_Server;Svr;tyrone-cluster;Scheduler was sent the command new
09/19/2014 04:23:37;0040;PBS_Server;Svr;tyrone-cluster;Scheduler was sent the command new
09/19/2014 04:24:09;0040;PBS_Server;Svr;tyrone-cluster;Scheduler was sent the command new
09/19/2014 04:24:49;0040;PBS_Server;Svr;tyrone-cluster;Scheduler was sent the command new
09/19/2014 04:25:13;0040;PBS_Server;Svr;tyrone-cluster;Scheduler was sent the command new
09/19/2014 04:25:45;0040;PBS_Server;Svr;tyrone-cluster;Scheduler was sent the command new
09/19/2014 04:26:19;0040;PBS_Server;Svr;tyrone-cluster;Scheduler was sent the command new
09/19/2014 04:26:49;0040;PBS_Server;Svr;tyrone-cluster;Scheduler was sent the command new
09/19/2014 04:27:20;0040;PBS_Server;Svr;tyrone-cluster;Scheduler was sent the command new
09/19/2014 04:27:40;0002;PBS_Server;Svr;PBS_Server;Torque Server Version = 3.0.5, loglevel = 0
09/19/2014 04:27:49;0040;PBS_Server;Svr;tyrone-cluster;Scheduler was sent the command new
09/19/2014 04:28:19;0040;PBS_Server;Svr;tyrone-cluster;Scheduler was sent the command new
09/19/2014 04:28:50;0040;PBS_Server;Svr;tyrone-cluster;Scheduler was sent the command new
09/19/2014 04:29:19;0040;PBS_Server;Svr;tyrone-cluster;Scheduler was sent the command new
09/19/2014 04:29:49;0040;PBS_Server;Svr;tyrone-cluster;Scheduler was sent the command new
09/19/2014 04:30:20;0040;PBS_Server;Svr;tyrone-cluster;Scheduler was sent the command new
09/19/2014 04:30:51;0040;PBS_Server;Svr;tyrone-cluster;Scheduler was sent the command new
09/19/2014 04:31:27;0040;PBS_Server;Svr;tyrone-cluster;Scheduler was sent the command new
09/19/2014 04:31:52;0040;PBS_Server;Svr;tyrone-cluster;Scheduler was sent the command new
09/19/2014 04:32:25;0040;PBS_Server;Svr;tyrone-cluster;Scheduler was sent the command new
09/19/2014 04:32:40;0002;PBS_Server;Svr;PBS_Server;Torque Server Version = 3.0.5, loglevel = 0
09/19/2014 04:32:58;0040;PBS_Server;Svr;tyrone-cluster;Scheduler was sent the command new
09/19/2014 04:33:25;0040;PBS_Server;Svr;tyrone-cluster;Scheduler was sent the command new
09/19/2014 04:33:59;0040;PBS_Server;Svr;tyrone-cluster;Scheduler was sent the command new
09/19/2014 04:34:34;0040;PBS_Server;Svr;tyrone-cluster;Scheduler was sent the command new
09/19/2014 04:35:01;0040;PBS_Server;Svr;tyrone-cluster;Scheduler was sent the command new
09/19/2014 04:35:30;0040;PBS_Server;Svr;tyrone-cluster;Scheduler was sent the command new
09/19/2014 04:36:04;0040;PBS_Server;Svr;tyrone-cluster;Scheduler was sent the command new
09/19/2014 04:36:35;0040;PBS_Server;Svr;tyrone-cluster;Scheduler was sent the command new
09/19/2014 04:37:05;0040;PBS_Server;Svr;tyrone-cluster;Scheduler was sent the command new
09/19/2014 04:37:06;000d;PBS_Server;Job;42510.tyrone-cluster;Not sending email: User does not want mail of this type.
09/19/2014 04:37:06;0010;PBS_Server;Job;42510.tyrone-cluster;Exit_status=143 resources_used.cput=63:40:44 resources_used.mem=451000kb resources_used.vmem=12112292kb resources_used.walltime=02:00:40
09/19/2014 04:37:06;0008;PBS_Server;Job;NULL;on_job_exit valid pjob: 0x2df5610 (substate=50)
09/19/2014 04:37:06;0008;PBS_Server;Job;NULL;on_job_exit valid pjob: 0x2df5610 (substate=51)
09/19/2014 04:37:06;0008;PBS_Server;Job;NULL;on_job_exit valid pjob: 0x2df5610 (substate=51)
09/19/2014 04:37:06;0008;PBS_Server;Job;NULL;on_job_exit valid pjob: 0x2df5610 (substate=53)
09/19/2014 04:37:06;0100;PBS_Server;Job;42510.tyrone-cluster;dequeuing from idqueue, state COMPLETE
09/19/2014 04:37:06;0040;PBS_Server;Svr;tyrone-cluster;Scheduler was sent the command term
09/19/2014 04:37:06;0008;PBS_Server;Job;42511.tyrone-cluster;Job Modified at request of Scheduler@tyrone-cluster
09/19/2014 04:37:06;0008;PBS_Server;Job;42511.tyrone-cluster;Job Run at request of Scheduler@tyrone-cluster
09/19/2014 04:37:06;0040;PBS_Server;Svr;tyrone-cluster;Scheduler was sent the command recyc
09/19/2014 04:37:06;000d;PBS_Server;Job;42511.tyrone-cluster;Not sending email: User does not want mail of this type.
09/19/2014 04:37:34;0040;PBS_Server;Svr;tyrone-cluster;Scheduler was sent the command new
09/19/2014 04:37:40;0002;PBS_Server;Svr;PBS_Server;Torque Server Version = 3.0.5, loglevel = 0
09/19/2014 04:38:07;0040;PBS_Server;Svr;tyrone-cluster;Scheduler was sent the command new
09/19/2014 04:38:35;0040;PBS_Server;Svr;tyrone-cluster;Scheduler was sent the command new
09/19/2014 04:39:04;0040;PBS_Server;Svr;tyrone-cluster;Scheduler was sent the command new
09/19/2014 04:39:35;0040;PBS_Server;Svr;tyrone-cluster;Scheduler was sent the command new
09/19/2014 04:40:05;0040;PBS_Server;Svr;tyrone-cluster;Scheduler was sent the command new
09/19/2014 04:40:34;0040;PBS_Server;Svr;tyrone-cluster;Scheduler was sent the command new
09/19/2014 04:41:05;0040;PBS_Server;Svr;tyrone-cluster;Scheduler was sent the command new
09/19/2014 04:41:35;0040;PBS_Server;Svr;tyrone-cluster;Scheduler was sent the command new
09/19/2014 04:42:04;0040;PBS_Server;Svr;tyrone-cluster;Scheduler was sent the command new
09/19/2014 04:42:35;0040;PBS_Server;Svr;tyrone-cluster;Scheduler was sent the command new
09/19/2014 04:42:40;0002;PBS_Server;Svr;PBS_Server;Torque Server Version = 3.0.5, loglevel = 0
09/19/2014 04:43:05;0040;PBS_Server;Svr;tyrone-cluster;Scheduler was sent the command new
09/19/2014 04:43:34;0040;PBS_Server;Svr;tyrone-cluster;Scheduler was sent the command new
09/19/2014 04:44:04;0040;PBS_Server;Svr;tyrone-cluster;Scheduler was sent the command new
09/19/2014 04:44:37;0040;PBS_Server;Svr;tyrone-cluster;Scheduler was sent the command new
09/19/2014 04:45:06;0040;PBS_Server;Svr;tyrone-cluster;Scheduler was sent the command new
09/19/2014 04:45:42;0040;PBS_Server;Svr;tyrone-cluster;Scheduler was sent the command new
09/19/2014 04:46:09;0040;PBS_Server;Svr;tyrone-cluster;Scheduler was sent the command new
09/19/2014 04:46:40;0040;PBS_Server;Svr;tyrone-cluster;Scheduler was sent the command new
09/19/2014 04:47:19;0040;PBS_Server;Svr;tyrone-cluster;Scheduler was sent the command new
09/19/2014 04:47:40;0002;PBS_Server;Svr;PBS_Server;Torque Server Version = 3.0.5, loglevel = 0
09/19/2014 04:47:43;0040;PBS_Server;Svr;tyrone-cluster;Scheduler was sent the command new
09/19/2014 04:48:15;0040;PBS_Server;Svr;tyrone-cluster;Scheduler was sent the command new
09/19/2014 04:48:49;0040;PBS_Server;Svr;tyrone-cluster;Scheduler was sent the command new
09/19/2014 04:49:22;0040;PBS_Server;Svr;tyrone-cluster;Scheduler was sent the command new
09/19/2014 04:49:52;0040;PBS_Server;Svr;tyrone-cluster;Scheduler was sent the command new
09/19/2014 04:50:21;0040;PBS_Server;Svr;tyrone-cluster;Scheduler was sent the command new
09/19/2014 04:50:57;0040;PBS_Server;Svr;tyrone-cluster;Scheduler was sent the command new
09/19/2014 04:51:24;0040;PBS_Server;Svr;tyrone-cluster;Scheduler was sent the command new
09/19/2014 04:51:58;0040;PBS_Server;Svr;tyrone-cluster;Scheduler was sent the command new
09/19/2014 04:52:31;0040;PBS_Server;Svr;tyrone-cluster;Scheduler was sent the command new
09/19/2014 04:52:40;0002;PBS_Server;Svr;PBS_Server;Torque Server Version = 3.0.5, loglevel = 0
09/19/2014 04:52:58;0040;PBS_Server;Svr;tyrone-cluster;Scheduler was sent the command new
09/19/2014 04:53:30;0040;PBS_Server;Svr;tyrone-cluster;Scheduler was sent the command new
09/19/2014 04:54:04;0040;PBS_Server;Svr;tyrone-cluster;Scheduler was sent the command new
09/19/2014 04:54:37;0040;PBS_Server;Svr;tyrone-cluster;Scheduler was sent the command new
09/19/2014 04:55:07;0040;PBS_Server;Svr;tyrone-cluster;Scheduler was sent the command new
09/19/2014 04:55:36;0040;PBS_Server;Svr;tyrone-cluster;Scheduler was sent the command new
09/19/2014 04:56:12;0040;PBS_Server;Svr;tyrone-cluster;Scheduler was sent the command new
09/19/2014 04:56:37;0040;PBS_Server;Svr;tyrone-cluster;Scheduler was sent the command new
09/19/2014 04:57:10;0040;PBS_Server;Svr;tyrone-cluster;Scheduler was sent the command new
09/19/2014 04:57:40;0002;PBS_Server;Svr;PBS_Server;Torque Server Version = 3.0.5, loglevel = 0
09/19/2014 04:57:42;0040;PBS_Server;Svr;tyrone-cluster;Scheduler was sent the command new
09/19/2014 04:58:13;0040;PBS_Server;Svr;tyrone-cluster;Scheduler was sent the command new
09/19/2014 04:58:45;0040;PBS_Server;Svr;tyrone-cluster;Scheduler was sent the command new
09/19/2014 04:59:19;0040;PBS_Server;Svr;tyrone-cluster;Scheduler was sent the command new
09/19/2014 04:59:52;0040;PBS_Server;Svr;tyrone-cluster;Scheduler was sent the command new
09/19/2014 05:00:22;0040;PBS_Server;Svr;tyrone-cluster;Scheduler was sent the command new
09/19/2014 05:00:51;0040;PBS_Server;Svr;tyrone-cluster;Scheduler was sent the command new
09/19/2014 05:01:27;0040;PBS_Server;Svr;tyrone-cluster;Scheduler was sent the command new
09/19/2014 05:01:54;0040;PBS_Server;Svr;tyrone-cluster;Scheduler was sent the command new
09/19/2014 05:02:28;0040;PBS_Server;Svr;tyrone-cluster;Scheduler was sent the command new
09/19/2014 05:02:40;0002;PBS_Server;Svr;PBS_Server;Torque Server Version = 3.0.5, loglevel = 0
09/19/2014 05:03:04;0040;PBS_Server;Svr;tyrone-cluster;Scheduler was sent the command new
09/19/2014 05:03:28;0040;PBS_Server;Svr;tyrone-cluster;Scheduler was sent the command new
09/19/2014 05:04:00;0040;PBS_Server;Svr;tyrone-cluster;Scheduler was sent the command new
09/19/2014 05:04:34;0040;PBS_Server;Svr;tyrone-cluster;Scheduler was sent the command new
09/19/2014 05:05:04;0040;PBS_Server;Svr;tyrone-cluster;Scheduler was sent the command new
09/19/2014 05:05:37;0040;PBS_Server;Svr;tyrone-cluster;Scheduler was sent the command new
09/19/2014 05:06:07;0040;PBS_Server;Svr;tyrone-cluster;Scheduler was sent the command new
09/19/2014 05:06:42;0040;PBS_Server;Svr;tyrone-cluster;Scheduler was sent the command new
09/19/2014 05:07:09;0040;PBS_Server;Svr;tyrone-cluster;Scheduler was sent the command new
09/19/2014 05:07:40;0002;PBS_Server;Svr;PBS_Server;Torque Server Version = 3.0.5, loglevel = 0
09/19/2014 05:07:40;0040;PBS_Server;Svr;tyrone-cluster;Scheduler was sent the command new
09/19/2014 05:08:19;0040;PBS_Server;Svr;tyrone-cluster;Scheduler was sent the command new
09/19/2014 05:08:43;0040;PBS_Server;Svr;tyrone-cluster;Scheduler was sent the command new
09/19/2014 05:09:14;0040;PBS_Server;Svr;tyrone-cluster;Scheduler was sent the command new
09/19/2014 05:09:49;0040;PBS_Server;Svr;tyrone-cluster;Scheduler was sent the command new
09/19/2014 05:10:22;0040;PBS_Server;Svr;tyrone-cluster;Scheduler was sent the command new
09/19/2014 05:10:52;0040;PBS_Server;Svr;tyrone-cluster;Scheduler was sent the command new
09/19/2014 05:11:21;0040;PBS_Server;Svr;tyrone-cluster;Scheduler was sent the command new
09/19/2014 05:11:57;0040;PBS_Server;Svr;tyrone-cluster;Scheduler was sent the command new
09/19/2014 05:12:22;0040;PBS_Server;Svr;tyrone-cluster;Scheduler was sent the command new
09/19/2014 05:12:40;0002;PBS_Server;Svr;PBS_Server;Torque Server Version = 3.0.5, loglevel = 0
09/19/2014 05:12:54;0040;PBS_Server;Svr;tyrone-cluster;Scheduler was sent the command new
09/19/2014 05:13:34;0040;PBS_Server;Svr;tyrone-cluster;Scheduler was sent the command new
09/19/2014 05:13:58;0040;PBS_Server;Svr;tyrone-cluster;Scheduler was sent the command new
09/19/2014 05:14:29;0040;PBS_Server;Svr;tyrone-cluster;Scheduler was sent the command new
09/19/2014 05:15:04;0040;PBS_Server;Svr;tyrone-cluster;Scheduler was sent the command new
09/19/2014 05:15:38;0040;PBS_Server;Svr;tyrone-cluster;Scheduler was sent the command new
09/19/2014 05:16:07;0040;PBS_Server;Svr;tyrone-cluster;Scheduler was sent the command new
09/19/2014 05:16:36;0040;PBS_Server;Svr;tyrone-cluster;Scheduler was sent the command new
09/19/2014 05:17:12;0040;PBS_Server;Svr;tyrone-cluster;Scheduler was sent the command new
09/19/2014 05:17:37;0040;PBS_Server;Svr;tyrone-cluster;Scheduler was sent the command new
09/19/2014 05:17:40;0002;PBS_Server;Svr;PBS_Server;Torque Server Version = 3.0.5, loglevel = 0
09/19/2014 05:18:09;0040;PBS_Server;Svr;tyrone-cluster;Scheduler was sent the command new
09/19/2014 05:18:49;0040;PBS_Server;Svr;tyrone-cluster;Scheduler was sent the command new
09/19/2014 05:19:13;0040;PBS_Server;Svr;tyrone-cluster;Scheduler was sent the command new
09/19/2014 05:19:45;0040;PBS_Server;Svr;tyrone-cluster;Scheduler was sent the command new
09/19/2014 05:20:19;0040;PBS_Server;Svr;tyrone-cluster;Scheduler was sent the command new
09/19/2014 05:20:52;0040;PBS_Server;Svr;tyrone-cluster;Scheduler was sent the command new
09/19/2014 05:21:22;0040;PBS_Server;Svr;tyrone-cluster;Scheduler was sent the command new
09/19/2014 05:21:51;0040;PBS_Server;Svr;tyrone-cluster;Scheduler was sent the command new
09/19/2014 05:22:27;0040;PBS_Server;Svr;tyrone-cluster;Scheduler was sent the command new
09/19/2014 05:22:40;0002;PBS_Server;Svr;PBS_Server;Torque Server Version = 3.0.5, loglevel = 0
09/19/2014 05:22:52;0040;PBS_Server;Svr;tyrone-cluster;Scheduler was sent the command new
09/19/2014 05:23:24;0040;PBS_Server;Svr;tyrone-cluster;Scheduler was sent the command new
09/19/2014 05:24:04;0040;PBS_Server;Svr;tyrone-cluster;Scheduler was sent the command new
09/19/2014 05:24:28;0040;PBS_Server;Svr;tyrone-cluster;Scheduler was sent the command new
09/19/2014 05:24:59;0040;PBS_Server;Svr;tyrone-cluster;Scheduler was sent the command new
09/19/2014 05:25:34;0040;PBS_Server;Svr;tyrone-cluster;Scheduler was sent the command new
09/19/2014 05:26:08;0040;PBS_Server;Svr;tyrone-cluster;Scheduler was sent the command new
09/19/2014 05:26:37;0040;PBS_Server;Svr;tyrone-cluster;Scheduler was sent the command new
09/19/2014 05:27:06;0040;PBS_Server;Svr;tyrone-cluster;Scheduler was sent the command new
09/19/2014 05:27:40;0002;PBS_Server;Svr;PBS_Server;Torque Server Version = 3.0.5, loglevel = 0
09/19/2014 05:27:40;0040;PBS_Server;Svr;tyrone-cluster;Scheduler was sent the command new
09/19/2014 05:28:07;0040;PBS_Server;Svr;tyrone-cluster;Scheduler was sent the command new
09/19/2014 05:28:39;0040;PBS_Server;Svr;tyrone-cluster;Scheduler was sent the command new
09/19/2014 05:29:19;0040;PBS_Server;Svr;tyrone-cluster;Scheduler was sent the command new
09/19/2014 05:29:43;0040;PBS_Server;Svr;tyrone-cluster;Scheduler was sent the command new
09/19/2014 05:30:12;0040;PBS_Server;Svr;tyrone-cluster;Scheduler was sent the command new
09/19/2014 05:30:49;0040;PBS_Server;Svr;tyrone-cluster;Scheduler was sent the command new
09/19/2014 05:31:13;0040;PBS_Server;Svr;tyrone-cluster;Scheduler was sent the command new
09/19/2014 05:31:46;0040;PBS_Server;Svr;tyrone-cluster;Scheduler was sent the command new
09/19/2014 05:32:19;0040;PBS_Server;Svr;tyrone-cluster;Scheduler was sent the command new
09/19/2014 05:32:40;0002;PBS_Server;Svr;PBS_Server;Torque Server Version = 3.0.5, loglevel = 0
09/19/2014 05:32:52;0040;PBS_Server;Svr;tyrone-cluster;Scheduler was sent the command new
09/19/2014 05:33:22;0040;PBS_Server;Svr;tyrone-cluster;Scheduler was sent the command new
09/19/2014 05:33:50;0040;PBS_Server;Svr;tyrone-cluster;Scheduler was sent the command new
09/19/2014 05:34:26;0040;PBS_Server;Svr;tyrone-cluster;Scheduler was sent the command new
09/19/2014 05:34:53;0040;PBS_Server;Svr;tyrone-cluster;Scheduler was sent the command new
09/19/2014 05:35:28;0040;PBS_Server;Svr;tyrone-cluster;Scheduler was sent the command new
09/19/2014 05:36:05;0040;PBS_Server;Svr;tyrone-cluster;Scheduler was sent the command new
09/19/2014 05:36:29;0040;PBS_Server;Svr;tyrone-cluster;Scheduler was sent the command new
09/19/2014 05:37:01;0040;PBS_Server;Svr;tyrone-cluster;Scheduler was sent the command new
09/19/2014 05:37:35;0040;PBS_Server;Svr;tyrone-cluster;Scheduler was sent the command new
09/19/2014 05:37:40;0002;PBS_Server;Svr;PBS_Server;Torque Server Version = 3.0.5, loglevel = 0
09/19/2014 05:38:02;0040;PBS_Server;Svr;tyrone-cluster;Scheduler was sent the command new
09/19/2014 05:38:35;0040;PBS_Server;Svr;tyrone-cluster;Scheduler was sent the command new
09/19/2014 05:39:05;0040;PBS_Server;Svr;tyrone-cluster;Scheduler was sent the command new
09/19/2014 05:39:41;0040;PBS_Server;Svr;tyrone-cluster;Scheduler was sent the command new
09/19/2014 05:40:08;0040;PBS_Server;Svr;tyrone-cluster;Scheduler was sent the command new
09/19/2014 05:40:39;0040;PBS_Server;Svr;tyrone-cluster;Scheduler was sent the command new
09/19/2014 05:41:20;0040;PBS_Server;Svr;tyrone-cluster;Scheduler was sent the command new
09/19/2014 05:41:44;0040;PBS_Server;Svr;tyrone-cluster;Scheduler was sent the command new
09/19/2014 05:42:14;0040;PBS_Server;Svr;tyrone-cluster;Scheduler was sent the command new
09/19/2014 05:42:40;0002;PBS_Server;Svr;PBS_Server;Torque Server Version = 3.0.5, loglevel = 0
09/19/2014 05:42:50;0040;PBS_Server;Svr;tyrone-cluster;Scheduler was sent the command new
09/19/2014 05:43:26;0040;PBS_Server;Svr;tyrone-cluster;Scheduler was sent the command new
09/19/2014 05:43:53;0040;PBS_Server;Svr;tyrone-cluster;Scheduler was sent the command new
09/19/2014 05:44:28;0040;PBS_Server;Svr;tyrone-cluster;Scheduler was sent the command new
09/19/2014 05:45:05;0040;PBS_Server;Svr;tyrone-cluster;Scheduler was sent the command new
09/19/2014 05:45:29;0040;PBS_Server;Svr;tyrone-cluster;Scheduler was sent the command new
09/19/2014 05:46:01;0040;PBS_Server;Svr;tyrone-cluster;Scheduler was sent the command new
09/19/2014 05:46:35;0040;PBS_Server;Svr;tyrone-cluster;Scheduler was sent the command new
09/19/2014 05:47:12;0040;PBS_Server;Svr;tyrone-cluster;Scheduler was sent the command new
09/19/2014 05:47:38;0040;PBS_Server;Svr;tyrone-cluster;Scheduler was sent the command new
09/19/2014 05:47:40;0002;PBS_Server;Svr;PBS_Server;Torque Server Version = 3.0.5, loglevel = 0
09/19/2014 05:48:09;0040;PBS_Server;Svr;tyrone-cluster;Scheduler was sent the command new
09/19/2014 05:48:50;0040;PBS_Server;Svr;tyrone-cluster;Scheduler was sent the command new
09/19/2014 05:49:14;0040;PBS_Server;Svr;tyrone-cluster;Scheduler was sent the command new
09/19/2014 05:49:46;0040;PBS_Server;Svr;tyrone-cluster;Scheduler was sent the command new
09/19/2014 05:50:20;0040;PBS_Server;Svr;tyrone-cluster;Scheduler was sent the command new
09/19/2014 05:50:56;0040;PBS_Server;Svr;tyrone-cluster;Scheduler was sent the command new
09/19/2014 05:51:23;0040;PBS_Server;Svr;tyrone-cluster;Scheduler was sent the command new
09/19/2014 05:51:54;0040;PBS_Server;Svr;tyrone-cluster;Scheduler was sent the command new
09/19/2014 05:52:31;0040;PBS_Server;Svr;tyrone-cluster;Scheduler was sent the command new
09/19/2014 05:52:40;0002;PBS_Server;Svr;PBS_Server;Torque Server Version = 3.0.5, loglevel = 0
09/19/2014 05:52:59;0040;PBS_Server;Svr;tyrone-cluster;Scheduler was sent the command new
09/19/2014 05:53:29;0040;PBS_Server;Svr;tyrone-cluster;Scheduler was sent the command new
09/19/2014 05:54:05;0040;PBS_Server;Svr;tyrone-cluster;Scheduler was sent the command new
09/19/2014 05:54:42;0040;PBS_Server;Svr;tyrone-cluster;Scheduler was sent the command new
09/19/2014 05:55:08;0040;PBS_Server;Svr;tyrone-cluster;Scheduler was sent the command new
09/19/2014 05:55:39;0040;PBS_Server;Svr;tyrone-cluster;Scheduler was sent the command new
09/19/2014 05:56:20;0040;PBS_Server;Svr;tyrone-cluster;Scheduler was sent the command new
09/19/2014 05:56:44;0040;PBS_Server;Svr;tyrone-cluster;Scheduler was sent the command new
09/19/2014 05:57:14;0040;PBS_Server;Svr;tyrone-cluster;Scheduler was sent the command new
09/19/2014 05:57:40;0002;PBS_Server;Svr;PBS_Server;Torque Server Version = 3.0.5, loglevel = 0
09/19/2014 05:57:50;0040;PBS_Server;Svr;tyrone-cluster;Scheduler was sent the command new
09/19/2014 05:58:14;0040;PBS_Server;Svr;tyrone-cluster;Scheduler was sent the command new
09/19/2014 05:58:44;0040;PBS_Server;Svr;tyrone-cluster;Scheduler was sent the command new
09/19/2014 05:59:20;0040;PBS_Server;Svr;tyrone-cluster;Scheduler was sent the command new
09/19/2014 05:59:57;0040;PBS_Server;Svr;tyrone-cluster;Scheduler was sent the command new
09/19/2014 06:00:23;0040;PBS_Server;Svr;tyrone-cluster;Scheduler was sent the command new
09/19/2014 06:00:54;0040;PBS_Server;Svr;tyrone-cluster;Scheduler was sent the command new
09/19/2014 06:01:35;0040;PBS_Server;Svr;tyrone-cluster;Scheduler was sent the command new
09/19/2014 06:01:57;0040;PBS_Server;Svr;tyrone-cluster;Scheduler was sent the command new
09/19/2014 06:02:29;0040;PBS_Server;Svr;tyrone-cluster;Scheduler was sent the command new
09/19/2014 06:02:40;0002;PBS_Server;Svr;PBS_Server;Torque Server Version = 3.0.5, loglevel = 0
09/19/2014 06:03:05;0040;PBS_Server;Svr;tyrone-cluster;Scheduler was sent the command new
09/19/2014 06:03:41;0040;PBS_Server;Svr;tyrone-cluster;Scheduler was sent the command new
09/19/2014 06:04:08;0040;PBS_Server;Svr;tyrone-cluster;Scheduler was sent the command new
09/19/2014 06:04:39;0040;PBS_Server;Svr;tyrone-cluster;Scheduler was sent the command new
09/19/2014 06:05:20;0040;PBS_Server;Svr;tyrone-cluster;Scheduler was sent the command new
09/19/2014 06:05:44;0040;PBS_Server;Svr;tyrone-cluster;Scheduler was sent the command new
09/19/2014 06:06:14;0040;PBS_Server;Svr;tyrone-cluster;Scheduler was sent the command new
09/19/2014 06:06:50;0040;PBS_Server;Svr;tyrone-cluster;Scheduler was sent the command new
09/19/2014 06:07:26;0040;PBS_Server;Svr;tyrone-cluster;Scheduler was sent the command new
09/19/2014 06:07:40;0002;PBS_Server;Svr;PBS_Server;Torque Server Version = 3.0.5, loglevel = 0
09/19/2014 06:07:53;0040;PBS_Server;Svr;tyrone-cluster;Scheduler was sent the command new
09/19/2014 06:08:24;0040;PBS_Server;Svr;tyrone-cluster;Scheduler was sent the command new
09/19/2014 06:09:05;0040;PBS_Server;Svr;tyrone-cluster;Scheduler was sent the command new
09/19/2014 06:09:27;0040;PBS_Server;Svr;tyrone-cluster;Scheduler was sent the command new
09/19/2014 06:09:59;0040;PBS_Server;Svr;tyrone-cluster;Scheduler was sent the command new
09/19/2014 06:10:35;0040;PBS_Server;Svr;tyrone-cluster;Scheduler was sent the command new
09/19/2014 06:11:11;0040;PBS_Server;Svr;tyrone-cluster;Scheduler was sent the command new
09/19/2014 06:11:38;0040;PBS_Server;Svr;tyrone-cluster;Scheduler was sent the command new
09/19/2014 06:12:09;0040;PBS_Server;Svr;tyrone-cluster;Scheduler was sent the command new
09/19/2014 06:12:40;0002;PBS_Server;Svr;PBS_Server;Torque Server Version = 3.0.5, loglevel = 0
09/19/2014 06:12:41;0040;PBS_Server;Svr;tyrone-cluster;Scheduler was sent the command new
09/19/2014 06:13:11;0040;PBS_Server;Svr;tyrone-cluster;Scheduler was sent the command new
09/19/2014 06:13:43;0040;PBS_Server;Svr;tyrone-cluster;Scheduler was sent the command new
09/19/2014 06:14:20;0040;PBS_Server;Svr;tyrone-cluster;Scheduler was sent the command new
09/19/2014 06:14:56;0040;PBS_Server;Svr;tyrone-cluster;Scheduler was sent the command new
09/19/2014 06:15:23;0040;PBS_Server;Svr;tyrone-cluster;Scheduler was sent the command new
09/19/2014 06:15:53;0040;PBS_Server;Svr;tyrone-cluster;Scheduler was sent the command new
09/19/2014 06:16:35;0040;PBS_Server;Svr;tyrone-cluster;Scheduler was sent the command new
09/19/2014 06:16:57;0040;PBS_Server;Svr;tyrone-cluster;Scheduler was sent the command new
09/19/2014 06:17:29;0040;PBS_Server;Svr;tyrone-cluster;Scheduler was sent the command new
09/19/2014 06:17:40;0002;PBS_Server;Svr;PBS_Server;Torque Server Version = 3.0.5, loglevel = 0
09/19/2014 06:18:05;0040;PBS_Server;Svr;tyrone-cluster;Scheduler was sent the command new
09/19/2014 06:18:41;0040;PBS_Server;Svr;tyrone-cluster;Scheduler was sent the command new
09/19/2014 06:19:08;0040;PBS_Server;Svr;tyrone-cluster;Scheduler was sent the command new
09/19/2014 06:19:38;0040;PBS_Server;Svr;tyrone-cluster;Scheduler was sent the command new
09/19/2014 06:20:12;0040;PBS_Server;Svr;tyrone-cluster;Scheduler was sent the command new
09/19/2014 06:20:41;0040;PBS_Server;Svr;tyrone-cluster;Scheduler was sent the command new
09/19/2014 06:21:14;0040;PBS_Server;Svr;tyrone-cluster;Scheduler was sent the command new
09/19/2014 06:21:50;0040;PBS_Server;Svr;tyrone-cluster;Scheduler was sent the command new
09/19/2014 06:22:26;0040;PBS_Server;Svr;tyrone-cluster;Scheduler was sent the command new
09/19/2014 06:22:40;0002;PBS_Server;Svr;PBS_Server;Torque Server Version = 3.0.5, loglevel = 0
09/19/2014 06:22:53;0040;PBS_Server;Svr;tyrone-cluster;Scheduler was sent the command new
09/19/2014 06:23:24;0040;PBS_Server;Svr;tyrone-cluster;Scheduler was sent the command new
09/19/2014 06:24:05;0040;PBS_Server;Svr;tyrone-cluster;Scheduler was sent the command new
09/19/2014 06:24:29;0040;PBS_Server;Svr;tyrone-cluster;Scheduler was sent the command new
09/19/2014 06:24:59;0040;PBS_Server;Svr;tyrone-cluster;Scheduler was sent the command new
09/19/2014 06:25:35;0040;PBS_Server;Svr;tyrone-cluster;Scheduler was sent the command new
09/19/2014 06:26:11;0040;PBS_Server;Svr;tyrone-cluster;Scheduler was sent the command new
09/19/2014 06:26:38;0040;PBS_Server;Svr;tyrone-cluster;Scheduler was sent the command new
09/19/2014 06:27:08;0040;PBS_Server;Svr;tyrone-cluster;Scheduler was sent the command new
09/19/2014 06:27:40;0002;PBS_Server;Svr;PBS_Server;Torque Server Version = 3.0.5, loglevel = 0
09/19/2014 06:27:41;0040;PBS_Server;Svr;tyrone-cluster;Scheduler was sent the command new
09/19/2014 06:28:11;0040;PBS_Server;Svr;tyrone-cluster;Scheduler was sent the command new
09/19/2014 06:28:44;0040;PBS_Server;Svr;tyrone-cluster;Scheduler was sent the command new
09/19/2014 06:29:20;0040;PBS_Server;Svr;tyrone-cluster;Scheduler was sent the command new
09/19/2014 06:29:56;0040;PBS_Server;Svr;tyrone-cluster;Scheduler was sent the command new
09/19/2014 06:30:23;0040;PBS_Server;Svr;tyrone-cluster;Scheduler was sent the command new
09/19/2014 06:30:54;0040;PBS_Server;Svr;tyrone-cluster;Scheduler was sent the command new
09/19/2014 06:31:35;0040;PBS_Server;Svr;tyrone-cluster;Scheduler was sent the command new
09/19/2014 06:31:59;0040;PBS_Server;Svr;tyrone-cluster;Scheduler was sent the command new
09/19/2014 06:32:28;0040;PBS_Server;Svr;tyrone-cluster;Scheduler was sent the command new
09/19/2014 06:32:40;0002;PBS_Server;Svr;PBS_Server;Torque Server Version = 3.0.5, loglevel = 0
09/19/2014 06:33:05;0040;PBS_Server;Svr;tyrone-cluster;Scheduler was sent the command new
09/19/2014 06:33:41;0040;PBS_Server;Svr;tyrone-cluster;Scheduler was sent the command new
09/19/2014 06:34:08;0040;PBS_Server;Svr;tyrone-cluster;Scheduler was sent the command new
09/19/2014 06:34:39;0040;PBS_Server;Svr;tyrone-cluster;Scheduler was sent the command new
09/19/2014 06:35:12;0040;PBS_Server;Svr;tyrone-cluster;Scheduler was sent the command new
09/19/2014 06:35:42;0040;PBS_Server;Svr;tyrone-cluster;Scheduler was sent the command new
09/19/2014 06:36:13;0040;PBS_Server;Svr;tyrone-cluster;Scheduler was sent the command new
09/19/2014 06:36:50;0040;PBS_Server;Svr;tyrone-cluster;Scheduler was sent the command new
09/19/2014 06:37:26;0040;PBS_Server;Svr;tyrone-cluster;Scheduler was sent the command new
09/19/2014 06:37:40;0002;PBS_Server;Svr;PBS_Server;Torque Server Version = 3.0.5, loglevel = 0
09/19/2014 06:37:53;0040;PBS_Server;Svr;tyrone-cluster;Scheduler was sent the command new
09/19/2014 06:37:53;000d;PBS_Server;Job;42511.tyrone-cluster;Not sending email: User does not want mail of this type.
09/19/2014 06:37:53;0010;PBS_Server;Job;42511.tyrone-cluster;Exit_status=143 resources_used.cput=63:52:36 resources_used.mem=441168kb resources_used.vmem=12112376kb resources_used.walltime=02:00:47
09/19/2014 06:37:53;0008;PBS_Server;Job;NULL;on_job_exit valid pjob: 0x2df68d0 (substate=50)
09/19/2014 06:37:53;0008;PBS_Server;Job;NULL;on_job_exit valid pjob: 0x2df68d0 (substate=51)
09/19/2014 06:37:53;0008;PBS_Server;Job;42525.tyrone-cluster;Job Modified at request of Scheduler@tyrone-cluster
09/19/2014 06:37:53;0008;PBS_Server;Job;42526.tyrone-cluster;Job Modified at request of Scheduler@tyrone-cluster
09/19/2014 06:37:53;0008;PBS_Server;Job;42527.tyrone-cluster;Job Modified at request of Scheduler@tyrone-cluster
09/19/2014 06:37:55;0008;PBS_Server;Job;NULL;on_job_exit valid pjob: 0x2df68d0 (substate=51)
09/19/2014 06:37:55;0008;PBS_Server;Job;NULL;on_job_exit valid pjob: 0x2df68d0 (substate=53)
09/19/2014 06:37:55;0100;PBS_Server;Job;42511.tyrone-cluster;dequeuing from idqueue, state COMPLETE
09/19/2014 06:37:55;0040;PBS_Server;Svr;tyrone-cluster;Scheduler was sent the command term
09/19/2014 06:37:56;0008;PBS_Server;Job;42525.tyrone-cluster;Job Modified at request of Scheduler@tyrone-cluster
09/19/2014 06:37:56;0008;PBS_Server;Job;42525.tyrone-cluster;Job Run at request of Scheduler@tyrone-cluster
09/19/2014 06:37:56;0008;PBS_Server;Job;42526.tyrone-cluster;Job Modified at request of Scheduler@tyrone-cluster
09/19/2014 06:37:56;0008;PBS_Server;Job;42527.tyrone-cluster;Job Modified at request of Scheduler@tyrone-cluster
09/19/2014 06:37:56;000d;PBS_Server;Job;42525.tyrone-cluster;Not sending email: User does not want mail of this type.
09/19/2014 06:37:56;0040;PBS_Server;Svr;tyrone-cluster;Scheduler was sent the command recyc
09/19/2014 06:38:23;0040;PBS_Server;Svr;tyrone-cluster;Scheduler was sent the command new
09/19/2014 06:39:05;0040;PBS_Server;Svr;tyrone-cluster;Scheduler was sent the command new
09/19/2014 06:39:27;0040;PBS_Server;Svr;tyrone-cluster;Scheduler was sent the command new
09/19/2014 06:39:58;0040;PBS_Server;Svr;tyrone-cluster;Scheduler was sent the command new
09/19/2014 06:40:35;0040;PBS_Server;Svr;tyrone-cluster;Scheduler was sent the command new
09/19/2014 06:41:11;0040;PBS_Server;Svr;tyrone-cluster;Scheduler was sent the command new
09/19/2014 06:41:40;0040;PBS_Server;Svr;tyrone-cluster;Scheduler was sent the command new
09/19/2014 06:42:08;0040;PBS_Server;Svr;tyrone-cluster;Scheduler was sent the command new
09/19/2014 06:42:40;0002;PBS_Server;Svr;PBS_Server;Torque Server Version = 3.0.5, loglevel = 0
09/19/2014 06:42:41;0040;PBS_Server;Svr;tyrone-cluster;Scheduler was sent the command new
09/19/2014 06:43:11;0040;PBS_Server;Svr;tyrone-cluster;Scheduler was sent the command new
09/19/2014 06:43:43;0040;PBS_Server;Svr;tyrone-cluster;Scheduler was sent the command new
09/19/2014 06:44:20;0040;PBS_Server;Svr;tyrone-cluster;Scheduler was sent the command new
09/19/2014 06:44:56;0040;PBS_Server;Svr;tyrone-cluster;Scheduler was sent the command new
09/19/2014 06:45:23;0040;PBS_Server;Svr;tyrone-cluster;Scheduler was sent the command new
09/19/2014 06:45:54;0040;PBS_Server;Svr;tyrone-cluster;Scheduler was sent the command new
09/19/2014 06:46:35;0040;PBS_Server;Svr;tyrone-cluster;Scheduler was sent the command new
09/19/2014 06:46:55;0040;PBS_Server;Svr;tyrone-cluster;Scheduler was sent the command new
09/19/2014 06:47:29;0040;PBS_Server;Svr;tyrone-cluster;Scheduler was sent the command new
09/19/2014 06:47:40;0002;PBS_Server;Svr;PBS_Server;Torque Server Version = 3.0.5, loglevel = 0
09/19/2014 06:48:05;0040;PBS_Server;Svr;tyrone-cluster;Scheduler was sent the command new
09/19/2014 06:48:41;0040;PBS_Server;Svr;tyrone-cluster;Scheduler was sent the command new
09/19/2014 06:49:08;0040;PBS_Server;Svr;tyrone-cluster;Scheduler was sent the command new
09/19/2014 06:49:39;0040;PBS_Server;Svr;tyrone-cluster;Scheduler was sent the command new
09/19/2014 06:50:12;0040;PBS_Server;Svr;tyrone-cluster;Scheduler was sent the command new
09/19/2014 06:50:41;0040;PBS_Server;Svr;tyrone-cluster;Scheduler was sent the command new
09/19/2014 06:51:13;0040;PBS_Server;Svr;tyrone-cluster;Scheduler was sent the command new
09/19/2014 06:51:50;0040;PBS_Server;Svr;tyrone-cluster;Scheduler was sent the command new
09/19/2014 06:52:26;0040;PBS_Server;Svr;tyrone-cluster;Scheduler was sent the command new
09/19/2014 06:52:40;0002;PBS_Server;Svr;PBS_Server;Torque Server Version = 3.0.5, loglevel = 0
09/19/2014 06:52:53;0040;PBS_Server;Svr;tyrone-cluster;Scheduler was sent the command new
09/19/2014 06:53:24;0040;PBS_Server;Svr;tyrone-cluster;Scheduler was sent the command new
09/19/2014 06:54:05;0040;PBS_Server;Svr;tyrone-cluster;Scheduler was sent the command new
09/19/2014 06:54:26;0040;PBS_Server;Svr;tyrone-cluster;Scheduler was sent the command new
09/19/2014 06:54:58;0040;PBS_Server;Svr;tyrone-cluster;Scheduler was sent the command new
09/19/2014 06:55:35;0040;PBS_Server;Svr;tyrone-cluster;Scheduler was sent the command new
09/19/2014 06:56:11;0040;PBS_Server;Svr;tyrone-cluster;Scheduler was sent the command new
09/19/2014 06:56:38;0040;PBS_Server;Svr;tyrone-cluster;Scheduler was sent the command new
09/19/2014 06:57:09;0040;PBS_Server;Svr;tyrone-cluster;Scheduler was sent the command new
09/19/2014 06:57:40;0002;PBS_Server;Svr;PBS_Server;Torque Server Version = 3.0.5, loglevel = 0
09/19/2014 06:57:40;0040;PBS_Server;Svr;tyrone-cluster;Scheduler was sent the command new
09/19/2014 06:58:11;0040;PBS_Server;Svr;tyrone-cluster;Scheduler was sent the command new
09/19/2014 06:58:43;0040;PBS_Server;Svr;tyrone-cluster;Scheduler was sent the command new
09/19/2014 06:59:21;0040;PBS_Server;Svr;tyrone-cluster;Scheduler was sent the command new
09/19/2014 06:59:56;0040;PBS_Server;Svr;tyrone-cluster;Scheduler was sent the command new
09/19/2014 07:00:23;0040;PBS_Server;Svr;tyrone-cluster;Scheduler was sent the command new
09/19/2014 07:00:53;0040;PBS_Server;Svr;tyrone-cluster;Scheduler was sent the command new
09/19/2014 07:01:35;0040;PBS_Server;Svr;tyrone-cluster;Scheduler was sent the command new
09/19/2014 07:01:55;0040;PBS_Server;Svr;tyrone-cluster;Scheduler was sent the command new
09/19/2014 07:02:28;0040;PBS_Server;Svr;tyrone-cluster;Scheduler was sent the command new
09/19/2014 07:02:40;0002;PBS_Server;Svr;PBS_Server;Torque Server Version = 3.0.5, loglevel = 0
09/19/2014 07:03:05;0040;PBS_Server;Svr;tyrone-cluster;Scheduler was sent the command new
09/19/2014 07:03:40;0040;PBS_Server;Svr;tyrone-cluster;Scheduler was sent the command new
09/19/2014 07:04:08;0040;PBS_Server;Svr;tyrone-cluster;Scheduler was sent the command new
09/19/2014 07:04:37;0040;PBS_Server;Svr;tyrone-cluster;Scheduler was sent the command new
09/19/2014 07:05:11;0040;PBS_Server;Svr;tyrone-cluster;Scheduler was sent the command new
09/19/2014 07:05:38;0040;PBS_Server;Svr;tyrone-cluster;Scheduler was sent the command new
09/19/2014 07:06:09;0040;PBS_Server;Svr;tyrone-cluster;Scheduler was sent the command new
09/19/2014 07:06:50;0040;PBS_Server;Svr;tyrone-cluster;Scheduler was sent the command new
09/19/2014 07:07:10;0040;PBS_Server;Svr;tyrone-cluster;Scheduler was sent the command new
09/19/2014 07:07:40;0002;PBS_Server;Svr;PBS_Server;Torque Server Version = 3.0.5, loglevel = 0
09/19/2014 07:07:42;0040;PBS_Server;Svr;tyrone-cluster;Scheduler was sent the command new
09/19/2014 07:08:20;0040;PBS_Server;Svr;tyrone-cluster;Scheduler was sent the command new
09/19/2014 07:08:41;0040;PBS_Server;Svr;tyrone-cluster;Scheduler was sent the command new
09/19/2014 07:09:13;0040;PBS_Server;Svr;tyrone-cluster;Scheduler was sent the command new
09/19/2014 07:09:50;0040;PBS_Server;Svr;tyrone-cluster;Scheduler was sent the command new
09/19/2014 07:10:25;0040;PBS_Server;Svr;tyrone-cluster;Scheduler was sent the command new
09/19/2014 07:10:53;0040;PBS_Server;Svr;tyrone-cluster;Scheduler was sent the command new
09/19/2014 07:11:22;0040;PBS_Server;Svr;tyrone-cluster;Scheduler was sent the command new
09/19/2014 07:12:05;0040;PBS_Server;Svr;tyrone-cluster;Scheduler was sent the command new
09/19/2014 07:12:26;0040;PBS_Server;Svr;tyrone-cluster;Scheduler was sent the command new
09/19/2014 07:12:40;0002;PBS_Server;Svr;PBS_Server;Torque Server Version = 3.0.5, loglevel = 0
09/19/2014 07:12:58;0040;PBS_Server;Svr;tyrone-cluster;Scheduler was sent the command new
09/19/2014 07:13:35;0040;PBS_Server;Svr;tyrone-cluster;Scheduler was sent the command new
09/19/2014 07:14:10;0040;PBS_Server;Svr;tyrone-cluster;Scheduler was sent the command new
09/19/2014 07:14:38;0040;PBS_Server;Svr;tyrone-cluster;Scheduler was sent the command new
09/19/2014 07:15:07;0040;PBS_Server;Svr;tyrone-cluster;Scheduler was sent the command new
09/19/2014 07:15:50;0040;PBS_Server;Svr;tyrone-cluster;Scheduler was sent the command new
09/19/2014 07:16:10;0040;PBS_Server;Svr;tyrone-cluster;Scheduler was sent the command new
09/19/2014 07:16:42;0040;PBS_Server;Svr;tyrone-cluster;Scheduler was sent the command new
09/19/2014 07:17:20;0040;PBS_Server;Svr;tyrone-cluster;Scheduler was sent the command new
09/19/2014 07:17:40;0002;PBS_Server;Svr;PBS_Server;Torque Server Version = 3.0.5, loglevel = 0
09/19/2014 07:17:55;0040;PBS_Server;Svr;tyrone-cluster;Scheduler was sent the command new
09/19/2014 07:18:23;0040;PBS_Server;Svr;tyrone-cluster;Scheduler was sent the command new
09/19/2014 07:18:52;0040;PBS_Server;Svr;tyrone-cluster;Scheduler was sent the command new
09/19/2014 07:19:26;0040;PBS_Server;Svr;tyrone-cluster;Scheduler was sent the command new
09/19/2014 07:19:53;0040;PBS_Server;Svr;tyrone-cluster;Scheduler was sent the command new
09/19/2014 07:20:24;0040;PBS_Server;Svr;tyrone-cluster;Scheduler was sent the command new
09/19/2014 07:21:05;0040;PBS_Server;Svr;tyrone-cluster;Scheduler was sent the command new
09/19/2014 07:21:26;0040;PBS_Server;Svr;tyrone-cluster;Scheduler was sent the command new
09/19/2014 07:21:58;0040;PBS_Server;Svr;tyrone-cluster;Scheduler was sent the command new
09/19/2014 07:22:35;0040;PBS_Server;Svr;tyrone-cluster;Scheduler was sent the command new
09/19/2014 07:22:40;0002;PBS_Server;Svr;PBS_Server;Torque Server Version = 3.0.5, loglevel = 0
09/19/2014 07:23:03;0040;PBS_Server;Svr;tyrone-cluster;Scheduler was sent the command new
09/19/2014 07:23:35;0040;PBS_Server;Svr;tyrone-cluster;Scheduler was sent the command new
09/19/2014 07:24:05;0040;PBS_Server;Svr;tyrone-cluster;Scheduler was sent the command new
09/19/2014 07:24:40;0040;PBS_Server;Svr;tyrone-cluster;Scheduler was sent the command new
09/19/2014 07:25:08;0040;PBS_Server;Svr;tyrone-cluster;Scheduler was sent the command new
09/19/2014 07:25:37;0040;PBS_Server;Svr;tyrone-cluster;Scheduler was sent the command new
09/19/2014 07:26:20;0040;PBS_Server;Svr;tyrone-cluster;Scheduler was sent the command new
09/19/2014 07:26:40;0040;PBS_Server;Svr;tyrone-cluster;Scheduler was sent the command new
09/19/2014 07:27:14;0040;PBS_Server;Svr;tyrone-cluster;Scheduler was sent the command new
09/19/2014 07:27:40;0002;PBS_Server;Svr;PBS_Server;Torque Server Version = 3.0.5, loglevel = 0
09/19/2014 07:27:50;0040;PBS_Server;Svr;tyrone-cluster;Scheduler was sent the command new
09/19/2014 07:28:15;0040;PBS_Server;Svr;tyrone-cluster;Scheduler was sent the command new
09/19/2014 07:28:50;0040;PBS_Server;Svr;tyrone-cluster;Scheduler was sent the command new
09/19/2014 07:29:20;0040;PBS_Server;Svr;tyrone-cluster;Scheduler was sent the command new
09/19/2014 07:29:55;0040;PBS_Server;Svr;tyrone-cluster;Scheduler was sent the command new
09/19/2014 07:30:23;0040;PBS_Server;Svr;tyrone-cluster;Scheduler was sent the command new
09/19/2014 07:30:53;0040;PBS_Server;Svr;tyrone-cluster;Scheduler was sent the command new
09/19/2014 07:31:35;0040;PBS_Server;Svr;tyrone-cluster;Scheduler was sent the command new
09/19/2014 07:32:00;0040;PBS_Server;Svr;tyrone-cluster;Scheduler was sent the command new
09/19/2014 07:32:29;0040;PBS_Server;Svr;tyrone-cluster;Scheduler was sent the command new
09/19/2014 07:32:40;0002;PBS_Server;Svr;PBS_Server;Torque Server Version = 3.0.5, loglevel = 0
09/19/2014 07:33:05;0040;PBS_Server;Svr;tyrone-cluster;Scheduler was sent the command new
09/19/2014 07:33:40;0040;PBS_Server;Svr;tyrone-cluster;Scheduler was sent the command new
09/19/2014 07:34:08;0040;PBS_Server;Svr;tyrone-cluster;Scheduler was sent the command new
09/19/2014 07:34:37;0040;PBS_Server;Svr;tyrone-cluster;Scheduler was sent the command new
09/19/2014 07:35:10;0040;PBS_Server;Svr;tyrone-cluster;Scheduler was sent the command new
09/19/2014 07:35:38;0040;PBS_Server;Svr;tyrone-cluster;Scheduler was sent the command new
09/19/2014 07:36:07;0040;PBS_Server;Svr;tyrone-cluster;Scheduler was sent the command new
09/19/2014 07:36:50;0040;PBS_Server;Svr;tyrone-cluster;Scheduler was sent the command new
09/19/2014 07:37:11;0040;PBS_Server;Svr;tyrone-cluster;Scheduler was sent the command new
09/19/2014 07:37:40;0002;PBS_Server;Svr;PBS_Server;Torque Server Version = 3.0.5, loglevel = 0
09/19/2014 07:37:42;0040;PBS_Server;Svr;tyrone-cluster;Scheduler was sent the command new
09/19/2014 07:38:20;0040;PBS_Server;Svr;tyrone-cluster;Scheduler was sent the command new
09/19/2014 07:38:40;0040;PBS_Server;Svr;tyrone-cluster;Scheduler was sent the command new
09/19/2014 07:39:14;0040;PBS_Server;Svr;tyrone-cluster;Scheduler was sent the command new
09/19/2014 07:39:50;0040;PBS_Server;Svr;tyrone-cluster;Scheduler was sent the command new
09/19/2014 07:40:26;0040;PBS_Server;Svr;tyrone-cluster;Scheduler was sent the command new
09/19/2014 07:40:53;0040;PBS_Server;Svr;tyrone-cluster;Scheduler was sent the command new
09/19/2014 07:41:24;0040;PBS_Server;Svr;tyrone-cluster;Scheduler was sent the command new
09/19/2014 07:42:05;0040;PBS_Server;Svr;tyrone-cluster;Scheduler was sent the command new
09/19/2014 07:42:25;0040;PBS_Server;Svr;tyrone-cluster;Scheduler was sent the command new
09/19/2014 07:42:40;0002;PBS_Server;Svr;PBS_Server;Torque Server Version = 3.0.5, loglevel = 0
09/19/2014 07:42:59;0040;PBS_Server;Svr;tyrone-cluster;Scheduler was sent the command new
09/19/2014 07:43:35;0040;PBS_Server;Svr;tyrone-cluster;Scheduler was sent the command new
09/19/2014 07:44:10;0040;PBS_Server;Svr;tyrone-cluster;Scheduler was sent the command new
09/19/2014 07:44:38;0040;PBS_Server;Svr;tyrone-cluster;Scheduler was sent the command new
09/19/2014 07:45:07;0040;PBS_Server;Svr;tyrone-cluster;Scheduler was sent the command new
09/19/2014 07:45:50;0040;PBS_Server;Svr;tyrone-cluster;Scheduler was sent the command new
09/19/2014 07:46:11;0040;PBS_Server;Svr;tyrone-cluster;Scheduler was sent the command new
09/19/2014 07:46:44;0040;PBS_Server;Svr;tyrone-cluster;Scheduler was sent the command new
09/19/2014 07:47:20;0040;PBS_Server;Svr;tyrone-cluster;Scheduler was sent the command new
09/19/2014 07:47:40;0002;PBS_Server;Svr;PBS_Server;Torque Server Version = 3.0.5, loglevel = 0
09/19/2014 07:47:55;0040;PBS_Server;Svr;tyrone-cluster;Scheduler was sent the command new
09/19/2014 07:48:23;0040;PBS_Server;Svr;tyrone-cluster;Scheduler was sent the command new
09/19/2014 07:48:52;0040;PBS_Server;Svr;tyrone-cluster;Scheduler was sent the command new
09/19/2014 07:49:35;0040;PBS_Server;Svr;tyrone-cluster;Scheduler was sent the command new
09/19/2014 07:49:55;0040;PBS_Server;Svr;tyrone-cluster;Scheduler was sent the command new
09/19/2014 07:50:29;0040;PBS_Server;Svr;tyrone-cluster;Scheduler was sent the command new
09/19/2014 07:51:05;0040;PBS_Server;Svr;tyrone-cluster;Scheduler was sent the command new
09/19/2014 07:51:40;0040;PBS_Server;Svr;tyrone-cluster;Scheduler was sent the command new
09/19/2014 07:52:08;0040;PBS_Server;Svr;tyrone-cluster;Scheduler was sent the command new
09/19/2014 07:52:37;0040;PBS_Server;Svr;tyrone-cluster;Scheduler was sent the command new
09/19/2014 07:52:40;0002;PBS_Server;Svr;PBS_Server;Torque Server Version = 3.0.5, loglevel = 0
09/19/2014 07:53:20;0040;PBS_Server;Svr;tyrone-cluster;Scheduler was sent the command new
09/19/2014 07:53:40;0040;PBS_Server;Svr;tyrone-cluster;Scheduler was sent the command new
09/19/2014 07:54:14;0040;PBS_Server;Svr;tyrone-cluster;Scheduler was sent the command new
09/19/2014 07:54:50;0040;PBS_Server;Svr;tyrone-cluster;Scheduler was sent the command new
09/19/2014 07:55:25;0040;PBS_Server;Svr;tyrone-cluster;Scheduler was sent the command new
09/19/2014 07:55:53;0040;PBS_Server;Svr;tyrone-cluster;Scheduler was sent the command new
09/19/2014 07:56:22;0040;PBS_Server;Svr;tyrone-cluster;Scheduler was sent the command new
09/19/2014 07:57:05;0040;PBS_Server;Svr;tyrone-cluster;Scheduler was sent the command new
09/19/2014 07:57:25;0040;PBS_Server;Svr;tyrone-cluster;Scheduler was sent the command new
09/19/2014 07:57:40;0002;PBS_Server;Svr;PBS_Server;Torque Server Version = 3.0.5, loglevel = 0
09/19/2014 07:57:58;0040;PBS_Server;Svr;tyrone-cluster;Scheduler was sent the command new
09/19/2014 07:58:36;0040;PBS_Server;Svr;tyrone-cluster;Scheduler was sent the command new
09/19/2014 07:59:10;0040;PBS_Server;Svr;tyrone-cluster;Scheduler was sent the command new
09/19/2014 07:59:38;0040;PBS_Server;Svr;tyrone-cluster;Scheduler was sent the command new
09/19/2014 08:00:07;0040;PBS_Server;Svr;tyrone-cluster;Scheduler was sent the command new
09/19/2014 08:00:50;0040;PBS_Server;Svr;tyrone-cluster;Scheduler was sent the command new
09/19/2014 08:01:11;0040;PBS_Server;Svr;tyrone-cluster;Scheduler was sent the command new
09/19/2014 08:01:43;0040;PBS_Server;Svr;tyrone-cluster;Scheduler was sent the command new
09/19/2014 08:02:20;0040;PBS_Server;Svr;tyrone-cluster;Scheduler was sent the command new
09/19/2014 08:02:40;0002;PBS_Server;Svr;PBS_Server;Torque Server Version = 3.0.5, loglevel = 0
09/19/2014 08:02:54;0040;PBS_Server;Svr;tyrone-cluster;Scheduler was sent the command new
09/19/2014 08:03:22;0040;PBS_Server;Svr;tyrone-cluster;Scheduler was sent the command new
09/19/2014 08:03:52;0040;PBS_Server;Svr;tyrone-cluster;Scheduler was sent the command new
09/19/2014 08:04:25;0040;PBS_Server;Svr;tyrone-cluster;Scheduler was sent the command new
09/19/2014 08:04:53;0040;PBS_Server;Svr;tyrone-cluster;Scheduler was sent the command new
09/19/2014 08:05:22;0040;PBS_Server;Svr;tyrone-cluster;Scheduler was sent the command new
09/19/2014 08:06:05;0040;PBS_Server;Svr;tyrone-cluster;Scheduler was sent the command new
09/19/2014 08:06:26;0040;PBS_Server;Svr;tyrone-cluster;Scheduler was sent the command new
09/19/2014 08:06:59;0040;PBS_Server;Svr;tyrone-cluster;Scheduler was sent the command new
09/19/2014 08:07:35;0040;PBS_Server;Svr;tyrone-cluster;Scheduler was sent the command new
09/19/2014 08:07:40;0002;PBS_Server;Svr;PBS_Server;Torque Server Version = 3.0.5, loglevel = 0
09/19/2014 08:08:03;0040;PBS_Server;Svr;tyrone-cluster;Scheduler was sent the command new
09/19/2014 08:08:37;0040;PBS_Server;Svr;tyrone-cluster;Scheduler was sent the command new
09/19/2014 08:09:05;0040;PBS_Server;Svr;tyrone-cluster;Scheduler was sent the command new
09/19/2014 08:09:40;0040;PBS_Server;Svr;tyrone-cluster;Scheduler was sent the command new
09/19/2014 08:10:08;0040;PBS_Server;Svr;tyrone-cluster;Scheduler was sent the command new
09/19/2014 08:10:37;0040;PBS_Server;Svr;tyrone-cluster;Scheduler was sent the command new
09/19/2014 08:11:20;0040;PBS_Server;Svr;tyrone-cluster;Scheduler was sent the command new
09/19/2014 08:11:40;0040;PBS_Server;Svr;tyrone-cluster;Scheduler was sent the command new
09/19/2014 08:12:13;0040;PBS_Server;Svr;tyrone-cluster;Scheduler was sent the command new
09/19/2014 08:12:40;0002;PBS_Server;Svr;PBS_Server;Torque Server Version = 3.0.5, loglevel = 0
09/19/2014 08:12:50;0040;PBS_Server;Svr;tyrone-cluster;Scheduler was sent the command new
09/19/2014 08:13:14;0040;PBS_Server;Svr;tyrone-cluster;Scheduler was sent the command new
09/19/2014 08:13:50;0040;PBS_Server;Svr;tyrone-cluster;Scheduler was sent the command new
09/19/2014 08:14:20;0040;PBS_Server;Svr;tyrone-cluster;Scheduler was sent the command new
09/19/2014 08:14:55;0040;PBS_Server;Svr;tyrone-cluster;Scheduler was sent the command new
09/19/2014 08:15:23;0040;PBS_Server;Svr;tyrone-cluster;Scheduler was sent the command new
09/19/2014 08:15:52;0040;PBS_Server;Svr;tyrone-cluster;Scheduler was sent the command new
09/19/2014 08:16:25;0040;PBS_Server;Svr;tyrone-cluster;Scheduler was sent the command new
09/19/2014 08:16:53;0040;PBS_Server;Svr;tyrone-cluster;Scheduler was sent the command new
09/19/2014 08:17:22;0040;PBS_Server;Svr;tyrone-cluster;Scheduler was sent the command new
09/19/2014 08:17:40;0002;PBS_Server;Svr;PBS_Server;Torque Server Version = 3.0.5, loglevel = 0
09/19/2014 08:17:55;0040;PBS_Server;Svr;tyrone-cluster;Scheduler was sent the command new
09/19/2014 08:18:23;0040;PBS_Server;Svr;tyrone-cluster;Scheduler was sent the command new
09/19/2014 08:18:52;0040;PBS_Server;Svr;tyrone-cluster;Scheduler was sent the command new
09/19/2014 08:19:35;0040;PBS_Server;Svr;tyrone-cluster;Scheduler was sent the command new
09/19/2014 08:19:55;0040;PBS_Server;Svr;tyrone-cluster;Scheduler was sent the command new
09/19/2014 08:20:28;0040;PBS_Server;Svr;tyrone-cluster;Scheduler was sent the command new
09/19/2014 08:21:05;0040;PBS_Server;Svr;tyrone-cluster;Scheduler was sent the command new
09/19/2014 08:21:40;0040;PBS_Server;Svr;tyrone-cluster;Scheduler was sent the command new
09/19/2014 08:22:08;0040;PBS_Server;Svr;tyrone-cluster;Scheduler was sent the command new
09/19/2014 08:22:37;0040;PBS_Server;Svr;tyrone-cluster;Scheduler was sent the command new
09/19/2014 08:22:40;0002;PBS_Server;Svr;PBS_Server;Torque Server Version = 3.0.5, loglevel = 0
09/19/2014 08:23:20;0040;PBS_Server;Svr;tyrone-cluster;Scheduler was sent the command new
09/19/2014 08:23:40;0040;PBS_Server;Svr;tyrone-cluster;Scheduler was sent the command new
09/19/2014 08:24:13;0040;PBS_Server;Svr;tyrone-cluster;Scheduler was sent the command new
09/19/2014 08:24:50;0040;PBS_Server;Svr;tyrone-cluster;Scheduler was sent the command new
09/19/2014 08:25:25;0040;PBS_Server;Svr;tyrone-cluster;Scheduler was sent the command new
09/19/2014 08:25:53;0040;PBS_Server;Svr;tyrone-cluster;Scheduler was sent the command new
09/19/2014 08:26:24;0040;PBS_Server;Svr;tyrone-cluster;Scheduler was sent the command new
09/19/2014 08:27:05;0040;PBS_Server;Svr;tyrone-cluster;Scheduler was sent the command new
09/19/2014 08:27:25;0040;PBS_Server;Svr;tyrone-cluster;Scheduler was sent the command new
09/19/2014 08:27:40;0002;PBS_Server;Svr;PBS_Server;Torque Server Version = 3.0.5, loglevel = 0
09/19/2014 08:27:58;0040;PBS_Server;Svr;tyrone-cluster;Scheduler was sent the command new
09/19/2014 08:28:35;0040;PBS_Server;Svr;tyrone-cluster;Scheduler was sent the command new
09/19/2014 08:29:09;0040;PBS_Server;Svr;tyrone-cluster;Scheduler was sent the command new
09/19/2014 08:29:38;0040;PBS_Server;Svr;tyrone-cluster;Scheduler was sent the command new
09/19/2014 08:30:07;0040;PBS_Server;Svr;tyrone-cluster;Scheduler was sent the command new
09/19/2014 08:30:50;0040;PBS_Server;Svr;tyrone-cluster;Scheduler was sent the command new
09/19/2014 08:31:11;0040;PBS_Server;Svr;tyrone-cluster;Scheduler was sent the command new
09/19/2014 08:31:43;0040;PBS_Server;Svr;tyrone-cluster;Scheduler was sent the command new
09/19/2014 08:32:20;0040;PBS_Server;Svr;tyrone-cluster;Scheduler was sent the command new
09/19/2014 08:32:40;0002;PBS_Server;Svr;PBS_Server;Torque Server Version = 3.0.5, loglevel = 0
09/19/2014 08:32:54;0040;PBS_Server;Svr;tyrone-cluster;Scheduler was sent the command new
09/19/2014 08:33:24;0040;PBS_Server;Svr;tyrone-cluster;Scheduler was sent the command new
09/19/2014 08:33:54;0040;PBS_Server;Svr;tyrone-cluster;Scheduler was sent the command new
09/19/2014 08:34:35;0040;PBS_Server;Svr;tyrone-cluster;Scheduler was sent the command new
09/19/2014 08:34:55;0040;PBS_Server;Svr;tyrone-cluster;Scheduler was sent the command new
09/19/2014 08:35:27;0040;PBS_Server;Svr;tyrone-cluster;Scheduler was sent the command new
09/19/2014 08:36:05;0040;PBS_Server;Svr;tyrone-cluster;Scheduler was sent the command new
09/19/2014 08:36:40;0040;PBS_Server;Svr;tyrone-cluster;Scheduler was sent the command new
09/19/2014 08:37:08;0040;PBS_Server;Svr;tyrone-cluster;Scheduler was sent the command new
09/19/2014 08:37:37;0040;PBS_Server;Svr;tyrone-cluster;Scheduler was sent the command new
09/19/2014 08:37:40;0002;PBS_Server;Svr;PBS_Server;Torque Server Version = 3.0.5, loglevel = 0
09/19/2014 08:38:09;0040;PBS_Server;Svr;tyrone-cluster;Scheduler was sent the command new
09/19/2014 08:38:37;000d;PBS_Server;Job;42525.tyrone-cluster;Not sending email: User does not want mail of this type.
09/19/2014 08:38:37;0010;PBS_Server;Job;42525.tyrone-cluster;Exit_status=143 resources_used.cput=63:47:07 resources_used.mem=447804kb resources_used.vmem=12112260kb resources_used.walltime=02:00:40
09/19/2014 08:38:37;0008;PBS_Server;Job;NULL;on_job_exit valid pjob: 0x2db04f0 (substate=50)
09/19/2014 08:38:37;0008;PBS_Server;Job;NULL;on_job_exit valid pjob: 0x2db04f0 (substate=51)
09/19/2014 08:38:37;0040;PBS_Server;Svr;tyrone-cluster;Scheduler was sent the command new
09/19/2014 08:38:37;0008;PBS_Server;Job;NULL;on_job_exit valid pjob: 0x2db04f0 (substate=51)
09/19/2014 08:38:37;0008;PBS_Server;Job;NULL;on_job_exit valid pjob: 0x2db04f0 (substate=53)
09/19/2014 08:38:37;0100;PBS_Server;Job;42525.tyrone-cluster;dequeuing from idqueue, state COMPLETE
09/19/2014 08:38:37;0008;PBS_Server;Job;42526.tyrone-cluster;Job Modified at request of Scheduler@tyrone-cluster
09/19/2014 08:38:37;0008;PBS_Server;Job;42526.tyrone-cluster;Job Run at request of Scheduler@tyrone-cluster
09/19/2014 08:38:37;0040;PBS_Server;Svr;tyrone-cluster;Scheduler was sent the command recyc
09/19/2014 08:38:37;000d;PBS_Server;Job;42526.tyrone-cluster;Not sending email: User does not want mail of this type.
09/19/2014 08:39:07;0040;PBS_Server;Svr;tyrone-cluster;Scheduler was sent the command new
09/19/2014 08:39:50;0040;PBS_Server;Svr;tyrone-cluster;Scheduler was sent the command new
09/19/2014 08:40:10;0040;PBS_Server;Svr;tyrone-cluster;Scheduler was sent the command new
09/19/2014 08:40:41;0040;PBS_Server;Svr;tyrone-cluster;Scheduler was sent the command new
09/19/2014 08:41:20;0040;PBS_Server;Svr;tyrone-cluster;Scheduler was sent the command new
09/19/2014 08:41:55;0040;PBS_Server;Svr;tyrone-cluster;Scheduler was sent the command new
09/19/2014 08:42:24;0040;PBS_Server;Svr;tyrone-cluster;Scheduler was sent the command new
09/19/2014 08:42:40;0002;PBS_Server;Svr;PBS_Server;Torque Server Version = 3.0.5, loglevel = 0
09/19/2014 08:42:56;0040;PBS_Server;Svr;tyrone-cluster;Scheduler was sent the command new
09/19/2014 08:43:35;0040;PBS_Server;Svr;tyrone-cluster;Scheduler was sent the command new
09/19/2014 08:43:55;0040;PBS_Server;Svr;tyrone-cluster;Scheduler was sent the command new
09/19/2014 08:44:26;0040;PBS_Server;Svr;tyrone-cluster;Scheduler was sent the command new
09/19/2014 08:45:05;0040;PBS_Server;Svr;tyrone-cluster;Scheduler was sent the command new
09/19/2014 08:45:39;0040;PBS_Server;Svr;tyrone-cluster;Scheduler was sent the command new
09/19/2014 08:46:08;0040;PBS_Server;Svr;tyrone-cluster;Scheduler was sent the command new
09/19/2014 08:46:40;0040;PBS_Server;Svr;tyrone-cluster;Scheduler was sent the command new
09/19/2014 08:47:20;0040;PBS_Server;Svr;tyrone-cluster;Scheduler was sent the command new
09/19/2014 08:47:40;0002;PBS_Server;Svr;PBS_Server;Torque Server Version = 3.0.5, loglevel = 0
09/19/2014 08:47:40;0040;PBS_Server;Svr;tyrone-cluster;Scheduler was sent the command new
09/19/2014 08:48:11;0040;PBS_Server;Svr;tyrone-cluster;Scheduler was sent the command new
09/19/2014 08:48:50;0040;PBS_Server;Svr;tyrone-cluster;Scheduler was sent the command new
09/19/2014 08:49:24;0040;PBS_Server;Svr;tyrone-cluster;Scheduler was sent the command new
09/19/2014 08:49:53;0040;PBS_Server;Svr;tyrone-cluster;Scheduler was sent the command new
09/19/2014 08:50:22;0040;PBS_Server;Svr;tyrone-cluster;Scheduler was sent the command new
09/19/2014 08:51:05;0040;PBS_Server;Svr;tyrone-cluster;Scheduler was sent the command new
09/19/2014 08:51:24;0040;PBS_Server;Svr;tyrone-cluster;Scheduler was sent the command new
09/19/2014 08:51:56;0040;PBS_Server;Svr;tyrone-cluster;Scheduler was sent the command new
09/19/2014 08:52:35;0040;PBS_Server;Svr;tyrone-cluster;Scheduler was sent the command new
09/19/2014 08:52:40;0002;PBS_Server;Svr;PBS_Server;Torque Server Version = 3.0.5, loglevel = 0
09/19/2014 08:53:03;0040;PBS_Server;Svr;tyrone-cluster;Scheduler was sent the command new
09/19/2014 08:53:36;0040;PBS_Server;Svr;tyrone-cluster;Scheduler was sent the command new
09/19/2014 08:54:05;0040;PBS_Server;Svr;tyrone-cluster;Scheduler was sent the command new
09/19/2014 08:54:39;0040;PBS_Server;Svr;tyrone-cluster;Scheduler was sent the command new
09/19/2014 08:55:08;0040;PBS_Server;Svr;tyrone-cluster;Scheduler was sent the command new
09/19/2014 08:55:40;0040;PBS_Server;Svr;tyrone-cluster;Scheduler was sent the command new
09/19/2014 08:56:20;0040;PBS_Server;Svr;tyrone-cluster;Scheduler was sent the command new
09/19/2014 08:56:40;0040;PBS_Server;Svr;tyrone-cluster;Scheduler was sent the command new
09/19/2014 08:57:11;0040;PBS_Server;Svr;tyrone-cluster;Scheduler was sent the command new
09/19/2014 08:57:40;0002;PBS_Server;Svr;PBS_Server;Torque Server Version = 3.0.5, loglevel = 0
09/19/2014 08:57:42;0040;PBS_Server;Svr;tyrone-cluster;Scheduler was sent the command new
09/19/2014 08:58:11;0040;PBS_Server;Svr;tyrone-cluster;Scheduler was sent the command new
09/19/2014 08:58:41;0040;PBS_Server;Svr;tyrone-cluster;Scheduler was sent the command new
09/19/2014 08:59:20;0040;PBS_Server;Svr;tyrone-cluster;Scheduler was sent the command new
09/19/2014 08:59:54;0040;PBS_Server;Svr;tyrone-cluster;Scheduler was sent the command new
09/19/2014 09:00:22;0040;PBS_Server;Svr;tyrone-cluster;Scheduler was sent the command new
09/19/2014 09:00:52;0040;PBS_Server;Svr;tyrone-cluster;Scheduler was sent the command new
09/19/2014 09:01:24;0040;PBS_Server;Svr;tyrone-cluster;Scheduler was sent the command new
09/19/2014 09:01:53;0040;PBS_Server;Svr;tyrone-cluster;Scheduler was sent the command new
09/19/2014 09:02:25;0040;PBS_Server;Svr;tyrone-cluster;Scheduler was sent the command new
09/19/2014 09:02:40;0002;PBS_Server;Svr;PBS_Server;Torque Server Version = 3.0.5, loglevel = 0
09/19/2014 09:03:05;0040;PBS_Server;Svr;tyrone-cluster;Scheduler was sent the command new
09/19/2014 09:03:24;0040;PBS_Server;Svr;tyrone-cluster;Scheduler was sent the command new
09/19/2014 09:03:56;0040;PBS_Server;Svr;tyrone-cluster;Scheduler was sent the command new
09/19/2014 09:04:36;0040;PBS_Server;Svr;tyrone-cluster;Scheduler was sent the command new
09/19/2014 09:05:09;0040;PBS_Server;Svr;tyrone-cluster;Scheduler was sent the command new
09/19/2014 09:05:38;0040;PBS_Server;Svr;tyrone-cluster;Scheduler was sent the command new
09/19/2014 09:06:10;0040;PBS_Server;Svr;tyrone-cluster;Scheduler was sent the command new
09/19/2014 09:06:50;0040;PBS_Server;Svr;tyrone-cluster;Scheduler was sent the command new
09/19/2014 09:07:10;0040;PBS_Server;Svr;tyrone-cluster;Scheduler was sent the command new
09/19/2014 09:07:40;0002;PBS_Server;Svr;PBS_Server;Torque Server Version = 3.0.5, loglevel = 0
09/19/2014 09:07:40;0040;PBS_Server;Svr;tyrone-cluster;Scheduler was sent the command new
09/19/2014 09:08:20;0040;PBS_Server;Svr;tyrone-cluster;Scheduler was sent the command new
09/19/2014 09:08:54;0040;PBS_Server;Svr;tyrone-cluster;Scheduler was sent the command new
09/19/2014 09:09:23;0040;PBS_Server;Svr;tyrone-cluster;Scheduler was sent the command new
09/19/2014 09:09:55;0040;PBS_Server;Svr;tyrone-cluster;Scheduler was sent the command new
09/19/2014 09:10:30;0040;PBS_Server;Svr;tyrone-cluster;Scheduler was sent the command new
09/19/2014 09:10:55;0040;PBS_Server;Svr;tyrone-cluster;Scheduler was sent the command new
09/19/2014 09:11:26;0040;PBS_Server;Svr;tyrone-cluster;Scheduler was sent the command new
09/19/2014 09:12:05;0040;PBS_Server;Svr;tyrone-cluster;Scheduler was sent the command new
09/19/2014 09:12:39;0040;PBS_Server;Svr;tyrone-cluster;Scheduler was sent the command new
09/19/2014 09:12:40;0002;PBS_Server;Svr;PBS_Server;Torque Server Version = 3.0.5, loglevel = 0
09/19/2014 09:13:08;0040;PBS_Server;Svr;tyrone-cluster;Scheduler was sent the command new
09/19/2014 09:13:40;0040;PBS_Server;Svr;tyrone-cluster;Scheduler was sent the command new
09/19/2014 09:14:20;0040;PBS_Server;Svr;tyrone-cluster;Scheduler was sent the command new
09/19/2014 09:14:40;0040;PBS_Server;Svr;tyrone-cluster;Scheduler was sent the command new
09/19/2014 09:15:11;0040;PBS_Server;Svr;tyrone-cluster;Scheduler was sent the command new
09/19/2014 09:15:50;0040;PBS_Server;Svr;tyrone-cluster;Scheduler was sent the command new
09/19/2014 09:16:24;0040;PBS_Server;Svr;tyrone-cluster;Scheduler was sent the command new
09/19/2014 09:16:53;0040;PBS_Server;Svr;tyrone-cluster;Scheduler was sent the command new
09/19/2014 09:17:22;0040;PBS_Server;Svr;tyrone-cluster;Scheduler was sent the command new
09/19/2014 09:17:40;0002;PBS_Server;Svr;PBS_Server;Torque Server Version = 3.0.5, loglevel = 0
09/19/2014 09:17:54;0040;PBS_Server;Svr;tyrone-cluster;Scheduler was sent the command new
09/19/2014 09:18:23;0040;PBS_Server;Svr;tyrone-cluster;Scheduler was sent the command new
09/19/2014 09:18:52;0040;PBS_Server;Svr;tyrone-cluster;Scheduler was sent the command new
09/19/2014 09:19:24;0040;PBS_Server;Svr;tyrone-cluster;Scheduler was sent the command new
09/19/2014 09:19:53;0040;PBS_Server;Svr;tyrone-cluster;Scheduler was sent the command new
09/19/2014 09:20:22;0040;PBS_Server;Svr;tyrone-cluster;Scheduler was sent the command new
09/19/2014 09:20:54;0040;PBS_Server;Svr;tyrone-cluster;Scheduler was sent the command new
09/19/2014 09:21:24;0040;PBS_Server;Svr;tyrone-cluster;Scheduler was sent the command new
09/19/2014 09:21:54;0040;PBS_Server;Svr;tyrone-cluster;Scheduler was sent the command new
09/19/2014 09:22:31;0040;PBS_Server;Svr;tyrone-cluster;Scheduler was sent the command new
09/19/2014 09:22:40;0002;PBS_Server;Svr;PBS_Server;Torque Server Version = 3.0.5, loglevel = 0
09/19/2014 09:22:53;0040;PBS_Server;Svr;tyrone-cluster;Scheduler was sent the command new
09/19/2014 09:23:25;0040;PBS_Server;Svr;tyrone-cluster;Scheduler was sent the command new
09/19/2014 09:24:05;0040;PBS_Server;Svr;tyrone-cluster;Scheduler was sent the command new
09/19/2014 09:24:24;0040;PBS_Server;Svr;tyrone-cluster;Scheduler was sent the command new
09/19/2014 09:24:56;0040;PBS_Server;Svr;tyrone-cluster;Scheduler was sent the command new
09/19/2014 09:25:35;0040;PBS_Server;Svr;tyrone-cluster;Scheduler was sent the command new
09/19/2014 09:26:09;0040;PBS_Server;Svr;tyrone-cluster;Scheduler was sent the command new
09/19/2014 09:26:38;0040;PBS_Server;Svr;tyrone-cluster;Scheduler was sent the command new
09/19/2014 09:27:07;0040;PBS_Server;Svr;tyrone-cluster;Scheduler was sent the command new
09/19/2014 09:27:39;0040;PBS_Server;Svr;tyrone-cluster;Scheduler was sent the command new
09/19/2014 09:27:40;0002;PBS_Server;Svr;PBS_Server;Torque Server Version = 3.0.5, loglevel = 0
09/19/2014 09:28:07;0040;PBS_Server;Svr;tyrone-cluster;Scheduler was sent the command new
09/19/2014 09:28:37;0040;PBS_Server;Svr;tyrone-cluster;Scheduler was sent the command new
09/19/2014 09:29:08;0040;PBS_Server;Svr;tyrone-cluster;Scheduler was sent the command new
09/19/2014 09:29:38;0040;PBS_Server;Svr;tyrone-cluster;Scheduler was sent the command new
09/19/2014 09:30:07;0040;PBS_Server;Svr;tyrone-cluster;Scheduler was sent the command new
09/19/2014 09:30:39;0040;PBS_Server;Svr;tyrone-cluster;Scheduler was sent the command new
09/19/2014 09:31:08;0040;PBS_Server;Svr;tyrone-cluster;Scheduler was sent the command new
09/19/2014 09:31:41;0040;PBS_Server;Svr;tyrone-cluster;Scheduler was sent the command new
09/19/2014 09:32:20;0040;PBS_Server;Svr;tyrone-cluster;Scheduler was sent the command new
09/19/2014 09:32:40;0002;PBS_Server;Svr;PBS_Server;Torque Server Version = 3.0.5, loglevel = 0
09/19/2014 09:32:54;0040;PBS_Server;Svr;tyrone-cluster;Scheduler was sent the command new
09/19/2014 09:33:23;0040;PBS_Server;Svr;tyrone-cluster;Scheduler was sent the command new
09/19/2014 09:33:52;0040;PBS_Server;Svr;tyrone-cluster;Scheduler was sent the command new
09/19/2014 09:34:35;0040;PBS_Server;Svr;tyrone-cluster;Scheduler was sent the command new
09/19/2014 09:34:53;0040;PBS_Server;Svr;tyrone-cluster;Scheduler was sent the command new
09/19/2014 09:35:24;0040;PBS_Server;Svr;tyrone-cluster;Scheduler was sent the command new
09/19/2014 09:36:05;0040;PBS_Server;Svr;tyrone-cluster;Scheduler was sent the command new
09/19/2014 09:36:25;0040;PBS_Server;Svr;tyrone-cluster;Scheduler was sent the command new
09/19/2014 09:36:56;0040;PBS_Server;Svr;tyrone-cluster;Scheduler was sent the command new
09/19/2014 09:37:35;0040;PBS_Server;Svr;tyrone-cluster;Scheduler was sent the command new
09/19/2014 09:37:40;0002;PBS_Server;Svr;PBS_Server;Torque Server Version = 3.0.5, loglevel = 0
09/19/2014 09:38:03;0040;PBS_Server;Svr;tyrone-cluster;Scheduler was sent the command new
09/19/2014 09:38:35;0040;PBS_Server;Svr;tyrone-cluster;Scheduler was sent the command new
09/19/2014 09:39:05;0040;PBS_Server;Svr;tyrone-cluster;Scheduler was sent the command new
09/19/2014 09:39:38;0040;PBS_Server;Svr;tyrone-cluster;Scheduler was sent the command new
09/19/2014 09:40:08;0040;PBS_Server;Svr;tyrone-cluster;Scheduler was sent the command new
09/19/2014 09:40:37;0040;PBS_Server;Svr;tyrone-cluster;Scheduler was sent the command new
09/19/2014 09:40:44;0008;PBS_Server;Job;42528.tyrone-cluster;Job deleted at request of chevadh@tyrone-cluster
09/19/2014 09:40:44;0008;PBS_Server;Job;NULL;on_job_exit valid pjob: 0x2cd1f70 (substate=59)
09/19/2014 09:40:44;0100;PBS_Server;Job;42528.tyrone-cluster;dequeuing from qp64, state COMPLETE
09/19/2014 09:40:44;0040;PBS_Server;Svr;tyrone-cluster;Scheduler was sent the command term
09/19/2014 09:40:47;0008;PBS_Server;Job;42529.tyrone-cluster;Job deleted at request of chevadh@tyrone-cluster
09/19/2014 09:40:47;0008;PBS_Server;Job;NULL;on_job_exit valid pjob: 0x2dbf7f0 (substate=59)
09/19/2014 09:40:47;0100;PBS_Server;Job;42529.tyrone-cluster;dequeuing from batch, state COMPLETE
09/19/2014 09:40:47;0040;PBS_Server;Svr;tyrone-cluster;Scheduler was sent the command term
09/19/2014 09:40:51;0008;PBS_Server;Job;42530.tyrone-cluster;Job deleted at request of chevadh@tyrone-cluster
09/19/2014 09:40:51;0008;PBS_Server;Job;NULL;on_job_exit valid pjob: 0x2dc0ab0 (substate=59)
09/19/2014 09:40:51;0100;PBS_Server;Job;42530.tyrone-cluster;dequeuing from batch, state COMPLETE
09/19/2014 09:40:51;0040;PBS_Server;Svr;tyrone-cluster;Scheduler was sent the command term
09/19/2014 09:40:55;0080;PBS_Server;Job;42530.tyrone-cluster;Unknown Job Id
09/19/2014 09:40:55;0080;PBS_Server;Req;req_reject;Reject reply code=15001(Unknown Job Id), aux=0, type=DeleteJob, from chevadh@tyrone-cluster
09/19/2014 09:40:55;0080;PBS_Server;Req;req_reject;Reject reply code=15001(Unknown Job Id), aux=0, type=LocateJob, from chevadh@tyrone-cluster
09/19/2014 09:41:18;0100;PBS_Server;Job;42534.tyrone-cluster;enqueuing into batch, state 1 hop 1
09/19/2014 09:41:18;0100;PBS_Server;Job;42534.tyrone-cluster;dequeuing from batch, state QUEUED
09/19/2014 09:41:18;0100;PBS_Server;Job;42534.tyrone-cluster;enqueuing into qp128, state 1 hop 1
09/19/2014 09:41:18;0008;PBS_Server;Job;42534.tyrone-cluster;Job Queued at request of chevadh@tyrone-cluster, owner = chevadh@tyrone-cluster, job name = jobname, queue = qp128
09/19/2014 09:41:18;0040;PBS_Server;Svr;tyrone-cluster;Scheduler was sent the command new
09/19/2014 09:41:19;0008;PBS_Server;Job;42534.tyrone-cluster;Job Modified at request of Scheduler@tyrone-cluster
09/19/2014 09:41:19;0008;PBS_Server;Job;42534.tyrone-cluster;Job Run at request of Scheduler@tyrone-cluster
09/19/2014 09:41:19;0040;PBS_Server;Svr;tyrone-cluster;Scheduler was sent the command recyc
09/19/2014 09:41:19;0100;PBS_Server;Job;42535.tyrone-cluster;enqueuing into batch, state 1 hop 1
09/19/2014 09:41:19;0100;PBS_Server;Job;42535.tyrone-cluster;dequeuing from batch, state QUEUED
09/19/2014 09:41:19;0100;PBS_Server;Job;42535.tyrone-cluster;enqueuing into qp128, state 1 hop 1
09/19/2014 09:41:19;0008;PBS_Server;Job;42535.tyrone-cluster;Job Queued at request of chevadh@tyrone-cluster, owner = chevadh@tyrone-cluster, job name = jobname, queue = qp128
09/19/2014 09:41:19;0040;PBS_Server;Svr;tyrone-cluster;Scheduler was sent the command new
09/19/2014 09:41:19;0008;PBS_Server;Job;42535.tyrone-cluster;Job Modified at request of Scheduler@tyrone-cluster
09/19/2014 09:41:41;000d;PBS_Server;Job;42534.tyrone-cluster;Not sending email: User does not want mail of this type.
09/19/2014 09:42:40;0002;PBS_Server;Svr;PBS_Server;Torque Server Version = 3.0.5, loglevel = 0
09/19/2014 09:42:51;0100;PBS_Server;Job;42536.tyrone-cluster;enqueuing into batch, state 1 hop 1
09/19/2014 09:42:51;0100;PBS_Server;Job;42536.tyrone-cluster;dequeuing from batch, state QUEUED
09/19/2014 09:42:51;0100;PBS_Server;Job;42536.tyrone-cluster;enqueuing into idqueue, state 1 hop 1
09/19/2014 09:42:51;0008;PBS_Server;Job;42536.tyrone-cluster;Job Queued at request of chevadh@tyrone-cluster, owner = chevadh@tyrone-cluster, job name = jobname, queue = idqueue
09/19/2014 09:42:51;0040;PBS_Server;Svr;tyrone-cluster;Scheduler was sent the command new
09/19/2014 09:42:51;0008;PBS_Server;Job;42536.tyrone-cluster;Job Modified at request of Scheduler@tyrone-cluster
09/19/2014 09:42:52;0100;PBS_Server;Job;42537.tyrone-cluster;enqueuing into batch, state 1 hop 1
09/19/2014 09:42:52;0100;PBS_Server;Job;42537.tyrone-cluster;dequeuing from batch, state QUEUED
09/19/2014 09:42:52;0100;PBS_Server;Job;42537.tyrone-cluster;enqueuing into idqueue, state 1 hop 1
09/19/2014 09:42:52;0008;PBS_Server;Job;42537.tyrone-cluster;Job Queued at request of chevadh@tyrone-cluster, owner = chevadh@tyrone-cluster, job name = jobname, queue = idqueue
09/19/2014 09:42:52;0040;PBS_Server;Svr;tyrone-cluster;Scheduler was sent the command new
09/19/2014 09:42:52;0008;PBS_Server;Job;42537.tyrone-cluster;Job Modified at request of Scheduler@tyrone-cluster
09/19/2014 09:47:40;0002;PBS_Server;Svr;PBS_Server;Torque Server Version = 3.0.5, loglevel = 0
09/19/2014 09:52:40;0002;PBS_Server;Svr;PBS_Server;Torque Server Version = 3.0.5, loglevel = 0
09/19/2014 09:52:52;0040;PBS_Server;Svr;tyrone-cluster;Scheduler was sent the command time
09/19/2014 09:57:40;0002;PBS_Server;Svr;PBS_Server;Torque Server Version = 3.0.5, loglevel = 0
09/19/2014 10:02:40;0002;PBS_Server;Svr;PBS_Server;Torque Server Version = 3.0.5, loglevel = 0
09/19/2014 10:02:52;0040;PBS_Server;Svr;tyrone-cluster;Scheduler was sent the command time
09/19/2014 10:07:40;0002;PBS_Server;Svr;PBS_Server;Torque Server Version = 3.0.5, loglevel = 0
09/19/2014 10:12:40;0002;PBS_Server;Svr;PBS_Server;Torque Server Version = 3.0.5, loglevel = 0
09/19/2014 10:12:52;0040;PBS_Server;Svr;tyrone-cluster;Scheduler was sent the command time
09/19/2014 10:17:40;0002;PBS_Server;Svr;PBS_Server;Torque Server Version = 3.0.5, loglevel = 0
09/19/2014 10:22:40;0002;PBS_Server;Svr;PBS_Server;Torque Server Version = 3.0.5, loglevel = 0
09/19/2014 10:22:52;0040;PBS_Server;Svr;tyrone-cluster;Scheduler was sent the command time
09/19/2014 10:27:40;0002;PBS_Server;Svr;PBS_Server;Torque Server Version = 3.0.5, loglevel = 0
09/19/2014 10:32:40;0002;PBS_Server;Svr;PBS_Server;Torque Server Version = 3.0.5, loglevel = 0
09/19/2014 10:32:52;0040;PBS_Server;Svr;tyrone-cluster;Scheduler was sent the command time
09/19/2014 10:37:40;0002;PBS_Server;Svr;PBS_Server;Torque Server Version = 3.0.5, loglevel = 0
09/19/2014 10:39:21;000d;PBS_Server;Job;42526.tyrone-cluster;Not sending email: User does not want mail of this type.
09/19/2014 10:39:21;0010;PBS_Server;Job;42526.tyrone-cluster;Exit_status=143 resources_used.cput=63:50:06 resources_used.mem=443292kb resources_used.vmem=12112292kb resources_used.walltime=02:00:44
09/19/2014 10:39:21;0008;PBS_Server;Job;NULL;on_job_exit valid pjob: 0x2cddd70 (substate=50)
09/19/2014 10:39:21;0008;PBS_Server;Job;NULL;on_job_exit valid pjob: 0x2cddd70 (substate=51)
09/19/2014 10:39:21;0008;PBS_Server;Job;NULL;on_job_exit valid pjob: 0x2cddd70 (substate=51)
09/19/2014 10:39:21;0008;PBS_Server;Job;NULL;on_job_exit valid pjob: 0x2cddd70 (substate=53)
09/19/2014 10:39:21;0100;PBS_Server;Job;42526.tyrone-cluster;dequeuing from idqueue, state COMPLETE
09/19/2014 10:39:21;0040;PBS_Server;Svr;tyrone-cluster;Scheduler was sent the command term
09/19/2014 10:39:22;0008;PBS_Server;Job;42527.tyrone-cluster;Job Modified at request of Scheduler@tyrone-cluster
09/19/2014 10:39:22;0008;PBS_Server;Job;42527.tyrone-cluster;Job Run at request of Scheduler@tyrone-cluster
09/19/2014 10:39:22;0040;PBS_Server;Svr;tyrone-cluster;Scheduler was sent the command recyc
09/19/2014 10:39:22;000d;PBS_Server;Job;42527.tyrone-cluster;Not sending email: User does not want mail of this type.
09/19/2014 10:39:23;0100;PBS_Server;Job;42538.tyrone-cluster;enqueuing into batch, state 1 hop 1
09/19/2014 10:39:23;0100;PBS_Server;Job;42538.tyrone-cluster;dequeuing from batch, state QUEUED
09/19/2014 10:39:23;0100;PBS_Server;Job;42538.tyrone-cluster;enqueuing into qp256, state 1 hop 1
09/19/2014 10:39:23;0008;PBS_Server;Job;42538.tyrone-cluster;Job Queued at request of chemraja@tyrone-cluster, owner = chemraja@tyrone-cluster, job name = epoxy_both, queue = qp256
09/19/2014 10:39:23;0040;PBS_Server;Svr;tyrone-cluster;Scheduler was sent the command new
09/19/2014 10:39:23;0008;PBS_Server;Job;42538.tyrone-cluster;Job Modified at request of Scheduler@tyrone-cluster
09/19/2014 10:39:23;0008;PBS_Server;Job;42538.tyrone-cluster;Job Run at request of Scheduler@tyrone-cluster
09/19/2014 10:39:23;0040;PBS_Server;Svr;tyrone-cluster;Scheduler was sent the command recyc
09/19/2014 10:39:33;000d;PBS_Server;Job;42538.tyrone-cluster;Not sending email: User does not want mail of this type.
09/19/2014 10:42:40;0002;PBS_Server;Svr;PBS_Server;Torque Server Version = 3.0.5, loglevel = 0
09/19/2014 10:45:42;0100;PBS_Server;Job;42539.tyrone-cluster;enqueuing into batch, state 1 hop 1
09/19/2014 10:45:42;0100;PBS_Server;Job;42539.tyrone-cluster;dequeuing from batch, state QUEUED
09/19/2014 10:45:42;0100;PBS_Server;Job;42539.tyrone-cluster;enqueuing into qp256, state 1 hop 1
09/19/2014 10:45:42;0008;PBS_Server;Job;42539.tyrone-cluster;Job Queued at request of chemraja@tyrone-cluster, owner = chemraja@tyrone-cluster, job name = run, queue = qp256
09/19/2014 10:45:42;0040;PBS_Server;Svr;tyrone-cluster;Scheduler was sent the command new
09/19/2014 10:45:42;0008;PBS_Server;Job;42539.tyrone-cluster;Job Modified at request of Scheduler@tyrone-cluster
09/19/2014 10:47:40;0002;PBS_Server;Svr;PBS_Server;Torque Server Version = 3.0.5, loglevel = 0
09/19/2014 10:52:40;0002;PBS_Server;Svr;PBS_Server;Torque Server Version = 3.0.5, loglevel = 0
09/19/2014 10:55:42;0040;PBS_Server;Svr;tyrone-cluster;Scheduler was sent the command time
09/19/2014 10:57:40;0002;PBS_Server;Svr;PBS_Server;Torque Server Version = 3.0.5, loglevel = 0
09/19/2014 11:02:40;0002;PBS_Server;Svr;PBS_Server;Torque Server Version = 3.0.5, loglevel = 0
09/19/2014 11:05:42;0040;PBS_Server;Svr;tyrone-cluster;Scheduler was sent the command time
09/19/2014 11:07:40;0002;PBS_Server;Svr;PBS_Server;Torque Server Version = 3.0.5, loglevel = 0
09/19/2014 11:12:40;0002;PBS_Server;Svr;PBS_Server;Torque Server Version = 3.0.5, loglevel = 0
09/19/2014 11:15:42;0040;PBS_Server;Svr;tyrone-cluster;Scheduler was sent the command time
09/19/2014 11:17:40;0002;PBS_Server;Svr;PBS_Server;Torque Server Version = 3.0.5, loglevel = 0
09/19/2014 11:22:40;0002;PBS_Server;Svr;PBS_Server;Torque Server Version = 3.0.5, loglevel = 0
09/19/2014 11:25:42;0040;PBS_Server;Svr;tyrone-cluster;Scheduler was sent the command time
09/19/2014 11:26:47;0100;PBS_Server;Job;42540.tyrone-cluster;enqueuing into batch, state 1 hop 1
09/19/2014 11:26:47;0100;PBS_Server;Job;42540.tyrone-cluster;dequeuing from batch, state QUEUED
09/19/2014 11:26:47;0100;PBS_Server;Job;42540.tyrone-cluster;enqueuing into qp256, state 1 hop 1
09/19/2014 11:26:47;0008;PBS_Server;Job;42540.tyrone-cluster;Job Queued at request of chevadh@tyrone-cluster, owner = chevadh@tyrone-cluster, job name = jobname, queue = qp256
09/19/2014 11:26:47;0040;PBS_Server;Svr;tyrone-cluster;Scheduler was sent the command new
09/19/2014 11:26:47;0008;PBS_Server;Job;42540.tyrone-cluster;Job Modified at request of Scheduler@tyrone-cluster
09/19/2014 11:27:40;0002;PBS_Server;Svr;PBS_Server;Torque Server Version = 3.0.5, loglevel = 0
09/19/2014 11:28:52;0100;PBS_Server;Job;42541.tyrone-cluster;enqueuing into batch, state 1 hop 1
09/19/2014 11:28:52;0100;PBS_Server;Job;42541.tyrone-cluster;dequeuing from batch, state QUEUED
09/19/2014 11:28:52;0100;PBS_Server;Job;42541.tyrone-cluster;enqueuing into qp32, state 1 hop 1
09/19/2014 11:28:52;0008;PBS_Server;Job;42541.tyrone-cluster;Job Queued at request of chevadh@tyrone-cluster, owner = chevadh@tyrone-cluster, job name = jobname, queue = qp32
09/19/2014 11:28:52;0040;PBS_Server;Svr;tyrone-cluster;Scheduler was sent the command new
09/19/2014 11:28:52;0008;PBS_Server;Job;42541.tyrone-cluster;Job Modified at request of Scheduler@tyrone-cluster
09/19/2014 11:29:05;0100;PBS_Server;Job;42542.tyrone-cluster;enqueuing into batch, state 1 hop 1
09/19/2014 11:29:05;0008;PBS_Server;Job;42542.tyrone-cluster;Job Queued at request of chemraja@tyrone-cluster, owner = chemraja@tyrone-cluster, job name = epoxy_hydroxyl, queue = batch
09/19/2014 11:29:05;0040;PBS_Server;Svr;tyrone-cluster;Scheduler was sent the command new
09/19/2014 11:29:06;0008;PBS_Server;Job;42542.tyrone-cluster;Job Modified at request of Scheduler@tyrone-cluster
09/19/2014 11:29:37;0040;PBS_Server;Svr;tyrone-cluster;Scheduler was sent the command new
09/19/2014 11:30:05;0040;PBS_Server;Svr;tyrone-cluster;Scheduler was sent the command new
09/19/2014 11:30:37;0040;PBS_Server;Svr;tyrone-cluster;Scheduler was sent the command new
09/19/2014 11:31:07;0040;PBS_Server;Svr;tyrone-cluster;Scheduler was sent the command new
09/19/2014 11:31:37;0040;PBS_Server;Svr;tyrone-cluster;Scheduler was sent the command new
09/19/2014 11:32:19;0040;PBS_Server;Svr;tyrone-cluster;Scheduler was sent the command new
09/19/2014 11:32:38;0040;PBS_Server;Svr;tyrone-cluster;Scheduler was sent the command new
09/19/2014 11:32:40;0002;PBS_Server;Svr;PBS_Server;Torque Server Version = 3.0.5, loglevel = 0
09/19/2014 11:33:07;0040;PBS_Server;Svr;tyrone-cluster;Scheduler was sent the command new
09/19/2014 11:33:49;0040;PBS_Server;Svr;tyrone-cluster;Scheduler was sent the command new
09/19/2014 11:34:07;0040;PBS_Server;Svr;tyrone-cluster;Scheduler was sent the command new
09/19/2014 11:34:37;0040;PBS_Server;Svr;tyrone-cluster;Scheduler was sent the command new
09/19/2014 11:35:12;0040;PBS_Server;Svr;tyrone-cluster;Scheduler was sent the command new
09/19/2014 11:35:37;0040;PBS_Server;Svr;tyrone-cluster;Scheduler was sent the command new
09/19/2014 11:36:07;0040;PBS_Server;Svr;tyrone-cluster;Scheduler was sent the command new
09/19/2014 11:36:49;0040;PBS_Server;Svr;tyrone-cluster;Scheduler was sent the command new
09/19/2014 11:37:07;0040;PBS_Server;Svr;tyrone-cluster;Scheduler was sent the command new
09/19/2014 11:37:37;0040;PBS_Server;Svr;tyrone-cluster;Scheduler was sent the command new
09/19/2014 11:37:40;0002;PBS_Server;Svr;PBS_Server;Torque Server Version = 3.0.5, loglevel = 0
09/19/2014 11:38:18;0040;PBS_Server;Svr;tyrone-cluster;Scheduler was sent the command new
09/19/2014 11:38:38;0040;PBS_Server;Svr;tyrone-cluster;Scheduler was sent the command new
09/19/2014 11:39:08;0040;PBS_Server;Svr;tyrone-cluster;Scheduler was sent the command new
09/19/2014 11:39:50;0040;PBS_Server;Svr;tyrone-cluster;Scheduler was sent the command new
09/19/2014 11:40:21;0040;PBS_Server;Svr;tyrone-cluster;Scheduler was sent the command new
09/19/2014 11:40:50;0040;PBS_Server;Svr;tyrone-cluster;Scheduler was sent the command new
09/19/2014 11:41:20;0040;PBS_Server;Svr;tyrone-cluster;Scheduler was sent the command new
09/19/2014 11:41:51;0040;PBS_Server;Svr;tyrone-cluster;Scheduler was sent the command new
09/19/2014 11:42:22;0040;PBS_Server;Svr;tyrone-cluster;Scheduler was sent the command new
09/19/2014 11:42:40;0002;PBS_Server;Svr;PBS_Server;Torque Server Version = 3.0.5, loglevel = 0
09/19/2014 11:42:50;0040;PBS_Server;Svr;tyrone-cluster;Scheduler was sent the command new
09/19/2014 11:43:20;0040;PBS_Server;Svr;tyrone-cluster;Scheduler was sent the command new
09/19/2014 11:43:20;0100;PBS_Server;Job;42543.tyrone-cluster;enqueuing into batch, state 1 hop 1
09/19/2014 11:43:20;0008;PBS_Server;Job;42543.tyrone-cluster;Job Queued at request of chevadh@tyrone-cluster, owner = chevadh@tyrone-cluster, job name = jobname, queue = batch
09/19/2014 11:43:21;0008;PBS_Server;Job;42543.tyrone-cluster;Job Modified at request of Scheduler@tyrone-cluster
09/19/2014 11:43:52;0040;PBS_Server;Svr;tyrone-cluster;Scheduler was sent the command new
09/19/2014 11:44:20;0040;PBS_Server;Svr;tyrone-cluster;Scheduler was sent the command new
09/19/2014 11:44:52;0040;PBS_Server;Svr;tyrone-cluster;Scheduler was sent the command new
09/19/2014 11:45:22;0040;PBS_Server;Svr;tyrone-cluster;Scheduler was sent the command new
09/19/2014 11:45:52;0040;PBS_Server;Svr;tyrone-cluster;Scheduler was sent the command new
09/19/2014 11:46:33;0040;PBS_Server;Svr;tyrone-cluster;Scheduler was sent the command new
09/19/2014 11:46:52;0040;PBS_Server;Svr;tyrone-cluster;Scheduler was sent the command new
09/19/2014 11:47:22;0040;PBS_Server;Svr;tyrone-cluster;Scheduler was sent the command new
09/19/2014 11:47:40;0002;PBS_Server;Svr;PBS_Server;Torque Server Version = 3.0.5, loglevel = 0
09/19/2014 11:48:03;0040;PBS_Server;Svr;tyrone-cluster;Scheduler was sent the command new
09/19/2014 11:48:23;0040;PBS_Server;Svr;tyrone-cluster;Scheduler was sent the command new
09/19/2014 11:48:55;0040;PBS_Server;Svr;tyrone-cluster;Scheduler was sent the command new
09/19/2014 11:49:35;0040;PBS_Server;Svr;tyrone-cluster;Scheduler was sent the command new
09/19/2014 11:50:06;0040;PBS_Server;Svr;tyrone-cluster;Scheduler was sent the command new
09/19/2014 11:50:35;0040;PBS_Server;Svr;tyrone-cluster;Scheduler was sent the command new
09/19/2014 11:51:05;0040;PBS_Server;Svr;tyrone-cluster;Scheduler was sent the command new
09/19/2014 11:51:37;0040;PBS_Server;Svr;tyrone-cluster;Scheduler was sent the command new
09/19/2014 11:52:08;0040;PBS_Server;Svr;tyrone-cluster;Scheduler was sent the command new
09/19/2014 11:52:35;0040;PBS_Server;Svr;tyrone-cluster;Scheduler was sent the command new
09/19/2014 11:52:40;0002;PBS_Server;Svr;PBS_Server;Torque Server Version = 3.0.5, loglevel = 0
09/19/2014 11:53:07;0040;PBS_Server;Svr;tyrone-cluster;Scheduler was sent the command new
09/19/2014 11:53:37;0040;PBS_Server;Svr;tyrone-cluster;Scheduler was sent the command new
09/19/2014 11:54:07;0040;PBS_Server;Svr;tyrone-cluster;Scheduler was sent the command new
09/19/2014 11:54:48;0040;PBS_Server;Svr;tyrone-cluster;Scheduler was sent the command new
09/19/2014 11:55:08;0040;PBS_Server;Svr;tyrone-cluster;Scheduler was sent the command new
09/19/2014 11:55:43;0040;PBS_Server;Svr;tyrone-cluster;Scheduler was sent the command new
09/19/2014 11:56:20;0040;PBS_Server;Svr;tyrone-cluster;Scheduler was sent the command new
09/19/2014 11:56:51;0040;PBS_Server;Svr;tyrone-cluster;Scheduler was sent the command new
09/19/2014 11:57:22;0040;PBS_Server;Svr;tyrone-cluster;Scheduler was sent the command new
09/19/2014 11:57:40;0002;PBS_Server;Svr;PBS_Server;Torque Server Version = 3.0.5, loglevel = 0
09/19/2014 11:57:50;0040;PBS_Server;Svr;tyrone-cluster;Scheduler was sent the command new
09/19/2014 11:58:22;0040;PBS_Server;Svr;tyrone-cluster;Scheduler was sent the command new
09/19/2014 11:58:52;0040;PBS_Server;Svr;tyrone-cluster;Scheduler was sent the command new
09/19/2014 11:59:20;0040;PBS_Server;Svr;tyrone-cluster;Scheduler was sent the command new
09/19/2014 11:59:51;0040;PBS_Server;Svr;tyrone-cluster;Scheduler was sent the command new
09/19/2014 12:00:22;0040;PBS_Server;Svr;tyrone-cluster;Scheduler was sent the command new
09/19/2014 12:00:50;0040;PBS_Server;Svr;tyrone-cluster;Scheduler was sent the command new
09/19/2014 12:01:22;0040;PBS_Server;Svr;tyrone-cluster;Scheduler was sent the command new
09/19/2014 12:01:52;0040;PBS_Server;Svr;tyrone-cluster;Scheduler was sent the command new
09/19/2014 12:02:20;0040;PBS_Server;Svr;tyrone-cluster;Scheduler was sent the command new
09/19/2014 12:02:40;0002;PBS_Server;Svr;PBS_Server;Torque Server Version = 3.0.5, loglevel = 0
09/19/2014 12:02:52;0040;PBS_Server;Svr;tyrone-cluster;Scheduler was sent the command new
09/19/2014 12:03:22;0040;PBS_Server;Svr;tyrone-cluster;Scheduler was sent the command new
09/19/2014 12:03:52;0040;PBS_Server;Svr;tyrone-cluster;Scheduler was sent the command new
09/19/2014 12:04:33;0040;PBS_Server;Svr;tyrone-cluster;Scheduler was sent the command new
09/19/2014 12:04:52;0040;PBS_Server;Svr;tyrone-cluster;Scheduler was sent the command new
09/19/2014 12:05:22;0040;PBS_Server;Svr;tyrone-cluster;Scheduler was sent the command new
09/19/2014 12:06:04;0040;PBS_Server;Svr;tyrone-cluster;Scheduler was sent the command new
09/19/2014 12:06:22;0040;PBS_Server;Svr;tyrone-cluster;Scheduler was sent the command new
09/19/2014 12:06:52;0040;PBS_Server;Svr;tyrone-cluster;Scheduler was sent the command new
09/19/2014 12:07:32;0040;PBS_Server;Svr;tyrone-cluster;Scheduler was sent the command new
09/19/2014 12:07:40;0002;PBS_Server;Svr;PBS_Server;Torque Server Version = 3.0.5, loglevel = 0
09/19/2014 12:07:53;0040;PBS_Server;Svr;tyrone-cluster;Scheduler was sent the command new
09/19/2014 12:08:22;0040;PBS_Server;Svr;tyrone-cluster;Scheduler was sent the command new
09/19/2014 12:09:04;0040;PBS_Server;Svr;tyrone-cluster;Scheduler was sent the command new
09/19/2014 12:09:22;0040;PBS_Server;Svr;tyrone-cluster;Scheduler was sent the command new
09/19/2014 12:09:52;0040;PBS_Server;Svr;tyrone-cluster;Scheduler was sent the command new
09/19/2014 12:10:33;0040;PBS_Server;Svr;tyrone-cluster;Scheduler was sent the command new
09/19/2014 12:10:52;0040;PBS_Server;Svr;tyrone-cluster;Scheduler was sent the command new
09/19/2014 12:11:22;0040;PBS_Server;Svr;tyrone-cluster;Scheduler was sent the command new
09/19/2014 12:12:04;0040;PBS_Server;Svr;tyrone-cluster;Scheduler was sent the command new
09/19/2014 12:12:22;0040;PBS_Server;Svr;tyrone-cluster;Scheduler was sent the command new
09/19/2014 12:12:40;0002;PBS_Server;Svr;PBS_Server;Torque Server Version = 3.0.5, loglevel = 0
09/19/2014 12:12:52;0040;PBS_Server;Svr;tyrone-cluster;Scheduler was sent the command new
09/19/2014 12:13:33;0040;PBS_Server;Svr;tyrone-cluster;Scheduler was sent the command new
09/19/2014 12:13:52;0040;PBS_Server;Svr;tyrone-cluster;Scheduler was sent the command new
09/19/2014 12:14:22;0040;PBS_Server;Svr;tyrone-cluster;Scheduler was sent the command new
09/19/2014 12:15:03;0040;PBS_Server;Svr;tyrone-cluster;Scheduler was sent the command new
09/19/2014 12:15:22;0040;PBS_Server;Svr;tyrone-cluster;Scheduler was sent the command new
09/19/2014 12:15:52;0040;PBS_Server;Svr;tyrone-cluster;Scheduler was sent the command new
09/19/2014 12:16:33;0040;PBS_Server;Svr;tyrone-cluster;Scheduler was sent the command new
09/19/2014 12:16:52;0040;PBS_Server;Svr;tyrone-cluster;Scheduler was sent the command new
09/19/2014 12:17:22;0040;PBS_Server;Svr;tyrone-cluster;Scheduler was sent the command new
09/19/2014 12:17:40;0002;PBS_Server;Svr;PBS_Server;Torque Server Version = 3.0.5, loglevel = 0
09/19/2014 12:18:03;0040;PBS_Server;Svr;tyrone-cluster;Scheduler was sent the command new
09/19/2014 12:18:23;0040;PBS_Server;Svr;tyrone-cluster;Scheduler was sent the command new
09/19/2014 12:18:52;0040;PBS_Server;Svr;tyrone-cluster;Scheduler was sent the command new
09/19/2014 12:19:33;0040;PBS_Server;Svr;tyrone-cluster;Scheduler was sent the command new
09/19/2014 12:19:52;0040;PBS_Server;Svr;tyrone-cluster;Scheduler was sent the command new
09/19/2014 12:20:22;0040;PBS_Server;Svr;tyrone-cluster;Scheduler was sent the command new
09/19/2014 12:20:59;0040;PBS_Server;Svr;tyrone-cluster;Scheduler was sent the command new
09/19/2014 12:21:23;0040;PBS_Server;Svr;tyrone-cluster;Scheduler was sent the command new
09/19/2014 12:21:52;0040;PBS_Server;Svr;tyrone-cluster;Scheduler was sent the command new
09/19/2014 12:22:32;0040;PBS_Server;Svr;tyrone-cluster;Scheduler was sent the command new
09/19/2014 12:22:40;0002;PBS_Server;Svr;PBS_Server;Torque Server Version = 3.0.5, loglevel = 0
09/19/2014 12:22:53;0040;PBS_Server;Svr;tyrone-cluster;Scheduler was sent the command new
09/19/2014 12:23:22;0040;PBS_Server;Svr;tyrone-cluster;Scheduler was sent the command new
09/19/2014 12:23:26;0001;PBS_Server;Svr;PBS_Server;LOG_ERROR::stream_eof, connection to tyrone-node6 is no longer valid, connection may have been closed remotely, remote service may be down, or message may be corrupt (End of File).  setting node state to down
09/19/2014 12:23:28;000d;PBS_Server;Job;42466.tyrone-cluster;Not sending email: User does not want mail of this type.
09/19/2014 12:23:28;0010;PBS_Server;Job;42466.tyrone-cluster;Exit_status=143 resources_used.cput=636:58:36 resources_used.mem=13504768kb resources_used.vmem=21943272kb resources_used.walltime=24:03:36
09/19/2014 12:23:28;0008;PBS_Server;Job;NULL;on_job_exit valid pjob: 0x2cd93d0 (substate=50)
09/19/2014 12:23:28;0008;PBS_Server;Job;NULL;on_job_exit valid pjob: 0x2cd93d0 (substate=51)
09/19/2014 12:23:29;0008;PBS_Server;Job;NULL;on_job_exit valid pjob: 0x2cd93d0 (substate=51)
09/19/2014 12:23:29;0008;PBS_Server;Job;NULL;on_job_exit valid pjob: 0x2cd93d0 (substate=53)
09/19/2014 12:23:29;0100;PBS_Server;Job;42466.tyrone-cluster;dequeuing from qp32, state COMPLETE
09/19/2014 12:23:29;0040;PBS_Server;Svr;tyrone-cluster;Scheduler was sent the command term
09/19/2014 12:23:29;0008;PBS_Server;Job;42496.tyrone-cluster;Job Modified at request of Scheduler@tyrone-cluster
09/19/2014 12:23:29;0008;PBS_Server;Job;42533.tyrone-cluster;Job Modified at request of Scheduler@tyrone-cluster
09/19/2014 12:23:29;0008;PBS_Server;Job;42533.tyrone-cluster;Job Run at request of Scheduler@tyrone-cluster
09/19/2014 12:23:29;0040;PBS_Server;Svr;tyrone-cluster;Scheduler was sent the command recyc
09/19/2014 12:23:29;000d;PBS_Server;Job;42533.tyrone-cluster;Not sending email: User does not want mail of this type.
09/19/2014 12:24:05;0040;PBS_Server;Svr;tyrone-cluster;Scheduler was sent the command new
09/19/2014 12:24:11;0008;PBS_Server;Job;42496.tyrone-cluster;Job Modified at request of Scheduler@tyrone-cluster
09/19/2014 12:24:33;0040;PBS_Server;Svr;tyrone-cluster;Scheduler was sent the command new
09/19/2014 12:25:05;0040;PBS_Server;Svr;tyrone-cluster;Scheduler was sent the command new
09/19/2014 12:25:35;0040;PBS_Server;Svr;tyrone-cluster;Scheduler was sent the command new
09/19/2014 12:26:03;0040;PBS_Server;Svr;tyrone-cluster;Scheduler was sent the command new
09/19/2014 12:26:35;0040;PBS_Server;Svr;tyrone-cluster;Scheduler was sent the command new
09/19/2014 12:27:05;0040;PBS_Server;Svr;tyrone-cluster;Scheduler was sent the command new
09/19/2014 12:27:33;0040;PBS_Server;Svr;tyrone-cluster;Scheduler was sent the command new
09/19/2014 12:27:40;0002;PBS_Server;Svr;PBS_Server;Torque Server Version = 3.0.5, loglevel = 0
09/19/2014 12:28:05;0040;PBS_Server;Svr;tyrone-cluster;Scheduler was sent the command new
09/19/2014 12:28:35;0040;PBS_Server;Svr;tyrone-cluster;Scheduler was sent the command new
09/19/2014 12:29:04;0040;PBS_Server;Svr;tyrone-cluster;Scheduler was sent the command new
09/19/2014 12:29:35;0040;PBS_Server;Svr;tyrone-cluster;Scheduler was sent the command new
09/19/2014 12:30:05;0040;PBS_Server;Svr;tyrone-cluster;Scheduler was sent the command new
09/19/2014 12:30:37;0040;PBS_Server;Svr;tyrone-cluster;Scheduler was sent the command new
09/19/2014 12:31:07;0040;PBS_Server;Svr;tyrone-cluster;Scheduler was sent the command new
09/19/2014 12:31:29;000d;PBS_Server;Job;42538.tyrone-cluster;Not sending email: User does not want mail of this type.
09/19/2014 12:31:29;0010;PBS_Server;Job;42538.tyrone-cluster;Exit_status=1 resources_used.cput=01:50:02 resources_used.mem=128404kb resources_used.vmem=1978984kb resources_used.walltime=01:52:07
09/19/2014 12:31:29;0008;PBS_Server;Job;NULL;on_job_exit valid pjob: 0x2cddd70 (substate=50)
09/19/2014 12:31:29;0008;PBS_Server;Job;NULL;on_job_exit valid pjob: 0x2cddd70 (substate=51)
09/19/2014 12:31:29;0008;PBS_Server;Job;NULL;on_job_exit valid pjob: 0x2cddd70 (substate=51)
09/19/2014 12:31:29;0008;PBS_Server;Job;NULL;on_job_exit valid pjob: 0x2cddd70 (substate=53)
09/19/2014 12:31:29;0100;PBS_Server;Job;42538.tyrone-cluster;dequeuing from qp256, state COMPLETE
09/19/2014 12:31:29;0040;PBS_Server;Svr;tyrone-cluster;Scheduler was sent the command term
09/19/2014 12:31:29;0008;PBS_Server;Job;42539.tyrone-cluster;Job Modified at request of Scheduler@tyrone-cluster
09/19/2014 12:31:29;0008;PBS_Server;Job;42539.tyrone-cluster;Job Run at request of Scheduler@tyrone-cluster
09/19/2014 12:31:29;0040;PBS_Server;Svr;tyrone-cluster;Scheduler was sent the command recyc
09/19/2014 12:31:30;000d;PBS_Server;Job;42539.tyrone-cluster;Not sending email: User does not want mail of this type.
09/19/2014 12:31:30;0010;PBS_Server;Job;42539.tyrone-cluster;Exit_status=1 resources_used.cput=00:00:00 resources_used.mem=804kb resources_used.vmem=13628kb resources_used.walltime=00:00:01
09/19/2014 12:31:30;0008;PBS_Server;Job;NULL;on_job_exit valid pjob: 0x2dba9d0 (substate=50)
09/19/2014 12:31:30;0008;PBS_Server;Job;NULL;on_job_exit valid pjob: 0x2dba9d0 (substate=51)
09/19/2014 12:31:30;0008;PBS_Server;Job;NULL;on_job_exit valid pjob: 0x2dba9d0 (substate=51)
09/19/2014 12:31:30;0008;PBS_Server;Job;NULL;on_job_exit valid pjob: 0x2dba9d0 (substate=53)
09/19/2014 12:31:30;0100;PBS_Server;Job;42539.tyrone-cluster;dequeuing from qp256, state COMPLETE
09/19/2014 12:31:30;0040;PBS_Server;Svr;tyrone-cluster;Scheduler was sent the command term
09/19/2014 12:31:30;0008;PBS_Server;Job;42540.tyrone-cluster;Job Modified at request of Scheduler@tyrone-cluster
09/19/2014 12:31:35;0100;PBS_Server;Job;42542.tyrone-cluster;dequeuing from batch, state QUEUED
09/19/2014 12:31:35;0100;PBS_Server;Job;42542.tyrone-cluster;enqueuing into qp256, state 1 hop 1
09/19/2014 12:31:35;0040;PBS_Server;Svr;tyrone-cluster;Scheduler was sent the command new
09/19/2014 12:31:35;0008;PBS_Server;Job;42542.tyrone-cluster;Job Modified at request of Scheduler@tyrone-cluster
09/19/2014 12:31:35;0008;PBS_Server;Job;42542.tyrone-cluster;Job Run at request of Scheduler@tyrone-cluster
09/19/2014 12:31:35;0040;PBS_Server;Svr;tyrone-cluster;Scheduler was sent the command recyc
09/19/2014 12:31:35;000d;PBS_Server;Job;42542.tyrone-cluster;Not sending email: User does not want mail of this type.
09/19/2014 12:31:35;0010;PBS_Server;Job;42542.tyrone-cluster;Exit_status=1 resources_used.cput=00:00:00 resources_used.mem=804kb resources_used.vmem=13628kb resources_used.walltime=00:00:01
09/19/2014 12:31:35;0008;PBS_Server;Job;NULL;on_job_exit valid pjob: 0x2dc2dc0 (substate=50)
09/19/2014 12:31:35;0008;PBS_Server;Job;NULL;on_job_exit valid pjob: 0x2dc2dc0 (substate=51)
09/19/2014 12:31:35;0008;PBS_Server;Job;NULL;on_job_exit valid pjob: 0x2dc2dc0 (substate=51)
09/19/2014 12:31:35;0008;PBS_Server;Job;NULL;on_job_exit valid pjob: 0x2dc2dc0 (substate=53)
09/19/2014 12:31:35;0100;PBS_Server;Job;42542.tyrone-cluster;dequeuing from qp256, state COMPLETE
09/19/2014 12:31:35;0040;PBS_Server;Svr;tyrone-cluster;Scheduler was sent the command term
09/19/2014 12:32:06;0040;PBS_Server;Svr;tyrone-cluster;Scheduler was sent the command new
09/19/2014 12:32:37;0040;PBS_Server;Svr;tyrone-cluster;Scheduler was sent the command new
09/19/2014 12:32:40;0002;PBS_Server;Svr;PBS_Server;Torque Server Version = 3.0.5, loglevel = 0
09/19/2014 12:33:05;0040;PBS_Server;Svr;tyrone-cluster;Scheduler was sent the command new
09/19/2014 12:33:37;0040;PBS_Server;Svr;tyrone-cluster;Scheduler was sent the command new
09/19/2014 12:34:08;0040;PBS_Server;Svr;tyrone-cluster;Scheduler was sent the command new
09/19/2014 12:34:37;0040;PBS_Server;Svr;tyrone-cluster;Scheduler was sent the command new
09/19/2014 12:35:12;0040;PBS_Server;Svr;tyrone-cluster;Scheduler was sent the command new
09/19/2014 12:35:38;0040;PBS_Server;Svr;tyrone-cluster;Scheduler was sent the command new
09/19/2014 12:36:07;0040;PBS_Server;Svr;tyrone-cluster;Scheduler was sent the command new
09/19/2014 12:36:50;0040;PBS_Server;Svr;tyrone-cluster;Scheduler was sent the command new
09/19/2014 12:37:08;0040;PBS_Server;Svr;tyrone-cluster;Scheduler was sent the command new
09/19/2014 12:37:11;0001;PBS_Server;Svr;PBS_Server;LOG_ERROR::stream_eof, connection to tyrone-node8 is no longer valid, connection may have been closed remotely, remote service may be down, or message may be corrupt (End of File).  setting node state to down
09/19/2014 12:37:12;000d;PBS_Server;Job;42475.tyrone-cluster;Not sending email: User does not want mail of this type.
09/19/2014 12:37:12;0010;PBS_Server;Job;42475.tyrone-cluster;Exit_status=143 resources_used.cput=666:35:53 resources_used.mem=11200740kb resources_used.vmem=19675708kb resources_used.walltime=24:01:59
09/19/2014 12:37:12;0008;PBS_Server;Job;NULL;on_job_exit valid pjob: 0x2ce1890 (substate=50)
09/19/2014 12:37:12;0008;PBS_Server;Job;NULL;on_job_exit valid pjob: 0x2ce1890 (substate=51)
09/19/2014 12:37:12;0008;PBS_Server;Job;NULL;on_job_exit valid pjob: 0x2ce1890 (substate=51)
09/19/2014 12:37:12;0008;PBS_Server;Job;NULL;on_job_exit valid pjob: 0x2ce1890 (substate=53)
09/19/2014 12:37:12;0100;PBS_Server;Job;42475.tyrone-cluster;dequeuing from qp64, state COMPLETE
09/19/2014 12:37:12;0040;PBS_Server;Svr;tyrone-cluster;Scheduler was sent the command term
09/19/2014 12:37:12;0008;PBS_Server;Job;42494.tyrone-cluster;Job Modified at request of Scheduler@tyrone-cluster
09/19/2014 12:37:12;0008;PBS_Server;Job;42494.tyrone-cluster;Job Run at request of Scheduler@tyrone-cluster
09/19/2014 12:37:12;0040;PBS_Server;Svr;tyrone-cluster;Scheduler was sent the command recyc
09/19/2014 12:37:13;000d;PBS_Server;Job;42494.tyrone-cluster;Not sending email: User does not want mail of this type.
09/19/2014 12:37:13;0010;PBS_Server;Job;42494.tyrone-cluster;Exit_status=127 resources_used.cput=00:00:00 resources_used.mem=800kb resources_used.vmem=13624kb resources_used.walltime=00:00:00
09/19/2014 12:37:13;0008;PBS_Server;Job;NULL;on_job_exit valid pjob: 0x2ce05d0 (substate=50)
09/19/2014 12:37:13;0008;PBS_Server;Job;NULL;on_job_exit valid pjob: 0x2ce05d0 (substate=51)
09/19/2014 12:37:13;0008;PBS_Server;Job;NULL;on_job_exit valid pjob: 0x2ce05d0 (substate=51)
09/19/2014 12:37:13;0008;PBS_Server;Job;NULL;on_job_exit valid pjob: 0x2ce05d0 (substate=53)
09/19/2014 12:37:13;0100;PBS_Server;Job;42494.tyrone-cluster;dequeuing from qp64, state COMPLETE
09/19/2014 12:37:13;0040;PBS_Server;Svr;tyrone-cluster;Scheduler was sent the command term
09/19/2014 12:37:13;0008;PBS_Server;Job;42515.tyrone-cluster;Job Modified at request of Scheduler@tyrone-cluster
09/19/2014 12:37:13;0008;PBS_Server;Job;42515.tyrone-cluster;Job Run at request of Scheduler@tyrone-cluster
09/19/2014 12:37:13;0040;PBS_Server;Svr;tyrone-cluster;Scheduler was sent the command recyc
09/19/2014 12:37:37;0040;PBS_Server;Svr;tyrone-cluster;Scheduler was sent the command new
09/19/2014 12:37:40;0002;PBS_Server;Svr;PBS_Server;Torque Server Version = 3.0.5, loglevel = 0
09/19/2014 12:38:02;000d;PBS_Server;Job;42515.tyrone-cluster;Not sending email: User does not want mail of this type.
09/19/2014 12:38:02;0010;PBS_Server;Job;42515.tyrone-cluster;Exit_status=0 resources_used.cput=00:00:32 resources_used.mem=34916kb resources_used.vmem=1684636kb resources_used.walltime=00:00:49
09/19/2014 12:38:02;0008;PBS_Server;Job;NULL;on_job_exit valid pjob: 0x2c82f50 (substate=50)
09/19/2014 12:38:02;0008;PBS_Server;Job;NULL;on_job_exit valid pjob: 0x2c82f50 (substate=51)
09/19/2014 12:38:11;0008;PBS_Server;Job;NULL;on_job_exit valid pjob: 0x2c82f50 (substate=51)
09/19/2014 12:38:11;000d;PBS_Server;Job;42515.tyrone-cluster;Post job file processing error; job 42515.tyrone-cluster on host tyrone-node8/31+tyrone-node8/30+tyrone-node8/29+tyrone-node8/28+tyrone-node8/27+tyrone-node8/26+tyrone-node8/25+tyrone-node8/24+tyrone-node8/23+tyrone-node8/22+tyrone-node8/21+tyrone-node8/20+tyrone-node8/19+tyrone-node8/18+tyrone-node8/17+tyrone-node8/16+tyrone-node8/15+tyrone-node8/14+tyrone-node8/13+tyrone-node8/12+tyrone-node8/11+tyrone-node8/10+tyrone-node8/9+tyrone-node8/8+tyrone-node8/7+tyrone-node8/6+tyrone-node8/5+tyrone-node8/4+tyrone-node8/3+tyrone-node8/2+tyrone-node8/1+tyrone-node8/0+tyrone-node7/31+tyrone-node7/30+tyrone-node7/29+tyrone-node7/28+tyrone-node7/27+tyrone-node7/26+tyrone-node7/25+tyrone-node7/24+tyrone-node7/23+tyrone-node7/22+tyrone-node7/21+tyrone-node7/20+tyrone-node7/19+tyrone-node7/18+tyrone-node7/17+tyrone-node7/16+tyrone-node7/15+tyrone-node7/14+tyrone-node7/13+tyrone-node7/12+tyrone-node7/11+tyrone-node7/10+tyrone-node7/9+tyrone-node7/8+tyrone-node7/7+tyrone-node7/6+tyrone-node7/5+tyrone-node7/4+tyrone-node7/3+tyrone-node7/2+tyrone-node7/1+tyrone-node7/0
09/19/2014 12:38:11;0008;PBS_Server;Job;NULL;on_job_exit valid pjob: 0x2c82f50 (substate=53)
09/19/2014 12:38:11;0100;PBS_Server;Job;42515.tyrone-cluster;dequeuing from qp64, state COMPLETE
09/19/2014 12:38:11;0040;PBS_Server;Svr;tyrone-cluster;Scheduler was sent the command term
09/19/2014 12:38:41;0040;PBS_Server;Svr;tyrone-cluster;Scheduler was sent the command new
09/19/2014 12:39:13;0040;PBS_Server;Svr;tyrone-cluster;Scheduler was sent the command new
09/19/2014 12:39:51;0040;PBS_Server;Svr;tyrone-cluster;Scheduler was sent the command new
09/19/2014 12:40:06;000d;PBS_Server;Job;42527.tyrone-cluster;Not sending email: User does not want mail of this type.
09/19/2014 12:40:06;0010;PBS_Server;Job;42527.tyrone-cluster;Exit_status=143 resources_used.cput=63:38:33 resources_used.mem=441128kb resources_used.vmem=12111652kb resources_used.walltime=02:00:44
09/19/2014 12:40:06;0008;PBS_Server;Job;NULL;on_job_exit valid pjob: 0x2d11ba0 (substate=50)
09/19/2014 12:40:06;0008;PBS_Server;Job;NULL;on_job_exit valid pjob: 0x2d11ba0 (substate=51)
09/19/2014 12:40:06;0008;PBS_Server;Job;NULL;on_job_exit valid pjob: 0x2d11ba0 (substate=51)
09/19/2014 12:40:06;0008;PBS_Server;Job;NULL;on_job_exit valid pjob: 0x2d11ba0 (substate=53)
09/19/2014 12:40:06;0100;PBS_Server;Job;42527.tyrone-cluster;dequeuing from idqueue, state COMPLETE
09/19/2014 12:40:06;0040;PBS_Server;Svr;tyrone-cluster;Scheduler was sent the command term
09/19/2014 12:40:06;0008;PBS_Server;Job;42536.tyrone-cluster;Job Modified at request of Scheduler@tyrone-cluster
09/19/2014 12:40:06;0008;PBS_Server;Job;42536.tyrone-cluster;Job Run at request of Scheduler@tyrone-cluster
09/19/2014 12:40:06;0040;PBS_Server;Svr;tyrone-cluster;Scheduler was sent the command recyc
09/19/2014 12:40:06;000d;PBS_Server;Job;42536.tyrone-cluster;Not sending email: User does not want mail of this type.
09/19/2014 12:40:22;0040;PBS_Server;Svr;tyrone-cluster;Scheduler was sent the command new
09/19/2014 12:40:53;0040;PBS_Server;Svr;tyrone-cluster;Scheduler was sent the command new
09/19/2014 12:41:22;0040;PBS_Server;Svr;tyrone-cluster;Scheduler was sent the command new
09/19/2014 12:42:07;0040;PBS_Server;Svr;tyrone-cluster;Scheduler was sent the command new
09/19/2014 12:42:37;0040;PBS_Server;Svr;tyrone-cluster;Scheduler was sent the command new
09/19/2014 12:42:40;0002;PBS_Server;Svr;PBS_Server;Torque Server Version = 3.0.5, loglevel = 0
09/19/2014 12:43:08;0040;PBS_Server;Svr;tyrone-cluster;Scheduler was sent the command new
09/19/2014 12:43:37;0040;PBS_Server;Svr;tyrone-cluster;Scheduler was sent the command new
09/19/2014 12:44:21;0040;PBS_Server;Svr;tyrone-cluster;Scheduler was sent the command new
09/19/2014 12:44:53;0040;PBS_Server;Svr;tyrone-cluster;Scheduler was sent the command new
09/19/2014 12:44:53;0100;PBS_Server;Job;42544.tyrone-cluster;enqueuing into batch, state 1 hop 1
09/19/2014 12:44:53;0100;PBS_Server;Job;42544.tyrone-cluster;dequeuing from batch, state QUEUED
09/19/2014 12:44:53;0100;PBS_Server;Job;42544.tyrone-cluster;enqueuing into qp256, state 1 hop 1
09/19/2014 12:44:53;0008;PBS_Server;Job;42544.tyrone-cluster;Job Queued at request of chemraja@tyrone-cluster, owner = chemraja@tyrone-cluster, job name = epoxy_both, queue = qp256
09/19/2014 12:44:53;0008;PBS_Server;Job;42544.tyrone-cluster;Job Modified at request of Scheduler@tyrone-cluster
09/19/2014 12:44:53;0008;PBS_Server;Job;42544.tyrone-cluster;Job Run at request of Scheduler@tyrone-cluster
09/19/2014 12:44:53;0040;PBS_Server;Svr;tyrone-cluster;Scheduler was sent the command recyc
09/19/2014 12:45:23;0040;PBS_Server;Svr;tyrone-cluster;Scheduler was sent the command new
09/19/2014 12:45:23;0008;PBS_Server;Job;42540.tyrone-cluster;Job Modified at request of Scheduler@tyrone-cluster
09/19/2014 12:45:44;000d;PBS_Server;Job;42544.tyrone-cluster;Not sending email: User does not want mail of this type.
09/19/2014 12:45:52;0040;PBS_Server;Svr;tyrone-cluster;Scheduler was sent the command new
09/19/2014 12:46:29;0040;PBS_Server;Svr;tyrone-cluster;Scheduler was sent the command new
09/19/2014 12:46:40;0100;PBS_Server;Job;42545.tyrone-cluster;enqueuing into batch, state 1 hop 1
09/19/2014 12:46:40;0100;PBS_Server;Job;42545.tyrone-cluster;dequeuing from batch, state QUEUED
09/19/2014 12:46:40;0100;PBS_Server;Job;42545.tyrone-cluster;enqueuing into qp256, state 1 hop 1
09/19/2014 12:46:40;0008;PBS_Server;Job;42545.tyrone-cluster;Job Queued at request of chemraja@tyrone-cluster, owner = chemraja@tyrone-cluster, job name = epoxy_hydroxyl, queue = qp256
09/19/2014 12:46:40;0040;PBS_Server;Svr;tyrone-cluster;Scheduler was sent the command new
09/19/2014 12:46:40;0008;PBS_Server;Job;42545.tyrone-cluster;Job Modified at request of Scheduler@tyrone-cluster
09/19/2014 12:46:59;0040;PBS_Server;Svr;tyrone-cluster;Scheduler was sent the command new
09/19/2014 12:47:33;0040;PBS_Server;Svr;tyrone-cluster;Scheduler was sent the command new
09/19/2014 12:47:40;0002;PBS_Server;Svr;PBS_Server;Torque Server Version = 3.0.5, loglevel = 0
09/19/2014 12:47:40;0100;PBS_Server;Job;42546.tyrone-cluster;enqueuing into batch, state 1 hop 1
09/19/2014 12:47:40;0100;PBS_Server;Job;42546.tyrone-cluster;dequeuing from batch, state QUEUED
09/19/2014 12:47:40;0100;PBS_Server;Job;42546.tyrone-cluster;enqueuing into qp64, state 1 hop 1
09/19/2014 12:47:40;0008;PBS_Server;Job;42546.tyrone-cluster;Job Queued at request of metsomya@tyrone-cluster, owner = metsomya@tyrone-cluster, job name = 35-2, queue = qp64
09/19/2014 12:47:40;0040;PBS_Server;Svr;tyrone-cluster;Scheduler was sent the command new
09/19/2014 12:47:40;0008;PBS_Server;Job;42546.tyrone-cluster;Job Modified at request of Scheduler@tyrone-cluster
09/19/2014 12:47:40;0008;PBS_Server;Job;42546.tyrone-cluster;Job Run at request of Scheduler@tyrone-cluster
09/19/2014 12:47:40;0040;PBS_Server;Svr;tyrone-cluster;Scheduler was sent the command recyc
09/19/2014 12:48:06;0040;PBS_Server;Svr;tyrone-cluster;Scheduler was sent the command new
09/19/2014 12:48:42;0040;PBS_Server;Svr;tyrone-cluster;Scheduler was sent the command new
09/19/2014 12:48:43;0100;PBS_Server;Job;42547.tyrone-cluster;enqueuing into batch, state 1 hop 1
09/19/2014 12:48:44;0100;PBS_Server;Job;42547.tyrone-cluster;dequeuing from batch, state QUEUED
09/19/2014 12:48:44;0100;PBS_Server;Job;42547.tyrone-cluster;enqueuing into qp32, state 1 hop 1
09/19/2014 12:48:44;0008;PBS_Server;Job;42547.tyrone-cluster;Job Queued at request of metsomya@tyrone-cluster, owner = metsomya@tyrone-cluster, job name = 30-2, queue = qp32
09/19/2014 12:48:48;000d;PBS_Server;Job;42546.tyrone-cluster;Not sending email: User does not want mail of this type.
09/19/2014 12:48:48;0008;PBS_Server;Job;42547.tyrone-cluster;Job Modified at request of Scheduler@tyrone-cluster
09/19/2014 12:48:58;0100;PBS_Server;Job;42548.tyrone-cluster;enqueuing into batch, state 1 hop 1
09/19/2014 12:48:58;0100;PBS_Server;Job;42548.tyrone-cluster;dequeuing from batch, state QUEUED
09/19/2014 12:48:58;0100;PBS_Server;Job;42548.tyrone-cluster;enqueuing into qp128, state 1 hop 1
09/19/2014 12:48:58;0008;PBS_Server;Job;42548.tyrone-cluster;Job Queued at request of chemraja@tyrone-cluster, owner = chemraja@tyrone-cluster, job name = epoxy_hydroxyl_carboxyl, queue = qp128
09/19/2014 12:48:58;0040;PBS_Server;Svr;tyrone-cluster;Scheduler was sent the command new
09/19/2014 12:48:58;0008;PBS_Server;Job;42548.tyrone-cluster;Job Modified at request of Scheduler@tyrone-cluster
09/19/2014 12:49:08;0040;PBS_Server;Svr;tyrone-cluster;Scheduler was sent the command new
09/19/2014 12:49:36;0040;PBS_Server;Svr;tyrone-cluster;Scheduler was sent the command new
09/19/2014 12:50:12;0040;PBS_Server;Svr;tyrone-cluster;Scheduler was sent the command new
09/19/2014 12:50:38;0040;PBS_Server;Svr;tyrone-cluster;Scheduler was sent the command new
09/19/2014 12:51:07;0040;PBS_Server;Svr;tyrone-cluster;Scheduler was sent the command new
09/19/2014 12:51:44;0040;PBS_Server;Svr;tyrone-cluster;Scheduler was sent the command new
09/19/2014 12:52:08;0040;PBS_Server;Svr;tyrone-cluster;Scheduler was sent the command new
09/19/2014 12:52:37;0040;PBS_Server;Svr;tyrone-cluster;Scheduler was sent the command new
09/19/2014 12:52:40;0002;PBS_Server;Svr;PBS_Server;Torque Server Version = 3.0.5, loglevel = 0
09/19/2014 12:53:14;0040;PBS_Server;Svr;tyrone-cluster;Scheduler was sent the command new
09/19/2014 12:53:44;0040;PBS_Server;Svr;tyrone-cluster;Scheduler was sent the command new
09/19/2014 12:54:20;0040;PBS_Server;Svr;tyrone-cluster;Scheduler was sent the command new
09/19/2014 12:54:48;0040;PBS_Server;Svr;tyrone-cluster;Scheduler was sent the command new
09/19/2014 12:55:20;0040;PBS_Server;Svr;tyrone-cluster;Scheduler was sent the command new
09/19/2014 12:55:52;0040;PBS_Server;Svr;tyrone-cluster;Scheduler was sent the command new
09/19/2014 12:56:21;0040;PBS_Server;Svr;tyrone-cluster;Scheduler was sent the command new
09/19/2014 12:56:51;0040;PBS_Server;Svr;tyrone-cluster;Scheduler was sent the command new
09/19/2014 12:57:23;0040;PBS_Server;Svr;tyrone-cluster;Scheduler was sent the command new
09/19/2014 12:57:40;0002;PBS_Server;Svr;PBS_Server;Torque Server Version = 3.0.5, loglevel = 0
09/19/2014 12:57:52;0040;PBS_Server;Svr;tyrone-cluster;Scheduler was sent the command new
09/19/2014 12:58:29;0040;PBS_Server;Svr;tyrone-cluster;Scheduler was sent the command new
09/19/2014 12:58:53;0040;PBS_Server;Svr;tyrone-cluster;Scheduler was sent the command new
09/19/2014 12:59:22;0040;PBS_Server;Svr;tyrone-cluster;Scheduler was sent the command new
09/19/2014 12:59:59;0040;PBS_Server;Svr;tyrone-cluster;Scheduler was sent the command new
09/19/2014 13:00:29;0040;PBS_Server;Svr;tyrone-cluster;Scheduler was sent the command new
09/19/2014 13:01:05;0040;PBS_Server;Svr;tyrone-cluster;Scheduler was sent the command new
09/19/2014 13:01:33;0040;PBS_Server;Svr;tyrone-cluster;Scheduler was sent the command new
09/19/2014 13:02:06;0040;PBS_Server;Svr;tyrone-cluster;Scheduler was sent the command new
09/19/2014 13:02:37;0040;PBS_Server;Svr;tyrone-cluster;Scheduler was sent the command new
09/19/2014 13:02:40;0002;PBS_Server;Svr;PBS_Server;Torque Server Version = 3.0.5, loglevel = 0
09/19/2014 13:03:06;0040;PBS_Server;Svr;tyrone-cluster;Scheduler was sent the command new
09/19/2014 13:03:44;0040;PBS_Server;Svr;tyrone-cluster;Scheduler was sent the command new
09/19/2014 13:04:08;0040;PBS_Server;Svr;tyrone-cluster;Scheduler was sent the command new
09/19/2014 13:04:37;0040;PBS_Server;Svr;tyrone-cluster;Scheduler was sent the command new
09/19/2014 13:05:14;0040;PBS_Server;Svr;tyrone-cluster;Scheduler was sent the command new
09/19/2014 13:05:44;0040;PBS_Server;Svr;tyrone-cluster;Scheduler was sent the command new
09/19/2014 13:06:13;0040;PBS_Server;Svr;tyrone-cluster;Scheduler was sent the command new
09/19/2014 13:06:44;0040;PBS_Server;Svr;tyrone-cluster;Scheduler was sent the command new
09/19/2014 13:07:14;0040;PBS_Server;Svr;tyrone-cluster;Scheduler was sent the command new
09/19/2014 13:07:40;0002;PBS_Server;Svr;PBS_Server;Torque Server Version = 3.0.5, loglevel = 0
09/19/2014 13:07:50;0040;PBS_Server;Svr;tyrone-cluster;Scheduler was sent the command new
09/19/2014 13:08:18;0040;PBS_Server;Svr;tyrone-cluster;Scheduler was sent the command new
09/19/2014 13:08:50;0040;PBS_Server;Svr;tyrone-cluster;Scheduler was sent the command new
09/19/2014 13:09:21;0040;PBS_Server;Svr;tyrone-cluster;Scheduler was sent the command new
09/19/2014 13:09:51;0040;PBS_Server;Svr;tyrone-cluster;Scheduler was sent the command new
09/19/2014 13:10:21;0040;PBS_Server;Svr;tyrone-cluster;Scheduler was sent the command new
09/19/2014 13:10:53;0040;PBS_Server;Svr;tyrone-cluster;Scheduler was sent the command new
09/19/2014 13:11:22;0040;PBS_Server;Svr;tyrone-cluster;Scheduler was sent the command new
09/19/2014 13:11:59;0040;PBS_Server;Svr;tyrone-cluster;Scheduler was sent the command new
09/19/2014 13:12:29;0040;PBS_Server;Svr;tyrone-cluster;Scheduler was sent the command new
09/19/2014 13:12:40;0002;PBS_Server;Svr;PBS_Server;Torque Server Version = 3.0.5, loglevel = 0
09/19/2014 13:13:05;0040;PBS_Server;Svr;tyrone-cluster;Scheduler was sent the command new
09/19/2014 13:13:33;0040;PBS_Server;Svr;tyrone-cluster;Scheduler was sent the command new
09/19/2014 13:14:06;0040;PBS_Server;Svr;tyrone-cluster;Scheduler was sent the command new
09/19/2014 13:14:37;0040;PBS_Server;Svr;tyrone-cluster;Scheduler was sent the command new
09/19/2014 13:15:06;0040;PBS_Server;Svr;tyrone-cluster;Scheduler was sent the command new
09/19/2014 13:15:44;0040;PBS_Server;Svr;tyrone-cluster;Scheduler was sent the command new
09/19/2014 13:16:08;0040;PBS_Server;Svr;tyrone-cluster;Scheduler was sent the command new
09/19/2014 13:16:37;0040;PBS_Server;Svr;tyrone-cluster;Scheduler was sent the command new
09/19/2014 13:17:14;0040;PBS_Server;Svr;tyrone-cluster;Scheduler was sent the command new
09/19/2014 13:17:40;0002;PBS_Server;Svr;PBS_Server;Torque Server Version = 3.0.5, loglevel = 0
09/19/2014 13:17:45;0040;PBS_Server;Svr;tyrone-cluster;Scheduler was sent the command new
09/19/2014 13:18:20;0040;PBS_Server;Svr;tyrone-cluster;Scheduler was sent the command new
09/19/2014 13:18:48;0040;PBS_Server;Svr;tyrone-cluster;Scheduler was sent the command new
09/19/2014 13:19:21;0040;PBS_Server;Svr;tyrone-cluster;Scheduler was sent the command new
09/19/2014 13:19:52;0040;PBS_Server;Svr;tyrone-cluster;Scheduler was sent the command new
09/19/2014 13:20:21;0040;PBS_Server;Svr;tyrone-cluster;Scheduler was sent the command new
09/19/2014 13:20:51;0040;PBS_Server;Svr;tyrone-cluster;Scheduler was sent the command new
09/19/2014 13:21:21;0040;PBS_Server;Svr;tyrone-cluster;Scheduler was sent the command new
09/19/2014 13:21:51;0040;PBS_Server;Svr;tyrone-cluster;Scheduler was sent the command new
09/19/2014 13:22:21;0040;PBS_Server;Svr;tyrone-cluster;Scheduler was sent the command new
09/19/2014 13:22:40;0002;PBS_Server;Svr;PBS_Server;Torque Server Version = 3.0.5, loglevel = 0
09/19/2014 13:22:53;0040;PBS_Server;Svr;tyrone-cluster;Scheduler was sent the command new
09/19/2014 13:23:22;0040;PBS_Server;Svr;tyrone-cluster;Scheduler was sent the command new
09/19/2014 13:23:59;0040;PBS_Server;Svr;tyrone-cluster;Scheduler was sent the command new
09/19/2014 13:24:29;0040;PBS_Server;Svr;tyrone-cluster;Scheduler was sent the command new
09/19/2014 13:25:05;0040;PBS_Server;Svr;tyrone-cluster;Scheduler was sent the command new
09/19/2014 13:25:33;0040;PBS_Server;Svr;tyrone-cluster;Scheduler was sent the command new
09/19/2014 13:26:05;0040;PBS_Server;Svr;tyrone-cluster;Scheduler was sent the command new
09/19/2014 13:26:37;0040;PBS_Server;Svr;tyrone-cluster;Scheduler was sent the command new
09/19/2014 13:27:06;0040;PBS_Server;Svr;tyrone-cluster;Scheduler was sent the command new
09/19/2014 13:27:40;0002;PBS_Server;Svr;PBS_Server;Torque Server Version = 3.0.5, loglevel = 0
09/19/2014 13:27:40;0040;PBS_Server;Svr;tyrone-cluster;Scheduler was sent the command new
09/19/2014 13:28:08;0040;PBS_Server;Svr;tyrone-cluster;Scheduler was sent the command new
09/19/2014 13:28:17;0100;PBS_Server;Job;42549.tyrone-cluster;enqueuing into batch, state 1 hop 1
09/19/2014 13:28:17;0008;PBS_Server;Job;42549.tyrone-cluster;Job Queued at request of metsomya@tyrone-cluster, owner = metsomya@tyrone-cluster, job name = 35-3, queue = batch
09/19/2014 13:28:17;0040;PBS_Server;Svr;tyrone-cluster;Scheduler was sent the command new
09/19/2014 13:28:17;0008;PBS_Server;Job;42549.tyrone-cluster;Job Modified at request of Scheduler@tyrone-cluster
09/19/2014 13:28:37;0040;PBS_Server;Svr;tyrone-cluster;Scheduler was sent the command new
09/19/2014 13:28:50;0040;PBS_Server;Svr;tyrone-cluster;Scheduler was sent the command new
09/19/2014 13:29:14;0040;PBS_Server;Svr;tyrone-cluster;Scheduler was sent the command new
09/19/2014 13:29:18;0040;PBS_Server;Svr;tyrone-cluster;Scheduler was sent the command new
09/19/2014 13:29:44;0040;PBS_Server;Svr;tyrone-cluster;Scheduler was sent the command new
09/19/2014 13:29:50;0040;PBS_Server;Svr;tyrone-cluster;Scheduler was sent the command new
09/19/2014 13:30:20;0040;PBS_Server;Svr;tyrone-cluster;Scheduler was sent the command new
09/19/2014 13:30:48;0040;PBS_Server;Svr;tyrone-cluster;Scheduler was sent the command new
09/19/2014 13:30:50;0040;PBS_Server;Svr;tyrone-cluster;Scheduler was sent the command new
09/19/2014 13:31:21;0040;PBS_Server;Svr;tyrone-cluster;Scheduler was sent the command new
09/19/2014 13:31:52;0040;PBS_Server;Svr;tyrone-cluster;Scheduler was sent the command new
09/19/2014 13:32:21;0040;PBS_Server;Svr;tyrone-cluster;Scheduler was sent the command new
09/19/2014 13:32:22;0040;PBS_Server;Svr;tyrone-cluster;Scheduler was sent the command new
09/19/2014 13:32:40;0002;PBS_Server;Svr;PBS_Server;Torque Server Version = 3.0.5, loglevel = 0
09/19/2014 13:32:51;0040;PBS_Server;Svr;tyrone-cluster;Scheduler was sent the command new
09/19/2014 13:32:59;0040;PBS_Server;Svr;tyrone-cluster;Scheduler was sent the command new
09/19/2014 13:33:23;0040;PBS_Server;Svr;tyrone-cluster;Scheduler was sent the command new
09/19/2014 13:33:29;0040;PBS_Server;Svr;tyrone-cluster;Scheduler was sent the command new
09/19/2014 13:33:51;0040;PBS_Server;Svr;tyrone-cluster;Scheduler was sent the command new
09/19/2014 13:34:05;0040;PBS_Server;Svr;tyrone-cluster;Scheduler was sent the command new
09/19/2014 13:34:29;0040;PBS_Server;Svr;tyrone-cluster;Scheduler was sent the command new
09/19/2014 13:34:33;0040;PBS_Server;Svr;tyrone-cluster;Scheduler was sent the command new
09/19/2014 13:34:53;0040;PBS_Server;Svr;tyrone-cluster;Scheduler was sent the command new
09/19/2014 13:35:06;0040;PBS_Server;Svr;tyrone-cluster;Scheduler was sent the command new
09/19/2014 13:35:23;0040;PBS_Server;Svr;tyrone-cluster;Scheduler was sent the command new
09/19/2014 13:35:37;0040;PBS_Server;Svr;tyrone-cluster;Scheduler was sent the command new
09/19/2014 13:35:51;0040;PBS_Server;Svr;tyrone-cluster;Scheduler was sent the command new
09/19/2014 13:36:05;0040;PBS_Server;Svr;tyrone-cluster;Scheduler was sent the command new
09/19/2014 13:36:23;0040;PBS_Server;Svr;tyrone-cluster;Scheduler was sent the command new
09/19/2014 13:36:36;0040;PBS_Server;Svr;tyrone-cluster;Scheduler was sent the command new
09/19/2014 13:36:51;0040;PBS_Server;Svr;tyrone-cluster;Scheduler was sent the command new
09/19/2014 13:37:07;0040;PBS_Server;Svr;tyrone-cluster;Scheduler was sent the command new
09/19/2014 13:37:29;0040;PBS_Server;Svr;tyrone-cluster;Scheduler was sent the command new
09/19/2014 13:37:35;0040;PBS_Server;Svr;tyrone-cluster;Scheduler was sent the command new
09/19/2014 13:37:40;0002;PBS_Server;Svr;PBS_Server;Torque Server Version = 3.0.5, loglevel = 0
09/19/2014 13:37:53;0040;PBS_Server;Svr;tyrone-cluster;Scheduler was sent the command new
09/19/2014 13:38:06;0040;PBS_Server;Svr;tyrone-cluster;Scheduler was sent the command new
09/19/2014 13:38:22;0040;PBS_Server;Svr;tyrone-cluster;Scheduler was sent the command new
09/19/2014 13:38:36;0040;PBS_Server;Svr;tyrone-cluster;Scheduler was sent the command new
09/19/2014 13:38:59;0040;PBS_Server;Svr;tyrone-cluster;Scheduler was sent the command new
09/19/2014 13:39:06;0040;PBS_Server;Svr;tyrone-cluster;Scheduler was sent the command new
09/19/2014 13:39:29;0040;PBS_Server;Svr;tyrone-cluster;Scheduler was sent the command new
09/19/2014 13:39:36;0040;PBS_Server;Svr;tyrone-cluster;Scheduler was sent the command new
09/19/2014 13:40:05;0040;PBS_Server;Svr;tyrone-cluster;Scheduler was sent the command new
09/19/2014 13:40:33;0040;PBS_Server;Svr;tyrone-cluster;Scheduler was sent the command new
09/19/2014 13:40:36;0040;PBS_Server;Svr;tyrone-cluster;Scheduler was sent the command new
09/19/2014 13:41:06;0040;PBS_Server;Svr;tyrone-cluster;Scheduler was sent the command new
09/19/2014 13:41:37;0040;PBS_Server;Svr;tyrone-cluster;Scheduler was sent the command new
09/19/2014 13:42:05;0040;PBS_Server;Svr;tyrone-cluster;Scheduler was sent the command new
09/19/2014 13:42:07;0040;PBS_Server;Svr;tyrone-cluster;Scheduler was sent the command new
09/19/2014 13:42:35;0040;PBS_Server;Svr;tyrone-cluster;Scheduler was sent the command new
09/19/2014 13:42:40;0002;PBS_Server;Svr;PBS_Server;Torque Server Version = 3.0.5, loglevel = 0
09/19/2014 13:42:42;0040;PBS_Server;Svr;tyrone-cluster;Scheduler was sent the command new
09/19/2014 13:43:07;0040;PBS_Server;Svr;tyrone-cluster;Scheduler was sent the command new
09/19/2014 13:43:10;0040;PBS_Server;Svr;tyrone-cluster;Scheduler was sent the command new
09/19/2014 13:43:35;0040;PBS_Server;Svr;tyrone-cluster;Scheduler was sent the command new
09/19/2014 13:43:42;0040;PBS_Server;Svr;tyrone-cluster;Scheduler was sent the command new
09/19/2014 13:44:06;0040;PBS_Server;Svr;tyrone-cluster;Scheduler was sent the command new
09/19/2014 13:44:14;0040;PBS_Server;Svr;tyrone-cluster;Scheduler was sent the command new
09/19/2014 13:44:36;0040;PBS_Server;Svr;tyrone-cluster;Scheduler was sent the command new
09/19/2014 13:44:44;0040;PBS_Server;Svr;tyrone-cluster;Scheduler was sent the command new
09/19/2014 13:45:05;0040;PBS_Server;Svr;tyrone-cluster;Scheduler was sent the command new
09/19/2014 13:45:20;0040;PBS_Server;Svr;tyrone-cluster;Scheduler was sent the command new
09/19/2014 13:45:36;0040;PBS_Server;Svr;tyrone-cluster;Scheduler was sent the command new
09/19/2014 13:45:48;0040;PBS_Server;Svr;tyrone-cluster;Scheduler was sent the command new
09/19/2014 13:46:06;0040;PBS_Server;Svr;tyrone-cluster;Scheduler was sent the command new
09/19/2014 13:46:20;0040;PBS_Server;Svr;tyrone-cluster;Scheduler was sent the command new
09/19/2014 13:46:36;0040;PBS_Server;Svr;tyrone-cluster;Scheduler was sent the command new
09/19/2014 13:46:52;0040;PBS_Server;Svr;tyrone-cluster;Scheduler was sent the command new
09/19/2014 13:47:06;0040;PBS_Server;Svr;tyrone-cluster;Scheduler was sent the command new
09/19/2014 13:47:20;0040;PBS_Server;Svr;tyrone-cluster;Scheduler was sent the command new
09/19/2014 13:47:37;0040;PBS_Server;Svr;tyrone-cluster;Scheduler was sent the command new
09/19/2014 13:47:40;0002;PBS_Server;Svr;PBS_Server;Torque Server Version = 3.0.5, loglevel = 0
09/19/2014 13:47:50;0040;PBS_Server;Svr;tyrone-cluster;Scheduler was sent the command new
09/19/2014 13:48:07;0040;PBS_Server;Svr;tyrone-cluster;Scheduler was sent the command new
09/19/2014 13:48:21;0040;PBS_Server;Svr;tyrone-cluster;Scheduler was sent the command new
09/19/2014 13:48:44;0040;PBS_Server;Svr;tyrone-cluster;Scheduler was sent the command new
09/19/2014 13:48:50;0040;PBS_Server;Svr;tyrone-cluster;Scheduler was sent the command new
09/19/2014 13:49:14;0040;PBS_Server;Svr;tyrone-cluster;Scheduler was sent the command new
09/19/2014 13:49:21;0040;PBS_Server;Svr;tyrone-cluster;Scheduler was sent the command new
09/19/2014 13:49:50;0040;PBS_Server;Svr;tyrone-cluster;Scheduler was sent the command new
09/19/2014 13:50:18;0040;PBS_Server;Svr;tyrone-cluster;Scheduler was sent the command new
09/19/2014 13:50:20;0040;PBS_Server;Svr;tyrone-cluster;Scheduler was sent the command new
09/19/2014 13:50:50;0040;PBS_Server;Svr;tyrone-cluster;Scheduler was sent the command new
09/19/2014 13:51:22;0040;PBS_Server;Svr;tyrone-cluster;Scheduler was sent the command new
09/19/2014 13:51:50;0040;PBS_Server;Svr;tyrone-cluster;Scheduler was sent the command new
09/19/2014 13:52:21;0040;PBS_Server;Svr;tyrone-cluster;Scheduler was sent the command new
09/19/2014 13:52:40;0002;PBS_Server;Svr;PBS_Server;Torque Server Version = 3.0.5, loglevel = 0
09/19/2014 13:52:52;0040;PBS_Server;Svr;tyrone-cluster;Scheduler was sent the command new
09/19/2014 13:53:22;0040;PBS_Server;Svr;tyrone-cluster;Scheduler was sent the command new
09/19/2014 13:53:59;0040;PBS_Server;Svr;tyrone-cluster;Scheduler was sent the command new
09/19/2014 13:54:29;0040;PBS_Server;Svr;tyrone-cluster;Scheduler was sent the command new
09/19/2014 13:55:05;0040;PBS_Server;Svr;tyrone-cluster;Scheduler was sent the command new
09/19/2014 13:55:33;0040;PBS_Server;Svr;tyrone-cluster;Scheduler was sent the command new
09/19/2014 13:56:05;0040;PBS_Server;Svr;tyrone-cluster;Scheduler was sent the command new
09/19/2014 13:56:36;0040;PBS_Server;Svr;tyrone-cluster;Scheduler was sent the command new
09/19/2014 13:57:05;0040;PBS_Server;Svr;tyrone-cluster;Scheduler was sent the command new
09/19/2014 13:57:36;0040;PBS_Server;Svr;tyrone-cluster;Scheduler was sent the command new
09/19/2014 13:57:40;0002;PBS_Server;Svr;PBS_Server;Torque Server Version = 3.0.5, loglevel = 0
09/19/2014 13:58:07;0040;PBS_Server;Svr;tyrone-cluster;Scheduler was sent the command new
09/19/2014 13:58:35;0040;PBS_Server;Svr;tyrone-cluster;Scheduler was sent the command new
09/19/2014 13:59:05;0040;PBS_Server;Svr;tyrone-cluster;Scheduler was sent the command new
09/19/2014 13:59:37;0040;PBS_Server;Svr;tyrone-cluster;Scheduler was sent the command new
09/19/2014 14:00:05;0040;PBS_Server;Svr;tyrone-cluster;Scheduler was sent the command new
09/19/2014 14:00:36;0040;PBS_Server;Svr;tyrone-cluster;Scheduler was sent the command new
09/19/2014 14:01:07;0040;PBS_Server;Svr;tyrone-cluster;Scheduler was sent the command new
09/19/2014 14:01:35;0040;PBS_Server;Svr;tyrone-cluster;Scheduler was sent the command new
09/19/2014 14:02:06;0040;PBS_Server;Svr;tyrone-cluster;Scheduler was sent the command new
09/19/2014 14:02:38;0040;PBS_Server;Svr;tyrone-cluster;Scheduler was sent the command new
09/19/2014 14:02:40;0002;PBS_Server;Svr;PBS_Server;Torque Server Version = 3.0.5, loglevel = 0
09/19/2014 14:03:07;0040;PBS_Server;Svr;tyrone-cluster;Scheduler was sent the command new
09/19/2014 14:03:19;0100;PBS_Server;Job;42550.tyrone-cluster;enqueuing into batch, state 1 hop 1
09/19/2014 14:03:19;0100;PBS_Server;Job;42550.tyrone-cluster;dequeuing from batch, state QUEUED
09/19/2014 14:03:19;0100;PBS_Server;Job;42550.tyrone-cluster;enqueuing into qp128, state 1 hop 1
09/19/2014 14:03:19;0008;PBS_Server;Job;42550.tyrone-cluster;Job Queued at request of chekpp@tyrone-cluster, owner = chekpp@tyrone-cluster, job name = fun, queue = qp128
09/19/2014 14:03:19;0040;PBS_Server;Svr;tyrone-cluster;Scheduler was sent the command new
09/19/2014 14:03:19;0008;PBS_Server;Job;42550.tyrone-cluster;Job Modified at request of Scheduler@tyrone-cluster
09/19/2014 14:03:44;0040;PBS_Server;Svr;tyrone-cluster;Scheduler was sent the command new
09/19/2014 14:04:14;0040;PBS_Server;Svr;tyrone-cluster;Scheduler was sent the command new
09/19/2014 14:04:50;0040;PBS_Server;Svr;tyrone-cluster;Scheduler was sent the command new
09/19/2014 14:05:18;0040;PBS_Server;Svr;tyrone-cluster;Scheduler was sent the command new
09/19/2014 14:05:50;0040;PBS_Server;Svr;tyrone-cluster;Scheduler was sent the command new
09/19/2014 14:06:21;0040;PBS_Server;Svr;tyrone-cluster;Scheduler was sent the command new
09/19/2014 14:06:50;0040;PBS_Server;Svr;tyrone-cluster;Scheduler was sent the command new
09/19/2014 14:07:21;0040;PBS_Server;Svr;tyrone-cluster;Scheduler was sent the command new
09/19/2014 14:07:40;0002;PBS_Server;Svr;PBS_Server;Torque Server Version = 3.0.5, loglevel = 0
09/19/2014 14:07:52;0040;PBS_Server;Svr;tyrone-cluster;Scheduler was sent the command new
09/19/2014 14:08:21;0040;PBS_Server;Svr;tyrone-cluster;Scheduler was sent the command new
09/19/2014 14:08:50;0040;PBS_Server;Svr;tyrone-cluster;Scheduler was sent the command new
09/19/2014 14:09:22;0040;PBS_Server;Svr;tyrone-cluster;Scheduler was sent the command new
09/19/2014 14:09:51;0040;PBS_Server;Svr;tyrone-cluster;Scheduler was sent the command new
09/19/2014 14:10:20;0040;PBS_Server;Svr;tyrone-cluster;Scheduler was sent the command new
09/19/2014 14:10:51;0040;PBS_Server;Svr;tyrone-cluster;Scheduler was sent the command new
09/19/2014 14:11:21;0040;PBS_Server;Svr;tyrone-cluster;Scheduler was sent the command new
09/19/2014 14:11:59;0040;PBS_Server;Svr;tyrone-cluster;Scheduler was sent the command new
09/19/2014 14:12:30;0040;PBS_Server;Svr;tyrone-cluster;Scheduler was sent the command new
09/19/2014 14:12:40;0002;PBS_Server;Svr;PBS_Server;Torque Server Version = 3.0.5, loglevel = 0
09/19/2014 14:13:05;0040;PBS_Server;Svr;tyrone-cluster;Scheduler was sent the command new
09/19/2014 14:13:33;0040;PBS_Server;Svr;tyrone-cluster;Scheduler was sent the command new
09/19/2014 14:14:05;0040;PBS_Server;Svr;tyrone-cluster;Scheduler was sent the command new
09/19/2014 14:14:36;0040;PBS_Server;Svr;tyrone-cluster;Scheduler was sent the command new
09/19/2014 14:15:05;0040;PBS_Server;Svr;tyrone-cluster;Scheduler was sent the command new
09/19/2014 14:15:09;0100;PBS_Server;Job;42551.tyrone-cluster;enqueuing into batch, state 1 hop 1
09/19/2014 14:15:09;0100;PBS_Server;Job;42551.tyrone-cluster;dequeuing from batch, state QUEUED
09/19/2014 14:15:09;0100;PBS_Server;Job;42551.tyrone-cluster;enqueuing into qp128, state 1 hop 1
09/19/2014 14:15:09;0008;PBS_Server;Job;42551.tyrone-cluster;Job Queued at request of chekpp@tyrone-cluster, owner = chekpp@tyrone-cluster, job name = fun1, queue = qp128
09/19/2014 14:15:09;0040;PBS_Server;Svr;tyrone-cluster;Scheduler was sent the command new
09/19/2014 14:15:09;0008;PBS_Server;Job;42551.tyrone-cluster;Job Modified at request of Scheduler@tyrone-cluster
09/19/2014 14:15:36;0040;PBS_Server;Svr;tyrone-cluster;Scheduler was sent the command new
09/19/2014 14:16:07;0040;PBS_Server;Svr;tyrone-cluster;Scheduler was sent the command new
09/19/2014 14:16:35;0040;PBS_Server;Svr;tyrone-cluster;Scheduler was sent the command new
09/19/2014 14:17:06;0040;PBS_Server;Svr;tyrone-cluster;Scheduler was sent the command new
09/19/2014 14:17:37;0040;PBS_Server;Svr;tyrone-cluster;Scheduler was sent the command new
09/19/2014 14:17:40;0002;PBS_Server;Svr;PBS_Server;Torque Server Version = 3.0.5, loglevel = 0
09/19/2014 14:18:06;0040;PBS_Server;Svr;tyrone-cluster;Scheduler was sent the command new
09/19/2014 14:18:44;0040;PBS_Server;Svr;tyrone-cluster;Scheduler was sent the command new
09/19/2014 14:19:14;0040;PBS_Server;Svr;tyrone-cluster;Scheduler was sent the command new
09/19/2014 14:19:50;0040;PBS_Server;Svr;tyrone-cluster;Scheduler was sent the command new
09/19/2014 14:20:07;0100;PBS_Server;Job;42552.tyrone-cluster;enqueuing into batch, state 1 hop 1
09/19/2014 14:20:07;0100;PBS_Server;Job;42552.tyrone-cluster;dequeuing from batch, state QUEUED
09/19/2014 14:20:07;0100;PBS_Server;Job;42552.tyrone-cluster;enqueuing into qp256, state 1 hop 1
09/19/2014 14:20:07;0008;PBS_Server;Job;42552.tyrone-cluster;Job Queued at request of sectanuj@tyrone-cluster, owner = sectanuj@tyrone-cluster, job name = 4CoresP88, queue = qp256
09/19/2014 14:20:07;0040;PBS_Server;Svr;tyrone-cluster;Scheduler was sent the command new
09/19/2014 14:20:07;0008;PBS_Server;Job;42552.tyrone-cluster;Job Modified at request of Scheduler@tyrone-cluster
09/19/2014 14:20:10;0100;PBS_Server;Job;42553.tyrone-cluster;enqueuing into batch, state 1 hop 1
09/19/2014 14:20:10;0100;PBS_Server;Job;42553.tyrone-cluster;dequeuing from batch, state QUEUED
09/19/2014 14:20:10;0100;PBS_Server;Job;42553.tyrone-cluster;enqueuing into qp256, state 1 hop 1
09/19/2014 14:20:10;0008;PBS_Server;Job;42553.tyrone-cluster;Job Queued at request of sectanuj@tyrone-cluster, owner = sectanuj@tyrone-cluster, job name = 4CoresP816, queue = qp256
09/19/2014 14:20:10;0040;PBS_Server;Svr;tyrone-cluster;Scheduler was sent the command new
09/19/2014 14:20:10;0008;PBS_Server;Job;42553.tyrone-cluster;Job Modified at request of Scheduler@tyrone-cluster
09/19/2014 14:20:18;0040;PBS_Server;Svr;tyrone-cluster;Scheduler was sent the command new
09/19/2014 14:20:50;0040;PBS_Server;Svr;tyrone-cluster;Scheduler was sent the command new
09/19/2014 14:21:03;0100;PBS_Server;Job;42554.tyrone-cluster;enqueuing into batch, state 1 hop 1
09/19/2014 14:21:03;0008;PBS_Server;Job;42554.tyrone-cluster;Job Queued at request of chemraja@tyrone-cluster, owner = chemraja@tyrone-cluster, job name = NAME, queue = batch
09/19/2014 14:21:03;0040;PBS_Server;Svr;tyrone-cluster;Scheduler was sent the command new
09/19/2014 14:21:03;0008;PBS_Server;Job;42554.tyrone-cluster;Job Modified at request of Scheduler@tyrone-cluster
09/19/2014 14:21:22;0040;PBS_Server;Svr;tyrone-cluster;Scheduler was sent the command new
09/19/2014 14:21:35;0040;PBS_Server;Svr;tyrone-cluster;Scheduler was sent the command new
09/19/2014 14:21:50;0040;PBS_Server;Svr;tyrone-cluster;Scheduler was sent the command new
09/19/2014 14:22:06;0040;PBS_Server;Svr;tyrone-cluster;Scheduler was sent the command new
09/19/2014 14:22:20;0040;PBS_Server;Svr;tyrone-cluster;Scheduler was sent the command new
09/19/2014 14:22:36;0040;PBS_Server;Svr;tyrone-cluster;Scheduler was sent the command new
09/19/2014 14:22:40;0002;PBS_Server;Svr;PBS_Server;Torque Server Version = 3.0.5, loglevel = 0
09/19/2014 14:22:47;0100;PBS_Server;Job;42555.tyrone-cluster;enqueuing into batch, state 1 hop 1
09/19/2014 14:22:47;0100;PBS_Server;Job;42555.tyrone-cluster;dequeuing from batch, state QUEUED
09/19/2014 14:22:47;0100;PBS_Server;Job;42555.tyrone-cluster;enqueuing into idqueue, state 1 hop 1
09/19/2014 14:22:47;0008;PBS_Server;Job;42555.tyrone-cluster;Job Queued at request of chevadh@tyrone-cluster, owner = chevadh@tyrone-cluster, job name = jobname, queue = idqueue
09/19/2014 14:22:47;0040;PBS_Server;Svr;tyrone-cluster;Scheduler was sent the command new
09/19/2014 14:22:48;0008;PBS_Server;Job;42555.tyrone-cluster;Job Modified at request of Scheduler@tyrone-cluster
09/19/2014 14:22:51;0040;PBS_Server;Svr;tyrone-cluster;Scheduler was sent the command new
09/19/2014 14:22:51;0100;PBS_Server;Job;42556.tyrone-cluster;enqueuing into batch, state 1 hop 1
09/19/2014 14:22:51;0100;PBS_Server;Job;42556.tyrone-cluster;dequeuing from batch, state QUEUED
09/19/2014 14:22:51;0100;PBS_Server;Job;42556.tyrone-cluster;enqueuing into idqueue, state 1 hop 1
09/19/2014 14:22:51;0008;PBS_Server;Job;42556.tyrone-cluster;Job Queued at request of chevadh@tyrone-cluster, owner = chevadh@tyrone-cluster, job name = jobname, queue = idqueue
09/19/2014 14:22:51;0008;PBS_Server;Job;42556.tyrone-cluster;Job Modified at request of Scheduler@tyrone-cluster
09/19/2014 14:23:05;0040;PBS_Server;Svr;tyrone-cluster;Scheduler was sent the command new
09/19/2014 14:23:20;0040;PBS_Server;Svr;tyrone-cluster;Scheduler was sent the command new
09/19/2014 14:23:37;0040;PBS_Server;Svr;tyrone-cluster;Scheduler was sent the command new
09/19/2014 14:23:51;0040;PBS_Server;Svr;tyrone-cluster;Scheduler was sent the command new
09/19/2014 14:24:06;0040;PBS_Server;Svr;tyrone-cluster;Scheduler was sent the command new
09/19/2014 14:24:22;0040;PBS_Server;Svr;tyrone-cluster;Scheduler was sent the command new
09/19/2014 14:24:44;0040;PBS_Server;Svr;tyrone-cluster;Scheduler was sent the command new
09/19/2014 14:24:50;0040;PBS_Server;Svr;tyrone-cluster;Scheduler was sent the command new
09/19/2014 14:25:14;0040;PBS_Server;Svr;tyrone-cluster;Scheduler was sent the command new
09/19/2014 14:25:21;0040;PBS_Server;Svr;tyrone-cluster;Scheduler was sent the command new
09/19/2014 14:25:50;0040;PBS_Server;Svr;tyrone-cluster;Scheduler was sent the command new
09/19/2014 14:25:52;0040;PBS_Server;Svr;tyrone-cluster;Scheduler was sent the command new
09/19/2014 14:26:18;0040;PBS_Server;Svr;tyrone-cluster;Scheduler was sent the command new
09/19/2014 14:26:22;0040;PBS_Server;Svr;tyrone-cluster;Scheduler was sent the command new
09/19/2014 14:26:50;0040;PBS_Server;Svr;tyrone-cluster;Scheduler was sent the command new
09/19/2014 14:26:59;0040;PBS_Server;Svr;tyrone-cluster;Scheduler was sent the command new
09/19/2014 14:27:21;0040;PBS_Server;Svr;tyrone-cluster;Scheduler was sent the command new
09/19/2014 14:27:29;0040;PBS_Server;Svr;tyrone-cluster;Scheduler was sent the command new
09/19/2014 14:27:40;0002;PBS_Server;Svr;PBS_Server;Torque Server Version = 3.0.5, loglevel = 0
09/19/2014 14:27:51;0040;PBS_Server;Svr;tyrone-cluster;Scheduler was sent the command new
09/19/2014 14:28:05;0040;PBS_Server;Svr;tyrone-cluster;Scheduler was sent the command new
09/19/2014 14:28:20;0040;PBS_Server;Svr;tyrone-cluster;Scheduler was sent the command new
09/19/2014 14:28:33;0040;PBS_Server;Svr;tyrone-cluster;Scheduler was sent the command new
09/19/2014 14:28:51;0040;PBS_Server;Svr;tyrone-cluster;Scheduler was sent the command new
09/19/2014 14:29:05;0040;PBS_Server;Svr;tyrone-cluster;Scheduler was sent the command new
09/19/2014 14:29:21;0040;PBS_Server;Svr;tyrone-cluster;Scheduler was sent the command new
09/19/2014 14:29:37;0040;PBS_Server;Svr;tyrone-cluster;Scheduler was sent the command new
09/19/2014 14:29:59;0040;PBS_Server;Svr;tyrone-cluster;Scheduler was sent the command new
09/19/2014 14:30:06;0040;PBS_Server;Svr;tyrone-cluster;Scheduler was sent the command new
09/19/2014 14:30:29;0040;PBS_Server;Svr;tyrone-cluster;Scheduler was sent the command new
09/19/2014 14:30:35;0040;PBS_Server;Svr;tyrone-cluster;Scheduler was sent the command new
09/19/2014 14:31:05;0040;PBS_Server;Svr;tyrone-cluster;Scheduler was sent the command new
09/19/2014 14:31:33;0040;PBS_Server;Svr;tyrone-cluster;Scheduler was sent the command new
09/19/2014 14:31:36;0040;PBS_Server;Svr;tyrone-cluster;Scheduler was sent the command new
09/19/2014 14:32:05;0040;PBS_Server;Svr;tyrone-cluster;Scheduler was sent the command new
09/19/2014 14:32:37;0040;PBS_Server;Svr;tyrone-cluster;Scheduler was sent the command new
09/19/2014 14:32:40;0002;PBS_Server;Svr;PBS_Server;Torque Server Version = 3.0.5, loglevel = 0
09/19/2014 14:33:05;0040;PBS_Server;Svr;tyrone-cluster;Scheduler was sent the command new
09/19/2014 14:33:35;0040;PBS_Server;Svr;tyrone-cluster;Scheduler was sent the command new
09/19/2014 14:34:06;0040;PBS_Server;Svr;tyrone-cluster;Scheduler was sent the command new
09/19/2014 14:34:36;0040;PBS_Server;Svr;tyrone-cluster;Scheduler was sent the command new
09/19/2014 14:35:05;0040;PBS_Server;Svr;tyrone-cluster;Scheduler was sent the command new
09/19/2014 14:35:36;0040;PBS_Server;Svr;tyrone-cluster;Scheduler was sent the command new
09/19/2014 14:36:06;0040;PBS_Server;Svr;tyrone-cluster;Scheduler was sent the command new
09/19/2014 14:36:35;0040;PBS_Server;Svr;tyrone-cluster;Scheduler was sent the command new
09/19/2014 14:37:06;0040;PBS_Server;Svr;tyrone-cluster;Scheduler was sent the command new
09/19/2014 14:37:36;0040;PBS_Server;Svr;tyrone-cluster;Scheduler was sent the command new
09/19/2014 14:37:40;0002;PBS_Server;Svr;PBS_Server;Torque Server Version = 3.0.5, loglevel = 0
09/19/2014 14:38:05;0040;PBS_Server;Svr;tyrone-cluster;Scheduler was sent the command new
09/19/2014 14:38:36;0040;PBS_Server;Svr;tyrone-cluster;Scheduler was sent the command new
09/19/2014 14:39:06;0040;PBS_Server;Svr;tyrone-cluster;Scheduler was sent the command new
09/19/2014 14:39:35;0040;PBS_Server;Svr;tyrone-cluster;Scheduler was sent the command new
09/19/2014 14:40:06;0040;PBS_Server;Svr;tyrone-cluster;Scheduler was sent the command new
09/19/2014 14:40:36;0040;PBS_Server;Svr;tyrone-cluster;Scheduler was sent the command new
09/19/2014 14:40:50;000d;PBS_Server;Job;42536.tyrone-cluster;Not sending email: User does not want mail of this type.
09/19/2014 14:40:50;0010;PBS_Server;Job;42536.tyrone-cluster;Exit_status=143 resources_used.cput=63:24:47 resources_used.mem=410544kb resources_used.vmem=12108120kb resources_used.walltime=02:00:44
09/19/2014 14:40:50;0008;PBS_Server;Job;NULL;on_job_exit valid pjob: 0x2cd6fe0 (substate=50)
09/19/2014 14:40:50;0008;PBS_Server;Job;NULL;on_job_exit valid pjob: 0x2cd6fe0 (substate=51)
09/19/2014 14:40:50;0008;PBS_Server;Job;NULL;on_job_exit valid pjob: 0x2cd6fe0 (substate=51)
09/19/2014 14:40:50;0008;PBS_Server;Job;NULL;on_job_exit valid pjob: 0x2cd6fe0 (substate=53)
09/19/2014 14:40:50;0100;PBS_Server;Job;42536.tyrone-cluster;dequeuing from idqueue, state COMPLETE
09/19/2014 14:40:50;0040;PBS_Server;Svr;tyrone-cluster;Scheduler was sent the command term
09/19/2014 14:40:50;0008;PBS_Server;Job;42537.tyrone-cluster;Job Modified at request of Scheduler@tyrone-cluster
09/19/2014 14:40:50;0008;PBS_Server;Job;42537.tyrone-cluster;Job Run at request of Scheduler@tyrone-cluster
09/19/2014 14:40:50;0040;PBS_Server;Svr;tyrone-cluster;Scheduler was sent the command recyc
09/19/2014 14:40:50;000d;PBS_Server;Job;42537.tyrone-cluster;Not sending email: User does not want mail of this type.
09/19/2014 14:41:05;0040;PBS_Server;Svr;tyrone-cluster;Scheduler was sent the command new
09/19/2014 14:41:36;0040;PBS_Server;Svr;tyrone-cluster;Scheduler was sent the command new
09/19/2014 14:42:05;0040;PBS_Server;Svr;tyrone-cluster;Scheduler was sent the command new
09/19/2014 14:42:35;0040;PBS_Server;Svr;tyrone-cluster;Scheduler was sent the command new
09/19/2014 14:42:40;0002;PBS_Server;Svr;PBS_Server;Torque Server Version = 3.0.5, loglevel = 0
09/19/2014 14:43:06;0040;PBS_Server;Svr;tyrone-cluster;Scheduler was sent the command new
09/19/2014 14:43:36;0040;PBS_Server;Svr;tyrone-cluster;Scheduler was sent the command new
09/19/2014 14:44:05;0040;PBS_Server;Svr;tyrone-cluster;Scheduler was sent the command new
09/19/2014 14:44:36;0040;PBS_Server;Svr;tyrone-cluster;Scheduler was sent the command new
09/19/2014 14:44:52;0100;PBS_Server;Job;42557.tyrone-cluster;enqueuing into batch, state 1 hop 1
09/19/2014 14:44:52;0008;PBS_Server;Job;42557.tyrone-cluster;Job Queued at request of sectanuj@tyrone-cluster, owner = sectanuj@tyrone-cluster, job name = 4Cores2C88, queue = batch
09/19/2014 14:44:52;0040;PBS_Server;Svr;tyrone-cluster;Scheduler was sent the command new
09/19/2014 14:44:52;0008;PBS_Server;Job;42557.tyrone-cluster;Job Modified at request of Scheduler@tyrone-cluster
09/19/2014 14:44:55;0100;PBS_Server;Job;42558.tyrone-cluster;enqueuing into batch, state 1 hop 1
09/19/2014 14:44:55;0008;PBS_Server;Job;42558.tyrone-cluster;Job Queued at request of sectanuj@tyrone-cluster, owner = sectanuj@tyrone-cluster, job name = 4Cores2C816, queue = batch
09/19/2014 14:44:55;0040;PBS_Server;Svr;tyrone-cluster;Scheduler was sent the command new
09/19/2014 14:44:55;0008;PBS_Server;Job;42558.tyrone-cluster;Job Modified at request of Scheduler@tyrone-cluster
09/19/2014 14:45:05;0040;PBS_Server;Svr;tyrone-cluster;Scheduler was sent the command new
09/19/2014 14:45:16;0100;PBS_Server;Job;42559.tyrone-cluster;enqueuing into batch, state 1 hop 1
09/19/2014 14:45:16;0008;PBS_Server;Job;42559.tyrone-cluster;Job Queued at request of sectanuj@tyrone-cluster, owner = sectanuj@tyrone-cluster, job name = 4Cores4C88, queue = batch
09/19/2014 14:45:16;0040;PBS_Server;Svr;tyrone-cluster;Scheduler was sent the command new
09/19/2014 14:45:16;0008;PBS_Server;Job;42559.tyrone-cluster;Job Modified at request of Scheduler@tyrone-cluster
09/19/2014 14:45:18;0100;PBS_Server;Job;42560.tyrone-cluster;enqueuing into batch, state 1 hop 1
09/19/2014 14:45:18;0008;PBS_Server;Job;42560.tyrone-cluster;Job Queued at request of sectanuj@tyrone-cluster, owner = sectanuj@tyrone-cluster, job name = 4Cores4C816, queue = batch
09/19/2014 14:45:18;0040;PBS_Server;Svr;tyrone-cluster;Scheduler was sent the command new
09/19/2014 14:45:19;0008;PBS_Server;Job;42560.tyrone-cluster;Job Modified at request of Scheduler@tyrone-cluster
09/19/2014 14:45:22;0040;PBS_Server;Svr;tyrone-cluster;Scheduler was sent the command new
09/19/2014 14:45:25;0040;PBS_Server;Svr;tyrone-cluster;Scheduler was sent the command new
09/19/2014 14:45:35;0040;PBS_Server;Svr;tyrone-cluster;Scheduler was sent the command new
09/19/2014 14:45:48;0040;PBS_Server;Svr;tyrone-cluster;Scheduler was sent the command new
09/19/2014 14:45:52;0040;PBS_Server;Svr;tyrone-cluster;Scheduler was sent the command new
09/19/2014 14:45:57;0040;PBS_Server;Svr;tyrone-cluster;Scheduler was sent the command new
09/19/2014 14:46:06;0040;PBS_Server;Svr;tyrone-cluster;Scheduler was sent the command new
09/19/2014 14:46:20;0040;PBS_Server;Svr;tyrone-cluster;Scheduler was sent the command new
09/19/2014 14:46:29;0040;PBS_Server;Svr;tyrone-cluster;Scheduler was sent the command new
09/19/2014 14:46:36;0040;PBS_Server;Svr;tyrone-cluster;Scheduler was sent the command new
09/19/2014 14:46:52;0040;PBS_Server;Svr;tyrone-cluster;Scheduler was sent the command new
09/19/2014 14:47:01;0040;PBS_Server;Svr;tyrone-cluster;Scheduler was sent the command new
09/19/2014 14:47:05;0040;PBS_Server;Svr;tyrone-cluster;Scheduler was sent the command new
09/19/2014 14:47:20;0040;PBS_Server;Svr;tyrone-cluster;Scheduler was sent the command new
09/19/2014 14:47:32;0040;PBS_Server;Svr;tyrone-cluster;Scheduler was sent the command new
09/19/2014 14:47:36;0040;PBS_Server;Svr;tyrone-cluster;Scheduler was sent the command new
09/19/2014 14:47:40;0002;PBS_Server;Svr;PBS_Server;Torque Server Version = 3.0.5, loglevel = 0
09/19/2014 14:47:50;0040;PBS_Server;Svr;tyrone-cluster;Scheduler was sent the command new
09/19/2014 14:48:03;0040;PBS_Server;Svr;tyrone-cluster;Scheduler was sent the command new
09/19/2014 14:48:06;0040;PBS_Server;Svr;tyrone-cluster;Scheduler was sent the command new
09/19/2014 14:48:22;0040;PBS_Server;Svr;tyrone-cluster;Scheduler was sent the command new
09/19/2014 14:48:35;0040;PBS_Server;Svr;tyrone-cluster;Scheduler was sent the command new
09/19/2014 14:48:50;0040;PBS_Server;Svr;tyrone-cluster;Scheduler was sent the command new
09/19/2014 14:49:06;0040;PBS_Server;Svr;tyrone-cluster;Scheduler was sent the command new
09/19/2014 14:49:20;0040;PBS_Server;Svr;tyrone-cluster;Scheduler was sent the command new
09/19/2014 14:49:35;0040;PBS_Server;Svr;tyrone-cluster;Scheduler was sent the command new
09/19/2014 14:49:51;0040;PBS_Server;Svr;tyrone-cluster;Scheduler was sent the command new
09/19/2014 14:50:05;0040;PBS_Server;Svr;tyrone-cluster;Scheduler was sent the command new
09/19/2014 14:50:20;0040;PBS_Server;Svr;tyrone-cluster;Scheduler was sent the command new
09/19/2014 14:50:36;0040;PBS_Server;Svr;tyrone-cluster;Scheduler was sent the command new
09/19/2014 14:50:50;0040;PBS_Server;Svr;tyrone-cluster;Scheduler was sent the command new
09/19/2014 14:51:06;0040;PBS_Server;Svr;tyrone-cluster;Scheduler was sent the command new
09/19/2014 14:51:22;0040;PBS_Server;Svr;tyrone-cluster;Scheduler was sent the command new
09/19/2014 14:51:35;0040;PBS_Server;Svr;tyrone-cluster;Scheduler was sent the command new
09/19/2014 14:51:50;0040;PBS_Server;Svr;tyrone-cluster;Scheduler was sent the command new
09/19/2014 14:52:06;0040;PBS_Server;Svr;tyrone-cluster;Scheduler was sent the command new
09/19/2014 14:52:20;0040;PBS_Server;Svr;tyrone-cluster;Scheduler was sent the command new
09/19/2014 14:52:36;0040;PBS_Server;Svr;tyrone-cluster;Scheduler was sent the command new
09/19/2014 14:52:40;0002;PBS_Server;Svr;PBS_Server;Torque Server Version = 3.0.5, loglevel = 0
09/19/2014 14:52:52;0040;PBS_Server;Svr;tyrone-cluster;Scheduler was sent the command new
09/19/2014 14:53:05;0040;PBS_Server;Svr;tyrone-cluster;Scheduler was sent the command new
09/19/2014 14:53:20;0040;PBS_Server;Svr;tyrone-cluster;Scheduler was sent the command new
09/19/2014 14:53:36;0040;PBS_Server;Svr;tyrone-cluster;Scheduler was sent the command new
09/19/2014 14:53:50;0040;PBS_Server;Svr;tyrone-cluster;Scheduler was sent the command new
09/19/2014 14:54:05;0040;PBS_Server;Svr;tyrone-cluster;Scheduler was sent the command new
09/19/2014 14:54:22;0040;PBS_Server;Svr;tyrone-cluster;Scheduler was sent the command new
09/19/2014 14:54:35;0040;PBS_Server;Svr;tyrone-cluster;Scheduler was sent the command new
09/19/2014 14:54:50;0040;PBS_Server;Svr;tyrone-cluster;Scheduler was sent the command new
09/19/2014 14:55:06;0040;PBS_Server;Svr;tyrone-cluster;Scheduler was sent the command new
09/19/2014 14:55:20;0040;PBS_Server;Svr;tyrone-cluster;Scheduler was sent the command new
09/19/2014 14:55:35;0040;PBS_Server;Svr;tyrone-cluster;Scheduler was sent the command new
09/19/2014 14:55:51;0040;PBS_Server;Svr;tyrone-cluster;Scheduler was sent the command new
09/19/2014 14:56:05;0040;PBS_Server;Svr;tyrone-cluster;Scheduler was sent the command new
09/19/2014 14:56:20;0040;PBS_Server;Svr;tyrone-cluster;Scheduler was sent the command new
09/19/2014 14:56:36;0040;PBS_Server;Svr;tyrone-cluster;Scheduler was sent the command new
09/19/2014 14:56:50;0040;PBS_Server;Svr;tyrone-cluster;Scheduler was sent the command new
09/19/2014 14:57:05;0040;PBS_Server;Svr;tyrone-cluster;Scheduler was sent the command new
09/19/2014 14:57:21;0040;PBS_Server;Svr;tyrone-cluster;Scheduler was sent the command new
09/19/2014 14:57:35;0040;PBS_Server;Svr;tyrone-cluster;Scheduler was sent the command new
09/19/2014 14:57:40;0002;PBS_Server;Svr;PBS_Server;Torque Server Version = 3.0.5, loglevel = 0
09/19/2014 14:57:50;0040;PBS_Server;Svr;tyrone-cluster;Scheduler was sent the command new
09/19/2014 14:58:07;0040;PBS_Server;Svr;tyrone-cluster;Scheduler was sent the command new
09/19/2014 14:58:20;0040;PBS_Server;Svr;tyrone-cluster;Scheduler was sent the command new
09/19/2014 14:58:35;0040;PBS_Server;Svr;tyrone-cluster;Scheduler was sent the command new
09/19/2014 14:58:51;0040;PBS_Server;Svr;tyrone-cluster;Scheduler was sent the command new
09/19/2014 14:59:05;0040;PBS_Server;Svr;tyrone-cluster;Scheduler was sent the command new
09/19/2014 14:59:20;0040;PBS_Server;Svr;tyrone-cluster;Scheduler was sent the command new
09/19/2014 14:59:36;0040;PBS_Server;Svr;tyrone-cluster;Scheduler was sent the command new
09/19/2014 14:59:50;0040;PBS_Server;Svr;tyrone-cluster;Scheduler was sent the command new
09/19/2014 15:00:05;0040;PBS_Server;Svr;tyrone-cluster;Scheduler was sent the command new
09/19/2014 15:00:21;0040;PBS_Server;Svr;tyrone-cluster;Scheduler was sent the command new
09/19/2014 15:00:35;0040;PBS_Server;Svr;tyrone-cluster;Scheduler was sent the command new
09/19/2014 15:00:50;0040;PBS_Server;Svr;tyrone-cluster;Scheduler was sent the command new
09/19/2014 15:01:06;0040;PBS_Server;Svr;tyrone-cluster;Scheduler was sent the command new
09/19/2014 15:01:20;0040;PBS_Server;Svr;tyrone-cluster;Scheduler was sent the command new
09/19/2014 15:01:35;0040;PBS_Server;Svr;tyrone-cluster;Scheduler was sent the command new
09/19/2014 15:01:51;0040;PBS_Server;Svr;tyrone-cluster;Scheduler was sent the command new
09/19/2014 15:02:05;0040;PBS_Server;Svr;tyrone-cluster;Scheduler was sent the command new
09/19/2014 15:02:20;0040;PBS_Server;Svr;tyrone-cluster;Scheduler was sent the command new
09/19/2014 15:02:36;0040;PBS_Server;Svr;tyrone-cluster;Scheduler was sent the command new
09/19/2014 15:02:40;0002;PBS_Server;Svr;PBS_Server;Torque Server Version = 3.0.5, loglevel = 0
09/19/2014 15:02:50;0040;PBS_Server;Svr;tyrone-cluster;Scheduler was sent the command new
09/19/2014 15:03:05;0040;PBS_Server;Svr;tyrone-cluster;Scheduler was sent the command new
09/19/2014 15:03:21;0040;PBS_Server;Svr;tyrone-cluster;Scheduler was sent the command new
09/19/2014 15:03:35;0040;PBS_Server;Svr;tyrone-cluster;Scheduler was sent the command new
09/19/2014 15:03:50;0040;PBS_Server;Svr;tyrone-cluster;Scheduler was sent the command new
09/19/2014 15:04:06;0040;PBS_Server;Svr;tyrone-cluster;Scheduler was sent the command new
09/19/2014 15:04:20;0040;PBS_Server;Svr;tyrone-cluster;Scheduler was sent the command new
09/19/2014 15:04:36;0040;PBS_Server;Svr;tyrone-cluster;Scheduler was sent the command new
09/19/2014 15:04:51;0040;PBS_Server;Svr;tyrone-cluster;Scheduler was sent the command new
09/19/2014 15:05:05;0040;PBS_Server;Svr;tyrone-cluster;Scheduler was sent the command new
09/19/2014 15:05:20;0040;PBS_Server;Svr;tyrone-cluster;Scheduler was sent the command new
09/19/2014 15:05:36;0040;PBS_Server;Svr;tyrone-cluster;Scheduler was sent the command new
09/19/2014 15:05:50;0040;PBS_Server;Svr;tyrone-cluster;Scheduler was sent the command new
09/19/2014 15:06:05;0040;PBS_Server;Svr;tyrone-cluster;Scheduler was sent the command new
09/19/2014 15:06:21;0040;PBS_Server;Svr;tyrone-cluster;Scheduler was sent the command new
09/19/2014 15:06:36;0040;PBS_Server;Svr;tyrone-cluster;Scheduler was sent the command new
09/19/2014 15:06:50;0040;PBS_Server;Svr;tyrone-cluster;Scheduler was sent the command new
09/19/2014 15:07:07;0040;PBS_Server;Svr;tyrone-cluster;Scheduler was sent the command new
09/19/2014 15:07:20;0040;PBS_Server;Svr;tyrone-cluster;Scheduler was sent the command new
09/19/2014 15:07:37;0040;PBS_Server;Svr;tyrone-cluster;Scheduler was sent the command new
09/19/2014 15:07:40;0002;PBS_Server;Svr;PBS_Server;Torque Server Version = 3.0.5, loglevel = 0
09/19/2014 15:07:51;0040;PBS_Server;Svr;tyrone-cluster;Scheduler was sent the command new
09/19/2014 15:08:14;0040;PBS_Server;Svr;tyrone-cluster;Scheduler was sent the command new
09/19/2014 15:08:46;0040;PBS_Server;Svr;tyrone-cluster;Scheduler was sent the command new
09/19/2014 15:08:59;0040;PBS_Server;Svr;tyrone-cluster;Scheduler was sent the command new
09/19/2014 15:09:20;0040;PBS_Server;Svr;tyrone-cluster;Scheduler was sent the command new
09/19/2014 15:09:31;0040;PBS_Server;Svr;tyrone-cluster;Scheduler was sent the command new
09/19/2014 15:09:48;0040;PBS_Server;Svr;tyrone-cluster;Scheduler was sent the command new
09/19/2014 15:10:05;0040;PBS_Server;Svr;tyrone-cluster;Scheduler was sent the command new
09/19/2014 15:10:20;0040;PBS_Server;Svr;tyrone-cluster;Scheduler was sent the command new
09/19/2014 15:10:33;0040;PBS_Server;Svr;tyrone-cluster;Scheduler was sent the command new
09/19/2014 15:10:51;0040;PBS_Server;Svr;tyrone-cluster;Scheduler was sent the command new
09/19/2014 15:11:05;0040;PBS_Server;Svr;tyrone-cluster;Scheduler was sent the command new
09/19/2014 15:11:20;0040;PBS_Server;Svr;tyrone-cluster;Scheduler was sent the command new
09/19/2014 15:11:36;0040;PBS_Server;Svr;tyrone-cluster;Scheduler was sent the command new
09/19/2014 15:11:50;0040;PBS_Server;Svr;tyrone-cluster;Scheduler was sent the command new
09/19/2014 15:12:06;0040;PBS_Server;Svr;tyrone-cluster;Scheduler was sent the command new
09/19/2014 15:12:21;0040;PBS_Server;Svr;tyrone-cluster;Scheduler was sent the command new
09/19/2014 15:12:40;0002;PBS_Server;Svr;PBS_Server;Torque Server Version = 3.0.5, loglevel = 0
09/19/2014 15:12:40;0040;PBS_Server;Svr;tyrone-cluster;Scheduler was sent the command new
09/19/2014 15:12:51;0040;PBS_Server;Svr;tyrone-cluster;Scheduler was sent the command new
09/19/2014 15:13:06;0040;PBS_Server;Svr;tyrone-cluster;Scheduler was sent the command new
09/19/2014 15:13:20;0040;PBS_Server;Svr;tyrone-cluster;Scheduler was sent the command new
09/19/2014 15:13:35;0040;PBS_Server;Svr;tyrone-cluster;Scheduler was sent the command new
09/19/2014 15:13:51;0040;PBS_Server;Svr;tyrone-cluster;Scheduler was sent the command new
09/19/2014 15:14:05;0040;PBS_Server;Svr;tyrone-cluster;Scheduler was sent the command new
09/19/2014 15:14:20;0040;PBS_Server;Svr;tyrone-cluster;Scheduler was sent the command new
09/19/2014 15:14:36;0040;PBS_Server;Svr;tyrone-cluster;Scheduler was sent the command new
09/19/2014 15:14:50;0040;PBS_Server;Svr;tyrone-cluster;Scheduler was sent the command new
09/19/2014 15:15:05;0040;PBS_Server;Svr;tyrone-cluster;Scheduler was sent the command new
09/19/2014 15:15:21;0040;PBS_Server;Svr;tyrone-cluster;Scheduler was sent the command new
09/19/2014 15:15:35;0040;PBS_Server;Svr;tyrone-cluster;Scheduler was sent the command new
09/19/2014 15:15:50;0040;PBS_Server;Svr;tyrone-cluster;Scheduler was sent the command new
09/19/2014 15:16:06;0040;PBS_Server;Svr;tyrone-cluster;Scheduler was sent the command new
09/19/2014 15:16:20;0040;PBS_Server;Svr;tyrone-cluster;Scheduler was sent the command new
09/19/2014 15:16:36;0040;PBS_Server;Svr;tyrone-cluster;Scheduler was sent the command new
09/19/2014 15:16:51;0040;PBS_Server;Svr;tyrone-cluster;Scheduler was sent the command new
09/19/2014 15:17:14;0040;PBS_Server;Svr;tyrone-cluster;Scheduler was sent the command new
09/19/2014 15:17:21;0040;PBS_Server;Svr;tyrone-cluster;Scheduler was sent the command new
09/19/2014 15:17:36;0040;PBS_Server;Svr;tyrone-cluster;Scheduler was sent the command new
09/19/2014 15:17:40;0002;PBS_Server;Svr;PBS_Server;Torque Server Version = 3.0.5, loglevel = 0
09/19/2014 15:17:50;0040;PBS_Server;Svr;tyrone-cluster;Scheduler was sent the command new
09/19/2014 15:18:05;0040;PBS_Server;Svr;tyrone-cluster;Scheduler was sent the command new
09/19/2014 15:18:21;0040;PBS_Server;Svr;tyrone-cluster;Scheduler was sent the command new
09/19/2014 15:18:44;0040;PBS_Server;Svr;tyrone-cluster;Scheduler was sent the command new
09/19/2014 15:18:51;0040;PBS_Server;Svr;tyrone-cluster;Scheduler was sent the command new
09/19/2014 15:19:05;0040;PBS_Server;Svr;tyrone-cluster;Scheduler was sent the command new
09/19/2014 15:19:20;0040;PBS_Server;Svr;tyrone-cluster;Scheduler was sent the command new
09/19/2014 15:19:35;0040;PBS_Server;Svr;tyrone-cluster;Scheduler was sent the command new
09/19/2014 15:19:51;0040;PBS_Server;Svr;tyrone-cluster;Scheduler was sent the command new
09/19/2014 15:20:05;0040;PBS_Server;Svr;tyrone-cluster;Scheduler was sent the command new
09/19/2014 15:20:21;0040;PBS_Server;Svr;tyrone-cluster;Scheduler was sent the command new
09/19/2014 15:20:36;0040;PBS_Server;Svr;tyrone-cluster;Scheduler was sent the command new
09/19/2014 15:20:50;0040;PBS_Server;Svr;tyrone-cluster;Scheduler was sent the command new
09/19/2014 15:21:06;0040;PBS_Server;Svr;tyrone-cluster;Scheduler was sent the command new
09/19/2014 15:21:20;0040;PBS_Server;Svr;tyrone-cluster;Scheduler was sent the command new
09/19/2014 15:21:35;0040;PBS_Server;Svr;tyrone-cluster;Scheduler was sent the command new
09/19/2014 15:21:50;0040;PBS_Server;Svr;tyrone-cluster;Scheduler was sent the command new
09/19/2014 15:22:06;0040;PBS_Server;Svr;tyrone-cluster;Scheduler was sent the command new
09/19/2014 15:22:29;0040;PBS_Server;Svr;tyrone-cluster;Scheduler was sent the command new
09/19/2014 15:22:36;0040;PBS_Server;Svr;tyrone-cluster;Scheduler was sent the command new
09/19/2014 15:22:40;0002;PBS_Server;Svr;PBS_Server;Torque Server Version = 3.0.5, loglevel = 0
09/19/2014 15:22:50;0040;PBS_Server;Svr;tyrone-cluster;Scheduler was sent the command new
09/19/2014 15:23:05;0040;PBS_Server;Svr;tyrone-cluster;Scheduler was sent the command new
09/19/2014 15:23:20;0040;PBS_Server;Svr;tyrone-cluster;Scheduler was sent the command new
09/19/2014 15:23:36;0040;PBS_Server;Svr;tyrone-cluster;Scheduler was sent the command new
09/19/2014 15:23:50;0040;PBS_Server;Svr;tyrone-cluster;Scheduler was sent the command new
09/19/2014 15:24:06;0040;PBS_Server;Svr;tyrone-cluster;Scheduler was sent the command new
09/19/2014 15:24:21;0040;PBS_Server;Svr;tyrone-cluster;Scheduler was sent the command new
09/19/2014 15:24:35;0040;PBS_Server;Svr;tyrone-cluster;Scheduler was sent the command new
09/19/2014 15:24:50;0040;PBS_Server;Svr;tyrone-cluster;Scheduler was sent the command new
09/19/2014 15:25:06;0040;PBS_Server;Svr;tyrone-cluster;Scheduler was sent the command new
09/19/2014 15:25:20;0040;PBS_Server;Svr;tyrone-cluster;Scheduler was sent the command new
09/19/2014 15:25:36;0040;PBS_Server;Svr;tyrone-cluster;Scheduler was sent the command new
09/19/2014 15:25:51;0040;PBS_Server;Svr;tyrone-cluster;Scheduler was sent the command new
09/19/2014 15:26:05;0040;PBS_Server;Svr;tyrone-cluster;Scheduler was sent the command new
09/19/2014 15:26:20;0040;PBS_Server;Svr;tyrone-cluster;Scheduler was sent the command new
09/19/2014 15:26:35;0040;PBS_Server;Svr;tyrone-cluster;Scheduler was sent the command new
09/19/2014 15:26:50;0040;PBS_Server;Svr;tyrone-cluster;Scheduler was sent the command new
09/19/2014 15:27:06;0040;PBS_Server;Svr;tyrone-cluster;Scheduler was sent the command new
09/19/2014 15:27:20;0040;PBS_Server;Svr;tyrone-cluster;Scheduler was sent the command new
09/19/2014 15:27:40;0002;PBS_Server;Svr;PBS_Server;Torque Server Version = 3.0.5, loglevel = 0
09/19/2014 15:27:40;0040;PBS_Server;Svr;tyrone-cluster;Scheduler was sent the command new
09/19/2014 15:27:52;0040;PBS_Server;Svr;tyrone-cluster;Scheduler was sent the command new
09/19/2014 15:28:06;0040;PBS_Server;Svr;tyrone-cluster;Scheduler was sent the command new
09/19/2014 15:28:20;0040;PBS_Server;Svr;tyrone-cluster;Scheduler was sent the command new
09/19/2014 15:28:36;0040;PBS_Server;Svr;tyrone-cluster;Scheduler was sent the command new
09/19/2014 15:28:51;0040;PBS_Server;Svr;tyrone-cluster;Scheduler was sent the command new
09/19/2014 15:29:14;0040;PBS_Server;Svr;tyrone-cluster;Scheduler was sent the command new
09/19/2014 15:29:22;0040;PBS_Server;Svr;tyrone-cluster;Scheduler was sent the command new
09/19/2014 15:29:36;0040;PBS_Server;Svr;tyrone-cluster;Scheduler was sent the command new
09/19/2014 15:29:59;0040;PBS_Server;Svr;tyrone-cluster;Scheduler was sent the command new
09/19/2014 15:30:05;0040;PBS_Server;Svr;tyrone-cluster;Scheduler was sent the command new
09/19/2014 15:30:31;0040;PBS_Server;Svr;tyrone-cluster;Scheduler was sent the command new
09/19/2014 15:30:38;0040;PBS_Server;Svr;tyrone-cluster;Scheduler was sent the command new
09/19/2014 15:30:54;0100;PBS_Server;Job;42561.tyrone-cluster;enqueuing into batch, state 1 hop 1
09/19/2014 15:30:54;0100;PBS_Server;Job;42561.tyrone-cluster;dequeuing from batch, state QUEUED
09/19/2014 15:30:54;0100;PBS_Server;Job;42561.tyrone-cluster;enqueuing into qp32, state 1 hop 1
09/19/2014 15:30:54;0008;PBS_Server;Job;42561.tyrone-cluster;Job Queued at request of asebala@tyrone-node9, owner = asebala@tyrone-node9, job name = HiLiFT, queue = qp32
09/19/2014 15:30:54;0040;PBS_Server;Svr;tyrone-cluster;Scheduler was sent the command new
09/19/2014 15:30:54;0008;PBS_Server;Job;42561.tyrone-cluster;Job Modified at request of Scheduler@tyrone-cluster
09/19/2014 15:31:05;0040;PBS_Server;Svr;tyrone-cluster;Scheduler was sent the command new
09/19/2014 15:31:33;0040;PBS_Server;Svr;tyrone-cluster;Scheduler was sent the command new
09/19/2014 15:31:36;0040;PBS_Server;Svr;tyrone-cluster;Scheduler was sent the command new
09/19/2014 15:32:05;0040;PBS_Server;Svr;tyrone-cluster;Scheduler was sent the command new
09/19/2014 15:32:36;0040;PBS_Server;Svr;tyrone-cluster;Scheduler was sent the command new
09/19/2014 15:32:40;0002;PBS_Server;Svr;PBS_Server;Torque Server Version = 3.0.5, loglevel = 0
09/19/2014 15:33:06;0040;PBS_Server;Svr;tyrone-cluster;Scheduler was sent the command new
09/19/2014 15:33:44;0040;PBS_Server;Svr;tyrone-cluster;Scheduler was sent the command new
09/19/2014 15:34:05;0040;PBS_Server;Svr;tyrone-cluster;Scheduler was sent the command new
09/19/2014 15:34:36;0040;PBS_Server;Svr;tyrone-cluster;Scheduler was sent the command new
09/19/2014 15:35:05;0040;PBS_Server;Svr;tyrone-cluster;Scheduler was sent the command new
09/19/2014 15:35:36;0040;PBS_Server;Svr;tyrone-cluster;Scheduler was sent the command new
09/19/2014 15:36:06;0040;PBS_Server;Svr;tyrone-cluster;Scheduler was sent the command new
09/19/2014 15:36:44;0040;PBS_Server;Svr;tyrone-cluster;Scheduler was sent the command new
09/19/2014 15:37:00;0008;PBS_Server;Job;42496.tyrone-cluster;Job deleted at request of aseraghu@tyrone-cluster
09/19/2014 15:37:00;0008;PBS_Server;Job;NULL;on_job_exit valid pjob: 0x2ce3630 (substate=59)
09/19/2014 15:37:00;0100;PBS_Server;Job;42496.tyrone-cluster;dequeuing from qp32, state COMPLETE
09/19/2014 15:37:00;0040;PBS_Server;Svr;tyrone-cluster;Scheduler was sent the command term
09/19/2014 15:37:06;0040;PBS_Server;Svr;tyrone-cluster;Scheduler was sent the command new
09/19/2014 15:37:36;0040;PBS_Server;Svr;tyrone-cluster;Scheduler was sent the command new
09/19/2014 15:37:40;0002;PBS_Server;Svr;PBS_Server;Torque Server Version = 3.0.5, loglevel = 0
09/19/2014 15:38:05;0040;PBS_Server;Svr;tyrone-cluster;Scheduler was sent the command new
09/19/2014 15:38:35;0040;PBS_Server;Svr;tyrone-cluster;Scheduler was sent the command new
09/19/2014 15:39:06;0040;PBS_Server;Svr;tyrone-cluster;Scheduler was sent the command new
09/19/2014 15:39:44;0040;PBS_Server;Svr;tyrone-cluster;Scheduler was sent the command new
09/19/2014 15:40:05;0040;PBS_Server;Svr;tyrone-cluster;Scheduler was sent the command new
09/19/2014 15:40:32;0100;PBS_Server;Job;42562.tyrone-cluster;enqueuing into batch, state 1 hop 1
09/19/2014 15:40:32;0100;PBS_Server;Job;42562.tyrone-cluster;dequeuing from batch, state QUEUED
09/19/2014 15:40:32;0100;PBS_Server;Job;42562.tyrone-cluster;enqueuing into qp32, state 1 hop 1
09/19/2014 15:40:32;0008;PBS_Server;Job;42562.tyrone-cluster;Job Queued at request of aseraghu@tyrone-cluster, owner = aseraghu@tyrone-cluster, job name = LCFDNS, queue = qp32
09/19/2014 15:40:32;0040;PBS_Server;Svr;tyrone-cluster;Scheduler was sent the command new
09/19/2014 15:40:32;0008;PBS_Server;Job;42562.tyrone-cluster;Job Modified at request of Scheduler@tyrone-cluster
09/19/2014 15:40:35;0040;PBS_Server;Svr;tyrone-cluster;Scheduler was sent the command new
09/19/2014 15:40:46;0008;PBS_Server;Job;42562.tyrone-cluster;Job deleted at request of aseraghu@tyrone-cluster
09/19/2014 15:40:46;0008;PBS_Server;Job;NULL;on_job_exit valid pjob: 0x2ce3630 (substate=59)
09/19/2014 15:40:46;0100;PBS_Server;Job;42562.tyrone-cluster;dequeuing from qp32, state COMPLETE
09/19/2014 15:40:46;0040;PBS_Server;Svr;tyrone-cluster;Scheduler was sent the command term
09/19/2014 15:41:05;0040;PBS_Server;Svr;tyrone-cluster;Scheduler was sent the command new
09/19/2014 15:41:35;0040;PBS_Server;Svr;tyrone-cluster;Scheduler was sent the command new
09/19/2014 15:41:36;0100;PBS_Server;Job;42563.tyrone-cluster;enqueuing into batch, state 1 hop 1
09/19/2014 15:41:36;0100;PBS_Server;Job;42563.tyrone-cluster;dequeuing from batch, state QUEUED
09/19/2014 15:41:36;0100;PBS_Server;Job;42563.tyrone-cluster;enqueuing into idqueue, state 1 hop 1
09/19/2014 15:41:36;0008;PBS_Server;Job;42563.tyrone-cluster;Job Queued at request of aseraghu@tyrone-cluster, owner = aseraghu@tyrone-cluster, job name = LCFDNS, queue = idqueue
09/19/2014 15:41:36;0040;PBS_Server;Svr;tyrone-cluster;Scheduler was sent the command new
09/19/2014 15:41:36;0008;PBS_Server;Job;42563.tyrone-cluster;Job Modified at request of Scheduler@tyrone-cluster
09/19/2014 15:42:06;0040;PBS_Server;Svr;tyrone-cluster;Scheduler was sent the command new
09/19/2014 15:42:40;0002;PBS_Server;Svr;PBS_Server;Torque Server Version = 3.0.5, loglevel = 0
09/19/2014 15:42:40;0040;PBS_Server;Svr;tyrone-cluster;Scheduler was sent the command new
09/19/2014 15:42:50;0100;PBS_Server;Job;42564.tyrone-cluster;enqueuing into batch, state 1 hop 1
09/19/2014 15:42:50;0100;PBS_Server;Job;42564.tyrone-cluster;dequeuing from batch, state QUEUED
09/19/2014 15:42:50;0100;PBS_Server;Job;42564.tyrone-cluster;enqueuing into qp64, state 1 hop 1
09/19/2014 15:42:50;0008;PBS_Server;Job;42564.tyrone-cluster;Job Queued at request of aseraghu@tyrone-cluster, owner = aseraghu@tyrone-cluster, job name = TBLDNS, queue = qp64
09/19/2014 15:42:50;0040;PBS_Server;Svr;tyrone-cluster;Scheduler was sent the command new
09/19/2014 15:42:50;0008;PBS_Server;Job;42564.tyrone-cluster;Job Modified at request of Scheduler@tyrone-cluster
09/19/2014 15:43:00;0008;PBS_Server;Job;42564.tyrone-cluster;Job deleted at request of aseraghu@tyrone-cluster
09/19/2014 15:43:00;0008;PBS_Server;Job;NULL;on_job_exit valid pjob: 0x2de6e10 (substate=59)
09/19/2014 15:43:00;0100;PBS_Server;Job;42564.tyrone-cluster;dequeuing from qp64, state COMPLETE
09/19/2014 15:43:00;0040;PBS_Server;Svr;tyrone-cluster;Scheduler was sent the command term
09/19/2014 15:43:06;0040;PBS_Server;Svr;tyrone-cluster;Scheduler was sent the command new
09/19/2014 15:43:36;0040;PBS_Server;Svr;tyrone-cluster;Scheduler was sent the command new
09/19/2014 15:43:44;0100;PBS_Server;Job;42565.tyrone-cluster;enqueuing into batch, state 1 hop 1
09/19/2014 15:43:44;0100;PBS_Server;Job;42565.tyrone-cluster;dequeuing from batch, state QUEUED
09/19/2014 15:43:44;0100;PBS_Server;Job;42565.tyrone-cluster;enqueuing into qp128, state 1 hop 1
09/19/2014 15:43:44;0008;PBS_Server;Job;42565.tyrone-cluster;Job Queued at request of aseraghu@tyrone-cluster, owner = aseraghu@tyrone-cluster, job name = TBLDNS, queue = qp128
09/19/2014 15:43:44;0040;PBS_Server;Svr;tyrone-cluster;Scheduler was sent the command new
09/19/2014 15:43:44;0008;PBS_Server;Job;42565.tyrone-cluster;Job Modified at request of Scheduler@tyrone-cluster
09/19/2014 15:44:14;0040;PBS_Server;Svr;tyrone-cluster;Scheduler was sent the command new
09/19/2014 15:44:35;0040;PBS_Server;Svr;tyrone-cluster;Scheduler was sent the command new
09/19/2014 15:45:06;0040;PBS_Server;Svr;tyrone-cluster;Scheduler was sent the command new
09/19/2014 15:45:13;0008;PBS_Server;Job;42565.tyrone-cluster;Job deleted at request of aseraghu@tyrone-cluster
09/19/2014 15:45:13;0008;PBS_Server;Job;NULL;on_job_exit valid pjob: 0x2ce3630 (substate=59)
09/19/2014 15:45:13;0100;PBS_Server;Job;42565.tyrone-cluster;dequeuing from qp128, state COMPLETE
09/19/2014 15:45:13;0040;PBS_Server;Svr;tyrone-cluster;Scheduler was sent the command term
09/19/2014 15:45:35;0040;PBS_Server;Svr;tyrone-cluster;Scheduler was sent the command new
09/19/2014 15:46:06;0040;PBS_Server;Svr;tyrone-cluster;Scheduler was sent the command new
09/19/2014 15:46:36;0040;PBS_Server;Svr;tyrone-cluster;Scheduler was sent the command new
09/19/2014 15:47:05;0040;PBS_Server;Svr;tyrone-cluster;Scheduler was sent the command new
09/19/2014 15:47:34;0100;PBS_Server;Job;42566.tyrone-cluster;enqueuing into batch, state 1 hop 1
09/19/2014 15:47:34;0100;PBS_Server;Job;42566.tyrone-cluster;dequeuing from batch, state QUEUED
09/19/2014 15:47:34;0100;PBS_Server;Job;42566.tyrone-cluster;enqueuing into idqueue, state 1 hop 1
09/19/2014 15:47:34;0008;PBS_Server;Job;42566.tyrone-cluster;Job Queued at request of aseraghu@tyrone-cluster, owner = aseraghu@tyrone-cluster, job name = TBLDNS, queue = idqueue
09/19/2014 15:47:34;0040;PBS_Server;Svr;tyrone-cluster;Scheduler was sent the command new
09/19/2014 15:47:34;0008;PBS_Server;Job;42566.tyrone-cluster;Job Modified at request of Scheduler@tyrone-cluster
09/19/2014 15:47:36;0040;PBS_Server;Svr;tyrone-cluster;Scheduler was sent the command new
09/19/2014 15:47:40;0002;PBS_Server;Svr;PBS_Server;Torque Server Version = 3.0.5, loglevel = 0
09/19/2014 15:48:06;0040;PBS_Server;Svr;tyrone-cluster;Scheduler was sent the command new
09/19/2014 15:48:35;0040;PBS_Server;Svr;tyrone-cluster;Scheduler was sent the command new
09/19/2014 15:49:05;0040;PBS_Server;Svr;tyrone-cluster;Scheduler was sent the command new
09/19/2014 15:49:36;0040;PBS_Server;Svr;tyrone-cluster;Scheduler was sent the command new
09/19/2014 15:50:05;0040;PBS_Server;Svr;tyrone-cluster;Scheduler was sent the command new
09/19/2014 15:50:35;0040;PBS_Server;Svr;tyrone-cluster;Scheduler was sent the command new
09/19/2014 15:51:07;0040;PBS_Server;Svr;tyrone-cluster;Scheduler was sent the command new
09/19/2014 15:51:44;0040;PBS_Server;Svr;tyrone-cluster;Scheduler was sent the command new
09/19/2014 15:52:16;0040;PBS_Server;Svr;tyrone-cluster;Scheduler was sent the command new
09/19/2014 15:52:40;0002;PBS_Server;Svr;PBS_Server;Torque Server Version = 3.0.5, loglevel = 0
09/19/2014 15:52:50;0040;PBS_Server;Svr;tyrone-cluster;Scheduler was sent the command new
09/19/2014 15:53:20;0040;PBS_Server;Svr;tyrone-cluster;Scheduler was sent the command new
09/19/2014 15:53:50;0040;PBS_Server;Svr;tyrone-cluster;Scheduler was sent the command new
09/19/2014 15:54:20;0040;PBS_Server;Svr;tyrone-cluster;Scheduler was sent the command new
09/19/2014 15:54:52;0040;PBS_Server;Svr;tyrone-cluster;Scheduler was sent the command new
09/19/2014 15:55:29;0040;PBS_Server;Svr;tyrone-cluster;Scheduler was sent the command new
09/19/2014 15:56:01;0040;PBS_Server;Svr;tyrone-cluster;Scheduler was sent the command new
09/19/2014 15:56:35;0040;PBS_Server;Svr;tyrone-cluster;Scheduler was sent the command new
09/19/2014 15:57:06;0040;PBS_Server;Svr;tyrone-cluster;Scheduler was sent the command new
09/19/2014 15:57:35;0040;PBS_Server;Svr;tyrone-cluster;Scheduler was sent the command new
09/19/2014 15:57:40;0002;PBS_Server;Svr;PBS_Server;Torque Server Version = 3.0.5, loglevel = 0
09/19/2014 15:58:05;0040;PBS_Server;Svr;tyrone-cluster;Scheduler was sent the command new
09/19/2014 15:58:37;0040;PBS_Server;Svr;tyrone-cluster;Scheduler was sent the command new
09/19/2014 15:59:05;0040;PBS_Server;Svr;tyrone-cluster;Scheduler was sent the command new
09/19/2014 15:59:35;0040;PBS_Server;Svr;tyrone-cluster;Scheduler was sent the command new
09/19/2014 16:00:07;0040;PBS_Server;Svr;tyrone-cluster;Scheduler was sent the command new
09/19/2014 16:00:44;0040;PBS_Server;Svr;tyrone-cluster;Scheduler was sent the command new
09/19/2014 16:01:16;0040;PBS_Server;Svr;tyrone-cluster;Scheduler was sent the command new
09/19/2014 16:01:50;0040;PBS_Server;Svr;tyrone-cluster;Scheduler was sent the command new
09/19/2014 16:02:18;0040;PBS_Server;Svr;tyrone-cluster;Scheduler was sent the command new
09/19/2014 16:02:40;0002;PBS_Server;Svr;PBS_Server;Torque Server Version = 3.0.5, loglevel = 0
09/19/2014 16:02:46;0040;PBS_Server;Svr;tyrone-cluster;Scheduler was sent the command new
09/19/2014 16:03:20;0040;PBS_Server;Svr;tyrone-cluster;Scheduler was sent the command new
09/19/2014 16:03:51;0040;PBS_Server;Svr;tyrone-cluster;Scheduler was sent the command new
09/19/2014 16:04:29;0040;PBS_Server;Svr;tyrone-cluster;Scheduler was sent the command new
09/19/2014 16:04:50;0040;PBS_Server;Svr;tyrone-cluster;Scheduler was sent the command new
09/19/2014 16:05:22;0040;PBS_Server;Svr;tyrone-cluster;Scheduler was sent the command new
09/19/2014 16:05:55;0040;PBS_Server;Svr;tyrone-cluster;Scheduler was sent the command new
09/19/2014 16:06:20;0040;PBS_Server;Svr;tyrone-cluster;Scheduler was sent the command new
09/19/2014 16:06:51;0040;PBS_Server;Svr;tyrone-cluster;Scheduler was sent the command new
09/19/2014 16:07:20;0040;PBS_Server;Svr;tyrone-cluster;Scheduler was sent the command new
09/19/2014 16:07:40;0002;PBS_Server;Svr;PBS_Server;Torque Server Version = 3.0.5, loglevel = 0
09/19/2014 16:07:50;0040;PBS_Server;Svr;tyrone-cluster;Scheduler was sent the command new
09/19/2014 16:08:22;0040;PBS_Server;Svr;tyrone-cluster;Scheduler was sent the command new
09/19/2014 16:08:59;0040;PBS_Server;Svr;tyrone-cluster;Scheduler was sent the command new
09/19/2014 16:09:20;0040;PBS_Server;Svr;tyrone-cluster;Scheduler was sent the command new
09/19/2014 16:09:50;0040;PBS_Server;Svr;tyrone-cluster;Scheduler was sent the command new
09/19/2014 16:10:20;0040;PBS_Server;Svr;tyrone-cluster;Scheduler was sent the command new
09/19/2014 16:10:50;0040;PBS_Server;Svr;tyrone-cluster;Scheduler was sent the command new
09/19/2014 16:11:22;0040;PBS_Server;Svr;tyrone-cluster;Scheduler was sent the command new
09/19/2014 16:11:59;0040;PBS_Server;Svr;tyrone-cluster;Scheduler was sent the command new
09/19/2014 16:12:21;0040;PBS_Server;Svr;tyrone-cluster;Scheduler was sent the command new
09/19/2014 16:12:40;0002;PBS_Server;Svr;PBS_Server;Torque Server Version = 3.0.5, loglevel = 0
09/19/2014 16:12:51;0040;PBS_Server;Svr;tyrone-cluster;Scheduler was sent the command new
09/19/2014 16:13:20;0040;PBS_Server;Svr;tyrone-cluster;Scheduler was sent the command new
09/19/2014 16:13:50;0040;PBS_Server;Svr;tyrone-cluster;Scheduler was sent the command new
09/19/2014 16:14:22;0040;PBS_Server;Svr;tyrone-cluster;Scheduler was sent the command new
09/19/2014 16:14:59;0040;PBS_Server;Svr;tyrone-cluster;Scheduler was sent the command new
09/19/2014 16:15:21;0040;PBS_Server;Svr;tyrone-cluster;Scheduler was sent the command new
09/19/2014 16:15:52;0040;PBS_Server;Svr;tyrone-cluster;Scheduler was sent the command new
09/19/2014 16:16:29;0040;PBS_Server;Svr;tyrone-cluster;Scheduler was sent the command new
09/19/2014 16:16:50;0040;PBS_Server;Svr;tyrone-cluster;Scheduler was sent the command new
09/19/2014 16:17:22;0040;PBS_Server;Svr;tyrone-cluster;Scheduler was sent the command new
09/19/2014 16:17:40;0002;PBS_Server;Svr;PBS_Server;Torque Server Version = 3.0.5, loglevel = 0
09/19/2014 16:17:59;0040;PBS_Server;Svr;tyrone-cluster;Scheduler was sent the command new
09/19/2014 16:18:21;0040;PBS_Server;Svr;tyrone-cluster;Scheduler was sent the command new
09/19/2014 16:18:52;0040;PBS_Server;Svr;tyrone-cluster;Scheduler was sent the command new
09/19/2014 16:19:20;0040;PBS_Server;Svr;tyrone-cluster;Scheduler was sent the command new
09/19/2014 16:19:50;0040;PBS_Server;Svr;tyrone-cluster;Scheduler was sent the command new
09/19/2014 16:20:22;0040;PBS_Server;Svr;tyrone-cluster;Scheduler was sent the command new
09/19/2014 16:20:59;0040;PBS_Server;Svr;tyrone-cluster;Scheduler was sent the command new
09/19/2014 16:21:20;0040;PBS_Server;Svr;tyrone-cluster;Scheduler was sent the command new
09/19/2014 16:21:52;0040;PBS_Server;Svr;tyrone-cluster;Scheduler was sent the command new
09/19/2014 16:22:20;0040;PBS_Server;Svr;tyrone-cluster;Scheduler was sent the command new
09/19/2014 16:22:40;0002;PBS_Server;Svr;PBS_Server;Torque Server Version = 3.0.5, loglevel = 0
09/19/2014 16:22:50;0040;PBS_Server;Svr;tyrone-cluster;Scheduler was sent the command new
09/19/2014 16:23:22;0040;PBS_Server;Svr;tyrone-cluster;Scheduler was sent the command new
09/19/2014 16:23:59;0040;PBS_Server;Svr;tyrone-cluster;Scheduler was sent the command new
09/19/2014 16:24:21;0040;PBS_Server;Svr;tyrone-cluster;Scheduler was sent the command new
09/19/2014 16:24:52;0040;PBS_Server;Svr;tyrone-cluster;Scheduler was sent the command new
09/19/2014 16:25:20;0040;PBS_Server;Svr;tyrone-cluster;Scheduler was sent the command new
09/19/2014 16:25:50;0040;PBS_Server;Svr;tyrone-cluster;Scheduler was sent the command new
09/19/2014 16:26:22;0040;PBS_Server;Svr;tyrone-cluster;Scheduler was sent the command new
09/19/2014 16:26:59;0040;PBS_Server;Svr;tyrone-cluster;Scheduler was sent the command new
09/19/2014 16:27:21;0040;PBS_Server;Svr;tyrone-cluster;Scheduler was sent the command new
09/19/2014 16:27:40;0002;PBS_Server;Svr;PBS_Server;Torque Server Version = 3.0.5, loglevel = 0
09/19/2014 16:27:52;0040;PBS_Server;Svr;tyrone-cluster;Scheduler was sent the command new
09/19/2014 16:28:29;0040;PBS_Server;Svr;tyrone-cluster;Scheduler was sent the command new
09/19/2014 16:29:01;0040;PBS_Server;Svr;tyrone-cluster;Scheduler was sent the command new
09/19/2014 16:29:35;0040;PBS_Server;Svr;tyrone-cluster;Scheduler was sent the command new
09/19/2014 16:30:07;0040;PBS_Server;Svr;tyrone-cluster;Scheduler was sent the command new
09/19/2014 16:30:44;0040;PBS_Server;Svr;tyrone-cluster;Scheduler was sent the command new
09/19/2014 16:31:06;0040;PBS_Server;Svr;tyrone-cluster;Scheduler was sent the command new
09/19/2014 16:31:29;0100;PBS_Server;Job;42567.tyrone-cluster;enqueuing into batch, state 1 hop 1
09/19/2014 16:31:29;0100;PBS_Server;Job;42567.tyrone-cluster;dequeuing from batch, state QUEUED
09/19/2014 16:31:29;0100;PBS_Server;Job;42567.tyrone-cluster;enqueuing into qp64, state 1 hop 1
09/19/2014 16:31:29;0008;PBS_Server;Job;42567.tyrone-cluster;Job Queued at request of asepk@tyrone-cluster, owner = asepk@tyrone-cluster, job name = CSTR, queue = qp64
09/19/2014 16:31:29;0040;PBS_Server;Svr;tyrone-cluster;Scheduler was sent the command new
09/19/2014 16:31:29;0008;PBS_Server;Job;42567.tyrone-cluster;Job Modified at request of Scheduler@tyrone-cluster
09/19/2014 16:31:37;0040;PBS_Server;Svr;tyrone-cluster;Scheduler was sent the command new
09/19/2014 16:32:14;0040;PBS_Server;Svr;tyrone-cluster;Scheduler was sent the command new
09/19/2014 16:32:36;0040;PBS_Server;Svr;tyrone-cluster;Scheduler was sent the command new
09/19/2014 16:32:40;0002;PBS_Server;Svr;PBS_Server;Torque Server Version = 3.0.5, loglevel = 0
09/19/2014 16:33:07;0040;PBS_Server;Svr;tyrone-cluster;Scheduler was sent the command new
09/19/2014 16:33:44;0040;PBS_Server;Svr;tyrone-cluster;Scheduler was sent the command new
09/19/2014 16:34:05;0040;PBS_Server;Svr;tyrone-cluster;Scheduler was sent the command new
09/19/2014 16:34:37;0040;PBS_Server;Svr;tyrone-cluster;Scheduler was sent the command new
09/19/2014 16:35:12;0040;PBS_Server;Svr;tyrone-cluster;Scheduler was sent the command new
09/19/2014 16:35:36;0040;PBS_Server;Svr;tyrone-cluster;Scheduler was sent the command new
09/19/2014 16:36:07;0040;PBS_Server;Svr;tyrone-cluster;Scheduler was sent the command new
09/19/2014 16:36:44;0040;PBS_Server;Svr;tyrone-cluster;Scheduler was sent the command new
09/19/2014 16:37:16;0040;PBS_Server;Svr;tyrone-cluster;Scheduler was sent the command new
09/19/2014 16:37:40;0002;PBS_Server;Svr;PBS_Server;Torque Server Version = 3.0.5, loglevel = 0
09/19/2014 16:37:50;0040;PBS_Server;Svr;tyrone-cluster;Scheduler was sent the command new
09/19/2014 16:38:20;0040;PBS_Server;Svr;tyrone-cluster;Scheduler was sent the command new
09/19/2014 16:38:49;0040;PBS_Server;Svr;tyrone-cluster;Scheduler was sent the command new
09/19/2014 16:39:20;0040;PBS_Server;Svr;tyrone-cluster;Scheduler was sent the command new
09/19/2014 16:39:49;0040;PBS_Server;Svr;tyrone-cluster;Scheduler was sent the command new
09/19/2014 16:40:20;0040;PBS_Server;Svr;tyrone-cluster;Scheduler was sent the command new
09/19/2014 16:40:50;0040;PBS_Server;Svr;tyrone-cluster;Scheduler was sent the command new
09/19/2014 16:41:20;0040;PBS_Server;Svr;tyrone-cluster;Scheduler was sent the command new
09/19/2014 16:41:38;000d;PBS_Server;Job;42537.tyrone-cluster;Not sending email: User does not want mail of this type.
09/19/2014 16:41:38;0010;PBS_Server;Job;42537.tyrone-cluster;Exit_status=143 resources_used.cput=63:33:35 resources_used.mem=405824kb resources_used.vmem=12108308kb resources_used.walltime=02:00:48
09/19/2014 16:41:38;0008;PBS_Server;Job;NULL;on_job_exit valid pjob: 0x2cd1f70 (substate=50)
09/19/2014 16:41:38;0008;PBS_Server;Job;NULL;on_job_exit valid pjob: 0x2cd1f70 (substate=51)
09/19/2014 16:41:39;0008;PBS_Server;Job;NULL;on_job_exit valid pjob: 0x2cd1f70 (substate=51)
09/19/2014 16:41:39;0008;PBS_Server;Job;NULL;on_job_exit valid pjob: 0x2cd1f70 (substate=53)
09/19/2014 16:41:39;0100;PBS_Server;Job;42537.tyrone-cluster;dequeuing from idqueue, state COMPLETE
09/19/2014 16:41:39;0040;PBS_Server;Svr;tyrone-cluster;Scheduler was sent the command term
09/19/2014 16:41:39;0008;PBS_Server;Job;42555.tyrone-cluster;Job Modified at request of Scheduler@tyrone-cluster
09/19/2014 16:41:39;0008;PBS_Server;Job;42555.tyrone-cluster;Job Run at request of Scheduler@tyrone-cluster
09/19/2014 16:41:39;0040;PBS_Server;Svr;tyrone-cluster;Scheduler was sent the command recyc
09/19/2014 16:41:39;000d;PBS_Server;Job;42555.tyrone-cluster;Not sending email: User does not want mail of this type.
09/19/2014 16:41:49;0040;PBS_Server;Svr;tyrone-cluster;Scheduler was sent the command new
09/19/2014 16:42:19;0040;PBS_Server;Svr;tyrone-cluster;Scheduler was sent the command new
09/19/2014 16:42:40;0002;PBS_Server;Svr;PBS_Server;Torque Server Version = 3.0.5, loglevel = 0
09/19/2014 16:42:49;0040;PBS_Server;Svr;tyrone-cluster;Scheduler was sent the command new
09/19/2014 16:43:19;0040;PBS_Server;Svr;tyrone-cluster;Scheduler was sent the command new
09/19/2014 16:43:49;0040;PBS_Server;Svr;tyrone-cluster;Scheduler was sent the command new
09/19/2014 16:44:20;0040;PBS_Server;Svr;tyrone-cluster;Scheduler was sent the command new
09/19/2014 16:44:50;0040;PBS_Server;Svr;tyrone-cluster;Scheduler was sent the command new
09/19/2014 16:45:19;0040;PBS_Server;Svr;tyrone-cluster;Scheduler was sent the command new
09/19/2014 16:45:50;0040;PBS_Server;Svr;tyrone-cluster;Scheduler was sent the command new
09/19/2014 16:46:20;0040;PBS_Server;Svr;tyrone-cluster;Scheduler was sent the command new
09/19/2014 16:46:49;0040;PBS_Server;Svr;tyrone-cluster;Scheduler was sent the command new
09/19/2014 16:47:20;0040;PBS_Server;Svr;tyrone-cluster;Scheduler was sent the command new
09/19/2014 16:47:40;0002;PBS_Server;Svr;PBS_Server;Torque Server Version = 3.0.5, loglevel = 0
09/19/2014 16:47:50;0040;PBS_Server;Svr;tyrone-cluster;Scheduler was sent the command new
09/19/2014 16:48:19;0040;PBS_Server;Svr;tyrone-cluster;Scheduler was sent the command new
09/19/2014 16:48:50;0040;PBS_Server;Svr;tyrone-cluster;Scheduler was sent the command new
09/19/2014 16:49:19;0040;PBS_Server;Svr;tyrone-cluster;Scheduler was sent the command new
09/19/2014 16:49:49;0040;PBS_Server;Svr;tyrone-cluster;Scheduler was sent the command new
09/19/2014 16:50:19;0040;PBS_Server;Svr;tyrone-cluster;Scheduler was sent the command new
09/19/2014 16:50:49;0040;PBS_Server;Svr;tyrone-cluster;Scheduler was sent the command new
09/19/2014 16:51:19;0040;PBS_Server;Svr;tyrone-cluster;Scheduler was sent the command new
09/19/2014 16:51:50;0040;PBS_Server;Svr;tyrone-cluster;Scheduler was sent the command new
09/19/2014 16:52:19;0040;PBS_Server;Svr;tyrone-cluster;Scheduler was sent the command new
09/19/2014 16:52:40;0002;PBS_Server;Svr;PBS_Server;Torque Server Version = 3.0.5, loglevel = 0
09/19/2014 16:52:49;0040;PBS_Server;Svr;tyrone-cluster;Scheduler was sent the command new
09/19/2014 16:53:19;0040;PBS_Server;Svr;tyrone-cluster;Scheduler was sent the command new
09/19/2014 16:53:49;0040;PBS_Server;Svr;tyrone-cluster;Scheduler was sent the command new
09/19/2014 16:54:19;0040;PBS_Server;Svr;tyrone-cluster;Scheduler was sent the command new
09/19/2014 16:54:50;0040;PBS_Server;Svr;tyrone-cluster;Scheduler was sent the command new
09/19/2014 16:55:19;0040;PBS_Server;Svr;tyrone-cluster;Scheduler was sent the command new
09/19/2014 16:55:49;0040;PBS_Server;Svr;tyrone-cluster;Scheduler was sent the command new
09/19/2014 16:56:20;0040;PBS_Server;Svr;tyrone-cluster;Scheduler was sent the command new
09/19/2014 16:56:49;0040;PBS_Server;Svr;tyrone-cluster;Scheduler was sent the command new
09/19/2014 16:57:19;0040;PBS_Server;Svr;tyrone-cluster;Scheduler was sent the command new
09/19/2014 16:57:40;0002;PBS_Server;Svr;PBS_Server;Torque Server Version = 3.0.5, loglevel = 0
09/19/2014 16:57:50;0040;PBS_Server;Svr;tyrone-cluster;Scheduler was sent the command new
09/19/2014 16:58:20;0040;PBS_Server;Svr;tyrone-cluster;Scheduler was sent the command new
09/19/2014 16:58:49;0040;PBS_Server;Svr;tyrone-cluster;Scheduler was sent the command new
09/19/2014 16:59:20;0040;PBS_Server;Svr;tyrone-cluster;Scheduler was sent the command new
09/19/2014 16:59:50;0040;PBS_Server;Svr;tyrone-cluster;Scheduler was sent the command new
09/19/2014 17:00:19;0040;PBS_Server;Svr;tyrone-cluster;Scheduler was sent the command new
09/19/2014 17:00:50;0040;PBS_Server;Svr;tyrone-cluster;Scheduler was sent the command new
09/19/2014 17:01:19;0040;PBS_Server;Svr;tyrone-cluster;Scheduler was sent the command new
09/19/2014 17:01:49;0040;PBS_Server;Svr;tyrone-cluster;Scheduler was sent the command new
09/19/2014 17:02:20;0040;PBS_Server;Svr;tyrone-cluster;Scheduler was sent the command new
09/19/2014 17:02:40;0002;PBS_Server;Svr;PBS_Server;Torque Server Version = 3.0.5, loglevel = 0
09/19/2014 17:02:49;0040;PBS_Server;Svr;tyrone-cluster;Scheduler was sent the command new
09/19/2014 17:03:19;0040;PBS_Server;Svr;tyrone-cluster;Scheduler was sent the command new
09/19/2014 17:03:49;0040;PBS_Server;Svr;tyrone-cluster;Scheduler was sent the command new
09/19/2014 17:04:19;0040;PBS_Server;Svr;tyrone-cluster;Scheduler was sent the command new
09/19/2014 17:04:49;0040;PBS_Server;Svr;tyrone-cluster;Scheduler was sent the command new
09/19/2014 17:05:20;0040;PBS_Server;Svr;tyrone-cluster;Scheduler was sent the command new
09/19/2014 17:05:50;0040;PBS_Server;Svr;tyrone-cluster;Scheduler was sent the command new
09/19/2014 17:06:19;0040;PBS_Server;Svr;tyrone-cluster;Scheduler was sent the command new
09/19/2014 17:06:49;0040;PBS_Server;Svr;tyrone-cluster;Scheduler was sent the command new
09/19/2014 17:07:19;0040;PBS_Server;Svr;tyrone-cluster;Scheduler was sent the command new
09/19/2014 17:07:40;0002;PBS_Server;Svr;PBS_Server;Torque Server Version = 3.0.5, loglevel = 0
09/19/2014 17:07:49;0040;PBS_Server;Svr;tyrone-cluster;Scheduler was sent the command new
09/19/2014 17:08:20;0040;PBS_Server;Svr;tyrone-cluster;Scheduler was sent the command new
09/19/2014 17:08:50;0040;PBS_Server;Svr;tyrone-cluster;Scheduler was sent the command new
09/19/2014 17:09:19;0040;PBS_Server;Svr;tyrone-cluster;Scheduler was sent the command new
09/19/2014 17:09:49;0040;PBS_Server;Svr;tyrone-cluster;Scheduler was sent the command new
09/19/2014 17:10:20;0040;PBS_Server;Svr;tyrone-cluster;Scheduler was sent the command new
09/19/2014 17:10:49;0040;PBS_Server;Svr;tyrone-cluster;Scheduler was sent the command new
09/19/2014 17:11:19;0040;PBS_Server;Svr;tyrone-cluster;Scheduler was sent the command new
09/19/2014 17:11:50;0040;PBS_Server;Svr;tyrone-cluster;Scheduler was sent the command new
09/19/2014 17:12:19;0040;PBS_Server;Svr;tyrone-cluster;Scheduler was sent the command new
09/19/2014 17:12:40;0002;PBS_Server;Svr;PBS_Server;Torque Server Version = 3.0.5, loglevel = 0
09/19/2014 17:12:52;0040;PBS_Server;Svr;tyrone-cluster;Scheduler was sent the command new
09/19/2014 17:13:20;0040;PBS_Server;Svr;tyrone-cluster;Scheduler was sent the command new
09/19/2014 17:13:51;0040;PBS_Server;Svr;tyrone-cluster;Scheduler was sent the command new
09/19/2014 17:14:22;0040;PBS_Server;Svr;tyrone-cluster;Scheduler was sent the command new
09/19/2014 17:14:59;0040;PBS_Server;Svr;tyrone-cluster;Scheduler was sent the command new
09/19/2014 17:15:34;0040;PBS_Server;Svr;tyrone-cluster;Scheduler was sent the command new
09/19/2014 17:16:04;0040;PBS_Server;Svr;tyrone-cluster;Scheduler was sent the command new
09/19/2014 17:16:33;0040;PBS_Server;Svr;tyrone-cluster;Scheduler was sent the command new
09/19/2014 17:17:04;0040;PBS_Server;Svr;tyrone-cluster;Scheduler was sent the command new
09/19/2014 17:17:34;0040;PBS_Server;Svr;tyrone-cluster;Scheduler was sent the command new
09/19/2014 17:17:40;0002;PBS_Server;Svr;PBS_Server;Torque Server Version = 3.0.5, loglevel = 0
09/19/2014 17:18:03;0040;PBS_Server;Svr;tyrone-cluster;Scheduler was sent the command new
09/19/2014 17:18:34;0040;PBS_Server;Svr;tyrone-cluster;Scheduler was sent the command new
09/19/2014 17:19:04;0040;PBS_Server;Svr;tyrone-cluster;Scheduler was sent the command new
09/19/2014 17:19:33;0040;PBS_Server;Svr;tyrone-cluster;Scheduler was sent the command new
09/19/2014 17:20:05;0040;PBS_Server;Svr;tyrone-cluster;Scheduler was sent the command new
09/19/2014 17:20:34;0040;PBS_Server;Svr;tyrone-cluster;Scheduler was sent the command new
09/19/2014 17:21:07;0040;PBS_Server;Svr;tyrone-cluster;Scheduler was sent the command new
09/19/2014 17:21:34;0040;PBS_Server;Svr;tyrone-cluster;Scheduler was sent the command new
09/19/2014 17:22:04;0040;PBS_Server;Svr;tyrone-cluster;Scheduler was sent the command new
09/19/2014 17:22:35;0040;PBS_Server;Svr;tyrone-cluster;Scheduler was sent the command new
09/19/2014 17:22:40;0002;PBS_Server;Svr;PBS_Server;Torque Server Version = 3.0.5, loglevel = 0
09/19/2014 17:23:05;0040;PBS_Server;Svr;tyrone-cluster;Scheduler was sent the command new
09/19/2014 17:23:34;0040;PBS_Server;Svr;tyrone-cluster;Scheduler was sent the command new
09/19/2014 17:24:07;0040;PBS_Server;Svr;tyrone-cluster;Scheduler was sent the command new
09/19/2014 17:24:34;0040;PBS_Server;Svr;tyrone-cluster;Scheduler was sent the command new
09/19/2014 17:25:04;0040;PBS_Server;Svr;tyrone-cluster;Scheduler was sent the command new
09/19/2014 17:25:34;0040;PBS_Server;Svr;tyrone-cluster;Scheduler was sent the command new
09/19/2014 17:26:05;0040;PBS_Server;Svr;tyrone-cluster;Scheduler was sent the command new
09/19/2014 17:26:34;0040;PBS_Server;Svr;tyrone-cluster;Scheduler was sent the command new
09/19/2014 17:27:07;0040;PBS_Server;Svr;tyrone-cluster;Scheduler was sent the command new
09/19/2014 17:27:34;0040;PBS_Server;Svr;tyrone-cluster;Scheduler was sent the command new
09/19/2014 17:27:40;0002;PBS_Server;Svr;PBS_Server;Torque Server Version = 3.0.5, loglevel = 0
09/19/2014 17:28:04;0040;PBS_Server;Svr;tyrone-cluster;Scheduler was sent the command new
09/19/2014 17:28:34;0040;PBS_Server;Svr;tyrone-cluster;Scheduler was sent the command new
09/19/2014 17:29:05;0040;PBS_Server;Svr;tyrone-cluster;Scheduler was sent the command new
09/19/2014 17:29:34;0040;PBS_Server;Svr;tyrone-cluster;Scheduler was sent the command new
09/19/2014 17:30:07;0040;PBS_Server;Svr;tyrone-cluster;Scheduler was sent the command new
09/19/2014 17:30:34;0040;PBS_Server;Svr;tyrone-cluster;Scheduler was sent the command new
09/19/2014 17:31:04;0040;PBS_Server;Svr;tyrone-cluster;Scheduler was sent the command new
09/19/2014 17:31:34;0040;PBS_Server;Svr;tyrone-cluster;Scheduler was sent the command new
09/19/2014 17:32:05;0040;PBS_Server;Svr;tyrone-cluster;Scheduler was sent the command new
09/19/2014 17:32:34;0040;PBS_Server;Svr;tyrone-cluster;Scheduler was sent the command new
09/19/2014 17:32:40;0002;PBS_Server;Svr;PBS_Server;Torque Server Version = 3.0.5, loglevel = 0
09/19/2014 17:33:07;0040;PBS_Server;Svr;tyrone-cluster;Scheduler was sent the command new
09/19/2014 17:33:34;0040;PBS_Server;Svr;tyrone-cluster;Scheduler was sent the command new
09/19/2014 17:34:04;0040;PBS_Server;Svr;tyrone-cluster;Scheduler was sent the command new
09/19/2014 17:34:34;0040;PBS_Server;Svr;tyrone-cluster;Scheduler was sent the command new
09/19/2014 17:35:04;0040;PBS_Server;Svr;tyrone-cluster;Scheduler was sent the command new
09/19/2014 17:35:34;0040;PBS_Server;Svr;tyrone-cluster;Scheduler was sent the command new
09/19/2014 17:36:04;0040;PBS_Server;Svr;tyrone-cluster;Scheduler was sent the command new
09/19/2014 17:36:35;0040;PBS_Server;Svr;tyrone-cluster;Scheduler was sent the command new
09/19/2014 17:37:06;0040;PBS_Server;Svr;tyrone-cluster;Scheduler was sent the command new
09/19/2014 17:37:37;0040;PBS_Server;Svr;tyrone-cluster;Scheduler was sent the command new
09/19/2014 17:37:40;0002;PBS_Server;Svr;PBS_Server;Torque Server Version = 3.0.5, loglevel = 0
09/19/2014 17:38:14;0040;PBS_Server;Svr;tyrone-cluster;Scheduler was sent the command new
09/19/2014 17:38:50;0040;PBS_Server;Svr;tyrone-cluster;Scheduler was sent the command new
09/19/2014 17:39:19;0040;PBS_Server;Svr;tyrone-cluster;Scheduler was sent the command new
09/19/2014 17:39:48;0040;PBS_Server;Svr;tyrone-cluster;Scheduler was sent the command new
09/19/2014 17:40:19;0040;PBS_Server;Svr;tyrone-cluster;Scheduler was sent the command new
09/19/2014 17:40:49;0040;PBS_Server;Svr;tyrone-cluster;Scheduler was sent the command new
09/19/2014 17:41:18;0040;PBS_Server;Svr;tyrone-cluster;Scheduler was sent the command new
09/19/2014 17:41:49;0040;PBS_Server;Svr;tyrone-cluster;Scheduler was sent the command new
09/19/2014 17:42:19;0040;PBS_Server;Svr;tyrone-cluster;Scheduler was sent the command new
09/19/2014 17:42:40;0002;PBS_Server;Svr;PBS_Server;Torque Server Version = 3.0.5, loglevel = 0
09/19/2014 17:42:48;0040;PBS_Server;Svr;tyrone-cluster;Scheduler was sent the command new
09/19/2014 17:43:19;0040;PBS_Server;Svr;tyrone-cluster;Scheduler was sent the command new
09/19/2014 17:43:49;0040;PBS_Server;Svr;tyrone-cluster;Scheduler was sent the command new
09/19/2014 17:44:18;0040;PBS_Server;Svr;tyrone-cluster;Scheduler was sent the command new
09/19/2014 17:44:49;0040;PBS_Server;Svr;tyrone-cluster;Scheduler was sent the command new
09/19/2014 17:45:19;0040;PBS_Server;Svr;tyrone-cluster;Scheduler was sent the command new
09/19/2014 17:45:48;0040;PBS_Server;Svr;tyrone-cluster;Scheduler was sent the command new
09/19/2014 17:46:19;0040;PBS_Server;Svr;tyrone-cluster;Scheduler was sent the command new
09/19/2014 17:46:49;0040;PBS_Server;Svr;tyrone-cluster;Scheduler was sent the command new
09/19/2014 17:47:18;0040;PBS_Server;Svr;tyrone-cluster;Scheduler was sent the command new
09/19/2014 17:47:40;0002;PBS_Server;Svr;PBS_Server;Torque Server Version = 3.0.5, loglevel = 0
09/19/2014 17:47:49;0040;PBS_Server;Svr;tyrone-cluster;Scheduler was sent the command new
09/19/2014 17:48:19;0040;PBS_Server;Svr;tyrone-cluster;Scheduler was sent the command new
09/19/2014 17:48:48;0040;PBS_Server;Svr;tyrone-cluster;Scheduler was sent the command new
09/19/2014 17:49:19;0040;PBS_Server;Svr;tyrone-cluster;Scheduler was sent the command new
09/19/2014 17:49:49;0040;PBS_Server;Svr;tyrone-cluster;Scheduler was sent the command new
09/19/2014 17:50:18;0040;PBS_Server;Svr;tyrone-cluster;Scheduler was sent the command new
09/19/2014 17:50:49;0040;PBS_Server;Svr;tyrone-cluster;Scheduler was sent the command new
09/19/2014 17:51:19;0040;PBS_Server;Svr;tyrone-cluster;Scheduler was sent the command new
09/19/2014 17:51:48;0040;PBS_Server;Svr;tyrone-cluster;Scheduler was sent the command new
09/19/2014 17:52:19;0040;PBS_Server;Svr;tyrone-cluster;Scheduler was sent the command new
09/19/2014 17:52:40;0002;PBS_Server;Svr;PBS_Server;Torque Server Version = 3.0.5, loglevel = 0
09/19/2014 17:52:49;0040;PBS_Server;Svr;tyrone-cluster;Scheduler was sent the command new
09/19/2014 17:53:19;0040;PBS_Server;Svr;tyrone-cluster;Scheduler was sent the command new
09/19/2014 17:53:50;0040;PBS_Server;Svr;tyrone-cluster;Scheduler was sent the command new
09/19/2014 17:54:19;0040;PBS_Server;Svr;tyrone-cluster;Scheduler was sent the command new
09/19/2014 17:54:52;0040;PBS_Server;Svr;tyrone-cluster;Scheduler was sent the command new
09/19/2014 17:55:19;0040;PBS_Server;Svr;tyrone-cluster;Scheduler was sent the command new
09/19/2014 17:55:49;0040;PBS_Server;Svr;tyrone-cluster;Scheduler was sent the command new
09/19/2014 17:56:19;0040;PBS_Server;Svr;tyrone-cluster;Scheduler was sent the command new
09/19/2014 17:56:50;0040;PBS_Server;Svr;tyrone-cluster;Scheduler was sent the command new
09/19/2014 17:57:19;0040;PBS_Server;Svr;tyrone-cluster;Scheduler was sent the command new
09/19/2014 17:57:40;0002;PBS_Server;Svr;PBS_Server;Torque Server Version = 3.0.5, loglevel = 0
09/19/2014 17:57:52;0040;PBS_Server;Svr;tyrone-cluster;Scheduler was sent the command new
09/19/2014 17:58:20;0040;PBS_Server;Svr;tyrone-cluster;Scheduler was sent the command new
09/19/2014 17:58:51;0040;PBS_Server;Svr;tyrone-cluster;Scheduler was sent the command new
09/19/2014 17:59:22;0040;PBS_Server;Svr;tyrone-cluster;Scheduler was sent the command new
09/19/2014 17:59:59;0040;PBS_Server;Svr;tyrone-cluster;Scheduler was sent the command new
09/19/2014 18:00:34;0040;PBS_Server;Svr;tyrone-cluster;Scheduler was sent the command new
09/19/2014 18:01:05;0040;PBS_Server;Svr;tyrone-cluster;Scheduler was sent the command new
09/19/2014 18:01:34;0040;PBS_Server;Svr;tyrone-cluster;Scheduler was sent the command new
09/19/2014 18:02:04;0040;PBS_Server;Svr;tyrone-cluster;Scheduler was sent the command new
09/19/2014 18:02:35;0040;PBS_Server;Svr;tyrone-cluster;Scheduler was sent the command new
09/19/2014 18:02:40;0002;PBS_Server;Svr;PBS_Server;Torque Server Version = 3.0.5, loglevel = 0
09/19/2014 18:03:08;0040;PBS_Server;Svr;tyrone-cluster;Scheduler was sent the command new
09/19/2014 18:03:45;0040;PBS_Server;Svr;tyrone-cluster;Scheduler was sent the command new
09/19/2014 18:04:19;0040;PBS_Server;Svr;tyrone-cluster;Scheduler was sent the command new
09/19/2014 18:04:50;0040;PBS_Server;Svr;tyrone-cluster;Scheduler was sent the command new
09/19/2014 18:05:18;0040;PBS_Server;Svr;tyrone-cluster;Scheduler was sent the command new
09/19/2014 18:05:49;0040;PBS_Server;Svr;tyrone-cluster;Scheduler was sent the command new
09/19/2014 18:06:20;0040;PBS_Server;Svr;tyrone-cluster;Scheduler was sent the command new
09/19/2014 18:06:53;0040;PBS_Server;Svr;tyrone-cluster;Scheduler was sent the command new
09/19/2014 18:07:30;0040;PBS_Server;Svr;tyrone-cluster;Scheduler was sent the command new
09/19/2014 18:07:40;0002;PBS_Server;Svr;PBS_Server;Torque Server Version = 3.0.5, loglevel = 0
09/19/2014 18:08:04;0040;PBS_Server;Svr;tyrone-cluster;Scheduler was sent the command new
09/19/2014 18:08:35;0040;PBS_Server;Svr;tyrone-cluster;Scheduler was sent the command new
09/19/2014 18:09:08;0040;PBS_Server;Svr;tyrone-cluster;Scheduler was sent the command new
09/19/2014 18:09:45;0040;PBS_Server;Svr;tyrone-cluster;Scheduler was sent the command new
09/19/2014 18:10:20;0040;PBS_Server;Svr;tyrone-cluster;Scheduler was sent the command new
09/19/2014 18:10:50;0040;PBS_Server;Svr;tyrone-cluster;Scheduler was sent the command new
09/19/2014 18:11:18;0040;PBS_Server;Svr;tyrone-cluster;Scheduler was sent the command new
09/19/2014 18:11:49;0040;PBS_Server;Svr;tyrone-cluster;Scheduler was sent the command new
09/19/2014 18:12:20;0040;PBS_Server;Svr;tyrone-cluster;Scheduler was sent the command new
09/19/2014 18:12:40;0002;PBS_Server;Svr;PBS_Server;Torque Server Version = 3.0.5, loglevel = 0
09/19/2014 18:12:49;0040;PBS_Server;Svr;tyrone-cluster;Scheduler was sent the command new
09/19/2014 18:13:19;0040;PBS_Server;Svr;tyrone-cluster;Scheduler was sent the command new
09/19/2014 18:13:50;0040;PBS_Server;Svr;tyrone-cluster;Scheduler was sent the command new
09/19/2014 18:14:23;0040;PBS_Server;Svr;tyrone-cluster;Scheduler was sent the command new
09/19/2014 18:15:00;0040;PBS_Server;Svr;tyrone-cluster;Scheduler was sent the command new
09/19/2014 18:15:27;0040;PBS_Server;Svr;tyrone-cluster;Scheduler was sent the command new
09/19/2014 18:16:02;0040;PBS_Server;Svr;tyrone-cluster;Scheduler was sent the command new
09/19/2014 18:16:30;0040;PBS_Server;Svr;tyrone-cluster;Scheduler was sent the command new
09/19/2014 18:17:04;0040;PBS_Server;Svr;tyrone-cluster;Scheduler was sent the command new
09/19/2014 18:17:33;0040;PBS_Server;Svr;tyrone-cluster;Scheduler was sent the command new
09/19/2014 18:17:40;0002;PBS_Server;Svr;PBS_Server;Torque Server Version = 3.0.5, loglevel = 0
09/19/2014 18:18:03;0040;PBS_Server;Svr;tyrone-cluster;Scheduler was sent the command new
09/19/2014 18:18:34;0040;PBS_Server;Svr;tyrone-cluster;Scheduler was sent the command new
09/19/2014 18:19:05;0040;PBS_Server;Svr;tyrone-cluster;Scheduler was sent the command new
09/19/2014 18:19:38;0040;PBS_Server;Svr;tyrone-cluster;Scheduler was sent the command new
09/19/2014 18:20:12;0040;PBS_Server;Svr;tyrone-cluster;Scheduler was sent the command new
09/19/2014 18:20:42;0040;PBS_Server;Svr;tyrone-cluster;Scheduler was sent the command new
09/19/2014 18:21:18;0040;PBS_Server;Svr;tyrone-cluster;Scheduler was sent the command new
09/19/2014 18:21:45;0040;PBS_Server;Svr;tyrone-cluster;Scheduler was sent the command new
09/19/2014 18:22:19;0040;PBS_Server;Svr;tyrone-cluster;Scheduler was sent the command new
09/19/2014 18:22:40;0002;PBS_Server;Svr;PBS_Server;Torque Server Version = 3.0.5, loglevel = 0
09/19/2014 18:22:50;0040;PBS_Server;Svr;tyrone-cluster;Scheduler was sent the command new
09/19/2014 18:23:18;0040;PBS_Server;Svr;tyrone-cluster;Scheduler was sent the command new
09/19/2014 18:23:49;0040;PBS_Server;Svr;tyrone-cluster;Scheduler was sent the command new
09/19/2014 18:24:20;0040;PBS_Server;Svr;tyrone-cluster;Scheduler was sent the command new
09/19/2014 18:24:49;0040;PBS_Server;Svr;tyrone-cluster;Scheduler was sent the command new
09/19/2014 18:25:19;0040;PBS_Server;Svr;tyrone-cluster;Scheduler was sent the command new
09/19/2014 18:25:50;0040;PBS_Server;Svr;tyrone-cluster;Scheduler was sent the command new
09/19/2014 18:26:23;0040;PBS_Server;Svr;tyrone-cluster;Scheduler was sent the command new
09/19/2014 18:27:00;0040;PBS_Server;Svr;tyrone-cluster;Scheduler was sent the command new
09/19/2014 18:27:27;0040;PBS_Server;Svr;tyrone-cluster;Scheduler was sent the command new
09/19/2014 18:27:40;0002;PBS_Server;Svr;PBS_Server;Torque Server Version = 3.0.5, loglevel = 0
09/19/2014 18:28:02;0040;PBS_Server;Svr;tyrone-cluster;Scheduler was sent the command new
09/19/2014 18:28:30;0040;PBS_Server;Svr;tyrone-cluster;Scheduler was sent the command new
09/19/2014 18:29:04;0040;PBS_Server;Svr;tyrone-cluster;Scheduler was sent the command new
09/19/2014 18:29:34;0040;PBS_Server;Svr;tyrone-cluster;Scheduler was sent the command new
09/19/2014 18:30:04;0040;PBS_Server;Svr;tyrone-cluster;Scheduler was sent the command new
09/19/2014 18:30:34;0040;PBS_Server;Svr;tyrone-cluster;Scheduler was sent the command new
09/19/2014 18:31:05;0040;PBS_Server;Svr;tyrone-cluster;Scheduler was sent the command new
09/19/2014 18:31:38;0040;PBS_Server;Svr;tyrone-cluster;Scheduler was sent the command new
09/19/2014 18:32:15;0040;PBS_Server;Svr;tyrone-cluster;Scheduler was sent the command new
09/19/2014 18:32:40;0002;PBS_Server;Svr;PBS_Server;Torque Server Version = 3.0.5, loglevel = 0
09/19/2014 18:32:42;0040;PBS_Server;Svr;tyrone-cluster;Scheduler was sent the command new
09/19/2014 18:33:17;0040;PBS_Server;Svr;tyrone-cluster;Scheduler was sent the command new
09/19/2014 18:33:45;0040;PBS_Server;Svr;tyrone-cluster;Scheduler was sent the command new
09/19/2014 18:34:19;0040;PBS_Server;Svr;tyrone-cluster;Scheduler was sent the command new
09/19/2014 18:34:49;0040;PBS_Server;Svr;tyrone-cluster;Scheduler was sent the command new
09/19/2014 18:35:18;0040;PBS_Server;Svr;tyrone-cluster;Scheduler was sent the command new
09/19/2014 18:35:49;0040;PBS_Server;Svr;tyrone-cluster;Scheduler was sent the command new
09/19/2014 18:36:20;0040;PBS_Server;Svr;tyrone-cluster;Scheduler was sent the command new
09/19/2014 18:36:53;0040;PBS_Server;Svr;tyrone-cluster;Scheduler was sent the command new
09/19/2014 18:37:30;0040;PBS_Server;Svr;tyrone-cluster;Scheduler was sent the command new
09/19/2014 18:37:40;0002;PBS_Server;Svr;PBS_Server;Torque Server Version = 3.0.5, loglevel = 0
09/19/2014 18:37:57;0040;PBS_Server;Svr;tyrone-cluster;Scheduler was sent the command new
09/19/2014 18:38:32;0040;PBS_Server;Svr;tyrone-cluster;Scheduler was sent the command new
09/19/2014 18:39:00;0040;PBS_Server;Svr;tyrone-cluster;Scheduler was sent the command new
09/19/2014 18:39:34;0040;PBS_Server;Svr;tyrone-cluster;Scheduler was sent the command new
09/19/2014 18:40:05;0040;PBS_Server;Svr;tyrone-cluster;Scheduler was sent the command new
09/19/2014 18:40:38;0040;PBS_Server;Svr;tyrone-cluster;Scheduler was sent the command new
09/19/2014 18:41:15;0040;PBS_Server;Svr;tyrone-cluster;Scheduler was sent the command new
09/19/2014 18:41:42;0040;PBS_Server;Svr;tyrone-cluster;Scheduler was sent the command new
09/19/2014 18:42:17;0040;PBS_Server;Svr;tyrone-cluster;Scheduler was sent the command new
09/19/2014 18:42:27;000d;PBS_Server;Job;42555.tyrone-cluster;Not sending email: User does not want mail of this type.
09/19/2014 18:42:27;0010;PBS_Server;Job;42555.tyrone-cluster;Exit_status=143 resources_used.cput=63:33:47 resources_used.mem=436288kb resources_used.vmem=12107920kb resources_used.walltime=02:00:48
09/19/2014 18:42:27;0008;PBS_Server;Job;NULL;on_job_exit valid pjob: 0x2dd6590 (substate=50)
09/19/2014 18:42:27;0008;PBS_Server;Job;NULL;on_job_exit valid pjob: 0x2dd6590 (substate=51)
09/19/2014 18:42:27;0008;PBS_Server;Job;NULL;on_job_exit valid pjob: 0x2dd6590 (substate=51)
09/19/2014 18:42:27;0008;PBS_Server;Job;NULL;on_job_exit valid pjob: 0x2dd6590 (substate=53)
09/19/2014 18:42:27;0100;PBS_Server;Job;42555.tyrone-cluster;dequeuing from idqueue, state COMPLETE
09/19/2014 18:42:27;0040;PBS_Server;Svr;tyrone-cluster;Scheduler was sent the command term
09/19/2014 18:42:28;0008;PBS_Server;Job;42556.tyrone-cluster;Job Modified at request of Scheduler@tyrone-cluster
09/19/2014 18:42:28;0008;PBS_Server;Job;42556.tyrone-cluster;Job Run at request of Scheduler@tyrone-cluster
09/19/2014 18:42:28;0040;PBS_Server;Svr;tyrone-cluster;Scheduler was sent the command recyc
09/19/2014 18:42:28;000d;PBS_Server;Job;42556.tyrone-cluster;Not sending email: User does not want mail of this type.
09/19/2014 18:42:40;0002;PBS_Server;Svr;PBS_Server;Torque Server Version = 3.0.5, loglevel = 0
09/19/2014 18:42:45;0040;PBS_Server;Svr;tyrone-cluster;Scheduler was sent the command new
09/19/2014 18:43:19;0040;PBS_Server;Svr;tyrone-cluster;Scheduler was sent the command new
09/19/2014 18:43:50;0040;PBS_Server;Svr;tyrone-cluster;Scheduler was sent the command new
09/19/2014 18:44:18;0040;PBS_Server;Svr;tyrone-cluster;Scheduler was sent the command new
09/19/2014 18:44:49;0040;PBS_Server;Svr;tyrone-cluster;Scheduler was sent the command new
09/19/2014 18:45:20;0040;PBS_Server;Svr;tyrone-cluster;Scheduler was sent the command new
09/19/2014 18:45:53;0040;PBS_Server;Svr;tyrone-cluster;Scheduler was sent the command new
09/19/2014 18:46:30;0040;PBS_Server;Svr;tyrone-cluster;Scheduler was sent the command new
09/19/2014 18:46:57;0040;PBS_Server;Svr;tyrone-cluster;Scheduler was sent the command new
09/19/2014 18:47:32;0040;PBS_Server;Svr;tyrone-cluster;Scheduler was sent the command new
09/19/2014 18:47:40;0002;PBS_Server;Svr;PBS_Server;Torque Server Version = 3.0.5, loglevel = 0
09/19/2014 18:48:00;0040;PBS_Server;Svr;tyrone-cluster;Scheduler was sent the command new
09/19/2014 18:48:34;0040;PBS_Server;Svr;tyrone-cluster;Scheduler was sent the command new
09/19/2014 18:49:04;0040;PBS_Server;Svr;tyrone-cluster;Scheduler was sent the command new
09/19/2014 18:49:14;0100;PBS_Server;Job;42568.tyrone-cluster;enqueuing into batch, state 1 hop 1
09/19/2014 18:49:14;0100;PBS_Server;Job;42568.tyrone-cluster;dequeuing from batch, state QUEUED
09/19/2014 18:49:14;0100;PBS_Server;Job;42568.tyrone-cluster;enqueuing into idqueue, state 1 hop 1
09/19/2014 18:49:14;0008;PBS_Server;Job;42568.tyrone-cluster;Job Queued at request of mecgrp@tyrone-cluster, owner = mecgrp@tyrone-cluster, job name = water_entry_sphere, queue = idqueue
09/19/2014 18:49:14;0040;PBS_Server;Svr;tyrone-cluster;Scheduler was sent the command new
09/19/2014 18:49:15;0008;PBS_Server;Job;42568.tyrone-cluster;Job Modified at request of Scheduler@tyrone-cluster
09/19/2014 18:49:33;0040;PBS_Server;Svr;tyrone-cluster;Scheduler was sent the command new
09/19/2014 18:50:04;0040;PBS_Server;Svr;tyrone-cluster;Scheduler was sent the command new
09/19/2014 18:50:35;0040;PBS_Server;Svr;tyrone-cluster;Scheduler was sent the command new
09/19/2014 18:51:08;0040;PBS_Server;Svr;tyrone-cluster;Scheduler was sent the command new
09/19/2014 18:51:44;0040;PBS_Server;Svr;tyrone-cluster;Scheduler was sent the command new
09/19/2014 18:52:12;0040;PBS_Server;Svr;tyrone-cluster;Scheduler was sent the command new
09/19/2014 18:52:40;0002;PBS_Server;Svr;PBS_Server;Torque Server Version = 3.0.5, loglevel = 0
09/19/2014 18:52:43;0040;PBS_Server;Svr;tyrone-cluster;Scheduler was sent the command new
09/19/2014 18:53:15;0040;PBS_Server;Svr;tyrone-cluster;Scheduler was sent the command new
09/19/2014 18:53:42;0040;PBS_Server;Svr;tyrone-cluster;Scheduler was sent the command new
09/19/2014 18:54:17;0040;PBS_Server;Svr;tyrone-cluster;Scheduler was sent the command new
09/19/2014 18:54:33;0008;PBS_Server;Job;42568.tyrone-cluster;Job deleted at request of mecgrp@tyrone-cluster
09/19/2014 18:54:33;0008;PBS_Server;Job;NULL;on_job_exit valid pjob: 0x2dd23d0 (substate=59)
09/19/2014 18:54:33;0100;PBS_Server;Job;42568.tyrone-cluster;dequeuing from idqueue, state COMPLETE
09/19/2014 18:54:33;0040;PBS_Server;Svr;tyrone-cluster;Scheduler was sent the command term
09/19/2014 18:54:45;0040;PBS_Server;Svr;tyrone-cluster;Scheduler was sent the command new
09/19/2014 18:55:19;0040;PBS_Server;Svr;tyrone-cluster;Scheduler was sent the command new
09/19/2014 18:55:50;0040;PBS_Server;Svr;tyrone-cluster;Scheduler was sent the command new
09/19/2014 18:56:19;0040;PBS_Server;Svr;tyrone-cluster;Scheduler was sent the command new
09/19/2014 18:56:50;0040;PBS_Server;Svr;tyrone-cluster;Scheduler was sent the command new
09/19/2014 18:57:20;0040;PBS_Server;Svr;tyrone-cluster;Scheduler was sent the command new
09/19/2014 18:57:40;0002;PBS_Server;Svr;PBS_Server;Torque Server Version = 3.0.5, loglevel = 0
09/19/2014 18:57:53;0040;PBS_Server;Svr;tyrone-cluster;Scheduler was sent the command new
09/19/2014 18:58:30;0040;PBS_Server;Svr;tyrone-cluster;Scheduler was sent the command new
09/19/2014 18:58:57;0040;PBS_Server;Svr;tyrone-cluster;Scheduler was sent the command new
09/19/2014 18:59:32;0040;PBS_Server;Svr;tyrone-cluster;Scheduler was sent the command new
09/19/2014 19:00:00;0040;PBS_Server;Svr;tyrone-cluster;Scheduler was sent the command new
09/19/2014 19:00:33;0040;PBS_Server;Svr;tyrone-cluster;Scheduler was sent the command new
09/19/2014 19:01:05;0040;PBS_Server;Svr;tyrone-cluster;Scheduler was sent the command new
09/19/2014 19:01:33;0040;PBS_Server;Svr;tyrone-cluster;Scheduler was sent the command new
09/19/2014 19:02:04;0040;PBS_Server;Svr;tyrone-cluster;Scheduler was sent the command new
09/19/2014 19:02:35;0040;PBS_Server;Svr;tyrone-cluster;Scheduler was sent the command new
09/19/2014 19:02:40;0002;PBS_Server;Svr;PBS_Server;Torque Server Version = 3.0.5, loglevel = 0
09/19/2014 19:03:04;0040;PBS_Server;Svr;tyrone-cluster;Scheduler was sent the command new
09/19/2014 19:03:35;0040;PBS_Server;Svr;tyrone-cluster;Scheduler was sent the command new
09/19/2014 19:04:05;0040;PBS_Server;Svr;tyrone-cluster;Scheduler was sent the command new
09/19/2014 19:04:38;0040;PBS_Server;Svr;tyrone-cluster;Scheduler was sent the command new
09/19/2014 19:05:12;0040;PBS_Server;Svr;tyrone-cluster;Scheduler was sent the command new
09/19/2014 19:05:42;0040;PBS_Server;Svr;tyrone-cluster;Scheduler was sent the command new
09/19/2014 19:06:16;0040;PBS_Server;Svr;tyrone-cluster;Scheduler was sent the command new
09/19/2014 19:06:45;0040;PBS_Server;Svr;tyrone-cluster;Scheduler was sent the command new
09/19/2014 19:07:19;0040;PBS_Server;Svr;tyrone-cluster;Scheduler was sent the command new
09/19/2014 19:07:40;0002;PBS_Server;Svr;PBS_Server;Torque Server Version = 3.0.5, loglevel = 0
09/19/2014 19:07:50;0040;PBS_Server;Svr;tyrone-cluster;Scheduler was sent the command new
09/19/2014 19:08:18;0040;PBS_Server;Svr;tyrone-cluster;Scheduler was sent the command new
09/19/2014 19:08:49;0040;PBS_Server;Svr;tyrone-cluster;Scheduler was sent the command new
09/19/2014 19:09:20;0040;PBS_Server;Svr;tyrone-cluster;Scheduler was sent the command new
09/19/2014 19:09:49;0040;PBS_Server;Svr;tyrone-cluster;Scheduler was sent the command new
09/19/2014 19:10:19;0040;PBS_Server;Svr;tyrone-cluster;Scheduler was sent the command new
09/19/2014 19:10:50;0040;PBS_Server;Svr;tyrone-cluster;Scheduler was sent the command new
09/19/2014 19:11:23;0040;PBS_Server;Svr;tyrone-cluster;Scheduler was sent the command new
09/19/2014 19:12:00;0040;PBS_Server;Svr;tyrone-cluster;Scheduler was sent the command new
09/19/2014 19:12:27;0040;PBS_Server;Svr;tyrone-cluster;Scheduler was sent the command new
09/19/2014 19:12:40;0002;PBS_Server;Svr;PBS_Server;Torque Server Version = 3.0.5, loglevel = 0
09/19/2014 19:13:02;0040;PBS_Server;Svr;tyrone-cluster;Scheduler was sent the command new
09/19/2014 19:13:30;0040;PBS_Server;Svr;tyrone-cluster;Scheduler was sent the command new
09/19/2014 19:14:04;0040;PBS_Server;Svr;tyrone-cluster;Scheduler was sent the command new
09/19/2014 19:14:34;0040;PBS_Server;Svr;tyrone-cluster;Scheduler was sent the command new
09/19/2014 19:15:03;0040;PBS_Server;Svr;tyrone-cluster;Scheduler was sent the command new
09/19/2014 19:15:34;0040;PBS_Server;Svr;tyrone-cluster;Scheduler was sent the command new
09/19/2014 19:16:05;0040;PBS_Server;Svr;tyrone-cluster;Scheduler was sent the command new
09/19/2014 19:16:34;0040;PBS_Server;Svr;tyrone-cluster;Scheduler was sent the command new
09/19/2014 19:17:04;0040;PBS_Server;Svr;tyrone-cluster;Scheduler was sent the command new
09/19/2014 19:17:35;0040;PBS_Server;Svr;tyrone-cluster;Scheduler was sent the command new
09/19/2014 19:17:40;0002;PBS_Server;Svr;PBS_Server;Torque Server Version = 3.0.5, loglevel = 0
09/19/2014 19:18:04;0040;PBS_Server;Svr;tyrone-cluster;Scheduler was sent the command new
09/19/2014 19:18:34;0040;PBS_Server;Svr;tyrone-cluster;Scheduler was sent the command new
09/19/2014 19:19:05;0040;PBS_Server;Svr;tyrone-cluster;Scheduler was sent the command new
09/19/2014 19:19:34;0040;PBS_Server;Svr;tyrone-cluster;Scheduler was sent the command new
09/19/2014 19:20:04;0040;PBS_Server;Svr;tyrone-cluster;Scheduler was sent the command new
09/19/2014 19:20:35;0040;PBS_Server;Svr;tyrone-cluster;Scheduler was sent the command new
09/19/2014 19:21:04;0040;PBS_Server;Svr;tyrone-cluster;Scheduler was sent the command new
09/19/2014 19:21:34;0040;PBS_Server;Svr;tyrone-cluster;Scheduler was sent the command new
09/19/2014 19:22:05;0040;PBS_Server;Svr;tyrone-cluster;Scheduler was sent the command new
09/19/2014 19:22:34;0040;PBS_Server;Svr;tyrone-cluster;Scheduler was sent the command new
09/19/2014 19:22:40;0002;PBS_Server;Svr;PBS_Server;Torque Server Version = 3.0.5, loglevel = 0
09/19/2014 19:23:04;0040;PBS_Server;Svr;tyrone-cluster;Scheduler was sent the command new
09/19/2014 19:23:35;0040;PBS_Server;Svr;tyrone-cluster;Scheduler was sent the command new
09/19/2014 19:24:04;0040;PBS_Server;Svr;tyrone-cluster;Scheduler was sent the command new
09/19/2014 19:24:34;0040;PBS_Server;Svr;tyrone-cluster;Scheduler was sent the command new
09/19/2014 19:25:05;0040;PBS_Server;Svr;tyrone-cluster;Scheduler was sent the command new
09/19/2014 19:25:36;0040;PBS_Server;Svr;tyrone-cluster;Scheduler was sent the command new
09/19/2014 19:26:04;0040;PBS_Server;Svr;tyrone-cluster;Scheduler was sent the command new
09/19/2014 19:26:35;0040;PBS_Server;Svr;tyrone-cluster;Scheduler was sent the command new
09/19/2014 19:27:04;0040;PBS_Server;Svr;tyrone-cluster;Scheduler was sent the command new
09/19/2014 19:27:34;0040;PBS_Server;Svr;tyrone-cluster;Scheduler was sent the command new
09/19/2014 19:27:40;0002;PBS_Server;Svr;PBS_Server;Torque Server Version = 3.0.5, loglevel = 0
09/19/2014 19:28:05;0040;PBS_Server;Svr;tyrone-cluster;Scheduler was sent the command new
09/19/2014 19:28:38;0040;PBS_Server;Svr;tyrone-cluster;Scheduler was sent the command new
09/19/2014 19:29:15;0040;PBS_Server;Svr;tyrone-cluster;Scheduler was sent the command new
09/19/2014 19:29:42;0040;PBS_Server;Svr;tyrone-cluster;Scheduler was sent the command new
09/19/2014 19:30:16;0040;PBS_Server;Svr;tyrone-cluster;Scheduler was sent the command new
09/19/2014 19:30:45;0040;PBS_Server;Svr;tyrone-cluster;Scheduler was sent the command new
09/19/2014 19:31:19;0040;PBS_Server;Svr;tyrone-cluster;Scheduler was sent the command new
09/19/2014 19:31:50;0040;PBS_Server;Svr;tyrone-cluster;Scheduler was sent the command new
09/19/2014 19:32:19;0040;PBS_Server;Svr;tyrone-cluster;Scheduler was sent the command new
09/19/2014 19:32:40;0002;PBS_Server;Svr;PBS_Server;Torque Server Version = 3.0.5, loglevel = 0
09/19/2014 19:32:56;0040;PBS_Server;Svr;tyrone-cluster;Scheduler was sent the command new
09/19/2014 19:33:20;0040;PBS_Server;Svr;tyrone-cluster;Scheduler was sent the command new
09/19/2014 19:33:49;0040;PBS_Server;Svr;tyrone-cluster;Scheduler was sent the command new
09/19/2014 19:34:19;0040;PBS_Server;Svr;tyrone-cluster;Scheduler was sent the command new
09/19/2014 19:34:50;0040;PBS_Server;Svr;tyrone-cluster;Scheduler was sent the command new
09/19/2014 19:35:19;0040;PBS_Server;Svr;tyrone-cluster;Scheduler was sent the command new
09/19/2014 19:35:49;0040;PBS_Server;Svr;tyrone-cluster;Scheduler was sent the command new
09/19/2014 19:36:20;0040;PBS_Server;Svr;tyrone-cluster;Scheduler was sent the command new
09/19/2014 19:36:23;0100;PBS_Server;Job;42569.tyrone-cluster;enqueuing into batch, state 1 hop 1
09/19/2014 19:36:23;0100;PBS_Server;Job;42569.tyrone-cluster;dequeuing from batch, state QUEUED
09/19/2014 19:36:23;0100;PBS_Server;Job;42569.tyrone-cluster;enqueuing into idqueue, state 1 hop 1
09/19/2014 19:36:23;0008;PBS_Server;Job;42569.tyrone-cluster;Job Queued at request of chevadh@tyrone-cluster, owner = chevadh@tyrone-cluster, job name = jobname, queue = idqueue
09/19/2014 19:36:23;0040;PBS_Server;Svr;tyrone-cluster;Scheduler was sent the command new
09/19/2014 19:36:23;0008;PBS_Server;Job;42569.tyrone-cluster;Job Modified at request of Scheduler@tyrone-cluster
09/19/2014 19:36:27;0100;PBS_Server;Job;42570.tyrone-cluster;enqueuing into batch, state 1 hop 1
09/19/2014 19:36:27;0100;PBS_Server;Job;42570.tyrone-cluster;dequeuing from batch, state QUEUED
09/19/2014 19:36:27;0100;PBS_Server;Job;42570.tyrone-cluster;enqueuing into idqueue, state 1 hop 1
09/19/2014 19:36:27;0008;PBS_Server;Job;42570.tyrone-cluster;Job Queued at request of chevadh@tyrone-cluster, owner = chevadh@tyrone-cluster, job name = jobname, queue = idqueue
09/19/2014 19:36:27;0040;PBS_Server;Svr;tyrone-cluster;Scheduler was sent the command new
09/19/2014 19:36:27;0008;PBS_Server;Job;42570.tyrone-cluster;Job Modified at request of Scheduler@tyrone-cluster
09/19/2014 19:36:49;0040;PBS_Server;Svr;tyrone-cluster;Scheduler was sent the command new
09/19/2014 19:37:25;0040;PBS_Server;Svr;tyrone-cluster;Scheduler was sent the command new
09/19/2014 19:37:40;0002;PBS_Server;Svr;PBS_Server;Torque Server Version = 3.0.5, loglevel = 0
09/19/2014 19:37:50;0040;PBS_Server;Svr;tyrone-cluster;Scheduler was sent the command new
09/19/2014 19:38:20;0040;PBS_Server;Svr;tyrone-cluster;Scheduler was sent the command new
09/19/2014 19:38:49;0040;PBS_Server;Svr;tyrone-cluster;Scheduler was sent the command new
09/19/2014 19:39:20;0040;PBS_Server;Svr;tyrone-cluster;Scheduler was sent the command new
09/19/2014 19:39:49;0040;PBS_Server;Svr;tyrone-cluster;Scheduler was sent the command new
09/19/2014 19:40:19;0040;PBS_Server;Svr;tyrone-cluster;Scheduler was sent the command new
09/19/2014 19:40:50;0040;PBS_Server;Svr;tyrone-cluster;Scheduler was sent the command new
09/19/2014 19:41:19;0040;PBS_Server;Svr;tyrone-cluster;Scheduler was sent the command new
09/19/2014 19:41:49;0040;PBS_Server;Svr;tyrone-cluster;Scheduler was sent the command new
09/19/2014 19:42:20;0040;PBS_Server;Svr;tyrone-cluster;Scheduler was sent the command new
09/19/2014 19:42:40;0002;PBS_Server;Svr;PBS_Server;Torque Server Version = 3.0.5, loglevel = 0
09/19/2014 19:42:53;0040;PBS_Server;Svr;tyrone-cluster;Scheduler was sent the command new
09/19/2014 19:43:30;0040;PBS_Server;Svr;tyrone-cluster;Scheduler was sent the command new
09/19/2014 19:43:57;0040;PBS_Server;Svr;tyrone-cluster;Scheduler was sent the command new
09/19/2014 19:44:31;0040;PBS_Server;Svr;tyrone-cluster;Scheduler was sent the command new
09/19/2014 19:45:00;0040;PBS_Server;Svr;tyrone-cluster;Scheduler was sent the command new
09/19/2014 19:45:34;0040;PBS_Server;Svr;tyrone-cluster;Scheduler was sent the command new
09/19/2014 19:46:05;0040;PBS_Server;Svr;tyrone-cluster;Scheduler was sent the command new
09/19/2014 19:46:34;0040;PBS_Server;Svr;tyrone-cluster;Scheduler was sent the command new
09/19/2014 19:47:10;0040;PBS_Server;Svr;tyrone-cluster;Scheduler was sent the command new
09/19/2014 19:47:35;0040;PBS_Server;Svr;tyrone-cluster;Scheduler was sent the command new
09/19/2014 19:47:40;0002;PBS_Server;Svr;PBS_Server;Torque Server Version = 3.0.5, loglevel = 0
09/19/2014 19:48:04;0040;PBS_Server;Svr;tyrone-cluster;Scheduler was sent the command new
09/19/2014 19:48:34;0040;PBS_Server;Svr;tyrone-cluster;Scheduler was sent the command new
09/19/2014 19:49:05;0040;PBS_Server;Svr;tyrone-cluster;Scheduler was sent the command new
09/19/2014 19:49:26;0008;PBS_Server;Job;42544.tyrone-cluster;Job deleted at request of root@tyrone-cluster
09/19/2014 19:49:26;0008;PBS_Server;Job;42544.tyrone-cluster;Job sent signal SIGTERM on delete
09/19/2014 19:49:28;0008;PBS_Server;Job;42544.tyrone-cluster;Job sent signal SIGKILL on delete
09/19/2014 19:49:32;000d;PBS_Server;Job;42544.tyrone-cluster;Not sending email: User does not want mail of this type.
09/19/2014 19:49:32;0010;PBS_Server;Job;42544.tyrone-cluster;Exit_status=271 resources_used.cput=07:03:33 resources_used.mem=154556kb resources_used.vmem=64633468kb resources_used.walltime=07:04:44
09/19/2014 19:49:32;0008;PBS_Server;Job;NULL;on_job_exit valid pjob: 0x2c82f50 (substate=50)
09/19/2014 19:49:32;0008;PBS_Server;Job;NULL;on_job_exit valid pjob: 0x2c82f50 (substate=51)
09/19/2014 19:49:32;0008;PBS_Server;Job;NULL;on_job_exit valid pjob: 0x2c82f50 (substate=51)
09/19/2014 19:49:32;0008;PBS_Server;Job;NULL;on_job_exit valid pjob: 0x2c82f50 (substate=53)
09/19/2014 19:49:32;0100;PBS_Server;Job;42544.tyrone-cluster;dequeuing from qp256, state COMPLETE
09/19/2014 19:49:32;0040;PBS_Server;Svr;tyrone-cluster;Scheduler was sent the command term
09/19/2014 19:49:32;0008;PBS_Server;Job;42540.tyrone-cluster;Job Modified at request of Scheduler@tyrone-cluster
09/19/2014 19:49:32;0008;PBS_Server;Job;42545.tyrone-cluster;Job Modified at request of Scheduler@tyrone-cluster
09/19/2014 19:49:32;0008;PBS_Server;Job;42545.tyrone-cluster;Job Run at request of Scheduler@tyrone-cluster
09/19/2014 19:49:32;0040;PBS_Server;Svr;tyrone-cluster;Scheduler was sent the command recyc
09/19/2014 19:49:35;0100;PBS_Server;Job;42554.tyrone-cluster;dequeuing from batch, state QUEUED
09/19/2014 19:49:35;0100;PBS_Server;Job;42554.tyrone-cluster;enqueuing into qp256, state 1 hop 1
09/19/2014 19:49:35;0040;PBS_Server;Svr;tyrone-cluster;Scheduler was sent the command new
09/19/2014 19:49:36;0008;PBS_Server;Job;42540.tyrone-cluster;Job Modified at request of Scheduler@tyrone-cluster
09/19/2014 19:49:36;0008;PBS_Server;Job;42554.tyrone-cluster;Job Modified at request of Scheduler@tyrone-cluster
09/19/2014 19:50:12;0040;PBS_Server;Svr;tyrone-cluster;Scheduler was sent the command new
09/19/2014 19:50:17;000d;PBS_Server;Job;42545.tyrone-cluster;Not sending email: User does not want mail of this type.
09/19/2014 19:50:42;0040;PBS_Server;Svr;tyrone-cluster;Scheduler was sent the command new
09/19/2014 19:51:15;0040;PBS_Server;Svr;tyrone-cluster;Scheduler was sent the command new
09/19/2014 19:51:47;0040;PBS_Server;Svr;tyrone-cluster;Scheduler was sent the command new
09/19/2014 19:52:19;0040;PBS_Server;Svr;tyrone-cluster;Scheduler was sent the command new
09/19/2014 19:52:40;0002;PBS_Server;Svr;PBS_Server;Torque Server Version = 3.0.5, loglevel = 0
09/19/2014 19:52:50;0040;PBS_Server;Svr;tyrone-cluster;Scheduler was sent the command new
09/19/2014 19:53:19;0040;PBS_Server;Svr;tyrone-cluster;Scheduler was sent the command new
09/19/2014 19:53:49;0040;PBS_Server;Svr;tyrone-cluster;Scheduler was sent the command new
09/19/2014 19:54:20;0040;PBS_Server;Svr;tyrone-cluster;Scheduler was sent the command new
09/19/2014 19:54:49;0040;PBS_Server;Svr;tyrone-cluster;Scheduler was sent the command new
09/19/2014 19:54:50;0008;PBS_Server;Job;42545.tyrone-cluster;Job deleted at request of root@tyrone-cluster
09/19/2014 19:54:50;0008;PBS_Server;Job;42545.tyrone-cluster;Job sent signal SIGTERM on delete
09/19/2014 19:54:52;0008;PBS_Server;Job;42545.tyrone-cluster;Job sent signal SIGKILL on delete
09/19/2014 19:54:56;000d;PBS_Server;Job;42545.tyrone-cluster;Not sending email: User does not want mail of this type.
09/19/2014 19:54:56;0010;PBS_Server;Job;42545.tyrone-cluster;Exit_status=271 resources_used.cput=00:05:11 resources_used.mem=169380kb resources_used.vmem=64633652kb resources_used.walltime=00:05:24
09/19/2014 19:54:56;0008;PBS_Server;Job;NULL;on_job_exit valid pjob: 0x2cddd70 (substate=50)
09/19/2014 19:54:56;0008;PBS_Server;Job;NULL;on_job_exit valid pjob: 0x2cddd70 (substate=51)
09/19/2014 19:54:56;0008;PBS_Server;Job;NULL;on_job_exit valid pjob: 0x2cddd70 (substate=51)
09/19/2014 19:54:56;0008;PBS_Server;Job;NULL;on_job_exit valid pjob: 0x2cddd70 (substate=53)
09/19/2014 19:54:56;0100;PBS_Server;Job;42545.tyrone-cluster;dequeuing from qp256, state COMPLETE
09/19/2014 19:54:56;0040;PBS_Server;Svr;tyrone-cluster;Scheduler was sent the command term
09/19/2014 19:54:56;0008;PBS_Server;Job;42540.tyrone-cluster;Job Modified at request of Scheduler@tyrone-cluster
09/19/2014 19:54:56;0008;PBS_Server;Job;42552.tyrone-cluster;Job Modified at request of Scheduler@tyrone-cluster
09/19/2014 19:54:56;0008;PBS_Server;Job;42552.tyrone-cluster;Job Run at request of Scheduler@tyrone-cluster
09/19/2014 19:54:56;0040;PBS_Server;Svr;tyrone-cluster;Scheduler was sent the command recyc
09/19/2014 19:55:19;0040;PBS_Server;Svr;tyrone-cluster;Scheduler was sent the command new
09/19/2014 19:55:19;0008;PBS_Server;Job;42540.tyrone-cluster;Job Modified at request of Scheduler@tyrone-cluster
09/19/2014 19:55:45;000d;PBS_Server;Job;42552.tyrone-cluster;Not sending email: User does not want mail of this type.
09/19/2014 19:55:50;0040;PBS_Server;Svr;tyrone-cluster;Scheduler was sent the command new
09/19/2014 19:56:19;0040;PBS_Server;Svr;tyrone-cluster;Scheduler was sent the command new
09/19/2014 19:56:49;0040;PBS_Server;Svr;tyrone-cluster;Scheduler was sent the command new
09/19/2014 19:56:50;0008;PBS_Server;Job;42569.tyrone-cluster;Job deleted at request of chevadh@tyrone-cluster
09/19/2014 19:56:50;0008;PBS_Server;Job;NULL;on_job_exit valid pjob: 0x2dd23d0 (substate=59)
09/19/2014 19:56:50;0100;PBS_Server;Job;42569.tyrone-cluster;dequeuing from idqueue, state COMPLETE
09/19/2014 19:56:50;0040;PBS_Server;Svr;tyrone-cluster;Scheduler was sent the command term
09/19/2014 19:56:53;0008;PBS_Server;Job;42570.tyrone-cluster;Job deleted at request of chevadh@tyrone-cluster
09/19/2014 19:56:53;0008;PBS_Server;Job;NULL;on_job_exit valid pjob: 0x2dd6240 (substate=59)
09/19/2014 19:56:53;0100;PBS_Server;Job;42570.tyrone-cluster;dequeuing from idqueue, state COMPLETE
09/19/2014 19:56:53;0040;PBS_Server;Svr;tyrone-cluster;Scheduler was sent the command term
09/19/2014 19:57:20;0040;PBS_Server;Svr;tyrone-cluster;Scheduler was sent the command new
09/19/2014 19:57:27;0100;PBS_Server;Job;42571.tyrone-cluster;enqueuing into batch, state 1 hop 1
09/19/2014 19:57:27;0100;PBS_Server;Job;42571.tyrone-cluster;dequeuing from batch, state QUEUED
09/19/2014 19:57:27;0100;PBS_Server;Job;42571.tyrone-cluster;enqueuing into idqueue, state 1 hop 1
09/19/2014 19:57:27;0008;PBS_Server;Job;42571.tyrone-cluster;Job Queued at request of chevadh@tyrone-cluster, owner = chevadh@tyrone-cluster, job name = jobname, queue = idqueue
09/19/2014 19:57:27;0040;PBS_Server;Svr;tyrone-cluster;Scheduler was sent the command new
09/19/2014 19:57:27;0008;PBS_Server;Job;42571.tyrone-cluster;Job Modified at request of Scheduler@tyrone-cluster
09/19/2014 19:57:28;0100;PBS_Server;Job;42572.tyrone-cluster;enqueuing into batch, state 1 hop 1
09/19/2014 19:57:28;0100;PBS_Server;Job;42572.tyrone-cluster;dequeuing from batch, state QUEUED
09/19/2014 19:57:28;0100;PBS_Server;Job;42572.tyrone-cluster;enqueuing into idqueue, state 1 hop 1
09/19/2014 19:57:28;0008;PBS_Server;Job;42572.tyrone-cluster;Job Queued at request of chevadh@tyrone-cluster, owner = chevadh@tyrone-cluster, job name = jobname, queue = idqueue
09/19/2014 19:57:28;0040;PBS_Server;Svr;tyrone-cluster;Scheduler was sent the command new
09/19/2014 19:57:28;0008;PBS_Server;Job;42572.tyrone-cluster;Job Modified at request of Scheduler@tyrone-cluster
09/19/2014 19:57:40;0002;PBS_Server;Svr;PBS_Server;Torque Server Version = 3.0.5, loglevel = 0
09/19/2014 19:57:49;0040;PBS_Server;Svr;tyrone-cluster;Scheduler was sent the command new
09/19/2014 19:58:19;0040;PBS_Server;Svr;tyrone-cluster;Scheduler was sent the command new
09/19/2014 19:58:25;0100;PBS_Server;Job;42573.tyrone-cluster;enqueuing into batch, state 1 hop 1
09/19/2014 19:58:25;0100;PBS_Server;Job;42573.tyrone-cluster;dequeuing from batch, state QUEUED
09/19/2014 19:58:25;0100;PBS_Server;Job;42573.tyrone-cluster;enqueuing into idqueue, state 1 hop 1
09/19/2014 19:58:25;0008;PBS_Server;Job;42573.tyrone-cluster;Job Queued at request of chevadh@tyrone-cluster, owner = chevadh@tyrone-cluster, job name = jobname, queue = idqueue
09/19/2014 19:58:25;0040;PBS_Server;Svr;tyrone-cluster;Scheduler was sent the command new
09/19/2014 19:58:26;0008;PBS_Server;Job;42573.tyrone-cluster;Job Modified at request of Scheduler@tyrone-cluster
09/19/2014 19:58:29;0100;PBS_Server;Job;42574.tyrone-cluster;enqueuing into batch, state 1 hop 1
09/19/2014 19:58:29;0100;PBS_Server;Job;42574.tyrone-cluster;dequeuing from batch, state QUEUED
09/19/2014 19:58:29;0100;PBS_Server;Job;42574.tyrone-cluster;enqueuing into idqueue, state 1 hop 1
09/19/2014 19:58:29;0008;PBS_Server;Job;42574.tyrone-cluster;Job Queued at request of chevadh@tyrone-cluster, owner = chevadh@tyrone-cluster, job name = jobname, queue = idqueue
09/19/2014 19:58:29;0040;PBS_Server;Svr;tyrone-cluster;Scheduler was sent the command new
09/19/2014 19:58:30;0008;PBS_Server;Job;42574.tyrone-cluster;Job Modified at request of Scheduler@tyrone-cluster
09/19/2014 19:58:50;0040;PBS_Server;Svr;tyrone-cluster;Scheduler was sent the command new
09/19/2014 19:59:22;0040;PBS_Server;Svr;tyrone-cluster;Scheduler was sent the command new
09/19/2014 20:00:00;0040;PBS_Server;Svr;tyrone-cluster;Scheduler was sent the command new
09/19/2014 20:00:27;0040;PBS_Server;Svr;tyrone-cluster;Scheduler was sent the command new
09/19/2014 20:01:00;0040;PBS_Server;Svr;tyrone-cluster;Scheduler was sent the command new
09/19/2014 20:01:32;0040;PBS_Server;Svr;tyrone-cluster;Scheduler was sent the command new
09/19/2014 20:02:04;0040;PBS_Server;Svr;tyrone-cluster;Scheduler was sent the command new
09/19/2014 20:02:33;0040;PBS_Server;Svr;tyrone-cluster;Scheduler was sent the command new
09/19/2014 20:02:40;0002;PBS_Server;Svr;PBS_Server;Torque Server Version = 3.0.5, loglevel = 0
09/19/2014 20:03:04;0040;PBS_Server;Svr;tyrone-cluster;Scheduler was sent the command new
09/19/2014 20:03:34;0040;PBS_Server;Svr;tyrone-cluster;Scheduler was sent the command new
09/19/2014 20:04:05;0040;PBS_Server;Svr;tyrone-cluster;Scheduler was sent the command new
09/19/2014 20:04:34;0040;PBS_Server;Svr;tyrone-cluster;Scheduler was sent the command new
09/19/2014 20:05:04;0040;PBS_Server;Svr;tyrone-cluster;Scheduler was sent the command new
09/19/2014 20:05:35;0040;PBS_Server;Svr;tyrone-cluster;Scheduler was sent the command new
09/19/2014 20:06:06;0040;PBS_Server;Svr;tyrone-cluster;Scheduler was sent the command new
09/19/2014 20:06:40;0040;PBS_Server;Svr;tyrone-cluster;Scheduler was sent the command new
09/19/2014 20:07:05;0040;PBS_Server;Svr;tyrone-cluster;Scheduler was sent the command new
09/19/2014 20:07:34;0040;PBS_Server;Svr;tyrone-cluster;Scheduler was sent the command new
09/19/2014 20:07:40;0002;PBS_Server;Svr;PBS_Server;Torque Server Version = 3.0.5, loglevel = 0
09/19/2014 20:08:04;0040;PBS_Server;Svr;tyrone-cluster;Scheduler was sent the command new
09/19/2014 20:08:35;0040;PBS_Server;Svr;tyrone-cluster;Scheduler was sent the command new
09/19/2014 20:09:08;0040;PBS_Server;Svr;tyrone-cluster;Scheduler was sent the command new
09/19/2014 20:09:45;0040;PBS_Server;Svr;tyrone-cluster;Scheduler was sent the command new
09/19/2014 20:10:12;0040;PBS_Server;Svr;tyrone-cluster;Scheduler was sent the command new
09/19/2014 20:10:45;0040;PBS_Server;Svr;tyrone-cluster;Scheduler was sent the command new
09/19/2014 20:11:17;0040;PBS_Server;Svr;tyrone-cluster;Scheduler was sent the command new
09/19/2014 20:11:49;0040;PBS_Server;Svr;tyrone-cluster;Scheduler was sent the command new
09/19/2014 20:12:20;0040;PBS_Server;Svr;tyrone-cluster;Scheduler was sent the command new
09/19/2014 20:12:40;0002;PBS_Server;Svr;PBS_Server;Torque Server Version = 3.0.5, loglevel = 0
09/19/2014 20:12:49;0040;PBS_Server;Svr;tyrone-cluster;Scheduler was sent the command new
09/19/2014 20:13:19;0040;PBS_Server;Svr;tyrone-cluster;Scheduler was sent the command new
09/19/2014 20:13:50;0040;PBS_Server;Svr;tyrone-cluster;Scheduler was sent the command new
09/19/2014 20:14:22;0040;PBS_Server;Svr;tyrone-cluster;Scheduler was sent the command new
09/19/2014 20:15:00;0040;PBS_Server;Svr;tyrone-cluster;Scheduler was sent the command new
09/19/2014 20:15:27;0040;PBS_Server;Svr;tyrone-cluster;Scheduler was sent the command new
09/19/2014 20:16:00;0040;PBS_Server;Svr;tyrone-cluster;Scheduler was sent the command new
09/19/2014 20:16:31;0040;PBS_Server;Svr;tyrone-cluster;Scheduler was sent the command new
09/19/2014 20:17:03;0040;PBS_Server;Svr;tyrone-cluster;Scheduler was sent the command new
09/19/2014 20:17:33;0040;PBS_Server;Svr;tyrone-cluster;Scheduler was sent the command new
09/19/2014 20:17:40;0002;PBS_Server;Svr;PBS_Server;Torque Server Version = 3.0.5, loglevel = 0
09/19/2014 20:18:03;0040;PBS_Server;Svr;tyrone-cluster;Scheduler was sent the command new
09/19/2014 20:18:34;0040;PBS_Server;Svr;tyrone-cluster;Scheduler was sent the command new
09/19/2014 20:19:05;0040;PBS_Server;Svr;tyrone-cluster;Scheduler was sent the command new
09/19/2014 20:19:34;0040;PBS_Server;Svr;tyrone-cluster;Scheduler was sent the command new
09/19/2014 20:20:04;0040;PBS_Server;Svr;tyrone-cluster;Scheduler was sent the command new
09/19/2014 20:20:35;0040;PBS_Server;Svr;tyrone-cluster;Scheduler was sent the command new
09/19/2014 20:21:07;0040;PBS_Server;Svr;tyrone-cluster;Scheduler was sent the command new
09/19/2014 20:21:45;0040;PBS_Server;Svr;tyrone-cluster;Scheduler was sent the command new
09/19/2014 20:22:09;0040;PBS_Server;Svr;tyrone-cluster;Scheduler was sent the command new
09/19/2014 20:22:40;0002;PBS_Server;Svr;PBS_Server;Torque Server Version = 3.0.5, loglevel = 0
09/19/2014 20:22:42;0040;PBS_Server;Svr;tyrone-cluster;Scheduler was sent the command new
09/19/2014 20:23:16;0040;PBS_Server;Svr;tyrone-cluster;Scheduler was sent the command new
09/19/2014 20:23:48;0040;PBS_Server;Svr;tyrone-cluster;Scheduler was sent the command new
09/19/2014 20:24:20;0040;PBS_Server;Svr;tyrone-cluster;Scheduler was sent the command new
09/19/2014 20:24:49;0040;PBS_Server;Svr;tyrone-cluster;Scheduler was sent the command new
09/19/2014 20:25:19;0040;PBS_Server;Svr;tyrone-cluster;Scheduler was sent the command new
09/19/2014 20:25:50;0040;PBS_Server;Svr;tyrone-cluster;Scheduler was sent the command new
09/19/2014 20:26:22;0040;PBS_Server;Svr;tyrone-cluster;Scheduler was sent the command new
09/19/2014 20:27:00;0040;PBS_Server;Svr;tyrone-cluster;Scheduler was sent the command new
09/19/2014 20:27:27;0040;PBS_Server;Svr;tyrone-cluster;Scheduler was sent the command new
09/19/2014 20:27:40;0002;PBS_Server;Svr;PBS_Server;Torque Server Version = 3.0.5, loglevel = 0
09/19/2014 20:27:59;0040;PBS_Server;Svr;tyrone-cluster;Scheduler was sent the command new
09/19/2014 20:28:31;0040;PBS_Server;Svr;tyrone-cluster;Scheduler was sent the command new
09/19/2014 20:29:04;0040;PBS_Server;Svr;tyrone-cluster;Scheduler was sent the command new
09/19/2014 20:29:35;0040;PBS_Server;Svr;tyrone-cluster;Scheduler was sent the command new
09/19/2014 20:30:04;0040;PBS_Server;Svr;tyrone-cluster;Scheduler was sent the command new
09/19/2014 20:30:34;0040;PBS_Server;Svr;tyrone-cluster;Scheduler was sent the command new
09/19/2014 20:31:05;0040;PBS_Server;Svr;tyrone-cluster;Scheduler was sent the command new
09/19/2014 20:31:37;0040;PBS_Server;Svr;tyrone-cluster;Scheduler was sent the command new
09/19/2014 20:32:15;0040;PBS_Server;Svr;tyrone-cluster;Scheduler was sent the command new
09/19/2014 20:32:40;0002;PBS_Server;Svr;PBS_Server;Torque Server Version = 3.0.5, loglevel = 0
09/19/2014 20:32:41;0040;PBS_Server;Svr;tyrone-cluster;Scheduler was sent the command new
09/19/2014 20:33:15;0040;PBS_Server;Svr;tyrone-cluster;Scheduler was sent the command new
09/19/2014 20:33:46;0040;PBS_Server;Svr;tyrone-cluster;Scheduler was sent the command new
09/19/2014 20:34:19;0040;PBS_Server;Svr;tyrone-cluster;Scheduler was sent the command new
09/19/2014 20:34:50;0040;PBS_Server;Svr;tyrone-cluster;Scheduler was sent the command new
09/19/2014 20:35:19;0040;PBS_Server;Svr;tyrone-cluster;Scheduler was sent the command new
09/19/2014 20:35:50;0040;PBS_Server;Svr;tyrone-cluster;Scheduler was sent the command new
09/19/2014 20:36:20;0040;PBS_Server;Svr;tyrone-cluster;Scheduler was sent the command new
09/19/2014 20:36:53;0040;PBS_Server;Svr;tyrone-cluster;Scheduler was sent the command new
09/19/2014 20:37:29;0040;PBS_Server;Svr;tyrone-cluster;Scheduler was sent the command new
09/19/2014 20:37:40;0002;PBS_Server;Svr;PBS_Server;Torque Server Version = 3.0.5, loglevel = 0
09/19/2014 20:37:54;0040;PBS_Server;Svr;tyrone-cluster;Scheduler was sent the command new
09/19/2014 20:38:30;0040;PBS_Server;Svr;tyrone-cluster;Scheduler was sent the command new
09/19/2014 20:39:01;0040;PBS_Server;Svr;tyrone-cluster;Scheduler was sent the command new
09/19/2014 20:39:33;0040;PBS_Server;Svr;tyrone-cluster;Scheduler was sent the command new
09/19/2014 20:40:00;0040;PBS_Server;Svr;tyrone-cluster;Scheduler was sent the command new
09/19/2014 20:40:32;0040;PBS_Server;Svr;tyrone-cluster;Scheduler was sent the command new
09/19/2014 20:41:04;0040;PBS_Server;Svr;tyrone-cluster;Scheduler was sent the command new
09/19/2014 20:41:35;0040;PBS_Server;Svr;tyrone-cluster;Scheduler was sent the command new
09/19/2014 20:42:05;0040;PBS_Server;Svr;tyrone-cluster;Scheduler was sent the command new
09/19/2014 20:42:39;0040;PBS_Server;Svr;tyrone-cluster;Scheduler was sent the command new
09/19/2014 20:42:40;0002;PBS_Server;Svr;PBS_Server;Torque Server Version = 3.0.5, loglevel = 0
09/19/2014 20:43:05;0040;PBS_Server;Svr;tyrone-cluster;Scheduler was sent the command new
09/19/2014 20:43:06;000d;PBS_Server;Job;42556.tyrone-cluster;Not sending email: User does not want mail of this type.
09/19/2014 20:43:06;0010;PBS_Server;Job;42556.tyrone-cluster;Exit_status=143 resources_used.cput=63:27:10 resources_used.mem=420704kb resources_used.vmem=12107860kb resources_used.walltime=02:00:38
09/19/2014 20:43:06;0008;PBS_Server;Job;NULL;on_job_exit valid pjob: 0x2dd39d0 (substate=50)
09/19/2014 20:43:06;0008;PBS_Server;Job;NULL;on_job_exit valid pjob: 0x2dd39d0 (substate=51)
09/19/2014 20:43:06;0008;PBS_Server;Job;NULL;on_job_exit valid pjob: 0x2dd39d0 (substate=51)
09/19/2014 20:43:06;0008;PBS_Server;Job;NULL;on_job_exit valid pjob: 0x2dd39d0 (substate=53)
09/19/2014 20:43:06;0100;PBS_Server;Job;42556.tyrone-cluster;dequeuing from idqueue, state COMPLETE
09/19/2014 20:43:15;0008;PBS_Server;Job;42563.tyrone-cluster;Job Modified at request of Scheduler@tyrone-cluster
09/19/2014 20:43:15;0008;PBS_Server;Job;42563.tyrone-cluster;Job Run at request of Scheduler@tyrone-cluster
09/19/2014 20:43:15;0040;PBS_Server;Svr;tyrone-cluster;Scheduler was sent the command recyc
09/19/2014 20:43:15;000d;PBS_Server;Job;42563.tyrone-cluster;Not sending email: User does not want mail of this type.
09/19/2014 20:43:16;000d;PBS_Server;Job;42563.tyrone-cluster;Not sending email: User does not want mail of this type.
09/19/2014 20:43:16;0010;PBS_Server;Job;42563.tyrone-cluster;Exit_status=29 resources_used.cput=00:00:17 resources_used.mem=0kb resources_used.vmem=0kb resources_used.walltime=00:00:01
09/19/2014 20:43:16;0008;PBS_Server;Job;NULL;on_job_exit valid pjob: 0x2de5b50 (substate=50)
09/19/2014 20:43:16;0008;PBS_Server;Job;NULL;on_job_exit valid pjob: 0x2de5b50 (substate=51)
09/19/2014 20:43:16;0008;PBS_Server;Job;NULL;on_job_exit valid pjob: 0x2de5b50 (substate=51)
09/19/2014 20:43:16;0008;PBS_Server;Job;NULL;on_job_exit valid pjob: 0x2de5b50 (substate=53)
09/19/2014 20:43:16;0100;PBS_Server;Job;42563.tyrone-cluster;dequeuing from idqueue, state COMPLETE
09/19/2014 20:43:16;0040;PBS_Server;Svr;tyrone-cluster;Scheduler was sent the command term
09/19/2014 20:43:17;0008;PBS_Server;Job;42566.tyrone-cluster;Job Modified at request of Scheduler@tyrone-cluster
09/19/2014 20:43:17;0008;PBS_Server;Job;42566.tyrone-cluster;Job Run at request of Scheduler@tyrone-cluster
09/19/2014 20:43:17;0040;PBS_Server;Svr;tyrone-cluster;Scheduler was sent the command recyc
09/19/2014 20:43:17;000d;PBS_Server;Job;42566.tyrone-cluster;Not sending email: User does not want mail of this type.
09/19/2014 20:43:35;0040;PBS_Server;Svr;tyrone-cluster;Scheduler was sent the command new
09/19/2014 20:44:09;0040;PBS_Server;Svr;tyrone-cluster;Scheduler was sent the command new
09/19/2014 20:44:40;0040;PBS_Server;Svr;tyrone-cluster;Scheduler was sent the command new
09/19/2014 20:45:12;0040;PBS_Server;Svr;tyrone-cluster;Scheduler was sent the command new
09/19/2014 20:45:45;0040;PBS_Server;Svr;tyrone-cluster;Scheduler was sent the command new
09/19/2014 20:46:19;0040;PBS_Server;Svr;tyrone-cluster;Scheduler was sent the command new
09/19/2014 20:46:46;0040;PBS_Server;Svr;tyrone-cluster;Scheduler was sent the command new
09/19/2014 20:47:17;0040;PBS_Server;Svr;tyrone-cluster;Scheduler was sent the command new
09/19/2014 20:47:40;0002;PBS_Server;Svr;PBS_Server;Torque Server Version = 3.0.5, loglevel = 0
09/19/2014 20:47:49;0040;PBS_Server;Svr;tyrone-cluster;Scheduler was sent the command new
09/19/2014 20:48:20;0040;PBS_Server;Svr;tyrone-cluster;Scheduler was sent the command new
09/19/2014 20:48:50;0040;PBS_Server;Svr;tyrone-cluster;Scheduler was sent the command new
09/19/2014 20:49:24;0040;PBS_Server;Svr;tyrone-cluster;Scheduler was sent the command new
09/19/2014 20:49:55;0040;PBS_Server;Svr;tyrone-cluster;Scheduler was sent the command new
09/19/2014 20:50:30;0040;PBS_Server;Svr;tyrone-cluster;Scheduler was sent the command new
09/19/2014 20:51:01;0040;PBS_Server;Svr;tyrone-cluster;Scheduler was sent the command new
09/19/2014 20:51:33;0040;PBS_Server;Svr;tyrone-cluster;Scheduler was sent the command new
09/19/2014 20:52:01;0040;PBS_Server;Svr;tyrone-cluster;Scheduler was sent the command new
09/19/2014 20:52:32;0040;PBS_Server;Svr;tyrone-cluster;Scheduler was sent the command new
09/19/2014 20:52:40;0002;PBS_Server;Svr;PBS_Server;Torque Server Version = 3.0.5, loglevel = 0
09/19/2014 20:53:04;0040;PBS_Server;Svr;tyrone-cluster;Scheduler was sent the command new
09/19/2014 20:53:35;0040;PBS_Server;Svr;tyrone-cluster;Scheduler was sent the command new
09/19/2014 20:54:05;0040;PBS_Server;Svr;tyrone-cluster;Scheduler was sent the command new
09/19/2014 20:54:39;0040;PBS_Server;Svr;tyrone-cluster;Scheduler was sent the command new
09/19/2014 20:55:10;0040;PBS_Server;Svr;tyrone-cluster;Scheduler was sent the command new
09/19/2014 20:55:44;0040;PBS_Server;Svr;tyrone-cluster;Scheduler was sent the command new
09/19/2014 20:56:16;0040;PBS_Server;Svr;tyrone-cluster;Scheduler was sent the command new
09/19/2014 20:56:49;0040;PBS_Server;Svr;tyrone-cluster;Scheduler was sent the command new
09/19/2014 20:57:16;0040;PBS_Server;Svr;tyrone-cluster;Scheduler was sent the command new
09/19/2014 20:57:40;0002;PBS_Server;Svr;PBS_Server;Torque Server Version = 3.0.5, loglevel = 0
09/19/2014 20:57:50;0040;PBS_Server;Svr;tyrone-cluster;Scheduler was sent the command new
09/19/2014 20:58:18;0040;PBS_Server;Svr;tyrone-cluster;Scheduler was sent the command new
09/19/2014 20:58:50;0040;PBS_Server;Svr;tyrone-cluster;Scheduler was sent the command new
09/19/2014 20:59:20;0040;PBS_Server;Svr;tyrone-cluster;Scheduler was sent the command new
09/19/2014 20:59:54;0040;PBS_Server;Svr;tyrone-cluster;Scheduler was sent the command new
09/19/2014 21:00:25;0040;PBS_Server;Svr;tyrone-cluster;Scheduler was sent the command new
09/19/2014 21:00:59;0040;PBS_Server;Svr;tyrone-cluster;Scheduler was sent the command new
09/19/2014 21:01:31;0040;PBS_Server;Svr;tyrone-cluster;Scheduler was sent the command new
09/19/2014 21:02:04;0040;PBS_Server;Svr;tyrone-cluster;Scheduler was sent the command new
09/19/2014 21:02:31;0040;PBS_Server;Svr;tyrone-cluster;Scheduler was sent the command new
09/19/2014 21:02:40;0002;PBS_Server;Svr;PBS_Server;Torque Server Version = 3.0.5, loglevel = 0
09/19/2014 21:03:05;0040;PBS_Server;Svr;tyrone-cluster;Scheduler was sent the command new
09/19/2014 21:03:34;0040;PBS_Server;Svr;tyrone-cluster;Scheduler was sent the command new
09/19/2014 21:04:05;0040;PBS_Server;Svr;tyrone-cluster;Scheduler was sent the command new
09/19/2014 21:04:35;0040;PBS_Server;Svr;tyrone-cluster;Scheduler was sent the command new
09/19/2014 21:05:09;0040;PBS_Server;Svr;tyrone-cluster;Scheduler was sent the command new
09/19/2014 21:05:40;0040;PBS_Server;Svr;tyrone-cluster;Scheduler was sent the command new
09/19/2014 21:06:14;0040;PBS_Server;Svr;tyrone-cluster;Scheduler was sent the command new
09/19/2014 21:06:46;0040;PBS_Server;Svr;tyrone-cluster;Scheduler was sent the command new
09/19/2014 21:07:19;0040;PBS_Server;Svr;tyrone-cluster;Scheduler was sent the command new
09/19/2014 21:07:40;0002;PBS_Server;Svr;PBS_Server;Torque Server Version = 3.0.5, loglevel = 0
09/19/2014 21:07:46;0040;PBS_Server;Svr;tyrone-cluster;Scheduler was sent the command new
09/19/2014 21:08:20;0040;PBS_Server;Svr;tyrone-cluster;Scheduler was sent the command new
09/19/2014 21:08:48;0040;PBS_Server;Svr;tyrone-cluster;Scheduler was sent the command new
09/19/2014 21:09:16;0040;PBS_Server;Svr;tyrone-cluster;Scheduler was sent the command new
09/19/2014 21:09:50;0040;PBS_Server;Svr;tyrone-cluster;Scheduler was sent the command new
09/19/2014 21:10:18;0040;PBS_Server;Svr;tyrone-cluster;Scheduler was sent the command new
09/19/2014 21:10:50;0040;PBS_Server;Svr;tyrone-cluster;Scheduler was sent the command new
09/19/2014 21:11:20;0040;PBS_Server;Svr;tyrone-cluster;Scheduler was sent the command new
09/19/2014 21:11:54;0040;PBS_Server;Svr;tyrone-cluster;Scheduler was sent the command new
09/19/2014 21:12:25;0040;PBS_Server;Svr;tyrone-cluster;Scheduler was sent the command new
09/19/2014 21:12:40;0002;PBS_Server;Svr;PBS_Server;Torque Server Version = 3.0.5, loglevel = 0
09/19/2014 21:12:59;0040;PBS_Server;Svr;tyrone-cluster;Scheduler was sent the command new
09/19/2014 21:13:31;0040;PBS_Server;Svr;tyrone-cluster;Scheduler was sent the command new
09/19/2014 21:14:04;0040;PBS_Server;Svr;tyrone-cluster;Scheduler was sent the command new
09/19/2014 21:14:31;0040;PBS_Server;Svr;tyrone-cluster;Scheduler was sent the command new
09/19/2014 21:15:05;0040;PBS_Server;Svr;tyrone-cluster;Scheduler was sent the command new
09/19/2014 21:15:33;0040;PBS_Server;Svr;tyrone-cluster;Scheduler was sent the command new
09/19/2014 21:16:01;0040;PBS_Server;Svr;tyrone-cluster;Scheduler was sent the command new
09/19/2014 21:16:35;0040;PBS_Server;Svr;tyrone-cluster;Scheduler was sent the command new
09/19/2014 21:17:03;0040;PBS_Server;Svr;tyrone-cluster;Scheduler was sent the command new
09/19/2014 21:17:35;0040;PBS_Server;Svr;tyrone-cluster;Scheduler was sent the command new
09/19/2014 21:17:40;0002;PBS_Server;Svr;PBS_Server;Torque Server Version = 3.0.5, loglevel = 0
09/19/2014 21:18:05;0040;PBS_Server;Svr;tyrone-cluster;Scheduler was sent the command new
09/19/2014 21:18:39;0040;PBS_Server;Svr;tyrone-cluster;Scheduler was sent the command new
09/19/2014 21:19:10;0040;PBS_Server;Svr;tyrone-cluster;Scheduler was sent the command new
09/19/2014 21:19:43;0040;PBS_Server;Svr;tyrone-cluster;Scheduler was sent the command new
09/19/2014 21:20:14;0040;PBS_Server;Svr;tyrone-cluster;Scheduler was sent the command new
09/19/2014 21:20:43;0040;PBS_Server;Svr;tyrone-cluster;Scheduler was sent the command new
09/19/2014 21:21:16;0040;PBS_Server;Svr;tyrone-cluster;Scheduler was sent the command new
09/19/2014 21:21:45;0040;PBS_Server;Svr;tyrone-cluster;Scheduler was sent the command new
09/19/2014 21:22:19;0040;PBS_Server;Svr;tyrone-cluster;Scheduler was sent the command new
09/19/2014 21:22:40;0002;PBS_Server;Svr;PBS_Server;Torque Server Version = 3.0.5, loglevel = 0
09/19/2014 21:22:46;0040;PBS_Server;Svr;tyrone-cluster;Scheduler was sent the command new
09/19/2014 21:23:16;0040;PBS_Server;Svr;tyrone-cluster;Scheduler was sent the command new
09/19/2014 21:23:49;0040;PBS_Server;Svr;tyrone-cluster;Scheduler was sent the command new
09/19/2014 21:24:16;0040;PBS_Server;Svr;tyrone-cluster;Scheduler was sent the command new
09/19/2014 21:24:46;0040;PBS_Server;Svr;tyrone-cluster;Scheduler was sent the command new
09/19/2014 21:25:18;0040;PBS_Server;Svr;tyrone-cluster;Scheduler was sent the command new
09/19/2014 21:25:46;0040;PBS_Server;Svr;tyrone-cluster;Scheduler was sent the command new
09/19/2014 21:26:20;0040;PBS_Server;Svr;tyrone-cluster;Scheduler was sent the command new
09/19/2014 21:26:49;0040;PBS_Server;Svr;tyrone-cluster;Scheduler was sent the command new
09/19/2014 21:27:20;0040;PBS_Server;Svr;tyrone-cluster;Scheduler was sent the command new
09/19/2014 21:27:40;0002;PBS_Server;Svr;PBS_Server;Torque Server Version = 3.0.5, loglevel = 0
09/19/2014 21:27:50;0040;PBS_Server;Svr;tyrone-cluster;Scheduler was sent the command new
09/19/2014 21:28:24;0040;PBS_Server;Svr;tyrone-cluster;Scheduler was sent the command new
09/19/2014 21:28:55;0040;PBS_Server;Svr;tyrone-cluster;Scheduler was sent the command new
09/19/2014 21:29:24;0040;PBS_Server;Svr;tyrone-cluster;Scheduler was sent the command new
09/19/2014 21:29:54;0040;PBS_Server;Svr;tyrone-cluster;Scheduler was sent the command new
09/19/2014 21:30:25;0040;PBS_Server;Svr;tyrone-cluster;Scheduler was sent the command new
09/19/2014 21:30:59;0040;PBS_Server;Svr;tyrone-cluster;Scheduler was sent the command new
09/19/2014 21:31:30;0040;PBS_Server;Svr;tyrone-cluster;Scheduler was sent the command new
09/19/2014 21:31:58;0040;PBS_Server;Svr;tyrone-cluster;Scheduler was sent the command new
09/19/2014 21:32:31;0040;PBS_Server;Svr;tyrone-cluster;Scheduler was sent the command new
09/19/2014 21:32:40;0002;PBS_Server;Svr;PBS_Server;Torque Server Version = 3.0.5, loglevel = 0
09/19/2014 21:33:00;0040;PBS_Server;Svr;tyrone-cluster;Scheduler was sent the command new
09/19/2014 21:33:28;0040;PBS_Server;Svr;tyrone-cluster;Scheduler was sent the command new
09/19/2014 21:34:01;0040;PBS_Server;Svr;tyrone-cluster;Scheduler was sent the command new
09/19/2014 21:34:30;0040;PBS_Server;Svr;tyrone-cluster;Scheduler was sent the command new
09/19/2014 21:35:04;0040;PBS_Server;Svr;tyrone-cluster;Scheduler was sent the command new
09/19/2014 21:35:31;0040;PBS_Server;Svr;tyrone-cluster;Scheduler was sent the command new
09/19/2014 21:36:05;0040;PBS_Server;Svr;tyrone-cluster;Scheduler was sent the command new
09/19/2014 21:36:34;0040;PBS_Server;Svr;tyrone-cluster;Scheduler was sent the command new
09/19/2014 21:37:05;0040;PBS_Server;Svr;tyrone-cluster;Scheduler was sent the command new
09/19/2014 21:37:35;0040;PBS_Server;Svr;tyrone-cluster;Scheduler was sent the command new
09/19/2014 21:37:40;0002;PBS_Server;Svr;PBS_Server;Torque Server Version = 3.0.5, loglevel = 0
09/19/2014 21:38:09;0040;PBS_Server;Svr;tyrone-cluster;Scheduler was sent the command new
09/19/2014 21:38:40;0040;PBS_Server;Svr;tyrone-cluster;Scheduler was sent the command new
09/19/2014 21:39:13;0040;PBS_Server;Svr;tyrone-cluster;Scheduler was sent the command new
09/19/2014 21:39:44;0040;PBS_Server;Svr;tyrone-cluster;Scheduler was sent the command new
09/19/2014 21:40:16;0040;PBS_Server;Svr;tyrone-cluster;Scheduler was sent the command new
09/19/2014 21:40:46;0040;PBS_Server;Svr;tyrone-cluster;Scheduler was sent the command new
09/19/2014 21:41:20;0040;PBS_Server;Svr;tyrone-cluster;Scheduler was sent the command new
09/19/2014 21:41:48;0040;PBS_Server;Svr;tyrone-cluster;Scheduler was sent the command new
09/19/2014 21:42:20;0040;PBS_Server;Svr;tyrone-cluster;Scheduler was sent the command new
09/19/2014 21:42:40;0002;PBS_Server;Svr;PBS_Server;Torque Server Version = 3.0.5, loglevel = 0
09/19/2014 21:42:50;0040;PBS_Server;Svr;tyrone-cluster;Scheduler was sent the command new
09/19/2014 21:43:24;0040;PBS_Server;Svr;tyrone-cluster;Scheduler was sent the command new
09/19/2014 21:43:52;0040;PBS_Server;Svr;tyrone-cluster;Scheduler was sent the command new
09/19/2014 21:44:22;0040;PBS_Server;Svr;tyrone-cluster;Scheduler was sent the command new
09/19/2014 21:44:54;0040;PBS_Server;Svr;tyrone-cluster;Scheduler was sent the command new
09/19/2014 21:45:22;0040;PBS_Server;Svr;tyrone-cluster;Scheduler was sent the command new
09/19/2014 21:45:54;0040;PBS_Server;Svr;tyrone-cluster;Scheduler was sent the command new
09/19/2014 21:46:24;0040;PBS_Server;Svr;tyrone-cluster;Scheduler was sent the command new
09/19/2014 21:46:55;0040;PBS_Server;Svr;tyrone-cluster;Scheduler was sent the command new
09/19/2014 21:47:24;0040;PBS_Server;Svr;tyrone-cluster;Scheduler was sent the command new
09/19/2014 21:47:40;0002;PBS_Server;Svr;PBS_Server;Torque Server Version = 3.0.5, loglevel = 0
09/19/2014 21:47:54;0040;PBS_Server;Svr;tyrone-cluster;Scheduler was sent the command new
09/19/2014 21:48:25;0040;PBS_Server;Svr;tyrone-cluster;Scheduler was sent the command new
09/19/2014 21:48:58;0040;PBS_Server;Svr;tyrone-cluster;Scheduler was sent the command new
09/19/2014 21:49:29;0040;PBS_Server;Svr;tyrone-cluster;Scheduler was sent the command new
09/19/2014 21:49:58;0040;PBS_Server;Svr;tyrone-cluster;Scheduler was sent the command new
09/19/2014 21:50:31;0040;PBS_Server;Svr;tyrone-cluster;Scheduler was sent the command new
09/19/2014 21:51:01;0040;PBS_Server;Svr;tyrone-cluster;Scheduler was sent the command new
09/19/2014 21:51:34;0040;PBS_Server;Svr;tyrone-cluster;Scheduler was sent the command new
09/19/2014 21:52:01;0040;PBS_Server;Svr;tyrone-cluster;Scheduler was sent the command new
09/19/2014 21:52:35;0040;PBS_Server;Svr;tyrone-cluster;Scheduler was sent the command new
09/19/2014 21:52:40;0002;PBS_Server;Svr;PBS_Server;Torque Server Version = 3.0.5, loglevel = 0
09/19/2014 21:53:04;0040;PBS_Server;Svr;tyrone-cluster;Scheduler was sent the command new
09/19/2014 21:53:35;0040;PBS_Server;Svr;tyrone-cluster;Scheduler was sent the command new
09/19/2014 21:54:05;0040;PBS_Server;Svr;tyrone-cluster;Scheduler was sent the command new
09/19/2014 21:54:39;0040;PBS_Server;Svr;tyrone-cluster;Scheduler was sent the command new
09/19/2014 21:55:07;0040;PBS_Server;Svr;tyrone-cluster;Scheduler was sent the command new
09/19/2014 21:55:39;0040;PBS_Server;Svr;tyrone-cluster;Scheduler was sent the command new
09/19/2014 21:56:09;0040;PBS_Server;Svr;tyrone-cluster;Scheduler was sent the command new
09/19/2014 21:56:40;0040;PBS_Server;Svr;tyrone-cluster;Scheduler was sent the command new
09/19/2014 21:57:13;0040;PBS_Server;Svr;tyrone-cluster;Scheduler was sent the command new
09/19/2014 21:57:40;0002;PBS_Server;Svr;PBS_Server;Torque Server Version = 3.0.5, loglevel = 0
09/19/2014 21:57:43;0040;PBS_Server;Svr;tyrone-cluster;Scheduler was sent the command new
09/19/2014 21:58:13;0040;PBS_Server;Svr;tyrone-cluster;Scheduler was sent the command new
09/19/2014 21:58:46;0040;PBS_Server;Svr;tyrone-cluster;Scheduler was sent the command new
09/19/2014 21:59:15;0040;PBS_Server;Svr;tyrone-cluster;Scheduler was sent the command new
09/19/2014 21:59:43;0040;PBS_Server;Svr;tyrone-cluster;Scheduler was sent the command new
09/19/2014 22:00:16;0040;PBS_Server;Svr;tyrone-cluster;Scheduler was sent the command new
09/19/2014 22:00:44;0040;PBS_Server;Svr;tyrone-cluster;Scheduler was sent the command new
09/19/2014 22:01:13;0040;PBS_Server;Svr;tyrone-cluster;Scheduler was sent the command new
09/19/2014 22:01:46;0040;PBS_Server;Svr;tyrone-cluster;Scheduler was sent the command new
09/19/2014 22:02:16;0040;PBS_Server;Svr;tyrone-cluster;Scheduler was sent the command new
09/19/2014 22:02:40;0002;PBS_Server;Svr;PBS_Server;Torque Server Version = 3.0.5, loglevel = 0
09/19/2014 22:02:48;0040;PBS_Server;Svr;tyrone-cluster;Scheduler was sent the command new
09/19/2014 22:03:16;0040;PBS_Server;Svr;tyrone-cluster;Scheduler was sent the command new
09/19/2014 22:03:50;0040;PBS_Server;Svr;tyrone-cluster;Scheduler was sent the command new
09/19/2014 22:04:19;0040;PBS_Server;Svr;tyrone-cluster;Scheduler was sent the command new
09/19/2014 22:04:50;0040;PBS_Server;Svr;tyrone-cluster;Scheduler was sent the command new
09/19/2014 22:05:20;0040;PBS_Server;Svr;tyrone-cluster;Scheduler was sent the command new
09/19/2014 22:05:54;0040;PBS_Server;Svr;tyrone-cluster;Scheduler was sent the command new
09/19/2014 22:06:25;0040;PBS_Server;Svr;tyrone-cluster;Scheduler was sent the command new
09/19/2014 22:06:54;0040;PBS_Server;Svr;tyrone-cluster;Scheduler was sent the command new
09/19/2014 22:07:24;0040;PBS_Server;Svr;tyrone-cluster;Scheduler was sent the command new
09/19/2014 22:07:40;0002;PBS_Server;Svr;PBS_Server;Torque Server Version = 3.0.5, loglevel = 0
09/19/2014 22:07:55;0040;PBS_Server;Svr;tyrone-cluster;Scheduler was sent the command new
09/19/2014 22:08:28;0040;PBS_Server;Svr;tyrone-cluster;Scheduler was sent the command new
09/19/2014 22:08:59;0040;PBS_Server;Svr;tyrone-cluster;Scheduler was sent the command new
09/19/2014 22:09:28;0040;PBS_Server;Svr;tyrone-cluster;Scheduler was sent the command new
09/19/2014 22:10:01;0040;PBS_Server;Svr;tyrone-cluster;Scheduler was sent the command new
09/19/2014 22:10:30;0040;PBS_Server;Svr;tyrone-cluster;Scheduler was sent the command new
09/19/2014 22:10:58;0040;PBS_Server;Svr;tyrone-cluster;Scheduler was sent the command new
09/19/2014 22:11:31;0040;PBS_Server;Svr;tyrone-cluster;Scheduler was sent the command new
09/19/2014 22:12:05;0040;PBS_Server;Svr;tyrone-cluster;Scheduler was sent the command new
09/19/2014 22:12:33;0040;PBS_Server;Svr;tyrone-cluster;Scheduler was sent the command new
09/19/2014 22:12:40;0002;PBS_Server;Svr;PBS_Server;Torque Server Version = 3.0.5, loglevel = 0
09/19/2014 22:13:05;0040;PBS_Server;Svr;tyrone-cluster;Scheduler was sent the command new
09/19/2014 22:13:35;0040;PBS_Server;Svr;tyrone-cluster;Scheduler was sent the command new
09/19/2014 22:14:09;0040;PBS_Server;Svr;tyrone-cluster;Scheduler was sent the command new
09/19/2014 22:14:37;0040;PBS_Server;Svr;tyrone-cluster;Scheduler was sent the command new
09/19/2014 22:15:06;0040;PBS_Server;Svr;tyrone-cluster;Scheduler was sent the command new
09/19/2014 22:15:39;0040;PBS_Server;Svr;tyrone-cluster;Scheduler was sent the command new
09/19/2014 22:16:07;0040;PBS_Server;Svr;tyrone-cluster;Scheduler was sent the command new
09/19/2014 22:16:40;0040;PBS_Server;Svr;tyrone-cluster;Scheduler was sent the command new
09/19/2014 22:17:09;0040;PBS_Server;Svr;tyrone-cluster;Scheduler was sent the command new
09/19/2014 22:17:37;0040;PBS_Server;Svr;tyrone-cluster;Scheduler was sent the command new
09/19/2014 22:17:40;0002;PBS_Server;Svr;PBS_Server;Torque Server Version = 3.0.5, loglevel = 0
09/19/2014 22:18:06;0040;PBS_Server;Svr;tyrone-cluster;Scheduler was sent the command new
09/19/2014 22:18:39;0040;PBS_Server;Svr;tyrone-cluster;Scheduler was sent the command new
09/19/2014 22:19:06;0040;PBS_Server;Svr;tyrone-cluster;Scheduler was sent the command new
09/19/2014 22:19:36;0040;PBS_Server;Svr;tyrone-cluster;Scheduler was sent the command new
09/19/2014 22:20:09;0040;PBS_Server;Svr;tyrone-cluster;Scheduler was sent the command new
09/19/2014 22:20:37;0040;PBS_Server;Svr;tyrone-cluster;Scheduler was sent the command new
09/19/2014 22:21:06;0040;PBS_Server;Svr;tyrone-cluster;Scheduler was sent the command new
09/19/2014 22:21:39;0040;PBS_Server;Svr;tyrone-cluster;Scheduler was sent the command new
09/19/2014 22:22:10;0040;PBS_Server;Svr;tyrone-cluster;Scheduler was sent the command new
09/19/2014 22:22:28;0100;PBS_Server;Job;42575.tyrone-cluster;enqueuing into batch, state 1 hop 1
09/19/2014 22:22:28;0100;PBS_Server;Job;42575.tyrone-cluster;dequeuing from batch, state QUEUED
09/19/2014 22:22:28;0100;PBS_Server;Job;42575.tyrone-cluster;enqueuing into qp64, state 1 hop 1
09/19/2014 22:22:28;0008;PBS_Server;Job;42575.tyrone-cluster;Job Queued at request of chemraja@tyrone-cluster, owner = chemraja@tyrone-cluster, job name = run, queue = qp64
09/19/2014 22:22:28;0040;PBS_Server;Svr;tyrone-cluster;Scheduler was sent the command new
09/19/2014 22:22:28;0008;PBS_Server;Job;42575.tyrone-cluster;Job Modified at request of Scheduler@tyrone-cluster
09/19/2014 22:22:39;0040;PBS_Server;Svr;tyrone-cluster;Scheduler was sent the command new
09/19/2014 22:22:40;0002;PBS_Server;Svr;PBS_Server;Torque Server Version = 3.0.5, loglevel = 0
09/19/2014 22:23:09;0040;PBS_Server;Svr;tyrone-cluster;Scheduler was sent the command new
09/19/2014 22:23:40;0040;PBS_Server;Svr;tyrone-cluster;Scheduler was sent the command new
09/19/2014 22:24:12;0040;PBS_Server;Svr;tyrone-cluster;Scheduler was sent the command new
09/19/2014 22:24:44;0040;PBS_Server;Svr;tyrone-cluster;Scheduler was sent the command new
09/19/2014 22:25:13;0040;PBS_Server;Svr;tyrone-cluster;Scheduler was sent the command new
09/19/2014 22:25:46;0040;PBS_Server;Svr;tyrone-cluster;Scheduler was sent the command new
09/19/2014 22:26:17;0040;PBS_Server;Svr;tyrone-cluster;Scheduler was sent the command new
09/19/2014 22:26:48;0040;PBS_Server;Svr;tyrone-cluster;Scheduler was sent the command new
09/19/2014 22:27:16;0040;PBS_Server;Svr;tyrone-cluster;Scheduler was sent the command new
09/19/2014 22:27:40;0002;PBS_Server;Svr;PBS_Server;Torque Server Version = 3.0.5, loglevel = 0
09/19/2014 22:27:50;0040;PBS_Server;Svr;tyrone-cluster;Scheduler was sent the command new
09/19/2014 22:28:18;0040;PBS_Server;Svr;tyrone-cluster;Scheduler was sent the command new
09/19/2014 22:28:50;0040;PBS_Server;Svr;tyrone-cluster;Scheduler was sent the command new
09/19/2014 22:29:20;0040;PBS_Server;Svr;tyrone-cluster;Scheduler was sent the command new
09/19/2014 22:29:54;0040;PBS_Server;Svr;tyrone-cluster;Scheduler was sent the command new
09/19/2014 22:30:22;0040;PBS_Server;Svr;tyrone-cluster;Scheduler was sent the command new
09/19/2014 22:30:51;0040;PBS_Server;Svr;tyrone-cluster;Scheduler was sent the command new
09/19/2014 22:31:24;0040;PBS_Server;Svr;tyrone-cluster;Scheduler was sent the command new
09/19/2014 22:31:52;0040;PBS_Server;Svr;tyrone-cluster;Scheduler was sent the command new
09/19/2014 22:32:21;0040;PBS_Server;Svr;tyrone-cluster;Scheduler was sent the command new
09/19/2014 22:32:40;0002;PBS_Server;Svr;PBS_Server;Torque Server Version = 3.0.5, loglevel = 0
09/19/2014 22:32:54;0040;PBS_Server;Svr;tyrone-cluster;Scheduler was sent the command new
09/19/2014 22:33:22;0040;PBS_Server;Svr;tyrone-cluster;Scheduler was sent the command new
09/19/2014 22:33:54;0040;PBS_Server;Svr;tyrone-cluster;Scheduler was sent the command new
09/19/2014 22:34:24;0040;PBS_Server;Svr;tyrone-cluster;Scheduler was sent the command new
09/19/2014 22:34:52;0040;PBS_Server;Svr;tyrone-cluster;Scheduler was sent the command new
09/19/2014 22:35:21;0040;PBS_Server;Svr;tyrone-cluster;Scheduler was sent the command new
09/19/2014 22:35:54;0040;PBS_Server;Svr;tyrone-cluster;Scheduler was sent the command new
09/19/2014 22:36:25;0040;PBS_Server;Svr;tyrone-cluster;Scheduler was sent the command new
09/19/2014 22:36:57;0040;PBS_Server;Svr;tyrone-cluster;Scheduler was sent the command new
09/19/2014 22:37:29;0040;PBS_Server;Svr;tyrone-cluster;Scheduler was sent the command new
09/19/2014 22:37:40;0002;PBS_Server;Svr;PBS_Server;Torque Server Version = 3.0.5, loglevel = 0
09/19/2014 22:37:58;0040;PBS_Server;Svr;tyrone-cluster;Scheduler was sent the command new
09/19/2014 22:38:31;0040;PBS_Server;Svr;tyrone-cluster;Scheduler was sent the command new
09/19/2014 22:39:02;0040;PBS_Server;Svr;tyrone-cluster;Scheduler was sent the command new
09/19/2014 22:39:33;0040;PBS_Server;Svr;tyrone-cluster;Scheduler was sent the command new
09/19/2014 22:40:01;0040;PBS_Server;Svr;tyrone-cluster;Scheduler was sent the command new
09/19/2014 22:40:35;0040;PBS_Server;Svr;tyrone-cluster;Scheduler was sent the command new
09/19/2014 22:41:04;0040;PBS_Server;Svr;tyrone-cluster;Scheduler was sent the command new
09/19/2014 22:41:35;0040;PBS_Server;Svr;tyrone-cluster;Scheduler was sent the command new
09/19/2014 22:42:05;0040;PBS_Server;Svr;tyrone-cluster;Scheduler was sent the command new
09/19/2014 22:42:35;0040;PBS_Server;Svr;tyrone-cluster;Scheduler was sent the command new
09/19/2014 22:42:40;0002;PBS_Server;Svr;PBS_Server;Torque Server Version = 3.0.5, loglevel = 0
09/19/2014 22:43:05;0040;PBS_Server;Svr;tyrone-cluster;Scheduler was sent the command new
09/19/2014 22:43:35;0040;PBS_Server;Svr;tyrone-cluster;Scheduler was sent the command new
09/19/2014 22:43:51;000d;PBS_Server;Job;42566.tyrone-cluster;Not sending email: User does not want mail of this type.
09/19/2014 22:43:51;0010;PBS_Server;Job;42566.tyrone-cluster;Exit_status=143 resources_used.cput=63:13:43 resources_used.mem=23982032kb resources_used.vmem=30212508kb resources_used.walltime=02:00:34
09/19/2014 22:43:51;0008;PBS_Server;Job;NULL;on_job_exit valid pjob: 0x2ce3630 (substate=50)
09/19/2014 22:43:51;0008;PBS_Server;Job;NULL;on_job_exit valid pjob: 0x2ce3630 (substate=51)
09/19/2014 22:43:51;0008;PBS_Server;Job;NULL;on_job_exit valid pjob: 0x2ce3630 (substate=51)
09/19/2014 22:43:51;0008;PBS_Server;Job;NULL;on_job_exit valid pjob: 0x2ce3630 (substate=53)
09/19/2014 22:43:51;0100;PBS_Server;Job;42566.tyrone-cluster;dequeuing from idqueue, state COMPLETE
09/19/2014 22:43:51;0040;PBS_Server;Svr;tyrone-cluster;Scheduler was sent the command term
09/19/2014 22:43:51;0008;PBS_Server;Job;42571.tyrone-cluster;Job Modified at request of Scheduler@tyrone-cluster
09/19/2014 22:43:51;0008;PBS_Server;Job;42571.tyrone-cluster;Job Run at request of Scheduler@tyrone-cluster
09/19/2014 22:43:51;0040;PBS_Server;Svr;tyrone-cluster;Scheduler was sent the command recyc
09/19/2014 22:43:51;000d;PBS_Server;Job;42571.tyrone-cluster;Not sending email: User does not want mail of this type.
09/19/2014 22:44:12;0040;PBS_Server;Svr;tyrone-cluster;Scheduler was sent the command new
09/19/2014 22:44:35;0040;PBS_Server;Svr;tyrone-cluster;Scheduler was sent the command new
09/19/2014 22:45:05;0040;PBS_Server;Svr;tyrone-cluster;Scheduler was sent the command new
09/19/2014 22:45:42;0040;PBS_Server;Svr;tyrone-cluster;Scheduler was sent the command new
09/19/2014 22:46:10;0040;PBS_Server;Svr;tyrone-cluster;Scheduler was sent the command new
09/19/2014 22:46:39;0040;PBS_Server;Svr;tyrone-cluster;Scheduler was sent the command new
09/19/2014 22:47:14;0040;PBS_Server;Svr;tyrone-cluster;Scheduler was sent the command new
09/19/2014 22:47:40;0002;PBS_Server;Svr;PBS_Server;Torque Server Version = 3.0.5, loglevel = 0
09/19/2014 22:47:43;0040;PBS_Server;Svr;tyrone-cluster;Scheduler was sent the command new
09/19/2014 22:48:16;0040;PBS_Server;Svr;tyrone-cluster;Scheduler was sent the command new
09/19/2014 22:48:43;0040;PBS_Server;Svr;tyrone-cluster;Scheduler was sent the command new
09/19/2014 22:49:13;0040;PBS_Server;Svr;tyrone-cluster;Scheduler was sent the command new
09/19/2014 22:49:45;0040;PBS_Server;Svr;tyrone-cluster;Scheduler was sent the command new
09/19/2014 22:50:12;0040;PBS_Server;Svr;tyrone-cluster;Scheduler was sent the command new
09/19/2014 22:50:43;0040;PBS_Server;Svr;tyrone-cluster;Scheduler was sent the command new
09/19/2014 22:51:15;0040;PBS_Server;Svr;tyrone-cluster;Scheduler was sent the command new
09/19/2014 22:51:44;0040;PBS_Server;Svr;tyrone-cluster;Scheduler was sent the command new
09/19/2014 22:52:13;0040;PBS_Server;Svr;tyrone-cluster;Scheduler was sent the command new
09/19/2014 22:52:40;0002;PBS_Server;Svr;PBS_Server;Torque Server Version = 3.0.5, loglevel = 0
09/19/2014 22:52:42;0040;PBS_Server;Svr;tyrone-cluster;Scheduler was sent the command new
09/19/2014 22:53:13;0040;PBS_Server;Svr;tyrone-cluster;Scheduler was sent the command new
09/19/2014 22:53:43;0040;PBS_Server;Svr;tyrone-cluster;Scheduler was sent the command new
09/19/2014 22:54:16;0040;PBS_Server;Svr;tyrone-cluster;Scheduler was sent the command new
09/19/2014 22:54:44;0040;PBS_Server;Svr;tyrone-cluster;Scheduler was sent the command new
09/19/2014 22:55:13;0040;PBS_Server;Svr;tyrone-cluster;Scheduler was sent the command new
09/19/2014 22:55:46;0040;PBS_Server;Svr;tyrone-cluster;Scheduler was sent the command new
09/19/2014 22:56:13;0040;PBS_Server;Svr;tyrone-cluster;Scheduler was sent the command new
09/19/2014 22:56:43;0040;PBS_Server;Svr;tyrone-cluster;Scheduler was sent the command new
09/19/2014 22:57:15;0040;PBS_Server;Svr;tyrone-cluster;Scheduler was sent the command new
09/19/2014 22:57:40;0002;PBS_Server;Svr;PBS_Server;Torque Server Version = 3.0.5, loglevel = 0
09/19/2014 22:57:42;0040;PBS_Server;Svr;tyrone-cluster;Scheduler was sent the command new
09/19/2014 22:58:13;0040;PBS_Server;Svr;tyrone-cluster;Scheduler was sent the command new
09/19/2014 22:58:46;0040;PBS_Server;Svr;tyrone-cluster;Scheduler was sent the command new
09/19/2014 22:59:13;0040;PBS_Server;Svr;tyrone-cluster;Scheduler was sent the command new
09/19/2014 22:59:43;0040;PBS_Server;Svr;tyrone-cluster;Scheduler was sent the command new
09/19/2014 23:00:12;0040;PBS_Server;Svr;tyrone-cluster;Scheduler was sent the command new
09/19/2014 23:00:43;0040;PBS_Server;Svr;tyrone-cluster;Scheduler was sent the command new
09/19/2014 23:01:13;0040;PBS_Server;Svr;tyrone-cluster;Scheduler was sent the command new
09/19/2014 23:01:46;0040;PBS_Server;Svr;tyrone-cluster;Scheduler was sent the command new
09/19/2014 23:02:20;0040;PBS_Server;Svr;tyrone-cluster;Scheduler was sent the command new
09/19/2014 23:02:40;0002;PBS_Server;Svr;PBS_Server;Torque Server Version = 3.0.5, loglevel = 0
09/19/2014 23:02:49;0040;PBS_Server;Svr;tyrone-cluster;Scheduler was sent the command new
09/19/2014 23:03:20;0040;PBS_Server;Svr;tyrone-cluster;Scheduler was sent the command new
09/19/2014 23:03:50;0040;PBS_Server;Svr;tyrone-cluster;Scheduler was sent the command new
09/19/2014 23:04:26;0040;PBS_Server;Svr;tyrone-cluster;Scheduler was sent the command new
09/19/2014 23:04:51;0040;PBS_Server;Svr;tyrone-cluster;Scheduler was sent the command new
09/19/2014 23:05:20;0040;PBS_Server;Svr;tyrone-cluster;Scheduler was sent the command new
09/19/2014 23:05:57;0040;PBS_Server;Svr;tyrone-cluster;Scheduler was sent the command new
09/19/2014 23:06:20;0040;PBS_Server;Svr;tyrone-cluster;Scheduler was sent the command new
09/19/2014 23:06:50;0040;PBS_Server;Svr;tyrone-cluster;Scheduler was sent the command new
09/19/2014 23:07:27;0040;PBS_Server;Svr;tyrone-cluster;Scheduler was sent the command new
09/19/2014 23:07:40;0002;PBS_Server;Svr;PBS_Server;Torque Server Version = 3.0.5, loglevel = 0
09/19/2014 23:07:50;0040;PBS_Server;Svr;tyrone-cluster;Scheduler was sent the command new
09/19/2014 23:08:20;0040;PBS_Server;Svr;tyrone-cluster;Scheduler was sent the command new
09/19/2014 23:08:57;0040;PBS_Server;Svr;tyrone-cluster;Scheduler was sent the command new
09/19/2014 23:09:20;0040;PBS_Server;Svr;tyrone-cluster;Scheduler was sent the command new
09/19/2014 23:09:50;0040;PBS_Server;Svr;tyrone-cluster;Scheduler was sent the command new
09/19/2014 23:10:26;0040;PBS_Server;Svr;tyrone-cluster;Scheduler was sent the command new
09/19/2014 23:10:50;0040;PBS_Server;Svr;tyrone-cluster;Scheduler was sent the command new
09/19/2014 23:11:20;0040;PBS_Server;Svr;tyrone-cluster;Scheduler was sent the command new
09/19/2014 23:11:57;0040;PBS_Server;Svr;tyrone-cluster;Scheduler was sent the command new
09/19/2014 23:12:20;0040;PBS_Server;Svr;tyrone-cluster;Scheduler was sent the command new
09/19/2014 23:12:40;0002;PBS_Server;Svr;PBS_Server;Torque Server Version = 3.0.5, loglevel = 0
09/19/2014 23:12:50;0040;PBS_Server;Svr;tyrone-cluster;Scheduler was sent the command new
09/19/2014 23:13:27;0040;PBS_Server;Svr;tyrone-cluster;Scheduler was sent the command new
09/19/2014 23:13:50;0040;PBS_Server;Svr;tyrone-cluster;Scheduler was sent the command new
09/19/2014 23:14:20;0040;PBS_Server;Svr;tyrone-cluster;Scheduler was sent the command new
09/19/2014 23:14:58;0040;PBS_Server;Svr;tyrone-cluster;Scheduler was sent the command new
09/19/2014 23:15:28;0040;PBS_Server;Svr;tyrone-cluster;Scheduler was sent the command new
09/19/2014 23:16:01;0040;PBS_Server;Svr;tyrone-cluster;Scheduler was sent the command new
09/19/2014 23:16:32;0040;PBS_Server;Svr;tyrone-cluster;Scheduler was sent the command new
09/19/2014 23:16:58;0040;PBS_Server;Svr;tyrone-cluster;Scheduler was sent the command new
09/19/2014 23:17:31;0040;PBS_Server;Svr;tyrone-cluster;Scheduler was sent the command new
09/19/2014 23:17:40;0002;PBS_Server;Svr;PBS_Server;Torque Server Version = 3.0.5, loglevel = 0
09/19/2014 23:18:05;0040;PBS_Server;Svr;tyrone-cluster;Scheduler was sent the command new
09/19/2014 23:18:33;0040;PBS_Server;Svr;tyrone-cluster;Scheduler was sent the command new
09/19/2014 23:19:05;0040;PBS_Server;Svr;tyrone-cluster;Scheduler was sent the command new
09/19/2014 23:19:35;0040;PBS_Server;Svr;tyrone-cluster;Scheduler was sent the command new
09/19/2014 23:20:04;0040;PBS_Server;Svr;tyrone-cluster;Scheduler was sent the command new
09/19/2014 23:20:35;0040;PBS_Server;Svr;tyrone-cluster;Scheduler was sent the command new
09/19/2014 23:21:05;0040;PBS_Server;Svr;tyrone-cluster;Scheduler was sent the command new
09/19/2014 23:21:43;0040;PBS_Server;Svr;tyrone-cluster;Scheduler was sent the command new
09/19/2014 23:22:13;0040;PBS_Server;Svr;tyrone-cluster;Scheduler was sent the command new
09/19/2014 23:22:40;0002;PBS_Server;Svr;PBS_Server;Torque Server Version = 3.0.5, loglevel = 0
09/19/2014 23:22:42;0040;PBS_Server;Svr;tyrone-cluster;Scheduler was sent the command new
09/19/2014 23:23:13;0040;PBS_Server;Svr;tyrone-cluster;Scheduler was sent the command new
09/19/2014 23:23:43;0040;PBS_Server;Svr;tyrone-cluster;Scheduler was sent the command new
09/19/2014 23:24:15;0040;PBS_Server;Svr;tyrone-cluster;Scheduler was sent the command new
09/19/2014 23:24:43;0040;PBS_Server;Svr;tyrone-cluster;Scheduler was sent the command new
09/19/2014 23:25:13;0040;PBS_Server;Svr;tyrone-cluster;Scheduler was sent the command new
09/19/2014 23:25:46;0040;PBS_Server;Svr;tyrone-cluster;Scheduler was sent the command new
09/19/2014 23:26:20;0040;PBS_Server;Svr;tyrone-cluster;Scheduler was sent the command new
09/19/2014 23:26:48;0040;PBS_Server;Svr;tyrone-cluster;Scheduler was sent the command new
09/19/2014 23:27:20;0040;PBS_Server;Svr;tyrone-cluster;Scheduler was sent the command new
09/19/2014 23:27:40;0002;PBS_Server;Svr;PBS_Server;Torque Server Version = 3.0.5, loglevel = 0
09/19/2014 23:27:50;0040;PBS_Server;Svr;tyrone-cluster;Scheduler was sent the command new
09/19/2014 23:28:19;0040;PBS_Server;Svr;tyrone-cluster;Scheduler was sent the command new
09/19/2014 23:28:50;0040;PBS_Server;Svr;tyrone-cluster;Scheduler was sent the command new
09/19/2014 23:29:20;0040;PBS_Server;Svr;tyrone-cluster;Scheduler was sent the command new
09/19/2014 23:29:58;0040;PBS_Server;Svr;tyrone-cluster;Scheduler was sent the command new
09/19/2014 23:30:28;0040;PBS_Server;Svr;tyrone-cluster;Scheduler was sent the command new
09/19/2014 23:31:01;0040;PBS_Server;Svr;tyrone-cluster;Scheduler was sent the command new
09/19/2014 23:31:34;0040;PBS_Server;Svr;tyrone-cluster;Scheduler was sent the command new
09/19/2014 23:32:04;0040;PBS_Server;Svr;tyrone-cluster;Scheduler was sent the command new
09/19/2014 23:32:35;0040;PBS_Server;Svr;tyrone-cluster;Scheduler was sent the command new
09/19/2014 23:32:40;0002;PBS_Server;Svr;PBS_Server;Torque Server Version = 3.0.5, loglevel = 0
09/19/2014 23:33:05;0040;PBS_Server;Svr;tyrone-cluster;Scheduler was sent the command new
09/19/2014 23:33:43;0040;PBS_Server;Svr;tyrone-cluster;Scheduler was sent the command new
09/19/2014 23:34:13;0040;PBS_Server;Svr;tyrone-cluster;Scheduler was sent the command new
09/19/2014 23:34:46;0040;PBS_Server;Svr;tyrone-cluster;Scheduler was sent the command new
09/19/2014 23:35:20;0040;PBS_Server;Svr;tyrone-cluster;Scheduler was sent the command new
09/19/2014 23:35:48;0040;PBS_Server;Svr;tyrone-cluster;Scheduler was sent the command new
09/19/2014 23:36:20;0040;PBS_Server;Svr;tyrone-cluster;Scheduler was sent the command new
09/19/2014 23:36:50;0040;PBS_Server;Svr;tyrone-cluster;Scheduler was sent the command new
09/19/2014 23:37:28;0040;PBS_Server;Svr;tyrone-cluster;Scheduler was sent the command new
09/19/2014 23:37:40;0002;PBS_Server;Svr;PBS_Server;Torque Server Version = 3.0.5, loglevel = 0
09/19/2014 23:37:58;0040;PBS_Server;Svr;tyrone-cluster;Scheduler was sent the command new
09/19/2014 23:38:31;0040;PBS_Server;Svr;tyrone-cluster;Scheduler was sent the command new
09/19/2014 23:39:05;0040;PBS_Server;Svr;tyrone-cluster;Scheduler was sent the command new
09/19/2014 23:39:33;0040;PBS_Server;Svr;tyrone-cluster;Scheduler was sent the command new
09/19/2014 23:40:05;0040;PBS_Server;Svr;tyrone-cluster;Scheduler was sent the command new
09/19/2014 23:40:35;0040;PBS_Server;Svr;tyrone-cluster;Scheduler was sent the command new
09/19/2014 23:41:13;0040;PBS_Server;Svr;tyrone-cluster;Scheduler was sent the command new
09/19/2014 23:41:43;0040;PBS_Server;Svr;tyrone-cluster;Scheduler was sent the command new
09/19/2014 23:42:16;0040;PBS_Server;Svr;tyrone-cluster;Scheduler was sent the command new
09/19/2014 23:42:40;0002;PBS_Server;Svr;PBS_Server;Torque Server Version = 3.0.5, loglevel = 0
09/19/2014 23:42:50;0040;PBS_Server;Svr;tyrone-cluster;Scheduler was sent the command new
09/19/2014 23:43:19;0040;PBS_Server;Svr;tyrone-cluster;Scheduler was sent the command new
09/19/2014 23:43:50;0040;PBS_Server;Svr;tyrone-cluster;Scheduler was sent the command new
09/19/2014 23:44:20;0040;PBS_Server;Svr;tyrone-cluster;Scheduler was sent the command new
09/19/2014 23:44:57;0040;PBS_Server;Svr;tyrone-cluster;Scheduler was sent the command new
09/19/2014 23:45:27;0040;PBS_Server;Svr;tyrone-cluster;Scheduler was sent the command new
09/19/2014 23:46:00;0040;PBS_Server;Svr;tyrone-cluster;Scheduler was sent the command new
09/19/2014 23:46:28;0040;PBS_Server;Svr;tyrone-cluster;Scheduler was sent the command new
09/19/2014 23:46:58;0040;PBS_Server;Svr;tyrone-cluster;Scheduler was sent the command new
09/19/2014 23:47:30;0040;PBS_Server;Svr;tyrone-cluster;Scheduler was sent the command new
09/19/2014 23:47:40;0002;PBS_Server;Svr;PBS_Server;Torque Server Version = 3.0.5, loglevel = 0
09/19/2014 23:48:05;0040;PBS_Server;Svr;tyrone-cluster;Scheduler was sent the command new
09/19/2014 23:48:33;0040;PBS_Server;Svr;tyrone-cluster;Scheduler was sent the command new
09/19/2014 23:49:03;0040;PBS_Server;Svr;tyrone-cluster;Scheduler was sent the command new
09/19/2014 23:49:03;000d;PBS_Server;Job;42524.tyrone-cluster;Not sending email: User does not want mail of this type.
09/19/2014 23:49:03;0010;PBS_Server;Job;42524.tyrone-cluster;Exit_status=143 resources_used.cput=1536:11:05 resources_used.mem=739848kb resources_used.vmem=53373020kb resources_used.walltime=24:00:39
09/19/2014 23:49:03;0008;PBS_Server;Job;NULL;on_job_exit valid pjob: 0x2dbc860 (substate=50)
09/19/2014 23:49:03;0008;PBS_Server;Job;NULL;on_job_exit valid pjob: 0x2dbc860 (substate=51)
09/19/2014 23:49:03;0008;PBS_Server;Job;42540.tyrone-cluster;Job Modified at request of Scheduler@tyrone-cluster
09/19/2014 23:49:03;0008;PBS_Server;Job;42553.tyrone-cluster;Job Modified at request of Scheduler@tyrone-cluster
09/19/2014 23:49:03;0008;PBS_Server;Job;42554.tyrone-cluster;Job Modified at request of Scheduler@tyrone-cluster
09/19/2014 23:49:04;0008;PBS_Server;Job;NULL;on_job_exit valid pjob: 0x2dbc860 (substate=51)
09/19/2014 23:49:04;0008;PBS_Server;Job;NULL;on_job_exit valid pjob: 0x2dbc860 (substate=53)
09/19/2014 23:49:04;0100;PBS_Server;Job;42524.tyrone-cluster;dequeuing from qp256, state COMPLETE
09/19/2014 23:49:04;0040;PBS_Server;Svr;tyrone-cluster;Scheduler was sent the command term
09/19/2014 23:49:04;0008;PBS_Server;Job;42540.tyrone-cluster;Job Modified at request of Scheduler@tyrone-cluster
09/19/2014 23:49:04;0008;PBS_Server;Job;42540.tyrone-cluster;Job Run at request of Scheduler@tyrone-cluster
09/19/2014 23:49:04;0008;PBS_Server;Job;42553.tyrone-cluster;Job Modified at request of Scheduler@tyrone-cluster
09/19/2014 23:49:04;0008;PBS_Server;Job;42554.tyrone-cluster;Job Modified at request of Scheduler@tyrone-cluster
09/19/2014 23:49:04;0040;PBS_Server;Svr;tyrone-cluster;Scheduler was sent the command recyc
09/19/2014 23:49:24;000d;PBS_Server;Job;42540.tyrone-cluster;Not sending email: User does not want mail of this type.
09/19/2014 23:49:35;0040;PBS_Server;Svr;tyrone-cluster;Scheduler was sent the command new
09/19/2014 23:50:09;0040;PBS_Server;Svr;tyrone-cluster;Scheduler was sent the command new
09/19/2014 23:50:40;0040;PBS_Server;Svr;tyrone-cluster;Scheduler was sent the command new
09/19/2014 23:51:15;0040;PBS_Server;Svr;tyrone-cluster;Scheduler was sent the command new
09/19/2014 23:51:43;0040;PBS_Server;Svr;tyrone-cluster;Scheduler was sent the command new
09/19/2014 23:52:13;0040;PBS_Server;Svr;tyrone-cluster;Scheduler was sent the command new
09/19/2014 23:52:40;0002;PBS_Server;Svr;PBS_Server;Torque Server Version = 3.0.5, loglevel = 0
09/19/2014 23:52:45;0040;PBS_Server;Svr;tyrone-cluster;Scheduler was sent the command new
09/19/2014 23:53:16;0040;PBS_Server;Svr;tyrone-cluster;Scheduler was sent the command new
09/19/2014 23:53:48;0040;PBS_Server;Svr;tyrone-cluster;Scheduler was sent the command new
09/19/2014 23:54:16;0040;PBS_Server;Svr;tyrone-cluster;Scheduler was sent the command new
09/19/2014 23:54:50;0040;PBS_Server;Svr;tyrone-cluster;Scheduler was sent the command new
09/19/2014 23:55:18;0040;PBS_Server;Svr;tyrone-cluster;Scheduler was sent the command new
09/19/2014 23:55:50;0040;PBS_Server;Svr;tyrone-cluster;Scheduler was sent the command new
09/19/2014 23:56:20;0040;PBS_Server;Svr;tyrone-cluster;Scheduler was sent the command new
09/19/2014 23:56:54;0040;PBS_Server;Svr;tyrone-cluster;Scheduler was sent the command new
09/19/2014 23:57:25;0040;PBS_Server;Svr;tyrone-cluster;Scheduler was sent the command new
09/19/2014 23:57:40;0002;PBS_Server;Svr;PBS_Server;Torque Server Version = 3.0.5, loglevel = 0
09/19/2014 23:57:59;0040;PBS_Server;Svr;tyrone-cluster;Scheduler was sent the command new
09/19/2014 23:58:28;0040;PBS_Server;Svr;tyrone-cluster;Scheduler was sent the command new
09/19/2014 23:58:58;0040;PBS_Server;Svr;tyrone-cluster;Scheduler was sent the command new
09/19/2014 23:59:31;0040;PBS_Server;Svr;tyrone-cluster;Scheduler was sent the command new
09/20/2014 00:00:01;0002;PBS_Server;Svr;Log;Log closed
