10/03/2014 00:00:16;0002;PBS_Server;Svr;Log;Log opened
10/03/2014 00:00:16;0040;PBS_Server;Svr;tyrone-cluster;Scheduler was sent the command new
10/03/2014 00:00:17;0002;PBS_Server;Svr;Act;Account file /var/spool/torque/server_priv/accounting/20141003 opened
10/03/2014 00:00:17;0008;PBS_Server;Job;43339.tyrone-cluster;Job deleted at request of asepk@tyrone-cluster
10/03/2014 00:00:17;0008;PBS_Server;Job;43339.tyrone-cluster;Job sent signal SIGTERM on delete
10/03/2014 00:00:18;000d;PBS_Server;Job;43339.tyrone-cluster;Not sending email: User does not want mail of this type.
10/03/2014 00:00:18;0010;PBS_Server;Job;43339.tyrone-cluster;Exit_status=143 resources_used.cput=00:56:54 resources_used.mem=939220kb resources_used.vmem=7369692kb resources_used.walltime=00:01:50
10/03/2014 00:00:18;0008;PBS_Server;Job;NULL;on_job_exit valid pjob: 0x2dbe110 (substate=50)
10/03/2014 00:00:18;0008;PBS_Server;Job;NULL;on_job_exit valid pjob: 0x2dbe110 (substate=51)
10/03/2014 00:00:18;0008;PBS_Server;Job;NULL;on_job_exit valid pjob: 0x2dbe110 (substate=51)
10/03/2014 00:00:18;0008;PBS_Server;Job;NULL;on_job_exit valid pjob: 0x2dbe110 (substate=53)
10/03/2014 00:00:18;0100;PBS_Server;Job;43339.tyrone-cluster;dequeuing from idqueue, state COMPLETE
10/03/2014 00:00:18;0040;PBS_Server;Svr;tyrone-cluster;Scheduler was sent the command term
10/03/2014 00:00:22;0100;PBS_Server;Job;43340.tyrone-cluster;enqueuing into batch, state 1 hop 1
10/03/2014 00:00:22;0100;PBS_Server;Job;43340.tyrone-cluster;dequeuing from batch, state QUEUED
10/03/2014 00:00:22;0100;PBS_Server;Job;43340.tyrone-cluster;enqueuing into idqueue, state 1 hop 1
10/03/2014 00:00:22;0008;PBS_Server;Job;43340.tyrone-cluster;Job Queued at request of asepk@tyrone-cluster, owner = asepk@tyrone-cluster, job name = AeDNs_4, queue = idqueue
10/03/2014 00:00:22;0040;PBS_Server;Svr;tyrone-cluster;Scheduler was sent the command new
10/03/2014 00:00:22;0008;PBS_Server;Job;43340.tyrone-cluster;Job Modified at request of Scheduler@tyrone-cluster
10/03/2014 00:00:22;0008;PBS_Server;Job;43340.tyrone-cluster;Job Run at request of Scheduler@tyrone-cluster
10/03/2014 00:00:22;0040;PBS_Server;Svr;tyrone-cluster;Scheduler was sent the command recyc
10/03/2014 00:00:22;000d;PBS_Server;Job;43340.tyrone-cluster;Not sending email: User does not want mail of this type.
10/03/2014 00:00:45;0040;PBS_Server;Svr;tyrone-cluster;Scheduler was sent the command new
10/03/2014 00:01:19;0040;PBS_Server;Svr;tyrone-cluster;Scheduler was sent the command new
10/03/2014 00:01:51;0040;PBS_Server;Svr;tyrone-cluster;Scheduler was sent the command new
10/03/2014 00:02:19;0040;PBS_Server;Svr;tyrone-cluster;Scheduler was sent the command new
10/03/2014 00:02:50;0002;PBS_Server;Svr;PBS_Server;Torque Server Version = 3.0.5, loglevel = 0
10/03/2014 00:02:50;0040;PBS_Server;Svr;tyrone-cluster;Scheduler was sent the command new
10/03/2014 00:03:22;0040;PBS_Server;Svr;tyrone-cluster;Scheduler was sent the command new
10/03/2014 00:03:57;0040;PBS_Server;Svr;tyrone-cluster;Scheduler was sent the command new
10/03/2014 00:04:30;0040;PBS_Server;Svr;tyrone-cluster;Scheduler was sent the command new
10/03/2014 00:05:04;0040;PBS_Server;Svr;tyrone-cluster;Scheduler was sent the command new
10/03/2014 00:05:36;0040;PBS_Server;Svr;tyrone-cluster;Scheduler was sent the command new
10/03/2014 00:06:12;0040;PBS_Server;Svr;tyrone-cluster;Scheduler was sent the command new
10/03/2014 00:06:45;0040;PBS_Server;Svr;tyrone-cluster;Scheduler was sent the command new
10/03/2014 00:07:19;0040;PBS_Server;Svr;tyrone-cluster;Scheduler was sent the command new
10/03/2014 00:07:50;0002;PBS_Server;Svr;PBS_Server;Torque Server Version = 3.0.5, loglevel = 0
10/03/2014 00:07:50;0040;PBS_Server;Svr;tyrone-cluster;Scheduler was sent the command new
10/03/2014 00:08:19;0040;PBS_Server;Svr;tyrone-cluster;Scheduler was sent the command new
10/03/2014 00:08:50;0040;PBS_Server;Svr;tyrone-cluster;Scheduler was sent the command new
10/03/2014 00:09:22;0040;PBS_Server;Svr;tyrone-cluster;Scheduler was sent the command new
10/03/2014 00:09:57;0040;PBS_Server;Svr;tyrone-cluster;Scheduler was sent the command new
10/03/2014 00:10:30;0040;PBS_Server;Svr;tyrone-cluster;Scheduler was sent the command new
10/03/2014 00:11:04;0040;PBS_Server;Svr;tyrone-cluster;Scheduler was sent the command new
10/03/2014 00:11:36;0040;PBS_Server;Svr;tyrone-cluster;Scheduler was sent the command new
10/03/2014 00:12:03;0040;PBS_Server;Svr;tyrone-cluster;Scheduler was sent the command new
10/03/2014 00:12:34;0040;PBS_Server;Svr;tyrone-cluster;Scheduler was sent the command new
10/03/2014 00:12:50;0002;PBS_Server;Svr;PBS_Server;Torque Server Version = 3.0.5, loglevel = 0
10/03/2014 00:13:06;0040;PBS_Server;Svr;tyrone-cluster;Scheduler was sent the command new
10/03/2014 00:13:34;0040;PBS_Server;Svr;tyrone-cluster;Scheduler was sent the command new
10/03/2014 00:14:05;0040;PBS_Server;Svr;tyrone-cluster;Scheduler was sent the command new
10/03/2014 00:14:36;0040;PBS_Server;Svr;tyrone-cluster;Scheduler was sent the command new
10/03/2014 00:15:12;0040;PBS_Server;Svr;tyrone-cluster;Scheduler was sent the command new
10/03/2014 00:15:45;0040;PBS_Server;Svr;tyrone-cluster;Scheduler was sent the command new
10/03/2014 00:16:19;0040;PBS_Server;Svr;tyrone-cluster;Scheduler was sent the command new
10/03/2014 00:16:52;0040;PBS_Server;Svr;tyrone-cluster;Scheduler was sent the command new
10/03/2014 00:17:27;0040;PBS_Server;Svr;tyrone-cluster;Scheduler was sent the command new
10/03/2014 00:17:50;0002;PBS_Server;Svr;PBS_Server;Torque Server Version = 3.0.5, loglevel = 0
10/03/2014 00:18:00;0040;PBS_Server;Svr;tyrone-cluster;Scheduler was sent the command new
10/03/2014 00:18:34;0040;PBS_Server;Svr;tyrone-cluster;Scheduler was sent the command new
10/03/2014 00:19:06;0040;PBS_Server;Svr;tyrone-cluster;Scheduler was sent the command new
10/03/2014 00:19:42;0040;PBS_Server;Svr;tyrone-cluster;Scheduler was sent the command new
10/03/2014 00:20:15;0040;PBS_Server;Svr;tyrone-cluster;Scheduler was sent the command new
10/03/2014 00:20:49;0040;PBS_Server;Svr;tyrone-cluster;Scheduler was sent the command new
10/03/2014 00:21:21;0040;PBS_Server;Svr;tyrone-cluster;Scheduler was sent the command new
10/03/2014 00:21:57;0040;PBS_Server;Svr;tyrone-cluster;Scheduler was sent the command new
10/03/2014 00:22:30;0040;PBS_Server;Svr;tyrone-cluster;Scheduler was sent the command new
10/03/2014 00:22:50;0002;PBS_Server;Svr;PBS_Server;Torque Server Version = 3.0.5, loglevel = 0
10/03/2014 00:23:05;0040;PBS_Server;Svr;tyrone-cluster;Scheduler was sent the command new
10/03/2014 00:23:37;0040;PBS_Server;Svr;tyrone-cluster;Scheduler was sent the command new
10/03/2014 00:24:12;0040;PBS_Server;Svr;tyrone-cluster;Scheduler was sent the command new
10/03/2014 00:24:45;0040;PBS_Server;Svr;tyrone-cluster;Scheduler was sent the command new
10/03/2014 00:25:19;0040;PBS_Server;Svr;tyrone-cluster;Scheduler was sent the command new
10/03/2014 00:25:51;0040;PBS_Server;Svr;tyrone-cluster;Scheduler was sent the command new
10/03/2014 00:26:27;0040;PBS_Server;Svr;tyrone-cluster;Scheduler was sent the command new
10/03/2014 00:27:00;0040;PBS_Server;Svr;tyrone-cluster;Scheduler was sent the command new
10/03/2014 00:27:34;0040;PBS_Server;Svr;tyrone-cluster;Scheduler was sent the command new
10/03/2014 00:27:50;0002;PBS_Server;Svr;PBS_Server;Torque Server Version = 3.0.5, loglevel = 0
10/03/2014 00:28:06;0040;PBS_Server;Svr;tyrone-cluster;Scheduler was sent the command new
10/03/2014 00:28:42;0040;PBS_Server;Svr;tyrone-cluster;Scheduler was sent the command new
10/03/2014 00:29:15;0040;PBS_Server;Svr;tyrone-cluster;Scheduler was sent the command new
10/03/2014 00:29:49;0040;PBS_Server;Svr;tyrone-cluster;Scheduler was sent the command new
10/03/2014 00:30:21;0040;PBS_Server;Svr;tyrone-cluster;Scheduler was sent the command new
10/03/2014 00:30:48;0040;PBS_Server;Svr;tyrone-cluster;Scheduler was sent the command new
10/03/2014 00:31:19;0040;PBS_Server;Svr;tyrone-cluster;Scheduler was sent the command new
10/03/2014 00:31:51;0040;PBS_Server;Svr;tyrone-cluster;Scheduler was sent the command new
10/03/2014 00:32:27;0040;PBS_Server;Svr;tyrone-cluster;Scheduler was sent the command new
10/03/2014 00:32:50;0002;PBS_Server;Svr;PBS_Server;Torque Server Version = 3.0.5, loglevel = 0
10/03/2014 00:33:00;0040;PBS_Server;Svr;tyrone-cluster;Scheduler was sent the command new
10/03/2014 00:33:34;0040;PBS_Server;Svr;tyrone-cluster;Scheduler was sent the command new
10/03/2014 00:34:06;0040;PBS_Server;Svr;tyrone-cluster;Scheduler was sent the command new
10/03/2014 00:34:42;0040;PBS_Server;Svr;tyrone-cluster;Scheduler was sent the command new
10/03/2014 00:35:15;0040;PBS_Server;Svr;tyrone-cluster;Scheduler was sent the command new
10/03/2014 00:35:49;0040;PBS_Server;Svr;tyrone-cluster;Scheduler was sent the command new
10/03/2014 00:36:21;0040;PBS_Server;Svr;tyrone-cluster;Scheduler was sent the command new
10/03/2014 00:36:57;0040;PBS_Server;Svr;tyrone-cluster;Scheduler was sent the command new
10/03/2014 00:37:30;0040;PBS_Server;Svr;tyrone-cluster;Scheduler was sent the command new
10/03/2014 00:37:50;0002;PBS_Server;Svr;PBS_Server;Torque Server Version = 3.0.5, loglevel = 0
10/03/2014 00:38:04;0040;PBS_Server;Svr;tyrone-cluster;Scheduler was sent the command new
10/03/2014 00:38:36;0040;PBS_Server;Svr;tyrone-cluster;Scheduler was sent the command new
10/03/2014 00:39:12;0040;PBS_Server;Svr;tyrone-cluster;Scheduler was sent the command new
10/03/2014 00:39:45;0040;PBS_Server;Svr;tyrone-cluster;Scheduler was sent the command new
10/03/2014 00:40:19;0040;PBS_Server;Svr;tyrone-cluster;Scheduler was sent the command new
10/03/2014 00:40:52;0040;PBS_Server;Svr;tyrone-cluster;Scheduler was sent the command new
10/03/2014 00:41:27;0040;PBS_Server;Svr;tyrone-cluster;Scheduler was sent the command new
10/03/2014 00:42:00;0040;PBS_Server;Svr;tyrone-cluster;Scheduler was sent the command new
10/03/2014 00:42:34;0040;PBS_Server;Svr;tyrone-cluster;Scheduler was sent the command new
10/03/2014 00:42:50;0002;PBS_Server;Svr;PBS_Server;Torque Server Version = 3.0.5, loglevel = 0
10/03/2014 00:43:06;0040;PBS_Server;Svr;tyrone-cluster;Scheduler was sent the command new
10/03/2014 00:43:42;0040;PBS_Server;Svr;tyrone-cluster;Scheduler was sent the command new
10/03/2014 00:44:15;0040;PBS_Server;Svr;tyrone-cluster;Scheduler was sent the command new
10/03/2014 00:44:45;0040;PBS_Server;Svr;tyrone-cluster;Scheduler was sent the command new
10/03/2014 00:44:45;0100;PBS_Server;Job;43341.tyrone-cluster;enqueuing into batch, state 1 hop 1
10/03/2014 00:44:45;0100;PBS_Server;Job;43341.tyrone-cluster;dequeuing from batch, state QUEUED
10/03/2014 00:44:45;0100;PBS_Server;Job;43341.tyrone-cluster;enqueuing into idqueue, state 1 hop 1
10/03/2014 00:44:45;0008;PBS_Server;Job;43341.tyrone-cluster;Job Queued at request of asepk@tyrone-cluster, owner = asepk@tyrone-cluster, job name = AeDNs_4, queue = idqueue
10/03/2014 00:44:45;0008;PBS_Server;Job;43341.tyrone-cluster;Job Modified at request of Scheduler@tyrone-cluster
10/03/2014 00:44:58;0008;PBS_Server;Job;43340.tyrone-cluster;Job deleted at request of asepk@tyrone-cluster
10/03/2014 00:44:58;0008;PBS_Server;Job;43340.tyrone-cluster;Job sent signal SIGTERM on delete
10/03/2014 00:44:58;000d;PBS_Server;Job;43340.tyrone-cluster;Not sending email: User does not want mail of this type.
10/03/2014 00:44:58;0010;PBS_Server;Job;43340.tyrone-cluster;Exit_status=143 resources_used.cput=23:29:04 resources_used.mem=975596kb resources_used.vmem=7374548kb resources_used.walltime=00:44:36
10/03/2014 00:44:58;0008;PBS_Server;Job;NULL;on_job_exit valid pjob: 0x2dbe110 (substate=50)
10/03/2014 00:44:58;0008;PBS_Server;Job;NULL;on_job_exit valid pjob: 0x2dbe110 (substate=51)
10/03/2014 00:44:58;0008;PBS_Server;Job;NULL;on_job_exit valid pjob: 0x2dbe110 (substate=51)
10/03/2014 00:44:58;0008;PBS_Server;Job;NULL;on_job_exit valid pjob: 0x2dbe110 (substate=53)
10/03/2014 00:44:58;0100;PBS_Server;Job;43340.tyrone-cluster;dequeuing from idqueue, state COMPLETE
10/03/2014 00:44:58;0040;PBS_Server;Svr;tyrone-cluster;Scheduler was sent the command term
10/03/2014 00:44:58;0008;PBS_Server;Job;43341.tyrone-cluster;Job Modified at request of Scheduler@tyrone-cluster
10/03/2014 00:44:58;0008;PBS_Server;Job;43341.tyrone-cluster;Job Run at request of Scheduler@tyrone-cluster
10/03/2014 00:44:58;0040;PBS_Server;Svr;tyrone-cluster;Scheduler was sent the command recyc
10/03/2014 00:44:58;000d;PBS_Server;Job;43341.tyrone-cluster;Not sending email: User does not want mail of this type.
10/03/2014 00:45:16;0040;PBS_Server;Svr;tyrone-cluster;Scheduler was sent the command new
10/03/2014 00:45:47;0040;PBS_Server;Svr;tyrone-cluster;Scheduler was sent the command new
10/03/2014 00:46:19;0040;PBS_Server;Svr;tyrone-cluster;Scheduler was sent the command new
10/03/2014 00:46:51;0040;PBS_Server;Svr;tyrone-cluster;Scheduler was sent the command new
10/03/2014 00:47:27;0040;PBS_Server;Svr;tyrone-cluster;Scheduler was sent the command new
10/03/2014 00:47:50;0002;PBS_Server;Svr;PBS_Server;Torque Server Version = 3.0.5, loglevel = 0
10/03/2014 00:48:02;0040;PBS_Server;Svr;tyrone-cluster;Scheduler was sent the command new
10/03/2014 00:48:34;0040;PBS_Server;Svr;tyrone-cluster;Scheduler was sent the command new
10/03/2014 00:49:06;0040;PBS_Server;Svr;tyrone-cluster;Scheduler was sent the command new
10/03/2014 00:49:42;0040;PBS_Server;Svr;tyrone-cluster;Scheduler was sent the command new
10/03/2014 00:50:17;0040;PBS_Server;Svr;tyrone-cluster;Scheduler was sent the command new
10/03/2014 00:50:49;0040;PBS_Server;Svr;tyrone-cluster;Scheduler was sent the command new
10/03/2014 00:51:21;0040;PBS_Server;Svr;tyrone-cluster;Scheduler was sent the command new
10/03/2014 00:51:57;0040;PBS_Server;Svr;tyrone-cluster;Scheduler was sent the command new
10/03/2014 00:52:32;0040;PBS_Server;Svr;tyrone-cluster;Scheduler was sent the command new
10/03/2014 00:52:50;0002;PBS_Server;Svr;PBS_Server;Torque Server Version = 3.0.5, loglevel = 0
10/03/2014 00:53:04;0040;PBS_Server;Svr;tyrone-cluster;Scheduler was sent the command new
10/03/2014 00:53:36;0040;PBS_Server;Svr;tyrone-cluster;Scheduler was sent the command new
10/03/2014 00:54:12;0040;PBS_Server;Svr;tyrone-cluster;Scheduler was sent the command new
10/03/2014 00:54:47;0040;PBS_Server;Svr;tyrone-cluster;Scheduler was sent the command new
10/03/2014 00:55:19;0040;PBS_Server;Svr;tyrone-cluster;Scheduler was sent the command new
10/03/2014 00:55:51;0040;PBS_Server;Svr;tyrone-cluster;Scheduler was sent the command new
10/03/2014 00:56:27;0040;PBS_Server;Svr;tyrone-cluster;Scheduler was sent the command new
10/03/2014 00:57:02;0040;PBS_Server;Svr;tyrone-cluster;Scheduler was sent the command new
10/03/2014 00:57:34;0040;PBS_Server;Svr;tyrone-cluster;Scheduler was sent the command new
10/03/2014 00:57:50;0002;PBS_Server;Svr;PBS_Server;Torque Server Version = 3.0.5, loglevel = 0
10/03/2014 00:58:06;0040;PBS_Server;Svr;tyrone-cluster;Scheduler was sent the command new
10/03/2014 00:58:37;0040;PBS_Server;Svr;tyrone-cluster;Scheduler was sent the command new
10/03/2014 00:58:37;0100;PBS_Server;Job;43342.tyrone-cluster;enqueuing into batch, state 1 hop 1
10/03/2014 00:58:37;0100;PBS_Server;Job;43342.tyrone-cluster;dequeuing from batch, state QUEUED
10/03/2014 00:58:37;0100;PBS_Server;Job;43342.tyrone-cluster;enqueuing into idqueue, state 1 hop 1
10/03/2014 00:58:37;0008;PBS_Server;Job;43342.tyrone-cluster;Job Queued at request of asepk@tyrone-cluster, owner = asepk@tyrone-cluster, job name = AeDNs_4, queue = idqueue
10/03/2014 00:58:37;0008;PBS_Server;Job;43342.tyrone-cluster;Job Modified at request of Scheduler@tyrone-cluster
10/03/2014 00:58:46;0008;PBS_Server;Job;43341.tyrone-cluster;Job deleted at request of asepk@tyrone-cluster
10/03/2014 00:58:46;0008;PBS_Server;Job;43341.tyrone-cluster;Job sent signal SIGTERM on delete
10/03/2014 00:58:47;000d;PBS_Server;Job;43341.tyrone-cluster;Not sending email: User does not want mail of this type.
10/03/2014 00:58:47;0010;PBS_Server;Job;43341.tyrone-cluster;Exit_status=143 resources_used.cput=07:15:06 resources_used.mem=974944kb resources_used.vmem=7377264kb resources_used.walltime=00:13:49
10/03/2014 00:58:47;0008;PBS_Server;Job;NULL;on_job_exit valid pjob: 0x2e9af40 (substate=50)
10/03/2014 00:58:47;0008;PBS_Server;Job;NULL;on_job_exit valid pjob: 0x2e9af40 (substate=51)
10/03/2014 00:58:47;0008;PBS_Server;Job;NULL;on_job_exit valid pjob: 0x2e9af40 (substate=51)
10/03/2014 00:58:47;0008;PBS_Server;Job;NULL;on_job_exit valid pjob: 0x2e9af40 (substate=53)
10/03/2014 00:58:47;0100;PBS_Server;Job;43341.tyrone-cluster;dequeuing from idqueue, state COMPLETE
10/03/2014 00:58:47;0040;PBS_Server;Svr;tyrone-cluster;Scheduler was sent the command term
10/03/2014 00:58:47;0008;PBS_Server;Job;43342.tyrone-cluster;Job Modified at request of Scheduler@tyrone-cluster
10/03/2014 00:58:47;0008;PBS_Server;Job;43342.tyrone-cluster;Job Run at request of Scheduler@tyrone-cluster
10/03/2014 00:58:47;0040;PBS_Server;Svr;tyrone-cluster;Scheduler was sent the command recyc
10/03/2014 00:58:47;000d;PBS_Server;Job;43342.tyrone-cluster;Not sending email: User does not want mail of this type.
10/03/2014 00:59:08;0040;PBS_Server;Svr;tyrone-cluster;Scheduler was sent the command new
10/03/2014 00:59:40;0040;PBS_Server;Svr;tyrone-cluster;Scheduler was sent the command new
10/03/2014 01:00:03;0008;PBS_Server;Job;43342.tyrone-cluster;Job deleted at request of asepk@tyrone-cluster
10/03/2014 01:00:03;0008;PBS_Server;Job;43342.tyrone-cluster;Job sent signal SIGTERM on delete
10/03/2014 01:00:03;000d;PBS_Server;Job;43342.tyrone-cluster;Not sending email: User does not want mail of this type.
10/03/2014 01:00:03;0010;PBS_Server;Job;43342.tyrone-cluster;Exit_status=143 resources_used.cput=00:39:29 resources_used.mem=929528kb resources_used.vmem=7370076kb resources_used.walltime=00:01:16
10/03/2014 01:00:03;0008;PBS_Server;Job;NULL;on_job_exit valid pjob: 0x2ce05b0 (substate=50)
10/03/2014 01:00:03;0008;PBS_Server;Job;NULL;on_job_exit valid pjob: 0x2ce05b0 (substate=51)
10/03/2014 01:00:03;0008;PBS_Server;Job;NULL;on_job_exit valid pjob: 0x2ce05b0 (substate=51)
10/03/2014 01:00:03;0008;PBS_Server;Job;NULL;on_job_exit valid pjob: 0x2ce05b0 (substate=53)
10/03/2014 01:00:03;0100;PBS_Server;Job;43342.tyrone-cluster;dequeuing from idqueue, state COMPLETE
10/03/2014 01:00:03;0040;PBS_Server;Svr;tyrone-cluster;Scheduler was sent the command term
10/03/2014 01:00:12;0040;PBS_Server;Svr;tyrone-cluster;Scheduler was sent the command new
10/03/2014 01:00:48;0040;PBS_Server;Svr;tyrone-cluster;Scheduler was sent the command new
10/03/2014 01:01:19;0040;PBS_Server;Svr;tyrone-cluster;Scheduler was sent the command new
10/03/2014 01:01:51;0040;PBS_Server;Svr;tyrone-cluster;Scheduler was sent the command new
10/03/2014 01:02:27;0040;PBS_Server;Svr;tyrone-cluster;Scheduler was sent the command new
10/03/2014 01:02:50;0002;PBS_Server;Svr;PBS_Server;Torque Server Version = 3.0.5, loglevel = 0
10/03/2014 01:03:03;0040;PBS_Server;Svr;tyrone-cluster;Scheduler was sent the command new
10/03/2014 01:03:34;0040;PBS_Server;Svr;tyrone-cluster;Scheduler was sent the command new
10/03/2014 01:04:06;0040;PBS_Server;Svr;tyrone-cluster;Scheduler was sent the command new
10/03/2014 01:04:42;0040;PBS_Server;Svr;tyrone-cluster;Scheduler was sent the command new
10/03/2014 01:05:17;0040;PBS_Server;Svr;tyrone-cluster;Scheduler was sent the command new
10/03/2014 01:05:50;0040;PBS_Server;Svr;tyrone-cluster;Scheduler was sent the command new
10/03/2014 01:06:21;0040;PBS_Server;Svr;tyrone-cluster;Scheduler was sent the command new
10/03/2014 01:06:57;0040;PBS_Server;Svr;tyrone-cluster;Scheduler was sent the command new
10/03/2014 01:07:33;0040;PBS_Server;Svr;tyrone-cluster;Scheduler was sent the command new
10/03/2014 01:07:50;0002;PBS_Server;Svr;PBS_Server;Torque Server Version = 3.0.5, loglevel = 0
10/03/2014 01:08:04;0040;PBS_Server;Svr;tyrone-cluster;Scheduler was sent the command new
10/03/2014 01:08:36;0040;PBS_Server;Svr;tyrone-cluster;Scheduler was sent the command new
10/03/2014 01:09:12;0040;PBS_Server;Svr;tyrone-cluster;Scheduler was sent the command new
10/03/2014 01:09:47;0040;PBS_Server;Svr;tyrone-cluster;Scheduler was sent the command new
10/03/2014 01:10:20;0040;PBS_Server;Svr;tyrone-cluster;Scheduler was sent the command new
10/03/2014 01:10:51;0040;PBS_Server;Svr;tyrone-cluster;Scheduler was sent the command new
10/03/2014 01:11:27;0040;PBS_Server;Svr;tyrone-cluster;Scheduler was sent the command new
10/03/2014 01:12:03;0040;PBS_Server;Svr;tyrone-cluster;Scheduler was sent the command new
10/03/2014 01:12:34;0040;PBS_Server;Svr;tyrone-cluster;Scheduler was sent the command new
10/03/2014 01:12:50;0002;PBS_Server;Svr;PBS_Server;Torque Server Version = 3.0.5, loglevel = 0
10/03/2014 01:13:06;0040;PBS_Server;Svr;tyrone-cluster;Scheduler was sent the command new
10/03/2014 01:13:42;0040;PBS_Server;Svr;tyrone-cluster;Scheduler was sent the command new
10/03/2014 01:14:17;0040;PBS_Server;Svr;tyrone-cluster;Scheduler was sent the command new
10/03/2014 01:14:49;0040;PBS_Server;Svr;tyrone-cluster;Scheduler was sent the command new
10/03/2014 01:15:21;0040;PBS_Server;Svr;tyrone-cluster;Scheduler was sent the command new
10/03/2014 01:15:57;0040;PBS_Server;Svr;tyrone-cluster;Scheduler was sent the command new
10/03/2014 01:16:33;0040;PBS_Server;Svr;tyrone-cluster;Scheduler was sent the command new
10/03/2014 01:17:04;0040;PBS_Server;Svr;tyrone-cluster;Scheduler was sent the command new
10/03/2014 01:17:35;0040;PBS_Server;Svr;tyrone-cluster;Scheduler was sent the command new
10/03/2014 01:17:50;0002;PBS_Server;Svr;PBS_Server;Torque Server Version = 3.0.5, loglevel = 0
10/03/2014 01:18:12;0040;PBS_Server;Svr;tyrone-cluster;Scheduler was sent the command new
10/03/2014 01:18:38;0040;PBS_Server;Svr;tyrone-cluster;Scheduler was sent the command new
10/03/2014 01:19:10;0040;PBS_Server;Svr;tyrone-cluster;Scheduler was sent the command new
10/03/2014 01:19:42;0040;PBS_Server;Svr;tyrone-cluster;Scheduler was sent the command new
10/03/2014 01:20:18;0040;PBS_Server;Svr;tyrone-cluster;Scheduler was sent the command new
10/03/2014 01:20:42;0040;PBS_Server;Svr;tyrone-cluster;Scheduler was sent the command new
10/03/2014 01:21:12;0040;PBS_Server;Svr;tyrone-cluster;Scheduler was sent the command new
10/03/2014 01:21:47;0040;PBS_Server;Svr;tyrone-cluster;Scheduler was sent the command new
10/03/2014 01:22:19;0040;PBS_Server;Svr;tyrone-cluster;Scheduler was sent the command new
10/03/2014 01:22:28;0100;PBS_Server;Job;43343.tyrone-cluster;enqueuing into batch, state 1 hop 1
10/03/2014 01:22:28;0100;PBS_Server;Job;43343.tyrone-cluster;dequeuing from batch, state QUEUED
10/03/2014 01:22:28;0100;PBS_Server;Job;43343.tyrone-cluster;enqueuing into idqueue, state 1 hop 1
10/03/2014 01:22:28;0008;PBS_Server;Job;43343.tyrone-cluster;Job Queued at request of asepk@tyrone-cluster, owner = asepk@tyrone-cluster, job name = AeDNs_4, queue = idqueue
10/03/2014 01:22:28;0040;PBS_Server;Svr;tyrone-cluster;Scheduler was sent the command new
10/03/2014 01:22:28;0008;PBS_Server;Job;43343.tyrone-cluster;Job Modified at request of Scheduler@tyrone-cluster
10/03/2014 01:22:28;0008;PBS_Server;Job;43343.tyrone-cluster;Job Run at request of Scheduler@tyrone-cluster
10/03/2014 01:22:28;0040;PBS_Server;Svr;tyrone-cluster;Scheduler was sent the command recyc
10/03/2014 01:22:28;000d;PBS_Server;Job;43343.tyrone-cluster;Not sending email: User does not want mail of this type.
10/03/2014 01:22:50;0002;PBS_Server;Svr;PBS_Server;Torque Server Version = 3.0.5, loglevel = 0
10/03/2014 01:22:51;0040;PBS_Server;Svr;tyrone-cluster;Scheduler was sent the command new
10/03/2014 01:22:58;0008;PBS_Server;Job;43343.tyrone-cluster;Job deleted at request of asepk@tyrone-cluster
10/03/2014 01:22:58;0008;PBS_Server;Job;43343.tyrone-cluster;Job sent signal SIGTERM on delete
10/03/2014 01:22:58;000d;PBS_Server;Job;43343.tyrone-cluster;Not sending email: User does not want mail of this type.
10/03/2014 01:22:58;0010;PBS_Server;Job;43343.tyrone-cluster;Exit_status=143 resources_used.cput=00:15:35 resources_used.mem=3260kb resources_used.vmem=94264kb resources_used.walltime=00:00:30
10/03/2014 01:22:58;0008;PBS_Server;Job;NULL;on_job_exit valid pjob: 0x2e9af40 (substate=50)
10/03/2014 01:22:58;0008;PBS_Server;Job;NULL;on_job_exit valid pjob: 0x2e9af40 (substate=51)
10/03/2014 01:22:58;0008;PBS_Server;Job;NULL;on_job_exit valid pjob: 0x2e9af40 (substate=51)
10/03/2014 01:22:58;0008;PBS_Server;Job;NULL;on_job_exit valid pjob: 0x2e9af40 (substate=53)
10/03/2014 01:22:58;0100;PBS_Server;Job;43343.tyrone-cluster;dequeuing from idqueue, state COMPLETE
10/03/2014 01:22:58;0040;PBS_Server;Svr;tyrone-cluster;Scheduler was sent the command term
10/03/2014 01:23:27;0040;PBS_Server;Svr;tyrone-cluster;Scheduler was sent the command new
10/03/2014 01:24:02;0040;PBS_Server;Svr;tyrone-cluster;Scheduler was sent the command new
10/03/2014 01:24:34;0040;PBS_Server;Svr;tyrone-cluster;Scheduler was sent the command new
10/03/2014 01:25:06;0040;PBS_Server;Svr;tyrone-cluster;Scheduler was sent the command new
10/03/2014 01:25:42;0040;PBS_Server;Svr;tyrone-cluster;Scheduler was sent the command new
10/03/2014 01:26:09;0040;PBS_Server;Svr;tyrone-cluster;Scheduler was sent the command new
10/03/2014 01:26:40;0040;PBS_Server;Svr;tyrone-cluster;Scheduler was sent the command new
10/03/2014 01:27:12;0040;PBS_Server;Svr;tyrone-cluster;Scheduler was sent the command new
10/03/2014 01:27:47;0040;PBS_Server;Svr;tyrone-cluster;Scheduler was sent the command new
10/03/2014 01:27:50;0002;PBS_Server;Svr;PBS_Server;Torque Server Version = 3.0.5, loglevel = 0
10/03/2014 01:28:19;0040;PBS_Server;Svr;tyrone-cluster;Scheduler was sent the command new
10/03/2014 01:28:50;0040;PBS_Server;Svr;tyrone-cluster;Scheduler was sent the command new
10/03/2014 01:29:27;0040;PBS_Server;Svr;tyrone-cluster;Scheduler was sent the command new
10/03/2014 01:30:03;0040;PBS_Server;Svr;tyrone-cluster;Scheduler was sent the command new
10/03/2014 01:30:34;0040;PBS_Server;Svr;tyrone-cluster;Scheduler was sent the command new
10/03/2014 01:31:05;0040;PBS_Server;Svr;tyrone-cluster;Scheduler was sent the command new
10/03/2014 01:31:42;0040;PBS_Server;Svr;tyrone-cluster;Scheduler was sent the command new
10/03/2014 01:32:17;0040;PBS_Server;Svr;tyrone-cluster;Scheduler was sent the command new
10/03/2014 01:32:49;0040;PBS_Server;Svr;tyrone-cluster;Scheduler was sent the command new
10/03/2014 01:32:50;0002;PBS_Server;Svr;PBS_Server;Torque Server Version = 3.0.5, loglevel = 0
10/03/2014 01:33:21;0040;PBS_Server;Svr;tyrone-cluster;Scheduler was sent the command new
10/03/2014 01:33:57;0040;PBS_Server;Svr;tyrone-cluster;Scheduler was sent the command new
10/03/2014 01:34:32;0040;PBS_Server;Svr;tyrone-cluster;Scheduler was sent the command new
10/03/2014 01:35:04;0040;PBS_Server;Svr;tyrone-cluster;Scheduler was sent the command new
10/03/2014 01:35:35;0040;PBS_Server;Svr;tyrone-cluster;Scheduler was sent the command new
10/03/2014 01:36:12;0040;PBS_Server;Svr;tyrone-cluster;Scheduler was sent the command new
10/03/2014 01:36:47;0040;PBS_Server;Svr;tyrone-cluster;Scheduler was sent the command new
10/03/2014 01:37:19;0040;PBS_Server;Svr;tyrone-cluster;Scheduler was sent the command new
10/03/2014 01:37:50;0002;PBS_Server;Svr;PBS_Server;Torque Server Version = 3.0.5, loglevel = 0
10/03/2014 01:37:50;0040;PBS_Server;Svr;tyrone-cluster;Scheduler was sent the command new
10/03/2014 01:38:27;0040;PBS_Server;Svr;tyrone-cluster;Scheduler was sent the command new
10/03/2014 01:39:02;0040;PBS_Server;Svr;tyrone-cluster;Scheduler was sent the command new
10/03/2014 01:39:34;0040;PBS_Server;Svr;tyrone-cluster;Scheduler was sent the command new
10/03/2014 01:40:05;0040;PBS_Server;Svr;tyrone-cluster;Scheduler was sent the command new
10/03/2014 01:40:36;0040;PBS_Server;Svr;tyrone-cluster;Scheduler was sent the command new
10/03/2014 01:41:05;0040;PBS_Server;Svr;tyrone-cluster;Scheduler was sent the command new
10/03/2014 01:41:35;0040;PBS_Server;Svr;tyrone-cluster;Scheduler was sent the command new
10/03/2014 01:42:12;0040;PBS_Server;Svr;tyrone-cluster;Scheduler was sent the command new
10/03/2014 01:42:47;0040;PBS_Server;Svr;tyrone-cluster;Scheduler was sent the command new
10/03/2014 01:42:50;0002;PBS_Server;Svr;PBS_Server;Torque Server Version = 3.0.5, loglevel = 0
10/03/2014 01:43:19;0040;PBS_Server;Svr;tyrone-cluster;Scheduler was sent the command new
10/03/2014 01:43:22;0100;PBS_Server;Job;43344.tyrone-cluster;enqueuing into batch, state 1 hop 1
10/03/2014 01:43:22;0100;PBS_Server;Job;43344.tyrone-cluster;dequeuing from batch, state QUEUED
10/03/2014 01:43:22;0100;PBS_Server;Job;43344.tyrone-cluster;enqueuing into idqueue, state 1 hop 1
10/03/2014 01:43:22;0008;PBS_Server;Job;43344.tyrone-cluster;Job Queued at request of asepk@tyrone-cluster, owner = asepk@tyrone-cluster, job name = AeDNs_4, queue = idqueue
10/03/2014 01:43:22;0040;PBS_Server;Svr;tyrone-cluster;Scheduler was sent the command new
10/03/2014 01:43:22;0008;PBS_Server;Job;43344.tyrone-cluster;Job Modified at request of Scheduler@tyrone-cluster
10/03/2014 01:43:22;0008;PBS_Server;Job;43344.tyrone-cluster;Job Run at request of Scheduler@tyrone-cluster
10/03/2014 01:43:22;0040;PBS_Server;Svr;tyrone-cluster;Scheduler was sent the command recyc
10/03/2014 01:43:22;000d;PBS_Server;Job;43344.tyrone-cluster;Not sending email: User does not want mail of this type.
10/03/2014 01:43:50;0040;PBS_Server;Svr;tyrone-cluster;Scheduler was sent the command new
10/03/2014 01:44:23;0040;PBS_Server;Svr;tyrone-cluster;Scheduler was sent the command new
10/03/2014 01:44:56;0040;PBS_Server;Svr;tyrone-cluster;Scheduler was sent the command new
10/03/2014 01:45:25;0040;PBS_Server;Svr;tyrone-cluster;Scheduler was sent the command new
10/03/2014 01:45:27;0008;PBS_Server;Job;43344.tyrone-cluster;Job deleted at request of asepk@tyrone-cluster
10/03/2014 01:45:27;0008;PBS_Server;Job;43344.tyrone-cluster;Job sent signal SIGTERM on delete
10/03/2014 01:45:28;000d;PBS_Server;Job;43344.tyrone-cluster;Not sending email: User does not want mail of this type.
10/03/2014 01:45:28;0010;PBS_Server;Job;43344.tyrone-cluster;Exit_status=143 resources_used.cput=01:05:28 resources_used.mem=752608kb resources_used.vmem=7369288kb resources_used.walltime=00:02:06
10/03/2014 01:45:28;0008;PBS_Server;Job;NULL;on_job_exit valid pjob: 0x2e9af40 (substate=50)
10/03/2014 01:45:28;0008;PBS_Server;Job;NULL;on_job_exit valid pjob: 0x2e9af40 (substate=51)
10/03/2014 01:45:28;0008;PBS_Server;Job;NULL;on_job_exit valid pjob: 0x2e9af40 (substate=51)
10/03/2014 01:45:28;0008;PBS_Server;Job;NULL;on_job_exit valid pjob: 0x2e9af40 (substate=53)
10/03/2014 01:45:28;0100;PBS_Server;Job;43344.tyrone-cluster;dequeuing from idqueue, state COMPLETE
10/03/2014 01:45:28;0040;PBS_Server;Svr;tyrone-cluster;Scheduler was sent the command term
10/03/2014 01:45:34;0100;PBS_Server;Job;43345.tyrone-cluster;enqueuing into batch, state 1 hop 1
10/03/2014 01:45:34;0100;PBS_Server;Job;43345.tyrone-cluster;dequeuing from batch, state QUEUED
10/03/2014 01:45:34;0100;PBS_Server;Job;43345.tyrone-cluster;enqueuing into idqueue, state 1 hop 1
10/03/2014 01:45:34;0008;PBS_Server;Job;43345.tyrone-cluster;Job Queued at request of asepk@tyrone-cluster, owner = asepk@tyrone-cluster, job name = AeDNs_4, queue = idqueue
10/03/2014 01:45:34;0040;PBS_Server;Svr;tyrone-cluster;Scheduler was sent the command new
10/03/2014 01:45:34;0008;PBS_Server;Job;43345.tyrone-cluster;Job Modified at request of Scheduler@tyrone-cluster
10/03/2014 01:45:34;0008;PBS_Server;Job;43345.tyrone-cluster;Job Run at request of Scheduler@tyrone-cluster
10/03/2014 01:45:34;0040;PBS_Server;Svr;tyrone-cluster;Scheduler was sent the command recyc
10/03/2014 01:45:34;000d;PBS_Server;Job;43345.tyrone-cluster;Not sending email: User does not want mail of this type.
10/03/2014 01:45:57;0040;PBS_Server;Svr;tyrone-cluster;Scheduler was sent the command new
10/03/2014 01:46:32;0040;PBS_Server;Svr;tyrone-cluster;Scheduler was sent the command new
10/03/2014 01:47:04;0040;PBS_Server;Svr;tyrone-cluster;Scheduler was sent the command new
10/03/2014 01:47:35;0040;PBS_Server;Svr;tyrone-cluster;Scheduler was sent the command new
10/03/2014 01:47:50;0002;PBS_Server;Svr;PBS_Server;Torque Server Version = 3.0.5, loglevel = 0
10/03/2014 01:48:10;0040;PBS_Server;Svr;tyrone-cluster;Scheduler was sent the command new
10/03/2014 01:48:39;0040;PBS_Server;Svr;tyrone-cluster;Scheduler was sent the command new
10/03/2014 01:49:10;0040;PBS_Server;Svr;tyrone-cluster;Scheduler was sent the command new
10/03/2014 01:49:40;0040;PBS_Server;Svr;tyrone-cluster;Scheduler was sent the command new
10/03/2014 01:50:11;0040;PBS_Server;Svr;tyrone-cluster;Scheduler was sent the command new
10/03/2014 01:50:37;0100;PBS_Server;Job;43346.tyrone-cluster;enqueuing into batch, state 1 hop 1
10/03/2014 01:50:37;0100;PBS_Server;Job;43346.tyrone-cluster;dequeuing from batch, state QUEUED
10/03/2014 01:50:37;0100;PBS_Server;Job;43346.tyrone-cluster;enqueuing into idqueue, state 1 hop 1
10/03/2014 01:50:37;0008;PBS_Server;Job;43346.tyrone-cluster;Job Queued at request of asepk@tyrone-cluster, owner = asepk@tyrone-cluster, job name = AeDNs_4, queue = idqueue
10/03/2014 01:50:37;0040;PBS_Server;Svr;tyrone-cluster;Scheduler was sent the command new
10/03/2014 01:50:37;0008;PBS_Server;Job;43346.tyrone-cluster;Job Modified at request of Scheduler@tyrone-cluster
10/03/2014 01:50:42;0040;PBS_Server;Svr;tyrone-cluster;Scheduler was sent the command new
10/03/2014 01:50:46;0008;PBS_Server;Job;43345.tyrone-cluster;Job deleted at request of asepk@tyrone-cluster
10/03/2014 01:50:46;0008;PBS_Server;Job;43345.tyrone-cluster;Job sent signal SIGTERM on delete
10/03/2014 01:50:46;000d;PBS_Server;Job;43345.tyrone-cluster;Not sending email: User does not want mail of this type.
10/03/2014 01:50:46;0010;PBS_Server;Job;43345.tyrone-cluster;Exit_status=143 resources_used.cput=02:44:28 resources_used.mem=933600kb resources_used.vmem=7369692kb resources_used.walltime=00:05:12
10/03/2014 01:50:46;0008;PBS_Server;Job;NULL;on_job_exit valid pjob: 0x2e9af40 (substate=50)
10/03/2014 01:50:46;0008;PBS_Server;Job;NULL;on_job_exit valid pjob: 0x2e9af40 (substate=51)
10/03/2014 01:50:46;0008;PBS_Server;Job;NULL;on_job_exit valid pjob: 0x2e9af40 (substate=51)
10/03/2014 01:50:46;0008;PBS_Server;Job;NULL;on_job_exit valid pjob: 0x2e9af40 (substate=53)
10/03/2014 01:50:46;0100;PBS_Server;Job;43345.tyrone-cluster;dequeuing from idqueue, state COMPLETE
10/03/2014 01:50:46;0040;PBS_Server;Svr;tyrone-cluster;Scheduler was sent the command term
10/03/2014 01:50:47;0008;PBS_Server;Job;43346.tyrone-cluster;Job Modified at request of Scheduler@tyrone-cluster
10/03/2014 01:50:47;0008;PBS_Server;Job;43346.tyrone-cluster;Job Run at request of Scheduler@tyrone-cluster
10/03/2014 01:50:47;0040;PBS_Server;Svr;tyrone-cluster;Scheduler was sent the command recyc
10/03/2014 01:50:47;000d;PBS_Server;Job;43346.tyrone-cluster;Not sending email: User does not want mail of this type.
10/03/2014 01:51:12;0040;PBS_Server;Svr;tyrone-cluster;Scheduler was sent the command new
10/03/2014 01:51:47;0040;PBS_Server;Svr;tyrone-cluster;Scheduler was sent the command new
10/03/2014 01:52:19;0040;PBS_Server;Svr;tyrone-cluster;Scheduler was sent the command new
10/03/2014 01:52:50;0002;PBS_Server;Svr;PBS_Server;Torque Server Version = 3.0.5, loglevel = 0
10/03/2014 01:52:50;0040;PBS_Server;Svr;tyrone-cluster;Scheduler was sent the command new
10/03/2014 01:53:27;0040;PBS_Server;Svr;tyrone-cluster;Scheduler was sent the command new
10/03/2014 01:53:34;0008;PBS_Server;Job;43346.tyrone-cluster;Job deleted at request of asepk@tyrone-cluster
10/03/2014 01:53:34;0008;PBS_Server;Job;43346.tyrone-cluster;Job sent signal SIGTERM on delete
10/03/2014 01:53:34;000d;PBS_Server;Job;43346.tyrone-cluster;Not sending email: User does not want mail of this type.
10/03/2014 01:53:34;0010;PBS_Server;Job;43346.tyrone-cluster;Exit_status=143 resources_used.cput=01:28:15 resources_used.mem=755492kb resources_used.vmem=7369288kb resources_used.walltime=00:02:47
10/03/2014 01:53:34;0008;PBS_Server;Job;NULL;on_job_exit valid pjob: 0x2dbe110 (substate=50)
10/03/2014 01:53:34;0008;PBS_Server;Job;NULL;on_job_exit valid pjob: 0x2dbe110 (substate=51)
10/03/2014 01:53:34;0008;PBS_Server;Job;NULL;on_job_exit valid pjob: 0x2dbe110 (substate=51)
10/03/2014 01:53:34;0008;PBS_Server;Job;NULL;on_job_exit valid pjob: 0x2dbe110 (substate=53)
10/03/2014 01:53:34;0100;PBS_Server;Job;43346.tyrone-cluster;dequeuing from idqueue, state COMPLETE
10/03/2014 01:53:34;0040;PBS_Server;Svr;tyrone-cluster;Scheduler was sent the command term
10/03/2014 01:53:50;0040;PBS_Server;Svr;tyrone-cluster;Scheduler was sent the command new
10/03/2014 01:54:20;0040;PBS_Server;Svr;tyrone-cluster;Scheduler was sent the command new
10/03/2014 01:54:57;0040;PBS_Server;Svr;tyrone-cluster;Scheduler was sent the command new
10/03/2014 01:54:58;0100;PBS_Server;Job;43347.tyrone-cluster;enqueuing into batch, state 1 hop 1
10/03/2014 01:54:58;0100;PBS_Server;Job;43347.tyrone-cluster;dequeuing from batch, state QUEUED
10/03/2014 01:54:58;0100;PBS_Server;Job;43347.tyrone-cluster;enqueuing into idqueue, state 1 hop 1
10/03/2014 01:54:58;0008;PBS_Server;Job;43347.tyrone-cluster;Job Queued at request of asepk@tyrone-cluster, owner = asepk@tyrone-cluster, job name = AeDNs_4, queue = idqueue
10/03/2014 01:54:58;0040;PBS_Server;Svr;tyrone-cluster;Scheduler was sent the command new
10/03/2014 01:54:58;0008;PBS_Server;Job;43347.tyrone-cluster;Job Modified at request of Scheduler@tyrone-cluster
10/03/2014 01:54:58;0008;PBS_Server;Job;43347.tyrone-cluster;Job Run at request of Scheduler@tyrone-cluster
10/03/2014 01:54:58;0040;PBS_Server;Svr;tyrone-cluster;Scheduler was sent the command recyc
10/03/2014 01:54:58;000d;PBS_Server;Job;43347.tyrone-cluster;Not sending email: User does not want mail of this type.
10/03/2014 01:55:32;0040;PBS_Server;Svr;tyrone-cluster;Scheduler was sent the command new
10/03/2014 01:56:04;0040;PBS_Server;Svr;tyrone-cluster;Scheduler was sent the command new
10/03/2014 01:56:35;0040;PBS_Server;Svr;tyrone-cluster;Scheduler was sent the command new
10/03/2014 01:57:12;0040;PBS_Server;Svr;tyrone-cluster;Scheduler was sent the command new
10/03/2014 01:57:35;0040;PBS_Server;Svr;tyrone-cluster;Scheduler was sent the command new
10/03/2014 01:57:50;0002;PBS_Server;Svr;PBS_Server;Torque Server Version = 3.0.5, loglevel = 0
10/03/2014 01:58:05;0040;PBS_Server;Svr;tyrone-cluster;Scheduler was sent the command new
10/03/2014 01:58:13;0008;PBS_Server;Job;43347.tyrone-cluster;Job deleted at request of asepk@tyrone-cluster
10/03/2014 01:58:13;0008;PBS_Server;Job;43347.tyrone-cluster;Job sent signal SIGTERM on delete
10/03/2014 01:58:14;000d;PBS_Server;Job;43347.tyrone-cluster;Not sending email: User does not want mail of this type.
10/03/2014 01:58:14;0010;PBS_Server;Job;43347.tyrone-cluster;Exit_status=143 resources_used.cput=01:42:39 resources_used.mem=759000kb resources_used.vmem=7369288kb resources_used.walltime=00:03:16
10/03/2014 01:58:14;0008;PBS_Server;Job;NULL;on_job_exit valid pjob: 0x2ce05b0 (substate=50)
10/03/2014 01:58:14;0008;PBS_Server;Job;NULL;on_job_exit valid pjob: 0x2ce05b0 (substate=51)
10/03/2014 01:58:14;0008;PBS_Server;Job;NULL;on_job_exit valid pjob: 0x2ce05b0 (substate=51)
10/03/2014 01:58:14;0008;PBS_Server;Job;NULL;on_job_exit valid pjob: 0x2ce05b0 (substate=53)
10/03/2014 01:58:14;0100;PBS_Server;Job;43347.tyrone-cluster;dequeuing from idqueue, state COMPLETE
10/03/2014 01:58:14;0040;PBS_Server;Svr;tyrone-cluster;Scheduler was sent the command term
10/03/2014 01:58:32;0100;PBS_Server;Job;43348.tyrone-cluster;enqueuing into batch, state 1 hop 1
10/03/2014 01:58:32;0100;PBS_Server;Job;43348.tyrone-cluster;dequeuing from batch, state QUEUED
10/03/2014 01:58:32;0100;PBS_Server;Job;43348.tyrone-cluster;enqueuing into idqueue, state 1 hop 1
10/03/2014 01:58:32;0008;PBS_Server;Job;43348.tyrone-cluster;Job Queued at request of asepk@tyrone-cluster, owner = asepk@tyrone-cluster, job name = AeDNs_4, queue = idqueue
10/03/2014 01:58:32;0040;PBS_Server;Svr;tyrone-cluster;Scheduler was sent the command new
10/03/2014 01:58:32;0008;PBS_Server;Job;43348.tyrone-cluster;Job Modified at request of Scheduler@tyrone-cluster
10/03/2014 01:58:32;0008;PBS_Server;Job;43348.tyrone-cluster;Job Run at request of Scheduler@tyrone-cluster
10/03/2014 01:58:32;0040;PBS_Server;Svr;tyrone-cluster;Scheduler was sent the command recyc
10/03/2014 01:58:32;000d;PBS_Server;Job;43348.tyrone-cluster;Not sending email: User does not want mail of this type.
10/03/2014 01:58:42;0040;PBS_Server;Svr;tyrone-cluster;Scheduler was sent the command new
10/03/2014 01:59:05;0040;PBS_Server;Svr;tyrone-cluster;Scheduler was sent the command new
10/03/2014 01:59:35;0040;PBS_Server;Svr;tyrone-cluster;Scheduler was sent the command new
10/03/2014 02:00:12;0040;PBS_Server;Svr;tyrone-cluster;Scheduler was sent the command new
10/03/2014 02:00:47;0040;PBS_Server;Svr;tyrone-cluster;Scheduler was sent the command new
10/03/2014 02:01:19;0040;PBS_Server;Svr;tyrone-cluster;Scheduler was sent the command new
10/03/2014 02:01:50;0040;PBS_Server;Svr;tyrone-cluster;Scheduler was sent the command new
10/03/2014 02:02:27;0040;PBS_Server;Svr;tyrone-cluster;Scheduler was sent the command new
10/03/2014 02:02:50;0002;PBS_Server;Svr;PBS_Server;Torque Server Version = 3.0.5, loglevel = 0
10/03/2014 02:02:50;0040;PBS_Server;Svr;tyrone-cluster;Scheduler was sent the command new
10/03/2014 02:03:20;0040;PBS_Server;Svr;tyrone-cluster;Scheduler was sent the command new
10/03/2014 02:03:57;0040;PBS_Server;Svr;tyrone-cluster;Scheduler was sent the command new
10/03/2014 02:04:20;0040;PBS_Server;Svr;tyrone-cluster;Scheduler was sent the command new
10/03/2014 02:04:49;0040;PBS_Server;Svr;tyrone-cluster;Scheduler was sent the command new
10/03/2014 02:05:27;0040;PBS_Server;Svr;tyrone-cluster;Scheduler was sent the command new
10/03/2014 02:05:49;0040;PBS_Server;Svr;tyrone-cluster;Scheduler was sent the command new
10/03/2014 02:06:20;0040;PBS_Server;Svr;tyrone-cluster;Scheduler was sent the command new
10/03/2014 02:06:57;0040;PBS_Server;Svr;tyrone-cluster;Scheduler was sent the command new
10/03/2014 02:07:20;0040;PBS_Server;Svr;tyrone-cluster;Scheduler was sent the command new
10/03/2014 02:07:50;0002;PBS_Server;Svr;PBS_Server;Torque Server Version = 3.0.5, loglevel = 0
10/03/2014 02:07:50;0040;PBS_Server;Svr;tyrone-cluster;Scheduler was sent the command new
10/03/2014 02:08:27;0040;PBS_Server;Svr;tyrone-cluster;Scheduler was sent the command new
10/03/2014 02:08:50;0040;PBS_Server;Svr;tyrone-cluster;Scheduler was sent the command new
10/03/2014 02:09:19;0040;PBS_Server;Svr;tyrone-cluster;Scheduler was sent the command new
10/03/2014 02:09:57;0040;PBS_Server;Svr;tyrone-cluster;Scheduler was sent the command new
10/03/2014 02:10:32;0040;PBS_Server;Svr;tyrone-cluster;Scheduler was sent the command new
10/03/2014 02:11:04;0040;PBS_Server;Svr;tyrone-cluster;Scheduler was sent the command new
10/03/2014 02:11:35;0040;PBS_Server;Svr;tyrone-cluster;Scheduler was sent the command new
10/03/2014 02:12:12;0040;PBS_Server;Svr;tyrone-cluster;Scheduler was sent the command new
10/03/2014 02:12:35;0040;PBS_Server;Svr;tyrone-cluster;Scheduler was sent the command new
10/03/2014 02:12:50;0002;PBS_Server;Svr;PBS_Server;Torque Server Version = 3.0.5, loglevel = 0
10/03/2014 02:13:05;0040;PBS_Server;Svr;tyrone-cluster;Scheduler was sent the command new
10/03/2014 02:13:42;0040;PBS_Server;Svr;tyrone-cluster;Scheduler was sent the command new
10/03/2014 02:14:05;0040;PBS_Server;Svr;tyrone-cluster;Scheduler was sent the command new
10/03/2014 02:14:34;0040;PBS_Server;Svr;tyrone-cluster;Scheduler was sent the command new
10/03/2014 02:15:12;0040;PBS_Server;Svr;tyrone-cluster;Scheduler was sent the command new
10/03/2014 02:15:47;0040;PBS_Server;Svr;tyrone-cluster;Scheduler was sent the command new
10/03/2014 02:16:19;0040;PBS_Server;Svr;tyrone-cluster;Scheduler was sent the command new
10/03/2014 02:16:50;0040;PBS_Server;Svr;tyrone-cluster;Scheduler was sent the command new
10/03/2014 02:17:27;0040;PBS_Server;Svr;tyrone-cluster;Scheduler was sent the command new
10/03/2014 02:17:50;0002;PBS_Server;Svr;PBS_Server;Torque Server Version = 3.0.5, loglevel = 0
10/03/2014 02:17:50;0040;PBS_Server;Svr;tyrone-cluster;Scheduler was sent the command new
10/03/2014 02:18:19;0040;PBS_Server;Svr;tyrone-cluster;Scheduler was sent the command new
10/03/2014 02:18:57;0040;PBS_Server;Svr;tyrone-cluster;Scheduler was sent the command new
10/03/2014 02:19:20;0040;PBS_Server;Svr;tyrone-cluster;Scheduler was sent the command new
10/03/2014 02:19:49;0040;PBS_Server;Svr;tyrone-cluster;Scheduler was sent the command new
10/03/2014 02:20:27;0040;PBS_Server;Svr;tyrone-cluster;Scheduler was sent the command new
10/03/2014 02:21:02;0040;PBS_Server;Svr;tyrone-cluster;Scheduler was sent the command new
10/03/2014 02:21:34;0040;PBS_Server;Svr;tyrone-cluster;Scheduler was sent the command new
10/03/2014 02:22:05;0040;PBS_Server;Svr;tyrone-cluster;Scheduler was sent the command new
10/03/2014 02:22:42;0040;PBS_Server;Svr;tyrone-cluster;Scheduler was sent the command new
10/03/2014 02:22:50;0002;PBS_Server;Svr;PBS_Server;Torque Server Version = 3.0.5, loglevel = 0
10/03/2014 02:23:05;0040;PBS_Server;Svr;tyrone-cluster;Scheduler was sent the command new
10/03/2014 02:23:34;0040;PBS_Server;Svr;tyrone-cluster;Scheduler was sent the command new
10/03/2014 02:24:12;0040;PBS_Server;Svr;tyrone-cluster;Scheduler was sent the command new
10/03/2014 02:24:46;0040;PBS_Server;Svr;tyrone-cluster;Scheduler was sent the command new
10/03/2014 02:25:19;0040;PBS_Server;Svr;tyrone-cluster;Scheduler was sent the command new
10/03/2014 02:25:50;0040;PBS_Server;Svr;tyrone-cluster;Scheduler was sent the command new
10/03/2014 02:26:27;0040;PBS_Server;Svr;tyrone-cluster;Scheduler was sent the command new
10/03/2014 02:26:50;0040;PBS_Server;Svr;tyrone-cluster;Scheduler was sent the command new
10/03/2014 02:27:19;0040;PBS_Server;Svr;tyrone-cluster;Scheduler was sent the command new
10/03/2014 02:27:50;0002;PBS_Server;Svr;PBS_Server;Torque Server Version = 3.0.5, loglevel = 0
10/03/2014 02:27:50;0040;PBS_Server;Svr;tyrone-cluster;Scheduler was sent the command new
10/03/2014 02:28:20;0040;PBS_Server;Svr;tyrone-cluster;Scheduler was sent the command new
10/03/2014 02:28:51;0040;PBS_Server;Svr;tyrone-cluster;Scheduler was sent the command new
10/03/2014 02:29:27;0040;PBS_Server;Svr;tyrone-cluster;Scheduler was sent the command new
10/03/2014 02:30:02;0040;PBS_Server;Svr;tyrone-cluster;Scheduler was sent the command new
10/03/2014 02:30:34;0040;PBS_Server;Svr;tyrone-cluster;Scheduler was sent the command new
10/03/2014 02:31:05;0040;PBS_Server;Svr;tyrone-cluster;Scheduler was sent the command new
10/03/2014 02:31:42;0040;PBS_Server;Svr;tyrone-cluster;Scheduler was sent the command new
10/03/2014 02:32:05;0040;PBS_Server;Svr;tyrone-cluster;Scheduler was sent the command new
10/03/2014 02:32:34;0040;PBS_Server;Svr;tyrone-cluster;Scheduler was sent the command new
10/03/2014 02:32:50;0002;PBS_Server;Svr;PBS_Server;Torque Server Version = 3.0.5, loglevel = 0
10/03/2014 02:33:06;0040;PBS_Server;Svr;tyrone-cluster;Scheduler was sent the command new
10/03/2014 02:33:35;0040;PBS_Server;Svr;tyrone-cluster;Scheduler was sent the command new
10/03/2014 02:34:05;0040;PBS_Server;Svr;tyrone-cluster;Scheduler was sent the command new
10/03/2014 02:34:42;0040;PBS_Server;Svr;tyrone-cluster;Scheduler was sent the command new
10/03/2014 02:35:05;0040;PBS_Server;Svr;tyrone-cluster;Scheduler was sent the command new
10/03/2014 02:35:34;0040;PBS_Server;Svr;tyrone-cluster;Scheduler was sent the command new
10/03/2014 02:36:12;0040;PBS_Server;Svr;tyrone-cluster;Scheduler was sent the command new
10/03/2014 02:36:35;0040;PBS_Server;Svr;tyrone-cluster;Scheduler was sent the command new
10/03/2014 02:37:06;0040;PBS_Server;Svr;tyrone-cluster;Scheduler was sent the command new
10/03/2014 02:37:42;0040;PBS_Server;Svr;tyrone-cluster;Scheduler was sent the command new
10/03/2014 02:37:50;0002;PBS_Server;Svr;PBS_Server;Torque Server Version = 3.0.5, loglevel = 0
10/03/2014 02:38:16;0040;PBS_Server;Svr;tyrone-cluster;Scheduler was sent the command new
10/03/2014 02:38:50;0040;PBS_Server;Svr;tyrone-cluster;Scheduler was sent the command new
10/03/2014 02:39:19;0040;PBS_Server;Svr;tyrone-cluster;Scheduler was sent the command new
10/03/2014 02:39:57;0040;PBS_Server;Svr;tyrone-cluster;Scheduler was sent the command new
10/03/2014 02:40:20;0040;PBS_Server;Svr;tyrone-cluster;Scheduler was sent the command new
10/03/2014 02:40:49;0040;PBS_Server;Svr;tyrone-cluster;Scheduler was sent the command new
10/03/2014 02:41:27;0040;PBS_Server;Svr;tyrone-cluster;Scheduler was sent the command new
10/03/2014 02:41:50;0040;PBS_Server;Svr;tyrone-cluster;Scheduler was sent the command new
10/03/2014 02:42:20;0040;PBS_Server;Svr;tyrone-cluster;Scheduler was sent the command new
10/03/2014 02:42:50;0002;PBS_Server;Svr;PBS_Server;Torque Server Version = 3.0.5, loglevel = 0
10/03/2014 02:42:50;0040;PBS_Server;Svr;tyrone-cluster;Scheduler was sent the command new
10/03/2014 02:43:20;0040;PBS_Server;Svr;tyrone-cluster;Scheduler was sent the command new
10/03/2014 02:43:49;0040;PBS_Server;Svr;tyrone-cluster;Scheduler was sent the command new
10/03/2014 02:44:27;0040;PBS_Server;Svr;tyrone-cluster;Scheduler was sent the command new
10/03/2014 02:44:50;0040;PBS_Server;Svr;tyrone-cluster;Scheduler was sent the command new
10/03/2014 02:45:19;0040;PBS_Server;Svr;tyrone-cluster;Scheduler was sent the command new
10/03/2014 02:45:57;0040;PBS_Server;Svr;tyrone-cluster;Scheduler was sent the command new
10/03/2014 02:46:32;0040;PBS_Server;Svr;tyrone-cluster;Scheduler was sent the command new
10/03/2014 02:47:04;0040;PBS_Server;Svr;tyrone-cluster;Scheduler was sent the command new
10/03/2014 02:47:34;0040;PBS_Server;Svr;tyrone-cluster;Scheduler was sent the command new
10/03/2014 02:47:50;0002;PBS_Server;Svr;PBS_Server;Torque Server Version = 3.0.5, loglevel = 0
10/03/2014 02:48:06;0040;PBS_Server;Svr;tyrone-cluster;Scheduler was sent the command new
10/03/2014 02:48:35;0040;PBS_Server;Svr;tyrone-cluster;Scheduler was sent the command new
10/03/2014 02:49:04;0040;PBS_Server;Svr;tyrone-cluster;Scheduler was sent the command new
10/03/2014 02:49:42;0040;PBS_Server;Svr;tyrone-cluster;Scheduler was sent the command new
10/03/2014 02:50:17;0040;PBS_Server;Svr;tyrone-cluster;Scheduler was sent the command new
10/03/2014 02:50:49;0040;PBS_Server;Svr;tyrone-cluster;Scheduler was sent the command new
10/03/2014 02:51:19;0040;PBS_Server;Svr;tyrone-cluster;Scheduler was sent the command new
10/03/2014 02:51:57;0040;PBS_Server;Svr;tyrone-cluster;Scheduler was sent the command new
10/03/2014 02:52:20;0040;PBS_Server;Svr;tyrone-cluster;Scheduler was sent the command new
10/03/2014 02:52:50;0002;PBS_Server;Svr;PBS_Server;Torque Server Version = 3.0.5, loglevel = 0
10/03/2014 02:52:50;0040;PBS_Server;Svr;tyrone-cluster;Scheduler was sent the command new
10/03/2014 02:53:27;0040;PBS_Server;Svr;tyrone-cluster;Scheduler was sent the command new
10/03/2014 02:54:02;0040;PBS_Server;Svr;tyrone-cluster;Scheduler was sent the command new
10/03/2014 02:54:34;0040;PBS_Server;Svr;tyrone-cluster;Scheduler was sent the command new
10/03/2014 02:55:04;0040;PBS_Server;Svr;tyrone-cluster;Scheduler was sent the command new
10/03/2014 02:55:36;0040;PBS_Server;Svr;tyrone-cluster;Scheduler was sent the command new
10/03/2014 02:56:05;0040;PBS_Server;Svr;tyrone-cluster;Scheduler was sent the command new
10/03/2014 02:56:36;0040;PBS_Server;Svr;tyrone-cluster;Scheduler was sent the command new
10/03/2014 02:57:12;0040;PBS_Server;Svr;tyrone-cluster;Scheduler was sent the command new
10/03/2014 02:57:34;0008;PBS_Server;Job;43348.tyrone-cluster;Job deleted at request of asepk@tyrone-cluster
10/03/2014 02:57:34;0008;PBS_Server;Job;43348.tyrone-cluster;Job sent signal SIGTERM on delete
10/03/2014 02:57:34;0040;PBS_Server;Svr;tyrone-cluster;Scheduler was sent the command new
10/03/2014 02:57:34;000d;PBS_Server;Job;43348.tyrone-cluster;Not sending email: User does not want mail of this type.
10/03/2014 02:57:34;0010;PBS_Server;Job;43348.tyrone-cluster;Exit_status=143 resources_used.cput=31:09:22 resources_used.mem=969156kb resources_used.vmem=7374548kb resources_used.walltime=00:59:02
10/03/2014 02:57:34;0008;PBS_Server;Job;NULL;on_job_exit valid pjob: 0x2ce05b0 (substate=50)
10/03/2014 02:57:34;0008;PBS_Server;Job;NULL;on_job_exit valid pjob: 0x2ce05b0 (substate=51)
10/03/2014 02:57:34;0008;PBS_Server;Job;NULL;on_job_exit valid pjob: 0x2ce05b0 (substate=51)
10/03/2014 02:57:34;0008;PBS_Server;Job;NULL;on_job_exit valid pjob: 0x2ce05b0 (substate=53)
10/03/2014 02:57:34;0100;PBS_Server;Job;43348.tyrone-cluster;dequeuing from idqueue, state COMPLETE
10/03/2014 02:57:50;0002;PBS_Server;Svr;PBS_Server;Torque Server Version = 3.0.5, loglevel = 0
10/03/2014 02:57:52;0100;PBS_Server;Job;43349.tyrone-cluster;enqueuing into batch, state 1 hop 1
10/03/2014 02:57:52;0100;PBS_Server;Job;43349.tyrone-cluster;dequeuing from batch, state QUEUED
10/03/2014 02:57:52;0100;PBS_Server;Job;43349.tyrone-cluster;enqueuing into idqueue, state 1 hop 1
10/03/2014 02:57:52;0008;PBS_Server;Job;43349.tyrone-cluster;Job Queued at request of asepk@tyrone-cluster, owner = asepk@tyrone-cluster, job name = AeDNs_4, queue = idqueue
10/03/2014 02:57:52;0040;PBS_Server;Svr;tyrone-cluster;Scheduler was sent the command new
10/03/2014 02:57:52;0008;PBS_Server;Job;43349.tyrone-cluster;Job Modified at request of Scheduler@tyrone-cluster
10/03/2014 02:57:52;0008;PBS_Server;Job;43349.tyrone-cluster;Job Run at request of Scheduler@tyrone-cluster
10/03/2014 02:57:52;0040;PBS_Server;Svr;tyrone-cluster;Scheduler was sent the command recyc
10/03/2014 02:57:52;000d;PBS_Server;Job;43349.tyrone-cluster;Not sending email: User does not want mail of this type.
10/03/2014 02:58:04;0040;PBS_Server;Svr;tyrone-cluster;Scheduler was sent the command new
10/03/2014 02:58:42;0040;PBS_Server;Svr;tyrone-cluster;Scheduler was sent the command new
10/03/2014 02:59:05;0040;PBS_Server;Svr;tyrone-cluster;Scheduler was sent the command new
10/03/2014 02:59:36;0040;PBS_Server;Svr;tyrone-cluster;Scheduler was sent the command new
10/03/2014 03:00:12;0040;PBS_Server;Svr;tyrone-cluster;Scheduler was sent the command new
10/03/2014 03:00:35;0040;PBS_Server;Svr;tyrone-cluster;Scheduler was sent the command new
10/03/2014 03:01:08;0040;PBS_Server;Svr;tyrone-cluster;Scheduler was sent the command new
10/03/2014 03:01:42;0040;PBS_Server;Svr;tyrone-cluster;Scheduler was sent the command new
10/03/2014 03:01:46;0100;PBS_Server;Job;43350.tyrone-cluster;enqueuing into batch, state 1 hop 1
10/03/2014 03:01:46;0100;PBS_Server;Job;43350.tyrone-cluster;dequeuing from batch, state QUEUED
10/03/2014 03:01:46;0100;PBS_Server;Job;43350.tyrone-cluster;enqueuing into idqueue, state 1 hop 1
10/03/2014 03:01:46;0008;PBS_Server;Job;43350.tyrone-cluster;Job Queued at request of asepk@tyrone-cluster, owner = asepk@tyrone-cluster, job name = AeDNs_4, queue = idqueue
10/03/2014 03:01:46;0040;PBS_Server;Svr;tyrone-cluster;Scheduler was sent the command new
10/03/2014 03:01:46;0008;PBS_Server;Job;43350.tyrone-cluster;Job Modified at request of Scheduler@tyrone-cluster
10/03/2014 03:01:55;0008;PBS_Server;Job;43349.tyrone-cluster;Job deleted at request of asepk@tyrone-cluster
10/03/2014 03:01:55;0008;PBS_Server;Job;43349.tyrone-cluster;Job sent signal SIGTERM on delete
10/03/2014 03:01:55;000d;PBS_Server;Job;43349.tyrone-cluster;Not sending email: User does not want mail of this type.
10/03/2014 03:01:55;0010;PBS_Server;Job;43349.tyrone-cluster;Exit_status=143 resources_used.cput=02:08:12 resources_used.mem=926844kb resources_used.vmem=7370084kb resources_used.walltime=00:04:03
10/03/2014 03:01:55;0008;PBS_Server;Job;NULL;on_job_exit valid pjob: 0x2ce05b0 (substate=50)
10/03/2014 03:01:55;0008;PBS_Server;Job;NULL;on_job_exit valid pjob: 0x2ce05b0 (substate=51)
10/03/2014 03:01:55;0008;PBS_Server;Job;NULL;on_job_exit valid pjob: 0x2ce05b0 (substate=51)
10/03/2014 03:01:55;0008;PBS_Server;Job;NULL;on_job_exit valid pjob: 0x2ce05b0 (substate=53)
10/03/2014 03:01:55;0100;PBS_Server;Job;43349.tyrone-cluster;dequeuing from idqueue, state COMPLETE
10/03/2014 03:01:55;0040;PBS_Server;Svr;tyrone-cluster;Scheduler was sent the command term
10/03/2014 03:01:56;0008;PBS_Server;Job;43350.tyrone-cluster;Job Modified at request of Scheduler@tyrone-cluster
10/03/2014 03:01:56;0008;PBS_Server;Job;43350.tyrone-cluster;Job Run at request of Scheduler@tyrone-cluster
10/03/2014 03:01:56;0040;PBS_Server;Svr;tyrone-cluster;Scheduler was sent the command recyc
10/03/2014 03:01:56;000d;PBS_Server;Job;43350.tyrone-cluster;Not sending email: User does not want mail of this type.
10/03/2014 03:02:17;0040;PBS_Server;Svr;tyrone-cluster;Scheduler was sent the command new
10/03/2014 03:02:49;0040;PBS_Server;Svr;tyrone-cluster;Scheduler was sent the command new
10/03/2014 03:02:50;0002;PBS_Server;Svr;PBS_Server;Torque Server Version = 3.0.5, loglevel = 0
10/03/2014 03:03:19;0040;PBS_Server;Svr;tyrone-cluster;Scheduler was sent the command new
10/03/2014 03:03:57;0040;PBS_Server;Svr;tyrone-cluster;Scheduler was sent the command new
10/03/2014 03:04:20;0040;PBS_Server;Svr;tyrone-cluster;Scheduler was sent the command new
10/03/2014 03:04:50;0040;PBS_Server;Svr;tyrone-cluster;Scheduler was sent the command new
10/03/2014 03:05:27;0040;PBS_Server;Svr;tyrone-cluster;Scheduler was sent the command new
10/03/2014 03:05:50;0040;PBS_Server;Svr;tyrone-cluster;Scheduler was sent the command new
10/03/2014 03:06:20;0040;PBS_Server;Svr;tyrone-cluster;Scheduler was sent the command new
10/03/2014 03:06:57;0040;PBS_Server;Svr;tyrone-cluster;Scheduler was sent the command new
10/03/2014 03:07:20;0040;PBS_Server;Svr;tyrone-cluster;Scheduler was sent the command new
10/03/2014 03:07:50;0002;PBS_Server;Svr;PBS_Server;Torque Server Version = 3.0.5, loglevel = 0
10/03/2014 03:07:50;0040;PBS_Server;Svr;tyrone-cluster;Scheduler was sent the command new
10/03/2014 03:08:27;0040;PBS_Server;Svr;tyrone-cluster;Scheduler was sent the command new
10/03/2014 03:08:50;0040;PBS_Server;Svr;tyrone-cluster;Scheduler was sent the command new
10/03/2014 03:09:20;0040;PBS_Server;Svr;tyrone-cluster;Scheduler was sent the command new
10/03/2014 03:09:57;0040;PBS_Server;Svr;tyrone-cluster;Scheduler was sent the command new
10/03/2014 03:10:31;0040;PBS_Server;Svr;tyrone-cluster;Scheduler was sent the command new
10/03/2014 03:11:04;0040;PBS_Server;Svr;tyrone-cluster;Scheduler was sent the command new
10/03/2014 03:11:34;0040;PBS_Server;Svr;tyrone-cluster;Scheduler was sent the command new
10/03/2014 03:12:12;0040;PBS_Server;Svr;tyrone-cluster;Scheduler was sent the command new
10/03/2014 03:12:35;0040;PBS_Server;Svr;tyrone-cluster;Scheduler was sent the command new
10/03/2014 03:12:50;0002;PBS_Server;Svr;PBS_Server;Torque Server Version = 3.0.5, loglevel = 0
10/03/2014 03:13:05;0040;PBS_Server;Svr;tyrone-cluster;Scheduler was sent the command new
10/03/2014 03:13:42;0040;PBS_Server;Svr;tyrone-cluster;Scheduler was sent the command new
10/03/2014 03:14:05;0040;PBS_Server;Svr;tyrone-cluster;Scheduler was sent the command new
10/03/2014 03:14:35;0040;PBS_Server;Svr;tyrone-cluster;Scheduler was sent the command new
10/03/2014 03:15:12;0040;PBS_Server;Svr;tyrone-cluster;Scheduler was sent the command new
10/03/2014 03:15:35;0040;PBS_Server;Svr;tyrone-cluster;Scheduler was sent the command new
10/03/2014 03:16:05;0040;PBS_Server;Svr;tyrone-cluster;Scheduler was sent the command new
10/03/2014 03:16:42;0040;PBS_Server;Svr;tyrone-cluster;Scheduler was sent the command new
10/03/2014 03:17:05;0040;PBS_Server;Svr;tyrone-cluster;Scheduler was sent the command new
10/03/2014 03:17:35;0040;PBS_Server;Svr;tyrone-cluster;Scheduler was sent the command new
10/03/2014 03:17:50;0002;PBS_Server;Svr;PBS_Server;Torque Server Version = 3.0.5, loglevel = 0
10/03/2014 03:18:06;0040;PBS_Server;Svr;tyrone-cluster;Scheduler was sent the command new
10/03/2014 03:18:35;0040;PBS_Server;Svr;tyrone-cluster;Scheduler was sent the command new
10/03/2014 03:19:05;0040;PBS_Server;Svr;tyrone-cluster;Scheduler was sent the command new
10/03/2014 03:19:42;0040;PBS_Server;Svr;tyrone-cluster;Scheduler was sent the command new
10/03/2014 03:20:05;0040;PBS_Server;Svr;tyrone-cluster;Scheduler was sent the command new
10/03/2014 03:20:35;0040;PBS_Server;Svr;tyrone-cluster;Scheduler was sent the command new
10/03/2014 03:21:12;0040;PBS_Server;Svr;tyrone-cluster;Scheduler was sent the command new
10/03/2014 03:21:47;0040;PBS_Server;Svr;tyrone-cluster;Scheduler was sent the command new
10/03/2014 03:22:19;0040;PBS_Server;Svr;tyrone-cluster;Scheduler was sent the command new
10/03/2014 03:22:49;0040;PBS_Server;Svr;tyrone-cluster;Scheduler was sent the command new
10/03/2014 03:22:50;0002;PBS_Server;Svr;PBS_Server;Torque Server Version = 3.0.5, loglevel = 0
10/03/2014 03:23:27;0040;PBS_Server;Svr;tyrone-cluster;Scheduler was sent the command new
10/03/2014 03:23:50;0040;PBS_Server;Svr;tyrone-cluster;Scheduler was sent the command new
10/03/2014 03:24:20;0040;PBS_Server;Svr;tyrone-cluster;Scheduler was sent the command new
10/03/2014 03:24:57;0040;PBS_Server;Svr;tyrone-cluster;Scheduler was sent the command new
10/03/2014 03:25:32;0040;PBS_Server;Svr;tyrone-cluster;Scheduler was sent the command new
10/03/2014 03:26:04;0040;PBS_Server;Svr;tyrone-cluster;Scheduler was sent the command new
10/03/2014 03:26:34;0040;PBS_Server;Svr;tyrone-cluster;Scheduler was sent the command new
10/03/2014 03:27:11;0040;PBS_Server;Svr;tyrone-cluster;Scheduler was sent the command new
10/03/2014 03:27:35;0040;PBS_Server;Svr;tyrone-cluster;Scheduler was sent the command new
10/03/2014 03:27:50;0002;PBS_Server;Svr;PBS_Server;Torque Server Version = 3.0.5, loglevel = 0
10/03/2014 03:28:05;0040;PBS_Server;Svr;tyrone-cluster;Scheduler was sent the command new
10/03/2014 03:28:42;0040;PBS_Server;Svr;tyrone-cluster;Scheduler was sent the command new
10/03/2014 03:29:11;0040;PBS_Server;Svr;tyrone-cluster;Scheduler was sent the command new
10/03/2014 03:29:42;0040;PBS_Server;Svr;tyrone-cluster;Scheduler was sent the command new
10/03/2014 03:30:12;0040;PBS_Server;Svr;tyrone-cluster;Scheduler was sent the command new
10/03/2014 03:30:47;0040;PBS_Server;Svr;tyrone-cluster;Scheduler was sent the command new
10/03/2014 03:31:19;0040;PBS_Server;Svr;tyrone-cluster;Scheduler was sent the command new
10/03/2014 03:31:48;0040;PBS_Server;Svr;tyrone-cluster;Scheduler was sent the command new
10/03/2014 03:32:26;0040;PBS_Server;Svr;tyrone-cluster;Scheduler was sent the command new
10/03/2014 03:32:49;0040;PBS_Server;Svr;tyrone-cluster;Scheduler was sent the command new
10/03/2014 03:32:50;0002;PBS_Server;Svr;PBS_Server;Torque Server Version = 3.0.5, loglevel = 0
10/03/2014 03:33:20;0040;PBS_Server;Svr;tyrone-cluster;Scheduler was sent the command new
10/03/2014 03:33:56;0040;PBS_Server;Svr;tyrone-cluster;Scheduler was sent the command new
10/03/2014 03:34:19;0040;PBS_Server;Svr;tyrone-cluster;Scheduler was sent the command new
10/03/2014 03:34:49;0040;PBS_Server;Svr;tyrone-cluster;Scheduler was sent the command new
10/03/2014 03:35:27;0040;PBS_Server;Svr;tyrone-cluster;Scheduler was sent the command new
10/03/2014 03:35:50;0040;PBS_Server;Svr;tyrone-cluster;Scheduler was sent the command new
10/03/2014 03:36:20;0040;PBS_Server;Svr;tyrone-cluster;Scheduler was sent the command new
10/03/2014 03:36:57;0040;PBS_Server;Svr;tyrone-cluster;Scheduler was sent the command new
10/03/2014 03:37:31;0040;PBS_Server;Svr;tyrone-cluster;Scheduler was sent the command new
10/03/2014 03:37:50;0002;PBS_Server;Svr;PBS_Server;Torque Server Version = 3.0.5, loglevel = 0
10/03/2014 03:38:04;0040;PBS_Server;Svr;tyrone-cluster;Scheduler was sent the command new
10/03/2014 03:38:34;0040;PBS_Server;Svr;tyrone-cluster;Scheduler was sent the command new
10/03/2014 03:39:12;0040;PBS_Server;Svr;tyrone-cluster;Scheduler was sent the command new
10/03/2014 03:39:35;0040;PBS_Server;Svr;tyrone-cluster;Scheduler was sent the command new
10/03/2014 03:40:05;0040;PBS_Server;Svr;tyrone-cluster;Scheduler was sent the command new
10/03/2014 03:40:42;0040;PBS_Server;Svr;tyrone-cluster;Scheduler was sent the command new
10/03/2014 03:41:09;0040;PBS_Server;Svr;tyrone-cluster;Scheduler was sent the command new
10/03/2014 03:41:38;0040;PBS_Server;Svr;tyrone-cluster;Scheduler was sent the command new
10/03/2014 03:42:12;0040;PBS_Server;Svr;tyrone-cluster;Scheduler was sent the command new
10/03/2014 03:42:46;0040;PBS_Server;Svr;tyrone-cluster;Scheduler was sent the command new
10/03/2014 03:42:50;0002;PBS_Server;Svr;PBS_Server;Torque Server Version = 3.0.5, loglevel = 0
10/03/2014 03:43:19;0040;PBS_Server;Svr;tyrone-cluster;Scheduler was sent the command new
10/03/2014 03:43:48;0040;PBS_Server;Svr;tyrone-cluster;Scheduler was sent the command new
10/03/2014 03:44:27;0040;PBS_Server;Svr;tyrone-cluster;Scheduler was sent the command new
10/03/2014 03:44:50;0040;PBS_Server;Svr;tyrone-cluster;Scheduler was sent the command new
10/03/2014 03:45:20;0040;PBS_Server;Svr;tyrone-cluster;Scheduler was sent the command new
10/03/2014 03:45:57;0040;PBS_Server;Svr;tyrone-cluster;Scheduler was sent the command new
10/03/2014 03:46:31;0040;PBS_Server;Svr;tyrone-cluster;Scheduler was sent the command new
10/03/2014 03:47:04;0040;PBS_Server;Svr;tyrone-cluster;Scheduler was sent the command new
10/03/2014 03:47:33;0040;PBS_Server;Svr;tyrone-cluster;Scheduler was sent the command new
10/03/2014 03:47:50;0002;PBS_Server;Svr;PBS_Server;Torque Server Version = 3.0.5, loglevel = 0
10/03/2014 03:48:06;0040;PBS_Server;Svr;tyrone-cluster;Scheduler was sent the command new
10/03/2014 03:48:35;0040;PBS_Server;Svr;tyrone-cluster;Scheduler was sent the command new
10/03/2014 03:49:05;0040;PBS_Server;Svr;tyrone-cluster;Scheduler was sent the command new
10/03/2014 03:49:42;0040;PBS_Server;Svr;tyrone-cluster;Scheduler was sent the command new
10/03/2014 03:50:16;0040;PBS_Server;Svr;tyrone-cluster;Scheduler was sent the command new
10/03/2014 03:50:49;0040;PBS_Server;Svr;tyrone-cluster;Scheduler was sent the command new
10/03/2014 03:51:19;0040;PBS_Server;Svr;tyrone-cluster;Scheduler was sent the command new
10/03/2014 03:51:57;0040;PBS_Server;Svr;tyrone-cluster;Scheduler was sent the command new
10/03/2014 03:52:20;0040;PBS_Server;Svr;tyrone-cluster;Scheduler was sent the command new
10/03/2014 03:52:50;0002;PBS_Server;Svr;PBS_Server;Torque Server Version = 3.0.5, loglevel = 0
10/03/2014 03:52:50;0040;PBS_Server;Svr;tyrone-cluster;Scheduler was sent the command new
10/03/2014 03:53:27;0040;PBS_Server;Svr;tyrone-cluster;Scheduler was sent the command new
10/03/2014 03:54:01;0040;PBS_Server;Svr;tyrone-cluster;Scheduler was sent the command new
10/03/2014 03:54:34;0040;PBS_Server;Svr;tyrone-cluster;Scheduler was sent the command new
10/03/2014 03:55:05;0040;PBS_Server;Svr;tyrone-cluster;Scheduler was sent the command new
10/03/2014 03:55:36;0040;PBS_Server;Svr;tyrone-cluster;Scheduler was sent the command new
10/03/2014 03:56:05;0040;PBS_Server;Svr;tyrone-cluster;Scheduler was sent the command new
10/03/2014 03:56:35;0040;PBS_Server;Svr;tyrone-cluster;Scheduler was sent the command new
10/03/2014 03:57:12;0040;PBS_Server;Svr;tyrone-cluster;Scheduler was sent the command new
10/03/2014 03:57:46;0040;PBS_Server;Svr;tyrone-cluster;Scheduler was sent the command new
10/03/2014 03:57:50;0002;PBS_Server;Svr;PBS_Server;Torque Server Version = 3.0.5, loglevel = 0
10/03/2014 03:58:19;0040;PBS_Server;Svr;tyrone-cluster;Scheduler was sent the command new
10/03/2014 03:58:50;0040;PBS_Server;Svr;tyrone-cluster;Scheduler was sent the command new
10/03/2014 03:59:26;0040;PBS_Server;Svr;tyrone-cluster;Scheduler was sent the command new
10/03/2014 03:59:50;0040;PBS_Server;Svr;tyrone-cluster;Scheduler was sent the command new
10/03/2014 04:00:20;0040;PBS_Server;Svr;tyrone-cluster;Scheduler was sent the command new
10/03/2014 04:00:57;0040;PBS_Server;Svr;tyrone-cluster;Scheduler was sent the command new
10/03/2014 04:01:31;0040;PBS_Server;Svr;tyrone-cluster;Scheduler was sent the command new
10/03/2014 04:02:04;0040;PBS_Server;Svr;tyrone-cluster;Scheduler was sent the command new
10/03/2014 04:02:35;0040;PBS_Server;Svr;tyrone-cluster;Scheduler was sent the command new
10/03/2014 04:02:50;0002;PBS_Server;Svr;PBS_Server;Torque Server Version = 3.0.5, loglevel = 0
10/03/2014 04:03:06;0040;PBS_Server;Svr;tyrone-cluster;Scheduler was sent the command new
10/03/2014 04:03:35;0040;PBS_Server;Svr;tyrone-cluster;Scheduler was sent the command new
10/03/2014 04:04:05;0040;PBS_Server;Svr;tyrone-cluster;Scheduler was sent the command new
10/03/2014 04:04:42;0040;PBS_Server;Svr;tyrone-cluster;Scheduler was sent the command new
10/03/2014 04:05:11;0040;PBS_Server;Svr;tyrone-cluster;Scheduler was sent the command new
10/03/2014 04:05:42;0040;PBS_Server;Svr;tyrone-cluster;Scheduler was sent the command new
10/03/2014 04:06:12;0040;PBS_Server;Svr;tyrone-cluster;Scheduler was sent the command new
10/03/2014 04:06:46;0040;PBS_Server;Svr;tyrone-cluster;Scheduler was sent the command new
10/03/2014 04:07:19;0040;PBS_Server;Svr;tyrone-cluster;Scheduler was sent the command new
10/03/2014 04:07:50;0002;PBS_Server;Svr;PBS_Server;Torque Server Version = 3.0.5, loglevel = 0
10/03/2014 04:07:50;0040;PBS_Server;Svr;tyrone-cluster;Scheduler was sent the command new
10/03/2014 04:08:26;0040;PBS_Server;Svr;tyrone-cluster;Scheduler was sent the command new
10/03/2014 04:08:50;0040;PBS_Server;Svr;tyrone-cluster;Scheduler was sent the command new
10/03/2014 04:09:20;0040;PBS_Server;Svr;tyrone-cluster;Scheduler was sent the command new
10/03/2014 04:09:57;0040;PBS_Server;Svr;tyrone-cluster;Scheduler was sent the command new
10/03/2014 04:10:26;0040;PBS_Server;Svr;tyrone-cluster;Scheduler was sent the command new
10/03/2014 04:10:57;0040;PBS_Server;Svr;tyrone-cluster;Scheduler was sent the command new
10/03/2014 04:11:27;0040;PBS_Server;Svr;tyrone-cluster;Scheduler was sent the command new
10/03/2014 04:12:01;0040;PBS_Server;Svr;tyrone-cluster;Scheduler was sent the command new
10/03/2014 04:12:34;0040;PBS_Server;Svr;tyrone-cluster;Scheduler was sent the command new
10/03/2014 04:12:50;0002;PBS_Server;Svr;PBS_Server;Torque Server Version = 3.0.5, loglevel = 0
10/03/2014 04:13:05;0040;PBS_Server;Svr;tyrone-cluster;Scheduler was sent the command new
10/03/2014 04:13:41;0040;PBS_Server;Svr;tyrone-cluster;Scheduler was sent the command new
10/03/2014 04:14:05;0040;PBS_Server;Svr;tyrone-cluster;Scheduler was sent the command new
10/03/2014 04:14:35;0040;PBS_Server;Svr;tyrone-cluster;Scheduler was sent the command new
10/03/2014 04:15:12;0040;PBS_Server;Svr;tyrone-cluster;Scheduler was sent the command new
10/03/2014 04:15:46;0040;PBS_Server;Svr;tyrone-cluster;Scheduler was sent the command new
10/03/2014 04:16:19;0040;PBS_Server;Svr;tyrone-cluster;Scheduler was sent the command new
10/03/2014 04:16:50;0040;PBS_Server;Svr;tyrone-cluster;Scheduler was sent the command new
10/03/2014 04:17:26;0040;PBS_Server;Svr;tyrone-cluster;Scheduler was sent the command new
10/03/2014 04:17:50;0002;PBS_Server;Svr;PBS_Server;Torque Server Version = 3.0.5, loglevel = 0
10/03/2014 04:17:50;0040;PBS_Server;Svr;tyrone-cluster;Scheduler was sent the command new
10/03/2014 04:18:20;0040;PBS_Server;Svr;tyrone-cluster;Scheduler was sent the command new
10/03/2014 04:18:57;0040;PBS_Server;Svr;tyrone-cluster;Scheduler was sent the command new
10/03/2014 04:19:26;0040;PBS_Server;Svr;tyrone-cluster;Scheduler was sent the command new
10/03/2014 04:19:57;0040;PBS_Server;Svr;tyrone-cluster;Scheduler was sent the command new
10/03/2014 04:20:27;0040;PBS_Server;Svr;tyrone-cluster;Scheduler was sent the command new
10/03/2014 04:21:01;0040;PBS_Server;Svr;tyrone-cluster;Scheduler was sent the command new
10/03/2014 04:21:34;0040;PBS_Server;Svr;tyrone-cluster;Scheduler was sent the command new
10/03/2014 04:22:05;0040;PBS_Server;Svr;tyrone-cluster;Scheduler was sent the command new
10/03/2014 04:22:42;0040;PBS_Server;Svr;tyrone-cluster;Scheduler was sent the command new
10/03/2014 04:22:50;0002;PBS_Server;Svr;PBS_Server;Torque Server Version = 3.0.5, loglevel = 0
10/03/2014 04:23:11;0040;PBS_Server;Svr;tyrone-cluster;Scheduler was sent the command new
10/03/2014 04:23:42;0040;PBS_Server;Svr;tyrone-cluster;Scheduler was sent the command new
10/03/2014 04:24:12;0040;PBS_Server;Svr;tyrone-cluster;Scheduler was sent the command new
10/03/2014 04:24:46;0040;PBS_Server;Svr;tyrone-cluster;Scheduler was sent the command new
10/03/2014 04:25:19;0040;PBS_Server;Svr;tyrone-cluster;Scheduler was sent the command new
10/03/2014 04:25:50;0040;PBS_Server;Svr;tyrone-cluster;Scheduler was sent the command new
10/03/2014 04:26:26;0040;PBS_Server;Svr;tyrone-cluster;Scheduler was sent the command new
10/03/2014 04:26:49;0040;PBS_Server;Svr;tyrone-cluster;Scheduler was sent the command new
10/03/2014 04:27:20;0040;PBS_Server;Svr;tyrone-cluster;Scheduler was sent the command new
10/03/2014 04:27:50;0002;PBS_Server;Svr;PBS_Server;Torque Server Version = 3.0.5, loglevel = 0
10/03/2014 04:27:56;0040;PBS_Server;Svr;tyrone-cluster;Scheduler was sent the command new
10/03/2014 04:28:24;0040;PBS_Server;Svr;tyrone-cluster;Scheduler was sent the command new
10/03/2014 04:28:50;0040;PBS_Server;Svr;tyrone-cluster;Scheduler was sent the command new
10/03/2014 04:29:27;0040;PBS_Server;Svr;tyrone-cluster;Scheduler was sent the command new
10/03/2014 04:29:56;0040;PBS_Server;Svr;tyrone-cluster;Scheduler was sent the command new
10/03/2014 04:30:27;0040;PBS_Server;Svr;tyrone-cluster;Scheduler was sent the command new
10/03/2014 04:30:57;0040;PBS_Server;Svr;tyrone-cluster;Scheduler was sent the command new
10/03/2014 04:31:30;0040;PBS_Server;Svr;tyrone-cluster;Scheduler was sent the command new
10/03/2014 04:32:04;0040;PBS_Server;Svr;tyrone-cluster;Scheduler was sent the command new
10/03/2014 04:32:35;0040;PBS_Server;Svr;tyrone-cluster;Scheduler was sent the command new
10/03/2014 04:32:50;0002;PBS_Server;Svr;PBS_Server;Torque Server Version = 3.0.5, loglevel = 0
10/03/2014 04:33:10;0040;PBS_Server;Svr;tyrone-cluster;Scheduler was sent the command new
10/03/2014 04:33:41;0040;PBS_Server;Svr;tyrone-cluster;Scheduler was sent the command new
10/03/2014 04:34:11;0040;PBS_Server;Svr;tyrone-cluster;Scheduler was sent the command new
10/03/2014 04:34:42;0040;PBS_Server;Svr;tyrone-cluster;Scheduler was sent the command new
10/03/2014 04:35:11;0040;PBS_Server;Svr;tyrone-cluster;Scheduler was sent the command new
10/03/2014 04:35:42;0040;PBS_Server;Svr;tyrone-cluster;Scheduler was sent the command new
10/03/2014 04:36:12;0040;PBS_Server;Svr;tyrone-cluster;Scheduler was sent the command new
10/03/2014 04:36:45;0040;PBS_Server;Svr;tyrone-cluster;Scheduler was sent the command new
10/03/2014 04:37:19;0040;PBS_Server;Svr;tyrone-cluster;Scheduler was sent the command new
10/03/2014 04:37:50;0002;PBS_Server;Svr;PBS_Server;Torque Server Version = 3.0.5, loglevel = 0
10/03/2014 04:37:50;0040;PBS_Server;Svr;tyrone-cluster;Scheduler was sent the command new
10/03/2014 04:38:25;0040;PBS_Server;Svr;tyrone-cluster;Scheduler was sent the command new
10/03/2014 04:38:49;0040;PBS_Server;Svr;tyrone-cluster;Scheduler was sent the command new
10/03/2014 04:39:20;0040;PBS_Server;Svr;tyrone-cluster;Scheduler was sent the command new
10/03/2014 04:39:57;0040;PBS_Server;Svr;tyrone-cluster;Scheduler was sent the command new
10/03/2014 04:40:26;0040;PBS_Server;Svr;tyrone-cluster;Scheduler was sent the command new
10/03/2014 04:40:57;0040;PBS_Server;Svr;tyrone-cluster;Scheduler was sent the command new
10/03/2014 04:41:27;0040;PBS_Server;Svr;tyrone-cluster;Scheduler was sent the command new
10/03/2014 04:42:00;0040;PBS_Server;Svr;tyrone-cluster;Scheduler was sent the command new
10/03/2014 04:42:29;0040;PBS_Server;Svr;tyrone-cluster;Scheduler was sent the command new
10/03/2014 04:42:50;0002;PBS_Server;Svr;PBS_Server;Torque Server Version = 3.0.5, loglevel = 0
10/03/2014 04:43:01;0040;PBS_Server;Svr;tyrone-cluster;Scheduler was sent the command new
10/03/2014 04:43:31;0040;PBS_Server;Svr;tyrone-cluster;Scheduler was sent the command new
10/03/2014 04:44:04;0040;PBS_Server;Svr;tyrone-cluster;Scheduler was sent the command new
10/03/2014 04:44:35;0040;PBS_Server;Svr;tyrone-cluster;Scheduler was sent the command new
10/03/2014 04:45:12;0040;PBS_Server;Svr;tyrone-cluster;Scheduler was sent the command new
10/03/2014 04:45:41;0040;PBS_Server;Svr;tyrone-cluster;Scheduler was sent the command new
10/03/2014 04:46:12;0040;PBS_Server;Svr;tyrone-cluster;Scheduler was sent the command new
10/03/2014 04:46:42;0040;PBS_Server;Svr;tyrone-cluster;Scheduler was sent the command new
10/03/2014 04:47:16;0040;PBS_Server;Svr;tyrone-cluster;Scheduler was sent the command new
10/03/2014 04:47:49;0040;PBS_Server;Svr;tyrone-cluster;Scheduler was sent the command new
10/03/2014 04:47:50;0002;PBS_Server;Svr;PBS_Server;Torque Server Version = 3.0.5, loglevel = 0
10/03/2014 04:48:20;0040;PBS_Server;Svr;tyrone-cluster;Scheduler was sent the command new
10/03/2014 04:48:57;0040;PBS_Server;Svr;tyrone-cluster;Scheduler was sent the command new
10/03/2014 04:49:26;0040;PBS_Server;Svr;tyrone-cluster;Scheduler was sent the command new
10/03/2014 04:49:57;0040;PBS_Server;Svr;tyrone-cluster;Scheduler was sent the command new
10/03/2014 04:50:27;0040;PBS_Server;Svr;tyrone-cluster;Scheduler was sent the command new
10/03/2014 04:51:01;0040;PBS_Server;Svr;tyrone-cluster;Scheduler was sent the command new
10/03/2014 04:51:34;0040;PBS_Server;Svr;tyrone-cluster;Scheduler was sent the command new
10/03/2014 04:52:05;0040;PBS_Server;Svr;tyrone-cluster;Scheduler was sent the command new
10/03/2014 04:52:42;0040;PBS_Server;Svr;tyrone-cluster;Scheduler was sent the command new
10/03/2014 04:52:50;0002;PBS_Server;Svr;PBS_Server;Torque Server Version = 3.0.5, loglevel = 0
10/03/2014 04:53:11;0040;PBS_Server;Svr;tyrone-cluster;Scheduler was sent the command new
10/03/2014 04:53:42;0040;PBS_Server;Svr;tyrone-cluster;Scheduler was sent the command new
10/03/2014 04:54:12;0040;PBS_Server;Svr;tyrone-cluster;Scheduler was sent the command new
10/03/2014 04:54:46;0040;PBS_Server;Svr;tyrone-cluster;Scheduler was sent the command new
10/03/2014 04:55:19;0040;PBS_Server;Svr;tyrone-cluster;Scheduler was sent the command new
10/03/2014 04:55:50;0040;PBS_Server;Svr;tyrone-cluster;Scheduler was sent the command new
10/03/2014 04:56:27;0040;PBS_Server;Svr;tyrone-cluster;Scheduler was sent the command new
10/03/2014 04:56:56;0040;PBS_Server;Svr;tyrone-cluster;Scheduler was sent the command new
10/03/2014 04:57:27;0040;PBS_Server;Svr;tyrone-cluster;Scheduler was sent the command new
10/03/2014 04:57:50;0002;PBS_Server;Svr;PBS_Server;Torque Server Version = 3.0.5, loglevel = 0
10/03/2014 04:57:57;0040;PBS_Server;Svr;tyrone-cluster;Scheduler was sent the command new
10/03/2014 04:58:30;0040;PBS_Server;Svr;tyrone-cluster;Scheduler was sent the command new
10/03/2014 04:59:04;0040;PBS_Server;Svr;tyrone-cluster;Scheduler was sent the command new
10/03/2014 04:59:35;0040;PBS_Server;Svr;tyrone-cluster;Scheduler was sent the command new
10/03/2014 05:00:12;0040;PBS_Server;Svr;tyrone-cluster;Scheduler was sent the command new
10/03/2014 05:00:41;0040;PBS_Server;Svr;tyrone-cluster;Scheduler was sent the command new
10/03/2014 05:01:12;0040;PBS_Server;Svr;tyrone-cluster;Scheduler was sent the command new
10/03/2014 05:01:42;0040;PBS_Server;Svr;tyrone-cluster;Scheduler was sent the command new
10/03/2014 05:02:10;000d;PBS_Server;Job;43350.tyrone-cluster;Not sending email: User does not want mail of this type.
10/03/2014 05:02:10;0010;PBS_Server;Job;43350.tyrone-cluster;Exit_status=143 resources_used.cput=63:23:21 resources_used.mem=983564kb resources_used.vmem=7374548kb resources_used.walltime=02:00:14
10/03/2014 05:02:10;0008;PBS_Server;Job;NULL;on_job_exit valid pjob: 0x2dbe110 (substate=50)
10/03/2014 05:02:10;0008;PBS_Server;Job;NULL;on_job_exit valid pjob: 0x2dbe110 (substate=51)
10/03/2014 05:02:10;0008;PBS_Server;Job;NULL;on_job_exit valid pjob: 0x2dbe110 (substate=51)
10/03/2014 05:02:10;0008;PBS_Server;Job;NULL;on_job_exit valid pjob: 0x2dbe110 (substate=53)
10/03/2014 05:02:10;0100;PBS_Server;Job;43350.tyrone-cluster;dequeuing from idqueue, state COMPLETE
10/03/2014 05:02:10;0040;PBS_Server;Svr;tyrone-cluster;Scheduler was sent the command term
10/03/2014 05:02:15;0040;PBS_Server;Svr;tyrone-cluster;Scheduler was sent the command new
10/03/2014 05:02:44;0040;PBS_Server;Svr;tyrone-cluster;Scheduler was sent the command new
10/03/2014 05:02:50;0002;PBS_Server;Svr;PBS_Server;Torque Server Version = 3.0.5, loglevel = 0
10/03/2014 05:03:16;0040;PBS_Server;Svr;tyrone-cluster;Scheduler was sent the command new
10/03/2014 05:03:55;0040;PBS_Server;Svr;tyrone-cluster;Scheduler was sent the command new
10/03/2014 05:04:20;0040;PBS_Server;Svr;tyrone-cluster;Scheduler was sent the command new
10/03/2014 05:04:52;0040;PBS_Server;Svr;tyrone-cluster;Scheduler was sent the command new
10/03/2014 05:05:27;0040;PBS_Server;Svr;tyrone-cluster;Scheduler was sent the command new
10/03/2014 05:05:56;0040;PBS_Server;Svr;tyrone-cluster;Scheduler was sent the command new
10/03/2014 05:06:27;0040;PBS_Server;Svr;tyrone-cluster;Scheduler was sent the command new
10/03/2014 05:06:57;0040;PBS_Server;Svr;tyrone-cluster;Scheduler was sent the command new
10/03/2014 05:07:30;0040;PBS_Server;Svr;tyrone-cluster;Scheduler was sent the command new
10/03/2014 05:07:50;0002;PBS_Server;Svr;PBS_Server;Torque Server Version = 3.0.5, loglevel = 0
10/03/2014 05:07:59;0040;PBS_Server;Svr;tyrone-cluster;Scheduler was sent the command new
10/03/2014 05:08:31;0040;PBS_Server;Svr;tyrone-cluster;Scheduler was sent the command new
10/03/2014 05:09:09;0040;PBS_Server;Svr;tyrone-cluster;Scheduler was sent the command new
10/03/2014 05:09:34;0040;PBS_Server;Svr;tyrone-cluster;Scheduler was sent the command new
10/03/2014 05:10:07;0040;PBS_Server;Svr;tyrone-cluster;Scheduler was sent the command new
10/03/2014 05:10:40;0040;PBS_Server;Svr;tyrone-cluster;Scheduler was sent the command new
10/03/2014 05:11:11;0040;PBS_Server;Svr;tyrone-cluster;Scheduler was sent the command new
10/03/2014 05:11:42;0040;PBS_Server;Svr;tyrone-cluster;Scheduler was sent the command new
10/03/2014 05:12:12;0040;PBS_Server;Svr;tyrone-cluster;Scheduler was sent the command new
10/03/2014 05:12:45;0040;PBS_Server;Svr;tyrone-cluster;Scheduler was sent the command new
10/03/2014 05:12:50;0002;PBS_Server;Svr;PBS_Server;Torque Server Version = 3.0.5, loglevel = 0
10/03/2014 05:13:14;0040;PBS_Server;Svr;tyrone-cluster;Scheduler was sent the command new
10/03/2014 05:13:46;0040;PBS_Server;Svr;tyrone-cluster;Scheduler was sent the command new
10/03/2014 05:14:25;0040;PBS_Server;Svr;tyrone-cluster;Scheduler was sent the command new
10/03/2014 05:14:49;0040;PBS_Server;Svr;tyrone-cluster;Scheduler was sent the command new
10/03/2014 05:15:22;0040;PBS_Server;Svr;tyrone-cluster;Scheduler was sent the command new
10/03/2014 05:15:57;0040;PBS_Server;Svr;tyrone-cluster;Scheduler was sent the command new
10/03/2014 05:16:26;0040;PBS_Server;Svr;tyrone-cluster;Scheduler was sent the command new
10/03/2014 05:16:57;0040;PBS_Server;Svr;tyrone-cluster;Scheduler was sent the command new
10/03/2014 05:17:27;0040;PBS_Server;Svr;tyrone-cluster;Scheduler was sent the command new
10/03/2014 05:17:50;0002;PBS_Server;Svr;PBS_Server;Torque Server Version = 3.0.5, loglevel = 0
10/03/2014 05:18:00;0040;PBS_Server;Svr;tyrone-cluster;Scheduler was sent the command new
10/03/2014 05:18:29;0040;PBS_Server;Svr;tyrone-cluster;Scheduler was sent the command new
10/03/2014 05:19:01;0040;PBS_Server;Svr;tyrone-cluster;Scheduler was sent the command new
10/03/2014 05:19:39;0040;PBS_Server;Svr;tyrone-cluster;Scheduler was sent the command new
10/03/2014 05:20:04;0040;PBS_Server;Svr;tyrone-cluster;Scheduler was sent the command new
10/03/2014 05:20:36;0040;PBS_Server;Svr;tyrone-cluster;Scheduler was sent the command new
10/03/2014 05:21:12;0040;PBS_Server;Svr;tyrone-cluster;Scheduler was sent the command new
10/03/2014 05:21:41;0040;PBS_Server;Svr;tyrone-cluster;Scheduler was sent the command new
10/03/2014 05:22:12;0040;PBS_Server;Svr;tyrone-cluster;Scheduler was sent the command new
10/03/2014 05:22:42;0040;PBS_Server;Svr;tyrone-cluster;Scheduler was sent the command new
10/03/2014 05:22:50;0002;PBS_Server;Svr;PBS_Server;Torque Server Version = 3.0.5, loglevel = 0
10/03/2014 05:23:15;0040;PBS_Server;Svr;tyrone-cluster;Scheduler was sent the command new
10/03/2014 05:23:44;0040;PBS_Server;Svr;tyrone-cluster;Scheduler was sent the command new
10/03/2014 05:24:16;0040;PBS_Server;Svr;tyrone-cluster;Scheduler was sent the command new
10/03/2014 05:24:54;0040;PBS_Server;Svr;tyrone-cluster;Scheduler was sent the command new
10/03/2014 05:25:19;0040;PBS_Server;Svr;tyrone-cluster;Scheduler was sent the command new
10/03/2014 05:25:52;0040;PBS_Server;Svr;tyrone-cluster;Scheduler was sent the command new
10/03/2014 05:26:27;0040;PBS_Server;Svr;tyrone-cluster;Scheduler was sent the command new
10/03/2014 05:26:56;0040;PBS_Server;Svr;tyrone-cluster;Scheduler was sent the command new
10/03/2014 05:27:27;0040;PBS_Server;Svr;tyrone-cluster;Scheduler was sent the command new
10/03/2014 05:27:50;0002;PBS_Server;Svr;PBS_Server;Torque Server Version = 3.0.5, loglevel = 0
10/03/2014 05:27:57;0040;PBS_Server;Svr;tyrone-cluster;Scheduler was sent the command new
10/03/2014 05:28:30;0040;PBS_Server;Svr;tyrone-cluster;Scheduler was sent the command new
10/03/2014 05:28:59;0040;PBS_Server;Svr;tyrone-cluster;Scheduler was sent the command new
10/03/2014 05:29:31;0040;PBS_Server;Svr;tyrone-cluster;Scheduler was sent the command new
10/03/2014 05:30:09;0040;PBS_Server;Svr;tyrone-cluster;Scheduler was sent the command new
10/03/2014 05:30:34;0040;PBS_Server;Svr;tyrone-cluster;Scheduler was sent the command new
10/03/2014 05:31:07;0040;PBS_Server;Svr;tyrone-cluster;Scheduler was sent the command new
10/03/2014 05:31:42;0040;PBS_Server;Svr;tyrone-cluster;Scheduler was sent the command new
10/03/2014 05:32:11;0040;PBS_Server;Svr;tyrone-cluster;Scheduler was sent the command new
10/03/2014 05:32:42;0040;PBS_Server;Svr;tyrone-cluster;Scheduler was sent the command new
10/03/2014 05:32:50;0002;PBS_Server;Svr;PBS_Server;Torque Server Version = 3.0.5, loglevel = 0
10/03/2014 05:33:12;0040;PBS_Server;Svr;tyrone-cluster;Scheduler was sent the command new
10/03/2014 05:33:45;0040;PBS_Server;Svr;tyrone-cluster;Scheduler was sent the command new
10/03/2014 05:34:14;0040;PBS_Server;Svr;tyrone-cluster;Scheduler was sent the command new
10/03/2014 05:34:46;0040;PBS_Server;Svr;tyrone-cluster;Scheduler was sent the command new
10/03/2014 05:35:24;0040;PBS_Server;Svr;tyrone-cluster;Scheduler was sent the command new
10/03/2014 05:35:50;0040;PBS_Server;Svr;tyrone-cluster;Scheduler was sent the command new
10/03/2014 05:36:21;0040;PBS_Server;Svr;tyrone-cluster;Scheduler was sent the command new
10/03/2014 05:36:54;0040;PBS_Server;Svr;tyrone-cluster;Scheduler was sent the command new
10/03/2014 05:37:26;0040;PBS_Server;Svr;tyrone-cluster;Scheduler was sent the command new
10/03/2014 05:37:50;0002;PBS_Server;Svr;PBS_Server;Torque Server Version = 3.0.5, loglevel = 0
10/03/2014 05:37:57;0040;PBS_Server;Svr;tyrone-cluster;Scheduler was sent the command new
10/03/2014 05:38:27;0040;PBS_Server;Svr;tyrone-cluster;Scheduler was sent the command new
10/03/2014 05:39:00;0040;PBS_Server;Svr;tyrone-cluster;Scheduler was sent the command new
10/03/2014 05:39:29;0040;PBS_Server;Svr;tyrone-cluster;Scheduler was sent the command new
10/03/2014 05:40:01;0040;PBS_Server;Svr;tyrone-cluster;Scheduler was sent the command new
10/03/2014 05:40:36;0040;PBS_Server;Svr;tyrone-cluster;Scheduler was sent the command new
10/03/2014 05:41:09;0040;PBS_Server;Svr;tyrone-cluster;Scheduler was sent the command new
10/03/2014 05:41:36;0040;PBS_Server;Svr;tyrone-cluster;Scheduler was sent the command new
10/03/2014 05:42:09;0040;PBS_Server;Svr;tyrone-cluster;Scheduler was sent the command new
10/03/2014 05:42:39;0040;PBS_Server;Svr;tyrone-cluster;Scheduler was sent the command new
10/03/2014 05:42:50;0002;PBS_Server;Svr;PBS_Server;Torque Server Version = 3.0.5, loglevel = 0
10/03/2014 05:43:06;0040;PBS_Server;Svr;tyrone-cluster;Scheduler was sent the command new
10/03/2014 05:43:42;0040;PBS_Server;Svr;tyrone-cluster;Scheduler was sent the command new
10/03/2014 05:44:11;0040;PBS_Server;Svr;tyrone-cluster;Scheduler was sent the command new
10/03/2014 05:44:42;0040;PBS_Server;Svr;tyrone-cluster;Scheduler was sent the command new
10/03/2014 05:45:12;0040;PBS_Server;Svr;tyrone-cluster;Scheduler was sent the command new
10/03/2014 05:45:44;0040;PBS_Server;Svr;tyrone-cluster;Scheduler was sent the command new
10/03/2014 05:46:14;0040;PBS_Server;Svr;tyrone-cluster;Scheduler was sent the command new
10/03/2014 05:46:46;0040;PBS_Server;Svr;tyrone-cluster;Scheduler was sent the command new
10/03/2014 05:47:23;0040;PBS_Server;Svr;tyrone-cluster;Scheduler was sent the command new
10/03/2014 05:47:50;0002;PBS_Server;Svr;PBS_Server;Torque Server Version = 3.0.5, loglevel = 0
10/03/2014 05:47:54;0040;PBS_Server;Svr;tyrone-cluster;Scheduler was sent the command new
10/03/2014 05:48:21;0040;PBS_Server;Svr;tyrone-cluster;Scheduler was sent the command new
10/03/2014 05:48:57;0040;PBS_Server;Svr;tyrone-cluster;Scheduler was sent the command new
10/03/2014 05:49:26;0040;PBS_Server;Svr;tyrone-cluster;Scheduler was sent the command new
10/03/2014 05:49:57;0040;PBS_Server;Svr;tyrone-cluster;Scheduler was sent the command new
10/03/2014 05:50:27;0040;PBS_Server;Svr;tyrone-cluster;Scheduler was sent the command new
10/03/2014 05:50:59;0040;PBS_Server;Svr;tyrone-cluster;Scheduler was sent the command new
10/03/2014 05:51:29;0040;PBS_Server;Svr;tyrone-cluster;Scheduler was sent the command new
10/03/2014 05:52:01;0040;PBS_Server;Svr;tyrone-cluster;Scheduler was sent the command new
10/03/2014 05:52:38;0040;PBS_Server;Svr;tyrone-cluster;Scheduler was sent the command new
10/03/2014 05:52:50;0002;PBS_Server;Svr;PBS_Server;Torque Server Version = 3.0.5, loglevel = 0
10/03/2014 05:53:06;0040;PBS_Server;Svr;tyrone-cluster;Scheduler was sent the command new
10/03/2014 05:53:36;0040;PBS_Server;Svr;tyrone-cluster;Scheduler was sent the command new
10/03/2014 05:54:12;0040;PBS_Server;Svr;tyrone-cluster;Scheduler was sent the command new
10/03/2014 05:54:41;0040;PBS_Server;Svr;tyrone-cluster;Scheduler was sent the command new
10/03/2014 05:55:12;0040;PBS_Server;Svr;tyrone-cluster;Scheduler was sent the command new
10/03/2014 05:55:42;0040;PBS_Server;Svr;tyrone-cluster;Scheduler was sent the command new
10/03/2014 05:56:14;0040;PBS_Server;Svr;tyrone-cluster;Scheduler was sent the command new
10/03/2014 05:56:44;0040;PBS_Server;Svr;tyrone-cluster;Scheduler was sent the command new
10/03/2014 05:57:16;0040;PBS_Server;Svr;tyrone-cluster;Scheduler was sent the command new
10/03/2014 05:57:50;0002;PBS_Server;Svr;PBS_Server;Torque Server Version = 3.0.5, loglevel = 0
10/03/2014 05:57:53;0040;PBS_Server;Svr;tyrone-cluster;Scheduler was sent the command new
10/03/2014 05:58:24;0040;PBS_Server;Svr;tyrone-cluster;Scheduler was sent the command new
10/03/2014 05:58:51;0040;PBS_Server;Svr;tyrone-cluster;Scheduler was sent the command new
10/03/2014 05:59:24;0040;PBS_Server;Svr;tyrone-cluster;Scheduler was sent the command new
10/03/2014 05:59:56;0040;PBS_Server;Svr;tyrone-cluster;Scheduler was sent the command new
10/03/2014 06:00:27;0040;PBS_Server;Svr;tyrone-cluster;Scheduler was sent the command new
10/03/2014 06:00:57;0040;PBS_Server;Svr;tyrone-cluster;Scheduler was sent the command new
10/03/2014 06:01:29;0040;PBS_Server;Svr;tyrone-cluster;Scheduler was sent the command new
10/03/2014 06:01:59;0040;PBS_Server;Svr;tyrone-cluster;Scheduler was sent the command new
10/03/2014 06:02:31;0040;PBS_Server;Svr;tyrone-cluster;Scheduler was sent the command new
10/03/2014 06:02:50;0002;PBS_Server;Svr;PBS_Server;Torque Server Version = 3.0.5, loglevel = 0
10/03/2014 06:03:06;0040;PBS_Server;Svr;tyrone-cluster;Scheduler was sent the command new
10/03/2014 06:03:41;0040;PBS_Server;Svr;tyrone-cluster;Scheduler was sent the command new
10/03/2014 06:04:11;0040;PBS_Server;Svr;tyrone-cluster;Scheduler was sent the command new
10/03/2014 06:04:42;0040;PBS_Server;Svr;tyrone-cluster;Scheduler was sent the command new
10/03/2014 06:05:15;0040;PBS_Server;Svr;tyrone-cluster;Scheduler was sent the command new
10/03/2014 06:05:44;0040;PBS_Server;Svr;tyrone-cluster;Scheduler was sent the command new
10/03/2014 06:06:16;0040;PBS_Server;Svr;tyrone-cluster;Scheduler was sent the command new
10/03/2014 06:06:53;0040;PBS_Server;Svr;tyrone-cluster;Scheduler was sent the command new
10/03/2014 06:07:26;0040;PBS_Server;Svr;tyrone-cluster;Scheduler was sent the command new
10/03/2014 06:07:50;0002;PBS_Server;Svr;PBS_Server;Torque Server Version = 3.0.5, loglevel = 0
10/03/2014 06:07:57;0040;PBS_Server;Svr;tyrone-cluster;Scheduler was sent the command new
10/03/2014 06:08:27;0040;PBS_Server;Svr;tyrone-cluster;Scheduler was sent the command new
10/03/2014 06:08:59;0040;PBS_Server;Svr;tyrone-cluster;Scheduler was sent the command new
10/03/2014 06:09:29;0040;PBS_Server;Svr;tyrone-cluster;Scheduler was sent the command new
10/03/2014 06:10:01;0040;PBS_Server;Svr;tyrone-cluster;Scheduler was sent the command new
10/03/2014 06:10:36;0040;PBS_Server;Svr;tyrone-cluster;Scheduler was sent the command new
10/03/2014 06:11:11;0040;PBS_Server;Svr;tyrone-cluster;Scheduler was sent the command new
10/03/2014 06:11:41;0040;PBS_Server;Svr;tyrone-cluster;Scheduler was sent the command new
10/03/2014 06:12:12;0040;PBS_Server;Svr;tyrone-cluster;Scheduler was sent the command new
10/03/2014 06:12:44;0040;PBS_Server;Svr;tyrone-cluster;Scheduler was sent the command new
10/03/2014 06:12:50;0002;PBS_Server;Svr;PBS_Server;Torque Server Version = 3.0.5, loglevel = 0
10/03/2014 06:13:14;0040;PBS_Server;Svr;tyrone-cluster;Scheduler was sent the command new
10/03/2014 06:13:46;0040;PBS_Server;Svr;tyrone-cluster;Scheduler was sent the command new
10/03/2014 06:14:23;0040;PBS_Server;Svr;tyrone-cluster;Scheduler was sent the command new
10/03/2014 06:14:56;0040;PBS_Server;Svr;tyrone-cluster;Scheduler was sent the command new
10/03/2014 06:15:26;0040;PBS_Server;Svr;tyrone-cluster;Scheduler was sent the command new
10/03/2014 06:15:57;0040;PBS_Server;Svr;tyrone-cluster;Scheduler was sent the command new
10/03/2014 06:16:26;0040;PBS_Server;Svr;tyrone-cluster;Scheduler was sent the command new
10/03/2014 06:16:59;0040;PBS_Server;Svr;tyrone-cluster;Scheduler was sent the command new
10/03/2014 06:17:27;0040;PBS_Server;Svr;tyrone-cluster;Scheduler was sent the command new
10/03/2014 06:17:50;0002;PBS_Server;Svr;PBS_Server;Torque Server Version = 3.0.5, loglevel = 0
10/03/2014 06:17:56;0040;PBS_Server;Svr;tyrone-cluster;Scheduler was sent the command new
10/03/2014 06:18:27;0040;PBS_Server;Svr;tyrone-cluster;Scheduler was sent the command new
10/03/2014 06:18:57;0040;PBS_Server;Svr;tyrone-cluster;Scheduler was sent the command new
10/03/2014 06:19:29;0040;PBS_Server;Svr;tyrone-cluster;Scheduler was sent the command new
10/03/2014 06:19:59;0040;PBS_Server;Svr;tyrone-cluster;Scheduler was sent the command new
10/03/2014 06:20:31;0040;PBS_Server;Svr;tyrone-cluster;Scheduler was sent the command new
10/03/2014 06:21:07;0040;PBS_Server;Svr;tyrone-cluster;Scheduler was sent the command new
10/03/2014 06:21:41;0040;PBS_Server;Svr;tyrone-cluster;Scheduler was sent the command new
10/03/2014 06:22:11;0040;PBS_Server;Svr;tyrone-cluster;Scheduler was sent the command new
10/03/2014 06:22:42;0040;PBS_Server;Svr;tyrone-cluster;Scheduler was sent the command new
10/03/2014 06:22:50;0002;PBS_Server;Svr;PBS_Server;Torque Server Version = 3.0.5, loglevel = 0
10/03/2014 06:23:14;0040;PBS_Server;Svr;tyrone-cluster;Scheduler was sent the command new
10/03/2014 06:23:44;0040;PBS_Server;Svr;tyrone-cluster;Scheduler was sent the command new
10/03/2014 06:24:16;0040;PBS_Server;Svr;tyrone-cluster;Scheduler was sent the command new
10/03/2014 06:24:52;0040;PBS_Server;Svr;tyrone-cluster;Scheduler was sent the command new
10/03/2014 06:25:26;0040;PBS_Server;Svr;tyrone-cluster;Scheduler was sent the command new
10/03/2014 06:25:56;0040;PBS_Server;Svr;tyrone-cluster;Scheduler was sent the command new
10/03/2014 06:26:27;0040;PBS_Server;Svr;tyrone-cluster;Scheduler was sent the command new
10/03/2014 06:26:56;0040;PBS_Server;Svr;tyrone-cluster;Scheduler was sent the command new
10/03/2014 06:27:29;0040;PBS_Server;Svr;tyrone-cluster;Scheduler was sent the command new
10/03/2014 06:27:50;0002;PBS_Server;Svr;PBS_Server;Torque Server Version = 3.0.5, loglevel = 0
10/03/2014 06:27:57;0040;PBS_Server;Svr;tyrone-cluster;Scheduler was sent the command new
10/03/2014 06:28:29;0040;PBS_Server;Svr;tyrone-cluster;Scheduler was sent the command new
10/03/2014 06:28:59;0040;PBS_Server;Svr;tyrone-cluster;Scheduler was sent the command new
10/03/2014 06:29:30;0040;PBS_Server;Svr;tyrone-cluster;Scheduler was sent the command new
10/03/2014 06:30:08;0040;PBS_Server;Svr;tyrone-cluster;Scheduler was sent the command new
10/03/2014 06:30:36;0040;PBS_Server;Svr;tyrone-cluster;Scheduler was sent the command new
10/03/2014 06:31:05;0040;PBS_Server;Svr;tyrone-cluster;Scheduler was sent the command new
10/03/2014 06:31:37;0040;PBS_Server;Svr;tyrone-cluster;Scheduler was sent the command new
10/03/2014 06:32:11;0040;PBS_Server;Svr;tyrone-cluster;Scheduler was sent the command new
10/03/2014 06:32:41;0040;PBS_Server;Svr;tyrone-cluster;Scheduler was sent the command new
10/03/2014 06:32:50;0002;PBS_Server;Svr;PBS_Server;Torque Server Version = 3.0.5, loglevel = 0
10/03/2014 06:33:12;0040;PBS_Server;Svr;tyrone-cluster;Scheduler was sent the command new
10/03/2014 06:33:41;0040;PBS_Server;Svr;tyrone-cluster;Scheduler was sent the command new
10/03/2014 06:34:14;0040;PBS_Server;Svr;tyrone-cluster;Scheduler was sent the command new
10/03/2014 06:34:42;0040;PBS_Server;Svr;tyrone-cluster;Scheduler was sent the command new
10/03/2014 06:35:12;0040;PBS_Server;Svr;tyrone-cluster;Scheduler was sent the command new
10/03/2014 06:35:44;0040;PBS_Server;Svr;tyrone-cluster;Scheduler was sent the command new
10/03/2014 06:36:12;0040;PBS_Server;Svr;tyrone-cluster;Scheduler was sent the command new
10/03/2014 06:36:44;0040;PBS_Server;Svr;tyrone-cluster;Scheduler was sent the command new
10/03/2014 06:37:14;0040;PBS_Server;Svr;tyrone-cluster;Scheduler was sent the command new
10/03/2014 06:37:46;0040;PBS_Server;Svr;tyrone-cluster;Scheduler was sent the command new
10/03/2014 06:37:50;0002;PBS_Server;Svr;PBS_Server;Torque Server Version = 3.0.5, loglevel = 0
10/03/2014 06:38:22;0040;PBS_Server;Svr;tyrone-cluster;Scheduler was sent the command new
10/03/2014 06:38:56;0040;PBS_Server;Svr;tyrone-cluster;Scheduler was sent the command new
10/03/2014 06:39:26;0040;PBS_Server;Svr;tyrone-cluster;Scheduler was sent the command new
10/03/2014 06:39:57;0040;PBS_Server;Svr;tyrone-cluster;Scheduler was sent the command new
10/03/2014 06:40:26;0040;PBS_Server;Svr;tyrone-cluster;Scheduler was sent the command new
10/03/2014 06:40:59;0040;PBS_Server;Svr;tyrone-cluster;Scheduler was sent the command new
10/03/2014 06:41:26;0040;PBS_Server;Svr;tyrone-cluster;Scheduler was sent the command new
10/03/2014 06:41:56;0040;PBS_Server;Svr;tyrone-cluster;Scheduler was sent the command new
10/03/2014 06:42:29;0040;PBS_Server;Svr;tyrone-cluster;Scheduler was sent the command new
10/03/2014 06:42:50;0002;PBS_Server;Svr;PBS_Server;Torque Server Version = 3.0.5, loglevel = 0
10/03/2014 06:42:57;0040;PBS_Server;Svr;tyrone-cluster;Scheduler was sent the command new
10/03/2014 06:43:29;0040;PBS_Server;Svr;tyrone-cluster;Scheduler was sent the command new
10/03/2014 06:43:59;0040;PBS_Server;Svr;tyrone-cluster;Scheduler was sent the command new
10/03/2014 06:44:30;0040;PBS_Server;Svr;tyrone-cluster;Scheduler was sent the command new
10/03/2014 06:45:07;0040;PBS_Server;Svr;tyrone-cluster;Scheduler was sent the command new
10/03/2014 06:45:39;0040;PBS_Server;Svr;tyrone-cluster;Scheduler was sent the command new
10/03/2014 06:46:09;0040;PBS_Server;Svr;tyrone-cluster;Scheduler was sent the command new
10/03/2014 06:46:41;0040;PBS_Server;Svr;tyrone-cluster;Scheduler was sent the command new
10/03/2014 06:47:11;0040;PBS_Server;Svr;tyrone-cluster;Scheduler was sent the command new
10/03/2014 06:47:42;0040;PBS_Server;Svr;tyrone-cluster;Scheduler was sent the command new
10/03/2014 06:47:50;0002;PBS_Server;Svr;PBS_Server;Torque Server Version = 3.0.5, loglevel = 0
10/03/2014 06:48:12;0040;PBS_Server;Svr;tyrone-cluster;Scheduler was sent the command new
10/03/2014 06:48:41;0040;PBS_Server;Svr;tyrone-cluster;Scheduler was sent the command new
10/03/2014 06:49:14;0040;PBS_Server;Svr;tyrone-cluster;Scheduler was sent the command new
10/03/2014 06:49:42;0040;PBS_Server;Svr;tyrone-cluster;Scheduler was sent the command new
10/03/2014 06:50:14;0040;PBS_Server;Svr;tyrone-cluster;Scheduler was sent the command new
10/03/2014 06:50:44;0040;PBS_Server;Svr;tyrone-cluster;Scheduler was sent the command new
10/03/2014 06:51:15;0040;PBS_Server;Svr;tyrone-cluster;Scheduler was sent the command new
10/03/2014 06:51:51;0040;PBS_Server;Svr;tyrone-cluster;Scheduler was sent the command new
10/03/2014 06:52:26;0040;PBS_Server;Svr;tyrone-cluster;Scheduler was sent the command new
10/03/2014 06:52:50;0002;PBS_Server;Svr;PBS_Server;Torque Server Version = 3.0.5, loglevel = 0
10/03/2014 06:52:56;0040;PBS_Server;Svr;tyrone-cluster;Scheduler was sent the command new
10/03/2014 06:53:27;0040;PBS_Server;Svr;tyrone-cluster;Scheduler was sent the command new
10/03/2014 06:53:56;0040;PBS_Server;Svr;tyrone-cluster;Scheduler was sent the command new
10/03/2014 06:54:29;0040;PBS_Server;Svr;tyrone-cluster;Scheduler was sent the command new
10/03/2014 06:54:57;0040;PBS_Server;Svr;tyrone-cluster;Scheduler was sent the command new
10/03/2014 06:55:29;0040;PBS_Server;Svr;tyrone-cluster;Scheduler was sent the command new
10/03/2014 06:55:59;0040;PBS_Server;Svr;tyrone-cluster;Scheduler was sent the command new
10/03/2014 06:56:30;0040;PBS_Server;Svr;tyrone-cluster;Scheduler was sent the command new
10/03/2014 06:57:06;0040;PBS_Server;Svr;tyrone-cluster;Scheduler was sent the command new
10/03/2014 06:57:41;0040;PBS_Server;Svr;tyrone-cluster;Scheduler was sent the command new
10/03/2014 06:57:50;0002;PBS_Server;Svr;PBS_Server;Torque Server Version = 3.0.5, loglevel = 0
10/03/2014 06:58:11;0040;PBS_Server;Svr;tyrone-cluster;Scheduler was sent the command new
10/03/2014 06:58:42;0040;PBS_Server;Svr;tyrone-cluster;Scheduler was sent the command new
10/03/2014 06:59:11;0040;PBS_Server;Svr;tyrone-cluster;Scheduler was sent the command new
10/03/2014 06:59:42;0040;PBS_Server;Svr;tyrone-cluster;Scheduler was sent the command new
10/03/2014 07:00:12;0040;PBS_Server;Svr;tyrone-cluster;Scheduler was sent the command new
10/03/2014 07:00:41;0040;PBS_Server;Svr;tyrone-cluster;Scheduler was sent the command new
10/03/2014 07:01:11;0040;PBS_Server;Svr;tyrone-cluster;Scheduler was sent the command new
10/03/2014 07:01:42;0040;PBS_Server;Svr;tyrone-cluster;Scheduler was sent the command new
10/03/2014 07:02:11;0040;PBS_Server;Svr;tyrone-cluster;Scheduler was sent the command new
10/03/2014 07:02:44;0040;PBS_Server;Svr;tyrone-cluster;Scheduler was sent the command new
10/03/2014 07:02:50;0002;PBS_Server;Svr;PBS_Server;Torque Server Version = 3.0.5, loglevel = 0
10/03/2014 07:03:11;0040;PBS_Server;Svr;tyrone-cluster;Scheduler was sent the command new
10/03/2014 07:03:41;0040;PBS_Server;Svr;tyrone-cluster;Scheduler was sent the command new
10/03/2014 07:04:14;0040;PBS_Server;Svr;tyrone-cluster;Scheduler was sent the command new
10/03/2014 07:04:42;0040;PBS_Server;Svr;tyrone-cluster;Scheduler was sent the command new
10/03/2014 07:05:14;0040;PBS_Server;Svr;tyrone-cluster;Scheduler was sent the command new
10/03/2014 07:05:44;0040;PBS_Server;Svr;tyrone-cluster;Scheduler was sent the command new
10/03/2014 07:06:15;0040;PBS_Server;Svr;tyrone-cluster;Scheduler was sent the command new
10/03/2014 07:06:51;0040;PBS_Server;Svr;tyrone-cluster;Scheduler was sent the command new
10/03/2014 07:07:26;0040;PBS_Server;Svr;tyrone-cluster;Scheduler was sent the command new
10/03/2014 07:07:50;0002;PBS_Server;Svr;PBS_Server;Torque Server Version = 3.0.5, loglevel = 0
10/03/2014 07:07:56;0040;PBS_Server;Svr;tyrone-cluster;Scheduler was sent the command new
10/03/2014 07:08:26;0040;PBS_Server;Svr;tyrone-cluster;Scheduler was sent the command new
10/03/2014 07:08:56;0040;PBS_Server;Svr;tyrone-cluster;Scheduler was sent the command new
10/03/2014 07:09:26;0040;PBS_Server;Svr;tyrone-cluster;Scheduler was sent the command new
10/03/2014 07:09:57;0040;PBS_Server;Svr;tyrone-cluster;Scheduler was sent the command new
10/03/2014 07:10:26;0040;PBS_Server;Svr;tyrone-cluster;Scheduler was sent the command new
10/03/2014 07:10:57;0040;PBS_Server;Svr;tyrone-cluster;Scheduler was sent the command new
10/03/2014 07:11:27;0040;PBS_Server;Svr;tyrone-cluster;Scheduler was sent the command new
10/03/2014 07:11:56;0040;PBS_Server;Svr;tyrone-cluster;Scheduler was sent the command new
10/03/2014 07:12:26;0040;PBS_Server;Svr;tyrone-cluster;Scheduler was sent the command new
10/03/2014 07:12:50;0002;PBS_Server;Svr;PBS_Server;Torque Server Version = 3.0.5, loglevel = 0
10/03/2014 07:12:56;0040;PBS_Server;Svr;tyrone-cluster;Scheduler was sent the command new
10/03/2014 07:13:26;0040;PBS_Server;Svr;tyrone-cluster;Scheduler was sent the command new
10/03/2014 07:13:59;0040;PBS_Server;Svr;tyrone-cluster;Scheduler was sent the command new
10/03/2014 07:14:27;0040;PBS_Server;Svr;tyrone-cluster;Scheduler was sent the command new
10/03/2014 07:14:56;0040;PBS_Server;Svr;tyrone-cluster;Scheduler was sent the command new
10/03/2014 07:15:27;0040;PBS_Server;Svr;tyrone-cluster;Scheduler was sent the command new
10/03/2014 07:15:57;0040;PBS_Server;Svr;tyrone-cluster;Scheduler was sent the command new
10/03/2014 07:16:26;0040;PBS_Server;Svr;tyrone-cluster;Scheduler was sent the command new
10/03/2014 07:16:57;0040;PBS_Server;Svr;tyrone-cluster;Scheduler was sent the command new
10/03/2014 07:17:27;0040;PBS_Server;Svr;tyrone-cluster;Scheduler was sent the command new
10/03/2014 07:17:50;0002;PBS_Server;Svr;PBS_Server;Torque Server Version = 3.0.5, loglevel = 0
10/03/2014 07:17:56;0040;PBS_Server;Svr;tyrone-cluster;Scheduler was sent the command new
10/03/2014 07:18:29;0040;PBS_Server;Svr;tyrone-cluster;Scheduler was sent the command new
10/03/2014 07:18:57;0040;PBS_Server;Svr;tyrone-cluster;Scheduler was sent the command new
10/03/2014 07:19:26;0040;PBS_Server;Svr;tyrone-cluster;Scheduler was sent the command new
10/03/2014 07:19:59;0040;PBS_Server;Svr;tyrone-cluster;Scheduler was sent the command new
10/03/2014 07:20:27;0040;PBS_Server;Svr;tyrone-cluster;Scheduler was sent the command new
10/03/2014 07:20:59;0040;PBS_Server;Svr;tyrone-cluster;Scheduler was sent the command new
10/03/2014 07:21:29;0040;PBS_Server;Svr;tyrone-cluster;Scheduler was sent the command new
10/03/2014 07:22:00;0040;PBS_Server;Svr;tyrone-cluster;Scheduler was sent the command new
10/03/2014 07:22:36;0040;PBS_Server;Svr;tyrone-cluster;Scheduler was sent the command new
10/03/2014 07:22:50;0002;PBS_Server;Svr;PBS_Server;Torque Server Version = 3.0.5, loglevel = 0
10/03/2014 07:23:09;0040;PBS_Server;Svr;tyrone-cluster;Scheduler was sent the command new
10/03/2014 07:23:40;0040;PBS_Server;Svr;tyrone-cluster;Scheduler was sent the command new
10/03/2014 07:24:11;0040;PBS_Server;Svr;tyrone-cluster;Scheduler was sent the command new
10/03/2014 07:24:41;0040;PBS_Server;Svr;tyrone-cluster;Scheduler was sent the command new
10/03/2014 07:25:14;0040;PBS_Server;Svr;tyrone-cluster;Scheduler was sent the command new
10/03/2014 07:25:42;0040;PBS_Server;Svr;tyrone-cluster;Scheduler was sent the command new
10/03/2014 07:26:13;0040;PBS_Server;Svr;tyrone-cluster;Scheduler was sent the command new
10/03/2014 07:26:44;0040;PBS_Server;Svr;tyrone-cluster;Scheduler was sent the command new
10/03/2014 07:27:15;0040;PBS_Server;Svr;tyrone-cluster;Scheduler was sent the command new
10/03/2014 07:27:50;0002;PBS_Server;Svr;PBS_Server;Torque Server Version = 3.0.5, loglevel = 0
10/03/2014 07:27:51;0040;PBS_Server;Svr;tyrone-cluster;Scheduler was sent the command new
10/03/2014 07:28:26;0040;PBS_Server;Svr;tyrone-cluster;Scheduler was sent the command new
10/03/2014 07:28:56;0040;PBS_Server;Svr;tyrone-cluster;Scheduler was sent the command new
10/03/2014 07:29:27;0040;PBS_Server;Svr;tyrone-cluster;Scheduler was sent the command new
10/03/2014 07:29:56;0040;PBS_Server;Svr;tyrone-cluster;Scheduler was sent the command new
10/03/2014 07:30:27;0040;PBS_Server;Svr;tyrone-cluster;Scheduler was sent the command new
10/03/2014 07:30:57;0040;PBS_Server;Svr;tyrone-cluster;Scheduler was sent the command new
10/03/2014 07:31:26;0040;PBS_Server;Svr;tyrone-cluster;Scheduler was sent the command new
10/03/2014 07:31:59;0040;PBS_Server;Svr;tyrone-cluster;Scheduler was sent the command new
10/03/2014 07:32:27;0040;PBS_Server;Svr;tyrone-cluster;Scheduler was sent the command new
10/03/2014 07:32:50;0002;PBS_Server;Svr;PBS_Server;Torque Server Version = 3.0.5, loglevel = 0
10/03/2014 07:32:56;0040;PBS_Server;Svr;tyrone-cluster;Scheduler was sent the command new
10/03/2014 07:33:29;0040;PBS_Server;Svr;tyrone-cluster;Scheduler was sent the command new
10/03/2014 07:33:57;0040;PBS_Server;Svr;tyrone-cluster;Scheduler was sent the command new
10/03/2014 07:34:26;0040;PBS_Server;Svr;tyrone-cluster;Scheduler was sent the command new
10/03/2014 07:34:59;0040;PBS_Server;Svr;tyrone-cluster;Scheduler was sent the command new
10/03/2014 07:35:27;0040;PBS_Server;Svr;tyrone-cluster;Scheduler was sent the command new
10/03/2014 07:35:58;0040;PBS_Server;Svr;tyrone-cluster;Scheduler was sent the command new
10/03/2014 07:36:29;0040;PBS_Server;Svr;tyrone-cluster;Scheduler was sent the command new
10/03/2014 07:37:00;0040;PBS_Server;Svr;tyrone-cluster;Scheduler was sent the command new
10/03/2014 07:37:35;0040;PBS_Server;Svr;tyrone-cluster;Scheduler was sent the command new
10/03/2014 07:37:50;0002;PBS_Server;Svr;PBS_Server;Torque Server Version = 3.0.5, loglevel = 0
10/03/2014 07:38:09;0040;PBS_Server;Svr;tyrone-cluster;Scheduler was sent the command new
10/03/2014 07:38:40;0040;PBS_Server;Svr;tyrone-cluster;Scheduler was sent the command new
10/03/2014 07:39:11;0040;PBS_Server;Svr;tyrone-cluster;Scheduler was sent the command new
10/03/2014 07:39:41;0040;PBS_Server;Svr;tyrone-cluster;Scheduler was sent the command new
10/03/2014 07:40:12;0040;PBS_Server;Svr;tyrone-cluster;Scheduler was sent the command new
10/03/2014 07:40:42;0040;PBS_Server;Svr;tyrone-cluster;Scheduler was sent the command new
10/03/2014 07:41:13;0040;PBS_Server;Svr;tyrone-cluster;Scheduler was sent the command new
10/03/2014 07:41:44;0040;PBS_Server;Svr;tyrone-cluster;Scheduler was sent the command new
10/03/2014 07:42:14;0040;PBS_Server;Svr;tyrone-cluster;Scheduler was sent the command new
10/03/2014 07:42:50;0002;PBS_Server;Svr;PBS_Server;Torque Server Version = 3.0.5, loglevel = 0
10/03/2014 07:42:50;0040;PBS_Server;Svr;tyrone-cluster;Scheduler was sent the command new
10/03/2014 07:43:26;0040;PBS_Server;Svr;tyrone-cluster;Scheduler was sent the command new
10/03/2014 07:43:56;0040;PBS_Server;Svr;tyrone-cluster;Scheduler was sent the command new
10/03/2014 07:44:26;0040;PBS_Server;Svr;tyrone-cluster;Scheduler was sent the command new
10/03/2014 07:44:56;0040;PBS_Server;Svr;tyrone-cluster;Scheduler was sent the command new
10/03/2014 07:45:27;0040;PBS_Server;Svr;tyrone-cluster;Scheduler was sent the command new
10/03/2014 07:45:57;0040;PBS_Server;Svr;tyrone-cluster;Scheduler was sent the command new
10/03/2014 07:46:28;0040;PBS_Server;Svr;tyrone-cluster;Scheduler was sent the command new
10/03/2014 07:46:59;0040;PBS_Server;Svr;tyrone-cluster;Scheduler was sent the command new
10/03/2014 07:47:29;0040;PBS_Server;Svr;tyrone-cluster;Scheduler was sent the command new
10/03/2014 07:47:50;0002;PBS_Server;Svr;PBS_Server;Torque Server Version = 3.0.5, loglevel = 0
10/03/2014 07:48:05;0040;PBS_Server;Svr;tyrone-cluster;Scheduler was sent the command new
10/03/2014 07:48:41;0040;PBS_Server;Svr;tyrone-cluster;Scheduler was sent the command new
10/03/2014 07:49:11;0040;PBS_Server;Svr;tyrone-cluster;Scheduler was sent the command new
10/03/2014 07:49:42;0040;PBS_Server;Svr;tyrone-cluster;Scheduler was sent the command new
10/03/2014 07:50:11;0040;PBS_Server;Svr;tyrone-cluster;Scheduler was sent the command new
10/03/2014 07:50:44;0040;PBS_Server;Svr;tyrone-cluster;Scheduler was sent the command new
10/03/2014 07:51:12;0040;PBS_Server;Svr;tyrone-cluster;Scheduler was sent the command new
10/03/2014 07:51:43;0040;PBS_Server;Svr;tyrone-cluster;Scheduler was sent the command new
10/03/2014 07:52:14;0040;PBS_Server;Svr;tyrone-cluster;Scheduler was sent the command new
10/03/2014 07:52:44;0040;PBS_Server;Svr;tyrone-cluster;Scheduler was sent the command new
10/03/2014 07:52:50;0002;PBS_Server;Svr;PBS_Server;Torque Server Version = 3.0.5, loglevel = 0
10/03/2014 07:53:21;0040;PBS_Server;Svr;tyrone-cluster;Scheduler was sent the command new
10/03/2014 07:53:49;0040;PBS_Server;Svr;tyrone-cluster;Scheduler was sent the command new
10/03/2014 07:54:19;0040;PBS_Server;Svr;tyrone-cluster;Scheduler was sent the command new
10/03/2014 07:54:50;0040;PBS_Server;Svr;tyrone-cluster;Scheduler was sent the command new
10/03/2014 07:55:26;0040;PBS_Server;Svr;tyrone-cluster;Scheduler was sent the command new
10/03/2014 07:55:56;0040;PBS_Server;Svr;tyrone-cluster;Scheduler was sent the command new
10/03/2014 07:56:27;0040;PBS_Server;Svr;tyrone-cluster;Scheduler was sent the command new
10/03/2014 07:56:56;0040;PBS_Server;Svr;tyrone-cluster;Scheduler was sent the command new
10/03/2014 07:57:29;0040;PBS_Server;Svr;tyrone-cluster;Scheduler was sent the command new
10/03/2014 07:57:50;0002;PBS_Server;Svr;PBS_Server;Torque Server Version = 3.0.5, loglevel = 0
10/03/2014 07:57:57;0040;PBS_Server;Svr;tyrone-cluster;Scheduler was sent the command new
10/03/2014 07:58:28;0040;PBS_Server;Svr;tyrone-cluster;Scheduler was sent the command new
10/03/2014 07:58:59;0040;PBS_Server;Svr;tyrone-cluster;Scheduler was sent the command new
10/03/2014 07:59:29;0040;PBS_Server;Svr;tyrone-cluster;Scheduler was sent the command new
10/03/2014 08:00:05;0040;PBS_Server;Svr;tyrone-cluster;Scheduler was sent the command new
10/03/2014 08:00:34;0040;PBS_Server;Svr;tyrone-cluster;Scheduler was sent the command new
10/03/2014 08:01:04;0040;PBS_Server;Svr;tyrone-cluster;Scheduler was sent the command new
10/03/2014 08:01:35;0040;PBS_Server;Svr;tyrone-cluster;Scheduler was sent the command new
10/03/2014 08:02:11;0040;PBS_Server;Svr;tyrone-cluster;Scheduler was sent the command new
10/03/2014 08:02:41;0040;PBS_Server;Svr;tyrone-cluster;Scheduler was sent the command new
10/03/2014 08:02:50;0002;PBS_Server;Svr;PBS_Server;Torque Server Version = 3.0.5, loglevel = 0
10/03/2014 08:03:12;0040;PBS_Server;Svr;tyrone-cluster;Scheduler was sent the command new
10/03/2014 08:03:43;0040;PBS_Server;Svr;tyrone-cluster;Scheduler was sent the command new
10/03/2014 08:04:14;0040;PBS_Server;Svr;tyrone-cluster;Scheduler was sent the command new
10/03/2014 08:04:44;0040;PBS_Server;Svr;tyrone-cluster;Scheduler was sent the command new
10/03/2014 08:05:20;0040;PBS_Server;Svr;tyrone-cluster;Scheduler was sent the command new
10/03/2014 08:05:56;0040;PBS_Server;Svr;tyrone-cluster;Scheduler was sent the command new
10/03/2014 08:06:26;0040;PBS_Server;Svr;tyrone-cluster;Scheduler was sent the command new
10/03/2014 08:06:57;0040;PBS_Server;Svr;tyrone-cluster;Scheduler was sent the command new
10/03/2014 08:07:26;0040;PBS_Server;Svr;tyrone-cluster;Scheduler was sent the command new
10/03/2014 08:07:50;0002;PBS_Server;Svr;PBS_Server;Torque Server Version = 3.0.5, loglevel = 0
10/03/2014 08:07:59;0040;PBS_Server;Svr;tyrone-cluster;Scheduler was sent the command new
10/03/2014 08:08:27;0040;PBS_Server;Svr;tyrone-cluster;Scheduler was sent the command new
10/03/2014 08:08:56;0040;PBS_Server;Svr;tyrone-cluster;Scheduler was sent the command new
10/03/2014 08:09:29;0040;PBS_Server;Svr;tyrone-cluster;Scheduler was sent the command new
10/03/2014 08:09:57;0040;PBS_Server;Svr;tyrone-cluster;Scheduler was sent the command new
10/03/2014 08:10:26;0040;PBS_Server;Svr;tyrone-cluster;Scheduler was sent the command new
10/03/2014 08:10:59;0040;PBS_Server;Svr;tyrone-cluster;Scheduler was sent the command new
10/03/2014 08:11:27;0040;PBS_Server;Svr;tyrone-cluster;Scheduler was sent the command new
10/03/2014 08:11:56;0040;PBS_Server;Svr;tyrone-cluster;Scheduler was sent the command new
10/03/2014 08:12:29;0040;PBS_Server;Svr;tyrone-cluster;Scheduler was sent the command new
10/03/2014 08:12:50;0002;PBS_Server;Svr;PBS_Server;Torque Server Version = 3.0.5, loglevel = 0
10/03/2014 08:12:57;0040;PBS_Server;Svr;tyrone-cluster;Scheduler was sent the command new
10/03/2014 08:13:26;0040;PBS_Server;Svr;tyrone-cluster;Scheduler was sent the command new
10/03/2014 08:13:59;0040;PBS_Server;Svr;tyrone-cluster;Scheduler was sent the command new
10/03/2014 08:14:27;0040;PBS_Server;Svr;tyrone-cluster;Scheduler was sent the command new
10/03/2014 08:14:56;0040;PBS_Server;Svr;tyrone-cluster;Scheduler was sent the command new
10/03/2014 08:15:29;0040;PBS_Server;Svr;tyrone-cluster;Scheduler was sent the command new
10/03/2014 08:15:57;0040;PBS_Server;Svr;tyrone-cluster;Scheduler was sent the command new
10/03/2014 08:16:26;0040;PBS_Server;Svr;tyrone-cluster;Scheduler was sent the command new
10/03/2014 08:16:59;0040;PBS_Server;Svr;tyrone-cluster;Scheduler was sent the command new
10/03/2014 08:17:27;0040;PBS_Server;Svr;tyrone-cluster;Scheduler was sent the command new
10/03/2014 08:17:50;0002;PBS_Server;Svr;PBS_Server;Torque Server Version = 3.0.5, loglevel = 0
10/03/2014 08:17:56;0040;PBS_Server;Svr;tyrone-cluster;Scheduler was sent the command new
10/03/2014 08:18:29;0040;PBS_Server;Svr;tyrone-cluster;Scheduler was sent the command new
10/03/2014 08:18:57;0040;PBS_Server;Svr;tyrone-cluster;Scheduler was sent the command new
10/03/2014 08:19:26;0040;PBS_Server;Svr;tyrone-cluster;Scheduler was sent the command new
10/03/2014 08:19:59;0040;PBS_Server;Svr;tyrone-cluster;Scheduler was sent the command new
10/03/2014 08:20:27;0040;PBS_Server;Svr;tyrone-cluster;Scheduler was sent the command new
10/03/2014 08:20:56;0040;PBS_Server;Svr;tyrone-cluster;Scheduler was sent the command new
10/03/2014 08:21:29;0040;PBS_Server;Svr;tyrone-cluster;Scheduler was sent the command new
10/03/2014 08:21:57;0040;PBS_Server;Svr;tyrone-cluster;Scheduler was sent the command new
10/03/2014 08:22:26;0040;PBS_Server;Svr;tyrone-cluster;Scheduler was sent the command new
10/03/2014 08:22:50;0002;PBS_Server;Svr;PBS_Server;Torque Server Version = 3.0.5, loglevel = 0
10/03/2014 08:22:59;0040;PBS_Server;Svr;tyrone-cluster;Scheduler was sent the command new
10/03/2014 08:23:27;0040;PBS_Server;Svr;tyrone-cluster;Scheduler was sent the command new
10/03/2014 08:23:57;0040;PBS_Server;Svr;tyrone-cluster;Scheduler was sent the command new
10/03/2014 08:24:29;0040;PBS_Server;Svr;tyrone-cluster;Scheduler was sent the command new
10/03/2014 08:24:59;0040;PBS_Server;Svr;tyrone-cluster;Scheduler was sent the command new
10/03/2014 08:25:35;0040;PBS_Server;Svr;tyrone-cluster;Scheduler was sent the command new
10/03/2014 08:26:04;0040;PBS_Server;Svr;tyrone-cluster;Scheduler was sent the command new
10/03/2014 08:26:34;0040;PBS_Server;Svr;tyrone-cluster;Scheduler was sent the command new
10/03/2014 08:27:05;0040;PBS_Server;Svr;tyrone-cluster;Scheduler was sent the command new
10/03/2014 08:27:39;0040;PBS_Server;Svr;tyrone-cluster;Scheduler was sent the command new
10/03/2014 08:27:50;0002;PBS_Server;Svr;PBS_Server;Torque Server Version = 3.0.5, loglevel = 0
10/03/2014 08:28:06;0040;PBS_Server;Svr;tyrone-cluster;Scheduler was sent the command new
10/03/2014 08:28:36;0040;PBS_Server;Svr;tyrone-cluster;Scheduler was sent the command new
10/03/2014 08:29:11;0040;PBS_Server;Svr;tyrone-cluster;Scheduler was sent the command new
10/03/2014 08:29:41;0040;PBS_Server;Svr;tyrone-cluster;Scheduler was sent the command new
10/03/2014 08:30:11;0040;PBS_Server;Svr;tyrone-cluster;Scheduler was sent the command new
10/03/2014 08:30:41;0040;PBS_Server;Svr;tyrone-cluster;Scheduler was sent the command new
10/03/2014 08:31:14;0040;PBS_Server;Svr;tyrone-cluster;Scheduler was sent the command new
10/03/2014 08:31:42;0040;PBS_Server;Svr;tyrone-cluster;Scheduler was sent the command new
10/03/2014 08:32:11;0040;PBS_Server;Svr;tyrone-cluster;Scheduler was sent the command new
10/03/2014 08:32:44;0040;PBS_Server;Svr;tyrone-cluster;Scheduler was sent the command new
10/03/2014 08:32:50;0002;PBS_Server;Svr;PBS_Server;Torque Server Version = 3.0.5, loglevel = 0
10/03/2014 08:33:12;0040;PBS_Server;Svr;tyrone-cluster;Scheduler was sent the command new
10/03/2014 08:33:43;0040;PBS_Server;Svr;tyrone-cluster;Scheduler was sent the command new
10/03/2014 08:34:14;0040;PBS_Server;Svr;tyrone-cluster;Scheduler was sent the command new
10/03/2014 08:34:44;0040;PBS_Server;Svr;tyrone-cluster;Scheduler was sent the command new
10/03/2014 08:35:21;0040;PBS_Server;Svr;tyrone-cluster;Scheduler was sent the command new
10/03/2014 08:35:49;0040;PBS_Server;Svr;tyrone-cluster;Scheduler was sent the command new
10/03/2014 08:36:21;0040;PBS_Server;Svr;tyrone-cluster;Scheduler was sent the command new
10/03/2014 08:36:54;0040;PBS_Server;Svr;tyrone-cluster;Scheduler was sent the command new
10/03/2014 08:37:26;0040;PBS_Server;Svr;tyrone-cluster;Scheduler was sent the command new
10/03/2014 08:37:50;0002;PBS_Server;Svr;PBS_Server;Torque Server Version = 3.0.5, loglevel = 0
10/03/2014 08:37:56;0040;PBS_Server;Svr;tyrone-cluster;Scheduler was sent the command new
10/03/2014 08:38:25;0040;PBS_Server;Svr;tyrone-cluster;Scheduler was sent the command new
10/03/2014 08:38:56;0040;PBS_Server;Svr;tyrone-cluster;Scheduler was sent the command new
10/03/2014 08:39:26;0040;PBS_Server;Svr;tyrone-cluster;Scheduler was sent the command new
10/03/2014 08:39:56;0040;PBS_Server;Svr;tyrone-cluster;Scheduler was sent the command new
10/03/2014 08:40:26;0040;PBS_Server;Svr;tyrone-cluster;Scheduler was sent the command new
10/03/2014 08:40:59;0040;PBS_Server;Svr;tyrone-cluster;Scheduler was sent the command new
10/03/2014 08:41:27;0040;PBS_Server;Svr;tyrone-cluster;Scheduler was sent the command new
10/03/2014 08:41:56;0040;PBS_Server;Svr;tyrone-cluster;Scheduler was sent the command new
10/03/2014 08:42:29;0040;PBS_Server;Svr;tyrone-cluster;Scheduler was sent the command new
10/03/2014 08:42:50;0002;PBS_Server;Svr;PBS_Server;Torque Server Version = 3.0.5, loglevel = 0
10/03/2014 08:42:57;0040;PBS_Server;Svr;tyrone-cluster;Scheduler was sent the command new
10/03/2014 08:43:28;0040;PBS_Server;Svr;tyrone-cluster;Scheduler was sent the command new
10/03/2014 08:43:59;0040;PBS_Server;Svr;tyrone-cluster;Scheduler was sent the command new
10/03/2014 08:44:29;0040;PBS_Server;Svr;tyrone-cluster;Scheduler was sent the command new
10/03/2014 08:45:06;0040;PBS_Server;Svr;tyrone-cluster;Scheduler was sent the command new
10/03/2014 08:45:34;0040;PBS_Server;Svr;tyrone-cluster;Scheduler was sent the command new
10/03/2014 08:46:06;0040;PBS_Server;Svr;tyrone-cluster;Scheduler was sent the command new
10/03/2014 08:46:39;0040;PBS_Server;Svr;tyrone-cluster;Scheduler was sent the command new
10/03/2014 08:47:11;0040;PBS_Server;Svr;tyrone-cluster;Scheduler was sent the command new
10/03/2014 08:47:41;0040;PBS_Server;Svr;tyrone-cluster;Scheduler was sent the command new
10/03/2014 08:47:50;0002;PBS_Server;Svr;PBS_Server;Torque Server Version = 3.0.5, loglevel = 0
10/03/2014 08:48:10;0040;PBS_Server;Svr;tyrone-cluster;Scheduler was sent the command new
10/03/2014 08:48:41;0040;PBS_Server;Svr;tyrone-cluster;Scheduler was sent the command new
10/03/2014 08:49:11;0040;PBS_Server;Svr;tyrone-cluster;Scheduler was sent the command new
10/03/2014 08:49:42;0040;PBS_Server;Svr;tyrone-cluster;Scheduler was sent the command new
10/03/2014 08:50:11;0040;PBS_Server;Svr;tyrone-cluster;Scheduler was sent the command new
10/03/2014 08:50:44;0040;PBS_Server;Svr;tyrone-cluster;Scheduler was sent the command new
10/03/2014 08:51:12;0040;PBS_Server;Svr;tyrone-cluster;Scheduler was sent the command new
10/03/2014 08:51:41;0040;PBS_Server;Svr;tyrone-cluster;Scheduler was sent the command new
10/03/2014 08:52:14;0040;PBS_Server;Svr;tyrone-cluster;Scheduler was sent the command new
10/03/2014 08:52:42;0040;PBS_Server;Svr;tyrone-cluster;Scheduler was sent the command new
10/03/2014 08:52:50;0002;PBS_Server;Svr;PBS_Server;Torque Server Version = 3.0.5, loglevel = 0
10/03/2014 08:53:18;0040;PBS_Server;Svr;tyrone-cluster;Scheduler was sent the command new
10/03/2014 08:53:44;0040;PBS_Server;Svr;tyrone-cluster;Scheduler was sent the command new
10/03/2014 08:54:14;0040;PBS_Server;Svr;tyrone-cluster;Scheduler was sent the command new
10/03/2014 08:54:51;0040;PBS_Server;Svr;tyrone-cluster;Scheduler was sent the command new
10/03/2014 08:55:19;0040;PBS_Server;Svr;tyrone-cluster;Scheduler was sent the command new
10/03/2014 08:55:51;0040;PBS_Server;Svr;tyrone-cluster;Scheduler was sent the command new
10/03/2014 08:56:24;0040;PBS_Server;Svr;tyrone-cluster;Scheduler was sent the command new
10/03/2014 08:56:56;0040;PBS_Server;Svr;tyrone-cluster;Scheduler was sent the command new
10/03/2014 08:57:26;0040;PBS_Server;Svr;tyrone-cluster;Scheduler was sent the command new
10/03/2014 08:57:50;0002;PBS_Server;Svr;PBS_Server;Torque Server Version = 3.0.5, loglevel = 0
10/03/2014 08:57:55;0040;PBS_Server;Svr;tyrone-cluster;Scheduler was sent the command new
10/03/2014 08:58:26;0040;PBS_Server;Svr;tyrone-cluster;Scheduler was sent the command new
10/03/2014 08:58:56;0040;PBS_Server;Svr;tyrone-cluster;Scheduler was sent the command new
10/03/2014 08:59:27;0040;PBS_Server;Svr;tyrone-cluster;Scheduler was sent the command new
10/03/2014 08:59:56;0040;PBS_Server;Svr;tyrone-cluster;Scheduler was sent the command new
10/03/2014 09:00:29;0040;PBS_Server;Svr;tyrone-cluster;Scheduler was sent the command new
10/03/2014 09:00:57;0040;PBS_Server;Svr;tyrone-cluster;Scheduler was sent the command new
10/03/2014 09:01:26;0040;PBS_Server;Svr;tyrone-cluster;Scheduler was sent the command new
10/03/2014 09:01:59;0040;PBS_Server;Svr;tyrone-cluster;Scheduler was sent the command new
10/03/2014 09:02:27;0040;PBS_Server;Svr;tyrone-cluster;Scheduler was sent the command new
10/03/2014 09:02:50;0002;PBS_Server;Svr;PBS_Server;Torque Server Version = 3.0.5, loglevel = 0
10/03/2014 09:03:03;0040;PBS_Server;Svr;tyrone-cluster;Scheduler was sent the command new
10/03/2014 09:03:29;0040;PBS_Server;Svr;tyrone-cluster;Scheduler was sent the command new
10/03/2014 09:04:01;0040;PBS_Server;Svr;tyrone-cluster;Scheduler was sent the command new
10/03/2014 09:04:36;0040;PBS_Server;Svr;tyrone-cluster;Scheduler was sent the command new
10/03/2014 09:05:04;0040;PBS_Server;Svr;tyrone-cluster;Scheduler was sent the command new
10/03/2014 09:05:36;0040;PBS_Server;Svr;tyrone-cluster;Scheduler was sent the command new
10/03/2014 09:06:09;0040;PBS_Server;Svr;tyrone-cluster;Scheduler was sent the command new
10/03/2014 09:06:41;0040;PBS_Server;Svr;tyrone-cluster;Scheduler was sent the command new
10/03/2014 09:07:11;0040;PBS_Server;Svr;tyrone-cluster;Scheduler was sent the command new
10/03/2014 09:07:40;0040;PBS_Server;Svr;tyrone-cluster;Scheduler was sent the command new
10/03/2014 09:07:50;0002;PBS_Server;Svr;PBS_Server;Torque Server Version = 3.0.5, loglevel = 0
10/03/2014 09:08:11;0040;PBS_Server;Svr;tyrone-cluster;Scheduler was sent the command new
10/03/2014 09:08:41;0040;PBS_Server;Svr;tyrone-cluster;Scheduler was sent the command new
10/03/2014 09:09:12;0040;PBS_Server;Svr;tyrone-cluster;Scheduler was sent the command new
10/03/2014 09:09:41;0040;PBS_Server;Svr;tyrone-cluster;Scheduler was sent the command new
10/03/2014 09:10:14;0040;PBS_Server;Svr;tyrone-cluster;Scheduler was sent the command new
10/03/2014 09:10:42;0040;PBS_Server;Svr;tyrone-cluster;Scheduler was sent the command new
10/03/2014 09:11:11;0040;PBS_Server;Svr;tyrone-cluster;Scheduler was sent the command new
10/03/2014 09:11:44;0040;PBS_Server;Svr;tyrone-cluster;Scheduler was sent the command new
10/03/2014 09:12:12;0040;PBS_Server;Svr;tyrone-cluster;Scheduler was sent the command new
10/03/2014 09:12:50;0002;PBS_Server;Svr;PBS_Server;Torque Server Version = 3.0.5, loglevel = 0
10/03/2014 09:12:50;0040;PBS_Server;Svr;tyrone-cluster;Scheduler was sent the command new
10/03/2014 09:13:19;0040;PBS_Server;Svr;tyrone-cluster;Scheduler was sent the command new
10/03/2014 09:13:49;0040;PBS_Server;Svr;tyrone-cluster;Scheduler was sent the command new
10/03/2014 09:14:21;0040;PBS_Server;Svr;tyrone-cluster;Scheduler was sent the command new
10/03/2014 09:14:49;0040;PBS_Server;Svr;tyrone-cluster;Scheduler was sent the command new
10/03/2014 09:15:21;0040;PBS_Server;Svr;tyrone-cluster;Scheduler was sent the command new
10/03/2014 09:15:54;0040;PBS_Server;Svr;tyrone-cluster;Scheduler was sent the command new
10/03/2014 09:16:26;0040;PBS_Server;Svr;tyrone-cluster;Scheduler was sent the command new
10/03/2014 09:16:56;0040;PBS_Server;Svr;tyrone-cluster;Scheduler was sent the command new
10/03/2014 09:17:25;0040;PBS_Server;Svr;tyrone-cluster;Scheduler was sent the command new
10/03/2014 09:17:50;0002;PBS_Server;Svr;PBS_Server;Torque Server Version = 3.0.5, loglevel = 0
10/03/2014 09:17:56;0040;PBS_Server;Svr;tyrone-cluster;Scheduler was sent the command new
10/03/2014 09:18:26;0040;PBS_Server;Svr;tyrone-cluster;Scheduler was sent the command new
10/03/2014 09:18:57;0040;PBS_Server;Svr;tyrone-cluster;Scheduler was sent the command new
10/03/2014 09:19:26;0040;PBS_Server;Svr;tyrone-cluster;Scheduler was sent the command new
10/03/2014 09:19:59;0040;PBS_Server;Svr;tyrone-cluster;Scheduler was sent the command new
10/03/2014 09:20:27;0040;PBS_Server;Svr;tyrone-cluster;Scheduler was sent the command new
10/03/2014 09:20:56;0040;PBS_Server;Svr;tyrone-cluster;Scheduler was sent the command new
10/03/2014 09:21:29;0040;PBS_Server;Svr;tyrone-cluster;Scheduler was sent the command new
10/03/2014 09:21:57;0040;PBS_Server;Svr;tyrone-cluster;Scheduler was sent the command new
10/03/2014 09:22:36;0040;PBS_Server;Svr;tyrone-cluster;Scheduler was sent the command new
10/03/2014 09:22:50;0002;PBS_Server;Svr;PBS_Server;Torque Server Version = 3.0.5, loglevel = 0
10/03/2014 09:23:04;0040;PBS_Server;Svr;tyrone-cluster;Scheduler was sent the command new
10/03/2014 09:23:35;0040;PBS_Server;Svr;tyrone-cluster;Scheduler was sent the command new
10/03/2014 09:24:07;0040;PBS_Server;Svr;tyrone-cluster;Scheduler was sent the command new
10/03/2014 09:24:34;0040;PBS_Server;Svr;tyrone-cluster;Scheduler was sent the command new
10/03/2014 09:25:06;0040;PBS_Server;Svr;tyrone-cluster;Scheduler was sent the command new
10/03/2014 09:25:37;0040;PBS_Server;Svr;tyrone-cluster;Scheduler was sent the command new
10/03/2014 09:26:11;0040;PBS_Server;Svr;tyrone-cluster;Scheduler was sent the command new
10/03/2014 09:26:41;0040;PBS_Server;Svr;tyrone-cluster;Scheduler was sent the command new
10/03/2014 09:27:12;0040;PBS_Server;Svr;tyrone-cluster;Scheduler was sent the command new
10/03/2014 09:27:41;0040;PBS_Server;Svr;tyrone-cluster;Scheduler was sent the command new
10/03/2014 09:27:50;0002;PBS_Server;Svr;PBS_Server;Torque Server Version = 3.0.5, loglevel = 0
10/03/2014 09:28:14;0040;PBS_Server;Svr;tyrone-cluster;Scheduler was sent the command new
10/03/2014 09:28:42;0040;PBS_Server;Svr;tyrone-cluster;Scheduler was sent the command new
10/03/2014 09:29:11;0040;PBS_Server;Svr;tyrone-cluster;Scheduler was sent the command new
10/03/2014 09:29:44;0040;PBS_Server;Svr;tyrone-cluster;Scheduler was sent the command new
10/03/2014 09:30:12;0040;PBS_Server;Svr;tyrone-cluster;Scheduler was sent the command new
10/03/2014 09:30:51;0040;PBS_Server;Svr;tyrone-cluster;Scheduler was sent the command new
10/03/2014 09:31:19;0040;PBS_Server;Svr;tyrone-cluster;Scheduler was sent the command new
10/03/2014 09:31:49;0040;PBS_Server;Svr;tyrone-cluster;Scheduler was sent the command new
10/03/2014 09:32:21;0040;PBS_Server;Svr;tyrone-cluster;Scheduler was sent the command new
10/03/2014 09:32:49;0040;PBS_Server;Svr;tyrone-cluster;Scheduler was sent the command new
10/03/2014 09:32:50;0002;PBS_Server;Svr;PBS_Server;Torque Server Version = 3.0.5, loglevel = 0
10/03/2014 09:33:21;0040;PBS_Server;Svr;tyrone-cluster;Scheduler was sent the command new
10/03/2014 09:33:53;0040;PBS_Server;Svr;tyrone-cluster;Scheduler was sent the command new
10/03/2014 09:34:26;0040;PBS_Server;Svr;tyrone-cluster;Scheduler was sent the command new
10/03/2014 09:34:56;0040;PBS_Server;Svr;tyrone-cluster;Scheduler was sent the command new
10/03/2014 09:35:27;0040;PBS_Server;Svr;tyrone-cluster;Scheduler was sent the command new
10/03/2014 09:35:56;0040;PBS_Server;Svr;tyrone-cluster;Scheduler was sent the command new
10/03/2014 09:36:29;0040;PBS_Server;Svr;tyrone-cluster;Scheduler was sent the command new
10/03/2014 09:36:57;0040;PBS_Server;Svr;tyrone-cluster;Scheduler was sent the command new
10/03/2014 09:37:36;0040;PBS_Server;Svr;tyrone-cluster;Scheduler was sent the command new
10/03/2014 09:37:50;0002;PBS_Server;Svr;PBS_Server;Torque Server Version = 3.0.5, loglevel = 0
10/03/2014 09:38:04;0040;PBS_Server;Svr;tyrone-cluster;Scheduler was sent the command new
10/03/2014 09:38:35;0040;PBS_Server;Svr;tyrone-cluster;Scheduler was sent the command new
10/03/2014 09:39:08;0040;PBS_Server;Svr;tyrone-cluster;Scheduler was sent the command new
10/03/2014 09:39:41;0040;PBS_Server;Svr;tyrone-cluster;Scheduler was sent the command new
10/03/2014 09:40:11;0040;PBS_Server;Svr;tyrone-cluster;Scheduler was sent the command new
10/03/2014 09:40:42;0040;PBS_Server;Svr;tyrone-cluster;Scheduler was sent the command new
10/03/2014 09:41:11;0040;PBS_Server;Svr;tyrone-cluster;Scheduler was sent the command new
10/03/2014 09:41:44;0040;PBS_Server;Svr;tyrone-cluster;Scheduler was sent the command new
10/03/2014 09:42:12;0040;PBS_Server;Svr;tyrone-cluster;Scheduler was sent the command new
10/03/2014 09:42:50;0002;PBS_Server;Svr;PBS_Server;Torque Server Version = 3.0.5, loglevel = 0
10/03/2014 09:42:50;0040;PBS_Server;Svr;tyrone-cluster;Scheduler was sent the command new
10/03/2014 09:43:19;0040;PBS_Server;Svr;tyrone-cluster;Scheduler was sent the command new
10/03/2014 09:43:49;0040;PBS_Server;Svr;tyrone-cluster;Scheduler was sent the command new
10/03/2014 09:44:21;0040;PBS_Server;Svr;tyrone-cluster;Scheduler was sent the command new
10/03/2014 09:44:49;0040;PBS_Server;Svr;tyrone-cluster;Scheduler was sent the command new
10/03/2014 09:45:21;0040;PBS_Server;Svr;tyrone-cluster;Scheduler was sent the command new
10/03/2014 09:45:53;0040;PBS_Server;Svr;tyrone-cluster;Scheduler was sent the command new
10/03/2014 09:46:26;0040;PBS_Server;Svr;tyrone-cluster;Scheduler was sent the command new
10/03/2014 09:46:56;0040;PBS_Server;Svr;tyrone-cluster;Scheduler was sent the command new
10/03/2014 09:47:27;0040;PBS_Server;Svr;tyrone-cluster;Scheduler was sent the command new
10/03/2014 09:47:50;0002;PBS_Server;Svr;PBS_Server;Torque Server Version = 3.0.5, loglevel = 0
10/03/2014 09:47:56;0040;PBS_Server;Svr;tyrone-cluster;Scheduler was sent the command new
10/03/2014 09:48:29;0040;PBS_Server;Svr;tyrone-cluster;Scheduler was sent the command new
10/03/2014 09:48:57;0040;PBS_Server;Svr;tyrone-cluster;Scheduler was sent the command new
10/03/2014 09:49:36;0040;PBS_Server;Svr;tyrone-cluster;Scheduler was sent the command new
10/03/2014 09:50:04;0040;PBS_Server;Svr;tyrone-cluster;Scheduler was sent the command new
10/03/2014 09:50:34;0040;PBS_Server;Svr;tyrone-cluster;Scheduler was sent the command new
10/03/2014 09:51:08;0040;PBS_Server;Svr;tyrone-cluster;Scheduler was sent the command new
10/03/2014 09:51:41;0040;PBS_Server;Svr;tyrone-cluster;Scheduler was sent the command new
10/03/2014 09:52:11;0040;PBS_Server;Svr;tyrone-cluster;Scheduler was sent the command new
10/03/2014 09:52:42;0040;PBS_Server;Svr;tyrone-cluster;Scheduler was sent the command new
10/03/2014 09:52:50;0002;PBS_Server;Svr;PBS_Server;Torque Server Version = 3.0.5, loglevel = 0
10/03/2014 09:53:11;0040;PBS_Server;Svr;tyrone-cluster;Scheduler was sent the command new
10/03/2014 09:53:44;0040;PBS_Server;Svr;tyrone-cluster;Scheduler was sent the command new
10/03/2014 09:54:12;0040;PBS_Server;Svr;tyrone-cluster;Scheduler was sent the command new
10/03/2014 09:54:52;0040;PBS_Server;Svr;tyrone-cluster;Scheduler was sent the command new
10/03/2014 09:55:19;0040;PBS_Server;Svr;tyrone-cluster;Scheduler was sent the command new
10/03/2014 09:55:50;0040;PBS_Server;Svr;tyrone-cluster;Scheduler was sent the command new
10/03/2014 09:56:23;0040;PBS_Server;Svr;tyrone-cluster;Scheduler was sent the command new
10/03/2014 09:56:55;0040;PBS_Server;Svr;tyrone-cluster;Scheduler was sent the command new
10/03/2014 09:57:25;0040;PBS_Server;Svr;tyrone-cluster;Scheduler was sent the command new
10/03/2014 09:57:50;0002;PBS_Server;Svr;PBS_Server;Torque Server Version = 3.0.5, loglevel = 0
10/03/2014 09:57:57;0040;PBS_Server;Svr;tyrone-cluster;Scheduler was sent the command new
10/03/2014 09:58:26;0040;PBS_Server;Svr;tyrone-cluster;Scheduler was sent the command new
10/03/2014 09:58:59;0040;PBS_Server;Svr;tyrone-cluster;Scheduler was sent the command new
10/03/2014 09:59:27;0040;PBS_Server;Svr;tyrone-cluster;Scheduler was sent the command new
10/03/2014 10:00:06;0040;PBS_Server;Svr;tyrone-cluster;Scheduler was sent the command new
10/03/2014 10:00:34;0040;PBS_Server;Svr;tyrone-cluster;Scheduler was sent the command new
10/03/2014 10:01:05;0040;PBS_Server;Svr;tyrone-cluster;Scheduler was sent the command new
10/03/2014 10:01:37;0040;PBS_Server;Svr;tyrone-cluster;Scheduler was sent the command new
10/03/2014 10:02:11;0040;PBS_Server;Svr;tyrone-cluster;Scheduler was sent the command new
10/03/2014 10:02:41;0040;PBS_Server;Svr;tyrone-cluster;Scheduler was sent the command new
10/03/2014 10:02:50;0002;PBS_Server;Svr;PBS_Server;Torque Server Version = 3.0.5, loglevel = 0
10/03/2014 10:03:12;0040;PBS_Server;Svr;tyrone-cluster;Scheduler was sent the command new
10/03/2014 10:03:41;0040;PBS_Server;Svr;tyrone-cluster;Scheduler was sent the command new
10/03/2014 10:04:14;0040;PBS_Server;Svr;tyrone-cluster;Scheduler was sent the command new
10/03/2014 10:04:42;0040;PBS_Server;Svr;tyrone-cluster;Scheduler was sent the command new
10/03/2014 10:05:21;0040;PBS_Server;Svr;tyrone-cluster;Scheduler was sent the command new
10/03/2014 10:05:49;0040;PBS_Server;Svr;tyrone-cluster;Scheduler was sent the command new
10/03/2014 10:06:20;0040;PBS_Server;Svr;tyrone-cluster;Scheduler was sent the command new
10/03/2014 10:06:52;0040;PBS_Server;Svr;tyrone-cluster;Scheduler was sent the command new
10/03/2014 10:07:25;0040;PBS_Server;Svr;tyrone-cluster;Scheduler was sent the command new
10/03/2014 10:07:50;0002;PBS_Server;Svr;PBS_Server;Torque Server Version = 3.0.5, loglevel = 0
10/03/2014 10:07:56;0040;PBS_Server;Svr;tyrone-cluster;Scheduler was sent the command new
10/03/2014 10:08:27;0040;PBS_Server;Svr;tyrone-cluster;Scheduler was sent the command new
10/03/2014 10:08:56;0040;PBS_Server;Svr;tyrone-cluster;Scheduler was sent the command new
10/03/2014 10:09:29;0040;PBS_Server;Svr;tyrone-cluster;Scheduler was sent the command new
10/03/2014 10:09:57;0040;PBS_Server;Svr;tyrone-cluster;Scheduler was sent the command new
10/03/2014 10:10:36;0040;PBS_Server;Svr;tyrone-cluster;Scheduler was sent the command new
10/03/2014 10:11:04;0040;PBS_Server;Svr;tyrone-cluster;Scheduler was sent the command new
10/03/2014 10:11:35;0040;PBS_Server;Svr;tyrone-cluster;Scheduler was sent the command new
10/03/2014 10:12:07;0040;PBS_Server;Svr;tyrone-cluster;Scheduler was sent the command new
10/03/2014 10:12:40;0040;PBS_Server;Svr;tyrone-cluster;Scheduler was sent the command new
10/03/2014 10:12:50;0002;PBS_Server;Svr;PBS_Server;Torque Server Version = 3.0.5, loglevel = 0
10/03/2014 10:13:10;0040;PBS_Server;Svr;tyrone-cluster;Scheduler was sent the command new
10/03/2014 10:13:41;0040;PBS_Server;Svr;tyrone-cluster;Scheduler was sent the command new
10/03/2014 10:14:11;0040;PBS_Server;Svr;tyrone-cluster;Scheduler was sent the command new
10/03/2014 10:14:44;0040;PBS_Server;Svr;tyrone-cluster;Scheduler was sent the command new
10/03/2014 10:15:12;0040;PBS_Server;Svr;tyrone-cluster;Scheduler was sent the command new
10/03/2014 10:15:52;0040;PBS_Server;Svr;tyrone-cluster;Scheduler was sent the command new
10/03/2014 10:16:19;0040;PBS_Server;Svr;tyrone-cluster;Scheduler was sent the command new
10/03/2014 10:16:51;0040;PBS_Server;Svr;tyrone-cluster;Scheduler was sent the command new
10/03/2014 10:17:22;0040;PBS_Server;Svr;tyrone-cluster;Scheduler was sent the command new
10/03/2014 10:17:50;0002;PBS_Server;Svr;PBS_Server;Torque Server Version = 3.0.5, loglevel = 0
10/03/2014 10:17:55;0040;PBS_Server;Svr;tyrone-cluster;Scheduler was sent the command new
10/03/2014 10:18:29;0040;PBS_Server;Svr;tyrone-cluster;Scheduler was sent the command new
10/03/2014 10:18:56;0040;PBS_Server;Svr;tyrone-cluster;Scheduler was sent the command new
10/03/2014 10:19:26;0040;PBS_Server;Svr;tyrone-cluster;Scheduler was sent the command new
10/03/2014 10:19:59;0040;PBS_Server;Svr;tyrone-cluster;Scheduler was sent the command new
10/03/2014 10:20:27;0040;PBS_Server;Svr;tyrone-cluster;Scheduler was sent the command new
10/03/2014 10:21:07;0040;PBS_Server;Svr;tyrone-cluster;Scheduler was sent the command new
10/03/2014 10:21:34;0040;PBS_Server;Svr;tyrone-cluster;Scheduler was sent the command new
10/03/2014 10:22:06;0040;PBS_Server;Svr;tyrone-cluster;Scheduler was sent the command new
10/03/2014 10:22:37;0040;PBS_Server;Svr;tyrone-cluster;Scheduler was sent the command new
10/03/2014 10:22:50;0002;PBS_Server;Svr;PBS_Server;Torque Server Version = 3.0.5, loglevel = 0
10/03/2014 10:23:09;0040;PBS_Server;Svr;tyrone-cluster;Scheduler was sent the command new
10/03/2014 10:23:38;0040;PBS_Server;Svr;tyrone-cluster;Scheduler was sent the command new
10/03/2014 10:24:07;0040;PBS_Server;Svr;tyrone-cluster;Scheduler was sent the command new
10/03/2014 10:24:40;0040;PBS_Server;Svr;tyrone-cluster;Scheduler was sent the command new
10/03/2014 10:25:14;0040;PBS_Server;Svr;tyrone-cluster;Scheduler was sent the command new
10/03/2014 10:25:41;0040;PBS_Server;Svr;tyrone-cluster;Scheduler was sent the command new
10/03/2014 10:26:11;0040;PBS_Server;Svr;tyrone-cluster;Scheduler was sent the command new
10/03/2014 10:26:44;0040;PBS_Server;Svr;tyrone-cluster;Scheduler was sent the command new
10/03/2014 10:27:12;0040;PBS_Server;Svr;tyrone-cluster;Scheduler was sent the command new
10/03/2014 10:27:50;0002;PBS_Server;Svr;PBS_Server;Torque Server Version = 3.0.5, loglevel = 0
10/03/2014 10:27:50;0040;PBS_Server;Svr;tyrone-cluster;Scheduler was sent the command new
10/03/2014 10:28:19;0040;PBS_Server;Svr;tyrone-cluster;Scheduler was sent the command new
10/03/2014 10:28:51;0040;PBS_Server;Svr;tyrone-cluster;Scheduler was sent the command new
10/03/2014 10:29:22;0040;PBS_Server;Svr;tyrone-cluster;Scheduler was sent the command new
10/03/2014 10:29:55;0040;PBS_Server;Svr;tyrone-cluster;Scheduler was sent the command new
10/03/2014 10:30:29;0040;PBS_Server;Svr;tyrone-cluster;Scheduler was sent the command new
10/03/2014 10:30:56;0040;PBS_Server;Svr;tyrone-cluster;Scheduler was sent the command new
10/03/2014 10:31:26;0040;PBS_Server;Svr;tyrone-cluster;Scheduler was sent the command new
10/03/2014 10:31:59;0040;PBS_Server;Svr;tyrone-cluster;Scheduler was sent the command new
10/03/2014 10:32:27;0040;PBS_Server;Svr;tyrone-cluster;Scheduler was sent the command new
10/03/2014 10:32:50;0002;PBS_Server;Svr;PBS_Server;Torque Server Version = 3.0.5, loglevel = 0
10/03/2014 10:33:06;0040;PBS_Server;Svr;tyrone-cluster;Scheduler was sent the command new
10/03/2014 10:33:34;0040;PBS_Server;Svr;tyrone-cluster;Scheduler was sent the command new
10/03/2014 10:34:06;0040;PBS_Server;Svr;tyrone-cluster;Scheduler was sent the command new
10/03/2014 10:34:37;0040;PBS_Server;Svr;tyrone-cluster;Scheduler was sent the command new
10/03/2014 10:35:10;0040;PBS_Server;Svr;tyrone-cluster;Scheduler was sent the command new
10/03/2014 10:35:44;0040;PBS_Server;Svr;tyrone-cluster;Scheduler was sent the command new
10/03/2014 10:36:11;0040;PBS_Server;Svr;tyrone-cluster;Scheduler was sent the command new
10/03/2014 10:36:41;0040;PBS_Server;Svr;tyrone-cluster;Scheduler was sent the command new
10/03/2014 10:37:14;0040;PBS_Server;Svr;tyrone-cluster;Scheduler was sent the command new
10/03/2014 10:37:42;0040;PBS_Server;Svr;tyrone-cluster;Scheduler was sent the command new
10/03/2014 10:37:50;0002;PBS_Server;Svr;PBS_Server;Torque Server Version = 3.0.5, loglevel = 0
10/03/2014 10:38:22;0040;PBS_Server;Svr;tyrone-cluster;Scheduler was sent the command new
10/03/2014 10:38:49;0040;PBS_Server;Svr;tyrone-cluster;Scheduler was sent the command new
10/03/2014 10:39:21;0040;PBS_Server;Svr;tyrone-cluster;Scheduler was sent the command new
10/03/2014 10:39:52;0040;PBS_Server;Svr;tyrone-cluster;Scheduler was sent the command new
10/03/2014 10:40:25;0040;PBS_Server;Svr;tyrone-cluster;Scheduler was sent the command new
10/03/2014 10:40:59;0040;PBS_Server;Svr;tyrone-cluster;Scheduler was sent the command new
10/03/2014 10:41:26;0040;PBS_Server;Svr;tyrone-cluster;Scheduler was sent the command new
10/03/2014 10:41:56;0040;PBS_Server;Svr;tyrone-cluster;Scheduler was sent the command new
10/03/2014 10:42:30;0040;PBS_Server;Svr;tyrone-cluster;Scheduler was sent the command new
10/03/2014 10:42:50;0002;PBS_Server;Svr;PBS_Server;Torque Server Version = 3.0.5, loglevel = 0
10/03/2014 10:42:57;0040;PBS_Server;Svr;tyrone-cluster;Scheduler was sent the command new
10/03/2014 10:43:26;0040;PBS_Server;Svr;tyrone-cluster;Scheduler was sent the command new
10/03/2014 10:43:59;0040;PBS_Server;Svr;tyrone-cluster;Scheduler was sent the command new
10/03/2014 10:44:27;0040;PBS_Server;Svr;tyrone-cluster;Scheduler was sent the command new
10/03/2014 10:44:56;0040;PBS_Server;Svr;tyrone-cluster;Scheduler was sent the command new
10/03/2014 10:45:29;0040;PBS_Server;Svr;tyrone-cluster;Scheduler was sent the command new
10/03/2014 10:45:57;0040;PBS_Server;Svr;tyrone-cluster;Scheduler was sent the command new
10/03/2014 10:46:26;0040;PBS_Server;Svr;tyrone-cluster;Scheduler was sent the command new
10/03/2014 10:46:59;0040;PBS_Server;Svr;tyrone-cluster;Scheduler was sent the command new
10/03/2014 10:47:31;0040;PBS_Server;Svr;tyrone-cluster;Scheduler was sent the command new
10/03/2014 10:47:50;0002;PBS_Server;Svr;PBS_Server;Torque Server Version = 3.0.5, loglevel = 0
10/03/2014 10:48:06;0040;PBS_Server;Svr;tyrone-cluster;Scheduler was sent the command new
10/03/2014 10:48:34;0040;PBS_Server;Svr;tyrone-cluster;Scheduler was sent the command new
10/03/2014 10:49:06;0040;PBS_Server;Svr;tyrone-cluster;Scheduler was sent the command new
10/03/2014 10:49:37;0040;PBS_Server;Svr;tyrone-cluster;Scheduler was sent the command new
10/03/2014 10:50:10;0040;PBS_Server;Svr;tyrone-cluster;Scheduler was sent the command new
10/03/2014 10:50:44;0040;PBS_Server;Svr;tyrone-cluster;Scheduler was sent the command new
10/03/2014 10:51:12;0040;PBS_Server;Svr;tyrone-cluster;Scheduler was sent the command new
10/03/2014 10:51:41;0040;PBS_Server;Svr;tyrone-cluster;Scheduler was sent the command new
10/03/2014 10:52:14;0040;PBS_Server;Svr;tyrone-cluster;Scheduler was sent the command new
10/03/2014 10:52:46;0040;PBS_Server;Svr;tyrone-cluster;Scheduler was sent the command new
10/03/2014 10:52:50;0002;PBS_Server;Svr;PBS_Server;Torque Server Version = 3.0.5, loglevel = 0
10/03/2014 10:53:22;0040;PBS_Server;Svr;tyrone-cluster;Scheduler was sent the command new
10/03/2014 10:53:49;0040;PBS_Server;Svr;tyrone-cluster;Scheduler was sent the command new
10/03/2014 10:54:21;0040;PBS_Server;Svr;tyrone-cluster;Scheduler was sent the command new
10/03/2014 10:54:52;0040;PBS_Server;Svr;tyrone-cluster;Scheduler was sent the command new
10/03/2014 10:55:24;0040;PBS_Server;Svr;tyrone-cluster;Scheduler was sent the command new
10/03/2014 10:55:59;0040;PBS_Server;Svr;tyrone-cluster;Scheduler was sent the command new
10/03/2014 10:56:26;0040;PBS_Server;Svr;tyrone-cluster;Scheduler was sent the command new
10/03/2014 10:56:56;0040;PBS_Server;Svr;tyrone-cluster;Scheduler was sent the command new
10/03/2014 10:57:29;0040;PBS_Server;Svr;tyrone-cluster;Scheduler was sent the command new
10/03/2014 10:57:50;0002;PBS_Server;Svr;PBS_Server;Torque Server Version = 3.0.5, loglevel = 0
10/03/2014 10:57:57;0040;PBS_Server;Svr;tyrone-cluster;Scheduler was sent the command new
10/03/2014 10:58:26;0040;PBS_Server;Svr;tyrone-cluster;Scheduler was sent the command new
10/03/2014 10:58:59;0040;PBS_Server;Svr;tyrone-cluster;Scheduler was sent the command new
10/03/2014 10:59:27;0040;PBS_Server;Svr;tyrone-cluster;Scheduler was sent the command new
10/03/2014 10:59:56;0040;PBS_Server;Svr;tyrone-cluster;Scheduler was sent the command new
10/03/2014 11:00:29;0040;PBS_Server;Svr;tyrone-cluster;Scheduler was sent the command new
10/03/2014 11:01:01;0040;PBS_Server;Svr;tyrone-cluster;Scheduler was sent the command new
10/03/2014 11:01:37;0040;PBS_Server;Svr;tyrone-cluster;Scheduler was sent the command new
10/03/2014 11:02:04;0040;PBS_Server;Svr;tyrone-cluster;Scheduler was sent the command new
10/03/2014 11:02:36;0040;PBS_Server;Svr;tyrone-cluster;Scheduler was sent the command new
10/03/2014 11:02:50;0002;PBS_Server;Svr;PBS_Server;Torque Server Version = 3.0.5, loglevel = 0
10/03/2014 11:03:07;0040;PBS_Server;Svr;tyrone-cluster;Scheduler was sent the command new
10/03/2014 11:03:39;0040;PBS_Server;Svr;tyrone-cluster;Scheduler was sent the command new
10/03/2014 11:04:14;0040;PBS_Server;Svr;tyrone-cluster;Scheduler was sent the command new
10/03/2014 11:04:41;0040;PBS_Server;Svr;tyrone-cluster;Scheduler was sent the command new
10/03/2014 11:05:10;0040;PBS_Server;Svr;tyrone-cluster;Scheduler was sent the command new
10/03/2014 11:05:44;0040;PBS_Server;Svr;tyrone-cluster;Scheduler was sent the command new
10/03/2014 11:06:12;0040;PBS_Server;Svr;tyrone-cluster;Scheduler was sent the command new
10/03/2014 11:06:41;0040;PBS_Server;Svr;tyrone-cluster;Scheduler was sent the command new
10/03/2014 11:07:14;0040;PBS_Server;Svr;tyrone-cluster;Scheduler was sent the command new
10/03/2014 11:07:46;0040;PBS_Server;Svr;tyrone-cluster;Scheduler was sent the command new
10/03/2014 11:07:50;0002;PBS_Server;Svr;PBS_Server;Torque Server Version = 3.0.5, loglevel = 0
10/03/2014 11:08:21;0040;PBS_Server;Svr;tyrone-cluster;Scheduler was sent the command new
10/03/2014 11:08:44;0040;PBS_Server;Svr;tyrone-cluster;Scheduler was sent the command new
10/03/2014 11:09:16;0040;PBS_Server;Svr;tyrone-cluster;Scheduler was sent the command new
10/03/2014 11:09:52;0040;PBS_Server;Svr;tyrone-cluster;Scheduler was sent the command new
10/03/2014 11:10:19;0040;PBS_Server;Svr;tyrone-cluster;Scheduler was sent the command new
10/03/2014 11:10:51;0040;PBS_Server;Svr;tyrone-cluster;Scheduler was sent the command new
10/03/2014 11:11:22;0040;PBS_Server;Svr;tyrone-cluster;Scheduler was sent the command new
10/03/2014 11:11:54;0040;PBS_Server;Svr;tyrone-cluster;Scheduler was sent the command new
10/03/2014 11:12:29;0040;PBS_Server;Svr;tyrone-cluster;Scheduler was sent the command new
10/03/2014 11:12:50;0002;PBS_Server;Svr;PBS_Server;Torque Server Version = 3.0.5, loglevel = 0
10/03/2014 11:12:57;0040;PBS_Server;Svr;tyrone-cluster;Scheduler was sent the command new
10/03/2014 11:13:26;0040;PBS_Server;Svr;tyrone-cluster;Scheduler was sent the command new
10/03/2014 11:13:59;0040;PBS_Server;Svr;tyrone-cluster;Scheduler was sent the command new
10/03/2014 11:14:31;0040;PBS_Server;Svr;tyrone-cluster;Scheduler was sent the command new
10/03/2014 11:15:07;0040;PBS_Server;Svr;tyrone-cluster;Scheduler was sent the command new
10/03/2014 11:15:34;0040;PBS_Server;Svr;tyrone-cluster;Scheduler was sent the command new
10/03/2014 11:16:06;0040;PBS_Server;Svr;tyrone-cluster;Scheduler was sent the command new
10/03/2014 11:16:37;0040;PBS_Server;Svr;tyrone-cluster;Scheduler was sent the command new
10/03/2014 11:17:09;0040;PBS_Server;Svr;tyrone-cluster;Scheduler was sent the command new
10/03/2014 11:17:44;0040;PBS_Server;Svr;tyrone-cluster;Scheduler was sent the command new
10/03/2014 11:17:50;0002;PBS_Server;Svr;PBS_Server;Torque Server Version = 3.0.5, loglevel = 0
10/03/2014 11:18:12;0040;PBS_Server;Svr;tyrone-cluster;Scheduler was sent the command new
10/03/2014 11:18:41;0040;PBS_Server;Svr;tyrone-cluster;Scheduler was sent the command new
10/03/2014 11:19:14;0040;PBS_Server;Svr;tyrone-cluster;Scheduler was sent the command new
10/03/2014 11:19:42;0040;PBS_Server;Svr;tyrone-cluster;Scheduler was sent the command new
10/03/2014 11:20:21;0040;PBS_Server;Svr;tyrone-cluster;Scheduler was sent the command new
10/03/2014 11:20:49;0040;PBS_Server;Svr;tyrone-cluster;Scheduler was sent the command new
10/03/2014 11:21:21;0040;PBS_Server;Svr;tyrone-cluster;Scheduler was sent the command new
10/03/2014 11:21:52;0040;PBS_Server;Svr;tyrone-cluster;Scheduler was sent the command new
10/03/2014 11:22:24;0040;PBS_Server;Svr;tyrone-cluster;Scheduler was sent the command new
10/03/2014 11:22:50;0002;PBS_Server;Svr;PBS_Server;Torque Server Version = 3.0.5, loglevel = 0
10/03/2014 11:22:59;0040;PBS_Server;Svr;tyrone-cluster;Scheduler was sent the command new
10/03/2014 11:23:13;0080;PBS_Server;Job;53315.tyrone-cluster;Unknown Job Id
10/03/2014 11:23:13;0080;PBS_Server;Req;req_reject;Reject reply code=15001(Unknown Job Id), aux=0, type=DeleteJob, from chevadh@tyrone-cluster
10/03/2014 11:23:13;0080;PBS_Server;Req;req_reject;Reject reply code=15001(Unknown Job Id), aux=0, type=LocateJob, from chevadh@tyrone-cluster
10/03/2014 11:23:17;0008;PBS_Server;Job;43315.tyrone-cluster;Job deleted at request of chevadh@tyrone-cluster
10/03/2014 11:23:17;0008;PBS_Server;Job;43315.tyrone-cluster;Job sent signal SIGTERM on delete
10/03/2014 11:23:17;000d;PBS_Server;Job;43315.tyrone-cluster;Not sending email: User does not want mail of this type.
10/03/2014 11:23:17;0010;PBS_Server;Job;43315.tyrone-cluster;Exit_status=143 resources_used.cput=637:02:07 resources_used.mem=855756kb resources_used.vmem=12494800kb resources_used.walltime=19:55:08
10/03/2014 11:23:17;0008;PBS_Server;Job;NULL;on_job_exit valid pjob: 0x2dd39b0 (substate=50)
10/03/2014 11:23:17;0008;PBS_Server;Job;NULL;on_job_exit valid pjob: 0x2dd39b0 (substate=51)
10/03/2014 11:23:18;0008;PBS_Server;Job;NULL;on_job_exit valid pjob: 0x2dd39b0 (substate=51)
10/03/2014 11:23:18;0008;PBS_Server;Job;NULL;on_job_exit valid pjob: 0x2dd39b0 (substate=53)
10/03/2014 11:23:18;0100;PBS_Server;Job;43315.tyrone-cluster;dequeuing from qp128, state COMPLETE
10/03/2014 11:23:18;0040;PBS_Server;Svr;tyrone-cluster;Scheduler was sent the command term
10/03/2014 11:23:27;0040;PBS_Server;Svr;tyrone-cluster;Scheduler was sent the command new
10/03/2014 11:24:06;0040;PBS_Server;Svr;tyrone-cluster;Scheduler was sent the command new
10/03/2014 11:24:29;0040;PBS_Server;Svr;tyrone-cluster;Scheduler was sent the command new
10/03/2014 11:25:01;0040;PBS_Server;Svr;tyrone-cluster;Scheduler was sent the command new
10/03/2014 11:25:36;0040;PBS_Server;Svr;tyrone-cluster;Scheduler was sent the command new
10/03/2014 11:25:59;0040;PBS_Server;Svr;tyrone-cluster;Scheduler was sent the command new
10/03/2014 11:26:31;0040;PBS_Server;Svr;tyrone-cluster;Scheduler was sent the command new
10/03/2014 11:27:07;0040;PBS_Server;Svr;tyrone-cluster;Scheduler was sent the command new
10/03/2014 11:27:35;0040;PBS_Server;Svr;tyrone-cluster;Scheduler was sent the command new
10/03/2014 11:27:50;0002;PBS_Server;Svr;PBS_Server;Torque Server Version = 3.0.5, loglevel = 0
10/03/2014 11:28:06;0040;PBS_Server;Svr;tyrone-cluster;Scheduler was sent the command new
10/03/2014 11:28:37;0040;PBS_Server;Svr;tyrone-cluster;Scheduler was sent the command new
10/03/2014 11:29:05;0100;PBS_Server;Job;43351.tyrone-cluster;enqueuing into batch, state 1 hop 1
10/03/2014 11:29:05;0100;PBS_Server;Job;43351.tyrone-cluster;dequeuing from batch, state QUEUED
10/03/2014 11:29:05;0100;PBS_Server;Job;43351.tyrone-cluster;enqueuing into qp256, state 1 hop 1
10/03/2014 11:29:05;0008;PBS_Server;Job;43351.tyrone-cluster;Job Queued at request of chevadh@tyrone-cluster, owner = chevadh@tyrone-cluster, job name = jobname, queue = qp256
10/03/2014 11:29:05;0040;PBS_Server;Svr;tyrone-cluster;Scheduler was sent the command new
10/03/2014 11:29:05;0008;PBS_Server;Job;43351.tyrone-cluster;Job Modified at request of Scheduler@tyrone-cluster
10/03/2014 11:29:05;0008;PBS_Server;Job;43351.tyrone-cluster;Job Run at request of Scheduler@tyrone-cluster
10/03/2014 11:29:05;0040;PBS_Server;Svr;tyrone-cluster;Scheduler was sent the command recyc
10/03/2014 11:29:06;0040;PBS_Server;Svr;tyrone-cluster;Scheduler was sent the command new
10/03/2014 11:29:06;000d;PBS_Server;Job;43351.tyrone-cluster;Not sending email: User does not want mail of this type.
10/03/2014 11:29:06;0010;PBS_Server;Job;43351.tyrone-cluster;Exit_status=255 resources_used.cput=00:00:00 resources_used.mem=796kb resources_used.vmem=13624kb resources_used.walltime=00:00:01
10/03/2014 11:29:06;0008;PBS_Server;Job;NULL;on_job_exit valid pjob: 0x2dd39b0 (substate=50)
10/03/2014 11:29:06;0008;PBS_Server;Job;NULL;on_job_exit valid pjob: 0x2dd39b0 (substate=51)
10/03/2014 11:29:07;0008;PBS_Server;Job;NULL;on_job_exit valid pjob: 0x2dd39b0 (substate=51)
10/03/2014 11:29:07;0008;PBS_Server;Job;NULL;on_job_exit valid pjob: 0x2dd39b0 (substate=53)
10/03/2014 11:29:07;0100;PBS_Server;Job;43351.tyrone-cluster;dequeuing from qp256, state COMPLETE
10/03/2014 11:29:07;0040;PBS_Server;Svr;tyrone-cluster;Scheduler was sent the command term
10/03/2014 11:29:37;0040;PBS_Server;Svr;tyrone-cluster;Scheduler was sent the command new
10/03/2014 11:29:37;0100;PBS_Server;Job;43352.tyrone-cluster;enqueuing into batch, state 1 hop 1
10/03/2014 11:29:37;0100;PBS_Server;Job;43352.tyrone-cluster;dequeuing from batch, state QUEUED
10/03/2014 11:29:37;0100;PBS_Server;Job;43352.tyrone-cluster;enqueuing into qp256, state 1 hop 1
10/03/2014 11:29:37;0008;PBS_Server;Job;43352.tyrone-cluster;Job Queued at request of chevadh@tyrone-cluster, owner = chevadh@tyrone-cluster, job name = jobname, queue = qp256
10/03/2014 11:29:37;0008;PBS_Server;Job;43352.tyrone-cluster;Job Modified at request of Scheduler@tyrone-cluster
10/03/2014 11:29:37;0008;PBS_Server;Job;43352.tyrone-cluster;Job Run at request of Scheduler@tyrone-cluster
10/03/2014 11:29:37;0040;PBS_Server;Svr;tyrone-cluster;Scheduler was sent the command recyc
10/03/2014 11:29:38;000d;PBS_Server;Job;43352.tyrone-cluster;Not sending email: User does not want mail of this type.
10/03/2014 11:29:38;0010;PBS_Server;Job;43352.tyrone-cluster;Exit_status=255 resources_used.cput=00:00:00 resources_used.mem=796kb resources_used.vmem=13624kb resources_used.walltime=00:00:01
10/03/2014 11:29:38;0008;PBS_Server;Job;NULL;on_job_exit valid pjob: 0x2dd39b0 (substate=50)
10/03/2014 11:29:38;0008;PBS_Server;Job;NULL;on_job_exit valid pjob: 0x2dd39b0 (substate=51)
10/03/2014 11:29:39;0008;PBS_Server;Job;NULL;on_job_exit valid pjob: 0x2dd39b0 (substate=51)
10/03/2014 11:29:39;0008;PBS_Server;Job;NULL;on_job_exit valid pjob: 0x2dd39b0 (substate=53)
10/03/2014 11:29:39;0100;PBS_Server;Job;43352.tyrone-cluster;dequeuing from qp256, state COMPLETE
10/03/2014 11:29:39;0040;PBS_Server;Svr;tyrone-cluster;Scheduler was sent the command term
10/03/2014 11:30:09;0040;PBS_Server;Svr;tyrone-cluster;Scheduler was sent the command new
10/03/2014 11:30:22;0100;PBS_Server;Job;43353.tyrone-cluster;enqueuing into batch, state 1 hop 1
10/03/2014 11:30:22;0100;PBS_Server;Job;43353.tyrone-cluster;dequeuing from batch, state QUEUED
10/03/2014 11:30:22;0100;PBS_Server;Job;43353.tyrone-cluster;enqueuing into qp256, state 1 hop 1
10/03/2014 11:30:22;0008;PBS_Server;Job;43353.tyrone-cluster;Job Queued at request of chevadh@tyrone-cluster, owner = chevadh@tyrone-cluster, job name = jobname, queue = qp256
10/03/2014 11:30:22;0040;PBS_Server;Svr;tyrone-cluster;Scheduler was sent the command new
10/03/2014 11:30:22;0008;PBS_Server;Job;43353.tyrone-cluster;Job Modified at request of Scheduler@tyrone-cluster
10/03/2014 11:30:22;0008;PBS_Server;Job;43353.tyrone-cluster;Job Run at request of Scheduler@tyrone-cluster
10/03/2014 11:30:22;0040;PBS_Server;Svr;tyrone-cluster;Scheduler was sent the command recyc
10/03/2014 11:30:23;000d;PBS_Server;Job;43353.tyrone-cluster;Not sending email: User does not want mail of this type.
10/03/2014 11:30:23;0010;PBS_Server;Job;43353.tyrone-cluster;Exit_status=255 resources_used.cput=00:00:00 resources_used.mem=800kb resources_used.vmem=13624kb resources_used.walltime=00:00:01
10/03/2014 11:30:23;0008;PBS_Server;Job;NULL;on_job_exit valid pjob: 0x2dd39b0 (substate=50)
10/03/2014 11:30:23;0008;PBS_Server;Job;NULL;on_job_exit valid pjob: 0x2dd39b0 (substate=51)
10/03/2014 11:30:24;0008;PBS_Server;Job;NULL;on_job_exit valid pjob: 0x2dd39b0 (substate=51)
10/03/2014 11:30:24;0008;PBS_Server;Job;NULL;on_job_exit valid pjob: 0x2dd39b0 (substate=53)
10/03/2014 11:30:24;0100;PBS_Server;Job;43353.tyrone-cluster;dequeuing from qp256, state COMPLETE
10/03/2014 11:30:24;0040;PBS_Server;Svr;tyrone-cluster;Scheduler was sent the command term
10/03/2014 11:30:39;0040;PBS_Server;Svr;tyrone-cluster;Scheduler was sent the command new
10/03/2014 11:31:14;0040;PBS_Server;Svr;tyrone-cluster;Scheduler was sent the command new
10/03/2014 11:31:14;0100;PBS_Server;Job;43354.tyrone-cluster;enqueuing into batch, state 1 hop 1
10/03/2014 11:31:14;0100;PBS_Server;Job;43354.tyrone-cluster;dequeuing from batch, state QUEUED
10/03/2014 11:31:14;0100;PBS_Server;Job;43354.tyrone-cluster;enqueuing into qp256, state 1 hop 1
10/03/2014 11:31:14;0008;PBS_Server;Job;43354.tyrone-cluster;Job Queued at request of chevadh@tyrone-cluster, owner = chevadh@tyrone-cluster, job name = jobname, queue = qp256
10/03/2014 11:31:14;0008;PBS_Server;Job;43354.tyrone-cluster;Job Modified at request of Scheduler@tyrone-cluster
10/03/2014 11:31:14;0008;PBS_Server;Job;43354.tyrone-cluster;Job Run at request of Scheduler@tyrone-cluster
10/03/2014 11:31:14;0040;PBS_Server;Svr;tyrone-cluster;Scheduler was sent the command recyc
10/03/2014 11:31:14;000d;PBS_Server;Job;43354.tyrone-cluster;Not sending email: User does not want mail of this type.
10/03/2014 11:31:14;0010;PBS_Server;Job;43354.tyrone-cluster;Exit_status=255 resources_used.cput=00:00:00 resources_used.mem=800kb resources_used.vmem=13624kb resources_used.walltime=00:00:01
10/03/2014 11:31:14;0008;PBS_Server;Job;NULL;on_job_exit valid pjob: 0x2dd39b0 (substate=50)
10/03/2014 11:31:14;0008;PBS_Server;Job;NULL;on_job_exit valid pjob: 0x2dd39b0 (substate=51)
10/03/2014 11:31:15;0008;PBS_Server;Job;NULL;on_job_exit valid pjob: 0x2dd39b0 (substate=51)
10/03/2014 11:31:15;0008;PBS_Server;Job;NULL;on_job_exit valid pjob: 0x2dd39b0 (substate=53)
10/03/2014 11:31:15;0100;PBS_Server;Job;43354.tyrone-cluster;dequeuing from qp256, state COMPLETE
10/03/2014 11:31:15;0040;PBS_Server;Svr;tyrone-cluster;Scheduler was sent the command term
10/03/2014 11:31:42;0040;PBS_Server;Svr;tyrone-cluster;Scheduler was sent the command new
10/03/2014 11:31:48;0100;PBS_Server;Job;43355.tyrone-cluster;enqueuing into batch, state 1 hop 1
10/03/2014 11:31:48;0100;PBS_Server;Job;43355.tyrone-cluster;dequeuing from batch, state QUEUED
10/03/2014 11:31:48;0100;PBS_Server;Job;43355.tyrone-cluster;enqueuing into qp256, state 1 hop 1
10/03/2014 11:31:48;0008;PBS_Server;Job;43355.tyrone-cluster;Job Queued at request of chevadh@tyrone-cluster, owner = chevadh@tyrone-cluster, job name = jobname, queue = qp256
10/03/2014 11:31:48;0040;PBS_Server;Svr;tyrone-cluster;Scheduler was sent the command new
10/03/2014 11:31:49;0008;PBS_Server;Job;43355.tyrone-cluster;Job Modified at request of Scheduler@tyrone-cluster
10/03/2014 11:31:49;0008;PBS_Server;Job;43355.tyrone-cluster;Job Run at request of Scheduler@tyrone-cluster
10/03/2014 11:31:49;0040;PBS_Server;Svr;tyrone-cluster;Scheduler was sent the command recyc
10/03/2014 11:31:49;000d;PBS_Server;Job;43355.tyrone-cluster;Not sending email: User does not want mail of this type.
10/03/2014 11:31:49;0010;PBS_Server;Job;43355.tyrone-cluster;Exit_status=255 resources_used.cput=00:00:00 resources_used.mem=800kb resources_used.vmem=13624kb resources_used.walltime=00:00:01
10/03/2014 11:31:49;0008;PBS_Server;Job;NULL;on_job_exit valid pjob: 0x2dd39b0 (substate=50)
10/03/2014 11:31:49;0008;PBS_Server;Job;NULL;on_job_exit valid pjob: 0x2dd39b0 (substate=51)
10/03/2014 11:31:50;0008;PBS_Server;Job;NULL;on_job_exit valid pjob: 0x2dd39b0 (substate=51)
10/03/2014 11:31:50;0008;PBS_Server;Job;NULL;on_job_exit valid pjob: 0x2dd39b0 (substate=53)
10/03/2014 11:31:50;0100;PBS_Server;Job;43355.tyrone-cluster;dequeuing from qp256, state COMPLETE
10/03/2014 11:31:50;0040;PBS_Server;Svr;tyrone-cluster;Scheduler was sent the command term
10/03/2014 11:32:21;0040;PBS_Server;Svr;tyrone-cluster;Scheduler was sent the command new
10/03/2014 11:32:44;0040;PBS_Server;Svr;tyrone-cluster;Scheduler was sent the command new
10/03/2014 11:32:50;0002;PBS_Server;Svr;PBS_Server;Torque Server Version = 3.0.5, loglevel = 0
10/03/2014 11:33:15;0040;PBS_Server;Svr;tyrone-cluster;Scheduler was sent the command new
10/03/2014 11:33:52;0040;PBS_Server;Svr;tyrone-cluster;Scheduler was sent the command new
10/03/2014 11:34:20;0040;PBS_Server;Svr;tyrone-cluster;Scheduler was sent the command new
10/03/2014 11:34:51;0040;PBS_Server;Svr;tyrone-cluster;Scheduler was sent the command new
10/03/2014 11:35:22;0040;PBS_Server;Svr;tyrone-cluster;Scheduler was sent the command new
10/03/2014 11:35:54;0040;PBS_Server;Svr;tyrone-cluster;Scheduler was sent the command new
10/03/2014 11:36:29;0040;PBS_Server;Svr;tyrone-cluster;Scheduler was sent the command new
10/03/2014 11:36:57;0040;PBS_Server;Svr;tyrone-cluster;Scheduler was sent the command new
10/03/2014 11:37:36;0040;PBS_Server;Svr;tyrone-cluster;Scheduler was sent the command new
10/03/2014 11:37:50;0002;PBS_Server;Svr;PBS_Server;Torque Server Version = 3.0.5, loglevel = 0
10/03/2014 11:37:59;0040;PBS_Server;Svr;tyrone-cluster;Scheduler was sent the command new
10/03/2014 11:38:31;0040;PBS_Server;Svr;tyrone-cluster;Scheduler was sent the command new
10/03/2014 11:38:47;0100;PBS_Server;Job;43356.tyrone-cluster;enqueuing into batch, state 1 hop 1
10/03/2014 11:38:47;0100;PBS_Server;Job;43356.tyrone-cluster;dequeuing from batch, state QUEUED
10/03/2014 11:38:47;0100;PBS_Server;Job;43356.tyrone-cluster;enqueuing into qp256, state 1 hop 1
10/03/2014 11:38:47;0008;PBS_Server;Job;43356.tyrone-cluster;Job Queued at request of chevadh@tyrone-cluster, owner = chevadh@tyrone-cluster, job name = jobname, queue = qp256
10/03/2014 11:38:47;0040;PBS_Server;Svr;tyrone-cluster;Scheduler was sent the command new
10/03/2014 11:38:47;0008;PBS_Server;Job;43356.tyrone-cluster;Job Modified at request of Scheduler@tyrone-cluster
10/03/2014 11:38:47;0008;PBS_Server;Job;43356.tyrone-cluster;Job Run at request of Scheduler@tyrone-cluster
10/03/2014 11:38:47;0040;PBS_Server;Svr;tyrone-cluster;Scheduler was sent the command recyc
10/03/2014 11:39:06;0040;PBS_Server;Svr;tyrone-cluster;Scheduler was sent the command new
10/03/2014 11:39:29;0040;PBS_Server;Svr;tyrone-cluster;Scheduler was sent the command new
10/03/2014 11:39:32;000d;PBS_Server;Job;43356.tyrone-cluster;Not sending email: User does not want mail of this type.
10/03/2014 11:40:00;0040;PBS_Server;Svr;tyrone-cluster;Scheduler was sent the command new
10/03/2014 11:40:36;0040;PBS_Server;Svr;tyrone-cluster;Scheduler was sent the command new
10/03/2014 11:40:59;0040;PBS_Server;Svr;tyrone-cluster;Scheduler was sent the command new
10/03/2014 11:41:31;0040;PBS_Server;Svr;tyrone-cluster;Scheduler was sent the command new
10/03/2014 11:42:07;0040;PBS_Server;Svr;tyrone-cluster;Scheduler was sent the command new
10/03/2014 11:42:29;0040;PBS_Server;Svr;tyrone-cluster;Scheduler was sent the command new
10/03/2014 11:42:50;0002;PBS_Server;Svr;PBS_Server;Torque Server Version = 3.0.5, loglevel = 0
10/03/2014 11:43:00;0040;PBS_Server;Svr;tyrone-cluster;Scheduler was sent the command new
10/03/2014 11:43:36;0040;PBS_Server;Svr;tyrone-cluster;Scheduler was sent the command new
10/03/2014 11:43:59;0040;PBS_Server;Svr;tyrone-cluster;Scheduler was sent the command new
10/03/2014 11:44:30;0040;PBS_Server;Svr;tyrone-cluster;Scheduler was sent the command new
10/03/2014 11:45:07;0040;PBS_Server;Svr;tyrone-cluster;Scheduler was sent the command new
10/03/2014 11:45:39;0040;PBS_Server;Svr;tyrone-cluster;Scheduler was sent the command new
10/03/2014 11:46:12;0040;PBS_Server;Svr;tyrone-cluster;Scheduler was sent the command new
10/03/2014 11:46:39;0040;PBS_Server;Svr;tyrone-cluster;Scheduler was sent the command new
10/03/2014 11:47:09;0040;PBS_Server;Svr;tyrone-cluster;Scheduler was sent the command new
10/03/2014 11:47:43;0040;PBS_Server;Svr;tyrone-cluster;Scheduler was sent the command new
10/03/2014 11:47:50;0002;PBS_Server;Svr;PBS_Server;Torque Server Version = 3.0.5, loglevel = 0
10/03/2014 11:48:12;0040;PBS_Server;Svr;tyrone-cluster;Scheduler was sent the command new
10/03/2014 11:48:51;0040;PBS_Server;Svr;tyrone-cluster;Scheduler was sent the command new
10/03/2014 11:49:14;0040;PBS_Server;Svr;tyrone-cluster;Scheduler was sent the command new
10/03/2014 11:49:46;0040;PBS_Server;Svr;tyrone-cluster;Scheduler was sent the command new
10/03/2014 11:50:22;0040;PBS_Server;Svr;tyrone-cluster;Scheduler was sent the command new
10/03/2014 11:50:44;0040;PBS_Server;Svr;tyrone-cluster;Scheduler was sent the command new
10/03/2014 11:51:15;0040;PBS_Server;Svr;tyrone-cluster;Scheduler was sent the command new
10/03/2014 11:51:51;0040;PBS_Server;Svr;tyrone-cluster;Scheduler was sent the command new
10/03/2014 11:52:14;0040;PBS_Server;Svr;tyrone-cluster;Scheduler was sent the command new
10/03/2014 11:52:45;0040;PBS_Server;Svr;tyrone-cluster;Scheduler was sent the command new
10/03/2014 11:52:50;0002;PBS_Server;Svr;PBS_Server;Torque Server Version = 3.0.5, loglevel = 0
10/03/2014 11:53:22;0040;PBS_Server;Svr;tyrone-cluster;Scheduler was sent the command new
10/03/2014 11:53:44;0040;PBS_Server;Svr;tyrone-cluster;Scheduler was sent the command new
10/03/2014 11:54:15;0040;PBS_Server;Svr;tyrone-cluster;Scheduler was sent the command new
10/03/2014 11:54:51;0040;PBS_Server;Svr;tyrone-cluster;Scheduler was sent the command new
10/03/2014 11:55:14;0040;PBS_Server;Svr;tyrone-cluster;Scheduler was sent the command new
10/03/2014 11:55:46;0040;PBS_Server;Svr;tyrone-cluster;Scheduler was sent the command new
10/03/2014 11:56:22;0040;PBS_Server;Svr;tyrone-cluster;Scheduler was sent the command new
10/03/2014 11:56:54;0040;PBS_Server;Svr;tyrone-cluster;Scheduler was sent the command new
10/03/2014 11:57:29;0040;PBS_Server;Svr;tyrone-cluster;Scheduler was sent the command new
10/03/2014 11:57:50;0002;PBS_Server;Svr;PBS_Server;Torque Server Version = 3.0.5, loglevel = 0
10/03/2014 11:57:57;0040;PBS_Server;Svr;tyrone-cluster;Scheduler was sent the command new
10/03/2014 11:58:36;0040;PBS_Server;Svr;tyrone-cluster;Scheduler was sent the command new
10/03/2014 11:58:59;0040;PBS_Server;Svr;tyrone-cluster;Scheduler was sent the command new
10/03/2014 11:59:31;0040;PBS_Server;Svr;tyrone-cluster;Scheduler was sent the command new
10/03/2014 12:00:07;0040;PBS_Server;Svr;tyrone-cluster;Scheduler was sent the command new
10/03/2014 12:00:39;0040;PBS_Server;Svr;tyrone-cluster;Scheduler was sent the command new
10/03/2014 12:01:11;0040;PBS_Server;Svr;tyrone-cluster;Scheduler was sent the command new
10/03/2014 12:01:14;0008;PBS_Server;Job;43323.tyrone-cluster;Job deleted at request of chevadh@tyrone-cluster
10/03/2014 12:01:14;0008;PBS_Server;Job;43323.tyrone-cluster;Job sent signal SIGTERM on delete
10/03/2014 12:01:15;000d;PBS_Server;Job;43323.tyrone-cluster;Not sending email: User does not want mail of this type.
10/03/2014 12:01:15;0010;PBS_Server;Job;43323.tyrone-cluster;Exit_status=143 resources_used.cput=525:14:19 resources_used.mem=586528kb resources_used.vmem=12283964kb resources_used.walltime=16:25:17
10/03/2014 12:01:15;0008;PBS_Server;Job;NULL;on_job_exit valid pjob: 0x2de5f90 (substate=50)
10/03/2014 12:01:15;0008;PBS_Server;Job;NULL;on_job_exit valid pjob: 0x2de5f90 (substate=51)
10/03/2014 12:01:15;0080;PBS_Server;Job;43323.tyrone-cluster;Request invalid for state of job EXITING
10/03/2014 12:01:15;0080;PBS_Server;Req;req_reject;Reject reply code=15018(Request invalid for state of job MSG=invalid state for job - EXITING), aux=0, type=DeleteJob, from chevadh@tyrone-cluster
10/03/2014 12:01:15;0008;PBS_Server;Job;NULL;on_job_exit valid pjob: 0x2de5f90 (substate=51)
10/03/2014 12:01:15;0008;PBS_Server;Job;NULL;on_job_exit valid pjob: 0x2de5f90 (substate=53)
10/03/2014 12:01:15;0100;PBS_Server;Job;43323.tyrone-cluster;dequeuing from qp32, state COMPLETE
10/03/2014 12:01:15;0040;PBS_Server;Svr;tyrone-cluster;Scheduler was sent the command term
10/03/2014 12:01:37;0100;PBS_Server;Job;43324.tyrone-cluster;dequeuing from batch, state QUEUED
10/03/2014 12:01:37;0100;PBS_Server;Job;43324.tyrone-cluster;enqueuing into qp32, state 1 hop 1
10/03/2014 12:01:39;0040;PBS_Server;Svr;tyrone-cluster;Scheduler was sent the command new
10/03/2014 12:01:40;0008;PBS_Server;Job;43324.tyrone-cluster;Job Modified at request of Scheduler@tyrone-cluster
10/03/2014 12:01:40;0008;PBS_Server;Job;43324.tyrone-cluster;Job Run at request of Scheduler@tyrone-cluster
10/03/2014 12:01:40;0040;PBS_Server;Svr;tyrone-cluster;Scheduler was sent the command recyc
10/03/2014 12:01:40;000d;PBS_Server;Job;43324.tyrone-cluster;Not sending email: User does not want mail of this type.
10/03/2014 12:01:40;000d;PBS_Server;Job;43324.tyrone-cluster;Not sending email: User does not want mail of this type.
10/03/2014 12:01:40;0010;PBS_Server;Job;43324.tyrone-cluster;Exit_status=255 resources_used.cput=00:00:04 resources_used.mem=0kb resources_used.vmem=0kb resources_used.walltime=00:00:01
10/03/2014 12:01:40;0008;PBS_Server;Job;NULL;on_job_exit valid pjob: 0x2ec6920 (substate=50)
10/03/2014 12:01:40;0008;PBS_Server;Job;NULL;on_job_exit valid pjob: 0x2ec6920 (substate=51)
10/03/2014 12:01:41;0008;PBS_Server;Job;NULL;on_job_exit valid pjob: 0x2ec6920 (substate=51)
10/03/2014 12:01:41;0008;PBS_Server;Job;NULL;on_job_exit valid pjob: 0x2ec6920 (substate=53)
10/03/2014 12:01:41;0100;PBS_Server;Job;43324.tyrone-cluster;dequeuing from qp32, state COMPLETE
10/03/2014 12:01:41;0040;PBS_Server;Svr;tyrone-cluster;Scheduler was sent the command term
10/03/2014 12:02:09;0040;PBS_Server;Svr;tyrone-cluster;Scheduler was sent the command new
10/03/2014 12:02:43;0040;PBS_Server;Svr;tyrone-cluster;Scheduler was sent the command new
10/03/2014 12:02:50;0002;PBS_Server;Svr;PBS_Server;Torque Server Version = 3.0.5, loglevel = 0
10/03/2014 12:03:13;0040;PBS_Server;Svr;tyrone-cluster;Scheduler was sent the command new
10/03/2014 12:03:52;0040;PBS_Server;Svr;tyrone-cluster;Scheduler was sent the command new
10/03/2014 12:04:14;0040;PBS_Server;Svr;tyrone-cluster;Scheduler was sent the command new
10/03/2014 12:04:46;0040;PBS_Server;Svr;tyrone-cluster;Scheduler was sent the command new
10/03/2014 12:05:21;0040;PBS_Server;Svr;tyrone-cluster;Scheduler was sent the command new
10/03/2014 12:05:44;0040;PBS_Server;Svr;tyrone-cluster;Scheduler was sent the command new
10/03/2014 12:06:15;0040;PBS_Server;Svr;tyrone-cluster;Scheduler was sent the command new
10/03/2014 12:06:52;0040;PBS_Server;Svr;tyrone-cluster;Scheduler was sent the command new
10/03/2014 12:07:24;0040;PBS_Server;Svr;tyrone-cluster;Scheduler was sent the command new
10/03/2014 12:07:49;0008;PBS_Server;Job;43356.tyrone-cluster;Job deleted at request of chevadh@tyrone-cluster
10/03/2014 12:07:49;0008;PBS_Server;Job;43356.tyrone-cluster;Job sent signal SIGTERM on delete
10/03/2014 12:07:50;0002;PBS_Server;Svr;PBS_Server;Torque Server Version = 3.0.5, loglevel = 0
10/03/2014 12:07:50;000d;PBS_Server;Job;43356.tyrone-cluster;Not sending email: User does not want mail of this type.
10/03/2014 12:07:50;0010;PBS_Server;Job;43356.tyrone-cluster;Exit_status=143 resources_used.cput=30:56:41 resources_used.mem=1002272kb resources_used.vmem=53837360kb resources_used.walltime=00:29:04
10/03/2014 12:07:50;0008;PBS_Server;Job;NULL;on_job_exit valid pjob: 0x2dd39b0 (substate=50)
10/03/2014 12:07:50;0008;PBS_Server;Job;NULL;on_job_exit valid pjob: 0x2dd39b0 (substate=51)
10/03/2014 12:07:51;0008;PBS_Server;Job;NULL;on_job_exit valid pjob: 0x2dd39b0 (substate=51)
10/03/2014 12:07:51;0008;PBS_Server;Job;NULL;on_job_exit valid pjob: 0x2dd39b0 (substate=53)
10/03/2014 12:07:51;0100;PBS_Server;Job;43356.tyrone-cluster;dequeuing from qp256, state COMPLETE
10/03/2014 12:07:51;0040;PBS_Server;Svr;tyrone-cluster;Scheduler was sent the command term
10/03/2014 12:07:55;0040;PBS_Server;Svr;tyrone-cluster;Scheduler was sent the command new
10/03/2014 12:07:55;0100;PBS_Server;Job;43357.tyrone-cluster;enqueuing into batch, state 1 hop 1
10/03/2014 12:07:55;0100;PBS_Server;Job;43357.tyrone-cluster;dequeuing from batch, state QUEUED
10/03/2014 12:07:55;0100;PBS_Server;Job;43357.tyrone-cluster;enqueuing into qp256, state 1 hop 1
10/03/2014 12:07:55;0008;PBS_Server;Job;43357.tyrone-cluster;Job Queued at request of chevadh@tyrone-cluster, owner = chevadh@tyrone-cluster, job name = jobname, queue = qp256
10/03/2014 12:07:55;0008;PBS_Server;Job;43357.tyrone-cluster;Job Modified at request of Scheduler@tyrone-cluster
10/03/2014 12:07:55;0008;PBS_Server;Job;43357.tyrone-cluster;Job Run at request of Scheduler@tyrone-cluster
10/03/2014 12:07:55;0040;PBS_Server;Svr;tyrone-cluster;Scheduler was sent the command recyc
10/03/2014 12:08:05;000d;PBS_Server;Job;43357.tyrone-cluster;Not sending email: User does not want mail of this type.
10/03/2014 12:08:26;0040;PBS_Server;Svr;tyrone-cluster;Scheduler was sent the command new
10/03/2014 12:09:06;0040;PBS_Server;Svr;tyrone-cluster;Scheduler was sent the command new
10/03/2014 12:09:29;0040;PBS_Server;Svr;tyrone-cluster;Scheduler was sent the command new
10/03/2014 12:10:00;0040;PBS_Server;Svr;tyrone-cluster;Scheduler was sent the command new
10/03/2014 12:10:37;0040;PBS_Server;Svr;tyrone-cluster;Scheduler was sent the command new
10/03/2014 12:10:59;0040;PBS_Server;Svr;tyrone-cluster;Scheduler was sent the command new
10/03/2014 12:11:30;0040;PBS_Server;Svr;tyrone-cluster;Scheduler was sent the command new
10/03/2014 12:12:07;0040;PBS_Server;Svr;tyrone-cluster;Scheduler was sent the command new
10/03/2014 12:12:39;0040;PBS_Server;Svr;tyrone-cluster;Scheduler was sent the command new
10/03/2014 12:12:50;0002;PBS_Server;Svr;PBS_Server;Torque Server Version = 3.0.5, loglevel = 0
10/03/2014 12:13:14;0040;PBS_Server;Svr;tyrone-cluster;Scheduler was sent the command new
10/03/2014 12:13:43;0040;PBS_Server;Svr;tyrone-cluster;Scheduler was sent the command new
10/03/2014 12:14:21;0040;PBS_Server;Svr;tyrone-cluster;Scheduler was sent the command new
10/03/2014 12:14:44;0040;PBS_Server;Svr;tyrone-cluster;Scheduler was sent the command new
10/03/2014 12:15:15;0040;PBS_Server;Svr;tyrone-cluster;Scheduler was sent the command new
10/03/2014 12:15:52;0040;PBS_Server;Svr;tyrone-cluster;Scheduler was sent the command new
10/03/2014 12:16:24;0040;PBS_Server;Svr;tyrone-cluster;Scheduler was sent the command new
10/03/2014 12:16:59;0040;PBS_Server;Svr;tyrone-cluster;Scheduler was sent the command new
10/03/2014 12:17:28;0040;PBS_Server;Svr;tyrone-cluster;Scheduler was sent the command new
10/03/2014 12:17:50;0002;PBS_Server;Svr;PBS_Server;Torque Server Version = 3.0.5, loglevel = 0
10/03/2014 12:18:06;0040;PBS_Server;Svr;tyrone-cluster;Scheduler was sent the command new
10/03/2014 12:18:29;0040;PBS_Server;Svr;tyrone-cluster;Scheduler was sent the command new
10/03/2014 12:19:01;0040;PBS_Server;Svr;tyrone-cluster;Scheduler was sent the command new
10/03/2014 12:19:37;0040;PBS_Server;Svr;tyrone-cluster;Scheduler was sent the command new
10/03/2014 12:20:09;0040;PBS_Server;Svr;tyrone-cluster;Scheduler was sent the command new
10/03/2014 12:20:44;0040;PBS_Server;Svr;tyrone-cluster;Scheduler was sent the command new
10/03/2014 12:21:13;0040;PBS_Server;Svr;tyrone-cluster;Scheduler was sent the command new
10/03/2014 12:21:51;0040;PBS_Server;Svr;tyrone-cluster;Scheduler was sent the command new
10/03/2014 12:22:14;0040;PBS_Server;Svr;tyrone-cluster;Scheduler was sent the command new
10/03/2014 12:22:46;0040;PBS_Server;Svr;tyrone-cluster;Scheduler was sent the command new
10/03/2014 12:22:50;0002;PBS_Server;Svr;PBS_Server;Torque Server Version = 3.0.5, loglevel = 0
10/03/2014 12:23:21;0040;PBS_Server;Svr;tyrone-cluster;Scheduler was sent the command new
10/03/2014 12:23:54;0040;PBS_Server;Svr;tyrone-cluster;Scheduler was sent the command new
10/03/2014 12:24:29;0040;PBS_Server;Svr;tyrone-cluster;Scheduler was sent the command new
10/03/2014 12:25:00;0040;PBS_Server;Svr;tyrone-cluster;Scheduler was sent the command new
10/03/2014 12:25:36;0040;PBS_Server;Svr;tyrone-cluster;Scheduler was sent the command new
10/03/2014 12:25:59;0040;PBS_Server;Svr;tyrone-cluster;Scheduler was sent the command new
10/03/2014 12:26:31;0040;PBS_Server;Svr;tyrone-cluster;Scheduler was sent the command new
10/03/2014 12:27:06;0040;PBS_Server;Svr;tyrone-cluster;Scheduler was sent the command new
10/03/2014 12:27:39;0040;PBS_Server;Svr;tyrone-cluster;Scheduler was sent the command new
10/03/2014 12:27:50;0002;PBS_Server;Svr;PBS_Server;Torque Server Version = 3.0.5, loglevel = 0
10/03/2014 12:28:14;0040;PBS_Server;Svr;tyrone-cluster;Scheduler was sent the command new
10/03/2014 12:28:44;0040;PBS_Server;Svr;tyrone-cluster;Scheduler was sent the command new
10/03/2014 12:29:21;0040;PBS_Server;Svr;tyrone-cluster;Scheduler was sent the command new
10/03/2014 12:29:44;0040;PBS_Server;Svr;tyrone-cluster;Scheduler was sent the command new
10/03/2014 12:30:16;0040;PBS_Server;Svr;tyrone-cluster;Scheduler was sent the command new
10/03/2014 12:30:51;0040;PBS_Server;Svr;tyrone-cluster;Scheduler was sent the command new
10/03/2014 12:31:24;0040;PBS_Server;Svr;tyrone-cluster;Scheduler was sent the command new
10/03/2014 12:31:59;0040;PBS_Server;Svr;tyrone-cluster;Scheduler was sent the command new
10/03/2014 12:32:28;0040;PBS_Server;Svr;tyrone-cluster;Scheduler was sent the command new
10/03/2014 12:32:50;0002;PBS_Server;Svr;PBS_Server;Torque Server Version = 3.0.5, loglevel = 0
10/03/2014 12:33:06;0040;PBS_Server;Svr;tyrone-cluster;Scheduler was sent the command new
10/03/2014 12:33:29;0040;PBS_Server;Svr;tyrone-cluster;Scheduler was sent the command new
10/03/2014 12:34:01;0040;PBS_Server;Svr;tyrone-cluster;Scheduler was sent the command new
10/03/2014 12:34:36;0040;PBS_Server;Svr;tyrone-cluster;Scheduler was sent the command new
10/03/2014 12:35:09;0040;PBS_Server;Svr;tyrone-cluster;Scheduler was sent the command new
10/03/2014 12:35:44;0040;PBS_Server;Svr;tyrone-cluster;Scheduler was sent the command new
10/03/2014 12:36:13;0040;PBS_Server;Svr;tyrone-cluster;Scheduler was sent the command new
10/03/2014 12:36:51;0040;PBS_Server;Svr;tyrone-cluster;Scheduler was sent the command new
10/03/2014 12:37:14;0040;PBS_Server;Svr;tyrone-cluster;Scheduler was sent the command new
10/03/2014 12:37:46;0040;PBS_Server;Svr;tyrone-cluster;Scheduler was sent the command new
10/03/2014 12:37:50;0002;PBS_Server;Svr;PBS_Server;Torque Server Version = 3.0.5, loglevel = 0
10/03/2014 12:38:21;0040;PBS_Server;Svr;tyrone-cluster;Scheduler was sent the command new
10/03/2014 12:38:54;0040;PBS_Server;Svr;tyrone-cluster;Scheduler was sent the command new
10/03/2014 12:39:29;0040;PBS_Server;Svr;tyrone-cluster;Scheduler was sent the command new
10/03/2014 12:39:59;0040;PBS_Server;Svr;tyrone-cluster;Scheduler was sent the command new
10/03/2014 12:40:36;0040;PBS_Server;Svr;tyrone-cluster;Scheduler was sent the command new
10/03/2014 12:41:08;0040;PBS_Server;Svr;tyrone-cluster;Scheduler was sent the command new
10/03/2014 12:41:44;0040;PBS_Server;Svr;tyrone-cluster;Scheduler was sent the command new
10/03/2014 12:42:13;0040;PBS_Server;Svr;tyrone-cluster;Scheduler was sent the command new
10/03/2014 12:42:50;0002;PBS_Server;Svr;PBS_Server;Torque Server Version = 3.0.5, loglevel = 0
10/03/2014 12:42:50;0040;PBS_Server;Svr;tyrone-cluster;Scheduler was sent the command new
10/03/2014 12:43:14;0040;PBS_Server;Svr;tyrone-cluster;Scheduler was sent the command new
10/03/2014 12:43:46;0040;PBS_Server;Svr;tyrone-cluster;Scheduler was sent the command new
10/03/2014 12:44:21;0040;PBS_Server;Svr;tyrone-cluster;Scheduler was sent the command new
10/03/2014 12:44:54;0040;PBS_Server;Svr;tyrone-cluster;Scheduler was sent the command new
10/03/2014 12:45:29;0040;PBS_Server;Svr;tyrone-cluster;Scheduler was sent the command new
10/03/2014 12:46:00;0040;PBS_Server;Svr;tyrone-cluster;Scheduler was sent the command new
10/03/2014 12:46:36;0040;PBS_Server;Svr;tyrone-cluster;Scheduler was sent the command new
10/03/2014 12:46:59;0040;PBS_Server;Svr;tyrone-cluster;Scheduler was sent the command new
10/03/2014 12:47:31;0040;PBS_Server;Svr;tyrone-cluster;Scheduler was sent the command new
10/03/2014 12:47:50;0002;PBS_Server;Svr;PBS_Server;Torque Server Version = 3.0.5, loglevel = 0
10/03/2014 12:48:06;0040;PBS_Server;Svr;tyrone-cluster;Scheduler was sent the command new
10/03/2014 12:48:38;0040;PBS_Server;Svr;tyrone-cluster;Scheduler was sent the command new
10/03/2014 12:49:13;0040;PBS_Server;Svr;tyrone-cluster;Scheduler was sent the command new
10/03/2014 12:49:43;0040;PBS_Server;Svr;tyrone-cluster;Scheduler was sent the command new
10/03/2014 12:50:21;0040;PBS_Server;Svr;tyrone-cluster;Scheduler was sent the command new
10/03/2014 12:50:44;0040;PBS_Server;Svr;tyrone-cluster;Scheduler was sent the command new
10/03/2014 12:51:16;0040;PBS_Server;Svr;tyrone-cluster;Scheduler was sent the command new
10/03/2014 12:51:52;0040;PBS_Server;Svr;tyrone-cluster;Scheduler was sent the command new
10/03/2014 12:52:20;0040;PBS_Server;Svr;tyrone-cluster;Scheduler was sent the command new
10/03/2014 12:52:50;0002;PBS_Server;Svr;PBS_Server;Torque Server Version = 3.0.5, loglevel = 0
10/03/2014 12:52:51;0040;PBS_Server;Svr;tyrone-cluster;Scheduler was sent the command new
10/03/2014 12:53:22;0040;PBS_Server;Svr;tyrone-cluster;Scheduler was sent the command new
10/03/2014 12:53:54;0040;PBS_Server;Svr;tyrone-cluster;Scheduler was sent the command new
10/03/2014 12:54:29;0040;PBS_Server;Svr;tyrone-cluster;Scheduler was sent the command new
10/03/2014 12:55:00;0040;PBS_Server;Svr;tyrone-cluster;Scheduler was sent the command new
10/03/2014 12:55:37;0040;PBS_Server;Svr;tyrone-cluster;Scheduler was sent the command new
10/03/2014 12:56:09;0040;PBS_Server;Svr;tyrone-cluster;Scheduler was sent the command new
10/03/2014 12:56:44;0040;PBS_Server;Svr;tyrone-cluster;Scheduler was sent the command new
10/03/2014 12:57:14;0040;PBS_Server;Svr;tyrone-cluster;Scheduler was sent the command new
10/03/2014 12:57:50;0002;PBS_Server;Svr;PBS_Server;Torque Server Version = 3.0.5, loglevel = 0
10/03/2014 12:57:50;0040;PBS_Server;Svr;tyrone-cluster;Scheduler was sent the command new
10/03/2014 12:58:14;0040;PBS_Server;Svr;tyrone-cluster;Scheduler was sent the command new
10/03/2014 12:58:46;0040;PBS_Server;Svr;tyrone-cluster;Scheduler was sent the command new
10/03/2014 12:59:22;0040;PBS_Server;Svr;tyrone-cluster;Scheduler was sent the command new
10/03/2014 12:59:54;0040;PBS_Server;Svr;tyrone-cluster;Scheduler was sent the command new
10/03/2014 13:00:29;0040;PBS_Server;Svr;tyrone-cluster;Scheduler was sent the command new
10/03/2014 13:01:00;0040;PBS_Server;Svr;tyrone-cluster;Scheduler was sent the command new
10/03/2014 13:01:37;0040;PBS_Server;Svr;tyrone-cluster;Scheduler was sent the command new
10/03/2014 13:02:08;0040;PBS_Server;Svr;tyrone-cluster;Scheduler was sent the command new
10/03/2014 13:02:43;0040;PBS_Server;Svr;tyrone-cluster;Scheduler was sent the command new
10/03/2014 13:02:50;0002;PBS_Server;Svr;PBS_Server;Torque Server Version = 3.0.5, loglevel = 0
10/03/2014 13:03:13;0040;PBS_Server;Svr;tyrone-cluster;Scheduler was sent the command new
10/03/2014 13:03:51;0040;PBS_Server;Svr;tyrone-cluster;Scheduler was sent the command new
10/03/2014 13:04:14;0040;PBS_Server;Svr;tyrone-cluster;Scheduler was sent the command new
10/03/2014 13:04:20;000d;PBS_Server;Job;43138.tyrone-cluster;Not sending email: User does not want mail of this type.
10/03/2014 13:04:20;0010;PBS_Server;Job;43138.tyrone-cluster;Exit_status=143 resources_used.cput=1535:44:15 resources_used.mem=30099852kb resources_used.vmem=74760132kb resources_used.walltime=24:00:45
10/03/2014 13:04:20;0008;PBS_Server;Job;NULL;on_job_exit valid pjob: 0x2ce5400 (substate=50)
10/03/2014 13:04:20;0008;PBS_Server;Job;NULL;on_job_exit valid pjob: 0x2ce5400 (substate=51)
10/03/2014 13:04:20;0008;PBS_Server;Job;NULL;on_job_exit valid pjob: 0x2ce5400 (substate=51)
10/03/2014 13:04:20;0008;PBS_Server;Job;NULL;on_job_exit valid pjob: 0x2ce5400 (substate=53)
10/03/2014 13:04:20;0100;PBS_Server;Job;43138.tyrone-cluster;dequeuing from qp256, state COMPLETE
10/03/2014 13:04:20;0040;PBS_Server;Svr;tyrone-cluster;Scheduler was sent the command term
10/03/2014 13:04:46;0040;PBS_Server;Svr;tyrone-cluster;Scheduler was sent the command new
10/03/2014 13:05:22;0040;PBS_Server;Svr;tyrone-cluster;Scheduler was sent the command new
10/03/2014 13:05:50;0040;PBS_Server;Svr;tyrone-cluster;Scheduler was sent the command new
10/03/2014 13:06:26;0040;PBS_Server;Svr;tyrone-cluster;Scheduler was sent the command new
10/03/2014 13:06:52;0040;PBS_Server;Svr;tyrone-cluster;Scheduler was sent the command new
10/03/2014 13:07:23;0040;PBS_Server;Svr;tyrone-cluster;Scheduler was sent the command new
10/03/2014 13:07:50;0002;PBS_Server;Svr;PBS_Server;Torque Server Version = 3.0.5, loglevel = 0
10/03/2014 13:07:57;0040;PBS_Server;Svr;tyrone-cluster;Scheduler was sent the command new
10/03/2014 13:08:24;0040;PBS_Server;Svr;tyrone-cluster;Scheduler was sent the command new
10/03/2014 13:08:54;0040;PBS_Server;Svr;tyrone-cluster;Scheduler was sent the command new
10/03/2014 13:09:29;0040;PBS_Server;Svr;tyrone-cluster;Scheduler was sent the command new
10/03/2014 13:09:59;0040;PBS_Server;Svr;tyrone-cluster;Scheduler was sent the command new
10/03/2014 13:10:35;0040;PBS_Server;Svr;tyrone-cluster;Scheduler was sent the command new
10/03/2014 13:11:03;0040;PBS_Server;Svr;tyrone-cluster;Scheduler was sent the command new
10/03/2014 13:11:31;0040;PBS_Server;Svr;tyrone-cluster;Scheduler was sent the command new
10/03/2014 13:12:07;0040;PBS_Server;Svr;tyrone-cluster;Scheduler was sent the command new
10/03/2014 13:12:38;0040;PBS_Server;Svr;tyrone-cluster;Scheduler was sent the command new
10/03/2014 13:12:50;0002;PBS_Server;Svr;PBS_Server;Torque Server Version = 3.0.5, loglevel = 0
10/03/2014 13:13:07;0040;PBS_Server;Svr;tyrone-cluster;Scheduler was sent the command new
10/03/2014 13:13:39;0040;PBS_Server;Svr;tyrone-cluster;Scheduler was sent the command new
10/03/2014 13:14:08;0040;PBS_Server;Svr;tyrone-cluster;Scheduler was sent the command new
10/03/2014 13:14:43;0040;PBS_Server;Svr;tyrone-cluster;Scheduler was sent the command new
10/03/2014 13:15:14;0040;PBS_Server;Svr;tyrone-cluster;Scheduler was sent the command new
10/03/2014 13:15:52;0040;PBS_Server;Svr;tyrone-cluster;Scheduler was sent the command new
10/03/2014 13:16:20;0040;PBS_Server;Svr;tyrone-cluster;Scheduler was sent the command new
10/03/2014 13:16:56;0040;PBS_Server;Svr;tyrone-cluster;Scheduler was sent the command new
10/03/2014 13:17:22;0040;PBS_Server;Svr;tyrone-cluster;Scheduler was sent the command new
10/03/2014 13:17:50;0002;PBS_Server;Svr;PBS_Server;Torque Server Version = 3.0.5, loglevel = 0
10/03/2014 13:17:54;0040;PBS_Server;Svr;tyrone-cluster;Scheduler was sent the command new
10/03/2014 13:18:26;0040;PBS_Server;Svr;tyrone-cluster;Scheduler was sent the command new
10/03/2014 13:18:54;0040;PBS_Server;Svr;tyrone-cluster;Scheduler was sent the command new
10/03/2014 13:19:23;0040;PBS_Server;Svr;tyrone-cluster;Scheduler was sent the command new
10/03/2014 13:19:58;0040;PBS_Server;Svr;tyrone-cluster;Scheduler was sent the command new
10/03/2014 13:20:29;0040;PBS_Server;Svr;tyrone-cluster;Scheduler was sent the command new
10/03/2014 13:21:07;0040;PBS_Server;Svr;tyrone-cluster;Scheduler was sent the command new
10/03/2014 13:21:35;0040;PBS_Server;Svr;tyrone-cluster;Scheduler was sent the command new
10/03/2014 13:22:11;0040;PBS_Server;Svr;tyrone-cluster;Scheduler was sent the command new
10/03/2014 13:22:38;0040;PBS_Server;Svr;tyrone-cluster;Scheduler was sent the command new
10/03/2014 13:22:50;0002;PBS_Server;Svr;PBS_Server;Torque Server Version = 3.0.5, loglevel = 0
10/03/2014 13:23:07;0040;PBS_Server;Svr;tyrone-cluster;Scheduler was sent the command new
10/03/2014 13:23:43;0040;PBS_Server;Svr;tyrone-cluster;Scheduler was sent the command new
10/03/2014 13:24:14;0040;PBS_Server;Svr;tyrone-cluster;Scheduler was sent the command new
10/03/2014 13:24:50;0040;PBS_Server;Svr;tyrone-cluster;Scheduler was sent the command new
10/03/2014 13:25:18;0040;PBS_Server;Svr;tyrone-cluster;Scheduler was sent the command new
10/03/2014 13:25:46;0040;PBS_Server;Svr;tyrone-cluster;Scheduler was sent the command new
10/03/2014 13:26:22;0040;PBS_Server;Svr;tyrone-cluster;Scheduler was sent the command new
10/03/2014 13:26:50;0040;PBS_Server;Svr;tyrone-cluster;Scheduler was sent the command new
10/03/2014 13:27:26;0040;PBS_Server;Svr;tyrone-cluster;Scheduler was sent the command new
10/03/2014 13:27:50;0002;PBS_Server;Svr;PBS_Server;Torque Server Version = 3.0.5, loglevel = 0
10/03/2014 13:27:53;0040;PBS_Server;Svr;tyrone-cluster;Scheduler was sent the command new
10/03/2014 13:28:23;0040;PBS_Server;Svr;tyrone-cluster;Scheduler was sent the command new
10/03/2014 13:28:56;0040;PBS_Server;Svr;tyrone-cluster;Scheduler was sent the command new
10/03/2014 13:29:24;0040;PBS_Server;Svr;tyrone-cluster;Scheduler was sent the command new
10/03/2014 13:29:53;0040;PBS_Server;Svr;tyrone-cluster;Scheduler was sent the command new
10/03/2014 13:30:28;0040;PBS_Server;Svr;tyrone-cluster;Scheduler was sent the command new
10/03/2014 13:30:59;0040;PBS_Server;Svr;tyrone-cluster;Scheduler was sent the command new
10/03/2014 13:31:37;0040;PBS_Server;Svr;tyrone-cluster;Scheduler was sent the command new
10/03/2014 13:32:05;0040;PBS_Server;Svr;tyrone-cluster;Scheduler was sent the command new
10/03/2014 13:32:41;0040;PBS_Server;Svr;tyrone-cluster;Scheduler was sent the command new
10/03/2014 13:32:50;0002;PBS_Server;Svr;PBS_Server;Torque Server Version = 3.0.5, loglevel = 0
10/03/2014 13:33:08;0040;PBS_Server;Svr;tyrone-cluster;Scheduler was sent the command new
10/03/2014 13:33:38;0040;PBS_Server;Svr;tyrone-cluster;Scheduler was sent the command new
10/03/2014 13:34:10;0040;PBS_Server;Svr;tyrone-cluster;Scheduler was sent the command new
10/03/2014 13:34:39;0040;PBS_Server;Svr;tyrone-cluster;Scheduler was sent the command new
10/03/2014 13:35:08;0040;PBS_Server;Svr;tyrone-cluster;Scheduler was sent the command new
10/03/2014 13:35:43;0040;PBS_Server;Svr;tyrone-cluster;Scheduler was sent the command new
10/03/2014 13:36:14;0040;PBS_Server;Svr;tyrone-cluster;Scheduler was sent the command new
10/03/2014 13:36:52;0040;PBS_Server;Svr;tyrone-cluster;Scheduler was sent the command new
10/03/2014 13:37:20;0040;PBS_Server;Svr;tyrone-cluster;Scheduler was sent the command new
10/03/2014 13:37:50;0002;PBS_Server;Svr;PBS_Server;Torque Server Version = 3.0.5, loglevel = 0
10/03/2014 13:37:51;0040;PBS_Server;Svr;tyrone-cluster;Scheduler was sent the command new
10/03/2014 13:38:22;0040;PBS_Server;Svr;tyrone-cluster;Scheduler was sent the command new
10/03/2014 13:38:53;0040;PBS_Server;Svr;tyrone-cluster;Scheduler was sent the command new
10/03/2014 13:39:28;0040;PBS_Server;Svr;tyrone-cluster;Scheduler was sent the command new
10/03/2014 13:39:59;0040;PBS_Server;Svr;tyrone-cluster;Scheduler was sent the command new
10/03/2014 13:40:37;0040;PBS_Server;Svr;tyrone-cluster;Scheduler was sent the command new
10/03/2014 13:41:05;0040;PBS_Server;Svr;tyrone-cluster;Scheduler was sent the command new
10/03/2014 13:41:41;0040;PBS_Server;Svr;tyrone-cluster;Scheduler was sent the command new
10/03/2014 13:42:08;0040;PBS_Server;Svr;tyrone-cluster;Scheduler was sent the command new
10/03/2014 13:42:38;0040;PBS_Server;Svr;tyrone-cluster;Scheduler was sent the command new
10/03/2014 13:42:50;0002;PBS_Server;Svr;PBS_Server;Torque Server Version = 3.0.5, loglevel = 0
10/03/2014 13:43:11;0040;PBS_Server;Svr;tyrone-cluster;Scheduler was sent the command new
10/03/2014 13:43:38;0040;PBS_Server;Svr;tyrone-cluster;Scheduler was sent the command new
10/03/2014 13:44:08;0040;PBS_Server;Svr;tyrone-cluster;Scheduler was sent the command new
10/03/2014 13:44:43;0040;PBS_Server;Svr;tyrone-cluster;Scheduler was sent the command new
10/03/2014 13:45:14;0040;PBS_Server;Svr;tyrone-cluster;Scheduler was sent the command new
10/03/2014 13:45:52;0040;PBS_Server;Svr;tyrone-cluster;Scheduler was sent the command new
10/03/2014 13:46:20;0040;PBS_Server;Svr;tyrone-cluster;Scheduler was sent the command new
10/03/2014 13:46:56;0040;PBS_Server;Svr;tyrone-cluster;Scheduler was sent the command new
10/03/2014 13:47:23;0040;PBS_Server;Svr;tyrone-cluster;Scheduler was sent the command new
10/03/2014 13:47:50;0002;PBS_Server;Svr;PBS_Server;Torque Server Version = 3.0.5, loglevel = 0
10/03/2014 13:47:53;0040;PBS_Server;Svr;tyrone-cluster;Scheduler was sent the command new
10/03/2014 13:48:27;0040;PBS_Server;Svr;tyrone-cluster;Scheduler was sent the command new
10/03/2014 13:48:58;0040;PBS_Server;Svr;tyrone-cluster;Scheduler was sent the command new
10/03/2014 13:49:36;0040;PBS_Server;Svr;tyrone-cluster;Scheduler was sent the command new
10/03/2014 13:50:05;0040;PBS_Server;Svr;tyrone-cluster;Scheduler was sent the command new
10/03/2014 13:50:37;0040;PBS_Server;Svr;tyrone-cluster;Scheduler was sent the command new
10/03/2014 13:51:08;0040;PBS_Server;Svr;tyrone-cluster;Scheduler was sent the command new
10/03/2014 13:51:38;0040;PBS_Server;Svr;tyrone-cluster;Scheduler was sent the command new
10/03/2014 13:52:13;0040;PBS_Server;Svr;tyrone-cluster;Scheduler was sent the command new
10/03/2014 13:52:43;0040;PBS_Server;Svr;tyrone-cluster;Scheduler was sent the command new
10/03/2014 13:52:50;0002;PBS_Server;Svr;PBS_Server;Torque Server Version = 3.0.5, loglevel = 0
10/03/2014 13:53:22;0040;PBS_Server;Svr;tyrone-cluster;Scheduler was sent the command new
10/03/2014 13:53:50;0040;PBS_Server;Svr;tyrone-cluster;Scheduler was sent the command new
10/03/2014 13:54:26;0040;PBS_Server;Svr;tyrone-cluster;Scheduler was sent the command new
10/03/2014 13:54:53;0040;PBS_Server;Svr;tyrone-cluster;Scheduler was sent the command new
10/03/2014 13:55:22;0040;PBS_Server;Svr;tyrone-cluster;Scheduler was sent the command new
10/03/2014 13:55:58;0040;PBS_Server;Svr;tyrone-cluster;Scheduler was sent the command new
10/03/2014 13:56:29;0040;PBS_Server;Svr;tyrone-cluster;Scheduler was sent the command new
10/03/2014 13:57:07;0040;PBS_Server;Svr;tyrone-cluster;Scheduler was sent the command new
10/03/2014 13:57:35;0040;PBS_Server;Svr;tyrone-cluster;Scheduler was sent the command new
10/03/2014 13:57:50;0002;PBS_Server;Svr;PBS_Server;Torque Server Version = 3.0.5, loglevel = 0
10/03/2014 13:58:07;0040;PBS_Server;Svr;tyrone-cluster;Scheduler was sent the command new
10/03/2014 13:58:38;0040;PBS_Server;Svr;tyrone-cluster;Scheduler was sent the command new
10/03/2014 13:59:08;0040;PBS_Server;Svr;tyrone-cluster;Scheduler was sent the command new
10/03/2014 13:59:42;0040;PBS_Server;Svr;tyrone-cluster;Scheduler was sent the command new
10/03/2014 14:00:13;0040;PBS_Server;Svr;tyrone-cluster;Scheduler was sent the command new
10/03/2014 14:00:51;0040;PBS_Server;Svr;tyrone-cluster;Scheduler was sent the command new
10/03/2014 14:01:20;0040;PBS_Server;Svr;tyrone-cluster;Scheduler was sent the command new
10/03/2014 14:01:51;0040;PBS_Server;Svr;tyrone-cluster;Scheduler was sent the command new
10/03/2014 14:02:22;0040;PBS_Server;Svr;tyrone-cluster;Scheduler was sent the command new
10/03/2014 14:02:50;0002;PBS_Server;Svr;PBS_Server;Torque Server Version = 3.0.5, loglevel = 0
10/03/2014 14:02:50;0040;PBS_Server;Svr;tyrone-cluster;Scheduler was sent the command new
10/03/2014 14:03:26;0040;PBS_Server;Svr;tyrone-cluster;Scheduler was sent the command new
10/03/2014 14:03:53;0040;PBS_Server;Svr;tyrone-cluster;Scheduler was sent the command new
10/03/2014 14:04:23;0040;PBS_Server;Svr;tyrone-cluster;Scheduler was sent the command new
10/03/2014 14:04:57;0040;PBS_Server;Svr;tyrone-cluster;Scheduler was sent the command new
10/03/2014 14:05:28;0040;PBS_Server;Svr;tyrone-cluster;Scheduler was sent the command new
10/03/2014 14:06:07;0040;PBS_Server;Svr;tyrone-cluster;Scheduler was sent the command new
10/03/2014 14:06:35;0040;PBS_Server;Svr;tyrone-cluster;Scheduler was sent the command new
10/03/2014 14:07:10;0040;PBS_Server;Svr;tyrone-cluster;Scheduler was sent the command new
10/03/2014 14:07:36;0040;PBS_Server;Svr;tyrone-cluster;Scheduler was sent the command new
10/03/2014 14:07:50;0002;PBS_Server;Svr;PBS_Server;Torque Server Version = 3.0.5, loglevel = 0
10/03/2014 14:08:05;0040;PBS_Server;Svr;tyrone-cluster;Scheduler was sent the command new
10/03/2014 14:08:41;0040;PBS_Server;Svr;tyrone-cluster;Scheduler was sent the command new
10/03/2014 14:09:08;0040;PBS_Server;Svr;tyrone-cluster;Scheduler was sent the command new
10/03/2014 14:09:38;0040;PBS_Server;Svr;tyrone-cluster;Scheduler was sent the command new
10/03/2014 14:10:12;0040;PBS_Server;Svr;tyrone-cluster;Scheduler was sent the command new
10/03/2014 14:10:43;0040;PBS_Server;Svr;tyrone-cluster;Scheduler was sent the command new
10/03/2014 14:11:22;0040;PBS_Server;Svr;tyrone-cluster;Scheduler was sent the command new
10/03/2014 14:11:50;0040;PBS_Server;Svr;tyrone-cluster;Scheduler was sent the command new
10/03/2014 14:12:20;0040;PBS_Server;Svr;tyrone-cluster;Scheduler was sent the command new
10/03/2014 14:12:50;0002;PBS_Server;Svr;PBS_Server;Torque Server Version = 3.0.5, loglevel = 0
10/03/2014 14:12:51;0040;PBS_Server;Svr;tyrone-cluster;Scheduler was sent the command new
10/03/2014 14:13:20;0040;PBS_Server;Svr;tyrone-cluster;Scheduler was sent the command new
10/03/2014 14:13:55;0040;PBS_Server;Svr;tyrone-cluster;Scheduler was sent the command new
10/03/2014 14:14:21;0040;PBS_Server;Svr;tyrone-cluster;Scheduler was sent the command new
10/03/2014 14:14:50;0040;PBS_Server;Svr;tyrone-cluster;Scheduler was sent the command new
10/03/2014 14:15:26;0040;PBS_Server;Svr;tyrone-cluster;Scheduler was sent the command new
10/03/2014 14:15:53;0040;PBS_Server;Svr;tyrone-cluster;Scheduler was sent the command new
10/03/2014 14:16:23;0040;PBS_Server;Svr;tyrone-cluster;Scheduler was sent the command new
10/03/2014 14:16:57;0040;PBS_Server;Svr;tyrone-cluster;Scheduler was sent the command new
10/03/2014 14:17:28;0040;PBS_Server;Svr;tyrone-cluster;Scheduler was sent the command new
10/03/2014 14:17:50;0002;PBS_Server;Svr;PBS_Server;Torque Server Version = 3.0.5, loglevel = 0
10/03/2014 14:18:07;0040;PBS_Server;Svr;tyrone-cluster;Scheduler was sent the command new
10/03/2014 14:18:35;0040;PBS_Server;Svr;tyrone-cluster;Scheduler was sent the command new
10/03/2014 14:19:05;0040;PBS_Server;Svr;tyrone-cluster;Scheduler was sent the command new
10/03/2014 14:19:36;0040;PBS_Server;Svr;tyrone-cluster;Scheduler was sent the command new
10/03/2014 14:20:05;0040;PBS_Server;Svr;tyrone-cluster;Scheduler was sent the command new
10/03/2014 14:20:37;0040;PBS_Server;Svr;tyrone-cluster;Scheduler was sent the command new
10/03/2014 14:21:08;0040;PBS_Server;Svr;tyrone-cluster;Scheduler was sent the command new
10/03/2014 14:21:38;0040;PBS_Server;Svr;tyrone-cluster;Scheduler was sent the command new
10/03/2014 14:22:12;0040;PBS_Server;Svr;tyrone-cluster;Scheduler was sent the command new
10/03/2014 14:22:43;0040;PBS_Server;Svr;tyrone-cluster;Scheduler was sent the command new
10/03/2014 14:22:50;0002;PBS_Server;Svr;PBS_Server;Torque Server Version = 3.0.5, loglevel = 0
10/03/2014 14:23:22;0040;PBS_Server;Svr;tyrone-cluster;Scheduler was sent the command new
10/03/2014 14:23:50;0040;PBS_Server;Svr;tyrone-cluster;Scheduler was sent the command new
10/03/2014 14:24:20;0040;PBS_Server;Svr;tyrone-cluster;Scheduler was sent the command new
10/03/2014 14:24:51;0040;PBS_Server;Svr;tyrone-cluster;Scheduler was sent the command new
10/03/2014 14:25:20;0040;PBS_Server;Svr;tyrone-cluster;Scheduler was sent the command new
10/03/2014 14:25:55;0040;PBS_Server;Svr;tyrone-cluster;Scheduler was sent the command new
10/03/2014 14:26:21;0040;PBS_Server;Svr;tyrone-cluster;Scheduler was sent the command new
10/03/2014 14:26:50;0040;PBS_Server;Svr;tyrone-cluster;Scheduler was sent the command new
10/03/2014 14:27:26;0040;PBS_Server;Svr;tyrone-cluster;Scheduler was sent the command new
10/03/2014 14:27:50;0002;PBS_Server;Svr;PBS_Server;Torque Server Version = 3.0.5, loglevel = 0
10/03/2014 14:27:53;0040;PBS_Server;Svr;tyrone-cluster;Scheduler was sent the command new
10/03/2014 14:28:23;0040;PBS_Server;Svr;tyrone-cluster;Scheduler was sent the command new
10/03/2014 14:28:57;0040;PBS_Server;Svr;tyrone-cluster;Scheduler was sent the command new
10/03/2014 14:29:28;0040;PBS_Server;Svr;tyrone-cluster;Scheduler was sent the command new
10/03/2014 14:30:07;0040;PBS_Server;Svr;tyrone-cluster;Scheduler was sent the command new
10/03/2014 14:30:35;0040;PBS_Server;Svr;tyrone-cluster;Scheduler was sent the command new
10/03/2014 14:31:05;0040;PBS_Server;Svr;tyrone-cluster;Scheduler was sent the command new
10/03/2014 14:31:37;0040;PBS_Server;Svr;tyrone-cluster;Scheduler was sent the command new
10/03/2014 14:32:05;0040;PBS_Server;Svr;tyrone-cluster;Scheduler was sent the command new
10/03/2014 14:32:35;0040;PBS_Server;Svr;tyrone-cluster;Scheduler was sent the command new
10/03/2014 14:32:50;0002;PBS_Server;Svr;PBS_Server;Torque Server Version = 3.0.5, loglevel = 0
10/03/2014 14:33:06;0040;PBS_Server;Svr;tyrone-cluster;Scheduler was sent the command new
10/03/2014 14:33:35;0040;PBS_Server;Svr;tyrone-cluster;Scheduler was sent the command new
10/03/2014 14:34:04;0040;PBS_Server;Svr;tyrone-cluster;Scheduler was sent the command new
10/03/2014 14:34:37;0040;PBS_Server;Svr;tyrone-cluster;Scheduler was sent the command new
10/03/2014 14:35:05;0040;PBS_Server;Svr;tyrone-cluster;Scheduler was sent the command new
10/03/2014 14:35:34;0040;PBS_Server;Svr;tyrone-cluster;Scheduler was sent the command new
10/03/2014 14:36:07;0040;PBS_Server;Svr;tyrone-cluster;Scheduler was sent the command new
10/03/2014 14:36:35;0040;PBS_Server;Svr;tyrone-cluster;Scheduler was sent the command new
10/03/2014 14:37:05;0040;PBS_Server;Svr;tyrone-cluster;Scheduler was sent the command new
10/03/2014 14:37:37;0040;PBS_Server;Svr;tyrone-cluster;Scheduler was sent the command new
10/03/2014 14:37:50;0002;PBS_Server;Svr;PBS_Server;Torque Server Version = 3.0.5, loglevel = 0
10/03/2014 14:38:05;0040;PBS_Server;Svr;tyrone-cluster;Scheduler was sent the command new
10/03/2014 14:38:35;0040;PBS_Server;Svr;tyrone-cluster;Scheduler was sent the command new
10/03/2014 14:39:06;0040;PBS_Server;Svr;tyrone-cluster;Scheduler was sent the command new
10/03/2014 14:39:35;0040;PBS_Server;Svr;tyrone-cluster;Scheduler was sent the command new
10/03/2014 14:40:10;0040;PBS_Server;Svr;tyrone-cluster;Scheduler was sent the command new
10/03/2014 14:40:37;0040;PBS_Server;Svr;tyrone-cluster;Scheduler was sent the command new
10/03/2014 14:41:08;0040;PBS_Server;Svr;tyrone-cluster;Scheduler was sent the command new
10/03/2014 14:41:41;0040;PBS_Server;Svr;tyrone-cluster;Scheduler was sent the command new
10/03/2014 14:42:08;0040;PBS_Server;Svr;tyrone-cluster;Scheduler was sent the command new
10/03/2014 14:42:37;0040;PBS_Server;Svr;tyrone-cluster;Scheduler was sent the command new
10/03/2014 14:42:50;0002;PBS_Server;Svr;PBS_Server;Torque Server Version = 3.0.5, loglevel = 0
10/03/2014 14:43:11;0040;PBS_Server;Svr;tyrone-cluster;Scheduler was sent the command new
10/03/2014 14:43:37;0040;PBS_Server;Svr;tyrone-cluster;Scheduler was sent the command new
10/03/2014 14:44:09;0040;PBS_Server;Svr;tyrone-cluster;Scheduler was sent the command new
10/03/2014 14:44:42;0040;PBS_Server;Svr;tyrone-cluster;Scheduler was sent the command new
10/03/2014 14:45:16;0040;PBS_Server;Svr;tyrone-cluster;Scheduler was sent the command new
10/03/2014 14:45:51;0040;PBS_Server;Svr;tyrone-cluster;Scheduler was sent the command new
10/03/2014 14:46:20;0040;PBS_Server;Svr;tyrone-cluster;Scheduler was sent the command new
10/03/2014 14:46:55;0040;PBS_Server;Svr;tyrone-cluster;Scheduler was sent the command new
10/03/2014 14:47:23;0040;PBS_Server;Svr;tyrone-cluster;Scheduler was sent the command new
10/03/2014 14:47:50;0002;PBS_Server;Svr;PBS_Server;Torque Server Version = 3.0.5, loglevel = 0
10/03/2014 14:47:52;0040;PBS_Server;Svr;tyrone-cluster;Scheduler was sent the command new
10/03/2014 14:48:27;0040;PBS_Server;Svr;tyrone-cluster;Scheduler was sent the command new
10/03/2014 14:49:01;0040;PBS_Server;Svr;tyrone-cluster;Scheduler was sent the command new
10/03/2014 14:49:37;0040;PBS_Server;Svr;tyrone-cluster;Scheduler was sent the command new
10/03/2014 14:50:05;0040;PBS_Server;Svr;tyrone-cluster;Scheduler was sent the command new
10/03/2014 14:50:37;0040;PBS_Server;Svr;tyrone-cluster;Scheduler was sent the command new
10/03/2014 14:51:06;0040;PBS_Server;Svr;tyrone-cluster;Scheduler was sent the command new
10/03/2014 14:51:35;0040;PBS_Server;Svr;tyrone-cluster;Scheduler was sent the command new
10/03/2014 14:52:11;0040;PBS_Server;Svr;tyrone-cluster;Scheduler was sent the command new
10/03/2014 14:52:37;0040;PBS_Server;Svr;tyrone-cluster;Scheduler was sent the command new
10/03/2014 14:52:50;0002;PBS_Server;Svr;PBS_Server;Torque Server Version = 3.0.5, loglevel = 0
10/03/2014 14:53:05;0040;PBS_Server;Svr;tyrone-cluster;Scheduler was sent the command new
10/03/2014 14:53:41;0040;PBS_Server;Svr;tyrone-cluster;Scheduler was sent the command new
10/03/2014 14:54:07;0040;PBS_Server;Svr;tyrone-cluster;Scheduler was sent the command new
10/03/2014 14:54:35;0040;PBS_Server;Svr;tyrone-cluster;Scheduler was sent the command new
10/03/2014 14:55:11;0040;PBS_Server;Svr;tyrone-cluster;Scheduler was sent the command new
10/03/2014 14:55:37;0040;PBS_Server;Svr;tyrone-cluster;Scheduler was sent the command new
10/03/2014 14:56:09;0040;PBS_Server;Svr;tyrone-cluster;Scheduler was sent the command new
10/03/2014 14:56:41;0040;PBS_Server;Svr;tyrone-cluster;Scheduler was sent the command new
10/03/2014 14:57:16;0040;PBS_Server;Svr;tyrone-cluster;Scheduler was sent the command new
10/03/2014 14:57:50;0002;PBS_Server;Svr;PBS_Server;Torque Server Version = 3.0.5, loglevel = 0
10/03/2014 14:57:51;0040;PBS_Server;Svr;tyrone-cluster;Scheduler was sent the command new
10/03/2014 14:58:20;0040;PBS_Server;Svr;tyrone-cluster;Scheduler was sent the command new
10/03/2014 14:58:56;0040;PBS_Server;Svr;tyrone-cluster;Scheduler was sent the command new
10/03/2014 14:59:22;0040;PBS_Server;Svr;tyrone-cluster;Scheduler was sent the command new
10/03/2014 14:59:50;0040;PBS_Server;Svr;tyrone-cluster;Scheduler was sent the command new
10/03/2014 15:00:26;0040;PBS_Server;Svr;tyrone-cluster;Scheduler was sent the command new
10/03/2014 15:00:52;0040;PBS_Server;Svr;tyrone-cluster;Scheduler was sent the command new
10/03/2014 15:01:20;0040;PBS_Server;Svr;tyrone-cluster;Scheduler was sent the command new
10/03/2014 15:01:56;0040;PBS_Server;Svr;tyrone-cluster;Scheduler was sent the command new
10/03/2014 15:02:22;0040;PBS_Server;Svr;tyrone-cluster;Scheduler was sent the command new
10/03/2014 15:02:50;0002;PBS_Server;Svr;PBS_Server;Torque Server Version = 3.0.5, loglevel = 0
10/03/2014 15:02:54;0040;PBS_Server;Svr;tyrone-cluster;Scheduler was sent the command new
10/03/2014 15:03:27;0040;PBS_Server;Svr;tyrone-cluster;Scheduler was sent the command new
10/03/2014 15:04:01;0040;PBS_Server;Svr;tyrone-cluster;Scheduler was sent the command new
10/03/2014 15:04:36;0040;PBS_Server;Svr;tyrone-cluster;Scheduler was sent the command new
10/03/2014 15:05:05;0040;PBS_Server;Svr;tyrone-cluster;Scheduler was sent the command new
10/03/2014 15:05:37;0040;PBS_Server;Svr;tyrone-cluster;Scheduler was sent the command new
10/03/2014 15:06:06;0040;PBS_Server;Svr;tyrone-cluster;Scheduler was sent the command new
10/03/2014 15:06:35;0040;PBS_Server;Svr;tyrone-cluster;Scheduler was sent the command new
10/03/2014 15:07:11;0040;PBS_Server;Svr;tyrone-cluster;Scheduler was sent the command new
10/03/2014 15:07:37;0040;PBS_Server;Svr;tyrone-cluster;Scheduler was sent the command new
10/03/2014 15:07:50;0002;PBS_Server;Svr;PBS_Server;Torque Server Version = 3.0.5, loglevel = 0
10/03/2014 15:08:05;0040;PBS_Server;Svr;tyrone-cluster;Scheduler was sent the command new
10/03/2014 15:08:41;0040;PBS_Server;Svr;tyrone-cluster;Scheduler was sent the command new
10/03/2014 15:09:07;0040;PBS_Server;Svr;tyrone-cluster;Scheduler was sent the command new
10/03/2014 15:09:35;0040;PBS_Server;Svr;tyrone-cluster;Scheduler was sent the command new
10/03/2014 15:10:11;0040;PBS_Server;Svr;tyrone-cluster;Scheduler was sent the command new
10/03/2014 15:10:37;0040;PBS_Server;Svr;tyrone-cluster;Scheduler was sent the command new
10/03/2014 15:11:08;0040;PBS_Server;Svr;tyrone-cluster;Scheduler was sent the command new
10/03/2014 15:11:41;0040;PBS_Server;Svr;tyrone-cluster;Scheduler was sent the command new
10/03/2014 15:12:16;0040;PBS_Server;Svr;tyrone-cluster;Scheduler was sent the command new
10/03/2014 15:12:50;0002;PBS_Server;Svr;PBS_Server;Torque Server Version = 3.0.5, loglevel = 0
10/03/2014 15:12:50;0040;PBS_Server;Svr;tyrone-cluster;Scheduler was sent the command new
10/03/2014 15:12:51;0100;PBS_Server;Job;43358.tyrone-cluster;enqueuing into batch, state 1 hop 1
10/03/2014 15:12:51;0100;PBS_Server;Job;43358.tyrone-cluster;dequeuing from batch, state QUEUED
10/03/2014 15:12:51;0100;PBS_Server;Job;43358.tyrone-cluster;enqueuing into qp256, state 1 hop 1
10/03/2014 15:12:51;0008;PBS_Server;Job;43358.tyrone-cluster;Job Queued at request of asejobin@tyrone-cluster, owner = asejobin@tyrone-cluster, job name = JOBNAME, queue = qp256
10/03/2014 15:12:51;0040;PBS_Server;Svr;tyrone-cluster;Scheduler was sent the command new
10/03/2014 15:12:51;0008;PBS_Server;Job;43358.tyrone-cluster;Job Modified at request of Scheduler@tyrone-cluster
10/03/2014 15:12:51;0008;PBS_Server;Job;43358.tyrone-cluster;Job Run at request of Scheduler@tyrone-cluster
10/03/2014 15:12:51;0040;PBS_Server;Svr;tyrone-cluster;Scheduler was sent the command recyc
10/03/2014 15:13:19;0040;PBS_Server;Svr;tyrone-cluster;Scheduler was sent the command new
10/03/2014 15:13:22;000d;PBS_Server;Job;43358.tyrone-cluster;Not sending email: User does not want mail of this type.
10/03/2014 15:13:49;0040;PBS_Server;Svr;tyrone-cluster;Scheduler was sent the command new
10/03/2014 15:14:22;0040;PBS_Server;Svr;tyrone-cluster;Scheduler was sent the command new
10/03/2014 15:14:50;0040;PBS_Server;Svr;tyrone-cluster;Scheduler was sent the command new
10/03/2014 15:15:20;0040;PBS_Server;Svr;tyrone-cluster;Scheduler was sent the command new
10/03/2014 15:15:52;0040;PBS_Server;Svr;tyrone-cluster;Scheduler was sent the command new
10/03/2014 15:16:20;0040;PBS_Server;Svr;tyrone-cluster;Scheduler was sent the command new
10/03/2014 15:16:56;0040;PBS_Server;Svr;tyrone-cluster;Scheduler was sent the command new
10/03/2014 15:17:22;0040;PBS_Server;Svr;tyrone-cluster;Scheduler was sent the command new
10/03/2014 15:17:50;0002;PBS_Server;Svr;PBS_Server;Torque Server Version = 3.0.5, loglevel = 0
10/03/2014 15:17:52;0040;PBS_Server;Svr;tyrone-cluster;Scheduler was sent the command new
10/03/2014 15:18:26;0040;PBS_Server;Svr;tyrone-cluster;Scheduler was sent the command new
10/03/2014 15:18:57;0040;PBS_Server;Svr;tyrone-cluster;Scheduler was sent the command new
10/03/2014 15:19:37;0040;PBS_Server;Svr;tyrone-cluster;Scheduler was sent the command new
10/03/2014 15:20:05;0040;PBS_Server;Svr;tyrone-cluster;Scheduler was sent the command new
10/03/2014 15:20:34;0040;PBS_Server;Svr;tyrone-cluster;Scheduler was sent the command new
10/03/2014 15:21:07;0040;PBS_Server;Svr;tyrone-cluster;Scheduler was sent the command new
10/03/2014 15:21:35;0040;PBS_Server;Svr;tyrone-cluster;Scheduler was sent the command new
10/03/2014 15:22:11;0040;PBS_Server;Svr;tyrone-cluster;Scheduler was sent the command new
10/03/2014 15:22:37;0040;PBS_Server;Svr;tyrone-cluster;Scheduler was sent the command new
10/03/2014 15:22:50;0002;PBS_Server;Svr;PBS_Server;Torque Server Version = 3.0.5, loglevel = 0
10/03/2014 15:23:07;0040;PBS_Server;Svr;tyrone-cluster;Scheduler was sent the command new
10/03/2014 15:23:41;0040;PBS_Server;Svr;tyrone-cluster;Scheduler was sent the command new
10/03/2014 15:24:12;0040;PBS_Server;Svr;tyrone-cluster;Scheduler was sent the command new
10/03/2014 15:24:52;0040;PBS_Server;Svr;tyrone-cluster;Scheduler was sent the command new
10/03/2014 15:25:20;0040;PBS_Server;Svr;tyrone-cluster;Scheduler was sent the command new
10/03/2014 15:25:50;0040;PBS_Server;Svr;tyrone-cluster;Scheduler was sent the command new
10/03/2014 15:26:22;0040;PBS_Server;Svr;tyrone-cluster;Scheduler was sent the command new
10/03/2014 15:26:50;0040;PBS_Server;Svr;tyrone-cluster;Scheduler was sent the command new
10/03/2014 15:27:26;0040;PBS_Server;Svr;tyrone-cluster;Scheduler was sent the command new
10/03/2014 15:27:50;0002;PBS_Server;Svr;PBS_Server;Torque Server Version = 3.0.5, loglevel = 0
10/03/2014 15:27:52;0040;PBS_Server;Svr;tyrone-cluster;Scheduler was sent the command new
10/03/2014 15:28:20;0040;PBS_Server;Svr;tyrone-cluster;Scheduler was sent the command new
10/03/2014 15:28:56;0040;PBS_Server;Svr;tyrone-cluster;Scheduler was sent the command new
10/03/2014 15:29:22;0040;PBS_Server;Svr;tyrone-cluster;Scheduler was sent the command new
10/03/2014 15:29:51;0040;PBS_Server;Svr;tyrone-cluster;Scheduler was sent the command new
10/03/2014 15:30:26;0040;PBS_Server;Svr;tyrone-cluster;Scheduler was sent the command new
10/03/2014 15:30:56;0040;PBS_Server;Svr;tyrone-cluster;Scheduler was sent the command new
10/03/2014 15:31:37;0040;PBS_Server;Svr;tyrone-cluster;Scheduler was sent the command new
10/03/2014 15:32:05;0040;PBS_Server;Svr;tyrone-cluster;Scheduler was sent the command new
10/03/2014 15:32:35;0040;PBS_Server;Svr;tyrone-cluster;Scheduler was sent the command new
10/03/2014 15:32:50;0002;PBS_Server;Svr;PBS_Server;Torque Server Version = 3.0.5, loglevel = 0
10/03/2014 15:33:07;0040;PBS_Server;Svr;tyrone-cluster;Scheduler was sent the command new
10/03/2014 15:33:35;0040;PBS_Server;Svr;tyrone-cluster;Scheduler was sent the command new
10/03/2014 15:34:11;0040;PBS_Server;Svr;tyrone-cluster;Scheduler was sent the command new
10/03/2014 15:34:37;0040;PBS_Server;Svr;tyrone-cluster;Scheduler was sent the command new
10/03/2014 15:35:07;0040;PBS_Server;Svr;tyrone-cluster;Scheduler was sent the command new
10/03/2014 15:35:40;0040;PBS_Server;Svr;tyrone-cluster;Scheduler was sent the command new
10/03/2014 15:36:08;0040;PBS_Server;Svr;tyrone-cluster;Scheduler was sent the command new
10/03/2014 15:36:37;0040;PBS_Server;Svr;tyrone-cluster;Scheduler was sent the command new
10/03/2014 15:37:11;0040;PBS_Server;Svr;tyrone-cluster;Scheduler was sent the command new
10/03/2014 15:37:46;0040;PBS_Server;Svr;tyrone-cluster;Scheduler was sent the command new
10/03/2014 15:37:50;0002;PBS_Server;Svr;PBS_Server;Torque Server Version = 3.0.5, loglevel = 0
10/03/2014 15:38:22;0040;PBS_Server;Svr;tyrone-cluster;Scheduler was sent the command new
10/03/2014 15:38:50;0040;PBS_Server;Svr;tyrone-cluster;Scheduler was sent the command new
10/03/2014 15:39:26;0040;PBS_Server;Svr;tyrone-cluster;Scheduler was sent the command new
10/03/2014 15:39:52;0040;PBS_Server;Svr;tyrone-cluster;Scheduler was sent the command new
10/03/2014 15:40:21;0040;PBS_Server;Svr;tyrone-cluster;Scheduler was sent the command new
10/03/2014 15:40:56;0040;PBS_Server;Svr;tyrone-cluster;Scheduler was sent the command new
10/03/2014 15:41:31;0040;PBS_Server;Svr;tyrone-cluster;Scheduler was sent the command new
10/03/2014 15:42:02;0040;PBS_Server;Svr;tyrone-cluster;Scheduler was sent the command new
10/03/2014 15:42:34;0040;PBS_Server;Svr;tyrone-cluster;Scheduler was sent the command new
10/03/2014 15:42:50;0002;PBS_Server;Svr;PBS_Server;Torque Server Version = 3.0.5, loglevel = 0
10/03/2014 15:43:04;0040;PBS_Server;Svr;tyrone-cluster;Scheduler was sent the command new
10/03/2014 15:43:37;0040;PBS_Server;Svr;tyrone-cluster;Scheduler was sent the command new
10/03/2014 15:44:05;0040;PBS_Server;Svr;tyrone-cluster;Scheduler was sent the command new
10/03/2014 15:44:41;0040;PBS_Server;Svr;tyrone-cluster;Scheduler was sent the command new
10/03/2014 15:45:07;0040;PBS_Server;Svr;tyrone-cluster;Scheduler was sent the command new
10/03/2014 15:45:37;0040;PBS_Server;Svr;tyrone-cluster;Scheduler was sent the command new
10/03/2014 15:46:11;0040;PBS_Server;Svr;tyrone-cluster;Scheduler was sent the command new
10/03/2014 15:46:46;0040;PBS_Server;Svr;tyrone-cluster;Scheduler was sent the command new
10/03/2014 15:47:21;0040;PBS_Server;Svr;tyrone-cluster;Scheduler was sent the command new
10/03/2014 15:47:50;0002;PBS_Server;Svr;PBS_Server;Torque Server Version = 3.0.5, loglevel = 0
10/03/2014 15:47:50;0040;PBS_Server;Svr;tyrone-cluster;Scheduler was sent the command new
10/03/2014 15:48:25;0040;PBS_Server;Svr;tyrone-cluster;Scheduler was sent the command new
10/03/2014 15:48:51;0040;PBS_Server;Svr;tyrone-cluster;Scheduler was sent the command new
10/03/2014 15:49:20;0040;PBS_Server;Svr;tyrone-cluster;Scheduler was sent the command new
10/03/2014 15:49:55;0040;PBS_Server;Svr;tyrone-cluster;Scheduler was sent the command new
10/03/2014 15:50:21;0040;PBS_Server;Svr;tyrone-cluster;Scheduler was sent the command new
10/03/2014 15:50:51;0040;PBS_Server;Svr;tyrone-cluster;Scheduler was sent the command new
10/03/2014 15:51:26;0040;PBS_Server;Svr;tyrone-cluster;Scheduler was sent the command new
10/03/2014 15:52:01;0040;PBS_Server;Svr;tyrone-cluster;Scheduler was sent the command new
10/03/2014 15:52:36;0040;PBS_Server;Svr;tyrone-cluster;Scheduler was sent the command new
10/03/2014 15:52:50;0002;PBS_Server;Svr;PBS_Server;Torque Server Version = 3.0.5, loglevel = 0
10/03/2014 15:53:05;0040;PBS_Server;Svr;tyrone-cluster;Scheduler was sent the command new
10/03/2014 15:53:39;0040;PBS_Server;Svr;tyrone-cluster;Scheduler was sent the command new
10/03/2014 15:54:06;0040;PBS_Server;Svr;tyrone-cluster;Scheduler was sent the command new
10/03/2014 15:54:35;0040;PBS_Server;Svr;tyrone-cluster;Scheduler was sent the command new
10/03/2014 15:55:11;0040;PBS_Server;Svr;tyrone-cluster;Scheduler was sent the command new
10/03/2014 15:55:36;0040;PBS_Server;Svr;tyrone-cluster;Scheduler was sent the command new
10/03/2014 15:56:05;0040;PBS_Server;Svr;tyrone-cluster;Scheduler was sent the command new
10/03/2014 15:56:40;0040;PBS_Server;Svr;tyrone-cluster;Scheduler was sent the command new
10/03/2014 15:57:06;0040;PBS_Server;Svr;tyrone-cluster;Scheduler was sent the command new
10/03/2014 15:57:37;0040;PBS_Server;Svr;tyrone-cluster;Scheduler was sent the command new
10/03/2014 15:57:50;0002;PBS_Server;Svr;PBS_Server;Torque Server Version = 3.0.5, loglevel = 0
10/03/2014 15:58:10;0040;PBS_Server;Svr;tyrone-cluster;Scheduler was sent the command new
10/03/2014 15:58:37;0040;PBS_Server;Svr;tyrone-cluster;Scheduler was sent the command new
10/03/2014 15:59:07;0040;PBS_Server;Svr;tyrone-cluster;Scheduler was sent the command new
10/03/2014 15:59:41;0040;PBS_Server;Svr;tyrone-cluster;Scheduler was sent the command new
10/03/2014 16:00:16;0040;PBS_Server;Svr;tyrone-cluster;Scheduler was sent the command new
10/03/2014 16:00:51;0040;PBS_Server;Svr;tyrone-cluster;Scheduler was sent the command new
10/03/2014 16:01:20;0040;PBS_Server;Svr;tyrone-cluster;Scheduler was sent the command new
10/03/2014 16:01:55;0040;PBS_Server;Svr;tyrone-cluster;Scheduler was sent the command new
10/03/2014 16:02:21;0040;PBS_Server;Svr;tyrone-cluster;Scheduler was sent the command new
10/03/2014 16:02:50;0002;PBS_Server;Svr;PBS_Server;Torque Server Version = 3.0.5, loglevel = 0
10/03/2014 16:02:52;0040;PBS_Server;Svr;tyrone-cluster;Scheduler was sent the command new
10/03/2014 16:03:26;0040;PBS_Server;Svr;tyrone-cluster;Scheduler was sent the command new
10/03/2014 16:04:01;0040;PBS_Server;Svr;tyrone-cluster;Scheduler was sent the command new
10/03/2014 16:04:36;0040;PBS_Server;Svr;tyrone-cluster;Scheduler was sent the command new
10/03/2014 16:05:05;0040;PBS_Server;Svr;tyrone-cluster;Scheduler was sent the command new
10/03/2014 16:05:37;0040;PBS_Server;Svr;tyrone-cluster;Scheduler was sent the command new
10/03/2014 16:06:07;0040;PBS_Server;Svr;tyrone-cluster;Scheduler was sent the command new
10/03/2014 16:06:37;0040;PBS_Server;Svr;tyrone-cluster;Scheduler was sent the command new
10/03/2014 16:07:11;0040;PBS_Server;Svr;tyrone-cluster;Scheduler was sent the command new
10/03/2014 16:07:46;0040;PBS_Server;Svr;tyrone-cluster;Scheduler was sent the command new
10/03/2014 16:07:50;0002;PBS_Server;Svr;PBS_Server;Torque Server Version = 3.0.5, loglevel = 0
10/03/2014 16:08:14;0040;PBS_Server;Svr;tyrone-cluster;Scheduler was sent the command new
10/03/2014 16:08:49;0040;PBS_Server;Svr;tyrone-cluster;Scheduler was sent the command new
10/03/2014 16:09:18;0040;PBS_Server;Svr;tyrone-cluster;Scheduler was sent the command new
10/03/2014 16:09:51;0040;PBS_Server;Svr;tyrone-cluster;Scheduler was sent the command new
10/03/2014 16:10:20;0040;PBS_Server;Svr;tyrone-cluster;Scheduler was sent the command new
10/03/2014 16:10:55;0040;PBS_Server;Svr;tyrone-cluster;Scheduler was sent the command new
10/03/2014 16:11:11;0008;PBS_Server;Job;43358.tyrone-cluster;Job deleted at request of asejobin@tyrone-cluster
10/03/2014 16:11:11;0008;PBS_Server;Job;43358.tyrone-cluster;Job sent signal SIGTERM on delete
10/03/2014 16:11:11;000d;PBS_Server;Job;43358.tyrone-cluster;Not sending email: User does not want mail of this type.
10/03/2014 16:11:11;0010;PBS_Server;Job;43358.tyrone-cluster;Exit_status=143 resources_used.cput=16:25:01 resources_used.mem=9394880kb resources_used.vmem=47374740kb resources_used.walltime=00:58:21
10/03/2014 16:11:11;0008;PBS_Server;Job;NULL;on_job_exit valid pjob: 0x2ce5400 (substate=50)
10/03/2014 16:11:11;0008;PBS_Server;Job;NULL;on_job_exit valid pjob: 0x2ce5400 (substate=51)
10/03/2014 16:11:11;0008;PBS_Server;Job;NULL;on_job_exit valid pjob: 0x2ce5400 (substate=51)
10/03/2014 16:11:11;0008;PBS_Server;Job;NULL;on_job_exit valid pjob: 0x2ce5400 (substate=53)
10/03/2014 16:11:11;0100;PBS_Server;Job;43358.tyrone-cluster;dequeuing from qp256, state COMPLETE
10/03/2014 16:11:11;0040;PBS_Server;Svr;tyrone-cluster;Scheduler was sent the command term
10/03/2014 16:11:20;0040;PBS_Server;Svr;tyrone-cluster;Scheduler was sent the command new
10/03/2014 16:11:23;0100;PBS_Server;Job;43359.tyrone-cluster;enqueuing into batch, state 1 hop 1
10/03/2014 16:11:23;0100;PBS_Server;Job;43359.tyrone-cluster;dequeuing from batch, state QUEUED
10/03/2014 16:11:23;0100;PBS_Server;Job;43359.tyrone-cluster;enqueuing into qp256, state 1 hop 1
10/03/2014 16:11:23;0008;PBS_Server;Job;43359.tyrone-cluster;Job Queued at request of asejobin@tyrone-cluster, owner = asejobin@tyrone-cluster, job name = JOBNAME, queue = qp256
10/03/2014 16:11:23;0040;PBS_Server;Svr;tyrone-cluster;Scheduler was sent the command new
10/03/2014 16:11:23;0008;PBS_Server;Job;43359.tyrone-cluster;Job Modified at request of Scheduler@tyrone-cluster
10/03/2014 16:11:23;0008;PBS_Server;Job;43359.tyrone-cluster;Job Run at request of Scheduler@tyrone-cluster
10/03/2014 16:11:23;0040;PBS_Server;Svr;tyrone-cluster;Scheduler was sent the command recyc
10/03/2014 16:11:50;0040;PBS_Server;Svr;tyrone-cluster;Scheduler was sent the command new
10/03/2014 16:11:54;000d;PBS_Server;Job;43359.tyrone-cluster;Not sending email: User does not want mail of this type.
10/03/2014 16:12:25;0040;PBS_Server;Svr;tyrone-cluster;Scheduler was sent the command new
10/03/2014 16:12:50;0002;PBS_Server;Svr;PBS_Server;Torque Server Version = 3.0.5, loglevel = 0
10/03/2014 16:12:51;0040;PBS_Server;Svr;tyrone-cluster;Scheduler was sent the command new
10/03/2014 16:13:20;0040;PBS_Server;Svr;tyrone-cluster;Scheduler was sent the command new
10/03/2014 16:13:55;0040;PBS_Server;Svr;tyrone-cluster;Scheduler was sent the command new
10/03/2014 16:14:31;0040;PBS_Server;Svr;tyrone-cluster;Scheduler was sent the command new
10/03/2014 16:15:06;0040;PBS_Server;Svr;tyrone-cluster;Scheduler was sent the command new
10/03/2014 16:15:08;0008;PBS_Server;Job;43359.tyrone-cluster;Job deleted at request of asejobin@tyrone-cluster
10/03/2014 16:15:08;0008;PBS_Server;Job;43359.tyrone-cluster;Job sent signal SIGTERM on delete
10/03/2014 16:15:08;000d;PBS_Server;Job;43359.tyrone-cluster;Not sending email: User does not want mail of this type.
10/03/2014 16:15:08;0010;PBS_Server;Job;43359.tyrone-cluster;Exit_status=143 resources_used.cput=00:20:10 resources_used.mem=4733000kb resources_used.vmem=40380300kb resources_used.walltime=00:03:44
10/03/2014 16:15:08;0008;PBS_Server;Job;NULL;on_job_exit valid pjob: 0x2ce5400 (substate=50)
10/03/2014 16:15:08;0008;PBS_Server;Job;NULL;on_job_exit valid pjob: 0x2ce5400 (substate=51)
10/03/2014 16:15:08;0008;PBS_Server;Job;NULL;on_job_exit valid pjob: 0x2ce5400 (substate=51)
10/03/2014 16:15:08;0008;PBS_Server;Job;NULL;on_job_exit valid pjob: 0x2ce5400 (substate=53)
10/03/2014 16:15:08;0100;PBS_Server;Job;43359.tyrone-cluster;dequeuing from qp256, state COMPLETE
10/03/2014 16:15:08;0040;PBS_Server;Svr;tyrone-cluster;Scheduler was sent the command term
10/03/2014 16:15:35;0040;PBS_Server;Svr;tyrone-cluster;Scheduler was sent the command new
10/03/2014 16:15:54;0100;PBS_Server;Job;43360.tyrone-cluster;enqueuing into batch, state 1 hop 1
10/03/2014 16:15:54;0100;PBS_Server;Job;43360.tyrone-cluster;dequeuing from batch, state QUEUED
10/03/2014 16:15:54;0100;PBS_Server;Job;43360.tyrone-cluster;enqueuing into qp256, state 1 hop 1
10/03/2014 16:15:54;0008;PBS_Server;Job;43360.tyrone-cluster;Job Queued at request of asejobin@tyrone-cluster, owner = asejobin@tyrone-cluster, job name = JOBNAME, queue = qp256
10/03/2014 16:15:54;0040;PBS_Server;Svr;tyrone-cluster;Scheduler was sent the command new
10/03/2014 16:15:54;0008;PBS_Server;Job;43360.tyrone-cluster;Job Modified at request of Scheduler@tyrone-cluster
10/03/2014 16:15:54;0008;PBS_Server;Job;43360.tyrone-cluster;Job Run at request of Scheduler@tyrone-cluster
10/03/2014 16:15:54;0040;PBS_Server;Svr;tyrone-cluster;Scheduler was sent the command recyc
10/03/2014 16:16:06;0040;PBS_Server;Svr;tyrone-cluster;Scheduler was sent the command new
10/03/2014 16:16:26;000d;PBS_Server;Job;43360.tyrone-cluster;Not sending email: User does not want mail of this type.
10/03/2014 16:16:35;0040;PBS_Server;Svr;tyrone-cluster;Scheduler was sent the command new
10/03/2014 16:17:05;0040;PBS_Server;Svr;tyrone-cluster;Scheduler was sent the command new
10/03/2014 16:17:41;0040;PBS_Server;Svr;tyrone-cluster;Scheduler was sent the command new
10/03/2014 16:17:50;0002;PBS_Server;Svr;PBS_Server;Torque Server Version = 3.0.5, loglevel = 0
10/03/2014 16:18:07;0040;PBS_Server;Svr;tyrone-cluster;Scheduler was sent the command new
10/03/2014 16:18:38;0040;PBS_Server;Svr;tyrone-cluster;Scheduler was sent the command new
10/03/2014 16:19:11;0040;PBS_Server;Svr;tyrone-cluster;Scheduler was sent the command new
10/03/2014 16:19:46;0040;PBS_Server;Svr;tyrone-cluster;Scheduler was sent the command new
10/03/2014 16:20:11;0040;PBS_Server;Svr;tyrone-cluster;Scheduler was sent the command new
10/03/2014 16:20:47;0040;PBS_Server;Svr;tyrone-cluster;Scheduler was sent the command new
10/03/2014 16:21:16;0040;PBS_Server;Svr;tyrone-cluster;Scheduler was sent the command new
10/03/2014 16:21:41;0040;PBS_Server;Svr;tyrone-cluster;Scheduler was sent the command new
10/03/2014 16:22:19;0040;PBS_Server;Svr;tyrone-cluster;Scheduler was sent the command new
10/03/2014 16:22:48;0040;PBS_Server;Svr;tyrone-cluster;Scheduler was sent the command new
10/03/2014 16:22:50;0002;PBS_Server;Svr;PBS_Server;Torque Server Version = 3.0.5, loglevel = 0
10/03/2014 16:23:20;0040;PBS_Server;Svr;tyrone-cluster;Scheduler was sent the command new
10/03/2014 16:23:50;0040;PBS_Server;Svr;tyrone-cluster;Scheduler was sent the command new
10/03/2014 16:24:26;0040;PBS_Server;Svr;tyrone-cluster;Scheduler was sent the command new
10/03/2014 16:24:52;0040;PBS_Server;Svr;tyrone-cluster;Scheduler was sent the command new
10/03/2014 16:25:22;0040;PBS_Server;Svr;tyrone-cluster;Scheduler was sent the command new
10/03/2014 16:25:55;0040;PBS_Server;Svr;tyrone-cluster;Scheduler was sent the command new
10/03/2014 16:26:31;0040;PBS_Server;Svr;tyrone-cluster;Scheduler was sent the command new
10/03/2014 16:26:56;0040;PBS_Server;Svr;tyrone-cluster;Scheduler was sent the command new
10/03/2014 16:27:34;0040;PBS_Server;Svr;tyrone-cluster;Scheduler was sent the command new
10/03/2014 16:27:50;0002;PBS_Server;Svr;PBS_Server;Torque Server Version = 3.0.5, loglevel = 0
10/03/2014 16:28:03;0040;PBS_Server;Svr;tyrone-cluster;Scheduler was sent the command new
10/03/2014 16:28:35;0040;PBS_Server;Svr;tyrone-cluster;Scheduler was sent the command new
10/03/2014 16:29:04;0040;PBS_Server;Svr;tyrone-cluster;Scheduler was sent the command new
10/03/2014 16:29:33;0040;PBS_Server;Svr;tyrone-cluster;Scheduler was sent the command new
10/03/2014 16:30:06;0040;PBS_Server;Svr;tyrone-cluster;Scheduler was sent the command new
10/03/2014 16:30:35;0040;PBS_Server;Svr;tyrone-cluster;Scheduler was sent the command new
10/03/2014 16:31:10;0040;PBS_Server;Svr;tyrone-cluster;Scheduler was sent the command new
10/03/2014 16:31:36;0040;PBS_Server;Svr;tyrone-cluster;Scheduler was sent the command new
10/03/2014 16:32:09;0040;PBS_Server;Svr;tyrone-cluster;Scheduler was sent the command new
10/03/2014 16:32:40;0040;PBS_Server;Svr;tyrone-cluster;Scheduler was sent the command new
10/03/2014 16:32:50;0002;PBS_Server;Svr;PBS_Server;Torque Server Version = 3.0.5, loglevel = 0
10/03/2014 16:33:16;0040;PBS_Server;Svr;tyrone-cluster;Scheduler was sent the command new
10/03/2014 16:33:41;0040;PBS_Server;Svr;tyrone-cluster;Scheduler was sent the command new
10/03/2014 16:34:19;0040;PBS_Server;Svr;tyrone-cluster;Scheduler was sent the command new
10/03/2014 16:34:48;0040;PBS_Server;Svr;tyrone-cluster;Scheduler was sent the command new
10/03/2014 16:35:21;0040;PBS_Server;Svr;tyrone-cluster;Scheduler was sent the command new
10/03/2014 16:35:49;0040;PBS_Server;Svr;tyrone-cluster;Scheduler was sent the command new
10/03/2014 16:36:18;0040;PBS_Server;Svr;tyrone-cluster;Scheduler was sent the command new
10/03/2014 16:36:51;0040;PBS_Server;Svr;tyrone-cluster;Scheduler was sent the command new
10/03/2014 16:37:20;0040;PBS_Server;Svr;tyrone-cluster;Scheduler was sent the command new
10/03/2014 16:37:50;0002;PBS_Server;Svr;PBS_Server;Torque Server Version = 3.0.5, loglevel = 0
10/03/2014 16:37:50;0040;PBS_Server;Svr;tyrone-cluster;Scheduler was sent the command new
10/03/2014 16:38:21;0040;PBS_Server;Svr;tyrone-cluster;Scheduler was sent the command new
10/03/2014 16:38:54;0040;PBS_Server;Svr;tyrone-cluster;Scheduler was sent the command new
10/03/2014 16:39:25;0040;PBS_Server;Svr;tyrone-cluster;Scheduler was sent the command new
10/03/2014 16:40:01;0040;PBS_Server;Svr;tyrone-cluster;Scheduler was sent the command new
10/03/2014 16:40:26;0040;PBS_Server;Svr;tyrone-cluster;Scheduler was sent the command new
10/03/2014 16:41:04;0040;PBS_Server;Svr;tyrone-cluster;Scheduler was sent the command new
10/03/2014 16:41:32;0040;PBS_Server;Svr;tyrone-cluster;Scheduler was sent the command new
10/03/2014 16:42:05;0040;PBS_Server;Svr;tyrone-cluster;Scheduler was sent the command new
10/03/2014 16:42:36;0040;PBS_Server;Svr;tyrone-cluster;Scheduler was sent the command new
10/03/2014 16:42:50;0002;PBS_Server;Svr;PBS_Server;Torque Server Version = 3.0.5, loglevel = 0
10/03/2014 16:43:07;0040;PBS_Server;Svr;tyrone-cluster;Scheduler was sent the command new
10/03/2014 16:43:37;0040;PBS_Server;Svr;tyrone-cluster;Scheduler was sent the command new
10/03/2014 16:44:07;0040;PBS_Server;Svr;tyrone-cluster;Scheduler was sent the command new
10/03/2014 16:44:41;0040;PBS_Server;Svr;tyrone-cluster;Scheduler was sent the command new
10/03/2014 16:45:16;0040;PBS_Server;Svr;tyrone-cluster;Scheduler was sent the command new
10/03/2014 16:45:41;0040;PBS_Server;Svr;tyrone-cluster;Scheduler was sent the command new
10/03/2014 16:46:19;0040;PBS_Server;Svr;tyrone-cluster;Scheduler was sent the command new
10/03/2014 16:46:48;0040;PBS_Server;Svr;tyrone-cluster;Scheduler was sent the command new
10/03/2014 16:47:20;0040;PBS_Server;Svr;tyrone-cluster;Scheduler was sent the command new
10/03/2014 16:47:50;0002;PBS_Server;Svr;PBS_Server;Torque Server Version = 3.0.5, loglevel = 0
10/03/2014 16:47:50;0040;PBS_Server;Svr;tyrone-cluster;Scheduler was sent the command new
10/03/2014 16:48:25;0040;PBS_Server;Svr;tyrone-cluster;Scheduler was sent the command new
10/03/2014 16:48:51;0040;PBS_Server;Svr;tyrone-cluster;Scheduler was sent the command new
10/03/2014 16:49:20;0040;PBS_Server;Svr;tyrone-cluster;Scheduler was sent the command new
10/03/2014 16:49:55;0040;PBS_Server;Svr;tyrone-cluster;Scheduler was sent the command new
10/03/2014 16:50:31;0040;PBS_Server;Svr;tyrone-cluster;Scheduler was sent the command new
10/03/2014 16:50:57;0040;PBS_Server;Svr;tyrone-cluster;Scheduler was sent the command new
10/03/2014 16:51:34;0040;PBS_Server;Svr;tyrone-cluster;Scheduler was sent the command new
10/03/2014 16:52:03;0040;PBS_Server;Svr;tyrone-cluster;Scheduler was sent the command new
10/03/2014 16:52:36;0040;PBS_Server;Svr;tyrone-cluster;Scheduler was sent the command new
10/03/2014 16:52:50;0002;PBS_Server;Svr;PBS_Server;Torque Server Version = 3.0.5, loglevel = 0
10/03/2014 16:53:05;0040;PBS_Server;Svr;tyrone-cluster;Scheduler was sent the command new
10/03/2014 16:53:40;0040;PBS_Server;Svr;tyrone-cluster;Scheduler was sent the command new
10/03/2014 16:54:06;0040;PBS_Server;Svr;tyrone-cluster;Scheduler was sent the command new
10/03/2014 16:54:35;0040;PBS_Server;Svr;tyrone-cluster;Scheduler was sent the command new
10/03/2014 16:55:10;0040;PBS_Server;Svr;tyrone-cluster;Scheduler was sent the command new
10/03/2014 16:55:46;0040;PBS_Server;Svr;tyrone-cluster;Scheduler was sent the command new
10/03/2014 16:56:11;0040;PBS_Server;Svr;tyrone-cluster;Scheduler was sent the command new
10/03/2014 16:56:49;0040;PBS_Server;Svr;tyrone-cluster;Scheduler was sent the command new
10/03/2014 16:57:18;0040;PBS_Server;Svr;tyrone-cluster;Scheduler was sent the command new
10/03/2014 16:57:50;0002;PBS_Server;Svr;PBS_Server;Torque Server Version = 3.0.5, loglevel = 0
10/03/2014 16:57:50;0040;PBS_Server;Svr;tyrone-cluster;Scheduler was sent the command new
10/03/2014 16:58:20;0040;PBS_Server;Svr;tyrone-cluster;Scheduler was sent the command new
10/03/2014 16:58:55;0040;PBS_Server;Svr;tyrone-cluster;Scheduler was sent the command new
10/03/2014 16:59:09;000d;PBS_Server;Job;43360.tyrone-cluster;Not sending email: User does not want mail of this type.
10/03/2014 16:59:09;0010;PBS_Server;Job;43360.tyrone-cluster;Exit_status=0 resources_used.cput=12:17:50 resources_used.mem=18512876kb resources_used.vmem=51538184kb resources_used.walltime=00:43:15
10/03/2014 16:59:09;0008;PBS_Server;Job;NULL;on_job_exit valid pjob: 0x2ce5400 (substate=50)
10/03/2014 16:59:09;0008;PBS_Server;Job;NULL;on_job_exit valid pjob: 0x2ce5400 (substate=51)
10/03/2014 16:59:10;0008;PBS_Server;Job;NULL;on_job_exit valid pjob: 0x2ce5400 (substate=51)
10/03/2014 16:59:10;0008;PBS_Server;Job;NULL;on_job_exit valid pjob: 0x2ce5400 (substate=53)
10/03/2014 16:59:10;0100;PBS_Server;Job;43360.tyrone-cluster;dequeuing from qp256, state COMPLETE
10/03/2014 16:59:10;0040;PBS_Server;Svr;tyrone-cluster;Scheduler was sent the command term
10/03/2014 16:59:21;0040;PBS_Server;Svr;tyrone-cluster;Scheduler was sent the command new
10/03/2014 16:59:50;0040;PBS_Server;Svr;tyrone-cluster;Scheduler was sent the command new
10/03/2014 17:00:25;0040;PBS_Server;Svr;tyrone-cluster;Scheduler was sent the command new
10/03/2014 17:01:01;0040;PBS_Server;Svr;tyrone-cluster;Scheduler was sent the command new
10/03/2014 17:01:35;0040;PBS_Server;Svr;tyrone-cluster;Scheduler was sent the command new
10/03/2014 17:02:04;0040;PBS_Server;Svr;tyrone-cluster;Scheduler was sent the command new
10/03/2014 17:02:33;0040;PBS_Server;Svr;tyrone-cluster;Scheduler was sent the command new
10/03/2014 17:02:50;0002;PBS_Server;Svr;PBS_Server;Torque Server Version = 3.0.5, loglevel = 0
10/03/2014 17:03:05;0040;PBS_Server;Svr;tyrone-cluster;Scheduler was sent the command new
10/03/2014 17:03:34;0040;PBS_Server;Svr;tyrone-cluster;Scheduler was sent the command new
10/03/2014 17:04:02;0040;PBS_Server;Svr;tyrone-cluster;Scheduler was sent the command new
10/03/2014 17:04:35;0040;PBS_Server;Svr;tyrone-cluster;Scheduler was sent the command new
10/03/2014 17:05:05;0040;PBS_Server;Svr;tyrone-cluster;Scheduler was sent the command new
10/03/2014 17:05:37;0040;PBS_Server;Svr;tyrone-cluster;Scheduler was sent the command new
10/03/2014 17:05:44;0100;PBS_Server;Job;43361.tyrone-cluster;enqueuing into batch, state 1 hop 1
10/03/2014 17:05:44;0100;PBS_Server;Job;43361.tyrone-cluster;dequeuing from batch, state QUEUED
10/03/2014 17:05:44;0100;PBS_Server;Job;43361.tyrone-cluster;enqueuing into qp256, state 1 hop 1
10/03/2014 17:05:44;0008;PBS_Server;Job;43361.tyrone-cluster;Job Queued at request of asejobin@tyrone-cluster, owner = asejobin@tyrone-cluster, job name = JOBNAME, queue = qp256
10/03/2014 17:05:44;0040;PBS_Server;Svr;tyrone-cluster;Scheduler was sent the command new
10/03/2014 17:05:44;0008;PBS_Server;Job;43361.tyrone-cluster;Job Modified at request of Scheduler@tyrone-cluster
10/03/2014 17:05:44;0008;PBS_Server;Job;43361.tyrone-cluster;Job Run at request of Scheduler@tyrone-cluster
10/03/2014 17:05:44;0040;PBS_Server;Svr;tyrone-cluster;Scheduler was sent the command recyc
10/03/2014 17:05:58;000d;PBS_Server;Job;43361.tyrone-cluster;Not sending email: User does not want mail of this type.
10/03/2014 17:06:06;0040;PBS_Server;Svr;tyrone-cluster;Scheduler was sent the command new
10/03/2014 17:06:35;0040;PBS_Server;Svr;tyrone-cluster;Scheduler was sent the command new
10/03/2014 17:07:11;0040;PBS_Server;Svr;tyrone-cluster;Scheduler was sent the command new
10/03/2014 17:07:46;0040;PBS_Server;Svr;tyrone-cluster;Scheduler was sent the command new
10/03/2014 17:07:50;0002;PBS_Server;Svr;PBS_Server;Torque Server Version = 3.0.5, loglevel = 0
10/03/2014 17:08:13;0040;PBS_Server;Svr;tyrone-cluster;Scheduler was sent the command new
10/03/2014 17:08:49;0040;PBS_Server;Svr;tyrone-cluster;Scheduler was sent the command new
10/03/2014 17:09:18;0040;PBS_Server;Svr;tyrone-cluster;Scheduler was sent the command new
10/03/2014 17:09:51;0040;PBS_Server;Svr;tyrone-cluster;Scheduler was sent the command new
10/03/2014 17:10:20;0040;PBS_Server;Svr;tyrone-cluster;Scheduler was sent the command new
10/03/2014 17:10:55;0040;PBS_Server;Svr;tyrone-cluster;Scheduler was sent the command new
10/03/2014 17:11:31;0040;PBS_Server;Svr;tyrone-cluster;Scheduler was sent the command new
10/03/2014 17:11:58;0040;PBS_Server;Svr;tyrone-cluster;Scheduler was sent the command new
10/03/2014 17:12:34;0040;PBS_Server;Svr;tyrone-cluster;Scheduler was sent the command new
10/03/2014 17:12:50;0002;PBS_Server;Svr;PBS_Server;Torque Server Version = 3.0.5, loglevel = 0
10/03/2014 17:13:02;0040;PBS_Server;Svr;tyrone-cluster;Scheduler was sent the command new
10/03/2014 17:13:35;0040;PBS_Server;Svr;tyrone-cluster;Scheduler was sent the command new
10/03/2014 17:14:05;0040;PBS_Server;Svr;tyrone-cluster;Scheduler was sent the command new
10/03/2014 17:14:40;0040;PBS_Server;Svr;tyrone-cluster;Scheduler was sent the command new
10/03/2014 17:15:06;0040;PBS_Server;Svr;tyrone-cluster;Scheduler was sent the command new
10/03/2014 17:15:35;0040;PBS_Server;Svr;tyrone-cluster;Scheduler was sent the command new
10/03/2014 17:16:10;0040;PBS_Server;Svr;tyrone-cluster;Scheduler was sent the command new
10/03/2014 17:16:46;0040;PBS_Server;Svr;tyrone-cluster;Scheduler was sent the command new
10/03/2014 17:17:13;0040;PBS_Server;Svr;tyrone-cluster;Scheduler was sent the command new
10/03/2014 17:17:49;0040;PBS_Server;Svr;tyrone-cluster;Scheduler was sent the command new
10/03/2014 17:17:50;0002;PBS_Server;Svr;PBS_Server;Torque Server Version = 3.0.5, loglevel = 0
10/03/2014 17:18:18;0040;PBS_Server;Svr;tyrone-cluster;Scheduler was sent the command new
10/03/2014 17:18:50;0040;PBS_Server;Svr;tyrone-cluster;Scheduler was sent the command new
10/03/2014 17:19:20;0040;PBS_Server;Svr;tyrone-cluster;Scheduler was sent the command new
10/03/2014 17:19:55;0040;PBS_Server;Svr;tyrone-cluster;Scheduler was sent the command new
10/03/2014 17:20:21;0040;PBS_Server;Svr;tyrone-cluster;Scheduler was sent the command new
10/03/2014 17:20:50;0040;PBS_Server;Svr;tyrone-cluster;Scheduler was sent the command new
10/03/2014 17:21:24;0040;PBS_Server;Svr;tyrone-cluster;Scheduler was sent the command new
10/03/2014 17:21:55;0040;PBS_Server;Svr;tyrone-cluster;Scheduler was sent the command new
10/03/2014 17:22:28;0040;PBS_Server;Svr;tyrone-cluster;Scheduler was sent the command new
10/03/2014 17:22:50;0002;PBS_Server;Svr;PBS_Server;Torque Server Version = 3.0.5, loglevel = 0
10/03/2014 17:22:55;0040;PBS_Server;Svr;tyrone-cluster;Scheduler was sent the command new
10/03/2014 17:23:26;0040;PBS_Server;Svr;tyrone-cluster;Scheduler was sent the command new
10/03/2014 17:23:58;0040;PBS_Server;Svr;tyrone-cluster;Scheduler was sent the command new
10/03/2014 17:24:26;0040;PBS_Server;Svr;tyrone-cluster;Scheduler was sent the command new
10/03/2014 17:25:01;0040;PBS_Server;Svr;tyrone-cluster;Scheduler was sent the command new
10/03/2014 17:25:28;0040;PBS_Server;Svr;tyrone-cluster;Scheduler was sent the command new
10/03/2014 17:26:04;0040;PBS_Server;Svr;tyrone-cluster;Scheduler was sent the command new
10/03/2014 17:26:33;0040;PBS_Server;Svr;tyrone-cluster;Scheduler was sent the command new
10/03/2014 17:27:05;0040;PBS_Server;Svr;tyrone-cluster;Scheduler was sent the command new
10/03/2014 17:27:34;0040;PBS_Server;Svr;tyrone-cluster;Scheduler was sent the command new
10/03/2014 17:27:50;0002;PBS_Server;Svr;PBS_Server;Torque Server Version = 3.0.5, loglevel = 0
10/03/2014 17:28:03;0040;PBS_Server;Svr;tyrone-cluster;Scheduler was sent the command new
10/03/2014 17:28:35;0040;PBS_Server;Svr;tyrone-cluster;Scheduler was sent the command new
10/03/2014 17:29:04;0040;PBS_Server;Svr;tyrone-cluster;Scheduler was sent the command new
10/03/2014 17:29:32;0040;PBS_Server;Svr;tyrone-cluster;Scheduler was sent the command new
10/03/2014 17:30:04;0040;PBS_Server;Svr;tyrone-cluster;Scheduler was sent the command new
10/03/2014 17:30:34;0040;PBS_Server;Svr;tyrone-cluster;Scheduler was sent the command new
10/03/2014 17:31:10;0040;PBS_Server;Svr;tyrone-cluster;Scheduler was sent the command new
10/03/2014 17:31:36;0040;PBS_Server;Svr;tyrone-cluster;Scheduler was sent the command new
10/03/2014 17:32:05;0040;PBS_Server;Svr;tyrone-cluster;Scheduler was sent the command new
10/03/2014 17:32:40;0040;PBS_Server;Svr;tyrone-cluster;Scheduler was sent the command new
10/03/2014 17:32:50;0002;PBS_Server;Svr;PBS_Server;Torque Server Version = 3.0.5, loglevel = 0
10/03/2014 17:33:16;0040;PBS_Server;Svr;tyrone-cluster;Scheduler was sent the command new
10/03/2014 17:33:43;0040;PBS_Server;Svr;tyrone-cluster;Scheduler was sent the command new
10/03/2014 17:34:19;0040;PBS_Server;Svr;tyrone-cluster;Scheduler was sent the command new
10/03/2014 17:34:48;0040;PBS_Server;Svr;tyrone-cluster;Scheduler was sent the command new
10/03/2014 17:35:19;0040;PBS_Server;Svr;tyrone-cluster;Scheduler was sent the command new
10/03/2014 17:35:49;0040;PBS_Server;Svr;tyrone-cluster;Scheduler was sent the command new
10/03/2014 17:36:17;0040;PBS_Server;Svr;tyrone-cluster;Scheduler was sent the command new
10/03/2014 17:36:49;0040;PBS_Server;Svr;tyrone-cluster;Scheduler was sent the command new
10/03/2014 17:37:19;0040;PBS_Server;Svr;tyrone-cluster;Scheduler was sent the command new
10/03/2014 17:37:47;0040;PBS_Server;Svr;tyrone-cluster;Scheduler was sent the command new
10/03/2014 17:37:50;0002;PBS_Server;Svr;PBS_Server;Torque Server Version = 3.0.5, loglevel = 0
10/03/2014 17:38:20;0040;PBS_Server;Svr;tyrone-cluster;Scheduler was sent the command new
10/03/2014 17:38:49;0040;PBS_Server;Svr;tyrone-cluster;Scheduler was sent the command new
10/03/2014 17:39:18;0040;PBS_Server;Svr;tyrone-cluster;Scheduler was sent the command new
10/03/2014 17:39:51;0040;PBS_Server;Svr;tyrone-cluster;Scheduler was sent the command new
10/03/2014 17:40:20;0040;PBS_Server;Svr;tyrone-cluster;Scheduler was sent the command new
10/03/2014 17:40:55;0040;PBS_Server;Svr;tyrone-cluster;Scheduler was sent the command new
10/03/2014 17:41:31;0040;PBS_Server;Svr;tyrone-cluster;Scheduler was sent the command new
10/03/2014 17:41:58;0040;PBS_Server;Svr;tyrone-cluster;Scheduler was sent the command new
10/03/2014 17:42:34;0040;PBS_Server;Svr;tyrone-cluster;Scheduler was sent the command new
10/03/2014 17:42:50;0002;PBS_Server;Svr;PBS_Server;Torque Server Version = 3.0.5, loglevel = 0
10/03/2014 17:43:03;0040;PBS_Server;Svr;tyrone-cluster;Scheduler was sent the command new
10/03/2014 17:43:34;0040;PBS_Server;Svr;tyrone-cluster;Scheduler was sent the command new
10/03/2014 17:44:04;0040;PBS_Server;Svr;tyrone-cluster;Scheduler was sent the command new
10/03/2014 17:44:32;0040;PBS_Server;Svr;tyrone-cluster;Scheduler was sent the command new
10/03/2014 17:45:04;0040;PBS_Server;Svr;tyrone-cluster;Scheduler was sent the command new
10/03/2014 17:45:34;0040;PBS_Server;Svr;tyrone-cluster;Scheduler was sent the command new
10/03/2014 17:46:02;0040;PBS_Server;Svr;tyrone-cluster;Scheduler was sent the command new
10/03/2014 17:46:34;0040;PBS_Server;Svr;tyrone-cluster;Scheduler was sent the command new
10/03/2014 17:47:04;0040;PBS_Server;Svr;tyrone-cluster;Scheduler was sent the command new
10/03/2014 17:47:33;0040;PBS_Server;Svr;tyrone-cluster;Scheduler was sent the command new
10/03/2014 17:47:50;0002;PBS_Server;Svr;PBS_Server;Torque Server Version = 3.0.5, loglevel = 0
10/03/2014 17:48:05;0040;PBS_Server;Svr;tyrone-cluster;Scheduler was sent the command new
10/03/2014 17:48:34;0040;PBS_Server;Svr;tyrone-cluster;Scheduler was sent the command new
10/03/2014 17:49:03;0040;PBS_Server;Svr;tyrone-cluster;Scheduler was sent the command new
10/03/2014 17:49:34;0040;PBS_Server;Svr;tyrone-cluster;Scheduler was sent the command new
10/03/2014 17:50:04;0040;PBS_Server;Svr;tyrone-cluster;Scheduler was sent the command new
10/03/2014 17:50:33;0040;PBS_Server;Svr;tyrone-cluster;Scheduler was sent the command new
10/03/2014 17:51:04;0040;PBS_Server;Svr;tyrone-cluster;Scheduler was sent the command new
10/03/2014 17:51:34;0040;PBS_Server;Svr;tyrone-cluster;Scheduler was sent the command new
10/03/2014 17:52:02;0040;PBS_Server;Svr;tyrone-cluster;Scheduler was sent the command new
10/03/2014 17:52:35;0040;PBS_Server;Svr;tyrone-cluster;Scheduler was sent the command new
10/03/2014 17:52:50;0002;PBS_Server;Svr;PBS_Server;Torque Server Version = 3.0.5, loglevel = 0
10/03/2014 17:53:05;0040;PBS_Server;Svr;tyrone-cluster;Scheduler was sent the command new
10/03/2014 17:53:40;0040;PBS_Server;Svr;tyrone-cluster;Scheduler was sent the command new
10/03/2014 17:54:16;0040;PBS_Server;Svr;tyrone-cluster;Scheduler was sent the command new
10/03/2014 17:54:43;0040;PBS_Server;Svr;tyrone-cluster;Scheduler was sent the command new
10/03/2014 17:55:19;0040;PBS_Server;Svr;tyrone-cluster;Scheduler was sent the command new
10/03/2014 17:55:48;0040;PBS_Server;Svr;tyrone-cluster;Scheduler was sent the command new
10/03/2014 17:56:19;0040;PBS_Server;Svr;tyrone-cluster;Scheduler was sent the command new
10/03/2014 17:56:49;0040;PBS_Server;Svr;tyrone-cluster;Scheduler was sent the command new
10/03/2014 17:57:18;0040;PBS_Server;Svr;tyrone-cluster;Scheduler was sent the command new
10/03/2014 17:57:50;0002;PBS_Server;Svr;PBS_Server;Torque Server Version = 3.0.5, loglevel = 0
10/03/2014 17:57:50;0040;PBS_Server;Svr;tyrone-cluster;Scheduler was sent the command new
10/03/2014 17:58:20;0040;PBS_Server;Svr;tyrone-cluster;Scheduler was sent the command new
10/03/2014 17:58:55;0040;PBS_Server;Svr;tyrone-cluster;Scheduler was sent the command new
10/03/2014 17:59:31;0040;PBS_Server;Svr;tyrone-cluster;Scheduler was sent the command new
10/03/2014 17:59:58;0040;PBS_Server;Svr;tyrone-cluster;Scheduler was sent the command new
10/03/2014 18:00:25;0040;PBS_Server;Svr;tyrone-cluster;Scheduler was sent the command new
10/03/2014 18:01:01;0040;PBS_Server;Svr;tyrone-cluster;Scheduler was sent the command new
10/03/2014 18:01:28;0040;PBS_Server;Svr;tyrone-cluster;Scheduler was sent the command new
10/03/2014 18:01:55;0040;PBS_Server;Svr;tyrone-cluster;Scheduler was sent the command new
10/03/2014 18:02:31;0040;PBS_Server;Svr;tyrone-cluster;Scheduler was sent the command new
10/03/2014 18:02:50;0002;PBS_Server;Svr;PBS_Server;Torque Server Version = 3.0.5, loglevel = 0
10/03/2014 18:02:58;0040;PBS_Server;Svr;tyrone-cluster;Scheduler was sent the command new
10/03/2014 18:03:34;0040;PBS_Server;Svr;tyrone-cluster;Scheduler was sent the command new
10/03/2014 18:04:03;0040;PBS_Server;Svr;tyrone-cluster;Scheduler was sent the command new
10/03/2014 18:04:34;0040;PBS_Server;Svr;tyrone-cluster;Scheduler was sent the command new
10/03/2014 18:05:04;0040;PBS_Server;Svr;tyrone-cluster;Scheduler was sent the command new
10/03/2014 18:05:33;0040;PBS_Server;Svr;tyrone-cluster;Scheduler was sent the command new
10/03/2014 18:06:05;0040;PBS_Server;Svr;tyrone-cluster;Scheduler was sent the command new
10/03/2014 18:06:34;0040;PBS_Server;Svr;tyrone-cluster;Scheduler was sent the command new
10/03/2014 18:07:10;0040;PBS_Server;Svr;tyrone-cluster;Scheduler was sent the command new
10/03/2014 18:07:46;0040;PBS_Server;Svr;tyrone-cluster;Scheduler was sent the command new
10/03/2014 18:07:50;0002;PBS_Server;Svr;PBS_Server;Torque Server Version = 3.0.5, loglevel = 0
10/03/2014 18:08:13;0040;PBS_Server;Svr;tyrone-cluster;Scheduler was sent the command new
10/03/2014 18:08:47;0040;PBS_Server;Svr;tyrone-cluster;Scheduler was sent the command new
10/03/2014 18:09:16;0040;PBS_Server;Svr;tyrone-cluster;Scheduler was sent the command new
10/03/2014 18:09:49;0040;PBS_Server;Svr;tyrone-cluster;Scheduler was sent the command new
10/03/2014 18:10:19;0040;PBS_Server;Svr;tyrone-cluster;Scheduler was sent the command new
10/03/2014 18:10:48;0040;PBS_Server;Svr;tyrone-cluster;Scheduler was sent the command new
10/03/2014 18:11:20;0040;PBS_Server;Svr;tyrone-cluster;Scheduler was sent the command new
10/03/2014 18:11:49;0040;PBS_Server;Svr;tyrone-cluster;Scheduler was sent the command new
10/03/2014 18:12:25;0040;PBS_Server;Svr;tyrone-cluster;Scheduler was sent the command new
10/03/2014 18:12:50;0002;PBS_Server;Svr;PBS_Server;Torque Server Version = 3.0.5, loglevel = 0
10/03/2014 18:13:01;0040;PBS_Server;Svr;tyrone-cluster;Scheduler was sent the command new
10/03/2014 18:13:28;0040;PBS_Server;Svr;tyrone-cluster;Scheduler was sent the command new
10/03/2014 18:13:55;0040;PBS_Server;Svr;tyrone-cluster;Scheduler was sent the command new
10/03/2014 18:14:31;0040;PBS_Server;Svr;tyrone-cluster;Scheduler was sent the command new
10/03/2014 18:14:58;0040;PBS_Server;Svr;tyrone-cluster;Scheduler was sent the command new
10/03/2014 18:15:31;0040;PBS_Server;Svr;tyrone-cluster;Scheduler was sent the command new
10/03/2014 18:16:01;0040;PBS_Server;Svr;tyrone-cluster;Scheduler was sent the command new
10/03/2014 18:16:28;0040;PBS_Server;Svr;tyrone-cluster;Scheduler was sent the command new
10/03/2014 18:17:04;0040;PBS_Server;Svr;tyrone-cluster;Scheduler was sent the command new
10/03/2014 18:17:33;0040;PBS_Server;Svr;tyrone-cluster;Scheduler was sent the command new
10/03/2014 18:17:50;0002;PBS_Server;Svr;PBS_Server;Torque Server Version = 3.0.5, loglevel = 0
10/03/2014 18:18:05;0040;PBS_Server;Svr;tyrone-cluster;Scheduler was sent the command new
10/03/2014 18:18:34;0040;PBS_Server;Svr;tyrone-cluster;Scheduler was sent the command new
10/03/2014 18:19:10;0040;PBS_Server;Svr;tyrone-cluster;Scheduler was sent the command new
10/03/2014 18:19:39;0040;PBS_Server;Svr;tyrone-cluster;Scheduler was sent the command new
10/03/2014 18:20:13;0040;PBS_Server;Svr;tyrone-cluster;Scheduler was sent the command new
10/03/2014 18:20:40;0040;PBS_Server;Svr;tyrone-cluster;Scheduler was sent the command new
10/03/2014 18:21:16;0040;PBS_Server;Svr;tyrone-cluster;Scheduler was sent the command new
10/03/2014 18:21:43;0040;PBS_Server;Svr;tyrone-cluster;Scheduler was sent the command new
10/03/2014 18:22:19;0040;PBS_Server;Svr;tyrone-cluster;Scheduler was sent the command new
10/03/2014 18:22:48;0040;PBS_Server;Svr;tyrone-cluster;Scheduler was sent the command new
10/03/2014 18:22:50;0002;PBS_Server;Svr;PBS_Server;Torque Server Version = 3.0.5, loglevel = 0
10/03/2014 18:23:20;0040;PBS_Server;Svr;tyrone-cluster;Scheduler was sent the command new
10/03/2014 18:23:50;0040;PBS_Server;Svr;tyrone-cluster;Scheduler was sent the command new
10/03/2014 18:24:25;0040;PBS_Server;Svr;tyrone-cluster;Scheduler was sent the command new
10/03/2014 18:25:01;0040;PBS_Server;Svr;tyrone-cluster;Scheduler was sent the command new
10/03/2014 18:25:28;0040;PBS_Server;Svr;tyrone-cluster;Scheduler was sent the command new
10/03/2014 18:25:55;0040;PBS_Server;Svr;tyrone-cluster;Scheduler was sent the command new
10/03/2014 18:26:31;0040;PBS_Server;Svr;tyrone-cluster;Scheduler was sent the command new
10/03/2014 18:26:58;0040;PBS_Server;Svr;tyrone-cluster;Scheduler was sent the command new
10/03/2014 18:27:34;0040;PBS_Server;Svr;tyrone-cluster;Scheduler was sent the command new
10/03/2014 18:27:50;0002;PBS_Server;Svr;PBS_Server;Torque Server Version = 3.0.5, loglevel = 0
10/03/2014 18:28:03;0040;PBS_Server;Svr;tyrone-cluster;Scheduler was sent the command new
10/03/2014 18:28:35;0040;PBS_Server;Svr;tyrone-cluster;Scheduler was sent the command new
10/03/2014 18:29:05;0040;PBS_Server;Svr;tyrone-cluster;Scheduler was sent the command new
10/03/2014 18:29:40;0040;PBS_Server;Svr;tyrone-cluster;Scheduler was sent the command new
10/03/2014 18:30:16;0040;PBS_Server;Svr;tyrone-cluster;Scheduler was sent the command new
10/03/2014 18:30:43;0040;PBS_Server;Svr;tyrone-cluster;Scheduler was sent the command new
10/03/2014 18:31:16;0040;PBS_Server;Svr;tyrone-cluster;Scheduler was sent the command new
10/03/2014 18:31:46;0040;PBS_Server;Svr;tyrone-cluster;Scheduler was sent the command new
10/03/2014 18:32:13;0040;PBS_Server;Svr;tyrone-cluster;Scheduler was sent the command new
10/03/2014 18:32:49;0040;PBS_Server;Svr;tyrone-cluster;Scheduler was sent the command new
10/03/2014 18:32:50;0002;PBS_Server;Svr;PBS_Server;Torque Server Version = 3.0.5, loglevel = 0
10/03/2014 18:33:18;0040;PBS_Server;Svr;tyrone-cluster;Scheduler was sent the command new
10/03/2014 18:33:50;0040;PBS_Server;Svr;tyrone-cluster;Scheduler was sent the command new
10/03/2014 18:34:20;0040;PBS_Server;Svr;tyrone-cluster;Scheduler was sent the command new
10/03/2014 18:34:55;0040;PBS_Server;Svr;tyrone-cluster;Scheduler was sent the command new
10/03/2014 18:35:31;0040;PBS_Server;Svr;tyrone-cluster;Scheduler was sent the command new
10/03/2014 18:35:58;0040;PBS_Server;Svr;tyrone-cluster;Scheduler was sent the command new
10/03/2014 18:36:32;0040;PBS_Server;Svr;tyrone-cluster;Scheduler was sent the command new
10/03/2014 18:37:01;0040;PBS_Server;Svr;tyrone-cluster;Scheduler was sent the command new
10/03/2014 18:37:34;0040;PBS_Server;Svr;tyrone-cluster;Scheduler was sent the command new
10/03/2014 18:37:50;0002;PBS_Server;Svr;PBS_Server;Torque Server Version = 3.0.5, loglevel = 0
10/03/2014 18:38:04;0040;PBS_Server;Svr;tyrone-cluster;Scheduler was sent the command new
10/03/2014 18:38:33;0040;PBS_Server;Svr;tyrone-cluster;Scheduler was sent the command new
10/03/2014 18:39:05;0040;PBS_Server;Svr;tyrone-cluster;Scheduler was sent the command new
10/03/2014 18:39:35;0040;PBS_Server;Svr;tyrone-cluster;Scheduler was sent the command new
10/03/2014 18:40:10;0040;PBS_Server;Svr;tyrone-cluster;Scheduler was sent the command new
10/03/2014 18:40:46;0040;PBS_Server;Svr;tyrone-cluster;Scheduler was sent the command new
10/03/2014 18:41:13;0040;PBS_Server;Svr;tyrone-cluster;Scheduler was sent the command new
10/03/2014 18:41:47;0040;PBS_Server;Svr;tyrone-cluster;Scheduler was sent the command new
10/03/2014 18:42:16;0040;PBS_Server;Svr;tyrone-cluster;Scheduler was sent the command new
10/03/2014 18:42:49;0040;PBS_Server;Svr;tyrone-cluster;Scheduler was sent the command new
10/03/2014 18:42:50;0002;PBS_Server;Svr;PBS_Server;Torque Server Version = 3.0.5, loglevel = 0
10/03/2014 18:43:19;0040;PBS_Server;Svr;tyrone-cluster;Scheduler was sent the command new
10/03/2014 18:43:46;0040;PBS_Server;Svr;tyrone-cluster;Scheduler was sent the command new
10/03/2014 18:44:19;0040;PBS_Server;Svr;tyrone-cluster;Scheduler was sent the command new
10/03/2014 18:44:49;0040;PBS_Server;Svr;tyrone-cluster;Scheduler was sent the command new
10/03/2014 18:45:18;0040;PBS_Server;Svr;tyrone-cluster;Scheduler was sent the command new
10/03/2014 18:45:50;0040;PBS_Server;Svr;tyrone-cluster;Scheduler was sent the command new
10/03/2014 18:46:20;0040;PBS_Server;Svr;tyrone-cluster;Scheduler was sent the command new
10/03/2014 18:46:55;0040;PBS_Server;Svr;tyrone-cluster;Scheduler was sent the command new
10/03/2014 18:47:31;0040;PBS_Server;Svr;tyrone-cluster;Scheduler was sent the command new
10/03/2014 18:47:50;0002;PBS_Server;Svr;PBS_Server;Torque Server Version = 3.0.5, loglevel = 0
10/03/2014 18:47:58;0040;PBS_Server;Svr;tyrone-cluster;Scheduler was sent the command new
10/03/2014 18:48:32;0040;PBS_Server;Svr;tyrone-cluster;Scheduler was sent the command new
10/03/2014 18:49:01;0040;PBS_Server;Svr;tyrone-cluster;Scheduler was sent the command new
10/03/2014 18:49:34;0040;PBS_Server;Svr;tyrone-cluster;Scheduler was sent the command new
10/03/2014 18:50:04;0040;PBS_Server;Svr;tyrone-cluster;Scheduler was sent the command new
10/03/2014 18:50:31;0040;PBS_Server;Svr;tyrone-cluster;Scheduler was sent the command new
10/03/2014 18:51:04;0040;PBS_Server;Svr;tyrone-cluster;Scheduler was sent the command new
10/03/2014 18:51:34;0040;PBS_Server;Svr;tyrone-cluster;Scheduler was sent the command new
10/03/2014 18:52:03;0040;PBS_Server;Svr;tyrone-cluster;Scheduler was sent the command new
10/03/2014 18:52:34;0040;PBS_Server;Svr;tyrone-cluster;Scheduler was sent the command new
10/03/2014 18:52:50;0002;PBS_Server;Svr;PBS_Server;Torque Server Version = 3.0.5, loglevel = 0
10/03/2014 18:53:04;0040;PBS_Server;Svr;tyrone-cluster;Scheduler was sent the command new
10/03/2014 18:53:40;0040;PBS_Server;Svr;tyrone-cluster;Scheduler was sent the command new
10/03/2014 18:54:16;0040;PBS_Server;Svr;tyrone-cluster;Scheduler was sent the command new
10/03/2014 18:54:43;0040;PBS_Server;Svr;tyrone-cluster;Scheduler was sent the command new
10/03/2014 18:55:16;0040;PBS_Server;Svr;tyrone-cluster;Scheduler was sent the command new
10/03/2014 18:55:46;0040;PBS_Server;Svr;tyrone-cluster;Scheduler was sent the command new
10/03/2014 18:56:19;0040;PBS_Server;Svr;tyrone-cluster;Scheduler was sent the command new
10/03/2014 18:56:49;0040;PBS_Server;Svr;tyrone-cluster;Scheduler was sent the command new
10/03/2014 18:57:18;0040;PBS_Server;Svr;tyrone-cluster;Scheduler was sent the command new
10/03/2014 18:57:49;0040;PBS_Server;Svr;tyrone-cluster;Scheduler was sent the command new
10/03/2014 18:57:50;0002;PBS_Server;Svr;PBS_Server;Torque Server Version = 3.0.5, loglevel = 0
10/03/2014 18:58:19;0040;PBS_Server;Svr;tyrone-cluster;Scheduler was sent the command new
10/03/2014 18:58:55;0040;PBS_Server;Svr;tyrone-cluster;Scheduler was sent the command new
10/03/2014 18:59:31;0040;PBS_Server;Svr;tyrone-cluster;Scheduler was sent the command new
10/03/2014 18:59:58;0040;PBS_Server;Svr;tyrone-cluster;Scheduler was sent the command new
10/03/2014 19:00:31;0040;PBS_Server;Svr;tyrone-cluster;Scheduler was sent the command new
10/03/2014 19:01:01;0040;PBS_Server;Svr;tyrone-cluster;Scheduler was sent the command new
10/03/2014 19:01:28;0040;PBS_Server;Svr;tyrone-cluster;Scheduler was sent the command new
10/03/2014 19:01:54;0040;PBS_Server;Svr;tyrone-cluster;Scheduler was sent the command new
10/03/2014 19:02:31;0040;PBS_Server;Svr;tyrone-cluster;Scheduler was sent the command new
10/03/2014 19:02:50;0002;PBS_Server;Svr;PBS_Server;Torque Server Version = 3.0.5, loglevel = 0
10/03/2014 19:02:58;0040;PBS_Server;Svr;tyrone-cluster;Scheduler was sent the command new
10/03/2014 19:03:34;0040;PBS_Server;Svr;tyrone-cluster;Scheduler was sent the command new
10/03/2014 19:04:03;0040;PBS_Server;Svr;tyrone-cluster;Scheduler was sent the command new
10/03/2014 19:04:34;0040;PBS_Server;Svr;tyrone-cluster;Scheduler was sent the command new
10/03/2014 19:05:04;0040;PBS_Server;Svr;tyrone-cluster;Scheduler was sent the command new
10/03/2014 19:05:38;0040;PBS_Server;Svr;tyrone-cluster;Scheduler was sent the command new
10/03/2014 19:06:16;0040;PBS_Server;Svr;tyrone-cluster;Scheduler was sent the command new
10/03/2014 19:06:43;0040;PBS_Server;Svr;tyrone-cluster;Scheduler was sent the command new
10/03/2014 19:07:18;0040;PBS_Server;Svr;tyrone-cluster;Scheduler was sent the command new
10/03/2014 19:07:47;0040;PBS_Server;Svr;tyrone-cluster;Scheduler was sent the command new
10/03/2014 19:07:50;0002;PBS_Server;Svr;PBS_Server;Torque Server Version = 3.0.5, loglevel = 0
10/03/2014 19:08:20;0040;PBS_Server;Svr;tyrone-cluster;Scheduler was sent the command new
10/03/2014 19:08:49;0040;PBS_Server;Svr;tyrone-cluster;Scheduler was sent the command new
10/03/2014 19:09:25;0040;PBS_Server;Svr;tyrone-cluster;Scheduler was sent the command new
10/03/2014 19:10:01;0040;PBS_Server;Svr;tyrone-cluster;Scheduler was sent the command new
10/03/2014 19:10:28;0040;PBS_Server;Svr;tyrone-cluster;Scheduler was sent the command new
10/03/2014 19:11:04;0040;PBS_Server;Svr;tyrone-cluster;Scheduler was sent the command new
10/03/2014 19:11:32;0040;PBS_Server;Svr;tyrone-cluster;Scheduler was sent the command new
10/03/2014 19:12:04;0040;PBS_Server;Svr;tyrone-cluster;Scheduler was sent the command new
10/03/2014 19:12:09;0100;PBS_Server;Job;43362.tyrone-cluster;enqueuing into batch, state 1 hop 1
10/03/2014 19:12:09;0100;PBS_Server;Job;43362.tyrone-cluster;dequeuing from batch, state QUEUED
10/03/2014 19:12:09;0100;PBS_Server;Job;43362.tyrone-cluster;enqueuing into idqueue, state 1 hop 1
10/03/2014 19:12:09;0008;PBS_Server;Job;43362.tyrone-cluster;Job Queued at request of phynagmp@tyrone-cluster, owner = phynagmp@tyrone-cluster, job name = poshit, queue = idqueue
10/03/2014 19:12:09;0040;PBS_Server;Svr;tyrone-cluster;Scheduler was sent the command new
10/03/2014 19:12:09;0008;PBS_Server;Job;43362.tyrone-cluster;Job Modified at request of Scheduler@tyrone-cluster
10/03/2014 19:12:09;0008;PBS_Server;Job;43362.tyrone-cluster;Job Run at request of Scheduler@tyrone-cluster
10/03/2014 19:12:09;0040;PBS_Server;Svr;tyrone-cluster;Scheduler was sent the command recyc
10/03/2014 19:12:09;000d;PBS_Server;Job;43362.tyrone-cluster;Not sending email: User does not want mail of this type.
10/03/2014 19:12:12;000d;PBS_Server;Job;43362.tyrone-cluster;Not sending email: User does not want mail of this type.
10/03/2014 19:12:12;0010;PBS_Server;Job;43362.tyrone-cluster;Exit_status=0 resources_used.cput=00:00:34 resources_used.mem=0kb resources_used.vmem=0kb resources_used.walltime=00:00:03
10/03/2014 19:12:12;0008;PBS_Server;Job;NULL;on_job_exit valid pjob: 0x2e9af40 (substate=50)
10/03/2014 19:12:12;0008;PBS_Server;Job;NULL;on_job_exit valid pjob: 0x2e9af40 (substate=51)
10/03/2014 19:12:12;0008;PBS_Server;Job;NULL;on_job_exit valid pjob: 0x2e9af40 (substate=51)
10/03/2014 19:12:12;0008;PBS_Server;Job;NULL;on_job_exit valid pjob: 0x2e9af40 (substate=53)
10/03/2014 19:12:12;0100;PBS_Server;Job;43362.tyrone-cluster;dequeuing from idqueue, state COMPLETE
10/03/2014 19:12:12;0040;PBS_Server;Svr;tyrone-cluster;Scheduler was sent the command term
10/03/2014 19:12:34;0040;PBS_Server;Svr;tyrone-cluster;Scheduler was sent the command new
10/03/2014 19:12:50;0002;PBS_Server;Svr;PBS_Server;Torque Server Version = 3.0.5, loglevel = 0
10/03/2014 19:13:08;0040;PBS_Server;Svr;tyrone-cluster;Scheduler was sent the command new
10/03/2014 19:13:46;0040;PBS_Server;Svr;tyrone-cluster;Scheduler was sent the command new
10/03/2014 19:14:13;0040;PBS_Server;Svr;tyrone-cluster;Scheduler was sent the command new
10/03/2014 19:14:47;0040;PBS_Server;Svr;tyrone-cluster;Scheduler was sent the command new
10/03/2014 19:15:16;0040;PBS_Server;Svr;tyrone-cluster;Scheduler was sent the command new
10/03/2014 19:15:48;0040;PBS_Server;Svr;tyrone-cluster;Scheduler was sent the command new
10/03/2014 19:16:19;0040;PBS_Server;Svr;tyrone-cluster;Scheduler was sent the command new
10/03/2014 19:16:48;0040;PBS_Server;Svr;tyrone-cluster;Scheduler was sent the command new
10/03/2014 19:17:19;0040;PBS_Server;Svr;tyrone-cluster;Scheduler was sent the command new
10/03/2014 19:17:19;0100;PBS_Server;Job;43363.tyrone-cluster;enqueuing into batch, state 1 hop 1
10/03/2014 19:17:19;0100;PBS_Server;Job;43363.tyrone-cluster;dequeuing from batch, state QUEUED
10/03/2014 19:17:19;0100;PBS_Server;Job;43363.tyrone-cluster;enqueuing into idqueue, state 1 hop 1
10/03/2014 19:17:19;0008;PBS_Server;Job;43363.tyrone-cluster;Job Queued at request of phynagmp@tyrone-cluster, owner = phynagmp@tyrone-cluster, job name = poshit, queue = idqueue
10/03/2014 19:17:19;0040;PBS_Server;Svr;tyrone-cluster;Scheduler was sent the command new
10/03/2014 19:17:19;0008;PBS_Server;Job;43363.tyrone-cluster;Job Modified at request of Scheduler@tyrone-cluster
10/03/2014 19:17:19;0008;PBS_Server;Job;43363.tyrone-cluster;Job Run at request of Scheduler@tyrone-cluster
10/03/2014 19:17:19;0040;PBS_Server;Svr;tyrone-cluster;Scheduler was sent the command recyc
10/03/2014 19:17:19;000d;PBS_Server;Job;43363.tyrone-cluster;Not sending email: User does not want mail of this type.
10/03/2014 19:17:25;000d;PBS_Server;Job;43363.tyrone-cluster;Not sending email: User does not want mail of this type.
10/03/2014 19:17:25;0010;PBS_Server;Job;43363.tyrone-cluster;Exit_status=0 resources_used.cput=00:02:21 resources_used.mem=0kb resources_used.vmem=0kb resources_used.walltime=00:00:06
10/03/2014 19:17:25;0008;PBS_Server;Job;NULL;on_job_exit valid pjob: 0x2ce05b0 (substate=50)
10/03/2014 19:17:25;0008;PBS_Server;Job;NULL;on_job_exit valid pjob: 0x2ce05b0 (substate=51)
10/03/2014 19:17:25;0008;PBS_Server;Job;NULL;on_job_exit valid pjob: 0x2ce05b0 (substate=51)
10/03/2014 19:17:25;0008;PBS_Server;Job;NULL;on_job_exit valid pjob: 0x2ce05b0 (substate=53)
10/03/2014 19:17:25;0100;PBS_Server;Job;43363.tyrone-cluster;dequeuing from idqueue, state COMPLETE
10/03/2014 19:17:25;0040;PBS_Server;Svr;tyrone-cluster;Scheduler was sent the command term
10/03/2014 19:17:49;0040;PBS_Server;Svr;tyrone-cluster;Scheduler was sent the command new
10/03/2014 19:17:50;0002;PBS_Server;Svr;PBS_Server;Torque Server Version = 3.0.5, loglevel = 0
10/03/2014 19:18:25;0040;PBS_Server;Svr;tyrone-cluster;Scheduler was sent the command new
10/03/2014 19:18:54;0040;PBS_Server;Svr;tyrone-cluster;Scheduler was sent the command new
10/03/2014 19:18:54;0100;PBS_Server;Job;43364.tyrone-cluster;enqueuing into batch, state 1 hop 1
10/03/2014 19:18:54;0100;PBS_Server;Job;43364.tyrone-cluster;dequeuing from batch, state QUEUED
10/03/2014 19:18:54;0100;PBS_Server;Job;43364.tyrone-cluster;enqueuing into idqueue, state 1 hop 1
10/03/2014 19:18:54;0008;PBS_Server;Job;43364.tyrone-cluster;Job Queued at request of phynagmp@tyrone-cluster, owner = phynagmp@tyrone-cluster, job name = poshit, queue = idqueue
10/03/2014 19:18:54;0008;PBS_Server;Job;43364.tyrone-cluster;Job Modified at request of Scheduler@tyrone-cluster
10/03/2014 19:18:54;0008;PBS_Server;Job;43364.tyrone-cluster;Job Run at request of Scheduler@tyrone-cluster
10/03/2014 19:18:54;0040;PBS_Server;Svr;tyrone-cluster;Scheduler was sent the command recyc
10/03/2014 19:18:54;000d;PBS_Server;Job;43364.tyrone-cluster;Not sending email: User does not want mail of this type.
10/03/2014 19:18:56;000d;PBS_Server;Job;43364.tyrone-cluster;Not sending email: User does not want mail of this type.
10/03/2014 19:18:56;0010;PBS_Server;Job;43364.tyrone-cluster;Exit_status=0 resources_used.cput=00:00:42 resources_used.mem=0kb resources_used.vmem=0kb resources_used.walltime=00:00:02
10/03/2014 19:18:56;0008;PBS_Server;Job;NULL;on_job_exit valid pjob: 0x2dbe110 (substate=50)
10/03/2014 19:18:56;0008;PBS_Server;Job;NULL;on_job_exit valid pjob: 0x2dbe110 (substate=51)
10/03/2014 19:18:56;0008;PBS_Server;Job;NULL;on_job_exit valid pjob: 0x2dbe110 (substate=51)
10/03/2014 19:18:56;0008;PBS_Server;Job;NULL;on_job_exit valid pjob: 0x2dbe110 (substate=53)
10/03/2014 19:18:56;0100;PBS_Server;Job;43364.tyrone-cluster;dequeuing from idqueue, state COMPLETE
10/03/2014 19:18:56;0040;PBS_Server;Svr;tyrone-cluster;Scheduler was sent the command term
10/03/2014 19:19:28;0040;PBS_Server;Svr;tyrone-cluster;Scheduler was sent the command new
10/03/2014 19:20:01;0040;PBS_Server;Svr;tyrone-cluster;Scheduler was sent the command new
10/03/2014 19:20:31;0040;PBS_Server;Svr;tyrone-cluster;Scheduler was sent the command new
10/03/2014 19:20:58;0040;PBS_Server;Svr;tyrone-cluster;Scheduler was sent the command new
10/03/2014 19:21:32;0040;PBS_Server;Svr;tyrone-cluster;Scheduler was sent the command new
10/03/2014 19:22:01;0040;PBS_Server;Svr;tyrone-cluster;Scheduler was sent the command new
10/03/2014 19:22:28;0040;PBS_Server;Svr;tyrone-cluster;Scheduler was sent the command new
10/03/2014 19:22:50;0002;PBS_Server;Svr;PBS_Server;Torque Server Version = 3.0.5, loglevel = 0
10/03/2014 19:22:50;0100;PBS_Server;Job;43365.tyrone-cluster;enqueuing into batch, state 1 hop 1
10/03/2014 19:22:50;0100;PBS_Server;Job;43365.tyrone-cluster;dequeuing from batch, state QUEUED
10/03/2014 19:22:50;0100;PBS_Server;Job;43365.tyrone-cluster;enqueuing into idqueue, state 1 hop 1
10/03/2014 19:22:50;0008;PBS_Server;Job;43365.tyrone-cluster;Job Queued at request of phynagmp@tyrone-cluster, owner = phynagmp@tyrone-cluster, job name = poshit, queue = idqueue
10/03/2014 19:22:50;0040;PBS_Server;Svr;tyrone-cluster;Scheduler was sent the command new
10/03/2014 19:22:50;0008;PBS_Server;Job;43365.tyrone-cluster;Job Modified at request of Scheduler@tyrone-cluster
10/03/2014 19:22:50;0008;PBS_Server;Job;43365.tyrone-cluster;Job Run at request of Scheduler@tyrone-cluster
10/03/2014 19:22:50;0040;PBS_Server;Svr;tyrone-cluster;Scheduler was sent the command recyc
10/03/2014 19:22:50;000d;PBS_Server;Job;43365.tyrone-cluster;Not sending email: User does not want mail of this type.
10/03/2014 19:22:56;000d;PBS_Server;Job;43365.tyrone-cluster;Not sending email: User does not want mail of this type.
10/03/2014 19:22:56;0010;PBS_Server;Job;43365.tyrone-cluster;Exit_status=0 resources_used.cput=00:02:46 resources_used.mem=0kb resources_used.vmem=0kb resources_used.walltime=00:00:06
10/03/2014 19:22:56;0008;PBS_Server;Job;NULL;on_job_exit valid pjob: 0x2de5f90 (substate=50)
10/03/2014 19:22:56;0008;PBS_Server;Job;NULL;on_job_exit valid pjob: 0x2de5f90 (substate=51)
10/03/2014 19:22:56;0008;PBS_Server;Job;NULL;on_job_exit valid pjob: 0x2de5f90 (substate=51)
10/03/2014 19:22:56;0008;PBS_Server;Job;NULL;on_job_exit valid pjob: 0x2de5f90 (substate=53)
10/03/2014 19:22:56;0100;PBS_Server;Job;43365.tyrone-cluster;dequeuing from idqueue, state COMPLETE
10/03/2014 19:22:56;0040;PBS_Server;Svr;tyrone-cluster;Scheduler was sent the command term
10/03/2014 19:22:58;0040;PBS_Server;Svr;tyrone-cluster;Scheduler was sent the command new
10/03/2014 19:23:31;0040;PBS_Server;Svr;tyrone-cluster;Scheduler was sent the command new
10/03/2014 19:24:03;0040;PBS_Server;Svr;tyrone-cluster;Scheduler was sent the command new
10/03/2014 19:24:34;0040;PBS_Server;Svr;tyrone-cluster;Scheduler was sent the command new
10/03/2014 19:25:01;0040;PBS_Server;Svr;tyrone-cluster;Scheduler was sent the command new
10/03/2014 19:25:34;0040;PBS_Server;Svr;tyrone-cluster;Scheduler was sent the command new
10/03/2014 19:26:04;0040;PBS_Server;Svr;tyrone-cluster;Scheduler was sent the command new
10/03/2014 19:26:37;0040;PBS_Server;Svr;tyrone-cluster;Scheduler was sent the command new
10/03/2014 19:26:47;0100;PBS_Server;Job;43366.tyrone-cluster;enqueuing into batch, state 1 hop 1
10/03/2014 19:26:47;0100;PBS_Server;Job;43366.tyrone-cluster;dequeuing from batch, state QUEUED
10/03/2014 19:26:47;0100;PBS_Server;Job;43366.tyrone-cluster;enqueuing into idqueue, state 1 hop 1
10/03/2014 19:26:47;0008;PBS_Server;Job;43366.tyrone-cluster;Job Queued at request of phynagmp@tyrone-cluster, owner = phynagmp@tyrone-cluster, job name = poshit, queue = idqueue
10/03/2014 19:26:47;0040;PBS_Server;Svr;tyrone-cluster;Scheduler was sent the command new
10/03/2014 19:26:48;0008;PBS_Server;Job;43366.tyrone-cluster;Job Modified at request of Scheduler@tyrone-cluster
10/03/2014 19:26:48;0008;PBS_Server;Job;43366.tyrone-cluster;Job Run at request of Scheduler@tyrone-cluster
10/03/2014 19:26:48;0040;PBS_Server;Svr;tyrone-cluster;Scheduler was sent the command recyc
10/03/2014 19:26:48;000d;PBS_Server;Job;43366.tyrone-cluster;Not sending email: User does not want mail of this type.
10/03/2014 19:26:49;000d;PBS_Server;Job;43366.tyrone-cluster;Not sending email: User does not want mail of this type.
10/03/2014 19:26:49;0010;PBS_Server;Job;43366.tyrone-cluster;Exit_status=0 resources_used.cput=00:00:28 resources_used.mem=0kb resources_used.vmem=0kb resources_used.walltime=00:00:01
10/03/2014 19:26:49;0008;PBS_Server;Job;NULL;on_job_exit valid pjob: 0x2e9af40 (substate=50)
10/03/2014 19:26:49;0008;PBS_Server;Job;NULL;on_job_exit valid pjob: 0x2e9af40 (substate=51)
10/03/2014 19:26:49;0008;PBS_Server;Job;NULL;on_job_exit valid pjob: 0x2e9af40 (substate=51)
10/03/2014 19:26:49;0008;PBS_Server;Job;NULL;on_job_exit valid pjob: 0x2e9af40 (substate=53)
10/03/2014 19:26:49;0100;PBS_Server;Job;43366.tyrone-cluster;dequeuing from idqueue, state COMPLETE
10/03/2014 19:26:49;0040;PBS_Server;Svr;tyrone-cluster;Scheduler was sent the command term
10/03/2014 19:27:06;0040;PBS_Server;Svr;tyrone-cluster;Scheduler was sent the command new
10/03/2014 19:27:43;0040;PBS_Server;Svr;tyrone-cluster;Scheduler was sent the command new
10/03/2014 19:27:50;0002;PBS_Server;Svr;PBS_Server;Torque Server Version = 3.0.5, loglevel = 0
10/03/2014 19:28:17;0040;PBS_Server;Svr;tyrone-cluster;Scheduler was sent the command new
10/03/2014 19:28:46;0040;PBS_Server;Svr;tyrone-cluster;Scheduler was sent the command new
10/03/2014 19:29:19;0040;PBS_Server;Svr;tyrone-cluster;Scheduler was sent the command new
10/03/2014 19:29:50;0040;PBS_Server;Svr;tyrone-cluster;Scheduler was sent the command new
10/03/2014 19:30:22;0040;PBS_Server;Svr;tyrone-cluster;Scheduler was sent the command new
10/03/2014 19:30:51;0040;PBS_Server;Svr;tyrone-cluster;Scheduler was sent the command new
10/03/2014 19:31:28;0040;PBS_Server;Svr;tyrone-cluster;Scheduler was sent the command new
10/03/2014 19:32:02;0040;PBS_Server;Svr;tyrone-cluster;Scheduler was sent the command new
10/03/2014 19:32:31;0040;PBS_Server;Svr;tyrone-cluster;Scheduler was sent the command new
10/03/2014 19:32:50;0002;PBS_Server;Svr;PBS_Server;Torque Server Version = 3.0.5, loglevel = 0
10/03/2014 19:33:03;0040;PBS_Server;Svr;tyrone-cluster;Scheduler was sent the command new
10/03/2014 19:33:34;0040;PBS_Server;Svr;tyrone-cluster;Scheduler was sent the command new
10/03/2014 19:34:04;0040;PBS_Server;Svr;tyrone-cluster;Scheduler was sent the command new
10/03/2014 19:34:07;0100;PBS_Server;Job;43367.tyrone-cluster;enqueuing into batch, state 1 hop 1
10/03/2014 19:34:07;0100;PBS_Server;Job;43367.tyrone-cluster;dequeuing from batch, state QUEUED
10/03/2014 19:34:07;0100;PBS_Server;Job;43367.tyrone-cluster;enqueuing into idqueue, state 1 hop 1
10/03/2014 19:34:07;0008;PBS_Server;Job;43367.tyrone-cluster;Job Queued at request of phynagmp@tyrone-cluster, owner = phynagmp@tyrone-cluster, job name = poshit, queue = idqueue
10/03/2014 19:34:07;0040;PBS_Server;Svr;tyrone-cluster;Scheduler was sent the command new
10/03/2014 19:34:07;0008;PBS_Server;Job;43367.tyrone-cluster;Job Modified at request of Scheduler@tyrone-cluster
10/03/2014 19:34:07;0008;PBS_Server;Job;43367.tyrone-cluster;Job Run at request of Scheduler@tyrone-cluster
10/03/2014 19:34:07;0040;PBS_Server;Svr;tyrone-cluster;Scheduler was sent the command recyc
10/03/2014 19:34:07;000d;PBS_Server;Job;43367.tyrone-cluster;Not sending email: User does not want mail of this type.
10/03/2014 19:34:09;000d;PBS_Server;Job;43367.tyrone-cluster;Not sending email: User does not want mail of this type.
10/03/2014 19:34:09;0010;PBS_Server;Job;43367.tyrone-cluster;Exit_status=0 resources_used.cput=00:00:32 resources_used.mem=0kb resources_used.vmem=0kb resources_used.walltime=00:00:02
10/03/2014 19:34:09;0008;PBS_Server;Job;NULL;on_job_exit valid pjob: 0x2dbe110 (substate=50)
10/03/2014 19:34:09;0008;PBS_Server;Job;NULL;on_job_exit valid pjob: 0x2dbe110 (substate=51)
10/03/2014 19:34:09;0008;PBS_Server;Job;NULL;on_job_exit valid pjob: 0x2dbe110 (substate=51)
10/03/2014 19:34:09;0008;PBS_Server;Job;NULL;on_job_exit valid pjob: 0x2dbe110 (substate=53)
10/03/2014 19:34:09;0100;PBS_Server;Job;43367.tyrone-cluster;dequeuing from idqueue, state COMPLETE
10/03/2014 19:34:09;0040;PBS_Server;Svr;tyrone-cluster;Scheduler was sent the command term
10/03/2014 19:34:33;0040;PBS_Server;Svr;tyrone-cluster;Scheduler was sent the command new
10/03/2014 19:35:04;0040;PBS_Server;Svr;tyrone-cluster;Scheduler was sent the command new
10/03/2014 19:35:37;0040;PBS_Server;Svr;tyrone-cluster;Scheduler was sent the command new
10/03/2014 19:36:16;0040;PBS_Server;Svr;tyrone-cluster;Scheduler was sent the command new
10/03/2014 19:36:39;0040;PBS_Server;Svr;tyrone-cluster;Scheduler was sent the command new
10/03/2014 19:36:39;0100;PBS_Server;Job;43368.tyrone-cluster;enqueuing into batch, state 1 hop 1
10/03/2014 19:36:39;0100;PBS_Server;Job;43368.tyrone-cluster;dequeuing from batch, state QUEUED
10/03/2014 19:36:39;0100;PBS_Server;Job;43368.tyrone-cluster;enqueuing into idqueue, state 1 hop 1
10/03/2014 19:36:39;0008;PBS_Server;Job;43368.tyrone-cluster;Job Queued at request of phynagmp@tyrone-cluster, owner = phynagmp@tyrone-cluster, job name = poshit, queue = idqueue
10/03/2014 19:36:39;0008;PBS_Server;Job;43368.tyrone-cluster;Job Modified at request of Scheduler@tyrone-cluster
10/03/2014 19:36:39;0008;PBS_Server;Job;43368.tyrone-cluster;Job Run at request of Scheduler@tyrone-cluster
10/03/2014 19:36:39;0040;PBS_Server;Svr;tyrone-cluster;Scheduler was sent the command recyc
10/03/2014 19:36:39;000d;PBS_Server;Job;43368.tyrone-cluster;Not sending email: User does not want mail of this type.
10/03/2014 19:37:02;000d;PBS_Server;Job;43368.tyrone-cluster;Not sending email: User does not want mail of this type.
10/03/2014 19:37:02;0010;PBS_Server;Job;43368.tyrone-cluster;Exit_status=0 resources_used.cput=00:10:55 resources_used.mem=0kb resources_used.vmem=0kb resources_used.walltime=00:00:22
10/03/2014 19:37:02;0008;PBS_Server;Job;NULL;on_job_exit valid pjob: 0x2ce05b0 (substate=50)
10/03/2014 19:37:02;0008;PBS_Server;Job;NULL;on_job_exit valid pjob: 0x2ce05b0 (substate=51)
10/03/2014 19:37:02;0008;PBS_Server;Job;NULL;on_job_exit valid pjob: 0x2ce05b0 (substate=51)
10/03/2014 19:37:02;0008;PBS_Server;Job;NULL;on_job_exit valid pjob: 0x2ce05b0 (substate=53)
10/03/2014 19:37:02;0100;PBS_Server;Job;43368.tyrone-cluster;dequeuing from idqueue, state COMPLETE
10/03/2014 19:37:02;0040;PBS_Server;Svr;tyrone-cluster;Scheduler was sent the command term
10/03/2014 19:37:17;0040;PBS_Server;Svr;tyrone-cluster;Scheduler was sent the command new
10/03/2014 19:37:46;0040;PBS_Server;Svr;tyrone-cluster;Scheduler was sent the command new
10/03/2014 19:37:50;0002;PBS_Server;Svr;PBS_Server;Torque Server Version = 3.0.5, loglevel = 0
10/03/2014 19:38:19;0040;PBS_Server;Svr;tyrone-cluster;Scheduler was sent the command new
10/03/2014 19:38:49;0040;PBS_Server;Svr;tyrone-cluster;Scheduler was sent the command new
10/03/2014 19:39:01;0100;PBS_Server;Job;43369.tyrone-cluster;enqueuing into batch, state 1 hop 1
10/03/2014 19:39:01;0100;PBS_Server;Job;43369.tyrone-cluster;dequeuing from batch, state QUEUED
10/03/2014 19:39:01;0100;PBS_Server;Job;43369.tyrone-cluster;enqueuing into idqueue, state 1 hop 1
10/03/2014 19:39:01;0008;PBS_Server;Job;43369.tyrone-cluster;Job Queued at request of phynagmp@tyrone-cluster, owner = phynagmp@tyrone-cluster, job name = poshit, queue = idqueue
10/03/2014 19:39:01;0040;PBS_Server;Svr;tyrone-cluster;Scheduler was sent the command new
10/03/2014 19:39:01;0008;PBS_Server;Job;43369.tyrone-cluster;Job Modified at request of Scheduler@tyrone-cluster
10/03/2014 19:39:01;0008;PBS_Server;Job;43369.tyrone-cluster;Job Run at request of Scheduler@tyrone-cluster
10/03/2014 19:39:01;0040;PBS_Server;Svr;tyrone-cluster;Scheduler was sent the command recyc
10/03/2014 19:39:01;000d;PBS_Server;Job;43369.tyrone-cluster;Not sending email: User does not want mail of this type.
10/03/2014 19:39:22;0040;PBS_Server;Svr;tyrone-cluster;Scheduler was sent the command new
10/03/2014 19:39:26;0100;PBS_Server;Job;43370.tyrone-cluster;enqueuing into batch, state 1 hop 1
10/03/2014 19:39:26;0100;PBS_Server;Job;43370.tyrone-cluster;dequeuing from batch, state QUEUED
10/03/2014 19:39:26;0100;PBS_Server;Job;43370.tyrone-cluster;enqueuing into idqueue, state 1 hop 1
10/03/2014 19:39:26;0008;PBS_Server;Job;43370.tyrone-cluster;Job Queued at request of phynagmp@tyrone-cluster, owner = phynagmp@tyrone-cluster, job name = poshit, queue = idqueue
10/03/2014 19:39:26;0040;PBS_Server;Svr;tyrone-cluster;Scheduler was sent the command new
10/03/2014 19:39:26;0008;PBS_Server;Job;43370.tyrone-cluster;Job Modified at request of Scheduler@tyrone-cluster
10/03/2014 19:39:33;0100;PBS_Server;Job;43371.tyrone-cluster;enqueuing into batch, state 1 hop 1
10/03/2014 19:39:33;0100;PBS_Server;Job;43371.tyrone-cluster;dequeuing from batch, state QUEUED
10/03/2014 19:39:33;0100;PBS_Server;Job;43371.tyrone-cluster;enqueuing into idqueue, state 1 hop 1
10/03/2014 19:39:33;0008;PBS_Server;Job;43371.tyrone-cluster;Job Queued at request of phynagmp@tyrone-cluster, owner = phynagmp@tyrone-cluster, job name = poshit, queue = idqueue
10/03/2014 19:39:33;0040;PBS_Server;Svr;tyrone-cluster;Scheduler was sent the command new
10/03/2014 19:39:33;0008;PBS_Server;Job;43371.tyrone-cluster;Job Modified at request of Scheduler@tyrone-cluster
10/03/2014 19:39:34;0100;PBS_Server;Job;43372.tyrone-cluster;enqueuing into batch, state 1 hop 1
10/03/2014 19:39:34;0100;PBS_Server;Job;43372.tyrone-cluster;dequeuing from batch, state QUEUED
10/03/2014 19:39:34;0100;PBS_Server;Job;43372.tyrone-cluster;enqueuing into idqueue, state 1 hop 1
10/03/2014 19:39:34;0008;PBS_Server;Job;43372.tyrone-cluster;Job Queued at request of phynagmp@tyrone-cluster, owner = phynagmp@tyrone-cluster, job name = poshit, queue = idqueue
10/03/2014 19:39:34;0040;PBS_Server;Svr;tyrone-cluster;Scheduler was sent the command new
10/03/2014 19:39:34;0008;PBS_Server;Job;43372.tyrone-cluster;Job Modified at request of Scheduler@tyrone-cluster
10/03/2014 19:39:43;000d;PBS_Server;Job;43369.tyrone-cluster;Not sending email: User does not want mail of this type.
10/03/2014 19:39:43;0010;PBS_Server;Job;43369.tyrone-cluster;Exit_status=0 resources_used.cput=00:20:48 resources_used.mem=1110192kb resources_used.vmem=9544672kb resources_used.walltime=00:00:42
10/03/2014 19:39:43;0008;PBS_Server;Job;NULL;on_job_exit valid pjob: 0x2dbe110 (substate=50)
10/03/2014 19:39:43;0008;PBS_Server;Job;NULL;on_job_exit valid pjob: 0x2dbe110 (substate=51)
10/03/2014 19:39:43;0008;PBS_Server;Job;NULL;on_job_exit valid pjob: 0x2dbe110 (substate=51)
10/03/2014 19:39:43;0008;PBS_Server;Job;NULL;on_job_exit valid pjob: 0x2dbe110 (substate=53)
10/03/2014 19:39:43;0100;PBS_Server;Job;43369.tyrone-cluster;dequeuing from idqueue, state COMPLETE
10/03/2014 19:39:43;0040;PBS_Server;Svr;tyrone-cluster;Scheduler was sent the command term
10/03/2014 19:39:44;0008;PBS_Server;Job;43370.tyrone-cluster;Job Modified at request of Scheduler@tyrone-cluster
10/03/2014 19:39:44;0008;PBS_Server;Job;43370.tyrone-cluster;Job Run at request of Scheduler@tyrone-cluster
10/03/2014 19:39:44;0040;PBS_Server;Svr;tyrone-cluster;Scheduler was sent the command recyc
10/03/2014 19:39:44;000d;PBS_Server;Job;43370.tyrone-cluster;Not sending email: User does not want mail of this type.
10/03/2014 19:39:53;0008;PBS_Server;Job;43372.tyrone-cluster;Job deleted at request of phynagmp@tyrone-cluster
10/03/2014 19:39:53;0008;PBS_Server;Job;NULL;on_job_exit valid pjob: 0x2cd6fe0 (substate=59)
10/03/2014 19:39:53;0100;PBS_Server;Job;43372.tyrone-cluster;dequeuing from idqueue, state COMPLETE
10/03/2014 19:39:53;0040;PBS_Server;Svr;tyrone-cluster;Scheduler was sent the command term
10/03/2014 19:40:10;0008;PBS_Server;Job;43371.tyrone-cluster;Job deleted at request of phynagmp@tyrone-cluster
10/03/2014 19:40:10;0008;PBS_Server;Job;NULL;on_job_exit valid pjob: 0x2e9af40 (substate=59)
10/03/2014 19:40:10;0100;PBS_Server;Job;43371.tyrone-cluster;dequeuing from idqueue, state COMPLETE
10/03/2014 19:40:10;0040;PBS_Server;Svr;tyrone-cluster;Scheduler was sent the command term
10/03/2014 19:40:23;0040;PBS_Server;Svr;tyrone-cluster;Scheduler was sent the command new
10/03/2014 19:40:43;000d;PBS_Server;Job;43370.tyrone-cluster;Not sending email: User does not want mail of this type.
10/03/2014 19:40:43;0010;PBS_Server;Job;43370.tyrone-cluster;Exit_status=0 resources_used.cput=00:29:00 resources_used.mem=1114028kb resources_used.vmem=9544648kb resources_used.walltime=00:00:59
10/03/2014 19:40:43;0008;PBS_Server;Job;NULL;on_job_exit valid pjob: 0x2de5f90 (substate=50)
10/03/2014 19:40:43;0008;PBS_Server;Job;NULL;on_job_exit valid pjob: 0x2de5f90 (substate=51)
10/03/2014 19:40:44;0008;PBS_Server;Job;NULL;on_job_exit valid pjob: 0x2de5f90 (substate=51)
10/03/2014 19:40:44;0008;PBS_Server;Job;NULL;on_job_exit valid pjob: 0x2de5f90 (substate=53)
10/03/2014 19:40:44;0100;PBS_Server;Job;43370.tyrone-cluster;dequeuing from idqueue, state COMPLETE
10/03/2014 19:40:44;0040;PBS_Server;Svr;tyrone-cluster;Scheduler was sent the command term
10/03/2014 19:40:55;0040;PBS_Server;Svr;tyrone-cluster;Scheduler was sent the command new
10/03/2014 19:41:31;0040;PBS_Server;Svr;tyrone-cluster;Scheduler was sent the command new
10/03/2014 19:41:58;0040;PBS_Server;Svr;tyrone-cluster;Scheduler was sent the command new
10/03/2014 19:42:32;0040;PBS_Server;Svr;tyrone-cluster;Scheduler was sent the command new
10/03/2014 19:42:50;0002;PBS_Server;Svr;PBS_Server;Torque Server Version = 3.0.5, loglevel = 0
10/03/2014 19:43:01;0040;PBS_Server;Svr;tyrone-cluster;Scheduler was sent the command new
10/03/2014 19:43:33;0040;PBS_Server;Svr;tyrone-cluster;Scheduler was sent the command new
10/03/2014 19:44:04;0040;PBS_Server;Svr;tyrone-cluster;Scheduler was sent the command new
10/03/2014 19:44:40;0040;PBS_Server;Svr;tyrone-cluster;Scheduler was sent the command new
10/03/2014 19:45:16;0040;PBS_Server;Svr;tyrone-cluster;Scheduler was sent the command new
10/03/2014 19:45:43;0040;PBS_Server;Svr;tyrone-cluster;Scheduler was sent the command new
10/03/2014 19:46:17;0040;PBS_Server;Svr;tyrone-cluster;Scheduler was sent the command new
10/03/2014 19:46:46;0040;PBS_Server;Svr;tyrone-cluster;Scheduler was sent the command new
10/03/2014 19:47:16;0040;PBS_Server;Svr;tyrone-cluster;Scheduler was sent the command new
10/03/2014 19:47:16;0100;PBS_Server;Job;43373.tyrone-cluster;enqueuing into batch, state 1 hop 1
10/03/2014 19:47:16;0100;PBS_Server;Job;43373.tyrone-cluster;dequeuing from batch, state QUEUED
10/03/2014 19:47:16;0100;PBS_Server;Job;43373.tyrone-cluster;enqueuing into idqueue, state 1 hop 1
10/03/2014 19:47:16;0008;PBS_Server;Job;43373.tyrone-cluster;Job Queued at request of phynagmp@tyrone-cluster, owner = phynagmp@tyrone-cluster, job name = poshit, queue = idqueue
10/03/2014 19:47:16;0008;PBS_Server;Job;43373.tyrone-cluster;Job Modified at request of Scheduler@tyrone-cluster
10/03/2014 19:47:16;0008;PBS_Server;Job;43373.tyrone-cluster;Job Run at request of Scheduler@tyrone-cluster
10/03/2014 19:47:16;0040;PBS_Server;Svr;tyrone-cluster;Scheduler was sent the command recyc
10/03/2014 19:47:16;000d;PBS_Server;Job;43373.tyrone-cluster;Not sending email: User does not want mail of this type.
10/03/2014 19:47:48;0040;PBS_Server;Svr;tyrone-cluster;Scheduler was sent the command new
10/03/2014 19:47:50;0002;PBS_Server;Svr;PBS_Server;Torque Server Version = 3.0.5, loglevel = 0
10/03/2014 19:48:17;0040;PBS_Server;Svr;tyrone-cluster;Scheduler was sent the command new
10/03/2014 19:48:19;000d;PBS_Server;Job;43373.tyrone-cluster;Not sending email: User does not want mail of this type.
10/03/2014 19:48:19;0010;PBS_Server;Job;43373.tyrone-cluster;Exit_status=0 resources_used.cput=00:31:41 resources_used.mem=962976kb resources_used.vmem=9371864kb resources_used.walltime=00:01:03
10/03/2014 19:48:19;0008;PBS_Server;Job;NULL;on_job_exit valid pjob: 0x2cd6fe0 (substate=50)
10/03/2014 19:48:19;0008;PBS_Server;Job;NULL;on_job_exit valid pjob: 0x2cd6fe0 (substate=51)
10/03/2014 19:48:19;0008;PBS_Server;Job;NULL;on_job_exit valid pjob: 0x2cd6fe0 (substate=51)
10/03/2014 19:48:19;0008;PBS_Server;Job;NULL;on_job_exit valid pjob: 0x2cd6fe0 (substate=53)
10/03/2014 19:48:19;0100;PBS_Server;Job;43373.tyrone-cluster;dequeuing from idqueue, state COMPLETE
10/03/2014 19:48:19;0040;PBS_Server;Svr;tyrone-cluster;Scheduler was sent the command term
10/03/2014 19:48:49;0040;PBS_Server;Svr;tyrone-cluster;Scheduler was sent the command new
10/03/2014 19:49:18;0040;PBS_Server;Svr;tyrone-cluster;Scheduler was sent the command new
10/03/2014 19:49:33;0100;PBS_Server;Job;43374.tyrone-cluster;enqueuing into batch, state 1 hop 1
10/03/2014 19:49:33;0100;PBS_Server;Job;43374.tyrone-cluster;dequeuing from batch, state QUEUED
10/03/2014 19:49:33;0100;PBS_Server;Job;43374.tyrone-cluster;enqueuing into idqueue, state 1 hop 1
10/03/2014 19:49:33;0008;PBS_Server;Job;43374.tyrone-cluster;Job Queued at request of phynagmp@tyrone-cluster, owner = phynagmp@tyrone-cluster, job name = poshit, queue = idqueue
10/03/2014 19:49:33;0040;PBS_Server;Svr;tyrone-cluster;Scheduler was sent the command new
10/03/2014 19:49:33;0008;PBS_Server;Job;43374.tyrone-cluster;Job Modified at request of Scheduler@tyrone-cluster
10/03/2014 19:49:33;0008;PBS_Server;Job;43374.tyrone-cluster;Job Run at request of Scheduler@tyrone-cluster
10/03/2014 19:49:33;0040;PBS_Server;Svr;tyrone-cluster;Scheduler was sent the command recyc
10/03/2014 19:49:33;000d;PBS_Server;Job;43374.tyrone-cluster;Not sending email: User does not want mail of this type.
10/03/2014 19:49:36;000d;PBS_Server;Job;43374.tyrone-cluster;Not sending email: User does not want mail of this type.
10/03/2014 19:49:36;0010;PBS_Server;Job;43374.tyrone-cluster;Exit_status=0 resources_used.cput=00:00:57 resources_used.mem=0kb resources_used.vmem=0kb resources_used.walltime=00:00:03
10/03/2014 19:49:36;0008;PBS_Server;Job;NULL;on_job_exit valid pjob: 0x2de5f90 (substate=50)
10/03/2014 19:49:36;0008;PBS_Server;Job;NULL;on_job_exit valid pjob: 0x2de5f90 (substate=51)
10/03/2014 19:49:36;0008;PBS_Server;Job;NULL;on_job_exit valid pjob: 0x2de5f90 (substate=51)
10/03/2014 19:49:36;0008;PBS_Server;Job;NULL;on_job_exit valid pjob: 0x2de5f90 (substate=53)
10/03/2014 19:49:36;0100;PBS_Server;Job;43374.tyrone-cluster;dequeuing from idqueue, state COMPLETE
10/03/2014 19:49:36;0040;PBS_Server;Svr;tyrone-cluster;Scheduler was sent the command term
10/03/2014 19:49:54;0040;PBS_Server;Svr;tyrone-cluster;Scheduler was sent the command new
10/03/2014 19:50:31;0040;PBS_Server;Svr;tyrone-cluster;Scheduler was sent the command new
10/03/2014 19:50:52;0100;PBS_Server;Job;43375.tyrone-cluster;enqueuing into batch, state 1 hop 1
10/03/2014 19:50:52;0100;PBS_Server;Job;43375.tyrone-cluster;dequeuing from batch, state QUEUED
10/03/2014 19:50:52;0100;PBS_Server;Job;43375.tyrone-cluster;enqueuing into idqueue, state 1 hop 1
10/03/2014 19:50:52;0008;PBS_Server;Job;43375.tyrone-cluster;Job Queued at request of phynagmp@tyrone-cluster, owner = phynagmp@tyrone-cluster, job name = poshit, queue = idqueue
10/03/2014 19:50:52;0040;PBS_Server;Svr;tyrone-cluster;Scheduler was sent the command new
10/03/2014 19:50:52;0008;PBS_Server;Job;43375.tyrone-cluster;Job Modified at request of Scheduler@tyrone-cluster
10/03/2014 19:50:52;0008;PBS_Server;Job;43375.tyrone-cluster;Job Run at request of Scheduler@tyrone-cluster
10/03/2014 19:50:52;0040;PBS_Server;Svr;tyrone-cluster;Scheduler was sent the command recyc
10/03/2014 19:50:52;000d;PBS_Server;Job;43375.tyrone-cluster;Not sending email: User does not want mail of this type.
10/03/2014 19:50:55;0040;PBS_Server;Svr;tyrone-cluster;Scheduler was sent the command new
10/03/2014 19:51:02;000d;PBS_Server;Job;43375.tyrone-cluster;Not sending email: User does not want mail of this type.
10/03/2014 19:51:02;0010;PBS_Server;Job;43375.tyrone-cluster;Exit_status=0 resources_used.cput=00:04:32 resources_used.mem=839816kb resources_used.vmem=9323496kb resources_used.walltime=00:00:10
10/03/2014 19:51:02;0008;PBS_Server;Job;NULL;on_job_exit valid pjob: 0x2dbe110 (substate=50)
10/03/2014 19:51:02;0008;PBS_Server;Job;NULL;on_job_exit valid pjob: 0x2dbe110 (substate=51)
10/03/2014 19:51:02;0008;PBS_Server;Job;NULL;on_job_exit valid pjob: 0x2dbe110 (substate=51)
10/03/2014 19:51:02;0008;PBS_Server;Job;NULL;on_job_exit valid pjob: 0x2dbe110 (substate=53)
10/03/2014 19:51:02;0100;PBS_Server;Job;43375.tyrone-cluster;dequeuing from idqueue, state COMPLETE
10/03/2014 19:51:02;0040;PBS_Server;Svr;tyrone-cluster;Scheduler was sent the command term
10/03/2014 19:51:31;0040;PBS_Server;Svr;tyrone-cluster;Scheduler was sent the command new
10/03/2014 19:52:01;0040;PBS_Server;Svr;tyrone-cluster;Scheduler was sent the command new
10/03/2014 19:52:07;0100;PBS_Server;Job;43376.tyrone-cluster;enqueuing into batch, state 1 hop 1
10/03/2014 19:52:07;0100;PBS_Server;Job;43376.tyrone-cluster;dequeuing from batch, state QUEUED
10/03/2014 19:52:07;0100;PBS_Server;Job;43376.tyrone-cluster;enqueuing into idqueue, state 1 hop 1
10/03/2014 19:52:07;0008;PBS_Server;Job;43376.tyrone-cluster;Job Queued at request of phynagmp@tyrone-cluster, owner = phynagmp@tyrone-cluster, job name = poshit, queue = idqueue
10/03/2014 19:52:07;0040;PBS_Server;Svr;tyrone-cluster;Scheduler was sent the command new
10/03/2014 19:52:07;0008;PBS_Server;Job;43376.tyrone-cluster;Job Modified at request of Scheduler@tyrone-cluster
10/03/2014 19:52:07;0008;PBS_Server;Job;43376.tyrone-cluster;Job Run at request of Scheduler@tyrone-cluster
10/03/2014 19:52:07;0040;PBS_Server;Svr;tyrone-cluster;Scheduler was sent the command recyc
10/03/2014 19:52:07;000d;PBS_Server;Job;43376.tyrone-cluster;Not sending email: User does not want mail of this type.
10/03/2014 19:52:28;0040;PBS_Server;Svr;tyrone-cluster;Scheduler was sent the command new
10/03/2014 19:52:50;0002;PBS_Server;Svr;PBS_Server;Torque Server Version = 3.0.5, loglevel = 0
10/03/2014 19:52:58;0040;PBS_Server;Svr;tyrone-cluster;Scheduler was sent the command new
10/03/2014 19:53:31;0040;PBS_Server;Svr;tyrone-cluster;Scheduler was sent the command new
10/03/2014 19:53:58;0040;PBS_Server;Svr;tyrone-cluster;Scheduler was sent the command new
10/03/2014 19:54:24;0040;PBS_Server;Svr;tyrone-cluster;Scheduler was sent the command new
10/03/2014 19:54:24;000d;PBS_Server;Job;43376.tyrone-cluster;Not sending email: User does not want mail of this type.
10/03/2014 19:54:24;0010;PBS_Server;Job;43376.tyrone-cluster;Exit_status=0 resources_used.cput=01:11:26 resources_used.mem=1624280kb resources_used.vmem=9935668kb resources_used.walltime=00:02:17
10/03/2014 19:54:24;0008;PBS_Server;Job;NULL;on_job_exit valid pjob: 0x2e9af40 (substate=50)
10/03/2014 19:54:24;0008;PBS_Server;Job;NULL;on_job_exit valid pjob: 0x2e9af40 (substate=51)
10/03/2014 19:54:24;0008;PBS_Server;Job;NULL;on_job_exit valid pjob: 0x2e9af40 (substate=51)
10/03/2014 19:54:24;0008;PBS_Server;Job;NULL;on_job_exit valid pjob: 0x2e9af40 (substate=53)
10/03/2014 19:54:24;0100;PBS_Server;Job;43376.tyrone-cluster;dequeuing from idqueue, state COMPLETE
10/03/2014 19:55:01;0040;PBS_Server;Svr;tyrone-cluster;Scheduler was sent the command new
10/03/2014 19:55:28;0040;PBS_Server;Svr;tyrone-cluster;Scheduler was sent the command new
10/03/2014 19:56:02;0040;PBS_Server;Svr;tyrone-cluster;Scheduler was sent the command new
10/03/2014 19:56:31;0040;PBS_Server;Svr;tyrone-cluster;Scheduler was sent the command new
10/03/2014 19:57:03;0040;PBS_Server;Svr;tyrone-cluster;Scheduler was sent the command new
10/03/2014 19:57:34;0040;PBS_Server;Svr;tyrone-cluster;Scheduler was sent the command new
10/03/2014 19:57:50;0002;PBS_Server;Svr;PBS_Server;Torque Server Version = 3.0.5, loglevel = 0
10/03/2014 19:58:07;0040;PBS_Server;Svr;tyrone-cluster;Scheduler was sent the command new
10/03/2014 19:58:45;0040;PBS_Server;Svr;tyrone-cluster;Scheduler was sent the command new
10/03/2014 19:59:13;0040;PBS_Server;Svr;tyrone-cluster;Scheduler was sent the command new
10/03/2014 19:59:16;0100;PBS_Server;Job;43377.tyrone-cluster;enqueuing into batch, state 1 hop 1
10/03/2014 19:59:16;0100;PBS_Server;Job;43377.tyrone-cluster;dequeuing from batch, state QUEUED
10/03/2014 19:59:16;0100;PBS_Server;Job;43377.tyrone-cluster;enqueuing into idqueue, state 1 hop 1
10/03/2014 19:59:16;0008;PBS_Server;Job;43377.tyrone-cluster;Job Queued at request of asepk@tyrone-cluster, owner = asepk@tyrone-cluster, job name = AeDNs_4, queue = idqueue
10/03/2014 19:59:16;0040;PBS_Server;Svr;tyrone-cluster;Scheduler was sent the command new
10/03/2014 19:59:16;0008;PBS_Server;Job;43377.tyrone-cluster;Job Modified at request of Scheduler@tyrone-cluster
10/03/2014 19:59:16;0008;PBS_Server;Job;43377.tyrone-cluster;Job Run at request of Scheduler@tyrone-cluster
10/03/2014 19:59:16;0040;PBS_Server;Svr;tyrone-cluster;Scheduler was sent the command recyc
10/03/2014 19:59:16;000d;PBS_Server;Job;43377.tyrone-cluster;Not sending email: User does not want mail of this type.
10/03/2014 19:59:40;0040;PBS_Server;Svr;tyrone-cluster;Scheduler was sent the command new
10/03/2014 19:59:40;0100;PBS_Server;Job;43378.tyrone-cluster;enqueuing into batch, state 1 hop 1
10/03/2014 19:59:40;0100;PBS_Server;Job;43378.tyrone-cluster;dequeuing from batch, state QUEUED
10/03/2014 19:59:40;0100;PBS_Server;Job;43378.tyrone-cluster;enqueuing into idqueue, state 1 hop 1
10/03/2014 19:59:40;0008;PBS_Server;Job;43378.tyrone-cluster;Job Queued at request of phynagmp@tyrone-cluster, owner = phynagmp@tyrone-cluster, job name = poshit, queue = idqueue
10/03/2014 19:59:40;0008;PBS_Server;Job;43378.tyrone-cluster;Job Modified at request of Scheduler@tyrone-cluster
10/03/2014 20:00:16;0040;PBS_Server;Svr;tyrone-cluster;Scheduler was sent the command new
10/03/2014 20:00:43;0040;PBS_Server;Svr;tyrone-cluster;Scheduler was sent the command new
10/03/2014 20:01:15;0040;PBS_Server;Svr;tyrone-cluster;Scheduler was sent the command new
10/03/2014 20:01:41;0040;PBS_Server;Svr;tyrone-cluster;Scheduler was sent the command new
10/03/2014 20:02:13;0040;PBS_Server;Svr;tyrone-cluster;Scheduler was sent the command new
10/03/2014 20:02:34;0100;PBS_Server;Job;43379.tyrone-cluster;enqueuing into batch, state 1 hop 1
10/03/2014 20:02:34;0100;PBS_Server;Job;43379.tyrone-cluster;dequeuing from batch, state QUEUED
10/03/2014 20:02:34;0100;PBS_Server;Job;43379.tyrone-cluster;enqueuing into idqueue, state 1 hop 1
10/03/2014 20:02:34;0008;PBS_Server;Job;43379.tyrone-cluster;Job Queued at request of asepk@tyrone-cluster, owner = asepk@tyrone-cluster, job name = AeDNs_4, queue = idqueue
10/03/2014 20:02:34;0040;PBS_Server;Svr;tyrone-cluster;Scheduler was sent the command new
10/03/2014 20:02:34;0008;PBS_Server;Job;43379.tyrone-cluster;Job Modified at request of Scheduler@tyrone-cluster
10/03/2014 20:02:43;0020;PBS_Server;Job;43378.tyrone-cluster;Unauthorized Request, request type: 6, Object: Job, Name: 43378.tyrone-cluster, request from: asepk@tyrone-cluster
10/03/2014 20:02:43;0080;PBS_Server;Req;req_reject;Reject reply code=15007(Unauthorized Request  MSG=operation not permitted), aux=0, type=DeleteJob, from asepk@tyrone-cluster
10/03/2014 20:02:43;0040;PBS_Server;Svr;tyrone-cluster;Scheduler was sent the command new
10/03/2014 20:02:50;0002;PBS_Server;Svr;PBS_Server;Torque Server Version = 3.0.5, loglevel = 0
10/03/2014 20:02:51;0008;PBS_Server;Job;43377.tyrone-cluster;Job deleted at request of asepk@tyrone-cluster
10/03/2014 20:02:51;0008;PBS_Server;Job;43377.tyrone-cluster;Job sent signal SIGTERM on delete
10/03/2014 20:02:51;000d;PBS_Server;Job;43377.tyrone-cluster;Not sending email: User does not want mail of this type.
10/03/2014 20:02:51;0010;PBS_Server;Job;43377.tyrone-cluster;Exit_status=143 resources_used.cput=01:52:42 resources_used.mem=755120kb resources_used.vmem=7364308kb resources_used.walltime=00:03:35
10/03/2014 20:02:51;0008;PBS_Server;Job;NULL;on_job_exit valid pjob: 0x2e9af40 (substate=50)
10/03/2014 20:02:51;0008;PBS_Server;Job;NULL;on_job_exit valid pjob: 0x2e9af40 (substate=51)
10/03/2014 20:02:51;0008;PBS_Server;Job;NULL;on_job_exit valid pjob: 0x2e9af40 (substate=51)
10/03/2014 20:02:51;0008;PBS_Server;Job;NULL;on_job_exit valid pjob: 0x2e9af40 (substate=53)
10/03/2014 20:02:51;0100;PBS_Server;Job;43377.tyrone-cluster;dequeuing from idqueue, state COMPLETE
10/03/2014 20:02:51;0040;PBS_Server;Svr;tyrone-cluster;Scheduler was sent the command term
10/03/2014 20:02:51;0008;PBS_Server;Job;43378.tyrone-cluster;Job Modified at request of Scheduler@tyrone-cluster
10/03/2014 20:02:51;0008;PBS_Server;Job;43378.tyrone-cluster;Job Run at request of Scheduler@tyrone-cluster
10/03/2014 20:02:51;0040;PBS_Server;Svr;tyrone-cluster;Scheduler was sent the command recyc
10/03/2014 20:02:51;000d;PBS_Server;Job;43378.tyrone-cluster;Not sending email: User does not want mail of this type.
10/03/2014 20:03:16;0040;PBS_Server;Svr;tyrone-cluster;Scheduler was sent the command new
10/03/2014 20:03:48;0040;PBS_Server;Svr;tyrone-cluster;Scheduler was sent the command new
10/03/2014 20:04:17;0040;PBS_Server;Svr;tyrone-cluster;Scheduler was sent the command new
10/03/2014 20:04:47;0040;PBS_Server;Svr;tyrone-cluster;Scheduler was sent the command new
10/03/2014 20:04:56;000d;PBS_Server;Job;43378.tyrone-cluster;Not sending email: User does not want mail of this type.
10/03/2014 20:04:56;0010;PBS_Server;Job;43378.tyrone-cluster;Exit_status=0 resources_used.cput=01:03:03 resources_used.mem=1620280kb resources_used.vmem=9935672kb resources_used.walltime=00:02:05
10/03/2014 20:04:56;0008;PBS_Server;Job;NULL;on_job_exit valid pjob: 0x2cd6fe0 (substate=50)
10/03/2014 20:04:56;0008;PBS_Server;Job;NULL;on_job_exit valid pjob: 0x2cd6fe0 (substate=51)
10/03/2014 20:04:56;0008;PBS_Server;Job;NULL;on_job_exit valid pjob: 0x2cd6fe0 (substate=51)
10/03/2014 20:04:56;0008;PBS_Server;Job;NULL;on_job_exit valid pjob: 0x2cd6fe0 (substate=53)
10/03/2014 20:04:56;0100;PBS_Server;Job;43378.tyrone-cluster;dequeuing from idqueue, state COMPLETE
10/03/2014 20:04:56;0040;PBS_Server;Svr;tyrone-cluster;Scheduler was sent the command term
10/03/2014 20:04:56;0008;PBS_Server;Job;43379.tyrone-cluster;Job Modified at request of Scheduler@tyrone-cluster
10/03/2014 20:04:56;0008;PBS_Server;Job;43379.tyrone-cluster;Job Run at request of Scheduler@tyrone-cluster
10/03/2014 20:04:56;0040;PBS_Server;Svr;tyrone-cluster;Scheduler was sent the command recyc
10/03/2014 20:04:56;000d;PBS_Server;Job;43379.tyrone-cluster;Not sending email: User does not want mail of this type.
10/03/2014 20:05:18;0040;PBS_Server;Svr;tyrone-cluster;Scheduler was sent the command new
10/03/2014 20:05:49;0040;PBS_Server;Svr;tyrone-cluster;Scheduler was sent the command new
10/03/2014 20:06:24;0040;PBS_Server;Svr;tyrone-cluster;Scheduler was sent the command new
10/03/2014 20:07:01;0040;PBS_Server;Svr;tyrone-cluster;Scheduler was sent the command new
10/03/2014 20:07:28;0040;PBS_Server;Svr;tyrone-cluster;Scheduler was sent the command new
10/03/2014 20:07:50;0002;PBS_Server;Svr;PBS_Server;Torque Server Version = 3.0.5, loglevel = 0
10/03/2014 20:08:02;0040;PBS_Server;Svr;tyrone-cluster;Scheduler was sent the command new
10/03/2014 20:08:18;000d;PBS_Server;Job;43308.tyrone-cluster;Not sending email: User does not want mail of this type.
10/03/2014 20:08:18;0010;PBS_Server;Job;43308.tyrone-cluster;Exit_status=143 resources_used.cput=669:13:42 resources_used.mem=24038340kb resources_used.vmem=30060964kb resources_used.walltime=24:00:44
10/03/2014 20:08:18;0008;PBS_Server;Job;NULL;on_job_exit valid pjob: 0x2dd4f90 (substate=50)
10/03/2014 20:08:18;0008;PBS_Server;Job;NULL;on_job_exit valid pjob: 0x2dd4f90 (substate=51)
10/03/2014 20:08:27;0008;PBS_Server;Job;NULL;on_job_exit valid pjob: 0x2dd4f90 (substate=51)
10/03/2014 20:08:27;000d;PBS_Server;Job;43308.tyrone-cluster;Post job file processing error; job 43308.tyrone-cluster on host tyrone-node8/31+tyrone-node8/30+tyrone-node8/29+tyrone-node8/28+tyrone-node8/27+tyrone-node8/26+tyrone-node8/25+tyrone-node8/24+tyrone-node8/23+tyrone-node8/22+tyrone-node8/21+tyrone-node8/20+tyrone-node8/19+tyrone-node8/18+tyrone-node8/17+tyrone-node8/16+tyrone-node8/15+tyrone-node8/14+tyrone-node8/13+tyrone-node8/12+tyrone-node8/11+tyrone-node8/10+tyrone-node8/9+tyrone-node8/8+tyrone-node8/7+tyrone-node8/6+tyrone-node8/5+tyrone-node8/4+tyrone-node8/3+tyrone-node8/2+tyrone-node8/1+tyrone-node8/0
10/03/2014 20:08:27;0008;PBS_Server;Job;NULL;on_job_exit valid pjob: 0x2dd4f90 (substate=53)
10/03/2014 20:08:27;0100;PBS_Server;Job;43308.tyrone-cluster;dequeuing from qp32, state COMPLETE
10/03/2014 20:08:27;0040;PBS_Server;Svr;tyrone-cluster;Scheduler was sent the command term
10/03/2014 20:08:27;0100;PBS_Server;Job;43326.tyrone-cluster;dequeuing from batch, state QUEUED
10/03/2014 20:08:27;0100;PBS_Server;Job;43326.tyrone-cluster;enqueuing into qp32, state 1 hop 1
10/03/2014 20:08:27;0008;PBS_Server;Job;43326.tyrone-cluster;Job Modified at request of Scheduler@tyrone-cluster
10/03/2014 20:08:27;0008;PBS_Server;Job;43326.tyrone-cluster;Job Run at request of Scheduler@tyrone-cluster
10/03/2014 20:08:27;0040;PBS_Server;Svr;tyrone-cluster;Scheduler was sent the command recyc
10/03/2014 20:08:27;000d;PBS_Server;Job;43326.tyrone-cluster;Not sending email: User does not want mail of this type.
10/03/2014 20:12:50;0002;PBS_Server;Svr;PBS_Server;Torque Server Version = 3.0.5, loglevel = 0
10/03/2014 20:13:19;0008;PBS_Server;Job;43379.tyrone-cluster;Job deleted at request of asepk@tyrone-cluster
10/03/2014 20:13:19;0008;PBS_Server;Job;43379.tyrone-cluster;Job sent signal SIGTERM on delete
10/03/2014 20:13:19;000d;PBS_Server;Job;43379.tyrone-cluster;Not sending email: User does not want mail of this type.
10/03/2014 20:13:19;0010;PBS_Server;Job;43379.tyrone-cluster;Exit_status=143 resources_used.cput=04:25:39 resources_used.mem=951144kb resources_used.vmem=7369568kb resources_used.walltime=00:08:23
10/03/2014 20:13:19;0008;PBS_Server;Job;NULL;on_job_exit valid pjob: 0x2de5f90 (substate=50)
10/03/2014 20:13:19;0008;PBS_Server;Job;NULL;on_job_exit valid pjob: 0x2de5f90 (substate=51)
10/03/2014 20:13:19;0008;PBS_Server;Job;NULL;on_job_exit valid pjob: 0x2de5f90 (substate=51)
10/03/2014 20:13:19;0008;PBS_Server;Job;NULL;on_job_exit valid pjob: 0x2de5f90 (substate=53)
10/03/2014 20:13:19;0100;PBS_Server;Job;43379.tyrone-cluster;dequeuing from idqueue, state COMPLETE
10/03/2014 20:13:19;0040;PBS_Server;Svr;tyrone-cluster;Scheduler was sent the command term
10/03/2014 20:16:03;0100;PBS_Server;Job;43380.tyrone-cluster;enqueuing into batch, state 1 hop 1
10/03/2014 20:16:03;0008;PBS_Server;Job;43380.tyrone-cluster;Job rejected by all possible destinations (check syntax, queue resources, ...)
10/03/2014 20:16:03;0100;PBS_Server;Job;43380.tyrone-cluster;dequeuing from batch, state QUEUED
10/03/2014 20:16:03;0080;PBS_Server;Req;req_reject;Reject reply code=15041(Job rejected by all possible destinations (check syntax, queue resources, ...)), aux=0, type=Commit, from asepk@tyrone-cluster
10/03/2014 20:16:03;0040;PBS_Server;Svr;tyrone-cluster;Scheduler was sent the command term
10/03/2014 20:17:15;0100;PBS_Server;Job;43381.tyrone-cluster;enqueuing into batch, state 1 hop 1
10/03/2014 20:17:15;0008;PBS_Server;Job;43381.tyrone-cluster;Job rejected by all possible destinations (check syntax, queue resources, ...)
10/03/2014 20:17:15;0100;PBS_Server;Job;43381.tyrone-cluster;dequeuing from batch, state QUEUED
10/03/2014 20:17:15;0080;PBS_Server;Req;req_reject;Reject reply code=15041(Job rejected by all possible destinations (check syntax, queue resources, ...)), aux=0, type=Commit, from asepk@tyrone-cluster
10/03/2014 20:17:15;0040;PBS_Server;Svr;tyrone-cluster;Scheduler was sent the command term
10/03/2014 20:17:38;0100;PBS_Server;Job;43382.tyrone-cluster;enqueuing into batch, state 1 hop 1
10/03/2014 20:17:38;0100;PBS_Server;Job;43382.tyrone-cluster;dequeuing from batch, state QUEUED
10/03/2014 20:17:38;0100;PBS_Server;Job;43382.tyrone-cluster;enqueuing into qp64, state 1 hop 1
10/03/2014 20:17:38;0008;PBS_Server;Job;43382.tyrone-cluster;Job Queued at request of asepk@tyrone-cluster, owner = asepk@tyrone-cluster, job name = AeDNs_4, queue = qp64
10/03/2014 20:17:38;0040;PBS_Server;Svr;tyrone-cluster;Scheduler was sent the command new
10/03/2014 20:17:38;0008;PBS_Server;Job;43382.tyrone-cluster;Job Modified at request of Scheduler@tyrone-cluster
10/03/2014 20:17:38;0008;PBS_Server;Job;43382.tyrone-cluster;Job Run at request of Scheduler@tyrone-cluster
10/03/2014 20:17:38;0040;PBS_Server;Svr;tyrone-cluster;Scheduler was sent the command recyc
10/03/2014 20:17:50;0002;PBS_Server;Svr;PBS_Server;Torque Server Version = 3.0.5, loglevel = 0
10/03/2014 20:17:54;000d;PBS_Server;Job;43382.tyrone-cluster;Not sending email: User does not want mail of this type.
10/03/2014 20:21:06;0100;PBS_Server;Job;43383.tyrone-cluster;enqueuing into batch, state 1 hop 1
10/03/2014 20:21:06;0008;PBS_Server;Job;43383.tyrone-cluster;Job Queued at request of asepk@tyrone-cluster, owner = asepk@tyrone-cluster, job name = AeDNs_4, queue = batch
10/03/2014 20:21:06;0040;PBS_Server;Svr;tyrone-cluster;Scheduler was sent the command new
10/03/2014 20:21:06;0008;PBS_Server;Job;43383.tyrone-cluster;Job Modified at request of Scheduler@tyrone-cluster
10/03/2014 20:21:17;0008;PBS_Server;Job;43382.tyrone-cluster;Job deleted at request of asepk@tyrone-cluster
10/03/2014 20:21:17;0008;PBS_Server;Job;43382.tyrone-cluster;Job sent signal SIGTERM on delete
10/03/2014 20:21:18;000d;PBS_Server;Job;43382.tyrone-cluster;Not sending email: User does not want mail of this type.
10/03/2014 20:21:18;0010;PBS_Server;Job;43382.tyrone-cluster;Exit_status=143 resources_used.cput=01:42:09 resources_used.mem=1359272kb resources_used.vmem=7719252kb resources_used.walltime=00:03:40
10/03/2014 20:21:18;0008;PBS_Server;Job;NULL;on_job_exit valid pjob: 0x2de5f90 (substate=50)
10/03/2014 20:21:18;0008;PBS_Server;Job;NULL;on_job_exit valid pjob: 0x2de5f90 (substate=51)
10/03/2014 20:21:26;0008;PBS_Server;Job;NULL;on_job_exit valid pjob: 0x2de5f90 (substate=51)
10/03/2014 20:21:26;000d;PBS_Server;Job;43382.tyrone-cluster;Post job file processing error; job 43382.tyrone-cluster on host tyrone-node3/31+tyrone-node3/30+tyrone-node3/29+tyrone-node3/28+tyrone-node3/27+tyrone-node3/26+tyrone-node3/25+tyrone-node3/24+tyrone-node3/23+tyrone-node3/22+tyrone-node3/21+tyrone-node3/20+tyrone-node3/19+tyrone-node3/18+tyrone-node3/17+tyrone-node3/16+tyrone-node3/15+tyrone-node3/14+tyrone-node3/13+tyrone-node3/12+tyrone-node3/11+tyrone-node3/10+tyrone-node3/9+tyrone-node3/8+tyrone-node3/7+tyrone-node3/6+tyrone-node3/5+tyrone-node3/4+tyrone-node3/3+tyrone-node3/2+tyrone-node3/1+tyrone-node3/0+tyrone-node2/31+tyrone-node2/30+tyrone-node2/29+tyrone-node2/28+tyrone-node2/27+tyrone-node2/26+tyrone-node2/25+tyrone-node2/24+tyrone-node2/23+tyrone-node2/22+tyrone-node2/21+tyrone-node2/20+tyrone-node2/19+tyrone-node2/18+tyrone-node2/17+tyrone-node2/16+tyrone-node2/15+tyrone-node2/14+tyrone-node2/13+tyrone-node2/12+tyrone-node2/11+tyrone-node2/10+tyrone-node2/9+tyrone-node2/8+tyrone-node2/7+tyrone-node2/6+tyrone-node2/5+tyrone-node2/4+tyrone-node2/3+tyrone-node2/2+tyrone-node2/1+tyrone-node2/0
10/03/2014 20:21:26;0008;PBS_Server;Job;NULL;on_job_exit valid pjob: 0x2de5f90 (substate=53)
10/03/2014 20:21:26;0100;PBS_Server;Job;43382.tyrone-cluster;dequeuing from qp64, state COMPLETE
10/03/2014 20:21:26;0040;PBS_Server;Svr;tyrone-cluster;Scheduler was sent the command term
10/03/2014 20:21:37;0100;PBS_Server;Job;43383.tyrone-cluster;dequeuing from batch, state QUEUED
10/03/2014 20:21:37;0100;PBS_Server;Job;43383.tyrone-cluster;enqueuing into qp64, state 1 hop 1
10/03/2014 20:21:37;0040;PBS_Server;Svr;tyrone-cluster;Scheduler was sent the command new
10/03/2014 20:21:37;0008;PBS_Server;Job;43383.tyrone-cluster;Job Modified at request of Scheduler@tyrone-cluster
10/03/2014 20:21:37;0008;PBS_Server;Job;43383.tyrone-cluster;Job Run at request of Scheduler@tyrone-cluster
10/03/2014 20:21:37;0040;PBS_Server;Svr;tyrone-cluster;Scheduler was sent the command recyc
10/03/2014 20:21:44;0008;PBS_Server;Job;43383.tyrone-cluster;Job deleted at request of asepk@tyrone-cluster
10/03/2014 20:21:44;0008;PBS_Server;Job;43383.tyrone-cluster;Job sent signal SIGTERM on delete
10/03/2014 20:21:44;000d;PBS_Server;Job;43383.tyrone-cluster;Not sending email: User does not want mail of this type.
10/03/2014 20:21:44;0010;PBS_Server;Job;43383.tyrone-cluster;Exit_status=143 resources_used.cput=00:02:07 resources_used.mem=3268kb resources_used.vmem=62840kb resources_used.walltime=00:00:07
10/03/2014 20:21:44;0008;PBS_Server;Job;NULL;on_job_exit valid pjob: 0x2dd4f90 (substate=50)
10/03/2014 20:21:44;0008;PBS_Server;Job;NULL;on_job_exit valid pjob: 0x2dd4f90 (substate=51)
10/03/2014 20:21:53;0008;PBS_Server;Job;NULL;on_job_exit valid pjob: 0x2dd4f90 (substate=51)
10/03/2014 20:21:53;000d;PBS_Server;Job;43383.tyrone-cluster;Post job file processing error; job 43383.tyrone-cluster on host tyrone-node3/31+tyrone-node3/30+tyrone-node3/29+tyrone-node3/28+tyrone-node3/27+tyrone-node3/26+tyrone-node3/25+tyrone-node3/24+tyrone-node3/23+tyrone-node3/22+tyrone-node3/21+tyrone-node3/20+tyrone-node3/19+tyrone-node3/18+tyrone-node3/17+tyrone-node3/16+tyrone-node3/15+tyrone-node3/14+tyrone-node3/13+tyrone-node3/12+tyrone-node3/11+tyrone-node3/10+tyrone-node3/9+tyrone-node3/8+tyrone-node3/7+tyrone-node3/6+tyrone-node3/5+tyrone-node3/4+tyrone-node3/3+tyrone-node3/2+tyrone-node3/1+tyrone-node3/0+tyrone-node2/31+tyrone-node2/30+tyrone-node2/29+tyrone-node2/28+tyrone-node2/27+tyrone-node2/26+tyrone-node2/25+tyrone-node2/24+tyrone-node2/23+tyrone-node2/22+tyrone-node2/21+tyrone-node2/20+tyrone-node2/19+tyrone-node2/18+tyrone-node2/17+tyrone-node2/16+tyrone-node2/15+tyrone-node2/14+tyrone-node2/13+tyrone-node2/12+tyrone-node2/11+tyrone-node2/10+tyrone-node2/9+tyrone-node2/8+tyrone-node2/7+tyrone-node2/6+tyrone-node2/5+tyrone-node2/4+tyrone-node2/3+tyrone-node2/2+tyrone-node2/1+tyrone-node2/0
10/03/2014 20:21:53;0008;PBS_Server;Job;NULL;on_job_exit valid pjob: 0x2dd4f90 (substate=53)
10/03/2014 20:21:53;0100;PBS_Server;Job;43383.tyrone-cluster;dequeuing from qp64, state COMPLETE
10/03/2014 20:21:53;0040;PBS_Server;Svr;tyrone-cluster;Scheduler was sent the command term
10/03/2014 20:22:10;0100;PBS_Server;Job;43384.tyrone-cluster;enqueuing into batch, state 1 hop 1
10/03/2014 20:22:10;0100;PBS_Server;Job;43384.tyrone-cluster;dequeuing from batch, state QUEUED
10/03/2014 20:22:10;0100;PBS_Server;Job;43384.tyrone-cluster;enqueuing into qp64, state 1 hop 1
10/03/2014 20:22:10;0008;PBS_Server;Job;43384.tyrone-cluster;Job Queued at request of asepk@tyrone-cluster, owner = asepk@tyrone-cluster, job name = AeDNs_4, queue = qp64
10/03/2014 20:22:10;0040;PBS_Server;Svr;tyrone-cluster;Scheduler was sent the command new
10/03/2014 20:22:10;0008;PBS_Server;Job;43384.tyrone-cluster;Job Modified at request of Scheduler@tyrone-cluster
10/03/2014 20:22:10;0008;PBS_Server;Job;43384.tyrone-cluster;Job Run at request of Scheduler@tyrone-cluster
10/03/2014 20:22:10;0040;PBS_Server;Svr;tyrone-cluster;Scheduler was sent the command recyc
10/03/2014 20:22:28;000d;PBS_Server;Job;43384.tyrone-cluster;Not sending email: User does not want mail of this type.
10/03/2014 20:22:50;0002;PBS_Server;Svr;PBS_Server;Torque Server Version = 3.0.5, loglevel = 0
10/03/2014 20:24:58;0008;PBS_Server;Job;43384.tyrone-cluster;Job deleted at request of asepk@tyrone-cluster
10/03/2014 20:24:58;0008;PBS_Server;Job;43384.tyrone-cluster;Job sent signal SIGTERM on delete
10/03/2014 20:24:59;000d;PBS_Server;Job;43384.tyrone-cluster;Not sending email: User does not want mail of this type.
10/03/2014 20:24:59;0010;PBS_Server;Job;43384.tyrone-cluster;Exit_status=143 resources_used.cput=01:18:37 resources_used.mem=1357480kb resources_used.vmem=7718340kb resources_used.walltime=00:02:49
10/03/2014 20:24:59;0008;PBS_Server;Job;NULL;on_job_exit valid pjob: 0x2de5f90 (substate=50)
10/03/2014 20:24:59;0008;PBS_Server;Job;NULL;on_job_exit valid pjob: 0x2de5f90 (substate=51)
10/03/2014 20:25:07;0008;PBS_Server;Job;NULL;on_job_exit valid pjob: 0x2de5f90 (substate=51)
10/03/2014 20:25:07;000d;PBS_Server;Job;43384.tyrone-cluster;Post job file processing error; job 43384.tyrone-cluster on host tyrone-node3/31+tyrone-node3/30+tyrone-node3/29+tyrone-node3/28+tyrone-node3/27+tyrone-node3/26+tyrone-node3/25+tyrone-node3/24+tyrone-node3/23+tyrone-node3/22+tyrone-node3/21+tyrone-node3/20+tyrone-node3/19+tyrone-node3/18+tyrone-node3/17+tyrone-node3/16+tyrone-node3/15+tyrone-node3/14+tyrone-node3/13+tyrone-node3/12+tyrone-node3/11+tyrone-node3/10+tyrone-node3/9+tyrone-node3/8+tyrone-node3/7+tyrone-node3/6+tyrone-node3/5+tyrone-node3/4+tyrone-node3/3+tyrone-node3/2+tyrone-node3/1+tyrone-node3/0+tyrone-node2/31+tyrone-node2/30+tyrone-node2/29+tyrone-node2/28+tyrone-node2/27+tyrone-node2/26+tyrone-node2/25+tyrone-node2/24+tyrone-node2/23+tyrone-node2/22+tyrone-node2/21+tyrone-node2/20+tyrone-node2/19+tyrone-node2/18+tyrone-node2/17+tyrone-node2/16+tyrone-node2/15+tyrone-node2/14+tyrone-node2/13+tyrone-node2/12+tyrone-node2/11+tyrone-node2/10+tyrone-node2/9+tyrone-node2/8+tyrone-node2/7+tyrone-node2/6+tyrone-node2/5+tyrone-node2/4+tyrone-node2/3+tyrone-node2/2+tyrone-node2/1+tyrone-node2/0
10/03/2014 20:25:07;0008;PBS_Server;Job;NULL;on_job_exit valid pjob: 0x2de5f90 (substate=53)
10/03/2014 20:25:07;0100;PBS_Server;Job;43384.tyrone-cluster;dequeuing from qp64, state COMPLETE
10/03/2014 20:25:07;0040;PBS_Server;Svr;tyrone-cluster;Scheduler was sent the command term
10/03/2014 20:25:36;0100;PBS_Server;Job;43385.tyrone-cluster;enqueuing into batch, state 1 hop 1
10/03/2014 20:25:36;0100;PBS_Server;Job;43385.tyrone-cluster;dequeuing from batch, state QUEUED
10/03/2014 20:25:36;0100;PBS_Server;Job;43385.tyrone-cluster;enqueuing into idqueue, state 1 hop 1
10/03/2014 20:25:36;0008;PBS_Server;Job;43385.tyrone-cluster;Job Queued at request of asepk@tyrone-cluster, owner = asepk@tyrone-cluster, job name = AeDNs_4, queue = idqueue
10/03/2014 20:25:36;0040;PBS_Server;Svr;tyrone-cluster;Scheduler was sent the command new
10/03/2014 20:25:36;0008;PBS_Server;Job;43385.tyrone-cluster;Job Modified at request of Scheduler@tyrone-cluster
10/03/2014 20:25:36;0008;PBS_Server;Job;43385.tyrone-cluster;Job Run at request of Scheduler@tyrone-cluster
10/03/2014 20:25:36;0040;PBS_Server;Svr;tyrone-cluster;Scheduler was sent the command recyc
10/03/2014 20:25:36;000d;PBS_Server;Job;43385.tyrone-cluster;Not sending email: User does not want mail of this type.
10/03/2014 20:25:37;000d;PBS_Server;Job;43385.tyrone-cluster;Not sending email: User does not want mail of this type.
10/03/2014 20:25:37;0010;PBS_Server;Job;43385.tyrone-cluster;Exit_status=0 resources_used.cput=00:00:13 resources_used.mem=0kb resources_used.vmem=0kb resources_used.walltime=00:00:01
10/03/2014 20:25:37;0008;PBS_Server;Job;NULL;on_job_exit valid pjob: 0x2dd4f90 (substate=50)
10/03/2014 20:25:37;0008;PBS_Server;Job;NULL;on_job_exit valid pjob: 0x2dd4f90 (substate=51)
10/03/2014 20:25:37;0008;PBS_Server;Job;NULL;on_job_exit valid pjob: 0x2dd4f90 (substate=51)
10/03/2014 20:25:37;0008;PBS_Server;Job;NULL;on_job_exit valid pjob: 0x2dd4f90 (substate=53)
10/03/2014 20:25:37;0100;PBS_Server;Job;43385.tyrone-cluster;dequeuing from idqueue, state COMPLETE
10/03/2014 20:25:37;0040;PBS_Server;Svr;tyrone-cluster;Scheduler was sent the command term
10/03/2014 20:27:17;0100;PBS_Server;Job;43386.tyrone-cluster;enqueuing into batch, state 1 hop 1
10/03/2014 20:27:17;0100;PBS_Server;Job;43386.tyrone-cluster;dequeuing from batch, state QUEUED
10/03/2014 20:27:17;0100;PBS_Server;Job;43386.tyrone-cluster;enqueuing into idqueue, state 1 hop 1
10/03/2014 20:27:17;0008;PBS_Server;Job;43386.tyrone-cluster;Job Queued at request of asepk@tyrone-cluster, owner = asepk@tyrone-cluster, job name = AeDNs_4, queue = idqueue
10/03/2014 20:27:17;0040;PBS_Server;Svr;tyrone-cluster;Scheduler was sent the command new
10/03/2014 20:27:18;0008;PBS_Server;Job;43386.tyrone-cluster;Job Modified at request of Scheduler@tyrone-cluster
10/03/2014 20:27:18;0008;PBS_Server;Job;43386.tyrone-cluster;Job Run at request of Scheduler@tyrone-cluster
10/03/2014 20:27:18;0040;PBS_Server;Svr;tyrone-cluster;Scheduler was sent the command recyc
10/03/2014 20:27:18;000d;PBS_Server;Job;43386.tyrone-cluster;Not sending email: User does not want mail of this type.
10/03/2014 20:27:50;0002;PBS_Server;Svr;PBS_Server;Torque Server Version = 3.0.5, loglevel = 0
10/03/2014 20:32:50;0002;PBS_Server;Svr;PBS_Server;Torque Server Version = 3.0.5, loglevel = 0
10/03/2014 20:34:12;0008;PBS_Server;Job;43386.tyrone-cluster;Job deleted at request of asepk@tyrone-cluster
10/03/2014 20:34:12;0008;PBS_Server;Job;43386.tyrone-cluster;Job sent signal SIGTERM on delete
10/03/2014 20:34:12;000d;PBS_Server;Job;43386.tyrone-cluster;Not sending email: User does not want mail of this type.
10/03/2014 20:34:12;0010;PBS_Server;Job;43386.tyrone-cluster;Exit_status=143 resources_used.cput=03:38:20 resources_used.mem=948436kb resources_used.vmem=7364704kb resources_used.walltime=00:06:54
10/03/2014 20:34:12;0008;PBS_Server;Job;NULL;on_job_exit valid pjob: 0x2e9af40 (substate=50)
10/03/2014 20:34:12;0008;PBS_Server;Job;NULL;on_job_exit valid pjob: 0x2e9af40 (substate=51)
10/03/2014 20:34:12;0008;PBS_Server;Job;NULL;on_job_exit valid pjob: 0x2e9af40 (substate=51)
10/03/2014 20:34:12;0008;PBS_Server;Job;NULL;on_job_exit valid pjob: 0x2e9af40 (substate=53)
10/03/2014 20:34:12;0100;PBS_Server;Job;43386.tyrone-cluster;dequeuing from idqueue, state COMPLETE
10/03/2014 20:34:12;0040;PBS_Server;Svr;tyrone-cluster;Scheduler was sent the command term
10/03/2014 20:35:10;0100;PBS_Server;Job;43387.tyrone-cluster;enqueuing into batch, state 1 hop 1
10/03/2014 20:35:10;0100;PBS_Server;Job;43387.tyrone-cluster;dequeuing from batch, state QUEUED
10/03/2014 20:35:10;0100;PBS_Server;Job;43387.tyrone-cluster;enqueuing into idqueue, state 1 hop 1
10/03/2014 20:35:10;0008;PBS_Server;Job;43387.tyrone-cluster;Job Queued at request of asepk@tyrone-cluster, owner = asepk@tyrone-cluster, job name = AeDNs_4, queue = idqueue
10/03/2014 20:35:10;0040;PBS_Server;Svr;tyrone-cluster;Scheduler was sent the command new
10/03/2014 20:35:10;0008;PBS_Server;Job;43387.tyrone-cluster;Job Modified at request of Scheduler@tyrone-cluster
10/03/2014 20:35:10;0008;PBS_Server;Job;43387.tyrone-cluster;Job Run at request of Scheduler@tyrone-cluster
10/03/2014 20:35:10;0040;PBS_Server;Svr;tyrone-cluster;Scheduler was sent the command recyc
10/03/2014 20:35:10;000d;PBS_Server;Job;43387.tyrone-cluster;Not sending email: User does not want mail of this type.
10/03/2014 20:37:50;0002;PBS_Server;Svr;PBS_Server;Torque Server Version = 3.0.5, loglevel = 0
10/03/2014 20:37:52;0100;PBS_Server;Job;43388.tyrone-cluster;enqueuing into batch, state 1 hop 1
10/03/2014 20:37:52;0100;PBS_Server;Job;43388.tyrone-cluster;dequeuing from batch, state QUEUED
10/03/2014 20:37:52;0100;PBS_Server;Job;43388.tyrone-cluster;enqueuing into idqueue, state 1 hop 1
10/03/2014 20:37:52;0008;PBS_Server;Job;43388.tyrone-cluster;Job Queued at request of asepk@tyrone-cluster, owner = asepk@tyrone-cluster, job name = AeDNs_4, queue = idqueue
10/03/2014 20:37:52;0040;PBS_Server;Svr;tyrone-cluster;Scheduler was sent the command new
10/03/2014 20:37:52;0008;PBS_Server;Job;43388.tyrone-cluster;Job Modified at request of Scheduler@tyrone-cluster
10/03/2014 20:38:00;0008;PBS_Server;Job;43387.tyrone-cluster;Job deleted at request of asepk@tyrone-cluster
10/03/2014 20:38:00;0008;PBS_Server;Job;43387.tyrone-cluster;Job sent signal SIGTERM on delete
10/03/2014 20:38:01;000d;PBS_Server;Job;43387.tyrone-cluster;Not sending email: User does not want mail of this type.
10/03/2014 20:38:01;0010;PBS_Server;Job;43387.tyrone-cluster;Exit_status=143 resources_used.cput=01:10:21 resources_used.mem=749932kb resources_used.vmem=7364308kb resources_used.walltime=00:02:51
10/03/2014 20:38:01;0008;PBS_Server;Job;NULL;on_job_exit valid pjob: 0x2dd4f90 (substate=50)
10/03/2014 20:38:01;0008;PBS_Server;Job;NULL;on_job_exit valid pjob: 0x2dd4f90 (substate=51)
10/03/2014 20:38:01;0008;PBS_Server;Job;NULL;on_job_exit valid pjob: 0x2dd4f90 (substate=51)
10/03/2014 20:38:01;0008;PBS_Server;Job;NULL;on_job_exit valid pjob: 0x2dd4f90 (substate=53)
10/03/2014 20:38:01;0100;PBS_Server;Job;43387.tyrone-cluster;dequeuing from idqueue, state COMPLETE
10/03/2014 20:38:01;0040;PBS_Server;Svr;tyrone-cluster;Scheduler was sent the command term
10/03/2014 20:38:01;0008;PBS_Server;Job;43388.tyrone-cluster;Job Modified at request of Scheduler@tyrone-cluster
10/03/2014 20:38:01;0008;PBS_Server;Job;43388.tyrone-cluster;Job Run at request of Scheduler@tyrone-cluster
10/03/2014 20:38:01;0040;PBS_Server;Svr;tyrone-cluster;Scheduler was sent the command recyc
10/03/2014 20:38:01;000d;PBS_Server;Job;43388.tyrone-cluster;Not sending email: User does not want mail of this type.
10/03/2014 20:40:45;0100;PBS_Server;Job;43389.tyrone-cluster;enqueuing into batch, state 1 hop 1
10/03/2014 20:40:45;0100;PBS_Server;Job;43389.tyrone-cluster;dequeuing from batch, state QUEUED
10/03/2014 20:40:45;0100;PBS_Server;Job;43389.tyrone-cluster;enqueuing into idqueue, state 1 hop 1
10/03/2014 20:40:45;0008;PBS_Server;Job;43389.tyrone-cluster;Job Queued at request of asepk@tyrone-cluster, owner = asepk@tyrone-cluster, job name = AeDNs_4, queue = idqueue
10/03/2014 20:40:45;0040;PBS_Server;Svr;tyrone-cluster;Scheduler was sent the command new
10/03/2014 20:40:45;0008;PBS_Server;Job;43389.tyrone-cluster;Job Modified at request of Scheduler@tyrone-cluster
10/03/2014 20:40:56;0008;PBS_Server;Job;43388.tyrone-cluster;Job deleted at request of asepk@tyrone-cluster
10/03/2014 20:40:56;0008;PBS_Server;Job;43388.tyrone-cluster;Job sent signal SIGTERM on delete
10/03/2014 20:40:57;000d;PBS_Server;Job;43388.tyrone-cluster;Not sending email: User does not want mail of this type.
10/03/2014 20:40:57;0010;PBS_Server;Job;43388.tyrone-cluster;Exit_status=143 resources_used.cput=01:32:30 resources_used.mem=754996kb resources_used.vmem=7364308kb resources_used.walltime=00:02:56
10/03/2014 20:40:57;0008;PBS_Server;Job;NULL;on_job_exit valid pjob: 0x2cd6fe0 (substate=50)
10/03/2014 20:40:57;0008;PBS_Server;Job;NULL;on_job_exit valid pjob: 0x2cd6fe0 (substate=51)
10/03/2014 20:40:57;0008;PBS_Server;Job;NULL;on_job_exit valid pjob: 0x2cd6fe0 (substate=51)
10/03/2014 20:40:57;0008;PBS_Server;Job;NULL;on_job_exit valid pjob: 0x2cd6fe0 (substate=53)
10/03/2014 20:40:57;0100;PBS_Server;Job;43388.tyrone-cluster;dequeuing from idqueue, state COMPLETE
10/03/2014 20:40:57;0040;PBS_Server;Svr;tyrone-cluster;Scheduler was sent the command term
10/03/2014 20:40:57;0008;PBS_Server;Job;43389.tyrone-cluster;Job Modified at request of Scheduler@tyrone-cluster
10/03/2014 20:40:57;0008;PBS_Server;Job;43389.tyrone-cluster;Job Run at request of Scheduler@tyrone-cluster
10/03/2014 20:40:57;0040;PBS_Server;Svr;tyrone-cluster;Scheduler was sent the command recyc
10/03/2014 20:40:57;000d;PBS_Server;Job;43389.tyrone-cluster;Not sending email: User does not want mail of this type.
10/03/2014 20:41:50;0008;PBS_Server;Job;43389.tyrone-cluster;Job deleted at request of asepk@tyrone-cluster
10/03/2014 20:41:50;0008;PBS_Server;Job;43389.tyrone-cluster;Job sent signal SIGTERM on delete
10/03/2014 20:41:50;000d;PBS_Server;Job;43389.tyrone-cluster;Not sending email: User does not want mail of this type.
10/03/2014 20:41:50;0010;PBS_Server;Job;43389.tyrone-cluster;Exit_status=143 resources_used.cput=00:05:49 resources_used.mem=719984kb resources_used.vmem=7364308kb resources_used.walltime=00:00:53
10/03/2014 20:41:50;0008;PBS_Server;Job;NULL;on_job_exit valid pjob: 0x2dbe110 (substate=50)
10/03/2014 20:41:50;0008;PBS_Server;Job;NULL;on_job_exit valid pjob: 0x2dbe110 (substate=51)
10/03/2014 20:41:50;0008;PBS_Server;Job;NULL;on_job_exit valid pjob: 0x2dbe110 (substate=51)
10/03/2014 20:41:50;0008;PBS_Server;Job;NULL;on_job_exit valid pjob: 0x2dbe110 (substate=53)
10/03/2014 20:41:50;0100;PBS_Server;Job;43389.tyrone-cluster;dequeuing from idqueue, state COMPLETE
10/03/2014 20:41:50;0040;PBS_Server;Svr;tyrone-cluster;Scheduler was sent the command term
10/03/2014 20:42:50;0002;PBS_Server;Svr;PBS_Server;Torque Server Version = 3.0.5, loglevel = 0
10/03/2014 20:44:27;0100;PBS_Server;Job;43390.tyrone-cluster;enqueuing into batch, state 1 hop 1
10/03/2014 20:44:27;0100;PBS_Server;Job;43390.tyrone-cluster;dequeuing from batch, state QUEUED
10/03/2014 20:44:27;0100;PBS_Server;Job;43390.tyrone-cluster;enqueuing into idqueue, state 1 hop 1
10/03/2014 20:44:27;0008;PBS_Server;Job;43390.tyrone-cluster;Job Queued at request of asepk@tyrone-cluster, owner = asepk@tyrone-cluster, job name = AeDNs_4, queue = idqueue
10/03/2014 20:44:27;0040;PBS_Server;Svr;tyrone-cluster;Scheduler was sent the command new
10/03/2014 20:44:27;0008;PBS_Server;Job;43390.tyrone-cluster;Job Modified at request of Scheduler@tyrone-cluster
10/03/2014 20:44:27;0008;PBS_Server;Job;43390.tyrone-cluster;Job Run at request of Scheduler@tyrone-cluster
10/03/2014 20:44:27;0040;PBS_Server;Svr;tyrone-cluster;Scheduler was sent the command recyc
10/03/2014 20:44:27;000d;PBS_Server;Job;43390.tyrone-cluster;Not sending email: User does not want mail of this type.
10/03/2014 20:45:00;0008;PBS_Server;Job;43390.tyrone-cluster;Job deleted at request of asepk@tyrone-cluster
10/03/2014 20:45:00;0008;PBS_Server;Job;43390.tyrone-cluster;Job sent signal SIGTERM on delete
10/03/2014 20:45:01;000d;PBS_Server;Job;43390.tyrone-cluster;Not sending email: User does not want mail of this type.
10/03/2014 20:45:01;0010;PBS_Server;Job;43390.tyrone-cluster;Exit_status=143 resources_used.cput=00:17:36 resources_used.mem=727448kb resources_used.vmem=7364308kb resources_used.walltime=00:00:34
10/03/2014 20:45:01;0008;PBS_Server;Job;NULL;on_job_exit valid pjob: 0x2e9af40 (substate=50)
10/03/2014 20:45:01;0008;PBS_Server;Job;NULL;on_job_exit valid pjob: 0x2e9af40 (substate=51)
10/03/2014 20:45:01;0008;PBS_Server;Job;NULL;on_job_exit valid pjob: 0x2e9af40 (substate=51)
10/03/2014 20:45:01;0008;PBS_Server;Job;NULL;on_job_exit valid pjob: 0x2e9af40 (substate=53)
10/03/2014 20:45:01;0100;PBS_Server;Job;43390.tyrone-cluster;dequeuing from idqueue, state COMPLETE
10/03/2014 20:45:01;0040;PBS_Server;Svr;tyrone-cluster;Scheduler was sent the command term
10/03/2014 20:47:33;0100;PBS_Server;Job;43391.tyrone-cluster;enqueuing into batch, state 1 hop 1
10/03/2014 20:47:33;0100;PBS_Server;Job;43391.tyrone-cluster;dequeuing from batch, state QUEUED
10/03/2014 20:47:33;0100;PBS_Server;Job;43391.tyrone-cluster;enqueuing into idqueue, state 1 hop 1
10/03/2014 20:47:33;0008;PBS_Server;Job;43391.tyrone-cluster;Job Queued at request of asepk@tyrone-cluster, owner = asepk@tyrone-cluster, job name = AeDNs_4, queue = idqueue
10/03/2014 20:47:33;0040;PBS_Server;Svr;tyrone-cluster;Scheduler was sent the command new
10/03/2014 20:47:33;0008;PBS_Server;Job;43391.tyrone-cluster;Job Modified at request of Scheduler@tyrone-cluster
10/03/2014 20:47:33;0008;PBS_Server;Job;43391.tyrone-cluster;Job Run at request of Scheduler@tyrone-cluster
10/03/2014 20:47:33;0040;PBS_Server;Svr;tyrone-cluster;Scheduler was sent the command recyc
10/03/2014 20:47:33;000d;PBS_Server;Job;43391.tyrone-cluster;Not sending email: User does not want mail of this type.
10/03/2014 20:47:50;0002;PBS_Server;Svr;PBS_Server;Torque Server Version = 3.0.5, loglevel = 0
10/03/2014 20:51:50;0100;PBS_Server;Job;43392.tyrone-cluster;enqueuing into batch, state 1 hop 1
10/03/2014 20:51:50;0100;PBS_Server;Job;43392.tyrone-cluster;dequeuing from batch, state QUEUED
10/03/2014 20:51:50;0100;PBS_Server;Job;43392.tyrone-cluster;enqueuing into idqueue, state 1 hop 1
10/03/2014 20:51:50;0008;PBS_Server;Job;43392.tyrone-cluster;Job Queued at request of asepk@tyrone-cluster, owner = asepk@tyrone-cluster, job name = AeDNs_4, queue = idqueue
10/03/2014 20:51:50;0040;PBS_Server;Svr;tyrone-cluster;Scheduler was sent the command new
10/03/2014 20:51:50;0008;PBS_Server;Job;43392.tyrone-cluster;Job Modified at request of Scheduler@tyrone-cluster
10/03/2014 20:52:00;0008;PBS_Server;Job;43391.tyrone-cluster;Job deleted at request of asepk@tyrone-cluster
10/03/2014 20:52:00;0008;PBS_Server;Job;43391.tyrone-cluster;Job sent signal SIGTERM on delete
10/03/2014 20:52:00;000d;PBS_Server;Job;43391.tyrone-cluster;Not sending email: User does not want mail of this type.
10/03/2014 20:52:00;0010;PBS_Server;Job;43391.tyrone-cluster;Exit_status=143 resources_used.cput=02:20:46 resources_used.mem=925852kb resources_used.vmem=7364712kb resources_used.walltime=00:04:27
10/03/2014 20:52:00;0008;PBS_Server;Job;NULL;on_job_exit valid pjob: 0x2dbe110 (substate=50)
10/03/2014 20:52:00;0008;PBS_Server;Job;NULL;on_job_exit valid pjob: 0x2dbe110 (substate=51)
10/03/2014 20:52:00;0008;PBS_Server;Job;NULL;on_job_exit valid pjob: 0x2dbe110 (substate=51)
10/03/2014 20:52:00;0008;PBS_Server;Job;NULL;on_job_exit valid pjob: 0x2dbe110 (substate=53)
10/03/2014 20:52:00;0100;PBS_Server;Job;43391.tyrone-cluster;dequeuing from idqueue, state COMPLETE
10/03/2014 20:52:00;0040;PBS_Server;Svr;tyrone-cluster;Scheduler was sent the command term
10/03/2014 20:52:00;0008;PBS_Server;Job;43392.tyrone-cluster;Job Modified at request of Scheduler@tyrone-cluster
10/03/2014 20:52:00;0008;PBS_Server;Job;43392.tyrone-cluster;Job Run at request of Scheduler@tyrone-cluster
10/03/2014 20:52:00;0040;PBS_Server;Svr;tyrone-cluster;Scheduler was sent the command recyc
10/03/2014 20:52:00;000d;PBS_Server;Job;43392.tyrone-cluster;Not sending email: User does not want mail of this type.
10/03/2014 20:52:50;0002;PBS_Server;Svr;PBS_Server;Torque Server Version = 3.0.5, loglevel = 0
10/03/2014 20:54:14;0008;PBS_Server;Job;43392.tyrone-cluster;Job deleted at request of asepk@tyrone-cluster
10/03/2014 20:54:14;0008;PBS_Server;Job;43392.tyrone-cluster;Job sent signal SIGTERM on delete
10/03/2014 20:54:14;000d;PBS_Server;Job;43392.tyrone-cluster;Not sending email: User does not want mail of this type.
10/03/2014 20:54:14;0010;PBS_Server;Job;43392.tyrone-cluster;Exit_status=143 resources_used.cput=01:09:56 resources_used.mem=746204kb resources_used.vmem=7364308kb resources_used.walltime=00:02:14
10/03/2014 20:54:14;0008;PBS_Server;Job;NULL;on_job_exit valid pjob: 0x2cd6fe0 (substate=50)
10/03/2014 20:54:14;0008;PBS_Server;Job;NULL;on_job_exit valid pjob: 0x2cd6fe0 (substate=51)
10/03/2014 20:54:14;0008;PBS_Server;Job;NULL;on_job_exit valid pjob: 0x2cd6fe0 (substate=51)
10/03/2014 20:54:14;0008;PBS_Server;Job;NULL;on_job_exit valid pjob: 0x2cd6fe0 (substate=53)
10/03/2014 20:54:14;0100;PBS_Server;Job;43392.tyrone-cluster;dequeuing from idqueue, state COMPLETE
10/03/2014 20:54:14;0040;PBS_Server;Svr;tyrone-cluster;Scheduler was sent the command term
10/03/2014 20:57:50;0002;PBS_Server;Svr;PBS_Server;Torque Server Version = 3.0.5, loglevel = 0
10/03/2014 21:02:50;0002;PBS_Server;Svr;PBS_Server;Torque Server Version = 3.0.5, loglevel = 0
10/03/2014 21:04:14;0040;PBS_Server;Svr;tyrone-cluster;Scheduler was sent the command time
10/03/2014 21:07:50;0002;PBS_Server;Svr;PBS_Server;Torque Server Version = 3.0.5, loglevel = 0
10/03/2014 21:12:50;0002;PBS_Server;Svr;PBS_Server;Torque Server Version = 3.0.5, loglevel = 0
10/03/2014 21:14:14;0040;PBS_Server;Svr;tyrone-cluster;Scheduler was sent the command time
10/03/2014 21:17:50;0002;PBS_Server;Svr;PBS_Server;Torque Server Version = 3.0.5, loglevel = 0
10/03/2014 21:22:50;0002;PBS_Server;Svr;PBS_Server;Torque Server Version = 3.0.5, loglevel = 0
10/03/2014 21:24:14;0040;PBS_Server;Svr;tyrone-cluster;Scheduler was sent the command time
10/03/2014 21:27:50;0002;PBS_Server;Svr;PBS_Server;Torque Server Version = 3.0.5, loglevel = 0
10/03/2014 21:32:50;0002;PBS_Server;Svr;PBS_Server;Torque Server Version = 3.0.5, loglevel = 0
10/03/2014 21:34:14;0040;PBS_Server;Svr;tyrone-cluster;Scheduler was sent the command time
10/03/2014 21:37:50;0002;PBS_Server;Svr;PBS_Server;Torque Server Version = 3.0.5, loglevel = 0
10/03/2014 21:42:50;0002;PBS_Server;Svr;PBS_Server;Torque Server Version = 3.0.5, loglevel = 0
10/03/2014 21:44:14;0040;PBS_Server;Svr;tyrone-cluster;Scheduler was sent the command time
10/03/2014 21:47:50;0002;PBS_Server;Svr;PBS_Server;Torque Server Version = 3.0.5, loglevel = 0
10/03/2014 21:52:50;0002;PBS_Server;Svr;PBS_Server;Torque Server Version = 3.0.5, loglevel = 0
10/03/2014 21:54:14;0040;PBS_Server;Svr;tyrone-cluster;Scheduler was sent the command time
10/03/2014 21:57:50;0002;PBS_Server;Svr;PBS_Server;Torque Server Version = 3.0.5, loglevel = 0
10/03/2014 22:02:50;0002;PBS_Server;Svr;PBS_Server;Torque Server Version = 3.0.5, loglevel = 0
10/03/2014 22:04:14;0040;PBS_Server;Svr;tyrone-cluster;Scheduler was sent the command time
10/03/2014 22:07:50;0002;PBS_Server;Svr;PBS_Server;Torque Server Version = 3.0.5, loglevel = 0
10/03/2014 22:12:50;0002;PBS_Server;Svr;PBS_Server;Torque Server Version = 3.0.5, loglevel = 0
10/03/2014 22:14:14;0040;PBS_Server;Svr;tyrone-cluster;Scheduler was sent the command time
10/03/2014 22:17:50;0002;PBS_Server;Svr;PBS_Server;Torque Server Version = 3.0.5, loglevel = 0
10/03/2014 22:22:50;0002;PBS_Server;Svr;PBS_Server;Torque Server Version = 3.0.5, loglevel = 0
10/03/2014 22:24:14;0040;PBS_Server;Svr;tyrone-cluster;Scheduler was sent the command time
10/03/2014 22:27:50;0002;PBS_Server;Svr;PBS_Server;Torque Server Version = 3.0.5, loglevel = 0
10/03/2014 22:32:50;0002;PBS_Server;Svr;PBS_Server;Torque Server Version = 3.0.5, loglevel = 0
10/03/2014 22:34:14;0040;PBS_Server;Svr;tyrone-cluster;Scheduler was sent the command time
10/03/2014 22:37:50;0002;PBS_Server;Svr;PBS_Server;Torque Server Version = 3.0.5, loglevel = 0
10/03/2014 22:42:50;0002;PBS_Server;Svr;PBS_Server;Torque Server Version = 3.0.5, loglevel = 0
10/03/2014 22:44:14;0040;PBS_Server;Svr;tyrone-cluster;Scheduler was sent the command time
10/03/2014 22:47:50;0002;PBS_Server;Svr;PBS_Server;Torque Server Version = 3.0.5, loglevel = 0
10/03/2014 22:52:50;0002;PBS_Server;Svr;PBS_Server;Torque Server Version = 3.0.5, loglevel = 0
10/03/2014 22:54:14;0040;PBS_Server;Svr;tyrone-cluster;Scheduler was sent the command time
10/03/2014 22:57:50;0002;PBS_Server;Svr;PBS_Server;Torque Server Version = 3.0.5, loglevel = 0
10/03/2014 23:02:50;0002;PBS_Server;Svr;PBS_Server;Torque Server Version = 3.0.5, loglevel = 0
10/03/2014 23:04:14;0040;PBS_Server;Svr;tyrone-cluster;Scheduler was sent the command time
10/03/2014 23:07:50;0002;PBS_Server;Svr;PBS_Server;Torque Server Version = 3.0.5, loglevel = 0
10/03/2014 23:12:50;0002;PBS_Server;Svr;PBS_Server;Torque Server Version = 3.0.5, loglevel = 0
10/03/2014 23:14:14;0040;PBS_Server;Svr;tyrone-cluster;Scheduler was sent the command time
10/03/2014 23:17:50;0002;PBS_Server;Svr;PBS_Server;Torque Server Version = 3.0.5, loglevel = 0
10/03/2014 23:22:50;0002;PBS_Server;Svr;PBS_Server;Torque Server Version = 3.0.5, loglevel = 0
10/03/2014 23:24:14;0040;PBS_Server;Svr;tyrone-cluster;Scheduler was sent the command time
10/03/2014 23:27:50;0002;PBS_Server;Svr;PBS_Server;Torque Server Version = 3.0.5, loglevel = 0
10/03/2014 23:32:50;0002;PBS_Server;Svr;PBS_Server;Torque Server Version = 3.0.5, loglevel = 0
10/03/2014 23:34:14;0040;PBS_Server;Svr;tyrone-cluster;Scheduler was sent the command time
10/03/2014 23:37:50;0002;PBS_Server;Svr;PBS_Server;Torque Server Version = 3.0.5, loglevel = 0
10/03/2014 23:42:50;0002;PBS_Server;Svr;PBS_Server;Torque Server Version = 3.0.5, loglevel = 0
10/03/2014 23:44:14;0040;PBS_Server;Svr;tyrone-cluster;Scheduler was sent the command time
10/03/2014 23:47:50;0002;PBS_Server;Svr;PBS_Server;Torque Server Version = 3.0.5, loglevel = 0
10/03/2014 23:52:50;0002;PBS_Server;Svr;PBS_Server;Torque Server Version = 3.0.5, loglevel = 0
10/03/2014 23:54:14;0040;PBS_Server;Svr;tyrone-cluster;Scheduler was sent the command time
10/03/2014 23:57:50;0002;PBS_Server;Svr;PBS_Server;Torque Server Version = 3.0.5, loglevel = 0
10/04/2014 00:02:50;0002;PBS_Server;Svr;Log;Log closed
