07/25/2014 00:00:19;0002;PBS_Server;Svr;Log;Log opened
07/25/2014 00:00:19;0002;PBS_Server;Svr;PBS_Server;Torque Server Version = 3.0.5, loglevel = 0
07/25/2014 00:05:19;0002;PBS_Server;Svr;PBS_Server;Torque Server Version = 3.0.5, loglevel = 0
07/25/2014 00:07:24;0040;PBS_Server;Svr;tyrone-cluster;Scheduler was sent the command time
07/25/2014 00:10:19;0002;PBS_Server;Svr;PBS_Server;Torque Server Version = 3.0.5, loglevel = 0
07/25/2014 00:15:19;0002;PBS_Server;Svr;PBS_Server;Torque Server Version = 3.0.5, loglevel = 0
07/25/2014 00:17:24;0040;PBS_Server;Svr;tyrone-cluster;Scheduler was sent the command time
07/25/2014 00:20:19;0002;PBS_Server;Svr;PBS_Server;Torque Server Version = 3.0.5, loglevel = 0
07/25/2014 00:25:19;0002;PBS_Server;Svr;PBS_Server;Torque Server Version = 3.0.5, loglevel = 0
07/25/2014 00:27:24;0040;PBS_Server;Svr;tyrone-cluster;Scheduler was sent the command time
07/25/2014 00:30:19;0002;PBS_Server;Svr;PBS_Server;Torque Server Version = 3.0.5, loglevel = 0
07/25/2014 00:35:19;0002;PBS_Server;Svr;PBS_Server;Torque Server Version = 3.0.5, loglevel = 0
07/25/2014 00:37:24;0040;PBS_Server;Svr;tyrone-cluster;Scheduler was sent the command time
07/25/2014 00:40:19;0002;PBS_Server;Svr;PBS_Server;Torque Server Version = 3.0.5, loglevel = 0
07/25/2014 00:45:19;0002;PBS_Server;Svr;PBS_Server;Torque Server Version = 3.0.5, loglevel = 0
07/25/2014 00:47:24;0040;PBS_Server;Svr;tyrone-cluster;Scheduler was sent the command time
07/25/2014 00:50:19;0002;PBS_Server;Svr;PBS_Server;Torque Server Version = 3.0.5, loglevel = 0
07/25/2014 00:55:19;0002;PBS_Server;Svr;PBS_Server;Torque Server Version = 3.0.5, loglevel = 0
07/25/2014 00:57:24;0040;PBS_Server;Svr;tyrone-cluster;Scheduler was sent the command time
07/25/2014 01:00:19;0002;PBS_Server;Svr;PBS_Server;Torque Server Version = 3.0.5, loglevel = 0
07/25/2014 01:05:19;0002;PBS_Server;Svr;PBS_Server;Torque Server Version = 3.0.5, loglevel = 0
07/25/2014 01:07:24;0040;PBS_Server;Svr;tyrone-cluster;Scheduler was sent the command time
07/25/2014 01:10:19;0002;PBS_Server;Svr;PBS_Server;Torque Server Version = 3.0.5, loglevel = 0
07/25/2014 01:15:19;0002;PBS_Server;Svr;PBS_Server;Torque Server Version = 3.0.5, loglevel = 0
07/25/2014 01:17:24;0040;PBS_Server;Svr;tyrone-cluster;Scheduler was sent the command time
07/25/2014 01:20:19;0002;PBS_Server;Svr;PBS_Server;Torque Server Version = 3.0.5, loglevel = 0
07/25/2014 01:25:19;0002;PBS_Server;Svr;PBS_Server;Torque Server Version = 3.0.5, loglevel = 0
07/25/2014 01:27:24;0040;PBS_Server;Svr;tyrone-cluster;Scheduler was sent the command time
07/25/2014 01:30:19;0002;PBS_Server;Svr;PBS_Server;Torque Server Version = 3.0.5, loglevel = 0
07/25/2014 01:35:19;0002;PBS_Server;Svr;PBS_Server;Torque Server Version = 3.0.5, loglevel = 0
07/25/2014 01:37:24;0040;PBS_Server;Svr;tyrone-cluster;Scheduler was sent the command time
07/25/2014 01:40:19;0002;PBS_Server;Svr;PBS_Server;Torque Server Version = 3.0.5, loglevel = 0
07/25/2014 01:45:19;0002;PBS_Server;Svr;PBS_Server;Torque Server Version = 3.0.5, loglevel = 0
07/25/2014 01:47:24;0040;PBS_Server;Svr;tyrone-cluster;Scheduler was sent the command time
07/25/2014 01:50:19;0002;PBS_Server;Svr;PBS_Server;Torque Server Version = 3.0.5, loglevel = 0
07/25/2014 01:55:19;0002;PBS_Server;Svr;PBS_Server;Torque Server Version = 3.0.5, loglevel = 0
07/25/2014 01:57:24;0040;PBS_Server;Svr;tyrone-cluster;Scheduler was sent the command time
07/25/2014 02:00:19;0002;PBS_Server;Svr;PBS_Server;Torque Server Version = 3.0.5, loglevel = 0
07/25/2014 02:05:19;0002;PBS_Server;Svr;PBS_Server;Torque Server Version = 3.0.5, loglevel = 0
07/25/2014 02:07:24;0040;PBS_Server;Svr;tyrone-cluster;Scheduler was sent the command time
07/25/2014 02:10:19;0002;PBS_Server;Svr;PBS_Server;Torque Server Version = 3.0.5, loglevel = 0
07/25/2014 02:15:19;0002;PBS_Server;Svr;PBS_Server;Torque Server Version = 3.0.5, loglevel = 0
07/25/2014 02:17:24;0040;PBS_Server;Svr;tyrone-cluster;Scheduler was sent the command time
07/25/2014 02:20:19;0002;PBS_Server;Svr;PBS_Server;Torque Server Version = 3.0.5, loglevel = 0
07/25/2014 02:25:19;0002;PBS_Server;Svr;PBS_Server;Torque Server Version = 3.0.5, loglevel = 0
07/25/2014 02:27:24;0040;PBS_Server;Svr;tyrone-cluster;Scheduler was sent the command time
07/25/2014 02:30:19;0002;PBS_Server;Svr;PBS_Server;Torque Server Version = 3.0.5, loglevel = 0
07/25/2014 02:35:19;0002;PBS_Server;Svr;PBS_Server;Torque Server Version = 3.0.5, loglevel = 0
07/25/2014 02:37:24;0040;PBS_Server;Svr;tyrone-cluster;Scheduler was sent the command time
07/25/2014 02:40:19;0002;PBS_Server;Svr;PBS_Server;Torque Server Version = 3.0.5, loglevel = 0
07/25/2014 02:45:19;0002;PBS_Server;Svr;PBS_Server;Torque Server Version = 3.0.5, loglevel = 0
07/25/2014 02:47:24;0040;PBS_Server;Svr;tyrone-cluster;Scheduler was sent the command time
07/25/2014 02:50:19;0002;PBS_Server;Svr;PBS_Server;Torque Server Version = 3.0.5, loglevel = 0
07/25/2014 02:55:19;0002;PBS_Server;Svr;PBS_Server;Torque Server Version = 3.0.5, loglevel = 0
07/25/2014 02:57:24;0040;PBS_Server;Svr;tyrone-cluster;Scheduler was sent the command time
07/25/2014 03:00:19;0002;PBS_Server;Svr;PBS_Server;Torque Server Version = 3.0.5, loglevel = 0
07/25/2014 03:05:19;0002;PBS_Server;Svr;PBS_Server;Torque Server Version = 3.0.5, loglevel = 0
07/25/2014 03:07:24;0040;PBS_Server;Svr;tyrone-cluster;Scheduler was sent the command time
07/25/2014 03:10:19;0002;PBS_Server;Svr;PBS_Server;Torque Server Version = 3.0.5, loglevel = 0
07/25/2014 03:15:19;0002;PBS_Server;Svr;PBS_Server;Torque Server Version = 3.0.5, loglevel = 0
07/25/2014 03:17:24;0040;PBS_Server;Svr;tyrone-cluster;Scheduler was sent the command time
07/25/2014 03:20:19;0002;PBS_Server;Svr;PBS_Server;Torque Server Version = 3.0.5, loglevel = 0
07/25/2014 03:25:19;0002;PBS_Server;Svr;PBS_Server;Torque Server Version = 3.0.5, loglevel = 0
07/25/2014 03:27:24;0040;PBS_Server;Svr;tyrone-cluster;Scheduler was sent the command time
07/25/2014 03:30:19;0002;PBS_Server;Svr;PBS_Server;Torque Server Version = 3.0.5, loglevel = 0
07/25/2014 03:35:19;0002;PBS_Server;Svr;PBS_Server;Torque Server Version = 3.0.5, loglevel = 0
07/25/2014 03:37:24;0040;PBS_Server;Svr;tyrone-cluster;Scheduler was sent the command time
07/25/2014 03:40:19;0002;PBS_Server;Svr;PBS_Server;Torque Server Version = 3.0.5, loglevel = 0
07/25/2014 03:45:19;0002;PBS_Server;Svr;PBS_Server;Torque Server Version = 3.0.5, loglevel = 0
07/25/2014 03:47:24;0040;PBS_Server;Svr;tyrone-cluster;Scheduler was sent the command time
07/25/2014 03:50:19;0002;PBS_Server;Svr;PBS_Server;Torque Server Version = 3.0.5, loglevel = 0
07/25/2014 03:55:19;0002;PBS_Server;Svr;PBS_Server;Torque Server Version = 3.0.5, loglevel = 0
07/25/2014 03:57:24;0040;PBS_Server;Svr;tyrone-cluster;Scheduler was sent the command time
07/25/2014 04:00:19;0002;PBS_Server;Svr;PBS_Server;Torque Server Version = 3.0.5, loglevel = 0
07/25/2014 04:05:19;0002;PBS_Server;Svr;PBS_Server;Torque Server Version = 3.0.5, loglevel = 0
07/25/2014 04:07:24;0040;PBS_Server;Svr;tyrone-cluster;Scheduler was sent the command time
07/25/2014 04:10:19;0002;PBS_Server;Svr;PBS_Server;Torque Server Version = 3.0.5, loglevel = 0
07/25/2014 04:15:19;0002;PBS_Server;Svr;PBS_Server;Torque Server Version = 3.0.5, loglevel = 0
07/25/2014 04:17:24;0040;PBS_Server;Svr;tyrone-cluster;Scheduler was sent the command time
07/25/2014 04:20:19;0002;PBS_Server;Svr;PBS_Server;Torque Server Version = 3.0.5, loglevel = 0
07/25/2014 04:25:19;0002;PBS_Server;Svr;PBS_Server;Torque Server Version = 3.0.5, loglevel = 0
07/25/2014 04:27:24;0040;PBS_Server;Svr;tyrone-cluster;Scheduler was sent the command time
07/25/2014 04:30:19;0002;PBS_Server;Svr;PBS_Server;Torque Server Version = 3.0.5, loglevel = 0
07/25/2014 04:35:19;0002;PBS_Server;Svr;PBS_Server;Torque Server Version = 3.0.5, loglevel = 0
07/25/2014 04:37:24;0040;PBS_Server;Svr;tyrone-cluster;Scheduler was sent the command time
07/25/2014 04:40:19;0002;PBS_Server;Svr;PBS_Server;Torque Server Version = 3.0.5, loglevel = 0
07/25/2014 04:45:19;0002;PBS_Server;Svr;PBS_Server;Torque Server Version = 3.0.5, loglevel = 0
07/25/2014 04:47:24;0040;PBS_Server;Svr;tyrone-cluster;Scheduler was sent the command time
07/25/2014 04:50:19;0002;PBS_Server;Svr;PBS_Server;Torque Server Version = 3.0.5, loglevel = 0
07/25/2014 04:55:19;0002;PBS_Server;Svr;PBS_Server;Torque Server Version = 3.0.5, loglevel = 0
07/25/2014 04:57:24;0040;PBS_Server;Svr;tyrone-cluster;Scheduler was sent the command time
07/25/2014 05:00:19;0002;PBS_Server;Svr;PBS_Server;Torque Server Version = 3.0.5, loglevel = 0
07/25/2014 05:05:19;0002;PBS_Server;Svr;PBS_Server;Torque Server Version = 3.0.5, loglevel = 0
07/25/2014 05:07:24;0040;PBS_Server;Svr;tyrone-cluster;Scheduler was sent the command time
07/25/2014 05:10:19;0002;PBS_Server;Svr;PBS_Server;Torque Server Version = 3.0.5, loglevel = 0
07/25/2014 05:15:19;0002;PBS_Server;Svr;PBS_Server;Torque Server Version = 3.0.5, loglevel = 0
07/25/2014 05:17:24;0040;PBS_Server;Svr;tyrone-cluster;Scheduler was sent the command time
07/25/2014 05:20:19;0002;PBS_Server;Svr;PBS_Server;Torque Server Version = 3.0.5, loglevel = 0
07/25/2014 05:25:19;0002;PBS_Server;Svr;PBS_Server;Torque Server Version = 3.0.5, loglevel = 0
07/25/2014 05:27:24;0040;PBS_Server;Svr;tyrone-cluster;Scheduler was sent the command time
07/25/2014 05:30:19;0002;PBS_Server;Svr;PBS_Server;Torque Server Version = 3.0.5, loglevel = 0
07/25/2014 05:35:19;0002;PBS_Server;Svr;PBS_Server;Torque Server Version = 3.0.5, loglevel = 0
07/25/2014 05:37:24;0040;PBS_Server;Svr;tyrone-cluster;Scheduler was sent the command time
07/25/2014 05:40:19;0002;PBS_Server;Svr;PBS_Server;Torque Server Version = 3.0.5, loglevel = 0
07/25/2014 05:45:19;0002;PBS_Server;Svr;PBS_Server;Torque Server Version = 3.0.5, loglevel = 0
07/25/2014 05:47:24;0040;PBS_Server;Svr;tyrone-cluster;Scheduler was sent the command time
07/25/2014 05:50:19;0002;PBS_Server;Svr;PBS_Server;Torque Server Version = 3.0.5, loglevel = 0
07/25/2014 05:55:19;0002;PBS_Server;Svr;PBS_Server;Torque Server Version = 3.0.5, loglevel = 0
07/25/2014 05:57:24;0040;PBS_Server;Svr;tyrone-cluster;Scheduler was sent the command time
07/25/2014 06:00:19;0002;PBS_Server;Svr;PBS_Server;Torque Server Version = 3.0.5, loglevel = 0
07/25/2014 06:05:19;0002;PBS_Server;Svr;PBS_Server;Torque Server Version = 3.0.5, loglevel = 0
07/25/2014 06:07:24;0040;PBS_Server;Svr;tyrone-cluster;Scheduler was sent the command time
07/25/2014 06:10:19;0002;PBS_Server;Svr;PBS_Server;Torque Server Version = 3.0.5, loglevel = 0
07/25/2014 06:15:19;0002;PBS_Server;Svr;PBS_Server;Torque Server Version = 3.0.5, loglevel = 0
07/25/2014 06:17:24;0040;PBS_Server;Svr;tyrone-cluster;Scheduler was sent the command time
07/25/2014 06:20:19;0002;PBS_Server;Svr;PBS_Server;Torque Server Version = 3.0.5, loglevel = 0
07/25/2014 06:25:19;0002;PBS_Server;Svr;PBS_Server;Torque Server Version = 3.0.5, loglevel = 0
07/25/2014 06:27:24;0040;PBS_Server;Svr;tyrone-cluster;Scheduler was sent the command time
07/25/2014 06:30:19;0002;PBS_Server;Svr;PBS_Server;Torque Server Version = 3.0.5, loglevel = 0
07/25/2014 06:35:19;0002;PBS_Server;Svr;PBS_Server;Torque Server Version = 3.0.5, loglevel = 0
07/25/2014 06:37:24;0040;PBS_Server;Svr;tyrone-cluster;Scheduler was sent the command time
07/25/2014 06:40:19;0002;PBS_Server;Svr;PBS_Server;Torque Server Version = 3.0.5, loglevel = 0
07/25/2014 06:45:19;0002;PBS_Server;Svr;PBS_Server;Torque Server Version = 3.0.5, loglevel = 0
07/25/2014 06:47:24;0040;PBS_Server;Svr;tyrone-cluster;Scheduler was sent the command time
07/25/2014 06:50:19;0002;PBS_Server;Svr;PBS_Server;Torque Server Version = 3.0.5, loglevel = 0
07/25/2014 06:55:19;0002;PBS_Server;Svr;PBS_Server;Torque Server Version = 3.0.5, loglevel = 0
07/25/2014 06:57:24;0040;PBS_Server;Svr;tyrone-cluster;Scheduler was sent the command time
07/25/2014 07:00:19;0002;PBS_Server;Svr;PBS_Server;Torque Server Version = 3.0.5, loglevel = 0
07/25/2014 07:05:19;0002;PBS_Server;Svr;PBS_Server;Torque Server Version = 3.0.5, loglevel = 0
07/25/2014 07:07:24;0040;PBS_Server;Svr;tyrone-cluster;Scheduler was sent the command time
07/25/2014 07:10:19;0002;PBS_Server;Svr;PBS_Server;Torque Server Version = 3.0.5, loglevel = 0
07/25/2014 07:15:19;0002;PBS_Server;Svr;PBS_Server;Torque Server Version = 3.0.5, loglevel = 0
07/25/2014 07:17:24;0040;PBS_Server;Svr;tyrone-cluster;Scheduler was sent the command time
07/25/2014 07:20:19;0002;PBS_Server;Svr;PBS_Server;Torque Server Version = 3.0.5, loglevel = 0
07/25/2014 07:25:19;0002;PBS_Server;Svr;PBS_Server;Torque Server Version = 3.0.5, loglevel = 0
07/25/2014 07:27:24;0040;PBS_Server;Svr;tyrone-cluster;Scheduler was sent the command time
07/25/2014 07:30:19;0002;PBS_Server;Svr;PBS_Server;Torque Server Version = 3.0.5, loglevel = 0
07/25/2014 07:35:19;0002;PBS_Server;Svr;PBS_Server;Torque Server Version = 3.0.5, loglevel = 0
07/25/2014 07:37:24;0040;PBS_Server;Svr;tyrone-cluster;Scheduler was sent the command time
07/25/2014 07:40:19;0002;PBS_Server;Svr;PBS_Server;Torque Server Version = 3.0.5, loglevel = 0
07/25/2014 07:45:19;0002;PBS_Server;Svr;PBS_Server;Torque Server Version = 3.0.5, loglevel = 0
07/25/2014 07:47:24;0040;PBS_Server;Svr;tyrone-cluster;Scheduler was sent the command time
07/25/2014 07:50:19;0002;PBS_Server;Svr;PBS_Server;Torque Server Version = 3.0.5, loglevel = 0
07/25/2014 07:55:19;0002;PBS_Server;Svr;PBS_Server;Torque Server Version = 3.0.5, loglevel = 0
07/25/2014 07:57:24;0040;PBS_Server;Svr;tyrone-cluster;Scheduler was sent the command time
07/25/2014 08:00:19;0002;PBS_Server;Svr;PBS_Server;Torque Server Version = 3.0.5, loglevel = 0
07/25/2014 08:05:19;0002;PBS_Server;Svr;PBS_Server;Torque Server Version = 3.0.5, loglevel = 0
07/25/2014 08:07:24;0040;PBS_Server;Svr;tyrone-cluster;Scheduler was sent the command time
07/25/2014 08:10:19;0002;PBS_Server;Svr;PBS_Server;Torque Server Version = 3.0.5, loglevel = 0
07/25/2014 08:15:19;0002;PBS_Server;Svr;PBS_Server;Torque Server Version = 3.0.5, loglevel = 0
07/25/2014 08:17:24;0040;PBS_Server;Svr;tyrone-cluster;Scheduler was sent the command time
07/25/2014 08:20:19;0002;PBS_Server;Svr;PBS_Server;Torque Server Version = 3.0.5, loglevel = 0
07/25/2014 08:25:19;0002;PBS_Server;Svr;PBS_Server;Torque Server Version = 3.0.5, loglevel = 0
07/25/2014 08:27:24;0040;PBS_Server;Svr;tyrone-cluster;Scheduler was sent the command time
07/25/2014 08:30:19;0002;PBS_Server;Svr;PBS_Server;Torque Server Version = 3.0.5, loglevel = 0
07/25/2014 08:35:19;0002;PBS_Server;Svr;PBS_Server;Torque Server Version = 3.0.5, loglevel = 0
07/25/2014 08:37:24;0040;PBS_Server;Svr;tyrone-cluster;Scheduler was sent the command time
07/25/2014 08:40:19;0002;PBS_Server;Svr;PBS_Server;Torque Server Version = 3.0.5, loglevel = 0
07/25/2014 08:45:19;0002;PBS_Server;Svr;PBS_Server;Torque Server Version = 3.0.5, loglevel = 0
07/25/2014 08:47:24;0040;PBS_Server;Svr;tyrone-cluster;Scheduler was sent the command time
07/25/2014 08:50:19;0002;PBS_Server;Svr;PBS_Server;Torque Server Version = 3.0.5, loglevel = 0
07/25/2014 08:55:19;0002;PBS_Server;Svr;PBS_Server;Torque Server Version = 3.0.5, loglevel = 0
07/25/2014 08:57:24;0040;PBS_Server;Svr;tyrone-cluster;Scheduler was sent the command time
07/25/2014 09:00:19;0002;PBS_Server;Svr;PBS_Server;Torque Server Version = 3.0.5, loglevel = 0
07/25/2014 09:05:19;0002;PBS_Server;Svr;PBS_Server;Torque Server Version = 3.0.5, loglevel = 0
07/25/2014 09:07:24;0040;PBS_Server;Svr;tyrone-cluster;Scheduler was sent the command time
07/25/2014 09:10:19;0002;PBS_Server;Svr;PBS_Server;Torque Server Version = 3.0.5, loglevel = 0
07/25/2014 09:15:19;0002;PBS_Server;Svr;PBS_Server;Torque Server Version = 3.0.5, loglevel = 0
07/25/2014 09:17:24;0040;PBS_Server;Svr;tyrone-cluster;Scheduler was sent the command time
07/25/2014 09:19:05;0100;PBS_Server;Job;40655.tyrone-cluster;enqueuing into batch, state 1 hop 1
07/25/2014 09:19:05;0002;PBS_Server;Svr;Act;Account file /var/spool/torque/server_priv/accounting/20140725 opened
07/25/2014 09:19:05;0100;PBS_Server;Job;40655.tyrone-cluster;dequeuing from batch, state QUEUED
07/25/2014 09:19:05;0100;PBS_Server;Job;40655.tyrone-cluster;enqueuing into qp32, state 1 hop 1
07/25/2014 09:19:05;0008;PBS_Server;Job;40655.tyrone-cluster;Job Queued at request of secpsm@tyrone-cluster, owner = secpsm@tyrone-cluster, job name = job32, queue = qp32
07/25/2014 09:19:05;0040;PBS_Server;Svr;tyrone-cluster;Scheduler was sent the command new
07/25/2014 09:19:05;0008;PBS_Server;Job;40655.tyrone-cluster;Job Modified at request of Scheduler@tyrone-cluster
07/25/2014 09:19:29;0100;PBS_Server;Job;40656.tyrone-cluster;enqueuing into batch, state 1 hop 1
07/25/2014 09:19:29;0100;PBS_Server;Job;40656.tyrone-cluster;dequeuing from batch, state QUEUED
07/25/2014 09:19:29;0100;PBS_Server;Job;40656.tyrone-cluster;enqueuing into idqueue, state 1 hop 1
07/25/2014 09:19:29;0008;PBS_Server;Job;40656.tyrone-cluster;Job Queued at request of secpsm@tyrone-cluster, owner = secpsm@tyrone-cluster, job name = job32, queue = idqueue
07/25/2014 09:19:29;0040;PBS_Server;Svr;tyrone-cluster;Scheduler was sent the command new
07/25/2014 09:19:29;0008;PBS_Server;Job;40656.tyrone-cluster;Job Modified at request of Scheduler@tyrone-cluster
07/25/2014 09:19:29;0008;PBS_Server;Job;40656.tyrone-cluster;Job Run at request of Scheduler@tyrone-cluster
07/25/2014 09:19:29;0040;PBS_Server;Svr;tyrone-cluster;Scheduler was sent the command recyc
07/25/2014 09:19:29;000d;PBS_Server;Job;40656.tyrone-cluster;Not sending email: User does not want mail of this type.
07/25/2014 09:20:19;0002;PBS_Server;Svr;PBS_Server;Torque Server Version = 3.0.5, loglevel = 0
07/25/2014 09:25:19;0002;PBS_Server;Svr;PBS_Server;Torque Server Version = 3.0.5, loglevel = 0
07/25/2014 09:29:29;0040;PBS_Server;Svr;tyrone-cluster;Scheduler was sent the command time
07/25/2014 09:30:19;0002;PBS_Server;Svr;PBS_Server;Torque Server Version = 3.0.5, loglevel = 0
07/25/2014 09:35:19;0002;PBS_Server;Svr;PBS_Server;Torque Server Version = 3.0.5, loglevel = 0
07/25/2014 09:39:29;0040;PBS_Server;Svr;tyrone-cluster;Scheduler was sent the command time
07/25/2014 09:40:19;0002;PBS_Server;Svr;PBS_Server;Torque Server Version = 3.0.5, loglevel = 0
07/25/2014 09:45:19;0002;PBS_Server;Svr;PBS_Server;Torque Server Version = 3.0.5, loglevel = 0
07/25/2014 09:49:29;0040;PBS_Server;Svr;tyrone-cluster;Scheduler was sent the command time
07/25/2014 09:50:19;0002;PBS_Server;Svr;PBS_Server;Torque Server Version = 3.0.5, loglevel = 0
07/25/2014 09:55:19;0002;PBS_Server;Svr;PBS_Server;Torque Server Version = 3.0.5, loglevel = 0
07/25/2014 09:56:23;000d;PBS_Server;Job;40603.tyrone-cluster;Not sending email: User does not want mail of this type.
07/25/2014 09:56:23;0010;PBS_Server;Job;40603.tyrone-cluster;Exit_status=271 resources_used.cput=1534:59:17 resources_used.mem=2657548kb resources_used.vmem=36338664kb resources_used.walltime=24:00:41
07/25/2014 09:56:23;0008;PBS_Server;Job;NULL;on_job_exit valid pjob: 0x1ebeb10 (substate=50)
07/25/2014 09:56:24;0008;PBS_Server;Job;NULL;on_job_exit valid pjob: 0x1ebeb10 (substate=51)
07/25/2014 09:56:35;0008;PBS_Server;Job;NULL;on_job_exit valid pjob: 0x1ebeb10 (substate=51)
07/25/2014 09:56:35;0008;PBS_Server;Job;NULL;on_job_exit valid pjob: 0x1ebeb10 (substate=53)
07/25/2014 09:56:35;0100;PBS_Server;Job;40603.tyrone-cluster;dequeuing from qp256, state COMPLETE
07/25/2014 09:56:35;0040;PBS_Server;Svr;tyrone-cluster;Scheduler was sent the command term
07/25/2014 09:56:35;0008;PBS_Server;Job;40654.tyrone-cluster;Job Modified at request of Scheduler@tyrone-cluster
07/25/2014 09:56:35;0008;PBS_Server;Job;40654.tyrone-cluster;Job Run at request of Scheduler@tyrone-cluster
07/25/2014 09:56:35;0040;PBS_Server;Svr;tyrone-cluster;Scheduler was sent the command recyc
07/25/2014 09:56:36;000d;PBS_Server;Job;40654.tyrone-cluster;Not sending email: User does not want mail of this type.
07/25/2014 09:56:36;0010;PBS_Server;Job;40654.tyrone-cluster;Exit_status=1 resources_used.cput=00:00:00 resources_used.mem=800kb resources_used.vmem=13624kb resources_used.walltime=00:00:01
07/25/2014 09:56:36;0008;PBS_Server;Job;NULL;on_job_exit valid pjob: 0x1f13f60 (substate=50)
07/25/2014 09:56:36;0008;PBS_Server;Job;NULL;on_job_exit valid pjob: 0x1f13f60 (substate=51)
07/25/2014 09:56:37;0008;PBS_Server;Job;NULL;on_job_exit valid pjob: 0x1f13f60 (substate=51)
07/25/2014 09:56:37;0008;PBS_Server;Job;NULL;on_job_exit valid pjob: 0x1f13f60 (substate=53)
07/25/2014 09:56:37;0100;PBS_Server;Job;40654.tyrone-cluster;dequeuing from qp256, state COMPLETE
07/25/2014 09:56:37;0040;PBS_Server;Svr;tyrone-cluster;Scheduler was sent the command term
07/25/2014 10:00:19;0002;PBS_Server;Svr;PBS_Server;Torque Server Version = 3.0.5, loglevel = 0
07/25/2014 10:05:19;0002;PBS_Server;Svr;PBS_Server;Torque Server Version = 3.0.5, loglevel = 0
07/25/2014 10:06:37;0040;PBS_Server;Svr;tyrone-cluster;Scheduler was sent the command time
07/25/2014 10:07:09;0100;PBS_Server;Job;40657.tyrone-cluster;enqueuing into batch, state 1 hop 1
07/25/2014 10:07:09;0100;PBS_Server;Job;40657.tyrone-cluster;dequeuing from batch, state QUEUED
07/25/2014 10:07:09;0100;PBS_Server;Job;40657.tyrone-cluster;enqueuing into qp32, state 1 hop 1
07/25/2014 10:07:09;0008;PBS_Server;Job;40657.tyrone-cluster;Job Queued at request of aseganes@tyrone-cluster, owner = aseganes@tyrone-cluster, job name = jobname, queue = qp32
07/25/2014 10:07:09;0040;PBS_Server;Svr;tyrone-cluster;Scheduler was sent the command new
07/25/2014 10:07:09;0008;PBS_Server;Job;40657.tyrone-cluster;Job Modified at request of Scheduler@tyrone-cluster
07/25/2014 10:07:23;0008;PBS_Server;Job;40657.tyrone-cluster;Job deleted at request of aseganes@tyrone-cluster
07/25/2014 10:07:23;0008;PBS_Server;Job;NULL;on_job_exit valid pjob: 0x1ebeb10 (substate=59)
07/25/2014 10:07:23;0100;PBS_Server;Job;40657.tyrone-cluster;dequeuing from qp32, state COMPLETE
07/25/2014 10:07:23;0040;PBS_Server;Svr;tyrone-cluster;Scheduler was sent the command term
07/25/2014 10:10:19;0002;PBS_Server;Svr;PBS_Server;Torque Server Version = 3.0.5, loglevel = 0
07/25/2014 10:12:44;0100;PBS_Server;Job;40658.tyrone-cluster;enqueuing into batch, state 1 hop 1
07/25/2014 10:12:44;0008;PBS_Server;Job;40658.tyrone-cluster;Job rejected by all possible destinations (check syntax, queue resources, ...)
07/25/2014 10:12:44;0100;PBS_Server;Job;40658.tyrone-cluster;dequeuing from batch, state QUEUED
07/25/2014 10:12:44;0080;PBS_Server;Req;req_reject;Reject reply code=15041(Job rejected by all possible destinations (check syntax, queue resources, ...)), aux=0, type=Commit, from aseganes@tyrone-cluster
07/25/2014 10:12:44;0040;PBS_Server;Svr;tyrone-cluster;Scheduler was sent the command term
07/25/2014 10:13:24;0100;PBS_Server;Job;40659.tyrone-cluster;enqueuing into batch, state 1 hop 1
07/25/2014 10:13:24;0008;PBS_Server;Job;40659.tyrone-cluster;Job rejected by all possible destinations (check syntax, queue resources, ...)
07/25/2014 10:13:24;0100;PBS_Server;Job;40659.tyrone-cluster;dequeuing from batch, state QUEUED
07/25/2014 10:13:24;0080;PBS_Server;Req;req_reject;Reject reply code=15041(Job rejected by all possible destinations (check syntax, queue resources, ...)), aux=0, type=Commit, from aseganes@tyrone-cluster
07/25/2014 10:13:24;0040;PBS_Server;Svr;tyrone-cluster;Scheduler was sent the command term
07/25/2014 10:14:25;0100;PBS_Server;Job;40660.tyrone-cluster;enqueuing into batch, state 1 hop 1
07/25/2014 10:14:25;0100;PBS_Server;Job;40660.tyrone-cluster;dequeuing from batch, state QUEUED
07/25/2014 10:14:25;0100;PBS_Server;Job;40660.tyrone-cluster;enqueuing into qp32, state 1 hop 1
07/25/2014 10:14:25;0008;PBS_Server;Job;40660.tyrone-cluster;Job Queued at request of aseganes@tyrone-cluster, owner = aseganes@tyrone-cluster, job name = jobname, queue = qp32
07/25/2014 10:14:25;0040;PBS_Server;Svr;tyrone-cluster;Scheduler was sent the command new
07/25/2014 10:14:25;0008;PBS_Server;Job;40660.tyrone-cluster;Job Modified at request of Scheduler@tyrone-cluster
07/25/2014 10:15:19;0002;PBS_Server;Svr;PBS_Server;Torque Server Version = 3.0.5, loglevel = 0
07/25/2014 10:15:21;0008;PBS_Server;Job;40660.tyrone-cluster;Job deleted at request of aseganes@tyrone-cluster
07/25/2014 10:15:21;0008;PBS_Server;Job;NULL;on_job_exit valid pjob: 0x1ebeb10 (substate=59)
07/25/2014 10:15:21;0100;PBS_Server;Job;40660.tyrone-cluster;dequeuing from qp32, state COMPLETE
07/25/2014 10:15:21;0040;PBS_Server;Svr;tyrone-cluster;Scheduler was sent the command term
07/25/2014 10:15:38;0100;PBS_Server;Job;40661.tyrone-cluster;enqueuing into batch, state 1 hop 1
07/25/2014 10:15:39;0008;PBS_Server;Job;40661.tyrone-cluster;Job rejected by all possible destinations (check syntax, queue resources, ...)
07/25/2014 10:15:39;0100;PBS_Server;Job;40661.tyrone-cluster;dequeuing from batch, state QUEUED
07/25/2014 10:15:39;0080;PBS_Server;Req;req_reject;Reject reply code=15041(Job rejected by all possible destinations (check syntax, queue resources, ...)), aux=0, type=Commit, from aseganes@tyrone-cluster
07/25/2014 10:15:39;0040;PBS_Server;Svr;tyrone-cluster;Scheduler was sent the command term
07/25/2014 10:16:50;0100;PBS_Server;Job;40662.tyrone-cluster;enqueuing into batch, state 1 hop 1
07/25/2014 10:16:50;0100;PBS_Server;Job;40662.tyrone-cluster;dequeuing from batch, state QUEUED
07/25/2014 10:16:50;0100;PBS_Server;Job;40662.tyrone-cluster;enqueuing into qp32, state 1 hop 1
07/25/2014 10:16:50;0008;PBS_Server;Job;40662.tyrone-cluster;Job Queued at request of aseganes@tyrone-cluster, owner = aseganes@tyrone-cluster, job name = jobname, queue = qp32
07/25/2014 10:16:50;0040;PBS_Server;Svr;tyrone-cluster;Scheduler was sent the command new
07/25/2014 10:16:50;0008;PBS_Server;Job;40662.tyrone-cluster;Job Modified at request of Scheduler@tyrone-cluster
07/25/2014 10:17:31;0100;PBS_Server;Job;40663.tyrone-cluster;enqueuing into batch, state 1 hop 1
07/25/2014 10:17:31;0008;PBS_Server;Job;40663.tyrone-cluster;Job Queued at request of aseganes@tyrone-cluster, owner = aseganes@tyrone-cluster, job name = jobname, queue = batch
07/25/2014 10:17:31;0040;PBS_Server;Svr;tyrone-cluster;Scheduler was sent the command new
07/25/2014 10:17:31;0008;PBS_Server;Job;40663.tyrone-cluster;Job Modified at request of Scheduler@tyrone-cluster
07/25/2014 10:17:39;0008;PBS_Server;Job;40662.tyrone-cluster;Job deleted at request of aseganes@tyrone-cluster
07/25/2014 10:17:39;0008;PBS_Server;Job;NULL;on_job_exit valid pjob: 0x1ebeb10 (substate=59)
07/25/2014 10:17:39;0100;PBS_Server;Job;40662.tyrone-cluster;dequeuing from qp32, state COMPLETE
07/25/2014 10:17:39;0040;PBS_Server;Svr;tyrone-cluster;Scheduler was sent the command term
07/25/2014 10:18:01;0008;PBS_Server;Job;40663.tyrone-cluster;Job rejected by all possible destinations (check syntax, queue resources, ...)
07/25/2014 10:18:01;0100;PBS_Server;Job;40663.tyrone-cluster;dequeuing from batch, state EXITING
07/25/2014 10:18:01;0040;PBS_Server;Svr;tyrone-cluster;Scheduler was sent the command term
07/25/2014 10:19:43;0100;PBS_Server;Job;40664.tyrone-cluster;enqueuing into batch, state 1 hop 1
07/25/2014 10:19:43;0008;PBS_Server;Job;40664.tyrone-cluster;Job rejected by all possible destinations (check syntax, queue resources, ...)
07/25/2014 10:19:43;0100;PBS_Server;Job;40664.tyrone-cluster;dequeuing from batch, state QUEUED
07/25/2014 10:19:43;0080;PBS_Server;Req;req_reject;Reject reply code=15041(Job rejected by all possible destinations (check syntax, queue resources, ...)), aux=0, type=Commit, from aseganes@tyrone-cluster
07/25/2014 10:19:43;0040;PBS_Server;Svr;tyrone-cluster;Scheduler was sent the command term
07/25/2014 10:20:19;0002;PBS_Server;Svr;PBS_Server;Torque Server Version = 3.0.5, loglevel = 0
07/25/2014 10:20:33;0100;PBS_Server;Job;40665.tyrone-cluster;enqueuing into batch, state 1 hop 1
07/25/2014 10:20:33;0100;PBS_Server;Job;40665.tyrone-cluster;dequeuing from batch, state QUEUED
07/25/2014 10:20:33;0100;PBS_Server;Job;40665.tyrone-cluster;enqueuing into qp32, state 1 hop 1
07/25/2014 10:20:33;0008;PBS_Server;Job;40665.tyrone-cluster;Job Queued at request of aseganes@tyrone-cluster, owner = aseganes@tyrone-cluster, job name = jobname, queue = qp32
07/25/2014 10:20:33;0040;PBS_Server;Svr;tyrone-cluster;Scheduler was sent the command new
07/25/2014 10:20:33;0008;PBS_Server;Job;40665.tyrone-cluster;Job Modified at request of Scheduler@tyrone-cluster
07/25/2014 10:22:34;0100;PBS_Server;Job;40666.tyrone-cluster;enqueuing into batch, state 1 hop 1
07/25/2014 10:22:34;0100;PBS_Server;Job;40666.tyrone-cluster;dequeuing from batch, state QUEUED
07/25/2014 10:22:34;0100;PBS_Server;Job;40666.tyrone-cluster;enqueuing into qp32, state 1 hop 1
07/25/2014 10:22:34;0008;PBS_Server;Job;40666.tyrone-cluster;Job Queued at request of mbunisha@tyrone-cluster, owner = mbunisha@tyrone-cluster, job name = erman8-24-7-14, queue = qp32
07/25/2014 10:22:34;0040;PBS_Server;Svr;tyrone-cluster;Scheduler was sent the command new
07/25/2014 10:22:34;0008;PBS_Server;Job;40666.tyrone-cluster;Job Modified at request of Scheduler@tyrone-cluster
07/25/2014 10:25:19;0002;PBS_Server;Svr;PBS_Server;Torque Server Version = 3.0.5, loglevel = 0
07/25/2014 10:30:19;0002;PBS_Server;Svr;PBS_Server;Torque Server Version = 3.0.5, loglevel = 0
07/25/2014 10:32:34;0040;PBS_Server;Svr;tyrone-cluster;Scheduler was sent the command time
07/25/2014 10:35:19;0002;PBS_Server;Svr;PBS_Server;Torque Server Version = 3.0.5, loglevel = 0
07/25/2014 10:40:19;0002;PBS_Server;Svr;PBS_Server;Torque Server Version = 3.0.5, loglevel = 0
07/25/2014 10:42:34;0040;PBS_Server;Svr;tyrone-cluster;Scheduler was sent the command time
07/25/2014 10:45:19;0002;PBS_Server;Svr;PBS_Server;Torque Server Version = 3.0.5, loglevel = 0
07/25/2014 10:50:19;0002;PBS_Server;Svr;PBS_Server;Torque Server Version = 3.0.5, loglevel = 0
07/25/2014 10:52:34;0040;PBS_Server;Svr;tyrone-cluster;Scheduler was sent the command time
07/25/2014 10:55:19;0002;PBS_Server;Svr;PBS_Server;Torque Server Version = 3.0.5, loglevel = 0
07/25/2014 11:00:06;0100;PBS_Server;Job;40667.tyrone-cluster;enqueuing into batch, state 1 hop 1
07/25/2014 11:00:06;0008;PBS_Server;Job;40667.tyrone-cluster;Job Queued at request of biosilva@tyrone-cluster, owner = biosilva@tyrone-cluster, job name = hammer_ncbi_4, queue = batch
07/25/2014 11:00:06;0040;PBS_Server;Svr;tyrone-cluster;Scheduler was sent the command new
07/25/2014 11:00:06;0008;PBS_Server;Job;40667.tyrone-cluster;Job Modified at request of Scheduler@tyrone-cluster
07/25/2014 11:00:19;0002;PBS_Server;Svr;PBS_Server;Torque Server Version = 3.0.5, loglevel = 0
07/25/2014 11:00:37;0040;PBS_Server;Svr;tyrone-cluster;Scheduler was sent the command new
07/25/2014 11:01:07;0040;PBS_Server;Svr;tyrone-cluster;Scheduler was sent the command new
07/25/2014 11:01:37;0040;PBS_Server;Svr;tyrone-cluster;Scheduler was sent the command new
07/25/2014 11:02:07;0040;PBS_Server;Svr;tyrone-cluster;Scheduler was sent the command new
07/25/2014 11:02:37;0040;PBS_Server;Svr;tyrone-cluster;Scheduler was sent the command new
07/25/2014 11:03:08;0040;PBS_Server;Svr;tyrone-cluster;Scheduler was sent the command new
07/25/2014 11:03:38;0040;PBS_Server;Svr;tyrone-cluster;Scheduler was sent the command new
07/25/2014 11:04:08;0040;PBS_Server;Svr;tyrone-cluster;Scheduler was sent the command new
07/25/2014 11:04:38;0040;PBS_Server;Svr;tyrone-cluster;Scheduler was sent the command new
07/25/2014 11:05:08;0040;PBS_Server;Svr;tyrone-cluster;Scheduler was sent the command new
07/25/2014 11:05:19;0002;PBS_Server;Svr;PBS_Server;Torque Server Version = 3.0.5, loglevel = 0
07/25/2014 11:05:38;0040;PBS_Server;Svr;tyrone-cluster;Scheduler was sent the command new
07/25/2014 11:06:08;0040;PBS_Server;Svr;tyrone-cluster;Scheduler was sent the command new
07/25/2014 11:06:38;0040;PBS_Server;Svr;tyrone-cluster;Scheduler was sent the command new
07/25/2014 11:07:08;0040;PBS_Server;Svr;tyrone-cluster;Scheduler was sent the command new
07/25/2014 11:07:38;0040;PBS_Server;Svr;tyrone-cluster;Scheduler was sent the command new
07/25/2014 11:08:08;0040;PBS_Server;Svr;tyrone-cluster;Scheduler was sent the command new
07/25/2014 11:08:38;0040;PBS_Server;Svr;tyrone-cluster;Scheduler was sent the command new
07/25/2014 11:09:08;0040;PBS_Server;Svr;tyrone-cluster;Scheduler was sent the command new
07/25/2014 11:09:38;0040;PBS_Server;Svr;tyrone-cluster;Scheduler was sent the command new
07/25/2014 11:10:08;0040;PBS_Server;Svr;tyrone-cluster;Scheduler was sent the command new
07/25/2014 11:10:19;0002;PBS_Server;Svr;PBS_Server;Torque Server Version = 3.0.5, loglevel = 0
07/25/2014 11:10:38;0040;PBS_Server;Svr;tyrone-cluster;Scheduler was sent the command new
07/25/2014 11:11:08;0040;PBS_Server;Svr;tyrone-cluster;Scheduler was sent the command new
07/25/2014 11:11:38;0040;PBS_Server;Svr;tyrone-cluster;Scheduler was sent the command new
07/25/2014 11:12:08;0040;PBS_Server;Svr;tyrone-cluster;Scheduler was sent the command new
07/25/2014 11:12:31;0008;PBS_Server;Job;40656.tyrone-cluster;Job deleted at request of secpsm@tyrone-cluster
07/25/2014 11:12:31;0008;PBS_Server;Job;40656.tyrone-cluster;Job sent signal SIGTERM on delete
07/25/2014 11:12:31;000d;PBS_Server;Job;40656.tyrone-cluster;Not sending email: User does not want mail of this type.
07/25/2014 11:12:31;0010;PBS_Server;Job;40656.tyrone-cluster;Exit_status=143 resources_used.cput=03:45:00 resources_used.mem=2735964kb resources_used.vmem=3680560kb resources_used.walltime=01:53:02
07/25/2014 11:12:31;0008;PBS_Server;Job;NULL;on_job_exit valid pjob: 0x1eb2700 (substate=50)
07/25/2014 11:12:31;0008;PBS_Server;Job;NULL;on_job_exit valid pjob: 0x1eb2700 (substate=51)
07/25/2014 11:12:31;0008;PBS_Server;Job;NULL;on_job_exit valid pjob: 0x1eb2700 (substate=51)
07/25/2014 11:12:31;0008;PBS_Server;Job;NULL;on_job_exit valid pjob: 0x1eb2700 (substate=53)
07/25/2014 11:12:31;0100;PBS_Server;Job;40656.tyrone-cluster;dequeuing from idqueue, state COMPLETE
07/25/2014 11:12:31;0040;PBS_Server;Svr;tyrone-cluster;Scheduler was sent the command term
07/25/2014 11:12:38;0040;PBS_Server;Svr;tyrone-cluster;Scheduler was sent the command new
07/25/2014 11:12:56;0100;PBS_Server;Job;40668.tyrone-cluster;enqueuing into batch, state 1 hop 1
07/25/2014 11:12:56;0008;PBS_Server;Job;40668.tyrone-cluster;Job Queued at request of secpsm@tyrone-cluster, owner = secpsm@tyrone-cluster, job name = job32, queue = batch
07/25/2014 11:12:56;0040;PBS_Server;Svr;tyrone-cluster;Scheduler was sent the command new
07/25/2014 11:12:57;0008;PBS_Server;Job;40668.tyrone-cluster;Job Modified at request of Scheduler@tyrone-cluster
07/25/2014 11:13:09;0040;PBS_Server;Svr;tyrone-cluster;Scheduler was sent the command new
07/25/2014 11:13:27;0040;PBS_Server;Svr;tyrone-cluster;Scheduler was sent the command new
07/25/2014 11:13:32;0008;PBS_Server;Job;40655.tyrone-cluster;Job deleted at request of secpsm@tyrone-cluster
07/25/2014 11:13:32;0008;PBS_Server;Job;NULL;on_job_exit valid pjob: 0x1eb94a0 (substate=59)
07/25/2014 11:13:32;0100;PBS_Server;Job;40655.tyrone-cluster;dequeuing from qp32, state COMPLETE
07/25/2014 11:13:32;0040;PBS_Server;Svr;tyrone-cluster;Scheduler was sent the command term
07/25/2014 11:13:39;0040;PBS_Server;Svr;tyrone-cluster;Scheduler was sent the command new
07/25/2014 11:13:59;0100;PBS_Server;Job;40668.tyrone-cluster;dequeuing from batch, state QUEUED
07/25/2014 11:13:59;0100;PBS_Server;Job;40668.tyrone-cluster;enqueuing into qp32, state 1 hop 1
07/25/2014 11:14:00;0040;PBS_Server;Svr;tyrone-cluster;Scheduler was sent the command new
07/25/2014 11:14:00;0008;PBS_Server;Job;40668.tyrone-cluster;Job Modified at request of Scheduler@tyrone-cluster
07/25/2014 11:14:09;0040;PBS_Server;Svr;tyrone-cluster;Scheduler was sent the command new
07/25/2014 11:14:39;0040;PBS_Server;Svr;tyrone-cluster;Scheduler was sent the command new
07/25/2014 11:15:09;0040;PBS_Server;Svr;tyrone-cluster;Scheduler was sent the command new
07/25/2014 11:15:19;0002;PBS_Server;Svr;PBS_Server;Torque Server Version = 3.0.5, loglevel = 0
07/25/2014 11:15:39;0040;PBS_Server;Svr;tyrone-cluster;Scheduler was sent the command new
07/25/2014 11:16:09;0040;PBS_Server;Svr;tyrone-cluster;Scheduler was sent the command new
07/25/2014 11:16:18;0008;PBS_Server;Job;40668.tyrone-cluster;Job deleted at request of secpsm@tyrone-cluster
07/25/2014 11:16:18;0008;PBS_Server;Job;NULL;on_job_exit valid pjob: 0x1eb2700 (substate=59)
07/25/2014 11:16:18;0100;PBS_Server;Job;40668.tyrone-cluster;dequeuing from qp32, state COMPLETE
07/25/2014 11:16:18;0040;PBS_Server;Svr;tyrone-cluster;Scheduler was sent the command term
07/25/2014 11:16:37;0100;PBS_Server;Job;40669.tyrone-cluster;enqueuing into batch, state 1 hop 1
07/25/2014 11:16:37;0100;PBS_Server;Job;40669.tyrone-cluster;dequeuing from batch, state QUEUED
07/25/2014 11:16:37;0100;PBS_Server;Job;40669.tyrone-cluster;enqueuing into qp32, state 1 hop 1
07/25/2014 11:16:37;0008;PBS_Server;Job;40669.tyrone-cluster;Job Queued at request of secpsm@tyrone-cluster, owner = secpsm@tyrone-cluster, job name = job32, queue = qp32
07/25/2014 11:16:37;0040;PBS_Server;Svr;tyrone-cluster;Scheduler was sent the command new
07/25/2014 11:16:37;0008;PBS_Server;Job;40669.tyrone-cluster;Job Modified at request of Scheduler@tyrone-cluster
07/25/2014 11:16:39;0040;PBS_Server;Svr;tyrone-cluster;Scheduler was sent the command new
07/25/2014 11:17:09;0040;PBS_Server;Svr;tyrone-cluster;Scheduler was sent the command new
07/25/2014 11:17:26;0008;PBS_Server;Job;40669.tyrone-cluster;Job deleted at request of secpsm@tyrone-cluster
07/25/2014 11:17:26;0008;PBS_Server;Job;NULL;on_job_exit valid pjob: 0x1eb94a0 (substate=59)
07/25/2014 11:17:26;0100;PBS_Server;Job;40669.tyrone-cluster;dequeuing from qp32, state COMPLETE
07/25/2014 11:17:26;0040;PBS_Server;Svr;tyrone-cluster;Scheduler was sent the command term
07/25/2014 11:17:39;0040;PBS_Server;Svr;tyrone-cluster;Scheduler was sent the command new
07/25/2014 11:18:09;0040;PBS_Server;Svr;tyrone-cluster;Scheduler was sent the command new
07/25/2014 11:18:14;0100;PBS_Server;Job;40670.tyrone-cluster;enqueuing into batch, state 1 hop 1
07/25/2014 11:18:14;0100;PBS_Server;Job;40670.tyrone-cluster;dequeuing from batch, state QUEUED
07/25/2014 11:18:14;0100;PBS_Server;Job;40670.tyrone-cluster;enqueuing into qp32, state 1 hop 1
07/25/2014 11:18:14;0008;PBS_Server;Job;40670.tyrone-cluster;Job Queued at request of secpsm@tyrone-cluster, owner = secpsm@tyrone-cluster, job name = job32, queue = qp32
07/25/2014 11:18:14;0040;PBS_Server;Svr;tyrone-cluster;Scheduler was sent the command new
07/25/2014 11:18:14;0008;PBS_Server;Job;40670.tyrone-cluster;Job Modified at request of Scheduler@tyrone-cluster
07/25/2014 11:18:39;0040;PBS_Server;Svr;tyrone-cluster;Scheduler was sent the command new
07/25/2014 11:19:09;0040;PBS_Server;Svr;tyrone-cluster;Scheduler was sent the command new
07/25/2014 11:19:39;0040;PBS_Server;Svr;tyrone-cluster;Scheduler was sent the command new
07/25/2014 11:20:09;0040;PBS_Server;Svr;tyrone-cluster;Scheduler was sent the command new
07/25/2014 11:20:19;0002;PBS_Server;Svr;PBS_Server;Torque Server Version = 3.0.5, loglevel = 0
07/25/2014 11:20:39;0040;PBS_Server;Svr;tyrone-cluster;Scheduler was sent the command new
07/25/2014 11:21:09;0040;PBS_Server;Svr;tyrone-cluster;Scheduler was sent the command new
07/25/2014 11:21:39;0040;PBS_Server;Svr;tyrone-cluster;Scheduler was sent the command new
07/25/2014 11:22:09;0040;PBS_Server;Svr;tyrone-cluster;Scheduler was sent the command new
07/25/2014 11:22:39;0040;PBS_Server;Svr;tyrone-cluster;Scheduler was sent the command new
07/25/2014 11:23:10;0040;PBS_Server;Svr;tyrone-cluster;Scheduler was sent the command new
07/25/2014 11:23:40;0040;PBS_Server;Svr;tyrone-cluster;Scheduler was sent the command new
07/25/2014 11:24:10;0040;PBS_Server;Svr;tyrone-cluster;Scheduler was sent the command new
07/25/2014 11:24:40;0040;PBS_Server;Svr;tyrone-cluster;Scheduler was sent the command new
07/25/2014 11:25:10;0040;PBS_Server;Svr;tyrone-cluster;Scheduler was sent the command new
07/25/2014 11:25:19;0002;PBS_Server;Svr;PBS_Server;Torque Server Version = 3.0.5, loglevel = 0
07/25/2014 11:25:40;0040;PBS_Server;Svr;tyrone-cluster;Scheduler was sent the command new
07/25/2014 11:26:10;0040;PBS_Server;Svr;tyrone-cluster;Scheduler was sent the command new
07/25/2014 11:26:40;0040;PBS_Server;Svr;tyrone-cluster;Scheduler was sent the command new
07/25/2014 11:27:10;0040;PBS_Server;Svr;tyrone-cluster;Scheduler was sent the command new
07/25/2014 11:27:40;0040;PBS_Server;Svr;tyrone-cluster;Scheduler was sent the command new
07/25/2014 11:28:10;0040;PBS_Server;Svr;tyrone-cluster;Scheduler was sent the command new
07/25/2014 11:28:40;0040;PBS_Server;Svr;tyrone-cluster;Scheduler was sent the command new
07/25/2014 11:29:10;0040;PBS_Server;Svr;tyrone-cluster;Scheduler was sent the command new
07/25/2014 11:29:40;0040;PBS_Server;Svr;tyrone-cluster;Scheduler was sent the command new
07/25/2014 11:30:10;0040;PBS_Server;Svr;tyrone-cluster;Scheduler was sent the command new
07/25/2014 11:30:19;0002;PBS_Server;Svr;PBS_Server;Torque Server Version = 3.0.5, loglevel = 0
07/25/2014 11:30:40;0040;PBS_Server;Svr;tyrone-cluster;Scheduler was sent the command new
07/25/2014 11:31:10;0040;PBS_Server;Svr;tyrone-cluster;Scheduler was sent the command new
07/25/2014 11:31:40;0040;PBS_Server;Svr;tyrone-cluster;Scheduler was sent the command new
07/25/2014 11:32:10;0040;PBS_Server;Svr;tyrone-cluster;Scheduler was sent the command new
07/25/2014 11:32:40;0040;PBS_Server;Svr;tyrone-cluster;Scheduler was sent the command new
07/25/2014 11:33:11;0040;PBS_Server;Svr;tyrone-cluster;Scheduler was sent the command new
07/25/2014 11:33:41;0040;PBS_Server;Svr;tyrone-cluster;Scheduler was sent the command new
07/25/2014 11:34:11;0040;PBS_Server;Svr;tyrone-cluster;Scheduler was sent the command new
07/25/2014 11:34:41;0040;PBS_Server;Svr;tyrone-cluster;Scheduler was sent the command new
07/25/2014 11:35:11;0040;PBS_Server;Svr;tyrone-cluster;Scheduler was sent the command new
07/25/2014 11:35:19;0002;PBS_Server;Svr;PBS_Server;Torque Server Version = 3.0.5, loglevel = 0
07/25/2014 11:35:41;0040;PBS_Server;Svr;tyrone-cluster;Scheduler was sent the command new
07/25/2014 11:36:11;0040;PBS_Server;Svr;tyrone-cluster;Scheduler was sent the command new
07/25/2014 11:36:41;0040;PBS_Server;Svr;tyrone-cluster;Scheduler was sent the command new
07/25/2014 11:37:11;0040;PBS_Server;Svr;tyrone-cluster;Scheduler was sent the command new
07/25/2014 11:37:41;0040;PBS_Server;Svr;tyrone-cluster;Scheduler was sent the command new
07/25/2014 11:38:11;0040;PBS_Server;Svr;tyrone-cluster;Scheduler was sent the command new
07/25/2014 11:38:41;0040;PBS_Server;Svr;tyrone-cluster;Scheduler was sent the command new
07/25/2014 11:39:11;0040;PBS_Server;Svr;tyrone-cluster;Scheduler was sent the command new
07/25/2014 11:39:41;0040;PBS_Server;Svr;tyrone-cluster;Scheduler was sent the command new
07/25/2014 11:40:11;0040;PBS_Server;Svr;tyrone-cluster;Scheduler was sent the command new
07/25/2014 11:40:19;0002;PBS_Server;Svr;PBS_Server;Torque Server Version = 3.0.5, loglevel = 0
07/25/2014 11:40:41;0040;PBS_Server;Svr;tyrone-cluster;Scheduler was sent the command new
07/25/2014 11:41:11;0040;PBS_Server;Svr;tyrone-cluster;Scheduler was sent the command new
07/25/2014 11:41:41;0040;PBS_Server;Svr;tyrone-cluster;Scheduler was sent the command new
07/25/2014 11:42:12;0040;PBS_Server;Svr;tyrone-cluster;Scheduler was sent the command new
07/25/2014 11:42:42;0040;PBS_Server;Svr;tyrone-cluster;Scheduler was sent the command new
07/25/2014 11:43:12;0040;PBS_Server;Svr;tyrone-cluster;Scheduler was sent the command new
07/25/2014 11:43:42;0040;PBS_Server;Svr;tyrone-cluster;Scheduler was sent the command new
07/25/2014 11:44:12;0040;PBS_Server;Svr;tyrone-cluster;Scheduler was sent the command new
07/25/2014 11:44:42;0040;PBS_Server;Svr;tyrone-cluster;Scheduler was sent the command new
07/25/2014 11:45:12;0040;PBS_Server;Svr;tyrone-cluster;Scheduler was sent the command new
07/25/2014 11:45:19;0002;PBS_Server;Svr;PBS_Server;Torque Server Version = 3.0.5, loglevel = 0
07/25/2014 11:45:42;0040;PBS_Server;Svr;tyrone-cluster;Scheduler was sent the command new
07/25/2014 11:46:12;0040;PBS_Server;Svr;tyrone-cluster;Scheduler was sent the command new
07/25/2014 11:46:42;0040;PBS_Server;Svr;tyrone-cluster;Scheduler was sent the command new
07/25/2014 11:47:12;0040;PBS_Server;Svr;tyrone-cluster;Scheduler was sent the command new
07/25/2014 11:47:42;0040;PBS_Server;Svr;tyrone-cluster;Scheduler was sent the command new
07/25/2014 11:48:12;0040;PBS_Server;Svr;tyrone-cluster;Scheduler was sent the command new
07/25/2014 11:48:42;0040;PBS_Server;Svr;tyrone-cluster;Scheduler was sent the command new
07/25/2014 11:49:12;0040;PBS_Server;Svr;tyrone-cluster;Scheduler was sent the command new
07/25/2014 11:49:42;0040;PBS_Server;Svr;tyrone-cluster;Scheduler was sent the command new
07/25/2014 11:50:12;0040;PBS_Server;Svr;tyrone-cluster;Scheduler was sent the command new
07/25/2014 11:50:19;0002;PBS_Server;Svr;PBS_Server;Torque Server Version = 3.0.5, loglevel = 0
07/25/2014 11:50:42;0040;PBS_Server;Svr;tyrone-cluster;Scheduler was sent the command new
07/25/2014 11:51:13;0040;PBS_Server;Svr;tyrone-cluster;Scheduler was sent the command new
07/25/2014 11:51:43;0040;PBS_Server;Svr;tyrone-cluster;Scheduler was sent the command new
07/25/2014 11:52:13;0040;PBS_Server;Svr;tyrone-cluster;Scheduler was sent the command new
07/25/2014 11:52:43;0040;PBS_Server;Svr;tyrone-cluster;Scheduler was sent the command new
07/25/2014 11:53:13;0040;PBS_Server;Svr;tyrone-cluster;Scheduler was sent the command new
07/25/2014 11:53:43;0040;PBS_Server;Svr;tyrone-cluster;Scheduler was sent the command new
07/25/2014 11:54:13;0040;PBS_Server;Svr;tyrone-cluster;Scheduler was sent the command new
07/25/2014 11:54:43;0040;PBS_Server;Svr;tyrone-cluster;Scheduler was sent the command new
07/25/2014 11:55:13;0040;PBS_Server;Svr;tyrone-cluster;Scheduler was sent the command new
07/25/2014 11:55:19;0002;PBS_Server;Svr;PBS_Server;Torque Server Version = 3.0.5, loglevel = 0
07/25/2014 11:55:43;0040;PBS_Server;Svr;tyrone-cluster;Scheduler was sent the command new
07/25/2014 11:56:13;0040;PBS_Server;Svr;tyrone-cluster;Scheduler was sent the command new
07/25/2014 11:56:43;0040;PBS_Server;Svr;tyrone-cluster;Scheduler was sent the command new
07/25/2014 11:57:13;0040;PBS_Server;Svr;tyrone-cluster;Scheduler was sent the command new
07/25/2014 11:57:43;0040;PBS_Server;Svr;tyrone-cluster;Scheduler was sent the command new
07/25/2014 11:58:13;0040;PBS_Server;Svr;tyrone-cluster;Scheduler was sent the command new
07/25/2014 11:58:43;0040;PBS_Server;Svr;tyrone-cluster;Scheduler was sent the command new
07/25/2014 11:59:13;0040;PBS_Server;Svr;tyrone-cluster;Scheduler was sent the command new
07/25/2014 11:59:43;0040;PBS_Server;Svr;tyrone-cluster;Scheduler was sent the command new
07/25/2014 12:00:13;0040;PBS_Server;Svr;tyrone-cluster;Scheduler was sent the command new
07/25/2014 12:00:19;0002;PBS_Server;Svr;PBS_Server;Torque Server Version = 3.0.5, loglevel = 0
07/25/2014 12:00:44;0040;PBS_Server;Svr;tyrone-cluster;Scheduler was sent the command new
07/25/2014 12:01:14;0040;PBS_Server;Svr;tyrone-cluster;Scheduler was sent the command new
07/25/2014 12:01:44;0040;PBS_Server;Svr;tyrone-cluster;Scheduler was sent the command new
07/25/2014 12:02:14;0040;PBS_Server;Svr;tyrone-cluster;Scheduler was sent the command new
07/25/2014 12:02:44;0040;PBS_Server;Svr;tyrone-cluster;Scheduler was sent the command new
07/25/2014 12:03:14;0040;PBS_Server;Svr;tyrone-cluster;Scheduler was sent the command new
07/25/2014 12:03:44;0040;PBS_Server;Svr;tyrone-cluster;Scheduler was sent the command new
07/25/2014 12:04:14;0040;PBS_Server;Svr;tyrone-cluster;Scheduler was sent the command new
07/25/2014 12:04:44;0040;PBS_Server;Svr;tyrone-cluster;Scheduler was sent the command new
07/25/2014 12:05:14;0040;PBS_Server;Svr;tyrone-cluster;Scheduler was sent the command new
07/25/2014 12:05:19;0002;PBS_Server;Svr;PBS_Server;Torque Server Version = 3.0.5, loglevel = 0
07/25/2014 12:05:44;0040;PBS_Server;Svr;tyrone-cluster;Scheduler was sent the command new
07/25/2014 12:06:14;0040;PBS_Server;Svr;tyrone-cluster;Scheduler was sent the command new
07/25/2014 12:06:44;0040;PBS_Server;Svr;tyrone-cluster;Scheduler was sent the command new
07/25/2014 12:07:14;0040;PBS_Server;Svr;tyrone-cluster;Scheduler was sent the command new
07/25/2014 12:07:44;0040;PBS_Server;Svr;tyrone-cluster;Scheduler was sent the command new
07/25/2014 12:08:14;0040;PBS_Server;Svr;tyrone-cluster;Scheduler was sent the command new
07/25/2014 12:08:44;0040;PBS_Server;Svr;tyrone-cluster;Scheduler was sent the command new
07/25/2014 12:09:14;0040;PBS_Server;Svr;tyrone-cluster;Scheduler was sent the command new
07/25/2014 12:09:44;0040;PBS_Server;Svr;tyrone-cluster;Scheduler was sent the command new
07/25/2014 12:10:08;0100;PBS_Server;Job;40671.tyrone-cluster;enqueuing into batch, state 1 hop 1
07/25/2014 12:10:08;0100;PBS_Server;Job;40671.tyrone-cluster;dequeuing from batch, state QUEUED
07/25/2014 12:10:08;0100;PBS_Server;Job;40671.tyrone-cluster;enqueuing into qp128, state 1 hop 1
07/25/2014 12:10:08;0008;PBS_Server;Job;40671.tyrone-cluster;Job Queued at request of ipcdskp@tyrone-cluster, owner = ipcdskp@tyrone-cluster, job name = script_scan, queue = qp128
07/25/2014 12:10:08;0040;PBS_Server;Svr;tyrone-cluster;Scheduler was sent the command new
07/25/2014 12:10:09;0008;PBS_Server;Job;40671.tyrone-cluster;Job Modified at request of Scheduler@tyrone-cluster
07/25/2014 12:10:09;0008;PBS_Server;Job;40671.tyrone-cluster;Job Run at request of Scheduler@tyrone-cluster
07/25/2014 12:10:09;0040;PBS_Server;Svr;tyrone-cluster;Scheduler was sent the command recyc
07/25/2014 12:10:14;0040;PBS_Server;Svr;tyrone-cluster;Scheduler was sent the command new
07/25/2014 12:10:19;0002;PBS_Server;Svr;PBS_Server;Torque Server Version = 3.0.5, loglevel = 0
07/25/2014 12:10:45;0040;PBS_Server;Svr;tyrone-cluster;Scheduler was sent the command new
07/25/2014 12:10:57;000d;PBS_Server;Job;40671.tyrone-cluster;Not sending email: User does not want mail of this type.
07/25/2014 12:11:15;0040;PBS_Server;Svr;tyrone-cluster;Scheduler was sent the command new
07/25/2014 12:11:45;0040;PBS_Server;Svr;tyrone-cluster;Scheduler was sent the command new
07/25/2014 12:12:15;0040;PBS_Server;Svr;tyrone-cluster;Scheduler was sent the command new
07/25/2014 12:12:45;0040;PBS_Server;Svr;tyrone-cluster;Scheduler was sent the command new
07/25/2014 12:13:15;0040;PBS_Server;Svr;tyrone-cluster;Scheduler was sent the command new
07/25/2014 12:13:45;0040;PBS_Server;Svr;tyrone-cluster;Scheduler was sent the command new
07/25/2014 12:14:15;0040;PBS_Server;Svr;tyrone-cluster;Scheduler was sent the command new
07/25/2014 12:14:45;0040;PBS_Server;Svr;tyrone-cluster;Scheduler was sent the command new
07/25/2014 12:15:15;0040;PBS_Server;Svr;tyrone-cluster;Scheduler was sent the command new
07/25/2014 12:15:19;0002;PBS_Server;Svr;PBS_Server;Torque Server Version = 3.0.5, loglevel = 0
07/25/2014 12:15:45;0040;PBS_Server;Svr;tyrone-cluster;Scheduler was sent the command new
07/25/2014 12:16:15;0040;PBS_Server;Svr;tyrone-cluster;Scheduler was sent the command new
07/25/2014 12:16:45;0040;PBS_Server;Svr;tyrone-cluster;Scheduler was sent the command new
07/25/2014 12:17:15;0040;PBS_Server;Svr;tyrone-cluster;Scheduler was sent the command new
07/25/2014 12:17:45;0040;PBS_Server;Svr;tyrone-cluster;Scheduler was sent the command new
07/25/2014 12:18:15;0040;PBS_Server;Svr;tyrone-cluster;Scheduler was sent the command new
07/25/2014 12:18:45;0040;PBS_Server;Svr;tyrone-cluster;Scheduler was sent the command new
07/25/2014 12:19:15;0040;PBS_Server;Svr;tyrone-cluster;Scheduler was sent the command new
07/25/2014 12:19:46;0040;PBS_Server;Svr;tyrone-cluster;Scheduler was sent the command new
07/25/2014 12:20:16;0040;PBS_Server;Svr;tyrone-cluster;Scheduler was sent the command new
07/25/2014 12:20:19;0002;PBS_Server;Svr;PBS_Server;Torque Server Version = 3.0.5, loglevel = 0
07/25/2014 12:20:46;0040;PBS_Server;Svr;tyrone-cluster;Scheduler was sent the command new
07/25/2014 12:21:16;0040;PBS_Server;Svr;tyrone-cluster;Scheduler was sent the command new
07/25/2014 12:21:46;0040;PBS_Server;Svr;tyrone-cluster;Scheduler was sent the command new
07/25/2014 12:22:16;0040;PBS_Server;Svr;tyrone-cluster;Scheduler was sent the command new
07/25/2014 12:22:46;0040;PBS_Server;Svr;tyrone-cluster;Scheduler was sent the command new
07/25/2014 12:23:16;0040;PBS_Server;Svr;tyrone-cluster;Scheduler was sent the command new
07/25/2014 12:23:46;0040;PBS_Server;Svr;tyrone-cluster;Scheduler was sent the command new
07/25/2014 12:24:16;0040;PBS_Server;Svr;tyrone-cluster;Scheduler was sent the command new
07/25/2014 12:24:46;0040;PBS_Server;Svr;tyrone-cluster;Scheduler was sent the command new
07/25/2014 12:25:16;0040;PBS_Server;Svr;tyrone-cluster;Scheduler was sent the command new
07/25/2014 12:25:19;0002;PBS_Server;Svr;PBS_Server;Torque Server Version = 3.0.5, loglevel = 0
07/25/2014 12:25:46;0040;PBS_Server;Svr;tyrone-cluster;Scheduler was sent the command new
07/25/2014 12:26:16;0040;PBS_Server;Svr;tyrone-cluster;Scheduler was sent the command new
07/25/2014 12:26:46;0040;PBS_Server;Svr;tyrone-cluster;Scheduler was sent the command new
07/25/2014 12:27:16;0040;PBS_Server;Svr;tyrone-cluster;Scheduler was sent the command new
07/25/2014 12:27:46;0040;PBS_Server;Svr;tyrone-cluster;Scheduler was sent the command new
07/25/2014 12:28:16;0040;PBS_Server;Svr;tyrone-cluster;Scheduler was sent the command new
07/25/2014 12:28:46;0040;PBS_Server;Svr;tyrone-cluster;Scheduler was sent the command new
07/25/2014 12:29:16;0040;PBS_Server;Svr;tyrone-cluster;Scheduler was sent the command new
07/25/2014 12:29:47;0040;PBS_Server;Svr;tyrone-cluster;Scheduler was sent the command new
07/25/2014 12:30:17;0040;PBS_Server;Svr;tyrone-cluster;Scheduler was sent the command new
07/25/2014 12:30:19;0002;PBS_Server;Svr;PBS_Server;Torque Server Version = 3.0.5, loglevel = 0
07/25/2014 12:30:47;0040;PBS_Server;Svr;tyrone-cluster;Scheduler was sent the command new
07/25/2014 12:31:17;0040;PBS_Server;Svr;tyrone-cluster;Scheduler was sent the command new
07/25/2014 12:31:47;0040;PBS_Server;Svr;tyrone-cluster;Scheduler was sent the command new
07/25/2014 12:32:17;0040;PBS_Server;Svr;tyrone-cluster;Scheduler was sent the command new
07/25/2014 12:32:47;0040;PBS_Server;Svr;tyrone-cluster;Scheduler was sent the command new
07/25/2014 12:33:17;0040;PBS_Server;Svr;tyrone-cluster;Scheduler was sent the command new
07/25/2014 12:33:47;0040;PBS_Server;Svr;tyrone-cluster;Scheduler was sent the command new
07/25/2014 12:34:17;0040;PBS_Server;Svr;tyrone-cluster;Scheduler was sent the command new
07/25/2014 12:34:47;0040;PBS_Server;Svr;tyrone-cluster;Scheduler was sent the command new
07/25/2014 12:35:17;0040;PBS_Server;Svr;tyrone-cluster;Scheduler was sent the command new
07/25/2014 12:35:19;0002;PBS_Server;Svr;PBS_Server;Torque Server Version = 3.0.5, loglevel = 0
07/25/2014 12:35:47;0040;PBS_Server;Svr;tyrone-cluster;Scheduler was sent the command new
07/25/2014 12:36:17;0040;PBS_Server;Svr;tyrone-cluster;Scheduler was sent the command new
07/25/2014 12:36:47;0040;PBS_Server;Svr;tyrone-cluster;Scheduler was sent the command new
07/25/2014 12:37:17;0040;PBS_Server;Svr;tyrone-cluster;Scheduler was sent the command new
07/25/2014 12:37:47;0040;PBS_Server;Svr;tyrone-cluster;Scheduler was sent the command new
07/25/2014 12:38:17;0040;PBS_Server;Svr;tyrone-cluster;Scheduler was sent the command new
07/25/2014 12:38:47;0040;PBS_Server;Svr;tyrone-cluster;Scheduler was sent the command new
07/25/2014 12:39:18;0040;PBS_Server;Svr;tyrone-cluster;Scheduler was sent the command new
07/25/2014 12:39:48;0040;PBS_Server;Svr;tyrone-cluster;Scheduler was sent the command new
07/25/2014 12:40:18;0040;PBS_Server;Svr;tyrone-cluster;Scheduler was sent the command new
07/25/2014 12:40:19;0002;PBS_Server;Svr;PBS_Server;Torque Server Version = 3.0.5, loglevel = 0
07/25/2014 12:40:48;0040;PBS_Server;Svr;tyrone-cluster;Scheduler was sent the command new
07/25/2014 12:41:18;0040;PBS_Server;Svr;tyrone-cluster;Scheduler was sent the command new
07/25/2014 12:41:48;0040;PBS_Server;Svr;tyrone-cluster;Scheduler was sent the command new
07/25/2014 12:42:18;0040;PBS_Server;Svr;tyrone-cluster;Scheduler was sent the command new
07/25/2014 12:42:48;0040;PBS_Server;Svr;tyrone-cluster;Scheduler was sent the command new
07/25/2014 12:43:18;0040;PBS_Server;Svr;tyrone-cluster;Scheduler was sent the command new
07/25/2014 12:43:48;0040;PBS_Server;Svr;tyrone-cluster;Scheduler was sent the command new
07/25/2014 12:44:18;0040;PBS_Server;Svr;tyrone-cluster;Scheduler was sent the command new
07/25/2014 12:44:48;0040;PBS_Server;Svr;tyrone-cluster;Scheduler was sent the command new
07/25/2014 12:45:18;0040;PBS_Server;Svr;tyrone-cluster;Scheduler was sent the command new
07/25/2014 12:45:19;0002;PBS_Server;Svr;PBS_Server;Torque Server Version = 3.0.5, loglevel = 0
07/25/2014 12:45:48;0040;PBS_Server;Svr;tyrone-cluster;Scheduler was sent the command new
07/25/2014 12:46:18;0040;PBS_Server;Svr;tyrone-cluster;Scheduler was sent the command new
07/25/2014 12:46:48;0040;PBS_Server;Svr;tyrone-cluster;Scheduler was sent the command new
07/25/2014 12:47:18;0040;PBS_Server;Svr;tyrone-cluster;Scheduler was sent the command new
07/25/2014 12:47:48;0040;PBS_Server;Svr;tyrone-cluster;Scheduler was sent the command new
07/25/2014 12:48:18;0040;PBS_Server;Svr;tyrone-cluster;Scheduler was sent the command new
07/25/2014 12:48:49;0040;PBS_Server;Svr;tyrone-cluster;Scheduler was sent the command new
07/25/2014 12:49:19;0040;PBS_Server;Svr;tyrone-cluster;Scheduler was sent the command new
07/25/2014 12:49:49;0040;PBS_Server;Svr;tyrone-cluster;Scheduler was sent the command new
07/25/2014 12:50:19;0002;PBS_Server;Svr;PBS_Server;Torque Server Version = 3.0.5, loglevel = 0
07/25/2014 12:50:19;0040;PBS_Server;Svr;tyrone-cluster;Scheduler was sent the command new
07/25/2014 12:50:49;0040;PBS_Server;Svr;tyrone-cluster;Scheduler was sent the command new
07/25/2014 12:51:19;0040;PBS_Server;Svr;tyrone-cluster;Scheduler was sent the command new
07/25/2014 12:51:49;0040;PBS_Server;Svr;tyrone-cluster;Scheduler was sent the command new
07/25/2014 12:52:19;0040;PBS_Server;Svr;tyrone-cluster;Scheduler was sent the command new
07/25/2014 12:52:49;0040;PBS_Server;Svr;tyrone-cluster;Scheduler was sent the command new
07/25/2014 12:53:19;0040;PBS_Server;Svr;tyrone-cluster;Scheduler was sent the command new
07/25/2014 12:53:49;0040;PBS_Server;Svr;tyrone-cluster;Scheduler was sent the command new
07/25/2014 12:54:19;0040;PBS_Server;Svr;tyrone-cluster;Scheduler was sent the command new
07/25/2014 12:54:49;0040;PBS_Server;Svr;tyrone-cluster;Scheduler was sent the command new
07/25/2014 12:55:19;0002;PBS_Server;Svr;PBS_Server;Torque Server Version = 3.0.5, loglevel = 0
07/25/2014 12:55:19;0040;PBS_Server;Svr;tyrone-cluster;Scheduler was sent the command new
07/25/2014 12:55:49;0040;PBS_Server;Svr;tyrone-cluster;Scheduler was sent the command new
07/25/2014 12:56:19;0040;PBS_Server;Svr;tyrone-cluster;Scheduler was sent the command new
07/25/2014 12:56:49;0040;PBS_Server;Svr;tyrone-cluster;Scheduler was sent the command new
07/25/2014 12:57:19;0040;PBS_Server;Svr;tyrone-cluster;Scheduler was sent the command new
07/25/2014 12:57:49;0040;PBS_Server;Svr;tyrone-cluster;Scheduler was sent the command new
07/25/2014 12:58:20;0040;PBS_Server;Svr;tyrone-cluster;Scheduler was sent the command new
07/25/2014 12:58:50;0040;PBS_Server;Svr;tyrone-cluster;Scheduler was sent the command new
07/25/2014 12:59:20;0040;PBS_Server;Svr;tyrone-cluster;Scheduler was sent the command new
07/25/2014 12:59:50;0040;PBS_Server;Svr;tyrone-cluster;Scheduler was sent the command new
07/25/2014 13:00:19;0002;PBS_Server;Svr;PBS_Server;Torque Server Version = 3.0.5, loglevel = 0
07/25/2014 13:00:20;0040;PBS_Server;Svr;tyrone-cluster;Scheduler was sent the command new
07/25/2014 13:00:50;0040;PBS_Server;Svr;tyrone-cluster;Scheduler was sent the command new
07/25/2014 13:01:20;0040;PBS_Server;Svr;tyrone-cluster;Scheduler was sent the command new
07/25/2014 13:01:50;0040;PBS_Server;Svr;tyrone-cluster;Scheduler was sent the command new
07/25/2014 13:02:20;0040;PBS_Server;Svr;tyrone-cluster;Scheduler was sent the command new
07/25/2014 13:02:50;0040;PBS_Server;Svr;tyrone-cluster;Scheduler was sent the command new
07/25/2014 13:03:20;0040;PBS_Server;Svr;tyrone-cluster;Scheduler was sent the command new
07/25/2014 13:03:50;0040;PBS_Server;Svr;tyrone-cluster;Scheduler was sent the command new
07/25/2014 13:04:20;0040;PBS_Server;Svr;tyrone-cluster;Scheduler was sent the command new
07/25/2014 13:04:50;0040;PBS_Server;Svr;tyrone-cluster;Scheduler was sent the command new
07/25/2014 13:05:19;0002;PBS_Server;Svr;PBS_Server;Torque Server Version = 3.0.5, loglevel = 0
07/25/2014 13:05:20;0040;PBS_Server;Svr;tyrone-cluster;Scheduler was sent the command new
07/25/2014 13:05:50;0040;PBS_Server;Svr;tyrone-cluster;Scheduler was sent the command new
07/25/2014 13:06:20;0040;PBS_Server;Svr;tyrone-cluster;Scheduler was sent the command new
07/25/2014 13:06:50;0040;PBS_Server;Svr;tyrone-cluster;Scheduler was sent the command new
07/25/2014 13:07:20;0040;PBS_Server;Svr;tyrone-cluster;Scheduler was sent the command new
07/25/2014 13:07:51;0040;PBS_Server;Svr;tyrone-cluster;Scheduler was sent the command new
07/25/2014 13:08:21;0040;PBS_Server;Svr;tyrone-cluster;Scheduler was sent the command new
07/25/2014 13:08:51;0040;PBS_Server;Svr;tyrone-cluster;Scheduler was sent the command new
07/25/2014 13:09:21;0040;PBS_Server;Svr;tyrone-cluster;Scheduler was sent the command new
07/25/2014 13:09:51;0040;PBS_Server;Svr;tyrone-cluster;Scheduler was sent the command new
07/25/2014 13:10:19;0002;PBS_Server;Svr;PBS_Server;Torque Server Version = 3.0.5, loglevel = 0
07/25/2014 13:10:21;0040;PBS_Server;Svr;tyrone-cluster;Scheduler was sent the command new
07/25/2014 13:10:51;0040;PBS_Server;Svr;tyrone-cluster;Scheduler was sent the command new
07/25/2014 13:11:21;0040;PBS_Server;Svr;tyrone-cluster;Scheduler was sent the command new
07/25/2014 13:11:51;0040;PBS_Server;Svr;tyrone-cluster;Scheduler was sent the command new
07/25/2014 13:12:21;0040;PBS_Server;Svr;tyrone-cluster;Scheduler was sent the command new
07/25/2014 13:12:51;0040;PBS_Server;Svr;tyrone-cluster;Scheduler was sent the command new
07/25/2014 13:13:21;0040;PBS_Server;Svr;tyrone-cluster;Scheduler was sent the command new
07/25/2014 13:13:51;0040;PBS_Server;Svr;tyrone-cluster;Scheduler was sent the command new
07/25/2014 13:14:21;0040;PBS_Server;Svr;tyrone-cluster;Scheduler was sent the command new
07/25/2014 13:14:51;0040;PBS_Server;Svr;tyrone-cluster;Scheduler was sent the command new
07/25/2014 13:15:19;0002;PBS_Server;Svr;PBS_Server;Torque Server Version = 3.0.5, loglevel = 0
07/25/2014 13:15:21;0040;PBS_Server;Svr;tyrone-cluster;Scheduler was sent the command new
07/25/2014 13:15:51;0040;PBS_Server;Svr;tyrone-cluster;Scheduler was sent the command new
07/25/2014 13:16:21;0040;PBS_Server;Svr;tyrone-cluster;Scheduler was sent the command new
07/25/2014 13:16:51;0040;PBS_Server;Svr;tyrone-cluster;Scheduler was sent the command new
07/25/2014 13:17:22;0040;PBS_Server;Svr;tyrone-cluster;Scheduler was sent the command new
07/25/2014 13:17:52;0040;PBS_Server;Svr;tyrone-cluster;Scheduler was sent the command new
07/25/2014 13:18:22;0040;PBS_Server;Svr;tyrone-cluster;Scheduler was sent the command new
07/25/2014 13:18:52;0040;PBS_Server;Svr;tyrone-cluster;Scheduler was sent the command new
07/25/2014 13:19:22;0040;PBS_Server;Svr;tyrone-cluster;Scheduler was sent the command new
07/25/2014 13:19:52;0040;PBS_Server;Svr;tyrone-cluster;Scheduler was sent the command new
07/25/2014 13:20:19;0002;PBS_Server;Svr;PBS_Server;Torque Server Version = 3.0.5, loglevel = 0
07/25/2014 13:20:22;0040;PBS_Server;Svr;tyrone-cluster;Scheduler was sent the command new
07/25/2014 13:20:52;0040;PBS_Server;Svr;tyrone-cluster;Scheduler was sent the command new
07/25/2014 13:21:22;0040;PBS_Server;Svr;tyrone-cluster;Scheduler was sent the command new
07/25/2014 13:21:52;0040;PBS_Server;Svr;tyrone-cluster;Scheduler was sent the command new
07/25/2014 13:22:22;0040;PBS_Server;Svr;tyrone-cluster;Scheduler was sent the command new
07/25/2014 13:22:52;0040;PBS_Server;Svr;tyrone-cluster;Scheduler was sent the command new
07/25/2014 13:23:22;0040;PBS_Server;Svr;tyrone-cluster;Scheduler was sent the command new
07/25/2014 13:23:52;0040;PBS_Server;Svr;tyrone-cluster;Scheduler was sent the command new
07/25/2014 13:24:22;0040;PBS_Server;Svr;tyrone-cluster;Scheduler was sent the command new
07/25/2014 13:24:52;0040;PBS_Server;Svr;tyrone-cluster;Scheduler was sent the command new
07/25/2014 13:25:19;0002;PBS_Server;Svr;PBS_Server;Torque Server Version = 3.0.5, loglevel = 0
07/25/2014 13:25:22;0040;PBS_Server;Svr;tyrone-cluster;Scheduler was sent the command new
07/25/2014 13:25:52;0040;PBS_Server;Svr;tyrone-cluster;Scheduler was sent the command new
07/25/2014 13:26:22;0040;PBS_Server;Svr;tyrone-cluster;Scheduler was sent the command new
07/25/2014 13:26:53;0040;PBS_Server;Svr;tyrone-cluster;Scheduler was sent the command new
07/25/2014 13:27:23;0040;PBS_Server;Svr;tyrone-cluster;Scheduler was sent the command new
07/25/2014 13:27:53;0040;PBS_Server;Svr;tyrone-cluster;Scheduler was sent the command new
07/25/2014 13:28:23;0040;PBS_Server;Svr;tyrone-cluster;Scheduler was sent the command new
07/25/2014 13:28:53;0040;PBS_Server;Svr;tyrone-cluster;Scheduler was sent the command new
07/25/2014 13:29:23;0040;PBS_Server;Svr;tyrone-cluster;Scheduler was sent the command new
07/25/2014 13:29:53;0040;PBS_Server;Svr;tyrone-cluster;Scheduler was sent the command new
07/25/2014 13:30:19;0002;PBS_Server;Svr;PBS_Server;Torque Server Version = 3.0.5, loglevel = 0
07/25/2014 13:30:23;0040;PBS_Server;Svr;tyrone-cluster;Scheduler was sent the command new
07/25/2014 13:30:53;0040;PBS_Server;Svr;tyrone-cluster;Scheduler was sent the command new
07/25/2014 13:31:23;0040;PBS_Server;Svr;tyrone-cluster;Scheduler was sent the command new
07/25/2014 13:31:53;0040;PBS_Server;Svr;tyrone-cluster;Scheduler was sent the command new
07/25/2014 13:32:23;0040;PBS_Server;Svr;tyrone-cluster;Scheduler was sent the command new
07/25/2014 13:32:53;0040;PBS_Server;Svr;tyrone-cluster;Scheduler was sent the command new
07/25/2014 13:33:23;0040;PBS_Server;Svr;tyrone-cluster;Scheduler was sent the command new
07/25/2014 13:33:53;0040;PBS_Server;Svr;tyrone-cluster;Scheduler was sent the command new
07/25/2014 13:34:23;0040;PBS_Server;Svr;tyrone-cluster;Scheduler was sent the command new
07/25/2014 13:34:53;0040;PBS_Server;Svr;tyrone-cluster;Scheduler was sent the command new
07/25/2014 13:35:19;0002;PBS_Server;Svr;PBS_Server;Torque Server Version = 3.0.5, loglevel = 0
07/25/2014 13:35:23;0040;PBS_Server;Svr;tyrone-cluster;Scheduler was sent the command new
07/25/2014 13:35:53;0040;PBS_Server;Svr;tyrone-cluster;Scheduler was sent the command new
07/25/2014 13:36:24;0040;PBS_Server;Svr;tyrone-cluster;Scheduler was sent the command new
07/25/2014 13:36:54;0040;PBS_Server;Svr;tyrone-cluster;Scheduler was sent the command new
07/25/2014 13:37:24;0040;PBS_Server;Svr;tyrone-cluster;Scheduler was sent the command new
07/25/2014 13:37:54;0040;PBS_Server;Svr;tyrone-cluster;Scheduler was sent the command new
07/25/2014 13:38:24;0040;PBS_Server;Svr;tyrone-cluster;Scheduler was sent the command new
07/25/2014 13:38:54;0040;PBS_Server;Svr;tyrone-cluster;Scheduler was sent the command new
07/25/2014 13:39:24;0040;PBS_Server;Svr;tyrone-cluster;Scheduler was sent the command new
07/25/2014 13:39:54;0040;PBS_Server;Svr;tyrone-cluster;Scheduler was sent the command new
07/25/2014 13:40:19;0002;PBS_Server;Svr;PBS_Server;Torque Server Version = 3.0.5, loglevel = 0
07/25/2014 13:40:24;0040;PBS_Server;Svr;tyrone-cluster;Scheduler was sent the command new
07/25/2014 13:40:54;0040;PBS_Server;Svr;tyrone-cluster;Scheduler was sent the command new
07/25/2014 13:41:24;0040;PBS_Server;Svr;tyrone-cluster;Scheduler was sent the command new
07/25/2014 13:41:54;0040;PBS_Server;Svr;tyrone-cluster;Scheduler was sent the command new
07/25/2014 13:42:24;0040;PBS_Server;Svr;tyrone-cluster;Scheduler was sent the command new
07/25/2014 13:42:54;0040;PBS_Server;Svr;tyrone-cluster;Scheduler was sent the command new
07/25/2014 13:43:24;0040;PBS_Server;Svr;tyrone-cluster;Scheduler was sent the command new
07/25/2014 13:43:54;0040;PBS_Server;Svr;tyrone-cluster;Scheduler was sent the command new
07/25/2014 13:44:24;0040;PBS_Server;Svr;tyrone-cluster;Scheduler was sent the command new
07/25/2014 13:44:54;0040;PBS_Server;Svr;tyrone-cluster;Scheduler was sent the command new
07/25/2014 13:45:19;0002;PBS_Server;Svr;PBS_Server;Torque Server Version = 3.0.5, loglevel = 0
07/25/2014 13:45:24;0040;PBS_Server;Svr;tyrone-cluster;Scheduler was sent the command new
07/25/2014 13:45:55;0040;PBS_Server;Svr;tyrone-cluster;Scheduler was sent the command new
07/25/2014 13:46:25;0040;PBS_Server;Svr;tyrone-cluster;Scheduler was sent the command new
07/25/2014 13:46:55;0040;PBS_Server;Svr;tyrone-cluster;Scheduler was sent the command new
07/25/2014 13:47:25;0040;PBS_Server;Svr;tyrone-cluster;Scheduler was sent the command new
07/25/2014 13:47:55;0040;PBS_Server;Svr;tyrone-cluster;Scheduler was sent the command new
07/25/2014 13:48:25;0040;PBS_Server;Svr;tyrone-cluster;Scheduler was sent the command new
07/25/2014 13:48:55;0040;PBS_Server;Svr;tyrone-cluster;Scheduler was sent the command new
07/25/2014 13:49:25;0040;PBS_Server;Svr;tyrone-cluster;Scheduler was sent the command new
07/25/2014 13:49:55;0040;PBS_Server;Svr;tyrone-cluster;Scheduler was sent the command new
07/25/2014 13:50:19;0002;PBS_Server;Svr;PBS_Server;Torque Server Version = 3.0.5, loglevel = 0
07/25/2014 13:50:25;0040;PBS_Server;Svr;tyrone-cluster;Scheduler was sent the command new
07/25/2014 13:50:55;0040;PBS_Server;Svr;tyrone-cluster;Scheduler was sent the command new
07/25/2014 13:51:25;0040;PBS_Server;Svr;tyrone-cluster;Scheduler was sent the command new
07/25/2014 13:51:55;0040;PBS_Server;Svr;tyrone-cluster;Scheduler was sent the command new
07/25/2014 13:52:25;0040;PBS_Server;Svr;tyrone-cluster;Scheduler was sent the command new
07/25/2014 13:52:55;0040;PBS_Server;Svr;tyrone-cluster;Scheduler was sent the command new
07/25/2014 13:53:25;0040;PBS_Server;Svr;tyrone-cluster;Scheduler was sent the command new
07/25/2014 13:53:55;0040;PBS_Server;Svr;tyrone-cluster;Scheduler was sent the command new
07/25/2014 13:54:25;0040;PBS_Server;Svr;tyrone-cluster;Scheduler was sent the command new
07/25/2014 13:54:55;0040;PBS_Server;Svr;tyrone-cluster;Scheduler was sent the command new
07/25/2014 13:55:19;0002;PBS_Server;Svr;PBS_Server;Torque Server Version = 3.0.5, loglevel = 0
07/25/2014 13:55:25;0040;PBS_Server;Svr;tyrone-cluster;Scheduler was sent the command new
07/25/2014 13:55:56;0040;PBS_Server;Svr;tyrone-cluster;Scheduler was sent the command new
07/25/2014 13:56:26;0040;PBS_Server;Svr;tyrone-cluster;Scheduler was sent the command new
07/25/2014 13:56:56;0040;PBS_Server;Svr;tyrone-cluster;Scheduler was sent the command new
07/25/2014 13:57:26;0040;PBS_Server;Svr;tyrone-cluster;Scheduler was sent the command new
07/25/2014 13:57:56;0040;PBS_Server;Svr;tyrone-cluster;Scheduler was sent the command new
07/25/2014 13:58:26;0040;PBS_Server;Svr;tyrone-cluster;Scheduler was sent the command new
07/25/2014 13:58:56;0040;PBS_Server;Svr;tyrone-cluster;Scheduler was sent the command new
07/25/2014 13:59:26;0040;PBS_Server;Svr;tyrone-cluster;Scheduler was sent the command new
07/25/2014 13:59:56;0040;PBS_Server;Svr;tyrone-cluster;Scheduler was sent the command new
07/25/2014 14:00:19;0002;PBS_Server;Svr;PBS_Server;Torque Server Version = 3.0.5, loglevel = 0
07/25/2014 14:00:26;0040;PBS_Server;Svr;tyrone-cluster;Scheduler was sent the command new
07/25/2014 14:00:56;0040;PBS_Server;Svr;tyrone-cluster;Scheduler was sent the command new
07/25/2014 14:01:26;0040;PBS_Server;Svr;tyrone-cluster;Scheduler was sent the command new
07/25/2014 14:01:56;0040;PBS_Server;Svr;tyrone-cluster;Scheduler was sent the command new
07/25/2014 14:02:26;0040;PBS_Server;Svr;tyrone-cluster;Scheduler was sent the command new
07/25/2014 14:02:56;0040;PBS_Server;Svr;tyrone-cluster;Scheduler was sent the command new
07/25/2014 14:03:26;0040;PBS_Server;Svr;tyrone-cluster;Scheduler was sent the command new
07/25/2014 14:03:56;0040;PBS_Server;Svr;tyrone-cluster;Scheduler was sent the command new
07/25/2014 14:04:26;0040;PBS_Server;Svr;tyrone-cluster;Scheduler was sent the command new
07/25/2014 14:04:57;0040;PBS_Server;Svr;tyrone-cluster;Scheduler was sent the command new
07/25/2014 14:05:19;0002;PBS_Server;Svr;PBS_Server;Torque Server Version = 3.0.5, loglevel = 0
07/25/2014 14:05:27;0040;PBS_Server;Svr;tyrone-cluster;Scheduler was sent the command new
07/25/2014 14:05:57;0040;PBS_Server;Svr;tyrone-cluster;Scheduler was sent the command new
07/25/2014 14:06:27;0040;PBS_Server;Svr;tyrone-cluster;Scheduler was sent the command new
07/25/2014 14:06:57;0040;PBS_Server;Svr;tyrone-cluster;Scheduler was sent the command new
07/25/2014 14:07:27;0040;PBS_Server;Svr;tyrone-cluster;Scheduler was sent the command new
07/25/2014 14:07:57;0040;PBS_Server;Svr;tyrone-cluster;Scheduler was sent the command new
07/25/2014 14:08:27;0040;PBS_Server;Svr;tyrone-cluster;Scheduler was sent the command new
07/25/2014 14:08:57;0040;PBS_Server;Svr;tyrone-cluster;Scheduler was sent the command new
07/25/2014 14:09:27;0040;PBS_Server;Svr;tyrone-cluster;Scheduler was sent the command new
07/25/2014 14:09:57;0040;PBS_Server;Svr;tyrone-cluster;Scheduler was sent the command new
07/25/2014 14:10:19;0002;PBS_Server;Svr;PBS_Server;Torque Server Version = 3.0.5, loglevel = 0
07/25/2014 14:10:27;0040;PBS_Server;Svr;tyrone-cluster;Scheduler was sent the command new
07/25/2014 14:10:57;0040;PBS_Server;Svr;tyrone-cluster;Scheduler was sent the command new
07/25/2014 14:11:27;0040;PBS_Server;Svr;tyrone-cluster;Scheduler was sent the command new
07/25/2014 14:11:57;0040;PBS_Server;Svr;tyrone-cluster;Scheduler was sent the command new
07/25/2014 14:12:27;0040;PBS_Server;Svr;tyrone-cluster;Scheduler was sent the command new
07/25/2014 14:12:57;0040;PBS_Server;Svr;tyrone-cluster;Scheduler was sent the command new
07/25/2014 14:13:27;0040;PBS_Server;Svr;tyrone-cluster;Scheduler was sent the command new
07/25/2014 14:13:57;0040;PBS_Server;Svr;tyrone-cluster;Scheduler was sent the command new
07/25/2014 14:14:28;0040;PBS_Server;Svr;tyrone-cluster;Scheduler was sent the command new
07/25/2014 14:14:58;0040;PBS_Server;Svr;tyrone-cluster;Scheduler was sent the command new
07/25/2014 14:15:19;0002;PBS_Server;Svr;PBS_Server;Torque Server Version = 3.0.5, loglevel = 0
07/25/2014 14:15:28;0040;PBS_Server;Svr;tyrone-cluster;Scheduler was sent the command new
07/25/2014 14:15:58;0040;PBS_Server;Svr;tyrone-cluster;Scheduler was sent the command new
07/25/2014 14:16:28;0040;PBS_Server;Svr;tyrone-cluster;Scheduler was sent the command new
07/25/2014 14:16:58;0040;PBS_Server;Svr;tyrone-cluster;Scheduler was sent the command new
07/25/2014 14:17:28;0040;PBS_Server;Svr;tyrone-cluster;Scheduler was sent the command new
07/25/2014 14:17:58;0040;PBS_Server;Svr;tyrone-cluster;Scheduler was sent the command new
07/25/2014 14:18:28;0040;PBS_Server;Svr;tyrone-cluster;Scheduler was sent the command new
07/25/2014 14:18:58;0040;PBS_Server;Svr;tyrone-cluster;Scheduler was sent the command new
07/25/2014 14:19:28;0040;PBS_Server;Svr;tyrone-cluster;Scheduler was sent the command new
07/25/2014 14:19:58;0040;PBS_Server;Svr;tyrone-cluster;Scheduler was sent the command new
07/25/2014 14:20:19;0002;PBS_Server;Svr;PBS_Server;Torque Server Version = 3.0.5, loglevel = 0
07/25/2014 14:20:28;0040;PBS_Server;Svr;tyrone-cluster;Scheduler was sent the command new
07/25/2014 14:20:58;0040;PBS_Server;Svr;tyrone-cluster;Scheduler was sent the command new
07/25/2014 14:21:28;0040;PBS_Server;Svr;tyrone-cluster;Scheduler was sent the command new
07/25/2014 14:21:58;0040;PBS_Server;Svr;tyrone-cluster;Scheduler was sent the command new
07/25/2014 14:22:28;0040;PBS_Server;Svr;tyrone-cluster;Scheduler was sent the command new
07/25/2014 14:22:58;0040;PBS_Server;Svr;tyrone-cluster;Scheduler was sent the command new
07/25/2014 14:23:28;0040;PBS_Server;Svr;tyrone-cluster;Scheduler was sent the command new
07/25/2014 14:23:58;0040;PBS_Server;Svr;tyrone-cluster;Scheduler was sent the command new
07/25/2014 14:24:28;0040;PBS_Server;Svr;tyrone-cluster;Scheduler was sent the command new
07/25/2014 14:24:59;0040;PBS_Server;Svr;tyrone-cluster;Scheduler was sent the command new
07/25/2014 14:25:19;0002;PBS_Server;Svr;PBS_Server;Torque Server Version = 3.0.5, loglevel = 0
07/25/2014 14:25:29;0040;PBS_Server;Svr;tyrone-cluster;Scheduler was sent the command new
07/25/2014 14:25:59;0040;PBS_Server;Svr;tyrone-cluster;Scheduler was sent the command new
07/25/2014 14:26:29;0040;PBS_Server;Svr;tyrone-cluster;Scheduler was sent the command new
07/25/2014 14:26:59;0040;PBS_Server;Svr;tyrone-cluster;Scheduler was sent the command new
07/25/2014 14:27:29;0040;PBS_Server;Svr;tyrone-cluster;Scheduler was sent the command new
07/25/2014 14:27:59;0040;PBS_Server;Svr;tyrone-cluster;Scheduler was sent the command new
07/25/2014 14:28:29;0040;PBS_Server;Svr;tyrone-cluster;Scheduler was sent the command new
07/25/2014 14:28:59;0040;PBS_Server;Svr;tyrone-cluster;Scheduler was sent the command new
07/25/2014 14:29:29;0040;PBS_Server;Svr;tyrone-cluster;Scheduler was sent the command new
07/25/2014 14:29:59;0040;PBS_Server;Svr;tyrone-cluster;Scheduler was sent the command new
07/25/2014 14:30:19;0002;PBS_Server;Svr;PBS_Server;Torque Server Version = 3.0.5, loglevel = 0
07/25/2014 14:30:29;0040;PBS_Server;Svr;tyrone-cluster;Scheduler was sent the command new
07/25/2014 14:30:59;0040;PBS_Server;Svr;tyrone-cluster;Scheduler was sent the command new
07/25/2014 14:31:29;0040;PBS_Server;Svr;tyrone-cluster;Scheduler was sent the command new
07/25/2014 14:31:59;0040;PBS_Server;Svr;tyrone-cluster;Scheduler was sent the command new
07/25/2014 14:32:29;0040;PBS_Server;Svr;tyrone-cluster;Scheduler was sent the command new
07/25/2014 14:32:59;0040;PBS_Server;Svr;tyrone-cluster;Scheduler was sent the command new
07/25/2014 14:33:30;0040;PBS_Server;Svr;tyrone-cluster;Scheduler was sent the command new
07/25/2014 14:34:00;0040;PBS_Server;Svr;tyrone-cluster;Scheduler was sent the command new
07/25/2014 14:34:30;0040;PBS_Server;Svr;tyrone-cluster;Scheduler was sent the command new
07/25/2014 14:35:00;0040;PBS_Server;Svr;tyrone-cluster;Scheduler was sent the command new
07/25/2014 14:35:19;0002;PBS_Server;Svr;PBS_Server;Torque Server Version = 3.0.5, loglevel = 0
07/25/2014 14:35:30;0040;PBS_Server;Svr;tyrone-cluster;Scheduler was sent the command new
07/25/2014 14:36:00;0040;PBS_Server;Svr;tyrone-cluster;Scheduler was sent the command new
07/25/2014 14:36:30;0040;PBS_Server;Svr;tyrone-cluster;Scheduler was sent the command new
07/25/2014 14:37:00;0040;PBS_Server;Svr;tyrone-cluster;Scheduler was sent the command new
07/25/2014 14:37:30;0040;PBS_Server;Svr;tyrone-cluster;Scheduler was sent the command new
07/25/2014 14:38:00;0040;PBS_Server;Svr;tyrone-cluster;Scheduler was sent the command new
07/25/2014 14:38:30;0040;PBS_Server;Svr;tyrone-cluster;Scheduler was sent the command new
07/25/2014 14:39:00;0040;PBS_Server;Svr;tyrone-cluster;Scheduler was sent the command new
07/25/2014 14:39:30;0040;PBS_Server;Svr;tyrone-cluster;Scheduler was sent the command new
07/25/2014 14:40:00;0040;PBS_Server;Svr;tyrone-cluster;Scheduler was sent the command new
07/25/2014 14:40:19;0002;PBS_Server;Svr;PBS_Server;Torque Server Version = 3.0.5, loglevel = 0
07/25/2014 14:40:30;0040;PBS_Server;Svr;tyrone-cluster;Scheduler was sent the command new
07/25/2014 14:41:00;0040;PBS_Server;Svr;tyrone-cluster;Scheduler was sent the command new
07/25/2014 14:41:30;0040;PBS_Server;Svr;tyrone-cluster;Scheduler was sent the command new
07/25/2014 14:42:00;0040;PBS_Server;Svr;tyrone-cluster;Scheduler was sent the command new
07/25/2014 14:42:30;0040;PBS_Server;Svr;tyrone-cluster;Scheduler was sent the command new
07/25/2014 14:43:01;0040;PBS_Server;Svr;tyrone-cluster;Scheduler was sent the command new
07/25/2014 14:43:31;0040;PBS_Server;Svr;tyrone-cluster;Scheduler was sent the command new
07/25/2014 14:44:01;0040;PBS_Server;Svr;tyrone-cluster;Scheduler was sent the command new
07/25/2014 14:44:31;0040;PBS_Server;Svr;tyrone-cluster;Scheduler was sent the command new
07/25/2014 14:45:01;0040;PBS_Server;Svr;tyrone-cluster;Scheduler was sent the command new
07/25/2014 14:45:19;0002;PBS_Server;Svr;PBS_Server;Torque Server Version = 3.0.5, loglevel = 0
07/25/2014 14:45:31;0040;PBS_Server;Svr;tyrone-cluster;Scheduler was sent the command new
07/25/2014 14:46:01;0040;PBS_Server;Svr;tyrone-cluster;Scheduler was sent the command new
07/25/2014 14:46:31;0040;PBS_Server;Svr;tyrone-cluster;Scheduler was sent the command new
07/25/2014 14:47:01;0040;PBS_Server;Svr;tyrone-cluster;Scheduler was sent the command new
07/25/2014 14:47:31;0040;PBS_Server;Svr;tyrone-cluster;Scheduler was sent the command new
07/25/2014 14:48:01;0040;PBS_Server;Svr;tyrone-cluster;Scheduler was sent the command new
07/25/2014 14:48:31;0040;PBS_Server;Svr;tyrone-cluster;Scheduler was sent the command new
07/25/2014 14:49:01;0040;PBS_Server;Svr;tyrone-cluster;Scheduler was sent the command new
07/25/2014 14:49:31;0040;PBS_Server;Svr;tyrone-cluster;Scheduler was sent the command new
07/25/2014 14:50:01;0040;PBS_Server;Svr;tyrone-cluster;Scheduler was sent the command new
07/25/2014 14:50:19;0002;PBS_Server;Svr;PBS_Server;Torque Server Version = 3.0.5, loglevel = 0
07/25/2014 14:50:31;0040;PBS_Server;Svr;tyrone-cluster;Scheduler was sent the command new
07/25/2014 14:51:01;0040;PBS_Server;Svr;tyrone-cluster;Scheduler was sent the command new
07/25/2014 14:51:31;0040;PBS_Server;Svr;tyrone-cluster;Scheduler was sent the command new
07/25/2014 14:52:01;0040;PBS_Server;Svr;tyrone-cluster;Scheduler was sent the command new
07/25/2014 14:52:31;0040;PBS_Server;Svr;tyrone-cluster;Scheduler was sent the command new
07/25/2014 14:53:02;0040;PBS_Server;Svr;tyrone-cluster;Scheduler was sent the command new
07/25/2014 14:53:32;0040;PBS_Server;Svr;tyrone-cluster;Scheduler was sent the command new
07/25/2014 14:54:02;0040;PBS_Server;Svr;tyrone-cluster;Scheduler was sent the command new
07/25/2014 14:54:32;0040;PBS_Server;Svr;tyrone-cluster;Scheduler was sent the command new
07/25/2014 14:55:02;0040;PBS_Server;Svr;tyrone-cluster;Scheduler was sent the command new
07/25/2014 14:55:19;0002;PBS_Server;Svr;PBS_Server;Torque Server Version = 3.0.5, loglevel = 0
07/25/2014 14:55:32;0040;PBS_Server;Svr;tyrone-cluster;Scheduler was sent the command new
07/25/2014 14:56:02;0040;PBS_Server;Svr;tyrone-cluster;Scheduler was sent the command new
07/25/2014 14:56:32;0040;PBS_Server;Svr;tyrone-cluster;Scheduler was sent the command new
07/25/2014 14:57:02;0040;PBS_Server;Svr;tyrone-cluster;Scheduler was sent the command new
07/25/2014 14:57:32;0040;PBS_Server;Svr;tyrone-cluster;Scheduler was sent the command new
07/25/2014 14:58:02;0040;PBS_Server;Svr;tyrone-cluster;Scheduler was sent the command new
07/25/2014 14:58:32;0040;PBS_Server;Svr;tyrone-cluster;Scheduler was sent the command new
07/25/2014 14:59:02;0040;PBS_Server;Svr;tyrone-cluster;Scheduler was sent the command new
07/25/2014 14:59:13;0100;PBS_Server;Job;40672.tyrone-cluster;enqueuing into batch, state 1 hop 1
07/25/2014 14:59:13;0100;PBS_Server;Job;40672.tyrone-cluster;dequeuing from batch, state QUEUED
07/25/2014 14:59:13;0100;PBS_Server;Job;40672.tyrone-cluster;enqueuing into idqueue, state 1 hop 1
07/25/2014 14:59:13;0008;PBS_Server;Job;40672.tyrone-cluster;Job Queued at request of phynagmp@tyrone-cluster, owner = phynagmp@tyrone-cluster, job name = poshit1, queue = idqueue
07/25/2014 14:59:13;0040;PBS_Server;Svr;tyrone-cluster;Scheduler was sent the command new
07/25/2014 14:59:13;0008;PBS_Server;Job;40672.tyrone-cluster;Job Modified at request of Scheduler@tyrone-cluster
07/25/2014 14:59:13;0008;PBS_Server;Job;40672.tyrone-cluster;Job Run at request of Scheduler@tyrone-cluster
07/25/2014 14:59:13;0040;PBS_Server;Svr;tyrone-cluster;Scheduler was sent the command recyc
07/25/2014 14:59:13;000d;PBS_Server;Job;40672.tyrone-cluster;Not sending email: User does not want mail of this type.
07/25/2014 14:59:32;0040;PBS_Server;Svr;tyrone-cluster;Scheduler was sent the command new
07/25/2014 15:00:02;0040;PBS_Server;Svr;tyrone-cluster;Scheduler was sent the command new
07/25/2014 15:00:19;0002;PBS_Server;Svr;PBS_Server;Torque Server Version = 3.0.5, loglevel = 0
07/25/2014 15:00:32;0040;PBS_Server;Svr;tyrone-cluster;Scheduler was sent the command new
07/25/2014 15:01:02;0040;PBS_Server;Svr;tyrone-cluster;Scheduler was sent the command new
07/25/2014 15:01:32;0040;PBS_Server;Svr;tyrone-cluster;Scheduler was sent the command new
07/25/2014 15:02:02;0040;PBS_Server;Svr;tyrone-cluster;Scheduler was sent the command new
07/25/2014 15:02:33;0040;PBS_Server;Svr;tyrone-cluster;Scheduler was sent the command new
07/25/2014 15:03:03;0040;PBS_Server;Svr;tyrone-cluster;Scheduler was sent the command new
07/25/2014 15:03:32;0040;PBS_Server;Svr;tyrone-cluster;Scheduler was sent the command new
07/25/2014 15:03:49;000d;PBS_Server;Job;40672.tyrone-cluster;Not sending email: User does not want mail of this type.
07/25/2014 15:03:49;0010;PBS_Server;Job;40672.tyrone-cluster;Exit_status=0 resources_used.cput=00:31:56 resources_used.mem=260164kb resources_used.vmem=692204kb resources_used.walltime=00:04:36
07/25/2014 15:03:49;0008;PBS_Server;Job;NULL;on_job_exit valid pjob: 0x1f0c0f0 (substate=50)
07/25/2014 15:03:49;0008;PBS_Server;Job;NULL;on_job_exit valid pjob: 0x1f0c0f0 (substate=51)
07/25/2014 15:03:49;0008;PBS_Server;Job;NULL;on_job_exit valid pjob: 0x1f0c0f0 (substate=51)
07/25/2014 15:03:49;0008;PBS_Server;Job;NULL;on_job_exit valid pjob: 0x1f0c0f0 (substate=53)
07/25/2014 15:03:49;0100;PBS_Server;Job;40672.tyrone-cluster;dequeuing from idqueue, state COMPLETE
07/25/2014 15:03:49;0040;PBS_Server;Svr;tyrone-cluster;Scheduler was sent the command term
07/25/2014 15:04:03;0040;PBS_Server;Svr;tyrone-cluster;Scheduler was sent the command new
07/25/2014 15:04:33;0040;PBS_Server;Svr;tyrone-cluster;Scheduler was sent the command new
07/25/2014 15:05:02;0040;PBS_Server;Svr;tyrone-cluster;Scheduler was sent the command new
07/25/2014 15:05:19;0002;PBS_Server;Svr;PBS_Server;Torque Server Version = 3.0.5, loglevel = 0
07/25/2014 15:05:33;0040;PBS_Server;Svr;tyrone-cluster;Scheduler was sent the command new
07/25/2014 15:06:03;0040;PBS_Server;Svr;tyrone-cluster;Scheduler was sent the command new
07/25/2014 15:06:33;0040;PBS_Server;Svr;tyrone-cluster;Scheduler was sent the command new
07/25/2014 15:07:03;0040;PBS_Server;Svr;tyrone-cluster;Scheduler was sent the command new
07/25/2014 15:07:33;0040;PBS_Server;Svr;tyrone-cluster;Scheduler was sent the command new
07/25/2014 15:08:03;0040;PBS_Server;Svr;tyrone-cluster;Scheduler was sent the command new
07/25/2014 15:08:33;0040;PBS_Server;Svr;tyrone-cluster;Scheduler was sent the command new
07/25/2014 15:09:03;0040;PBS_Server;Svr;tyrone-cluster;Scheduler was sent the command new
07/25/2014 15:09:33;0040;PBS_Server;Svr;tyrone-cluster;Scheduler was sent the command new
07/25/2014 15:10:03;0040;PBS_Server;Svr;tyrone-cluster;Scheduler was sent the command new
07/25/2014 15:10:19;0002;PBS_Server;Svr;PBS_Server;Torque Server Version = 3.0.5, loglevel = 0
07/25/2014 15:10:33;0040;PBS_Server;Svr;tyrone-cluster;Scheduler was sent the command new
07/25/2014 15:11:04;0040;PBS_Server;Svr;tyrone-cluster;Scheduler was sent the command new
07/25/2014 15:11:34;0040;PBS_Server;Svr;tyrone-cluster;Scheduler was sent the command new
07/25/2014 15:12:04;0040;PBS_Server;Svr;tyrone-cluster;Scheduler was sent the command new
07/25/2014 15:12:34;0040;PBS_Server;Svr;tyrone-cluster;Scheduler was sent the command new
07/25/2014 15:13:04;0040;PBS_Server;Svr;tyrone-cluster;Scheduler was sent the command new
07/25/2014 15:13:34;0040;PBS_Server;Svr;tyrone-cluster;Scheduler was sent the command new
07/25/2014 15:14:04;0040;PBS_Server;Svr;tyrone-cluster;Scheduler was sent the command new
07/25/2014 15:14:34;0040;PBS_Server;Svr;tyrone-cluster;Scheduler was sent the command new
07/25/2014 15:15:04;0040;PBS_Server;Svr;tyrone-cluster;Scheduler was sent the command new
07/25/2014 15:15:19;0002;PBS_Server;Svr;PBS_Server;Torque Server Version = 3.0.5, loglevel = 0
07/25/2014 15:15:34;0040;PBS_Server;Svr;tyrone-cluster;Scheduler was sent the command new
07/25/2014 15:16:04;0040;PBS_Server;Svr;tyrone-cluster;Scheduler was sent the command new
07/25/2014 15:16:34;0040;PBS_Server;Svr;tyrone-cluster;Scheduler was sent the command new
07/25/2014 15:17:04;0040;PBS_Server;Svr;tyrone-cluster;Scheduler was sent the command new
07/25/2014 15:17:34;0040;PBS_Server;Svr;tyrone-cluster;Scheduler was sent the command new
07/25/2014 15:18:04;0040;PBS_Server;Svr;tyrone-cluster;Scheduler was sent the command new
07/25/2014 15:18:34;0040;PBS_Server;Svr;tyrone-cluster;Scheduler was sent the command new
07/25/2014 15:19:04;0040;PBS_Server;Svr;tyrone-cluster;Scheduler was sent the command new
07/25/2014 15:19:34;0040;PBS_Server;Svr;tyrone-cluster;Scheduler was sent the command new
07/25/2014 15:20:01;0100;PBS_Server;Job;40673.tyrone-cluster;enqueuing into batch, state 1 hop 1
07/25/2014 15:20:01;0100;PBS_Server;Job;40673.tyrone-cluster;dequeuing from batch, state QUEUED
07/25/2014 15:20:01;0100;PBS_Server;Job;40673.tyrone-cluster;enqueuing into qp64, state 1 hop 1
07/25/2014 15:20:01;0008;PBS_Server;Job;40673.tyrone-cluster;Job Queued at request of mbuhrid@tyrone-cluster, owner = mbuhrid@tyrone-cluster, job name = jobname, queue = qp64
07/25/2014 15:20:01;0040;PBS_Server;Svr;tyrone-cluster;Scheduler was sent the command new
07/25/2014 15:20:01;0008;PBS_Server;Job;40673.tyrone-cluster;Job Modified at request of Scheduler@tyrone-cluster
07/25/2014 15:20:01;0008;PBS_Server;Job;40673.tyrone-cluster;Job Run at request of Scheduler@tyrone-cluster
07/25/2014 15:20:01;0040;PBS_Server;Svr;tyrone-cluster;Scheduler was sent the command recyc
07/25/2014 15:20:02;000d;PBS_Server;Job;40673.tyrone-cluster;Not sending email: User does not want mail of this type.
07/25/2014 15:20:02;0010;PBS_Server;Job;40673.tyrone-cluster;Exit_status=1 resources_used.cput=00:00:00 resources_used.mem=800kb resources_used.vmem=13624kb resources_used.walltime=00:00:01
07/25/2014 15:20:02;0008;PBS_Server;Job;NULL;on_job_exit valid pjob: 0x1f14010 (substate=50)
07/25/2014 15:20:02;0008;PBS_Server;Job;NULL;on_job_exit valid pjob: 0x1f14010 (substate=51)
07/25/2014 15:20:04;0040;PBS_Server;Svr;tyrone-cluster;Scheduler was sent the command new
07/25/2014 15:20:10;0008;PBS_Server;Job;NULL;on_job_exit valid pjob: 0x1f14010 (substate=51)
07/25/2014 15:20:10;000d;PBS_Server;Job;40673.tyrone-cluster;Post job file processing error; job 40673.tyrone-cluster on host tyrone-node8/31+tyrone-node8/30+tyrone-node8/29+tyrone-node8/28+tyrone-node8/27+tyrone-node8/26+tyrone-node8/25+tyrone-node8/24+tyrone-node8/23+tyrone-node8/22+tyrone-node8/21+tyrone-node8/20+tyrone-node8/19+tyrone-node8/18+tyrone-node8/17+tyrone-node8/16+tyrone-node8/15+tyrone-node8/14+tyrone-node8/13+tyrone-node8/12+tyrone-node8/11+tyrone-node8/10+tyrone-node8/9+tyrone-node8/8+tyrone-node8/7+tyrone-node8/6+tyrone-node8/5+tyrone-node8/4+tyrone-node8/3+tyrone-node8/2+tyrone-node8/1+tyrone-node8/0+tyrone-node7/31+tyrone-node7/30+tyrone-node7/29+tyrone-node7/28+tyrone-node7/27+tyrone-node7/26+tyrone-node7/25+tyrone-node7/24+tyrone-node7/23+tyrone-node7/22+tyrone-node7/21+tyrone-node7/20+tyrone-node7/19+tyrone-node7/18+tyrone-node7/17+tyrone-node7/16+tyrone-node7/15+tyrone-node7/14+tyrone-node7/13+tyrone-node7/12+tyrone-node7/11+tyrone-node7/10+tyrone-node7/9+tyrone-node7/8+tyrone-node7/7+tyrone-node7/6+tyrone-node7/5+tyrone-node7/4+tyrone-node7/3+tyrone-node7/2+tyrone-node7/1+tyrone-node7/0
07/25/2014 15:20:10;0008;PBS_Server;Job;NULL;on_job_exit valid pjob: 0x1f14010 (substate=53)
07/25/2014 15:20:10;0100;PBS_Server;Job;40673.tyrone-cluster;dequeuing from qp64, state COMPLETE
07/25/2014 15:20:10;0040;PBS_Server;Svr;tyrone-cluster;Scheduler was sent the command term
07/25/2014 15:20:19;0002;PBS_Server;Svr;PBS_Server;Torque Server Version = 3.0.5, loglevel = 0
07/25/2014 15:20:35;0040;PBS_Server;Svr;tyrone-cluster;Scheduler was sent the command new
07/25/2014 15:21:05;0040;PBS_Server;Svr;tyrone-cluster;Scheduler was sent the command new
07/25/2014 15:21:30;0100;PBS_Server;Job;40674.tyrone-cluster;enqueuing into batch, state 1 hop 1
07/25/2014 15:21:30;0100;PBS_Server;Job;40674.tyrone-cluster;dequeuing from batch, state QUEUED
07/25/2014 15:21:30;0100;PBS_Server;Job;40674.tyrone-cluster;enqueuing into qp64, state 1 hop 1
07/25/2014 15:21:30;0008;PBS_Server;Job;40674.tyrone-cluster;Job Queued at request of mbuhrid@tyrone-cluster, owner = mbuhrid@tyrone-cluster, job name = job, queue = qp64
07/25/2014 15:21:30;0040;PBS_Server;Svr;tyrone-cluster;Scheduler was sent the command new
07/25/2014 15:21:30;0008;PBS_Server;Job;40674.tyrone-cluster;Job Modified at request of Scheduler@tyrone-cluster
07/25/2014 15:21:30;0008;PBS_Server;Job;40674.tyrone-cluster;Job Run at request of Scheduler@tyrone-cluster
07/25/2014 15:21:30;0040;PBS_Server;Svr;tyrone-cluster;Scheduler was sent the command recyc
07/25/2014 15:21:31;000d;PBS_Server;Job;40674.tyrone-cluster;Not sending email: User does not want mail of this type.
07/25/2014 15:21:31;0010;PBS_Server;Job;40674.tyrone-cluster;Exit_status=1 resources_used.cput=00:00:00 resources_used.mem=800kb resources_used.vmem=13624kb resources_used.walltime=00:00:01
07/25/2014 15:21:31;0008;PBS_Server;Job;NULL;on_job_exit valid pjob: 0x1f14010 (substate=50)
07/25/2014 15:21:31;0008;PBS_Server;Job;NULL;on_job_exit valid pjob: 0x1f14010 (substate=51)
07/25/2014 15:21:35;0040;PBS_Server;Svr;tyrone-cluster;Scheduler was sent the command new
07/25/2014 15:21:40;0008;PBS_Server;Job;NULL;on_job_exit valid pjob: 0x1f14010 (substate=51)
07/25/2014 15:21:40;000d;PBS_Server;Job;40674.tyrone-cluster;Post job file processing error; job 40674.tyrone-cluster on host tyrone-node8/31+tyrone-node8/30+tyrone-node8/29+tyrone-node8/28+tyrone-node8/27+tyrone-node8/26+tyrone-node8/25+tyrone-node8/24+tyrone-node8/23+tyrone-node8/22+tyrone-node8/21+tyrone-node8/20+tyrone-node8/19+tyrone-node8/18+tyrone-node8/17+tyrone-node8/16+tyrone-node8/15+tyrone-node8/14+tyrone-node8/13+tyrone-node8/12+tyrone-node8/11+tyrone-node8/10+tyrone-node8/9+tyrone-node8/8+tyrone-node8/7+tyrone-node8/6+tyrone-node8/5+tyrone-node8/4+tyrone-node8/3+tyrone-node8/2+tyrone-node8/1+tyrone-node8/0+tyrone-node7/31+tyrone-node7/30+tyrone-node7/29+tyrone-node7/28+tyrone-node7/27+tyrone-node7/26+tyrone-node7/25+tyrone-node7/24+tyrone-node7/23+tyrone-node7/22+tyrone-node7/21+tyrone-node7/20+tyrone-node7/19+tyrone-node7/18+tyrone-node7/17+tyrone-node7/16+tyrone-node7/15+tyrone-node7/14+tyrone-node7/13+tyrone-node7/12+tyrone-node7/11+tyrone-node7/10+tyrone-node7/9+tyrone-node7/8+tyrone-node7/7+tyrone-node7/6+tyrone-node7/5+tyrone-node7/4+tyrone-node7/3+tyrone-node7/2+tyrone-node7/1+tyrone-node7/0
07/25/2014 15:21:40;0008;PBS_Server;Job;NULL;on_job_exit valid pjob: 0x1f14010 (substate=53)
07/25/2014 15:21:40;0100;PBS_Server;Job;40674.tyrone-cluster;dequeuing from qp64, state COMPLETE
07/25/2014 15:21:40;0040;PBS_Server;Svr;tyrone-cluster;Scheduler was sent the command term
07/25/2014 15:22:05;0040;PBS_Server;Svr;tyrone-cluster;Scheduler was sent the command new
07/25/2014 15:22:35;0040;PBS_Server;Svr;tyrone-cluster;Scheduler was sent the command new
07/25/2014 15:22:39;0100;PBS_Server;Job;40675.tyrone-cluster;enqueuing into batch, state 1 hop 1
07/25/2014 15:22:39;0100;PBS_Server;Job;40675.tyrone-cluster;dequeuing from batch, state QUEUED
07/25/2014 15:22:39;0100;PBS_Server;Job;40675.tyrone-cluster;enqueuing into qp64, state 1 hop 1
07/25/2014 15:22:39;0008;PBS_Server;Job;40675.tyrone-cluster;Job Queued at request of mbuhrid@tyrone-cluster, owner = mbuhrid@tyrone-cluster, job name = job, queue = qp64
07/25/2014 15:22:39;0040;PBS_Server;Svr;tyrone-cluster;Scheduler was sent the command new
07/25/2014 15:22:39;0008;PBS_Server;Job;40675.tyrone-cluster;Job Modified at request of Scheduler@tyrone-cluster
07/25/2014 15:22:39;0008;PBS_Server;Job;40675.tyrone-cluster;Job Run at request of Scheduler@tyrone-cluster
07/25/2014 15:22:39;0040;PBS_Server;Svr;tyrone-cluster;Scheduler was sent the command recyc
07/25/2014 15:22:40;000d;PBS_Server;Job;40675.tyrone-cluster;Not sending email: User does not want mail of this type.
07/25/2014 15:22:40;0010;PBS_Server;Job;40675.tyrone-cluster;Exit_status=1 resources_used.cput=00:00:00 resources_used.mem=800kb resources_used.vmem=13624kb resources_used.walltime=00:00:01
07/25/2014 15:22:40;0008;PBS_Server;Job;NULL;on_job_exit valid pjob: 0x1f14010 (substate=50)
07/25/2014 15:22:40;0008;PBS_Server;Job;NULL;on_job_exit valid pjob: 0x1f14010 (substate=51)
07/25/2014 15:22:49;0008;PBS_Server;Job;NULL;on_job_exit valid pjob: 0x1f14010 (substate=51)
07/25/2014 15:22:49;000d;PBS_Server;Job;40675.tyrone-cluster;Post job file processing error; job 40675.tyrone-cluster on host tyrone-node8/31+tyrone-node8/30+tyrone-node8/29+tyrone-node8/28+tyrone-node8/27+tyrone-node8/26+tyrone-node8/25+tyrone-node8/24+tyrone-node8/23+tyrone-node8/22+tyrone-node8/21+tyrone-node8/20+tyrone-node8/19+tyrone-node8/18+tyrone-node8/17+tyrone-node8/16+tyrone-node8/15+tyrone-node8/14+tyrone-node8/13+tyrone-node8/12+tyrone-node8/11+tyrone-node8/10+tyrone-node8/9+tyrone-node8/8+tyrone-node8/7+tyrone-node8/6+tyrone-node8/5+tyrone-node8/4+tyrone-node8/3+tyrone-node8/2+tyrone-node8/1+tyrone-node8/0+tyrone-node7/31+tyrone-node7/30+tyrone-node7/29+tyrone-node7/28+tyrone-node7/27+tyrone-node7/26+tyrone-node7/25+tyrone-node7/24+tyrone-node7/23+tyrone-node7/22+tyrone-node7/21+tyrone-node7/20+tyrone-node7/19+tyrone-node7/18+tyrone-node7/17+tyrone-node7/16+tyrone-node7/15+tyrone-node7/14+tyrone-node7/13+tyrone-node7/12+tyrone-node7/11+tyrone-node7/10+tyrone-node7/9+tyrone-node7/8+tyrone-node7/7+tyrone-node7/6+tyrone-node7/5+tyrone-node7/4+tyrone-node7/3+tyrone-node7/2+tyrone-node7/1+tyrone-node7/0
07/25/2014 15:22:49;0008;PBS_Server;Job;NULL;on_job_exit valid pjob: 0x1f14010 (substate=53)
07/25/2014 15:22:49;0100;PBS_Server;Job;40675.tyrone-cluster;dequeuing from qp64, state COMPLETE
07/25/2014 15:22:49;0040;PBS_Server;Svr;tyrone-cluster;Scheduler was sent the command term
07/25/2014 15:23:05;0040;PBS_Server;Svr;tyrone-cluster;Scheduler was sent the command new
07/25/2014 15:23:35;0040;PBS_Server;Svr;tyrone-cluster;Scheduler was sent the command new
07/25/2014 15:23:53;0100;PBS_Server;Job;40676.tyrone-cluster;enqueuing into batch, state 1 hop 1
07/25/2014 15:23:53;0100;PBS_Server;Job;40676.tyrone-cluster;dequeuing from batch, state QUEUED
07/25/2014 15:23:53;0100;PBS_Server;Job;40676.tyrone-cluster;enqueuing into qp64, state 1 hop 1
07/25/2014 15:23:53;0008;PBS_Server;Job;40676.tyrone-cluster;Job Queued at request of mbuhrid@tyrone-cluster, owner = mbuhrid@tyrone-cluster, job name = job, queue = qp64
07/25/2014 15:23:53;0040;PBS_Server;Svr;tyrone-cluster;Scheduler was sent the command new
07/25/2014 15:23:53;0008;PBS_Server;Job;40676.tyrone-cluster;Job Modified at request of Scheduler@tyrone-cluster
07/25/2014 15:23:53;0008;PBS_Server;Job;40676.tyrone-cluster;Job Run at request of Scheduler@tyrone-cluster
07/25/2014 15:23:53;0040;PBS_Server;Svr;tyrone-cluster;Scheduler was sent the command recyc
07/25/2014 15:23:53;000d;PBS_Server;Job;40676.tyrone-cluster;Not sending email: User does not want mail of this type.
07/25/2014 15:23:53;0010;PBS_Server;Job;40676.tyrone-cluster;Exit_status=2 resources_used.cput=00:00:00 resources_used.mem=796kb resources_used.vmem=13624kb resources_used.walltime=00:00:01
07/25/2014 15:23:53;0008;PBS_Server;Job;NULL;on_job_exit valid pjob: 0x1f14010 (substate=50)
07/25/2014 15:23:53;0008;PBS_Server;Job;NULL;on_job_exit valid pjob: 0x1f14010 (substate=51)
07/25/2014 15:24:02;0008;PBS_Server;Job;NULL;on_job_exit valid pjob: 0x1f14010 (substate=51)
07/25/2014 15:24:02;000d;PBS_Server;Job;40676.tyrone-cluster;Post job file processing error; job 40676.tyrone-cluster on host tyrone-node8/31+tyrone-node8/30+tyrone-node8/29+tyrone-node8/28+tyrone-node8/27+tyrone-node8/26+tyrone-node8/25+tyrone-node8/24+tyrone-node8/23+tyrone-node8/22+tyrone-node8/21+tyrone-node8/20+tyrone-node8/19+tyrone-node8/18+tyrone-node8/17+tyrone-node8/16+tyrone-node8/15+tyrone-node8/14+tyrone-node8/13+tyrone-node8/12+tyrone-node8/11+tyrone-node8/10+tyrone-node8/9+tyrone-node8/8+tyrone-node8/7+tyrone-node8/6+tyrone-node8/5+tyrone-node8/4+tyrone-node8/3+tyrone-node8/2+tyrone-node8/1+tyrone-node8/0+tyrone-node7/31+tyrone-node7/30+tyrone-node7/29+tyrone-node7/28+tyrone-node7/27+tyrone-node7/26+tyrone-node7/25+tyrone-node7/24+tyrone-node7/23+tyrone-node7/22+tyrone-node7/21+tyrone-node7/20+tyrone-node7/19+tyrone-node7/18+tyrone-node7/17+tyrone-node7/16+tyrone-node7/15+tyrone-node7/14+tyrone-node7/13+tyrone-node7/12+tyrone-node7/11+tyrone-node7/10+tyrone-node7/9+tyrone-node7/8+tyrone-node7/7+tyrone-node7/6+tyrone-node7/5+tyrone-node7/4+tyrone-node7/3+tyrone-node7/2+tyrone-node7/1+tyrone-node7/0
07/25/2014 15:24:02;0008;PBS_Server;Job;NULL;on_job_exit valid pjob: 0x1f14010 (substate=53)
07/25/2014 15:24:02;0100;PBS_Server;Job;40676.tyrone-cluster;dequeuing from qp64, state COMPLETE
07/25/2014 15:24:02;0040;PBS_Server;Svr;tyrone-cluster;Scheduler was sent the command term
07/25/2014 15:24:05;0040;PBS_Server;Svr;tyrone-cluster;Scheduler was sent the command new
07/25/2014 15:24:16;0100;PBS_Server;Job;40677.tyrone-cluster;enqueuing into batch, state 1 hop 1
07/25/2014 15:24:16;0100;PBS_Server;Job;40677.tyrone-cluster;dequeuing from batch, state QUEUED
07/25/2014 15:24:16;0100;PBS_Server;Job;40677.tyrone-cluster;enqueuing into qp64, state 1 hop 1
07/25/2014 15:24:16;0008;PBS_Server;Job;40677.tyrone-cluster;Job Queued at request of mbuhrid@tyrone-cluster, owner = mbuhrid@tyrone-cluster, job name = job, queue = qp64
07/25/2014 15:24:16;0040;PBS_Server;Svr;tyrone-cluster;Scheduler was sent the command new
07/25/2014 15:24:16;0008;PBS_Server;Job;40677.tyrone-cluster;Job Modified at request of Scheduler@tyrone-cluster
07/25/2014 15:24:16;0008;PBS_Server;Job;40677.tyrone-cluster;Job Run at request of Scheduler@tyrone-cluster
07/25/2014 15:24:16;0040;PBS_Server;Svr;tyrone-cluster;Scheduler was sent the command recyc
07/25/2014 15:24:17;000d;PBS_Server;Job;40677.tyrone-cluster;Not sending email: User does not want mail of this type.
07/25/2014 15:24:17;0010;PBS_Server;Job;40677.tyrone-cluster;Exit_status=2 resources_used.cput=00:00:00 resources_used.mem=796kb resources_used.vmem=13624kb resources_used.walltime=00:00:00
07/25/2014 15:24:17;0008;PBS_Server;Job;NULL;on_job_exit valid pjob: 0x1f14010 (substate=50)
07/25/2014 15:24:17;0008;PBS_Server;Job;NULL;on_job_exit valid pjob: 0x1f14010 (substate=51)
07/25/2014 15:24:25;0008;PBS_Server;Job;NULL;on_job_exit valid pjob: 0x1f14010 (substate=51)
07/25/2014 15:24:25;000d;PBS_Server;Job;40677.tyrone-cluster;Post job file processing error; job 40677.tyrone-cluster on host tyrone-node8/31+tyrone-node8/30+tyrone-node8/29+tyrone-node8/28+tyrone-node8/27+tyrone-node8/26+tyrone-node8/25+tyrone-node8/24+tyrone-node8/23+tyrone-node8/22+tyrone-node8/21+tyrone-node8/20+tyrone-node8/19+tyrone-node8/18+tyrone-node8/17+tyrone-node8/16+tyrone-node8/15+tyrone-node8/14+tyrone-node8/13+tyrone-node8/12+tyrone-node8/11+tyrone-node8/10+tyrone-node8/9+tyrone-node8/8+tyrone-node8/7+tyrone-node8/6+tyrone-node8/5+tyrone-node8/4+tyrone-node8/3+tyrone-node8/2+tyrone-node8/1+tyrone-node8/0+tyrone-node7/31+tyrone-node7/30+tyrone-node7/29+tyrone-node7/28+tyrone-node7/27+tyrone-node7/26+tyrone-node7/25+tyrone-node7/24+tyrone-node7/23+tyrone-node7/22+tyrone-node7/21+tyrone-node7/20+tyrone-node7/19+tyrone-node7/18+tyrone-node7/17+tyrone-node7/16+tyrone-node7/15+tyrone-node7/14+tyrone-node7/13+tyrone-node7/12+tyrone-node7/11+tyrone-node7/10+tyrone-node7/9+tyrone-node7/8+tyrone-node7/7+tyrone-node7/6+tyrone-node7/5+tyrone-node7/4+tyrone-node7/3+tyrone-node7/2+tyrone-node7/1+tyrone-node7/0
07/25/2014 15:24:25;0008;PBS_Server;Job;NULL;on_job_exit valid pjob: 0x1f14010 (substate=53)
07/25/2014 15:24:25;0100;PBS_Server;Job;40677.tyrone-cluster;dequeuing from qp64, state COMPLETE
07/25/2014 15:24:25;0040;PBS_Server;Svr;tyrone-cluster;Scheduler was sent the command term
07/25/2014 15:24:35;0040;PBS_Server;Svr;tyrone-cluster;Scheduler was sent the command new
07/25/2014 15:25:05;0040;PBS_Server;Svr;tyrone-cluster;Scheduler was sent the command new
07/25/2014 15:25:19;0002;PBS_Server;Svr;PBS_Server;Torque Server Version = 3.0.5, loglevel = 0
07/25/2014 15:25:35;0040;PBS_Server;Svr;tyrone-cluster;Scheduler was sent the command new
07/25/2014 15:26:05;0040;PBS_Server;Svr;tyrone-cluster;Scheduler was sent the command new
07/25/2014 15:26:35;0040;PBS_Server;Svr;tyrone-cluster;Scheduler was sent the command new
07/25/2014 15:27:03;0100;PBS_Server;Job;40678.tyrone-cluster;enqueuing into batch, state 1 hop 1
07/25/2014 15:27:03;0100;PBS_Server;Job;40678.tyrone-cluster;dequeuing from batch, state QUEUED
07/25/2014 15:27:03;0100;PBS_Server;Job;40678.tyrone-cluster;enqueuing into qp64, state 1 hop 1
07/25/2014 15:27:03;0008;PBS_Server;Job;40678.tyrone-cluster;Job Queued at request of mbuhrid@tyrone-cluster, owner = mbuhrid@tyrone-cluster, job name = job, queue = qp64
07/25/2014 15:27:03;0040;PBS_Server;Svr;tyrone-cluster;Scheduler was sent the command new
07/25/2014 15:27:03;0008;PBS_Server;Job;40678.tyrone-cluster;Job Modified at request of Scheduler@tyrone-cluster
07/25/2014 15:27:03;0008;PBS_Server;Job;40678.tyrone-cluster;Job Run at request of Scheduler@tyrone-cluster
07/25/2014 15:27:03;0040;PBS_Server;Svr;tyrone-cluster;Scheduler was sent the command recyc
07/25/2014 15:27:04;000d;PBS_Server;Job;40678.tyrone-cluster;Not sending email: User does not want mail of this type.
07/25/2014 15:27:04;0010;PBS_Server;Job;40678.tyrone-cluster;Exit_status=2 resources_used.cput=00:00:00 resources_used.mem=800kb resources_used.vmem=13624kb resources_used.walltime=00:00:00
07/25/2014 15:27:04;0008;PBS_Server;Job;NULL;on_job_exit valid pjob: 0x1f14010 (substate=50)
07/25/2014 15:27:04;0008;PBS_Server;Job;NULL;on_job_exit valid pjob: 0x1f14010 (substate=51)
07/25/2014 15:27:05;0040;PBS_Server;Svr;tyrone-cluster;Scheduler was sent the command new
07/25/2014 15:27:12;0008;PBS_Server;Job;NULL;on_job_exit valid pjob: 0x1f14010 (substate=51)
07/25/2014 15:27:12;000d;PBS_Server;Job;40678.tyrone-cluster;Post job file processing error; job 40678.tyrone-cluster on host tyrone-node8/31+tyrone-node8/30+tyrone-node8/29+tyrone-node8/28+tyrone-node8/27+tyrone-node8/26+tyrone-node8/25+tyrone-node8/24+tyrone-node8/23+tyrone-node8/22+tyrone-node8/21+tyrone-node8/20+tyrone-node8/19+tyrone-node8/18+tyrone-node8/17+tyrone-node8/16+tyrone-node8/15+tyrone-node8/14+tyrone-node8/13+tyrone-node8/12+tyrone-node8/11+tyrone-node8/10+tyrone-node8/9+tyrone-node8/8+tyrone-node8/7+tyrone-node8/6+tyrone-node8/5+tyrone-node8/4+tyrone-node8/3+tyrone-node8/2+tyrone-node8/1+tyrone-node8/0+tyrone-node7/31+tyrone-node7/30+tyrone-node7/29+tyrone-node7/28+tyrone-node7/27+tyrone-node7/26+tyrone-node7/25+tyrone-node7/24+tyrone-node7/23+tyrone-node7/22+tyrone-node7/21+tyrone-node7/20+tyrone-node7/19+tyrone-node7/18+tyrone-node7/17+tyrone-node7/16+tyrone-node7/15+tyrone-node7/14+tyrone-node7/13+tyrone-node7/12+tyrone-node7/11+tyrone-node7/10+tyrone-node7/9+tyrone-node7/8+tyrone-node7/7+tyrone-node7/6+tyrone-node7/5+tyrone-node7/4+tyrone-node7/3+tyrone-node7/2+tyrone-node7/1+tyrone-node7/0
07/25/2014 15:27:12;0008;PBS_Server;Job;NULL;on_job_exit valid pjob: 0x1f14010 (substate=53)
07/25/2014 15:27:12;0100;PBS_Server;Job;40678.tyrone-cluster;dequeuing from qp64, state COMPLETE
07/25/2014 15:27:12;0040;PBS_Server;Svr;tyrone-cluster;Scheduler was sent the command term
07/25/2014 15:27:35;0040;PBS_Server;Svr;tyrone-cluster;Scheduler was sent the command new
07/25/2014 15:28:05;0040;PBS_Server;Svr;tyrone-cluster;Scheduler was sent the command new
07/25/2014 15:28:35;0040;PBS_Server;Svr;tyrone-cluster;Scheduler was sent the command new
07/25/2014 15:29:05;0040;PBS_Server;Svr;tyrone-cluster;Scheduler was sent the command new
07/25/2014 15:29:35;0040;PBS_Server;Svr;tyrone-cluster;Scheduler was sent the command new
07/25/2014 15:30:06;0040;PBS_Server;Svr;tyrone-cluster;Scheduler was sent the command new
07/25/2014 15:30:19;0002;PBS_Server;Svr;PBS_Server;Torque Server Version = 3.0.5, loglevel = 0
07/25/2014 15:30:36;0040;PBS_Server;Svr;tyrone-cluster;Scheduler was sent the command new
07/25/2014 15:31:06;0040;PBS_Server;Svr;tyrone-cluster;Scheduler was sent the command new
07/25/2014 15:31:36;0040;PBS_Server;Svr;tyrone-cluster;Scheduler was sent the command new
07/25/2014 15:32:06;0040;PBS_Server;Svr;tyrone-cluster;Scheduler was sent the command new
07/25/2014 15:32:36;0040;PBS_Server;Svr;tyrone-cluster;Scheduler was sent the command new
07/25/2014 15:33:06;0040;PBS_Server;Svr;tyrone-cluster;Scheduler was sent the command new
07/25/2014 15:33:36;0040;PBS_Server;Svr;tyrone-cluster;Scheduler was sent the command new
07/25/2014 15:34:06;0040;PBS_Server;Svr;tyrone-cluster;Scheduler was sent the command new
07/25/2014 15:34:36;0040;PBS_Server;Svr;tyrone-cluster;Scheduler was sent the command new
07/25/2014 15:35:06;0040;PBS_Server;Svr;tyrone-cluster;Scheduler was sent the command new
07/25/2014 15:35:19;0002;PBS_Server;Svr;PBS_Server;Torque Server Version = 3.0.5, loglevel = 0
07/25/2014 15:35:36;0040;PBS_Server;Svr;tyrone-cluster;Scheduler was sent the command new
07/25/2014 15:36:06;0040;PBS_Server;Svr;tyrone-cluster;Scheduler was sent the command new
07/25/2014 15:36:36;0040;PBS_Server;Svr;tyrone-cluster;Scheduler was sent the command new
07/25/2014 15:37:06;0040;PBS_Server;Svr;tyrone-cluster;Scheduler was sent the command new
07/25/2014 15:37:36;0040;PBS_Server;Svr;tyrone-cluster;Scheduler was sent the command new
07/25/2014 15:38:06;0040;PBS_Server;Svr;tyrone-cluster;Scheduler was sent the command new
07/25/2014 15:38:36;0040;PBS_Server;Svr;tyrone-cluster;Scheduler was sent the command new
07/25/2014 15:39:06;0040;PBS_Server;Svr;tyrone-cluster;Scheduler was sent the command new
07/25/2014 15:39:37;0040;PBS_Server;Svr;tyrone-cluster;Scheduler was sent the command new
07/25/2014 15:40:07;0040;PBS_Server;Svr;tyrone-cluster;Scheduler was sent the command new
07/25/2014 15:40:19;0002;PBS_Server;Svr;PBS_Server;Torque Server Version = 3.0.5, loglevel = 0
07/25/2014 15:40:37;0040;PBS_Server;Svr;tyrone-cluster;Scheduler was sent the command new
07/25/2014 15:41:07;0040;PBS_Server;Svr;tyrone-cluster;Scheduler was sent the command new
07/25/2014 15:41:37;0040;PBS_Server;Svr;tyrone-cluster;Scheduler was sent the command new
07/25/2014 15:42:07;0040;PBS_Server;Svr;tyrone-cluster;Scheduler was sent the command new
07/25/2014 15:42:37;0040;PBS_Server;Svr;tyrone-cluster;Scheduler was sent the command new
07/25/2014 15:43:07;0040;PBS_Server;Svr;tyrone-cluster;Scheduler was sent the command new
07/25/2014 15:43:37;0040;PBS_Server;Svr;tyrone-cluster;Scheduler was sent the command new
07/25/2014 15:44:07;0040;PBS_Server;Svr;tyrone-cluster;Scheduler was sent the command new
07/25/2014 15:44:37;0040;PBS_Server;Svr;tyrone-cluster;Scheduler was sent the command new
07/25/2014 15:45:07;0040;PBS_Server;Svr;tyrone-cluster;Scheduler was sent the command new
07/25/2014 15:45:19;0002;PBS_Server;Svr;PBS_Server;Torque Server Version = 3.0.5, loglevel = 0
07/25/2014 15:45:37;0040;PBS_Server;Svr;tyrone-cluster;Scheduler was sent the command new
07/25/2014 15:46:07;0040;PBS_Server;Svr;tyrone-cluster;Scheduler was sent the command new
07/25/2014 15:46:37;0040;PBS_Server;Svr;tyrone-cluster;Scheduler was sent the command new
07/25/2014 15:47:07;0040;PBS_Server;Svr;tyrone-cluster;Scheduler was sent the command new
07/25/2014 15:47:37;0040;PBS_Server;Svr;tyrone-cluster;Scheduler was sent the command new
07/25/2014 15:48:07;0040;PBS_Server;Svr;tyrone-cluster;Scheduler was sent the command new
07/25/2014 15:48:37;0040;PBS_Server;Svr;tyrone-cluster;Scheduler was sent the command new
07/25/2014 15:49:08;0040;PBS_Server;Svr;tyrone-cluster;Scheduler was sent the command new
07/25/2014 15:49:22;0100;PBS_Server;Job;40679.tyrone-cluster;enqueuing into batch, state 1 hop 1
07/25/2014 15:49:22;0100;PBS_Server;Job;40679.tyrone-cluster;dequeuing from batch, state QUEUED
07/25/2014 15:49:22;0100;PBS_Server;Job;40679.tyrone-cluster;enqueuing into qp64, state 1 hop 1
07/25/2014 15:49:22;0008;PBS_Server;Job;40679.tyrone-cluster;Job Queued at request of mbuhrid@tyrone-cluster, owner = mbuhrid@tyrone-cluster, job name = job, queue = qp64
07/25/2014 15:49:22;0040;PBS_Server;Svr;tyrone-cluster;Scheduler was sent the command new
07/25/2014 15:49:22;0008;PBS_Server;Job;40679.tyrone-cluster;Job Modified at request of Scheduler@tyrone-cluster
07/25/2014 15:49:22;0008;PBS_Server;Job;40679.tyrone-cluster;Job Run at request of Scheduler@tyrone-cluster
07/25/2014 15:49:22;0040;PBS_Server;Svr;tyrone-cluster;Scheduler was sent the command recyc
07/25/2014 15:49:23;000d;PBS_Server;Job;40679.tyrone-cluster;Not sending email: User does not want mail of this type.
07/25/2014 15:49:23;0010;PBS_Server;Job;40679.tyrone-cluster;Exit_status=0 resources_used.cput=00:00:00 resources_used.mem=800kb resources_used.vmem=13624kb resources_used.walltime=00:00:00
07/25/2014 15:49:23;0008;PBS_Server;Job;NULL;on_job_exit valid pjob: 0x1f14010 (substate=50)
07/25/2014 15:49:23;0008;PBS_Server;Job;NULL;on_job_exit valid pjob: 0x1f14010 (substate=51)
07/25/2014 15:49:23;0008;PBS_Server;Job;NULL;on_job_exit valid pjob: 0x1f14010 (substate=51)
07/25/2014 15:49:23;0008;PBS_Server;Job;NULL;on_job_exit valid pjob: 0x1f14010 (substate=53)
07/25/2014 15:49:23;0100;PBS_Server;Job;40679.tyrone-cluster;dequeuing from qp64, state COMPLETE
07/25/2014 15:49:23;0040;PBS_Server;Svr;tyrone-cluster;Scheduler was sent the command term
07/25/2014 15:49:38;0040;PBS_Server;Svr;tyrone-cluster;Scheduler was sent the command new
07/25/2014 15:50:01;0100;PBS_Server;Job;40680.tyrone-cluster;enqueuing into batch, state 1 hop 1
07/25/2014 15:50:01;0100;PBS_Server;Job;40680.tyrone-cluster;dequeuing from batch, state QUEUED
07/25/2014 15:50:01;0100;PBS_Server;Job;40680.tyrone-cluster;enqueuing into qp64, state 1 hop 1
07/25/2014 15:50:01;0008;PBS_Server;Job;40680.tyrone-cluster;Job Queued at request of mbuhrid@tyrone-cluster, owner = mbuhrid@tyrone-cluster, job name = job, queue = qp64
07/25/2014 15:50:01;0040;PBS_Server;Svr;tyrone-cluster;Scheduler was sent the command new
07/25/2014 15:50:01;0008;PBS_Server;Job;40680.tyrone-cluster;Job Modified at request of Scheduler@tyrone-cluster
07/25/2014 15:50:01;0008;PBS_Server;Job;40680.tyrone-cluster;Job Run at request of Scheduler@tyrone-cluster
07/25/2014 15:50:01;0040;PBS_Server;Svr;tyrone-cluster;Scheduler was sent the command recyc
07/25/2014 15:50:01;000d;PBS_Server;Job;40680.tyrone-cluster;Not sending email: User does not want mail of this type.
07/25/2014 15:50:01;0010;PBS_Server;Job;40680.tyrone-cluster;Exit_status=2 resources_used.cput=00:00:00 resources_used.mem=796kb resources_used.vmem=13624kb resources_used.walltime=00:00:01
07/25/2014 15:50:01;0008;PBS_Server;Job;NULL;on_job_exit valid pjob: 0x1f14010 (substate=50)
07/25/2014 15:50:01;0008;PBS_Server;Job;NULL;on_job_exit valid pjob: 0x1f14010 (substate=51)
07/25/2014 15:50:01;0008;PBS_Server;Job;NULL;on_job_exit valid pjob: 0x1f14010 (substate=51)
07/25/2014 15:50:01;0008;PBS_Server;Job;NULL;on_job_exit valid pjob: 0x1f14010 (substate=53)
07/25/2014 15:50:01;0100;PBS_Server;Job;40680.tyrone-cluster;dequeuing from qp64, state COMPLETE
07/25/2014 15:50:01;0040;PBS_Server;Svr;tyrone-cluster;Scheduler was sent the command term
07/25/2014 15:50:08;0040;PBS_Server;Svr;tyrone-cluster;Scheduler was sent the command new
07/25/2014 15:50:19;0002;PBS_Server;Svr;PBS_Server;Torque Server Version = 3.0.5, loglevel = 0
07/25/2014 15:50:30;0100;PBS_Server;Job;40681.tyrone-cluster;enqueuing into batch, state 1 hop 1
07/25/2014 15:50:30;0100;PBS_Server;Job;40681.tyrone-cluster;dequeuing from batch, state QUEUED
07/25/2014 15:50:30;0100;PBS_Server;Job;40681.tyrone-cluster;enqueuing into qp64, state 1 hop 1
07/25/2014 15:50:30;0008;PBS_Server;Job;40681.tyrone-cluster;Job Queued at request of mbuhrid@tyrone-cluster, owner = mbuhrid@tyrone-cluster, job name = job, queue = qp64
07/25/2014 15:50:30;0040;PBS_Server;Svr;tyrone-cluster;Scheduler was sent the command new
07/25/2014 15:50:30;0008;PBS_Server;Job;40681.tyrone-cluster;Job Modified at request of Scheduler@tyrone-cluster
07/25/2014 15:50:30;0008;PBS_Server;Job;40681.tyrone-cluster;Job Run at request of Scheduler@tyrone-cluster
07/25/2014 15:50:30;0040;PBS_Server;Svr;tyrone-cluster;Scheduler was sent the command recyc
07/25/2014 15:50:30;000d;PBS_Server;Job;40681.tyrone-cluster;Not sending email: User does not want mail of this type.
07/25/2014 15:50:30;0010;PBS_Server;Job;40681.tyrone-cluster;Exit_status=2 resources_used.cput=00:00:00 resources_used.mem=800kb resources_used.vmem=13624kb resources_used.walltime=00:00:01
07/25/2014 15:50:30;0008;PBS_Server;Job;NULL;on_job_exit valid pjob: 0x1f14010 (substate=50)
07/25/2014 15:50:30;0008;PBS_Server;Job;NULL;on_job_exit valid pjob: 0x1f14010 (substate=51)
07/25/2014 15:50:30;0008;PBS_Server;Job;NULL;on_job_exit valid pjob: 0x1f14010 (substate=51)
07/25/2014 15:50:30;0008;PBS_Server;Job;NULL;on_job_exit valid pjob: 0x1f14010 (substate=53)
07/25/2014 15:50:30;0100;PBS_Server;Job;40681.tyrone-cluster;dequeuing from qp64, state COMPLETE
07/25/2014 15:50:30;0040;PBS_Server;Svr;tyrone-cluster;Scheduler was sent the command term
07/25/2014 15:50:38;0040;PBS_Server;Svr;tyrone-cluster;Scheduler was sent the command new
07/25/2014 15:51:08;0040;PBS_Server;Svr;tyrone-cluster;Scheduler was sent the command new
07/25/2014 15:51:38;0040;PBS_Server;Svr;tyrone-cluster;Scheduler was sent the command new
07/25/2014 15:52:08;0040;PBS_Server;Svr;tyrone-cluster;Scheduler was sent the command new
07/25/2014 15:52:17;0100;PBS_Server;Job;40682.tyrone-cluster;enqueuing into batch, state 1 hop 1
07/25/2014 15:52:17;0100;PBS_Server;Job;40682.tyrone-cluster;dequeuing from batch, state QUEUED
07/25/2014 15:52:17;0100;PBS_Server;Job;40682.tyrone-cluster;enqueuing into qp64, state 1 hop 1
07/25/2014 15:52:17;0008;PBS_Server;Job;40682.tyrone-cluster;Job Queued at request of mbuhrid@tyrone-cluster, owner = mbuhrid@tyrone-cluster, job name = job, queue = qp64
07/25/2014 15:52:17;0040;PBS_Server;Svr;tyrone-cluster;Scheduler was sent the command new
07/25/2014 15:52:17;0008;PBS_Server;Job;40682.tyrone-cluster;Job Modified at request of Scheduler@tyrone-cluster
07/25/2014 15:52:17;0008;PBS_Server;Job;40682.tyrone-cluster;Job Run at request of Scheduler@tyrone-cluster
07/25/2014 15:52:17;0040;PBS_Server;Svr;tyrone-cluster;Scheduler was sent the command recyc
07/25/2014 15:52:18;000d;PBS_Server;Job;40682.tyrone-cluster;Not sending email: User does not want mail of this type.
07/25/2014 15:52:18;0010;PBS_Server;Job;40682.tyrone-cluster;Exit_status=0 resources_used.cput=00:00:00 resources_used.mem=800kb resources_used.vmem=13624kb resources_used.walltime=00:00:00
07/25/2014 15:52:18;0008;PBS_Server;Job;NULL;on_job_exit valid pjob: 0x1f14010 (substate=50)
07/25/2014 15:52:18;0008;PBS_Server;Job;NULL;on_job_exit valid pjob: 0x1f14010 (substate=51)
07/25/2014 15:52:18;0008;PBS_Server;Job;NULL;on_job_exit valid pjob: 0x1f14010 (substate=51)
07/25/2014 15:52:18;0008;PBS_Server;Job;NULL;on_job_exit valid pjob: 0x1f14010 (substate=53)
07/25/2014 15:52:18;0100;PBS_Server;Job;40682.tyrone-cluster;dequeuing from qp64, state COMPLETE
07/25/2014 15:52:18;0040;PBS_Server;Svr;tyrone-cluster;Scheduler was sent the command term
07/25/2014 15:52:38;0040;PBS_Server;Svr;tyrone-cluster;Scheduler was sent the command new
07/25/2014 15:53:08;0040;PBS_Server;Svr;tyrone-cluster;Scheduler was sent the command new
07/25/2014 15:53:38;0040;PBS_Server;Svr;tyrone-cluster;Scheduler was sent the command new
07/25/2014 15:53:38;0100;PBS_Server;Job;40683.tyrone-cluster;enqueuing into batch, state 1 hop 1
07/25/2014 15:53:38;0100;PBS_Server;Job;40683.tyrone-cluster;dequeuing from batch, state QUEUED
07/25/2014 15:53:38;0100;PBS_Server;Job;40683.tyrone-cluster;enqueuing into qp64, state 1 hop 1
07/25/2014 15:53:38;0008;PBS_Server;Job;40683.tyrone-cluster;Job Queued at request of mbuhrid@tyrone-cluster, owner = mbuhrid@tyrone-cluster, job name = job, queue = qp64
07/25/2014 15:53:38;0008;PBS_Server;Job;40683.tyrone-cluster;Job Modified at request of Scheduler@tyrone-cluster
07/25/2014 15:53:38;0008;PBS_Server;Job;40683.tyrone-cluster;Job Run at request of Scheduler@tyrone-cluster
07/25/2014 15:53:38;0040;PBS_Server;Svr;tyrone-cluster;Scheduler was sent the command recyc
07/25/2014 15:53:38;000d;PBS_Server;Job;40683.tyrone-cluster;Not sending email: User does not want mail of this type.
07/25/2014 15:53:38;0010;PBS_Server;Job;40683.tyrone-cluster;Exit_status=0 resources_used.cput=00:00:00 resources_used.mem=796kb resources_used.vmem=13624kb resources_used.walltime=00:00:01
07/25/2014 15:53:38;0008;PBS_Server;Job;NULL;on_job_exit valid pjob: 0x1f15930 (substate=50)
07/25/2014 15:53:38;0008;PBS_Server;Job;NULL;on_job_exit valid pjob: 0x1f15930 (substate=51)
07/25/2014 15:53:38;0008;PBS_Server;Job;NULL;on_job_exit valid pjob: 0x1f15930 (substate=51)
07/25/2014 15:53:38;0008;PBS_Server;Job;NULL;on_job_exit valid pjob: 0x1f15930 (substate=53)
07/25/2014 15:53:38;0100;PBS_Server;Job;40683.tyrone-cluster;dequeuing from qp64, state COMPLETE
07/25/2014 15:53:38;0040;PBS_Server;Svr;tyrone-cluster;Scheduler was sent the command term
07/25/2014 15:54:08;0040;PBS_Server;Svr;tyrone-cluster;Scheduler was sent the command new
07/25/2014 15:54:38;0040;PBS_Server;Svr;tyrone-cluster;Scheduler was sent the command new
07/25/2014 15:55:08;0040;PBS_Server;Svr;tyrone-cluster;Scheduler was sent the command new
07/25/2014 15:55:19;0002;PBS_Server;Svr;PBS_Server;Torque Server Version = 3.0.5, loglevel = 0
07/25/2014 15:55:38;0040;PBS_Server;Svr;tyrone-cluster;Scheduler was sent the command new
07/25/2014 15:55:50;0100;PBS_Server;Job;40684.tyrone-cluster;enqueuing into batch, state 1 hop 1
07/25/2014 15:55:50;0100;PBS_Server;Job;40684.tyrone-cluster;dequeuing from batch, state QUEUED
07/25/2014 15:55:50;0100;PBS_Server;Job;40684.tyrone-cluster;enqueuing into qp64, state 1 hop 1
07/25/2014 15:55:50;0008;PBS_Server;Job;40684.tyrone-cluster;Job Queued at request of mbuhrid@tyrone-cluster, owner = mbuhrid@tyrone-cluster, job name = job, queue = qp64
07/25/2014 15:55:50;0040;PBS_Server;Svr;tyrone-cluster;Scheduler was sent the command new
07/25/2014 15:55:50;0008;PBS_Server;Job;40684.tyrone-cluster;Job Modified at request of Scheduler@tyrone-cluster
07/25/2014 15:55:50;0008;PBS_Server;Job;40684.tyrone-cluster;Job Run at request of Scheduler@tyrone-cluster
07/25/2014 15:55:50;0040;PBS_Server;Svr;tyrone-cluster;Scheduler was sent the command recyc
07/25/2014 15:55:51;000d;PBS_Server;Job;40684.tyrone-cluster;Not sending email: User does not want mail of this type.
07/25/2014 15:55:51;0010;PBS_Server;Job;40684.tyrone-cluster;Exit_status=0 resources_used.cput=00:00:00 resources_used.mem=796kb resources_used.vmem=13624kb resources_used.walltime=00:00:00
07/25/2014 15:55:51;0008;PBS_Server;Job;NULL;on_job_exit valid pjob: 0x1f14010 (substate=50)
07/25/2014 15:55:51;0008;PBS_Server;Job;NULL;on_job_exit valid pjob: 0x1f14010 (substate=51)
07/25/2014 15:55:51;0008;PBS_Server;Job;NULL;on_job_exit valid pjob: 0x1f14010 (substate=51)
07/25/2014 15:55:51;0008;PBS_Server;Job;NULL;on_job_exit valid pjob: 0x1f14010 (substate=53)
07/25/2014 15:55:51;0100;PBS_Server;Job;40684.tyrone-cluster;dequeuing from qp64, state COMPLETE
07/25/2014 15:55:51;0040;PBS_Server;Svr;tyrone-cluster;Scheduler was sent the command term
07/25/2014 15:56:08;0040;PBS_Server;Svr;tyrone-cluster;Scheduler was sent the command new
07/25/2014 15:56:38;0040;PBS_Server;Svr;tyrone-cluster;Scheduler was sent the command new
07/25/2014 15:56:48;0100;PBS_Server;Job;40685.tyrone-cluster;enqueuing into batch, state 1 hop 1
07/25/2014 15:56:48;0100;PBS_Server;Job;40685.tyrone-cluster;dequeuing from batch, state QUEUED
07/25/2014 15:56:48;0100;PBS_Server;Job;40685.tyrone-cluster;enqueuing into qp64, state 1 hop 1
07/25/2014 15:56:48;0008;PBS_Server;Job;40685.tyrone-cluster;Job Queued at request of mbuhrid@tyrone-cluster, owner = mbuhrid@tyrone-cluster, job name = job, queue = qp64
07/25/2014 15:56:48;0040;PBS_Server;Svr;tyrone-cluster;Scheduler was sent the command new
07/25/2014 15:56:48;0008;PBS_Server;Job;40685.tyrone-cluster;Job Modified at request of Scheduler@tyrone-cluster
07/25/2014 15:56:48;0008;PBS_Server;Job;40685.tyrone-cluster;Job Run at request of Scheduler@tyrone-cluster
07/25/2014 15:56:48;0040;PBS_Server;Svr;tyrone-cluster;Scheduler was sent the command recyc
07/25/2014 15:56:49;000d;PBS_Server;Job;40685.tyrone-cluster;Not sending email: User does not want mail of this type.
07/25/2014 15:56:49;0010;PBS_Server;Job;40685.tyrone-cluster;Exit_status=0 resources_used.cput=00:00:00 resources_used.mem=800kb resources_used.vmem=13624kb resources_used.walltime=00:00:00
07/25/2014 15:56:49;0008;PBS_Server;Job;NULL;on_job_exit valid pjob: 0x1f15930 (substate=50)
07/25/2014 15:56:49;0008;PBS_Server;Job;NULL;on_job_exit valid pjob: 0x1f15930 (substate=51)
07/25/2014 15:56:49;0008;PBS_Server;Job;NULL;on_job_exit valid pjob: 0x1f15930 (substate=51)
07/25/2014 15:56:49;0008;PBS_Server;Job;NULL;on_job_exit valid pjob: 0x1f15930 (substate=53)
07/25/2014 15:56:49;0100;PBS_Server;Job;40685.tyrone-cluster;dequeuing from qp64, state COMPLETE
07/25/2014 15:56:49;0040;PBS_Server;Svr;tyrone-cluster;Scheduler was sent the command term
07/25/2014 15:57:08;0040;PBS_Server;Svr;tyrone-cluster;Scheduler was sent the command new
07/25/2014 15:57:38;0040;PBS_Server;Svr;tyrone-cluster;Scheduler was sent the command new
07/25/2014 15:58:08;0040;PBS_Server;Svr;tyrone-cluster;Scheduler was sent the command new
07/25/2014 15:58:39;0040;PBS_Server;Svr;tyrone-cluster;Scheduler was sent the command new
07/25/2014 15:59:09;0040;PBS_Server;Svr;tyrone-cluster;Scheduler was sent the command new
07/25/2014 15:59:39;0040;PBS_Server;Svr;tyrone-cluster;Scheduler was sent the command new
07/25/2014 16:00:09;0040;PBS_Server;Svr;tyrone-cluster;Scheduler was sent the command new
07/25/2014 16:00:19;0002;PBS_Server;Svr;PBS_Server;Torque Server Version = 3.0.5, loglevel = 0
07/25/2014 16:00:39;0040;PBS_Server;Svr;tyrone-cluster;Scheduler was sent the command new
07/25/2014 16:01:09;0040;PBS_Server;Svr;tyrone-cluster;Scheduler was sent the command new
07/25/2014 16:01:39;0040;PBS_Server;Svr;tyrone-cluster;Scheduler was sent the command new
07/25/2014 16:02:09;0040;PBS_Server;Svr;tyrone-cluster;Scheduler was sent the command new
07/25/2014 16:02:39;0040;PBS_Server;Svr;tyrone-cluster;Scheduler was sent the command new
07/25/2014 16:03:09;0040;PBS_Server;Svr;tyrone-cluster;Scheduler was sent the command new
07/25/2014 16:03:39;0040;PBS_Server;Svr;tyrone-cluster;Scheduler was sent the command new
07/25/2014 16:04:09;0040;PBS_Server;Svr;tyrone-cluster;Scheduler was sent the command new
07/25/2014 16:04:39;0040;PBS_Server;Svr;tyrone-cluster;Scheduler was sent the command new
07/25/2014 16:05:09;0040;PBS_Server;Svr;tyrone-cluster;Scheduler was sent the command new
07/25/2014 16:05:19;0002;PBS_Server;Svr;PBS_Server;Torque Server Version = 3.0.5, loglevel = 0
07/25/2014 16:05:39;0040;PBS_Server;Svr;tyrone-cluster;Scheduler was sent the command new
07/25/2014 16:06:09;0040;PBS_Server;Svr;tyrone-cluster;Scheduler was sent the command new
07/25/2014 16:06:39;0040;PBS_Server;Svr;tyrone-cluster;Scheduler was sent the command new
07/25/2014 16:07:09;0040;PBS_Server;Svr;tyrone-cluster;Scheduler was sent the command new
07/25/2014 16:07:40;0040;PBS_Server;Svr;tyrone-cluster;Scheduler was sent the command new
07/25/2014 16:08:10;0040;PBS_Server;Svr;tyrone-cluster;Scheduler was sent the command new
07/25/2014 16:08:40;0040;PBS_Server;Svr;tyrone-cluster;Scheduler was sent the command new
07/25/2014 16:09:10;0040;PBS_Server;Svr;tyrone-cluster;Scheduler was sent the command new
07/25/2014 16:09:40;0040;PBS_Server;Svr;tyrone-cluster;Scheduler was sent the command new
07/25/2014 16:09:50;0100;PBS_Server;Job;40686.tyrone-cluster;enqueuing into batch, state 1 hop 1
07/25/2014 16:09:50;0100;PBS_Server;Job;40686.tyrone-cluster;dequeuing from batch, state QUEUED
07/25/2014 16:09:50;0100;PBS_Server;Job;40686.tyrone-cluster;enqueuing into qp256, state 1 hop 1
07/25/2014 16:09:50;0008;PBS_Server;Job;40686.tyrone-cluster;Job Queued at request of ipckousi@tyrone-cluster, owner = ipckousi@tyrone-cluster, job name = scan, queue = qp256
07/25/2014 16:09:50;0040;PBS_Server;Svr;tyrone-cluster;Scheduler was sent the command new
07/25/2014 16:09:50;0008;PBS_Server;Job;40686.tyrone-cluster;Job Modified at request of Scheduler@tyrone-cluster
07/25/2014 16:09:50;0008;PBS_Server;Job;40686.tyrone-cluster;Job Run at request of Scheduler@tyrone-cluster
07/25/2014 16:09:50;0040;PBS_Server;Svr;tyrone-cluster;Scheduler was sent the command recyc
07/25/2014 16:09:52;000d;PBS_Server;Job;40686.tyrone-cluster;Not sending email: User does not want mail of this type.
07/25/2014 16:09:52;0010;PBS_Server;Job;40686.tyrone-cluster;Exit_status=2 resources_used.cput=00:00:00 resources_used.mem=800kb resources_used.vmem=13624kb resources_used.walltime=00:00:01
07/25/2014 16:09:52;0008;PBS_Server;Job;NULL;on_job_exit valid pjob: 0x1f14010 (substate=50)
07/25/2014 16:09:52;0008;PBS_Server;Job;NULL;on_job_exit valid pjob: 0x1f14010 (substate=51)
07/25/2014 16:09:52;0008;PBS_Server;Job;NULL;on_job_exit valid pjob: 0x1f14010 (substate=51)
07/25/2014 16:09:52;0008;PBS_Server;Job;NULL;on_job_exit valid pjob: 0x1f14010 (substate=53)
07/25/2014 16:09:52;0100;PBS_Server;Job;40686.tyrone-cluster;dequeuing from qp256, state COMPLETE
07/25/2014 16:09:52;0040;PBS_Server;Svr;tyrone-cluster;Scheduler was sent the command term
07/25/2014 16:10:10;0040;PBS_Server;Svr;tyrone-cluster;Scheduler was sent the command new
07/25/2014 16:10:19;0002;PBS_Server;Svr;PBS_Server;Torque Server Version = 3.0.5, loglevel = 0
07/25/2014 16:10:40;0040;PBS_Server;Svr;tyrone-cluster;Scheduler was sent the command new
07/25/2014 16:11:10;0040;PBS_Server;Svr;tyrone-cluster;Scheduler was sent the command new
07/25/2014 16:11:40;0040;PBS_Server;Svr;tyrone-cluster;Scheduler was sent the command new
07/25/2014 16:12:10;0040;PBS_Server;Svr;tyrone-cluster;Scheduler was sent the command new
07/25/2014 16:12:40;0040;PBS_Server;Svr;tyrone-cluster;Scheduler was sent the command new
07/25/2014 16:13:10;0040;PBS_Server;Svr;tyrone-cluster;Scheduler was sent the command new
07/25/2014 16:13:13;0100;PBS_Server;Job;40687.tyrone-cluster;enqueuing into batch, state 1 hop 1
07/25/2014 16:13:13;0100;PBS_Server;Job;40687.tyrone-cluster;dequeuing from batch, state QUEUED
07/25/2014 16:13:13;0100;PBS_Server;Job;40687.tyrone-cluster;enqueuing into qp32, state 1 hop 1
07/25/2014 16:13:13;0008;PBS_Server;Job;40687.tyrone-cluster;Job Queued at request of ipckousi@tyrone-cluster, owner = ipckousi@tyrone-cluster, job name = scan, queue = qp32
07/25/2014 16:13:13;0040;PBS_Server;Svr;tyrone-cluster;Scheduler was sent the command new
07/25/2014 16:13:13;0008;PBS_Server;Job;40687.tyrone-cluster;Job Modified at request of Scheduler@tyrone-cluster
07/25/2014 16:13:25;0008;PBS_Server;Job;40687.tyrone-cluster;Job deleted at request of ipckousi@tyrone-cluster
07/25/2014 16:13:25;0008;PBS_Server;Job;NULL;on_job_exit valid pjob: 0x1f15930 (substate=59)
07/25/2014 16:13:25;0100;PBS_Server;Job;40687.tyrone-cluster;dequeuing from qp32, state COMPLETE
07/25/2014 16:13:25;0040;PBS_Server;Svr;tyrone-cluster;Scheduler was sent the command term
07/25/2014 16:13:40;0040;PBS_Server;Svr;tyrone-cluster;Scheduler was sent the command new
07/25/2014 16:13:50;0100;PBS_Server;Job;40688.tyrone-cluster;enqueuing into batch, state 1 hop 1
07/25/2014 16:13:50;0100;PBS_Server;Job;40688.tyrone-cluster;dequeuing from batch, state QUEUED
07/25/2014 16:13:50;0100;PBS_Server;Job;40688.tyrone-cluster;enqueuing into idqueue, state 1 hop 1
07/25/2014 16:13:50;0008;PBS_Server;Job;40688.tyrone-cluster;Job Queued at request of ipckousi@tyrone-cluster, owner = ipckousi@tyrone-cluster, job name = scan, queue = idqueue
07/25/2014 16:13:50;0040;PBS_Server;Svr;tyrone-cluster;Scheduler was sent the command new
07/25/2014 16:13:50;0008;PBS_Server;Job;40688.tyrone-cluster;Job Modified at request of Scheduler@tyrone-cluster
07/25/2014 16:13:50;0008;PBS_Server;Job;40688.tyrone-cluster;Job Run at request of Scheduler@tyrone-cluster
07/25/2014 16:13:50;0040;PBS_Server;Svr;tyrone-cluster;Scheduler was sent the command recyc
07/25/2014 16:13:50;000d;PBS_Server;Job;40688.tyrone-cluster;Not sending email: User does not want mail of this type.
07/25/2014 16:14:10;0040;PBS_Server;Svr;tyrone-cluster;Scheduler was sent the command new
07/25/2014 16:14:40;0040;PBS_Server;Svr;tyrone-cluster;Scheduler was sent the command new
07/25/2014 16:15:10;0040;PBS_Server;Svr;tyrone-cluster;Scheduler was sent the command new
07/25/2014 16:15:19;0002;PBS_Server;Svr;PBS_Server;Torque Server Version = 3.0.5, loglevel = 0
07/25/2014 16:15:40;0040;PBS_Server;Svr;tyrone-cluster;Scheduler was sent the command new
07/25/2014 16:16:10;0040;PBS_Server;Svr;tyrone-cluster;Scheduler was sent the command new
07/25/2014 16:16:40;0040;PBS_Server;Svr;tyrone-cluster;Scheduler was sent the command new
07/25/2014 16:17:11;0040;PBS_Server;Svr;tyrone-cluster;Scheduler was sent the command new
07/25/2014 16:17:41;0040;PBS_Server;Svr;tyrone-cluster;Scheduler was sent the command new
07/25/2014 16:18:11;0040;PBS_Server;Svr;tyrone-cluster;Scheduler was sent the command new
07/25/2014 16:18:41;0040;PBS_Server;Svr;tyrone-cluster;Scheduler was sent the command new
07/25/2014 16:19:11;0040;PBS_Server;Svr;tyrone-cluster;Scheduler was sent the command new
07/25/2014 16:19:41;0040;PBS_Server;Svr;tyrone-cluster;Scheduler was sent the command new
07/25/2014 16:20:11;0040;PBS_Server;Svr;tyrone-cluster;Scheduler was sent the command new
07/25/2014 16:20:19;0002;PBS_Server;Svr;PBS_Server;Torque Server Version = 3.0.5, loglevel = 0
07/25/2014 16:20:41;0040;PBS_Server;Svr;tyrone-cluster;Scheduler was sent the command new
07/25/2014 16:21:11;0040;PBS_Server;Svr;tyrone-cluster;Scheduler was sent the command new
07/25/2014 16:21:41;0040;PBS_Server;Svr;tyrone-cluster;Scheduler was sent the command new
07/25/2014 16:22:11;0040;PBS_Server;Svr;tyrone-cluster;Scheduler was sent the command new
07/25/2014 16:22:41;0040;PBS_Server;Svr;tyrone-cluster;Scheduler was sent the command new
07/25/2014 16:23:11;0040;PBS_Server;Svr;tyrone-cluster;Scheduler was sent the command new
07/25/2014 16:23:41;0040;PBS_Server;Svr;tyrone-cluster;Scheduler was sent the command new
07/25/2014 16:24:11;0040;PBS_Server;Svr;tyrone-cluster;Scheduler was sent the command new
07/25/2014 16:24:41;0040;PBS_Server;Svr;tyrone-cluster;Scheduler was sent the command new
07/25/2014 16:25:11;0040;PBS_Server;Svr;tyrone-cluster;Scheduler was sent the command new
07/25/2014 16:25:19;0002;PBS_Server;Svr;PBS_Server;Torque Server Version = 3.0.5, loglevel = 0
07/25/2014 16:25:41;0040;PBS_Server;Svr;tyrone-cluster;Scheduler was sent the command new
07/25/2014 16:26:11;0040;PBS_Server;Svr;tyrone-cluster;Scheduler was sent the command new
07/25/2014 16:26:41;0040;PBS_Server;Svr;tyrone-cluster;Scheduler was sent the command new
07/25/2014 16:27:11;0040;PBS_Server;Svr;tyrone-cluster;Scheduler was sent the command new
07/25/2014 16:27:41;0040;PBS_Server;Svr;tyrone-cluster;Scheduler was sent the command new
07/25/2014 16:28:10;0100;PBS_Server;Job;40689.tyrone-cluster;enqueuing into batch, state 1 hop 1
07/25/2014 16:28:10;0100;PBS_Server;Job;40689.tyrone-cluster;dequeuing from batch, state QUEUED
07/25/2014 16:28:10;0100;PBS_Server;Job;40689.tyrone-cluster;enqueuing into qp256, state 1 hop 1
07/25/2014 16:28:10;0008;PBS_Server;Job;40689.tyrone-cluster;Job Queued at request of mbumv@tyrone-node9, owner = mbumv@tyrone-node9, job name = EcF1C-rep18, queue = qp256
07/25/2014 16:28:10;0040;PBS_Server;Svr;tyrone-cluster;Scheduler was sent the command new
07/25/2014 16:28:10;0008;PBS_Server;Job;40689.tyrone-cluster;Job Modified at request of Scheduler@tyrone-cluster
07/25/2014 16:28:10;0008;PBS_Server;Job;40689.tyrone-cluster;Job Run at request of Scheduler@tyrone-cluster
07/25/2014 16:28:10;0040;PBS_Server;Svr;tyrone-cluster;Scheduler was sent the command recyc
07/25/2014 16:28:12;0040;PBS_Server;Svr;tyrone-cluster;Scheduler was sent the command new
07/25/2014 16:28:42;0040;PBS_Server;Svr;tyrone-cluster;Scheduler was sent the command new
07/25/2014 16:28:49;000d;PBS_Server;Job;40689.tyrone-cluster;Not sending email: User does not want mail of this type.
07/25/2014 16:28:52;0100;PBS_Server;Job;40690.tyrone-cluster;enqueuing into batch, state 1 hop 1
07/25/2014 16:28:52;0100;PBS_Server;Job;40690.tyrone-cluster;dequeuing from batch, state QUEUED
07/25/2014 16:28:52;0100;PBS_Server;Job;40690.tyrone-cluster;enqueuing into qp256, state 1 hop 1
07/25/2014 16:28:52;0008;PBS_Server;Job;40690.tyrone-cluster;Job Queued at request of mbumv@tyrone-node9, owner = mbumv@tyrone-node9, job name = EcF1C-rep19, queue = qp256
07/25/2014 16:28:52;0040;PBS_Server;Svr;tyrone-cluster;Scheduler was sent the command new
07/25/2014 16:28:52;0008;PBS_Server;Job;40690.tyrone-cluster;Job Modified at request of Scheduler@tyrone-cluster
07/25/2014 16:29:12;0040;PBS_Server;Svr;tyrone-cluster;Scheduler was sent the command new
07/25/2014 16:29:34;0100;PBS_Server;Job;40691.tyrone-cluster;enqueuing into batch, state 1 hop 1
07/25/2014 16:29:34;0008;PBS_Server;Job;40691.tyrone-cluster;Job Queued at request of mbumv@tyrone-node9, owner = mbumv@tyrone-node9, job name = EcF1C-rep20, queue = batch
07/25/2014 16:29:34;0040;PBS_Server;Svr;tyrone-cluster;Scheduler was sent the command new
07/25/2014 16:29:35;0008;PBS_Server;Job;40691.tyrone-cluster;Job Modified at request of Scheduler@tyrone-cluster
07/25/2014 16:29:42;0040;PBS_Server;Svr;tyrone-cluster;Scheduler was sent the command new
07/25/2014 16:30:12;0040;PBS_Server;Svr;tyrone-cluster;Scheduler was sent the command new
07/25/2014 16:30:18;0100;PBS_Server;Job;40692.tyrone-cluster;enqueuing into batch, state 1 hop 1
07/25/2014 16:30:18;0008;PBS_Server;Job;40692.tyrone-cluster;Job Queued at request of mbumv@tyrone-node9, owner = mbumv@tyrone-node9, job name = EcF1C-rep21, queue = batch
07/25/2014 16:30:18;0040;PBS_Server;Svr;tyrone-cluster;Scheduler was sent the command new
07/25/2014 16:30:18;0008;PBS_Server;Job;40692.tyrone-cluster;Job Modified at request of Scheduler@tyrone-cluster
07/25/2014 16:30:19;0002;PBS_Server;Svr;PBS_Server;Torque Server Version = 3.0.5, loglevel = 0
07/25/2014 16:30:39;0040;PBS_Server;Svr;tyrone-cluster;Scheduler was sent the command new
07/25/2014 16:30:42;0040;PBS_Server;Svr;tyrone-cluster;Scheduler was sent the command new
07/25/2014 16:30:52;0040;PBS_Server;Svr;tyrone-cluster;Scheduler was sent the command new
07/25/2014 16:30:58;0100;PBS_Server;Job;40693.tyrone-cluster;enqueuing into batch, state 1 hop 1
07/25/2014 16:30:58;0008;PBS_Server;Job;40693.tyrone-cluster;Job Queued at request of mbumv@tyrone-node9, owner = mbumv@tyrone-node9, job name = EcF1C-rep22, queue = batch
07/25/2014 16:30:58;0040;PBS_Server;Svr;tyrone-cluster;Scheduler was sent the command new
07/25/2014 16:30:58;0008;PBS_Server;Job;40693.tyrone-cluster;Job Modified at request of Scheduler@tyrone-cluster
07/25/2014 16:31:12;0040;PBS_Server;Svr;tyrone-cluster;Scheduler was sent the command new
07/25/2014 16:31:23;0040;PBS_Server;Svr;tyrone-cluster;Scheduler was sent the command new
07/25/2014 16:31:28;0040;PBS_Server;Svr;tyrone-cluster;Scheduler was sent the command new
07/25/2014 16:31:40;0040;PBS_Server;Svr;tyrone-cluster;Scheduler was sent the command new
07/25/2014 16:31:40;0100;PBS_Server;Job;40694.tyrone-cluster;enqueuing into batch, state 1 hop 1
07/25/2014 16:31:40;0008;PBS_Server;Job;40694.tyrone-cluster;Job Queued at request of mbumv@tyrone-node9, owner = mbumv@tyrone-node9, job name = EcF1C-rep23, queue = batch
07/25/2014 16:31:40;0008;PBS_Server;Job;40694.tyrone-cluster;Job Modified at request of Scheduler@tyrone-cluster
07/25/2014 16:31:42;0040;PBS_Server;Svr;tyrone-cluster;Scheduler was sent the command new
07/25/2014 16:31:53;0040;PBS_Server;Svr;tyrone-cluster;Scheduler was sent the command new
07/25/2014 16:31:58;0040;PBS_Server;Svr;tyrone-cluster;Scheduler was sent the command new
07/25/2014 16:32:11;0040;PBS_Server;Svr;tyrone-cluster;Scheduler was sent the command new
07/25/2014 16:32:12;0040;PBS_Server;Svr;tyrone-cluster;Scheduler was sent the command new
07/25/2014 16:32:23;0040;PBS_Server;Svr;tyrone-cluster;Scheduler was sent the command new
07/25/2014 16:32:32;0040;PBS_Server;Svr;tyrone-cluster;Scheduler was sent the command new
07/25/2014 16:32:42;0040;PBS_Server;Svr;tyrone-cluster;Scheduler was sent the command new
07/25/2014 16:32:53;0040;PBS_Server;Svr;tyrone-cluster;Scheduler was sent the command new
07/25/2014 16:33:02;0040;PBS_Server;Svr;tyrone-cluster;Scheduler was sent the command new
07/25/2014 16:33:12;0040;PBS_Server;Svr;tyrone-cluster;Scheduler was sent the command new
07/25/2014 16:33:23;0040;PBS_Server;Svr;tyrone-cluster;Scheduler was sent the command new
07/25/2014 16:33:32;0040;PBS_Server;Svr;tyrone-cluster;Scheduler was sent the command new
07/25/2014 16:33:42;0040;PBS_Server;Svr;tyrone-cluster;Scheduler was sent the command new
07/25/2014 16:33:53;0040;PBS_Server;Svr;tyrone-cluster;Scheduler was sent the command new
07/25/2014 16:34:02;0040;PBS_Server;Svr;tyrone-cluster;Scheduler was sent the command new
07/25/2014 16:34:12;0040;PBS_Server;Svr;tyrone-cluster;Scheduler was sent the command new
07/25/2014 16:34:24;0040;PBS_Server;Svr;tyrone-cluster;Scheduler was sent the command new
07/25/2014 16:34:32;0040;PBS_Server;Svr;tyrone-cluster;Scheduler was sent the command new
07/25/2014 16:34:42;0040;PBS_Server;Svr;tyrone-cluster;Scheduler was sent the command new
07/25/2014 16:34:54;0040;PBS_Server;Svr;tyrone-cluster;Scheduler was sent the command new
07/25/2014 16:35:02;0040;PBS_Server;Svr;tyrone-cluster;Scheduler was sent the command new
07/25/2014 16:35:12;0040;PBS_Server;Svr;tyrone-cluster;Scheduler was sent the command new
07/25/2014 16:35:19;0002;PBS_Server;Svr;PBS_Server;Torque Server Version = 3.0.5, loglevel = 0
07/25/2014 16:35:24;0040;PBS_Server;Svr;tyrone-cluster;Scheduler was sent the command new
07/25/2014 16:35:32;0040;PBS_Server;Svr;tyrone-cluster;Scheduler was sent the command new
07/25/2014 16:35:42;0040;PBS_Server;Svr;tyrone-cluster;Scheduler was sent the command new
07/25/2014 16:35:54;0040;PBS_Server;Svr;tyrone-cluster;Scheduler was sent the command new
07/25/2014 16:36:03;0040;PBS_Server;Svr;tyrone-cluster;Scheduler was sent the command new
07/25/2014 16:36:12;0040;PBS_Server;Svr;tyrone-cluster;Scheduler was sent the command new
07/25/2014 16:36:24;0040;PBS_Server;Svr;tyrone-cluster;Scheduler was sent the command new
07/25/2014 16:36:32;0040;PBS_Server;Svr;tyrone-cluster;Scheduler was sent the command new
07/25/2014 16:36:42;0040;PBS_Server;Svr;tyrone-cluster;Scheduler was sent the command new
07/25/2014 16:36:54;0040;PBS_Server;Svr;tyrone-cluster;Scheduler was sent the command new
07/25/2014 16:37:02;0040;PBS_Server;Svr;tyrone-cluster;Scheduler was sent the command new
07/25/2014 16:37:12;0040;PBS_Server;Svr;tyrone-cluster;Scheduler was sent the command new
07/25/2014 16:37:24;0040;PBS_Server;Svr;tyrone-cluster;Scheduler was sent the command new
07/25/2014 16:37:33;0040;PBS_Server;Svr;tyrone-cluster;Scheduler was sent the command new
07/25/2014 16:37:43;0040;PBS_Server;Svr;tyrone-cluster;Scheduler was sent the command new
07/25/2014 16:37:54;0040;PBS_Server;Svr;tyrone-cluster;Scheduler was sent the command new
07/25/2014 16:38:02;0040;PBS_Server;Svr;tyrone-cluster;Scheduler was sent the command new
07/25/2014 16:38:13;0040;PBS_Server;Svr;tyrone-cluster;Scheduler was sent the command new
07/25/2014 16:38:24;0040;PBS_Server;Svr;tyrone-cluster;Scheduler was sent the command new
07/25/2014 16:38:32;0040;PBS_Server;Svr;tyrone-cluster;Scheduler was sent the command new
07/25/2014 16:38:43;0040;PBS_Server;Svr;tyrone-cluster;Scheduler was sent the command new
07/25/2014 16:38:54;0040;PBS_Server;Svr;tyrone-cluster;Scheduler was sent the command new
07/25/2014 16:39:03;0040;PBS_Server;Svr;tyrone-cluster;Scheduler was sent the command new
07/25/2014 16:39:13;0040;PBS_Server;Svr;tyrone-cluster;Scheduler was sent the command new
07/25/2014 16:39:24;0040;PBS_Server;Svr;tyrone-cluster;Scheduler was sent the command new
07/25/2014 16:39:32;0040;PBS_Server;Svr;tyrone-cluster;Scheduler was sent the command new
07/25/2014 16:39:43;0040;PBS_Server;Svr;tyrone-cluster;Scheduler was sent the command new
07/25/2014 16:39:54;0040;PBS_Server;Svr;tyrone-cluster;Scheduler was sent the command new
07/25/2014 16:40:02;0040;PBS_Server;Svr;tyrone-cluster;Scheduler was sent the command new
07/25/2014 16:40:13;0040;PBS_Server;Svr;tyrone-cluster;Scheduler was sent the command new
07/25/2014 16:40:19;0002;PBS_Server;Svr;PBS_Server;Torque Server Version = 3.0.5, loglevel = 0
07/25/2014 16:40:24;0040;PBS_Server;Svr;tyrone-cluster;Scheduler was sent the command new
07/25/2014 16:40:33;0040;PBS_Server;Svr;tyrone-cluster;Scheduler was sent the command new
07/25/2014 16:40:43;0040;PBS_Server;Svr;tyrone-cluster;Scheduler was sent the command new
07/25/2014 16:40:54;0040;PBS_Server;Svr;tyrone-cluster;Scheduler was sent the command new
07/25/2014 16:41:05;0040;PBS_Server;Svr;tyrone-cluster;Scheduler was sent the command new
07/25/2014 16:41:13;0040;PBS_Server;Svr;tyrone-cluster;Scheduler was sent the command new
07/25/2014 16:41:24;0040;PBS_Server;Svr;tyrone-cluster;Scheduler was sent the command new
07/25/2014 16:41:32;0040;PBS_Server;Svr;tyrone-cluster;Scheduler was sent the command new
07/25/2014 16:41:43;0040;PBS_Server;Svr;tyrone-cluster;Scheduler was sent the command new
07/25/2014 16:41:54;0040;PBS_Server;Svr;tyrone-cluster;Scheduler was sent the command new
07/25/2014 16:42:03;0040;PBS_Server;Svr;tyrone-cluster;Scheduler was sent the command new
07/25/2014 16:42:13;0040;PBS_Server;Svr;tyrone-cluster;Scheduler was sent the command new
07/25/2014 16:42:24;0040;PBS_Server;Svr;tyrone-cluster;Scheduler was sent the command new
07/25/2014 16:42:32;0040;PBS_Server;Svr;tyrone-cluster;Scheduler was sent the command new
07/25/2014 16:42:35;0100;PBS_Server;Job;40695.tyrone-cluster;enqueuing into batch, state 1 hop 1
07/25/2014 16:42:35;0100;PBS_Server;Job;40695.tyrone-cluster;dequeuing from batch, state QUEUED
07/25/2014 16:42:35;0100;PBS_Server;Job;40695.tyrone-cluster;enqueuing into qp256, state 1 hop 1
07/25/2014 16:42:35;0008;PBS_Server;Job;40695.tyrone-cluster;Job Queued at request of mbuhrid@tyrone-cluster, owner = mbuhrid@tyrone-cluster, job name = job, queue = qp256
07/25/2014 16:42:35;0040;PBS_Server;Svr;tyrone-cluster;Scheduler was sent the command new
07/25/2014 16:42:35;0008;PBS_Server;Job;40695.tyrone-cluster;Job Modified at request of Scheduler@tyrone-cluster
07/25/2014 16:42:43;0040;PBS_Server;Svr;tyrone-cluster;Scheduler was sent the command new
07/25/2014 16:42:55;0040;PBS_Server;Svr;tyrone-cluster;Scheduler was sent the command new
07/25/2014 16:43:02;0040;PBS_Server;Svr;tyrone-cluster;Scheduler was sent the command new
07/25/2014 16:43:13;0040;PBS_Server;Svr;tyrone-cluster;Scheduler was sent the command new
07/25/2014 16:43:25;0040;PBS_Server;Svr;tyrone-cluster;Scheduler was sent the command new
07/25/2014 16:43:33;0040;PBS_Server;Svr;tyrone-cluster;Scheduler was sent the command new
07/25/2014 16:43:43;0040;PBS_Server;Svr;tyrone-cluster;Scheduler was sent the command new
07/25/2014 16:43:55;0040;PBS_Server;Svr;tyrone-cluster;Scheduler was sent the command new
07/25/2014 16:44:02;0040;PBS_Server;Svr;tyrone-cluster;Scheduler was sent the command new
07/25/2014 16:44:13;0040;PBS_Server;Svr;tyrone-cluster;Scheduler was sent the command new
07/25/2014 16:44:25;0040;PBS_Server;Svr;tyrone-cluster;Scheduler was sent the command new
07/25/2014 16:44:32;0040;PBS_Server;Svr;tyrone-cluster;Scheduler was sent the command new
07/25/2014 16:44:43;0040;PBS_Server;Svr;tyrone-cluster;Scheduler was sent the command new
07/25/2014 16:44:55;0040;PBS_Server;Svr;tyrone-cluster;Scheduler was sent the command new
07/25/2014 16:45:03;0040;PBS_Server;Svr;tyrone-cluster;Scheduler was sent the command new
07/25/2014 16:45:13;0040;PBS_Server;Svr;tyrone-cluster;Scheduler was sent the command new
07/25/2014 16:45:19;0002;PBS_Server;Svr;PBS_Server;Torque Server Version = 3.0.5, loglevel = 0
07/25/2014 16:45:25;0040;PBS_Server;Svr;tyrone-cluster;Scheduler was sent the command new
07/25/2014 16:45:32;0040;PBS_Server;Svr;tyrone-cluster;Scheduler was sent the command new
07/25/2014 16:45:43;0040;PBS_Server;Svr;tyrone-cluster;Scheduler was sent the command new
07/25/2014 16:45:55;0040;PBS_Server;Svr;tyrone-cluster;Scheduler was sent the command new
07/25/2014 16:46:02;0040;PBS_Server;Svr;tyrone-cluster;Scheduler was sent the command new
07/25/2014 16:46:13;0040;PBS_Server;Svr;tyrone-cluster;Scheduler was sent the command new
07/25/2014 16:46:25;0040;PBS_Server;Svr;tyrone-cluster;Scheduler was sent the command new
07/25/2014 16:46:33;0040;PBS_Server;Svr;tyrone-cluster;Scheduler was sent the command new
07/25/2014 16:46:44;0040;PBS_Server;Svr;tyrone-cluster;Scheduler was sent the command new
07/25/2014 16:46:55;0040;PBS_Server;Svr;tyrone-cluster;Scheduler was sent the command new
07/25/2014 16:47:02;0040;PBS_Server;Svr;tyrone-cluster;Scheduler was sent the command new
07/25/2014 16:47:14;0040;PBS_Server;Svr;tyrone-cluster;Scheduler was sent the command new
07/25/2014 16:47:25;0040;PBS_Server;Svr;tyrone-cluster;Scheduler was sent the command new
07/25/2014 16:47:32;0040;PBS_Server;Svr;tyrone-cluster;Scheduler was sent the command new
07/25/2014 16:47:44;0040;PBS_Server;Svr;tyrone-cluster;Scheduler was sent the command new
07/25/2014 16:47:55;0040;PBS_Server;Svr;tyrone-cluster;Scheduler was sent the command new
07/25/2014 16:48:07;0040;PBS_Server;Svr;tyrone-cluster;Scheduler was sent the command new
07/25/2014 16:48:14;0040;PBS_Server;Svr;tyrone-cluster;Scheduler was sent the command new
07/25/2014 16:48:25;0040;PBS_Server;Svr;tyrone-cluster;Scheduler was sent the command new
07/25/2014 16:48:32;0040;PBS_Server;Svr;tyrone-cluster;Scheduler was sent the command new
07/25/2014 16:48:44;0040;PBS_Server;Svr;tyrone-cluster;Scheduler was sent the command new
07/25/2014 16:48:55;0040;PBS_Server;Svr;tyrone-cluster;Scheduler was sent the command new
07/25/2014 16:49:02;0040;PBS_Server;Svr;tyrone-cluster;Scheduler was sent the command new
07/25/2014 16:49:14;0040;PBS_Server;Svr;tyrone-cluster;Scheduler was sent the command new
07/25/2014 16:49:25;0040;PBS_Server;Svr;tyrone-cluster;Scheduler was sent the command new
07/25/2014 16:49:32;0040;PBS_Server;Svr;tyrone-cluster;Scheduler was sent the command new
07/25/2014 16:49:44;0040;PBS_Server;Svr;tyrone-cluster;Scheduler was sent the command new
07/25/2014 16:49:55;0040;PBS_Server;Svr;tyrone-cluster;Scheduler was sent the command new
07/25/2014 16:50:05;0040;PBS_Server;Svr;tyrone-cluster;Scheduler was sent the command new
07/25/2014 16:50:14;0040;PBS_Server;Svr;tyrone-cluster;Scheduler was sent the command new
07/25/2014 16:50:19;0002;PBS_Server;Svr;PBS_Server;Torque Server Version = 3.0.5, loglevel = 0
07/25/2014 16:50:25;0040;PBS_Server;Svr;tyrone-cluster;Scheduler was sent the command new
07/25/2014 16:50:32;0040;PBS_Server;Svr;tyrone-cluster;Scheduler was sent the command new
07/25/2014 16:50:44;0040;PBS_Server;Svr;tyrone-cluster;Scheduler was sent the command new
07/25/2014 16:50:55;0040;PBS_Server;Svr;tyrone-cluster;Scheduler was sent the command new
07/25/2014 16:51:03;0040;PBS_Server;Svr;tyrone-cluster;Scheduler was sent the command new
07/25/2014 16:51:14;0040;PBS_Server;Svr;tyrone-cluster;Scheduler was sent the command new
07/25/2014 16:51:26;0040;PBS_Server;Svr;tyrone-cluster;Scheduler was sent the command new
07/25/2014 16:51:32;0040;PBS_Server;Svr;tyrone-cluster;Scheduler was sent the command new
07/25/2014 16:51:44;0040;PBS_Server;Svr;tyrone-cluster;Scheduler was sent the command new
07/25/2014 16:51:56;0040;PBS_Server;Svr;tyrone-cluster;Scheduler was sent the command new
07/25/2014 16:52:02;0040;PBS_Server;Svr;tyrone-cluster;Scheduler was sent the command new
07/25/2014 16:52:14;0040;PBS_Server;Svr;tyrone-cluster;Scheduler was sent the command new
07/25/2014 16:52:26;0040;PBS_Server;Svr;tyrone-cluster;Scheduler was sent the command new
07/25/2014 16:52:33;0040;PBS_Server;Svr;tyrone-cluster;Scheduler was sent the command new
07/25/2014 16:52:44;0040;PBS_Server;Svr;tyrone-cluster;Scheduler was sent the command new
07/25/2014 16:52:56;0040;PBS_Server;Svr;tyrone-cluster;Scheduler was sent the command new
07/25/2014 16:53:02;0040;PBS_Server;Svr;tyrone-cluster;Scheduler was sent the command new
07/25/2014 16:53:14;0040;PBS_Server;Svr;tyrone-cluster;Scheduler was sent the command new
07/25/2014 16:53:26;0040;PBS_Server;Svr;tyrone-cluster;Scheduler was sent the command new
07/25/2014 16:53:32;0040;PBS_Server;Svr;tyrone-cluster;Scheduler was sent the command new
07/25/2014 16:53:44;0040;PBS_Server;Svr;tyrone-cluster;Scheduler was sent the command new
07/25/2014 16:53:56;0040;PBS_Server;Svr;tyrone-cluster;Scheduler was sent the command new
07/25/2014 16:54:03;0040;PBS_Server;Svr;tyrone-cluster;Scheduler was sent the command new
07/25/2014 16:54:14;0040;PBS_Server;Svr;tyrone-cluster;Scheduler was sent the command new
07/25/2014 16:54:26;0040;PBS_Server;Svr;tyrone-cluster;Scheduler was sent the command new
07/25/2014 16:54:32;0040;PBS_Server;Svr;tyrone-cluster;Scheduler was sent the command new
07/25/2014 16:54:44;0040;PBS_Server;Svr;tyrone-cluster;Scheduler was sent the command new
07/25/2014 16:54:56;0040;PBS_Server;Svr;tyrone-cluster;Scheduler was sent the command new
07/25/2014 16:55:02;0040;PBS_Server;Svr;tyrone-cluster;Scheduler was sent the command new
07/25/2014 16:55:14;0040;PBS_Server;Svr;tyrone-cluster;Scheduler was sent the command new
07/25/2014 16:55:19;0002;PBS_Server;Svr;PBS_Server;Torque Server Version = 3.0.5, loglevel = 0
07/25/2014 16:55:26;0040;PBS_Server;Svr;tyrone-cluster;Scheduler was sent the command new
07/25/2014 16:55:33;0040;PBS_Server;Svr;tyrone-cluster;Scheduler was sent the command new
07/25/2014 16:55:45;0040;PBS_Server;Svr;tyrone-cluster;Scheduler was sent the command new
07/25/2014 16:55:56;0040;PBS_Server;Svr;tyrone-cluster;Scheduler was sent the command new
07/25/2014 16:56:02;0040;PBS_Server;Svr;tyrone-cluster;Scheduler was sent the command new
07/25/2014 16:56:15;0040;PBS_Server;Svr;tyrone-cluster;Scheduler was sent the command new
07/25/2014 16:56:26;0040;PBS_Server;Svr;tyrone-cluster;Scheduler was sent the command new
07/25/2014 16:56:32;0040;PBS_Server;Svr;tyrone-cluster;Scheduler was sent the command new
07/25/2014 16:56:45;0040;PBS_Server;Svr;tyrone-cluster;Scheduler was sent the command new
07/25/2014 16:56:56;0040;PBS_Server;Svr;tyrone-cluster;Scheduler was sent the command new
07/25/2014 16:57:03;0040;PBS_Server;Svr;tyrone-cluster;Scheduler was sent the command new
07/25/2014 16:57:15;0040;PBS_Server;Svr;tyrone-cluster;Scheduler was sent the command new
07/25/2014 16:57:26;0040;PBS_Server;Svr;tyrone-cluster;Scheduler was sent the command new
07/25/2014 16:57:32;0040;PBS_Server;Svr;tyrone-cluster;Scheduler was sent the command new
07/25/2014 16:57:45;0040;PBS_Server;Svr;tyrone-cluster;Scheduler was sent the command new
07/25/2014 16:57:56;0040;PBS_Server;Svr;tyrone-cluster;Scheduler was sent the command new
07/25/2014 16:58:02;0040;PBS_Server;Svr;tyrone-cluster;Scheduler was sent the command new
07/25/2014 16:58:15;0040;PBS_Server;Svr;tyrone-cluster;Scheduler was sent the command new
07/25/2014 16:58:26;0040;PBS_Server;Svr;tyrone-cluster;Scheduler was sent the command new
07/25/2014 16:58:33;0040;PBS_Server;Svr;tyrone-cluster;Scheduler was sent the command new
07/25/2014 16:58:45;0040;PBS_Server;Svr;tyrone-cluster;Scheduler was sent the command new
07/25/2014 16:58:56;0040;PBS_Server;Svr;tyrone-cluster;Scheduler was sent the command new
07/25/2014 16:59:05;0040;PBS_Server;Svr;tyrone-cluster;Scheduler was sent the command new
07/25/2014 16:59:15;0040;PBS_Server;Svr;tyrone-cluster;Scheduler was sent the command new
07/25/2014 16:59:26;0040;PBS_Server;Svr;tyrone-cluster;Scheduler was sent the command new
07/25/2014 16:59:32;0040;PBS_Server;Svr;tyrone-cluster;Scheduler was sent the command new
07/25/2014 16:59:41;000d;PBS_Server;Job;40651.tyrone-cluster;Not sending email: User does not want mail of this type.
07/25/2014 16:59:41;0010;PBS_Server;Job;40651.tyrone-cluster;Exit_status=143 resources_used.cput=725:32:16 resources_used.mem=3182748kb resources_used.vmem=5825604kb resources_used.walltime=24:00:21
07/25/2014 16:59:41;0008;PBS_Server;Job;NULL;on_job_exit valid pjob: 0x1f04e40 (substate=50)
07/25/2014 16:59:41;0008;PBS_Server;Job;NULL;on_job_exit valid pjob: 0x1f04e40 (substate=51)
07/25/2014 16:59:45;0100;PBS_Server;Job;40667.tyrone-cluster;dequeuing from batch, state QUEUED
07/25/2014 16:59:45;0100;PBS_Server;Job;40667.tyrone-cluster;enqueuing into qp32, state 1 hop 1
07/25/2014 16:59:45;0040;PBS_Server;Svr;tyrone-cluster;Scheduler was sent the command new
07/25/2014 16:59:45;0008;PBS_Server;Job;40665.tyrone-cluster;Job Modified at request of Scheduler@tyrone-cluster
07/25/2014 16:59:45;0008;PBS_Server;Job;40665.tyrone-cluster;Job Run at request of Scheduler@tyrone-cluster
07/25/2014 16:59:45;0008;PBS_Server;Job;40667.tyrone-cluster;Job Modified at request of Scheduler@tyrone-cluster
07/25/2014 16:59:45;0040;PBS_Server;Svr;tyrone-cluster;Scheduler was sent the command recyc
07/25/2014 16:59:45;000d;PBS_Server;Job;40665.tyrone-cluster;Not sending email: User does not want mail of this type.
07/25/2014 16:59:48;0008;PBS_Server;Job;NULL;on_job_exit valid pjob: 0x1f04e40 (substate=51)
07/25/2014 16:59:48;0008;PBS_Server;Job;NULL;on_job_exit valid pjob: 0x1f04e40 (substate=53)
07/25/2014 16:59:48;0100;PBS_Server;Job;40651.tyrone-cluster;dequeuing from qp32, state COMPLETE
07/25/2014 16:59:48;0040;PBS_Server;Svr;tyrone-cluster;Scheduler was sent the command term
07/25/2014 16:59:56;0040;PBS_Server;Svr;tyrone-cluster;Scheduler was sent the command new
07/25/2014 17:00:03;0040;PBS_Server;Svr;tyrone-cluster;Scheduler was sent the command new
07/25/2014 17:00:15;0040;PBS_Server;Svr;tyrone-cluster;Scheduler was sent the command new
07/25/2014 17:00:19;0002;PBS_Server;Svr;PBS_Server;Torque Server Version = 3.0.5, loglevel = 0
07/25/2014 17:00:26;0040;PBS_Server;Svr;tyrone-cluster;Scheduler was sent the command new
07/25/2014 17:00:32;0040;PBS_Server;Svr;tyrone-cluster;Scheduler was sent the command new
07/25/2014 17:00:45;0040;PBS_Server;Svr;tyrone-cluster;Scheduler was sent the command new
07/25/2014 17:00:46;000d;PBS_Server;Job;40665.tyrone-cluster;Not sending email: User does not want mail of this type.
07/25/2014 17:00:46;0010;PBS_Server;Job;40665.tyrone-cluster;Exit_status=0 resources_used.cput=00:00:02 resources_used.mem=314440kb resources_used.vmem=4516348kb resources_used.walltime=00:01:01
07/25/2014 17:00:46;0008;PBS_Server;Job;NULL;on_job_exit valid pjob: 0x1ebeb10 (substate=50)
07/25/2014 17:00:46;0008;PBS_Server;Job;NULL;on_job_exit valid pjob: 0x1ebeb10 (substate=51)
07/25/2014 17:00:46;0008;PBS_Server;Job;NULL;on_job_exit valid pjob: 0x1ebeb10 (substate=51)
07/25/2014 17:00:46;0008;PBS_Server;Job;NULL;on_job_exit valid pjob: 0x1ebeb10 (substate=53)
07/25/2014 17:00:46;0100;PBS_Server;Job;40665.tyrone-cluster;dequeuing from qp32, state COMPLETE
07/25/2014 17:00:46;0040;PBS_Server;Svr;tyrone-cluster;Scheduler was sent the command term
07/25/2014 17:00:46;0008;PBS_Server;Job;40666.tyrone-cluster;Job Modified at request of Scheduler@tyrone-cluster
07/25/2014 17:00:46;0008;PBS_Server;Job;40666.tyrone-cluster;Job Run at request of Scheduler@tyrone-cluster
07/25/2014 17:00:46;0040;PBS_Server;Svr;tyrone-cluster;Scheduler was sent the command recyc
07/25/2014 17:00:46;000d;PBS_Server;Job;40666.tyrone-cluster;Not sending email: User does not want mail of this type.
07/25/2014 17:00:57;0040;PBS_Server;Svr;tyrone-cluster;Scheduler was sent the command new
07/25/2014 17:01:02;0040;PBS_Server;Svr;tyrone-cluster;Scheduler was sent the command new
07/25/2014 17:01:15;0040;PBS_Server;Svr;tyrone-cluster;Scheduler was sent the command new
07/25/2014 17:01:27;0040;PBS_Server;Svr;tyrone-cluster;Scheduler was sent the command new
07/25/2014 17:01:33;0040;PBS_Server;Svr;tyrone-cluster;Scheduler was sent the command new
07/25/2014 17:01:45;0040;PBS_Server;Svr;tyrone-cluster;Scheduler was sent the command new
07/25/2014 17:01:57;0040;PBS_Server;Svr;tyrone-cluster;Scheduler was sent the command new
07/25/2014 17:02:02;0040;PBS_Server;Svr;tyrone-cluster;Scheduler was sent the command new
07/25/2014 17:02:15;0040;PBS_Server;Svr;tyrone-cluster;Scheduler was sent the command new
07/25/2014 17:02:27;0040;PBS_Server;Svr;tyrone-cluster;Scheduler was sent the command new
07/25/2014 17:02:32;0040;PBS_Server;Svr;tyrone-cluster;Scheduler was sent the command new
07/25/2014 17:02:45;0040;PBS_Server;Svr;tyrone-cluster;Scheduler was sent the command new
07/25/2014 17:02:57;0040;PBS_Server;Svr;tyrone-cluster;Scheduler was sent the command new
07/25/2014 17:03:03;0040;PBS_Server;Svr;tyrone-cluster;Scheduler was sent the command new
07/25/2014 17:03:15;0040;PBS_Server;Svr;tyrone-cluster;Scheduler was sent the command new
07/25/2014 17:03:27;0040;PBS_Server;Svr;tyrone-cluster;Scheduler was sent the command new
07/25/2014 17:03:32;0040;PBS_Server;Svr;tyrone-cluster;Scheduler was sent the command new
07/25/2014 17:03:45;0040;PBS_Server;Svr;tyrone-cluster;Scheduler was sent the command new
07/25/2014 17:03:57;0040;PBS_Server;Svr;tyrone-cluster;Scheduler was sent the command new
07/25/2014 17:04:02;0040;PBS_Server;Svr;tyrone-cluster;Scheduler was sent the command new
07/25/2014 17:04:16;0040;PBS_Server;Svr;tyrone-cluster;Scheduler was sent the command new
07/25/2014 17:04:17;000d;PBS_Server;Job;40652.tyrone-cluster;Not sending email: User does not want mail of this type.
07/25/2014 17:04:17;0010;PBS_Server;Job;40652.tyrone-cluster;Exit_status=143 resources_used.cput=1529:11:33 resources_used.mem=13137000kb resources_used.vmem=54658088kb resources_used.walltime=24:00:33
07/25/2014 17:04:17;0008;PBS_Server;Job;NULL;on_job_exit valid pjob: 0x1eb13d0 (substate=50)
07/25/2014 17:04:17;0008;PBS_Server;Job;NULL;on_job_exit valid pjob: 0x1eb13d0 (substate=51)
07/25/2014 17:04:17;0008;PBS_Server;Job;NULL;on_job_exit valid pjob: 0x1eb13d0 (substate=51)
07/25/2014 17:04:17;0008;PBS_Server;Job;NULL;on_job_exit valid pjob: 0x1eb13d0 (substate=53)
07/25/2014 17:04:17;0100;PBS_Server;Job;40652.tyrone-cluster;dequeuing from qp256, state COMPLETE
07/25/2014 17:04:17;0040;PBS_Server;Svr;tyrone-cluster;Scheduler was sent the command term
07/25/2014 17:04:17;0008;PBS_Server;Job;40690.tyrone-cluster;Job Modified at request of Scheduler@tyrone-cluster
07/25/2014 17:04:17;0008;PBS_Server;Job;40695.tyrone-cluster;Job Modified at request of Scheduler@tyrone-cluster
07/25/2014 17:04:17;0008;PBS_Server;Job;40695.tyrone-cluster;Job Run at request of Scheduler@tyrone-cluster
07/25/2014 17:04:17;0040;PBS_Server;Svr;tyrone-cluster;Scheduler was sent the command recyc
07/25/2014 17:04:18;000d;PBS_Server;Job;40695.tyrone-cluster;Not sending email: User does not want mail of this type.
07/25/2014 17:04:18;0010;PBS_Server;Job;40695.tyrone-cluster;Exit_status=1 resources_used.cput=00:00:00 resources_used.mem=796kb resources_used.vmem=13624kb resources_used.walltime=00:00:00
07/25/2014 17:04:18;0008;PBS_Server;Job;NULL;on_job_exit valid pjob: 0x1f37c00 (substate=50)
07/25/2014 17:04:18;0008;PBS_Server;Job;NULL;on_job_exit valid pjob: 0x1f37c00 (substate=51)
07/25/2014 17:04:18;0008;PBS_Server;Job;NULL;on_job_exit valid pjob: 0x1f37c00 (substate=51)
07/25/2014 17:04:18;0008;PBS_Server;Job;NULL;on_job_exit valid pjob: 0x1f37c00 (substate=53)
07/25/2014 17:04:18;0100;PBS_Server;Job;40695.tyrone-cluster;dequeuing from qp256, state COMPLETE
07/25/2014 17:04:18;0040;PBS_Server;Svr;tyrone-cluster;Scheduler was sent the command term
07/25/2014 17:04:27;0040;PBS_Server;Svr;tyrone-cluster;Scheduler was sent the command new
07/25/2014 17:04:33;0040;PBS_Server;Svr;tyrone-cluster;Scheduler was sent the command new
07/25/2014 17:04:46;0040;PBS_Server;Svr;tyrone-cluster;Scheduler was sent the command new
07/25/2014 17:04:57;0040;PBS_Server;Svr;tyrone-cluster;Scheduler was sent the command new
07/25/2014 17:05:02;0040;PBS_Server;Svr;tyrone-cluster;Scheduler was sent the command new
07/25/2014 17:05:16;0040;PBS_Server;Svr;tyrone-cluster;Scheduler was sent the command new
07/25/2014 17:05:19;0002;PBS_Server;Svr;PBS_Server;Torque Server Version = 3.0.5, loglevel = 0
07/25/2014 17:05:27;0040;PBS_Server;Svr;tyrone-cluster;Scheduler was sent the command new
07/25/2014 17:05:32;0040;PBS_Server;Svr;tyrone-cluster;Scheduler was sent the command new
07/25/2014 17:05:46;0040;PBS_Server;Svr;tyrone-cluster;Scheduler was sent the command new
07/25/2014 17:05:57;0040;PBS_Server;Svr;tyrone-cluster;Scheduler was sent the command new
07/25/2014 17:06:03;0040;PBS_Server;Svr;tyrone-cluster;Scheduler was sent the command new
07/25/2014 17:06:16;0040;PBS_Server;Svr;tyrone-cluster;Scheduler was sent the command new
07/25/2014 17:06:27;0040;PBS_Server;Svr;tyrone-cluster;Scheduler was sent the command new
07/25/2014 17:06:32;0040;PBS_Server;Svr;tyrone-cluster;Scheduler was sent the command new
07/25/2014 17:06:46;0040;PBS_Server;Svr;tyrone-cluster;Scheduler was sent the command new
07/25/2014 17:06:57;0040;PBS_Server;Svr;tyrone-cluster;Scheduler was sent the command new
07/25/2014 17:07:02;0040;PBS_Server;Svr;tyrone-cluster;Scheduler was sent the command new
07/25/2014 17:07:16;0040;PBS_Server;Svr;tyrone-cluster;Scheduler was sent the command new
07/25/2014 17:07:27;0040;PBS_Server;Svr;tyrone-cluster;Scheduler was sent the command new
07/25/2014 17:07:37;0040;PBS_Server;Svr;tyrone-cluster;Scheduler was sent the command new
07/25/2014 17:07:46;0040;PBS_Server;Svr;tyrone-cluster;Scheduler was sent the command new
07/25/2014 17:07:57;0040;PBS_Server;Svr;tyrone-cluster;Scheduler was sent the command new
07/25/2014 17:08:05;0040;PBS_Server;Svr;tyrone-cluster;Scheduler was sent the command new
07/25/2014 17:08:16;0040;PBS_Server;Svr;tyrone-cluster;Scheduler was sent the command new
07/25/2014 17:08:27;0040;PBS_Server;Svr;tyrone-cluster;Scheduler was sent the command new
07/25/2014 17:08:32;0040;PBS_Server;Svr;tyrone-cluster;Scheduler was sent the command new
07/25/2014 17:08:46;0040;PBS_Server;Svr;tyrone-cluster;Scheduler was sent the command new
07/25/2014 17:08:57;0040;PBS_Server;Svr;tyrone-cluster;Scheduler was sent the command new
07/25/2014 17:08:59;0100;PBS_Server;Job;40696.tyrone-cluster;enqueuing into batch, state 1 hop 1
07/25/2014 17:08:59;0100;PBS_Server;Job;40696.tyrone-cluster;dequeuing from batch, state QUEUED
07/25/2014 17:08:59;0100;PBS_Server;Job;40696.tyrone-cluster;enqueuing into qp256, state 1 hop 1
07/25/2014 17:08:59;0008;PBS_Server;Job;40696.tyrone-cluster;Job Queued at request of mbuhrid@tyrone-cluster, owner = mbuhrid@tyrone-cluster, job name = job, queue = qp256
07/25/2014 17:08:59;0040;PBS_Server;Svr;tyrone-cluster;Scheduler was sent the command new
07/25/2014 17:08:59;0008;PBS_Server;Job;40696.tyrone-cluster;Job Modified at request of Scheduler@tyrone-cluster
07/25/2014 17:08:59;0008;PBS_Server;Job;40696.tyrone-cluster;Job Run at request of Scheduler@tyrone-cluster
07/25/2014 17:08:59;0040;PBS_Server;Svr;tyrone-cluster;Scheduler was sent the command recyc
07/25/2014 17:09:00;000d;PBS_Server;Job;40696.tyrone-cluster;Not sending email: User does not want mail of this type.
07/25/2014 17:09:00;0010;PBS_Server;Job;40696.tyrone-cluster;Exit_status=1 resources_used.cput=00:00:00 resources_used.mem=800kb resources_used.vmem=13624kb resources_used.walltime=00:00:02
07/25/2014 17:09:00;0008;PBS_Server;Job;NULL;on_job_exit valid pjob: 0x1f04e40 (substate=50)
07/25/2014 17:09:00;0008;PBS_Server;Job;NULL;on_job_exit valid pjob: 0x1f04e40 (substate=51)
07/25/2014 17:09:00;0008;PBS_Server;Job;NULL;on_job_exit valid pjob: 0x1f04e40 (substate=51)
07/25/2014 17:09:00;0008;PBS_Server;Job;NULL;on_job_exit valid pjob: 0x1f04e40 (substate=53)
07/25/2014 17:09:00;0100;PBS_Server;Job;40696.tyrone-cluster;dequeuing from qp256, state COMPLETE
07/25/2014 17:09:00;0040;PBS_Server;Svr;tyrone-cluster;Scheduler was sent the command term
07/25/2014 17:09:02;0040;PBS_Server;Svr;tyrone-cluster;Scheduler was sent the command new
07/25/2014 17:09:16;0040;PBS_Server;Svr;tyrone-cluster;Scheduler was sent the command new
07/25/2014 17:09:19;0100;PBS_Server;Job;40697.tyrone-cluster;enqueuing into batch, state 1 hop 1
07/25/2014 17:09:19;0100;PBS_Server;Job;40697.tyrone-cluster;dequeuing from batch, state QUEUED
07/25/2014 17:09:19;0100;PBS_Server;Job;40697.tyrone-cluster;enqueuing into qp256, state 1 hop 1
07/25/2014 17:09:19;0008;PBS_Server;Job;40697.tyrone-cluster;Job Queued at request of mbuhrid@tyrone-cluster, owner = mbuhrid@tyrone-cluster, job name = job, queue = qp256
07/25/2014 17:09:19;0040;PBS_Server;Svr;tyrone-cluster;Scheduler was sent the command new
07/25/2014 17:09:19;0008;PBS_Server;Job;40697.tyrone-cluster;Job Modified at request of Scheduler@tyrone-cluster
07/25/2014 17:09:19;0008;PBS_Server;Job;40697.tyrone-cluster;Job Run at request of Scheduler@tyrone-cluster
07/25/2014 17:09:19;0040;PBS_Server;Svr;tyrone-cluster;Scheduler was sent the command recyc
07/25/2014 17:09:20;000d;PBS_Server;Job;40697.tyrone-cluster;Not sending email: User does not want mail of this type.
07/25/2014 17:09:20;0010;PBS_Server;Job;40697.tyrone-cluster;Exit_status=1 resources_used.cput=00:00:00 resources_used.mem=800kb resources_used.vmem=13624kb resources_used.walltime=00:00:01
07/25/2014 17:09:20;0008;PBS_Server;Job;NULL;on_job_exit valid pjob: 0x1f04e40 (substate=50)
07/25/2014 17:09:20;0008;PBS_Server;Job;NULL;on_job_exit valid pjob: 0x1f04e40 (substate=51)
07/25/2014 17:09:20;0008;PBS_Server;Job;NULL;on_job_exit valid pjob: 0x1f04e40 (substate=51)
07/25/2014 17:09:20;0008;PBS_Server;Job;NULL;on_job_exit valid pjob: 0x1f04e40 (substate=53)
07/25/2014 17:09:20;0100;PBS_Server;Job;40697.tyrone-cluster;dequeuing from qp256, state COMPLETE
07/25/2014 17:09:20;0040;PBS_Server;Svr;tyrone-cluster;Scheduler was sent the command term
07/25/2014 17:09:27;0040;PBS_Server;Svr;tyrone-cluster;Scheduler was sent the command new
07/25/2014 17:09:35;0040;PBS_Server;Svr;tyrone-cluster;Scheduler was sent the command new
07/25/2014 17:09:46;0040;PBS_Server;Svr;tyrone-cluster;Scheduler was sent the command new
07/25/2014 17:09:57;0040;PBS_Server;Svr;tyrone-cluster;Scheduler was sent the command new
07/25/2014 17:10:02;0040;PBS_Server;Svr;tyrone-cluster;Scheduler was sent the command new
07/25/2014 17:10:16;0040;PBS_Server;Svr;tyrone-cluster;Scheduler was sent the command new
07/25/2014 17:10:16;0100;PBS_Server;Job;40698.tyrone-cluster;enqueuing into batch, state 1 hop 1
07/25/2014 17:10:16;0100;PBS_Server;Job;40698.tyrone-cluster;dequeuing from batch, state QUEUED
07/25/2014 17:10:16;0100;PBS_Server;Job;40698.tyrone-cluster;enqueuing into qp256, state 1 hop 1
07/25/2014 17:10:16;0008;PBS_Server;Job;40698.tyrone-cluster;Job Queued at request of mbuhrid@tyrone-cluster, owner = mbuhrid@tyrone-cluster, job name = job, queue = qp256
07/25/2014 17:10:16;0040;PBS_Server;Svr;tyrone-cluster;Scheduler was sent the command new
07/25/2014 17:10:17;0008;PBS_Server;Job;40698.tyrone-cluster;Job Modified at request of Scheduler@tyrone-cluster
07/25/2014 17:10:17;0008;PBS_Server;Job;40698.tyrone-cluster;Job Run at request of Scheduler@tyrone-cluster
07/25/2014 17:10:17;0040;PBS_Server;Svr;tyrone-cluster;Scheduler was sent the command recyc
07/25/2014 17:10:18;000d;PBS_Server;Job;40698.tyrone-cluster;Not sending email: User does not want mail of this type.
07/25/2014 17:10:18;0010;PBS_Server;Job;40698.tyrone-cluster;Exit_status=1 resources_used.cput=00:00:00 resources_used.mem=796kb resources_used.vmem=13624kb resources_used.walltime=00:00:01
07/25/2014 17:10:18;0008;PBS_Server;Job;NULL;on_job_exit valid pjob: 0x1f04e40 (substate=50)
07/25/2014 17:10:18;0008;PBS_Server;Job;NULL;on_job_exit valid pjob: 0x1f04e40 (substate=51)
07/25/2014 17:10:18;0008;PBS_Server;Job;NULL;on_job_exit valid pjob: 0x1f04e40 (substate=51)
07/25/2014 17:10:18;0008;PBS_Server;Job;NULL;on_job_exit valid pjob: 0x1f04e40 (substate=53)
07/25/2014 17:10:18;0100;PBS_Server;Job;40698.tyrone-cluster;dequeuing from qp256, state COMPLETE
07/25/2014 17:10:18;0040;PBS_Server;Svr;tyrone-cluster;Scheduler was sent the command term
07/25/2014 17:10:19;0002;PBS_Server;Svr;PBS_Server;Torque Server Version = 3.0.5, loglevel = 0
07/25/2014 17:10:28;0040;PBS_Server;Svr;tyrone-cluster;Scheduler was sent the command new
07/25/2014 17:10:38;0040;PBS_Server;Svr;tyrone-cluster;Scheduler was sent the command new
07/25/2014 17:10:46;0040;PBS_Server;Svr;tyrone-cluster;Scheduler was sent the command new
07/25/2014 17:10:58;0040;PBS_Server;Svr;tyrone-cluster;Scheduler was sent the command new
07/25/2014 17:11:13;0040;PBS_Server;Svr;tyrone-cluster;Scheduler was sent the command new
07/25/2014 17:11:16;0040;PBS_Server;Svr;tyrone-cluster;Scheduler was sent the command new
07/25/2014 17:11:28;0040;PBS_Server;Svr;tyrone-cluster;Scheduler was sent the command new
07/25/2014 17:11:38;0040;PBS_Server;Svr;tyrone-cluster;Scheduler was sent the command new
07/25/2014 17:11:46;0040;PBS_Server;Svr;tyrone-cluster;Scheduler was sent the command new
07/25/2014 17:11:58;0040;PBS_Server;Svr;tyrone-cluster;Scheduler was sent the command new
07/25/2014 17:12:16;0040;PBS_Server;Svr;tyrone-cluster;Scheduler was sent the command new
07/25/2014 17:12:28;0040;PBS_Server;Svr;tyrone-cluster;Scheduler was sent the command new
07/25/2014 17:12:43;0040;PBS_Server;Svr;tyrone-cluster;Scheduler was sent the command new
07/25/2014 17:12:47;0040;PBS_Server;Svr;tyrone-cluster;Scheduler was sent the command new
07/25/2014 17:12:58;0040;PBS_Server;Svr;tyrone-cluster;Scheduler was sent the command new
07/25/2014 17:13:13;0040;PBS_Server;Svr;tyrone-cluster;Scheduler was sent the command new
07/25/2014 17:13:17;0040;PBS_Server;Svr;tyrone-cluster;Scheduler was sent the command new
07/25/2014 17:13:28;0040;PBS_Server;Svr;tyrone-cluster;Scheduler was sent the command new
07/25/2014 17:13:47;0040;PBS_Server;Svr;tyrone-cluster;Scheduler was sent the command new
07/25/2014 17:13:58;0040;PBS_Server;Svr;tyrone-cluster;Scheduler was sent the command new
07/25/2014 17:14:17;0040;PBS_Server;Svr;tyrone-cluster;Scheduler was sent the command new
07/25/2014 17:14:28;0040;PBS_Server;Svr;tyrone-cluster;Scheduler was sent the command new
07/25/2014 17:14:47;0040;PBS_Server;Svr;tyrone-cluster;Scheduler was sent the command new
07/25/2014 17:14:58;0040;PBS_Server;Svr;tyrone-cluster;Scheduler was sent the command new
07/25/2014 17:15:17;0040;PBS_Server;Svr;tyrone-cluster;Scheduler was sent the command new
07/25/2014 17:15:19;0002;PBS_Server;Svr;PBS_Server;Torque Server Version = 3.0.5, loglevel = 0
07/25/2014 17:15:28;0040;PBS_Server;Svr;tyrone-cluster;Scheduler was sent the command new
07/25/2014 17:15:47;0040;PBS_Server;Svr;tyrone-cluster;Scheduler was sent the command new
07/25/2014 17:15:58;0040;PBS_Server;Svr;tyrone-cluster;Scheduler was sent the command new
07/25/2014 17:16:17;0040;PBS_Server;Svr;tyrone-cluster;Scheduler was sent the command new
07/25/2014 17:16:28;0040;PBS_Server;Svr;tyrone-cluster;Scheduler was sent the command new
07/25/2014 17:16:47;0040;PBS_Server;Svr;tyrone-cluster;Scheduler was sent the command new
07/25/2014 17:16:58;0040;PBS_Server;Svr;tyrone-cluster;Scheduler was sent the command new
07/25/2014 17:17:17;0040;PBS_Server;Svr;tyrone-cluster;Scheduler was sent the command new
07/25/2014 17:17:28;0040;PBS_Server;Svr;tyrone-cluster;Scheduler was sent the command new
07/25/2014 17:17:47;0040;PBS_Server;Svr;tyrone-cluster;Scheduler was sent the command new
07/25/2014 17:17:58;0040;PBS_Server;Svr;tyrone-cluster;Scheduler was sent the command new
07/25/2014 17:18:17;0040;PBS_Server;Svr;tyrone-cluster;Scheduler was sent the command new
07/25/2014 17:18:28;0040;PBS_Server;Svr;tyrone-cluster;Scheduler was sent the command new
07/25/2014 17:18:47;0040;PBS_Server;Svr;tyrone-cluster;Scheduler was sent the command new
07/25/2014 17:18:58;0040;PBS_Server;Svr;tyrone-cluster;Scheduler was sent the command new
07/25/2014 17:19:17;0040;PBS_Server;Svr;tyrone-cluster;Scheduler was sent the command new
07/25/2014 17:19:28;0040;PBS_Server;Svr;tyrone-cluster;Scheduler was sent the command new
07/25/2014 17:19:47;0040;PBS_Server;Svr;tyrone-cluster;Scheduler was sent the command new
07/25/2014 17:19:58;0040;PBS_Server;Svr;tyrone-cluster;Scheduler was sent the command new
07/25/2014 17:20:17;0040;PBS_Server;Svr;tyrone-cluster;Scheduler was sent the command new
07/25/2014 17:20:19;0002;PBS_Server;Svr;PBS_Server;Torque Server Version = 3.0.5, loglevel = 0
07/25/2014 17:20:29;0040;PBS_Server;Svr;tyrone-cluster;Scheduler was sent the command new
07/25/2014 17:20:47;0040;PBS_Server;Svr;tyrone-cluster;Scheduler was sent the command new
07/25/2014 17:20:59;0040;PBS_Server;Svr;tyrone-cluster;Scheduler was sent the command new
07/25/2014 17:21:17;0040;PBS_Server;Svr;tyrone-cluster;Scheduler was sent the command new
07/25/2014 17:21:29;0040;PBS_Server;Svr;tyrone-cluster;Scheduler was sent the command new
07/25/2014 17:21:47;0040;PBS_Server;Svr;tyrone-cluster;Scheduler was sent the command new
07/25/2014 17:21:59;0040;PBS_Server;Svr;tyrone-cluster;Scheduler was sent the command new
07/25/2014 17:22:17;0040;PBS_Server;Svr;tyrone-cluster;Scheduler was sent the command new
07/25/2014 17:22:29;0040;PBS_Server;Svr;tyrone-cluster;Scheduler was sent the command new
07/25/2014 17:22:47;0040;PBS_Server;Svr;tyrone-cluster;Scheduler was sent the command new
07/25/2014 17:22:59;0040;PBS_Server;Svr;tyrone-cluster;Scheduler was sent the command new
07/25/2014 17:23:18;0040;PBS_Server;Svr;tyrone-cluster;Scheduler was sent the command new
07/25/2014 17:23:29;0040;PBS_Server;Svr;tyrone-cluster;Scheduler was sent the command new
07/25/2014 17:23:47;0040;PBS_Server;Svr;tyrone-cluster;Scheduler was sent the command new
07/25/2014 17:23:59;0040;PBS_Server;Svr;tyrone-cluster;Scheduler was sent the command new
07/25/2014 17:24:17;0040;PBS_Server;Svr;tyrone-cluster;Scheduler was sent the command new
07/25/2014 17:24:29;0040;PBS_Server;Svr;tyrone-cluster;Scheduler was sent the command new
07/25/2014 17:24:48;0040;PBS_Server;Svr;tyrone-cluster;Scheduler was sent the command new
07/25/2014 17:24:59;0040;PBS_Server;Svr;tyrone-cluster;Scheduler was sent the command new
07/25/2014 17:25:17;0040;PBS_Server;Svr;tyrone-cluster;Scheduler was sent the command new
07/25/2014 17:25:19;0002;PBS_Server;Svr;PBS_Server;Torque Server Version = 3.0.5, loglevel = 0
07/25/2014 17:25:29;0040;PBS_Server;Svr;tyrone-cluster;Scheduler was sent the command new
07/25/2014 17:25:47;0040;PBS_Server;Svr;tyrone-cluster;Scheduler was sent the command new
07/25/2014 17:25:59;0040;PBS_Server;Svr;tyrone-cluster;Scheduler was sent the command new
07/25/2014 17:26:18;0040;PBS_Server;Svr;tyrone-cluster;Scheduler was sent the command new
07/25/2014 17:26:29;0040;PBS_Server;Svr;tyrone-cluster;Scheduler was sent the command new
07/25/2014 17:26:47;0040;PBS_Server;Svr;tyrone-cluster;Scheduler was sent the command new
07/25/2014 17:26:59;0040;PBS_Server;Svr;tyrone-cluster;Scheduler was sent the command new
07/25/2014 17:27:17;0040;PBS_Server;Svr;tyrone-cluster;Scheduler was sent the command new
07/25/2014 17:27:29;0040;PBS_Server;Svr;tyrone-cluster;Scheduler was sent the command new
07/25/2014 17:27:47;0040;PBS_Server;Svr;tyrone-cluster;Scheduler was sent the command new
07/25/2014 17:27:59;0040;PBS_Server;Svr;tyrone-cluster;Scheduler was sent the command new
07/25/2014 17:28:18;0040;PBS_Server;Svr;tyrone-cluster;Scheduler was sent the command new
07/25/2014 17:28:29;0040;PBS_Server;Svr;tyrone-cluster;Scheduler was sent the command new
07/25/2014 17:28:47;0040;PBS_Server;Svr;tyrone-cluster;Scheduler was sent the command new
07/25/2014 17:28:59;0040;PBS_Server;Svr;tyrone-cluster;Scheduler was sent the command new
07/25/2014 17:29:18;0040;PBS_Server;Svr;tyrone-cluster;Scheduler was sent the command new
07/25/2014 17:29:29;0040;PBS_Server;Svr;tyrone-cluster;Scheduler was sent the command new
07/25/2014 17:29:47;0040;PBS_Server;Svr;tyrone-cluster;Scheduler was sent the command new
07/25/2014 17:29:59;0040;PBS_Server;Svr;tyrone-cluster;Scheduler was sent the command new
07/25/2014 17:30:17;0040;PBS_Server;Svr;tyrone-cluster;Scheduler was sent the command new
07/25/2014 17:30:19;0002;PBS_Server;Svr;PBS_Server;Torque Server Version = 3.0.5, loglevel = 0
07/25/2014 17:30:29;0040;PBS_Server;Svr;tyrone-cluster;Scheduler was sent the command new
07/25/2014 17:30:48;0040;PBS_Server;Svr;tyrone-cluster;Scheduler was sent the command new
07/25/2014 17:31:00;0040;PBS_Server;Svr;tyrone-cluster;Scheduler was sent the command new
07/25/2014 17:31:17;0040;PBS_Server;Svr;tyrone-cluster;Scheduler was sent the command new
07/25/2014 17:31:30;0040;PBS_Server;Svr;tyrone-cluster;Scheduler was sent the command new
07/25/2014 17:31:47;0040;PBS_Server;Svr;tyrone-cluster;Scheduler was sent the command new
07/25/2014 17:32:00;0040;PBS_Server;Svr;tyrone-cluster;Scheduler was sent the command new
07/25/2014 17:32:18;0040;PBS_Server;Svr;tyrone-cluster;Scheduler was sent the command new
07/25/2014 17:32:30;0040;PBS_Server;Svr;tyrone-cluster;Scheduler was sent the command new
07/25/2014 17:32:47;0040;PBS_Server;Svr;tyrone-cluster;Scheduler was sent the command new
07/25/2014 17:33:00;0040;PBS_Server;Svr;tyrone-cluster;Scheduler was sent the command new
07/25/2014 17:33:17;0040;PBS_Server;Svr;tyrone-cluster;Scheduler was sent the command new
07/25/2014 17:33:30;0040;PBS_Server;Svr;tyrone-cluster;Scheduler was sent the command new
07/25/2014 17:33:48;0040;PBS_Server;Svr;tyrone-cluster;Scheduler was sent the command new
07/25/2014 17:34:00;0040;PBS_Server;Svr;tyrone-cluster;Scheduler was sent the command new
07/25/2014 17:34:17;0040;PBS_Server;Svr;tyrone-cluster;Scheduler was sent the command new
07/25/2014 17:34:30;0040;PBS_Server;Svr;tyrone-cluster;Scheduler was sent the command new
07/25/2014 17:34:47;0040;PBS_Server;Svr;tyrone-cluster;Scheduler was sent the command new
07/25/2014 17:35:00;0040;PBS_Server;Svr;tyrone-cluster;Scheduler was sent the command new
07/25/2014 17:35:18;0040;PBS_Server;Svr;tyrone-cluster;Scheduler was sent the command new
07/25/2014 17:35:19;0002;PBS_Server;Svr;PBS_Server;Torque Server Version = 3.0.5, loglevel = 0
07/25/2014 17:35:30;0040;PBS_Server;Svr;tyrone-cluster;Scheduler was sent the command new
07/25/2014 17:35:47;0040;PBS_Server;Svr;tyrone-cluster;Scheduler was sent the command new
07/25/2014 17:36:00;0040;PBS_Server;Svr;tyrone-cluster;Scheduler was sent the command new
07/25/2014 17:36:17;0040;PBS_Server;Svr;tyrone-cluster;Scheduler was sent the command new
07/25/2014 17:36:30;0040;PBS_Server;Svr;tyrone-cluster;Scheduler was sent the command new
07/25/2014 17:36:48;0040;PBS_Server;Svr;tyrone-cluster;Scheduler was sent the command new
07/25/2014 17:37:00;0040;PBS_Server;Svr;tyrone-cluster;Scheduler was sent the command new
07/25/2014 17:37:19;0040;PBS_Server;Svr;tyrone-cluster;Scheduler was sent the command new
07/25/2014 17:37:30;0040;PBS_Server;Svr;tyrone-cluster;Scheduler was sent the command new
07/25/2014 17:37:47;0040;PBS_Server;Svr;tyrone-cluster;Scheduler was sent the command new
07/25/2014 17:38:00;0040;PBS_Server;Svr;tyrone-cluster;Scheduler was sent the command new
07/25/2014 17:38:18;0040;PBS_Server;Svr;tyrone-cluster;Scheduler was sent the command new
07/25/2014 17:38:30;0040;PBS_Server;Svr;tyrone-cluster;Scheduler was sent the command new
07/25/2014 17:38:49;0040;PBS_Server;Svr;tyrone-cluster;Scheduler was sent the command new
07/25/2014 17:39:00;0040;PBS_Server;Svr;tyrone-cluster;Scheduler was sent the command new
07/25/2014 17:39:17;0040;PBS_Server;Svr;tyrone-cluster;Scheduler was sent the command new
07/25/2014 17:39:30;0040;PBS_Server;Svr;tyrone-cluster;Scheduler was sent the command new
07/25/2014 17:39:48;0040;PBS_Server;Svr;tyrone-cluster;Scheduler was sent the command new
07/25/2014 17:40:01;0040;PBS_Server;Svr;tyrone-cluster;Scheduler was sent the command new
07/25/2014 17:40:17;0040;PBS_Server;Svr;tyrone-cluster;Scheduler was sent the command new
07/25/2014 17:40:19;0002;PBS_Server;Svr;PBS_Server;Torque Server Version = 3.0.5, loglevel = 0
07/25/2014 17:40:31;0040;PBS_Server;Svr;tyrone-cluster;Scheduler was sent the command new
07/25/2014 17:40:47;0040;PBS_Server;Svr;tyrone-cluster;Scheduler was sent the command new
07/25/2014 17:41:01;0040;PBS_Server;Svr;tyrone-cluster;Scheduler was sent the command new
07/25/2014 17:41:18;0040;PBS_Server;Svr;tyrone-cluster;Scheduler was sent the command new
07/25/2014 17:41:31;0040;PBS_Server;Svr;tyrone-cluster;Scheduler was sent the command new
07/25/2014 17:41:47;0040;PBS_Server;Svr;tyrone-cluster;Scheduler was sent the command new
07/25/2014 17:42:01;0040;PBS_Server;Svr;tyrone-cluster;Scheduler was sent the command new
07/25/2014 17:42:17;0040;PBS_Server;Svr;tyrone-cluster;Scheduler was sent the command new
07/25/2014 17:42:31;0040;PBS_Server;Svr;tyrone-cluster;Scheduler was sent the command new
07/25/2014 17:42:48;0040;PBS_Server;Svr;tyrone-cluster;Scheduler was sent the command new
07/25/2014 17:43:01;0040;PBS_Server;Svr;tyrone-cluster;Scheduler was sent the command new
07/25/2014 17:43:17;0040;PBS_Server;Svr;tyrone-cluster;Scheduler was sent the command new
07/25/2014 17:43:31;0040;PBS_Server;Svr;tyrone-cluster;Scheduler was sent the command new
07/25/2014 17:43:47;0040;PBS_Server;Svr;tyrone-cluster;Scheduler was sent the command new
07/25/2014 17:44:01;0040;PBS_Server;Svr;tyrone-cluster;Scheduler was sent the command new
07/25/2014 17:44:18;0040;PBS_Server;Svr;tyrone-cluster;Scheduler was sent the command new
07/25/2014 17:44:31;0040;PBS_Server;Svr;tyrone-cluster;Scheduler was sent the command new
07/25/2014 17:44:47;0040;PBS_Server;Svr;tyrone-cluster;Scheduler was sent the command new
07/25/2014 17:45:01;0040;PBS_Server;Svr;tyrone-cluster;Scheduler was sent the command new
07/25/2014 17:45:17;0040;PBS_Server;Svr;tyrone-cluster;Scheduler was sent the command new
07/25/2014 17:45:19;0002;PBS_Server;Svr;PBS_Server;Torque Server Version = 3.0.5, loglevel = 0
07/25/2014 17:45:31;0040;PBS_Server;Svr;tyrone-cluster;Scheduler was sent the command new
07/25/2014 17:45:48;0040;PBS_Server;Svr;tyrone-cluster;Scheduler was sent the command new
07/25/2014 17:46:01;0040;PBS_Server;Svr;tyrone-cluster;Scheduler was sent the command new
07/25/2014 17:46:17;0040;PBS_Server;Svr;tyrone-cluster;Scheduler was sent the command new
07/25/2014 17:46:31;0040;PBS_Server;Svr;tyrone-cluster;Scheduler was sent the command new
07/25/2014 17:46:47;0040;PBS_Server;Svr;tyrone-cluster;Scheduler was sent the command new
07/25/2014 17:47:01;0040;PBS_Server;Svr;tyrone-cluster;Scheduler was sent the command new
07/25/2014 17:47:18;0040;PBS_Server;Svr;tyrone-cluster;Scheduler was sent the command new
07/25/2014 17:47:31;0040;PBS_Server;Svr;tyrone-cluster;Scheduler was sent the command new
07/25/2014 17:47:50;0040;PBS_Server;Svr;tyrone-cluster;Scheduler was sent the command new
07/25/2014 17:48:01;0040;PBS_Server;Svr;tyrone-cluster;Scheduler was sent the command new
07/25/2014 17:48:17;0040;PBS_Server;Svr;tyrone-cluster;Scheduler was sent the command new
07/25/2014 17:48:31;0040;PBS_Server;Svr;tyrone-cluster;Scheduler was sent the command new
07/25/2014 17:48:48;0040;PBS_Server;Svr;tyrone-cluster;Scheduler was sent the command new
07/25/2014 17:49:01;0040;PBS_Server;Svr;tyrone-cluster;Scheduler was sent the command new
07/25/2014 17:49:20;0040;PBS_Server;Svr;tyrone-cluster;Scheduler was sent the command new
07/25/2014 17:49:31;0040;PBS_Server;Svr;tyrone-cluster;Scheduler was sent the command new
07/25/2014 17:49:50;0040;PBS_Server;Svr;tyrone-cluster;Scheduler was sent the command new
07/25/2014 17:50:02;0040;PBS_Server;Svr;tyrone-cluster;Scheduler was sent the command new
07/25/2014 17:50:19;0002;PBS_Server;Svr;PBS_Server;Torque Server Version = 3.0.5, loglevel = 0
07/25/2014 17:50:20;0040;PBS_Server;Svr;tyrone-cluster;Scheduler was sent the command new
07/25/2014 17:50:32;0040;PBS_Server;Svr;tyrone-cluster;Scheduler was sent the command new
07/25/2014 17:50:50;0040;PBS_Server;Svr;tyrone-cluster;Scheduler was sent the command new
07/25/2014 17:51:02;0040;PBS_Server;Svr;tyrone-cluster;Scheduler was sent the command new
07/25/2014 17:51:20;0040;PBS_Server;Svr;tyrone-cluster;Scheduler was sent the command new
07/25/2014 17:51:32;0040;PBS_Server;Svr;tyrone-cluster;Scheduler was sent the command new
07/25/2014 17:51:50;0040;PBS_Server;Svr;tyrone-cluster;Scheduler was sent the command new
07/25/2014 17:52:02;0040;PBS_Server;Svr;tyrone-cluster;Scheduler was sent the command new
07/25/2014 17:52:20;0040;PBS_Server;Svr;tyrone-cluster;Scheduler was sent the command new
07/25/2014 17:52:32;0040;PBS_Server;Svr;tyrone-cluster;Scheduler was sent the command new
07/25/2014 17:52:50;0040;PBS_Server;Svr;tyrone-cluster;Scheduler was sent the command new
07/25/2014 17:53:02;0040;PBS_Server;Svr;tyrone-cluster;Scheduler was sent the command new
07/25/2014 17:53:21;0040;PBS_Server;Svr;tyrone-cluster;Scheduler was sent the command new
07/25/2014 17:53:32;0040;PBS_Server;Svr;tyrone-cluster;Scheduler was sent the command new
07/25/2014 17:53:51;0040;PBS_Server;Svr;tyrone-cluster;Scheduler was sent the command new
07/25/2014 17:54:02;0040;PBS_Server;Svr;tyrone-cluster;Scheduler was sent the command new
07/25/2014 17:54:21;0040;PBS_Server;Svr;tyrone-cluster;Scheduler was sent the command new
07/25/2014 17:54:32;0040;PBS_Server;Svr;tyrone-cluster;Scheduler was sent the command new
07/25/2014 17:54:51;0040;PBS_Server;Svr;tyrone-cluster;Scheduler was sent the command new
07/25/2014 17:55:02;0040;PBS_Server;Svr;tyrone-cluster;Scheduler was sent the command new
07/25/2014 17:55:19;0002;PBS_Server;Svr;PBS_Server;Torque Server Version = 3.0.5, loglevel = 0
07/25/2014 17:55:21;0040;PBS_Server;Svr;tyrone-cluster;Scheduler was sent the command new
07/25/2014 17:55:32;0040;PBS_Server;Svr;tyrone-cluster;Scheduler was sent the command new
07/25/2014 17:55:51;0040;PBS_Server;Svr;tyrone-cluster;Scheduler was sent the command new
07/25/2014 17:56:02;0040;PBS_Server;Svr;tyrone-cluster;Scheduler was sent the command new
07/25/2014 17:56:21;0040;PBS_Server;Svr;tyrone-cluster;Scheduler was sent the command new
07/25/2014 17:56:32;0040;PBS_Server;Svr;tyrone-cluster;Scheduler was sent the command new
07/25/2014 17:56:51;0040;PBS_Server;Svr;tyrone-cluster;Scheduler was sent the command new
07/25/2014 17:57:02;0040;PBS_Server;Svr;tyrone-cluster;Scheduler was sent the command new
07/25/2014 17:57:21;0040;PBS_Server;Svr;tyrone-cluster;Scheduler was sent the command new
07/25/2014 17:57:32;0040;PBS_Server;Svr;tyrone-cluster;Scheduler was sent the command new
07/25/2014 17:57:51;0040;PBS_Server;Svr;tyrone-cluster;Scheduler was sent the command new
07/25/2014 17:58:02;0040;PBS_Server;Svr;tyrone-cluster;Scheduler was sent the command new
07/25/2014 17:58:21;0040;PBS_Server;Svr;tyrone-cluster;Scheduler was sent the command new
07/25/2014 17:58:32;0040;PBS_Server;Svr;tyrone-cluster;Scheduler was sent the command new
07/25/2014 17:58:51;0040;PBS_Server;Svr;tyrone-cluster;Scheduler was sent the command new
07/25/2014 17:59:02;0040;PBS_Server;Svr;tyrone-cluster;Scheduler was sent the command new
07/25/2014 17:59:21;0040;PBS_Server;Svr;tyrone-cluster;Scheduler was sent the command new
07/25/2014 17:59:32;0040;PBS_Server;Svr;tyrone-cluster;Scheduler was sent the command new
07/25/2014 17:59:51;0040;PBS_Server;Svr;tyrone-cluster;Scheduler was sent the command new
07/25/2014 18:00:03;0040;PBS_Server;Svr;tyrone-cluster;Scheduler was sent the command new
07/25/2014 18:00:19;0002;PBS_Server;Svr;PBS_Server;Torque Server Version = 3.0.5, loglevel = 0
07/25/2014 18:00:21;0040;PBS_Server;Svr;tyrone-cluster;Scheduler was sent the command new
07/25/2014 18:00:33;0040;PBS_Server;Svr;tyrone-cluster;Scheduler was sent the command new
07/25/2014 18:00:51;0040;PBS_Server;Svr;tyrone-cluster;Scheduler was sent the command new
07/25/2014 18:01:02;0040;PBS_Server;Svr;tyrone-cluster;Scheduler was sent the command new
07/25/2014 18:01:21;0040;PBS_Server;Svr;tyrone-cluster;Scheduler was sent the command new
07/25/2014 18:01:33;0040;PBS_Server;Svr;tyrone-cluster;Scheduler was sent the command new
07/25/2014 18:01:51;0040;PBS_Server;Svr;tyrone-cluster;Scheduler was sent the command new
07/25/2014 18:02:03;0040;PBS_Server;Svr;tyrone-cluster;Scheduler was sent the command new
07/25/2014 18:02:21;0040;PBS_Server;Svr;tyrone-cluster;Scheduler was sent the command new
07/25/2014 18:02:33;0040;PBS_Server;Svr;tyrone-cluster;Scheduler was sent the command new
07/25/2014 18:02:52;0040;PBS_Server;Svr;tyrone-cluster;Scheduler was sent the command new
07/25/2014 18:03:03;0040;PBS_Server;Svr;tyrone-cluster;Scheduler was sent the command new
07/25/2014 18:03:22;0040;PBS_Server;Svr;tyrone-cluster;Scheduler was sent the command new
07/25/2014 18:03:33;0040;PBS_Server;Svr;tyrone-cluster;Scheduler was sent the command new
07/25/2014 18:03:52;0040;PBS_Server;Svr;tyrone-cluster;Scheduler was sent the command new
07/25/2014 18:04:03;0040;PBS_Server;Svr;tyrone-cluster;Scheduler was sent the command new
07/25/2014 18:04:22;0040;PBS_Server;Svr;tyrone-cluster;Scheduler was sent the command new
07/25/2014 18:04:33;0040;PBS_Server;Svr;tyrone-cluster;Scheduler was sent the command new
07/25/2014 18:04:52;0040;PBS_Server;Svr;tyrone-cluster;Scheduler was sent the command new
07/25/2014 18:05:03;0040;PBS_Server;Svr;tyrone-cluster;Scheduler was sent the command new
07/25/2014 18:05:19;0002;PBS_Server;Svr;PBS_Server;Torque Server Version = 3.0.5, loglevel = 0
07/25/2014 18:05:22;0040;PBS_Server;Svr;tyrone-cluster;Scheduler was sent the command new
07/25/2014 18:05:33;0040;PBS_Server;Svr;tyrone-cluster;Scheduler was sent the command new
07/25/2014 18:05:52;0040;PBS_Server;Svr;tyrone-cluster;Scheduler was sent the command new
07/25/2014 18:06:03;0040;PBS_Server;Svr;tyrone-cluster;Scheduler was sent the command new
07/25/2014 18:06:22;0040;PBS_Server;Svr;tyrone-cluster;Scheduler was sent the command new
07/25/2014 18:06:33;0040;PBS_Server;Svr;tyrone-cluster;Scheduler was sent the command new
07/25/2014 18:06:52;0040;PBS_Server;Svr;tyrone-cluster;Scheduler was sent the command new
07/25/2014 18:07:03;0040;PBS_Server;Svr;tyrone-cluster;Scheduler was sent the command new
07/25/2014 18:07:22;0040;PBS_Server;Svr;tyrone-cluster;Scheduler was sent the command new
07/25/2014 18:07:33;0040;PBS_Server;Svr;tyrone-cluster;Scheduler was sent the command new
07/25/2014 18:07:52;0040;PBS_Server;Svr;tyrone-cluster;Scheduler was sent the command new
07/25/2014 18:08:03;0040;PBS_Server;Svr;tyrone-cluster;Scheduler was sent the command new
07/25/2014 18:08:22;0040;PBS_Server;Svr;tyrone-cluster;Scheduler was sent the command new
07/25/2014 18:08:33;0040;PBS_Server;Svr;tyrone-cluster;Scheduler was sent the command new
07/25/2014 18:08:52;0040;PBS_Server;Svr;tyrone-cluster;Scheduler was sent the command new
07/25/2014 18:09:04;0040;PBS_Server;Svr;tyrone-cluster;Scheduler was sent the command new
07/25/2014 18:09:22;0040;PBS_Server;Svr;tyrone-cluster;Scheduler was sent the command new
07/25/2014 18:09:34;0040;PBS_Server;Svr;tyrone-cluster;Scheduler was sent the command new
07/25/2014 18:09:52;0040;PBS_Server;Svr;tyrone-cluster;Scheduler was sent the command new
07/25/2014 18:10:04;0040;PBS_Server;Svr;tyrone-cluster;Scheduler was sent the command new
07/25/2014 18:10:19;0002;PBS_Server;Svr;PBS_Server;Torque Server Version = 3.0.5, loglevel = 0
07/25/2014 18:10:22;0040;PBS_Server;Svr;tyrone-cluster;Scheduler was sent the command new
07/25/2014 18:10:34;0040;PBS_Server;Svr;tyrone-cluster;Scheduler was sent the command new
07/25/2014 18:10:52;0040;PBS_Server;Svr;tyrone-cluster;Scheduler was sent the command new
07/25/2014 18:11:04;0040;PBS_Server;Svr;tyrone-cluster;Scheduler was sent the command new
07/25/2014 18:11:22;0040;PBS_Server;Svr;tyrone-cluster;Scheduler was sent the command new
07/25/2014 18:11:34;0040;PBS_Server;Svr;tyrone-cluster;Scheduler was sent the command new
07/25/2014 18:11:53;0040;PBS_Server;Svr;tyrone-cluster;Scheduler was sent the command new
07/25/2014 18:12:04;0040;PBS_Server;Svr;tyrone-cluster;Scheduler was sent the command new
07/25/2014 18:12:23;0040;PBS_Server;Svr;tyrone-cluster;Scheduler was sent the command new
07/25/2014 18:12:34;0040;PBS_Server;Svr;tyrone-cluster;Scheduler was sent the command new
07/25/2014 18:12:53;0040;PBS_Server;Svr;tyrone-cluster;Scheduler was sent the command new
07/25/2014 18:13:04;0040;PBS_Server;Svr;tyrone-cluster;Scheduler was sent the command new
07/25/2014 18:13:23;0040;PBS_Server;Svr;tyrone-cluster;Scheduler was sent the command new
07/25/2014 18:13:34;0040;PBS_Server;Svr;tyrone-cluster;Scheduler was sent the command new
07/25/2014 18:13:53;0040;PBS_Server;Svr;tyrone-cluster;Scheduler was sent the command new
07/25/2014 18:14:04;0040;PBS_Server;Svr;tyrone-cluster;Scheduler was sent the command new
07/25/2014 18:14:06;000d;PBS_Server;Job;40688.tyrone-cluster;Not sending email: User does not want mail of this type.
07/25/2014 18:14:06;0010;PBS_Server;Job;40688.tyrone-cluster;Exit_status=143 resources_used.cput=63:49:27 resources_used.mem=7867516kb resources_used.vmem=19432580kb resources_used.walltime=02:00:16
07/25/2014 18:14:06;0008;PBS_Server;Job;NULL;on_job_exit valid pjob: 0x1f143f0 (substate=50)
07/25/2014 18:14:06;0008;PBS_Server;Job;NULL;on_job_exit valid pjob: 0x1f143f0 (substate=51)
07/25/2014 18:14:06;0008;PBS_Server;Job;NULL;on_job_exit valid pjob: 0x1f143f0 (substate=51)
07/25/2014 18:14:06;0008;PBS_Server;Job;NULL;on_job_exit valid pjob: 0x1f143f0 (substate=53)
07/25/2014 18:14:06;0100;PBS_Server;Job;40688.tyrone-cluster;dequeuing from idqueue, state COMPLETE
07/25/2014 18:14:06;0040;PBS_Server;Svr;tyrone-cluster;Scheduler was sent the command term
07/25/2014 18:14:23;0040;PBS_Server;Svr;tyrone-cluster;Scheduler was sent the command new
07/25/2014 18:14:34;0040;PBS_Server;Svr;tyrone-cluster;Scheduler was sent the command new
07/25/2014 18:14:53;0040;PBS_Server;Svr;tyrone-cluster;Scheduler was sent the command new
07/25/2014 18:15:04;0040;PBS_Server;Svr;tyrone-cluster;Scheduler was sent the command new
07/25/2014 18:15:19;0002;PBS_Server;Svr;PBS_Server;Torque Server Version = 3.0.5, loglevel = 0
07/25/2014 18:15:23;0040;PBS_Server;Svr;tyrone-cluster;Scheduler was sent the command new
07/25/2014 18:15:34;0040;PBS_Server;Svr;tyrone-cluster;Scheduler was sent the command new
07/25/2014 18:15:53;0040;PBS_Server;Svr;tyrone-cluster;Scheduler was sent the command new
07/25/2014 18:16:04;0040;PBS_Server;Svr;tyrone-cluster;Scheduler was sent the command new
07/25/2014 18:16:23;0040;PBS_Server;Svr;tyrone-cluster;Scheduler was sent the command new
07/25/2014 18:16:34;0040;PBS_Server;Svr;tyrone-cluster;Scheduler was sent the command new
07/25/2014 18:16:53;0040;PBS_Server;Svr;tyrone-cluster;Scheduler was sent the command new
07/25/2014 18:17:04;0040;PBS_Server;Svr;tyrone-cluster;Scheduler was sent the command new
07/25/2014 18:17:23;0040;PBS_Server;Svr;tyrone-cluster;Scheduler was sent the command new
07/25/2014 18:17:34;0040;PBS_Server;Svr;tyrone-cluster;Scheduler was sent the command new
07/25/2014 18:17:53;0040;PBS_Server;Svr;tyrone-cluster;Scheduler was sent the command new
07/25/2014 18:18:05;0040;PBS_Server;Svr;tyrone-cluster;Scheduler was sent the command new
07/25/2014 18:18:23;0040;PBS_Server;Svr;tyrone-cluster;Scheduler was sent the command new
07/25/2014 18:18:35;0040;PBS_Server;Svr;tyrone-cluster;Scheduler was sent the command new
07/25/2014 18:18:53;0040;PBS_Server;Svr;tyrone-cluster;Scheduler was sent the command new
07/25/2014 18:19:05;0040;PBS_Server;Svr;tyrone-cluster;Scheduler was sent the command new
07/25/2014 18:19:23;0040;PBS_Server;Svr;tyrone-cluster;Scheduler was sent the command new
07/25/2014 18:19:35;0040;PBS_Server;Svr;tyrone-cluster;Scheduler was sent the command new
07/25/2014 18:19:53;0040;PBS_Server;Svr;tyrone-cluster;Scheduler was sent the command new
07/25/2014 18:20:05;0040;PBS_Server;Svr;tyrone-cluster;Scheduler was sent the command new
07/25/2014 18:20:19;0002;PBS_Server;Svr;PBS_Server;Torque Server Version = 3.0.5, loglevel = 0
07/25/2014 18:20:23;0040;PBS_Server;Svr;tyrone-cluster;Scheduler was sent the command new
07/25/2014 18:20:35;0040;PBS_Server;Svr;tyrone-cluster;Scheduler was sent the command new
07/25/2014 18:20:54;0040;PBS_Server;Svr;tyrone-cluster;Scheduler was sent the command new
07/25/2014 18:21:05;0040;PBS_Server;Svr;tyrone-cluster;Scheduler was sent the command new
07/25/2014 18:21:24;0040;PBS_Server;Svr;tyrone-cluster;Scheduler was sent the command new
07/25/2014 18:21:35;0040;PBS_Server;Svr;tyrone-cluster;Scheduler was sent the command new
07/25/2014 18:21:54;0040;PBS_Server;Svr;tyrone-cluster;Scheduler was sent the command new
07/25/2014 18:22:05;0040;PBS_Server;Svr;tyrone-cluster;Scheduler was sent the command new
07/25/2014 18:22:24;0040;PBS_Server;Svr;tyrone-cluster;Scheduler was sent the command new
07/25/2014 18:22:35;0040;PBS_Server;Svr;tyrone-cluster;Scheduler was sent the command new
07/25/2014 18:22:54;0040;PBS_Server;Svr;tyrone-cluster;Scheduler was sent the command new
07/25/2014 18:23:05;0040;PBS_Server;Svr;tyrone-cluster;Scheduler was sent the command new
07/25/2014 18:23:24;0040;PBS_Server;Svr;tyrone-cluster;Scheduler was sent the command new
07/25/2014 18:23:35;0040;PBS_Server;Svr;tyrone-cluster;Scheduler was sent the command new
07/25/2014 18:23:54;0040;PBS_Server;Svr;tyrone-cluster;Scheduler was sent the command new
07/25/2014 18:24:05;0040;PBS_Server;Svr;tyrone-cluster;Scheduler was sent the command new
07/25/2014 18:24:24;0040;PBS_Server;Svr;tyrone-cluster;Scheduler was sent the command new
07/25/2014 18:24:35;0040;PBS_Server;Svr;tyrone-cluster;Scheduler was sent the command new
07/25/2014 18:24:54;0040;PBS_Server;Svr;tyrone-cluster;Scheduler was sent the command new
07/25/2014 18:25:05;0040;PBS_Server;Svr;tyrone-cluster;Scheduler was sent the command new
07/25/2014 18:25:19;0002;PBS_Server;Svr;PBS_Server;Torque Server Version = 3.0.5, loglevel = 0
07/25/2014 18:25:24;0040;PBS_Server;Svr;tyrone-cluster;Scheduler was sent the command new
07/25/2014 18:25:35;0040;PBS_Server;Svr;tyrone-cluster;Scheduler was sent the command new
07/25/2014 18:25:54;0040;PBS_Server;Svr;tyrone-cluster;Scheduler was sent the command new
07/25/2014 18:26:05;0040;PBS_Server;Svr;tyrone-cluster;Scheduler was sent the command new
07/25/2014 18:26:24;0040;PBS_Server;Svr;tyrone-cluster;Scheduler was sent the command new
07/25/2014 18:26:35;0040;PBS_Server;Svr;tyrone-cluster;Scheduler was sent the command new
07/25/2014 18:26:54;0040;PBS_Server;Svr;tyrone-cluster;Scheduler was sent the command new
07/25/2014 18:27:05;0040;PBS_Server;Svr;tyrone-cluster;Scheduler was sent the command new
07/25/2014 18:27:24;0040;PBS_Server;Svr;tyrone-cluster;Scheduler was sent the command new
07/25/2014 18:27:36;0040;PBS_Server;Svr;tyrone-cluster;Scheduler was sent the command new
07/25/2014 18:27:54;0040;PBS_Server;Svr;tyrone-cluster;Scheduler was sent the command new
07/25/2014 18:28:06;0040;PBS_Server;Svr;tyrone-cluster;Scheduler was sent the command new
07/25/2014 18:28:24;0040;PBS_Server;Svr;tyrone-cluster;Scheduler was sent the command new
07/25/2014 18:28:36;0040;PBS_Server;Svr;tyrone-cluster;Scheduler was sent the command new
07/25/2014 18:28:54;0040;PBS_Server;Svr;tyrone-cluster;Scheduler was sent the command new
07/25/2014 18:29:06;0040;PBS_Server;Svr;tyrone-cluster;Scheduler was sent the command new
07/25/2014 18:29:24;0040;PBS_Server;Svr;tyrone-cluster;Scheduler was sent the command new
07/25/2014 18:29:36;0040;PBS_Server;Svr;tyrone-cluster;Scheduler was sent the command new
07/25/2014 18:29:55;0040;PBS_Server;Svr;tyrone-cluster;Scheduler was sent the command new
07/25/2014 18:30:06;0040;PBS_Server;Svr;tyrone-cluster;Scheduler was sent the command new
07/25/2014 18:30:19;0002;PBS_Server;Svr;PBS_Server;Torque Server Version = 3.0.5, loglevel = 0
07/25/2014 18:30:25;0040;PBS_Server;Svr;tyrone-cluster;Scheduler was sent the command new
07/25/2014 18:30:36;0040;PBS_Server;Svr;tyrone-cluster;Scheduler was sent the command new
07/25/2014 18:30:55;0040;PBS_Server;Svr;tyrone-cluster;Scheduler was sent the command new
07/25/2014 18:31:06;0040;PBS_Server;Svr;tyrone-cluster;Scheduler was sent the command new
07/25/2014 18:31:25;0040;PBS_Server;Svr;tyrone-cluster;Scheduler was sent the command new
07/25/2014 18:31:36;0040;PBS_Server;Svr;tyrone-cluster;Scheduler was sent the command new
07/25/2014 18:31:55;0040;PBS_Server;Svr;tyrone-cluster;Scheduler was sent the command new
07/25/2014 18:32:06;0040;PBS_Server;Svr;tyrone-cluster;Scheduler was sent the command new
07/25/2014 18:32:25;0040;PBS_Server;Svr;tyrone-cluster;Scheduler was sent the command new
07/25/2014 18:32:36;0040;PBS_Server;Svr;tyrone-cluster;Scheduler was sent the command new
07/25/2014 18:32:55;0040;PBS_Server;Svr;tyrone-cluster;Scheduler was sent the command new
07/25/2014 18:33:06;0040;PBS_Server;Svr;tyrone-cluster;Scheduler was sent the command new
07/25/2014 18:33:25;0040;PBS_Server;Svr;tyrone-cluster;Scheduler was sent the command new
07/25/2014 18:33:36;0040;PBS_Server;Svr;tyrone-cluster;Scheduler was sent the command new
07/25/2014 18:33:55;0040;PBS_Server;Svr;tyrone-cluster;Scheduler was sent the command new
07/25/2014 18:34:06;0040;PBS_Server;Svr;tyrone-cluster;Scheduler was sent the command new
07/25/2014 18:34:25;0040;PBS_Server;Svr;tyrone-cluster;Scheduler was sent the command new
07/25/2014 18:34:36;0040;PBS_Server;Svr;tyrone-cluster;Scheduler was sent the command new
07/25/2014 18:34:55;0040;PBS_Server;Svr;tyrone-cluster;Scheduler was sent the command new
07/25/2014 18:35:06;0040;PBS_Server;Svr;tyrone-cluster;Scheduler was sent the command new
07/25/2014 18:35:19;0002;PBS_Server;Svr;PBS_Server;Torque Server Version = 3.0.5, loglevel = 0
07/25/2014 18:35:25;0040;PBS_Server;Svr;tyrone-cluster;Scheduler was sent the command new
07/25/2014 18:35:36;0040;PBS_Server;Svr;tyrone-cluster;Scheduler was sent the command new
07/25/2014 18:35:55;0040;PBS_Server;Svr;tyrone-cluster;Scheduler was sent the command new
07/25/2014 18:36:06;0040;PBS_Server;Svr;tyrone-cluster;Scheduler was sent the command new
07/25/2014 18:36:25;0040;PBS_Server;Svr;tyrone-cluster;Scheduler was sent the command new
07/25/2014 18:36:36;0040;PBS_Server;Svr;tyrone-cluster;Scheduler was sent the command new
07/25/2014 18:36:40;0100;PBS_Server;Job;40699.tyrone-cluster;enqueuing into batch, state 1 hop 1
07/25/2014 18:36:40;0100;PBS_Server;Job;40699.tyrone-cluster;dequeuing from batch, state QUEUED
07/25/2014 18:36:40;0100;PBS_Server;Job;40699.tyrone-cluster;enqueuing into idqueue, state 1 hop 1
07/25/2014 18:36:40;0008;PBS_Server;Job;40699.tyrone-cluster;Job Queued at request of phynagmp@tyrone-cluster, owner = phynagmp@tyrone-cluster, job name = poshit1, queue = idqueue
07/25/2014 18:36:40;0040;PBS_Server;Svr;tyrone-cluster;Scheduler was sent the command new
07/25/2014 18:36:40;0008;PBS_Server;Job;40699.tyrone-cluster;Job Modified at request of Scheduler@tyrone-cluster
07/25/2014 18:36:40;0008;PBS_Server;Job;40699.tyrone-cluster;Job Run at request of Scheduler@tyrone-cluster
07/25/2014 18:36:40;0040;PBS_Server;Svr;tyrone-cluster;Scheduler was sent the command recyc
07/25/2014 18:36:40;000d;PBS_Server;Job;40699.tyrone-cluster;Not sending email: User does not want mail of this type.
07/25/2014 18:36:41;000d;PBS_Server;Job;40699.tyrone-cluster;Not sending email: User does not want mail of this type.
07/25/2014 18:36:41;0010;PBS_Server;Job;40699.tyrone-cluster;Exit_status=2 resources_used.cput=00:00:00 resources_used.mem=0kb resources_used.vmem=0kb resources_used.walltime=00:00:01
07/25/2014 18:36:41;0008;PBS_Server;Job;NULL;on_job_exit valid pjob: 0x1eb13d0 (substate=50)
07/25/2014 18:36:41;0008;PBS_Server;Job;NULL;on_job_exit valid pjob: 0x1eb13d0 (substate=51)
07/25/2014 18:36:41;0008;PBS_Server;Job;NULL;on_job_exit valid pjob: 0x1eb13d0 (substate=51)
07/25/2014 18:36:41;0008;PBS_Server;Job;NULL;on_job_exit valid pjob: 0x1eb13d0 (substate=53)
07/25/2014 18:36:41;0100;PBS_Server;Job;40699.tyrone-cluster;dequeuing from idqueue, state COMPLETE
07/25/2014 18:36:41;0040;PBS_Server;Svr;tyrone-cluster;Scheduler was sent the command term
07/25/2014 18:36:55;0040;PBS_Server;Svr;tyrone-cluster;Scheduler was sent the command new
07/25/2014 18:37:07;0040;PBS_Server;Svr;tyrone-cluster;Scheduler was sent the command new
07/25/2014 18:37:25;0040;PBS_Server;Svr;tyrone-cluster;Scheduler was sent the command new
07/25/2014 18:37:37;0040;PBS_Server;Svr;tyrone-cluster;Scheduler was sent the command new
07/25/2014 18:37:55;0040;PBS_Server;Svr;tyrone-cluster;Scheduler was sent the command new
07/25/2014 18:38:06;0100;PBS_Server;Job;40700.tyrone-cluster;enqueuing into batch, state 1 hop 1
07/25/2014 18:38:06;0100;PBS_Server;Job;40700.tyrone-cluster;dequeuing from batch, state QUEUED
07/25/2014 18:38:06;0100;PBS_Server;Job;40700.tyrone-cluster;enqueuing into idqueue, state 1 hop 1
07/25/2014 18:38:06;0008;PBS_Server;Job;40700.tyrone-cluster;Job Queued at request of phynagmp@tyrone-cluster, owner = phynagmp@tyrone-cluster, job name = poshit1, queue = idqueue
07/25/2014 18:38:06;0040;PBS_Server;Svr;tyrone-cluster;Scheduler was sent the command new
07/25/2014 18:38:06;0008;PBS_Server;Job;40700.tyrone-cluster;Job Modified at request of Scheduler@tyrone-cluster
07/25/2014 18:38:06;0008;PBS_Server;Job;40700.tyrone-cluster;Job Run at request of Scheduler@tyrone-cluster
07/25/2014 18:38:06;0040;PBS_Server;Svr;tyrone-cluster;Scheduler was sent the command recyc
07/25/2014 18:38:06;000d;PBS_Server;Job;40700.tyrone-cluster;Not sending email: User does not want mail of this type.
07/25/2014 18:38:07;0040;PBS_Server;Svr;tyrone-cluster;Scheduler was sent the command new
07/25/2014 18:38:25;0040;PBS_Server;Svr;tyrone-cluster;Scheduler was sent the command new
07/25/2014 18:38:37;0040;PBS_Server;Svr;tyrone-cluster;Scheduler was sent the command new
07/25/2014 18:38:56;0040;PBS_Server;Svr;tyrone-cluster;Scheduler was sent the command new
07/25/2014 18:39:07;0040;PBS_Server;Svr;tyrone-cluster;Scheduler was sent the command new
07/25/2014 18:39:26;0040;PBS_Server;Svr;tyrone-cluster;Scheduler was sent the command new
07/25/2014 18:39:37;0040;PBS_Server;Svr;tyrone-cluster;Scheduler was sent the command new
07/25/2014 18:39:56;0040;PBS_Server;Svr;tyrone-cluster;Scheduler was sent the command new
07/25/2014 18:40:07;0040;PBS_Server;Svr;tyrone-cluster;Scheduler was sent the command new
07/25/2014 18:40:19;0002;PBS_Server;Svr;PBS_Server;Torque Server Version = 3.0.5, loglevel = 0
07/25/2014 18:40:26;0040;PBS_Server;Svr;tyrone-cluster;Scheduler was sent the command new
07/25/2014 18:40:37;0040;PBS_Server;Svr;tyrone-cluster;Scheduler was sent the command new
07/25/2014 18:40:56;0040;PBS_Server;Svr;tyrone-cluster;Scheduler was sent the command new
07/25/2014 18:41:07;0040;PBS_Server;Svr;tyrone-cluster;Scheduler was sent the command new
07/25/2014 18:41:26;0040;PBS_Server;Svr;tyrone-cluster;Scheduler was sent the command new
07/25/2014 18:41:37;0040;PBS_Server;Svr;tyrone-cluster;Scheduler was sent the command new
07/25/2014 18:41:56;0040;PBS_Server;Svr;tyrone-cluster;Scheduler was sent the command new
07/25/2014 18:42:07;0040;PBS_Server;Svr;tyrone-cluster;Scheduler was sent the command new
07/25/2014 18:42:26;0040;PBS_Server;Svr;tyrone-cluster;Scheduler was sent the command new
07/25/2014 18:42:37;0040;PBS_Server;Svr;tyrone-cluster;Scheduler was sent the command new
07/25/2014 18:42:56;0040;PBS_Server;Svr;tyrone-cluster;Scheduler was sent the command new
07/25/2014 18:43:06;000d;PBS_Server;Job;40700.tyrone-cluster;Not sending email: User does not want mail of this type.
07/25/2014 18:43:06;0010;PBS_Server;Job;40700.tyrone-cluster;Exit_status=2 resources_used.cput=01:04:49 resources_used.mem=536136kb resources_used.vmem=1136524kb resources_used.walltime=00:05:00
07/25/2014 18:43:06;0008;PBS_Server;Job;NULL;on_job_exit valid pjob: 0x1eb13d0 (substate=50)
07/25/2014 18:43:06;0008;PBS_Server;Job;NULL;on_job_exit valid pjob: 0x1eb13d0 (substate=51)
07/25/2014 18:43:06;0008;PBS_Server;Job;NULL;on_job_exit valid pjob: 0x1eb13d0 (substate=51)
07/25/2014 18:43:06;0008;PBS_Server;Job;NULL;on_job_exit valid pjob: 0x1eb13d0 (substate=53)
07/25/2014 18:43:06;0100;PBS_Server;Job;40700.tyrone-cluster;dequeuing from idqueue, state COMPLETE
07/25/2014 18:43:06;0040;PBS_Server;Svr;tyrone-cluster;Scheduler was sent the command term
07/25/2014 18:43:07;0040;PBS_Server;Svr;tyrone-cluster;Scheduler was sent the command new
07/25/2014 18:43:26;0040;PBS_Server;Svr;tyrone-cluster;Scheduler was sent the command new
07/25/2014 18:43:37;0040;PBS_Server;Svr;tyrone-cluster;Scheduler was sent the command new
07/25/2014 18:43:56;0040;PBS_Server;Svr;tyrone-cluster;Scheduler was sent the command new
07/25/2014 18:44:07;0040;PBS_Server;Svr;tyrone-cluster;Scheduler was sent the command new
07/25/2014 18:44:26;0040;PBS_Server;Svr;tyrone-cluster;Scheduler was sent the command new
07/25/2014 18:44:37;0040;PBS_Server;Svr;tyrone-cluster;Scheduler was sent the command new
07/25/2014 18:44:56;0040;PBS_Server;Svr;tyrone-cluster;Scheduler was sent the command new
07/25/2014 18:45:07;0040;PBS_Server;Svr;tyrone-cluster;Scheduler was sent the command new
07/25/2014 18:45:19;0002;PBS_Server;Svr;PBS_Server;Torque Server Version = 3.0.5, loglevel = 0
07/25/2014 18:45:26;0040;PBS_Server;Svr;tyrone-cluster;Scheduler was sent the command new
07/25/2014 18:45:37;0040;PBS_Server;Svr;tyrone-cluster;Scheduler was sent the command new
07/25/2014 18:45:56;0040;PBS_Server;Svr;tyrone-cluster;Scheduler was sent the command new
07/25/2014 18:46:07;0040;PBS_Server;Svr;tyrone-cluster;Scheduler was sent the command new
07/25/2014 18:46:26;0040;PBS_Server;Svr;tyrone-cluster;Scheduler was sent the command new
07/25/2014 18:46:38;0040;PBS_Server;Svr;tyrone-cluster;Scheduler was sent the command new
07/25/2014 18:46:56;0040;PBS_Server;Svr;tyrone-cluster;Scheduler was sent the command new
07/25/2014 18:47:08;0040;PBS_Server;Svr;tyrone-cluster;Scheduler was sent the command new
07/25/2014 18:47:26;0040;PBS_Server;Svr;tyrone-cluster;Scheduler was sent the command new
07/25/2014 18:47:38;0040;PBS_Server;Svr;tyrone-cluster;Scheduler was sent the command new
07/25/2014 18:47:57;0040;PBS_Server;Svr;tyrone-cluster;Scheduler was sent the command new
07/25/2014 18:48:08;0040;PBS_Server;Svr;tyrone-cluster;Scheduler was sent the command new
07/25/2014 18:48:27;0040;PBS_Server;Svr;tyrone-cluster;Scheduler was sent the command new
07/25/2014 18:48:38;0040;PBS_Server;Svr;tyrone-cluster;Scheduler was sent the command new
07/25/2014 18:48:57;0040;PBS_Server;Svr;tyrone-cluster;Scheduler was sent the command new
07/25/2014 18:49:08;0040;PBS_Server;Svr;tyrone-cluster;Scheduler was sent the command new
07/25/2014 18:49:27;0040;PBS_Server;Svr;tyrone-cluster;Scheduler was sent the command new
07/25/2014 18:49:38;0040;PBS_Server;Svr;tyrone-cluster;Scheduler was sent the command new
07/25/2014 18:49:57;0040;PBS_Server;Svr;tyrone-cluster;Scheduler was sent the command new
07/25/2014 18:50:08;0040;PBS_Server;Svr;tyrone-cluster;Scheduler was sent the command new
07/25/2014 18:50:19;0002;PBS_Server;Svr;PBS_Server;Torque Server Version = 3.0.5, loglevel = 0
07/25/2014 18:50:27;0040;PBS_Server;Svr;tyrone-cluster;Scheduler was sent the command new
07/25/2014 18:50:38;0040;PBS_Server;Svr;tyrone-cluster;Scheduler was sent the command new
07/25/2014 18:50:57;0040;PBS_Server;Svr;tyrone-cluster;Scheduler was sent the command new
07/25/2014 18:51:08;0040;PBS_Server;Svr;tyrone-cluster;Scheduler was sent the command new
07/25/2014 18:51:27;0040;PBS_Server;Svr;tyrone-cluster;Scheduler was sent the command new
07/25/2014 18:51:38;0040;PBS_Server;Svr;tyrone-cluster;Scheduler was sent the command new
07/25/2014 18:51:57;0040;PBS_Server;Svr;tyrone-cluster;Scheduler was sent the command new
07/25/2014 18:52:08;0040;PBS_Server;Svr;tyrone-cluster;Scheduler was sent the command new
07/25/2014 18:52:27;0040;PBS_Server;Svr;tyrone-cluster;Scheduler was sent the command new
07/25/2014 18:52:38;0040;PBS_Server;Svr;tyrone-cluster;Scheduler was sent the command new
07/25/2014 18:52:57;0040;PBS_Server;Svr;tyrone-cluster;Scheduler was sent the command new
07/25/2014 18:53:08;0040;PBS_Server;Svr;tyrone-cluster;Scheduler was sent the command new
07/25/2014 18:53:27;0040;PBS_Server;Svr;tyrone-cluster;Scheduler was sent the command new
07/25/2014 18:53:38;0040;PBS_Server;Svr;tyrone-cluster;Scheduler was sent the command new
07/25/2014 18:53:57;0040;PBS_Server;Svr;tyrone-cluster;Scheduler was sent the command new
07/25/2014 18:54:08;0040;PBS_Server;Svr;tyrone-cluster;Scheduler was sent the command new
07/25/2014 18:54:27;0040;PBS_Server;Svr;tyrone-cluster;Scheduler was sent the command new
07/25/2014 18:54:39;0040;PBS_Server;Svr;tyrone-cluster;Scheduler was sent the command new
07/25/2014 18:54:57;0040;PBS_Server;Svr;tyrone-cluster;Scheduler was sent the command new
07/25/2014 18:55:09;0040;PBS_Server;Svr;tyrone-cluster;Scheduler was sent the command new
07/25/2014 18:55:19;0002;PBS_Server;Svr;PBS_Server;Torque Server Version = 3.0.5, loglevel = 0
07/25/2014 18:55:27;0040;PBS_Server;Svr;tyrone-cluster;Scheduler was sent the command new
07/25/2014 18:55:39;0040;PBS_Server;Svr;tyrone-cluster;Scheduler was sent the command new
07/25/2014 18:55:57;0040;PBS_Server;Svr;tyrone-cluster;Scheduler was sent the command new
07/25/2014 18:56:09;0040;PBS_Server;Svr;tyrone-cluster;Scheduler was sent the command new
07/25/2014 18:56:27;0040;PBS_Server;Svr;tyrone-cluster;Scheduler was sent the command new
07/25/2014 18:56:39;0040;PBS_Server;Svr;tyrone-cluster;Scheduler was sent the command new
07/25/2014 18:56:57;0040;PBS_Server;Svr;tyrone-cluster;Scheduler was sent the command new
07/25/2014 18:57:09;0040;PBS_Server;Svr;tyrone-cluster;Scheduler was sent the command new
07/25/2014 18:57:28;0040;PBS_Server;Svr;tyrone-cluster;Scheduler was sent the command new
07/25/2014 18:57:39;0040;PBS_Server;Svr;tyrone-cluster;Scheduler was sent the command new
07/25/2014 18:57:58;0040;PBS_Server;Svr;tyrone-cluster;Scheduler was sent the command new
07/25/2014 18:58:09;0040;PBS_Server;Svr;tyrone-cluster;Scheduler was sent the command new
07/25/2014 18:58:28;0040;PBS_Server;Svr;tyrone-cluster;Scheduler was sent the command new
07/25/2014 18:58:39;0040;PBS_Server;Svr;tyrone-cluster;Scheduler was sent the command new
07/25/2014 18:58:58;0040;PBS_Server;Svr;tyrone-cluster;Scheduler was sent the command new
07/25/2014 18:59:09;0040;PBS_Server;Svr;tyrone-cluster;Scheduler was sent the command new
07/25/2014 18:59:28;0040;PBS_Server;Svr;tyrone-cluster;Scheduler was sent the command new
07/25/2014 18:59:39;0040;PBS_Server;Svr;tyrone-cluster;Scheduler was sent the command new
07/25/2014 18:59:58;0040;PBS_Server;Svr;tyrone-cluster;Scheduler was sent the command new
07/25/2014 19:00:09;0040;PBS_Server;Svr;tyrone-cluster;Scheduler was sent the command new
07/25/2014 19:00:19;0002;PBS_Server;Svr;PBS_Server;Torque Server Version = 3.0.5, loglevel = 0
07/25/2014 19:00:28;0040;PBS_Server;Svr;tyrone-cluster;Scheduler was sent the command new
07/25/2014 19:00:39;0040;PBS_Server;Svr;tyrone-cluster;Scheduler was sent the command new
07/25/2014 19:00:58;0040;PBS_Server;Svr;tyrone-cluster;Scheduler was sent the command new
07/25/2014 19:01:09;0040;PBS_Server;Svr;tyrone-cluster;Scheduler was sent the command new
07/25/2014 19:01:28;0040;PBS_Server;Svr;tyrone-cluster;Scheduler was sent the command new
07/25/2014 19:01:39;0040;PBS_Server;Svr;tyrone-cluster;Scheduler was sent the command new
07/25/2014 19:01:58;0040;PBS_Server;Svr;tyrone-cluster;Scheduler was sent the command new
07/25/2014 19:02:09;0040;PBS_Server;Svr;tyrone-cluster;Scheduler was sent the command new
07/25/2014 19:02:28;0040;PBS_Server;Svr;tyrone-cluster;Scheduler was sent the command new
07/25/2014 19:02:39;0040;PBS_Server;Svr;tyrone-cluster;Scheduler was sent the command new
07/25/2014 19:02:58;0040;PBS_Server;Svr;tyrone-cluster;Scheduler was sent the command new
07/25/2014 19:03:09;0040;PBS_Server;Svr;tyrone-cluster;Scheduler was sent the command new
07/25/2014 19:03:28;0040;PBS_Server;Svr;tyrone-cluster;Scheduler was sent the command new
07/25/2014 19:03:40;0040;PBS_Server;Svr;tyrone-cluster;Scheduler was sent the command new
07/25/2014 19:03:58;0040;PBS_Server;Svr;tyrone-cluster;Scheduler was sent the command new
07/25/2014 19:04:10;0040;PBS_Server;Svr;tyrone-cluster;Scheduler was sent the command new
07/25/2014 19:04:28;0040;PBS_Server;Svr;tyrone-cluster;Scheduler was sent the command new
07/25/2014 19:04:40;0040;PBS_Server;Svr;tyrone-cluster;Scheduler was sent the command new
07/25/2014 19:04:58;0040;PBS_Server;Svr;tyrone-cluster;Scheduler was sent the command new
07/25/2014 19:05:10;0040;PBS_Server;Svr;tyrone-cluster;Scheduler was sent the command new
07/25/2014 19:05:19;0002;PBS_Server;Svr;PBS_Server;Torque Server Version = 3.0.5, loglevel = 0
07/25/2014 19:05:28;0040;PBS_Server;Svr;tyrone-cluster;Scheduler was sent the command new
07/25/2014 19:05:40;0040;PBS_Server;Svr;tyrone-cluster;Scheduler was sent the command new
07/25/2014 19:05:58;0040;PBS_Server;Svr;tyrone-cluster;Scheduler was sent the command new
07/25/2014 19:06:10;0040;PBS_Server;Svr;tyrone-cluster;Scheduler was sent the command new
07/25/2014 19:06:28;0040;PBS_Server;Svr;tyrone-cluster;Scheduler was sent the command new
07/25/2014 19:06:40;0040;PBS_Server;Svr;tyrone-cluster;Scheduler was sent the command new
07/25/2014 19:06:59;0040;PBS_Server;Svr;tyrone-cluster;Scheduler was sent the command new
07/25/2014 19:07:10;0040;PBS_Server;Svr;tyrone-cluster;Scheduler was sent the command new
07/25/2014 19:07:29;0040;PBS_Server;Svr;tyrone-cluster;Scheduler was sent the command new
07/25/2014 19:07:40;0040;PBS_Server;Svr;tyrone-cluster;Scheduler was sent the command new
07/25/2014 19:07:59;0040;PBS_Server;Svr;tyrone-cluster;Scheduler was sent the command new
07/25/2014 19:08:10;0040;PBS_Server;Svr;tyrone-cluster;Scheduler was sent the command new
07/25/2014 19:08:29;0040;PBS_Server;Svr;tyrone-cluster;Scheduler was sent the command new
07/25/2014 19:08:40;0040;PBS_Server;Svr;tyrone-cluster;Scheduler was sent the command new
07/25/2014 19:08:59;0040;PBS_Server;Svr;tyrone-cluster;Scheduler was sent the command new
07/25/2014 19:09:10;0040;PBS_Server;Svr;tyrone-cluster;Scheduler was sent the command new
07/25/2014 19:09:29;0040;PBS_Server;Svr;tyrone-cluster;Scheduler was sent the command new
07/25/2014 19:09:40;0040;PBS_Server;Svr;tyrone-cluster;Scheduler was sent the command new
07/25/2014 19:09:59;0040;PBS_Server;Svr;tyrone-cluster;Scheduler was sent the command new
07/25/2014 19:10:10;0040;PBS_Server;Svr;tyrone-cluster;Scheduler was sent the command new
07/25/2014 19:10:19;0002;PBS_Server;Svr;PBS_Server;Torque Server Version = 3.0.5, loglevel = 0
07/25/2014 19:10:29;0040;PBS_Server;Svr;tyrone-cluster;Scheduler was sent the command new
07/25/2014 19:10:40;0040;PBS_Server;Svr;tyrone-cluster;Scheduler was sent the command new
07/25/2014 19:10:59;0040;PBS_Server;Svr;tyrone-cluster;Scheduler was sent the command new
07/25/2014 19:11:10;0040;PBS_Server;Svr;tyrone-cluster;Scheduler was sent the command new
07/25/2014 19:11:29;0040;PBS_Server;Svr;tyrone-cluster;Scheduler was sent the command new
07/25/2014 19:11:40;0040;PBS_Server;Svr;tyrone-cluster;Scheduler was sent the command new
07/25/2014 19:11:59;0040;PBS_Server;Svr;tyrone-cluster;Scheduler was sent the command new
07/25/2014 19:12:10;0040;PBS_Server;Svr;tyrone-cluster;Scheduler was sent the command new
07/25/2014 19:12:29;0040;PBS_Server;Svr;tyrone-cluster;Scheduler was sent the command new
07/25/2014 19:12:40;0040;PBS_Server;Svr;tyrone-cluster;Scheduler was sent the command new
07/25/2014 19:12:59;0040;PBS_Server;Svr;tyrone-cluster;Scheduler was sent the command new
07/25/2014 19:13:11;0040;PBS_Server;Svr;tyrone-cluster;Scheduler was sent the command new
07/25/2014 19:13:29;0040;PBS_Server;Svr;tyrone-cluster;Scheduler was sent the command new
07/25/2014 19:13:41;0040;PBS_Server;Svr;tyrone-cluster;Scheduler was sent the command new
07/25/2014 19:13:59;0040;PBS_Server;Svr;tyrone-cluster;Scheduler was sent the command new
07/25/2014 19:14:11;0040;PBS_Server;Svr;tyrone-cluster;Scheduler was sent the command new
07/25/2014 19:14:29;0040;PBS_Server;Svr;tyrone-cluster;Scheduler was sent the command new
07/25/2014 19:14:41;0040;PBS_Server;Svr;tyrone-cluster;Scheduler was sent the command new
07/25/2014 19:14:59;0040;PBS_Server;Svr;tyrone-cluster;Scheduler was sent the command new
07/25/2014 19:15:11;0040;PBS_Server;Svr;tyrone-cluster;Scheduler was sent the command new
07/25/2014 19:15:19;0002;PBS_Server;Svr;PBS_Server;Torque Server Version = 3.0.5, loglevel = 0
07/25/2014 19:15:29;0040;PBS_Server;Svr;tyrone-cluster;Scheduler was sent the command new
07/25/2014 19:15:41;0040;PBS_Server;Svr;tyrone-cluster;Scheduler was sent the command new
07/25/2014 19:16:00;0040;PBS_Server;Svr;tyrone-cluster;Scheduler was sent the command new
07/25/2014 19:16:11;0040;PBS_Server;Svr;tyrone-cluster;Scheduler was sent the command new
07/25/2014 19:16:30;0040;PBS_Server;Svr;tyrone-cluster;Scheduler was sent the command new
07/25/2014 19:16:41;0040;PBS_Server;Svr;tyrone-cluster;Scheduler was sent the command new
07/25/2014 19:17:00;0040;PBS_Server;Svr;tyrone-cluster;Scheduler was sent the command new
07/25/2014 19:17:11;0040;PBS_Server;Svr;tyrone-cluster;Scheduler was sent the command new
07/25/2014 19:17:30;0040;PBS_Server;Svr;tyrone-cluster;Scheduler was sent the command new
07/25/2014 19:17:41;0040;PBS_Server;Svr;tyrone-cluster;Scheduler was sent the command new
07/25/2014 19:18:00;0040;PBS_Server;Svr;tyrone-cluster;Scheduler was sent the command new
07/25/2014 19:18:11;0040;PBS_Server;Svr;tyrone-cluster;Scheduler was sent the command new
07/25/2014 19:18:30;0040;PBS_Server;Svr;tyrone-cluster;Scheduler was sent the command new
07/25/2014 19:18:41;0040;PBS_Server;Svr;tyrone-cluster;Scheduler was sent the command new
07/25/2014 19:19:00;0040;PBS_Server;Svr;tyrone-cluster;Scheduler was sent the command new
07/25/2014 19:19:11;0040;PBS_Server;Svr;tyrone-cluster;Scheduler was sent the command new
07/25/2014 19:19:30;0040;PBS_Server;Svr;tyrone-cluster;Scheduler was sent the command new
07/25/2014 19:19:41;0040;PBS_Server;Svr;tyrone-cluster;Scheduler was sent the command new
07/25/2014 19:20:00;0040;PBS_Server;Svr;tyrone-cluster;Scheduler was sent the command new
07/25/2014 19:20:11;0040;PBS_Server;Svr;tyrone-cluster;Scheduler was sent the command new
07/25/2014 19:20:19;0002;PBS_Server;Svr;PBS_Server;Torque Server Version = 3.0.5, loglevel = 0
07/25/2014 19:20:30;0040;PBS_Server;Svr;tyrone-cluster;Scheduler was sent the command new
07/25/2014 19:20:41;0040;PBS_Server;Svr;tyrone-cluster;Scheduler was sent the command new
07/25/2014 19:21:00;0040;PBS_Server;Svr;tyrone-cluster;Scheduler was sent the command new
07/25/2014 19:21:11;0040;PBS_Server;Svr;tyrone-cluster;Scheduler was sent the command new
07/25/2014 19:21:30;0040;PBS_Server;Svr;tyrone-cluster;Scheduler was sent the command new
07/25/2014 19:21:41;0040;PBS_Server;Svr;tyrone-cluster;Scheduler was sent the command new
07/25/2014 19:22:00;0040;PBS_Server;Svr;tyrone-cluster;Scheduler was sent the command new
07/25/2014 19:22:12;0040;PBS_Server;Svr;tyrone-cluster;Scheduler was sent the command new
07/25/2014 19:22:30;0040;PBS_Server;Svr;tyrone-cluster;Scheduler was sent the command new
07/25/2014 19:22:42;0040;PBS_Server;Svr;tyrone-cluster;Scheduler was sent the command new
07/25/2014 19:23:00;0040;PBS_Server;Svr;tyrone-cluster;Scheduler was sent the command new
07/25/2014 19:23:12;0040;PBS_Server;Svr;tyrone-cluster;Scheduler was sent the command new
07/25/2014 19:23:30;0040;PBS_Server;Svr;tyrone-cluster;Scheduler was sent the command new
07/25/2014 19:23:42;0040;PBS_Server;Svr;tyrone-cluster;Scheduler was sent the command new
07/25/2014 19:24:00;0040;PBS_Server;Svr;tyrone-cluster;Scheduler was sent the command new
07/25/2014 19:24:12;0040;PBS_Server;Svr;tyrone-cluster;Scheduler was sent the command new
07/25/2014 19:24:30;0040;PBS_Server;Svr;tyrone-cluster;Scheduler was sent the command new
07/25/2014 19:24:42;0040;PBS_Server;Svr;tyrone-cluster;Scheduler was sent the command new
07/25/2014 19:25:01;0040;PBS_Server;Svr;tyrone-cluster;Scheduler was sent the command new
07/25/2014 19:25:12;0040;PBS_Server;Svr;tyrone-cluster;Scheduler was sent the command new
07/25/2014 19:25:19;0002;PBS_Server;Svr;PBS_Server;Torque Server Version = 3.0.5, loglevel = 0
07/25/2014 19:25:31;0040;PBS_Server;Svr;tyrone-cluster;Scheduler was sent the command new
07/25/2014 19:25:42;0040;PBS_Server;Svr;tyrone-cluster;Scheduler was sent the command new
07/25/2014 19:26:01;0040;PBS_Server;Svr;tyrone-cluster;Scheduler was sent the command new
07/25/2014 19:26:12;0040;PBS_Server;Svr;tyrone-cluster;Scheduler was sent the command new
07/25/2014 19:26:31;0040;PBS_Server;Svr;tyrone-cluster;Scheduler was sent the command new
07/25/2014 19:26:42;0040;PBS_Server;Svr;tyrone-cluster;Scheduler was sent the command new
07/25/2014 19:27:01;0040;PBS_Server;Svr;tyrone-cluster;Scheduler was sent the command new
07/25/2014 19:27:12;0040;PBS_Server;Svr;tyrone-cluster;Scheduler was sent the command new
07/25/2014 19:27:31;0040;PBS_Server;Svr;tyrone-cluster;Scheduler was sent the command new
07/25/2014 19:27:42;0040;PBS_Server;Svr;tyrone-cluster;Scheduler was sent the command new
07/25/2014 19:28:01;0040;PBS_Server;Svr;tyrone-cluster;Scheduler was sent the command new
07/25/2014 19:28:12;0040;PBS_Server;Svr;tyrone-cluster;Scheduler was sent the command new
07/25/2014 19:28:31;0040;PBS_Server;Svr;tyrone-cluster;Scheduler was sent the command new
07/25/2014 19:28:42;0040;PBS_Server;Svr;tyrone-cluster;Scheduler was sent the command new
07/25/2014 19:29:01;0040;PBS_Server;Svr;tyrone-cluster;Scheduler was sent the command new
07/25/2014 19:29:12;0040;PBS_Server;Svr;tyrone-cluster;Scheduler was sent the command new
07/25/2014 19:29:31;0040;PBS_Server;Svr;tyrone-cluster;Scheduler was sent the command new
07/25/2014 19:29:42;0040;PBS_Server;Svr;tyrone-cluster;Scheduler was sent the command new
07/25/2014 19:30:01;0040;PBS_Server;Svr;tyrone-cluster;Scheduler was sent the command new
07/25/2014 19:30:12;0040;PBS_Server;Svr;tyrone-cluster;Scheduler was sent the command new
07/25/2014 19:30:19;0002;PBS_Server;Svr;PBS_Server;Torque Server Version = 3.0.5, loglevel = 0
07/25/2014 19:30:31;0040;PBS_Server;Svr;tyrone-cluster;Scheduler was sent the command new
07/25/2014 19:30:42;0040;PBS_Server;Svr;tyrone-cluster;Scheduler was sent the command new
07/25/2014 19:31:01;0040;PBS_Server;Svr;tyrone-cluster;Scheduler was sent the command new
07/25/2014 19:31:13;0040;PBS_Server;Svr;tyrone-cluster;Scheduler was sent the command new
07/25/2014 19:31:31;0040;PBS_Server;Svr;tyrone-cluster;Scheduler was sent the command new
07/25/2014 19:31:43;0040;PBS_Server;Svr;tyrone-cluster;Scheduler was sent the command new
07/25/2014 19:32:01;0040;PBS_Server;Svr;tyrone-cluster;Scheduler was sent the command new
07/25/2014 19:32:13;0040;PBS_Server;Svr;tyrone-cluster;Scheduler was sent the command new
07/25/2014 19:32:31;0040;PBS_Server;Svr;tyrone-cluster;Scheduler was sent the command new
07/25/2014 19:32:43;0040;PBS_Server;Svr;tyrone-cluster;Scheduler was sent the command new
07/25/2014 19:33:01;0040;PBS_Server;Svr;tyrone-cluster;Scheduler was sent the command new
07/25/2014 19:33:13;0040;PBS_Server;Svr;tyrone-cluster;Scheduler was sent the command new
07/25/2014 19:33:31;0040;PBS_Server;Svr;tyrone-cluster;Scheduler was sent the command new
07/25/2014 19:33:43;0040;PBS_Server;Svr;tyrone-cluster;Scheduler was sent the command new
07/25/2014 19:34:02;0040;PBS_Server;Svr;tyrone-cluster;Scheduler was sent the command new
07/25/2014 19:34:13;0040;PBS_Server;Svr;tyrone-cluster;Scheduler was sent the command new
07/25/2014 19:34:32;0040;PBS_Server;Svr;tyrone-cluster;Scheduler was sent the command new
07/25/2014 19:34:43;0040;PBS_Server;Svr;tyrone-cluster;Scheduler was sent the command new
07/25/2014 19:35:02;0040;PBS_Server;Svr;tyrone-cluster;Scheduler was sent the command new
07/25/2014 19:35:13;0040;PBS_Server;Svr;tyrone-cluster;Scheduler was sent the command new
07/25/2014 19:35:19;0002;PBS_Server;Svr;PBS_Server;Torque Server Version = 3.0.5, loglevel = 0
07/25/2014 19:35:32;0040;PBS_Server;Svr;tyrone-cluster;Scheduler was sent the command new
07/25/2014 19:35:43;0040;PBS_Server;Svr;tyrone-cluster;Scheduler was sent the command new
07/25/2014 19:36:02;0040;PBS_Server;Svr;tyrone-cluster;Scheduler was sent the command new
07/25/2014 19:36:13;0040;PBS_Server;Svr;tyrone-cluster;Scheduler was sent the command new
07/25/2014 19:36:32;0040;PBS_Server;Svr;tyrone-cluster;Scheduler was sent the command new
07/25/2014 19:36:43;0040;PBS_Server;Svr;tyrone-cluster;Scheduler was sent the command new
07/25/2014 19:37:02;0040;PBS_Server;Svr;tyrone-cluster;Scheduler was sent the command new
07/25/2014 19:37:13;0040;PBS_Server;Svr;tyrone-cluster;Scheduler was sent the command new
07/25/2014 19:37:32;0040;PBS_Server;Svr;tyrone-cluster;Scheduler was sent the command new
07/25/2014 19:37:43;0040;PBS_Server;Svr;tyrone-cluster;Scheduler was sent the command new
07/25/2014 19:38:02;0040;PBS_Server;Svr;tyrone-cluster;Scheduler was sent the command new
07/25/2014 19:38:13;0040;PBS_Server;Svr;tyrone-cluster;Scheduler was sent the command new
07/25/2014 19:38:32;0040;PBS_Server;Svr;tyrone-cluster;Scheduler was sent the command new
07/25/2014 19:38:43;0040;PBS_Server;Svr;tyrone-cluster;Scheduler was sent the command new
07/25/2014 19:39:02;0040;PBS_Server;Svr;tyrone-cluster;Scheduler was sent the command new
07/25/2014 19:39:13;0040;PBS_Server;Svr;tyrone-cluster;Scheduler was sent the command new
07/25/2014 19:39:32;0040;PBS_Server;Svr;tyrone-cluster;Scheduler was sent the command new
07/25/2014 19:39:43;0040;PBS_Server;Svr;tyrone-cluster;Scheduler was sent the command new
07/25/2014 19:40:02;0040;PBS_Server;Svr;tyrone-cluster;Scheduler was sent the command new
07/25/2014 19:40:13;0040;PBS_Server;Svr;tyrone-cluster;Scheduler was sent the command new
07/25/2014 19:40:19;0002;PBS_Server;Svr;PBS_Server;Torque Server Version = 3.0.5, loglevel = 0
07/25/2014 19:40:32;0040;PBS_Server;Svr;tyrone-cluster;Scheduler was sent the command new
07/25/2014 19:40:44;0040;PBS_Server;Svr;tyrone-cluster;Scheduler was sent the command new
07/25/2014 19:41:02;0040;PBS_Server;Svr;tyrone-cluster;Scheduler was sent the command new
07/25/2014 19:41:14;0040;PBS_Server;Svr;tyrone-cluster;Scheduler was sent the command new
07/25/2014 19:41:32;0040;PBS_Server;Svr;tyrone-cluster;Scheduler was sent the command new
07/25/2014 19:41:44;0040;PBS_Server;Svr;tyrone-cluster;Scheduler was sent the command new
07/25/2014 19:42:02;0040;PBS_Server;Svr;tyrone-cluster;Scheduler was sent the command new
07/25/2014 19:42:14;0040;PBS_Server;Svr;tyrone-cluster;Scheduler was sent the command new
07/25/2014 19:42:32;0040;PBS_Server;Svr;tyrone-cluster;Scheduler was sent the command new
07/25/2014 19:42:44;0040;PBS_Server;Svr;tyrone-cluster;Scheduler was sent the command new
07/25/2014 19:43:02;0040;PBS_Server;Svr;tyrone-cluster;Scheduler was sent the command new
07/25/2014 19:43:14;0040;PBS_Server;Svr;tyrone-cluster;Scheduler was sent the command new
07/25/2014 19:43:33;0040;PBS_Server;Svr;tyrone-cluster;Scheduler was sent the command new
07/25/2014 19:43:44;0040;PBS_Server;Svr;tyrone-cluster;Scheduler was sent the command new
07/25/2014 19:44:02;0040;PBS_Server;Svr;tyrone-cluster;Scheduler was sent the command new
07/25/2014 19:44:14;0040;PBS_Server;Svr;tyrone-cluster;Scheduler was sent the command new
07/25/2014 19:44:33;0040;PBS_Server;Svr;tyrone-cluster;Scheduler was sent the command new
07/25/2014 19:44:44;0040;PBS_Server;Svr;tyrone-cluster;Scheduler was sent the command new
07/25/2014 19:45:03;0040;PBS_Server;Svr;tyrone-cluster;Scheduler was sent the command new
07/25/2014 19:45:14;0040;PBS_Server;Svr;tyrone-cluster;Scheduler was sent the command new
07/25/2014 19:45:19;0002;PBS_Server;Svr;PBS_Server;Torque Server Version = 3.0.5, loglevel = 0
07/25/2014 19:45:33;0040;PBS_Server;Svr;tyrone-cluster;Scheduler was sent the command new
07/25/2014 19:45:44;0040;PBS_Server;Svr;tyrone-cluster;Scheduler was sent the command new
07/25/2014 19:46:03;0040;PBS_Server;Svr;tyrone-cluster;Scheduler was sent the command new
07/25/2014 19:46:14;0040;PBS_Server;Svr;tyrone-cluster;Scheduler was sent the command new
07/25/2014 19:46:33;0040;PBS_Server;Svr;tyrone-cluster;Scheduler was sent the command new
07/25/2014 19:46:44;0040;PBS_Server;Svr;tyrone-cluster;Scheduler was sent the command new
07/25/2014 19:47:03;0040;PBS_Server;Svr;tyrone-cluster;Scheduler was sent the command new
07/25/2014 19:47:14;0040;PBS_Server;Svr;tyrone-cluster;Scheduler was sent the command new
07/25/2014 19:47:33;0040;PBS_Server;Svr;tyrone-cluster;Scheduler was sent the command new
07/25/2014 19:47:44;0040;PBS_Server;Svr;tyrone-cluster;Scheduler was sent the command new
07/25/2014 19:48:03;0040;PBS_Server;Svr;tyrone-cluster;Scheduler was sent the command new
07/25/2014 19:48:14;0040;PBS_Server;Svr;tyrone-cluster;Scheduler was sent the command new
07/25/2014 19:48:33;0040;PBS_Server;Svr;tyrone-cluster;Scheduler was sent the command new
07/25/2014 19:48:44;0040;PBS_Server;Svr;tyrone-cluster;Scheduler was sent the command new
07/25/2014 19:49:03;0040;PBS_Server;Svr;tyrone-cluster;Scheduler was sent the command new
07/25/2014 19:49:14;0040;PBS_Server;Svr;tyrone-cluster;Scheduler was sent the command new
07/25/2014 19:49:33;0040;PBS_Server;Svr;tyrone-cluster;Scheduler was sent the command new
07/25/2014 19:49:45;0040;PBS_Server;Svr;tyrone-cluster;Scheduler was sent the command new
07/25/2014 19:50:03;0040;PBS_Server;Svr;tyrone-cluster;Scheduler was sent the command new
07/25/2014 19:50:15;0040;PBS_Server;Svr;tyrone-cluster;Scheduler was sent the command new
07/25/2014 19:50:19;0002;PBS_Server;Svr;PBS_Server;Torque Server Version = 3.0.5, loglevel = 0
07/25/2014 19:50:33;0040;PBS_Server;Svr;tyrone-cluster;Scheduler was sent the command new
07/25/2014 19:50:45;0040;PBS_Server;Svr;tyrone-cluster;Scheduler was sent the command new
07/25/2014 19:51:03;0040;PBS_Server;Svr;tyrone-cluster;Scheduler was sent the command new
07/25/2014 19:51:15;0040;PBS_Server;Svr;tyrone-cluster;Scheduler was sent the command new
07/25/2014 19:51:33;0040;PBS_Server;Svr;tyrone-cluster;Scheduler was sent the command new
07/25/2014 19:51:45;0040;PBS_Server;Svr;tyrone-cluster;Scheduler was sent the command new
07/25/2014 19:52:03;0040;PBS_Server;Svr;tyrone-cluster;Scheduler was sent the command new
07/25/2014 19:52:15;0040;PBS_Server;Svr;tyrone-cluster;Scheduler was sent the command new
07/25/2014 19:52:33;0040;PBS_Server;Svr;tyrone-cluster;Scheduler was sent the command new
07/25/2014 19:52:45;0040;PBS_Server;Svr;tyrone-cluster;Scheduler was sent the command new
07/25/2014 19:53:04;0040;PBS_Server;Svr;tyrone-cluster;Scheduler was sent the command new
07/25/2014 19:53:15;0040;PBS_Server;Svr;tyrone-cluster;Scheduler was sent the command new
07/25/2014 19:53:34;0040;PBS_Server;Svr;tyrone-cluster;Scheduler was sent the command new
07/25/2014 19:53:41;000d;PBS_Server;Job;40653.tyrone-cluster;Not sending email: User does not want mail of this type.
07/25/2014 19:53:41;0010;PBS_Server;Job;40653.tyrone-cluster;Exit_status=143 resources_used.cput=767:00:54 resources_used.mem=2195296kb resources_used.vmem=5874828kb resources_used.walltime=24:00:36
07/25/2014 19:53:41;0008;PBS_Server;Job;NULL;on_job_exit valid pjob: 0x1f0d660 (substate=50)
07/25/2014 19:53:41;0008;PBS_Server;Job;NULL;on_job_exit valid pjob: 0x1f0d660 (substate=51)
07/25/2014 19:53:41;0008;PBS_Server;Job;NULL;on_job_exit valid pjob: 0x1f0d660 (substate=51)
07/25/2014 19:53:41;0008;PBS_Server;Job;NULL;on_job_exit valid pjob: 0x1f0d660 (substate=53)
07/25/2014 19:53:41;0100;PBS_Server;Job;40653.tyrone-cluster;dequeuing from qp32, state COMPLETE
07/25/2014 19:53:41;0040;PBS_Server;Svr;tyrone-cluster;Scheduler was sent the command term
07/25/2014 19:53:41;0008;PBS_Server;Job;40670.tyrone-cluster;Job Modified at request of Scheduler@tyrone-cluster
07/25/2014 19:53:41;0008;PBS_Server;Job;40670.tyrone-cluster;Job Run at request of Scheduler@tyrone-cluster
07/25/2014 19:53:41;0040;PBS_Server;Svr;tyrone-cluster;Scheduler was sent the command recyc
07/25/2014 19:53:41;000d;PBS_Server;Job;40670.tyrone-cluster;Not sending email: User does not want mail of this type.
07/25/2014 19:53:45;0040;PBS_Server;Svr;tyrone-cluster;Scheduler was sent the command new
07/25/2014 19:54:04;0040;PBS_Server;Svr;tyrone-cluster;Scheduler was sent the command new
07/25/2014 19:54:15;0040;PBS_Server;Svr;tyrone-cluster;Scheduler was sent the command new
07/25/2014 19:54:34;0040;PBS_Server;Svr;tyrone-cluster;Scheduler was sent the command new
07/25/2014 19:54:45;0040;PBS_Server;Svr;tyrone-cluster;Scheduler was sent the command new
07/25/2014 19:55:04;0040;PBS_Server;Svr;tyrone-cluster;Scheduler was sent the command new
07/25/2014 19:55:15;0040;PBS_Server;Svr;tyrone-cluster;Scheduler was sent the command new
07/25/2014 19:55:19;0002;PBS_Server;Svr;PBS_Server;Torque Server Version = 3.0.5, loglevel = 0
07/25/2014 19:55:34;0040;PBS_Server;Svr;tyrone-cluster;Scheduler was sent the command new
07/25/2014 19:55:45;0040;PBS_Server;Svr;tyrone-cluster;Scheduler was sent the command new
07/25/2014 19:56:04;0040;PBS_Server;Svr;tyrone-cluster;Scheduler was sent the command new
07/25/2014 19:56:15;0040;PBS_Server;Svr;tyrone-cluster;Scheduler was sent the command new
07/25/2014 19:56:34;0040;PBS_Server;Svr;tyrone-cluster;Scheduler was sent the command new
07/25/2014 19:56:45;0040;PBS_Server;Svr;tyrone-cluster;Scheduler was sent the command new
07/25/2014 19:57:04;0040;PBS_Server;Svr;tyrone-cluster;Scheduler was sent the command new
07/25/2014 19:57:15;0040;PBS_Server;Svr;tyrone-cluster;Scheduler was sent the command new
07/25/2014 19:57:34;0040;PBS_Server;Svr;tyrone-cluster;Scheduler was sent the command new
07/25/2014 19:57:45;0040;PBS_Server;Svr;tyrone-cluster;Scheduler was sent the command new
07/25/2014 19:58:04;0040;PBS_Server;Svr;tyrone-cluster;Scheduler was sent the command new
07/25/2014 19:58:15;0040;PBS_Server;Svr;tyrone-cluster;Scheduler was sent the command new
07/25/2014 19:58:34;0040;PBS_Server;Svr;tyrone-cluster;Scheduler was sent the command new
07/25/2014 19:58:46;0040;PBS_Server;Svr;tyrone-cluster;Scheduler was sent the command new
07/25/2014 19:59:04;0040;PBS_Server;Svr;tyrone-cluster;Scheduler was sent the command new
07/25/2014 19:59:16;0040;PBS_Server;Svr;tyrone-cluster;Scheduler was sent the command new
07/25/2014 19:59:34;0040;PBS_Server;Svr;tyrone-cluster;Scheduler was sent the command new
07/25/2014 19:59:46;0040;PBS_Server;Svr;tyrone-cluster;Scheduler was sent the command new
07/25/2014 20:00:04;0040;PBS_Server;Svr;tyrone-cluster;Scheduler was sent the command new
07/25/2014 20:00:16;0040;PBS_Server;Svr;tyrone-cluster;Scheduler was sent the command new
07/25/2014 20:00:19;0002;PBS_Server;Svr;PBS_Server;Torque Server Version = 3.0.5, loglevel = 0
07/25/2014 20:00:34;0040;PBS_Server;Svr;tyrone-cluster;Scheduler was sent the command new
07/25/2014 20:00:46;0040;PBS_Server;Svr;tyrone-cluster;Scheduler was sent the command new
07/25/2014 20:01:04;0040;PBS_Server;Svr;tyrone-cluster;Scheduler was sent the command new
07/25/2014 20:01:16;0040;PBS_Server;Svr;tyrone-cluster;Scheduler was sent the command new
07/25/2014 20:01:35;0040;PBS_Server;Svr;tyrone-cluster;Scheduler was sent the command new
07/25/2014 20:01:46;0040;PBS_Server;Svr;tyrone-cluster;Scheduler was sent the command new
07/25/2014 20:02:05;0040;PBS_Server;Svr;tyrone-cluster;Scheduler was sent the command new
07/25/2014 20:02:16;0040;PBS_Server;Svr;tyrone-cluster;Scheduler was sent the command new
07/25/2014 20:02:35;0040;PBS_Server;Svr;tyrone-cluster;Scheduler was sent the command new
07/25/2014 20:02:46;0040;PBS_Server;Svr;tyrone-cluster;Scheduler was sent the command new
07/25/2014 20:03:05;0040;PBS_Server;Svr;tyrone-cluster;Scheduler was sent the command new
07/25/2014 20:03:16;0040;PBS_Server;Svr;tyrone-cluster;Scheduler was sent the command new
07/25/2014 20:03:35;0040;PBS_Server;Svr;tyrone-cluster;Scheduler was sent the command new
07/25/2014 20:03:46;0040;PBS_Server;Svr;tyrone-cluster;Scheduler was sent the command new
07/25/2014 20:04:05;0040;PBS_Server;Svr;tyrone-cluster;Scheduler was sent the command new
07/25/2014 20:04:16;0040;PBS_Server;Svr;tyrone-cluster;Scheduler was sent the command new
07/25/2014 20:04:35;0040;PBS_Server;Svr;tyrone-cluster;Scheduler was sent the command new
07/25/2014 20:04:46;0040;PBS_Server;Svr;tyrone-cluster;Scheduler was sent the command new
07/25/2014 20:05:05;0040;PBS_Server;Svr;tyrone-cluster;Scheduler was sent the command new
07/25/2014 20:05:16;0040;PBS_Server;Svr;tyrone-cluster;Scheduler was sent the command new
07/25/2014 20:05:19;0002;PBS_Server;Svr;PBS_Server;Torque Server Version = 3.0.5, loglevel = 0
07/25/2014 20:05:35;0040;PBS_Server;Svr;tyrone-cluster;Scheduler was sent the command new
07/25/2014 20:05:46;0040;PBS_Server;Svr;tyrone-cluster;Scheduler was sent the command new
07/25/2014 20:06:05;0040;PBS_Server;Svr;tyrone-cluster;Scheduler was sent the command new
07/25/2014 20:06:16;0040;PBS_Server;Svr;tyrone-cluster;Scheduler was sent the command new
07/25/2014 20:06:35;0040;PBS_Server;Svr;tyrone-cluster;Scheduler was sent the command new
07/25/2014 20:06:46;0040;PBS_Server;Svr;tyrone-cluster;Scheduler was sent the command new
07/25/2014 20:07:05;0040;PBS_Server;Svr;tyrone-cluster;Scheduler was sent the command new
07/25/2014 20:07:16;0040;PBS_Server;Svr;tyrone-cluster;Scheduler was sent the command new
07/25/2014 20:07:35;0040;PBS_Server;Svr;tyrone-cluster;Scheduler was sent the command new
07/25/2014 20:07:47;0040;PBS_Server;Svr;tyrone-cluster;Scheduler was sent the command new
07/25/2014 20:08:05;0040;PBS_Server;Svr;tyrone-cluster;Scheduler was sent the command new
07/25/2014 20:08:17;0040;PBS_Server;Svr;tyrone-cluster;Scheduler was sent the command new
07/25/2014 20:08:35;0040;PBS_Server;Svr;tyrone-cluster;Scheduler was sent the command new
07/25/2014 20:08:47;0040;PBS_Server;Svr;tyrone-cluster;Scheduler was sent the command new
07/25/2014 20:09:05;0040;PBS_Server;Svr;tyrone-cluster;Scheduler was sent the command new
07/25/2014 20:09:17;0040;PBS_Server;Svr;tyrone-cluster;Scheduler was sent the command new
07/25/2014 20:09:35;0040;PBS_Server;Svr;tyrone-cluster;Scheduler was sent the command new
07/25/2014 20:09:47;0040;PBS_Server;Svr;tyrone-cluster;Scheduler was sent the command new
07/25/2014 20:10:05;0040;PBS_Server;Svr;tyrone-cluster;Scheduler was sent the command new
07/25/2014 20:10:17;0040;PBS_Server;Svr;tyrone-cluster;Scheduler was sent the command new
07/25/2014 20:10:19;0002;PBS_Server;Svr;PBS_Server;Torque Server Version = 3.0.5, loglevel = 0
07/25/2014 20:10:35;0040;PBS_Server;Svr;tyrone-cluster;Scheduler was sent the command new
07/25/2014 20:10:47;0040;PBS_Server;Svr;tyrone-cluster;Scheduler was sent the command new
07/25/2014 20:11:06;0040;PBS_Server;Svr;tyrone-cluster;Scheduler was sent the command new
07/25/2014 20:11:17;0040;PBS_Server;Svr;tyrone-cluster;Scheduler was sent the command new
07/25/2014 20:11:36;0040;PBS_Server;Svr;tyrone-cluster;Scheduler was sent the command new
07/25/2014 20:11:47;0040;PBS_Server;Svr;tyrone-cluster;Scheduler was sent the command new
07/25/2014 20:12:06;0040;PBS_Server;Svr;tyrone-cluster;Scheduler was sent the command new
07/25/2014 20:12:17;0040;PBS_Server;Svr;tyrone-cluster;Scheduler was sent the command new
07/25/2014 20:12:36;0040;PBS_Server;Svr;tyrone-cluster;Scheduler was sent the command new
07/25/2014 20:12:47;0040;PBS_Server;Svr;tyrone-cluster;Scheduler was sent the command new
07/25/2014 20:13:06;0040;PBS_Server;Svr;tyrone-cluster;Scheduler was sent the command new
07/25/2014 20:13:17;0040;PBS_Server;Svr;tyrone-cluster;Scheduler was sent the command new
07/25/2014 20:13:36;0040;PBS_Server;Svr;tyrone-cluster;Scheduler was sent the command new
07/25/2014 20:13:47;0040;PBS_Server;Svr;tyrone-cluster;Scheduler was sent the command new
07/25/2014 20:14:06;0040;PBS_Server;Svr;tyrone-cluster;Scheduler was sent the command new
07/25/2014 20:14:17;0040;PBS_Server;Svr;tyrone-cluster;Scheduler was sent the command new
07/25/2014 20:14:36;0040;PBS_Server;Svr;tyrone-cluster;Scheduler was sent the command new
07/25/2014 20:14:47;0040;PBS_Server;Svr;tyrone-cluster;Scheduler was sent the command new
07/25/2014 20:15:06;0040;PBS_Server;Svr;tyrone-cluster;Scheduler was sent the command new
07/25/2014 20:15:17;0040;PBS_Server;Svr;tyrone-cluster;Scheduler was sent the command new
07/25/2014 20:15:17;000d;PBS_Server;Job;40671.tyrone-cluster;Not sending email: User does not want mail of this type.
07/25/2014 20:15:17;0010;PBS_Server;Job;40671.tyrone-cluster;Exit_status=0 resources_used.cput=253:41:49 resources_used.mem=6802016kb resources_used.vmem=18589108kb resources_used.walltime=08:05:09
07/25/2014 20:15:17;0008;PBS_Server;Job;NULL;on_job_exit valid pjob: 0x1eb2700 (substate=50)
07/25/2014 20:15:17;0008;PBS_Server;Job;NULL;on_job_exit valid pjob: 0x1eb2700 (substate=51)
07/25/2014 20:15:17;0008;PBS_Server;Job;NULL;on_job_exit valid pjob: 0x1eb2700 (substate=51)
07/25/2014 20:15:17;0008;PBS_Server;Job;NULL;on_job_exit valid pjob: 0x1eb2700 (substate=53)
07/25/2014 20:15:17;0100;PBS_Server;Job;40671.tyrone-cluster;dequeuing from qp128, state COMPLETE
07/25/2014 20:15:19;0002;PBS_Server;Svr;PBS_Server;Torque Server Version = 3.0.5, loglevel = 0
07/25/2014 20:15:36;0040;PBS_Server;Svr;tyrone-cluster;Scheduler was sent the command new
07/25/2014 20:15:47;0040;PBS_Server;Svr;tyrone-cluster;Scheduler was sent the command new
07/25/2014 20:16:06;0040;PBS_Server;Svr;tyrone-cluster;Scheduler was sent the command new
07/25/2014 20:16:17;0040;PBS_Server;Svr;tyrone-cluster;Scheduler was sent the command new
07/25/2014 20:16:36;0040;PBS_Server;Svr;tyrone-cluster;Scheduler was sent the command new
07/25/2014 20:16:47;0040;PBS_Server;Svr;tyrone-cluster;Scheduler was sent the command new
07/25/2014 20:17:06;0040;PBS_Server;Svr;tyrone-cluster;Scheduler was sent the command new
07/25/2014 20:17:17;0040;PBS_Server;Svr;tyrone-cluster;Scheduler was sent the command new
07/25/2014 20:17:36;0040;PBS_Server;Svr;tyrone-cluster;Scheduler was sent the command new
07/25/2014 20:17:48;0040;PBS_Server;Svr;tyrone-cluster;Scheduler was sent the command new
07/25/2014 20:18:06;0040;PBS_Server;Svr;tyrone-cluster;Scheduler was sent the command new
07/25/2014 20:18:18;0040;PBS_Server;Svr;tyrone-cluster;Scheduler was sent the command new
07/25/2014 20:18:36;0040;PBS_Server;Svr;tyrone-cluster;Scheduler was sent the command new
07/25/2014 20:18:48;0040;PBS_Server;Svr;tyrone-cluster;Scheduler was sent the command new
07/25/2014 20:19:06;0040;PBS_Server;Svr;tyrone-cluster;Scheduler was sent the command new
07/25/2014 20:19:18;0040;PBS_Server;Svr;tyrone-cluster;Scheduler was sent the command new
07/25/2014 20:19:36;0040;PBS_Server;Svr;tyrone-cluster;Scheduler was sent the command new
07/25/2014 20:19:48;0040;PBS_Server;Svr;tyrone-cluster;Scheduler was sent the command new
07/25/2014 20:20:06;0040;PBS_Server;Svr;tyrone-cluster;Scheduler was sent the command new
07/25/2014 20:20:18;0040;PBS_Server;Svr;tyrone-cluster;Scheduler was sent the command new
07/25/2014 20:20:19;0002;PBS_Server;Svr;PBS_Server;Torque Server Version = 3.0.5, loglevel = 0
07/25/2014 20:20:37;0040;PBS_Server;Svr;tyrone-cluster;Scheduler was sent the command new
07/25/2014 20:20:48;0040;PBS_Server;Svr;tyrone-cluster;Scheduler was sent the command new
07/25/2014 20:21:07;0040;PBS_Server;Svr;tyrone-cluster;Scheduler was sent the command new
07/25/2014 20:21:18;0040;PBS_Server;Svr;tyrone-cluster;Scheduler was sent the command new
07/25/2014 20:21:37;0040;PBS_Server;Svr;tyrone-cluster;Scheduler was sent the command new
07/25/2014 20:21:48;0040;PBS_Server;Svr;tyrone-cluster;Scheduler was sent the command new
07/25/2014 20:22:07;0040;PBS_Server;Svr;tyrone-cluster;Scheduler was sent the command new
07/25/2014 20:22:18;0040;PBS_Server;Svr;tyrone-cluster;Scheduler was sent the command new
07/25/2014 20:22:37;0040;PBS_Server;Svr;tyrone-cluster;Scheduler was sent the command new
07/25/2014 20:22:48;0040;PBS_Server;Svr;tyrone-cluster;Scheduler was sent the command new
07/25/2014 20:23:07;0040;PBS_Server;Svr;tyrone-cluster;Scheduler was sent the command new
07/25/2014 20:23:18;0040;PBS_Server;Svr;tyrone-cluster;Scheduler was sent the command new
07/25/2014 20:23:37;0040;PBS_Server;Svr;tyrone-cluster;Scheduler was sent the command new
07/25/2014 20:23:48;0040;PBS_Server;Svr;tyrone-cluster;Scheduler was sent the command new
07/25/2014 20:24:07;0040;PBS_Server;Svr;tyrone-cluster;Scheduler was sent the command new
07/25/2014 20:24:18;0040;PBS_Server;Svr;tyrone-cluster;Scheduler was sent the command new
07/25/2014 20:24:37;0040;PBS_Server;Svr;tyrone-cluster;Scheduler was sent the command new
07/25/2014 20:24:48;0040;PBS_Server;Svr;tyrone-cluster;Scheduler was sent the command new
07/25/2014 20:25:07;0040;PBS_Server;Svr;tyrone-cluster;Scheduler was sent the command new
07/25/2014 20:25:18;0040;PBS_Server;Svr;tyrone-cluster;Scheduler was sent the command new
07/25/2014 20:25:19;0002;PBS_Server;Svr;PBS_Server;Torque Server Version = 3.0.5, loglevel = 0
07/25/2014 20:25:37;0040;PBS_Server;Svr;tyrone-cluster;Scheduler was sent the command new
07/25/2014 20:25:48;0040;PBS_Server;Svr;tyrone-cluster;Scheduler was sent the command new
07/25/2014 20:26:07;0040;PBS_Server;Svr;tyrone-cluster;Scheduler was sent the command new
07/25/2014 20:26:18;0040;PBS_Server;Svr;tyrone-cluster;Scheduler was sent the command new
07/25/2014 20:26:37;0040;PBS_Server;Svr;tyrone-cluster;Scheduler was sent the command new
07/25/2014 20:26:48;0040;PBS_Server;Svr;tyrone-cluster;Scheduler was sent the command new
07/25/2014 20:27:07;0040;PBS_Server;Svr;tyrone-cluster;Scheduler was sent the command new
07/25/2014 20:27:19;0040;PBS_Server;Svr;tyrone-cluster;Scheduler was sent the command new
07/25/2014 20:27:37;0040;PBS_Server;Svr;tyrone-cluster;Scheduler was sent the command new
07/25/2014 20:27:49;0040;PBS_Server;Svr;tyrone-cluster;Scheduler was sent the command new
07/25/2014 20:28:07;0040;PBS_Server;Svr;tyrone-cluster;Scheduler was sent the command new
07/25/2014 20:28:19;0040;PBS_Server;Svr;tyrone-cluster;Scheduler was sent the command new
07/25/2014 20:28:37;0040;PBS_Server;Svr;tyrone-cluster;Scheduler was sent the command new
07/25/2014 20:28:49;0040;PBS_Server;Svr;tyrone-cluster;Scheduler was sent the command new
07/25/2014 20:29:07;0040;PBS_Server;Svr;tyrone-cluster;Scheduler was sent the command new
07/25/2014 20:29:19;0040;PBS_Server;Svr;tyrone-cluster;Scheduler was sent the command new
07/25/2014 20:29:38;0040;PBS_Server;Svr;tyrone-cluster;Scheduler was sent the command new
07/25/2014 20:29:49;0040;PBS_Server;Svr;tyrone-cluster;Scheduler was sent the command new
07/25/2014 20:30:08;0040;PBS_Server;Svr;tyrone-cluster;Scheduler was sent the command new
07/25/2014 20:30:19;0002;PBS_Server;Svr;PBS_Server;Torque Server Version = 3.0.5, loglevel = 0
07/25/2014 20:30:19;0040;PBS_Server;Svr;tyrone-cluster;Scheduler was sent the command new
07/25/2014 20:30:38;0040;PBS_Server;Svr;tyrone-cluster;Scheduler was sent the command new
07/25/2014 20:30:39;0100;PBS_Server;Job;40701.tyrone-cluster;enqueuing into batch, state 1 hop 1
07/25/2014 20:30:39;0100;PBS_Server;Job;40701.tyrone-cluster;dequeuing from batch, state QUEUED
07/25/2014 20:30:39;0100;PBS_Server;Job;40701.tyrone-cluster;enqueuing into qp32, state 1 hop 1
07/25/2014 20:30:39;0008;PBS_Server;Job;40701.tyrone-cluster;Job Queued at request of asesaba@tyrone-cluster, owner = asesaba@tyrone-cluster, job name = laminarunsteady, queue = qp32
07/25/2014 20:30:39;0040;PBS_Server;Svr;tyrone-cluster;Scheduler was sent the command new
07/25/2014 20:30:39;0008;PBS_Server;Job;40701.tyrone-cluster;Job Modified at request of Scheduler@tyrone-cluster
07/25/2014 20:30:49;0040;PBS_Server;Svr;tyrone-cluster;Scheduler was sent the command new
07/25/2014 20:31:08;0040;PBS_Server;Svr;tyrone-cluster;Scheduler was sent the command new
07/25/2014 20:31:19;0040;PBS_Server;Svr;tyrone-cluster;Scheduler was sent the command new
07/25/2014 20:31:38;0040;PBS_Server;Svr;tyrone-cluster;Scheduler was sent the command new
07/25/2014 20:31:49;0040;PBS_Server;Svr;tyrone-cluster;Scheduler was sent the command new
07/25/2014 20:32:08;0040;PBS_Server;Svr;tyrone-cluster;Scheduler was sent the command new
07/25/2014 20:32:19;0040;PBS_Server;Svr;tyrone-cluster;Scheduler was sent the command new
07/25/2014 20:32:38;0040;PBS_Server;Svr;tyrone-cluster;Scheduler was sent the command new
07/25/2014 20:32:49;0040;PBS_Server;Svr;tyrone-cluster;Scheduler was sent the command new
07/25/2014 20:33:08;0040;PBS_Server;Svr;tyrone-cluster;Scheduler was sent the command new
07/25/2014 20:33:19;0040;PBS_Server;Svr;tyrone-cluster;Scheduler was sent the command new
07/25/2014 20:33:38;0040;PBS_Server;Svr;tyrone-cluster;Scheduler was sent the command new
07/25/2014 20:33:49;0040;PBS_Server;Svr;tyrone-cluster;Scheduler was sent the command new
07/25/2014 20:34:08;0040;PBS_Server;Svr;tyrone-cluster;Scheduler was sent the command new
07/25/2014 20:34:19;0040;PBS_Server;Svr;tyrone-cluster;Scheduler was sent the command new
07/25/2014 20:34:38;0040;PBS_Server;Svr;tyrone-cluster;Scheduler was sent the command new
07/25/2014 20:34:49;0040;PBS_Server;Svr;tyrone-cluster;Scheduler was sent the command new
07/25/2014 20:35:08;0040;PBS_Server;Svr;tyrone-cluster;Scheduler was sent the command new
07/25/2014 20:35:19;0002;PBS_Server;Svr;PBS_Server;Torque Server Version = 3.0.5, loglevel = 0
07/25/2014 20:35:19;0040;PBS_Server;Svr;tyrone-cluster;Scheduler was sent the command new
07/25/2014 20:35:38;0040;PBS_Server;Svr;tyrone-cluster;Scheduler was sent the command new
07/25/2014 20:35:49;0040;PBS_Server;Svr;tyrone-cluster;Scheduler was sent the command new
07/25/2014 20:36:08;0040;PBS_Server;Svr;tyrone-cluster;Scheduler was sent the command new
07/25/2014 20:36:19;0040;PBS_Server;Svr;tyrone-cluster;Scheduler was sent the command new
07/25/2014 20:36:38;0040;PBS_Server;Svr;tyrone-cluster;Scheduler was sent the command new
07/25/2014 20:36:50;0040;PBS_Server;Svr;tyrone-cluster;Scheduler was sent the command new
07/25/2014 20:37:08;0040;PBS_Server;Svr;tyrone-cluster;Scheduler was sent the command new
07/25/2014 20:37:20;0040;PBS_Server;Svr;tyrone-cluster;Scheduler was sent the command new
07/25/2014 20:37:38;0040;PBS_Server;Svr;tyrone-cluster;Scheduler was sent the command new
07/25/2014 20:37:50;0040;PBS_Server;Svr;tyrone-cluster;Scheduler was sent the command new
07/25/2014 20:38:08;0040;PBS_Server;Svr;tyrone-cluster;Scheduler was sent the command new
07/25/2014 20:38:20;0040;PBS_Server;Svr;tyrone-cluster;Scheduler was sent the command new
07/25/2014 20:38:38;0040;PBS_Server;Svr;tyrone-cluster;Scheduler was sent the command new
07/25/2014 20:38:50;0040;PBS_Server;Svr;tyrone-cluster;Scheduler was sent the command new
07/25/2014 20:39:09;0040;PBS_Server;Svr;tyrone-cluster;Scheduler was sent the command new
07/25/2014 20:39:20;0040;PBS_Server;Svr;tyrone-cluster;Scheduler was sent the command new
07/25/2014 20:39:39;0040;PBS_Server;Svr;tyrone-cluster;Scheduler was sent the command new
07/25/2014 20:39:50;0040;PBS_Server;Svr;tyrone-cluster;Scheduler was sent the command new
07/25/2014 20:40:09;0040;PBS_Server;Svr;tyrone-cluster;Scheduler was sent the command new
07/25/2014 20:40:19;0002;PBS_Server;Svr;PBS_Server;Torque Server Version = 3.0.5, loglevel = 0
07/25/2014 20:40:20;0040;PBS_Server;Svr;tyrone-cluster;Scheduler was sent the command new
07/25/2014 20:40:39;0040;PBS_Server;Svr;tyrone-cluster;Scheduler was sent the command new
07/25/2014 20:40:50;0040;PBS_Server;Svr;tyrone-cluster;Scheduler was sent the command new
07/25/2014 20:41:09;0040;PBS_Server;Svr;tyrone-cluster;Scheduler was sent the command new
07/25/2014 20:41:20;0040;PBS_Server;Svr;tyrone-cluster;Scheduler was sent the command new
07/25/2014 20:41:39;0040;PBS_Server;Svr;tyrone-cluster;Scheduler was sent the command new
07/25/2014 20:41:50;0040;PBS_Server;Svr;tyrone-cluster;Scheduler was sent the command new
07/25/2014 20:42:09;0040;PBS_Server;Svr;tyrone-cluster;Scheduler was sent the command new
07/25/2014 20:42:20;0040;PBS_Server;Svr;tyrone-cluster;Scheduler was sent the command new
07/25/2014 20:42:39;0040;PBS_Server;Svr;tyrone-cluster;Scheduler was sent the command new
07/25/2014 20:42:50;0040;PBS_Server;Svr;tyrone-cluster;Scheduler was sent the command new
07/25/2014 20:43:09;0040;PBS_Server;Svr;tyrone-cluster;Scheduler was sent the command new
07/25/2014 20:43:20;0040;PBS_Server;Svr;tyrone-cluster;Scheduler was sent the command new
07/25/2014 20:43:39;0040;PBS_Server;Svr;tyrone-cluster;Scheduler was sent the command new
07/25/2014 20:43:50;0040;PBS_Server;Svr;tyrone-cluster;Scheduler was sent the command new
07/25/2014 20:44:09;0040;PBS_Server;Svr;tyrone-cluster;Scheduler was sent the command new
07/25/2014 20:44:20;0040;PBS_Server;Svr;tyrone-cluster;Scheduler was sent the command new
07/25/2014 20:44:39;0040;PBS_Server;Svr;tyrone-cluster;Scheduler was sent the command new
07/25/2014 20:44:50;0040;PBS_Server;Svr;tyrone-cluster;Scheduler was sent the command new
07/25/2014 20:45:09;0040;PBS_Server;Svr;tyrone-cluster;Scheduler was sent the command new
07/25/2014 20:45:19;0002;PBS_Server;Svr;PBS_Server;Torque Server Version = 3.0.5, loglevel = 0
07/25/2014 20:45:20;0040;PBS_Server;Svr;tyrone-cluster;Scheduler was sent the command new
07/25/2014 20:45:39;0040;PBS_Server;Svr;tyrone-cluster;Scheduler was sent the command new
07/25/2014 20:45:51;0040;PBS_Server;Svr;tyrone-cluster;Scheduler was sent the command new
07/25/2014 20:46:09;0040;PBS_Server;Svr;tyrone-cluster;Scheduler was sent the command new
07/25/2014 20:46:21;0040;PBS_Server;Svr;tyrone-cluster;Scheduler was sent the command new
07/25/2014 20:46:39;0040;PBS_Server;Svr;tyrone-cluster;Scheduler was sent the command new
07/25/2014 20:46:51;0040;PBS_Server;Svr;tyrone-cluster;Scheduler was sent the command new
07/25/2014 20:47:09;0040;PBS_Server;Svr;tyrone-cluster;Scheduler was sent the command new
07/25/2014 20:47:21;0040;PBS_Server;Svr;tyrone-cluster;Scheduler was sent the command new
07/25/2014 20:47:39;0040;PBS_Server;Svr;tyrone-cluster;Scheduler was sent the command new
07/25/2014 20:47:51;0040;PBS_Server;Svr;tyrone-cluster;Scheduler was sent the command new
07/25/2014 20:48:10;0040;PBS_Server;Svr;tyrone-cluster;Scheduler was sent the command new
07/25/2014 20:48:21;0040;PBS_Server;Svr;tyrone-cluster;Scheduler was sent the command new
07/25/2014 20:48:40;0040;PBS_Server;Svr;tyrone-cluster;Scheduler was sent the command new
07/25/2014 20:48:51;0040;PBS_Server;Svr;tyrone-cluster;Scheduler was sent the command new
07/25/2014 20:49:10;0040;PBS_Server;Svr;tyrone-cluster;Scheduler was sent the command new
07/25/2014 20:49:21;0040;PBS_Server;Svr;tyrone-cluster;Scheduler was sent the command new
07/25/2014 20:49:40;0040;PBS_Server;Svr;tyrone-cluster;Scheduler was sent the command new
07/25/2014 20:49:51;0040;PBS_Server;Svr;tyrone-cluster;Scheduler was sent the command new
07/25/2014 20:50:10;0040;PBS_Server;Svr;tyrone-cluster;Scheduler was sent the command new
07/25/2014 20:50:19;0002;PBS_Server;Svr;PBS_Server;Torque Server Version = 3.0.5, loglevel = 0
07/25/2014 20:50:21;0040;PBS_Server;Svr;tyrone-cluster;Scheduler was sent the command new
07/25/2014 20:50:40;0040;PBS_Server;Svr;tyrone-cluster;Scheduler was sent the command new
07/25/2014 20:50:51;0040;PBS_Server;Svr;tyrone-cluster;Scheduler was sent the command new
07/25/2014 20:51:10;0040;PBS_Server;Svr;tyrone-cluster;Scheduler was sent the command new
07/25/2014 20:51:21;0040;PBS_Server;Svr;tyrone-cluster;Scheduler was sent the command new
07/25/2014 20:51:40;0040;PBS_Server;Svr;tyrone-cluster;Scheduler was sent the command new
07/25/2014 20:51:51;0040;PBS_Server;Svr;tyrone-cluster;Scheduler was sent the command new
07/25/2014 20:52:10;0040;PBS_Server;Svr;tyrone-cluster;Scheduler was sent the command new
07/25/2014 20:52:21;0040;PBS_Server;Svr;tyrone-cluster;Scheduler was sent the command new
07/25/2014 20:52:40;0040;PBS_Server;Svr;tyrone-cluster;Scheduler was sent the command new
07/25/2014 20:52:51;0040;PBS_Server;Svr;tyrone-cluster;Scheduler was sent the command new
07/25/2014 20:53:10;0040;PBS_Server;Svr;tyrone-cluster;Scheduler was sent the command new
07/25/2014 20:53:21;0040;PBS_Server;Svr;tyrone-cluster;Scheduler was sent the command new
07/25/2014 20:53:40;0040;PBS_Server;Svr;tyrone-cluster;Scheduler was sent the command new
07/25/2014 20:53:51;0040;PBS_Server;Svr;tyrone-cluster;Scheduler was sent the command new
07/25/2014 20:54:10;0040;PBS_Server;Svr;tyrone-cluster;Scheduler was sent the command new
07/25/2014 20:54:21;0040;PBS_Server;Svr;tyrone-cluster;Scheduler was sent the command new
07/25/2014 20:54:40;0040;PBS_Server;Svr;tyrone-cluster;Scheduler was sent the command new
07/25/2014 20:54:52;0040;PBS_Server;Svr;tyrone-cluster;Scheduler was sent the command new
07/25/2014 20:55:10;0040;PBS_Server;Svr;tyrone-cluster;Scheduler was sent the command new
07/25/2014 20:55:19;0002;PBS_Server;Svr;PBS_Server;Torque Server Version = 3.0.5, loglevel = 0
07/25/2014 20:55:22;0040;PBS_Server;Svr;tyrone-cluster;Scheduler was sent the command new
07/25/2014 20:55:40;0040;PBS_Server;Svr;tyrone-cluster;Scheduler was sent the command new
07/25/2014 20:55:52;0040;PBS_Server;Svr;tyrone-cluster;Scheduler was sent the command new
07/25/2014 20:56:10;0040;PBS_Server;Svr;tyrone-cluster;Scheduler was sent the command new
07/25/2014 20:56:22;0040;PBS_Server;Svr;tyrone-cluster;Scheduler was sent the command new
07/25/2014 20:56:40;0040;PBS_Server;Svr;tyrone-cluster;Scheduler was sent the command new
07/25/2014 20:56:52;0040;PBS_Server;Svr;tyrone-cluster;Scheduler was sent the command new
07/25/2014 20:57:11;0040;PBS_Server;Svr;tyrone-cluster;Scheduler was sent the command new
07/25/2014 20:57:22;0040;PBS_Server;Svr;tyrone-cluster;Scheduler was sent the command new
07/25/2014 20:57:41;0040;PBS_Server;Svr;tyrone-cluster;Scheduler was sent the command new
07/25/2014 20:57:52;0040;PBS_Server;Svr;tyrone-cluster;Scheduler was sent the command new
07/25/2014 20:58:11;0040;PBS_Server;Svr;tyrone-cluster;Scheduler was sent the command new
07/25/2014 20:58:22;0040;PBS_Server;Svr;tyrone-cluster;Scheduler was sent the command new
07/25/2014 20:58:41;0040;PBS_Server;Svr;tyrone-cluster;Scheduler was sent the command new
07/25/2014 20:58:52;0040;PBS_Server;Svr;tyrone-cluster;Scheduler was sent the command new
07/25/2014 20:59:11;0040;PBS_Server;Svr;tyrone-cluster;Scheduler was sent the command new
07/25/2014 20:59:22;0040;PBS_Server;Svr;tyrone-cluster;Scheduler was sent the command new
07/25/2014 20:59:41;0040;PBS_Server;Svr;tyrone-cluster;Scheduler was sent the command new
07/25/2014 20:59:52;0040;PBS_Server;Svr;tyrone-cluster;Scheduler was sent the command new
07/25/2014 21:00:11;0040;PBS_Server;Svr;tyrone-cluster;Scheduler was sent the command new
07/25/2014 21:00:19;0002;PBS_Server;Svr;PBS_Server;Torque Server Version = 3.0.5, loglevel = 0
07/25/2014 21:00:22;0040;PBS_Server;Svr;tyrone-cluster;Scheduler was sent the command new
07/25/2014 21:00:41;0040;PBS_Server;Svr;tyrone-cluster;Scheduler was sent the command new
07/25/2014 21:00:52;0040;PBS_Server;Svr;tyrone-cluster;Scheduler was sent the command new
07/25/2014 21:01:11;0040;PBS_Server;Svr;tyrone-cluster;Scheduler was sent the command new
07/25/2014 21:01:22;0040;PBS_Server;Svr;tyrone-cluster;Scheduler was sent the command new
07/25/2014 21:01:41;0040;PBS_Server;Svr;tyrone-cluster;Scheduler was sent the command new
07/25/2014 21:01:52;0040;PBS_Server;Svr;tyrone-cluster;Scheduler was sent the command new
07/25/2014 21:02:11;0040;PBS_Server;Svr;tyrone-cluster;Scheduler was sent the command new
07/25/2014 21:02:22;0040;PBS_Server;Svr;tyrone-cluster;Scheduler was sent the command new
07/25/2014 21:02:41;0040;PBS_Server;Svr;tyrone-cluster;Scheduler was sent the command new
07/25/2014 21:02:52;0040;PBS_Server;Svr;tyrone-cluster;Scheduler was sent the command new
07/25/2014 21:03:11;0040;PBS_Server;Svr;tyrone-cluster;Scheduler was sent the command new
07/25/2014 21:03:22;0040;PBS_Server;Svr;tyrone-cluster;Scheduler was sent the command new
07/25/2014 21:03:41;0040;PBS_Server;Svr;tyrone-cluster;Scheduler was sent the command new
07/25/2014 21:03:52;0040;PBS_Server;Svr;tyrone-cluster;Scheduler was sent the command new
07/25/2014 21:04:11;0040;PBS_Server;Svr;tyrone-cluster;Scheduler was sent the command new
07/25/2014 21:04:23;0040;PBS_Server;Svr;tyrone-cluster;Scheduler was sent the command new
07/25/2014 21:04:41;0040;PBS_Server;Svr;tyrone-cluster;Scheduler was sent the command new
07/25/2014 21:04:53;0040;PBS_Server;Svr;tyrone-cluster;Scheduler was sent the command new
07/25/2014 21:05:11;0040;PBS_Server;Svr;tyrone-cluster;Scheduler was sent the command new
07/25/2014 21:05:19;0002;PBS_Server;Svr;PBS_Server;Torque Server Version = 3.0.5, loglevel = 0
07/25/2014 21:05:23;0040;PBS_Server;Svr;tyrone-cluster;Scheduler was sent the command new
07/25/2014 21:05:41;0040;PBS_Server;Svr;tyrone-cluster;Scheduler was sent the command new
07/25/2014 21:05:53;0040;PBS_Server;Svr;tyrone-cluster;Scheduler was sent the command new
07/25/2014 21:06:11;0040;PBS_Server;Svr;tyrone-cluster;Scheduler was sent the command new
07/25/2014 21:06:23;0040;PBS_Server;Svr;tyrone-cluster;Scheduler was sent the command new
07/25/2014 21:06:41;0040;PBS_Server;Svr;tyrone-cluster;Scheduler was sent the command new
07/25/2014 21:06:53;0040;PBS_Server;Svr;tyrone-cluster;Scheduler was sent the command new
07/25/2014 21:07:11;0040;PBS_Server;Svr;tyrone-cluster;Scheduler was sent the command new
07/25/2014 21:07:23;0040;PBS_Server;Svr;tyrone-cluster;Scheduler was sent the command new
07/25/2014 21:07:42;0040;PBS_Server;Svr;tyrone-cluster;Scheduler was sent the command new
07/25/2014 21:07:53;0040;PBS_Server;Svr;tyrone-cluster;Scheduler was sent the command new
07/25/2014 21:08:12;0040;PBS_Server;Svr;tyrone-cluster;Scheduler was sent the command new
07/25/2014 21:08:23;0040;PBS_Server;Svr;tyrone-cluster;Scheduler was sent the command new
07/25/2014 21:08:42;0040;PBS_Server;Svr;tyrone-cluster;Scheduler was sent the command new
07/25/2014 21:08:53;0040;PBS_Server;Svr;tyrone-cluster;Scheduler was sent the command new
07/25/2014 21:09:12;0040;PBS_Server;Svr;tyrone-cluster;Scheduler was sent the command new
07/25/2014 21:09:23;0040;PBS_Server;Svr;tyrone-cluster;Scheduler was sent the command new
07/25/2014 21:09:42;0040;PBS_Server;Svr;tyrone-cluster;Scheduler was sent the command new
07/25/2014 21:09:53;0040;PBS_Server;Svr;tyrone-cluster;Scheduler was sent the command new
07/25/2014 21:10:12;0040;PBS_Server;Svr;tyrone-cluster;Scheduler was sent the command new
07/25/2014 21:10:19;0002;PBS_Server;Svr;PBS_Server;Torque Server Version = 3.0.5, loglevel = 0
07/25/2014 21:10:23;0040;PBS_Server;Svr;tyrone-cluster;Scheduler was sent the command new
07/25/2014 21:10:42;0040;PBS_Server;Svr;tyrone-cluster;Scheduler was sent the command new
07/25/2014 21:10:53;0040;PBS_Server;Svr;tyrone-cluster;Scheduler was sent the command new
07/25/2014 21:11:12;0040;PBS_Server;Svr;tyrone-cluster;Scheduler was sent the command new
07/25/2014 21:11:23;0040;PBS_Server;Svr;tyrone-cluster;Scheduler was sent the command new
07/25/2014 21:11:42;0040;PBS_Server;Svr;tyrone-cluster;Scheduler was sent the command new
07/25/2014 21:11:53;0040;PBS_Server;Svr;tyrone-cluster;Scheduler was sent the command new
07/25/2014 21:12:12;0040;PBS_Server;Svr;tyrone-cluster;Scheduler was sent the command new
07/25/2014 21:12:23;0040;PBS_Server;Svr;tyrone-cluster;Scheduler was sent the command new
07/25/2014 21:12:42;0040;PBS_Server;Svr;tyrone-cluster;Scheduler was sent the command new
07/25/2014 21:12:53;0040;PBS_Server;Svr;tyrone-cluster;Scheduler was sent the command new
07/25/2014 21:13:12;0040;PBS_Server;Svr;tyrone-cluster;Scheduler was sent the command new
07/25/2014 21:13:23;0040;PBS_Server;Svr;tyrone-cluster;Scheduler was sent the command new
07/25/2014 21:13:42;0040;PBS_Server;Svr;tyrone-cluster;Scheduler was sent the command new
07/25/2014 21:13:53;0040;PBS_Server;Svr;tyrone-cluster;Scheduler was sent the command new
07/25/2014 21:14:12;0040;PBS_Server;Svr;tyrone-cluster;Scheduler was sent the command new
07/25/2014 21:14:24;0040;PBS_Server;Svr;tyrone-cluster;Scheduler was sent the command new
07/25/2014 21:14:42;0040;PBS_Server;Svr;tyrone-cluster;Scheduler was sent the command new
07/25/2014 21:14:54;0040;PBS_Server;Svr;tyrone-cluster;Scheduler was sent the command new
07/25/2014 21:15:12;0040;PBS_Server;Svr;tyrone-cluster;Scheduler was sent the command new
07/25/2014 21:15:19;0002;PBS_Server;Svr;PBS_Server;Torque Server Version = 3.0.5, loglevel = 0
07/25/2014 21:15:24;0040;PBS_Server;Svr;tyrone-cluster;Scheduler was sent the command new
07/25/2014 21:15:42;0040;PBS_Server;Svr;tyrone-cluster;Scheduler was sent the command new
07/25/2014 21:15:54;0040;PBS_Server;Svr;tyrone-cluster;Scheduler was sent the command new
07/25/2014 21:16:12;0040;PBS_Server;Svr;tyrone-cluster;Scheduler was sent the command new
07/25/2014 21:16:24;0040;PBS_Server;Svr;tyrone-cluster;Scheduler was sent the command new
07/25/2014 21:16:42;0040;PBS_Server;Svr;tyrone-cluster;Scheduler was sent the command new
07/25/2014 21:16:54;0040;PBS_Server;Svr;tyrone-cluster;Scheduler was sent the command new
07/25/2014 21:17:13;0040;PBS_Server;Svr;tyrone-cluster;Scheduler was sent the command new
07/25/2014 21:17:24;0040;PBS_Server;Svr;tyrone-cluster;Scheduler was sent the command new
07/25/2014 21:17:43;0040;PBS_Server;Svr;tyrone-cluster;Scheduler was sent the command new
07/25/2014 21:17:54;0040;PBS_Server;Svr;tyrone-cluster;Scheduler was sent the command new
07/25/2014 21:18:13;0040;PBS_Server;Svr;tyrone-cluster;Scheduler was sent the command new
07/25/2014 21:18:24;0040;PBS_Server;Svr;tyrone-cluster;Scheduler was sent the command new
07/25/2014 21:18:43;0040;PBS_Server;Svr;tyrone-cluster;Scheduler was sent the command new
07/25/2014 21:18:54;0040;PBS_Server;Svr;tyrone-cluster;Scheduler was sent the command new
07/25/2014 21:19:13;0040;PBS_Server;Svr;tyrone-cluster;Scheduler was sent the command new
07/25/2014 21:19:24;0040;PBS_Server;Svr;tyrone-cluster;Scheduler was sent the command new
07/25/2014 21:19:43;0040;PBS_Server;Svr;tyrone-cluster;Scheduler was sent the command new
07/25/2014 21:19:54;0040;PBS_Server;Svr;tyrone-cluster;Scheduler was sent the command new
07/25/2014 21:20:13;0040;PBS_Server;Svr;tyrone-cluster;Scheduler was sent the command new
07/25/2014 21:20:19;0002;PBS_Server;Svr;PBS_Server;Torque Server Version = 3.0.5, loglevel = 0
07/25/2014 21:20:24;0040;PBS_Server;Svr;tyrone-cluster;Scheduler was sent the command new
07/25/2014 21:20:43;0040;PBS_Server;Svr;tyrone-cluster;Scheduler was sent the command new
07/25/2014 21:20:54;0040;PBS_Server;Svr;tyrone-cluster;Scheduler was sent the command new
07/25/2014 21:21:13;0040;PBS_Server;Svr;tyrone-cluster;Scheduler was sent the command new
07/25/2014 21:21:24;0040;PBS_Server;Svr;tyrone-cluster;Scheduler was sent the command new
07/25/2014 21:21:43;0040;PBS_Server;Svr;tyrone-cluster;Scheduler was sent the command new
07/25/2014 21:21:54;0040;PBS_Server;Svr;tyrone-cluster;Scheduler was sent the command new
07/25/2014 21:22:13;0040;PBS_Server;Svr;tyrone-cluster;Scheduler was sent the command new
07/25/2014 21:22:24;0040;PBS_Server;Svr;tyrone-cluster;Scheduler was sent the command new
07/25/2014 21:22:43;0040;PBS_Server;Svr;tyrone-cluster;Scheduler was sent the command new
07/25/2014 21:22:55;0040;PBS_Server;Svr;tyrone-cluster;Scheduler was sent the command new
07/25/2014 21:23:13;0040;PBS_Server;Svr;tyrone-cluster;Scheduler was sent the command new
07/25/2014 21:23:25;0040;PBS_Server;Svr;tyrone-cluster;Scheduler was sent the command new
07/25/2014 21:23:43;0040;PBS_Server;Svr;tyrone-cluster;Scheduler was sent the command new
07/25/2014 21:23:55;0040;PBS_Server;Svr;tyrone-cluster;Scheduler was sent the command new
07/25/2014 21:24:13;0040;PBS_Server;Svr;tyrone-cluster;Scheduler was sent the command new
07/25/2014 21:24:25;0040;PBS_Server;Svr;tyrone-cluster;Scheduler was sent the command new
07/25/2014 21:24:43;0040;PBS_Server;Svr;tyrone-cluster;Scheduler was sent the command new
07/25/2014 21:24:55;0040;PBS_Server;Svr;tyrone-cluster;Scheduler was sent the command new
07/25/2014 21:25:13;0040;PBS_Server;Svr;tyrone-cluster;Scheduler was sent the command new
07/25/2014 21:25:19;0002;PBS_Server;Svr;PBS_Server;Torque Server Version = 3.0.5, loglevel = 0
07/25/2014 21:25:25;0040;PBS_Server;Svr;tyrone-cluster;Scheduler was sent the command new
07/25/2014 21:25:43;0040;PBS_Server;Svr;tyrone-cluster;Scheduler was sent the command new
07/25/2014 21:25:55;0040;PBS_Server;Svr;tyrone-cluster;Scheduler was sent the command new
07/25/2014 21:26:13;0040;PBS_Server;Svr;tyrone-cluster;Scheduler was sent the command new
07/25/2014 21:26:25;0040;PBS_Server;Svr;tyrone-cluster;Scheduler was sent the command new
07/25/2014 21:26:43;0040;PBS_Server;Svr;tyrone-cluster;Scheduler was sent the command new
07/25/2014 21:26:55;0040;PBS_Server;Svr;tyrone-cluster;Scheduler was sent the command new
07/25/2014 21:27:14;0040;PBS_Server;Svr;tyrone-cluster;Scheduler was sent the command new
07/25/2014 21:27:25;0040;PBS_Server;Svr;tyrone-cluster;Scheduler was sent the command new
07/25/2014 21:27:44;0040;PBS_Server;Svr;tyrone-cluster;Scheduler was sent the command new
07/25/2014 21:27:55;0040;PBS_Server;Svr;tyrone-cluster;Scheduler was sent the command new
07/25/2014 21:28:14;0040;PBS_Server;Svr;tyrone-cluster;Scheduler was sent the command new
07/25/2014 21:28:25;0040;PBS_Server;Svr;tyrone-cluster;Scheduler was sent the command new
07/25/2014 21:28:44;0040;PBS_Server;Svr;tyrone-cluster;Scheduler was sent the command new
07/25/2014 21:28:55;0040;PBS_Server;Svr;tyrone-cluster;Scheduler was sent the command new
07/25/2014 21:29:14;0040;PBS_Server;Svr;tyrone-cluster;Scheduler was sent the command new
07/25/2014 21:29:25;0040;PBS_Server;Svr;tyrone-cluster;Scheduler was sent the command new
07/25/2014 21:29:44;0040;PBS_Server;Svr;tyrone-cluster;Scheduler was sent the command new
07/25/2014 21:29:55;0040;PBS_Server;Svr;tyrone-cluster;Scheduler was sent the command new
07/25/2014 21:30:14;0040;PBS_Server;Svr;tyrone-cluster;Scheduler was sent the command new
07/25/2014 21:30:19;0002;PBS_Server;Svr;PBS_Server;Torque Server Version = 3.0.5, loglevel = 0
07/25/2014 21:30:25;0040;PBS_Server;Svr;tyrone-cluster;Scheduler was sent the command new
07/25/2014 21:30:44;0040;PBS_Server;Svr;tyrone-cluster;Scheduler was sent the command new
07/25/2014 21:30:55;0040;PBS_Server;Svr;tyrone-cluster;Scheduler was sent the command new
07/25/2014 21:31:14;0040;PBS_Server;Svr;tyrone-cluster;Scheduler was sent the command new
07/25/2014 21:31:25;0040;PBS_Server;Svr;tyrone-cluster;Scheduler was sent the command new
07/25/2014 21:31:44;0040;PBS_Server;Svr;tyrone-cluster;Scheduler was sent the command new
07/25/2014 21:31:55;0040;PBS_Server;Svr;tyrone-cluster;Scheduler was sent the command new
07/25/2014 21:32:14;0040;PBS_Server;Svr;tyrone-cluster;Scheduler was sent the command new
07/25/2014 21:32:26;0040;PBS_Server;Svr;tyrone-cluster;Scheduler was sent the command new
07/25/2014 21:32:44;0040;PBS_Server;Svr;tyrone-cluster;Scheduler was sent the command new
07/25/2014 21:32:56;0040;PBS_Server;Svr;tyrone-cluster;Scheduler was sent the command new
07/25/2014 21:33:14;0040;PBS_Server;Svr;tyrone-cluster;Scheduler was sent the command new
07/25/2014 21:33:26;0040;PBS_Server;Svr;tyrone-cluster;Scheduler was sent the command new
07/25/2014 21:33:44;0040;PBS_Server;Svr;tyrone-cluster;Scheduler was sent the command new
07/25/2014 21:33:56;0040;PBS_Server;Svr;tyrone-cluster;Scheduler was sent the command new
07/25/2014 21:34:14;0040;PBS_Server;Svr;tyrone-cluster;Scheduler was sent the command new
07/25/2014 21:34:26;0040;PBS_Server;Svr;tyrone-cluster;Scheduler was sent the command new
07/25/2014 21:34:44;0040;PBS_Server;Svr;tyrone-cluster;Scheduler was sent the command new
07/25/2014 21:34:56;0040;PBS_Server;Svr;tyrone-cluster;Scheduler was sent the command new
07/25/2014 21:35:14;0040;PBS_Server;Svr;tyrone-cluster;Scheduler was sent the command new
07/25/2014 21:35:19;0002;PBS_Server;Svr;PBS_Server;Torque Server Version = 3.0.5, loglevel = 0
07/25/2014 21:35:26;0040;PBS_Server;Svr;tyrone-cluster;Scheduler was sent the command new
07/25/2014 21:35:44;0040;PBS_Server;Svr;tyrone-cluster;Scheduler was sent the command new
07/25/2014 21:35:56;0040;PBS_Server;Svr;tyrone-cluster;Scheduler was sent the command new
07/25/2014 21:36:15;0040;PBS_Server;Svr;tyrone-cluster;Scheduler was sent the command new
07/25/2014 21:36:26;0040;PBS_Server;Svr;tyrone-cluster;Scheduler was sent the command new
07/25/2014 21:36:45;0040;PBS_Server;Svr;tyrone-cluster;Scheduler was sent the command new
07/25/2014 21:36:56;0040;PBS_Server;Svr;tyrone-cluster;Scheduler was sent the command new
07/25/2014 21:37:15;0040;PBS_Server;Svr;tyrone-cluster;Scheduler was sent the command new
07/25/2014 21:37:26;0040;PBS_Server;Svr;tyrone-cluster;Scheduler was sent the command new
07/25/2014 21:37:45;0040;PBS_Server;Svr;tyrone-cluster;Scheduler was sent the command new
07/25/2014 21:37:56;0040;PBS_Server;Svr;tyrone-cluster;Scheduler was sent the command new
07/25/2014 21:38:15;0040;PBS_Server;Svr;tyrone-cluster;Scheduler was sent the command new
07/25/2014 21:38:26;0040;PBS_Server;Svr;tyrone-cluster;Scheduler was sent the command new
07/25/2014 21:38:45;0040;PBS_Server;Svr;tyrone-cluster;Scheduler was sent the command new
07/25/2014 21:38:56;0040;PBS_Server;Svr;tyrone-cluster;Scheduler was sent the command new
07/25/2014 21:39:15;0040;PBS_Server;Svr;tyrone-cluster;Scheduler was sent the command new
07/25/2014 21:39:26;0040;PBS_Server;Svr;tyrone-cluster;Scheduler was sent the command new
07/25/2014 21:39:45;0040;PBS_Server;Svr;tyrone-cluster;Scheduler was sent the command new
07/25/2014 21:39:56;0040;PBS_Server;Svr;tyrone-cluster;Scheduler was sent the command new
07/25/2014 21:40:15;0040;PBS_Server;Svr;tyrone-cluster;Scheduler was sent the command new
07/25/2014 21:40:19;0002;PBS_Server;Svr;PBS_Server;Torque Server Version = 3.0.5, loglevel = 0
07/25/2014 21:40:26;0040;PBS_Server;Svr;tyrone-cluster;Scheduler was sent the command new
07/25/2014 21:40:45;0040;PBS_Server;Svr;tyrone-cluster;Scheduler was sent the command new
07/25/2014 21:40:56;0040;PBS_Server;Svr;tyrone-cluster;Scheduler was sent the command new
07/25/2014 21:41:15;0040;PBS_Server;Svr;tyrone-cluster;Scheduler was sent the command new
07/25/2014 21:41:27;0040;PBS_Server;Svr;tyrone-cluster;Scheduler was sent the command new
07/25/2014 21:41:45;0040;PBS_Server;Svr;tyrone-cluster;Scheduler was sent the command new
07/25/2014 21:41:57;0040;PBS_Server;Svr;tyrone-cluster;Scheduler was sent the command new
07/25/2014 21:42:15;0040;PBS_Server;Svr;tyrone-cluster;Scheduler was sent the command new
07/25/2014 21:42:27;0040;PBS_Server;Svr;tyrone-cluster;Scheduler was sent the command new
07/25/2014 21:42:45;0040;PBS_Server;Svr;tyrone-cluster;Scheduler was sent the command new
07/25/2014 21:42:57;0040;PBS_Server;Svr;tyrone-cluster;Scheduler was sent the command new
07/25/2014 21:43:15;0040;PBS_Server;Svr;tyrone-cluster;Scheduler was sent the command new
07/25/2014 21:43:27;0040;PBS_Server;Svr;tyrone-cluster;Scheduler was sent the command new
07/25/2014 21:43:45;0040;PBS_Server;Svr;tyrone-cluster;Scheduler was sent the command new
07/25/2014 21:43:57;0040;PBS_Server;Svr;tyrone-cluster;Scheduler was sent the command new
07/25/2014 21:44:15;0040;PBS_Server;Svr;tyrone-cluster;Scheduler was sent the command new
07/25/2014 21:44:27;0040;PBS_Server;Svr;tyrone-cluster;Scheduler was sent the command new
07/25/2014 21:44:46;0040;PBS_Server;Svr;tyrone-cluster;Scheduler was sent the command new
07/25/2014 21:44:57;0040;PBS_Server;Svr;tyrone-cluster;Scheduler was sent the command new
07/25/2014 21:45:16;0040;PBS_Server;Svr;tyrone-cluster;Scheduler was sent the command new
07/25/2014 21:45:19;0002;PBS_Server;Svr;PBS_Server;Torque Server Version = 3.0.5, loglevel = 0
07/25/2014 21:45:27;0040;PBS_Server;Svr;tyrone-cluster;Scheduler was sent the command new
07/25/2014 21:45:46;0040;PBS_Server;Svr;tyrone-cluster;Scheduler was sent the command new
07/25/2014 21:45:57;0040;PBS_Server;Svr;tyrone-cluster;Scheduler was sent the command new
07/25/2014 21:46:16;0040;PBS_Server;Svr;tyrone-cluster;Scheduler was sent the command new
07/25/2014 21:46:27;0040;PBS_Server;Svr;tyrone-cluster;Scheduler was sent the command new
07/25/2014 21:46:46;0040;PBS_Server;Svr;tyrone-cluster;Scheduler was sent the command new
07/25/2014 21:46:57;0040;PBS_Server;Svr;tyrone-cluster;Scheduler was sent the command new
07/25/2014 21:47:16;0040;PBS_Server;Svr;tyrone-cluster;Scheduler was sent the command new
07/25/2014 21:47:27;0040;PBS_Server;Svr;tyrone-cluster;Scheduler was sent the command new
07/25/2014 21:47:46;0040;PBS_Server;Svr;tyrone-cluster;Scheduler was sent the command new
07/25/2014 21:47:57;0040;PBS_Server;Svr;tyrone-cluster;Scheduler was sent the command new
07/25/2014 21:48:16;0040;PBS_Server;Svr;tyrone-cluster;Scheduler was sent the command new
07/25/2014 21:48:27;0040;PBS_Server;Svr;tyrone-cluster;Scheduler was sent the command new
07/25/2014 21:48:46;0040;PBS_Server;Svr;tyrone-cluster;Scheduler was sent the command new
07/25/2014 21:48:57;0040;PBS_Server;Svr;tyrone-cluster;Scheduler was sent the command new
07/25/2014 21:49:16;0040;PBS_Server;Svr;tyrone-cluster;Scheduler was sent the command new
07/25/2014 21:49:27;0040;PBS_Server;Svr;tyrone-cluster;Scheduler was sent the command new
07/25/2014 21:49:46;0040;PBS_Server;Svr;tyrone-cluster;Scheduler was sent the command new
07/25/2014 21:49:57;0040;PBS_Server;Svr;tyrone-cluster;Scheduler was sent the command new
07/25/2014 21:50:16;0040;PBS_Server;Svr;tyrone-cluster;Scheduler was sent the command new
07/25/2014 21:50:19;0002;PBS_Server;Svr;PBS_Server;Torque Server Version = 3.0.5, loglevel = 0
07/25/2014 21:50:27;0040;PBS_Server;Svr;tyrone-cluster;Scheduler was sent the command new
07/25/2014 21:50:46;0040;PBS_Server;Svr;tyrone-cluster;Scheduler was sent the command new
07/25/2014 21:50:58;0040;PBS_Server;Svr;tyrone-cluster;Scheduler was sent the command new
07/25/2014 21:51:16;0040;PBS_Server;Svr;tyrone-cluster;Scheduler was sent the command new
07/25/2014 21:51:28;0040;PBS_Server;Svr;tyrone-cluster;Scheduler was sent the command new
07/25/2014 21:51:46;0040;PBS_Server;Svr;tyrone-cluster;Scheduler was sent the command new
07/25/2014 21:51:58;0040;PBS_Server;Svr;tyrone-cluster;Scheduler was sent the command new
07/25/2014 21:52:16;0040;PBS_Server;Svr;tyrone-cluster;Scheduler was sent the command new
07/25/2014 21:52:28;0040;PBS_Server;Svr;tyrone-cluster;Scheduler was sent the command new
07/25/2014 21:52:46;0040;PBS_Server;Svr;tyrone-cluster;Scheduler was sent the command new
07/25/2014 21:52:58;0040;PBS_Server;Svr;tyrone-cluster;Scheduler was sent the command new
07/25/2014 21:53:16;0040;PBS_Server;Svr;tyrone-cluster;Scheduler was sent the command new
07/25/2014 21:53:28;0040;PBS_Server;Svr;tyrone-cluster;Scheduler was sent the command new
07/25/2014 21:53:47;0040;PBS_Server;Svr;tyrone-cluster;Scheduler was sent the command new
07/25/2014 21:53:58;0040;PBS_Server;Svr;tyrone-cluster;Scheduler was sent the command new
07/25/2014 21:54:17;0040;PBS_Server;Svr;tyrone-cluster;Scheduler was sent the command new
07/25/2014 21:54:28;0040;PBS_Server;Svr;tyrone-cluster;Scheduler was sent the command new
07/25/2014 21:54:47;0040;PBS_Server;Svr;tyrone-cluster;Scheduler was sent the command new
07/25/2014 21:54:58;0040;PBS_Server;Svr;tyrone-cluster;Scheduler was sent the command new
07/25/2014 21:55:17;0040;PBS_Server;Svr;tyrone-cluster;Scheduler was sent the command new
07/25/2014 21:55:19;0002;PBS_Server;Svr;PBS_Server;Torque Server Version = 3.0.5, loglevel = 0
07/25/2014 21:55:28;0040;PBS_Server;Svr;tyrone-cluster;Scheduler was sent the command new
07/25/2014 21:55:47;0040;PBS_Server;Svr;tyrone-cluster;Scheduler was sent the command new
07/25/2014 21:55:58;0040;PBS_Server;Svr;tyrone-cluster;Scheduler was sent the command new
07/25/2014 21:56:17;0040;PBS_Server;Svr;tyrone-cluster;Scheduler was sent the command new
07/25/2014 21:56:28;0040;PBS_Server;Svr;tyrone-cluster;Scheduler was sent the command new
07/25/2014 21:56:47;0040;PBS_Server;Svr;tyrone-cluster;Scheduler was sent the command new
07/25/2014 21:56:58;0040;PBS_Server;Svr;tyrone-cluster;Scheduler was sent the command new
07/25/2014 21:57:17;0040;PBS_Server;Svr;tyrone-cluster;Scheduler was sent the command new
07/25/2014 21:57:28;0040;PBS_Server;Svr;tyrone-cluster;Scheduler was sent the command new
07/25/2014 21:57:47;0040;PBS_Server;Svr;tyrone-cluster;Scheduler was sent the command new
07/25/2014 21:57:58;0040;PBS_Server;Svr;tyrone-cluster;Scheduler was sent the command new
07/25/2014 21:58:17;0040;PBS_Server;Svr;tyrone-cluster;Scheduler was sent the command new
07/25/2014 21:58:28;0040;PBS_Server;Svr;tyrone-cluster;Scheduler was sent the command new
07/25/2014 21:58:47;0040;PBS_Server;Svr;tyrone-cluster;Scheduler was sent the command new
07/25/2014 21:58:58;0040;PBS_Server;Svr;tyrone-cluster;Scheduler was sent the command new
07/25/2014 21:59:17;0040;PBS_Server;Svr;tyrone-cluster;Scheduler was sent the command new
07/25/2014 21:59:28;0040;PBS_Server;Svr;tyrone-cluster;Scheduler was sent the command new
07/25/2014 21:59:47;0040;PBS_Server;Svr;tyrone-cluster;Scheduler was sent the command new
07/25/2014 21:59:58;0040;PBS_Server;Svr;tyrone-cluster;Scheduler was sent the command new
07/25/2014 22:00:17;0040;PBS_Server;Svr;tyrone-cluster;Scheduler was sent the command new
07/25/2014 22:00:19;0002;PBS_Server;Svr;PBS_Server;Torque Server Version = 3.0.5, loglevel = 0
07/25/2014 22:00:29;0040;PBS_Server;Svr;tyrone-cluster;Scheduler was sent the command new
07/25/2014 22:00:47;0040;PBS_Server;Svr;tyrone-cluster;Scheduler was sent the command new
07/25/2014 22:00:59;0040;PBS_Server;Svr;tyrone-cluster;Scheduler was sent the command new
07/25/2014 22:01:17;0040;PBS_Server;Svr;tyrone-cluster;Scheduler was sent the command new
07/25/2014 22:01:29;0040;PBS_Server;Svr;tyrone-cluster;Scheduler was sent the command new
07/25/2014 22:01:47;0040;PBS_Server;Svr;tyrone-cluster;Scheduler was sent the command new
07/25/2014 22:01:59;0040;PBS_Server;Svr;tyrone-cluster;Scheduler was sent the command new
07/25/2014 22:02:17;0040;PBS_Server;Svr;tyrone-cluster;Scheduler was sent the command new
07/25/2014 22:02:29;0040;PBS_Server;Svr;tyrone-cluster;Scheduler was sent the command new
07/25/2014 22:02:47;0040;PBS_Server;Svr;tyrone-cluster;Scheduler was sent the command new
07/25/2014 22:02:59;0040;PBS_Server;Svr;tyrone-cluster;Scheduler was sent the command new
07/25/2014 22:03:18;0040;PBS_Server;Svr;tyrone-cluster;Scheduler was sent the command new
07/25/2014 22:03:29;0040;PBS_Server;Svr;tyrone-cluster;Scheduler was sent the command new
07/25/2014 22:03:48;0040;PBS_Server;Svr;tyrone-cluster;Scheduler was sent the command new
07/25/2014 22:03:59;0040;PBS_Server;Svr;tyrone-cluster;Scheduler was sent the command new
07/25/2014 22:04:18;0040;PBS_Server;Svr;tyrone-cluster;Scheduler was sent the command new
07/25/2014 22:04:29;0040;PBS_Server;Svr;tyrone-cluster;Scheduler was sent the command new
07/25/2014 22:04:48;0040;PBS_Server;Svr;tyrone-cluster;Scheduler was sent the command new
07/25/2014 22:04:59;0040;PBS_Server;Svr;tyrone-cluster;Scheduler was sent the command new
07/25/2014 22:05:18;0040;PBS_Server;Svr;tyrone-cluster;Scheduler was sent the command new
07/25/2014 22:05:19;0002;PBS_Server;Svr;PBS_Server;Torque Server Version = 3.0.5, loglevel = 0
07/25/2014 22:05:29;0040;PBS_Server;Svr;tyrone-cluster;Scheduler was sent the command new
07/25/2014 22:05:48;0040;PBS_Server;Svr;tyrone-cluster;Scheduler was sent the command new
07/25/2014 22:05:59;0040;PBS_Server;Svr;tyrone-cluster;Scheduler was sent the command new
07/25/2014 22:06:18;0040;PBS_Server;Svr;tyrone-cluster;Scheduler was sent the command new
07/25/2014 22:06:29;0040;PBS_Server;Svr;tyrone-cluster;Scheduler was sent the command new
07/25/2014 22:06:48;0040;PBS_Server;Svr;tyrone-cluster;Scheduler was sent the command new
07/25/2014 22:06:59;0040;PBS_Server;Svr;tyrone-cluster;Scheduler was sent the command new
07/25/2014 22:07:18;0040;PBS_Server;Svr;tyrone-cluster;Scheduler was sent the command new
07/25/2014 22:07:29;0040;PBS_Server;Svr;tyrone-cluster;Scheduler was sent the command new
07/25/2014 22:07:48;0040;PBS_Server;Svr;tyrone-cluster;Scheduler was sent the command new
07/25/2014 22:07:59;0040;PBS_Server;Svr;tyrone-cluster;Scheduler was sent the command new
07/25/2014 22:08:18;0040;PBS_Server;Svr;tyrone-cluster;Scheduler was sent the command new
07/25/2014 22:08:29;0040;PBS_Server;Svr;tyrone-cluster;Scheduler was sent the command new
07/25/2014 22:08:48;0040;PBS_Server;Svr;tyrone-cluster;Scheduler was sent the command new
07/25/2014 22:08:59;0040;PBS_Server;Svr;tyrone-cluster;Scheduler was sent the command new
07/25/2014 22:09:18;0040;PBS_Server;Svr;tyrone-cluster;Scheduler was sent the command new
07/25/2014 22:09:29;0040;PBS_Server;Svr;tyrone-cluster;Scheduler was sent the command new
07/25/2014 22:09:48;0040;PBS_Server;Svr;tyrone-cluster;Scheduler was sent the command new
07/25/2014 22:10:00;0040;PBS_Server;Svr;tyrone-cluster;Scheduler was sent the command new
07/25/2014 22:10:18;0040;PBS_Server;Svr;tyrone-cluster;Scheduler was sent the command new
07/25/2014 22:10:19;0002;PBS_Server;Svr;PBS_Server;Torque Server Version = 3.0.5, loglevel = 0
07/25/2014 22:10:30;0040;PBS_Server;Svr;tyrone-cluster;Scheduler was sent the command new
07/25/2014 22:10:48;0040;PBS_Server;Svr;tyrone-cluster;Scheduler was sent the command new
07/25/2014 22:11:00;0040;PBS_Server;Svr;tyrone-cluster;Scheduler was sent the command new
07/25/2014 22:11:18;0040;PBS_Server;Svr;tyrone-cluster;Scheduler was sent the command new
07/25/2014 22:11:30;0040;PBS_Server;Svr;tyrone-cluster;Scheduler was sent the command new
07/25/2014 22:11:48;0040;PBS_Server;Svr;tyrone-cluster;Scheduler was sent the command new
07/25/2014 22:12:00;0040;PBS_Server;Svr;tyrone-cluster;Scheduler was sent the command new
07/25/2014 22:12:19;0040;PBS_Server;Svr;tyrone-cluster;Scheduler was sent the command new
07/25/2014 22:12:30;0040;PBS_Server;Svr;tyrone-cluster;Scheduler was sent the command new
07/25/2014 22:12:49;0040;PBS_Server;Svr;tyrone-cluster;Scheduler was sent the command new
07/25/2014 22:13:00;0040;PBS_Server;Svr;tyrone-cluster;Scheduler was sent the command new
07/25/2014 22:13:19;0040;PBS_Server;Svr;tyrone-cluster;Scheduler was sent the command new
07/25/2014 22:13:30;0040;PBS_Server;Svr;tyrone-cluster;Scheduler was sent the command new
07/25/2014 22:13:49;0040;PBS_Server;Svr;tyrone-cluster;Scheduler was sent the command new
07/25/2014 22:14:00;0040;PBS_Server;Svr;tyrone-cluster;Scheduler was sent the command new
07/25/2014 22:14:19;0040;PBS_Server;Svr;tyrone-cluster;Scheduler was sent the command new
07/25/2014 22:14:30;0040;PBS_Server;Svr;tyrone-cluster;Scheduler was sent the command new
07/25/2014 22:14:49;0040;PBS_Server;Svr;tyrone-cluster;Scheduler was sent the command new
07/25/2014 22:14:53;0100;PBS_Server;Job;40702.tyrone-cluster;enqueuing into batch, state 1 hop 1
07/25/2014 22:14:53;0100;PBS_Server;Job;40702.tyrone-cluster;dequeuing from batch, state QUEUED
07/25/2014 22:14:53;0100;PBS_Server;Job;40702.tyrone-cluster;enqueuing into idqueue, state 1 hop 1
07/25/2014 22:14:53;0008;PBS_Server;Job;40702.tyrone-cluster;Job Queued at request of phynagmp@tyrone-cluster, owner = phynagmp@tyrone-cluster, job name = poshit1, queue = idqueue
07/25/2014 22:14:53;0040;PBS_Server;Svr;tyrone-cluster;Scheduler was sent the command new
07/25/2014 22:14:53;0008;PBS_Server;Job;40702.tyrone-cluster;Job Modified at request of Scheduler@tyrone-cluster
07/25/2014 22:14:53;0008;PBS_Server;Job;40702.tyrone-cluster;Job Run at request of Scheduler@tyrone-cluster
07/25/2014 22:14:53;0040;PBS_Server;Svr;tyrone-cluster;Scheduler was sent the command recyc
07/25/2014 22:14:53;000d;PBS_Server;Job;40702.tyrone-cluster;Not sending email: User does not want mail of this type.
07/25/2014 22:15:00;0040;PBS_Server;Svr;tyrone-cluster;Scheduler was sent the command new
07/25/2014 22:15:19;0002;PBS_Server;Svr;PBS_Server;Torque Server Version = 3.0.5, loglevel = 0
07/25/2014 22:15:19;0040;PBS_Server;Svr;tyrone-cluster;Scheduler was sent the command new
07/25/2014 22:15:30;0040;PBS_Server;Svr;tyrone-cluster;Scheduler was sent the command new
07/25/2014 22:15:49;0040;PBS_Server;Svr;tyrone-cluster;Scheduler was sent the command new
07/25/2014 22:16:00;0040;PBS_Server;Svr;tyrone-cluster;Scheduler was sent the command new
07/25/2014 22:16:19;0040;PBS_Server;Svr;tyrone-cluster;Scheduler was sent the command new
07/25/2014 22:16:30;0040;PBS_Server;Svr;tyrone-cluster;Scheduler was sent the command new
07/25/2014 22:16:49;0040;PBS_Server;Svr;tyrone-cluster;Scheduler was sent the command new
07/25/2014 22:17:00;0040;PBS_Server;Svr;tyrone-cluster;Scheduler was sent the command new
07/25/2014 22:17:19;0040;PBS_Server;Svr;tyrone-cluster;Scheduler was sent the command new
07/25/2014 22:17:30;0040;PBS_Server;Svr;tyrone-cluster;Scheduler was sent the command new
07/25/2014 22:17:49;0040;PBS_Server;Svr;tyrone-cluster;Scheduler was sent the command new
07/25/2014 22:18:00;0040;PBS_Server;Svr;tyrone-cluster;Scheduler was sent the command new
07/25/2014 22:18:19;0040;PBS_Server;Svr;tyrone-cluster;Scheduler was sent the command new
07/25/2014 22:18:30;0040;PBS_Server;Svr;tyrone-cluster;Scheduler was sent the command new
07/25/2014 22:18:49;0040;PBS_Server;Svr;tyrone-cluster;Scheduler was sent the command new
07/25/2014 22:19:01;0040;PBS_Server;Svr;tyrone-cluster;Scheduler was sent the command new
07/25/2014 22:19:19;0040;PBS_Server;Svr;tyrone-cluster;Scheduler was sent the command new
07/25/2014 22:19:31;0040;PBS_Server;Svr;tyrone-cluster;Scheduler was sent the command new
07/25/2014 22:19:44;000d;PBS_Server;Job;40702.tyrone-cluster;Not sending email: User does not want mail of this type.
07/25/2014 22:19:44;0010;PBS_Server;Job;40702.tyrone-cluster;Exit_status=2 resources_used.cput=00:47:11 resources_used.mem=384596kb resources_used.vmem=882624kb resources_used.walltime=00:04:51
07/25/2014 22:19:44;0008;PBS_Server;Job;NULL;on_job_exit valid pjob: 0x1ebeab0 (substate=50)
07/25/2014 22:19:44;0008;PBS_Server;Job;NULL;on_job_exit valid pjob: 0x1ebeab0 (substate=51)
07/25/2014 22:19:44;0008;PBS_Server;Job;NULL;on_job_exit valid pjob: 0x1ebeab0 (substate=51)
07/25/2014 22:19:44;0008;PBS_Server;Job;NULL;on_job_exit valid pjob: 0x1ebeab0 (substate=53)
07/25/2014 22:19:44;0100;PBS_Server;Job;40702.tyrone-cluster;dequeuing from idqueue, state COMPLETE
07/25/2014 22:19:44;0040;PBS_Server;Svr;tyrone-cluster;Scheduler was sent the command term
07/25/2014 22:19:49;0040;PBS_Server;Svr;tyrone-cluster;Scheduler was sent the command new
07/25/2014 22:20:01;0040;PBS_Server;Svr;tyrone-cluster;Scheduler was sent the command new
07/25/2014 22:20:19;0002;PBS_Server;Svr;PBS_Server;Torque Server Version = 3.0.5, loglevel = 0
07/25/2014 22:20:19;0040;PBS_Server;Svr;tyrone-cluster;Scheduler was sent the command new
07/25/2014 22:20:31;0040;PBS_Server;Svr;tyrone-cluster;Scheduler was sent the command new
07/25/2014 22:20:50;0040;PBS_Server;Svr;tyrone-cluster;Scheduler was sent the command new
07/25/2014 22:21:01;0040;PBS_Server;Svr;tyrone-cluster;Scheduler was sent the command new
07/25/2014 22:21:20;0040;PBS_Server;Svr;tyrone-cluster;Scheduler was sent the command new
07/25/2014 22:21:31;0040;PBS_Server;Svr;tyrone-cluster;Scheduler was sent the command new
07/25/2014 22:21:50;0040;PBS_Server;Svr;tyrone-cluster;Scheduler was sent the command new
07/25/2014 22:22:01;0040;PBS_Server;Svr;tyrone-cluster;Scheduler was sent the command new
07/25/2014 22:22:20;0040;PBS_Server;Svr;tyrone-cluster;Scheduler was sent the command new
07/25/2014 22:22:31;0040;PBS_Server;Svr;tyrone-cluster;Scheduler was sent the command new
07/25/2014 22:22:50;0040;PBS_Server;Svr;tyrone-cluster;Scheduler was sent the command new
07/25/2014 22:23:01;0040;PBS_Server;Svr;tyrone-cluster;Scheduler was sent the command new
07/25/2014 22:23:20;0040;PBS_Server;Svr;tyrone-cluster;Scheduler was sent the command new
07/25/2014 22:23:31;0040;PBS_Server;Svr;tyrone-cluster;Scheduler was sent the command new
07/25/2014 22:23:50;0040;PBS_Server;Svr;tyrone-cluster;Scheduler was sent the command new
07/25/2014 22:24:01;0040;PBS_Server;Svr;tyrone-cluster;Scheduler was sent the command new
07/25/2014 22:24:20;0040;PBS_Server;Svr;tyrone-cluster;Scheduler was sent the command new
07/25/2014 22:24:31;0040;PBS_Server;Svr;tyrone-cluster;Scheduler was sent the command new
07/25/2014 22:24:50;0040;PBS_Server;Svr;tyrone-cluster;Scheduler was sent the command new
07/25/2014 22:25:01;0040;PBS_Server;Svr;tyrone-cluster;Scheduler was sent the command new
07/25/2014 22:25:19;0002;PBS_Server;Svr;PBS_Server;Torque Server Version = 3.0.5, loglevel = 0
07/25/2014 22:25:20;0040;PBS_Server;Svr;tyrone-cluster;Scheduler was sent the command new
07/25/2014 22:25:31;0040;PBS_Server;Svr;tyrone-cluster;Scheduler was sent the command new
07/25/2014 22:25:50;0040;PBS_Server;Svr;tyrone-cluster;Scheduler was sent the command new
07/25/2014 22:26:01;0040;PBS_Server;Svr;tyrone-cluster;Scheduler was sent the command new
07/25/2014 22:26:20;0040;PBS_Server;Svr;tyrone-cluster;Scheduler was sent the command new
07/25/2014 22:26:31;0040;PBS_Server;Svr;tyrone-cluster;Scheduler was sent the command new
07/25/2014 22:26:50;0040;PBS_Server;Svr;tyrone-cluster;Scheduler was sent the command new
07/25/2014 22:27:01;0040;PBS_Server;Svr;tyrone-cluster;Scheduler was sent the command new
07/25/2014 22:27:20;0040;PBS_Server;Svr;tyrone-cluster;Scheduler was sent the command new
07/25/2014 22:27:31;0040;PBS_Server;Svr;tyrone-cluster;Scheduler was sent the command new
07/25/2014 22:27:50;0040;PBS_Server;Svr;tyrone-cluster;Scheduler was sent the command new
07/25/2014 22:28:02;0040;PBS_Server;Svr;tyrone-cluster;Scheduler was sent the command new
07/25/2014 22:28:20;0040;PBS_Server;Svr;tyrone-cluster;Scheduler was sent the command new
07/25/2014 22:28:32;0040;PBS_Server;Svr;tyrone-cluster;Scheduler was sent the command new
07/25/2014 22:28:50;0040;PBS_Server;Svr;tyrone-cluster;Scheduler was sent the command new
07/25/2014 22:29:02;0040;PBS_Server;Svr;tyrone-cluster;Scheduler was sent the command new
07/25/2014 22:29:20;0040;PBS_Server;Svr;tyrone-cluster;Scheduler was sent the command new
07/25/2014 22:29:32;0040;PBS_Server;Svr;tyrone-cluster;Scheduler was sent the command new
07/25/2014 22:29:51;0040;PBS_Server;Svr;tyrone-cluster;Scheduler was sent the command new
07/25/2014 22:30:02;0040;PBS_Server;Svr;tyrone-cluster;Scheduler was sent the command new
07/25/2014 22:30:19;0002;PBS_Server;Svr;PBS_Server;Torque Server Version = 3.0.5, loglevel = 0
07/25/2014 22:30:21;0040;PBS_Server;Svr;tyrone-cluster;Scheduler was sent the command new
07/25/2014 22:30:32;0040;PBS_Server;Svr;tyrone-cluster;Scheduler was sent the command new
07/25/2014 22:30:51;0040;PBS_Server;Svr;tyrone-cluster;Scheduler was sent the command new
07/25/2014 22:31:02;0040;PBS_Server;Svr;tyrone-cluster;Scheduler was sent the command new
07/25/2014 22:31:21;0040;PBS_Server;Svr;tyrone-cluster;Scheduler was sent the command new
07/25/2014 22:31:32;0040;PBS_Server;Svr;tyrone-cluster;Scheduler was sent the command new
07/25/2014 22:31:51;0040;PBS_Server;Svr;tyrone-cluster;Scheduler was sent the command new
07/25/2014 22:32:02;0040;PBS_Server;Svr;tyrone-cluster;Scheduler was sent the command new
07/25/2014 22:32:21;0040;PBS_Server;Svr;tyrone-cluster;Scheduler was sent the command new
07/25/2014 22:32:32;0040;PBS_Server;Svr;tyrone-cluster;Scheduler was sent the command new
07/25/2014 22:32:51;0040;PBS_Server;Svr;tyrone-cluster;Scheduler was sent the command new
07/25/2014 22:33:02;0040;PBS_Server;Svr;tyrone-cluster;Scheduler was sent the command new
07/25/2014 22:33:21;0040;PBS_Server;Svr;tyrone-cluster;Scheduler was sent the command new
07/25/2014 22:33:32;0040;PBS_Server;Svr;tyrone-cluster;Scheduler was sent the command new
07/25/2014 22:33:51;0040;PBS_Server;Svr;tyrone-cluster;Scheduler was sent the command new
07/25/2014 22:34:02;0040;PBS_Server;Svr;tyrone-cluster;Scheduler was sent the command new
07/25/2014 22:34:21;0040;PBS_Server;Svr;tyrone-cluster;Scheduler was sent the command new
07/25/2014 22:34:32;0040;PBS_Server;Svr;tyrone-cluster;Scheduler was sent the command new
07/25/2014 22:34:51;0040;PBS_Server;Svr;tyrone-cluster;Scheduler was sent the command new
07/25/2014 22:35:02;0040;PBS_Server;Svr;tyrone-cluster;Scheduler was sent the command new
07/25/2014 22:35:19;0002;PBS_Server;Svr;PBS_Server;Torque Server Version = 3.0.5, loglevel = 0
07/25/2014 22:35:21;0040;PBS_Server;Svr;tyrone-cluster;Scheduler was sent the command new
07/25/2014 22:35:32;0040;PBS_Server;Svr;tyrone-cluster;Scheduler was sent the command new
07/25/2014 22:35:51;0040;PBS_Server;Svr;tyrone-cluster;Scheduler was sent the command new
07/25/2014 22:36:02;0040;PBS_Server;Svr;tyrone-cluster;Scheduler was sent the command new
07/25/2014 22:36:21;0040;PBS_Server;Svr;tyrone-cluster;Scheduler was sent the command new
07/25/2014 22:36:32;0040;PBS_Server;Svr;tyrone-cluster;Scheduler was sent the command new
07/25/2014 22:36:51;0040;PBS_Server;Svr;tyrone-cluster;Scheduler was sent the command new
07/25/2014 22:37:03;0040;PBS_Server;Svr;tyrone-cluster;Scheduler was sent the command new
07/25/2014 22:37:21;0040;PBS_Server;Svr;tyrone-cluster;Scheduler was sent the command new
07/25/2014 22:37:33;0040;PBS_Server;Svr;tyrone-cluster;Scheduler was sent the command new
07/25/2014 22:37:51;0040;PBS_Server;Svr;tyrone-cluster;Scheduler was sent the command new
07/25/2014 22:38:03;0040;PBS_Server;Svr;tyrone-cluster;Scheduler was sent the command new
07/25/2014 22:38:21;0040;PBS_Server;Svr;tyrone-cluster;Scheduler was sent the command new
07/25/2014 22:38:33;0040;PBS_Server;Svr;tyrone-cluster;Scheduler was sent the command new
07/25/2014 22:38:51;0040;PBS_Server;Svr;tyrone-cluster;Scheduler was sent the command new
07/25/2014 22:39:03;0040;PBS_Server;Svr;tyrone-cluster;Scheduler was sent the command new
07/25/2014 22:39:21;0040;PBS_Server;Svr;tyrone-cluster;Scheduler was sent the command new
07/25/2014 22:39:33;0040;PBS_Server;Svr;tyrone-cluster;Scheduler was sent the command new
07/25/2014 22:39:52;0040;PBS_Server;Svr;tyrone-cluster;Scheduler was sent the command new
07/25/2014 22:40:03;0040;PBS_Server;Svr;tyrone-cluster;Scheduler was sent the command new
07/25/2014 22:40:19;0002;PBS_Server;Svr;PBS_Server;Torque Server Version = 3.0.5, loglevel = 0
07/25/2014 22:40:22;0040;PBS_Server;Svr;tyrone-cluster;Scheduler was sent the command new
07/25/2014 22:40:33;0040;PBS_Server;Svr;tyrone-cluster;Scheduler was sent the command new
07/25/2014 22:40:52;0040;PBS_Server;Svr;tyrone-cluster;Scheduler was sent the command new
07/25/2014 22:41:03;0040;PBS_Server;Svr;tyrone-cluster;Scheduler was sent the command new
07/25/2014 22:41:22;0040;PBS_Server;Svr;tyrone-cluster;Scheduler was sent the command new
07/25/2014 22:41:33;0040;PBS_Server;Svr;tyrone-cluster;Scheduler was sent the command new
07/25/2014 22:41:52;0040;PBS_Server;Svr;tyrone-cluster;Scheduler was sent the command new
07/25/2014 22:42:03;0040;PBS_Server;Svr;tyrone-cluster;Scheduler was sent the command new
07/25/2014 22:42:22;0040;PBS_Server;Svr;tyrone-cluster;Scheduler was sent the command new
07/25/2014 22:42:33;0040;PBS_Server;Svr;tyrone-cluster;Scheduler was sent the command new
07/25/2014 22:42:52;0040;PBS_Server;Svr;tyrone-cluster;Scheduler was sent the command new
07/25/2014 22:43:03;0040;PBS_Server;Svr;tyrone-cluster;Scheduler was sent the command new
07/25/2014 22:43:22;0040;PBS_Server;Svr;tyrone-cluster;Scheduler was sent the command new
07/25/2014 22:43:33;0040;PBS_Server;Svr;tyrone-cluster;Scheduler was sent the command new
07/25/2014 22:43:52;0040;PBS_Server;Svr;tyrone-cluster;Scheduler was sent the command new
07/25/2014 22:44:03;0040;PBS_Server;Svr;tyrone-cluster;Scheduler was sent the command new
07/25/2014 22:44:22;0040;PBS_Server;Svr;tyrone-cluster;Scheduler was sent the command new
07/25/2014 22:44:33;0040;PBS_Server;Svr;tyrone-cluster;Scheduler was sent the command new
07/25/2014 22:44:52;0040;PBS_Server;Svr;tyrone-cluster;Scheduler was sent the command new
07/25/2014 22:45:03;0040;PBS_Server;Svr;tyrone-cluster;Scheduler was sent the command new
07/25/2014 22:45:19;0002;PBS_Server;Svr;PBS_Server;Torque Server Version = 3.0.5, loglevel = 0
07/25/2014 22:45:22;0040;PBS_Server;Svr;tyrone-cluster;Scheduler was sent the command new
07/25/2014 22:45:33;0040;PBS_Server;Svr;tyrone-cluster;Scheduler was sent the command new
07/25/2014 22:45:52;0040;PBS_Server;Svr;tyrone-cluster;Scheduler was sent the command new
07/25/2014 22:46:04;0040;PBS_Server;Svr;tyrone-cluster;Scheduler was sent the command new
07/25/2014 22:46:22;0040;PBS_Server;Svr;tyrone-cluster;Scheduler was sent the command new
07/25/2014 22:46:34;0040;PBS_Server;Svr;tyrone-cluster;Scheduler was sent the command new
07/25/2014 22:46:52;0040;PBS_Server;Svr;tyrone-cluster;Scheduler was sent the command new
07/25/2014 22:47:04;0040;PBS_Server;Svr;tyrone-cluster;Scheduler was sent the command new
07/25/2014 22:47:22;0040;PBS_Server;Svr;tyrone-cluster;Scheduler was sent the command new
07/25/2014 22:47:34;0040;PBS_Server;Svr;tyrone-cluster;Scheduler was sent the command new
07/25/2014 22:47:52;0040;PBS_Server;Svr;tyrone-cluster;Scheduler was sent the command new
07/25/2014 22:48:04;0040;PBS_Server;Svr;tyrone-cluster;Scheduler was sent the command new
07/25/2014 22:48:22;0040;PBS_Server;Svr;tyrone-cluster;Scheduler was sent the command new
07/25/2014 22:48:34;0040;PBS_Server;Svr;tyrone-cluster;Scheduler was sent the command new
07/25/2014 22:48:52;0040;PBS_Server;Svr;tyrone-cluster;Scheduler was sent the command new
07/25/2014 22:49:04;0040;PBS_Server;Svr;tyrone-cluster;Scheduler was sent the command new
07/25/2014 22:49:23;0040;PBS_Server;Svr;tyrone-cluster;Scheduler was sent the command new
07/25/2014 22:49:34;0040;PBS_Server;Svr;tyrone-cluster;Scheduler was sent the command new
07/25/2014 22:49:53;0040;PBS_Server;Svr;tyrone-cluster;Scheduler was sent the command new
07/25/2014 22:50:04;0040;PBS_Server;Svr;tyrone-cluster;Scheduler was sent the command new
07/25/2014 22:50:19;0002;PBS_Server;Svr;PBS_Server;Torque Server Version = 3.0.5, loglevel = 0
07/25/2014 22:50:23;0040;PBS_Server;Svr;tyrone-cluster;Scheduler was sent the command new
07/25/2014 22:50:34;0040;PBS_Server;Svr;tyrone-cluster;Scheduler was sent the command new
07/25/2014 22:50:53;0040;PBS_Server;Svr;tyrone-cluster;Scheduler was sent the command new
07/25/2014 22:51:04;0040;PBS_Server;Svr;tyrone-cluster;Scheduler was sent the command new
07/25/2014 22:51:23;0040;PBS_Server;Svr;tyrone-cluster;Scheduler was sent the command new
07/25/2014 22:51:34;0040;PBS_Server;Svr;tyrone-cluster;Scheduler was sent the command new
07/25/2014 22:51:53;0040;PBS_Server;Svr;tyrone-cluster;Scheduler was sent the command new
07/25/2014 22:52:04;0040;PBS_Server;Svr;tyrone-cluster;Scheduler was sent the command new
07/25/2014 22:52:23;0040;PBS_Server;Svr;tyrone-cluster;Scheduler was sent the command new
07/25/2014 22:52:34;0040;PBS_Server;Svr;tyrone-cluster;Scheduler was sent the command new
07/25/2014 22:52:53;0040;PBS_Server;Svr;tyrone-cluster;Scheduler was sent the command new
07/25/2014 22:53:04;0040;PBS_Server;Svr;tyrone-cluster;Scheduler was sent the command new
07/25/2014 22:53:23;0040;PBS_Server;Svr;tyrone-cluster;Scheduler was sent the command new
07/25/2014 22:53:34;0040;PBS_Server;Svr;tyrone-cluster;Scheduler was sent the command new
07/25/2014 22:53:53;0040;PBS_Server;Svr;tyrone-cluster;Scheduler was sent the command new
07/25/2014 22:54:04;0040;PBS_Server;Svr;tyrone-cluster;Scheduler was sent the command new
07/25/2014 22:54:23;0040;PBS_Server;Svr;tyrone-cluster;Scheduler was sent the command new
07/25/2014 22:54:34;0040;PBS_Server;Svr;tyrone-cluster;Scheduler was sent the command new
07/25/2014 22:54:53;0040;PBS_Server;Svr;tyrone-cluster;Scheduler was sent the command new
07/25/2014 22:55:04;0040;PBS_Server;Svr;tyrone-cluster;Scheduler was sent the command new
07/25/2014 22:55:19;0002;PBS_Server;Svr;PBS_Server;Torque Server Version = 3.0.5, loglevel = 0
07/25/2014 22:55:23;0040;PBS_Server;Svr;tyrone-cluster;Scheduler was sent the command new
07/25/2014 22:55:35;0040;PBS_Server;Svr;tyrone-cluster;Scheduler was sent the command new
07/25/2014 22:55:53;0040;PBS_Server;Svr;tyrone-cluster;Scheduler was sent the command new
07/25/2014 22:56:05;0040;PBS_Server;Svr;tyrone-cluster;Scheduler was sent the command new
07/25/2014 22:56:23;0040;PBS_Server;Svr;tyrone-cluster;Scheduler was sent the command new
07/25/2014 22:56:35;0040;PBS_Server;Svr;tyrone-cluster;Scheduler was sent the command new
07/25/2014 22:56:53;0040;PBS_Server;Svr;tyrone-cluster;Scheduler was sent the command new
07/25/2014 22:57:05;0040;PBS_Server;Svr;tyrone-cluster;Scheduler was sent the command new
07/25/2014 22:57:23;0040;PBS_Server;Svr;tyrone-cluster;Scheduler was sent the command new
07/25/2014 22:57:35;0040;PBS_Server;Svr;tyrone-cluster;Scheduler was sent the command new
07/25/2014 22:57:53;0040;PBS_Server;Svr;tyrone-cluster;Scheduler was sent the command new
07/25/2014 22:58:05;0040;PBS_Server;Svr;tyrone-cluster;Scheduler was sent the command new
07/25/2014 22:58:23;0040;PBS_Server;Svr;tyrone-cluster;Scheduler was sent the command new
07/25/2014 22:58:35;0040;PBS_Server;Svr;tyrone-cluster;Scheduler was sent the command new
07/25/2014 22:58:53;0040;PBS_Server;Svr;tyrone-cluster;Scheduler was sent the command new
07/25/2014 22:59:05;0040;PBS_Server;Svr;tyrone-cluster;Scheduler was sent the command new
07/25/2014 22:59:24;0040;PBS_Server;Svr;tyrone-cluster;Scheduler was sent the command new
07/25/2014 22:59:35;0040;PBS_Server;Svr;tyrone-cluster;Scheduler was sent the command new
07/25/2014 22:59:54;0040;PBS_Server;Svr;tyrone-cluster;Scheduler was sent the command new
07/25/2014 23:00:05;0040;PBS_Server;Svr;tyrone-cluster;Scheduler was sent the command new
07/25/2014 23:00:19;0002;PBS_Server;Svr;PBS_Server;Torque Server Version = 3.0.5, loglevel = 0
07/25/2014 23:00:24;0040;PBS_Server;Svr;tyrone-cluster;Scheduler was sent the command new
07/25/2014 23:00:35;0040;PBS_Server;Svr;tyrone-cluster;Scheduler was sent the command new
07/25/2014 23:00:54;0040;PBS_Server;Svr;tyrone-cluster;Scheduler was sent the command new
07/25/2014 23:01:05;0040;PBS_Server;Svr;tyrone-cluster;Scheduler was sent the command new
07/25/2014 23:01:24;0040;PBS_Server;Svr;tyrone-cluster;Scheduler was sent the command new
07/25/2014 23:01:35;0040;PBS_Server;Svr;tyrone-cluster;Scheduler was sent the command new
07/25/2014 23:01:54;0040;PBS_Server;Svr;tyrone-cluster;Scheduler was sent the command new
07/25/2014 23:02:05;0040;PBS_Server;Svr;tyrone-cluster;Scheduler was sent the command new
07/25/2014 23:02:24;0040;PBS_Server;Svr;tyrone-cluster;Scheduler was sent the command new
07/25/2014 23:02:35;0040;PBS_Server;Svr;tyrone-cluster;Scheduler was sent the command new
07/25/2014 23:02:54;0040;PBS_Server;Svr;tyrone-cluster;Scheduler was sent the command new
07/25/2014 23:03:05;0040;PBS_Server;Svr;tyrone-cluster;Scheduler was sent the command new
07/25/2014 23:03:24;0040;PBS_Server;Svr;tyrone-cluster;Scheduler was sent the command new
07/25/2014 23:03:35;0040;PBS_Server;Svr;tyrone-cluster;Scheduler was sent the command new
07/25/2014 23:03:54;0040;PBS_Server;Svr;tyrone-cluster;Scheduler was sent the command new
07/25/2014 23:04:05;0040;PBS_Server;Svr;tyrone-cluster;Scheduler was sent the command new
07/25/2014 23:04:24;0040;PBS_Server;Svr;tyrone-cluster;Scheduler was sent the command new
07/25/2014 23:04:36;0040;PBS_Server;Svr;tyrone-cluster;Scheduler was sent the command new
07/25/2014 23:04:54;0040;PBS_Server;Svr;tyrone-cluster;Scheduler was sent the command new
07/25/2014 23:05:06;0040;PBS_Server;Svr;tyrone-cluster;Scheduler was sent the command new
07/25/2014 23:05:19;0002;PBS_Server;Svr;PBS_Server;Torque Server Version = 3.0.5, loglevel = 0
07/25/2014 23:05:24;0040;PBS_Server;Svr;tyrone-cluster;Scheduler was sent the command new
07/25/2014 23:05:36;0040;PBS_Server;Svr;tyrone-cluster;Scheduler was sent the command new
07/25/2014 23:05:54;0040;PBS_Server;Svr;tyrone-cluster;Scheduler was sent the command new
07/25/2014 23:06:06;0040;PBS_Server;Svr;tyrone-cluster;Scheduler was sent the command new
07/25/2014 23:06:24;0040;PBS_Server;Svr;tyrone-cluster;Scheduler was sent the command new
07/25/2014 23:06:36;0040;PBS_Server;Svr;tyrone-cluster;Scheduler was sent the command new
07/25/2014 23:06:54;0040;PBS_Server;Svr;tyrone-cluster;Scheduler was sent the command new
07/25/2014 23:07:06;0040;PBS_Server;Svr;tyrone-cluster;Scheduler was sent the command new
07/25/2014 23:07:24;0040;PBS_Server;Svr;tyrone-cluster;Scheduler was sent the command new
07/25/2014 23:07:36;0040;PBS_Server;Svr;tyrone-cluster;Scheduler was sent the command new
07/25/2014 23:07:54;0040;PBS_Server;Svr;tyrone-cluster;Scheduler was sent the command new
07/25/2014 23:08:06;0040;PBS_Server;Svr;tyrone-cluster;Scheduler was sent the command new
07/25/2014 23:08:25;0040;PBS_Server;Svr;tyrone-cluster;Scheduler was sent the command new
07/25/2014 23:08:36;0040;PBS_Server;Svr;tyrone-cluster;Scheduler was sent the command new
07/25/2014 23:08:55;0040;PBS_Server;Svr;tyrone-cluster;Scheduler was sent the command new
07/25/2014 23:09:06;0040;PBS_Server;Svr;tyrone-cluster;Scheduler was sent the command new
07/25/2014 23:09:25;0040;PBS_Server;Svr;tyrone-cluster;Scheduler was sent the command new
07/25/2014 23:09:36;0040;PBS_Server;Svr;tyrone-cluster;Scheduler was sent the command new
07/25/2014 23:09:55;0040;PBS_Server;Svr;tyrone-cluster;Scheduler was sent the command new
07/25/2014 23:10:06;0040;PBS_Server;Svr;tyrone-cluster;Scheduler was sent the command new
07/25/2014 23:10:19;0002;PBS_Server;Svr;PBS_Server;Torque Server Version = 3.0.5, loglevel = 0
07/25/2014 23:10:25;0040;PBS_Server;Svr;tyrone-cluster;Scheduler was sent the command new
07/25/2014 23:10:36;0040;PBS_Server;Svr;tyrone-cluster;Scheduler was sent the command new
07/25/2014 23:10:55;0040;PBS_Server;Svr;tyrone-cluster;Scheduler was sent the command new
07/25/2014 23:11:06;0040;PBS_Server;Svr;tyrone-cluster;Scheduler was sent the command new
07/25/2014 23:11:25;0040;PBS_Server;Svr;tyrone-cluster;Scheduler was sent the command new
07/25/2014 23:11:36;0040;PBS_Server;Svr;tyrone-cluster;Scheduler was sent the command new
07/25/2014 23:11:55;0040;PBS_Server;Svr;tyrone-cluster;Scheduler was sent the command new
07/25/2014 23:12:06;0040;PBS_Server;Svr;tyrone-cluster;Scheduler was sent the command new
07/25/2014 23:12:25;0040;PBS_Server;Svr;tyrone-cluster;Scheduler was sent the command new
07/25/2014 23:12:36;0040;PBS_Server;Svr;tyrone-cluster;Scheduler was sent the command new
07/25/2014 23:12:55;0040;PBS_Server;Svr;tyrone-cluster;Scheduler was sent the command new
07/25/2014 23:13:06;0040;PBS_Server;Svr;tyrone-cluster;Scheduler was sent the command new
07/25/2014 23:13:25;0040;PBS_Server;Svr;tyrone-cluster;Scheduler was sent the command new
07/25/2014 23:13:36;0040;PBS_Server;Svr;tyrone-cluster;Scheduler was sent the command new
07/25/2014 23:13:55;0040;PBS_Server;Svr;tyrone-cluster;Scheduler was sent the command new
07/25/2014 23:14:07;0040;PBS_Server;Svr;tyrone-cluster;Scheduler was sent the command new
07/25/2014 23:14:25;0040;PBS_Server;Svr;tyrone-cluster;Scheduler was sent the command new
07/25/2014 23:14:37;0040;PBS_Server;Svr;tyrone-cluster;Scheduler was sent the command new
07/25/2014 23:14:55;0040;PBS_Server;Svr;tyrone-cluster;Scheduler was sent the command new
07/25/2014 23:15:07;0040;PBS_Server;Svr;tyrone-cluster;Scheduler was sent the command new
07/25/2014 23:15:19;0002;PBS_Server;Svr;PBS_Server;Torque Server Version = 3.0.5, loglevel = 0
07/25/2014 23:15:25;0040;PBS_Server;Svr;tyrone-cluster;Scheduler was sent the command new
07/25/2014 23:15:37;0040;PBS_Server;Svr;tyrone-cluster;Scheduler was sent the command new
07/25/2014 23:15:55;0040;PBS_Server;Svr;tyrone-cluster;Scheduler was sent the command new
07/25/2014 23:16:07;0040;PBS_Server;Svr;tyrone-cluster;Scheduler was sent the command new
07/25/2014 23:16:25;0040;PBS_Server;Svr;tyrone-cluster;Scheduler was sent the command new
07/25/2014 23:16:37;0040;PBS_Server;Svr;tyrone-cluster;Scheduler was sent the command new
07/25/2014 23:16:55;0040;PBS_Server;Svr;tyrone-cluster;Scheduler was sent the command new
07/25/2014 23:17:07;0040;PBS_Server;Svr;tyrone-cluster;Scheduler was sent the command new
07/25/2014 23:17:26;0040;PBS_Server;Svr;tyrone-cluster;Scheduler was sent the command new
07/25/2014 23:17:37;0040;PBS_Server;Svr;tyrone-cluster;Scheduler was sent the command new
07/25/2014 23:17:56;0040;PBS_Server;Svr;tyrone-cluster;Scheduler was sent the command new
07/25/2014 23:18:07;0040;PBS_Server;Svr;tyrone-cluster;Scheduler was sent the command new
07/25/2014 23:18:26;0040;PBS_Server;Svr;tyrone-cluster;Scheduler was sent the command new
07/25/2014 23:18:37;0040;PBS_Server;Svr;tyrone-cluster;Scheduler was sent the command new
07/25/2014 23:18:56;0040;PBS_Server;Svr;tyrone-cluster;Scheduler was sent the command new
07/25/2014 23:19:07;0040;PBS_Server;Svr;tyrone-cluster;Scheduler was sent the command new
07/25/2014 23:19:26;0040;PBS_Server;Svr;tyrone-cluster;Scheduler was sent the command new
07/25/2014 23:19:37;0040;PBS_Server;Svr;tyrone-cluster;Scheduler was sent the command new
07/25/2014 23:19:56;0040;PBS_Server;Svr;tyrone-cluster;Scheduler was sent the command new
07/25/2014 23:20:07;0040;PBS_Server;Svr;tyrone-cluster;Scheduler was sent the command new
07/25/2014 23:20:19;0002;PBS_Server;Svr;PBS_Server;Torque Server Version = 3.0.5, loglevel = 0
07/25/2014 23:20:26;0040;PBS_Server;Svr;tyrone-cluster;Scheduler was sent the command new
07/25/2014 23:20:37;0040;PBS_Server;Svr;tyrone-cluster;Scheduler was sent the command new
07/25/2014 23:20:56;0040;PBS_Server;Svr;tyrone-cluster;Scheduler was sent the command new
07/25/2014 23:21:07;0040;PBS_Server;Svr;tyrone-cluster;Scheduler was sent the command new
07/25/2014 23:21:26;0040;PBS_Server;Svr;tyrone-cluster;Scheduler was sent the command new
07/25/2014 23:21:37;0040;PBS_Server;Svr;tyrone-cluster;Scheduler was sent the command new
07/25/2014 23:21:56;0040;PBS_Server;Svr;tyrone-cluster;Scheduler was sent the command new
07/25/2014 23:22:07;0040;PBS_Server;Svr;tyrone-cluster;Scheduler was sent the command new
07/25/2014 23:22:26;0040;PBS_Server;Svr;tyrone-cluster;Scheduler was sent the command new
07/25/2014 23:22:37;0040;PBS_Server;Svr;tyrone-cluster;Scheduler was sent the command new
07/25/2014 23:22:56;0040;PBS_Server;Svr;tyrone-cluster;Scheduler was sent the command new
07/25/2014 23:23:07;0040;PBS_Server;Svr;tyrone-cluster;Scheduler was sent the command new
07/25/2014 23:23:26;0040;PBS_Server;Svr;tyrone-cluster;Scheduler was sent the command new
07/25/2014 23:23:37;0040;PBS_Server;Svr;tyrone-cluster;Scheduler was sent the command new
07/25/2014 23:23:56;0040;PBS_Server;Svr;tyrone-cluster;Scheduler was sent the command new
07/25/2014 23:24:08;0040;PBS_Server;Svr;tyrone-cluster;Scheduler was sent the command new
07/25/2014 23:24:26;0040;PBS_Server;Svr;tyrone-cluster;Scheduler was sent the command new
07/25/2014 23:24:38;0040;PBS_Server;Svr;tyrone-cluster;Scheduler was sent the command new
07/25/2014 23:24:56;0040;PBS_Server;Svr;tyrone-cluster;Scheduler was sent the command new
07/25/2014 23:25:08;0040;PBS_Server;Svr;tyrone-cluster;Scheduler was sent the command new
07/25/2014 23:25:19;0002;PBS_Server;Svr;PBS_Server;Torque Server Version = 3.0.5, loglevel = 0
07/25/2014 23:25:26;0040;PBS_Server;Svr;tyrone-cluster;Scheduler was sent the command new
07/25/2014 23:25:38;0040;PBS_Server;Svr;tyrone-cluster;Scheduler was sent the command new
07/25/2014 23:25:56;0040;PBS_Server;Svr;tyrone-cluster;Scheduler was sent the command new
07/25/2014 23:26:08;0040;PBS_Server;Svr;tyrone-cluster;Scheduler was sent the command new
07/25/2014 23:26:26;0040;PBS_Server;Svr;tyrone-cluster;Scheduler was sent the command new
07/25/2014 23:26:38;0040;PBS_Server;Svr;tyrone-cluster;Scheduler was sent the command new
07/25/2014 23:26:56;0040;PBS_Server;Svr;tyrone-cluster;Scheduler was sent the command new
07/25/2014 23:27:08;0040;PBS_Server;Svr;tyrone-cluster;Scheduler was sent the command new
07/25/2014 23:27:26;0040;PBS_Server;Svr;tyrone-cluster;Scheduler was sent the command new
07/25/2014 23:27:38;0040;PBS_Server;Svr;tyrone-cluster;Scheduler was sent the command new
07/25/2014 23:27:57;0040;PBS_Server;Svr;tyrone-cluster;Scheduler was sent the command new
07/25/2014 23:28:08;0040;PBS_Server;Svr;tyrone-cluster;Scheduler was sent the command new
07/25/2014 23:28:27;0040;PBS_Server;Svr;tyrone-cluster;Scheduler was sent the command new
07/25/2014 23:28:38;0040;PBS_Server;Svr;tyrone-cluster;Scheduler was sent the command new
07/25/2014 23:28:57;0040;PBS_Server;Svr;tyrone-cluster;Scheduler was sent the command new
07/25/2014 23:29:08;0040;PBS_Server;Svr;tyrone-cluster;Scheduler was sent the command new
07/25/2014 23:29:27;0040;PBS_Server;Svr;tyrone-cluster;Scheduler was sent the command new
07/25/2014 23:29:38;0040;PBS_Server;Svr;tyrone-cluster;Scheduler was sent the command new
07/25/2014 23:29:57;0040;PBS_Server;Svr;tyrone-cluster;Scheduler was sent the command new
07/25/2014 23:30:08;0040;PBS_Server;Svr;tyrone-cluster;Scheduler was sent the command new
07/25/2014 23:30:19;0002;PBS_Server;Svr;PBS_Server;Torque Server Version = 3.0.5, loglevel = 0
07/25/2014 23:30:27;0040;PBS_Server;Svr;tyrone-cluster;Scheduler was sent the command new
07/25/2014 23:30:38;0040;PBS_Server;Svr;tyrone-cluster;Scheduler was sent the command new
07/25/2014 23:30:57;0040;PBS_Server;Svr;tyrone-cluster;Scheduler was sent the command new
07/25/2014 23:31:08;0040;PBS_Server;Svr;tyrone-cluster;Scheduler was sent the command new
07/25/2014 23:31:27;0040;PBS_Server;Svr;tyrone-cluster;Scheduler was sent the command new
07/25/2014 23:31:38;0040;PBS_Server;Svr;tyrone-cluster;Scheduler was sent the command new
07/25/2014 23:31:57;0040;PBS_Server;Svr;tyrone-cluster;Scheduler was sent the command new
07/25/2014 23:32:08;0040;PBS_Server;Svr;tyrone-cluster;Scheduler was sent the command new
07/25/2014 23:32:27;0040;PBS_Server;Svr;tyrone-cluster;Scheduler was sent the command new
07/25/2014 23:32:38;0040;PBS_Server;Svr;tyrone-cluster;Scheduler was sent the command new
07/25/2014 23:32:57;0040;PBS_Server;Svr;tyrone-cluster;Scheduler was sent the command new
07/25/2014 23:33:08;0040;PBS_Server;Svr;tyrone-cluster;Scheduler was sent the command new
07/25/2014 23:33:27;0040;PBS_Server;Svr;tyrone-cluster;Scheduler was sent the command new
07/25/2014 23:33:39;0040;PBS_Server;Svr;tyrone-cluster;Scheduler was sent the command new
07/25/2014 23:33:57;0040;PBS_Server;Svr;tyrone-cluster;Scheduler was sent the command new
07/25/2014 23:34:09;0040;PBS_Server;Svr;tyrone-cluster;Scheduler was sent the command new
07/25/2014 23:34:27;0040;PBS_Server;Svr;tyrone-cluster;Scheduler was sent the command new
07/25/2014 23:34:39;0040;PBS_Server;Svr;tyrone-cluster;Scheduler was sent the command new
07/25/2014 23:34:57;0040;PBS_Server;Svr;tyrone-cluster;Scheduler was sent the command new
07/25/2014 23:35:09;0040;PBS_Server;Svr;tyrone-cluster;Scheduler was sent the command new
07/25/2014 23:35:19;0002;PBS_Server;Svr;PBS_Server;Torque Server Version = 3.0.5, loglevel = 0
07/25/2014 23:35:27;0040;PBS_Server;Svr;tyrone-cluster;Scheduler was sent the command new
07/25/2014 23:35:39;0040;PBS_Server;Svr;tyrone-cluster;Scheduler was sent the command new
07/25/2014 23:35:57;0040;PBS_Server;Svr;tyrone-cluster;Scheduler was sent the command new
07/25/2014 23:36:09;0040;PBS_Server;Svr;tyrone-cluster;Scheduler was sent the command new
07/25/2014 23:36:27;0040;PBS_Server;Svr;tyrone-cluster;Scheduler was sent the command new
07/25/2014 23:36:39;0040;PBS_Server;Svr;tyrone-cluster;Scheduler was sent the command new
07/25/2014 23:36:58;0040;PBS_Server;Svr;tyrone-cluster;Scheduler was sent the command new
07/25/2014 23:37:09;0040;PBS_Server;Svr;tyrone-cluster;Scheduler was sent the command new
07/25/2014 23:37:28;0040;PBS_Server;Svr;tyrone-cluster;Scheduler was sent the command new
07/25/2014 23:37:39;0040;PBS_Server;Svr;tyrone-cluster;Scheduler was sent the command new
07/25/2014 23:37:58;0040;PBS_Server;Svr;tyrone-cluster;Scheduler was sent the command new
07/25/2014 23:38:09;0040;PBS_Server;Svr;tyrone-cluster;Scheduler was sent the command new
07/25/2014 23:38:28;0040;PBS_Server;Svr;tyrone-cluster;Scheduler was sent the command new
07/25/2014 23:38:39;0040;PBS_Server;Svr;tyrone-cluster;Scheduler was sent the command new
07/25/2014 23:38:58;0040;PBS_Server;Svr;tyrone-cluster;Scheduler was sent the command new
07/25/2014 23:39:09;0040;PBS_Server;Svr;tyrone-cluster;Scheduler was sent the command new
07/25/2014 23:39:28;0040;PBS_Server;Svr;tyrone-cluster;Scheduler was sent the command new
07/25/2014 23:39:39;0040;PBS_Server;Svr;tyrone-cluster;Scheduler was sent the command new
07/25/2014 23:39:58;0040;PBS_Server;Svr;tyrone-cluster;Scheduler was sent the command new
07/25/2014 23:40:09;0040;PBS_Server;Svr;tyrone-cluster;Scheduler was sent the command new
07/25/2014 23:40:19;0002;PBS_Server;Svr;PBS_Server;Torque Server Version = 3.0.5, loglevel = 0
07/25/2014 23:40:28;0040;PBS_Server;Svr;tyrone-cluster;Scheduler was sent the command new
07/25/2014 23:40:39;0040;PBS_Server;Svr;tyrone-cluster;Scheduler was sent the command new
07/25/2014 23:40:58;0040;PBS_Server;Svr;tyrone-cluster;Scheduler was sent the command new
07/25/2014 23:41:09;0040;PBS_Server;Svr;tyrone-cluster;Scheduler was sent the command new
07/25/2014 23:41:28;0040;PBS_Server;Svr;tyrone-cluster;Scheduler was sent the command new
07/25/2014 23:41:39;0040;PBS_Server;Svr;tyrone-cluster;Scheduler was sent the command new
07/25/2014 23:41:58;0040;PBS_Server;Svr;tyrone-cluster;Scheduler was sent the command new
07/25/2014 23:42:09;0040;PBS_Server;Svr;tyrone-cluster;Scheduler was sent the command new
07/25/2014 23:42:28;0040;PBS_Server;Svr;tyrone-cluster;Scheduler was sent the command new
07/25/2014 23:42:39;0040;PBS_Server;Svr;tyrone-cluster;Scheduler was sent the command new
07/25/2014 23:42:58;0040;PBS_Server;Svr;tyrone-cluster;Scheduler was sent the command new
07/25/2014 23:43:10;0040;PBS_Server;Svr;tyrone-cluster;Scheduler was sent the command new
07/25/2014 23:43:28;0040;PBS_Server;Svr;tyrone-cluster;Scheduler was sent the command new
07/25/2014 23:43:40;0040;PBS_Server;Svr;tyrone-cluster;Scheduler was sent the command new
07/25/2014 23:43:58;0040;PBS_Server;Svr;tyrone-cluster;Scheduler was sent the command new
07/25/2014 23:44:10;0040;PBS_Server;Svr;tyrone-cluster;Scheduler was sent the command new
07/25/2014 23:44:28;0040;PBS_Server;Svr;tyrone-cluster;Scheduler was sent the command new
07/25/2014 23:44:40;0040;PBS_Server;Svr;tyrone-cluster;Scheduler was sent the command new
07/25/2014 23:44:58;0040;PBS_Server;Svr;tyrone-cluster;Scheduler was sent the command new
07/25/2014 23:45:10;0040;PBS_Server;Svr;tyrone-cluster;Scheduler was sent the command new
07/25/2014 23:45:19;0002;PBS_Server;Svr;PBS_Server;Torque Server Version = 3.0.5, loglevel = 0
07/25/2014 23:45:28;0040;PBS_Server;Svr;tyrone-cluster;Scheduler was sent the command new
07/25/2014 23:45:40;0040;PBS_Server;Svr;tyrone-cluster;Scheduler was sent the command new
07/25/2014 23:45:59;0040;PBS_Server;Svr;tyrone-cluster;Scheduler was sent the command new
07/25/2014 23:46:10;0040;PBS_Server;Svr;tyrone-cluster;Scheduler was sent the command new
07/25/2014 23:46:29;0040;PBS_Server;Svr;tyrone-cluster;Scheduler was sent the command new
07/25/2014 23:46:40;0040;PBS_Server;Svr;tyrone-cluster;Scheduler was sent the command new
07/25/2014 23:46:59;0040;PBS_Server;Svr;tyrone-cluster;Scheduler was sent the command new
07/25/2014 23:47:10;0040;PBS_Server;Svr;tyrone-cluster;Scheduler was sent the command new
07/25/2014 23:47:29;0040;PBS_Server;Svr;tyrone-cluster;Scheduler was sent the command new
07/25/2014 23:47:40;0040;PBS_Server;Svr;tyrone-cluster;Scheduler was sent the command new
07/25/2014 23:47:59;0040;PBS_Server;Svr;tyrone-cluster;Scheduler was sent the command new
07/25/2014 23:48:10;0040;PBS_Server;Svr;tyrone-cluster;Scheduler was sent the command new
07/25/2014 23:48:29;0040;PBS_Server;Svr;tyrone-cluster;Scheduler was sent the command new
07/25/2014 23:48:40;0040;PBS_Server;Svr;tyrone-cluster;Scheduler was sent the command new
07/25/2014 23:48:59;0040;PBS_Server;Svr;tyrone-cluster;Scheduler was sent the command new
07/25/2014 23:49:10;0040;PBS_Server;Svr;tyrone-cluster;Scheduler was sent the command new
07/25/2014 23:49:29;0040;PBS_Server;Svr;tyrone-cluster;Scheduler was sent the command new
07/25/2014 23:49:40;0040;PBS_Server;Svr;tyrone-cluster;Scheduler was sent the command new
07/25/2014 23:49:59;0040;PBS_Server;Svr;tyrone-cluster;Scheduler was sent the command new
07/25/2014 23:50:10;0040;PBS_Server;Svr;tyrone-cluster;Scheduler was sent the command new
07/25/2014 23:50:19;0002;PBS_Server;Svr;PBS_Server;Torque Server Version = 3.0.5, loglevel = 0
07/25/2014 23:50:29;0040;PBS_Server;Svr;tyrone-cluster;Scheduler was sent the command new
07/25/2014 23:50:40;0040;PBS_Server;Svr;tyrone-cluster;Scheduler was sent the command new
07/25/2014 23:50:59;0040;PBS_Server;Svr;tyrone-cluster;Scheduler was sent the command new
07/25/2014 23:51:10;0040;PBS_Server;Svr;tyrone-cluster;Scheduler was sent the command new
07/25/2014 23:51:29;0040;PBS_Server;Svr;tyrone-cluster;Scheduler was sent the command new
07/25/2014 23:51:40;0040;PBS_Server;Svr;tyrone-cluster;Scheduler was sent the command new
07/25/2014 23:51:59;0040;PBS_Server;Svr;tyrone-cluster;Scheduler was sent the command new
07/25/2014 23:52:10;0040;PBS_Server;Svr;tyrone-cluster;Scheduler was sent the command new
07/25/2014 23:52:29;0040;PBS_Server;Svr;tyrone-cluster;Scheduler was sent the command new
07/25/2014 23:52:41;0040;PBS_Server;Svr;tyrone-cluster;Scheduler was sent the command new
07/25/2014 23:52:59;0040;PBS_Server;Svr;tyrone-cluster;Scheduler was sent the command new
07/25/2014 23:53:11;0040;PBS_Server;Svr;tyrone-cluster;Scheduler was sent the command new
07/25/2014 23:53:29;0040;PBS_Server;Svr;tyrone-cluster;Scheduler was sent the command new
07/25/2014 23:53:41;0040;PBS_Server;Svr;tyrone-cluster;Scheduler was sent the command new
07/25/2014 23:53:59;0040;PBS_Server;Svr;tyrone-cluster;Scheduler was sent the command new
07/25/2014 23:54:11;0040;PBS_Server;Svr;tyrone-cluster;Scheduler was sent the command new
07/25/2014 23:54:29;0040;PBS_Server;Svr;tyrone-cluster;Scheduler was sent the command new
07/25/2014 23:54:41;0040;PBS_Server;Svr;tyrone-cluster;Scheduler was sent the command new
07/25/2014 23:54:59;0040;PBS_Server;Svr;tyrone-cluster;Scheduler was sent the command new
07/25/2014 23:55:11;0040;PBS_Server;Svr;tyrone-cluster;Scheduler was sent the command new
07/25/2014 23:55:19;0002;PBS_Server;Svr;PBS_Server;Torque Server Version = 3.0.5, loglevel = 0
07/25/2014 23:55:30;0040;PBS_Server;Svr;tyrone-cluster;Scheduler was sent the command new
07/25/2014 23:55:41;0040;PBS_Server;Svr;tyrone-cluster;Scheduler was sent the command new
07/25/2014 23:55:59;0040;PBS_Server;Svr;tyrone-cluster;Scheduler was sent the command new
07/25/2014 23:56:11;0040;PBS_Server;Svr;tyrone-cluster;Scheduler was sent the command new
07/25/2014 23:56:30;0040;PBS_Server;Svr;tyrone-cluster;Scheduler was sent the command new
07/25/2014 23:56:41;0040;PBS_Server;Svr;tyrone-cluster;Scheduler was sent the command new
07/25/2014 23:57:00;0040;PBS_Server;Svr;tyrone-cluster;Scheduler was sent the command new
07/25/2014 23:57:11;0040;PBS_Server;Svr;tyrone-cluster;Scheduler was sent the command new
07/25/2014 23:57:30;0040;PBS_Server;Svr;tyrone-cluster;Scheduler was sent the command new
07/25/2014 23:57:41;0040;PBS_Server;Svr;tyrone-cluster;Scheduler was sent the command new
07/25/2014 23:58:00;0040;PBS_Server;Svr;tyrone-cluster;Scheduler was sent the command new
07/25/2014 23:58:11;0040;PBS_Server;Svr;tyrone-cluster;Scheduler was sent the command new
07/25/2014 23:58:30;0040;PBS_Server;Svr;tyrone-cluster;Scheduler was sent the command new
07/25/2014 23:58:41;0040;PBS_Server;Svr;tyrone-cluster;Scheduler was sent the command new
07/25/2014 23:59:00;0040;PBS_Server;Svr;tyrone-cluster;Scheduler was sent the command new
07/25/2014 23:59:11;0040;PBS_Server;Svr;tyrone-cluster;Scheduler was sent the command new
07/25/2014 23:59:30;0040;PBS_Server;Svr;tyrone-cluster;Scheduler was sent the command new
07/25/2014 23:59:41;0040;PBS_Server;Svr;tyrone-cluster;Scheduler was sent the command new
07/26/2014 00:00:00;0002;PBS_Server;Svr;Log;Log closed
