07/14/2015 00:00:06;0002;PBS_Server;Svr;Log;Log opened
07/14/2015 00:00:05;0008;PBS_Server;Job;NULL;on_job_exit valid pjob: 0x1dcb770 (substate=10)
07/14/2015 00:00:09;0040;PBS_Server;Svr;tyrone-cluster;Scheduler was sent the command new
07/14/2015 00:00:35;0008;PBS_Server;Job;NULL;on_job_exit valid pjob: 0x1dcb770 (substate=10)
07/14/2015 00:00:41;0040;PBS_Server;Svr;tyrone-cluster;Scheduler was sent the command new
07/14/2015 00:01:05;0008;PBS_Server;Job;NULL;on_job_exit valid pjob: 0x1dcb770 (substate=10)
07/14/2015 00:01:10;0040;PBS_Server;Svr;tyrone-cluster;Scheduler was sent the command new
07/14/2015 00:01:20;0002;PBS_Server;Svr;PBS_Server;Torque Server Version = 3.0.5, loglevel = 0
07/14/2015 00:01:35;0008;PBS_Server;Job;NULL;on_job_exit valid pjob: 0x1dcb770 (substate=10)
07/14/2015 00:01:51;0040;PBS_Server;Svr;tyrone-cluster;Scheduler was sent the command new
07/14/2015 00:02:05;0008;PBS_Server;Job;NULL;on_job_exit valid pjob: 0x1dcb770 (substate=10)
07/14/2015 00:02:19;0040;PBS_Server;Svr;tyrone-cluster;Scheduler was sent the command new
07/14/2015 00:02:35;0008;PBS_Server;Job;NULL;on_job_exit valid pjob: 0x1dcb770 (substate=10)
07/14/2015 00:02:45;0040;PBS_Server;Svr;tyrone-cluster;Scheduler was sent the command new
07/14/2015 00:03:05;0008;PBS_Server;Job;NULL;on_job_exit valid pjob: 0x1dcb770 (substate=10)
07/14/2015 00:03:26;0040;PBS_Server;Svr;tyrone-cluster;Scheduler was sent the command new
07/14/2015 00:03:35;0008;PBS_Server;Job;NULL;on_job_exit valid pjob: 0x1dcb770 (substate=10)
07/14/2015 00:03:54;0040;PBS_Server;Svr;tyrone-cluster;Scheduler was sent the command new
07/14/2015 00:04:05;0008;PBS_Server;Job;NULL;on_job_exit valid pjob: 0x1dcb770 (substate=10)
07/14/2015 00:04:24;0040;PBS_Server;Svr;tyrone-cluster;Scheduler was sent the command new
07/14/2015 00:04:35;0008;PBS_Server;Job;NULL;on_job_exit valid pjob: 0x1dcb770 (substate=10)
07/14/2015 00:04:55;0040;PBS_Server;Svr;tyrone-cluster;Scheduler was sent the command new
07/14/2015 00:05:05;0008;PBS_Server;Job;NULL;on_job_exit valid pjob: 0x1dcb770 (substate=10)
07/14/2015 00:05:24;0040;PBS_Server;Svr;tyrone-cluster;Scheduler was sent the command new
07/14/2015 00:05:35;0008;PBS_Server;Job;NULL;on_job_exit valid pjob: 0x1dcb770 (substate=10)
07/14/2015 00:05:53;0040;PBS_Server;Svr;tyrone-cluster;Scheduler was sent the command new
07/14/2015 00:06:05;0008;PBS_Server;Job;NULL;on_job_exit valid pjob: 0x1dcb770 (substate=10)
07/14/2015 00:06:20;0002;PBS_Server;Svr;PBS_Server;Torque Server Version = 3.0.5, loglevel = 0
07/14/2015 00:06:25;0040;PBS_Server;Svr;tyrone-cluster;Scheduler was sent the command new
07/14/2015 00:06:35;0008;PBS_Server;Job;NULL;on_job_exit valid pjob: 0x1dcb770 (substate=10)
07/14/2015 00:06:54;0040;PBS_Server;Svr;tyrone-cluster;Scheduler was sent the command new
07/14/2015 00:07:05;0008;PBS_Server;Job;NULL;on_job_exit valid pjob: 0x1dcb770 (substate=10)
07/14/2015 00:07:21;0040;PBS_Server;Svr;tyrone-cluster;Scheduler was sent the command new
07/14/2015 00:07:35;0008;PBS_Server;Job;NULL;on_job_exit valid pjob: 0x1dcb770 (substate=10)
07/14/2015 00:07:56;0040;PBS_Server;Svr;tyrone-cluster;Scheduler was sent the command new
07/14/2015 00:08:05;0008;PBS_Server;Job;NULL;on_job_exit valid pjob: 0x1dcb770 (substate=10)
07/14/2015 00:08:24;0040;PBS_Server;Svr;tyrone-cluster;Scheduler was sent the command new
07/14/2015 00:09:13;0008;PBS_Server;Job;NULL;on_job_exit valid pjob: 0x1dcb770 (substate=10)
07/14/2015 00:09:13;0080;PBS_Server;Req;dis_request_read;req header bad, dis error 7 (Premature end of message), type=Connect
07/14/2015 00:09:13;0080;PBS_Server;Req;req_reject;Reject reply code=15058(Bad DIS based Request Protocol MSG=cannot decode message), aux=0, type=Connect, from @
07/14/2015 00:09:13;0002;PBS_Server;Req;dis_reply_write;DIS reply failure, -1
07/14/2015 00:09:13;0040;PBS_Server;Svr;tyrone-cluster;Scheduler was sent the command new
07/14/2015 00:09:43;0008;PBS_Server;Job;NULL;on_job_exit valid pjob: 0x1dcb770 (substate=10)
07/14/2015 00:09:48;0040;PBS_Server;Svr;tyrone-cluster;Scheduler was sent the command new
07/14/2015 00:10:13;0008;PBS_Server;Job;NULL;on_job_exit valid pjob: 0x1dcb770 (substate=10)
07/14/2015 00:10:14;0040;PBS_Server;Svr;tyrone-cluster;Scheduler was sent the command new
07/14/2015 00:10:43;0008;PBS_Server;Job;NULL;on_job_exit valid pjob: 0x1dcb770 (substate=10)
07/14/2015 00:10:44;0040;PBS_Server;Svr;tyrone-cluster;Scheduler was sent the command new
07/14/2015 00:11:13;0008;PBS_Server;Job;NULL;on_job_exit valid pjob: 0x1dcb770 (substate=10)
07/14/2015 00:11:13;0040;PBS_Server;Svr;tyrone-cluster;Scheduler was sent the command new
07/14/2015 00:11:20;0002;PBS_Server;Svr;PBS_Server;Torque Server Version = 3.0.5, loglevel = 0
07/14/2015 00:11:43;0008;PBS_Server;Job;NULL;on_job_exit valid pjob: 0x1dcb770 (substate=10)
07/14/2015 00:11:44;0040;PBS_Server;Svr;tyrone-cluster;Scheduler was sent the command new
07/14/2015 00:12:13;0008;PBS_Server;Job;NULL;on_job_exit valid pjob: 0x1dcb770 (substate=10)
07/14/2015 00:12:14;0040;PBS_Server;Svr;tyrone-cluster;Scheduler was sent the command new
07/14/2015 00:12:43;0008;PBS_Server;Job;NULL;on_job_exit valid pjob: 0x1dcb770 (substate=10)
07/14/2015 00:12:43;0040;PBS_Server;Svr;tyrone-cluster;Scheduler was sent the command new
07/14/2015 00:13:13;0008;PBS_Server;Job;NULL;on_job_exit valid pjob: 0x1dcb770 (substate=10)
07/14/2015 00:13:14;0040;PBS_Server;Svr;tyrone-cluster;Scheduler was sent the command new
07/14/2015 00:13:43;0008;PBS_Server;Job;NULL;on_job_exit valid pjob: 0x1dcb770 (substate=10)
07/14/2015 00:13:44;0040;PBS_Server;Svr;tyrone-cluster;Scheduler was sent the command new
07/14/2015 00:14:13;0008;PBS_Server;Job;NULL;on_job_exit valid pjob: 0x1dcb770 (substate=10)
07/14/2015 00:14:13;0040;PBS_Server;Svr;tyrone-cluster;Scheduler was sent the command new
07/14/2015 00:14:43;0008;PBS_Server;Job;NULL;on_job_exit valid pjob: 0x1dcb770 (substate=10)
07/14/2015 00:14:44;0040;PBS_Server;Svr;tyrone-cluster;Scheduler was sent the command new
07/14/2015 00:15:13;0008;PBS_Server;Job;NULL;on_job_exit valid pjob: 0x1dcb770 (substate=10)
07/14/2015 00:15:14;0040;PBS_Server;Svr;tyrone-cluster;Scheduler was sent the command new
07/14/2015 00:15:43;0008;PBS_Server;Job;NULL;on_job_exit valid pjob: 0x1dcb770 (substate=10)
07/14/2015 00:15:43;0040;PBS_Server;Svr;tyrone-cluster;Scheduler was sent the command new
07/14/2015 00:16:13;0008;PBS_Server;Job;NULL;on_job_exit valid pjob: 0x1dcb770 (substate=10)
07/14/2015 00:16:14;0040;PBS_Server;Svr;tyrone-cluster;Scheduler was sent the command new
07/14/2015 00:16:20;0002;PBS_Server;Svr;PBS_Server;Torque Server Version = 3.0.5, loglevel = 0
07/14/2015 00:16:43;0008;PBS_Server;Job;NULL;on_job_exit valid pjob: 0x1dcb770 (substate=10)
07/14/2015 00:16:44;0040;PBS_Server;Svr;tyrone-cluster;Scheduler was sent the command new
07/14/2015 00:17:13;0008;PBS_Server;Job;NULL;on_job_exit valid pjob: 0x1dcb770 (substate=10)
07/14/2015 00:17:13;0040;PBS_Server;Svr;tyrone-cluster;Scheduler was sent the command new
07/14/2015 00:17:43;0008;PBS_Server;Job;NULL;on_job_exit valid pjob: 0x1dcb770 (substate=10)
07/14/2015 00:17:44;0040;PBS_Server;Svr;tyrone-cluster;Scheduler was sent the command new
07/14/2015 00:18:13;0008;PBS_Server;Job;NULL;on_job_exit valid pjob: 0x1dcb770 (substate=10)
07/14/2015 00:18:14;0040;PBS_Server;Svr;tyrone-cluster;Scheduler was sent the command new
07/14/2015 00:18:43;0008;PBS_Server;Job;NULL;on_job_exit valid pjob: 0x1dcb770 (substate=10)
07/14/2015 00:18:43;0040;PBS_Server;Svr;tyrone-cluster;Scheduler was sent the command new
07/14/2015 00:19:13;0008;PBS_Server;Job;NULL;on_job_exit valid pjob: 0x1dcb770 (substate=10)
07/14/2015 00:19:14;0040;PBS_Server;Svr;tyrone-cluster;Scheduler was sent the command new
07/14/2015 00:19:43;0008;PBS_Server;Job;NULL;on_job_exit valid pjob: 0x1dcb770 (substate=10)
07/14/2015 00:19:44;0040;PBS_Server;Svr;tyrone-cluster;Scheduler was sent the command new
07/14/2015 00:20:13;0008;PBS_Server;Job;NULL;on_job_exit valid pjob: 0x1dcb770 (substate=10)
07/14/2015 00:20:19;0040;PBS_Server;Svr;tyrone-cluster;Scheduler was sent the command new
07/14/2015 00:20:43;0008;PBS_Server;Job;NULL;on_job_exit valid pjob: 0x1dcb770 (substate=10)
07/14/2015 00:20:44;0040;PBS_Server;Svr;tyrone-cluster;Scheduler was sent the command new
07/14/2015 00:21:13;0008;PBS_Server;Job;NULL;on_job_exit valid pjob: 0x1dcb770 (substate=10)
07/14/2015 00:21:14;0040;PBS_Server;Svr;tyrone-cluster;Scheduler was sent the command new
07/14/2015 00:21:20;0002;PBS_Server;Svr;PBS_Server;Torque Server Version = 3.0.5, loglevel = 0
07/14/2015 00:21:43;0008;PBS_Server;Job;NULL;on_job_exit valid pjob: 0x1dcb770 (substate=10)
07/14/2015 00:21:43;0040;PBS_Server;Svr;tyrone-cluster;Scheduler was sent the command new
07/14/2015 00:22:13;0008;PBS_Server;Job;NULL;on_job_exit valid pjob: 0x1dcb770 (substate=10)
07/14/2015 00:22:14;0040;PBS_Server;Svr;tyrone-cluster;Scheduler was sent the command new
07/14/2015 00:22:43;0008;PBS_Server;Job;NULL;on_job_exit valid pjob: 0x1dcb770 (substate=10)
07/14/2015 00:22:44;0040;PBS_Server;Svr;tyrone-cluster;Scheduler was sent the command new
07/14/2015 00:23:13;0008;PBS_Server;Job;NULL;on_job_exit valid pjob: 0x1dcb770 (substate=10)
07/14/2015 00:23:13;0040;PBS_Server;Svr;tyrone-cluster;Scheduler was sent the command new
07/14/2015 00:23:43;0008;PBS_Server;Job;NULL;on_job_exit valid pjob: 0x1dcb770 (substate=10)
07/14/2015 00:23:44;0040;PBS_Server;Svr;tyrone-cluster;Scheduler was sent the command new
07/14/2015 00:24:13;0008;PBS_Server;Job;NULL;on_job_exit valid pjob: 0x1dcb770 (substate=10)
07/14/2015 00:24:14;0040;PBS_Server;Svr;tyrone-cluster;Scheduler was sent the command new
07/14/2015 00:24:43;0008;PBS_Server;Job;NULL;on_job_exit valid pjob: 0x1dcb770 (substate=10)
07/14/2015 00:24:43;0040;PBS_Server;Svr;tyrone-cluster;Scheduler was sent the command new
07/14/2015 00:25:13;0008;PBS_Server;Job;NULL;on_job_exit valid pjob: 0x1dcb770 (substate=10)
07/14/2015 00:25:14;0040;PBS_Server;Svr;tyrone-cluster;Scheduler was sent the command new
07/14/2015 00:25:43;0008;PBS_Server;Job;NULL;on_job_exit valid pjob: 0x1dcb770 (substate=10)
07/14/2015 00:25:44;0040;PBS_Server;Svr;tyrone-cluster;Scheduler was sent the command new
07/14/2015 00:26:13;0008;PBS_Server;Job;NULL;on_job_exit valid pjob: 0x1dcb770 (substate=10)
07/14/2015 00:26:13;0040;PBS_Server;Svr;tyrone-cluster;Scheduler was sent the command new
07/14/2015 00:26:20;0002;PBS_Server;Svr;PBS_Server;Torque Server Version = 3.0.5, loglevel = 0
07/14/2015 00:26:43;0008;PBS_Server;Job;NULL;on_job_exit valid pjob: 0x1dcb770 (substate=10)
07/14/2015 00:26:44;0040;PBS_Server;Svr;tyrone-cluster;Scheduler was sent the command new
07/14/2015 00:27:13;0008;PBS_Server;Job;NULL;on_job_exit valid pjob: 0x1dcb770 (substate=10)
07/14/2015 00:27:14;0040;PBS_Server;Svr;tyrone-cluster;Scheduler was sent the command new
07/14/2015 00:27:43;0008;PBS_Server;Job;NULL;on_job_exit valid pjob: 0x1dcb770 (substate=10)
07/14/2015 00:27:43;0040;PBS_Server;Svr;tyrone-cluster;Scheduler was sent the command new
07/14/2015 00:28:13;0008;PBS_Server;Job;NULL;on_job_exit valid pjob: 0x1dcb770 (substate=10)
07/14/2015 00:28:14;0040;PBS_Server;Svr;tyrone-cluster;Scheduler was sent the command new
07/14/2015 00:28:43;0008;PBS_Server;Job;NULL;on_job_exit valid pjob: 0x1dcb770 (substate=10)
07/14/2015 00:28:44;0040;PBS_Server;Svr;tyrone-cluster;Scheduler was sent the command new
07/14/2015 00:29:13;0008;PBS_Server;Job;NULL;on_job_exit valid pjob: 0x1dcb770 (substate=10)
07/14/2015 00:29:13;0040;PBS_Server;Svr;tyrone-cluster;Scheduler was sent the command new
07/14/2015 00:29:43;0008;PBS_Server;Job;NULL;on_job_exit valid pjob: 0x1dcb770 (substate=10)
07/14/2015 00:29:44;0040;PBS_Server;Svr;tyrone-cluster;Scheduler was sent the command new
07/14/2015 00:30:13;0008;PBS_Server;Job;NULL;on_job_exit valid pjob: 0x1dcb770 (substate=10)
07/14/2015 00:30:14;0040;PBS_Server;Svr;tyrone-cluster;Scheduler was sent the command new
07/14/2015 00:30:43;0008;PBS_Server;Job;NULL;on_job_exit valid pjob: 0x1dcb770 (substate=10)
07/14/2015 00:30:43;0040;PBS_Server;Svr;tyrone-cluster;Scheduler was sent the command new
07/14/2015 00:31:13;0008;PBS_Server;Job;NULL;on_job_exit valid pjob: 0x1dcb770 (substate=10)
07/14/2015 00:31:14;0040;PBS_Server;Svr;tyrone-cluster;Scheduler was sent the command new
07/14/2015 00:31:20;0002;PBS_Server;Svr;PBS_Server;Torque Server Version = 3.0.5, loglevel = 0
07/14/2015 00:31:43;0008;PBS_Server;Job;NULL;on_job_exit valid pjob: 0x1dcb770 (substate=10)
07/14/2015 00:31:44;0040;PBS_Server;Svr;tyrone-cluster;Scheduler was sent the command new
07/14/2015 00:32:13;0008;PBS_Server;Job;NULL;on_job_exit valid pjob: 0x1dcb770 (substate=10)
07/14/2015 00:32:13;0040;PBS_Server;Svr;tyrone-cluster;Scheduler was sent the command new
07/14/2015 00:32:43;0008;PBS_Server;Job;NULL;on_job_exit valid pjob: 0x1dcb770 (substate=10)
07/14/2015 00:32:44;0040;PBS_Server;Svr;tyrone-cluster;Scheduler was sent the command new
07/14/2015 00:33:13;0008;PBS_Server;Job;NULL;on_job_exit valid pjob: 0x1dcb770 (substate=10)
07/14/2015 00:33:14;0040;PBS_Server;Svr;tyrone-cluster;Scheduler was sent the command new
07/14/2015 00:33:43;0008;PBS_Server;Job;NULL;on_job_exit valid pjob: 0x1dcb770 (substate=10)
07/14/2015 00:33:43;0040;PBS_Server;Svr;tyrone-cluster;Scheduler was sent the command new
07/14/2015 00:34:13;0008;PBS_Server;Job;NULL;on_job_exit valid pjob: 0x1dcb770 (substate=10)
07/14/2015 00:34:14;0040;PBS_Server;Svr;tyrone-cluster;Scheduler was sent the command new
07/14/2015 00:34:43;0008;PBS_Server;Job;NULL;on_job_exit valid pjob: 0x1dcb770 (substate=10)
07/14/2015 00:34:44;0040;PBS_Server;Svr;tyrone-cluster;Scheduler was sent the command new
07/14/2015 00:35:13;0008;PBS_Server;Job;NULL;on_job_exit valid pjob: 0x1dcb770 (substate=10)
07/14/2015 00:35:13;0040;PBS_Server;Svr;tyrone-cluster;Scheduler was sent the command new
07/14/2015 00:35:43;0008;PBS_Server;Job;NULL;on_job_exit valid pjob: 0x1dcb770 (substate=10)
07/14/2015 00:35:44;0040;PBS_Server;Svr;tyrone-cluster;Scheduler was sent the command new
07/14/2015 00:36:13;0008;PBS_Server;Job;NULL;on_job_exit valid pjob: 0x1dcb770 (substate=10)
07/14/2015 00:36:14;0040;PBS_Server;Svr;tyrone-cluster;Scheduler was sent the command new
07/14/2015 00:36:20;0002;PBS_Server;Svr;PBS_Server;Torque Server Version = 3.0.5, loglevel = 0
07/14/2015 00:36:43;0008;PBS_Server;Job;NULL;on_job_exit valid pjob: 0x1dcb770 (substate=10)
07/14/2015 00:36:43;0040;PBS_Server;Svr;tyrone-cluster;Scheduler was sent the command new
07/14/2015 00:37:13;0008;PBS_Server;Job;NULL;on_job_exit valid pjob: 0x1dcb770 (substate=10)
07/14/2015 00:37:14;0040;PBS_Server;Svr;tyrone-cluster;Scheduler was sent the command new
07/14/2015 00:37:43;0008;PBS_Server;Job;NULL;on_job_exit valid pjob: 0x1dcb770 (substate=10)
07/14/2015 00:37:44;0040;PBS_Server;Svr;tyrone-cluster;Scheduler was sent the command new
07/14/2015 00:38:13;0008;PBS_Server;Job;NULL;on_job_exit valid pjob: 0x1dcb770 (substate=10)
07/14/2015 00:38:13;0040;PBS_Server;Svr;tyrone-cluster;Scheduler was sent the command new
07/14/2015 00:38:43;0008;PBS_Server;Job;NULL;on_job_exit valid pjob: 0x1dcb770 (substate=10)
07/14/2015 00:38:44;0040;PBS_Server;Svr;tyrone-cluster;Scheduler was sent the command new
07/14/2015 00:39:13;0008;PBS_Server;Job;NULL;on_job_exit valid pjob: 0x1dcb770 (substate=10)
07/14/2015 00:39:14;0040;PBS_Server;Svr;tyrone-cluster;Scheduler was sent the command new
07/14/2015 00:39:43;0008;PBS_Server;Job;NULL;on_job_exit valid pjob: 0x1dcb770 (substate=10)
07/14/2015 00:39:43;0040;PBS_Server;Svr;tyrone-cluster;Scheduler was sent the command new
07/14/2015 00:40:13;0008;PBS_Server;Job;NULL;on_job_exit valid pjob: 0x1dcb770 (substate=10)
07/14/2015 00:40:14;0040;PBS_Server;Svr;tyrone-cluster;Scheduler was sent the command new
07/14/2015 00:40:43;0008;PBS_Server;Job;NULL;on_job_exit valid pjob: 0x1dcb770 (substate=10)
07/14/2015 00:40:44;0040;PBS_Server;Svr;tyrone-cluster;Scheduler was sent the command new
07/14/2015 00:41:13;0008;PBS_Server;Job;NULL;on_job_exit valid pjob: 0x1dcb770 (substate=10)
07/14/2015 00:41:13;0040;PBS_Server;Svr;tyrone-cluster;Scheduler was sent the command new
07/14/2015 00:41:20;0002;PBS_Server;Svr;PBS_Server;Torque Server Version = 3.0.5, loglevel = 0
07/14/2015 00:41:43;0008;PBS_Server;Job;NULL;on_job_exit valid pjob: 0x1dcb770 (substate=10)
07/14/2015 00:41:44;0040;PBS_Server;Svr;tyrone-cluster;Scheduler was sent the command new
07/14/2015 00:42:13;0008;PBS_Server;Job;NULL;on_job_exit valid pjob: 0x1dcb770 (substate=10)
07/14/2015 00:42:14;0040;PBS_Server;Svr;tyrone-cluster;Scheduler was sent the command new
07/14/2015 00:42:43;0008;PBS_Server;Job;NULL;on_job_exit valid pjob: 0x1dcb770 (substate=10)
07/14/2015 00:42:44;0040;PBS_Server;Svr;tyrone-cluster;Scheduler was sent the command new
07/14/2015 00:43:13;0008;PBS_Server;Job;NULL;on_job_exit valid pjob: 0x1dcb770 (substate=10)
07/14/2015 00:43:14;0040;PBS_Server;Svr;tyrone-cluster;Scheduler was sent the command new
07/14/2015 00:43:43;0008;PBS_Server;Job;NULL;on_job_exit valid pjob: 0x1dcb770 (substate=10)
07/14/2015 00:43:44;0040;PBS_Server;Svr;tyrone-cluster;Scheduler was sent the command new
07/14/2015 00:44:13;0008;PBS_Server;Job;NULL;on_job_exit valid pjob: 0x1dcb770 (substate=10)
07/14/2015 00:44:19;0040;PBS_Server;Svr;tyrone-cluster;Scheduler was sent the command new
07/14/2015 00:44:43;0008;PBS_Server;Job;NULL;on_job_exit valid pjob: 0x1dcb770 (substate=10)
07/14/2015 00:44:45;0040;PBS_Server;Svr;tyrone-cluster;Scheduler was sent the command new
07/14/2015 00:45:13;0008;PBS_Server;Job;NULL;on_job_exit valid pjob: 0x1dcb770 (substate=10)
07/14/2015 00:45:14;0040;PBS_Server;Svr;tyrone-cluster;Scheduler was sent the command new
07/14/2015 00:45:43;0008;PBS_Server;Job;NULL;on_job_exit valid pjob: 0x1dcb770 (substate=10)
07/14/2015 00:45:43;0040;PBS_Server;Svr;tyrone-cluster;Scheduler was sent the command new
07/14/2015 00:46:13;0008;PBS_Server;Job;NULL;on_job_exit valid pjob: 0x1dcb770 (substate=10)
07/14/2015 00:46:14;0040;PBS_Server;Svr;tyrone-cluster;Scheduler was sent the command new
07/14/2015 00:46:20;0002;PBS_Server;Svr;PBS_Server;Torque Server Version = 3.0.5, loglevel = 0
07/14/2015 00:46:43;0008;PBS_Server;Job;NULL;on_job_exit valid pjob: 0x1dcb770 (substate=10)
07/14/2015 00:46:45;0040;PBS_Server;Svr;tyrone-cluster;Scheduler was sent the command new
07/14/2015 00:47:13;0008;PBS_Server;Job;NULL;on_job_exit valid pjob: 0x1dcb770 (substate=10)
07/14/2015 00:47:13;0040;PBS_Server;Svr;tyrone-cluster;Scheduler was sent the command new
07/14/2015 00:47:43;0008;PBS_Server;Job;NULL;on_job_exit valid pjob: 0x1dcb770 (substate=10)
07/14/2015 00:47:44;0040;PBS_Server;Svr;tyrone-cluster;Scheduler was sent the command new
07/14/2015 00:48:13;0008;PBS_Server;Job;NULL;on_job_exit valid pjob: 0x1dcb770 (substate=10)
07/14/2015 00:48:14;0040;PBS_Server;Svr;tyrone-cluster;Scheduler was sent the command new
07/14/2015 00:48:43;0008;PBS_Server;Job;NULL;on_job_exit valid pjob: 0x1dcb770 (substate=10)
07/14/2015 00:48:43;0040;PBS_Server;Svr;tyrone-cluster;Scheduler was sent the command new
07/14/2015 00:49:13;0008;PBS_Server;Job;NULL;on_job_exit valid pjob: 0x1dcb770 (substate=10)
07/14/2015 00:49:14;0040;PBS_Server;Svr;tyrone-cluster;Scheduler was sent the command new
07/14/2015 00:49:43;0008;PBS_Server;Job;NULL;on_job_exit valid pjob: 0x1dcb770 (substate=10)
07/14/2015 00:49:44;0040;PBS_Server;Svr;tyrone-cluster;Scheduler was sent the command new
07/14/2015 00:50:13;0008;PBS_Server;Job;NULL;on_job_exit valid pjob: 0x1dcb770 (substate=10)
07/14/2015 00:50:19;0040;PBS_Server;Svr;tyrone-cluster;Scheduler was sent the command new
07/14/2015 00:50:43;0008;PBS_Server;Job;NULL;on_job_exit valid pjob: 0x1dcb770 (substate=10)
07/14/2015 00:50:44;0040;PBS_Server;Svr;tyrone-cluster;Scheduler was sent the command new
07/14/2015 00:51:13;0008;PBS_Server;Job;NULL;on_job_exit valid pjob: 0x1dcb770 (substate=10)
07/14/2015 00:51:14;0040;PBS_Server;Svr;tyrone-cluster;Scheduler was sent the command new
07/14/2015 00:51:20;0002;PBS_Server;Svr;PBS_Server;Torque Server Version = 3.0.5, loglevel = 0
07/14/2015 00:51:43;0008;PBS_Server;Job;NULL;on_job_exit valid pjob: 0x1dcb770 (substate=10)
07/14/2015 00:51:43;0040;PBS_Server;Svr;tyrone-cluster;Scheduler was sent the command new
07/14/2015 00:52:13;0008;PBS_Server;Job;NULL;on_job_exit valid pjob: 0x1dcb770 (substate=10)
07/14/2015 00:52:14;0040;PBS_Server;Svr;tyrone-cluster;Scheduler was sent the command new
07/14/2015 00:52:43;0008;PBS_Server;Job;NULL;on_job_exit valid pjob: 0x1dcb770 (substate=10)
07/14/2015 00:52:44;0040;PBS_Server;Svr;tyrone-cluster;Scheduler was sent the command new
07/14/2015 00:53:13;0008;PBS_Server;Job;NULL;on_job_exit valid pjob: 0x1dcb770 (substate=10)
07/14/2015 00:53:18;0040;PBS_Server;Svr;tyrone-cluster;Scheduler was sent the command new
07/14/2015 00:53:43;0008;PBS_Server;Job;NULL;on_job_exit valid pjob: 0x1dcb770 (substate=10)
07/14/2015 00:53:44;0040;PBS_Server;Svr;tyrone-cluster;Scheduler was sent the command new
07/14/2015 00:54:13;0008;PBS_Server;Job;NULL;on_job_exit valid pjob: 0x1dcb770 (substate=10)
07/14/2015 00:54:14;0040;PBS_Server;Svr;tyrone-cluster;Scheduler was sent the command new
07/14/2015 00:54:43;0008;PBS_Server;Job;NULL;on_job_exit valid pjob: 0x1dcb770 (substate=10)
07/14/2015 00:54:43;0040;PBS_Server;Svr;tyrone-cluster;Scheduler was sent the command new
07/14/2015 00:55:13;0008;PBS_Server;Job;NULL;on_job_exit valid pjob: 0x1dcb770 (substate=10)
07/14/2015 00:55:14;0040;PBS_Server;Svr;tyrone-cluster;Scheduler was sent the command new
07/14/2015 00:55:43;0008;PBS_Server;Job;NULL;on_job_exit valid pjob: 0x1dcb770 (substate=10)
07/14/2015 00:55:44;0040;PBS_Server;Svr;tyrone-cluster;Scheduler was sent the command new
07/14/2015 00:56:13;0008;PBS_Server;Job;NULL;on_job_exit valid pjob: 0x1dcb770 (substate=10)
07/14/2015 00:56:13;0040;PBS_Server;Svr;tyrone-cluster;Scheduler was sent the command new
07/14/2015 00:56:20;0002;PBS_Server;Svr;PBS_Server;Torque Server Version = 3.0.5, loglevel = 0
07/14/2015 00:56:43;0008;PBS_Server;Job;NULL;on_job_exit valid pjob: 0x1dcb770 (substate=10)
07/14/2015 00:56:44;0040;PBS_Server;Svr;tyrone-cluster;Scheduler was sent the command new
07/14/2015 00:57:13;0008;PBS_Server;Job;NULL;on_job_exit valid pjob: 0x1dcb770 (substate=10)
07/14/2015 00:57:14;0040;PBS_Server;Svr;tyrone-cluster;Scheduler was sent the command new
07/14/2015 00:57:43;0008;PBS_Server;Job;NULL;on_job_exit valid pjob: 0x1dcb770 (substate=10)
07/14/2015 00:57:43;0040;PBS_Server;Svr;tyrone-cluster;Scheduler was sent the command new
07/14/2015 00:58:13;0008;PBS_Server;Job;NULL;on_job_exit valid pjob: 0x1dcb770 (substate=10)
07/14/2015 00:58:14;0040;PBS_Server;Svr;tyrone-cluster;Scheduler was sent the command new
07/14/2015 00:58:43;0008;PBS_Server;Job;NULL;on_job_exit valid pjob: 0x1dcb770 (substate=10)
07/14/2015 00:58:44;0040;PBS_Server;Svr;tyrone-cluster;Scheduler was sent the command new
07/14/2015 00:59:13;0008;PBS_Server;Job;NULL;on_job_exit valid pjob: 0x1dcb770 (substate=10)
07/14/2015 00:59:13;0040;PBS_Server;Svr;tyrone-cluster;Scheduler was sent the command new
07/14/2015 00:59:43;0008;PBS_Server;Job;NULL;on_job_exit valid pjob: 0x1dcb770 (substate=10)
07/14/2015 00:59:44;0040;PBS_Server;Svr;tyrone-cluster;Scheduler was sent the command new
07/14/2015 01:00:13;0008;PBS_Server;Job;NULL;on_job_exit valid pjob: 0x1dcb770 (substate=10)
07/14/2015 01:00:14;0040;PBS_Server;Svr;tyrone-cluster;Scheduler was sent the command new
07/14/2015 01:00:43;0008;PBS_Server;Job;NULL;on_job_exit valid pjob: 0x1dcb770 (substate=10)
07/14/2015 01:00:44;0040;PBS_Server;Svr;tyrone-cluster;Scheduler was sent the command new
07/14/2015 01:01:13;0008;PBS_Server;Job;NULL;on_job_exit valid pjob: 0x1dcb770 (substate=10)
07/14/2015 01:01:14;0040;PBS_Server;Svr;tyrone-cluster;Scheduler was sent the command new
07/14/2015 01:01:20;0002;PBS_Server;Svr;PBS_Server;Torque Server Version = 3.0.5, loglevel = 0
07/14/2015 01:01:43;0008;PBS_Server;Job;NULL;on_job_exit valid pjob: 0x1dcb770 (substate=10)
07/14/2015 01:01:44;0040;PBS_Server;Svr;tyrone-cluster;Scheduler was sent the command new
07/14/2015 01:02:13;0008;PBS_Server;Job;NULL;on_job_exit valid pjob: 0x1dcb770 (substate=10)
07/14/2015 01:02:13;0040;PBS_Server;Svr;tyrone-cluster;Scheduler was sent the command new
07/14/2015 01:02:43;0008;PBS_Server;Job;NULL;on_job_exit valid pjob: 0x1dcb770 (substate=10)
07/14/2015 01:02:44;0040;PBS_Server;Svr;tyrone-cluster;Scheduler was sent the command new
07/14/2015 01:03:13;0008;PBS_Server;Job;NULL;on_job_exit valid pjob: 0x1dcb770 (substate=10)
07/14/2015 01:03:14;0040;PBS_Server;Svr;tyrone-cluster;Scheduler was sent the command new
07/14/2015 01:03:43;0008;PBS_Server;Job;NULL;on_job_exit valid pjob: 0x1dcb770 (substate=10)
07/14/2015 01:03:43;0040;PBS_Server;Svr;tyrone-cluster;Scheduler was sent the command new
07/14/2015 01:04:13;0008;PBS_Server;Job;NULL;on_job_exit valid pjob: 0x1dcb770 (substate=10)
07/14/2015 01:04:14;0040;PBS_Server;Svr;tyrone-cluster;Scheduler was sent the command new
07/14/2015 01:04:43;0008;PBS_Server;Job;NULL;on_job_exit valid pjob: 0x1dcb770 (substate=10)
07/14/2015 01:04:44;0040;PBS_Server;Svr;tyrone-cluster;Scheduler was sent the command new
07/14/2015 01:05:13;0008;PBS_Server;Job;NULL;on_job_exit valid pjob: 0x1dcb770 (substate=10)
07/14/2015 01:05:13;0040;PBS_Server;Svr;tyrone-cluster;Scheduler was sent the command new
07/14/2015 01:05:43;0008;PBS_Server;Job;NULL;on_job_exit valid pjob: 0x1dcb770 (substate=10)
07/14/2015 01:05:44;0040;PBS_Server;Svr;tyrone-cluster;Scheduler was sent the command new
07/14/2015 01:06:13;0008;PBS_Server;Job;NULL;on_job_exit valid pjob: 0x1dcb770 (substate=10)
07/14/2015 01:06:14;0040;PBS_Server;Svr;tyrone-cluster;Scheduler was sent the command new
07/14/2015 01:06:20;0002;PBS_Server;Svr;PBS_Server;Torque Server Version = 3.0.5, loglevel = 0
07/14/2015 01:06:43;0008;PBS_Server;Job;NULL;on_job_exit valid pjob: 0x1dcb770 (substate=10)
07/14/2015 01:06:49;0040;PBS_Server;Svr;tyrone-cluster;Scheduler was sent the command new
07/14/2015 01:07:13;0008;PBS_Server;Job;NULL;on_job_exit valid pjob: 0x1dcb770 (substate=10)
07/14/2015 01:07:14;0040;PBS_Server;Svr;tyrone-cluster;Scheduler was sent the command new
07/14/2015 01:07:43;0008;PBS_Server;Job;NULL;on_job_exit valid pjob: 0x1dcb770 (substate=10)
07/14/2015 01:07:44;0040;PBS_Server;Svr;tyrone-cluster;Scheduler was sent the command new
07/14/2015 01:08:13;0008;PBS_Server;Job;NULL;on_job_exit valid pjob: 0x1dcb770 (substate=10)
07/14/2015 01:08:13;0040;PBS_Server;Svr;tyrone-cluster;Scheduler was sent the command new
07/14/2015 01:08:43;0008;PBS_Server;Job;NULL;on_job_exit valid pjob: 0x1dcb770 (substate=10)
07/14/2015 01:08:44;0040;PBS_Server;Svr;tyrone-cluster;Scheduler was sent the command new
07/14/2015 01:09:13;0008;PBS_Server;Job;NULL;on_job_exit valid pjob: 0x1dcb770 (substate=10)
07/14/2015 01:09:14;0040;PBS_Server;Svr;tyrone-cluster;Scheduler was sent the command new
07/14/2015 01:09:43;0008;PBS_Server;Job;NULL;on_job_exit valid pjob: 0x1dcb770 (substate=10)
07/14/2015 01:09:43;0040;PBS_Server;Svr;tyrone-cluster;Scheduler was sent the command new
07/14/2015 01:10:13;0008;PBS_Server;Job;NULL;on_job_exit valid pjob: 0x1dcb770 (substate=10)
07/14/2015 01:10:14;0040;PBS_Server;Svr;tyrone-cluster;Scheduler was sent the command new
07/14/2015 01:10:43;0008;PBS_Server;Job;NULL;on_job_exit valid pjob: 0x1dcb770 (substate=10)
07/14/2015 01:10:44;0040;PBS_Server;Svr;tyrone-cluster;Scheduler was sent the command new
07/14/2015 01:11:13;0008;PBS_Server;Job;NULL;on_job_exit valid pjob: 0x1dcb770 (substate=10)
07/14/2015 01:11:13;0040;PBS_Server;Svr;tyrone-cluster;Scheduler was sent the command new
07/14/2015 01:11:20;0002;PBS_Server;Svr;PBS_Server;Torque Server Version = 3.0.5, loglevel = 0
07/14/2015 01:11:43;0008;PBS_Server;Job;NULL;on_job_exit valid pjob: 0x1dcb770 (substate=10)
07/14/2015 01:11:44;0040;PBS_Server;Svr;tyrone-cluster;Scheduler was sent the command new
07/14/2015 01:12:13;0008;PBS_Server;Job;NULL;on_job_exit valid pjob: 0x1dcb770 (substate=10)
07/14/2015 01:12:14;0040;PBS_Server;Svr;tyrone-cluster;Scheduler was sent the command new
07/14/2015 01:12:43;0008;PBS_Server;Job;NULL;on_job_exit valid pjob: 0x1dcb770 (substate=10)
07/14/2015 01:12:43;0040;PBS_Server;Svr;tyrone-cluster;Scheduler was sent the command new
07/14/2015 01:13:13;0008;PBS_Server;Job;NULL;on_job_exit valid pjob: 0x1dcb770 (substate=10)
07/14/2015 01:13:14;0040;PBS_Server;Svr;tyrone-cluster;Scheduler was sent the command new
07/14/2015 01:13:43;0008;PBS_Server;Job;NULL;on_job_exit valid pjob: 0x1dcb770 (substate=10)
07/14/2015 01:13:44;0040;PBS_Server;Svr;tyrone-cluster;Scheduler was sent the command new
07/14/2015 01:14:13;0008;PBS_Server;Job;NULL;on_job_exit valid pjob: 0x1dcb770 (substate=10)
07/14/2015 01:14:13;0040;PBS_Server;Svr;tyrone-cluster;Scheduler was sent the command new
07/14/2015 01:14:43;0008;PBS_Server;Job;NULL;on_job_exit valid pjob: 0x1dcb770 (substate=10)
07/14/2015 01:14:44;0040;PBS_Server;Svr;tyrone-cluster;Scheduler was sent the command new
07/14/2015 01:15:13;0008;PBS_Server;Job;NULL;on_job_exit valid pjob: 0x1dcb770 (substate=10)
07/14/2015 01:15:14;0040;PBS_Server;Svr;tyrone-cluster;Scheduler was sent the command new
07/14/2015 01:15:43;0008;PBS_Server;Job;NULL;on_job_exit valid pjob: 0x1dcb770 (substate=10)
07/14/2015 01:15:43;0040;PBS_Server;Svr;tyrone-cluster;Scheduler was sent the command new
07/14/2015 01:16:13;0008;PBS_Server;Job;NULL;on_job_exit valid pjob: 0x1dcb770 (substate=10)
07/14/2015 01:16:14;0040;PBS_Server;Svr;tyrone-cluster;Scheduler was sent the command new
07/14/2015 01:16:20;0002;PBS_Server;Svr;PBS_Server;Torque Server Version = 3.0.5, loglevel = 0
07/14/2015 01:16:43;0008;PBS_Server;Job;NULL;on_job_exit valid pjob: 0x1dcb770 (substate=10)
07/14/2015 01:16:44;0040;PBS_Server;Svr;tyrone-cluster;Scheduler was sent the command new
07/14/2015 01:17:13;0008;PBS_Server;Job;NULL;on_job_exit valid pjob: 0x1dcb770 (substate=10)
07/14/2015 01:17:13;0040;PBS_Server;Svr;tyrone-cluster;Scheduler was sent the command new
07/14/2015 01:17:43;0008;PBS_Server;Job;NULL;on_job_exit valid pjob: 0x1dcb770 (substate=10)
07/14/2015 01:17:44;0040;PBS_Server;Svr;tyrone-cluster;Scheduler was sent the command new
07/14/2015 01:18:13;0008;PBS_Server;Job;NULL;on_job_exit valid pjob: 0x1dcb770 (substate=10)
07/14/2015 01:18:14;0040;PBS_Server;Svr;tyrone-cluster;Scheduler was sent the command new
07/14/2015 01:18:43;0008;PBS_Server;Job;NULL;on_job_exit valid pjob: 0x1dcb770 (substate=10)
07/14/2015 01:18:43;0040;PBS_Server;Svr;tyrone-cluster;Scheduler was sent the command new
07/14/2015 01:19:13;0008;PBS_Server;Job;NULL;on_job_exit valid pjob: 0x1dcb770 (substate=10)
07/14/2015 01:19:14;0040;PBS_Server;Svr;tyrone-cluster;Scheduler was sent the command new
07/14/2015 01:19:43;0008;PBS_Server;Job;NULL;on_job_exit valid pjob: 0x1dcb770 (substate=10)
07/14/2015 01:19:44;0040;PBS_Server;Svr;tyrone-cluster;Scheduler was sent the command new
07/14/2015 01:20:13;0008;PBS_Server;Job;NULL;on_job_exit valid pjob: 0x1dcb770 (substate=10)
07/14/2015 01:20:13;0040;PBS_Server;Svr;tyrone-cluster;Scheduler was sent the command new
07/14/2015 01:20:43;0008;PBS_Server;Job;NULL;on_job_exit valid pjob: 0x1dcb770 (substate=10)
07/14/2015 01:20:44;0040;PBS_Server;Svr;tyrone-cluster;Scheduler was sent the command new
07/14/2015 01:21:13;0008;PBS_Server;Job;NULL;on_job_exit valid pjob: 0x1dcb770 (substate=10)
07/14/2015 01:21:14;0040;PBS_Server;Svr;tyrone-cluster;Scheduler was sent the command new
07/14/2015 01:21:20;0002;PBS_Server;Svr;PBS_Server;Torque Server Version = 3.0.5, loglevel = 0
07/14/2015 01:21:43;0008;PBS_Server;Job;NULL;on_job_exit valid pjob: 0x1dcb770 (substate=10)
07/14/2015 01:21:44;0040;PBS_Server;Svr;tyrone-cluster;Scheduler was sent the command new
07/14/2015 01:22:13;0008;PBS_Server;Job;NULL;on_job_exit valid pjob: 0x1dcb770 (substate=10)
07/14/2015 01:22:14;0040;PBS_Server;Svr;tyrone-cluster;Scheduler was sent the command new
07/14/2015 01:22:43;0008;PBS_Server;Job;NULL;on_job_exit valid pjob: 0x1dcb770 (substate=10)
07/14/2015 01:22:44;0040;PBS_Server;Svr;tyrone-cluster;Scheduler was sent the command new
07/14/2015 01:23:13;0008;PBS_Server;Job;NULL;on_job_exit valid pjob: 0x1dcb770 (substate=10)
07/14/2015 01:23:13;0040;PBS_Server;Svr;tyrone-cluster;Scheduler was sent the command new
07/14/2015 01:23:43;0008;PBS_Server;Job;NULL;on_job_exit valid pjob: 0x1dcb770 (substate=10)
07/14/2015 01:23:44;0040;PBS_Server;Svr;tyrone-cluster;Scheduler was sent the command new
07/14/2015 01:24:13;0008;PBS_Server;Job;NULL;on_job_exit valid pjob: 0x1dcb770 (substate=10)
07/14/2015 01:24:15;0040;PBS_Server;Svr;tyrone-cluster;Scheduler was sent the command new
07/14/2015 01:24:43;0008;PBS_Server;Job;NULL;on_job_exit valid pjob: 0x1dcb770 (substate=10)
07/14/2015 01:24:43;0040;PBS_Server;Svr;tyrone-cluster;Scheduler was sent the command new
07/14/2015 01:25:13;0008;PBS_Server;Job;NULL;on_job_exit valid pjob: 0x1dcb770 (substate=10)
07/14/2015 01:25:14;0040;PBS_Server;Svr;tyrone-cluster;Scheduler was sent the command new
07/14/2015 01:25:43;0008;PBS_Server;Job;NULL;on_job_exit valid pjob: 0x1dcb770 (substate=10)
07/14/2015 01:25:44;0040;PBS_Server;Svr;tyrone-cluster;Scheduler was sent the command new
07/14/2015 01:26:13;0008;PBS_Server;Job;NULL;on_job_exit valid pjob: 0x1dcb770 (substate=10)
07/14/2015 01:26:13;0040;PBS_Server;Svr;tyrone-cluster;Scheduler was sent the command new
07/14/2015 01:26:20;0002;PBS_Server;Svr;PBS_Server;Torque Server Version = 3.0.5, loglevel = 0
07/14/2015 01:26:43;0008;PBS_Server;Job;NULL;on_job_exit valid pjob: 0x1dcb770 (substate=10)
07/14/2015 01:26:44;0040;PBS_Server;Svr;tyrone-cluster;Scheduler was sent the command new
07/14/2015 01:27:13;0008;PBS_Server;Job;NULL;on_job_exit valid pjob: 0x1dcb770 (substate=10)
07/14/2015 01:27:14;0040;PBS_Server;Svr;tyrone-cluster;Scheduler was sent the command new
07/14/2015 01:27:43;0008;PBS_Server;Job;NULL;on_job_exit valid pjob: 0x1dcb770 (substate=10)
07/14/2015 01:27:43;0040;PBS_Server;Svr;tyrone-cluster;Scheduler was sent the command new
07/14/2015 01:28:13;0008;PBS_Server;Job;NULL;on_job_exit valid pjob: 0x1dcb770 (substate=10)
07/14/2015 01:28:14;0040;PBS_Server;Svr;tyrone-cluster;Scheduler was sent the command new
07/14/2015 01:28:43;0008;PBS_Server;Job;NULL;on_job_exit valid pjob: 0x1dcb770 (substate=10)
07/14/2015 01:28:44;0040;PBS_Server;Svr;tyrone-cluster;Scheduler was sent the command new
07/14/2015 01:29:13;0008;PBS_Server;Job;NULL;on_job_exit valid pjob: 0x1dcb770 (substate=10)
07/14/2015 01:29:14;0040;PBS_Server;Svr;tyrone-cluster;Scheduler was sent the command new
07/14/2015 01:29:43;0008;PBS_Server;Job;NULL;on_job_exit valid pjob: 0x1dcb770 (substate=10)
07/14/2015 01:29:44;0040;PBS_Server;Svr;tyrone-cluster;Scheduler was sent the command new
07/14/2015 01:30:13;0008;PBS_Server;Job;NULL;on_job_exit valid pjob: 0x1dcb770 (substate=10)
07/14/2015 01:30:15;0040;PBS_Server;Svr;tyrone-cluster;Scheduler was sent the command new
07/14/2015 01:30:43;0008;PBS_Server;Job;NULL;on_job_exit valid pjob: 0x1dcb770 (substate=10)
07/14/2015 01:30:43;0040;PBS_Server;Svr;tyrone-cluster;Scheduler was sent the command new
07/14/2015 01:31:13;0008;PBS_Server;Job;NULL;on_job_exit valid pjob: 0x1dcb770 (substate=10)
07/14/2015 01:31:14;0040;PBS_Server;Svr;tyrone-cluster;Scheduler was sent the command new
07/14/2015 01:31:20;0002;PBS_Server;Svr;PBS_Server;Torque Server Version = 3.0.5, loglevel = 0
07/14/2015 01:31:43;0008;PBS_Server;Job;NULL;on_job_exit valid pjob: 0x1dcb770 (substate=10)
07/14/2015 01:31:44;0040;PBS_Server;Svr;tyrone-cluster;Scheduler was sent the command new
07/14/2015 01:32:13;0008;PBS_Server;Job;NULL;on_job_exit valid pjob: 0x1dcb770 (substate=10)
07/14/2015 01:32:14;0040;PBS_Server;Svr;tyrone-cluster;Scheduler was sent the command new
07/14/2015 01:32:43;0008;PBS_Server;Job;NULL;on_job_exit valid pjob: 0x1dcb770 (substate=10)
07/14/2015 01:32:44;0040;PBS_Server;Svr;tyrone-cluster;Scheduler was sent the command new
07/14/2015 01:33:13;0008;PBS_Server;Job;NULL;on_job_exit valid pjob: 0x1dcb770 (substate=10)
07/14/2015 01:33:14;0040;PBS_Server;Svr;tyrone-cluster;Scheduler was sent the command new
07/14/2015 01:33:43;0008;PBS_Server;Job;NULL;on_job_exit valid pjob: 0x1dcb770 (substate=10)
07/14/2015 01:33:43;0040;PBS_Server;Svr;tyrone-cluster;Scheduler was sent the command new
07/14/2015 01:34:13;0008;PBS_Server;Job;NULL;on_job_exit valid pjob: 0x1dcb770 (substate=10)
07/14/2015 01:34:14;0040;PBS_Server;Svr;tyrone-cluster;Scheduler was sent the command new
07/14/2015 01:34:43;0008;PBS_Server;Job;NULL;on_job_exit valid pjob: 0x1dcb770 (substate=10)
07/14/2015 01:34:50;0040;PBS_Server;Svr;tyrone-cluster;Scheduler was sent the command new
07/14/2015 01:35:13;0008;PBS_Server;Job;NULL;on_job_exit valid pjob: 0x1dcb770 (substate=10)
07/14/2015 01:35:13;0040;PBS_Server;Svr;tyrone-cluster;Scheduler was sent the command new
07/14/2015 01:35:43;0008;PBS_Server;Job;NULL;on_job_exit valid pjob: 0x1dcb770 (substate=10)
07/14/2015 01:36:29;0008;PBS_Server;Job;NULL;on_job_exit valid pjob: 0x1dcb770 (substate=10)
07/14/2015 01:36:29;0002;PBS_Server;Svr;PBS_Server;Torque Server Version = 3.0.5, loglevel = 0
07/14/2015 01:36:29;0040;PBS_Server;Svr;tyrone-cluster;Scheduler was sent the command new
07/14/2015 01:36:59;0008;PBS_Server;Job;NULL;on_job_exit valid pjob: 0x1dcb770 (substate=10)
07/14/2015 01:37:07;0040;PBS_Server;Svr;tyrone-cluster;Scheduler was sent the command new
07/14/2015 01:37:29;0008;PBS_Server;Job;NULL;on_job_exit valid pjob: 0x1dcb770 (substate=10)
07/14/2015 01:37:30;0040;PBS_Server;Svr;tyrone-cluster;Scheduler was sent the command new
07/14/2015 01:37:59;0008;PBS_Server;Job;NULL;on_job_exit valid pjob: 0x1dcb770 (substate=10)
07/14/2015 01:38:00;0040;PBS_Server;Svr;tyrone-cluster;Scheduler was sent the command new
07/14/2015 01:38:29;0008;PBS_Server;Job;NULL;on_job_exit valid pjob: 0x1dcb770 (substate=10)
07/14/2015 01:38:37;0040;PBS_Server;Svr;tyrone-cluster;Scheduler was sent the command new
07/14/2015 01:38:59;0008;PBS_Server;Job;NULL;on_job_exit valid pjob: 0x1dcb770 (substate=10)
07/14/2015 01:39:00;0040;PBS_Server;Svr;tyrone-cluster;Scheduler was sent the command new
07/14/2015 01:39:29;0008;PBS_Server;Job;NULL;on_job_exit valid pjob: 0x1dcb770 (substate=10)
07/14/2015 01:39:30;0040;PBS_Server;Svr;tyrone-cluster;Scheduler was sent the command new
07/14/2015 01:39:59;0008;PBS_Server;Job;NULL;on_job_exit valid pjob: 0x1dcb770 (substate=10)
07/14/2015 01:40:07;0040;PBS_Server;Svr;tyrone-cluster;Scheduler was sent the command new
07/14/2015 01:40:29;0008;PBS_Server;Job;NULL;on_job_exit valid pjob: 0x1dcb770 (substate=10)
07/14/2015 01:40:30;0040;PBS_Server;Svr;tyrone-cluster;Scheduler was sent the command new
07/14/2015 01:40:59;0008;PBS_Server;Job;NULL;on_job_exit valid pjob: 0x1dcb770 (substate=10)
07/14/2015 01:41:00;0040;PBS_Server;Svr;tyrone-cluster;Scheduler was sent the command new
07/14/2015 01:41:29;0002;PBS_Server;Svr;PBS_Server;Torque Server Version = 3.0.5, loglevel = 0
07/14/2015 01:41:29;0008;PBS_Server;Job;NULL;on_job_exit valid pjob: 0x1dcb770 (substate=10)
07/14/2015 01:41:37;0040;PBS_Server;Svr;tyrone-cluster;Scheduler was sent the command new
07/14/2015 01:41:59;0008;PBS_Server;Job;NULL;on_job_exit valid pjob: 0x1dcb770 (substate=10)
07/14/2015 01:42:01;0040;PBS_Server;Svr;tyrone-cluster;Scheduler was sent the command new
07/14/2015 01:42:29;0008;PBS_Server;Job;NULL;on_job_exit valid pjob: 0x1dcb770 (substate=10)
07/14/2015 01:42:30;0040;PBS_Server;Svr;tyrone-cluster;Scheduler was sent the command new
07/14/2015 01:42:59;0008;PBS_Server;Job;NULL;on_job_exit valid pjob: 0x1dcb770 (substate=10)
07/14/2015 01:43:07;0040;PBS_Server;Svr;tyrone-cluster;Scheduler was sent the command new
07/14/2015 01:43:29;0008;PBS_Server;Job;NULL;on_job_exit valid pjob: 0x1dcb770 (substate=10)
07/14/2015 01:43:31;0040;PBS_Server;Svr;tyrone-cluster;Scheduler was sent the command new
07/14/2015 01:43:59;0008;PBS_Server;Job;NULL;on_job_exit valid pjob: 0x1dcb770 (substate=10)
07/14/2015 01:44:00;0040;PBS_Server;Svr;tyrone-cluster;Scheduler was sent the command new
07/14/2015 01:44:29;0008;PBS_Server;Job;NULL;on_job_exit valid pjob: 0x1dcb770 (substate=10)
07/14/2015 01:44:37;0040;PBS_Server;Svr;tyrone-cluster;Scheduler was sent the command new
07/14/2015 01:44:59;0008;PBS_Server;Job;NULL;on_job_exit valid pjob: 0x1dcb770 (substate=10)
07/14/2015 01:45:01;0040;PBS_Server;Svr;tyrone-cluster;Scheduler was sent the command new
07/14/2015 01:45:29;0008;PBS_Server;Job;NULL;on_job_exit valid pjob: 0x1dcb770 (substate=10)
07/14/2015 01:45:30;0040;PBS_Server;Svr;tyrone-cluster;Scheduler was sent the command new
07/14/2015 01:45:59;0008;PBS_Server;Job;NULL;on_job_exit valid pjob: 0x1dcb770 (substate=10)
07/14/2015 01:46:07;0040;PBS_Server;Svr;tyrone-cluster;Scheduler was sent the command new
07/14/2015 01:46:29;0002;PBS_Server;Svr;PBS_Server;Torque Server Version = 3.0.5, loglevel = 0
07/14/2015 01:46:29;0008;PBS_Server;Job;NULL;on_job_exit valid pjob: 0x1dcb770 (substate=10)
07/14/2015 01:46:31;0040;PBS_Server;Svr;tyrone-cluster;Scheduler was sent the command new
07/14/2015 01:46:59;0008;PBS_Server;Job;NULL;on_job_exit valid pjob: 0x1dcb770 (substate=10)
07/14/2015 01:47:00;0040;PBS_Server;Svr;tyrone-cluster;Scheduler was sent the command new
07/14/2015 01:47:29;0008;PBS_Server;Job;NULL;on_job_exit valid pjob: 0x1dcb770 (substate=10)
07/14/2015 01:47:37;0040;PBS_Server;Svr;tyrone-cluster;Scheduler was sent the command new
07/14/2015 01:47:59;0008;PBS_Server;Job;NULL;on_job_exit valid pjob: 0x1dcb770 (substate=10)
07/14/2015 01:48:01;0040;PBS_Server;Svr;tyrone-cluster;Scheduler was sent the command new
07/14/2015 01:48:29;0008;PBS_Server;Job;NULL;on_job_exit valid pjob: 0x1dcb770 (substate=10)
07/14/2015 01:48:30;0040;PBS_Server;Svr;tyrone-cluster;Scheduler was sent the command new
07/14/2015 01:48:59;0008;PBS_Server;Job;NULL;on_job_exit valid pjob: 0x1dcb770 (substate=10)
07/14/2015 01:49:07;0040;PBS_Server;Svr;tyrone-cluster;Scheduler was sent the command new
07/14/2015 01:49:29;0008;PBS_Server;Job;NULL;on_job_exit valid pjob: 0x1dcb770 (substate=10)
07/14/2015 01:49:31;0040;PBS_Server;Svr;tyrone-cluster;Scheduler was sent the command new
07/14/2015 01:49:59;0008;PBS_Server;Job;NULL;on_job_exit valid pjob: 0x1dcb770 (substate=10)
07/14/2015 01:50:00;0040;PBS_Server;Svr;tyrone-cluster;Scheduler was sent the command new
07/14/2015 01:50:29;0008;PBS_Server;Job;NULL;on_job_exit valid pjob: 0x1dcb770 (substate=10)
07/14/2015 01:50:37;0040;PBS_Server;Svr;tyrone-cluster;Scheduler was sent the command new
07/14/2015 01:50:59;0008;PBS_Server;Job;NULL;on_job_exit valid pjob: 0x1dcb770 (substate=10)
07/14/2015 01:51:01;0040;PBS_Server;Svr;tyrone-cluster;Scheduler was sent the command new
07/14/2015 01:51:29;0002;PBS_Server;Svr;PBS_Server;Torque Server Version = 3.0.5, loglevel = 0
07/14/2015 01:51:29;0008;PBS_Server;Job;NULL;on_job_exit valid pjob: 0x1dcb770 (substate=10)
07/14/2015 01:51:30;0040;PBS_Server;Svr;tyrone-cluster;Scheduler was sent the command new
07/14/2015 01:51:59;0008;PBS_Server;Job;NULL;on_job_exit valid pjob: 0x1dcb770 (substate=10)
07/14/2015 01:52:07;0040;PBS_Server;Svr;tyrone-cluster;Scheduler was sent the command new
07/14/2015 01:52:29;0008;PBS_Server;Job;NULL;on_job_exit valid pjob: 0x1dcb770 (substate=10)
07/14/2015 01:52:31;0040;PBS_Server;Svr;tyrone-cluster;Scheduler was sent the command new
07/14/2015 01:52:59;0008;PBS_Server;Job;NULL;on_job_exit valid pjob: 0x1dcb770 (substate=10)
07/14/2015 01:53:00;0040;PBS_Server;Svr;tyrone-cluster;Scheduler was sent the command new
07/14/2015 01:53:29;0008;PBS_Server;Job;NULL;on_job_exit valid pjob: 0x1dcb770 (substate=10)
07/14/2015 01:53:37;0040;PBS_Server;Svr;tyrone-cluster;Scheduler was sent the command new
07/14/2015 01:53:59;0008;PBS_Server;Job;NULL;on_job_exit valid pjob: 0x1dcb770 (substate=10)
07/14/2015 01:54:01;0040;PBS_Server;Svr;tyrone-cluster;Scheduler was sent the command new
07/14/2015 01:54:29;0008;PBS_Server;Job;NULL;on_job_exit valid pjob: 0x1dcb770 (substate=10)
07/14/2015 01:54:30;0040;PBS_Server;Svr;tyrone-cluster;Scheduler was sent the command new
07/14/2015 01:54:59;0008;PBS_Server;Job;NULL;on_job_exit valid pjob: 0x1dcb770 (substate=10)
07/14/2015 01:55:07;0040;PBS_Server;Svr;tyrone-cluster;Scheduler was sent the command new
07/14/2015 01:55:29;0008;PBS_Server;Job;NULL;on_job_exit valid pjob: 0x1dcb770 (substate=10)
07/14/2015 01:55:31;0040;PBS_Server;Svr;tyrone-cluster;Scheduler was sent the command new
07/14/2015 01:55:59;0008;PBS_Server;Job;NULL;on_job_exit valid pjob: 0x1dcb770 (substate=10)
07/14/2015 01:56:00;0040;PBS_Server;Svr;tyrone-cluster;Scheduler was sent the command new
07/14/2015 01:56:29;0002;PBS_Server;Svr;PBS_Server;Torque Server Version = 3.0.5, loglevel = 0
07/14/2015 01:56:29;0008;PBS_Server;Job;NULL;on_job_exit valid pjob: 0x1dcb770 (substate=10)
07/14/2015 01:56:37;0040;PBS_Server;Svr;tyrone-cluster;Scheduler was sent the command new
07/14/2015 01:56:59;0008;PBS_Server;Job;NULL;on_job_exit valid pjob: 0x1dcb770 (substate=10)
07/14/2015 01:57:01;0040;PBS_Server;Svr;tyrone-cluster;Scheduler was sent the command new
07/14/2015 01:57:29;0008;PBS_Server;Job;NULL;on_job_exit valid pjob: 0x1dcb770 (substate=10)
07/14/2015 01:57:30;0040;PBS_Server;Svr;tyrone-cluster;Scheduler was sent the command new
07/14/2015 01:57:59;0008;PBS_Server;Job;NULL;on_job_exit valid pjob: 0x1dcb770 (substate=10)
07/14/2015 01:58:07;0040;PBS_Server;Svr;tyrone-cluster;Scheduler was sent the command new
07/14/2015 01:58:29;0008;PBS_Server;Job;NULL;on_job_exit valid pjob: 0x1dcb770 (substate=10)
07/14/2015 01:58:31;0040;PBS_Server;Svr;tyrone-cluster;Scheduler was sent the command new
07/14/2015 01:58:59;0008;PBS_Server;Job;NULL;on_job_exit valid pjob: 0x1dcb770 (substate=10)
07/14/2015 01:59:00;0040;PBS_Server;Svr;tyrone-cluster;Scheduler was sent the command new
07/14/2015 01:59:29;0008;PBS_Server;Job;NULL;on_job_exit valid pjob: 0x1dcb770 (substate=10)
07/14/2015 01:59:37;0040;PBS_Server;Svr;tyrone-cluster;Scheduler was sent the command new
07/14/2015 01:59:59;0008;PBS_Server;Job;NULL;on_job_exit valid pjob: 0x1dcb770 (substate=10)
07/14/2015 02:00:01;0040;PBS_Server;Svr;tyrone-cluster;Scheduler was sent the command new
07/14/2015 02:00:29;0008;PBS_Server;Job;NULL;on_job_exit valid pjob: 0x1dcb770 (substate=10)
07/14/2015 02:00:30;0040;PBS_Server;Svr;tyrone-cluster;Scheduler was sent the command new
07/14/2015 02:00:59;0008;PBS_Server;Job;NULL;on_job_exit valid pjob: 0x1dcb770 (substate=10)
07/14/2015 02:01:07;0040;PBS_Server;Svr;tyrone-cluster;Scheduler was sent the command new
07/14/2015 02:01:29;0002;PBS_Server;Svr;PBS_Server;Torque Server Version = 3.0.5, loglevel = 0
07/14/2015 02:01:29;0008;PBS_Server;Job;NULL;on_job_exit valid pjob: 0x1dcb770 (substate=10)
07/14/2015 02:01:31;0040;PBS_Server;Svr;tyrone-cluster;Scheduler was sent the command new
07/14/2015 02:01:59;0008;PBS_Server;Job;NULL;on_job_exit valid pjob: 0x1dcb770 (substate=10)
07/14/2015 02:02:00;0040;PBS_Server;Svr;tyrone-cluster;Scheduler was sent the command new
07/14/2015 02:02:29;0008;PBS_Server;Job;NULL;on_job_exit valid pjob: 0x1dcb770 (substate=10)
07/14/2015 02:02:38;0040;PBS_Server;Svr;tyrone-cluster;Scheduler was sent the command new
07/14/2015 02:02:59;0008;PBS_Server;Job;NULL;on_job_exit valid pjob: 0x1dcb770 (substate=10)
07/14/2015 02:02:59;0040;PBS_Server;Svr;tyrone-cluster;Scheduler was sent the command new
07/14/2015 02:03:29;0008;PBS_Server;Job;NULL;on_job_exit valid pjob: 0x1dcb770 (substate=10)
07/14/2015 02:03:30;0040;PBS_Server;Svr;tyrone-cluster;Scheduler was sent the command new
07/14/2015 02:03:59;0008;PBS_Server;Job;NULL;on_job_exit valid pjob: 0x1dcb770 (substate=10)
07/14/2015 02:04:07;0040;PBS_Server;Svr;tyrone-cluster;Scheduler was sent the command new
07/14/2015 02:04:29;0008;PBS_Server;Job;NULL;on_job_exit valid pjob: 0x1dcb770 (substate=10)
07/14/2015 02:04:31;0040;PBS_Server;Svr;tyrone-cluster;Scheduler was sent the command new
07/14/2015 02:04:59;0008;PBS_Server;Job;NULL;on_job_exit valid pjob: 0x1dcb770 (substate=10)
07/14/2015 02:05:00;0040;PBS_Server;Svr;tyrone-cluster;Scheduler was sent the command new
07/14/2015 02:05:29;0008;PBS_Server;Job;NULL;on_job_exit valid pjob: 0x1dcb770 (substate=10)
07/14/2015 02:05:37;0040;PBS_Server;Svr;tyrone-cluster;Scheduler was sent the command new
07/14/2015 02:05:59;0008;PBS_Server;Job;NULL;on_job_exit valid pjob: 0x1dcb770 (substate=10)
07/14/2015 02:06:01;0040;PBS_Server;Svr;tyrone-cluster;Scheduler was sent the command new
07/14/2015 02:06:29;0002;PBS_Server;Svr;PBS_Server;Torque Server Version = 3.0.5, loglevel = 0
07/14/2015 02:06:29;0008;PBS_Server;Job;NULL;on_job_exit valid pjob: 0x1dcb770 (substate=10)
07/14/2015 02:06:30;0040;PBS_Server;Svr;tyrone-cluster;Scheduler was sent the command new
07/14/2015 02:06:59;0008;PBS_Server;Job;NULL;on_job_exit valid pjob: 0x1dcb770 (substate=10)
07/14/2015 02:07:07;0040;PBS_Server;Svr;tyrone-cluster;Scheduler was sent the command new
07/14/2015 02:07:29;0008;PBS_Server;Job;NULL;on_job_exit valid pjob: 0x1dcb770 (substate=10)
07/14/2015 02:07:31;0040;PBS_Server;Svr;tyrone-cluster;Scheduler was sent the command new
07/14/2015 02:07:59;0008;PBS_Server;Job;NULL;on_job_exit valid pjob: 0x1dcb770 (substate=10)
07/14/2015 02:08:01;0040;PBS_Server;Svr;tyrone-cluster;Scheduler was sent the command new
07/14/2015 02:08:29;0008;PBS_Server;Job;NULL;on_job_exit valid pjob: 0x1dcb770 (substate=10)
07/14/2015 02:08:42;0040;PBS_Server;Svr;tyrone-cluster;Scheduler was sent the command new
07/14/2015 02:08:59;0008;PBS_Server;Job;NULL;on_job_exit valid pjob: 0x1dcb770 (substate=10)
07/14/2015 02:09:10;0040;PBS_Server;Svr;tyrone-cluster;Scheduler was sent the command new
07/14/2015 02:09:29;0008;PBS_Server;Job;NULL;on_job_exit valid pjob: 0x1dcb770 (substate=10)
07/14/2015 02:09:40;0040;PBS_Server;Svr;tyrone-cluster;Scheduler was sent the command new
07/14/2015 02:09:59;0008;PBS_Server;Job;NULL;on_job_exit valid pjob: 0x1dcb770 (substate=10)
07/14/2015 02:10:15;0040;PBS_Server;Svr;tyrone-cluster;Scheduler was sent the command new
07/14/2015 02:10:29;0008;PBS_Server;Job;NULL;on_job_exit valid pjob: 0x1dcb770 (substate=10)
07/14/2015 02:10:53;0040;PBS_Server;Svr;tyrone-cluster;Scheduler was sent the command new
07/14/2015 02:10:59;0008;PBS_Server;Job;NULL;on_job_exit valid pjob: 0x1dcb770 (substate=10)
07/14/2015 02:11:13;0040;PBS_Server;Svr;tyrone-cluster;Scheduler was sent the command new
07/14/2015 02:11:29;0002;PBS_Server;Svr;PBS_Server;Torque Server Version = 3.0.5, loglevel = 0
07/14/2015 02:11:29;0008;PBS_Server;Job;NULL;on_job_exit valid pjob: 0x1dcb770 (substate=10)
07/14/2015 02:11:45;0040;PBS_Server;Svr;tyrone-cluster;Scheduler was sent the command new
07/14/2015 02:11:59;0008;PBS_Server;Job;NULL;on_job_exit valid pjob: 0x1dcb770 (substate=10)
07/14/2015 02:12:27;0040;PBS_Server;Svr;tyrone-cluster;Scheduler was sent the command new
07/14/2015 02:12:29;0008;PBS_Server;Job;NULL;on_job_exit valid pjob: 0x1dcb770 (substate=10)
07/14/2015 02:12:55;0040;PBS_Server;Svr;tyrone-cluster;Scheduler was sent the command new
07/14/2015 02:12:59;0008;PBS_Server;Job;NULL;on_job_exit valid pjob: 0x1dcb770 (substate=10)
07/14/2015 02:13:26;0040;PBS_Server;Svr;tyrone-cluster;Scheduler was sent the command new
07/14/2015 02:13:29;0008;PBS_Server;Job;NULL;on_job_exit valid pjob: 0x1dcb770 (substate=10)
07/14/2015 02:13:59;0008;PBS_Server;Job;NULL;on_job_exit valid pjob: 0x1dcb770 (substate=10)
07/14/2015 02:13:59;0040;PBS_Server;Svr;tyrone-cluster;Scheduler was sent the command new
07/14/2015 02:14:28;0040;PBS_Server;Svr;tyrone-cluster;Scheduler was sent the command new
07/14/2015 02:14:29;0008;PBS_Server;Job;NULL;on_job_exit valid pjob: 0x1dcb770 (substate=10)
07/14/2015 02:14:58;0040;PBS_Server;Svr;tyrone-cluster;Scheduler was sent the command new
07/14/2015 02:14:59;0008;PBS_Server;Job;NULL;on_job_exit valid pjob: 0x1dcb770 (substate=10)
07/14/2015 02:15:29;0008;PBS_Server;Job;NULL;on_job_exit valid pjob: 0x1dcb770 (substate=10)
07/14/2015 02:15:29;0040;PBS_Server;Svr;tyrone-cluster;Scheduler was sent the command new
07/14/2015 02:15:59;0008;PBS_Server;Job;NULL;on_job_exit valid pjob: 0x1dcb770 (substate=10)
07/14/2015 02:16:08;0040;PBS_Server;Svr;tyrone-cluster;Scheduler was sent the command new
07/14/2015 02:16:29;0002;PBS_Server;Svr;PBS_Server;Torque Server Version = 3.0.5, loglevel = 0
07/14/2015 02:16:29;0008;PBS_Server;Job;NULL;on_job_exit valid pjob: 0x1dcb770 (substate=10)
07/14/2015 02:16:31;0040;PBS_Server;Svr;tyrone-cluster;Scheduler was sent the command new
07/14/2015 02:16:59;0008;PBS_Server;Job;NULL;on_job_exit valid pjob: 0x1dcb770 (substate=10)
07/14/2015 02:17:00;0040;PBS_Server;Svr;tyrone-cluster;Scheduler was sent the command new
07/14/2015 02:17:29;0008;PBS_Server;Job;NULL;on_job_exit valid pjob: 0x1dcb770 (substate=10)
07/14/2015 02:17:38;0040;PBS_Server;Svr;tyrone-cluster;Scheduler was sent the command new
07/14/2015 02:17:59;0008;PBS_Server;Job;NULL;on_job_exit valid pjob: 0x1dcb770 (substate=10)
07/14/2015 02:18:01;0040;PBS_Server;Svr;tyrone-cluster;Scheduler was sent the command new
07/14/2015 02:18:29;0008;PBS_Server;Job;NULL;on_job_exit valid pjob: 0x1dcb770 (substate=10)
07/14/2015 02:18:30;0040;PBS_Server;Svr;tyrone-cluster;Scheduler was sent the command new
07/14/2015 02:18:59;0008;PBS_Server;Job;NULL;on_job_exit valid pjob: 0x1dcb770 (substate=10)
07/14/2015 02:19:08;0040;PBS_Server;Svr;tyrone-cluster;Scheduler was sent the command new
07/14/2015 02:19:29;0008;PBS_Server;Job;NULL;on_job_exit valid pjob: 0x1dcb770 (substate=10)
07/14/2015 02:19:31;0040;PBS_Server;Svr;tyrone-cluster;Scheduler was sent the command new
07/14/2015 02:19:59;0008;PBS_Server;Job;NULL;on_job_exit valid pjob: 0x1dcb770 (substate=10)
07/14/2015 02:20:00;0040;PBS_Server;Svr;tyrone-cluster;Scheduler was sent the command new
07/14/2015 02:20:29;0008;PBS_Server;Job;NULL;on_job_exit valid pjob: 0x1dcb770 (substate=10)
07/14/2015 02:20:39;0040;PBS_Server;Svr;tyrone-cluster;Scheduler was sent the command new
07/14/2015 02:20:59;0008;PBS_Server;Job;NULL;on_job_exit valid pjob: 0x1dcb770 (substate=10)
07/14/2015 02:20:59;0040;PBS_Server;Svr;tyrone-cluster;Scheduler was sent the command new
07/14/2015 02:21:29;0002;PBS_Server;Svr;PBS_Server;Torque Server Version = 3.0.5, loglevel = 0
07/14/2015 02:21:29;0008;PBS_Server;Job;NULL;on_job_exit valid pjob: 0x1dcb770 (substate=10)
07/14/2015 02:21:30;0040;PBS_Server;Svr;tyrone-cluster;Scheduler was sent the command new
07/14/2015 02:21:59;0008;PBS_Server;Job;NULL;on_job_exit valid pjob: 0x1dcb770 (substate=10)
07/14/2015 02:22:08;0040;PBS_Server;Svr;tyrone-cluster;Scheduler was sent the command new
07/14/2015 02:22:29;0008;PBS_Server;Job;NULL;on_job_exit valid pjob: 0x1dcb770 (substate=10)
07/14/2015 02:22:31;0040;PBS_Server;Svr;tyrone-cluster;Scheduler was sent the command new
07/14/2015 02:22:59;0008;PBS_Server;Job;NULL;on_job_exit valid pjob: 0x1dcb770 (substate=10)
07/14/2015 02:23:01;0040;PBS_Server;Svr;tyrone-cluster;Scheduler was sent the command new
07/14/2015 02:23:29;0008;PBS_Server;Job;NULL;on_job_exit valid pjob: 0x1dcb770 (substate=10)
07/14/2015 02:23:42;0040;PBS_Server;Svr;tyrone-cluster;Scheduler was sent the command new
07/14/2015 02:23:59;0008;PBS_Server;Job;NULL;on_job_exit valid pjob: 0x1dcb770 (substate=10)
07/14/2015 02:24:10;0040;PBS_Server;Svr;tyrone-cluster;Scheduler was sent the command new
07/14/2015 02:24:29;0008;PBS_Server;Job;NULL;on_job_exit valid pjob: 0x1dcb770 (substate=10)
07/14/2015 02:24:40;0040;PBS_Server;Svr;tyrone-cluster;Scheduler was sent the command new
07/14/2015 02:24:59;0008;PBS_Server;Job;NULL;on_job_exit valid pjob: 0x1dcb770 (substate=10)
07/14/2015 02:25:15;0040;PBS_Server;Svr;tyrone-cluster;Scheduler was sent the command new
07/14/2015 02:25:29;0008;PBS_Server;Job;NULL;on_job_exit valid pjob: 0x1dcb770 (substate=10)
07/14/2015 02:25:54;0040;PBS_Server;Svr;tyrone-cluster;Scheduler was sent the command new
07/14/2015 02:25:59;0008;PBS_Server;Job;NULL;on_job_exit valid pjob: 0x1dcb770 (substate=10)
07/14/2015 02:26:12;0040;PBS_Server;Svr;tyrone-cluster;Scheduler was sent the command new
07/14/2015 02:26:29;0002;PBS_Server;Svr;PBS_Server;Torque Server Version = 3.0.5, loglevel = 0
07/14/2015 02:26:29;0008;PBS_Server;Job;NULL;on_job_exit valid pjob: 0x1dcb770 (substate=10)
07/14/2015 02:26:45;0040;PBS_Server;Svr;tyrone-cluster;Scheduler was sent the command new
07/14/2015 02:26:59;0008;PBS_Server;Job;NULL;on_job_exit valid pjob: 0x1dcb770 (substate=10)
07/14/2015 02:27:27;0040;PBS_Server;Svr;tyrone-cluster;Scheduler was sent the command new
07/14/2015 02:27:29;0008;PBS_Server;Job;NULL;on_job_exit valid pjob: 0x1dcb770 (substate=10)
07/14/2015 02:27:55;0040;PBS_Server;Svr;tyrone-cluster;Scheduler was sent the command new
07/14/2015 02:27:59;0008;PBS_Server;Job;NULL;on_job_exit valid pjob: 0x1dcb770 (substate=10)
07/14/2015 02:28:25;0040;PBS_Server;Svr;tyrone-cluster;Scheduler was sent the command new
07/14/2015 02:28:29;0008;PBS_Server;Job;NULL;on_job_exit valid pjob: 0x1dcb770 (substate=10)
07/14/2015 02:28:59;0008;PBS_Server;Job;NULL;on_job_exit valid pjob: 0x1dcb770 (substate=10)
07/14/2015 02:28:59;0040;PBS_Server;Svr;tyrone-cluster;Scheduler was sent the command new
07/14/2015 02:29:29;0008;PBS_Server;Job;NULL;on_job_exit valid pjob: 0x1dcb770 (substate=10)
07/14/2015 02:29:29;0040;PBS_Server;Svr;tyrone-cluster;Scheduler was sent the command new
07/14/2015 02:29:59;0008;PBS_Server;Job;NULL;on_job_exit valid pjob: 0x1dcb770 (substate=10)
07/14/2015 02:29:59;0040;PBS_Server;Svr;tyrone-cluster;Scheduler was sent the command new
07/14/2015 02:30:29;0008;PBS_Server;Job;NULL;on_job_exit valid pjob: 0x1dcb770 (substate=10)
07/14/2015 02:30:30;0040;PBS_Server;Svr;tyrone-cluster;Scheduler was sent the command new
07/14/2015 02:30:59;0008;PBS_Server;Job;NULL;on_job_exit valid pjob: 0x1dcb770 (substate=10)
07/14/2015 02:31:08;0040;PBS_Server;Svr;tyrone-cluster;Scheduler was sent the command new
07/14/2015 02:31:29;0002;PBS_Server;Svr;PBS_Server;Torque Server Version = 3.0.5, loglevel = 0
07/14/2015 02:31:29;0008;PBS_Server;Job;NULL;on_job_exit valid pjob: 0x1dcb770 (substate=10)
07/14/2015 02:31:31;0040;PBS_Server;Svr;tyrone-cluster;Scheduler was sent the command new
07/14/2015 02:31:59;0008;PBS_Server;Job;NULL;on_job_exit valid pjob: 0x1dcb770 (substate=10)
07/14/2015 02:32:00;0040;PBS_Server;Svr;tyrone-cluster;Scheduler was sent the command new
07/14/2015 02:32:29;0008;PBS_Server;Job;NULL;on_job_exit valid pjob: 0x1dcb770 (substate=10)
07/14/2015 02:32:39;0040;PBS_Server;Svr;tyrone-cluster;Scheduler was sent the command new
07/14/2015 02:32:59;0008;PBS_Server;Job;NULL;on_job_exit valid pjob: 0x1dcb770 (substate=10)
07/14/2015 02:33:01;0040;PBS_Server;Svr;tyrone-cluster;Scheduler was sent the command new
07/14/2015 02:33:29;0008;PBS_Server;Job;NULL;on_job_exit valid pjob: 0x1dcb770 (substate=10)
07/14/2015 02:33:30;0040;PBS_Server;Svr;tyrone-cluster;Scheduler was sent the command new
07/14/2015 02:33:59;0008;PBS_Server;Job;NULL;on_job_exit valid pjob: 0x1dcb770 (substate=10)
07/14/2015 02:34:08;0040;PBS_Server;Svr;tyrone-cluster;Scheduler was sent the command new
07/14/2015 02:34:29;0008;PBS_Server;Job;NULL;on_job_exit valid pjob: 0x1dcb770 (substate=10)
07/14/2015 02:34:31;0040;PBS_Server;Svr;tyrone-cluster;Scheduler was sent the command new
07/14/2015 02:34:59;0008;PBS_Server;Job;NULL;on_job_exit valid pjob: 0x1dcb770 (substate=10)
07/14/2015 02:35:00;0040;PBS_Server;Svr;tyrone-cluster;Scheduler was sent the command new
07/14/2015 02:35:29;0008;PBS_Server;Job;NULL;on_job_exit valid pjob: 0x1dcb770 (substate=10)
07/14/2015 02:35:38;0040;PBS_Server;Svr;tyrone-cluster;Scheduler was sent the command new
07/14/2015 02:35:59;0008;PBS_Server;Job;NULL;on_job_exit valid pjob: 0x1dcb770 (substate=10)
07/14/2015 02:36:01;0040;PBS_Server;Svr;tyrone-cluster;Scheduler was sent the command new
07/14/2015 02:36:29;0002;PBS_Server;Svr;PBS_Server;Torque Server Version = 3.0.5, loglevel = 0
07/14/2015 02:36:29;0008;PBS_Server;Job;NULL;on_job_exit valid pjob: 0x1dcb770 (substate=10)
07/14/2015 02:36:30;0040;PBS_Server;Svr;tyrone-cluster;Scheduler was sent the command new
07/14/2015 02:36:59;0008;PBS_Server;Job;NULL;on_job_exit valid pjob: 0x1dcb770 (substate=10)
07/14/2015 02:37:08;0040;PBS_Server;Svr;tyrone-cluster;Scheduler was sent the command new
07/14/2015 02:37:29;0008;PBS_Server;Job;NULL;on_job_exit valid pjob: 0x1dcb770 (substate=10)
07/14/2015 02:37:31;0040;PBS_Server;Svr;tyrone-cluster;Scheduler was sent the command new
07/14/2015 02:37:59;0008;PBS_Server;Job;NULL;on_job_exit valid pjob: 0x1dcb770 (substate=10)
07/14/2015 02:38:00;0040;PBS_Server;Svr;tyrone-cluster;Scheduler was sent the command new
07/14/2015 02:38:29;0008;PBS_Server;Job;NULL;on_job_exit valid pjob: 0x1dcb770 (substate=10)
07/14/2015 02:38:39;0040;PBS_Server;Svr;tyrone-cluster;Scheduler was sent the command new
07/14/2015 02:38:59;0008;PBS_Server;Job;NULL;on_job_exit valid pjob: 0x1dcb770 (substate=10)
07/14/2015 02:38:59;0040;PBS_Server;Svr;tyrone-cluster;Scheduler was sent the command new
07/14/2015 02:39:29;0008;PBS_Server;Job;NULL;on_job_exit valid pjob: 0x1dcb770 (substate=10)
07/14/2015 02:39:30;0040;PBS_Server;Svr;tyrone-cluster;Scheduler was sent the command new
07/14/2015 02:39:59;0008;PBS_Server;Job;NULL;on_job_exit valid pjob: 0x1dcb770 (substate=10)
07/14/2015 02:40:08;0040;PBS_Server;Svr;tyrone-cluster;Scheduler was sent the command new
07/14/2015 02:40:29;0008;PBS_Server;Job;NULL;on_job_exit valid pjob: 0x1dcb770 (substate=10)
07/14/2015 02:40:31;0040;PBS_Server;Svr;tyrone-cluster;Scheduler was sent the command new
07/14/2015 02:40:59;0008;PBS_Server;Job;NULL;on_job_exit valid pjob: 0x1dcb770 (substate=10)
07/14/2015 02:41:00;0040;PBS_Server;Svr;tyrone-cluster;Scheduler was sent the command new
07/14/2015 02:41:29;0002;PBS_Server;Svr;PBS_Server;Torque Server Version = 3.0.5, loglevel = 0
07/14/2015 02:41:29;0008;PBS_Server;Job;NULL;on_job_exit valid pjob: 0x1dcb770 (substate=10)
07/14/2015 02:41:39;0040;PBS_Server;Svr;tyrone-cluster;Scheduler was sent the command new
07/14/2015 02:41:59;0008;PBS_Server;Job;NULL;on_job_exit valid pjob: 0x1dcb770 (substate=10)
07/14/2015 02:41:59;0040;PBS_Server;Svr;tyrone-cluster;Scheduler was sent the command new
07/14/2015 02:42:29;0008;PBS_Server;Job;NULL;on_job_exit valid pjob: 0x1dcb770 (substate=10)
07/14/2015 02:42:30;0040;PBS_Server;Svr;tyrone-cluster;Scheduler was sent the command new
07/14/2015 02:42:59;0008;PBS_Server;Job;NULL;on_job_exit valid pjob: 0x1dcb770 (substate=10)
07/14/2015 02:43:09;0040;PBS_Server;Svr;tyrone-cluster;Scheduler was sent the command new
07/14/2015 02:43:29;0008;PBS_Server;Job;NULL;on_job_exit valid pjob: 0x1dcb770 (substate=10)
07/14/2015 02:43:31;0040;PBS_Server;Svr;tyrone-cluster;Scheduler was sent the command new
07/14/2015 02:43:59;0008;PBS_Server;Job;NULL;on_job_exit valid pjob: 0x1dcb770 (substate=10)
07/14/2015 02:44:00;0040;PBS_Server;Svr;tyrone-cluster;Scheduler was sent the command new
07/14/2015 02:44:29;0008;PBS_Server;Job;NULL;on_job_exit valid pjob: 0x1dcb770 (substate=10)
07/14/2015 02:44:38;0040;PBS_Server;Svr;tyrone-cluster;Scheduler was sent the command new
07/14/2015 02:44:59;0008;PBS_Server;Job;NULL;on_job_exit valid pjob: 0x1dcb770 (substate=10)
07/14/2015 02:45:01;0040;PBS_Server;Svr;tyrone-cluster;Scheduler was sent the command new
07/14/2015 02:45:29;0008;PBS_Server;Job;NULL;on_job_exit valid pjob: 0x1dcb770 (substate=10)
07/14/2015 02:45:30;0040;PBS_Server;Svr;tyrone-cluster;Scheduler was sent the command new
07/14/2015 02:45:59;0008;PBS_Server;Job;NULL;on_job_exit valid pjob: 0x1dcb770 (substate=10)
07/14/2015 02:46:09;0040;PBS_Server;Svr;tyrone-cluster;Scheduler was sent the command new
07/14/2015 02:46:29;0002;PBS_Server;Svr;PBS_Server;Torque Server Version = 3.0.5, loglevel = 0
07/14/2015 02:46:29;0008;PBS_Server;Job;NULL;on_job_exit valid pjob: 0x1dcb770 (substate=10)
07/14/2015 02:46:31;0040;PBS_Server;Svr;tyrone-cluster;Scheduler was sent the command new
07/14/2015 02:46:59;0008;PBS_Server;Job;NULL;on_job_exit valid pjob: 0x1dcb770 (substate=10)
07/14/2015 02:47:00;0040;PBS_Server;Svr;tyrone-cluster;Scheduler was sent the command new
07/14/2015 02:47:29;0008;PBS_Server;Job;NULL;on_job_exit valid pjob: 0x1dcb770 (substate=10)
07/14/2015 02:47:40;0040;PBS_Server;Svr;tyrone-cluster;Scheduler was sent the command new
07/14/2015 02:47:59;0008;PBS_Server;Job;NULL;on_job_exit valid pjob: 0x1dcb770 (substate=10)
07/14/2015 02:47:59;0040;PBS_Server;Svr;tyrone-cluster;Scheduler was sent the command new
07/14/2015 02:48:29;0008;PBS_Server;Job;NULL;on_job_exit valid pjob: 0x1dcb770 (substate=10)
07/14/2015 02:48:30;0040;PBS_Server;Svr;tyrone-cluster;Scheduler was sent the command new
07/14/2015 02:48:59;0008;PBS_Server;Job;NULL;on_job_exit valid pjob: 0x1dcb770 (substate=10)
07/14/2015 02:49:09;0040;PBS_Server;Svr;tyrone-cluster;Scheduler was sent the command new
07/14/2015 02:49:29;0008;PBS_Server;Job;NULL;on_job_exit valid pjob: 0x1dcb770 (substate=10)
07/14/2015 02:49:31;0040;PBS_Server;Svr;tyrone-cluster;Scheduler was sent the command new
07/14/2015 02:49:59;0008;PBS_Server;Job;NULL;on_job_exit valid pjob: 0x1dcb770 (substate=10)
07/14/2015 02:50:00;0040;PBS_Server;Svr;tyrone-cluster;Scheduler was sent the command new
07/14/2015 02:50:29;0008;PBS_Server;Job;NULL;on_job_exit valid pjob: 0x1dcb770 (substate=10)
07/14/2015 02:50:39;0040;PBS_Server;Svr;tyrone-cluster;Scheduler was sent the command new
07/14/2015 02:50:59;0008;PBS_Server;Job;NULL;on_job_exit valid pjob: 0x1dcb770 (substate=10)
07/14/2015 02:51:01;0040;PBS_Server;Svr;tyrone-cluster;Scheduler was sent the command new
07/14/2015 02:51:29;0002;PBS_Server;Svr;PBS_Server;Torque Server Version = 3.0.5, loglevel = 0
07/14/2015 02:51:29;0008;PBS_Server;Job;NULL;on_job_exit valid pjob: 0x1dcb770 (substate=10)
07/14/2015 02:51:30;0040;PBS_Server;Svr;tyrone-cluster;Scheduler was sent the command new
07/14/2015 02:51:59;0008;PBS_Server;Job;NULL;on_job_exit valid pjob: 0x1dcb770 (substate=10)
07/14/2015 02:52:10;0040;PBS_Server;Svr;tyrone-cluster;Scheduler was sent the command new
07/14/2015 02:52:29;0008;PBS_Server;Job;NULL;on_job_exit valid pjob: 0x1dcb770 (substate=10)
07/14/2015 02:52:29;0040;PBS_Server;Svr;tyrone-cluster;Scheduler was sent the command new
07/14/2015 02:52:59;0008;PBS_Server;Job;NULL;on_job_exit valid pjob: 0x1dcb770 (substate=10)
07/14/2015 02:53:00;0040;PBS_Server;Svr;tyrone-cluster;Scheduler was sent the command new
07/14/2015 02:53:29;0008;PBS_Server;Job;NULL;on_job_exit valid pjob: 0x1dcb770 (substate=10)
07/14/2015 02:53:39;0040;PBS_Server;Svr;tyrone-cluster;Scheduler was sent the command new
07/14/2015 02:53:59;0008;PBS_Server;Job;NULL;on_job_exit valid pjob: 0x1dcb770 (substate=10)
07/14/2015 02:54:01;0040;PBS_Server;Svr;tyrone-cluster;Scheduler was sent the command new
07/14/2015 02:54:29;0008;PBS_Server;Job;NULL;on_job_exit valid pjob: 0x1dcb770 (substate=10)
07/14/2015 02:54:30;0040;PBS_Server;Svr;tyrone-cluster;Scheduler was sent the command new
07/14/2015 02:54:59;0008;PBS_Server;Job;NULL;on_job_exit valid pjob: 0x1dcb770 (substate=10)
07/14/2015 02:55:10;0040;PBS_Server;Svr;tyrone-cluster;Scheduler was sent the command new
07/14/2015 02:55:29;0008;PBS_Server;Job;NULL;on_job_exit valid pjob: 0x1dcb770 (substate=10)
07/14/2015 02:55:31;0040;PBS_Server;Svr;tyrone-cluster;Scheduler was sent the command new
07/14/2015 02:55:59;0008;PBS_Server;Job;NULL;on_job_exit valid pjob: 0x1dcb770 (substate=10)
07/14/2015 02:56:00;0040;PBS_Server;Svr;tyrone-cluster;Scheduler was sent the command new
07/14/2015 02:56:30;0002;PBS_Server;Svr;PBS_Server;Torque Server Version = 3.0.5, loglevel = 0
07/14/2015 02:56:30;0008;PBS_Server;Job;NULL;on_job_exit valid pjob: 0x1dcb770 (substate=10)
07/14/2015 02:56:39;0040;PBS_Server;Svr;tyrone-cluster;Scheduler was sent the command new
07/14/2015 02:56:59;0008;PBS_Server;Job;NULL;on_job_exit valid pjob: 0x1dcb770 (substate=10)
07/14/2015 02:57:01;0040;PBS_Server;Svr;tyrone-cluster;Scheduler was sent the command new
07/14/2015 02:57:29;0008;PBS_Server;Job;NULL;on_job_exit valid pjob: 0x1dcb770 (substate=10)
07/14/2015 02:57:30;0040;PBS_Server;Svr;tyrone-cluster;Scheduler was sent the command new
07/14/2015 02:57:59;0008;PBS_Server;Job;NULL;on_job_exit valid pjob: 0x1dcb770 (substate=10)
07/14/2015 02:58:10;0040;PBS_Server;Svr;tyrone-cluster;Scheduler was sent the command new
07/14/2015 02:58:29;0008;PBS_Server;Job;NULL;on_job_exit valid pjob: 0x1dcb770 (substate=10)
07/14/2015 02:58:31;0040;PBS_Server;Svr;tyrone-cluster;Scheduler was sent the command new
07/14/2015 02:58:59;0008;PBS_Server;Job;NULL;on_job_exit valid pjob: 0x1dcb770 (substate=10)
07/14/2015 02:59:00;0040;PBS_Server;Svr;tyrone-cluster;Scheduler was sent the command new
07/14/2015 02:59:29;0008;PBS_Server;Job;NULL;on_job_exit valid pjob: 0x1dcb770 (substate=10)
07/14/2015 02:59:39;0040;PBS_Server;Svr;tyrone-cluster;Scheduler was sent the command new
07/14/2015 02:59:59;0008;PBS_Server;Job;NULL;on_job_exit valid pjob: 0x1dcb770 (substate=10)
07/14/2015 03:00:01;0040;PBS_Server;Svr;tyrone-cluster;Scheduler was sent the command new
07/14/2015 03:00:29;0008;PBS_Server;Job;NULL;on_job_exit valid pjob: 0x1dcb770 (substate=10)
07/14/2015 03:00:30;0040;PBS_Server;Svr;tyrone-cluster;Scheduler was sent the command new
07/14/2015 03:00:59;0008;PBS_Server;Job;NULL;on_job_exit valid pjob: 0x1dcb770 (substate=10)
07/14/2015 03:01:09;0040;PBS_Server;Svr;tyrone-cluster;Scheduler was sent the command new
07/14/2015 03:01:29;0002;PBS_Server;Svr;PBS_Server;Torque Server Version = 3.0.5, loglevel = 0
07/14/2015 03:01:29;0008;PBS_Server;Job;NULL;on_job_exit valid pjob: 0x1dcb770 (substate=10)
07/14/2015 03:01:31;0040;PBS_Server;Svr;tyrone-cluster;Scheduler was sent the command new
07/14/2015 03:01:59;0008;PBS_Server;Job;NULL;on_job_exit valid pjob: 0x1dcb770 (substate=10)
07/14/2015 03:02:00;0040;PBS_Server;Svr;tyrone-cluster;Scheduler was sent the command new
07/14/2015 03:02:29;0008;PBS_Server;Job;NULL;on_job_exit valid pjob: 0x1dcb770 (substate=10)
07/14/2015 03:02:39;0040;PBS_Server;Svr;tyrone-cluster;Scheduler was sent the command new
07/14/2015 03:02:59;0008;PBS_Server;Job;NULL;on_job_exit valid pjob: 0x1dcb770 (substate=10)
07/14/2015 03:03:01;0040;PBS_Server;Svr;tyrone-cluster;Scheduler was sent the command new
07/14/2015 03:03:29;0008;PBS_Server;Job;NULL;on_job_exit valid pjob: 0x1dcb770 (substate=10)
07/14/2015 03:03:30;0040;PBS_Server;Svr;tyrone-cluster;Scheduler was sent the command new
07/14/2015 03:03:59;0008;PBS_Server;Job;NULL;on_job_exit valid pjob: 0x1dcb770 (substate=10)
07/14/2015 03:04:10;0040;PBS_Server;Svr;tyrone-cluster;Scheduler was sent the command new
07/14/2015 03:04:29;0008;PBS_Server;Job;NULL;on_job_exit valid pjob: 0x1dcb770 (substate=10)
07/14/2015 03:04:31;0040;PBS_Server;Svr;tyrone-cluster;Scheduler was sent the command new
07/14/2015 03:04:59;0008;PBS_Server;Job;NULL;on_job_exit valid pjob: 0x1dcb770 (substate=10)
07/14/2015 03:05:00;0040;PBS_Server;Svr;tyrone-cluster;Scheduler was sent the command new
07/14/2015 03:05:29;0008;PBS_Server;Job;NULL;on_job_exit valid pjob: 0x1dcb770 (substate=10)
07/14/2015 03:05:40;0040;PBS_Server;Svr;tyrone-cluster;Scheduler was sent the command new
07/14/2015 03:05:59;0008;PBS_Server;Job;NULL;on_job_exit valid pjob: 0x1dcb770 (substate=10)
07/14/2015 03:05:59;0040;PBS_Server;Svr;tyrone-cluster;Scheduler was sent the command new
07/14/2015 03:06:29;0002;PBS_Server;Svr;PBS_Server;Torque Server Version = 3.0.5, loglevel = 0
07/14/2015 03:06:29;0008;PBS_Server;Job;NULL;on_job_exit valid pjob: 0x1dcb770 (substate=10)
07/14/2015 03:06:30;0040;PBS_Server;Svr;tyrone-cluster;Scheduler was sent the command new
07/14/2015 03:06:59;0008;PBS_Server;Job;NULL;on_job_exit valid pjob: 0x1dcb770 (substate=10)
07/14/2015 03:07:10;0040;PBS_Server;Svr;tyrone-cluster;Scheduler was sent the command new
07/14/2015 03:07:29;0008;PBS_Server;Job;NULL;on_job_exit valid pjob: 0x1dcb770 (substate=10)
07/14/2015 03:07:29;0040;PBS_Server;Svr;tyrone-cluster;Scheduler was sent the command new
07/14/2015 03:07:59;0008;PBS_Server;Job;NULL;on_job_exit valid pjob: 0x1dcb770 (substate=10)
07/14/2015 03:08:00;0040;PBS_Server;Svr;tyrone-cluster;Scheduler was sent the command new
07/14/2015 03:08:29;0008;PBS_Server;Job;NULL;on_job_exit valid pjob: 0x1dcb770 (substate=10)
07/14/2015 03:08:40;0040;PBS_Server;Svr;tyrone-cluster;Scheduler was sent the command new
07/14/2015 03:08:59;0008;PBS_Server;Job;NULL;on_job_exit valid pjob: 0x1dcb770 (substate=10)
07/14/2015 03:09:01;0040;PBS_Server;Svr;tyrone-cluster;Scheduler was sent the command new
07/14/2015 03:09:29;0008;PBS_Server;Job;NULL;on_job_exit valid pjob: 0x1dcb770 (substate=10)
07/14/2015 03:09:30;0040;PBS_Server;Svr;tyrone-cluster;Scheduler was sent the command new
07/14/2015 03:09:59;0008;PBS_Server;Job;NULL;on_job_exit valid pjob: 0x1dcb770 (substate=10)
07/14/2015 03:10:09;0040;PBS_Server;Svr;tyrone-cluster;Scheduler was sent the command new
07/14/2015 03:10:29;0008;PBS_Server;Job;NULL;on_job_exit valid pjob: 0x1dcb770 (substate=10)
07/14/2015 03:10:29;0040;PBS_Server;Svr;tyrone-cluster;Scheduler was sent the command new
07/14/2015 03:10:59;0008;PBS_Server;Job;NULL;on_job_exit valid pjob: 0x1dcb770 (substate=10)
07/14/2015 03:11:35;0002;PBS_Server;Svr;PBS_Server;Torque Server Version = 3.0.5, loglevel = 0
07/14/2015 03:11:35;0008;PBS_Server;Job;NULL;on_job_exit valid pjob: 0x1dcb770 (substate=10)
07/14/2015 03:11:35;0040;PBS_Server;Svr;tyrone-cluster;Scheduler was sent the command new
07/14/2015 03:12:05;0008;PBS_Server;Job;NULL;on_job_exit valid pjob: 0x1dcb770 (substate=10)
07/14/2015 03:12:07;0040;PBS_Server;Svr;tyrone-cluster;Scheduler was sent the command new
07/14/2015 03:12:35;0008;PBS_Server;Job;NULL;on_job_exit valid pjob: 0x1dcb770 (substate=10)
07/14/2015 03:12:36;0040;PBS_Server;Svr;tyrone-cluster;Scheduler was sent the command new
07/14/2015 03:13:05;0008;PBS_Server;Job;NULL;on_job_exit valid pjob: 0x1dcb770 (substate=10)
07/14/2015 03:13:06;0040;PBS_Server;Svr;tyrone-cluster;Scheduler was sent the command new
07/14/2015 03:13:35;0008;PBS_Server;Job;NULL;on_job_exit valid pjob: 0x1dcb770 (substate=10)
07/14/2015 03:13:37;0040;PBS_Server;Svr;tyrone-cluster;Scheduler was sent the command new
07/14/2015 03:14:05;0008;PBS_Server;Job;NULL;on_job_exit valid pjob: 0x1dcb770 (substate=10)
07/14/2015 03:14:05;0040;PBS_Server;Svr;tyrone-cluster;Scheduler was sent the command new
07/14/2015 03:14:35;0008;PBS_Server;Job;NULL;on_job_exit valid pjob: 0x1dcb770 (substate=10)
07/14/2015 03:14:36;0040;PBS_Server;Svr;tyrone-cluster;Scheduler was sent the command new
07/14/2015 03:15:05;0008;PBS_Server;Job;NULL;on_job_exit valid pjob: 0x1dcb770 (substate=10)
07/14/2015 03:15:07;0040;PBS_Server;Svr;tyrone-cluster;Scheduler was sent the command new
07/14/2015 03:15:35;0008;PBS_Server;Job;NULL;on_job_exit valid pjob: 0x1dcb770 (substate=10)
07/14/2015 03:15:35;0040;PBS_Server;Svr;tyrone-cluster;Scheduler was sent the command new
07/14/2015 03:16:05;0008;PBS_Server;Job;NULL;on_job_exit valid pjob: 0x1dcb770 (substate=10)
07/14/2015 03:16:06;0040;PBS_Server;Svr;tyrone-cluster;Scheduler was sent the command new
07/14/2015 03:16:35;0002;PBS_Server;Svr;PBS_Server;Torque Server Version = 3.0.5, loglevel = 0
07/14/2015 03:16:35;0008;PBS_Server;Job;NULL;on_job_exit valid pjob: 0x1dcb770 (substate=10)
07/14/2015 03:16:37;0040;PBS_Server;Svr;tyrone-cluster;Scheduler was sent the command new
07/14/2015 03:17:05;0008;PBS_Server;Job;NULL;on_job_exit valid pjob: 0x1dcb770 (substate=10)
07/14/2015 03:17:05;0040;PBS_Server;Svr;tyrone-cluster;Scheduler was sent the command new
07/14/2015 03:17:35;0008;PBS_Server;Job;NULL;on_job_exit valid pjob: 0x1dcb770 (substate=10)
07/14/2015 03:17:36;0040;PBS_Server;Svr;tyrone-cluster;Scheduler was sent the command new
07/14/2015 03:18:05;0008;PBS_Server;Job;NULL;on_job_exit valid pjob: 0x1dcb770 (substate=10)
07/14/2015 03:18:08;0040;PBS_Server;Svr;tyrone-cluster;Scheduler was sent the command new
07/14/2015 03:18:35;0008;PBS_Server;Job;NULL;on_job_exit valid pjob: 0x1dcb770 (substate=10)
07/14/2015 03:18:35;0040;PBS_Server;Svr;tyrone-cluster;Scheduler was sent the command new
07/14/2015 03:19:05;0008;PBS_Server;Job;NULL;on_job_exit valid pjob: 0x1dcb770 (substate=10)
07/14/2015 03:19:06;0040;PBS_Server;Svr;tyrone-cluster;Scheduler was sent the command new
07/14/2015 03:19:35;0008;PBS_Server;Job;NULL;on_job_exit valid pjob: 0x1dcb770 (substate=10)
07/14/2015 03:19:37;0040;PBS_Server;Svr;tyrone-cluster;Scheduler was sent the command new
07/14/2015 03:20:05;0008;PBS_Server;Job;NULL;on_job_exit valid pjob: 0x1dcb770 (substate=10)
07/14/2015 03:20:05;0040;PBS_Server;Svr;tyrone-cluster;Scheduler was sent the command new
07/14/2015 03:20:35;0008;PBS_Server;Job;NULL;on_job_exit valid pjob: 0x1dcb770 (substate=10)
07/14/2015 03:20:36;0040;PBS_Server;Svr;tyrone-cluster;Scheduler was sent the command new
07/14/2015 03:21:05;0008;PBS_Server;Job;NULL;on_job_exit valid pjob: 0x1dcb770 (substate=10)
07/14/2015 03:21:07;0040;PBS_Server;Svr;tyrone-cluster;Scheduler was sent the command new
07/14/2015 03:21:35;0002;PBS_Server;Svr;PBS_Server;Torque Server Version = 3.0.5, loglevel = 0
07/14/2015 03:21:35;0008;PBS_Server;Job;NULL;on_job_exit valid pjob: 0x1dcb770 (substate=10)
07/14/2015 03:21:35;0040;PBS_Server;Svr;tyrone-cluster;Scheduler was sent the command new
07/14/2015 03:22:05;0008;PBS_Server;Job;NULL;on_job_exit valid pjob: 0x1dcb770 (substate=10)
07/14/2015 03:22:06;0040;PBS_Server;Svr;tyrone-cluster;Scheduler was sent the command new
07/14/2015 03:22:35;0008;PBS_Server;Job;NULL;on_job_exit valid pjob: 0x1dcb770 (substate=10)
07/14/2015 03:22:37;0040;PBS_Server;Svr;tyrone-cluster;Scheduler was sent the command new
07/14/2015 03:23:05;0008;PBS_Server;Job;NULL;on_job_exit valid pjob: 0x1dcb770 (substate=10)
07/14/2015 03:23:05;0040;PBS_Server;Svr;tyrone-cluster;Scheduler was sent the command new
07/14/2015 03:23:35;0008;PBS_Server;Job;NULL;on_job_exit valid pjob: 0x1dcb770 (substate=10)
07/14/2015 03:23:36;0040;PBS_Server;Svr;tyrone-cluster;Scheduler was sent the command new
07/14/2015 03:24:05;0008;PBS_Server;Job;NULL;on_job_exit valid pjob: 0x1dcb770 (substate=10)
07/14/2015 03:24:07;0040;PBS_Server;Svr;tyrone-cluster;Scheduler was sent the command new
07/14/2015 03:24:35;0008;PBS_Server;Job;NULL;on_job_exit valid pjob: 0x1dcb770 (substate=10)
07/14/2015 03:24:35;0040;PBS_Server;Svr;tyrone-cluster;Scheduler was sent the command new
07/14/2015 03:25:05;0008;PBS_Server;Job;NULL;on_job_exit valid pjob: 0x1dcb770 (substate=10)
07/14/2015 03:25:06;0040;PBS_Server;Svr;tyrone-cluster;Scheduler was sent the command new
07/14/2015 03:25:35;0008;PBS_Server;Job;NULL;on_job_exit valid pjob: 0x1dcb770 (substate=10)
07/14/2015 03:25:37;0040;PBS_Server;Svr;tyrone-cluster;Scheduler was sent the command new
07/14/2015 03:26:05;0008;PBS_Server;Job;NULL;on_job_exit valid pjob: 0x1dcb770 (substate=10)
07/14/2015 03:26:05;0040;PBS_Server;Svr;tyrone-cluster;Scheduler was sent the command new
07/14/2015 03:26:35;0002;PBS_Server;Svr;PBS_Server;Torque Server Version = 3.0.5, loglevel = 0
07/14/2015 03:26:35;0008;PBS_Server;Job;NULL;on_job_exit valid pjob: 0x1dcb770 (substate=10)
07/14/2015 03:26:36;0040;PBS_Server;Svr;tyrone-cluster;Scheduler was sent the command new
07/14/2015 03:27:05;0008;PBS_Server;Job;NULL;on_job_exit valid pjob: 0x1dcb770 (substate=10)
07/14/2015 03:27:07;0040;PBS_Server;Svr;tyrone-cluster;Scheduler was sent the command new
07/14/2015 03:27:35;0008;PBS_Server;Job;NULL;on_job_exit valid pjob: 0x1dcb770 (substate=10)
07/14/2015 03:27:35;0040;PBS_Server;Svr;tyrone-cluster;Scheduler was sent the command new
07/14/2015 03:28:05;0008;PBS_Server;Job;NULL;on_job_exit valid pjob: 0x1dcb770 (substate=10)
07/14/2015 03:28:06;0040;PBS_Server;Svr;tyrone-cluster;Scheduler was sent the command new
07/14/2015 03:28:35;0008;PBS_Server;Job;NULL;on_job_exit valid pjob: 0x1dcb770 (substate=10)
07/14/2015 03:28:38;0040;PBS_Server;Svr;tyrone-cluster;Scheduler was sent the command new
07/14/2015 03:29:05;0008;PBS_Server;Job;NULL;on_job_exit valid pjob: 0x1dcb770 (substate=10)
07/14/2015 03:29:06;0040;PBS_Server;Svr;tyrone-cluster;Scheduler was sent the command new
07/14/2015 03:29:35;0008;PBS_Server;Job;NULL;on_job_exit valid pjob: 0x1dcb770 (substate=10)
07/14/2015 03:29:36;0040;PBS_Server;Svr;tyrone-cluster;Scheduler was sent the command new
07/14/2015 03:30:05;0008;PBS_Server;Job;NULL;on_job_exit valid pjob: 0x1dcb770 (substate=10)
07/14/2015 03:30:07;0040;PBS_Server;Svr;tyrone-cluster;Scheduler was sent the command new
07/14/2015 03:30:35;0008;PBS_Server;Job;NULL;on_job_exit valid pjob: 0x1dcb770 (substate=10)
07/14/2015 03:30:35;0040;PBS_Server;Svr;tyrone-cluster;Scheduler was sent the command new
07/14/2015 03:31:05;0008;PBS_Server;Job;NULL;on_job_exit valid pjob: 0x1dcb770 (substate=10)
07/14/2015 03:31:06;0040;PBS_Server;Svr;tyrone-cluster;Scheduler was sent the command new
07/14/2015 03:31:36;0002;PBS_Server;Svr;PBS_Server;Torque Server Version = 3.0.5, loglevel = 0
07/14/2015 03:31:36;0008;PBS_Server;Job;NULL;on_job_exit valid pjob: 0x1dcb770 (substate=10)
07/14/2015 03:31:38;0040;PBS_Server;Svr;tyrone-cluster;Scheduler was sent the command new
07/14/2015 03:32:06;0008;PBS_Server;Job;NULL;on_job_exit valid pjob: 0x1dcb770 (substate=10)
07/14/2015 03:32:07;0040;PBS_Server;Svr;tyrone-cluster;Scheduler was sent the command new
07/14/2015 03:32:36;0008;PBS_Server;Job;NULL;on_job_exit valid pjob: 0x1dcb770 (substate=10)
07/14/2015 03:32:37;0040;PBS_Server;Svr;tyrone-cluster;Scheduler was sent the command new
07/14/2015 03:33:06;0008;PBS_Server;Job;NULL;on_job_exit valid pjob: 0x1dcb770 (substate=10)
07/14/2015 03:33:07;0040;PBS_Server;Svr;tyrone-cluster;Scheduler was sent the command new
07/14/2015 03:33:36;0008;PBS_Server;Job;NULL;on_job_exit valid pjob: 0x1dcb770 (substate=10)
07/14/2015 03:33:37;0040;PBS_Server;Svr;tyrone-cluster;Scheduler was sent the command new
07/14/2015 03:34:06;0008;PBS_Server;Job;NULL;on_job_exit valid pjob: 0x1dcb770 (substate=10)
07/14/2015 03:34:07;0040;PBS_Server;Svr;tyrone-cluster;Scheduler was sent the command new
07/14/2015 03:34:36;0008;PBS_Server;Job;NULL;on_job_exit valid pjob: 0x1dcb770 (substate=10)
07/14/2015 03:34:37;0040;PBS_Server;Svr;tyrone-cluster;Scheduler was sent the command new
07/14/2015 03:35:06;0008;PBS_Server;Job;NULL;on_job_exit valid pjob: 0x1dcb770 (substate=10)
07/14/2015 03:35:07;0040;PBS_Server;Svr;tyrone-cluster;Scheduler was sent the command new
07/14/2015 03:35:36;0008;PBS_Server;Job;NULL;on_job_exit valid pjob: 0x1dcb770 (substate=10)
07/14/2015 03:35:37;0040;PBS_Server;Svr;tyrone-cluster;Scheduler was sent the command new
07/14/2015 03:36:06;0008;PBS_Server;Job;NULL;on_job_exit valid pjob: 0x1dcb770 (substate=10)
07/14/2015 03:36:07;0040;PBS_Server;Svr;tyrone-cluster;Scheduler was sent the command new
07/14/2015 03:36:36;0002;PBS_Server;Svr;PBS_Server;Torque Server Version = 3.0.5, loglevel = 0
07/14/2015 03:36:36;0008;PBS_Server;Job;NULL;on_job_exit valid pjob: 0x1dcb770 (substate=10)
07/14/2015 03:36:37;0040;PBS_Server;Svr;tyrone-cluster;Scheduler was sent the command new
07/14/2015 03:37:06;0008;PBS_Server;Job;NULL;on_job_exit valid pjob: 0x1dcb770 (substate=10)
07/14/2015 03:37:07;0040;PBS_Server;Svr;tyrone-cluster;Scheduler was sent the command new
07/14/2015 03:37:36;0008;PBS_Server;Job;NULL;on_job_exit valid pjob: 0x1dcb770 (substate=10)
07/14/2015 03:37:37;0040;PBS_Server;Svr;tyrone-cluster;Scheduler was sent the command new
07/14/2015 03:38:06;0008;PBS_Server;Job;NULL;on_job_exit valid pjob: 0x1dcb770 (substate=10)
07/14/2015 03:38:06;0040;PBS_Server;Svr;tyrone-cluster;Scheduler was sent the command new
07/14/2015 03:38:36;0008;PBS_Server;Job;NULL;on_job_exit valid pjob: 0x1dcb770 (substate=10)
07/14/2015 03:38:37;0040;PBS_Server;Svr;tyrone-cluster;Scheduler was sent the command new
07/14/2015 03:39:06;0008;PBS_Server;Job;NULL;on_job_exit valid pjob: 0x1dcb770 (substate=10)
07/14/2015 03:39:08;0040;PBS_Server;Svr;tyrone-cluster;Scheduler was sent the command new
07/14/2015 03:39:36;0008;PBS_Server;Job;NULL;on_job_exit valid pjob: 0x1dcb770 (substate=10)
07/14/2015 03:39:37;0040;PBS_Server;Svr;tyrone-cluster;Scheduler was sent the command new
07/14/2015 03:40:06;0008;PBS_Server;Job;NULL;on_job_exit valid pjob: 0x1dcb770 (substate=10)
07/14/2015 03:40:07;0040;PBS_Server;Svr;tyrone-cluster;Scheduler was sent the command new
07/14/2015 03:40:36;0008;PBS_Server;Job;NULL;on_job_exit valid pjob: 0x1dcb770 (substate=10)
07/14/2015 03:40:37;0040;PBS_Server;Svr;tyrone-cluster;Scheduler was sent the command new
07/14/2015 03:41:06;0008;PBS_Server;Job;NULL;on_job_exit valid pjob: 0x1dcb770 (substate=10)
07/14/2015 03:41:07;0040;PBS_Server;Svr;tyrone-cluster;Scheduler was sent the command new
07/14/2015 03:41:36;0002;PBS_Server;Svr;PBS_Server;Torque Server Version = 3.0.5, loglevel = 0
07/14/2015 03:41:36;0008;PBS_Server;Job;NULL;on_job_exit valid pjob: 0x1dcb770 (substate=10)
07/14/2015 03:41:37;0040;PBS_Server;Svr;tyrone-cluster;Scheduler was sent the command new
07/14/2015 03:42:06;0008;PBS_Server;Job;NULL;on_job_exit valid pjob: 0x1dcb770 (substate=10)
07/14/2015 03:42:07;0040;PBS_Server;Svr;tyrone-cluster;Scheduler was sent the command new
07/14/2015 03:42:36;0008;PBS_Server;Job;NULL;on_job_exit valid pjob: 0x1dcb770 (substate=10)
07/14/2015 03:42:36;0040;PBS_Server;Svr;tyrone-cluster;Scheduler was sent the command new
07/14/2015 03:43:07;0008;PBS_Server;Job;NULL;on_job_exit valid pjob: 0x1dcb770 (substate=10)
07/14/2015 03:43:08;0040;PBS_Server;Svr;tyrone-cluster;Scheduler was sent the command new
07/14/2015 03:43:37;0008;PBS_Server;Job;NULL;on_job_exit valid pjob: 0x1dcb770 (substate=10)
07/14/2015 03:43:37;0040;PBS_Server;Svr;tyrone-cluster;Scheduler was sent the command new
07/14/2015 03:44:07;0008;PBS_Server;Job;NULL;on_job_exit valid pjob: 0x1dcb770 (substate=10)
07/14/2015 03:44:08;0040;PBS_Server;Svr;tyrone-cluster;Scheduler was sent the command new
07/14/2015 03:44:37;0008;PBS_Server;Job;NULL;on_job_exit valid pjob: 0x1dcb770 (substate=10)
07/14/2015 03:44:38;0040;PBS_Server;Svr;tyrone-cluster;Scheduler was sent the command new
07/14/2015 03:45:07;0008;PBS_Server;Job;NULL;on_job_exit valid pjob: 0x1dcb770 (substate=10)
07/14/2015 03:45:09;0040;PBS_Server;Svr;tyrone-cluster;Scheduler was sent the command new
07/14/2015 03:45:37;0008;PBS_Server;Job;NULL;on_job_exit valid pjob: 0x1dcb770 (substate=10)
07/14/2015 03:45:37;0040;PBS_Server;Svr;tyrone-cluster;Scheduler was sent the command new
07/14/2015 03:46:07;0008;PBS_Server;Job;NULL;on_job_exit valid pjob: 0x1dcb770 (substate=10)
07/14/2015 03:46:08;0040;PBS_Server;Svr;tyrone-cluster;Scheduler was sent the command new
07/14/2015 03:46:36;0002;PBS_Server;Svr;PBS_Server;Torque Server Version = 3.0.5, loglevel = 0
07/14/2015 03:46:37;0008;PBS_Server;Job;NULL;on_job_exit valid pjob: 0x1dcb770 (substate=10)
07/14/2015 03:46:38;0040;PBS_Server;Svr;tyrone-cluster;Scheduler was sent the command new
07/14/2015 03:47:07;0008;PBS_Server;Job;NULL;on_job_exit valid pjob: 0x1dcb770 (substate=10)
07/14/2015 03:47:08;0040;PBS_Server;Svr;tyrone-cluster;Scheduler was sent the command new
07/14/2015 03:47:37;0008;PBS_Server;Job;NULL;on_job_exit valid pjob: 0x1dcb770 (substate=10)
07/14/2015 03:47:38;0040;PBS_Server;Svr;tyrone-cluster;Scheduler was sent the command new
07/14/2015 03:48:07;0008;PBS_Server;Job;NULL;on_job_exit valid pjob: 0x1dcb770 (substate=10)
07/14/2015 03:48:09;0040;PBS_Server;Svr;tyrone-cluster;Scheduler was sent the command new
07/14/2015 03:48:37;0008;PBS_Server;Job;NULL;on_job_exit valid pjob: 0x1dcb770 (substate=10)
07/14/2015 03:48:38;0040;PBS_Server;Svr;tyrone-cluster;Scheduler was sent the command new
07/14/2015 03:49:07;0008;PBS_Server;Job;NULL;on_job_exit valid pjob: 0x1dcb770 (substate=10)
07/14/2015 03:49:08;0040;PBS_Server;Svr;tyrone-cluster;Scheduler was sent the command new
07/14/2015 03:49:37;0008;PBS_Server;Job;NULL;on_job_exit valid pjob: 0x1dcb770 (substate=10)
07/14/2015 03:49:39;0040;PBS_Server;Svr;tyrone-cluster;Scheduler was sent the command new
07/14/2015 03:50:07;0008;PBS_Server;Job;NULL;on_job_exit valid pjob: 0x1dcb770 (substate=10)
07/14/2015 03:50:07;0040;PBS_Server;Svr;tyrone-cluster;Scheduler was sent the command new
07/14/2015 03:50:37;0008;PBS_Server;Job;NULL;on_job_exit valid pjob: 0x1dcb770 (substate=10)
07/14/2015 03:50:38;0040;PBS_Server;Svr;tyrone-cluster;Scheduler was sent the command new
07/14/2015 03:51:07;0008;PBS_Server;Job;NULL;on_job_exit valid pjob: 0x1dcb770 (substate=10)
07/14/2015 03:51:08;0040;PBS_Server;Svr;tyrone-cluster;Scheduler was sent the command new
07/14/2015 03:51:36;0002;PBS_Server;Svr;PBS_Server;Torque Server Version = 3.0.5, loglevel = 0
07/14/2015 03:51:37;0008;PBS_Server;Job;NULL;on_job_exit valid pjob: 0x1dcb770 (substate=10)
07/14/2015 03:51:38;0040;PBS_Server;Svr;tyrone-cluster;Scheduler was sent the command new
07/14/2015 03:52:07;0008;PBS_Server;Job;NULL;on_job_exit valid pjob: 0x1dcb770 (substate=10)
07/14/2015 03:52:08;0040;PBS_Server;Svr;tyrone-cluster;Scheduler was sent the command new
07/14/2015 03:52:37;0008;PBS_Server;Job;NULL;on_job_exit valid pjob: 0x1dcb770 (substate=10)
07/14/2015 03:52:37;0040;PBS_Server;Svr;tyrone-cluster;Scheduler was sent the command new
07/14/2015 03:53:07;0008;PBS_Server;Job;NULL;on_job_exit valid pjob: 0x1dcb770 (substate=10)
07/14/2015 03:53:08;0040;PBS_Server;Svr;tyrone-cluster;Scheduler was sent the command new
07/14/2015 03:53:37;0008;PBS_Server;Job;NULL;on_job_exit valid pjob: 0x1dcb770 (substate=10)
07/14/2015 03:53:38;0040;PBS_Server;Svr;tyrone-cluster;Scheduler was sent the command new
07/14/2015 03:54:07;0008;PBS_Server;Job;NULL;on_job_exit valid pjob: 0x1dcb770 (substate=10)
07/14/2015 03:54:07;0040;PBS_Server;Svr;tyrone-cluster;Scheduler was sent the command new
07/14/2015 03:54:37;0008;PBS_Server;Job;NULL;on_job_exit valid pjob: 0x1dcb770 (substate=10)
07/14/2015 03:54:37;0040;PBS_Server;Svr;tyrone-cluster;Scheduler was sent the command new
07/14/2015 03:55:07;0008;PBS_Server;Job;NULL;on_job_exit valid pjob: 0x1dcb770 (substate=10)
07/14/2015 03:55:08;0040;PBS_Server;Svr;tyrone-cluster;Scheduler was sent the command new
07/14/2015 03:55:37;0008;PBS_Server;Job;NULL;on_job_exit valid pjob: 0x1dcb770 (substate=10)
07/14/2015 03:55:39;0040;PBS_Server;Svr;tyrone-cluster;Scheduler was sent the command new
07/14/2015 03:56:07;0008;PBS_Server;Job;NULL;on_job_exit valid pjob: 0x1dcb770 (substate=10)
07/14/2015 03:56:08;0040;PBS_Server;Svr;tyrone-cluster;Scheduler was sent the command new
07/14/2015 03:56:36;0002;PBS_Server;Svr;PBS_Server;Torque Server Version = 3.0.5, loglevel = 0
07/14/2015 03:56:37;0008;PBS_Server;Job;NULL;on_job_exit valid pjob: 0x1dcb770 (substate=10)
07/14/2015 03:56:38;0040;PBS_Server;Svr;tyrone-cluster;Scheduler was sent the command new
07/14/2015 03:57:07;0008;PBS_Server;Job;NULL;on_job_exit valid pjob: 0x1dcb770 (substate=10)
07/14/2015 03:57:09;0040;PBS_Server;Svr;tyrone-cluster;Scheduler was sent the command new
07/14/2015 03:57:37;0008;PBS_Server;Job;NULL;on_job_exit valid pjob: 0x1dcb770 (substate=10)
07/14/2015 03:57:38;0040;PBS_Server;Svr;tyrone-cluster;Scheduler was sent the command new
07/14/2015 03:58:07;0008;PBS_Server;Job;NULL;on_job_exit valid pjob: 0x1dcb770 (substate=10)
07/14/2015 03:58:08;0040;PBS_Server;Svr;tyrone-cluster;Scheduler was sent the command new
07/14/2015 03:58:37;0008;PBS_Server;Job;NULL;on_job_exit valid pjob: 0x1dcb770 (substate=10)
07/14/2015 03:58:38;0040;PBS_Server;Svr;tyrone-cluster;Scheduler was sent the command new
07/14/2015 03:59:07;0008;PBS_Server;Job;NULL;on_job_exit valid pjob: 0x1dcb770 (substate=10)
07/14/2015 03:59:08;0040;PBS_Server;Svr;tyrone-cluster;Scheduler was sent the command new
07/14/2015 03:59:37;0008;PBS_Server;Job;NULL;on_job_exit valid pjob: 0x1dcb770 (substate=10)
07/14/2015 03:59:38;0040;PBS_Server;Svr;tyrone-cluster;Scheduler was sent the command new
07/14/2015 04:00:07;0008;PBS_Server;Job;NULL;on_job_exit valid pjob: 0x1dcb770 (substate=10)
07/14/2015 04:00:07;0040;PBS_Server;Svr;tyrone-cluster;Scheduler was sent the command new
07/14/2015 04:00:37;0008;PBS_Server;Job;NULL;on_job_exit valid pjob: 0x1dcb770 (substate=10)
07/14/2015 04:00:38;0040;PBS_Server;Svr;tyrone-cluster;Scheduler was sent the command new
07/14/2015 04:01:07;0008;PBS_Server;Job;NULL;on_job_exit valid pjob: 0x1dcb770 (substate=10)
07/14/2015 04:01:08;0040;PBS_Server;Svr;tyrone-cluster;Scheduler was sent the command new
07/14/2015 04:01:36;0002;PBS_Server;Svr;PBS_Server;Torque Server Version = 3.0.5, loglevel = 0
07/14/2015 04:01:37;0008;PBS_Server;Job;NULL;on_job_exit valid pjob: 0x1dcb770 (substate=10)
07/14/2015 04:01:37;0040;PBS_Server;Svr;tyrone-cluster;Scheduler was sent the command new
07/14/2015 04:02:07;0008;PBS_Server;Job;NULL;on_job_exit valid pjob: 0x1dcb770 (substate=10)
07/14/2015 04:02:08;0040;PBS_Server;Svr;tyrone-cluster;Scheduler was sent the command new
07/14/2015 04:02:37;0008;PBS_Server;Job;NULL;on_job_exit valid pjob: 0x1dcb770 (substate=10)
07/14/2015 04:02:38;0040;PBS_Server;Svr;tyrone-cluster;Scheduler was sent the command new
07/14/2015 04:03:07;0008;PBS_Server;Job;NULL;on_job_exit valid pjob: 0x1dcb770 (substate=10)
07/14/2015 04:03:07;0040;PBS_Server;Svr;tyrone-cluster;Scheduler was sent the command new
07/14/2015 04:03:37;0008;PBS_Server;Job;NULL;on_job_exit valid pjob: 0x1dcb770 (substate=10)
07/14/2015 04:03:38;0040;PBS_Server;Svr;tyrone-cluster;Scheduler was sent the command new
07/14/2015 04:04:07;0008;PBS_Server;Job;NULL;on_job_exit valid pjob: 0x1dcb770 (substate=10)
07/14/2015 04:04:08;0040;PBS_Server;Svr;tyrone-cluster;Scheduler was sent the command new
07/14/2015 04:04:37;0008;PBS_Server;Job;NULL;on_job_exit valid pjob: 0x1dcb770 (substate=10)
07/14/2015 04:04:37;0040;PBS_Server;Svr;tyrone-cluster;Scheduler was sent the command new
07/14/2015 04:05:07;0008;PBS_Server;Job;NULL;on_job_exit valid pjob: 0x1dcb770 (substate=10)
07/14/2015 04:05:07;0040;PBS_Server;Svr;tyrone-cluster;Scheduler was sent the command new
07/14/2015 04:05:37;0008;PBS_Server;Job;NULL;on_job_exit valid pjob: 0x1dcb770 (substate=10)
07/14/2015 04:05:39;0040;PBS_Server;Svr;tyrone-cluster;Scheduler was sent the command new
07/14/2015 04:06:07;0008;PBS_Server;Job;NULL;on_job_exit valid pjob: 0x1dcb770 (substate=10)
07/14/2015 04:06:08;0040;PBS_Server;Svr;tyrone-cluster;Scheduler was sent the command new
07/14/2015 04:06:36;0002;PBS_Server;Svr;PBS_Server;Torque Server Version = 3.0.5, loglevel = 0
07/14/2015 04:06:37;0008;PBS_Server;Job;NULL;on_job_exit valid pjob: 0x1dcb770 (substate=10)
07/14/2015 04:06:38;0040;PBS_Server;Svr;tyrone-cluster;Scheduler was sent the command new
07/14/2015 04:07:07;0008;PBS_Server;Job;NULL;on_job_exit valid pjob: 0x1dcb770 (substate=10)
07/14/2015 04:07:08;0040;PBS_Server;Svr;tyrone-cluster;Scheduler was sent the command new
07/14/2015 04:07:37;0008;PBS_Server;Job;NULL;on_job_exit valid pjob: 0x1dcb770 (substate=10)
07/14/2015 04:07:39;0040;PBS_Server;Svr;tyrone-cluster;Scheduler was sent the command new
07/14/2015 04:08:07;0008;PBS_Server;Job;NULL;on_job_exit valid pjob: 0x1dcb770 (substate=10)
07/14/2015 04:08:07;0040;PBS_Server;Svr;tyrone-cluster;Scheduler was sent the command new
07/14/2015 04:08:37;0008;PBS_Server;Job;NULL;on_job_exit valid pjob: 0x1dcb770 (substate=10)
07/14/2015 04:08:38;0040;PBS_Server;Svr;tyrone-cluster;Scheduler was sent the command new
07/14/2015 04:09:07;0008;PBS_Server;Job;NULL;on_job_exit valid pjob: 0x1dcb770 (substate=10)
07/14/2015 04:09:07;0040;PBS_Server;Svr;tyrone-cluster;Scheduler was sent the command new
07/14/2015 04:09:37;0008;PBS_Server;Job;NULL;on_job_exit valid pjob: 0x1dcb770 (substate=10)
07/14/2015 04:09:37;0040;PBS_Server;Svr;tyrone-cluster;Scheduler was sent the command new
07/14/2015 04:10:07;0008;PBS_Server;Job;NULL;on_job_exit valid pjob: 0x1dcb770 (substate=10)
07/14/2015 04:10:08;0040;PBS_Server;Svr;tyrone-cluster;Scheduler was sent the command new
07/14/2015 04:10:37;0008;PBS_Server;Job;NULL;on_job_exit valid pjob: 0x1dcb770 (substate=10)
07/14/2015 04:10:38;0040;PBS_Server;Svr;tyrone-cluster;Scheduler was sent the command new
07/14/2015 04:11:07;0008;PBS_Server;Job;NULL;on_job_exit valid pjob: 0x1dcb770 (substate=10)
07/14/2015 04:11:08;0040;PBS_Server;Svr;tyrone-cluster;Scheduler was sent the command new
07/14/2015 04:11:36;0002;PBS_Server;Svr;PBS_Server;Torque Server Version = 3.0.5, loglevel = 0
07/14/2015 04:11:37;0008;PBS_Server;Job;NULL;on_job_exit valid pjob: 0x1dcb770 (substate=10)
07/14/2015 04:11:38;0040;PBS_Server;Svr;tyrone-cluster;Scheduler was sent the command new
07/14/2015 04:12:07;0008;PBS_Server;Job;NULL;on_job_exit valid pjob: 0x1dcb770 (substate=10)
07/14/2015 04:12:07;0040;PBS_Server;Svr;tyrone-cluster;Scheduler was sent the command new
07/14/2015 04:12:37;0008;PBS_Server;Job;NULL;on_job_exit valid pjob: 0x1dcb770 (substate=10)
07/14/2015 04:12:37;0040;PBS_Server;Svr;tyrone-cluster;Scheduler was sent the command new
07/14/2015 04:13:07;0008;PBS_Server;Job;NULL;on_job_exit valid pjob: 0x1dcb770 (substate=10)
07/14/2015 04:13:08;0040;PBS_Server;Svr;tyrone-cluster;Scheduler was sent the command new
07/14/2015 04:13:38;0008;PBS_Server;Job;NULL;on_job_exit valid pjob: 0x1dcb770 (substate=10)
07/14/2015 04:13:38;0040;PBS_Server;Svr;tyrone-cluster;Scheduler was sent the command new
07/14/2015 04:14:07;0008;PBS_Server;Job;NULL;on_job_exit valid pjob: 0x1dcb770 (substate=10)
07/14/2015 04:14:08;0040;PBS_Server;Svr;tyrone-cluster;Scheduler was sent the command new
07/14/2015 04:14:37;0008;PBS_Server;Job;NULL;on_job_exit valid pjob: 0x1dcb770 (substate=10)
07/14/2015 04:14:38;0040;PBS_Server;Svr;tyrone-cluster;Scheduler was sent the command new
07/14/2015 04:15:07;0008;PBS_Server;Job;NULL;on_job_exit valid pjob: 0x1dcb770 (substate=10)
07/14/2015 04:15:07;0040;PBS_Server;Svr;tyrone-cluster;Scheduler was sent the command new
07/14/2015 04:15:37;0008;PBS_Server;Job;NULL;on_job_exit valid pjob: 0x1dcb770 (substate=10)
07/14/2015 04:15:37;0040;PBS_Server;Svr;tyrone-cluster;Scheduler was sent the command new
07/14/2015 04:16:07;0008;PBS_Server;Job;NULL;on_job_exit valid pjob: 0x1dcb770 (substate=10)
07/14/2015 04:16:08;0040;PBS_Server;Svr;tyrone-cluster;Scheduler was sent the command new
07/14/2015 04:16:36;0002;PBS_Server;Svr;PBS_Server;Torque Server Version = 3.0.5, loglevel = 0
07/14/2015 04:16:37;0008;PBS_Server;Job;NULL;on_job_exit valid pjob: 0x1dcb770 (substate=10)
07/14/2015 04:16:37;0040;PBS_Server;Svr;tyrone-cluster;Scheduler was sent the command new
07/14/2015 04:17:07;0008;PBS_Server;Job;NULL;on_job_exit valid pjob: 0x1dcb770 (substate=10)
07/14/2015 04:17:07;0040;PBS_Server;Svr;tyrone-cluster;Scheduler was sent the command new
07/14/2015 04:17:37;0008;PBS_Server;Job;NULL;on_job_exit valid pjob: 0x1dcb770 (substate=10)
07/14/2015 04:17:38;0040;PBS_Server;Svr;tyrone-cluster;Scheduler was sent the command new
07/14/2015 04:18:07;0008;PBS_Server;Job;NULL;on_job_exit valid pjob: 0x1dcb770 (substate=10)
07/14/2015 04:18:08;0040;PBS_Server;Svr;tyrone-cluster;Scheduler was sent the command new
07/14/2015 04:18:37;0008;PBS_Server;Job;NULL;on_job_exit valid pjob: 0x1dcb770 (substate=10)
07/14/2015 04:18:38;0040;PBS_Server;Svr;tyrone-cluster;Scheduler was sent the command new
07/14/2015 04:19:07;0008;PBS_Server;Job;NULL;on_job_exit valid pjob: 0x1dcb770 (substate=10)
07/14/2015 04:19:08;0040;PBS_Server;Svr;tyrone-cluster;Scheduler was sent the command new
07/14/2015 04:19:37;0008;PBS_Server;Job;NULL;on_job_exit valid pjob: 0x1dcb770 (substate=10)
07/14/2015 04:19:39;0040;PBS_Server;Svr;tyrone-cluster;Scheduler was sent the command new
07/14/2015 04:20:07;0008;PBS_Server;Job;NULL;on_job_exit valid pjob: 0x1dcb770 (substate=10)
07/14/2015 04:20:07;0040;PBS_Server;Svr;tyrone-cluster;Scheduler was sent the command new
07/14/2015 04:20:37;0008;PBS_Server;Job;NULL;on_job_exit valid pjob: 0x1dcb770 (substate=10)
07/14/2015 04:20:38;0040;PBS_Server;Svr;tyrone-cluster;Scheduler was sent the command new
07/14/2015 04:21:07;0008;PBS_Server;Job;NULL;on_job_exit valid pjob: 0x1dcb770 (substate=10)
07/14/2015 04:21:08;0040;PBS_Server;Svr;tyrone-cluster;Scheduler was sent the command new
07/14/2015 04:21:36;0002;PBS_Server;Svr;PBS_Server;Torque Server Version = 3.0.5, loglevel = 0
07/14/2015 04:21:37;0008;PBS_Server;Job;NULL;on_job_exit valid pjob: 0x1dcb770 (substate=10)
07/14/2015 04:21:38;0040;PBS_Server;Svr;tyrone-cluster;Scheduler was sent the command new
07/14/2015 04:22:07;0008;PBS_Server;Job;NULL;on_job_exit valid pjob: 0x1dcb770 (substate=10)
07/14/2015 04:22:08;0040;PBS_Server;Svr;tyrone-cluster;Scheduler was sent the command new
07/14/2015 04:22:37;0008;PBS_Server;Job;NULL;on_job_exit valid pjob: 0x1dcb770 (substate=10)
07/14/2015 04:22:37;0040;PBS_Server;Svr;tyrone-cluster;Scheduler was sent the command new
07/14/2015 04:23:07;0008;PBS_Server;Job;NULL;on_job_exit valid pjob: 0x1dcb770 (substate=10)
07/14/2015 04:23:08;0040;PBS_Server;Svr;tyrone-cluster;Scheduler was sent the command new
07/14/2015 04:23:37;0008;PBS_Server;Job;NULL;on_job_exit valid pjob: 0x1dcb770 (substate=10)
07/14/2015 04:23:38;0040;PBS_Server;Svr;tyrone-cluster;Scheduler was sent the command new
07/14/2015 04:24:07;0008;PBS_Server;Job;NULL;on_job_exit valid pjob: 0x1dcb770 (substate=10)
07/14/2015 04:24:07;0040;PBS_Server;Svr;tyrone-cluster;Scheduler was sent the command new
07/14/2015 04:24:37;0008;PBS_Server;Job;NULL;on_job_exit valid pjob: 0x1dcb770 (substate=10)
07/14/2015 04:24:37;0040;PBS_Server;Svr;tyrone-cluster;Scheduler was sent the command new
07/14/2015 04:25:07;0008;PBS_Server;Job;NULL;on_job_exit valid pjob: 0x1dcb770 (substate=10)
07/14/2015 04:25:08;0040;PBS_Server;Svr;tyrone-cluster;Scheduler was sent the command new
07/14/2015 04:25:37;0008;PBS_Server;Job;NULL;on_job_exit valid pjob: 0x1dcb770 (substate=10)
07/14/2015 04:25:38;0040;PBS_Server;Svr;tyrone-cluster;Scheduler was sent the command new
07/14/2015 04:26:07;0008;PBS_Server;Job;NULL;on_job_exit valid pjob: 0x1dcb770 (substate=10)
07/14/2015 04:26:08;0040;PBS_Server;Svr;tyrone-cluster;Scheduler was sent the command new
07/14/2015 04:26:36;0002;PBS_Server;Svr;PBS_Server;Torque Server Version = 3.0.5, loglevel = 0
07/14/2015 04:26:37;0008;PBS_Server;Job;NULL;on_job_exit valid pjob: 0x1dcb770 (substate=10)
07/14/2015 04:26:38;0040;PBS_Server;Svr;tyrone-cluster;Scheduler was sent the command new
07/14/2015 04:27:07;0008;PBS_Server;Job;NULL;on_job_exit valid pjob: 0x1dcb770 (substate=10)
07/14/2015 04:27:09;0040;PBS_Server;Svr;tyrone-cluster;Scheduler was sent the command new
07/14/2015 04:27:37;0008;PBS_Server;Job;NULL;on_job_exit valid pjob: 0x1dcb770 (substate=10)
07/14/2015 04:27:37;0040;PBS_Server;Svr;tyrone-cluster;Scheduler was sent the command new
07/14/2015 04:28:07;0008;PBS_Server;Job;NULL;on_job_exit valid pjob: 0x1dcb770 (substate=10)
07/14/2015 04:28:08;0040;PBS_Server;Svr;tyrone-cluster;Scheduler was sent the command new
07/14/2015 04:28:37;0008;PBS_Server;Job;NULL;on_job_exit valid pjob: 0x1dcb770 (substate=10)
07/14/2015 04:28:37;0040;PBS_Server;Svr;tyrone-cluster;Scheduler was sent the command new
07/14/2015 04:29:07;0008;PBS_Server;Job;NULL;on_job_exit valid pjob: 0x1dcb770 (substate=10)
07/14/2015 04:29:07;0040;PBS_Server;Svr;tyrone-cluster;Scheduler was sent the command new
07/14/2015 04:29:37;0008;PBS_Server;Job;NULL;on_job_exit valid pjob: 0x1dcb770 (substate=10)
07/14/2015 04:29:38;0040;PBS_Server;Svr;tyrone-cluster;Scheduler was sent the command new
07/14/2015 04:30:07;0008;PBS_Server;Job;NULL;on_job_exit valid pjob: 0x1dcb770 (substate=10)
07/14/2015 04:30:07;0040;PBS_Server;Svr;tyrone-cluster;Scheduler was sent the command new
07/14/2015 04:30:37;0008;PBS_Server;Job;NULL;on_job_exit valid pjob: 0x1dcb770 (substate=10)
07/14/2015 04:30:37;0040;PBS_Server;Svr;tyrone-cluster;Scheduler was sent the command new
07/14/2015 04:31:07;0008;PBS_Server;Job;NULL;on_job_exit valid pjob: 0x1dcb770 (substate=10)
07/14/2015 04:31:08;0040;PBS_Server;Svr;tyrone-cluster;Scheduler was sent the command new
07/14/2015 04:31:36;0002;PBS_Server;Svr;PBS_Server;Torque Server Version = 3.0.5, loglevel = 0
07/14/2015 04:31:37;0008;PBS_Server;Job;NULL;on_job_exit valid pjob: 0x1dcb770 (substate=10)
07/14/2015 04:31:38;0040;PBS_Server;Svr;tyrone-cluster;Scheduler was sent the command new
07/14/2015 04:32:07;0008;PBS_Server;Job;NULL;on_job_exit valid pjob: 0x1dcb770 (substate=10)
07/14/2015 04:32:08;0040;PBS_Server;Svr;tyrone-cluster;Scheduler was sent the command new
07/14/2015 04:32:37;0008;PBS_Server;Job;NULL;on_job_exit valid pjob: 0x1dcb770 (substate=10)
07/14/2015 04:32:38;0040;PBS_Server;Svr;tyrone-cluster;Scheduler was sent the command new
07/14/2015 04:33:07;0008;PBS_Server;Job;NULL;on_job_exit valid pjob: 0x1dcb770 (substate=10)
07/14/2015 04:33:07;0040;PBS_Server;Svr;tyrone-cluster;Scheduler was sent the command new
07/14/2015 04:33:37;0008;PBS_Server;Job;NULL;on_job_exit valid pjob: 0x1dcb770 (substate=10)
07/14/2015 04:33:37;0040;PBS_Server;Svr;tyrone-cluster;Scheduler was sent the command new
07/14/2015 04:34:07;0008;PBS_Server;Job;NULL;on_job_exit valid pjob: 0x1dcb770 (substate=10)
07/14/2015 04:34:08;0040;PBS_Server;Svr;tyrone-cluster;Scheduler was sent the command new
07/14/2015 04:34:37;0008;PBS_Server;Job;NULL;on_job_exit valid pjob: 0x1dcb770 (substate=10)
07/14/2015 04:34:38;0040;PBS_Server;Svr;tyrone-cluster;Scheduler was sent the command new
07/14/2015 04:35:07;0008;PBS_Server;Job;NULL;on_job_exit valid pjob: 0x1dcb770 (substate=10)
07/14/2015 04:35:08;0040;PBS_Server;Svr;tyrone-cluster;Scheduler was sent the command new
07/14/2015 04:35:37;0008;PBS_Server;Job;NULL;on_job_exit valid pjob: 0x1dcb770 (substate=10)
07/14/2015 04:35:38;0040;PBS_Server;Svr;tyrone-cluster;Scheduler was sent the command new
07/14/2015 04:36:07;0008;PBS_Server;Job;NULL;on_job_exit valid pjob: 0x1dcb770 (substate=10)
07/14/2015 04:36:07;0040;PBS_Server;Svr;tyrone-cluster;Scheduler was sent the command new
07/14/2015 04:36:36;0002;PBS_Server;Svr;PBS_Server;Torque Server Version = 3.0.5, loglevel = 0
07/14/2015 04:36:37;0008;PBS_Server;Job;NULL;on_job_exit valid pjob: 0x1dcb770 (substate=10)
07/14/2015 04:36:37;0040;PBS_Server;Svr;tyrone-cluster;Scheduler was sent the command new
07/14/2015 04:37:07;0008;PBS_Server;Job;NULL;on_job_exit valid pjob: 0x1dcb770 (substate=10)
07/14/2015 04:37:08;0040;PBS_Server;Svr;tyrone-cluster;Scheduler was sent the command new
07/14/2015 04:37:37;0008;PBS_Server;Job;NULL;on_job_exit valid pjob: 0x1dcb770 (substate=10)
07/14/2015 04:37:38;0040;PBS_Server;Svr;tyrone-cluster;Scheduler was sent the command new
07/14/2015 04:38:07;0008;PBS_Server;Job;NULL;on_job_exit valid pjob: 0x1dcb770 (substate=10)
07/14/2015 04:38:07;0040;PBS_Server;Svr;tyrone-cluster;Scheduler was sent the command new
07/14/2015 04:38:37;0008;PBS_Server;Job;NULL;on_job_exit valid pjob: 0x1dcb770 (substate=10)
07/14/2015 04:38:38;0040;PBS_Server;Svr;tyrone-cluster;Scheduler was sent the command new
07/14/2015 04:39:07;0008;PBS_Server;Job;NULL;on_job_exit valid pjob: 0x1dcb770 (substate=10)
07/14/2015 04:39:08;0040;PBS_Server;Svr;tyrone-cluster;Scheduler was sent the command new
07/14/2015 04:39:37;0008;PBS_Server;Job;NULL;on_job_exit valid pjob: 0x1dcb770 (substate=10)
07/14/2015 04:39:38;0040;PBS_Server;Svr;tyrone-cluster;Scheduler was sent the command new
07/14/2015 04:40:07;0008;PBS_Server;Job;NULL;on_job_exit valid pjob: 0x1dcb770 (substate=10)
07/14/2015 04:40:08;0040;PBS_Server;Svr;tyrone-cluster;Scheduler was sent the command new
07/14/2015 04:40:37;0008;PBS_Server;Job;NULL;on_job_exit valid pjob: 0x1dcb770 (substate=10)
07/14/2015 04:40:37;0040;PBS_Server;Svr;tyrone-cluster;Scheduler was sent the command new
07/14/2015 04:41:07;0008;PBS_Server;Job;NULL;on_job_exit valid pjob: 0x1dcb770 (substate=10)
07/14/2015 04:41:07;0040;PBS_Server;Svr;tyrone-cluster;Scheduler was sent the command new
07/14/2015 04:41:36;0002;PBS_Server;Svr;PBS_Server;Torque Server Version = 3.0.5, loglevel = 0
07/14/2015 04:41:37;0008;PBS_Server;Job;NULL;on_job_exit valid pjob: 0x1dcb770 (substate=10)
07/14/2015 04:41:38;0040;PBS_Server;Svr;tyrone-cluster;Scheduler was sent the command new
07/14/2015 04:42:07;0008;PBS_Server;Job;NULL;on_job_exit valid pjob: 0x1dcb770 (substate=10)
07/14/2015 04:42:07;0040;PBS_Server;Svr;tyrone-cluster;Scheduler was sent the command new
07/14/2015 04:42:37;0008;PBS_Server;Job;NULL;on_job_exit valid pjob: 0x1dcb770 (substate=10)
07/14/2015 04:42:37;0040;PBS_Server;Svr;tyrone-cluster;Scheduler was sent the command new
07/14/2015 04:43:07;0008;PBS_Server;Job;NULL;on_job_exit valid pjob: 0x1dcb770 (substate=10)
07/14/2015 04:43:08;0040;PBS_Server;Svr;tyrone-cluster;Scheduler was sent the command new
07/14/2015 04:43:37;0008;PBS_Server;Job;NULL;on_job_exit valid pjob: 0x1dcb770 (substate=10)
07/14/2015 04:43:38;0040;PBS_Server;Svr;tyrone-cluster;Scheduler was sent the command new
07/14/2015 04:44:07;0008;PBS_Server;Job;NULL;on_job_exit valid pjob: 0x1dcb770 (substate=10)
07/14/2015 04:44:08;0040;PBS_Server;Svr;tyrone-cluster;Scheduler was sent the command new
07/14/2015 04:44:37;0008;PBS_Server;Job;NULL;on_job_exit valid pjob: 0x1dcb770 (substate=10)
07/14/2015 04:44:38;0040;PBS_Server;Svr;tyrone-cluster;Scheduler was sent the command new
07/14/2015 04:45:07;0008;PBS_Server;Job;NULL;on_job_exit valid pjob: 0x1dcb770 (substate=10)
07/14/2015 04:45:07;0040;PBS_Server;Svr;tyrone-cluster;Scheduler was sent the command new
07/14/2015 04:45:37;0008;PBS_Server;Job;NULL;on_job_exit valid pjob: 0x1dcb770 (substate=10)
07/14/2015 04:45:37;0040;PBS_Server;Svr;tyrone-cluster;Scheduler was sent the command new
07/14/2015 04:46:07;0008;PBS_Server;Job;NULL;on_job_exit valid pjob: 0x1dcb770 (substate=10)
07/14/2015 04:46:08;0040;PBS_Server;Svr;tyrone-cluster;Scheduler was sent the command new
07/14/2015 04:46:36;0002;PBS_Server;Svr;PBS_Server;Torque Server Version = 3.0.5, loglevel = 0
07/14/2015 04:46:37;0008;PBS_Server;Job;NULL;on_job_exit valid pjob: 0x1dcb770 (substate=10)
07/14/2015 04:46:38;0040;PBS_Server;Svr;tyrone-cluster;Scheduler was sent the command new
07/14/2015 04:47:07;0008;PBS_Server;Job;NULL;on_job_exit valid pjob: 0x1dcb770 (substate=10)
07/14/2015 04:47:07;0040;PBS_Server;Svr;tyrone-cluster;Scheduler was sent the command new
07/14/2015 04:47:37;0008;PBS_Server;Job;NULL;on_job_exit valid pjob: 0x1dcb770 (substate=10)
07/14/2015 04:47:38;0040;PBS_Server;Svr;tyrone-cluster;Scheduler was sent the command new
07/14/2015 04:48:07;0008;PBS_Server;Job;NULL;on_job_exit valid pjob: 0x1dcb770 (substate=10)
07/14/2015 04:48:08;0040;PBS_Server;Svr;tyrone-cluster;Scheduler was sent the command new
07/14/2015 04:48:37;0008;PBS_Server;Job;NULL;on_job_exit valid pjob: 0x1dcb770 (substate=10)
07/14/2015 04:48:38;0040;PBS_Server;Svr;tyrone-cluster;Scheduler was sent the command new
07/14/2015 04:49:07;0008;PBS_Server;Job;NULL;on_job_exit valid pjob: 0x1dcb770 (substate=10)
07/14/2015 04:49:08;0040;PBS_Server;Svr;tyrone-cluster;Scheduler was sent the command new
07/14/2015 04:49:37;0008;PBS_Server;Job;NULL;on_job_exit valid pjob: 0x1dcb770 (substate=10)
07/14/2015 04:49:39;0040;PBS_Server;Svr;tyrone-cluster;Scheduler was sent the command new
07/14/2015 04:50:07;0008;PBS_Server;Job;NULL;on_job_exit valid pjob: 0x1dcb770 (substate=10)
07/14/2015 04:50:07;0040;PBS_Server;Svr;tyrone-cluster;Scheduler was sent the command new
07/14/2015 04:50:37;0008;PBS_Server;Job;NULL;on_job_exit valid pjob: 0x1dcb770 (substate=10)
07/14/2015 04:50:38;0040;PBS_Server;Svr;tyrone-cluster;Scheduler was sent the command new
07/14/2015 04:51:07;0008;PBS_Server;Job;NULL;on_job_exit valid pjob: 0x1dcb770 (substate=10)
07/14/2015 04:51:08;0040;PBS_Server;Svr;tyrone-cluster;Scheduler was sent the command new
07/14/2015 04:51:36;0002;PBS_Server;Svr;PBS_Server;Torque Server Version = 3.0.5, loglevel = 0
07/14/2015 04:51:37;0008;PBS_Server;Job;NULL;on_job_exit valid pjob: 0x1dcb770 (substate=10)
07/14/2015 04:51:38;0040;PBS_Server;Svr;tyrone-cluster;Scheduler was sent the command new
07/14/2015 04:52:07;0008;PBS_Server;Job;NULL;on_job_exit valid pjob: 0x1dcb770 (substate=10)
07/14/2015 04:52:08;0040;PBS_Server;Svr;tyrone-cluster;Scheduler was sent the command new
07/14/2015 04:52:37;0008;PBS_Server;Job;NULL;on_job_exit valid pjob: 0x1dcb770 (substate=10)
07/14/2015 04:52:38;0040;PBS_Server;Svr;tyrone-cluster;Scheduler was sent the command new
07/14/2015 04:53:07;0008;PBS_Server;Job;NULL;on_job_exit valid pjob: 0x1dcb770 (substate=10)
07/14/2015 04:53:08;0040;PBS_Server;Svr;tyrone-cluster;Scheduler was sent the command new
07/14/2015 04:53:37;0008;PBS_Server;Job;NULL;on_job_exit valid pjob: 0x1dcb770 (substate=10)
07/14/2015 04:53:38;0040;PBS_Server;Svr;tyrone-cluster;Scheduler was sent the command new
07/14/2015 04:54:07;0008;PBS_Server;Job;NULL;on_job_exit valid pjob: 0x1dcb770 (substate=10)
07/14/2015 04:54:07;0040;PBS_Server;Svr;tyrone-cluster;Scheduler was sent the command new
07/14/2015 04:54:37;0008;PBS_Server;Job;NULL;on_job_exit valid pjob: 0x1dcb770 (substate=10)
07/14/2015 04:54:37;0040;PBS_Server;Svr;tyrone-cluster;Scheduler was sent the command new
07/14/2015 04:55:07;0008;PBS_Server;Job;NULL;on_job_exit valid pjob: 0x1dcb770 (substate=10)
07/14/2015 04:55:08;0040;PBS_Server;Svr;tyrone-cluster;Scheduler was sent the command new
07/14/2015 04:55:37;0008;PBS_Server;Job;NULL;on_job_exit valid pjob: 0x1dcb770 (substate=10)
07/14/2015 04:55:37;0040;PBS_Server;Svr;tyrone-cluster;Scheduler was sent the command new
07/14/2015 04:56:07;0008;PBS_Server;Job;NULL;on_job_exit valid pjob: 0x1dcb770 (substate=10)
07/14/2015 04:56:08;0040;PBS_Server;Svr;tyrone-cluster;Scheduler was sent the command new
07/14/2015 04:56:36;0002;PBS_Server;Svr;PBS_Server;Torque Server Version = 3.0.5, loglevel = 0
07/14/2015 04:56:37;0008;PBS_Server;Job;NULL;on_job_exit valid pjob: 0x1dcb770 (substate=10)
07/14/2015 04:56:38;0040;PBS_Server;Svr;tyrone-cluster;Scheduler was sent the command new
07/14/2015 04:57:07;0008;PBS_Server;Job;NULL;on_job_exit valid pjob: 0x1dcb770 (substate=10)
07/14/2015 04:57:08;0040;PBS_Server;Svr;tyrone-cluster;Scheduler was sent the command new
07/14/2015 04:57:37;0008;PBS_Server;Job;NULL;on_job_exit valid pjob: 0x1dcb770 (substate=10)
07/14/2015 04:57:37;0040;PBS_Server;Svr;tyrone-cluster;Scheduler was sent the command new
07/14/2015 04:58:07;0008;PBS_Server;Job;NULL;on_job_exit valid pjob: 0x1dcb770 (substate=10)
07/14/2015 04:58:08;0040;PBS_Server;Svr;tyrone-cluster;Scheduler was sent the command new
07/14/2015 04:58:37;0008;PBS_Server;Job;NULL;on_job_exit valid pjob: 0x1dcb770 (substate=10)
07/14/2015 04:58:37;0040;PBS_Server;Svr;tyrone-cluster;Scheduler was sent the command new
07/14/2015 04:59:07;0008;PBS_Server;Job;NULL;on_job_exit valid pjob: 0x1dcb770 (substate=10)
07/14/2015 04:59:07;0040;PBS_Server;Svr;tyrone-cluster;Scheduler was sent the command new
07/14/2015 04:59:37;0008;PBS_Server;Job;NULL;on_job_exit valid pjob: 0x1dcb770 (substate=10)
07/14/2015 04:59:38;0040;PBS_Server;Svr;tyrone-cluster;Scheduler was sent the command new
07/14/2015 05:00:07;0008;PBS_Server;Job;NULL;on_job_exit valid pjob: 0x1dcb770 (substate=10)
07/14/2015 05:00:08;0040;PBS_Server;Svr;tyrone-cluster;Scheduler was sent the command new
07/14/2015 05:00:37;0008;PBS_Server;Job;NULL;on_job_exit valid pjob: 0x1dcb770 (substate=10)
07/14/2015 05:00:37;0040;PBS_Server;Svr;tyrone-cluster;Scheduler was sent the command new
07/14/2015 05:01:07;0008;PBS_Server;Job;NULL;on_job_exit valid pjob: 0x1dcb770 (substate=10)
07/14/2015 05:01:08;0040;PBS_Server;Svr;tyrone-cluster;Scheduler was sent the command new
07/14/2015 05:01:36;0002;PBS_Server;Svr;PBS_Server;Torque Server Version = 3.0.5, loglevel = 0
07/14/2015 05:01:37;0008;PBS_Server;Job;NULL;on_job_exit valid pjob: 0x1dcb770 (substate=10)
07/14/2015 05:01:37;0040;PBS_Server;Svr;tyrone-cluster;Scheduler was sent the command new
07/14/2015 05:02:07;0008;PBS_Server;Job;NULL;on_job_exit valid pjob: 0x1dcb770 (substate=10)
07/14/2015 05:02:07;0040;PBS_Server;Svr;tyrone-cluster;Scheduler was sent the command new
07/14/2015 05:02:37;0008;PBS_Server;Job;NULL;on_job_exit valid pjob: 0x1dcb770 (substate=10)
07/14/2015 05:02:38;0040;PBS_Server;Svr;tyrone-cluster;Scheduler was sent the command new
07/14/2015 05:03:07;0008;PBS_Server;Job;NULL;on_job_exit valid pjob: 0x1dcb770 (substate=10)
07/14/2015 05:03:08;0040;PBS_Server;Svr;tyrone-cluster;Scheduler was sent the command new
07/14/2015 05:03:37;0008;PBS_Server;Job;NULL;on_job_exit valid pjob: 0x1dcb770 (substate=10)
07/14/2015 05:03:38;0040;PBS_Server;Svr;tyrone-cluster;Scheduler was sent the command new
07/14/2015 05:04:07;0008;PBS_Server;Job;NULL;on_job_exit valid pjob: 0x1dcb770 (substate=10)
07/14/2015 05:04:08;0040;PBS_Server;Svr;tyrone-cluster;Scheduler was sent the command new
07/14/2015 05:04:37;0008;PBS_Server;Job;NULL;on_job_exit valid pjob: 0x1dcb770 (substate=10)
07/14/2015 05:04:37;0040;PBS_Server;Svr;tyrone-cluster;Scheduler was sent the command new
07/14/2015 05:05:07;0008;PBS_Server;Job;NULL;on_job_exit valid pjob: 0x1dcb770 (substate=10)
07/14/2015 05:05:07;0040;PBS_Server;Svr;tyrone-cluster;Scheduler was sent the command new
07/14/2015 05:05:37;0008;PBS_Server;Job;NULL;on_job_exit valid pjob: 0x1dcb770 (substate=10)
07/14/2015 05:05:38;0040;PBS_Server;Svr;tyrone-cluster;Scheduler was sent the command new
07/14/2015 05:06:07;0008;PBS_Server;Job;NULL;on_job_exit valid pjob: 0x1dcb770 (substate=10)
07/14/2015 05:06:08;0040;PBS_Server;Svr;tyrone-cluster;Scheduler was sent the command new
07/14/2015 05:06:36;0002;PBS_Server;Svr;PBS_Server;Torque Server Version = 3.0.5, loglevel = 0
07/14/2015 05:06:37;0008;PBS_Server;Job;NULL;on_job_exit valid pjob: 0x1dcb770 (substate=10)
07/14/2015 05:06:38;0040;PBS_Server;Svr;tyrone-cluster;Scheduler was sent the command new
07/14/2015 05:07:07;0008;PBS_Server;Job;NULL;on_job_exit valid pjob: 0x1dcb770 (substate=10)
07/14/2015 05:07:08;0040;PBS_Server;Svr;tyrone-cluster;Scheduler was sent the command new
07/14/2015 05:07:37;0008;PBS_Server;Job;NULL;on_job_exit valid pjob: 0x1dcb770 (substate=10)
07/14/2015 05:07:38;0040;PBS_Server;Svr;tyrone-cluster;Scheduler was sent the command new
07/14/2015 05:08:07;0008;PBS_Server;Job;NULL;on_job_exit valid pjob: 0x1dcb770 (substate=10)
07/14/2015 05:08:07;0040;PBS_Server;Svr;tyrone-cluster;Scheduler was sent the command new
07/14/2015 05:08:37;0008;PBS_Server;Job;NULL;on_job_exit valid pjob: 0x1dcb770 (substate=10)
07/14/2015 05:08:38;0040;PBS_Server;Svr;tyrone-cluster;Scheduler was sent the command new
07/14/2015 05:09:07;0008;PBS_Server;Job;NULL;on_job_exit valid pjob: 0x1dcb770 (substate=10)
07/14/2015 05:09:07;0040;PBS_Server;Svr;tyrone-cluster;Scheduler was sent the command new
07/14/2015 05:09:37;0008;PBS_Server;Job;NULL;on_job_exit valid pjob: 0x1dcb770 (substate=10)
07/14/2015 05:09:37;0040;PBS_Server;Svr;tyrone-cluster;Scheduler was sent the command new
07/14/2015 05:10:08;0008;PBS_Server;Job;NULL;on_job_exit valid pjob: 0x1dcb770 (substate=10)
07/14/2015 05:10:09;0040;PBS_Server;Svr;tyrone-cluster;Scheduler was sent the command new
07/14/2015 05:10:38;0008;PBS_Server;Job;NULL;on_job_exit valid pjob: 0x1dcb770 (substate=10)
07/14/2015 05:10:39;0040;PBS_Server;Svr;tyrone-cluster;Scheduler was sent the command new
07/14/2015 05:11:08;0008;PBS_Server;Job;NULL;on_job_exit valid pjob: 0x1dcb770 (substate=10)
07/14/2015 05:11:08;0040;PBS_Server;Svr;tyrone-cluster;Scheduler was sent the command new
07/14/2015 05:11:36;0002;PBS_Server;Svr;PBS_Server;Torque Server Version = 3.0.5, loglevel = 0
07/14/2015 05:11:38;0008;PBS_Server;Job;NULL;on_job_exit valid pjob: 0x1dcb770 (substate=10)
07/14/2015 05:11:39;0040;PBS_Server;Svr;tyrone-cluster;Scheduler was sent the command new
07/14/2015 05:12:08;0008;PBS_Server;Job;NULL;on_job_exit valid pjob: 0x1dcb770 (substate=10)
07/14/2015 05:12:08;0040;PBS_Server;Svr;tyrone-cluster;Scheduler was sent the command new
07/14/2015 05:12:38;0008;PBS_Server;Job;NULL;on_job_exit valid pjob: 0x1dcb770 (substate=10)
07/14/2015 05:12:38;0040;PBS_Server;Svr;tyrone-cluster;Scheduler was sent the command new
07/14/2015 05:13:08;0008;PBS_Server;Job;NULL;on_job_exit valid pjob: 0x1dcb770 (substate=10)
07/14/2015 05:13:09;0040;PBS_Server;Svr;tyrone-cluster;Scheduler was sent the command new
07/14/2015 05:13:38;0008;PBS_Server;Job;NULL;on_job_exit valid pjob: 0x1dcb770 (substate=10)
07/14/2015 05:13:39;0040;PBS_Server;Svr;tyrone-cluster;Scheduler was sent the command new
07/14/2015 05:14:08;0008;PBS_Server;Job;NULL;on_job_exit valid pjob: 0x1dcb770 (substate=10)
07/14/2015 05:14:09;0040;PBS_Server;Svr;tyrone-cluster;Scheduler was sent the command new
07/14/2015 05:14:38;0008;PBS_Server;Job;NULL;on_job_exit valid pjob: 0x1dcb770 (substate=10)
07/14/2015 05:14:39;0040;PBS_Server;Svr;tyrone-cluster;Scheduler was sent the command new
07/14/2015 05:15:08;0008;PBS_Server;Job;NULL;on_job_exit valid pjob: 0x1dcb770 (substate=10)
07/14/2015 05:15:08;0040;PBS_Server;Svr;tyrone-cluster;Scheduler was sent the command new
07/14/2015 05:15:38;0008;PBS_Server;Job;NULL;on_job_exit valid pjob: 0x1dcb770 (substate=10)
07/14/2015 05:15:38;0040;PBS_Server;Svr;tyrone-cluster;Scheduler was sent the command new
07/14/2015 05:16:08;0008;PBS_Server;Job;NULL;on_job_exit valid pjob: 0x1dcb770 (substate=10)
07/14/2015 05:16:09;0040;PBS_Server;Svr;tyrone-cluster;Scheduler was sent the command new
07/14/2015 05:16:36;0002;PBS_Server;Svr;PBS_Server;Torque Server Version = 3.0.5, loglevel = 0
07/14/2015 05:16:38;0008;PBS_Server;Job;NULL;on_job_exit valid pjob: 0x1dcb770 (substate=10)
07/14/2015 05:16:39;0040;PBS_Server;Svr;tyrone-cluster;Scheduler was sent the command new
07/14/2015 05:17:08;0008;PBS_Server;Job;NULL;on_job_exit valid pjob: 0x1dcb770 (substate=10)
07/14/2015 05:17:09;0040;PBS_Server;Svr;tyrone-cluster;Scheduler was sent the command new
07/14/2015 05:17:38;0008;PBS_Server;Job;NULL;on_job_exit valid pjob: 0x1dcb770 (substate=10)
07/14/2015 05:17:39;0040;PBS_Server;Svr;tyrone-cluster;Scheduler was sent the command new
07/14/2015 05:18:08;0008;PBS_Server;Job;NULL;on_job_exit valid pjob: 0x1dcb770 (substate=10)
07/14/2015 05:18:09;0040;PBS_Server;Svr;tyrone-cluster;Scheduler was sent the command new
07/14/2015 05:18:38;0008;PBS_Server;Job;NULL;on_job_exit valid pjob: 0x1dcb770 (substate=10)
07/14/2015 05:18:38;0040;PBS_Server;Svr;tyrone-cluster;Scheduler was sent the command new
07/14/2015 05:19:08;0008;PBS_Server;Job;NULL;on_job_exit valid pjob: 0x1dcb770 (substate=10)
07/14/2015 05:19:09;0040;PBS_Server;Svr;tyrone-cluster;Scheduler was sent the command new
07/14/2015 05:19:38;0008;PBS_Server;Job;NULL;on_job_exit valid pjob: 0x1dcb770 (substate=10)
07/14/2015 05:19:38;0040;PBS_Server;Svr;tyrone-cluster;Scheduler was sent the command new
07/14/2015 05:20:08;0008;PBS_Server;Job;NULL;on_job_exit valid pjob: 0x1dcb770 (substate=10)
07/14/2015 05:20:08;0040;PBS_Server;Svr;tyrone-cluster;Scheduler was sent the command new
07/14/2015 05:20:38;0008;PBS_Server;Job;NULL;on_job_exit valid pjob: 0x1dcb770 (substate=10)
07/14/2015 05:20:39;0040;PBS_Server;Svr;tyrone-cluster;Scheduler was sent the command new
07/14/2015 05:21:08;0008;PBS_Server;Job;NULL;on_job_exit valid pjob: 0x1dcb770 (substate=10)
07/14/2015 05:21:09;0040;PBS_Server;Svr;tyrone-cluster;Scheduler was sent the command new
07/14/2015 05:21:36;0002;PBS_Server;Svr;PBS_Server;Torque Server Version = 3.0.5, loglevel = 0
07/14/2015 05:21:38;0008;PBS_Server;Job;NULL;on_job_exit valid pjob: 0x1dcb770 (substate=10)
07/14/2015 05:21:38;0040;PBS_Server;Svr;tyrone-cluster;Scheduler was sent the command new
07/14/2015 05:22:08;0008;PBS_Server;Job;NULL;on_job_exit valid pjob: 0x1dcb770 (substate=10)
07/14/2015 05:22:09;0040;PBS_Server;Svr;tyrone-cluster;Scheduler was sent the command new
07/14/2015 05:22:38;0008;PBS_Server;Job;NULL;on_job_exit valid pjob: 0x1dcb770 (substate=10)
07/14/2015 05:22:38;0040;PBS_Server;Svr;tyrone-cluster;Scheduler was sent the command new
07/14/2015 05:23:08;0008;PBS_Server;Job;NULL;on_job_exit valid pjob: 0x1dcb770 (substate=10)
07/14/2015 05:23:08;0040;PBS_Server;Svr;tyrone-cluster;Scheduler was sent the command new
07/14/2015 05:23:38;0008;PBS_Server;Job;NULL;on_job_exit valid pjob: 0x1dcb770 (substate=10)
07/14/2015 05:23:39;0040;PBS_Server;Svr;tyrone-cluster;Scheduler was sent the command new
07/14/2015 05:24:08;0008;PBS_Server;Job;NULL;on_job_exit valid pjob: 0x1dcb770 (substate=10)
07/14/2015 05:24:09;0040;PBS_Server;Svr;tyrone-cluster;Scheduler was sent the command new
07/14/2015 05:24:38;0008;PBS_Server;Job;NULL;on_job_exit valid pjob: 0x1dcb770 (substate=10)
07/14/2015 05:24:38;0040;PBS_Server;Svr;tyrone-cluster;Scheduler was sent the command new
07/14/2015 05:25:08;0008;PBS_Server;Job;NULL;on_job_exit valid pjob: 0x1dcb770 (substate=10)
07/14/2015 05:25:09;0040;PBS_Server;Svr;tyrone-cluster;Scheduler was sent the command new
07/14/2015 05:25:38;0008;PBS_Server;Job;NULL;on_job_exit valid pjob: 0x1dcb770 (substate=10)
07/14/2015 05:25:38;0040;PBS_Server;Svr;tyrone-cluster;Scheduler was sent the command new
07/14/2015 05:26:08;0008;PBS_Server;Job;NULL;on_job_exit valid pjob: 0x1dcb770 (substate=10)
07/14/2015 05:26:08;0040;PBS_Server;Svr;tyrone-cluster;Scheduler was sent the command new
07/14/2015 05:26:36;0002;PBS_Server;Svr;PBS_Server;Torque Server Version = 3.0.5, loglevel = 0
07/14/2015 05:26:38;0008;PBS_Server;Job;NULL;on_job_exit valid pjob: 0x1dcb770 (substate=10)
07/14/2015 05:26:39;0040;PBS_Server;Svr;tyrone-cluster;Scheduler was sent the command new
07/14/2015 05:27:08;0008;PBS_Server;Job;NULL;on_job_exit valid pjob: 0x1dcb770 (substate=10)
07/14/2015 05:27:08;0040;PBS_Server;Svr;tyrone-cluster;Scheduler was sent the command new
07/14/2015 05:27:38;0008;PBS_Server;Job;NULL;on_job_exit valid pjob: 0x1dcb770 (substate=10)
07/14/2015 05:27:38;0040;PBS_Server;Svr;tyrone-cluster;Scheduler was sent the command new
07/14/2015 05:28:08;0008;PBS_Server;Job;NULL;on_job_exit valid pjob: 0x1dcb770 (substate=10)
07/14/2015 05:28:09;0040;PBS_Server;Svr;tyrone-cluster;Scheduler was sent the command new
07/14/2015 05:28:38;0008;PBS_Server;Job;NULL;on_job_exit valid pjob: 0x1dcb770 (substate=10)
07/14/2015 05:28:39;0040;PBS_Server;Svr;tyrone-cluster;Scheduler was sent the command new
07/14/2015 05:29:08;0008;PBS_Server;Job;NULL;on_job_exit valid pjob: 0x1dcb770 (substate=10)
07/14/2015 05:29:09;0040;PBS_Server;Svr;tyrone-cluster;Scheduler was sent the command new
07/14/2015 05:29:38;0008;PBS_Server;Job;NULL;on_job_exit valid pjob: 0x1dcb770 (substate=10)
07/14/2015 05:29:39;0040;PBS_Server;Svr;tyrone-cluster;Scheduler was sent the command new
07/14/2015 05:30:08;0008;PBS_Server;Job;NULL;on_job_exit valid pjob: 0x1dcb770 (substate=10)
07/14/2015 05:30:08;0040;PBS_Server;Svr;tyrone-cluster;Scheduler was sent the command new
07/14/2015 05:30:38;0008;PBS_Server;Job;NULL;on_job_exit valid pjob: 0x1dcb770 (substate=10)
07/14/2015 05:30:38;0040;PBS_Server;Svr;tyrone-cluster;Scheduler was sent the command new
07/14/2015 05:31:08;0008;PBS_Server;Job;NULL;on_job_exit valid pjob: 0x1dcb770 (substate=10)
07/14/2015 05:31:09;0040;PBS_Server;Svr;tyrone-cluster;Scheduler was sent the command new
07/14/2015 05:31:36;0002;PBS_Server;Svr;PBS_Server;Torque Server Version = 3.0.5, loglevel = 0
07/14/2015 05:31:38;0008;PBS_Server;Job;NULL;on_job_exit valid pjob: 0x1dcb770 (substate=10)
07/14/2015 05:31:39;0040;PBS_Server;Svr;tyrone-cluster;Scheduler was sent the command new
07/14/2015 05:32:08;0008;PBS_Server;Job;NULL;on_job_exit valid pjob: 0x1dcb770 (substate=10)
07/14/2015 05:32:08;0040;PBS_Server;Svr;tyrone-cluster;Scheduler was sent the command new
07/14/2015 05:32:38;0008;PBS_Server;Job;NULL;on_job_exit valid pjob: 0x1dcb770 (substate=10)
07/14/2015 05:32:39;0040;PBS_Server;Svr;tyrone-cluster;Scheduler was sent the command new
07/14/2015 05:33:08;0008;PBS_Server;Job;NULL;on_job_exit valid pjob: 0x1dcb770 (substate=10)
07/14/2015 05:33:08;0040;PBS_Server;Svr;tyrone-cluster;Scheduler was sent the command new
07/14/2015 05:33:38;0008;PBS_Server;Job;NULL;on_job_exit valid pjob: 0x1dcb770 (substate=10)
07/14/2015 05:33:38;0040;PBS_Server;Svr;tyrone-cluster;Scheduler was sent the command new
07/14/2015 05:34:08;0008;PBS_Server;Job;NULL;on_job_exit valid pjob: 0x1dcb770 (substate=10)
07/14/2015 05:34:09;0040;PBS_Server;Svr;tyrone-cluster;Scheduler was sent the command new
07/14/2015 05:34:38;0008;PBS_Server;Job;NULL;on_job_exit valid pjob: 0x1dcb770 (substate=10)
07/14/2015 05:34:39;0040;PBS_Server;Svr;tyrone-cluster;Scheduler was sent the command new
07/14/2015 05:35:08;0008;PBS_Server;Job;NULL;on_job_exit valid pjob: 0x1dcb770 (substate=10)
07/14/2015 05:35:08;0040;PBS_Server;Svr;tyrone-cluster;Scheduler was sent the command new
07/14/2015 05:35:38;0008;PBS_Server;Job;NULL;on_job_exit valid pjob: 0x1dcb770 (substate=10)
07/14/2015 05:35:39;0040;PBS_Server;Svr;tyrone-cluster;Scheduler was sent the command new
07/14/2015 05:36:08;0008;PBS_Server;Job;NULL;on_job_exit valid pjob: 0x1dcb770 (substate=10)
07/14/2015 05:36:08;0040;PBS_Server;Svr;tyrone-cluster;Scheduler was sent the command new
07/14/2015 05:36:36;0002;PBS_Server;Svr;PBS_Server;Torque Server Version = 3.0.5, loglevel = 0
07/14/2015 05:36:38;0008;PBS_Server;Job;NULL;on_job_exit valid pjob: 0x1dcb770 (substate=10)
07/14/2015 05:36:39;0040;PBS_Server;Svr;tyrone-cluster;Scheduler was sent the command new
07/14/2015 05:37:08;0008;PBS_Server;Job;NULL;on_job_exit valid pjob: 0x1dcb770 (substate=10)
07/14/2015 05:37:09;0040;PBS_Server;Svr;tyrone-cluster;Scheduler was sent the command new
07/14/2015 05:37:38;0008;PBS_Server;Job;NULL;on_job_exit valid pjob: 0x1dcb770 (substate=10)
07/14/2015 05:37:38;0040;PBS_Server;Svr;tyrone-cluster;Scheduler was sent the command new
07/14/2015 05:38:08;0008;PBS_Server;Job;NULL;on_job_exit valid pjob: 0x1dcb770 (substate=10)
07/14/2015 05:38:08;0040;PBS_Server;Svr;tyrone-cluster;Scheduler was sent the command new
07/14/2015 05:38:38;0008;PBS_Server;Job;NULL;on_job_exit valid pjob: 0x1dcb770 (substate=10)
07/14/2015 05:38:39;0040;PBS_Server;Svr;tyrone-cluster;Scheduler was sent the command new
07/14/2015 05:39:08;0008;PBS_Server;Job;NULL;on_job_exit valid pjob: 0x1dcb770 (substate=10)
07/14/2015 05:39:09;0040;PBS_Server;Svr;tyrone-cluster;Scheduler was sent the command new
07/14/2015 05:39:38;0008;PBS_Server;Job;NULL;on_job_exit valid pjob: 0x1dcb770 (substate=10)
07/14/2015 05:39:38;0040;PBS_Server;Svr;tyrone-cluster;Scheduler was sent the command new
07/14/2015 05:40:08;0008;PBS_Server;Job;NULL;on_job_exit valid pjob: 0x1dcb770 (substate=10)
07/14/2015 05:40:09;0040;PBS_Server;Svr;tyrone-cluster;Scheduler was sent the command new
07/14/2015 05:40:38;0008;PBS_Server;Job;NULL;on_job_exit valid pjob: 0x1dcb770 (substate=10)
07/14/2015 05:40:38;0040;PBS_Server;Svr;tyrone-cluster;Scheduler was sent the command new
07/14/2015 05:41:08;0008;PBS_Server;Job;NULL;on_job_exit valid pjob: 0x1dcb770 (substate=10)
07/14/2015 05:41:08;0040;PBS_Server;Svr;tyrone-cluster;Scheduler was sent the command new
07/14/2015 05:41:36;0002;PBS_Server;Svr;PBS_Server;Torque Server Version = 3.0.5, loglevel = 0
07/14/2015 05:41:38;0008;PBS_Server;Job;NULL;on_job_exit valid pjob: 0x1dcb770 (substate=10)
07/14/2015 05:41:39;0040;PBS_Server;Svr;tyrone-cluster;Scheduler was sent the command new
07/14/2015 05:42:08;0008;PBS_Server;Job;NULL;on_job_exit valid pjob: 0x1dcb770 (substate=10)
07/14/2015 05:42:09;0040;PBS_Server;Svr;tyrone-cluster;Scheduler was sent the command new
07/14/2015 05:42:38;0008;PBS_Server;Job;NULL;on_job_exit valid pjob: 0x1dcb770 (substate=10)
07/14/2015 05:42:38;0040;PBS_Server;Svr;tyrone-cluster;Scheduler was sent the command new
07/14/2015 05:43:08;0008;PBS_Server;Job;NULL;on_job_exit valid pjob: 0x1dcb770 (substate=10)
07/14/2015 05:43:09;0040;PBS_Server;Svr;tyrone-cluster;Scheduler was sent the command new
07/14/2015 05:43:38;0008;PBS_Server;Job;NULL;on_job_exit valid pjob: 0x1dcb770 (substate=10)
07/14/2015 05:43:38;0040;PBS_Server;Svr;tyrone-cluster;Scheduler was sent the command new
07/14/2015 05:44:08;0008;PBS_Server;Job;NULL;on_job_exit valid pjob: 0x1dcb770 (substate=10)
07/14/2015 05:44:08;0040;PBS_Server;Svr;tyrone-cluster;Scheduler was sent the command new
07/14/2015 05:44:38;0008;PBS_Server;Job;NULL;on_job_exit valid pjob: 0x1dcb770 (substate=10)
07/14/2015 05:44:39;0040;PBS_Server;Svr;tyrone-cluster;Scheduler was sent the command new
07/14/2015 05:45:08;0008;PBS_Server;Job;NULL;on_job_exit valid pjob: 0x1dcb770 (substate=10)
07/14/2015 05:45:08;0040;PBS_Server;Svr;tyrone-cluster;Scheduler was sent the command new
07/14/2015 05:45:38;0008;PBS_Server;Job;NULL;on_job_exit valid pjob: 0x1dcb770 (substate=10)
07/14/2015 05:45:38;0040;PBS_Server;Svr;tyrone-cluster;Scheduler was sent the command new
07/14/2015 05:46:08;0008;PBS_Server;Job;NULL;on_job_exit valid pjob: 0x1dcb770 (substate=10)
07/14/2015 05:46:09;0040;PBS_Server;Svr;tyrone-cluster;Scheduler was sent the command new
07/14/2015 05:46:36;0002;PBS_Server;Svr;PBS_Server;Torque Server Version = 3.0.5, loglevel = 0
07/14/2015 05:46:38;0008;PBS_Server;Job;NULL;on_job_exit valid pjob: 0x1dcb770 (substate=10)
07/14/2015 05:46:38;0040;PBS_Server;Svr;tyrone-cluster;Scheduler was sent the command new
07/14/2015 05:47:08;0008;PBS_Server;Job;NULL;on_job_exit valid pjob: 0x1dcb770 (substate=10)
07/14/2015 05:47:08;0040;PBS_Server;Svr;tyrone-cluster;Scheduler was sent the command new
07/14/2015 05:47:38;0008;PBS_Server;Job;NULL;on_job_exit valid pjob: 0x1dcb770 (substate=10)
07/14/2015 05:47:39;0040;PBS_Server;Svr;tyrone-cluster;Scheduler was sent the command new
07/14/2015 05:48:08;0008;PBS_Server;Job;NULL;on_job_exit valid pjob: 0x1dcb770 (substate=10)
07/14/2015 05:48:08;0040;PBS_Server;Svr;tyrone-cluster;Scheduler was sent the command new
07/14/2015 05:48:38;0008;PBS_Server;Job;NULL;on_job_exit valid pjob: 0x1dcb770 (substate=10)
07/14/2015 05:48:38;0040;PBS_Server;Svr;tyrone-cluster;Scheduler was sent the command new
07/14/2015 05:49:08;0008;PBS_Server;Job;NULL;on_job_exit valid pjob: 0x1dcb770 (substate=10)
07/14/2015 05:49:09;0040;PBS_Server;Svr;tyrone-cluster;Scheduler was sent the command new
07/14/2015 05:49:38;0008;PBS_Server;Job;NULL;on_job_exit valid pjob: 0x1dcb770 (substate=10)
07/14/2015 05:49:39;0040;PBS_Server;Svr;tyrone-cluster;Scheduler was sent the command new
07/14/2015 05:50:08;0008;PBS_Server;Job;NULL;on_job_exit valid pjob: 0x1dcb770 (substate=10)
07/14/2015 05:50:08;0040;PBS_Server;Svr;tyrone-cluster;Scheduler was sent the command new
07/14/2015 05:50:38;0008;PBS_Server;Job;NULL;on_job_exit valid pjob: 0x1dcb770 (substate=10)
07/14/2015 05:50:39;0040;PBS_Server;Svr;tyrone-cluster;Scheduler was sent the command new
07/14/2015 05:51:08;0008;PBS_Server;Job;NULL;on_job_exit valid pjob: 0x1dcb770 (substate=10)
07/14/2015 05:51:08;0040;PBS_Server;Svr;tyrone-cluster;Scheduler was sent the command new
07/14/2015 05:51:36;0002;PBS_Server;Svr;PBS_Server;Torque Server Version = 3.0.5, loglevel = 0
07/14/2015 05:51:38;0008;PBS_Server;Job;NULL;on_job_exit valid pjob: 0x1dcb770 (substate=10)
07/14/2015 05:51:38;0040;PBS_Server;Svr;tyrone-cluster;Scheduler was sent the command new
07/14/2015 05:52:08;0008;PBS_Server;Job;NULL;on_job_exit valid pjob: 0x1dcb770 (substate=10)
07/14/2015 05:52:09;0040;PBS_Server;Svr;tyrone-cluster;Scheduler was sent the command new
07/14/2015 05:52:38;0008;PBS_Server;Job;NULL;on_job_exit valid pjob: 0x1dcb770 (substate=10)
07/14/2015 05:52:39;0040;PBS_Server;Svr;tyrone-cluster;Scheduler was sent the command new
07/14/2015 05:53:08;0008;PBS_Server;Job;NULL;on_job_exit valid pjob: 0x1dcb770 (substate=10)
07/14/2015 05:53:08;0040;PBS_Server;Svr;tyrone-cluster;Scheduler was sent the command new
07/14/2015 05:53:38;0008;PBS_Server;Job;NULL;on_job_exit valid pjob: 0x1dcb770 (substate=10)
07/14/2015 05:53:39;0040;PBS_Server;Svr;tyrone-cluster;Scheduler was sent the command new
07/14/2015 05:54:08;0008;PBS_Server;Job;NULL;on_job_exit valid pjob: 0x1dcb770 (substate=10)
07/14/2015 05:54:08;0040;PBS_Server;Svr;tyrone-cluster;Scheduler was sent the command new
07/14/2015 05:54:38;0008;PBS_Server;Job;NULL;on_job_exit valid pjob: 0x1dcb770 (substate=10)
07/14/2015 05:54:38;0040;PBS_Server;Svr;tyrone-cluster;Scheduler was sent the command new
07/14/2015 05:55:08;0008;PBS_Server;Job;NULL;on_job_exit valid pjob: 0x1dcb770 (substate=10)
07/14/2015 05:55:09;0040;PBS_Server;Svr;tyrone-cluster;Scheduler was sent the command new
07/14/2015 05:55:38;0008;PBS_Server;Job;NULL;on_job_exit valid pjob: 0x1dcb770 (substate=10)
07/14/2015 05:55:38;0040;PBS_Server;Svr;tyrone-cluster;Scheduler was sent the command new
07/14/2015 05:56:08;0008;PBS_Server;Job;NULL;on_job_exit valid pjob: 0x1dcb770 (substate=10)
07/14/2015 05:56:08;0040;PBS_Server;Svr;tyrone-cluster;Scheduler was sent the command new
07/14/2015 05:56:36;0002;PBS_Server;Svr;PBS_Server;Torque Server Version = 3.0.5, loglevel = 0
07/14/2015 05:56:38;0008;PBS_Server;Job;NULL;on_job_exit valid pjob: 0x1dcb770 (substate=10)
07/14/2015 05:56:39;0040;PBS_Server;Svr;tyrone-cluster;Scheduler was sent the command new
07/14/2015 05:57:08;0008;PBS_Server;Job;NULL;on_job_exit valid pjob: 0x1dcb770 (substate=10)
07/14/2015 05:57:08;0040;PBS_Server;Svr;tyrone-cluster;Scheduler was sent the command new
07/14/2015 05:57:38;0008;PBS_Server;Job;NULL;on_job_exit valid pjob: 0x1dcb770 (substate=10)
07/14/2015 05:57:38;0040;PBS_Server;Svr;tyrone-cluster;Scheduler was sent the command new
07/14/2015 05:58:08;0008;PBS_Server;Job;NULL;on_job_exit valid pjob: 0x1dcb770 (substate=10)
07/14/2015 05:58:09;0040;PBS_Server;Svr;tyrone-cluster;Scheduler was sent the command new
07/14/2015 05:58:38;0008;PBS_Server;Job;NULL;on_job_exit valid pjob: 0x1dcb770 (substate=10)
07/14/2015 05:58:38;0040;PBS_Server;Svr;tyrone-cluster;Scheduler was sent the command new
07/14/2015 05:59:08;0008;PBS_Server;Job;NULL;on_job_exit valid pjob: 0x1dcb770 (substate=10)
07/14/2015 05:59:08;0040;PBS_Server;Svr;tyrone-cluster;Scheduler was sent the command new
07/14/2015 05:59:38;0008;PBS_Server;Job;NULL;on_job_exit valid pjob: 0x1dcb770 (substate=10)
07/14/2015 05:59:39;0040;PBS_Server;Svr;tyrone-cluster;Scheduler was sent the command new
07/14/2015 06:00:08;0008;PBS_Server;Job;NULL;on_job_exit valid pjob: 0x1dcb770 (substate=10)
07/14/2015 06:00:08;0040;PBS_Server;Svr;tyrone-cluster;Scheduler was sent the command new
07/14/2015 06:00:38;0008;PBS_Server;Job;NULL;on_job_exit valid pjob: 0x1dcb770 (substate=10)
07/14/2015 06:00:38;0040;PBS_Server;Svr;tyrone-cluster;Scheduler was sent the command new
07/14/2015 06:01:08;0008;PBS_Server;Job;NULL;on_job_exit valid pjob: 0x1dcb770 (substate=10)
07/14/2015 06:01:09;0040;PBS_Server;Svr;tyrone-cluster;Scheduler was sent the command new
07/14/2015 06:01:36;0002;PBS_Server;Svr;PBS_Server;Torque Server Version = 3.0.5, loglevel = 0
07/14/2015 06:01:38;0008;PBS_Server;Job;NULL;on_job_exit valid pjob: 0x1dcb770 (substate=10)
07/14/2015 06:01:38;0040;PBS_Server;Svr;tyrone-cluster;Scheduler was sent the command new
07/14/2015 06:02:08;0008;PBS_Server;Job;NULL;on_job_exit valid pjob: 0x1dcb770 (substate=10)
07/14/2015 06:02:08;0040;PBS_Server;Svr;tyrone-cluster;Scheduler was sent the command new
07/14/2015 06:02:38;0008;PBS_Server;Job;NULL;on_job_exit valid pjob: 0x1dcb770 (substate=10)
07/14/2015 06:02:39;0040;PBS_Server;Svr;tyrone-cluster;Scheduler was sent the command new
07/14/2015 06:03:08;0008;PBS_Server;Job;NULL;on_job_exit valid pjob: 0x1dcb770 (substate=10)
07/14/2015 06:03:09;0040;PBS_Server;Svr;tyrone-cluster;Scheduler was sent the command new
07/14/2015 06:03:38;0008;PBS_Server;Job;NULL;on_job_exit valid pjob: 0x1dcb770 (substate=10)
07/14/2015 06:03:39;0040;PBS_Server;Svr;tyrone-cluster;Scheduler was sent the command new
07/14/2015 06:04:08;0008;PBS_Server;Job;NULL;on_job_exit valid pjob: 0x1dcb770 (substate=10)
07/14/2015 06:04:09;0040;PBS_Server;Svr;tyrone-cluster;Scheduler was sent the command new
07/14/2015 06:04:38;0008;PBS_Server;Job;NULL;on_job_exit valid pjob: 0x1dcb770 (substate=10)
07/14/2015 06:04:38;0040;PBS_Server;Svr;tyrone-cluster;Scheduler was sent the command new
07/14/2015 06:05:08;0008;PBS_Server;Job;NULL;on_job_exit valid pjob: 0x1dcb770 (substate=10)
07/14/2015 06:05:08;0040;PBS_Server;Svr;tyrone-cluster;Scheduler was sent the command new
07/14/2015 06:05:38;0008;PBS_Server;Job;NULL;on_job_exit valid pjob: 0x1dcb770 (substate=10)
07/14/2015 06:05:39;0040;PBS_Server;Svr;tyrone-cluster;Scheduler was sent the command new
07/14/2015 06:06:08;0008;PBS_Server;Job;NULL;on_job_exit valid pjob: 0x1dcb770 (substate=10)
07/14/2015 06:06:09;0040;PBS_Server;Svr;tyrone-cluster;Scheduler was sent the command new
07/14/2015 06:06:36;0002;PBS_Server;Svr;PBS_Server;Torque Server Version = 3.0.5, loglevel = 0
07/14/2015 06:06:38;0008;PBS_Server;Job;NULL;on_job_exit valid pjob: 0x1dcb770 (substate=10)
07/14/2015 06:06:38;0040;PBS_Server;Svr;tyrone-cluster;Scheduler was sent the command new
07/14/2015 06:07:08;0008;PBS_Server;Job;NULL;on_job_exit valid pjob: 0x1dcb770 (substate=10)
07/14/2015 06:07:09;0040;PBS_Server;Svr;tyrone-cluster;Scheduler was sent the command new
07/14/2015 06:07:38;0008;PBS_Server;Job;NULL;on_job_exit valid pjob: 0x1dcb770 (substate=10)
07/14/2015 06:07:38;0040;PBS_Server;Svr;tyrone-cluster;Scheduler was sent the command new
07/14/2015 06:08:08;0008;PBS_Server;Job;NULL;on_job_exit valid pjob: 0x1dcb770 (substate=10)
07/14/2015 06:08:08;0040;PBS_Server;Svr;tyrone-cluster;Scheduler was sent the command new
07/14/2015 06:08:38;0008;PBS_Server;Job;NULL;on_job_exit valid pjob: 0x1dcb770 (substate=10)
07/14/2015 06:08:39;0040;PBS_Server;Svr;tyrone-cluster;Scheduler was sent the command new
07/14/2015 06:09:08;0008;PBS_Server;Job;NULL;on_job_exit valid pjob: 0x1dcb770 (substate=10)
07/14/2015 06:09:08;0040;PBS_Server;Svr;tyrone-cluster;Scheduler was sent the command new
07/14/2015 06:09:38;0008;PBS_Server;Job;NULL;on_job_exit valid pjob: 0x1dcb770 (substate=10)
07/14/2015 06:09:40;0040;PBS_Server;Svr;tyrone-cluster;Scheduler was sent the command new
07/14/2015 06:10:08;0008;PBS_Server;Job;NULL;on_job_exit valid pjob: 0x1dcb770 (substate=10)
07/14/2015 06:10:09;0040;PBS_Server;Svr;tyrone-cluster;Scheduler was sent the command new
07/14/2015 06:10:38;0008;PBS_Server;Job;NULL;on_job_exit valid pjob: 0x1dcb770 (substate=10)
07/14/2015 06:10:38;0040;PBS_Server;Svr;tyrone-cluster;Scheduler was sent the command new
07/14/2015 06:11:08;0008;PBS_Server;Job;NULL;on_job_exit valid pjob: 0x1dcb770 (substate=10)
07/14/2015 06:11:08;0040;PBS_Server;Svr;tyrone-cluster;Scheduler was sent the command new
07/14/2015 06:11:36;0002;PBS_Server;Svr;PBS_Server;Torque Server Version = 3.0.5, loglevel = 0
07/14/2015 06:11:38;0008;PBS_Server;Job;NULL;on_job_exit valid pjob: 0x1dcb770 (substate=10)
07/14/2015 06:11:39;0040;PBS_Server;Svr;tyrone-cluster;Scheduler was sent the command new
07/14/2015 06:12:08;0008;PBS_Server;Job;NULL;on_job_exit valid pjob: 0x1dcb770 (substate=10)
07/14/2015 06:12:08;0040;PBS_Server;Svr;tyrone-cluster;Scheduler was sent the command new
07/14/2015 06:12:38;0008;PBS_Server;Job;NULL;on_job_exit valid pjob: 0x1dcb770 (substate=10)
07/14/2015 06:12:38;0040;PBS_Server;Svr;tyrone-cluster;Scheduler was sent the command new
07/14/2015 06:13:08;0008;PBS_Server;Job;NULL;on_job_exit valid pjob: 0x1dcb770 (substate=10)
07/14/2015 06:13:09;0040;PBS_Server;Svr;tyrone-cluster;Scheduler was sent the command new
07/14/2015 06:13:38;0008;PBS_Server;Job;NULL;on_job_exit valid pjob: 0x1dcb770 (substate=10)
07/14/2015 06:13:38;0040;PBS_Server;Svr;tyrone-cluster;Scheduler was sent the command new
07/14/2015 06:14:08;0008;PBS_Server;Job;NULL;on_job_exit valid pjob: 0x1dcb770 (substate=10)
07/14/2015 06:14:08;0040;PBS_Server;Svr;tyrone-cluster;Scheduler was sent the command new
07/14/2015 06:14:38;0008;PBS_Server;Job;NULL;on_job_exit valid pjob: 0x1dcb770 (substate=10)
07/14/2015 06:14:39;0040;PBS_Server;Svr;tyrone-cluster;Scheduler was sent the command new
07/14/2015 06:15:08;0008;PBS_Server;Job;NULL;on_job_exit valid pjob: 0x1dcb770 (substate=10)
07/14/2015 06:15:08;0040;PBS_Server;Svr;tyrone-cluster;Scheduler was sent the command new
07/14/2015 06:15:38;0008;PBS_Server;Job;NULL;on_job_exit valid pjob: 0x1dcb770 (substate=10)
07/14/2015 06:15:38;0040;PBS_Server;Svr;tyrone-cluster;Scheduler was sent the command new
07/14/2015 06:16:08;0008;PBS_Server;Job;NULL;on_job_exit valid pjob: 0x1dcb770 (substate=10)
07/14/2015 06:16:09;0040;PBS_Server;Svr;tyrone-cluster;Scheduler was sent the command new
07/14/2015 06:16:36;0002;PBS_Server;Svr;PBS_Server;Torque Server Version = 3.0.5, loglevel = 0
07/14/2015 06:16:38;0008;PBS_Server;Job;NULL;on_job_exit valid pjob: 0x1dcb770 (substate=10)
07/14/2015 06:16:38;0040;PBS_Server;Svr;tyrone-cluster;Scheduler was sent the command new
07/14/2015 06:17:08;0008;PBS_Server;Job;NULL;on_job_exit valid pjob: 0x1dcb770 (substate=10)
07/14/2015 06:17:08;0040;PBS_Server;Svr;tyrone-cluster;Scheduler was sent the command new
07/14/2015 06:17:38;0008;PBS_Server;Job;NULL;on_job_exit valid pjob: 0x1dcb770 (substate=10)
07/14/2015 06:17:39;0040;PBS_Server;Svr;tyrone-cluster;Scheduler was sent the command new
07/14/2015 06:18:08;0008;PBS_Server;Job;NULL;on_job_exit valid pjob: 0x1dcb770 (substate=10)
07/14/2015 06:18:08;0040;PBS_Server;Svr;tyrone-cluster;Scheduler was sent the command new
07/14/2015 06:18:38;0008;PBS_Server;Job;NULL;on_job_exit valid pjob: 0x1dcb770 (substate=10)
07/14/2015 06:18:38;0040;PBS_Server;Svr;tyrone-cluster;Scheduler was sent the command new
07/14/2015 06:19:08;0008;PBS_Server;Job;NULL;on_job_exit valid pjob: 0x1dcb770 (substate=10)
07/14/2015 06:19:09;0040;PBS_Server;Svr;tyrone-cluster;Scheduler was sent the command new
07/14/2015 06:19:38;0008;PBS_Server;Job;NULL;on_job_exit valid pjob: 0x1dcb770 (substate=10)
07/14/2015 06:19:38;0040;PBS_Server;Svr;tyrone-cluster;Scheduler was sent the command new
07/14/2015 06:20:08;0008;PBS_Server;Job;NULL;on_job_exit valid pjob: 0x1dcb770 (substate=10)
07/14/2015 06:20:08;0040;PBS_Server;Svr;tyrone-cluster;Scheduler was sent the command new
07/14/2015 06:20:38;0008;PBS_Server;Job;NULL;on_job_exit valid pjob: 0x1dcb770 (substate=10)
07/14/2015 06:20:39;0040;PBS_Server;Svr;tyrone-cluster;Scheduler was sent the command new
07/14/2015 06:21:08;0008;PBS_Server;Job;NULL;on_job_exit valid pjob: 0x1dcb770 (substate=10)
07/14/2015 06:21:08;0040;PBS_Server;Svr;tyrone-cluster;Scheduler was sent the command new
07/14/2015 06:21:36;0002;PBS_Server;Svr;PBS_Server;Torque Server Version = 3.0.5, loglevel = 0
07/14/2015 06:21:38;0008;PBS_Server;Job;NULL;on_job_exit valid pjob: 0x1dcb770 (substate=10)
07/14/2015 06:21:38;0040;PBS_Server;Svr;tyrone-cluster;Scheduler was sent the command new
07/14/2015 06:22:08;0008;PBS_Server;Job;NULL;on_job_exit valid pjob: 0x1dcb770 (substate=10)
07/14/2015 06:22:09;0040;PBS_Server;Svr;tyrone-cluster;Scheduler was sent the command new
07/14/2015 06:22:38;0008;PBS_Server;Job;NULL;on_job_exit valid pjob: 0x1dcb770 (substate=10)
07/14/2015 06:22:38;0040;PBS_Server;Svr;tyrone-cluster;Scheduler was sent the command new
07/14/2015 06:23:08;0008;PBS_Server;Job;NULL;on_job_exit valid pjob: 0x1dcb770 (substate=10)
07/14/2015 06:23:08;0040;PBS_Server;Svr;tyrone-cluster;Scheduler was sent the command new
07/14/2015 06:23:38;0008;PBS_Server;Job;NULL;on_job_exit valid pjob: 0x1dcb770 (substate=10)
07/14/2015 06:23:39;0040;PBS_Server;Svr;tyrone-cluster;Scheduler was sent the command new
07/14/2015 06:24:08;0008;PBS_Server;Job;NULL;on_job_exit valid pjob: 0x1dcb770 (substate=10)
07/14/2015 06:24:08;0040;PBS_Server;Svr;tyrone-cluster;Scheduler was sent the command new
07/14/2015 06:24:38;0008;PBS_Server;Job;NULL;on_job_exit valid pjob: 0x1dcb770 (substate=10)
07/14/2015 06:24:38;0040;PBS_Server;Svr;tyrone-cluster;Scheduler was sent the command new
07/14/2015 06:25:08;0008;PBS_Server;Job;NULL;on_job_exit valid pjob: 0x1dcb770 (substate=10)
07/14/2015 06:25:09;0040;PBS_Server;Svr;tyrone-cluster;Scheduler was sent the command new
07/14/2015 06:25:38;0008;PBS_Server;Job;NULL;on_job_exit valid pjob: 0x1dcb770 (substate=10)
07/14/2015 06:25:38;0040;PBS_Server;Svr;tyrone-cluster;Scheduler was sent the command new
07/14/2015 06:26:08;0008;PBS_Server;Job;NULL;on_job_exit valid pjob: 0x1dcb770 (substate=10)
07/14/2015 06:26:10;0040;PBS_Server;Svr;tyrone-cluster;Scheduler was sent the command new
07/14/2015 06:26:36;0002;PBS_Server;Svr;PBS_Server;Torque Server Version = 3.0.5, loglevel = 0
07/14/2015 06:26:38;0008;PBS_Server;Job;NULL;on_job_exit valid pjob: 0x1dcb770 (substate=10)
07/14/2015 06:26:39;0040;PBS_Server;Svr;tyrone-cluster;Scheduler was sent the command new
07/14/2015 06:27:08;0008;PBS_Server;Job;NULL;on_job_exit valid pjob: 0x1dcb770 (substate=10)
07/14/2015 06:27:08;0040;PBS_Server;Svr;tyrone-cluster;Scheduler was sent the command new
07/14/2015 06:27:38;0008;PBS_Server;Job;NULL;on_job_exit valid pjob: 0x1dcb770 (substate=10)
07/14/2015 06:27:38;0040;PBS_Server;Svr;tyrone-cluster;Scheduler was sent the command new
07/14/2015 06:28:08;0008;PBS_Server;Job;NULL;on_job_exit valid pjob: 0x1dcb770 (substate=10)
07/14/2015 06:28:09;0040;PBS_Server;Svr;tyrone-cluster;Scheduler was sent the command new
07/14/2015 06:28:38;0008;PBS_Server;Job;NULL;on_job_exit valid pjob: 0x1dcb770 (substate=10)
07/14/2015 06:28:38;0040;PBS_Server;Svr;tyrone-cluster;Scheduler was sent the command new
07/14/2015 06:29:08;0008;PBS_Server;Job;NULL;on_job_exit valid pjob: 0x1dcb770 (substate=10)
07/14/2015 06:29:08;0040;PBS_Server;Svr;tyrone-cluster;Scheduler was sent the command new
07/14/2015 06:29:38;0008;PBS_Server;Job;NULL;on_job_exit valid pjob: 0x1dcb770 (substate=10)
07/14/2015 06:29:39;0040;PBS_Server;Svr;tyrone-cluster;Scheduler was sent the command new
07/14/2015 06:30:08;0008;PBS_Server;Job;NULL;on_job_exit valid pjob: 0x1dcb770 (substate=10)
07/14/2015 06:30:08;0040;PBS_Server;Svr;tyrone-cluster;Scheduler was sent the command new
07/14/2015 06:30:38;0008;PBS_Server;Job;NULL;on_job_exit valid pjob: 0x1dcb770 (substate=10)
07/14/2015 06:30:38;0040;PBS_Server;Svr;tyrone-cluster;Scheduler was sent the command new
07/14/2015 06:31:08;0008;PBS_Server;Job;NULL;on_job_exit valid pjob: 0x1dcb770 (substate=10)
07/14/2015 06:31:09;0040;PBS_Server;Svr;tyrone-cluster;Scheduler was sent the command new
07/14/2015 06:31:36;0002;PBS_Server;Svr;PBS_Server;Torque Server Version = 3.0.5, loglevel = 0
07/14/2015 06:31:38;0008;PBS_Server;Job;NULL;on_job_exit valid pjob: 0x1dcb770 (substate=10)
07/14/2015 06:31:38;0040;PBS_Server;Svr;tyrone-cluster;Scheduler was sent the command new
07/14/2015 06:32:08;0008;PBS_Server;Job;NULL;on_job_exit valid pjob: 0x1dcb770 (substate=10)
07/14/2015 06:32:08;0040;PBS_Server;Svr;tyrone-cluster;Scheduler was sent the command new
07/14/2015 06:32:38;0008;PBS_Server;Job;NULL;on_job_exit valid pjob: 0x1dcb770 (substate=10)
07/14/2015 06:32:39;0040;PBS_Server;Svr;tyrone-cluster;Scheduler was sent the command new
07/14/2015 06:33:08;0008;PBS_Server;Job;NULL;on_job_exit valid pjob: 0x1dcb770 (substate=10)
07/14/2015 06:33:08;0040;PBS_Server;Svr;tyrone-cluster;Scheduler was sent the command new
07/14/2015 06:33:38;0008;PBS_Server;Job;NULL;on_job_exit valid pjob: 0x1dcb770 (substate=10)
07/14/2015 06:33:38;0040;PBS_Server;Svr;tyrone-cluster;Scheduler was sent the command new
07/14/2015 06:34:08;0008;PBS_Server;Job;NULL;on_job_exit valid pjob: 0x1dcb770 (substate=10)
07/14/2015 06:34:09;0040;PBS_Server;Svr;tyrone-cluster;Scheduler was sent the command new
07/14/2015 06:34:38;0008;PBS_Server;Job;NULL;on_job_exit valid pjob: 0x1dcb770 (substate=10)
07/14/2015 06:34:38;0040;PBS_Server;Svr;tyrone-cluster;Scheduler was sent the command new
07/14/2015 06:35:08;0008;PBS_Server;Job;NULL;on_job_exit valid pjob: 0x1dcb770 (substate=10)
07/14/2015 06:35:08;0040;PBS_Server;Svr;tyrone-cluster;Scheduler was sent the command new
07/14/2015 06:35:38;0008;PBS_Server;Job;NULL;on_job_exit valid pjob: 0x1dcb770 (substate=10)
07/14/2015 06:35:39;0040;PBS_Server;Svr;tyrone-cluster;Scheduler was sent the command new
07/14/2015 06:36:08;0008;PBS_Server;Job;NULL;on_job_exit valid pjob: 0x1dcb770 (substate=10)
07/14/2015 06:36:08;0040;PBS_Server;Svr;tyrone-cluster;Scheduler was sent the command new
07/14/2015 06:36:36;0002;PBS_Server;Svr;PBS_Server;Torque Server Version = 3.0.5, loglevel = 0
07/14/2015 06:36:38;0008;PBS_Server;Job;NULL;on_job_exit valid pjob: 0x1dcb770 (substate=10)
07/14/2015 06:36:38;0040;PBS_Server;Svr;tyrone-cluster;Scheduler was sent the command new
07/14/2015 06:37:08;0008;PBS_Server;Job;NULL;on_job_exit valid pjob: 0x1dcb770 (substate=10)
07/14/2015 06:37:09;0040;PBS_Server;Svr;tyrone-cluster;Scheduler was sent the command new
07/14/2015 06:37:38;0008;PBS_Server;Job;NULL;on_job_exit valid pjob: 0x1dcb770 (substate=10)
07/14/2015 06:37:38;0040;PBS_Server;Svr;tyrone-cluster;Scheduler was sent the command new
07/14/2015 06:38:08;0008;PBS_Server;Job;NULL;on_job_exit valid pjob: 0x1dcb770 (substate=10)
07/14/2015 06:38:08;0040;PBS_Server;Svr;tyrone-cluster;Scheduler was sent the command new
07/14/2015 06:38:38;0008;PBS_Server;Job;NULL;on_job_exit valid pjob: 0x1dcb770 (substate=10)
07/14/2015 06:38:39;0040;PBS_Server;Svr;tyrone-cluster;Scheduler was sent the command new
07/14/2015 06:39:08;0008;PBS_Server;Job;NULL;on_job_exit valid pjob: 0x1dcb770 (substate=10)
07/14/2015 06:39:08;0040;PBS_Server;Svr;tyrone-cluster;Scheduler was sent the command new
07/14/2015 06:39:38;0008;PBS_Server;Job;NULL;on_job_exit valid pjob: 0x1dcb770 (substate=10)
07/14/2015 06:39:38;0040;PBS_Server;Svr;tyrone-cluster;Scheduler was sent the command new
07/14/2015 06:40:08;0008;PBS_Server;Job;NULL;on_job_exit valid pjob: 0x1dcb770 (substate=10)
07/14/2015 06:40:09;0040;PBS_Server;Svr;tyrone-cluster;Scheduler was sent the command new
07/14/2015 06:40:38;0008;PBS_Server;Job;NULL;on_job_exit valid pjob: 0x1dcb770 (substate=10)
07/14/2015 06:40:38;0040;PBS_Server;Svr;tyrone-cluster;Scheduler was sent the command new
07/14/2015 06:41:08;0008;PBS_Server;Job;NULL;on_job_exit valid pjob: 0x1dcb770 (substate=10)
07/14/2015 06:41:10;0040;PBS_Server;Svr;tyrone-cluster;Scheduler was sent the command new
07/14/2015 06:41:36;0002;PBS_Server;Svr;PBS_Server;Torque Server Version = 3.0.5, loglevel = 0
07/14/2015 06:41:38;0008;PBS_Server;Job;NULL;on_job_exit valid pjob: 0x1dcb770 (substate=10)
07/14/2015 06:41:39;0040;PBS_Server;Svr;tyrone-cluster;Scheduler was sent the command new
07/14/2015 06:42:08;0008;PBS_Server;Job;NULL;on_job_exit valid pjob: 0x1dcb770 (substate=10)
07/14/2015 06:42:08;0040;PBS_Server;Svr;tyrone-cluster;Scheduler was sent the command new
07/14/2015 06:42:38;0008;PBS_Server;Job;NULL;on_job_exit valid pjob: 0x1dcb770 (substate=10)
07/14/2015 06:42:38;0040;PBS_Server;Svr;tyrone-cluster;Scheduler was sent the command new
07/14/2015 06:43:08;0008;PBS_Server;Job;NULL;on_job_exit valid pjob: 0x1dcb770 (substate=10)
07/14/2015 06:43:09;0040;PBS_Server;Svr;tyrone-cluster;Scheduler was sent the command new
07/14/2015 06:43:38;0008;PBS_Server;Job;NULL;on_job_exit valid pjob: 0x1dcb770 (substate=10)
07/14/2015 06:43:38;0040;PBS_Server;Svr;tyrone-cluster;Scheduler was sent the command new
07/14/2015 06:44:08;0008;PBS_Server;Job;NULL;on_job_exit valid pjob: 0x1dcb770 (substate=10)
07/14/2015 06:44:08;0040;PBS_Server;Svr;tyrone-cluster;Scheduler was sent the command new
07/14/2015 06:44:38;0008;PBS_Server;Job;NULL;on_job_exit valid pjob: 0x1dcb770 (substate=10)
07/14/2015 06:44:39;0040;PBS_Server;Svr;tyrone-cluster;Scheduler was sent the command new
07/14/2015 06:45:08;0008;PBS_Server;Job;NULL;on_job_exit valid pjob: 0x1dcb770 (substate=10)
07/14/2015 06:45:09;0040;PBS_Server;Svr;tyrone-cluster;Scheduler was sent the command new
07/14/2015 06:45:38;0008;PBS_Server;Job;NULL;on_job_exit valid pjob: 0x1dcb770 (substate=10)
07/14/2015 06:45:38;0040;PBS_Server;Svr;tyrone-cluster;Scheduler was sent the command new
07/14/2015 06:46:08;0008;PBS_Server;Job;NULL;on_job_exit valid pjob: 0x1dcb770 (substate=10)
07/14/2015 06:46:09;0040;PBS_Server;Svr;tyrone-cluster;Scheduler was sent the command new
07/14/2015 06:46:36;0002;PBS_Server;Svr;PBS_Server;Torque Server Version = 3.0.5, loglevel = 0
07/14/2015 06:46:38;0008;PBS_Server;Job;NULL;on_job_exit valid pjob: 0x1dcb770 (substate=10)
07/14/2015 06:46:38;0040;PBS_Server;Svr;tyrone-cluster;Scheduler was sent the command new
07/14/2015 06:47:08;0008;PBS_Server;Job;NULL;on_job_exit valid pjob: 0x1dcb770 (substate=10)
07/14/2015 06:47:08;0040;PBS_Server;Svr;tyrone-cluster;Scheduler was sent the command new
07/14/2015 06:47:38;0008;PBS_Server;Job;NULL;on_job_exit valid pjob: 0x1dcb770 (substate=10)
07/14/2015 06:47:39;0040;PBS_Server;Svr;tyrone-cluster;Scheduler was sent the command new
07/14/2015 06:48:08;0008;PBS_Server;Job;NULL;on_job_exit valid pjob: 0x1dcb770 (substate=10)
07/14/2015 06:48:08;0040;PBS_Server;Svr;tyrone-cluster;Scheduler was sent the command new
07/14/2015 06:48:38;0008;PBS_Server;Job;NULL;on_job_exit valid pjob: 0x1dcb770 (substate=10)
07/14/2015 06:48:38;0040;PBS_Server;Svr;tyrone-cluster;Scheduler was sent the command new
07/14/2015 06:49:08;0008;PBS_Server;Job;NULL;on_job_exit valid pjob: 0x1dcb770 (substate=10)
07/14/2015 06:49:09;0040;PBS_Server;Svr;tyrone-cluster;Scheduler was sent the command new
07/14/2015 06:49:38;0008;PBS_Server;Job;NULL;on_job_exit valid pjob: 0x1dcb770 (substate=10)
07/14/2015 06:49:39;0040;PBS_Server;Svr;tyrone-cluster;Scheduler was sent the command new
07/14/2015 06:50:08;0008;PBS_Server;Job;NULL;on_job_exit valid pjob: 0x1dcb770 (substate=10)
07/14/2015 06:50:08;0040;PBS_Server;Svr;tyrone-cluster;Scheduler was sent the command new
07/14/2015 06:50:38;0008;PBS_Server;Job;NULL;on_job_exit valid pjob: 0x1dcb770 (substate=10)
07/14/2015 06:50:39;0040;PBS_Server;Svr;tyrone-cluster;Scheduler was sent the command new
07/14/2015 06:51:08;0008;PBS_Server;Job;NULL;on_job_exit valid pjob: 0x1dcb770 (substate=10)
07/14/2015 06:51:08;0040;PBS_Server;Svr;tyrone-cluster;Scheduler was sent the command new
07/14/2015 06:51:36;0002;PBS_Server;Svr;PBS_Server;Torque Server Version = 3.0.5, loglevel = 0
07/14/2015 06:51:38;0008;PBS_Server;Job;NULL;on_job_exit valid pjob: 0x1dcb770 (substate=10)
07/14/2015 06:51:38;0040;PBS_Server;Svr;tyrone-cluster;Scheduler was sent the command new
07/14/2015 06:52:08;0008;PBS_Server;Job;NULL;on_job_exit valid pjob: 0x1dcb770 (substate=10)
07/14/2015 06:52:09;0040;PBS_Server;Svr;tyrone-cluster;Scheduler was sent the command new
07/14/2015 06:52:38;0008;PBS_Server;Job;NULL;on_job_exit valid pjob: 0x1dcb770 (substate=10)
07/14/2015 06:52:39;0040;PBS_Server;Svr;tyrone-cluster;Scheduler was sent the command new
07/14/2015 06:53:08;0008;PBS_Server;Job;NULL;on_job_exit valid pjob: 0x1dcb770 (substate=10)
07/14/2015 06:53:08;0040;PBS_Server;Svr;tyrone-cluster;Scheduler was sent the command new
07/14/2015 06:53:38;0008;PBS_Server;Job;NULL;on_job_exit valid pjob: 0x1dcb770 (substate=10)
07/14/2015 06:53:39;0040;PBS_Server;Svr;tyrone-cluster;Scheduler was sent the command new
07/14/2015 06:54:08;0008;PBS_Server;Job;NULL;on_job_exit valid pjob: 0x1dcb770 (substate=10)
07/14/2015 06:54:08;0040;PBS_Server;Svr;tyrone-cluster;Scheduler was sent the command new
07/14/2015 06:54:38;0008;PBS_Server;Job;NULL;on_job_exit valid pjob: 0x1dcb770 (substate=10)
07/14/2015 06:54:40;0040;PBS_Server;Svr;tyrone-cluster;Scheduler was sent the command new
07/14/2015 06:55:08;0008;PBS_Server;Job;NULL;on_job_exit valid pjob: 0x1dcb770 (substate=10)
07/14/2015 06:55:09;0040;PBS_Server;Svr;tyrone-cluster;Scheduler was sent the command new
07/14/2015 06:55:38;0008;PBS_Server;Job;NULL;on_job_exit valid pjob: 0x1dcb770 (substate=10)
07/14/2015 06:55:38;0040;PBS_Server;Svr;tyrone-cluster;Scheduler was sent the command new
07/14/2015 06:56:08;0008;PBS_Server;Job;NULL;on_job_exit valid pjob: 0x1dcb770 (substate=10)
07/14/2015 06:56:10;0040;PBS_Server;Svr;tyrone-cluster;Scheduler was sent the command new
07/14/2015 06:56:36;0002;PBS_Server;Svr;PBS_Server;Torque Server Version = 3.0.5, loglevel = 0
07/14/2015 06:56:38;0008;PBS_Server;Job;NULL;on_job_exit valid pjob: 0x1dcb770 (substate=10)
07/14/2015 06:56:39;0040;PBS_Server;Svr;tyrone-cluster;Scheduler was sent the command new
07/14/2015 06:57:08;0008;PBS_Server;Job;NULL;on_job_exit valid pjob: 0x1dcb770 (substate=10)
07/14/2015 06:57:08;0040;PBS_Server;Svr;tyrone-cluster;Scheduler was sent the command new
07/14/2015 06:57:38;0008;PBS_Server;Job;NULL;on_job_exit valid pjob: 0x1dcb770 (substate=10)
07/14/2015 06:57:38;0040;PBS_Server;Svr;tyrone-cluster;Scheduler was sent the command new
07/14/2015 06:58:08;0008;PBS_Server;Job;NULL;on_job_exit valid pjob: 0x1dcb770 (substate=10)
07/14/2015 06:58:09;0040;PBS_Server;Svr;tyrone-cluster;Scheduler was sent the command new
07/14/2015 06:58:38;0008;PBS_Server;Job;NULL;on_job_exit valid pjob: 0x1dcb770 (substate=10)
07/14/2015 06:58:38;0040;PBS_Server;Svr;tyrone-cluster;Scheduler was sent the command new
07/14/2015 06:59:08;0008;PBS_Server;Job;NULL;on_job_exit valid pjob: 0x1dcb770 (substate=10)
07/14/2015 06:59:08;0040;PBS_Server;Svr;tyrone-cluster;Scheduler was sent the command new
07/14/2015 06:59:38;0008;PBS_Server;Job;NULL;on_job_exit valid pjob: 0x1dcb770 (substate=10)
07/14/2015 06:59:39;0040;PBS_Server;Svr;tyrone-cluster;Scheduler was sent the command new
07/14/2015 07:00:08;0008;PBS_Server;Job;NULL;on_job_exit valid pjob: 0x1dcb770 (substate=10)
07/14/2015 07:00:08;0040;PBS_Server;Svr;tyrone-cluster;Scheduler was sent the command new
07/14/2015 07:00:38;0008;PBS_Server;Job;NULL;on_job_exit valid pjob: 0x1dcb770 (substate=10)
07/14/2015 07:00:40;0040;PBS_Server;Svr;tyrone-cluster;Scheduler was sent the command new
07/14/2015 07:01:08;0008;PBS_Server;Job;NULL;on_job_exit valid pjob: 0x1dcb770 (substate=10)
07/14/2015 07:01:09;0040;PBS_Server;Svr;tyrone-cluster;Scheduler was sent the command new
07/14/2015 07:01:36;0002;PBS_Server;Svr;PBS_Server;Torque Server Version = 3.0.5, loglevel = 0
07/14/2015 07:01:38;0008;PBS_Server;Job;NULL;on_job_exit valid pjob: 0x1dcb770 (substate=10)
07/14/2015 07:01:38;0040;PBS_Server;Svr;tyrone-cluster;Scheduler was sent the command new
07/14/2015 07:02:08;0008;PBS_Server;Job;NULL;on_job_exit valid pjob: 0x1dcb770 (substate=10)
07/14/2015 07:02:10;0040;PBS_Server;Svr;tyrone-cluster;Scheduler was sent the command new
07/14/2015 07:02:38;0008;PBS_Server;Job;NULL;on_job_exit valid pjob: 0x1dcb770 (substate=10)
07/14/2015 07:02:39;0040;PBS_Server;Svr;tyrone-cluster;Scheduler was sent the command new
07/14/2015 07:03:08;0008;PBS_Server;Job;NULL;on_job_exit valid pjob: 0x1dcb770 (substate=10)
07/14/2015 07:03:08;0040;PBS_Server;Svr;tyrone-cluster;Scheduler was sent the command new
07/14/2015 07:03:38;0008;PBS_Server;Job;NULL;on_job_exit valid pjob: 0x1dcb770 (substate=10)
07/14/2015 07:03:38;0040;PBS_Server;Svr;tyrone-cluster;Scheduler was sent the command new
07/14/2015 07:04:08;0008;PBS_Server;Job;NULL;on_job_exit valid pjob: 0x1dcb770 (substate=10)
07/14/2015 07:04:09;0040;PBS_Server;Svr;tyrone-cluster;Scheduler was sent the command new
07/14/2015 07:04:38;0008;PBS_Server;Job;NULL;on_job_exit valid pjob: 0x1dcb770 (substate=10)
07/14/2015 07:04:38;0040;PBS_Server;Svr;tyrone-cluster;Scheduler was sent the command new
07/14/2015 07:05:08;0008;PBS_Server;Job;NULL;on_job_exit valid pjob: 0x1dcb770 (substate=10)
07/14/2015 07:05:11;0040;PBS_Server;Svr;tyrone-cluster;Scheduler was sent the command new
07/14/2015 07:05:38;0008;PBS_Server;Job;NULL;on_job_exit valid pjob: 0x1dcb770 (substate=10)
07/14/2015 07:05:40;0040;PBS_Server;Svr;tyrone-cluster;Scheduler was sent the command new
07/14/2015 07:06:08;0008;PBS_Server;Job;NULL;on_job_exit valid pjob: 0x1dcb770 (substate=10)
07/14/2015 07:06:08;0040;PBS_Server;Svr;tyrone-cluster;Scheduler was sent the command new
07/14/2015 07:06:36;0002;PBS_Server;Svr;PBS_Server;Torque Server Version = 3.0.5, loglevel = 0
07/14/2015 07:06:38;0008;PBS_Server;Job;NULL;on_job_exit valid pjob: 0x1dcb770 (substate=10)
07/14/2015 07:06:38;0040;PBS_Server;Svr;tyrone-cluster;Scheduler was sent the command new
07/14/2015 07:07:08;0008;PBS_Server;Job;NULL;on_job_exit valid pjob: 0x1dcb770 (substate=10)
07/14/2015 07:07:10;0040;PBS_Server;Svr;tyrone-cluster;Scheduler was sent the command new
07/14/2015 07:07:38;0008;PBS_Server;Job;NULL;on_job_exit valid pjob: 0x1dcb770 (substate=10)
07/14/2015 07:07:38;0040;PBS_Server;Svr;tyrone-cluster;Scheduler was sent the command new
07/14/2015 07:08:08;0008;PBS_Server;Job;NULL;on_job_exit valid pjob: 0x1dcb770 (substate=10)
07/14/2015 07:08:11;0040;PBS_Server;Svr;tyrone-cluster;Scheduler was sent the command new
07/14/2015 07:08:38;0008;PBS_Server;Job;NULL;on_job_exit valid pjob: 0x1dcb770 (substate=10)
07/14/2015 07:08:40;0040;PBS_Server;Svr;tyrone-cluster;Scheduler was sent the command new
07/14/2015 07:09:08;0008;PBS_Server;Job;NULL;on_job_exit valid pjob: 0x1dcb770 (substate=10)
07/14/2015 07:09:08;0040;PBS_Server;Svr;tyrone-cluster;Scheduler was sent the command new
07/14/2015 07:09:38;0008;PBS_Server;Job;NULL;on_job_exit valid pjob: 0x1dcb770 (substate=10)
07/14/2015 07:09:38;0040;PBS_Server;Svr;tyrone-cluster;Scheduler was sent the command new
07/14/2015 07:10:08;0008;PBS_Server;Job;NULL;on_job_exit valid pjob: 0x1dcb770 (substate=10)
07/14/2015 07:10:10;0040;PBS_Server;Svr;tyrone-cluster;Scheduler was sent the command new
07/14/2015 07:10:38;0008;PBS_Server;Job;NULL;on_job_exit valid pjob: 0x1dcb770 (substate=10)
07/14/2015 07:10:38;0040;PBS_Server;Svr;tyrone-cluster;Scheduler was sent the command new
07/14/2015 07:11:08;0008;PBS_Server;Job;NULL;on_job_exit valid pjob: 0x1dcb770 (substate=10)
07/14/2015 07:11:11;0040;PBS_Server;Svr;tyrone-cluster;Scheduler was sent the command new
07/14/2015 07:11:36;0002;PBS_Server;Svr;PBS_Server;Torque Server Version = 3.0.5, loglevel = 0
07/14/2015 07:11:38;0008;PBS_Server;Job;NULL;on_job_exit valid pjob: 0x1dcb770 (substate=10)
07/14/2015 07:11:40;0040;PBS_Server;Svr;tyrone-cluster;Scheduler was sent the command new
07/14/2015 07:12:08;0008;PBS_Server;Job;NULL;on_job_exit valid pjob: 0x1dcb770 (substate=10)
07/14/2015 07:12:09;0040;PBS_Server;Svr;tyrone-cluster;Scheduler was sent the command new
07/14/2015 07:12:38;0008;PBS_Server;Job;NULL;on_job_exit valid pjob: 0x1dcb770 (substate=10)
07/14/2015 07:12:38;0040;PBS_Server;Svr;tyrone-cluster;Scheduler was sent the command new
07/14/2015 07:13:08;0008;PBS_Server;Job;NULL;on_job_exit valid pjob: 0x1dcb770 (substate=10)
07/14/2015 07:13:10;0040;PBS_Server;Svr;tyrone-cluster;Scheduler was sent the command new
07/14/2015 07:13:38;0008;PBS_Server;Job;NULL;on_job_exit valid pjob: 0x1dcb770 (substate=10)
07/14/2015 07:13:38;0040;PBS_Server;Svr;tyrone-cluster;Scheduler was sent the command new
07/14/2015 07:14:08;0008;PBS_Server;Job;NULL;on_job_exit valid pjob: 0x1dcb770 (substate=10)
07/14/2015 07:14:11;0040;PBS_Server;Svr;tyrone-cluster;Scheduler was sent the command new
07/14/2015 07:14:38;0008;PBS_Server;Job;NULL;on_job_exit valid pjob: 0x1dcb770 (substate=10)
07/14/2015 07:14:40;0040;PBS_Server;Svr;tyrone-cluster;Scheduler was sent the command new
07/14/2015 07:15:08;0008;PBS_Server;Job;NULL;on_job_exit valid pjob: 0x1dcb770 (substate=10)
07/14/2015 07:15:09;0040;PBS_Server;Svr;tyrone-cluster;Scheduler was sent the command new
07/14/2015 07:15:38;0008;PBS_Server;Job;NULL;on_job_exit valid pjob: 0x1dcb770 (substate=10)
07/14/2015 07:15:38;0040;PBS_Server;Svr;tyrone-cluster;Scheduler was sent the command new
07/14/2015 07:16:08;0008;PBS_Server;Job;NULL;on_job_exit valid pjob: 0x1dcb770 (substate=10)
07/14/2015 07:16:10;0040;PBS_Server;Svr;tyrone-cluster;Scheduler was sent the command new
07/14/2015 07:16:36;0002;PBS_Server;Svr;PBS_Server;Torque Server Version = 3.0.5, loglevel = 0
07/14/2015 07:16:38;0008;PBS_Server;Job;NULL;on_job_exit valid pjob: 0x1dcb770 (substate=10)
07/14/2015 07:16:38;0040;PBS_Server;Svr;tyrone-cluster;Scheduler was sent the command new
07/14/2015 07:17:08;0008;PBS_Server;Job;NULL;on_job_exit valid pjob: 0x1dcb770 (substate=10)
07/14/2015 07:17:08;0040;PBS_Server;Svr;tyrone-cluster;Scheduler was sent the command new
07/14/2015 07:17:38;0008;PBS_Server;Job;NULL;on_job_exit valid pjob: 0x1dcb770 (substate=10)
07/14/2015 07:17:40;0040;PBS_Server;Svr;tyrone-cluster;Scheduler was sent the command new
07/14/2015 07:18:08;0008;PBS_Server;Job;NULL;on_job_exit valid pjob: 0x1dcb770 (substate=10)
07/14/2015 07:18:08;0040;PBS_Server;Svr;tyrone-cluster;Scheduler was sent the command new
07/14/2015 07:18:38;0008;PBS_Server;Job;NULL;on_job_exit valid pjob: 0x1dcb770 (substate=10)
07/14/2015 07:18:41;0040;PBS_Server;Svr;tyrone-cluster;Scheduler was sent the command new
07/14/2015 07:19:08;0008;PBS_Server;Job;NULL;on_job_exit valid pjob: 0x1dcb770 (substate=10)
07/14/2015 07:19:10;0040;PBS_Server;Svr;tyrone-cluster;Scheduler was sent the command new
07/14/2015 07:19:38;0008;PBS_Server;Job;NULL;on_job_exit valid pjob: 0x1dcb770 (substate=10)
07/14/2015 07:19:38;0040;PBS_Server;Svr;tyrone-cluster;Scheduler was sent the command new
07/14/2015 07:20:08;0008;PBS_Server;Job;NULL;on_job_exit valid pjob: 0x1dcb770 (substate=10)
07/14/2015 07:20:08;0040;PBS_Server;Svr;tyrone-cluster;Scheduler was sent the command new
07/14/2015 07:20:38;0008;PBS_Server;Job;NULL;on_job_exit valid pjob: 0x1dcb770 (substate=10)
07/14/2015 07:20:40;0040;PBS_Server;Svr;tyrone-cluster;Scheduler was sent the command new
07/14/2015 07:21:08;0008;PBS_Server;Job;NULL;on_job_exit valid pjob: 0x1dcb770 (substate=10)
07/14/2015 07:21:08;0040;PBS_Server;Svr;tyrone-cluster;Scheduler was sent the command new
07/14/2015 07:21:36;0002;PBS_Server;Svr;PBS_Server;Torque Server Version = 3.0.5, loglevel = 0
07/14/2015 07:21:38;0008;PBS_Server;Job;NULL;on_job_exit valid pjob: 0x1dcb770 (substate=10)
07/14/2015 07:21:41;0040;PBS_Server;Svr;tyrone-cluster;Scheduler was sent the command new
07/14/2015 07:22:08;0008;PBS_Server;Job;NULL;on_job_exit valid pjob: 0x1dcb770 (substate=10)
07/14/2015 07:22:10;0040;PBS_Server;Svr;tyrone-cluster;Scheduler was sent the command new
07/14/2015 07:22:38;0008;PBS_Server;Job;NULL;on_job_exit valid pjob: 0x1dcb770 (substate=10)
07/14/2015 07:22:38;0040;PBS_Server;Svr;tyrone-cluster;Scheduler was sent the command new
07/14/2015 07:23:08;0008;PBS_Server;Job;NULL;on_job_exit valid pjob: 0x1dcb770 (substate=10)
07/14/2015 07:23:08;0040;PBS_Server;Svr;tyrone-cluster;Scheduler was sent the command new
07/14/2015 07:23:38;0008;PBS_Server;Job;NULL;on_job_exit valid pjob: 0x1dcb770 (substate=10)
07/14/2015 07:23:40;0040;PBS_Server;Svr;tyrone-cluster;Scheduler was sent the command new
07/14/2015 07:24:08;0008;PBS_Server;Job;NULL;on_job_exit valid pjob: 0x1dcb770 (substate=10)
07/14/2015 07:24:08;0040;PBS_Server;Svr;tyrone-cluster;Scheduler was sent the command new
07/14/2015 07:24:38;0008;PBS_Server;Job;NULL;on_job_exit valid pjob: 0x1dcb770 (substate=10)
07/14/2015 07:24:41;0040;PBS_Server;Svr;tyrone-cluster;Scheduler was sent the command new
07/14/2015 07:25:08;0008;PBS_Server;Job;NULL;on_job_exit valid pjob: 0x1dcb770 (substate=10)
07/14/2015 07:25:10;0040;PBS_Server;Svr;tyrone-cluster;Scheduler was sent the command new
07/14/2015 07:25:38;0008;PBS_Server;Job;NULL;on_job_exit valid pjob: 0x1dcb770 (substate=10)
07/14/2015 07:25:39;0040;PBS_Server;Svr;tyrone-cluster;Scheduler was sent the command new
07/14/2015 07:26:08;0008;PBS_Server;Job;NULL;on_job_exit valid pjob: 0x1dcb770 (substate=10)
07/14/2015 07:26:08;0040;PBS_Server;Svr;tyrone-cluster;Scheduler was sent the command new
07/14/2015 07:26:36;0002;PBS_Server;Svr;PBS_Server;Torque Server Version = 3.0.5, loglevel = 0
07/14/2015 07:26:38;0008;PBS_Server;Job;NULL;on_job_exit valid pjob: 0x1dcb770 (substate=10)
07/14/2015 07:26:40;0040;PBS_Server;Svr;tyrone-cluster;Scheduler was sent the command new
07/14/2015 07:27:08;0008;PBS_Server;Job;NULL;on_job_exit valid pjob: 0x1dcb770 (substate=10)
07/14/2015 07:27:08;0040;PBS_Server;Svr;tyrone-cluster;Scheduler was sent the command new
07/14/2015 07:27:38;0008;PBS_Server;Job;NULL;on_job_exit valid pjob: 0x1dcb770 (substate=10)
07/14/2015 07:27:41;0040;PBS_Server;Svr;tyrone-cluster;Scheduler was sent the command new
07/14/2015 07:28:08;0008;PBS_Server;Job;NULL;on_job_exit valid pjob: 0x1dcb770 (substate=10)
07/14/2015 07:28:10;0040;PBS_Server;Svr;tyrone-cluster;Scheduler was sent the command new
07/14/2015 07:28:38;0008;PBS_Server;Job;NULL;on_job_exit valid pjob: 0x1dcb770 (substate=10)
07/14/2015 07:28:39;0040;PBS_Server;Svr;tyrone-cluster;Scheduler was sent the command new
07/14/2015 07:29:08;0008;PBS_Server;Job;NULL;on_job_exit valid pjob: 0x1dcb770 (substate=10)
07/14/2015 07:29:08;0040;PBS_Server;Svr;tyrone-cluster;Scheduler was sent the command new
07/14/2015 07:29:38;0008;PBS_Server;Job;NULL;on_job_exit valid pjob: 0x1dcb770 (substate=10)
07/14/2015 07:29:40;0040;PBS_Server;Svr;tyrone-cluster;Scheduler was sent the command new
07/14/2015 07:30:08;0008;PBS_Server;Job;NULL;on_job_exit valid pjob: 0x1dcb770 (substate=10)
07/14/2015 07:30:08;0040;PBS_Server;Svr;tyrone-cluster;Scheduler was sent the command new
07/14/2015 07:30:38;0008;PBS_Server;Job;NULL;on_job_exit valid pjob: 0x1dcb770 (substate=10)
07/14/2015 07:30:38;0040;PBS_Server;Svr;tyrone-cluster;Scheduler was sent the command new
07/14/2015 07:31:08;0008;PBS_Server;Job;NULL;on_job_exit valid pjob: 0x1dcb770 (substate=10)
07/14/2015 07:31:10;0040;PBS_Server;Svr;tyrone-cluster;Scheduler was sent the command new
07/14/2015 07:31:36;0002;PBS_Server;Svr;PBS_Server;Torque Server Version = 3.0.5, loglevel = 0
07/14/2015 07:31:38;0008;PBS_Server;Job;NULL;on_job_exit valid pjob: 0x1dcb770 (substate=10)
07/14/2015 07:31:38;0040;PBS_Server;Svr;tyrone-cluster;Scheduler was sent the command new
07/14/2015 07:32:08;0008;PBS_Server;Job;NULL;on_job_exit valid pjob: 0x1dcb770 (substate=10)
07/14/2015 07:32:11;0040;PBS_Server;Svr;tyrone-cluster;Scheduler was sent the command new
07/14/2015 07:32:38;0008;PBS_Server;Job;NULL;on_job_exit valid pjob: 0x1dcb770 (substate=10)
07/14/2015 07:32:40;0040;PBS_Server;Svr;tyrone-cluster;Scheduler was sent the command new
07/14/2015 07:33:08;0008;PBS_Server;Job;NULL;on_job_exit valid pjob: 0x1dcb770 (substate=10)
07/14/2015 07:33:09;0040;PBS_Server;Svr;tyrone-cluster;Scheduler was sent the command new
07/14/2015 07:33:38;0008;PBS_Server;Job;NULL;on_job_exit valid pjob: 0x1dcb770 (substate=10)
07/14/2015 07:33:38;0040;PBS_Server;Svr;tyrone-cluster;Scheduler was sent the command new
07/14/2015 07:34:08;0008;PBS_Server;Job;NULL;on_job_exit valid pjob: 0x1dcb770 (substate=10)
07/14/2015 07:34:10;0040;PBS_Server;Svr;tyrone-cluster;Scheduler was sent the command new
07/14/2015 07:34:38;0008;PBS_Server;Job;NULL;on_job_exit valid pjob: 0x1dcb770 (substate=10)
07/14/2015 07:34:38;0040;PBS_Server;Svr;tyrone-cluster;Scheduler was sent the command new
07/14/2015 07:35:08;0008;PBS_Server;Job;NULL;on_job_exit valid pjob: 0x1dcb770 (substate=10)
07/14/2015 07:35:11;0040;PBS_Server;Svr;tyrone-cluster;Scheduler was sent the command new
07/14/2015 07:35:38;0008;PBS_Server;Job;NULL;on_job_exit valid pjob: 0x1dcb770 (substate=10)
07/14/2015 07:35:40;0040;PBS_Server;Svr;tyrone-cluster;Scheduler was sent the command new
07/14/2015 07:36:08;0008;PBS_Server;Job;NULL;on_job_exit valid pjob: 0x1dcb770 (substate=10)
07/14/2015 07:36:09;0040;PBS_Server;Svr;tyrone-cluster;Scheduler was sent the command new
07/14/2015 07:36:36;0002;PBS_Server;Svr;PBS_Server;Torque Server Version = 3.0.5, loglevel = 0
07/14/2015 07:36:38;0008;PBS_Server;Job;NULL;on_job_exit valid pjob: 0x1dcb770 (substate=10)
07/14/2015 07:36:38;0040;PBS_Server;Svr;tyrone-cluster;Scheduler was sent the command new
07/14/2015 07:37:08;0008;PBS_Server;Job;NULL;on_job_exit valid pjob: 0x1dcb770 (substate=10)
07/14/2015 07:37:10;0040;PBS_Server;Svr;tyrone-cluster;Scheduler was sent the command new
07/14/2015 07:37:38;0008;PBS_Server;Job;NULL;on_job_exit valid pjob: 0x1dcb770 (substate=10)
07/14/2015 07:37:38;0040;PBS_Server;Svr;tyrone-cluster;Scheduler was sent the command new
07/14/2015 07:38:08;0008;PBS_Server;Job;NULL;on_job_exit valid pjob: 0x1dcb770 (substate=10)
07/14/2015 07:38:11;0040;PBS_Server;Svr;tyrone-cluster;Scheduler was sent the command new
07/14/2015 07:38:38;0008;PBS_Server;Job;NULL;on_job_exit valid pjob: 0x1dcb770 (substate=10)
07/14/2015 07:38:40;0040;PBS_Server;Svr;tyrone-cluster;Scheduler was sent the command new
07/14/2015 07:39:08;0008;PBS_Server;Job;NULL;on_job_exit valid pjob: 0x1dcb770 (substate=10)
07/14/2015 07:39:08;0040;PBS_Server;Svr;tyrone-cluster;Scheduler was sent the command new
07/14/2015 07:39:38;0008;PBS_Server;Job;NULL;on_job_exit valid pjob: 0x1dcb770 (substate=10)
07/14/2015 07:39:41;0040;PBS_Server;Svr;tyrone-cluster;Scheduler was sent the command new
07/14/2015 07:40:08;0008;PBS_Server;Job;NULL;on_job_exit valid pjob: 0x1dcb770 (substate=10)
07/14/2015 07:40:10;0040;PBS_Server;Svr;tyrone-cluster;Scheduler was sent the command new
07/14/2015 07:40:38;0008;PBS_Server;Job;NULL;on_job_exit valid pjob: 0x1dcb770 (substate=10)
07/14/2015 07:40:38;0040;PBS_Server;Svr;tyrone-cluster;Scheduler was sent the command new
07/14/2015 07:41:08;0008;PBS_Server;Job;NULL;on_job_exit valid pjob: 0x1dcb770 (substate=10)
07/14/2015 07:41:08;0040;PBS_Server;Svr;tyrone-cluster;Scheduler was sent the command new
07/14/2015 07:41:36;0002;PBS_Server;Svr;PBS_Server;Torque Server Version = 3.0.5, loglevel = 0
07/14/2015 07:41:38;0008;PBS_Server;Job;NULL;on_job_exit valid pjob: 0x1dcb770 (substate=10)
07/14/2015 07:41:40;0040;PBS_Server;Svr;tyrone-cluster;Scheduler was sent the command new
07/14/2015 07:42:08;0008;PBS_Server;Job;NULL;on_job_exit valid pjob: 0x1dcb770 (substate=10)
07/14/2015 07:42:08;0040;PBS_Server;Svr;tyrone-cluster;Scheduler was sent the command new
07/14/2015 07:42:38;0008;PBS_Server;Job;NULL;on_job_exit valid pjob: 0x1dcb770 (substate=10)
07/14/2015 07:42:42;0040;PBS_Server;Svr;tyrone-cluster;Scheduler was sent the command new
07/14/2015 07:43:08;0008;PBS_Server;Job;NULL;on_job_exit valid pjob: 0x1dcb770 (substate=10)
07/14/2015 07:43:10;0040;PBS_Server;Svr;tyrone-cluster;Scheduler was sent the command new
07/14/2015 07:43:38;0008;PBS_Server;Job;NULL;on_job_exit valid pjob: 0x1dcb770 (substate=10)
07/14/2015 07:43:38;0040;PBS_Server;Svr;tyrone-cluster;Scheduler was sent the command new
07/14/2015 07:44:08;0008;PBS_Server;Job;NULL;on_job_exit valid pjob: 0x1dcb770 (substate=10)
07/14/2015 07:44:11;0040;PBS_Server;Svr;tyrone-cluster;Scheduler was sent the command new
07/14/2015 07:44:38;0008;PBS_Server;Job;NULL;on_job_exit valid pjob: 0x1dcb770 (substate=10)
07/14/2015 07:44:40;0040;PBS_Server;Svr;tyrone-cluster;Scheduler was sent the command new
07/14/2015 07:45:08;0008;PBS_Server;Job;NULL;on_job_exit valid pjob: 0x1dcb770 (substate=10)
07/14/2015 07:45:08;0040;PBS_Server;Svr;tyrone-cluster;Scheduler was sent the command new
07/14/2015 07:45:38;0008;PBS_Server;Job;NULL;on_job_exit valid pjob: 0x1dcb770 (substate=10)
07/14/2015 07:45:41;0040;PBS_Server;Svr;tyrone-cluster;Scheduler was sent the command new
07/14/2015 07:46:08;0008;PBS_Server;Job;NULL;on_job_exit valid pjob: 0x1dcb770 (substate=10)
07/14/2015 07:46:10;0040;PBS_Server;Svr;tyrone-cluster;Scheduler was sent the command new
07/14/2015 07:46:36;0002;PBS_Server;Svr;PBS_Server;Torque Server Version = 3.0.5, loglevel = 0
07/14/2015 07:46:38;0008;PBS_Server;Job;NULL;on_job_exit valid pjob: 0x1dcb770 (substate=10)
07/14/2015 07:46:38;0040;PBS_Server;Svr;tyrone-cluster;Scheduler was sent the command new
07/14/2015 07:47:08;0008;PBS_Server;Job;NULL;on_job_exit valid pjob: 0x1dcb770 (substate=10)
07/14/2015 07:47:08;0040;PBS_Server;Svr;tyrone-cluster;Scheduler was sent the command new
07/14/2015 07:47:38;0008;PBS_Server;Job;NULL;on_job_exit valid pjob: 0x1dcb770 (substate=10)
07/14/2015 07:47:40;0040;PBS_Server;Svr;tyrone-cluster;Scheduler was sent the command new
07/14/2015 07:48:08;0008;PBS_Server;Job;NULL;on_job_exit valid pjob: 0x1dcb770 (substate=10)
07/14/2015 07:48:08;0040;PBS_Server;Svr;tyrone-cluster;Scheduler was sent the command new
07/14/2015 07:48:38;0008;PBS_Server;Job;NULL;on_job_exit valid pjob: 0x1dcb770 (substate=10)
07/14/2015 07:48:41;0040;PBS_Server;Svr;tyrone-cluster;Scheduler was sent the command new
07/14/2015 07:49:08;0008;PBS_Server;Job;NULL;on_job_exit valid pjob: 0x1dcb770 (substate=10)
07/14/2015 07:49:10;0040;PBS_Server;Svr;tyrone-cluster;Scheduler was sent the command new
07/14/2015 07:49:38;0008;PBS_Server;Job;NULL;on_job_exit valid pjob: 0x1dcb770 (substate=10)
07/14/2015 07:49:39;0040;PBS_Server;Svr;tyrone-cluster;Scheduler was sent the command new
07/14/2015 07:50:08;0008;PBS_Server;Job;NULL;on_job_exit valid pjob: 0x1dcb770 (substate=10)
07/14/2015 07:50:08;0040;PBS_Server;Svr;tyrone-cluster;Scheduler was sent the command new
07/14/2015 07:50:38;0008;PBS_Server;Job;NULL;on_job_exit valid pjob: 0x1dcb770 (substate=10)
07/14/2015 07:50:40;0040;PBS_Server;Svr;tyrone-cluster;Scheduler was sent the command new
07/14/2015 07:51:08;0008;PBS_Server;Job;NULL;on_job_exit valid pjob: 0x1dcb770 (substate=10)
07/14/2015 07:51:08;0040;PBS_Server;Svr;tyrone-cluster;Scheduler was sent the command new
07/14/2015 07:51:36;0002;PBS_Server;Svr;PBS_Server;Torque Server Version = 3.0.5, loglevel = 0
07/14/2015 07:51:38;0008;PBS_Server;Job;NULL;on_job_exit valid pjob: 0x1dcb770 (substate=10)
07/14/2015 07:51:41;0040;PBS_Server;Svr;tyrone-cluster;Scheduler was sent the command new
07/14/2015 07:52:08;0008;PBS_Server;Job;NULL;on_job_exit valid pjob: 0x1dcb770 (substate=10)
07/14/2015 07:52:10;0040;PBS_Server;Svr;tyrone-cluster;Scheduler was sent the command new
07/14/2015 07:52:38;0008;PBS_Server;Job;NULL;on_job_exit valid pjob: 0x1dcb770 (substate=10)
07/14/2015 07:52:38;0040;PBS_Server;Svr;tyrone-cluster;Scheduler was sent the command new
07/14/2015 07:53:08;0008;PBS_Server;Job;NULL;on_job_exit valid pjob: 0x1dcb770 (substate=10)
07/14/2015 07:53:08;0040;PBS_Server;Svr;tyrone-cluster;Scheduler was sent the command new
07/14/2015 07:53:38;0008;PBS_Server;Job;NULL;on_job_exit valid pjob: 0x1dcb770 (substate=10)
07/14/2015 07:53:40;0040;PBS_Server;Svr;tyrone-cluster;Scheduler was sent the command new
07/14/2015 07:54:08;0008;PBS_Server;Job;NULL;on_job_exit valid pjob: 0x1dcb770 (substate=10)
07/14/2015 07:54:08;0040;PBS_Server;Svr;tyrone-cluster;Scheduler was sent the command new
07/14/2015 07:54:38;0008;PBS_Server;Job;NULL;on_job_exit valid pjob: 0x1dcb770 (substate=10)
07/14/2015 07:54:41;0040;PBS_Server;Svr;tyrone-cluster;Scheduler was sent the command new
07/14/2015 07:55:08;0008;PBS_Server;Job;NULL;on_job_exit valid pjob: 0x1dcb770 (substate=10)
07/14/2015 07:55:10;0040;PBS_Server;Svr;tyrone-cluster;Scheduler was sent the command new
07/14/2015 07:55:38;0008;PBS_Server;Job;NULL;on_job_exit valid pjob: 0x1dcb770 (substate=10)
07/14/2015 07:55:38;0040;PBS_Server;Svr;tyrone-cluster;Scheduler was sent the command new
07/14/2015 07:56:08;0008;PBS_Server;Job;NULL;on_job_exit valid pjob: 0x1dcb770 (substate=10)
07/14/2015 07:56:11;0040;PBS_Server;Svr;tyrone-cluster;Scheduler was sent the command new
07/14/2015 07:56:36;0002;PBS_Server;Svr;PBS_Server;Torque Server Version = 3.0.5, loglevel = 0
07/14/2015 07:56:38;0008;PBS_Server;Job;NULL;on_job_exit valid pjob: 0x1dcb770 (substate=10)
07/14/2015 07:56:40;0040;PBS_Server;Svr;tyrone-cluster;Scheduler was sent the command new
07/14/2015 07:57:08;0008;PBS_Server;Job;NULL;on_job_exit valid pjob: 0x1dcb770 (substate=10)
07/14/2015 07:57:09;0040;PBS_Server;Svr;tyrone-cluster;Scheduler was sent the command new
07/14/2015 07:57:38;0008;PBS_Server;Job;NULL;on_job_exit valid pjob: 0x1dcb770 (substate=10)
07/14/2015 07:57:38;0040;PBS_Server;Svr;tyrone-cluster;Scheduler was sent the command new
07/14/2015 07:58:08;0008;PBS_Server;Job;NULL;on_job_exit valid pjob: 0x1dcb770 (substate=10)
07/14/2015 07:58:10;0040;PBS_Server;Svr;tyrone-cluster;Scheduler was sent the command new
07/14/2015 07:58:38;0008;PBS_Server;Job;NULL;on_job_exit valid pjob: 0x1dcb770 (substate=10)
07/14/2015 07:58:38;0040;PBS_Server;Svr;tyrone-cluster;Scheduler was sent the command new
07/14/2015 07:59:08;0008;PBS_Server;Job;NULL;on_job_exit valid pjob: 0x1dcb770 (substate=10)
07/14/2015 07:59:11;0040;PBS_Server;Svr;tyrone-cluster;Scheduler was sent the command new
07/14/2015 07:59:38;0008;PBS_Server;Job;NULL;on_job_exit valid pjob: 0x1dcb770 (substate=10)
07/14/2015 07:59:40;0040;PBS_Server;Svr;tyrone-cluster;Scheduler was sent the command new
07/14/2015 08:00:08;0008;PBS_Server;Job;NULL;on_job_exit valid pjob: 0x1dcb770 (substate=10)
07/14/2015 08:00:09;0040;PBS_Server;Svr;tyrone-cluster;Scheduler was sent the command new
07/14/2015 08:00:38;0008;PBS_Server;Job;NULL;on_job_exit valid pjob: 0x1dcb770 (substate=10)
07/14/2015 08:00:38;0040;PBS_Server;Svr;tyrone-cluster;Scheduler was sent the command new
07/14/2015 08:01:08;0008;PBS_Server;Job;NULL;on_job_exit valid pjob: 0x1dcb770 (substate=10)
07/14/2015 08:01:10;0040;PBS_Server;Svr;tyrone-cluster;Scheduler was sent the command new
07/14/2015 08:01:36;0002;PBS_Server;Svr;PBS_Server;Torque Server Version = 3.0.5, loglevel = 0
07/14/2015 08:01:38;0008;PBS_Server;Job;NULL;on_job_exit valid pjob: 0x1dcb770 (substate=10)
07/14/2015 08:01:38;0040;PBS_Server;Svr;tyrone-cluster;Scheduler was sent the command new
07/14/2015 08:02:08;0008;PBS_Server;Job;NULL;on_job_exit valid pjob: 0x1dcb770 (substate=10)
07/14/2015 08:02:11;0040;PBS_Server;Svr;tyrone-cluster;Scheduler was sent the command new
07/14/2015 08:02:38;0008;PBS_Server;Job;NULL;on_job_exit valid pjob: 0x1dcb770 (substate=10)
07/14/2015 08:02:40;0040;PBS_Server;Svr;tyrone-cluster;Scheduler was sent the command new
07/14/2015 08:03:08;0008;PBS_Server;Job;NULL;on_job_exit valid pjob: 0x1dcb770 (substate=10)
07/14/2015 08:03:08;0040;PBS_Server;Svr;tyrone-cluster;Scheduler was sent the command new
07/14/2015 08:03:38;0008;PBS_Server;Job;NULL;on_job_exit valid pjob: 0x1dcb770 (substate=10)
07/14/2015 08:03:41;0040;PBS_Server;Svr;tyrone-cluster;Scheduler was sent the command new
07/14/2015 08:04:08;0008;PBS_Server;Job;NULL;on_job_exit valid pjob: 0x1dcb770 (substate=10)
07/14/2015 08:04:10;0040;PBS_Server;Svr;tyrone-cluster;Scheduler was sent the command new
07/14/2015 08:04:38;0008;PBS_Server;Job;NULL;on_job_exit valid pjob: 0x1dcb770 (substate=10)
07/14/2015 08:04:39;0040;PBS_Server;Svr;tyrone-cluster;Scheduler was sent the command new
07/14/2015 08:05:08;0008;PBS_Server;Job;NULL;on_job_exit valid pjob: 0x1dcb770 (substate=10)
07/14/2015 08:05:08;0040;PBS_Server;Svr;tyrone-cluster;Scheduler was sent the command new
07/14/2015 08:05:38;0008;PBS_Server;Job;NULL;on_job_exit valid pjob: 0x1dcb770 (substate=10)
07/14/2015 08:05:40;0040;PBS_Server;Svr;tyrone-cluster;Scheduler was sent the command new
07/14/2015 08:06:08;0008;PBS_Server;Job;NULL;on_job_exit valid pjob: 0x1dcb770 (substate=10)
07/14/2015 08:06:08;0040;PBS_Server;Svr;tyrone-cluster;Scheduler was sent the command new
07/14/2015 08:06:36;0002;PBS_Server;Svr;PBS_Server;Torque Server Version = 3.0.5, loglevel = 0
07/14/2015 08:06:38;0008;PBS_Server;Job;NULL;on_job_exit valid pjob: 0x1dcb770 (substate=10)
07/14/2015 08:06:41;0040;PBS_Server;Svr;tyrone-cluster;Scheduler was sent the command new
07/14/2015 08:07:08;0008;PBS_Server;Job;NULL;on_job_exit valid pjob: 0x1dcb770 (substate=10)
07/14/2015 08:07:10;0040;PBS_Server;Svr;tyrone-cluster;Scheduler was sent the command new
07/14/2015 08:07:38;0008;PBS_Server;Job;NULL;on_job_exit valid pjob: 0x1dcb770 (substate=10)
07/14/2015 08:07:38;0040;PBS_Server;Svr;tyrone-cluster;Scheduler was sent the command new
07/14/2015 08:08:08;0008;PBS_Server;Job;NULL;on_job_exit valid pjob: 0x1dcb770 (substate=10)
07/14/2015 08:08:11;0040;PBS_Server;Svr;tyrone-cluster;Scheduler was sent the command new
07/14/2015 08:08:38;0008;PBS_Server;Job;NULL;on_job_exit valid pjob: 0x1dcb770 (substate=10)
07/14/2015 08:08:40;0040;PBS_Server;Svr;tyrone-cluster;Scheduler was sent the command new
07/14/2015 08:09:08;0008;PBS_Server;Job;NULL;on_job_exit valid pjob: 0x1dcb770 (substate=10)
07/14/2015 08:09:09;0040;PBS_Server;Svr;tyrone-cluster;Scheduler was sent the command new
07/14/2015 08:09:38;0008;PBS_Server;Job;NULL;on_job_exit valid pjob: 0x1dcb770 (substate=10)
07/14/2015 08:09:38;0040;PBS_Server;Svr;tyrone-cluster;Scheduler was sent the command new
07/14/2015 08:10:08;0008;PBS_Server;Job;NULL;on_job_exit valid pjob: 0x1dcb770 (substate=10)
07/14/2015 08:10:10;0040;PBS_Server;Svr;tyrone-cluster;Scheduler was sent the command new
07/14/2015 08:10:38;0008;PBS_Server;Job;NULL;on_job_exit valid pjob: 0x1dcb770 (substate=10)
07/14/2015 08:10:38;0040;PBS_Server;Svr;tyrone-cluster;Scheduler was sent the command new
07/14/2015 08:11:08;0008;PBS_Server;Job;NULL;on_job_exit valid pjob: 0x1dcb770 (substate=10)
07/14/2015 08:11:11;0040;PBS_Server;Svr;tyrone-cluster;Scheduler was sent the command new
07/14/2015 08:11:36;0002;PBS_Server;Svr;PBS_Server;Torque Server Version = 3.0.5, loglevel = 0
07/14/2015 08:11:38;0008;PBS_Server;Job;NULL;on_job_exit valid pjob: 0x1dcb770 (substate=10)
07/14/2015 08:11:40;0040;PBS_Server;Svr;tyrone-cluster;Scheduler was sent the command new
07/14/2015 08:12:08;0008;PBS_Server;Job;NULL;on_job_exit valid pjob: 0x1dcb770 (substate=10)
07/14/2015 08:12:09;0040;PBS_Server;Svr;tyrone-cluster;Scheduler was sent the command new
07/14/2015 08:12:38;0008;PBS_Server;Job;NULL;on_job_exit valid pjob: 0x1dcb770 (substate=10)
07/14/2015 08:12:41;0040;PBS_Server;Svr;tyrone-cluster;Scheduler was sent the command new
07/14/2015 08:13:08;0008;PBS_Server;Job;NULL;on_job_exit valid pjob: 0x1dcb770 (substate=10)
07/14/2015 08:13:10;0040;PBS_Server;Svr;tyrone-cluster;Scheduler was sent the command new
07/14/2015 08:13:38;0008;PBS_Server;Job;NULL;on_job_exit valid pjob: 0x1dcb770 (substate=10)
07/14/2015 08:13:38;0040;PBS_Server;Svr;tyrone-cluster;Scheduler was sent the command new
07/14/2015 08:14:08;0008;PBS_Server;Job;NULL;on_job_exit valid pjob: 0x1dcb770 (substate=10)
07/14/2015 08:14:11;0040;PBS_Server;Svr;tyrone-cluster;Scheduler was sent the command new
07/14/2015 08:14:38;0008;PBS_Server;Job;NULL;on_job_exit valid pjob: 0x1dcb770 (substate=10)
07/14/2015 08:14:40;0040;PBS_Server;Svr;tyrone-cluster;Scheduler was sent the command new
07/14/2015 08:15:08;0008;PBS_Server;Job;NULL;on_job_exit valid pjob: 0x1dcb770 (substate=10)
07/14/2015 08:15:08;0040;PBS_Server;Svr;tyrone-cluster;Scheduler was sent the command new
07/14/2015 08:15:38;0008;PBS_Server;Job;NULL;on_job_exit valid pjob: 0x1dcb770 (substate=10)
07/14/2015 08:15:41;0040;PBS_Server;Svr;tyrone-cluster;Scheduler was sent the command new
07/14/2015 08:16:08;0008;PBS_Server;Job;NULL;on_job_exit valid pjob: 0x1dcb770 (substate=10)
07/14/2015 08:16:10;0040;PBS_Server;Svr;tyrone-cluster;Scheduler was sent the command new
07/14/2015 08:16:36;0002;PBS_Server;Svr;PBS_Server;Torque Server Version = 3.0.5, loglevel = 0
07/14/2015 08:16:38;0008;PBS_Server;Job;NULL;on_job_exit valid pjob: 0x1dcb770 (substate=10)
07/14/2015 08:16:38;0040;PBS_Server;Svr;tyrone-cluster;Scheduler was sent the command new
07/14/2015 08:17:08;0008;PBS_Server;Job;NULL;on_job_exit valid pjob: 0x1dcb770 (substate=10)
07/14/2015 08:17:11;0040;PBS_Server;Svr;tyrone-cluster;Scheduler was sent the command new
07/14/2015 08:17:38;0008;PBS_Server;Job;NULL;on_job_exit valid pjob: 0x1dcb770 (substate=10)
07/14/2015 08:17:40;0040;PBS_Server;Svr;tyrone-cluster;Scheduler was sent the command new
07/14/2015 08:18:08;0008;PBS_Server;Job;NULL;on_job_exit valid pjob: 0x1dcb770 (substate=10)
07/14/2015 08:18:08;0040;PBS_Server;Svr;tyrone-cluster;Scheduler was sent the command new
07/14/2015 08:18:38;0008;PBS_Server;Job;NULL;on_job_exit valid pjob: 0x1dcb770 (substate=10)
07/14/2015 08:18:41;0040;PBS_Server;Svr;tyrone-cluster;Scheduler was sent the command new
07/14/2015 08:19:08;0008;PBS_Server;Job;NULL;on_job_exit valid pjob: 0x1dcb770 (substate=10)
07/14/2015 08:19:10;0040;PBS_Server;Svr;tyrone-cluster;Scheduler was sent the command new
07/14/2015 08:19:38;0008;PBS_Server;Job;NULL;on_job_exit valid pjob: 0x1dcb770 (substate=10)
07/14/2015 08:19:38;0040;PBS_Server;Svr;tyrone-cluster;Scheduler was sent the command new
07/14/2015 08:20:08;0008;PBS_Server;Job;NULL;on_job_exit valid pjob: 0x1dcb770 (substate=10)
07/14/2015 08:20:11;0040;PBS_Server;Svr;tyrone-cluster;Scheduler was sent the command new
07/14/2015 08:20:38;0008;PBS_Server;Job;NULL;on_job_exit valid pjob: 0x1dcb770 (substate=10)
07/14/2015 08:20:40;0040;PBS_Server;Svr;tyrone-cluster;Scheduler was sent the command new
07/14/2015 08:21:08;0008;PBS_Server;Job;NULL;on_job_exit valid pjob: 0x1dcb770 (substate=10)
07/14/2015 08:21:08;0040;PBS_Server;Svr;tyrone-cluster;Scheduler was sent the command new
07/14/2015 08:21:36;0002;PBS_Server;Svr;PBS_Server;Torque Server Version = 3.0.5, loglevel = 0
07/14/2015 08:21:38;0008;PBS_Server;Job;NULL;on_job_exit valid pjob: 0x1dcb770 (substate=10)
07/14/2015 08:21:41;0040;PBS_Server;Svr;tyrone-cluster;Scheduler was sent the command new
07/14/2015 08:22:08;0008;PBS_Server;Job;NULL;on_job_exit valid pjob: 0x1dcb770 (substate=10)
07/14/2015 08:22:10;0040;PBS_Server;Svr;tyrone-cluster;Scheduler was sent the command new
07/14/2015 08:22:38;0008;PBS_Server;Job;NULL;on_job_exit valid pjob: 0x1dcb770 (substate=10)
07/14/2015 08:22:38;0040;PBS_Server;Svr;tyrone-cluster;Scheduler was sent the command new
07/14/2015 08:23:08;0008;PBS_Server;Job;NULL;on_job_exit valid pjob: 0x1dcb770 (substate=10)
07/14/2015 08:23:08;0040;PBS_Server;Svr;tyrone-cluster;Scheduler was sent the command new
07/14/2015 08:23:38;0008;PBS_Server;Job;NULL;on_job_exit valid pjob: 0x1dcb770 (substate=10)
07/14/2015 08:23:40;0040;PBS_Server;Svr;tyrone-cluster;Scheduler was sent the command new
07/14/2015 08:24:00;000d;PBS_Server;Job;54559.tyrone-cluster;Not sending email: User does not want mail of this type.
07/14/2015 08:24:00;0002;PBS_Server;Svr;Act;Account file /var/spool/torque/server_priv/accounting/20150714 opened
07/14/2015 08:24:00;0010;PBS_Server;Job;54559.tyrone-cluster;Exit_status=143 resources_used.cput=48:39:43 resources_used.mem=24958208kb resources_used.vmem=28077548kb resources_used.walltime=24:00:15
07/14/2015 08:24:00;0008;PBS_Server;Job;NULL;on_job_exit valid pjob: 0x1da4410 (substate=50)
07/14/2015 08:24:00;0008;PBS_Server;Job;NULL;on_job_exit valid pjob: 0x1da4410 (substate=51)
07/14/2015 08:24:01;0008;PBS_Server;Job;NULL;on_job_exit valid pjob: 0x1da4410 (substate=51)
07/14/2015 08:24:01;0008;PBS_Server;Job;NULL;on_job_exit valid pjob: 0x1da4410 (substate=53)
07/14/2015 08:24:01;0100;PBS_Server;Job;54559.tyrone-cluster;dequeuing from qp32, state COMPLETE
07/14/2015 08:24:01;0040;PBS_Server;Svr;tyrone-cluster;Scheduler was sent the command term
07/14/2015 08:24:01;0008;PBS_Server;Job;54587.tyrone-cluster;Job Modified at request of Scheduler@tyrone-cluster
07/14/2015 08:24:01;0008;PBS_Server;Job;54587.tyrone-cluster;Job Run at request of Scheduler@tyrone-cluster
07/14/2015 08:24:01;000d;PBS_Server;Job;54587.tyrone-cluster;Not sending email: User does not want mail of this type.
07/14/2015 08:24:01;0040;PBS_Server;Svr;tyrone-cluster;Scheduler was sent the command recyc
07/14/2015 08:24:08;0008;PBS_Server;Job;NULL;on_job_exit valid pjob: 0x1dcb770 (substate=42)
07/14/2015 08:24:08;0040;PBS_Server;Svr;tyrone-cluster;Scheduler was sent the command new
07/14/2015 08:24:42;0040;PBS_Server;Svr;tyrone-cluster;Scheduler was sent the command new
07/14/2015 08:25:15;0040;PBS_Server;Svr;tyrone-cluster;Scheduler was sent the command new
07/14/2015 08:25:55;0040;PBS_Server;Svr;tyrone-cluster;Scheduler was sent the command new
07/14/2015 08:26:15;0040;PBS_Server;Svr;tyrone-cluster;Scheduler was sent the command new
07/14/2015 08:26:36;0002;PBS_Server;Svr;PBS_Server;Torque Server Version = 3.0.5, loglevel = 0
07/14/2015 08:26:46;0040;PBS_Server;Svr;tyrone-cluster;Scheduler was sent the command new
07/14/2015 08:27:26;0040;PBS_Server;Svr;tyrone-cluster;Scheduler was sent the command new
07/14/2015 08:28:10;0040;PBS_Server;Svr;tyrone-cluster;Scheduler was sent the command new
07/14/2015 08:28:30;0040;PBS_Server;Svr;tyrone-cluster;Scheduler was sent the command new
07/14/2015 08:29:00;0040;PBS_Server;Svr;tyrone-cluster;Scheduler was sent the command new
07/14/2015 08:29:40;0040;PBS_Server;Svr;tyrone-cluster;Scheduler was sent the command new
07/14/2015 08:30:01;0040;PBS_Server;Svr;tyrone-cluster;Scheduler was sent the command new
07/14/2015 08:30:31;0040;PBS_Server;Svr;tyrone-cluster;Scheduler was sent the command new
07/14/2015 08:31:11;0040;PBS_Server;Svr;tyrone-cluster;Scheduler was sent the command new
07/14/2015 08:31:36;0002;PBS_Server;Svr;PBS_Server;Torque Server Version = 3.0.5, loglevel = 0
07/14/2015 08:31:55;0040;PBS_Server;Svr;tyrone-cluster;Scheduler was sent the command new
07/14/2015 08:32:15;0040;PBS_Server;Svr;tyrone-cluster;Scheduler was sent the command new
07/14/2015 08:32:45;0040;PBS_Server;Svr;tyrone-cluster;Scheduler was sent the command new
07/14/2015 08:33:25;0040;PBS_Server;Svr;tyrone-cluster;Scheduler was sent the command new
07/14/2015 08:33:44;0040;PBS_Server;Svr;tyrone-cluster;Scheduler was sent the command new
07/14/2015 08:34:15;0040;PBS_Server;Svr;tyrone-cluster;Scheduler was sent the command new
07/14/2015 08:34:51;0040;PBS_Server;Svr;tyrone-cluster;Scheduler was sent the command new
07/14/2015 08:35:15;0040;PBS_Server;Svr;tyrone-cluster;Scheduler was sent the command new
07/14/2015 08:35:46;0040;PBS_Server;Svr;tyrone-cluster;Scheduler was sent the command new
07/14/2015 08:36:25;0040;PBS_Server;Svr;tyrone-cluster;Scheduler was sent the command new
07/14/2015 08:36:36;0002;PBS_Server;Svr;PBS_Server;Torque Server Version = 3.0.5, loglevel = 0
07/14/2015 08:36:44;0040;PBS_Server;Svr;tyrone-cluster;Scheduler was sent the command new
07/14/2015 08:37:15;0040;PBS_Server;Svr;tyrone-cluster;Scheduler was sent the command new
07/14/2015 08:37:55;0040;PBS_Server;Svr;tyrone-cluster;Scheduler was sent the command new
07/14/2015 08:38:17;0040;PBS_Server;Svr;tyrone-cluster;Scheduler was sent the command new
07/14/2015 08:38:46;0040;PBS_Server;Svr;tyrone-cluster;Scheduler was sent the command new
07/14/2015 08:39:09;0001;PBS_Server;Svr;PBS_Server;LOG_ERROR::process_Dreply, malloc failed
07/14/2015 08:39:26;0040;PBS_Server;Svr;tyrone-cluster;Scheduler was sent the command new
07/14/2015 08:40:10;0040;PBS_Server;Svr;tyrone-cluster;Scheduler was sent the command new
07/14/2015 08:40:30;0040;PBS_Server;Svr;tyrone-cluster;Scheduler was sent the command new
07/14/2015 08:41:00;0040;PBS_Server;Svr;tyrone-cluster;Scheduler was sent the command new
07/14/2015 08:41:36;0002;PBS_Server;Svr;PBS_Server;Torque Server Version = 3.0.5, loglevel = 0
07/14/2015 08:41:36;0040;PBS_Server;Svr;tyrone-cluster;Scheduler was sent the command new
07/14/2015 08:41:59;0040;PBS_Server;Svr;tyrone-cluster;Scheduler was sent the command new
07/14/2015 08:42:30;0040;PBS_Server;Svr;tyrone-cluster;Scheduler was sent the command new
07/14/2015 08:43:11;0040;PBS_Server;Svr;tyrone-cluster;Scheduler was sent the command new
07/14/2015 08:43:55;0040;PBS_Server;Svr;tyrone-cluster;Scheduler was sent the command new
07/14/2015 08:44:15;0040;PBS_Server;Svr;tyrone-cluster;Scheduler was sent the command new
07/14/2015 08:44:45;0040;PBS_Server;Svr;tyrone-cluster;Scheduler was sent the command new
07/14/2015 08:45:25;0040;PBS_Server;Svr;tyrone-cluster;Scheduler was sent the command new
07/14/2015 08:45:44;0040;PBS_Server;Svr;tyrone-cluster;Scheduler was sent the command new
07/14/2015 08:46:15;0040;PBS_Server;Svr;tyrone-cluster;Scheduler was sent the command new
07/14/2015 08:46:36;0002;PBS_Server;Svr;PBS_Server;Torque Server Version = 3.0.5, loglevel = 0
07/14/2015 08:46:55;0040;PBS_Server;Svr;tyrone-cluster;Scheduler was sent the command new
07/14/2015 08:47:14;0040;PBS_Server;Svr;tyrone-cluster;Scheduler was sent the command new
07/14/2015 08:47:45;0040;PBS_Server;Svr;tyrone-cluster;Scheduler was sent the command new
07/14/2015 08:48:26;0040;PBS_Server;Svr;tyrone-cluster;Scheduler was sent the command new
07/14/2015 08:49:10;0040;PBS_Server;Svr;tyrone-cluster;Scheduler was sent the command new
07/14/2015 08:49:29;0040;PBS_Server;Svr;tyrone-cluster;Scheduler was sent the command new
07/14/2015 08:50:00;0040;PBS_Server;Svr;tyrone-cluster;Scheduler was sent the command new
07/14/2015 08:50:40;0040;PBS_Server;Svr;tyrone-cluster;Scheduler was sent the command new
07/14/2015 08:51:00;0040;PBS_Server;Svr;tyrone-cluster;Scheduler was sent the command new
07/14/2015 08:51:31;0040;PBS_Server;Svr;tyrone-cluster;Scheduler was sent the command new
07/14/2015 08:51:36;0002;PBS_Server;Svr;PBS_Server;Torque Server Version = 3.0.5, loglevel = 0
07/14/2015 08:52:11;0040;PBS_Server;Svr;tyrone-cluster;Scheduler was sent the command new
07/14/2015 08:52:55;0040;PBS_Server;Svr;tyrone-cluster;Scheduler was sent the command new
07/14/2015 08:53:15;0040;PBS_Server;Svr;tyrone-cluster;Scheduler was sent the command new
07/14/2015 08:53:45;0040;PBS_Server;Svr;tyrone-cluster;Scheduler was sent the command new
07/14/2015 08:54:25;0040;PBS_Server;Svr;tyrone-cluster;Scheduler was sent the command new
07/14/2015 08:54:44;0040;PBS_Server;Svr;tyrone-cluster;Scheduler was sent the command new
07/14/2015 08:55:16;0040;PBS_Server;Svr;tyrone-cluster;Scheduler was sent the command new
07/14/2015 08:55:57;0040;PBS_Server;Svr;tyrone-cluster;Scheduler was sent the command new
07/14/2015 08:56:36;0002;PBS_Server;Svr;PBS_Server;Torque Server Version = 3.0.5, loglevel = 0
07/14/2015 08:56:36;0040;PBS_Server;Svr;tyrone-cluster;Scheduler was sent the command new
07/14/2015 08:56:59;0040;PBS_Server;Svr;tyrone-cluster;Scheduler was sent the command new
07/14/2015 08:57:31;0040;PBS_Server;Svr;tyrone-cluster;Scheduler was sent the command new
07/14/2015 08:58:12;0040;PBS_Server;Svr;tyrone-cluster;Scheduler was sent the command new
07/14/2015 08:58:56;0040;PBS_Server;Svr;tyrone-cluster;Scheduler was sent the command new
07/14/2015 08:59:14;0040;PBS_Server;Svr;tyrone-cluster;Scheduler was sent the command new
07/14/2015 08:59:45;0040;PBS_Server;Svr;tyrone-cluster;Scheduler was sent the command new
07/14/2015 09:00:26;0040;PBS_Server;Svr;tyrone-cluster;Scheduler was sent the command new
07/14/2015 09:00:44;0040;PBS_Server;Svr;tyrone-cluster;Scheduler was sent the command new
07/14/2015 09:01:16;0040;PBS_Server;Svr;tyrone-cluster;Scheduler was sent the command new
07/14/2015 09:01:36;0002;PBS_Server;Svr;PBS_Server;Torque Server Version = 3.0.5, loglevel = 0
07/14/2015 09:01:57;0040;PBS_Server;Svr;tyrone-cluster;Scheduler was sent the command new
07/14/2015 09:02:41;0040;PBS_Server;Svr;tyrone-cluster;Scheduler was sent the command new
07/14/2015 09:02:59;0040;PBS_Server;Svr;tyrone-cluster;Scheduler was sent the command new
07/14/2015 09:03:30;0040;PBS_Server;Svr;tyrone-cluster;Scheduler was sent the command new
07/14/2015 09:04:12;0040;PBS_Server;Svr;tyrone-cluster;Scheduler was sent the command new
07/14/2015 09:04:56;0040;PBS_Server;Svr;tyrone-cluster;Scheduler was sent the command new
07/14/2015 09:05:14;0040;PBS_Server;Svr;tyrone-cluster;Scheduler was sent the command new
07/14/2015 09:05:46;0040;PBS_Server;Svr;tyrone-cluster;Scheduler was sent the command new
07/14/2015 09:06:27;0040;PBS_Server;Svr;tyrone-cluster;Scheduler was sent the command new
07/14/2015 09:06:36;0002;PBS_Server;Svr;PBS_Server;Torque Server Version = 3.0.5, loglevel = 0
07/14/2015 09:07:11;0040;PBS_Server;Svr;tyrone-cluster;Scheduler was sent the command new
07/14/2015 09:07:29;0040;PBS_Server;Svr;tyrone-cluster;Scheduler was sent the command new
07/14/2015 09:08:00;0040;PBS_Server;Svr;tyrone-cluster;Scheduler was sent the command new
07/14/2015 09:08:42;0040;PBS_Server;Svr;tyrone-cluster;Scheduler was sent the command new
07/14/2015 09:09:26;0040;PBS_Server;Svr;tyrone-cluster;Scheduler was sent the command new
07/14/2015 09:09:44;0040;PBS_Server;Svr;tyrone-cluster;Scheduler was sent the command new
07/14/2015 09:10:16;0040;PBS_Server;Svr;tyrone-cluster;Scheduler was sent the command new
07/14/2015 09:10:57;0040;PBS_Server;Svr;tyrone-cluster;Scheduler was sent the command new
07/14/2015 09:11:36;0002;PBS_Server;Svr;PBS_Server;Torque Server Version = 3.0.5, loglevel = 0
07/14/2015 09:11:36;0040;PBS_Server;Svr;tyrone-cluster;Scheduler was sent the command new
07/14/2015 09:11:59;0040;PBS_Server;Svr;tyrone-cluster;Scheduler was sent the command new
07/14/2015 09:12:30;0040;PBS_Server;Svr;tyrone-cluster;Scheduler was sent the command new
07/14/2015 09:13:12;0040;PBS_Server;Svr;tyrone-cluster;Scheduler was sent the command new
07/14/2015 09:13:56;0040;PBS_Server;Svr;tyrone-cluster;Scheduler was sent the command new
07/14/2015 09:14:14;0040;PBS_Server;Svr;tyrone-cluster;Scheduler was sent the command new
07/14/2015 09:14:46;0040;PBS_Server;Svr;tyrone-cluster;Scheduler was sent the command new
07/14/2015 09:15:27;0040;PBS_Server;Svr;tyrone-cluster;Scheduler was sent the command new
07/14/2015 09:16:11;0040;PBS_Server;Svr;tyrone-cluster;Scheduler was sent the command new
07/14/2015 09:16:29;0040;PBS_Server;Svr;tyrone-cluster;Scheduler was sent the command new
07/14/2015 09:16:36;0002;PBS_Server;Svr;PBS_Server;Torque Server Version = 3.0.5, loglevel = 0
07/14/2015 09:17:00;0040;PBS_Server;Svr;tyrone-cluster;Scheduler was sent the command new
07/14/2015 09:17:41;0040;PBS_Server;Svr;tyrone-cluster;Scheduler was sent the command new
07/14/2015 09:17:59;0040;PBS_Server;Svr;tyrone-cluster;Scheduler was sent the command new
07/14/2015 09:18:30;0040;PBS_Server;Svr;tyrone-cluster;Scheduler was sent the command new
07/14/2015 09:19:11;0040;PBS_Server;Svr;tyrone-cluster;Scheduler was sent the command new
07/14/2015 09:19:29;0040;PBS_Server;Svr;tyrone-cluster;Scheduler was sent the command new
07/14/2015 09:20:00;0040;PBS_Server;Svr;tyrone-cluster;Scheduler was sent the command new
07/14/2015 09:20:42;0040;PBS_Server;Svr;tyrone-cluster;Scheduler was sent the command new
07/14/2015 09:21:26;0040;PBS_Server;Svr;tyrone-cluster;Scheduler was sent the command new
07/14/2015 09:21:36;0002;PBS_Server;Svr;PBS_Server;Torque Server Version = 3.0.5, loglevel = 0
07/14/2015 09:21:44;0040;PBS_Server;Svr;tyrone-cluster;Scheduler was sent the command new
07/14/2015 09:22:15;0040;PBS_Server;Svr;tyrone-cluster;Scheduler was sent the command new
07/14/2015 09:22:56;0040;PBS_Server;Svr;tyrone-cluster;Scheduler was sent the command new
07/14/2015 09:23:14;0040;PBS_Server;Svr;tyrone-cluster;Scheduler was sent the command new
07/14/2015 09:23:45;0040;PBS_Server;Svr;tyrone-cluster;Scheduler was sent the command new
07/14/2015 09:24:27;0040;PBS_Server;Svr;tyrone-cluster;Scheduler was sent the command new
07/14/2015 09:25:11;0040;PBS_Server;Svr;tyrone-cluster;Scheduler was sent the command new
07/14/2015 09:25:29;0040;PBS_Server;Svr;tyrone-cluster;Scheduler was sent the command new
07/14/2015 09:26:00;0040;PBS_Server;Svr;tyrone-cluster;Scheduler was sent the command new
07/14/2015 09:26:36;0002;PBS_Server;Svr;PBS_Server;Torque Server Version = 3.0.5, loglevel = 0
07/14/2015 09:26:41;0040;PBS_Server;Svr;tyrone-cluster;Scheduler was sent the command new
07/14/2015 09:27:08;0040;PBS_Server;Svr;tyrone-cluster;Scheduler was sent the command new
07/14/2015 09:27:43;0040;PBS_Server;Svr;tyrone-cluster;Scheduler was sent the command new
07/14/2015 09:28:12;0040;PBS_Server;Svr;tyrone-cluster;Scheduler was sent the command new
07/14/2015 09:28:56;0040;PBS_Server;Svr;tyrone-cluster;Scheduler was sent the command new
07/14/2015 09:29:14;0040;PBS_Server;Svr;tyrone-cluster;Scheduler was sent the command new
07/14/2015 09:29:45;0040;PBS_Server;Svr;tyrone-cluster;Scheduler was sent the command new
07/14/2015 09:30:27;0040;PBS_Server;Svr;tyrone-cluster;Scheduler was sent the command new
07/14/2015 09:31:11;0040;PBS_Server;Svr;tyrone-cluster;Scheduler was sent the command new
07/14/2015 09:31:29;0040;PBS_Server;Svr;tyrone-cluster;Scheduler was sent the command new
07/14/2015 09:31:36;0002;PBS_Server;Svr;PBS_Server;Torque Server Version = 3.0.5, loglevel = 0
07/14/2015 09:32:00;0040;PBS_Server;Svr;tyrone-cluster;Scheduler was sent the command new
07/14/2015 09:32:41;0040;PBS_Server;Svr;tyrone-cluster;Scheduler was sent the command new
07/14/2015 09:32:59;0040;PBS_Server;Svr;tyrone-cluster;Scheduler was sent the command new
07/14/2015 09:33:30;0040;PBS_Server;Svr;tyrone-cluster;Scheduler was sent the command new
07/14/2015 09:34:12;0040;PBS_Server;Svr;tyrone-cluster;Scheduler was sent the command new
07/14/2015 09:34:51;0040;PBS_Server;Svr;tyrone-cluster;Scheduler was sent the command new
07/14/2015 09:35:14;0040;PBS_Server;Svr;tyrone-cluster;Scheduler was sent the command new
07/14/2015 09:35:45;0040;PBS_Server;Svr;tyrone-cluster;Scheduler was sent the command new
07/14/2015 09:36:26;0040;PBS_Server;Svr;tyrone-cluster;Scheduler was sent the command new
07/14/2015 09:36:36;0002;PBS_Server;Svr;PBS_Server;Torque Server Version = 3.0.5, loglevel = 0
07/14/2015 09:36:44;0040;PBS_Server;Svr;tyrone-cluster;Scheduler was sent the command new
07/14/2015 09:37:15;0040;PBS_Server;Svr;tyrone-cluster;Scheduler was sent the command new
07/14/2015 09:37:57;0040;PBS_Server;Svr;tyrone-cluster;Scheduler was sent the command new
07/14/2015 09:38:41;0040;PBS_Server;Svr;tyrone-cluster;Scheduler was sent the command new
07/14/2015 09:38:59;0040;PBS_Server;Svr;tyrone-cluster;Scheduler was sent the command new
07/14/2015 09:39:30;0040;PBS_Server;Svr;tyrone-cluster;Scheduler was sent the command new
07/14/2015 09:39:51;0100;PBS_Server;Job;54626.tyrone-cluster;enqueuing into batch, state 1 hop 1
07/14/2015 09:39:51;0100;PBS_Server;Job;54626.tyrone-cluster;dequeuing from batch, state QUEUED
07/14/2015 09:39:51;0100;PBS_Server;Job;54626.tyrone-cluster;enqueuing into qp128, state 1 hop 1
07/14/2015 09:39:51;0008;PBS_Server;Job;54626.tyrone-cluster;Job Queued at request of asenave@tyrone-cluster, owner = asenave@tyrone-cluster, job name = channel, queue = qp128
07/14/2015 09:39:51;0040;PBS_Server;Svr;tyrone-cluster;Scheduler was sent the command new
07/14/2015 09:39:51;0008;PBS_Server;Job;54626.tyrone-cluster;Job Modified at request of Scheduler@tyrone-cluster
07/14/2015 09:39:51;0008;PBS_Server;Job;54626.tyrone-cluster;Job Run at request of Scheduler@tyrone-cluster
07/14/2015 09:39:51;0040;PBS_Server;Svr;tyrone-cluster;Scheduler was sent the command recyc
07/14/2015 09:40:09;0040;PBS_Server;Svr;tyrone-cluster;Scheduler was sent the command new
07/14/2015 09:40:12;000d;PBS_Server;Job;54626.tyrone-cluster;Not sending email: User does not want mail of this type.
07/14/2015 09:40:29;0040;PBS_Server;Svr;tyrone-cluster;Scheduler was sent the command new
07/14/2015 09:41:00;0040;PBS_Server;Svr;tyrone-cluster;Scheduler was sent the command new
07/14/2015 09:41:36;0002;PBS_Server;Svr;PBS_Server;Torque Server Version = 3.0.5, loglevel = 0
07/14/2015 09:41:41;0040;PBS_Server;Svr;tyrone-cluster;Scheduler was sent the command new
07/14/2015 09:42:07;0040;PBS_Server;Svr;tyrone-cluster;Scheduler was sent the command new
07/14/2015 09:42:43;0040;PBS_Server;Svr;tyrone-cluster;Scheduler was sent the command new
07/14/2015 09:43:12;0040;PBS_Server;Svr;tyrone-cluster;Scheduler was sent the command new
07/14/2015 09:43:56;0040;PBS_Server;Svr;tyrone-cluster;Scheduler was sent the command new
07/14/2015 09:44:17;0040;PBS_Server;Svr;tyrone-cluster;Scheduler was sent the command new
07/14/2015 09:44:45;0040;PBS_Server;Svr;tyrone-cluster;Scheduler was sent the command new
07/14/2015 09:45:27;0040;PBS_Server;Svr;tyrone-cluster;Scheduler was sent the command new
07/14/2015 09:46:11;0040;PBS_Server;Svr;tyrone-cluster;Scheduler was sent the command new
07/14/2015 09:46:29;0040;PBS_Server;Svr;tyrone-cluster;Scheduler was sent the command new
07/14/2015 09:46:36;0002;PBS_Server;Svr;PBS_Server;Torque Server Version = 3.0.5, loglevel = 0
07/14/2015 09:47:00;0040;PBS_Server;Svr;tyrone-cluster;Scheduler was sent the command new
07/14/2015 09:47:41;0040;PBS_Server;Svr;tyrone-cluster;Scheduler was sent the command new
07/14/2015 09:47:59;0040;PBS_Server;Svr;tyrone-cluster;Scheduler was sent the command new
07/14/2015 09:48:30;0040;PBS_Server;Svr;tyrone-cluster;Scheduler was sent the command new
07/14/2015 09:49:12;0040;PBS_Server;Svr;tyrone-cluster;Scheduler was sent the command new
07/14/2015 09:49:56;0040;PBS_Server;Svr;tyrone-cluster;Scheduler was sent the command new
07/14/2015 09:50:14;0040;PBS_Server;Svr;tyrone-cluster;Scheduler was sent the command new
07/14/2015 09:50:45;0040;PBS_Server;Svr;tyrone-cluster;Scheduler was sent the command new
07/14/2015 09:51:27;0040;PBS_Server;Svr;tyrone-cluster;Scheduler was sent the command new
07/14/2015 09:51:36;0002;PBS_Server;Svr;PBS_Server;Torque Server Version = 3.0.5, loglevel = 0
07/14/2015 09:52:11;0040;PBS_Server;Svr;tyrone-cluster;Scheduler was sent the command new
07/14/2015 09:52:29;0040;PBS_Server;Svr;tyrone-cluster;Scheduler was sent the command new
07/14/2015 09:53:00;0040;PBS_Server;Svr;tyrone-cluster;Scheduler was sent the command new
07/14/2015 09:53:42;0040;PBS_Server;Svr;tyrone-cluster;Scheduler was sent the command new
07/14/2015 09:54:26;0040;PBS_Server;Svr;tyrone-cluster;Scheduler was sent the command new
07/14/2015 09:54:44;0040;PBS_Server;Svr;tyrone-cluster;Scheduler was sent the command new
07/14/2015 09:55:15;0040;PBS_Server;Svr;tyrone-cluster;Scheduler was sent the command new
07/14/2015 09:55:57;0040;PBS_Server;Svr;tyrone-cluster;Scheduler was sent the command new
07/14/2015 09:56:36;0002;PBS_Server;Svr;PBS_Server;Torque Server Version = 3.0.5, loglevel = 0
07/14/2015 09:56:36;0040;PBS_Server;Svr;tyrone-cluster;Scheduler was sent the command new
07/14/2015 09:56:59;0040;PBS_Server;Svr;tyrone-cluster;Scheduler was sent the command new
07/14/2015 09:57:30;0040;PBS_Server;Svr;tyrone-cluster;Scheduler was sent the command new
07/14/2015 09:58:12;0040;PBS_Server;Svr;tyrone-cluster;Scheduler was sent the command new
07/14/2015 09:58:56;0040;PBS_Server;Svr;tyrone-cluster;Scheduler was sent the command new
07/14/2015 09:59:15;0040;PBS_Server;Svr;tyrone-cluster;Scheduler was sent the command new
07/14/2015 09:59:45;0040;PBS_Server;Svr;tyrone-cluster;Scheduler was sent the command new
07/14/2015 10:00:27;0040;PBS_Server;Svr;tyrone-cluster;Scheduler was sent the command new
07/14/2015 10:01:11;0040;PBS_Server;Svr;tyrone-cluster;Scheduler was sent the command new
07/14/2015 10:01:29;0040;PBS_Server;Svr;tyrone-cluster;Scheduler was sent the command new
07/14/2015 10:01:36;0002;PBS_Server;Svr;PBS_Server;Torque Server Version = 3.0.5, loglevel = 0
07/14/2015 10:02:00;0040;PBS_Server;Svr;tyrone-cluster;Scheduler was sent the command new
07/14/2015 10:02:41;0040;PBS_Server;Svr;tyrone-cluster;Scheduler was sent the command new
07/14/2015 10:02:59;0040;PBS_Server;Svr;tyrone-cluster;Scheduler was sent the command new
07/14/2015 10:03:30;0040;PBS_Server;Svr;tyrone-cluster;Scheduler was sent the command new
07/14/2015 10:04:03;0040;PBS_Server;Svr;tyrone-cluster;Scheduler was sent the command new
07/14/2015 10:04:35;0040;PBS_Server;Svr;tyrone-cluster;Scheduler was sent the command new
07/14/2015 10:05:07;0040;PBS_Server;Svr;tyrone-cluster;Scheduler was sent the command new
07/14/2015 10:05:42;0040;PBS_Server;Svr;tyrone-cluster;Scheduler was sent the command new
07/14/2015 10:06:26;0040;PBS_Server;Svr;tyrone-cluster;Scheduler was sent the command new
07/14/2015 10:06:36;0002;PBS_Server;Svr;PBS_Server;Torque Server Version = 3.0.5, loglevel = 0
07/14/2015 10:06:44;0040;PBS_Server;Svr;tyrone-cluster;Scheduler was sent the command new
07/14/2015 10:07:15;0040;PBS_Server;Svr;tyrone-cluster;Scheduler was sent the command new
07/14/2015 10:07:57;0040;PBS_Server;Svr;tyrone-cluster;Scheduler was sent the command new
07/14/2015 10:08:27;0040;PBS_Server;Svr;tyrone-cluster;Scheduler was sent the command new
07/14/2015 10:08:58;0040;PBS_Server;Svr;tyrone-cluster;Scheduler was sent the command new
07/14/2015 10:09:30;0040;PBS_Server;Svr;tyrone-cluster;Scheduler was sent the command new
07/14/2015 10:10:11;0040;PBS_Server;Svr;tyrone-cluster;Scheduler was sent the command new
07/14/2015 10:10:29;0040;PBS_Server;Svr;tyrone-cluster;Scheduler was sent the command new
07/14/2015 10:11:00;0040;PBS_Server;Svr;tyrone-cluster;Scheduler was sent the command new
07/14/2015 10:11:36;0002;PBS_Server;Svr;PBS_Server;Torque Server Version = 3.0.5, loglevel = 0
07/14/2015 10:11:41;0040;PBS_Server;Svr;tyrone-cluster;Scheduler was sent the command new
07/14/2015 10:12:08;0040;PBS_Server;Svr;tyrone-cluster;Scheduler was sent the command new
07/14/2015 10:12:38;0040;PBS_Server;Svr;tyrone-cluster;Scheduler was sent the command new
07/14/2015 10:13:12;0040;PBS_Server;Svr;tyrone-cluster;Scheduler was sent the command new
07/14/2015 10:13:56;0040;PBS_Server;Svr;tyrone-cluster;Scheduler was sent the command new
07/14/2015 10:13:56;0100;PBS_Server;Job;54627.tyrone-cluster;enqueuing into batch, state 1 hop 1
07/14/2015 10:13:56;0100;PBS_Server;Job;54627.tyrone-cluster;dequeuing from batch, state QUEUED
07/14/2015 10:13:56;0100;PBS_Server;Job;54627.tyrone-cluster;enqueuing into qp32, state 1 hop 1
07/14/2015 10:13:56;0008;PBS_Server;Job;54627.tyrone-cluster;Job Queued at request of secvinod@tyrone-cluster, owner = secvinod@tyrone-cluster, job name = test, queue = qp32
07/14/2015 10:13:56;0040;PBS_Server;Svr;tyrone-cluster;Scheduler was sent the command new
07/14/2015 10:13:57;0008;PBS_Server;Job;54627.tyrone-cluster;Job Modified at request of Scheduler@tyrone-cluster
07/14/2015 10:14:14;0040;PBS_Server;Svr;tyrone-cluster;Scheduler was sent the command new
07/14/2015 10:14:18;0008;PBS_Server;Job;54627.tyrone-cluster;Job deleted at request of secvinod@tyrone-cluster
07/14/2015 10:14:18;0008;PBS_Server;Job;NULL;on_job_exit valid pjob: 0x1cbbf10 (substate=59)
07/14/2015 10:14:18;0100;PBS_Server;Job;54627.tyrone-cluster;dequeuing from qp32, state COMPLETE
07/14/2015 10:14:18;0040;PBS_Server;Svr;tyrone-cluster;Scheduler was sent the command term
07/14/2015 10:14:31;0100;PBS_Server;Job;54628.tyrone-cluster;enqueuing into batch, state 1 hop 1
07/14/2015 10:14:31;0100;PBS_Server;Job;54628.tyrone-cluster;dequeuing from batch, state QUEUED
07/14/2015 10:14:31;0100;PBS_Server;Job;54628.tyrone-cluster;enqueuing into idqueue, state 1 hop 1
07/14/2015 10:14:31;0008;PBS_Server;Job;54628.tyrone-cluster;Job Queued at request of secvinod@tyrone-cluster, owner = secvinod@tyrone-cluster, job name = test, queue = idqueue
07/14/2015 10:14:31;0040;PBS_Server;Svr;tyrone-cluster;Scheduler was sent the command new
07/14/2015 10:14:31;0008;PBS_Server;Job;54628.tyrone-cluster;Job Modified at request of Scheduler@tyrone-cluster
07/14/2015 10:14:31;0008;PBS_Server;Job;54628.tyrone-cluster;Job Run at request of Scheduler@tyrone-cluster
07/14/2015 10:14:31;0040;PBS_Server;Svr;tyrone-cluster;Scheduler was sent the command recyc
07/14/2015 10:14:31;000d;PBS_Server;Job;54628.tyrone-cluster;Not sending email: User does not want mail of this type.
07/14/2015 10:14:32;000d;PBS_Server;Job;54628.tyrone-cluster;Not sending email: User does not want mail of this type.
07/14/2015 10:14:32;0010;PBS_Server;Job;54628.tyrone-cluster;Exit_status=255 resources_used.cput=00:00:00 resources_used.mem=0kb resources_used.vmem=0kb resources_used.walltime=00:00:01
07/14/2015 10:14:32;0008;PBS_Server;Job;NULL;on_job_exit valid pjob: 0x1dee940 (substate=50)
07/14/2015 10:14:32;0008;PBS_Server;Job;NULL;on_job_exit valid pjob: 0x1dee940 (substate=51)
07/14/2015 10:14:32;0008;PBS_Server;Job;NULL;on_job_exit valid pjob: 0x1dee940 (substate=51)
07/14/2015 10:14:32;0008;PBS_Server;Job;NULL;on_job_exit valid pjob: 0x1dee940 (substate=53)
07/14/2015 10:14:32;0100;PBS_Server;Job;54628.tyrone-cluster;dequeuing from idqueue, state COMPLETE
07/14/2015 10:14:32;0040;PBS_Server;Svr;tyrone-cluster;Scheduler was sent the command term
07/14/2015 10:14:45;0040;PBS_Server;Svr;tyrone-cluster;Scheduler was sent the command new
07/14/2015 10:15:27;0040;PBS_Server;Svr;tyrone-cluster;Scheduler was sent the command new
07/14/2015 10:16:11;0040;PBS_Server;Svr;tyrone-cluster;Scheduler was sent the command new
07/14/2015 10:16:30;0040;PBS_Server;Svr;tyrone-cluster;Scheduler was sent the command new
07/14/2015 10:16:36;0002;PBS_Server;Svr;PBS_Server;Torque Server Version = 3.0.5, loglevel = 0
07/14/2015 10:17:00;0040;PBS_Server;Svr;tyrone-cluster;Scheduler was sent the command new
07/14/2015 10:17:36;0040;PBS_Server;Svr;tyrone-cluster;Scheduler was sent the command new
07/14/2015 10:17:36;0100;PBS_Server;Job;54629.tyrone-cluster;enqueuing into batch, state 1 hop 1
07/14/2015 10:17:36;0100;PBS_Server;Job;54629.tyrone-cluster;dequeuing from batch, state QUEUED
07/14/2015 10:17:36;0100;PBS_Server;Job;54629.tyrone-cluster;enqueuing into idqueue, state 1 hop 1
07/14/2015 10:17:36;0008;PBS_Server;Job;54629.tyrone-cluster;Job Queued at request of secvinod@tyrone-cluster, owner = secvinod@tyrone-cluster, job name = test, queue = idqueue
07/14/2015 10:17:36;0008;PBS_Server;Job;54629.tyrone-cluster;Job Modified at request of Scheduler@tyrone-cluster
07/14/2015 10:17:36;0008;PBS_Server;Job;54629.tyrone-cluster;Job Run at request of Scheduler@tyrone-cluster
07/14/2015 10:17:36;0040;PBS_Server;Svr;tyrone-cluster;Scheduler was sent the command recyc
07/14/2015 10:17:36;000d;PBS_Server;Job;54629.tyrone-cluster;Not sending email: User does not want mail of this type.
07/14/2015 10:17:37;000d;PBS_Server;Job;54629.tyrone-cluster;Not sending email: User does not want mail of this type.
07/14/2015 10:17:37;0010;PBS_Server;Job;54629.tyrone-cluster;Exit_status=0 resources_used.cput=00:00:18 resources_used.mem=0kb resources_used.vmem=0kb resources_used.walltime=00:00:01
07/14/2015 10:17:37;0008;PBS_Server;Job;NULL;on_job_exit valid pjob: 0x1da82f0 (substate=50)
07/14/2015 10:17:37;0008;PBS_Server;Job;NULL;on_job_exit valid pjob: 0x1da82f0 (substate=51)
07/14/2015 10:17:37;0008;PBS_Server;Job;NULL;on_job_exit valid pjob: 0x1da82f0 (substate=51)
07/14/2015 10:17:37;0008;PBS_Server;Job;NULL;on_job_exit valid pjob: 0x1da82f0 (substate=53)
07/14/2015 10:17:37;0100;PBS_Server;Job;54629.tyrone-cluster;dequeuing from idqueue, state COMPLETE
07/14/2015 10:17:37;0040;PBS_Server;Svr;tyrone-cluster;Scheduler was sent the command term
07/14/2015 10:18:07;0040;PBS_Server;Svr;tyrone-cluster;Scheduler was sent the command new
07/14/2015 10:18:40;0040;PBS_Server;Svr;tyrone-cluster;Scheduler was sent the command new
07/14/2015 10:19:12;0040;PBS_Server;Svr;tyrone-cluster;Scheduler was sent the command new
07/14/2015 10:19:44;0040;PBS_Server;Svr;tyrone-cluster;Scheduler was sent the command new
07/14/2015 10:20:13;0040;PBS_Server;Svr;tyrone-cluster;Scheduler was sent the command new
07/14/2015 10:20:45;0040;PBS_Server;Svr;tyrone-cluster;Scheduler was sent the command new
07/14/2015 10:21:26;0040;PBS_Server;Svr;tyrone-cluster;Scheduler was sent the command new
07/14/2015 10:21:36;0002;PBS_Server;Svr;PBS_Server;Torque Server Version = 3.0.5, loglevel = 0
07/14/2015 10:21:45;0040;PBS_Server;Svr;tyrone-cluster;Scheduler was sent the command new
07/14/2015 10:22:15;0040;PBS_Server;Svr;tyrone-cluster;Scheduler was sent the command new
07/14/2015 10:22:57;0040;PBS_Server;Svr;tyrone-cluster;Scheduler was sent the command new
07/14/2015 10:23:41;0040;PBS_Server;Svr;tyrone-cluster;Scheduler was sent the command new
07/14/2015 10:23:59;0040;PBS_Server;Svr;tyrone-cluster;Scheduler was sent the command new
07/14/2015 10:24:30;0040;PBS_Server;Svr;tyrone-cluster;Scheduler was sent the command new
07/14/2015 10:25:03;0040;PBS_Server;Svr;tyrone-cluster;Scheduler was sent the command new
07/14/2015 10:25:32;0040;PBS_Server;Svr;tyrone-cluster;Scheduler was sent the command new
07/14/2015 10:26:00;0040;PBS_Server;Svr;tyrone-cluster;Scheduler was sent the command new
07/14/2015 10:26:36;0002;PBS_Server;Svr;PBS_Server;Torque Server Version = 3.0.5, loglevel = 0
07/14/2015 10:26:36;0040;PBS_Server;Svr;tyrone-cluster;Scheduler was sent the command new
07/14/2015 10:27:00;0040;PBS_Server;Svr;tyrone-cluster;Scheduler was sent the command new
07/14/2015 10:27:30;0040;PBS_Server;Svr;tyrone-cluster;Scheduler was sent the command new
07/14/2015 10:28:12;0040;PBS_Server;Svr;tyrone-cluster;Scheduler was sent the command new
07/14/2015 10:28:44;0040;PBS_Server;Svr;tyrone-cluster;Scheduler was sent the command new
07/14/2015 10:29:13;0040;PBS_Server;Svr;tyrone-cluster;Scheduler was sent the command new
07/14/2015 10:29:45;0040;PBS_Server;Svr;tyrone-cluster;Scheduler was sent the command new
07/14/2015 10:30:26;0040;PBS_Server;Svr;tyrone-cluster;Scheduler was sent the command new
07/14/2015 10:30:45;0040;PBS_Server;Svr;tyrone-cluster;Scheduler was sent the command new
07/14/2015 10:31:15;0040;PBS_Server;Svr;tyrone-cluster;Scheduler was sent the command new
07/14/2015 10:31:36;0002;PBS_Server;Svr;PBS_Server;Torque Server Version = 3.0.5, loglevel = 0
07/14/2015 10:31:57;0040;PBS_Server;Svr;tyrone-cluster;Scheduler was sent the command new
07/14/2015 10:32:41;0040;PBS_Server;Svr;tyrone-cluster;Scheduler was sent the command new
07/14/2015 10:32:59;0040;PBS_Server;Svr;tyrone-cluster;Scheduler was sent the command new
07/14/2015 10:33:31;0040;PBS_Server;Svr;tyrone-cluster;Scheduler was sent the command new
07/14/2015 10:34:11;0040;PBS_Server;Svr;tyrone-cluster;Scheduler was sent the command new
07/14/2015 10:34:30;0040;PBS_Server;Svr;tyrone-cluster;Scheduler was sent the command new
07/14/2015 10:35:00;0040;PBS_Server;Svr;tyrone-cluster;Scheduler was sent the command new
07/14/2015 10:35:42;0040;PBS_Server;Svr;tyrone-cluster;Scheduler was sent the command new
07/14/2015 10:36:26;0040;PBS_Server;Svr;tyrone-cluster;Scheduler was sent the command new
07/14/2015 10:36:36;0002;PBS_Server;Svr;PBS_Server;Torque Server Version = 3.0.5, loglevel = 0
07/14/2015 10:36:44;0040;PBS_Server;Svr;tyrone-cluster;Scheduler was sent the command new
07/14/2015 10:37:15;0040;PBS_Server;Svr;tyrone-cluster;Scheduler was sent the command new
07/14/2015 10:37:56;0040;PBS_Server;Svr;tyrone-cluster;Scheduler was sent the command new
07/14/2015 10:38:15;0040;PBS_Server;Svr;tyrone-cluster;Scheduler was sent the command new
07/14/2015 10:38:45;0040;PBS_Server;Svr;tyrone-cluster;Scheduler was sent the command new
07/14/2015 10:39:27;0040;PBS_Server;Svr;tyrone-cluster;Scheduler was sent the command new
07/14/2015 10:40:00;0040;PBS_Server;Svr;tyrone-cluster;Scheduler was sent the command new
07/14/2015 10:40:28;0040;PBS_Server;Svr;tyrone-cluster;Scheduler was sent the command new
07/14/2015 10:41:01;0040;PBS_Server;Svr;tyrone-cluster;Scheduler was sent the command new
07/14/2015 10:41:34;0040;PBS_Server;Svr;tyrone-cluster;Scheduler was sent the command new
07/14/2015 10:41:36;0002;PBS_Server;Svr;PBS_Server;Torque Server Version = 3.0.5, loglevel = 0
07/14/2015 10:42:01;0040;PBS_Server;Svr;tyrone-cluster;Scheduler was sent the command new
07/14/2015 10:42:30;0040;PBS_Server;Svr;tyrone-cluster;Scheduler was sent the command new
07/14/2015 10:43:11;0040;PBS_Server;Svr;tyrone-cluster;Scheduler was sent the command new
07/14/2015 10:43:30;0040;PBS_Server;Svr;tyrone-cluster;Scheduler was sent the command new
07/14/2015 10:44:00;0040;PBS_Server;Svr;tyrone-cluster;Scheduler was sent the command new
07/14/2015 10:44:41;0040;PBS_Server;Svr;tyrone-cluster;Scheduler was sent the command new
07/14/2015 10:45:00;0040;PBS_Server;Svr;tyrone-cluster;Scheduler was sent the command new
07/14/2015 10:45:30;0040;PBS_Server;Svr;tyrone-cluster;Scheduler was sent the command new
07/14/2015 10:46:12;0040;PBS_Server;Svr;tyrone-cluster;Scheduler was sent the command new
07/14/2015 10:46:36;0002;PBS_Server;Svr;PBS_Server;Torque Server Version = 3.0.5, loglevel = 0
07/14/2015 10:46:45;0040;PBS_Server;Svr;tyrone-cluster;Scheduler was sent the command new
07/14/2015 10:47:13;0040;PBS_Server;Svr;tyrone-cluster;Scheduler was sent the command new
07/14/2015 10:47:46;0040;PBS_Server;Svr;tyrone-cluster;Scheduler was sent the command new
07/14/2015 10:48:26;0040;PBS_Server;Svr;tyrone-cluster;Scheduler was sent the command new
07/14/2015 10:48:45;0040;PBS_Server;Svr;tyrone-cluster;Scheduler was sent the command new
07/14/2015 10:49:15;0040;PBS_Server;Svr;tyrone-cluster;Scheduler was sent the command new
07/14/2015 10:49:57;0040;PBS_Server;Svr;tyrone-cluster;Scheduler was sent the command new
07/14/2015 10:50:29;0040;PBS_Server;Svr;tyrone-cluster;Scheduler was sent the command new
07/14/2015 10:50:58;0040;PBS_Server;Svr;tyrone-cluster;Scheduler was sent the command new
07/14/2015 10:51:30;0040;PBS_Server;Svr;tyrone-cluster;Scheduler was sent the command new
07/14/2015 10:51:36;0002;PBS_Server;Svr;PBS_Server;Torque Server Version = 3.0.5, loglevel = 0
07/14/2015 10:52:00;0040;PBS_Server;Svr;tyrone-cluster;Scheduler was sent the command new
07/14/2015 10:52:29;0040;PBS_Server;Svr;tyrone-cluster;Scheduler was sent the command new
07/14/2015 10:53:01;0040;PBS_Server;Svr;tyrone-cluster;Scheduler was sent the command new
07/14/2015 10:53:41;0040;PBS_Server;Svr;tyrone-cluster;Scheduler was sent the command new
07/14/2015 10:54:00;0040;PBS_Server;Svr;tyrone-cluster;Scheduler was sent the command new
07/14/2015 10:54:30;0040;PBS_Server;Svr;tyrone-cluster;Scheduler was sent the command new
07/14/2015 10:55:12;0040;PBS_Server;Svr;tyrone-cluster;Scheduler was sent the command new
07/14/2015 10:55:44;0040;PBS_Server;Svr;tyrone-cluster;Scheduler was sent the command new
07/14/2015 10:56:13;0040;PBS_Server;Svr;tyrone-cluster;Scheduler was sent the command new
07/14/2015 10:56:36;0002;PBS_Server;Svr;PBS_Server;Torque Server Version = 3.0.5, loglevel = 0
07/14/2015 10:56:45;0040;PBS_Server;Svr;tyrone-cluster;Scheduler was sent the command new
07/14/2015 10:57:26;0040;PBS_Server;Svr;tyrone-cluster;Scheduler was sent the command new
07/14/2015 10:57:45;0040;PBS_Server;Svr;tyrone-cluster;Scheduler was sent the command new
07/14/2015 10:58:15;0040;PBS_Server;Svr;tyrone-cluster;Scheduler was sent the command new
07/14/2015 10:58:56;0040;PBS_Server;Svr;tyrone-cluster;Scheduler was sent the command new
07/14/2015 10:59:15;0040;PBS_Server;Svr;tyrone-cluster;Scheduler was sent the command new
07/14/2015 10:59:45;0040;PBS_Server;Svr;tyrone-cluster;Scheduler was sent the command new
07/14/2015 11:00:27;0040;PBS_Server;Svr;tyrone-cluster;Scheduler was sent the command new
07/14/2015 11:01:00;0040;PBS_Server;Svr;tyrone-cluster;Scheduler was sent the command new
07/14/2015 11:01:28;0040;PBS_Server;Svr;tyrone-cluster;Scheduler was sent the command new
07/14/2015 11:01:36;0002;PBS_Server;Svr;PBS_Server;Torque Server Version = 3.0.5, loglevel = 0
07/14/2015 11:02:00;0040;PBS_Server;Svr;tyrone-cluster;Scheduler was sent the command new
07/14/2015 11:02:31;0040;PBS_Server;Svr;tyrone-cluster;Scheduler was sent the command new
07/14/2015 11:03:02;0040;PBS_Server;Svr;tyrone-cluster;Scheduler was sent the command new
07/14/2015 11:03:30;0040;PBS_Server;Svr;tyrone-cluster;Scheduler was sent the command new
07/14/2015 11:04:11;0040;PBS_Server;Svr;tyrone-cluster;Scheduler was sent the command new
07/14/2015 11:04:30;0040;PBS_Server;Svr;tyrone-cluster;Scheduler was sent the command new
07/14/2015 11:05:00;0040;PBS_Server;Svr;tyrone-cluster;Scheduler was sent the command new
07/14/2015 11:05:42;0040;PBS_Server;Svr;tyrone-cluster;Scheduler was sent the command new
07/14/2015 11:06:15;0040;PBS_Server;Svr;tyrone-cluster;Scheduler was sent the command new
07/14/2015 11:06:36;0002;PBS_Server;Svr;PBS_Server;Torque Server Version = 3.0.5, loglevel = 0
07/14/2015 11:06:43;0040;PBS_Server;Svr;tyrone-cluster;Scheduler was sent the command new
07/14/2015 11:07:15;0040;PBS_Server;Svr;tyrone-cluster;Scheduler was sent the command new
07/14/2015 11:07:56;0040;PBS_Server;Svr;tyrone-cluster;Scheduler was sent the command new
07/14/2015 11:08:15;0040;PBS_Server;Svr;tyrone-cluster;Scheduler was sent the command new
07/14/2015 11:08:45;0040;PBS_Server;Svr;tyrone-cluster;Scheduler was sent the command new
07/14/2015 11:09:27;0040;PBS_Server;Svr;tyrone-cluster;Scheduler was sent the command new
07/14/2015 11:09:59;0040;PBS_Server;Svr;tyrone-cluster;Scheduler was sent the command new
07/14/2015 11:10:28;0040;PBS_Server;Svr;tyrone-cluster;Scheduler was sent the command new
07/14/2015 11:11:00;0040;PBS_Server;Svr;tyrone-cluster;Scheduler was sent the command new
07/14/2015 11:11:36;0002;PBS_Server;Svr;PBS_Server;Torque Server Version = 3.0.5, loglevel = 0
07/14/2015 11:11:36;0040;PBS_Server;Svr;tyrone-cluster;Scheduler was sent the command new
07/14/2015 11:12:00;0040;PBS_Server;Svr;tyrone-cluster;Scheduler was sent the command new
07/14/2015 11:12:30;0040;PBS_Server;Svr;tyrone-cluster;Scheduler was sent the command new
07/14/2015 11:12:48;0008;PBS_Server;Job;54607.tyrone-cluster;Job deleted at request of physkgly@tyrone-cluster
07/14/2015 11:12:48;0008;PBS_Server;Job;54607.tyrone-cluster;Job sent signal SIGTERM on delete
07/14/2015 11:12:48;000d;PBS_Server;Job;54607.tyrone-cluster;Not sending email: User does not want mail of this type.
07/14/2015 11:12:48;0010;PBS_Server;Job;54607.tyrone-cluster;Exit_status=143 resources_used.cput=00:00:01 resources_used.mem=28772kb resources_used.vmem=1062104kb resources_used.walltime=13:00:24
07/14/2015 11:12:48;0008;PBS_Server;Job;NULL;on_job_exit valid pjob: 0x1cc2e00 (substate=50)
07/14/2015 11:12:48;0008;PBS_Server;Job;NULL;on_job_exit valid pjob: 0x1cc2e00 (substate=51)
07/14/2015 11:12:48;0008;PBS_Server;Job;NULL;on_job_exit valid pjob: 0x1cc2e00 (substate=51)
07/14/2015 11:12:48;0008;PBS_Server;Job;NULL;on_job_exit valid pjob: 0x1cc2e00 (substate=53)
07/14/2015 11:12:48;0100;PBS_Server;Job;54607.tyrone-cluster;dequeuing from qp64, state COMPLETE
07/14/2015 11:12:48;0040;PBS_Server;Svr;tyrone-cluster;Scheduler was sent the command term
07/14/2015 11:12:48;0008;PBS_Server;Job;54625.tyrone-cluster;Job Modified at request of Scheduler@tyrone-cluster
07/14/2015 11:12:48;0008;PBS_Server;Job;54625.tyrone-cluster;Job Run at request of Scheduler@tyrone-cluster
07/14/2015 11:12:48;0040;PBS_Server;Svr;tyrone-cluster;Scheduler was sent the command recyc
07/14/2015 11:12:59;0100;PBS_Server;Job;54630.tyrone-cluster;enqueuing into batch, state 1 hop 1
07/14/2015 11:12:59;0100;PBS_Server;Job;54630.tyrone-cluster;dequeuing from batch, state QUEUED
07/14/2015 11:12:59;0100;PBS_Server;Job;54630.tyrone-cluster;enqueuing into qp64, state 1 hop 1
07/14/2015 11:12:59;0008;PBS_Server;Job;54630.tyrone-cluster;Job Queued at request of physkgly@tyrone-cluster, owner = physkgly@tyrone-cluster, job name = test2, queue = qp64
07/14/2015 11:12:59;0040;PBS_Server;Svr;tyrone-cluster;Scheduler was sent the command new
07/14/2015 11:12:59;0008;PBS_Server;Job;54630.tyrone-cluster;Job Modified at request of Scheduler@tyrone-cluster
07/14/2015 11:13:11;0040;PBS_Server;Svr;tyrone-cluster;Scheduler was sent the command new
07/14/2015 11:13:30;0040;PBS_Server;Svr;tyrone-cluster;Scheduler was sent the command new
07/14/2015 11:13:54;000d;PBS_Server;Job;54625.tyrone-cluster;Not sending email: User does not want mail of this type.
07/14/2015 11:14:00;0040;PBS_Server;Svr;tyrone-cluster;Scheduler was sent the command new
07/14/2015 11:14:39;0040;PBS_Server;Svr;tyrone-cluster;Scheduler was sent the command new
07/14/2015 11:15:14;0040;PBS_Server;Svr;tyrone-cluster;Scheduler was sent the command new
07/14/2015 11:15:44;0040;PBS_Server;Svr;tyrone-cluster;Scheduler was sent the command new
07/14/2015 11:16:15;0040;PBS_Server;Svr;tyrone-cluster;Scheduler was sent the command new
07/14/2015 11:16:36;0002;PBS_Server;Svr;PBS_Server;Torque Server Version = 3.0.5, loglevel = 0
07/14/2015 11:16:54;0040;PBS_Server;Svr;tyrone-cluster;Scheduler was sent the command new
07/14/2015 11:17:15;0040;PBS_Server;Svr;tyrone-cluster;Scheduler was sent the command new
07/14/2015 11:17:45;0040;PBS_Server;Svr;tyrone-cluster;Scheduler was sent the command new
07/14/2015 11:18:24;0040;PBS_Server;Svr;tyrone-cluster;Scheduler was sent the command new
07/14/2015 11:19:00;0040;PBS_Server;Svr;tyrone-cluster;Scheduler was sent the command new
07/14/2015 11:19:29;0040;PBS_Server;Svr;tyrone-cluster;Scheduler was sent the command new
07/14/2015 11:20:00;0040;PBS_Server;Svr;tyrone-cluster;Scheduler was sent the command new
07/14/2015 11:20:39;0040;PBS_Server;Svr;tyrone-cluster;Scheduler was sent the command new
07/14/2015 11:21:00;0040;PBS_Server;Svr;tyrone-cluster;Scheduler was sent the command new
07/14/2015 11:21:30;0040;PBS_Server;Svr;tyrone-cluster;Scheduler was sent the command new
07/14/2015 11:21:36;0002;PBS_Server;Svr;PBS_Server;Torque Server Version = 3.0.5, loglevel = 0
07/14/2015 11:22:09;0040;PBS_Server;Svr;tyrone-cluster;Scheduler was sent the command new
07/14/2015 11:22:45;0040;PBS_Server;Svr;tyrone-cluster;Scheduler was sent the command new
07/14/2015 11:23:14;0040;PBS_Server;Svr;tyrone-cluster;Scheduler was sent the command new
07/14/2015 11:23:45;0040;PBS_Server;Svr;tyrone-cluster;Scheduler was sent the command new
07/14/2015 11:24:24;0040;PBS_Server;Svr;tyrone-cluster;Scheduler was sent the command new
07/14/2015 11:24:45;0040;PBS_Server;Svr;tyrone-cluster;Scheduler was sent the command new
07/14/2015 11:25:15;0040;PBS_Server;Svr;tyrone-cluster;Scheduler was sent the command new
07/14/2015 11:25:54;0040;PBS_Server;Svr;tyrone-cluster;Scheduler was sent the command new
07/14/2015 11:26:30;0040;PBS_Server;Svr;tyrone-cluster;Scheduler was sent the command new
07/14/2015 11:26:36;0002;PBS_Server;Svr;PBS_Server;Torque Server Version = 3.0.5, loglevel = 0
07/14/2015 11:26:59;0040;PBS_Server;Svr;tyrone-cluster;Scheduler was sent the command new
07/14/2015 11:27:30;0040;PBS_Server;Svr;tyrone-cluster;Scheduler was sent the command new
07/14/2015 11:28:09;0040;PBS_Server;Svr;tyrone-cluster;Scheduler was sent the command new
07/14/2015 11:28:30;0040;PBS_Server;Svr;tyrone-cluster;Scheduler was sent the command new
07/14/2015 11:28:59;0100;PBS_Server;Job;54631.tyrone-cluster;enqueuing into batch, state 1 hop 1
07/14/2015 11:28:59;0100;PBS_Server;Job;54631.tyrone-cluster;dequeuing from batch, state QUEUED
07/14/2015 11:28:59;0100;PBS_Server;Job;54631.tyrone-cluster;enqueuing into idqueue, state 1 hop 1
07/14/2015 11:28:59;0008;PBS_Server;Job;54631.tyrone-cluster;Job Queued at request of metgkch@tyrone-cluster, owner = metgkch@tyrone-cluster, job name = Opt2, queue = idqueue
07/14/2015 11:28:59;0040;PBS_Server;Svr;tyrone-cluster;Scheduler was sent the command new
07/14/2015 11:28:59;0008;PBS_Server;Job;54631.tyrone-cluster;Job Modified at request of Scheduler@tyrone-cluster
07/14/2015 11:28:59;0008;PBS_Server;Job;54631.tyrone-cluster;Job Run at request of Scheduler@tyrone-cluster
07/14/2015 11:28:59;0040;PBS_Server;Svr;tyrone-cluster;Scheduler was sent the command recyc
07/14/2015 11:28:59;000d;PBS_Server;Job;54631.tyrone-cluster;Not sending email: User does not want mail of this type.
07/14/2015 11:29:00;0040;PBS_Server;Svr;tyrone-cluster;Scheduler was sent the command new
07/14/2015 11:29:39;0040;PBS_Server;Svr;tyrone-cluster;Scheduler was sent the command new
07/14/2015 11:30:14;0040;PBS_Server;Svr;tyrone-cluster;Scheduler was sent the command new
07/14/2015 11:30:44;0040;PBS_Server;Svr;tyrone-cluster;Scheduler was sent the command new
07/14/2015 11:31:15;0040;PBS_Server;Svr;tyrone-cluster;Scheduler was sent the command new
07/14/2015 11:31:16;0008;PBS_Server;Job;54631.tyrone-cluster;Job deleted at request of metgkch@tyrone-cluster
07/14/2015 11:31:16;0008;PBS_Server;Job;54631.tyrone-cluster;Job sent signal SIGTERM on delete
07/14/2015 11:31:16;000d;PBS_Server;Job;54631.tyrone-cluster;Not sending email: User does not want mail of this type.
07/14/2015 11:31:16;0010;PBS_Server;Job;54631.tyrone-cluster;Exit_status=265 resources_used.cput=00:00:00 resources_used.mem=6396kb resources_used.vmem=1862996kb resources_used.walltime=00:02:17
07/14/2015 11:31:16;0008;PBS_Server;Job;NULL;on_job_exit valid pjob: 0x1dee940 (substate=50)
07/14/2015 11:31:16;0008;PBS_Server;Job;NULL;on_job_exit valid pjob: 0x1dee940 (substate=51)
07/14/2015 11:31:16;0008;PBS_Server;Job;NULL;on_job_exit valid pjob: 0x1dee940 (substate=51)
07/14/2015 11:31:16;0008;PBS_Server;Job;NULL;on_job_exit valid pjob: 0x1dee940 (substate=53)
07/14/2015 11:31:16;0100;PBS_Server;Job;54631.tyrone-cluster;dequeuing from idqueue, state COMPLETE
07/14/2015 11:31:16;0040;PBS_Server;Svr;tyrone-cluster;Scheduler was sent the command term
07/14/2015 11:31:36;0002;PBS_Server;Svr;PBS_Server;Torque Server Version = 3.0.5, loglevel = 0
07/14/2015 11:31:54;0040;PBS_Server;Svr;tyrone-cluster;Scheduler was sent the command new
07/14/2015 11:31:57;0100;PBS_Server;Job;54632.tyrone-cluster;enqueuing into batch, state 1 hop 1
07/14/2015 11:31:57;0100;PBS_Server;Job;54632.tyrone-cluster;dequeuing from batch, state QUEUED
07/14/2015 11:31:57;0100;PBS_Server;Job;54632.tyrone-cluster;enqueuing into idqueue, state 1 hop 1
07/14/2015 11:31:57;0008;PBS_Server;Job;54632.tyrone-cluster;Job Queued at request of metgkch@tyrone-cluster, owner = metgkch@tyrone-cluster, job name = Opt2, queue = idqueue
07/14/2015 11:31:57;0040;PBS_Server;Svr;tyrone-cluster;Scheduler was sent the command new
07/14/2015 11:31:58;0008;PBS_Server;Job;54632.tyrone-cluster;Job Modified at request of Scheduler@tyrone-cluster
07/14/2015 11:31:58;0008;PBS_Server;Job;54632.tyrone-cluster;Job Run at request of Scheduler@tyrone-cluster
07/14/2015 11:31:58;0040;PBS_Server;Svr;tyrone-cluster;Scheduler was sent the command recyc
07/14/2015 11:31:58;000d;PBS_Server;Job;54632.tyrone-cluster;Not sending email: User does not want mail of this type.
07/14/2015 11:32:29;0040;PBS_Server;Svr;tyrone-cluster;Scheduler was sent the command new
07/14/2015 11:32:59;0040;PBS_Server;Svr;tyrone-cluster;Scheduler was sent the command new
07/14/2015 11:33:30;0040;PBS_Server;Svr;tyrone-cluster;Scheduler was sent the command new
07/14/2015 11:34:09;0040;PBS_Server;Svr;tyrone-cluster;Scheduler was sent the command new
07/14/2015 11:34:30;0040;PBS_Server;Svr;tyrone-cluster;Scheduler was sent the command new
07/14/2015 11:35:01;0040;PBS_Server;Svr;tyrone-cluster;Scheduler was sent the command new
07/14/2015 11:35:39;0040;PBS_Server;Svr;tyrone-cluster;Scheduler was sent the command new
07/14/2015 11:36:00;0040;PBS_Server;Svr;tyrone-cluster;Scheduler was sent the command new
07/14/2015 11:36:30;0040;PBS_Server;Svr;tyrone-cluster;Scheduler was sent the command new
07/14/2015 11:36:36;0002;PBS_Server;Svr;PBS_Server;Torque Server Version = 3.0.5, loglevel = 0
07/14/2015 11:37:00;0040;PBS_Server;Svr;tyrone-cluster;Scheduler was sent the command new
07/14/2015 11:37:00;0008;PBS_Server;Job;54632.tyrone-cluster;Job deleted at request of metgkch@tyrone-cluster
07/14/2015 11:37:00;0008;PBS_Server;Job;54632.tyrone-cluster;Job sent signal SIGTERM on delete
07/14/2015 11:37:00;000d;PBS_Server;Job;54632.tyrone-cluster;Not sending email: User does not want mail of this type.
07/14/2015 11:37:00;0010;PBS_Server;Job;54632.tyrone-cluster;Exit_status=265 resources_used.cput=00:00:00 resources_used.mem=6416kb resources_used.vmem=1863016kb resources_used.walltime=00:05:02
07/14/2015 11:37:00;0008;PBS_Server;Job;NULL;on_job_exit valid pjob: 0x1da8250 (substate=50)
07/14/2015 11:37:00;0008;PBS_Server;Job;NULL;on_job_exit valid pjob: 0x1da8250 (substate=51)
07/14/2015 11:37:00;0008;PBS_Server;Job;NULL;on_job_exit valid pjob: 0x1da8250 (substate=51)
07/14/2015 11:37:00;0008;PBS_Server;Job;NULL;on_job_exit valid pjob: 0x1da8250 (substate=53)
07/14/2015 11:37:00;0100;PBS_Server;Job;54632.tyrone-cluster;dequeuing from idqueue, state COMPLETE
07/14/2015 11:37:30;0040;PBS_Server;Svr;tyrone-cluster;Scheduler was sent the command new
07/14/2015 11:38:00;0040;PBS_Server;Svr;tyrone-cluster;Scheduler was sent the command new
07/14/2015 11:38:33;0040;PBS_Server;Svr;tyrone-cluster;Scheduler was sent the command new
07/14/2015 11:39:02;0100;PBS_Server;Job;54634.tyrone-cluster;enqueuing into batch, state 1 hop 1
07/14/2015 11:39:02;0100;PBS_Server;Job;54634.tyrone-cluster;dequeuing from batch, state QUEUED
07/14/2015 11:39:02;0100;PBS_Server;Job;54634.tyrone-cluster;enqueuing into idqueue, state 1 hop 1
07/14/2015 11:39:02;0008;PBS_Server;Job;54634.tyrone-cluster;Job Queued at request of metgkch@tyrone-cluster, owner = metgkch@tyrone-cluster, job name = OptCh, queue = idqueue
07/14/2015 11:39:02;0040;PBS_Server;Svr;tyrone-cluster;Scheduler was sent the command new
07/14/2015 11:39:02;0008;PBS_Server;Job;54634.tyrone-cluster;Job Modified at request of Scheduler@tyrone-cluster
07/14/2015 11:39:02;0008;PBS_Server;Job;54634.tyrone-cluster;Job Run at request of Scheduler@tyrone-cluster
07/14/2015 11:39:02;0040;PBS_Server;Svr;tyrone-cluster;Scheduler was sent the command recyc
07/14/2015 11:39:02;000d;PBS_Server;Job;54634.tyrone-cluster;Not sending email: User does not want mail of this type.
07/14/2015 11:39:03;0040;PBS_Server;Svr;tyrone-cluster;Scheduler was sent the command new
07/14/2015 11:39:03;000d;PBS_Server;Job;54634.tyrone-cluster;Not sending email: User does not want mail of this type.
07/14/2015 11:39:03;0010;PBS_Server;Job;54634.tyrone-cluster;Exit_status=1 resources_used.cput=00:00:00 resources_used.mem=0kb resources_used.vmem=0kb resources_used.walltime=00:00:01
07/14/2015 11:39:03;0008;PBS_Server;Job;NULL;on_job_exit valid pjob: 0x1df1b80 (substate=50)
07/14/2015 11:39:03;0008;PBS_Server;Job;NULL;on_job_exit valid pjob: 0x1df1b80 (substate=51)
07/14/2015 11:39:03;0008;PBS_Server;Job;NULL;on_job_exit valid pjob: 0x1df1b80 (substate=51)
07/14/2015 11:39:03;0008;PBS_Server;Job;NULL;on_job_exit valid pjob: 0x1df1b80 (substate=53)
07/14/2015 11:39:03;0100;PBS_Server;Job;54634.tyrone-cluster;dequeuing from idqueue, state COMPLETE
07/14/2015 11:39:36;0040;PBS_Server;Svr;tyrone-cluster;Scheduler was sent the command new
07/14/2015 11:39:47;0100;PBS_Server;Job;54635.tyrone-cluster;enqueuing into batch, state 1 hop 1
07/14/2015 11:39:47;0100;PBS_Server;Job;54635.tyrone-cluster;dequeuing from batch, state QUEUED
07/14/2015 11:39:47;0100;PBS_Server;Job;54635.tyrone-cluster;enqueuing into idqueue, state 1 hop 1
07/14/2015 11:39:47;0008;PBS_Server;Job;54635.tyrone-cluster;Job Queued at request of metgkch@tyrone-cluster, owner = metgkch@tyrone-cluster, job name = OptCh, queue = idqueue
07/14/2015 11:39:47;0040;PBS_Server;Svr;tyrone-cluster;Scheduler was sent the command new
07/14/2015 11:39:47;0008;PBS_Server;Job;54635.tyrone-cluster;Job Modified at request of Scheduler@tyrone-cluster
07/14/2015 11:39:47;0008;PBS_Server;Job;54635.tyrone-cluster;Job Run at request of Scheduler@tyrone-cluster
07/14/2015 11:39:47;0040;PBS_Server;Svr;tyrone-cluster;Scheduler was sent the command recyc
07/14/2015 11:39:47;000d;PBS_Server;Job;54635.tyrone-cluster;Not sending email: User does not want mail of this type.
07/14/2015 11:40:09;0040;PBS_Server;Svr;tyrone-cluster;Scheduler was sent the command new
07/14/2015 11:40:45;0040;PBS_Server;Svr;tyrone-cluster;Scheduler was sent the command new
07/14/2015 11:41:12;0040;PBS_Server;Svr;tyrone-cluster;Scheduler was sent the command new
07/14/2015 11:41:36;0002;PBS_Server;Svr;PBS_Server;Torque Server Version = 3.0.5, loglevel = 0
07/14/2015 11:41:42;0040;PBS_Server;Svr;tyrone-cluster;Scheduler was sent the command new
07/14/2015 11:42:24;0040;PBS_Server;Svr;tyrone-cluster;Scheduler was sent the command new
07/14/2015 11:42:33;0008;PBS_Server;Job;54635.tyrone-cluster;Job deleted at request of metgkch@tyrone-cluster
07/14/2015 11:42:33;0008;PBS_Server;Job;54635.tyrone-cluster;Job sent signal SIGTERM on delete
07/14/2015 11:42:33;000d;PBS_Server;Job;54635.tyrone-cluster;Not sending email: User does not want mail of this type.
07/14/2015 11:42:33;0010;PBS_Server;Job;54635.tyrone-cluster;Exit_status=265 resources_used.cput=00:00:00 resources_used.mem=6420kb resources_used.vmem=1863016kb resources_used.walltime=00:02:46
07/14/2015 11:42:33;0008;PBS_Server;Job;NULL;on_job_exit valid pjob: 0x1df2bf0 (substate=50)
07/14/2015 11:42:33;0008;PBS_Server;Job;NULL;on_job_exit valid pjob: 0x1df2bf0 (substate=51)
07/14/2015 11:42:33;0008;PBS_Server;Job;NULL;on_job_exit valid pjob: 0x1df2bf0 (substate=51)
07/14/2015 11:42:33;0008;PBS_Server;Job;NULL;on_job_exit valid pjob: 0x1df2bf0 (substate=53)
07/14/2015 11:42:33;0100;PBS_Server;Job;54635.tyrone-cluster;dequeuing from idqueue, state COMPLETE
07/14/2015 11:42:33;0040;PBS_Server;Svr;tyrone-cluster;Scheduler was sent the command term
07/14/2015 11:42:45;0040;PBS_Server;Svr;tyrone-cluster;Scheduler was sent the command new
07/14/2015 11:43:15;0040;PBS_Server;Svr;tyrone-cluster;Scheduler was sent the command new
07/14/2015 11:43:49;0040;PBS_Server;Svr;tyrone-cluster;Scheduler was sent the command new
07/14/2015 11:43:56;0100;PBS_Server;Job;54636.tyrone-cluster;enqueuing into batch, state 1 hop 1
07/14/2015 11:43:56;0100;PBS_Server;Job;54636.tyrone-cluster;dequeuing from batch, state QUEUED
07/14/2015 11:43:56;0100;PBS_Server;Job;54636.tyrone-cluster;enqueuing into idqueue, state 1 hop 1
07/14/2015 11:43:56;0008;PBS_Server;Job;54636.tyrone-cluster;Job Queued at request of metgkch@tyrone-cluster, owner = metgkch@tyrone-cluster, job name = OptCh, queue = idqueue
07/14/2015 11:43:56;0040;PBS_Server;Svr;tyrone-cluster;Scheduler was sent the command new
07/14/2015 11:43:56;0008;PBS_Server;Job;54636.tyrone-cluster;Job Modified at request of Scheduler@tyrone-cluster
07/14/2015 11:43:56;0008;PBS_Server;Job;54636.tyrone-cluster;Job Run at request of Scheduler@tyrone-cluster
07/14/2015 11:43:56;0040;PBS_Server;Svr;tyrone-cluster;Scheduler was sent the command recyc
07/14/2015 11:43:56;000d;PBS_Server;Job;54636.tyrone-cluster;Not sending email: User does not want mail of this type.
07/14/2015 11:43:58;000d;PBS_Server;Job;54636.tyrone-cluster;Not sending email: User does not want mail of this type.
07/14/2015 11:43:58;0010;PBS_Server;Job;54636.tyrone-cluster;Exit_status=1 resources_used.cput=00:00:00 resources_used.mem=0kb resources_used.vmem=0kb resources_used.walltime=00:00:02
07/14/2015 11:43:58;0008;PBS_Server;Job;NULL;on_job_exit valid pjob: 0x1df0260 (substate=50)
07/14/2015 11:43:58;0008;PBS_Server;Job;NULL;on_job_exit valid pjob: 0x1df0260 (substate=51)
07/14/2015 11:43:58;0008;PBS_Server;Job;NULL;on_job_exit valid pjob: 0x1df0260 (substate=51)
07/14/2015 11:43:58;0008;PBS_Server;Job;NULL;on_job_exit valid pjob: 0x1df0260 (substate=53)
07/14/2015 11:43:58;0100;PBS_Server;Job;54636.tyrone-cluster;dequeuing from idqueue, state COMPLETE
07/14/2015 11:43:58;0040;PBS_Server;Svr;tyrone-cluster;Scheduler was sent the command term
07/14/2015 11:44:15;0040;PBS_Server;Svr;tyrone-cluster;Scheduler was sent the command new
07/14/2015 11:44:45;0040;PBS_Server;Svr;tyrone-cluster;Scheduler was sent the command new
07/14/2015 11:45:24;0040;PBS_Server;Svr;tyrone-cluster;Scheduler was sent the command new
07/14/2015 11:46:00;0040;PBS_Server;Svr;tyrone-cluster;Scheduler was sent the command new
07/14/2015 11:46:29;0040;PBS_Server;Svr;tyrone-cluster;Scheduler was sent the command new
07/14/2015 11:46:36;0002;PBS_Server;Svr;PBS_Server;Torque Server Version = 3.0.5, loglevel = 0
07/14/2015 11:47:00;0040;PBS_Server;Svr;tyrone-cluster;Scheduler was sent the command new
07/14/2015 11:47:39;0040;PBS_Server;Svr;tyrone-cluster;Scheduler was sent the command new
07/14/2015 11:48:00;0040;PBS_Server;Svr;tyrone-cluster;Scheduler was sent the command new
07/14/2015 11:48:30;0040;PBS_Server;Svr;tyrone-cluster;Scheduler was sent the command new
07/14/2015 11:49:03;0040;PBS_Server;Svr;tyrone-cluster;Scheduler was sent the command new
07/14/2015 11:49:16;0100;PBS_Server;Job;54637.tyrone-cluster;enqueuing into batch, state 1 hop 1
07/14/2015 11:49:16;0100;PBS_Server;Job;54637.tyrone-cluster;dequeuing from batch, state QUEUED
07/14/2015 11:49:16;0100;PBS_Server;Job;54637.tyrone-cluster;enqueuing into idqueue, state 1 hop 1
07/14/2015 11:49:16;0008;PBS_Server;Job;54637.tyrone-cluster;Job Queued at request of metgkch@tyrone-cluster, owner = metgkch@tyrone-cluster, job name = OptCh, queue = idqueue
07/14/2015 11:49:16;0040;PBS_Server;Svr;tyrone-cluster;Scheduler was sent the command new
07/14/2015 11:49:17;0008;PBS_Server;Job;54637.tyrone-cluster;Job Modified at request of Scheduler@tyrone-cluster
07/14/2015 11:49:17;0008;PBS_Server;Job;54637.tyrone-cluster;Job Run at request of Scheduler@tyrone-cluster
07/14/2015 11:49:17;0040;PBS_Server;Svr;tyrone-cluster;Scheduler was sent the command recyc
07/14/2015 11:49:17;000d;PBS_Server;Job;54637.tyrone-cluster;Not sending email: User does not want mail of this type.
07/14/2015 11:49:20;000d;PBS_Server;Job;54637.tyrone-cluster;Not sending email: User does not want mail of this type.
07/14/2015 11:49:20;0010;PBS_Server;Job;54637.tyrone-cluster;Exit_status=1 resources_used.cput=00:00:01 resources_used.mem=0kb resources_used.vmem=0kb resources_used.walltime=00:00:03
07/14/2015 11:49:20;0008;PBS_Server;Job;NULL;on_job_exit valid pjob: 0x1dee940 (substate=50)
07/14/2015 11:49:20;0008;PBS_Server;Job;NULL;on_job_exit valid pjob: 0x1dee940 (substate=51)
07/14/2015 11:49:20;0008;PBS_Server;Job;NULL;on_job_exit valid pjob: 0x1dee940 (substate=51)
07/14/2015 11:49:20;0008;PBS_Server;Job;NULL;on_job_exit valid pjob: 0x1dee940 (substate=53)
07/14/2015 11:49:20;0100;PBS_Server;Job;54637.tyrone-cluster;dequeuing from idqueue, state COMPLETE
07/14/2015 11:49:20;0040;PBS_Server;Svr;tyrone-cluster;Scheduler was sent the command term
07/14/2015 11:49:35;0040;PBS_Server;Svr;tyrone-cluster;Scheduler was sent the command new
07/14/2015 11:50:06;0040;PBS_Server;Svr;tyrone-cluster;Scheduler was sent the command new
07/14/2015 11:50:12;0100;PBS_Server;Job;54638.tyrone-cluster;enqueuing into batch, state 1 hop 1
07/14/2015 11:50:12;0100;PBS_Server;Job;54638.tyrone-cluster;dequeuing from batch, state QUEUED
07/14/2015 11:50:12;0100;PBS_Server;Job;54638.tyrone-cluster;enqueuing into qp64, state 1 hop 1
07/14/2015 11:50:12;0008;PBS_Server;Job;54638.tyrone-cluster;Job Queued at request of metnvv@tyrone-cluster, owner = metnvv@tyrone-cluster, job name = job256, queue = qp64
07/14/2015 11:50:12;0040;PBS_Server;Svr;tyrone-cluster;Scheduler was sent the command new
07/14/2015 11:50:12;0008;PBS_Server;Job;54638.tyrone-cluster;Job Modified at request of Scheduler@tyrone-cluster
07/14/2015 11:50:39;0040;PBS_Server;Svr;tyrone-cluster;Scheduler was sent the command new
07/14/2015 11:51:14;0040;PBS_Server;Svr;tyrone-cluster;Scheduler was sent the command new
07/14/2015 11:51:36;0002;PBS_Server;Svr;PBS_Server;Torque Server Version = 3.0.5, loglevel = 0
07/14/2015 11:51:44;0040;PBS_Server;Svr;tyrone-cluster;Scheduler was sent the command new
07/14/2015 11:52:14;0040;PBS_Server;Svr;tyrone-cluster;Scheduler was sent the command new
07/14/2015 11:52:44;0040;PBS_Server;Svr;tyrone-cluster;Scheduler was sent the command new
07/14/2015 11:53:14;0040;PBS_Server;Svr;tyrone-cluster;Scheduler was sent the command new
07/14/2015 11:53:26;0100;PBS_Server;Job;54639.tyrone-cluster;enqueuing into batch, state 1 hop 1
07/14/2015 11:53:26;0100;PBS_Server;Job;54639.tyrone-cluster;dequeuing from batch, state QUEUED
07/14/2015 11:53:26;0100;PBS_Server;Job;54639.tyrone-cluster;enqueuing into idqueue, state 1 hop 1
07/14/2015 11:53:26;0008;PBS_Server;Job;54639.tyrone-cluster;Job Queued at request of metgkch@tyrone-cluster, owner = metgkch@tyrone-cluster, job name = OptCh, queue = idqueue
07/14/2015 11:53:26;0040;PBS_Server;Svr;tyrone-cluster;Scheduler was sent the command new
07/14/2015 11:53:28;0008;PBS_Server;Job;54639.tyrone-cluster;Job Modified at request of Scheduler@tyrone-cluster
07/14/2015 11:53:28;0008;PBS_Server;Job;54639.tyrone-cluster;Job Run at request of Scheduler@tyrone-cluster
07/14/2015 11:53:29;0040;PBS_Server;Svr;tyrone-cluster;Scheduler was sent the command recyc
07/14/2015 11:53:29;000d;PBS_Server;Job;54639.tyrone-cluster;Not sending email: User does not want mail of this type.
07/14/2015 11:53:30;000d;PBS_Server;Job;54639.tyrone-cluster;Not sending email: User does not want mail of this type.
07/14/2015 11:53:30;0010;PBS_Server;Job;54639.tyrone-cluster;Exit_status=1 resources_used.cput=00:00:00 resources_used.mem=0kb resources_used.vmem=0kb resources_used.walltime=00:00:02
07/14/2015 11:53:30;0008;PBS_Server;Job;NULL;on_job_exit valid pjob: 0x1df3930 (substate=50)
07/14/2015 11:53:30;0008;PBS_Server;Job;NULL;on_job_exit valid pjob: 0x1df3930 (substate=51)
07/14/2015 11:53:30;0008;PBS_Server;Job;NULL;on_job_exit valid pjob: 0x1df3930 (substate=51)
07/14/2015 11:53:30;0008;PBS_Server;Job;NULL;on_job_exit valid pjob: 0x1df3930 (substate=53)
07/14/2015 11:53:30;0100;PBS_Server;Job;54639.tyrone-cluster;dequeuing from idqueue, state COMPLETE
07/14/2015 11:53:30;0040;PBS_Server;Svr;tyrone-cluster;Scheduler was sent the command term
07/14/2015 11:53:45;0040;PBS_Server;Svr;tyrone-cluster;Scheduler was sent the command new
07/14/2015 11:54:24;0040;PBS_Server;Svr;tyrone-cluster;Scheduler was sent the command new
07/14/2015 11:54:45;0040;PBS_Server;Svr;tyrone-cluster;Scheduler was sent the command new
07/14/2015 11:54:48;000d;PBS_Server;Job;54495.tyrone-cluster;Not sending email: User does not want mail of this type.
07/14/2015 11:54:48;0010;PBS_Server;Job;54495.tyrone-cluster;Exit_status=271 resources_used.cput=1535:06:42 resources_used.mem=2611876kb resources_used.vmem=36281616kb resources_used.walltime=24:00:48
07/14/2015 11:54:48;0008;PBS_Server;Job;NULL;on_job_exit valid pjob: 0x1c6fca0 (substate=50)
07/14/2015 11:54:48;0008;PBS_Server;Job;NULL;on_job_exit valid pjob: 0x1c6fca0 (substate=51)
07/14/2015 11:54:49;0008;PBS_Server;Job;NULL;on_job_exit valid pjob: 0x1c6fca0 (substate=51)
07/14/2015 11:54:49;0008;PBS_Server;Job;NULL;on_job_exit valid pjob: 0x1c6fca0 (substate=53)
07/14/2015 11:54:49;0100;PBS_Server;Job;54495.tyrone-cluster;dequeuing from qp256, state COMPLETE
07/14/2015 11:54:49;0040;PBS_Server;Svr;tyrone-cluster;Scheduler was sent the command term
07/14/2015 11:54:49;0008;PBS_Server;Job;54496.tyrone-cluster;Job Modified at request of Scheduler@tyrone-cluster
07/14/2015 11:54:49;0008;PBS_Server;Job;54496.tyrone-cluster;Job Run at request of Scheduler@tyrone-cluster
07/14/2015 11:54:49;0040;PBS_Server;Svr;tyrone-cluster;Scheduler was sent the command recyc
07/14/2015 11:55:14;000d;PBS_Server;Job;54496.tyrone-cluster;Not sending email: User does not want mail of this type.
07/14/2015 11:55:14;0010;PBS_Server;Job;54496.tyrone-cluster;Exit_status=255 resources_used.cput=00:21:26 resources_used.mem=808kb resources_used.vmem=13628kb resources_used.walltime=00:00:25
07/14/2015 11:55:14;0008;PBS_Server;Job;NULL;on_job_exit valid pjob: 0x1dc1260 (substate=50)
07/14/2015 11:55:14;0008;PBS_Server;Job;NULL;on_job_exit valid pjob: 0x1dc1260 (substate=51)
07/14/2015 11:55:14;0008;PBS_Server;Job;NULL;on_job_exit valid pjob: 0x1dc1260 (substate=51)
07/14/2015 11:55:14;0008;PBS_Server;Job;NULL;on_job_exit valid pjob: 0x1dc1260 (substate=53)
07/14/2015 11:55:14;0100;PBS_Server;Job;54496.tyrone-cluster;dequeuing from qp256, state COMPLETE
07/14/2015 11:55:14;0040;PBS_Server;Svr;tyrone-cluster;Scheduler was sent the command term
07/14/2015 11:55:14;0008;PBS_Server;Job;54610.tyrone-cluster;Job Modified at request of Scheduler@tyrone-cluster
07/14/2015 11:55:14;0008;PBS_Server;Job;54615.tyrone-cluster;Job Modified at request of Scheduler@tyrone-cluster
07/14/2015 11:55:14;0008;PBS_Server;Job;54615.tyrone-cluster;Job Run at request of Scheduler@tyrone-cluster
07/14/2015 11:55:14;0040;PBS_Server;Svr;tyrone-cluster;Scheduler was sent the command recyc
07/14/2015 11:55:15;0100;PBS_Server;Job;54497.tyrone-cluster;dequeuing from batch, state QUEUED
07/14/2015 11:55:15;0100;PBS_Server;Job;54497.tyrone-cluster;enqueuing into qp256, state 1 hop 1
07/14/2015 11:55:16;0040;PBS_Server;Svr;tyrone-cluster;Scheduler was sent the command new
07/14/2015 11:55:16;0008;PBS_Server;Job;54610.tyrone-cluster;Job Modified at request of Scheduler@tyrone-cluster
07/14/2015 11:55:16;0008;PBS_Server;Job;54497.tyrone-cluster;Job Modified at request of Scheduler@tyrone-cluster
07/14/2015 11:55:54;0040;PBS_Server;Svr;tyrone-cluster;Scheduler was sent the command new
07/14/2015 11:56:03;0100;PBS_Server;Job;54640.tyrone-cluster;enqueuing into batch, state 1 hop 1
07/14/2015 11:56:03;0100;PBS_Server;Job;54640.tyrone-cluster;dequeuing from batch, state QUEUED
07/14/2015 11:56:03;0100;PBS_Server;Job;54640.tyrone-cluster;enqueuing into idqueue, state 1 hop 1
07/14/2015 11:56:03;0008;PBS_Server;Job;54640.tyrone-cluster;Job Queued at request of metgkch@tyrone-cluster, owner = metgkch@tyrone-cluster, job name = OptCh, queue = idqueue
07/14/2015 11:56:03;0040;PBS_Server;Svr;tyrone-cluster;Scheduler was sent the command new
07/14/2015 11:56:03;0008;PBS_Server;Job;54640.tyrone-cluster;Job Modified at request of Scheduler@tyrone-cluster
07/14/2015 11:56:03;0008;PBS_Server;Job;54640.tyrone-cluster;Job Run at request of Scheduler@tyrone-cluster
07/14/2015 11:56:03;0040;PBS_Server;Svr;tyrone-cluster;Scheduler was sent the command recyc
07/14/2015 11:56:03;000d;PBS_Server;Job;54640.tyrone-cluster;Not sending email: User does not want mail of this type.
07/14/2015 11:56:05;000d;PBS_Server;Job;54640.tyrone-cluster;Not sending email: User does not want mail of this type.
07/14/2015 11:56:05;0010;PBS_Server;Job;54640.tyrone-cluster;Exit_status=1 resources_used.cput=00:00:00 resources_used.mem=0kb resources_used.vmem=0kb resources_used.walltime=00:00:02
07/14/2015 11:56:05;0008;PBS_Server;Job;NULL;on_job_exit valid pjob: 0x1c6fca0 (substate=50)
07/14/2015 11:56:05;0008;PBS_Server;Job;NULL;on_job_exit valid pjob: 0x1c6fca0 (substate=51)
07/14/2015 11:56:05;0008;PBS_Server;Job;NULL;on_job_exit valid pjob: 0x1c6fca0 (substate=51)
07/14/2015 11:56:05;0008;PBS_Server;Job;NULL;on_job_exit valid pjob: 0x1c6fca0 (substate=53)
07/14/2015 11:56:05;0100;PBS_Server;Job;54640.tyrone-cluster;dequeuing from idqueue, state COMPLETE
07/14/2015 11:56:05;0040;PBS_Server;Svr;tyrone-cluster;Scheduler was sent the command term
07/14/2015 11:56:15;0040;PBS_Server;Svr;tyrone-cluster;Scheduler was sent the command new
07/14/2015 11:56:25;000d;PBS_Server;Job;54615.tyrone-cluster;Not sending email: User does not want mail of this type.
07/14/2015 11:56:36;0002;PBS_Server;Svr;PBS_Server;Torque Server Version = 3.0.5, loglevel = 0
07/14/2015 11:56:46;0040;PBS_Server;Svr;tyrone-cluster;Scheduler was sent the command new
07/14/2015 11:57:24;0040;PBS_Server;Svr;tyrone-cluster;Scheduler was sent the command new
07/14/2015 11:57:45;0040;PBS_Server;Svr;tyrone-cluster;Scheduler was sent the command new
07/14/2015 11:57:53;0100;PBS_Server;Job;54641.tyrone-cluster;enqueuing into batch, state 1 hop 1
07/14/2015 11:57:53;0100;PBS_Server;Job;54641.tyrone-cluster;dequeuing from batch, state QUEUED
07/14/2015 11:57:53;0100;PBS_Server;Job;54641.tyrone-cluster;enqueuing into qp256, state 1 hop 1
07/14/2015 11:57:53;0008;PBS_Server;Job;54641.tyrone-cluster;Job Queued at request of asenave@tyrone-cluster, owner = asenave@tyrone-cluster, job name = channel, queue = qp256
07/14/2015 11:57:53;0040;PBS_Server;Svr;tyrone-cluster;Scheduler was sent the command new
07/14/2015 11:57:54;0008;PBS_Server;Job;54641.tyrone-cluster;Job Modified at request of Scheduler@tyrone-cluster
07/14/2015 11:58:15;0040;PBS_Server;Svr;tyrone-cluster;Scheduler was sent the command new
07/14/2015 11:58:54;0040;PBS_Server;Svr;tyrone-cluster;Scheduler was sent the command new
07/14/2015 11:59:05;0100;PBS_Server;Job;54642.tyrone-cluster;enqueuing into batch, state 1 hop 1
07/14/2015 11:59:05;0100;PBS_Server;Job;54642.tyrone-cluster;dequeuing from batch, state QUEUED
07/14/2015 11:59:05;0100;PBS_Server;Job;54642.tyrone-cluster;enqueuing into idqueue, state 1 hop 1
07/14/2015 11:59:05;0008;PBS_Server;Job;54642.tyrone-cluster;Job Queued at request of metgkch@tyrone-cluster, owner = metgkch@tyrone-cluster, job name = OptCh, queue = idqueue
07/14/2015 11:59:05;0040;PBS_Server;Svr;tyrone-cluster;Scheduler was sent the command new
07/14/2015 11:59:05;0008;PBS_Server;Job;54642.tyrone-cluster;Job Modified at request of Scheduler@tyrone-cluster
07/14/2015 11:59:05;0008;PBS_Server;Job;54642.tyrone-cluster;Job Run at request of Scheduler@tyrone-cluster
07/14/2015 11:59:05;0040;PBS_Server;Svr;tyrone-cluster;Scheduler was sent the command recyc
07/14/2015 11:59:05;000d;PBS_Server;Job;54642.tyrone-cluster;Not sending email: User does not want mail of this type.
07/14/2015 11:59:15;0040;PBS_Server;Svr;tyrone-cluster;Scheduler was sent the command new
07/14/2015 11:59:46;0040;PBS_Server;Svr;tyrone-cluster;Scheduler was sent the command new
07/14/2015 12:00:24;0040;PBS_Server;Svr;tyrone-cluster;Scheduler was sent the command new
07/14/2015 12:00:45;0040;PBS_Server;Svr;tyrone-cluster;Scheduler was sent the command new
07/14/2015 12:01:15;0040;PBS_Server;Svr;tyrone-cluster;Scheduler was sent the command new
07/14/2015 12:01:36;0002;PBS_Server;Svr;PBS_Server;Torque Server Version = 3.0.5, loglevel = 0
07/14/2015 12:01:54;0040;PBS_Server;Svr;tyrone-cluster;Scheduler was sent the command new
07/14/2015 12:02:15;0040;PBS_Server;Svr;tyrone-cluster;Scheduler was sent the command new
07/14/2015 12:02:46;0040;PBS_Server;Svr;tyrone-cluster;Scheduler was sent the command new
07/14/2015 12:03:24;0040;PBS_Server;Svr;tyrone-cluster;Scheduler was sent the command new
07/14/2015 12:03:55;0040;PBS_Server;Svr;tyrone-cluster;Scheduler was sent the command new
07/14/2015 12:04:29;0040;PBS_Server;Svr;tyrone-cluster;Scheduler was sent the command new
07/14/2015 12:05:00;0040;PBS_Server;Svr;tyrone-cluster;Scheduler was sent the command new
07/14/2015 12:05:39;0040;PBS_Server;Svr;tyrone-cluster;Scheduler was sent the command new
07/14/2015 12:06:00;0040;PBS_Server;Svr;tyrone-cluster;Scheduler was sent the command new
07/14/2015 12:06:31;0040;PBS_Server;Svr;tyrone-cluster;Scheduler was sent the command new
07/14/2015 12:06:36;0002;PBS_Server;Svr;PBS_Server;Torque Server Version = 3.0.5, loglevel = 0
07/14/2015 12:07:09;0040;PBS_Server;Svr;tyrone-cluster;Scheduler was sent the command new
07/14/2015 12:07:40;0040;PBS_Server;Svr;tyrone-cluster;Scheduler was sent the command new
07/14/2015 12:08:14;0040;PBS_Server;Svr;tyrone-cluster;Scheduler was sent the command new
07/14/2015 12:08:45;0040;PBS_Server;Svr;tyrone-cluster;Scheduler was sent the command new
07/14/2015 12:09:07;000d;PBS_Server;Job;54642.tyrone-cluster;Not sending email: User does not want mail of this type.
07/14/2015 12:09:07;0010;PBS_Server;Job;54642.tyrone-cluster;Exit_status=265 resources_used.cput=00:00:00 resources_used.mem=66520kb resources_used.vmem=3807376kb resources_used.walltime=00:10:02
07/14/2015 12:09:07;0008;PBS_Server;Job;NULL;on_job_exit valid pjob: 0x1cf09a0 (substate=50)
07/14/2015 12:09:07;0008;PBS_Server;Job;NULL;on_job_exit valid pjob: 0x1cf09a0 (substate=51)
07/14/2015 12:09:07;0008;PBS_Server;Job;NULL;on_job_exit valid pjob: 0x1cf09a0 (substate=51)
07/14/2015 12:09:07;0008;PBS_Server;Job;NULL;on_job_exit valid pjob: 0x1cf09a0 (substate=53)
07/14/2015 12:09:07;0100;PBS_Server;Job;54642.tyrone-cluster;dequeuing from idqueue, state COMPLETE
07/14/2015 12:09:07;0040;PBS_Server;Svr;tyrone-cluster;Scheduler was sent the command term
07/14/2015 12:09:24;0040;PBS_Server;Svr;tyrone-cluster;Scheduler was sent the command new
07/14/2015 12:09:45;0040;PBS_Server;Svr;tyrone-cluster;Scheduler was sent the command new
07/14/2015 12:10:15;0040;PBS_Server;Svr;tyrone-cluster;Scheduler was sent the command new
07/14/2015 12:10:54;0040;PBS_Server;Svr;tyrone-cluster;Scheduler was sent the command new
07/14/2015 12:11:15;0040;PBS_Server;Svr;tyrone-cluster;Scheduler was sent the command new
07/14/2015 12:11:36;0002;PBS_Server;Svr;PBS_Server;Torque Server Version = 3.0.5, loglevel = 0
07/14/2015 12:11:46;0040;PBS_Server;Svr;tyrone-cluster;Scheduler was sent the command new
07/14/2015 12:12:24;0040;PBS_Server;Svr;tyrone-cluster;Scheduler was sent the command new
07/14/2015 12:12:45;0040;PBS_Server;Svr;tyrone-cluster;Scheduler was sent the command new
07/14/2015 12:13:15;0040;PBS_Server;Svr;tyrone-cluster;Scheduler was sent the command new
07/14/2015 12:13:54;0040;PBS_Server;Svr;tyrone-cluster;Scheduler was sent the command new
07/14/2015 12:14:16;0040;PBS_Server;Svr;tyrone-cluster;Scheduler was sent the command new
07/14/2015 12:14:46;0040;PBS_Server;Svr;tyrone-cluster;Scheduler was sent the command new
07/14/2015 12:15:24;0040;PBS_Server;Svr;tyrone-cluster;Scheduler was sent the command new
07/14/2015 12:15:45;0040;PBS_Server;Svr;tyrone-cluster;Scheduler was sent the command new
07/14/2015 12:16:16;0040;PBS_Server;Svr;tyrone-cluster;Scheduler was sent the command new
07/14/2015 12:16:36;0002;PBS_Server;Svr;PBS_Server;Torque Server Version = 3.0.5, loglevel = 0
07/14/2015 12:16:54;0040;PBS_Server;Svr;tyrone-cluster;Scheduler was sent the command new
07/14/2015 12:17:15;0040;PBS_Server;Svr;tyrone-cluster;Scheduler was sent the command new
07/14/2015 12:17:45;0040;PBS_Server;Svr;tyrone-cluster;Scheduler was sent the command new
07/14/2015 12:18:21;0040;PBS_Server;Svr;tyrone-cluster;Scheduler was sent the command new
07/14/2015 12:18:21;0100;PBS_Server;Job;54643.tyrone-cluster;enqueuing into batch, state 1 hop 1
07/14/2015 12:18:21;0008;PBS_Server;Job;54643.tyrone-cluster;Job Queued at request of icrtaraf@tyrone-cluster, owner = icrtaraf@tyrone-cluster, job name = OptCh, queue = batch
07/14/2015 12:18:21;0008;PBS_Server;Job;54643.tyrone-cluster;Job Modified at request of Scheduler@tyrone-cluster
07/14/2015 12:18:45;0040;PBS_Server;Svr;tyrone-cluster;Scheduler was sent the command new
07/14/2015 12:18:52;0040;PBS_Server;Svr;tyrone-cluster;Scheduler was sent the command new
07/14/2015 12:19:16;0040;PBS_Server;Svr;tyrone-cluster;Scheduler was sent the command new
07/14/2015 12:19:21;0040;PBS_Server;Svr;tyrone-cluster;Scheduler was sent the command new
07/14/2015 12:19:54;0040;PBS_Server;Svr;tyrone-cluster;Scheduler was sent the command new
07/14/2015 12:20:15;0040;PBS_Server;Svr;tyrone-cluster;Scheduler was sent the command new
07/14/2015 12:20:25;0040;PBS_Server;Svr;tyrone-cluster;Scheduler was sent the command new
07/14/2015 12:20:45;0040;PBS_Server;Svr;tyrone-cluster;Scheduler was sent the command new
07/14/2015 12:20:59;0040;PBS_Server;Svr;tyrone-cluster;Scheduler was sent the command new
07/14/2015 12:21:24;0040;PBS_Server;Svr;tyrone-cluster;Scheduler was sent the command new
07/14/2015 12:21:30;0040;PBS_Server;Svr;tyrone-cluster;Scheduler was sent the command new
07/14/2015 12:21:36;0002;PBS_Server;Svr;PBS_Server;Torque Server Version = 3.0.5, loglevel = 0
07/14/2015 12:21:45;0040;PBS_Server;Svr;tyrone-cluster;Scheduler was sent the command new
07/14/2015 12:22:09;0040;PBS_Server;Svr;tyrone-cluster;Scheduler was sent the command new
07/14/2015 12:22:16;0040;PBS_Server;Svr;tyrone-cluster;Scheduler was sent the command new
07/14/2015 12:22:30;0040;PBS_Server;Svr;tyrone-cluster;Scheduler was sent the command new
07/14/2015 12:22:54;0040;PBS_Server;Svr;tyrone-cluster;Scheduler was sent the command new
07/14/2015 12:23:01;0040;PBS_Server;Svr;tyrone-cluster;Scheduler was sent the command new
07/14/2015 12:23:01;0100;PBS_Server;Job;54644.tyrone-cluster;enqueuing into batch, state 1 hop 1
07/14/2015 12:23:01;0008;PBS_Server;Job;54644.tyrone-cluster;Job Queued at request of icrtaraf@tyrone-cluster, owner = icrtaraf@tyrone-cluster, job name = OptCh, queue = batch
07/14/2015 12:23:02;0008;PBS_Server;Job;54644.tyrone-cluster;Job Modified at request of Scheduler@tyrone-cluster
07/14/2015 12:23:15;0040;PBS_Server;Svr;tyrone-cluster;Scheduler was sent the command new
07/14/2015 12:23:40;0040;PBS_Server;Svr;tyrone-cluster;Scheduler was sent the command new
07/14/2015 12:23:46;0040;PBS_Server;Svr;tyrone-cluster;Scheduler was sent the command new
07/14/2015 12:24:00;0040;PBS_Server;Svr;tyrone-cluster;Scheduler was sent the command new
07/14/2015 12:24:11;0040;PBS_Server;Svr;tyrone-cluster;Scheduler was sent the command new
07/14/2015 12:24:25;0040;PBS_Server;Svr;tyrone-cluster;Scheduler was sent the command new
07/14/2015 12:24:31;0040;PBS_Server;Svr;tyrone-cluster;Scheduler was sent the command new
07/14/2015 12:24:45;0040;PBS_Server;Svr;tyrone-cluster;Scheduler was sent the command new
07/14/2015 12:25:10;0040;PBS_Server;Svr;tyrone-cluster;Scheduler was sent the command new
07/14/2015 12:25:15;0040;PBS_Server;Svr;tyrone-cluster;Scheduler was sent the command new
07/14/2015 12:25:30;0040;PBS_Server;Svr;tyrone-cluster;Scheduler was sent the command new
07/14/2015 12:25:55;0040;PBS_Server;Svr;tyrone-cluster;Scheduler was sent the command new
07/14/2015 12:26:01;0040;PBS_Server;Svr;tyrone-cluster;Scheduler was sent the command new
07/14/2015 12:26:15;0040;PBS_Server;Svr;tyrone-cluster;Scheduler was sent the command new
07/14/2015 12:26:36;0002;PBS_Server;Svr;PBS_Server;Torque Server Version = 3.0.5, loglevel = 0
07/14/2015 12:26:36;0040;PBS_Server;Svr;tyrone-cluster;Scheduler was sent the command new
07/14/2015 12:26:46;0040;PBS_Server;Svr;tyrone-cluster;Scheduler was sent the command new
07/14/2015 12:27:00;0040;PBS_Server;Svr;tyrone-cluster;Scheduler was sent the command new
07/14/2015 12:27:25;0040;PBS_Server;Svr;tyrone-cluster;Scheduler was sent the command new
07/14/2015 12:27:31;0040;PBS_Server;Svr;tyrone-cluster;Scheduler was sent the command new
07/14/2015 12:27:45;0040;PBS_Server;Svr;tyrone-cluster;Scheduler was sent the command new
07/14/2015 12:28:10;0040;PBS_Server;Svr;tyrone-cluster;Scheduler was sent the command new
07/14/2015 12:28:16;0040;PBS_Server;Svr;tyrone-cluster;Scheduler was sent the command new
07/14/2015 12:28:30;0040;PBS_Server;Svr;tyrone-cluster;Scheduler was sent the command new
07/14/2015 12:28:55;0040;PBS_Server;Svr;tyrone-cluster;Scheduler was sent the command new
07/14/2015 12:29:01;0040;PBS_Server;Svr;tyrone-cluster;Scheduler was sent the command new
07/14/2015 12:29:15;0040;PBS_Server;Svr;tyrone-cluster;Scheduler was sent the command new
07/14/2015 12:29:40;0040;PBS_Server;Svr;tyrone-cluster;Scheduler was sent the command new
07/14/2015 12:29:46;0040;PBS_Server;Svr;tyrone-cluster;Scheduler was sent the command new
07/14/2015 12:30:00;0040;PBS_Server;Svr;tyrone-cluster;Scheduler was sent the command new
07/14/2015 12:30:25;0040;PBS_Server;Svr;tyrone-cluster;Scheduler was sent the command new
07/14/2015 12:30:31;0040;PBS_Server;Svr;tyrone-cluster;Scheduler was sent the command new
07/14/2015 12:30:56;0040;PBS_Server;Svr;tyrone-cluster;Scheduler was sent the command new
07/14/2015 12:31:10;0040;PBS_Server;Svr;tyrone-cluster;Scheduler was sent the command new
07/14/2015 12:31:30;0040;PBS_Server;Svr;tyrone-cluster;Scheduler was sent the command new
07/14/2015 12:31:36;0002;PBS_Server;Svr;PBS_Server;Torque Server Version = 3.0.5, loglevel = 0
07/14/2015 12:31:59;0040;PBS_Server;Svr;tyrone-cluster;Scheduler was sent the command new
07/14/2015 12:32:01;0040;PBS_Server;Svr;tyrone-cluster;Scheduler was sent the command new
07/14/2015 12:32:40;0040;PBS_Server;Svr;tyrone-cluster;Scheduler was sent the command new
07/14/2015 12:33:00;0040;PBS_Server;Svr;tyrone-cluster;Scheduler was sent the command new
07/14/2015 12:33:31;0040;PBS_Server;Svr;tyrone-cluster;Scheduler was sent the command new
07/14/2015 12:34:10;0040;PBS_Server;Svr;tyrone-cluster;Scheduler was sent the command new
07/14/2015 12:34:30;0040;PBS_Server;Svr;tyrone-cluster;Scheduler was sent the command new
07/14/2015 12:35:01;0040;PBS_Server;Svr;tyrone-cluster;Scheduler was sent the command new
07/14/2015 12:35:40;0040;PBS_Server;Svr;tyrone-cluster;Scheduler was sent the command new
07/14/2015 12:36:00;0040;PBS_Server;Svr;tyrone-cluster;Scheduler was sent the command new
07/14/2015 12:36:31;0040;PBS_Server;Svr;tyrone-cluster;Scheduler was sent the command new
07/14/2015 12:36:36;0002;PBS_Server;Svr;PBS_Server;Torque Server Version = 3.0.5, loglevel = 0
07/14/2015 12:37:10;0040;PBS_Server;Svr;tyrone-cluster;Scheduler was sent the command new
07/14/2015 12:37:30;0040;PBS_Server;Svr;tyrone-cluster;Scheduler was sent the command new
07/14/2015 12:38:01;0040;PBS_Server;Svr;tyrone-cluster;Scheduler was sent the command new
07/14/2015 12:38:40;0040;PBS_Server;Svr;tyrone-cluster;Scheduler was sent the command new
07/14/2015 12:39:00;0040;PBS_Server;Svr;tyrone-cluster;Scheduler was sent the command new
07/14/2015 12:39:31;0040;PBS_Server;Svr;tyrone-cluster;Scheduler was sent the command new
07/14/2015 12:40:10;0040;PBS_Server;Svr;tyrone-cluster;Scheduler was sent the command new
07/14/2015 12:40:30;0040;PBS_Server;Svr;tyrone-cluster;Scheduler was sent the command new
07/14/2015 12:41:01;0040;PBS_Server;Svr;tyrone-cluster;Scheduler was sent the command new
07/14/2015 12:41:36;0002;PBS_Server;Svr;PBS_Server;Torque Server Version = 3.0.5, loglevel = 0
07/14/2015 12:41:36;0040;PBS_Server;Svr;tyrone-cluster;Scheduler was sent the command new
07/14/2015 12:42:00;0040;PBS_Server;Svr;tyrone-cluster;Scheduler was sent the command new
07/14/2015 12:42:02;000d;PBS_Server;Job;54625.tyrone-cluster;Not sending email: User does not want mail of this type.
07/14/2015 12:42:02;0010;PBS_Server;Job;54625.tyrone-cluster;Exit_status=0 resources_used.cput=47:20:52 resources_used.mem=1990040kb resources_used.vmem=8842648kb resources_used.walltime=01:29:13
07/14/2015 12:42:02;0008;PBS_Server;Job;NULL;on_job_exit valid pjob: 0x1d6c780 (substate=50)
07/14/2015 12:42:02;0008;PBS_Server;Job;NULL;on_job_exit valid pjob: 0x1d6c780 (substate=51)
07/14/2015 12:42:11;0008;PBS_Server;Job;NULL;on_job_exit valid pjob: 0x1d6c780 (substate=51)
07/14/2015 12:42:11;000d;PBS_Server;Job;54625.tyrone-cluster;Post job file processing error; job 54625.tyrone-cluster on host tyrone-node3/31+tyrone-node3/30+tyrone-node3/29+tyrone-node3/28+tyrone-node3/27+tyrone-node3/26+tyrone-node3/25+tyrone-node3/24+tyrone-node3/23+tyrone-node3/22+tyrone-node3/21+tyrone-node3/20+tyrone-node3/19+tyrone-node3/18+tyrone-node3/17+tyrone-node3/16+tyrone-node3/15+tyrone-node3/14+tyrone-node3/13+tyrone-node3/12+tyrone-node3/11+tyrone-node3/10+tyrone-node3/9+tyrone-node3/8+tyrone-node3/7+tyrone-node3/6+tyrone-node3/5+tyrone-node3/4+tyrone-node3/3+tyrone-node3/2+tyrone-node3/1+tyrone-node3/0+tyrone-node2/31+tyrone-node2/30+tyrone-node2/29+tyrone-node2/28+tyrone-node2/27+tyrone-node2/26+tyrone-node2/25+tyrone-node2/24+tyrone-node2/23+tyrone-node2/22+tyrone-node2/21+tyrone-node2/20+tyrone-node2/19+tyrone-node2/18+tyrone-node2/17+tyrone-node2/16+tyrone-node2/15+tyrone-node2/14+tyrone-node2/13+tyrone-node2/12+tyrone-node2/11+tyrone-node2/10+tyrone-node2/9+tyrone-node2/8+tyrone-node2/7+tyrone-node2/6+tyrone-node2/5+tyrone-node2/4+tyrone-node2/3+tyrone-node2/2+tyrone-node2/1+tyrone-node2/0
07/14/2015 12:42:11;0008;PBS_Server;Job;NULL;on_job_exit valid pjob: 0x1d6c780 (substate=53)
07/14/2015 12:42:11;0100;PBS_Server;Job;54625.tyrone-cluster;dequeuing from qp64, state COMPLETE
07/14/2015 12:42:11;0040;PBS_Server;Svr;tyrone-cluster;Scheduler was sent the command term
07/14/2015 12:42:11;0008;PBS_Server;Job;54630.tyrone-cluster;Job Modified at request of Scheduler@tyrone-cluster
07/14/2015 12:42:11;0008;PBS_Server;Job;54630.tyrone-cluster;Job Run at request of Scheduler@tyrone-cluster
07/14/2015 12:42:11;0040;PBS_Server;Svr;tyrone-cluster;Scheduler was sent the command recyc
07/14/2015 12:42:31;0040;PBS_Server;Svr;tyrone-cluster;Scheduler was sent the command new
07/14/2015 12:42:35;000d;PBS_Server;Job;54630.tyrone-cluster;Not sending email: User does not want mail of this type.
07/14/2015 12:43:12;0040;PBS_Server;Svr;tyrone-cluster;Scheduler was sent the command new
07/14/2015 12:43:30;0040;PBS_Server;Svr;tyrone-cluster;Scheduler was sent the command new
07/14/2015 12:44:01;0040;PBS_Server;Svr;tyrone-cluster;Scheduler was sent the command new
07/14/2015 12:44:42;0040;PBS_Server;Svr;tyrone-cluster;Scheduler was sent the command new
07/14/2015 12:45:00;0040;PBS_Server;Svr;tyrone-cluster;Scheduler was sent the command new
07/14/2015 12:45:31;0040;PBS_Server;Svr;tyrone-cluster;Scheduler was sent the command new
07/14/2015 12:46:12;0040;PBS_Server;Svr;tyrone-cluster;Scheduler was sent the command new
07/14/2015 12:46:30;0040;PBS_Server;Svr;tyrone-cluster;Scheduler was sent the command new
07/14/2015 12:46:36;0002;PBS_Server;Svr;PBS_Server;Torque Server Version = 3.0.5, loglevel = 0
07/14/2015 12:47:01;0040;PBS_Server;Svr;tyrone-cluster;Scheduler was sent the command new
07/14/2015 12:47:42;0040;PBS_Server;Svr;tyrone-cluster;Scheduler was sent the command new
07/14/2015 12:48:00;0040;PBS_Server;Svr;tyrone-cluster;Scheduler was sent the command new
07/14/2015 12:48:31;0040;PBS_Server;Svr;tyrone-cluster;Scheduler was sent the command new
07/14/2015 12:49:12;0040;PBS_Server;Svr;tyrone-cluster;Scheduler was sent the command new
07/14/2015 12:49:30;0040;PBS_Server;Svr;tyrone-cluster;Scheduler was sent the command new
07/14/2015 12:50:01;0040;PBS_Server;Svr;tyrone-cluster;Scheduler was sent the command new
07/14/2015 12:50:42;0040;PBS_Server;Svr;tyrone-cluster;Scheduler was sent the command new
07/14/2015 12:51:00;0040;PBS_Server;Svr;tyrone-cluster;Scheduler was sent the command new
07/14/2015 12:51:31;0040;PBS_Server;Svr;tyrone-cluster;Scheduler was sent the command new
07/14/2015 12:51:36;0002;PBS_Server;Svr;PBS_Server;Torque Server Version = 3.0.5, loglevel = 0
07/14/2015 12:52:12;0040;PBS_Server;Svr;tyrone-cluster;Scheduler was sent the command new
07/14/2015 12:52:30;0040;PBS_Server;Svr;tyrone-cluster;Scheduler was sent the command new
07/14/2015 12:53:01;0040;PBS_Server;Svr;tyrone-cluster;Scheduler was sent the command new
07/14/2015 12:53:42;0040;PBS_Server;Svr;tyrone-cluster;Scheduler was sent the command new
07/14/2015 12:54:00;0040;PBS_Server;Svr;tyrone-cluster;Scheduler was sent the command new
07/14/2015 12:54:31;0040;PBS_Server;Svr;tyrone-cluster;Scheduler was sent the command new
07/14/2015 12:55:12;0040;PBS_Server;Svr;tyrone-cluster;Scheduler was sent the command new
07/14/2015 12:55:30;0040;PBS_Server;Svr;tyrone-cluster;Scheduler was sent the command new
07/14/2015 12:56:01;0040;PBS_Server;Svr;tyrone-cluster;Scheduler was sent the command new
07/14/2015 12:56:36;0002;PBS_Server;Svr;PBS_Server;Torque Server Version = 3.0.5, loglevel = 0
07/14/2015 12:56:36;0040;PBS_Server;Svr;tyrone-cluster;Scheduler was sent the command new
07/14/2015 12:57:00;0040;PBS_Server;Svr;tyrone-cluster;Scheduler was sent the command new
07/14/2015 12:57:31;0040;PBS_Server;Svr;tyrone-cluster;Scheduler was sent the command new
07/14/2015 12:58:12;0040;PBS_Server;Svr;tyrone-cluster;Scheduler was sent the command new
07/14/2015 12:58:30;0040;PBS_Server;Svr;tyrone-cluster;Scheduler was sent the command new
07/14/2015 12:59:01;0040;PBS_Server;Svr;tyrone-cluster;Scheduler was sent the command new
07/14/2015 12:59:42;0040;PBS_Server;Svr;tyrone-cluster;Scheduler was sent the command new
07/14/2015 13:00:00;0040;PBS_Server;Svr;tyrone-cluster;Scheduler was sent the command new
07/14/2015 13:00:31;0040;PBS_Server;Svr;tyrone-cluster;Scheduler was sent the command new
07/14/2015 13:01:12;0040;PBS_Server;Svr;tyrone-cluster;Scheduler was sent the command new
07/14/2015 13:01:30;0040;PBS_Server;Svr;tyrone-cluster;Scheduler was sent the command new
07/14/2015 13:01:36;0002;PBS_Server;Svr;PBS_Server;Torque Server Version = 3.0.5, loglevel = 0
07/14/2015 13:02:01;0040;PBS_Server;Svr;tyrone-cluster;Scheduler was sent the command new
07/14/2015 13:02:42;0040;PBS_Server;Svr;tyrone-cluster;Scheduler was sent the command new
07/14/2015 13:03:00;0040;PBS_Server;Svr;tyrone-cluster;Scheduler was sent the command new
07/14/2015 13:03:31;0040;PBS_Server;Svr;tyrone-cluster;Scheduler was sent the command new
07/14/2015 13:04:12;0040;PBS_Server;Svr;tyrone-cluster;Scheduler was sent the command new
07/14/2015 13:04:30;0040;PBS_Server;Svr;tyrone-cluster;Scheduler was sent the command new
07/14/2015 13:05:01;0040;PBS_Server;Svr;tyrone-cluster;Scheduler was sent the command new
07/14/2015 13:05:42;0040;PBS_Server;Svr;tyrone-cluster;Scheduler was sent the command new
07/14/2015 13:06:00;0040;PBS_Server;Svr;tyrone-cluster;Scheduler was sent the command new
07/14/2015 13:06:31;0040;PBS_Server;Svr;tyrone-cluster;Scheduler was sent the command new
07/14/2015 13:06:36;0002;PBS_Server;Svr;PBS_Server;Torque Server Version = 3.0.5, loglevel = 0
07/14/2015 13:07:12;0040;PBS_Server;Svr;tyrone-cluster;Scheduler was sent the command new
07/14/2015 13:07:30;0040;PBS_Server;Svr;tyrone-cluster;Scheduler was sent the command new
07/14/2015 13:08:01;0040;PBS_Server;Svr;tyrone-cluster;Scheduler was sent the command new
07/14/2015 13:08:42;0040;PBS_Server;Svr;tyrone-cluster;Scheduler was sent the command new
07/14/2015 13:09:00;0040;PBS_Server;Svr;tyrone-cluster;Scheduler was sent the command new
07/14/2015 13:09:07;000d;PBS_Server;Job;54584.tyrone-cluster;Not sending email: User does not want mail of this type.
07/14/2015 13:09:07;0010;PBS_Server;Job;54584.tyrone-cluster;Exit_status=143 resources_used.cput=21:39:42 resources_used.mem=319096kb resources_used.vmem=4195080kb resources_used.walltime=24:00:44
07/14/2015 13:09:07;0008;PBS_Server;Job;NULL;on_job_exit valid pjob: 0x1d13ae0 (substate=50)
07/14/2015 13:09:07;0008;PBS_Server;Job;NULL;on_job_exit valid pjob: 0x1d13ae0 (substate=51)
07/14/2015 13:09:07;0008;PBS_Server;Job;NULL;on_job_exit valid pjob: 0x1d13ae0 (substate=51)
07/14/2015 13:09:07;0008;PBS_Server;Job;NULL;on_job_exit valid pjob: 0x1d13ae0 (substate=53)
07/14/2015 13:09:07;0100;PBS_Server;Job;54584.tyrone-cluster;dequeuing from qp32, state COMPLETE
07/14/2015 13:09:07;0040;PBS_Server;Svr;tyrone-cluster;Scheduler was sent the command term
07/14/2015 13:09:07;0008;PBS_Server;Job;54589.tyrone-cluster;Job Modified at request of Scheduler@tyrone-cluster
07/14/2015 13:09:07;0008;PBS_Server;Job;54589.tyrone-cluster;Job Run at request of Scheduler@tyrone-cluster
07/14/2015 13:09:07;0040;PBS_Server;Svr;tyrone-cluster;Scheduler was sent the command recyc
07/14/2015 13:09:07;000d;PBS_Server;Job;54589.tyrone-cluster;Not sending email: User does not want mail of this type.
07/14/2015 13:09:30;0100;PBS_Server;Job;54643.tyrone-cluster;dequeuing from batch, state QUEUED
07/14/2015 13:09:30;0100;PBS_Server;Job;54643.tyrone-cluster;enqueuing into qp32, state 1 hop 1
07/14/2015 13:09:31;0040;PBS_Server;Svr;tyrone-cluster;Scheduler was sent the command new
07/14/2015 13:09:31;0008;PBS_Server;Job;54643.tyrone-cluster;Job Modified at request of Scheduler@tyrone-cluster
07/14/2015 13:10:12;0040;PBS_Server;Svr;tyrone-cluster;Scheduler was sent the command new
07/14/2015 13:10:30;0040;PBS_Server;Svr;tyrone-cluster;Scheduler was sent the command new
07/14/2015 13:11:01;0040;PBS_Server;Svr;tyrone-cluster;Scheduler was sent the command new
07/14/2015 13:11:36;0002;PBS_Server;Svr;PBS_Server;Torque Server Version = 3.0.5, loglevel = 0
07/14/2015 13:11:36;0040;PBS_Server;Svr;tyrone-cluster;Scheduler was sent the command new
07/14/2015 13:12:01;0040;PBS_Server;Svr;tyrone-cluster;Scheduler was sent the command new
07/14/2015 13:12:32;0040;PBS_Server;Svr;tyrone-cluster;Scheduler was sent the command new
07/14/2015 13:13:13;0040;PBS_Server;Svr;tyrone-cluster;Scheduler was sent the command new
07/14/2015 13:13:50;0040;PBS_Server;Svr;tyrone-cluster;Scheduler was sent the command new
07/14/2015 13:14:16;0040;PBS_Server;Svr;tyrone-cluster;Scheduler was sent the command new
07/14/2015 13:14:46;0040;PBS_Server;Svr;tyrone-cluster;Scheduler was sent the command new
07/14/2015 13:15:27;0040;PBS_Server;Svr;tyrone-cluster;Scheduler was sent the command new
07/14/2015 13:15:46;0040;PBS_Server;Svr;tyrone-cluster;Scheduler was sent the command new
07/14/2015 13:16:16;0040;PBS_Server;Svr;tyrone-cluster;Scheduler was sent the command new
07/14/2015 13:16:36;0002;PBS_Server;Svr;PBS_Server;Torque Server Version = 3.0.5, loglevel = 0
07/14/2015 13:16:57;0040;PBS_Server;Svr;tyrone-cluster;Scheduler was sent the command new
07/14/2015 13:17:15;0040;PBS_Server;Svr;tyrone-cluster;Scheduler was sent the command new
07/14/2015 13:17:46;0040;PBS_Server;Svr;tyrone-cluster;Scheduler was sent the command new
07/14/2015 13:18:27;0040;PBS_Server;Svr;tyrone-cluster;Scheduler was sent the command new
07/14/2015 13:18:46;0040;PBS_Server;Svr;tyrone-cluster;Scheduler was sent the command new
07/14/2015 13:19:16;0040;PBS_Server;Svr;tyrone-cluster;Scheduler was sent the command new
07/14/2015 13:19:57;0040;PBS_Server;Svr;tyrone-cluster;Scheduler was sent the command new
07/14/2015 13:20:15;0040;PBS_Server;Svr;tyrone-cluster;Scheduler was sent the command new
07/14/2015 13:20:46;0040;PBS_Server;Svr;tyrone-cluster;Scheduler was sent the command new
07/14/2015 13:21:27;0040;PBS_Server;Svr;tyrone-cluster;Scheduler was sent the command new
07/14/2015 13:21:36;0002;PBS_Server;Svr;PBS_Server;Torque Server Version = 3.0.5, loglevel = 0
07/14/2015 13:21:45;0040;PBS_Server;Svr;tyrone-cluster;Scheduler was sent the command new
07/14/2015 13:22:16;0040;PBS_Server;Svr;tyrone-cluster;Scheduler was sent the command new
07/14/2015 13:22:57;0040;PBS_Server;Svr;tyrone-cluster;Scheduler was sent the command new
07/14/2015 13:23:16;0040;PBS_Server;Svr;tyrone-cluster;Scheduler was sent the command new
07/14/2015 13:23:47;0040;PBS_Server;Svr;tyrone-cluster;Scheduler was sent the command new
07/14/2015 13:24:28;0040;PBS_Server;Svr;tyrone-cluster;Scheduler was sent the command new
07/14/2015 13:25:00;0040;PBS_Server;Svr;tyrone-cluster;Scheduler was sent the command new
07/14/2015 13:25:31;0040;PBS_Server;Svr;tyrone-cluster;Scheduler was sent the command new
07/14/2015 13:26:01;0040;PBS_Server;Svr;tyrone-cluster;Scheduler was sent the command new
07/14/2015 13:26:36;0002;PBS_Server;Svr;PBS_Server;Torque Server Version = 3.0.5, loglevel = 0
07/14/2015 13:26:36;0040;PBS_Server;Svr;tyrone-cluster;Scheduler was sent the command new
07/14/2015 13:27:00;0040;PBS_Server;Svr;tyrone-cluster;Scheduler was sent the command new
07/14/2015 13:27:31;0040;PBS_Server;Svr;tyrone-cluster;Scheduler was sent the command new
07/14/2015 13:28:12;0040;PBS_Server;Svr;tyrone-cluster;Scheduler was sent the command new
07/14/2015 13:28:31;0040;PBS_Server;Svr;tyrone-cluster;Scheduler was sent the command new
07/14/2015 13:29:01;0040;PBS_Server;Svr;tyrone-cluster;Scheduler was sent the command new
07/14/2015 13:29:42;0040;PBS_Server;Svr;tyrone-cluster;Scheduler was sent the command new
07/14/2015 13:30:00;0040;PBS_Server;Svr;tyrone-cluster;Scheduler was sent the command new
07/14/2015 13:30:31;0040;PBS_Server;Svr;tyrone-cluster;Scheduler was sent the command new
07/14/2015 13:31:12;0040;PBS_Server;Svr;tyrone-cluster;Scheduler was sent the command new
07/14/2015 13:31:31;0040;PBS_Server;Svr;tyrone-cluster;Scheduler was sent the command new
07/14/2015 13:31:36;0002;PBS_Server;Svr;PBS_Server;Torque Server Version = 3.0.5, loglevel = 0
07/14/2015 13:32:02;0040;PBS_Server;Svr;tyrone-cluster;Scheduler was sent the command new
07/14/2015 13:32:43;0040;PBS_Server;Svr;tyrone-cluster;Scheduler was sent the command new
07/14/2015 13:33:27;0040;PBS_Server;Svr;tyrone-cluster;Scheduler was sent the command new
07/14/2015 13:33:45;0040;PBS_Server;Svr;tyrone-cluster;Scheduler was sent the command new
07/14/2015 13:34:16;0040;PBS_Server;Svr;tyrone-cluster;Scheduler was sent the command new
07/14/2015 13:34:51;0040;PBS_Server;Svr;tyrone-cluster;Scheduler was sent the command new
07/14/2015 13:35:15;0040;PBS_Server;Svr;tyrone-cluster;Scheduler was sent the command new
07/14/2015 13:35:46;0040;PBS_Server;Svr;tyrone-cluster;Scheduler was sent the command new
07/14/2015 13:36:27;0040;PBS_Server;Svr;tyrone-cluster;Scheduler was sent the command new
07/14/2015 13:36:36;0002;PBS_Server;Svr;PBS_Server;Torque Server Version = 3.0.5, loglevel = 0
07/14/2015 13:36:46;0040;PBS_Server;Svr;tyrone-cluster;Scheduler was sent the command new
07/14/2015 13:37:15;0040;PBS_Server;Svr;tyrone-cluster;Scheduler was sent the command new
07/14/2015 13:37:57;0040;PBS_Server;Svr;tyrone-cluster;Scheduler was sent the command new
07/14/2015 13:38:15;0040;PBS_Server;Svr;tyrone-cluster;Scheduler was sent the command new
07/14/2015 13:38:46;0040;PBS_Server;Svr;tyrone-cluster;Scheduler was sent the command new
07/14/2015 13:39:27;0040;PBS_Server;Svr;tyrone-cluster;Scheduler was sent the command new
07/14/2015 13:39:45;0040;PBS_Server;Svr;tyrone-cluster;Scheduler was sent the command new
07/14/2015 13:40:16;0040;PBS_Server;Svr;tyrone-cluster;Scheduler was sent the command new
07/14/2015 13:40:57;0040;PBS_Server;Svr;tyrone-cluster;Scheduler was sent the command new
07/14/2015 13:41:16;0040;PBS_Server;Svr;tyrone-cluster;Scheduler was sent the command new
07/14/2015 13:41:36;0002;PBS_Server;Svr;PBS_Server;Torque Server Version = 3.0.5, loglevel = 0
07/14/2015 13:41:47;0040;PBS_Server;Svr;tyrone-cluster;Scheduler was sent the command new
07/14/2015 13:42:28;0040;PBS_Server;Svr;tyrone-cluster;Scheduler was sent the command new
07/14/2015 13:43:12;0040;PBS_Server;Svr;tyrone-cluster;Scheduler was sent the command new
07/14/2015 13:43:30;0040;PBS_Server;Svr;tyrone-cluster;Scheduler was sent the command new
07/14/2015 13:44:01;0040;PBS_Server;Svr;tyrone-cluster;Scheduler was sent the command new
07/14/2015 13:44:42;0040;PBS_Server;Svr;tyrone-cluster;Scheduler was sent the command new
07/14/2015 13:45:01;0040;PBS_Server;Svr;tyrone-cluster;Scheduler was sent the command new
07/14/2015 13:45:32;0040;PBS_Server;Svr;tyrone-cluster;Scheduler was sent the command new
07/14/2015 13:46:13;0040;PBS_Server;Svr;tyrone-cluster;Scheduler was sent the command new
07/14/2015 13:46:36;0002;PBS_Server;Svr;PBS_Server;Torque Server Version = 3.0.5, loglevel = 0
07/14/2015 13:46:57;0040;PBS_Server;Svr;tyrone-cluster;Scheduler was sent the command new
07/14/2015 13:47:16;0040;PBS_Server;Svr;tyrone-cluster;Scheduler was sent the command new
07/14/2015 13:47:47;0040;PBS_Server;Svr;tyrone-cluster;Scheduler was sent the command new
07/14/2015 13:48:27;0040;PBS_Server;Svr;tyrone-cluster;Scheduler was sent the command new
07/14/2015 13:48:46;0040;PBS_Server;Svr;tyrone-cluster;Scheduler was sent the command new
07/14/2015 13:49:16;0040;PBS_Server;Svr;tyrone-cluster;Scheduler was sent the command new
07/14/2015 13:49:58;0040;PBS_Server;Svr;tyrone-cluster;Scheduler was sent the command new
07/14/2015 13:50:42;0040;PBS_Server;Svr;tyrone-cluster;Scheduler was sent the command new
07/14/2015 13:51:01;0040;PBS_Server;Svr;tyrone-cluster;Scheduler was sent the command new
07/14/2015 13:51:32;0040;PBS_Server;Svr;tyrone-cluster;Scheduler was sent the command new
07/14/2015 13:51:36;0002;PBS_Server;Svr;PBS_Server;Torque Server Version = 3.0.5, loglevel = 0
07/14/2015 13:52:13;0040;PBS_Server;Svr;tyrone-cluster;Scheduler was sent the command new
07/14/2015 13:52:57;0040;PBS_Server;Svr;tyrone-cluster;Scheduler was sent the command new
07/14/2015 13:53:16;0040;PBS_Server;Svr;tyrone-cluster;Scheduler was sent the command new
07/14/2015 13:53:47;0040;PBS_Server;Svr;tyrone-cluster;Scheduler was sent the command new
07/14/2015 13:54:27;0040;PBS_Server;Svr;tyrone-cluster;Scheduler was sent the command new
07/14/2015 13:54:46;0040;PBS_Server;Svr;tyrone-cluster;Scheduler was sent the command new
07/14/2015 13:55:17;0040;PBS_Server;Svr;tyrone-cluster;Scheduler was sent the command new
07/14/2015 13:55:57;0040;PBS_Server;Svr;tyrone-cluster;Scheduler was sent the command new
07/14/2015 13:56:16;0040;PBS_Server;Svr;tyrone-cluster;Scheduler was sent the command new
07/14/2015 13:56:36;0002;PBS_Server;Svr;PBS_Server;Torque Server Version = 3.0.5, loglevel = 0
07/14/2015 13:56:46;0040;PBS_Server;Svr;tyrone-cluster;Scheduler was sent the command new
07/14/2015 13:57:27;0040;PBS_Server;Svr;tyrone-cluster;Scheduler was sent the command new
07/14/2015 13:57:46;0040;PBS_Server;Svr;tyrone-cluster;Scheduler was sent the command new
07/14/2015 13:58:17;0040;PBS_Server;Svr;tyrone-cluster;Scheduler was sent the command new
07/14/2015 13:58:58;0040;PBS_Server;Svr;tyrone-cluster;Scheduler was sent the command new
07/14/2015 13:59:42;0040;PBS_Server;Svr;tyrone-cluster;Scheduler was sent the command new
07/14/2015 14:00:01;0040;PBS_Server;Svr;tyrone-cluster;Scheduler was sent the command new
07/14/2015 14:00:32;0040;PBS_Server;Svr;tyrone-cluster;Scheduler was sent the command new
07/14/2015 14:01:12;0040;PBS_Server;Svr;tyrone-cluster;Scheduler was sent the command new
07/14/2015 14:01:31;0040;PBS_Server;Svr;tyrone-cluster;Scheduler was sent the command new
07/14/2015 14:01:36;0002;PBS_Server;Svr;PBS_Server;Torque Server Version = 3.0.5, loglevel = 0
07/14/2015 14:02:02;0040;PBS_Server;Svr;tyrone-cluster;Scheduler was sent the command new
07/14/2015 14:02:43;0040;PBS_Server;Svr;tyrone-cluster;Scheduler was sent the command new
07/14/2015 14:03:15;0040;PBS_Server;Svr;tyrone-cluster;Scheduler was sent the command new
07/14/2015 14:03:46;0040;PBS_Server;Svr;tyrone-cluster;Scheduler was sent the command new
07/14/2015 14:04:17;0040;PBS_Server;Svr;tyrone-cluster;Scheduler was sent the command new
07/14/2015 14:04:57;0040;PBS_Server;Svr;tyrone-cluster;Scheduler was sent the command new
07/14/2015 14:05:16;0040;PBS_Server;Svr;tyrone-cluster;Scheduler was sent the command new
07/14/2015 14:05:47;0040;PBS_Server;Svr;tyrone-cluster;Scheduler was sent the command new
07/14/2015 14:06:28;0040;PBS_Server;Svr;tyrone-cluster;Scheduler was sent the command new
07/14/2015 14:06:36;0002;PBS_Server;Svr;PBS_Server;Torque Server Version = 3.0.5, loglevel = 0
07/14/2015 14:07:00;0040;PBS_Server;Svr;tyrone-cluster;Scheduler was sent the command new
07/14/2015 14:07:31;0040;PBS_Server;Svr;tyrone-cluster;Scheduler was sent the command new
07/14/2015 14:08:02;0040;PBS_Server;Svr;tyrone-cluster;Scheduler was sent the command new
07/14/2015 14:08:42;0040;PBS_Server;Svr;tyrone-cluster;Scheduler was sent the command new
07/14/2015 14:09:01;0040;PBS_Server;Svr;tyrone-cluster;Scheduler was sent the command new
07/14/2015 14:09:32;0040;PBS_Server;Svr;tyrone-cluster;Scheduler was sent the command new
07/14/2015 14:10:13;0040;PBS_Server;Svr;tyrone-cluster;Scheduler was sent the command new
07/14/2015 14:10:57;0040;PBS_Server;Svr;tyrone-cluster;Scheduler was sent the command new
07/14/2015 14:11:16;0040;PBS_Server;Svr;tyrone-cluster;Scheduler was sent the command new
07/14/2015 14:11:36;0002;PBS_Server;Svr;PBS_Server;Torque Server Version = 3.0.5, loglevel = 0
07/14/2015 14:11:47;0040;PBS_Server;Svr;tyrone-cluster;Scheduler was sent the command new
07/14/2015 14:12:27;0040;PBS_Server;Svr;tyrone-cluster;Scheduler was sent the command new
07/14/2015 14:12:46;0040;PBS_Server;Svr;tyrone-cluster;Scheduler was sent the command new
07/14/2015 14:13:17;0040;PBS_Server;Svr;tyrone-cluster;Scheduler was sent the command new
07/14/2015 14:13:58;0040;PBS_Server;Svr;tyrone-cluster;Scheduler was sent the command new
07/14/2015 14:14:30;0040;PBS_Server;Svr;tyrone-cluster;Scheduler was sent the command new
07/14/2015 14:15:01;0040;PBS_Server;Svr;tyrone-cluster;Scheduler was sent the command new
07/14/2015 14:15:32;0040;PBS_Server;Svr;tyrone-cluster;Scheduler was sent the command new
07/14/2015 14:16:12;0040;PBS_Server;Svr;tyrone-cluster;Scheduler was sent the command new
07/14/2015 14:16:31;0040;PBS_Server;Svr;tyrone-cluster;Scheduler was sent the command new
07/14/2015 14:16:36;0002;PBS_Server;Svr;PBS_Server;Torque Server Version = 3.0.5, loglevel = 0
07/14/2015 14:17:01;0040;PBS_Server;Svr;tyrone-cluster;Scheduler was sent the command new
07/14/2015 14:17:42;0040;PBS_Server;Svr;tyrone-cluster;Scheduler was sent the command new
07/14/2015 14:18:01;0040;PBS_Server;Svr;tyrone-cluster;Scheduler was sent the command new
07/14/2015 14:18:32;0040;PBS_Server;Svr;tyrone-cluster;Scheduler was sent the command new
07/14/2015 14:19:12;0040;PBS_Server;Svr;tyrone-cluster;Scheduler was sent the command new
07/14/2015 14:19:31;0040;PBS_Server;Svr;tyrone-cluster;Scheduler was sent the command new
07/14/2015 14:20:02;0040;PBS_Server;Svr;tyrone-cluster;Scheduler was sent the command new
07/14/2015 14:20:43;0040;PBS_Server;Svr;tyrone-cluster;Scheduler was sent the command new
07/14/2015 14:21:15;0040;PBS_Server;Svr;tyrone-cluster;Scheduler was sent the command new
07/14/2015 14:21:36;0002;PBS_Server;Svr;PBS_Server;Torque Server Version = 3.0.5, loglevel = 0
07/14/2015 14:21:46;0040;PBS_Server;Svr;tyrone-cluster;Scheduler was sent the command new
07/14/2015 14:22:17;0040;PBS_Server;Svr;tyrone-cluster;Scheduler was sent the command new
07/14/2015 14:22:58;0040;PBS_Server;Svr;tyrone-cluster;Scheduler was sent the command new
07/14/2015 14:23:42;0040;PBS_Server;Svr;tyrone-cluster;Scheduler was sent the command new
07/14/2015 14:24:01;0040;PBS_Server;Svr;tyrone-cluster;Scheduler was sent the command new
07/14/2015 14:24:32;0040;PBS_Server;Svr;tyrone-cluster;Scheduler was sent the command new
07/14/2015 14:25:13;0040;PBS_Server;Svr;tyrone-cluster;Scheduler was sent the command new
07/14/2015 14:25:45;0040;PBS_Server;Svr;tyrone-cluster;Scheduler was sent the command new
07/14/2015 14:26:16;0040;PBS_Server;Svr;tyrone-cluster;Scheduler was sent the command new
07/14/2015 14:26:36;0002;PBS_Server;Svr;PBS_Server;Torque Server Version = 3.0.5, loglevel = 0
07/14/2015 14:26:47;0040;PBS_Server;Svr;tyrone-cluster;Scheduler was sent the command new
07/14/2015 14:27:28;0040;PBS_Server;Svr;tyrone-cluster;Scheduler was sent the command new
07/14/2015 14:28:01;0040;PBS_Server;Svr;tyrone-cluster;Scheduler was sent the command new
07/14/2015 14:28:31;0040;PBS_Server;Svr;tyrone-cluster;Scheduler was sent the command new
07/14/2015 14:29:02;0040;PBS_Server;Svr;tyrone-cluster;Scheduler was sent the command new
07/14/2015 14:29:42;0040;PBS_Server;Svr;tyrone-cluster;Scheduler was sent the command new
07/14/2015 14:30:01;0040;PBS_Server;Svr;tyrone-cluster;Scheduler was sent the command new
07/14/2015 14:30:31;0040;PBS_Server;Svr;tyrone-cluster;Scheduler was sent the command new
07/14/2015 14:31:12;0040;PBS_Server;Svr;tyrone-cluster;Scheduler was sent the command new
07/14/2015 14:31:31;0040;PBS_Server;Svr;tyrone-cluster;Scheduler was sent the command new
07/14/2015 14:31:36;0002;PBS_Server;Svr;PBS_Server;Torque Server Version = 3.0.5, loglevel = 0
07/14/2015 14:32:02;0040;PBS_Server;Svr;tyrone-cluster;Scheduler was sent the command new
07/14/2015 14:32:42;0040;PBS_Server;Svr;tyrone-cluster;Scheduler was sent the command new
07/14/2015 14:33:01;0040;PBS_Server;Svr;tyrone-cluster;Scheduler was sent the command new
07/14/2015 14:33:32;0040;PBS_Server;Svr;tyrone-cluster;Scheduler was sent the command new
07/14/2015 14:34:13;0040;PBS_Server;Svr;tyrone-cluster;Scheduler was sent the command new
07/14/2015 14:34:46;0040;PBS_Server;Svr;tyrone-cluster;Scheduler was sent the command new
07/14/2015 14:35:16;0040;PBS_Server;Svr;tyrone-cluster;Scheduler was sent the command new
07/14/2015 14:35:47;0040;PBS_Server;Svr;tyrone-cluster;Scheduler was sent the command new
07/14/2015 14:36:27;0040;PBS_Server;Svr;tyrone-cluster;Scheduler was sent the command new
07/14/2015 14:36:36;0002;PBS_Server;Svr;PBS_Server;Torque Server Version = 3.0.5, loglevel = 0
07/14/2015 14:36:46;0040;PBS_Server;Svr;tyrone-cluster;Scheduler was sent the command new
07/14/2015 14:37:17;0040;PBS_Server;Svr;tyrone-cluster;Scheduler was sent the command new
07/14/2015 14:37:58;0040;PBS_Server;Svr;tyrone-cluster;Scheduler was sent the command new
07/14/2015 14:38:42;0040;PBS_Server;Svr;tyrone-cluster;Scheduler was sent the command new
07/14/2015 14:39:01;0040;PBS_Server;Svr;tyrone-cluster;Scheduler was sent the command new
07/14/2015 14:39:32;0040;PBS_Server;Svr;tyrone-cluster;Scheduler was sent the command new
07/14/2015 14:40:12;0040;PBS_Server;Svr;tyrone-cluster;Scheduler was sent the command new
07/14/2015 14:40:31;0040;PBS_Server;Svr;tyrone-cluster;Scheduler was sent the command new
07/14/2015 14:41:01;0040;PBS_Server;Svr;tyrone-cluster;Scheduler was sent the command new
07/14/2015 14:41:36;0002;PBS_Server;Svr;PBS_Server;Torque Server Version = 3.0.5, loglevel = 0
07/14/2015 14:41:36;0040;PBS_Server;Svr;tyrone-cluster;Scheduler was sent the command new
07/14/2015 14:42:01;0040;PBS_Server;Svr;tyrone-cluster;Scheduler was sent the command new
07/14/2015 14:42:32;0040;PBS_Server;Svr;tyrone-cluster;Scheduler was sent the command new
07/14/2015 14:43:12;0040;PBS_Server;Svr;tyrone-cluster;Scheduler was sent the command new
07/14/2015 14:43:31;0040;PBS_Server;Svr;tyrone-cluster;Scheduler was sent the command new
07/14/2015 14:44:02;0040;PBS_Server;Svr;tyrone-cluster;Scheduler was sent the command new
07/14/2015 14:44:43;0040;PBS_Server;Svr;tyrone-cluster;Scheduler was sent the command new
07/14/2015 14:45:16;0040;PBS_Server;Svr;tyrone-cluster;Scheduler was sent the command new
07/14/2015 14:45:46;0040;PBS_Server;Svr;tyrone-cluster;Scheduler was sent the command new
07/14/2015 14:46:17;0040;PBS_Server;Svr;tyrone-cluster;Scheduler was sent the command new
07/14/2015 14:46:36;0002;PBS_Server;Svr;PBS_Server;Torque Server Version = 3.0.5, loglevel = 0
07/14/2015 14:46:57;0040;PBS_Server;Svr;tyrone-cluster;Scheduler was sent the command new
07/14/2015 14:47:16;0040;PBS_Server;Svr;tyrone-cluster;Scheduler was sent the command new
07/14/2015 14:47:47;0040;PBS_Server;Svr;tyrone-cluster;Scheduler was sent the command new
07/14/2015 14:48:27;0040;PBS_Server;Svr;tyrone-cluster;Scheduler was sent the command new
07/14/2015 14:48:46;0040;PBS_Server;Svr;tyrone-cluster;Scheduler was sent the command new
07/14/2015 14:49:17;0040;PBS_Server;Svr;tyrone-cluster;Scheduler was sent the command new
07/14/2015 14:49:57;0040;PBS_Server;Svr;tyrone-cluster;Scheduler was sent the command new
07/14/2015 14:50:16;0040;PBS_Server;Svr;tyrone-cluster;Scheduler was sent the command new
07/14/2015 14:50:47;0040;PBS_Server;Svr;tyrone-cluster;Scheduler was sent the command new
07/14/2015 14:51:27;0040;PBS_Server;Svr;tyrone-cluster;Scheduler was sent the command new
07/14/2015 14:51:36;0002;PBS_Server;Svr;PBS_Server;Torque Server Version = 3.0.5, loglevel = 0
07/14/2015 14:51:46;0040;PBS_Server;Svr;tyrone-cluster;Scheduler was sent the command new
07/14/2015 14:52:17;0040;PBS_Server;Svr;tyrone-cluster;Scheduler was sent the command new
07/14/2015 14:52:57;0040;PBS_Server;Svr;tyrone-cluster;Scheduler was sent the command new
07/14/2015 14:53:17;0040;PBS_Server;Svr;tyrone-cluster;Scheduler was sent the command new
07/14/2015 14:53:47;0040;PBS_Server;Svr;tyrone-cluster;Scheduler was sent the command new
07/14/2015 14:54:28;0040;PBS_Server;Svr;tyrone-cluster;Scheduler was sent the command new
07/14/2015 14:55:01;0040;PBS_Server;Svr;tyrone-cluster;Scheduler was sent the command new
07/14/2015 14:55:31;0040;PBS_Server;Svr;tyrone-cluster;Scheduler was sent the command new
07/14/2015 14:56:02;0040;PBS_Server;Svr;tyrone-cluster;Scheduler was sent the command new
07/14/2015 14:56:36;0002;PBS_Server;Svr;PBS_Server;Torque Server Version = 3.0.5, loglevel = 0
07/14/2015 14:56:42;0040;PBS_Server;Svr;tyrone-cluster;Scheduler was sent the command new
07/14/2015 14:57:06;0040;PBS_Server;Svr;tyrone-cluster;Scheduler was sent the command new
07/14/2015 14:57:39;0040;PBS_Server;Svr;tyrone-cluster;Scheduler was sent the command new
07/14/2015 14:58:14;0040;PBS_Server;Svr;tyrone-cluster;Scheduler was sent the command new
07/14/2015 14:58:46;0040;PBS_Server;Svr;tyrone-cluster;Scheduler was sent the command new
07/14/2015 14:59:16;0040;PBS_Server;Svr;tyrone-cluster;Scheduler was sent the command new
07/14/2015 14:59:47;0040;PBS_Server;Svr;tyrone-cluster;Scheduler was sent the command new
07/14/2015 15:00:28;0040;PBS_Server;Svr;tyrone-cluster;Scheduler was sent the command new
07/14/2015 15:01:01;0040;PBS_Server;Svr;tyrone-cluster;Scheduler was sent the command new
07/14/2015 15:01:29;0040;PBS_Server;Svr;tyrone-cluster;Scheduler was sent the command new
07/14/2015 15:01:36;0002;PBS_Server;Svr;PBS_Server;Torque Server Version = 3.0.5, loglevel = 0
07/14/2015 15:02:00;0040;PBS_Server;Svr;tyrone-cluster;Scheduler was sent the command new
07/14/2015 15:02:43;0040;PBS_Server;Svr;tyrone-cluster;Scheduler was sent the command new
07/14/2015 15:03:01;0040;PBS_Server;Svr;tyrone-cluster;Scheduler was sent the command new
07/14/2015 15:03:33;0040;PBS_Server;Svr;tyrone-cluster;Scheduler was sent the command new
07/14/2015 15:04:14;0040;PBS_Server;Svr;tyrone-cluster;Scheduler was sent the command new
07/14/2015 15:04:58;0040;PBS_Server;Svr;tyrone-cluster;Scheduler was sent the command new
07/14/2015 15:05:16;0040;PBS_Server;Svr;tyrone-cluster;Scheduler was sent the command new
07/14/2015 15:05:47;0040;PBS_Server;Svr;tyrone-cluster;Scheduler was sent the command new
07/14/2015 15:06:28;0040;PBS_Server;Svr;tyrone-cluster;Scheduler was sent the command new
07/14/2015 15:06:36;0002;PBS_Server;Svr;PBS_Server;Torque Server Version = 3.0.5, loglevel = 0
07/14/2015 15:07:00;0040;PBS_Server;Svr;tyrone-cluster;Scheduler was sent the command new
07/14/2015 15:07:31;0040;PBS_Server;Svr;tyrone-cluster;Scheduler was sent the command new
07/14/2015 15:08:02;0040;PBS_Server;Svr;tyrone-cluster;Scheduler was sent the command new
07/14/2015 15:08:43;0040;PBS_Server;Svr;tyrone-cluster;Scheduler was sent the command new
07/14/2015 15:09:16;0040;PBS_Server;Svr;tyrone-cluster;Scheduler was sent the command new
07/14/2015 15:09:46;0040;PBS_Server;Svr;tyrone-cluster;Scheduler was sent the command new
07/14/2015 15:10:17;0040;PBS_Server;Svr;tyrone-cluster;Scheduler was sent the command new
07/14/2015 15:10:58;0040;PBS_Server;Svr;tyrone-cluster;Scheduler was sent the command new
07/14/2015 15:11:17;0040;PBS_Server;Svr;tyrone-cluster;Scheduler was sent the command new
07/14/2015 15:11:36;0002;PBS_Server;Svr;PBS_Server;Torque Server Version = 3.0.5, loglevel = 0
07/14/2015 15:11:47;0040;PBS_Server;Svr;tyrone-cluster;Scheduler was sent the command new
07/14/2015 15:12:28;0040;PBS_Server;Svr;tyrone-cluster;Scheduler was sent the command new
07/14/2015 15:12:46;0040;PBS_Server;Svr;tyrone-cluster;Scheduler was sent the command new
07/14/2015 15:13:17;0040;PBS_Server;Svr;tyrone-cluster;Scheduler was sent the command new
07/14/2015 15:13:58;0040;PBS_Server;Svr;tyrone-cluster;Scheduler was sent the command new
07/14/2015 15:14:30;0040;PBS_Server;Svr;tyrone-cluster;Scheduler was sent the command new
07/14/2015 15:15:01;0040;PBS_Server;Svr;tyrone-cluster;Scheduler was sent the command new
07/14/2015 15:15:32;0040;PBS_Server;Svr;tyrone-cluster;Scheduler was sent the command new
07/14/2015 15:16:13;0040;PBS_Server;Svr;tyrone-cluster;Scheduler was sent the command new
07/14/2015 15:16:31;0040;PBS_Server;Svr;tyrone-cluster;Scheduler was sent the command new
07/14/2015 15:16:36;0002;PBS_Server;Svr;PBS_Server;Torque Server Version = 3.0.5, loglevel = 0
07/14/2015 15:17:03;0040;PBS_Server;Svr;tyrone-cluster;Scheduler was sent the command new
07/14/2015 15:17:43;0040;PBS_Server;Svr;tyrone-cluster;Scheduler was sent the command new
07/14/2015 15:18:01;0040;PBS_Server;Svr;tyrone-cluster;Scheduler was sent the command new
07/14/2015 15:18:32;0040;PBS_Server;Svr;tyrone-cluster;Scheduler was sent the command new
07/14/2015 15:19:13;0040;PBS_Server;Svr;tyrone-cluster;Scheduler was sent the command new
07/14/2015 15:19:46;0040;PBS_Server;Svr;tyrone-cluster;Scheduler was sent the command new
07/14/2015 15:20:16;0040;PBS_Server;Svr;tyrone-cluster;Scheduler was sent the command new
07/14/2015 15:20:47;0040;PBS_Server;Svr;tyrone-cluster;Scheduler was sent the command new
07/14/2015 15:21:28;0040;PBS_Server;Svr;tyrone-cluster;Scheduler was sent the command new
07/14/2015 15:21:36;0002;PBS_Server;Svr;PBS_Server;Torque Server Version = 3.0.5, loglevel = 0
07/14/2015 15:21:46;0040;PBS_Server;Svr;tyrone-cluster;Scheduler was sent the command new
07/14/2015 15:22:17;0040;PBS_Server;Svr;tyrone-cluster;Scheduler was sent the command new
07/14/2015 15:22:58;0040;PBS_Server;Svr;tyrone-cluster;Scheduler was sent the command new
07/14/2015 15:23:16;0040;PBS_Server;Svr;tyrone-cluster;Scheduler was sent the command new
07/14/2015 15:23:47;0040;PBS_Server;Svr;tyrone-cluster;Scheduler was sent the command new
07/14/2015 15:24:28;0040;PBS_Server;Svr;tyrone-cluster;Scheduler was sent the command new
07/14/2015 15:24:47;0040;PBS_Server;Svr;tyrone-cluster;Scheduler was sent the command new
07/14/2015 15:25:18;0040;PBS_Server;Svr;tyrone-cluster;Scheduler was sent the command new
07/14/2015 15:25:59;0040;PBS_Server;Svr;tyrone-cluster;Scheduler was sent the command new
07/14/2015 15:26:31;0040;PBS_Server;Svr;tyrone-cluster;Scheduler was sent the command new
07/14/2015 15:26:36;0002;PBS_Server;Svr;PBS_Server;Torque Server Version = 3.0.5, loglevel = 0
07/14/2015 15:27:01;0040;PBS_Server;Svr;tyrone-cluster;Scheduler was sent the command new
07/14/2015 15:27:32;0040;PBS_Server;Svr;tyrone-cluster;Scheduler was sent the command new
07/14/2015 15:28:13;0040;PBS_Server;Svr;tyrone-cluster;Scheduler was sent the command new
07/14/2015 15:28:31;0040;PBS_Server;Svr;tyrone-cluster;Scheduler was sent the command new
07/14/2015 15:29:02;0040;PBS_Server;Svr;tyrone-cluster;Scheduler was sent the command new
07/14/2015 15:29:43;0040;PBS_Server;Svr;tyrone-cluster;Scheduler was sent the command new
07/14/2015 15:30:01;0040;PBS_Server;Svr;tyrone-cluster;Scheduler was sent the command new
07/14/2015 15:30:32;0040;PBS_Server;Svr;tyrone-cluster;Scheduler was sent the command new
07/14/2015 15:31:13;0040;PBS_Server;Svr;tyrone-cluster;Scheduler was sent the command new
07/14/2015 15:31:31;0040;PBS_Server;Svr;tyrone-cluster;Scheduler was sent the command new
07/14/2015 15:31:36;0002;PBS_Server;Svr;PBS_Server;Torque Server Version = 3.0.5, loglevel = 0
07/14/2015 15:32:03;0040;PBS_Server;Svr;tyrone-cluster;Scheduler was sent the command new
07/14/2015 15:32:43;0040;PBS_Server;Svr;tyrone-cluster;Scheduler was sent the command new
07/14/2015 15:33:01;0040;PBS_Server;Svr;tyrone-cluster;Scheduler was sent the command new
07/14/2015 15:33:32;0040;PBS_Server;Svr;tyrone-cluster;Scheduler was sent the command new
07/14/2015 15:34:13;0040;PBS_Server;Svr;tyrone-cluster;Scheduler was sent the command new
07/14/2015 15:34:31;0040;PBS_Server;Svr;tyrone-cluster;Scheduler was sent the command new
07/14/2015 15:35:03;0040;PBS_Server;Svr;tyrone-cluster;Scheduler was sent the command new
07/14/2015 15:35:43;0040;PBS_Server;Svr;tyrone-cluster;Scheduler was sent the command new
07/14/2015 15:36:01;0040;PBS_Server;Svr;tyrone-cluster;Scheduler was sent the command new
07/14/2015 15:36:32;0040;PBS_Server;Svr;tyrone-cluster;Scheduler was sent the command new
07/14/2015 15:36:36;0002;PBS_Server;Svr;PBS_Server;Torque Server Version = 3.0.5, loglevel = 0
07/14/2015 15:37:13;0040;PBS_Server;Svr;tyrone-cluster;Scheduler was sent the command new
07/14/2015 15:37:46;0040;PBS_Server;Svr;tyrone-cluster;Scheduler was sent the command new
07/14/2015 15:38:16;0040;PBS_Server;Svr;tyrone-cluster;Scheduler was sent the command new
07/14/2015 15:38:47;0040;PBS_Server;Svr;tyrone-cluster;Scheduler was sent the command new
07/14/2015 15:39:28;0040;PBS_Server;Svr;tyrone-cluster;Scheduler was sent the command new
07/14/2015 15:39:46;0040;PBS_Server;Svr;tyrone-cluster;Scheduler was sent the command new
07/14/2015 15:40:17;0040;PBS_Server;Svr;tyrone-cluster;Scheduler was sent the command new
07/14/2015 15:40:59;0040;PBS_Server;Svr;tyrone-cluster;Scheduler was sent the command new
07/14/2015 15:41:36;0002;PBS_Server;Svr;PBS_Server;Torque Server Version = 3.0.5, loglevel = 0
07/14/2015 15:41:36;0040;PBS_Server;Svr;tyrone-cluster;Scheduler was sent the command new
07/14/2015 15:42:01;0040;PBS_Server;Svr;tyrone-cluster;Scheduler was sent the command new
07/14/2015 15:42:32;0040;PBS_Server;Svr;tyrone-cluster;Scheduler was sent the command new
07/14/2015 15:43:13;0040;PBS_Server;Svr;tyrone-cluster;Scheduler was sent the command new
07/14/2015 15:43:31;0040;PBS_Server;Svr;tyrone-cluster;Scheduler was sent the command new
07/14/2015 15:44:03;0040;PBS_Server;Svr;tyrone-cluster;Scheduler was sent the command new
07/14/2015 15:44:44;0040;PBS_Server;Svr;tyrone-cluster;Scheduler was sent the command new
07/14/2015 15:45:01;0040;PBS_Server;Svr;tyrone-cluster;Scheduler was sent the command new
07/14/2015 15:45:32;0040;PBS_Server;Svr;tyrone-cluster;Scheduler was sent the command new
07/14/2015 15:46:13;0040;PBS_Server;Svr;tyrone-cluster;Scheduler was sent the command new
07/14/2015 15:46:32;0040;PBS_Server;Svr;tyrone-cluster;Scheduler was sent the command new
07/14/2015 15:46:36;0002;PBS_Server;Svr;PBS_Server;Torque Server Version = 3.0.5, loglevel = 0
07/14/2015 15:47:03;0040;PBS_Server;Svr;tyrone-cluster;Scheduler was sent the command new
07/14/2015 15:47:43;0040;PBS_Server;Svr;tyrone-cluster;Scheduler was sent the command new
07/14/2015 15:48:01;0040;PBS_Server;Svr;tyrone-cluster;Scheduler was sent the command new
07/14/2015 15:48:32;0040;PBS_Server;Svr;tyrone-cluster;Scheduler was sent the command new
07/14/2015 15:49:15;0040;PBS_Server;Svr;tyrone-cluster;Scheduler was sent the command new
07/14/2015 15:49:59;0040;PBS_Server;Svr;tyrone-cluster;Scheduler was sent the command new
07/14/2015 15:50:16;0040;PBS_Server;Svr;tyrone-cluster;Scheduler was sent the command new
07/14/2015 15:50:47;0040;PBS_Server;Svr;tyrone-cluster;Scheduler was sent the command new
07/14/2015 15:51:28;0040;PBS_Server;Svr;tyrone-cluster;Scheduler was sent the command new
07/14/2015 15:51:36;0002;PBS_Server;Svr;PBS_Server;Torque Server Version = 3.0.5, loglevel = 0
07/14/2015 15:51:46;0040;PBS_Server;Svr;tyrone-cluster;Scheduler was sent the command new
07/14/2015 15:52:17;0040;PBS_Server;Svr;tyrone-cluster;Scheduler was sent the command new
07/14/2015 15:52:58;0040;PBS_Server;Svr;tyrone-cluster;Scheduler was sent the command new
07/14/2015 15:53:16;0040;PBS_Server;Svr;tyrone-cluster;Scheduler was sent the command new
07/14/2015 15:53:48;0040;PBS_Server;Svr;tyrone-cluster;Scheduler was sent the command new
07/14/2015 15:54:28;0040;PBS_Server;Svr;tyrone-cluster;Scheduler was sent the command new
07/14/2015 15:54:46;0040;PBS_Server;Svr;tyrone-cluster;Scheduler was sent the command new
07/14/2015 15:55:17;0040;PBS_Server;Svr;tyrone-cluster;Scheduler was sent the command new
07/14/2015 15:55:59;0040;PBS_Server;Svr;tyrone-cluster;Scheduler was sent the command new
07/14/2015 15:56:16;0040;PBS_Server;Svr;tyrone-cluster;Scheduler was sent the command new
07/14/2015 15:56:36;0002;PBS_Server;Svr;PBS_Server;Torque Server Version = 3.0.5, loglevel = 0
07/14/2015 15:56:47;0040;PBS_Server;Svr;tyrone-cluster;Scheduler was sent the command new
07/14/2015 15:57:28;0040;PBS_Server;Svr;tyrone-cluster;Scheduler was sent the command new
07/14/2015 15:57:46;0040;PBS_Server;Svr;tyrone-cluster;Scheduler was sent the command new
07/14/2015 15:58:18;0040;PBS_Server;Svr;tyrone-cluster;Scheduler was sent the command new
07/14/2015 15:58:58;0040;PBS_Server;Svr;tyrone-cluster;Scheduler was sent the command new
07/14/2015 15:59:16;0040;PBS_Server;Svr;tyrone-cluster;Scheduler was sent the command new
07/14/2015 15:59:48;0040;PBS_Server;Svr;tyrone-cluster;Scheduler was sent the command new
07/14/2015 16:00:28;0040;PBS_Server;Svr;tyrone-cluster;Scheduler was sent the command new
07/14/2015 16:00:46;0040;PBS_Server;Svr;tyrone-cluster;Scheduler was sent the command new
07/14/2015 16:01:17;0040;PBS_Server;Svr;tyrone-cluster;Scheduler was sent the command new
07/14/2015 16:01:36;0002;PBS_Server;Svr;PBS_Server;Torque Server Version = 3.0.5, loglevel = 0
07/14/2015 16:01:58;0040;PBS_Server;Svr;tyrone-cluster;Scheduler was sent the command new
07/14/2015 16:02:17;0040;PBS_Server;Svr;tyrone-cluster;Scheduler was sent the command new
07/14/2015 16:02:48;0040;PBS_Server;Svr;tyrone-cluster;Scheduler was sent the command new
07/14/2015 16:03:28;0040;PBS_Server;Svr;tyrone-cluster;Scheduler was sent the command new
07/14/2015 16:03:46;0040;PBS_Server;Svr;tyrone-cluster;Scheduler was sent the command new
07/14/2015 16:04:19;0040;PBS_Server;Svr;tyrone-cluster;Scheduler was sent the command new
07/14/2015 16:04:59;0040;PBS_Server;Svr;tyrone-cluster;Scheduler was sent the command new
07/14/2015 16:05:28;0040;PBS_Server;Svr;tyrone-cluster;Scheduler was sent the command new
07/14/2015 16:06:01;0040;PBS_Server;Svr;tyrone-cluster;Scheduler was sent the command new
07/14/2015 16:06:32;0040;PBS_Server;Svr;tyrone-cluster;Scheduler was sent the command new
07/14/2015 16:06:36;0002;PBS_Server;Svr;PBS_Server;Torque Server Version = 3.0.5, loglevel = 0
07/14/2015 16:07:13;0040;PBS_Server;Svr;tyrone-cluster;Scheduler was sent the command new
07/14/2015 16:07:31;0040;PBS_Server;Svr;tyrone-cluster;Scheduler was sent the command new
07/14/2015 16:08:03;0040;PBS_Server;Svr;tyrone-cluster;Scheduler was sent the command new
07/14/2015 16:08:44;0040;PBS_Server;Svr;tyrone-cluster;Scheduler was sent the command new
07/14/2015 16:09:01;0040;PBS_Server;Svr;tyrone-cluster;Scheduler was sent the command new
07/14/2015 16:09:33;0040;PBS_Server;Svr;tyrone-cluster;Scheduler was sent the command new
07/14/2015 16:10:13;0040;PBS_Server;Svr;tyrone-cluster;Scheduler was sent the command new
07/14/2015 16:10:31;0040;PBS_Server;Svr;tyrone-cluster;Scheduler was sent the command new
07/14/2015 16:11:03;0040;PBS_Server;Svr;tyrone-cluster;Scheduler was sent the command new
07/14/2015 16:11:36;0002;PBS_Server;Svr;PBS_Server;Torque Server Version = 3.0.5, loglevel = 0
07/14/2015 16:11:36;0040;PBS_Server;Svr;tyrone-cluster;Scheduler was sent the command new
07/14/2015 16:12:02;0040;PBS_Server;Svr;tyrone-cluster;Scheduler was sent the command new
07/14/2015 16:12:33;0040;PBS_Server;Svr;tyrone-cluster;Scheduler was sent the command new
07/14/2015 16:13:13;0040;PBS_Server;Svr;tyrone-cluster;Scheduler was sent the command new
07/14/2015 16:13:31;0040;PBS_Server;Svr;tyrone-cluster;Scheduler was sent the command new
07/14/2015 16:14:03;0040;PBS_Server;Svr;tyrone-cluster;Scheduler was sent the command new
07/14/2015 16:14:44;0040;PBS_Server;Svr;tyrone-cluster;Scheduler was sent the command new
07/14/2015 16:15:02;0040;PBS_Server;Svr;tyrone-cluster;Scheduler was sent the command new
07/14/2015 16:15:34;0040;PBS_Server;Svr;tyrone-cluster;Scheduler was sent the command new
07/14/2015 16:16:14;0040;PBS_Server;Svr;tyrone-cluster;Scheduler was sent the command new
07/14/2015 16:16:36;0002;PBS_Server;Svr;PBS_Server;Torque Server Version = 3.0.5, loglevel = 0
07/14/2015 16:16:43;0040;PBS_Server;Svr;tyrone-cluster;Scheduler was sent the command new
07/14/2015 16:17:17;0040;PBS_Server;Svr;tyrone-cluster;Scheduler was sent the command new
07/14/2015 16:17:48;0040;PBS_Server;Svr;tyrone-cluster;Scheduler was sent the command new
07/14/2015 16:18:28;0040;PBS_Server;Svr;tyrone-cluster;Scheduler was sent the command new
07/14/2015 16:18:46;0040;PBS_Server;Svr;tyrone-cluster;Scheduler was sent the command new
07/14/2015 16:19:19;0040;PBS_Server;Svr;tyrone-cluster;Scheduler was sent the command new
07/14/2015 16:19:58;0040;PBS_Server;Svr;tyrone-cluster;Scheduler was sent the command new
07/14/2015 16:20:28;0040;PBS_Server;Svr;tyrone-cluster;Scheduler was sent the command new
07/14/2015 16:21:02;0040;PBS_Server;Svr;tyrone-cluster;Scheduler was sent the command new
07/14/2015 16:21:33;0040;PBS_Server;Svr;tyrone-cluster;Scheduler was sent the command new
07/14/2015 16:21:36;0002;PBS_Server;Svr;PBS_Server;Torque Server Version = 3.0.5, loglevel = 0
07/14/2015 16:22:13;0040;PBS_Server;Svr;tyrone-cluster;Scheduler was sent the command new
07/14/2015 16:22:31;0040;PBS_Server;Svr;tyrone-cluster;Scheduler was sent the command new
07/14/2015 16:23:04;0040;PBS_Server;Svr;tyrone-cluster;Scheduler was sent the command new
07/14/2015 16:23:44;0040;PBS_Server;Svr;tyrone-cluster;Scheduler was sent the command new
07/14/2015 16:24:13;0040;PBS_Server;Svr;tyrone-cluster;Scheduler was sent the command new
07/14/2015 16:24:46;0040;PBS_Server;Svr;tyrone-cluster;Scheduler was sent the command new
07/14/2015 16:25:18;0040;PBS_Server;Svr;tyrone-cluster;Scheduler was sent the command new
07/14/2015 16:25:58;0040;PBS_Server;Svr;tyrone-cluster;Scheduler was sent the command new
07/14/2015 16:26:16;0040;PBS_Server;Svr;tyrone-cluster;Scheduler was sent the command new
07/14/2015 16:26:36;0002;PBS_Server;Svr;PBS_Server;Torque Server Version = 3.0.5, loglevel = 0
07/14/2015 16:26:49;0040;PBS_Server;Svr;tyrone-cluster;Scheduler was sent the command new
07/14/2015 16:27:29;0040;PBS_Server;Svr;tyrone-cluster;Scheduler was sent the command new
07/14/2015 16:27:47;0040;PBS_Server;Svr;tyrone-cluster;Scheduler was sent the command new
07/14/2015 16:28:19;0040;PBS_Server;Svr;tyrone-cluster;Scheduler was sent the command new
07/14/2015 16:28:59;0040;PBS_Server;Svr;tyrone-cluster;Scheduler was sent the command new
07/14/2015 16:29:28;0040;PBS_Server;Svr;tyrone-cluster;Scheduler was sent the command new
07/14/2015 16:30:01;0040;PBS_Server;Svr;tyrone-cluster;Scheduler was sent the command new
07/14/2015 16:30:33;0040;PBS_Server;Svr;tyrone-cluster;Scheduler was sent the command new
07/14/2015 16:31:13;0040;PBS_Server;Svr;tyrone-cluster;Scheduler was sent the command new
07/14/2015 16:31:31;0040;PBS_Server;Svr;tyrone-cluster;Scheduler was sent the command new
07/14/2015 16:31:36;0002;PBS_Server;Svr;PBS_Server;Torque Server Version = 3.0.5, loglevel = 0
07/14/2015 16:32:03;0040;PBS_Server;Svr;tyrone-cluster;Scheduler was sent the command new
07/14/2015 16:32:43;0040;PBS_Server;Svr;tyrone-cluster;Scheduler was sent the command new
07/14/2015 16:33:02;0040;PBS_Server;Svr;tyrone-cluster;Scheduler was sent the command new
07/14/2015 16:33:34;0040;PBS_Server;Svr;tyrone-cluster;Scheduler was sent the command new
07/14/2015 16:34:14;0040;PBS_Server;Svr;tyrone-cluster;Scheduler was sent the command new
07/14/2015 16:34:43;0040;PBS_Server;Svr;tyrone-cluster;Scheduler was sent the command new
07/14/2015 16:35:16;0040;PBS_Server;Svr;tyrone-cluster;Scheduler was sent the command new
07/14/2015 16:35:48;0040;PBS_Server;Svr;tyrone-cluster;Scheduler was sent the command new
07/14/2015 16:36:28;0040;PBS_Server;Svr;tyrone-cluster;Scheduler was sent the command new
07/14/2015 16:36:36;0002;PBS_Server;Svr;PBS_Server;Torque Server Version = 3.0.5, loglevel = 0
07/14/2015 16:36:46;0040;PBS_Server;Svr;tyrone-cluster;Scheduler was sent the command new
07/14/2015 16:37:18;0040;PBS_Server;Svr;tyrone-cluster;Scheduler was sent the command new
07/14/2015 16:37:58;0040;PBS_Server;Svr;tyrone-cluster;Scheduler was sent the command new
07/14/2015 16:38:17;0040;PBS_Server;Svr;tyrone-cluster;Scheduler was sent the command new
07/14/2015 16:38:48;0040;PBS_Server;Svr;tyrone-cluster;Scheduler was sent the command new
07/14/2015 16:39:28;0040;PBS_Server;Svr;tyrone-cluster;Scheduler was sent the command new
07/14/2015 16:39:46;0040;PBS_Server;Svr;tyrone-cluster;Scheduler was sent the command new
07/14/2015 16:40:18;0040;PBS_Server;Svr;tyrone-cluster;Scheduler was sent the command new
07/14/2015 16:40:58;0040;PBS_Server;Svr;tyrone-cluster;Scheduler was sent the command new
07/14/2015 16:41:16;0040;PBS_Server;Svr;tyrone-cluster;Scheduler was sent the command new
07/14/2015 16:41:36;0002;PBS_Server;Svr;PBS_Server;Torque Server Version = 3.0.5, loglevel = 0
07/14/2015 16:41:49;0040;PBS_Server;Svr;tyrone-cluster;Scheduler was sent the command new
07/14/2015 16:42:28;0040;PBS_Server;Svr;tyrone-cluster;Scheduler was sent the command new
07/14/2015 16:42:58;0040;PBS_Server;Svr;tyrone-cluster;Scheduler was sent the command new
07/14/2015 16:43:32;0040;PBS_Server;Svr;tyrone-cluster;Scheduler was sent the command new
07/14/2015 16:44:03;0040;PBS_Server;Svr;tyrone-cluster;Scheduler was sent the command new
07/14/2015 16:44:43;0040;PBS_Server;Svr;tyrone-cluster;Scheduler was sent the command new
07/14/2015 16:45:01;0040;PBS_Server;Svr;tyrone-cluster;Scheduler was sent the command new
07/14/2015 16:45:33;0040;PBS_Server;Svr;tyrone-cluster;Scheduler was sent the command new
07/14/2015 16:46:13;0040;PBS_Server;Svr;tyrone-cluster;Scheduler was sent the command new
07/14/2015 16:46:32;0040;PBS_Server;Svr;tyrone-cluster;Scheduler was sent the command new
07/14/2015 16:46:36;0002;PBS_Server;Svr;PBS_Server;Torque Server Version = 3.0.5, loglevel = 0
07/14/2015 16:47:04;0040;PBS_Server;Svr;tyrone-cluster;Scheduler was sent the command new
07/14/2015 16:47:43;0040;PBS_Server;Svr;tyrone-cluster;Scheduler was sent the command new
07/14/2015 16:48:13;0040;PBS_Server;Svr;tyrone-cluster;Scheduler was sent the command new
07/14/2015 16:48:46;0040;PBS_Server;Svr;tyrone-cluster;Scheduler was sent the command new
07/14/2015 16:49:18;0040;PBS_Server;Svr;tyrone-cluster;Scheduler was sent the command new
07/14/2015 16:49:58;0040;PBS_Server;Svr;tyrone-cluster;Scheduler was sent the command new
07/14/2015 16:50:17;0040;PBS_Server;Svr;tyrone-cluster;Scheduler was sent the command new
07/14/2015 16:50:48;0040;PBS_Server;Svr;tyrone-cluster;Scheduler was sent the command new
07/14/2015 16:51:28;0040;PBS_Server;Svr;tyrone-cluster;Scheduler was sent the command new
07/14/2015 16:51:36;0002;PBS_Server;Svr;PBS_Server;Torque Server Version = 3.0.5, loglevel = 0
07/14/2015 16:51:47;0040;PBS_Server;Svr;tyrone-cluster;Scheduler was sent the command new
07/14/2015 16:52:18;0040;PBS_Server;Svr;tyrone-cluster;Scheduler was sent the command new
07/14/2015 16:52:58;0040;PBS_Server;Svr;tyrone-cluster;Scheduler was sent the command new
07/14/2015 16:53:17;0040;PBS_Server;Svr;tyrone-cluster;Scheduler was sent the command new
07/14/2015 16:53:48;0040;PBS_Server;Svr;tyrone-cluster;Scheduler was sent the command new
07/14/2015 16:54:28;0040;PBS_Server;Svr;tyrone-cluster;Scheduler was sent the command new
07/14/2015 16:54:47;0040;PBS_Server;Svr;tyrone-cluster;Scheduler was sent the command new
07/14/2015 16:55:18;0040;PBS_Server;Svr;tyrone-cluster;Scheduler was sent the command new
07/14/2015 16:55:58;0040;PBS_Server;Svr;tyrone-cluster;Scheduler was sent the command new
07/14/2015 16:56:17;0040;PBS_Server;Svr;tyrone-cluster;Scheduler was sent the command new
07/14/2015 16:56:36;0002;PBS_Server;Svr;PBS_Server;Torque Server Version = 3.0.5, loglevel = 0
07/14/2015 16:56:48;0040;PBS_Server;Svr;tyrone-cluster;Scheduler was sent the command new
07/14/2015 16:57:28;0040;PBS_Server;Svr;tyrone-cluster;Scheduler was sent the command new
07/14/2015 16:57:47;0040;PBS_Server;Svr;tyrone-cluster;Scheduler was sent the command new
07/14/2015 16:58:19;0040;PBS_Server;Svr;tyrone-cluster;Scheduler was sent the command new
07/14/2015 16:58:58;0040;PBS_Server;Svr;tyrone-cluster;Scheduler was sent the command new
07/14/2015 16:59:28;0040;PBS_Server;Svr;tyrone-cluster;Scheduler was sent the command new
07/14/2015 17:00:01;0040;PBS_Server;Svr;tyrone-cluster;Scheduler was sent the command new
07/14/2015 17:00:33;0040;PBS_Server;Svr;tyrone-cluster;Scheduler was sent the command new
07/14/2015 17:01:13;0040;PBS_Server;Svr;tyrone-cluster;Scheduler was sent the command new
07/14/2015 17:01:32;0040;PBS_Server;Svr;tyrone-cluster;Scheduler was sent the command new
07/14/2015 17:01:36;0002;PBS_Server;Svr;PBS_Server;Torque Server Version = 3.0.5, loglevel = 0
07/14/2015 17:01:43;0100;PBS_Server;Job;54645.tyrone-cluster;enqueuing into batch, state 1 hop 1
07/14/2015 17:01:43;0008;PBS_Server;Job;54645.tyrone-cluster;Job Queued at request of physkgly@tyrone-cluster, owner = physkgly@tyrone-cluster, job name = ab_test, queue = batch
07/14/2015 17:01:43;0040;PBS_Server;Svr;tyrone-cluster;Scheduler was sent the command new
07/14/2015 17:01:43;0008;PBS_Server;Job;54645.tyrone-cluster;Job Modified at request of Scheduler@tyrone-cluster
07/14/2015 17:02:04;0040;PBS_Server;Svr;tyrone-cluster;Scheduler was sent the command new
07/14/2015 17:02:13;0008;PBS_Server;Job;54645.tyrone-cluster;Job deleted at request of physkgly@tyrone-cluster
07/14/2015 17:02:13;0008;PBS_Server;Job;NULL;on_job_exit valid pjob: 0x1d6c780 (substate=59)
07/14/2015 17:02:13;0100;PBS_Server;Job;54645.tyrone-cluster;dequeuing from batch, state COMPLETE
07/14/2015 17:02:13;0040;PBS_Server;Svr;tyrone-cluster;Scheduler was sent the command term
07/14/2015 17:02:22;0100;PBS_Server;Job;54646.tyrone-cluster;enqueuing into batch, state 1 hop 1
07/14/2015 17:02:22;0100;PBS_Server;Job;54646.tyrone-cluster;dequeuing from batch, state QUEUED
07/14/2015 17:02:22;0100;PBS_Server;Job;54646.tyrone-cluster;enqueuing into qp128, state 1 hop 1
07/14/2015 17:02:22;0008;PBS_Server;Job;54646.tyrone-cluster;Job Queued at request of physkgly@tyrone-cluster, owner = physkgly@tyrone-cluster, job name = ab_test, queue = qp128
07/14/2015 17:02:22;0040;PBS_Server;Svr;tyrone-cluster;Scheduler was sent the command new
07/14/2015 17:02:23;0008;PBS_Server;Job;54646.tyrone-cluster;Job Modified at request of Scheduler@tyrone-cluster
07/14/2015 17:02:31;0100;PBS_Server;Job;54647.tyrone-cluster;enqueuing into batch, state 1 hop 1
07/14/2015 17:02:31;0100;PBS_Server;Job;54647.tyrone-cluster;dequeuing from batch, state QUEUED
07/14/2015 17:02:31;0100;PBS_Server;Job;54647.tyrone-cluster;enqueuing into qp128, state 1 hop 1
07/14/2015 17:02:31;0008;PBS_Server;Job;54647.tyrone-cluster;Job Queued at request of physkgly@tyrone-cluster, owner = physkgly@tyrone-cluster, job name = ab_test, queue = qp128
07/14/2015 17:02:31;0040;PBS_Server;Svr;tyrone-cluster;Scheduler was sent the command new
07/14/2015 17:02:31;0008;PBS_Server;Job;54647.tyrone-cluster;Job Modified at request of Scheduler@tyrone-cluster
07/14/2015 17:02:33;0040;PBS_Server;Svr;tyrone-cluster;Scheduler was sent the command new
07/14/2015 17:02:41;0008;PBS_Server;Job;54646.tyrone-cluster;Job deleted at request of physkgly@tyrone-cluster
07/14/2015 17:02:41;0008;PBS_Server;Job;NULL;on_job_exit valid pjob: 0x1d6c780 (substate=59)
07/14/2015 17:02:41;0100;PBS_Server;Job;54646.tyrone-cluster;dequeuing from qp128, state COMPLETE
07/14/2015 17:02:41;0040;PBS_Server;Svr;tyrone-cluster;Scheduler was sent the command term
07/14/2015 17:02:42;0008;PBS_Server;Job;54647.tyrone-cluster;Job deleted at request of physkgly@tyrone-cluster
07/14/2015 17:02:42;0008;PBS_Server;Job;NULL;on_job_exit valid pjob: 0x1cbbf10 (substate=59)
07/14/2015 17:02:42;0100;PBS_Server;Job;54647.tyrone-cluster;dequeuing from qp128, state COMPLETE
07/14/2015 17:02:42;0040;PBS_Server;Svr;tyrone-cluster;Scheduler was sent the command term
07/14/2015 17:03:05;0040;PBS_Server;Svr;tyrone-cluster;Scheduler was sent the command new
07/14/2015 17:03:37;0040;PBS_Server;Svr;tyrone-cluster;Scheduler was sent the command new
07/14/2015 17:04:13;0040;PBS_Server;Svr;tyrone-cluster;Scheduler was sent the command new
07/14/2015 17:04:43;0040;PBS_Server;Svr;tyrone-cluster;Scheduler was sent the command new
07/14/2015 17:05:17;0040;PBS_Server;Svr;tyrone-cluster;Scheduler was sent the command new
07/14/2015 17:05:48;0040;PBS_Server;Svr;tyrone-cluster;Scheduler was sent the command new
07/14/2015 17:06:28;0040;PBS_Server;Svr;tyrone-cluster;Scheduler was sent the command new
07/14/2015 17:06:36;0002;PBS_Server;Svr;PBS_Server;Torque Server Version = 3.0.5, loglevel = 0
07/14/2015 17:06:47;0040;PBS_Server;Svr;tyrone-cluster;Scheduler was sent the command new
07/14/2015 17:07:19;0040;PBS_Server;Svr;tyrone-cluster;Scheduler was sent the command new
07/14/2015 17:07:50;0040;PBS_Server;Svr;tyrone-cluster;Scheduler was sent the command new
07/14/2015 17:07:50;0100;PBS_Server;Job;54648.tyrone-cluster;enqueuing into batch, state 1 hop 1
07/14/2015 17:07:50;0100;PBS_Server;Job;54648.tyrone-cluster;dequeuing from batch, state QUEUED
07/14/2015 17:07:50;0100;PBS_Server;Job;54648.tyrone-cluster;enqueuing into idqueue, state 1 hop 1
07/14/2015 17:07:50;0008;PBS_Server;Job;54648.tyrone-cluster;Job Queued at request of physkgly@tyrone-cluster, owner = physkgly@tyrone-cluster, job name = ab_test, queue = idqueue
07/14/2015 17:07:52;0008;PBS_Server;Job;54648.tyrone-cluster;Job Modified at request of Scheduler@tyrone-cluster
07/14/2015 17:07:52;0008;PBS_Server;Job;54648.tyrone-cluster;Job Run at request of Scheduler@tyrone-cluster
07/14/2015 17:07:52;0040;PBS_Server;Svr;tyrone-cluster;Scheduler was sent the command recyc
07/14/2015 17:07:52;000d;PBS_Server;Job;54648.tyrone-cluster;Not sending email: User does not want mail of this type.
07/14/2015 17:07:53;000d;PBS_Server;Job;54648.tyrone-cluster;Not sending email: User does not want mail of this type.
07/14/2015 17:07:53;0010;PBS_Server;Job;54648.tyrone-cluster;Exit_status=0 resources_used.cput=00:00:16 resources_used.mem=0kb resources_used.vmem=0kb resources_used.walltime=00:00:01
07/14/2015 17:07:53;0008;PBS_Server;Job;NULL;on_job_exit valid pjob: 0x1d13ae0 (substate=50)
07/14/2015 17:07:53;0008;PBS_Server;Job;NULL;on_job_exit valid pjob: 0x1d13ae0 (substate=51)
07/14/2015 17:07:53;0008;PBS_Server;Job;NULL;on_job_exit valid pjob: 0x1d13ae0 (substate=51)
07/14/2015 17:07:53;0008;PBS_Server;Job;NULL;on_job_exit valid pjob: 0x1d13ae0 (substate=53)
07/14/2015 17:07:53;0100;PBS_Server;Job;54648.tyrone-cluster;dequeuing from idqueue, state COMPLETE
07/14/2015 17:07:53;0040;PBS_Server;Svr;tyrone-cluster;Scheduler was sent the command term
07/14/2015 17:08:20;0040;PBS_Server;Svr;tyrone-cluster;Scheduler was sent the command new
07/14/2015 17:08:52;0040;PBS_Server;Svr;tyrone-cluster;Scheduler was sent the command new
07/14/2015 17:09:28;0040;PBS_Server;Svr;tyrone-cluster;Scheduler was sent the command new
07/14/2015 17:09:58;0040;PBS_Server;Svr;tyrone-cluster;Scheduler was sent the command new
07/14/2015 17:10:32;0040;PBS_Server;Svr;tyrone-cluster;Scheduler was sent the command new
07/14/2015 17:11:03;0040;PBS_Server;Svr;tyrone-cluster;Scheduler was sent the command new
07/14/2015 17:11:36;0002;PBS_Server;Svr;PBS_Server;Torque Server Version = 3.0.5, loglevel = 0
07/14/2015 17:11:36;0040;PBS_Server;Svr;tyrone-cluster;Scheduler was sent the command new
07/14/2015 17:12:02;0040;PBS_Server;Svr;tyrone-cluster;Scheduler was sent the command new
07/14/2015 17:12:34;0040;PBS_Server;Svr;tyrone-cluster;Scheduler was sent the command new
07/14/2015 17:13:13;0040;PBS_Server;Svr;tyrone-cluster;Scheduler was sent the command new
07/14/2015 17:13:43;0040;PBS_Server;Svr;tyrone-cluster;Scheduler was sent the command new
07/14/2015 17:14:16;0040;PBS_Server;Svr;tyrone-cluster;Scheduler was sent the command new
07/14/2015 17:14:45;0040;PBS_Server;Svr;tyrone-cluster;Scheduler was sent the command new
07/14/2015 17:15:17;0040;PBS_Server;Svr;tyrone-cluster;Scheduler was sent the command new
07/14/2015 17:15:46;0040;PBS_Server;Svr;tyrone-cluster;Scheduler was sent the command new
07/14/2015 17:16:18;0040;PBS_Server;Svr;tyrone-cluster;Scheduler was sent the command new
07/14/2015 17:16:36;0002;PBS_Server;Svr;PBS_Server;Torque Server Version = 3.0.5, loglevel = 0
07/14/2015 17:16:58;0040;PBS_Server;Svr;tyrone-cluster;Scheduler was sent the command new
07/14/2015 17:17:17;0040;PBS_Server;Svr;tyrone-cluster;Scheduler was sent the command new
07/14/2015 17:17:49;0040;PBS_Server;Svr;tyrone-cluster;Scheduler was sent the command new
07/14/2015 17:18:28;0040;PBS_Server;Svr;tyrone-cluster;Scheduler was sent the command new
07/14/2015 17:18:58;0040;PBS_Server;Svr;tyrone-cluster;Scheduler was sent the command new
07/14/2015 17:19:31;0040;PBS_Server;Svr;tyrone-cluster;Scheduler was sent the command new
07/14/2015 17:20:03;0040;PBS_Server;Svr;tyrone-cluster;Scheduler was sent the command new
07/14/2015 17:20:25;0008;PBS_Server;Job;54630.tyrone-cluster;Job deleted at request of physkgly@tyrone-cluster
07/14/2015 17:20:25;0008;PBS_Server;Job;54630.tyrone-cluster;Job sent signal SIGTERM on delete
07/14/2015 17:20:26;000d;PBS_Server;Job;54630.tyrone-cluster;Not sending email: User does not want mail of this type.
07/14/2015 17:20:26;0010;PBS_Server;Job;54630.tyrone-cluster;Exit_status=255 resources_used.cput=00:00:01 resources_used.mem=175184kb resources_used.vmem=3349164kb resources_used.walltime=04:38:13
07/14/2015 17:20:26;0008;PBS_Server;Job;NULL;on_job_exit valid pjob: 0x1cc2e00 (substate=50)
07/14/2015 17:20:26;0008;PBS_Server;Job;NULL;on_job_exit valid pjob: 0x1cc2e00 (substate=51)
07/14/2015 17:20:26;0008;PBS_Server;Job;NULL;on_job_exit valid pjob: 0x1cc2e00 (substate=51)
07/14/2015 17:20:26;0008;PBS_Server;Job;NULL;on_job_exit valid pjob: 0x1cc2e00 (substate=53)
07/14/2015 17:20:26;0100;PBS_Server;Job;54630.tyrone-cluster;dequeuing from qp64, state COMPLETE
07/14/2015 17:20:26;0040;PBS_Server;Svr;tyrone-cluster;Scheduler was sent the command term
07/14/2015 17:20:26;0008;PBS_Server;Job;54638.tyrone-cluster;Job Modified at request of Scheduler@tyrone-cluster
07/14/2015 17:20:26;0008;PBS_Server;Job;54638.tyrone-cluster;Job Run at request of Scheduler@tyrone-cluster
07/14/2015 17:20:26;0040;PBS_Server;Svr;tyrone-cluster;Scheduler was sent the command recyc
07/14/2015 17:20:43;0040;PBS_Server;Svr;tyrone-cluster;Scheduler was sent the command new
07/14/2015 17:21:02;0040;PBS_Server;Svr;tyrone-cluster;Scheduler was sent the command new
07/14/2015 17:21:06;000d;PBS_Server;Job;54638.tyrone-cluster;Not sending email: User does not want mail of this type.
07/14/2015 17:21:34;0040;PBS_Server;Svr;tyrone-cluster;Scheduler was sent the command new
07/14/2015 17:21:36;0002;PBS_Server;Svr;PBS_Server;Torque Server Version = 3.0.5, loglevel = 0
07/14/2015 17:22:14;0040;PBS_Server;Svr;tyrone-cluster;Scheduler was sent the command new
07/14/2015 17:22:43;0040;PBS_Server;Svr;tyrone-cluster;Scheduler was sent the command new
07/14/2015 17:23:16;0040;PBS_Server;Svr;tyrone-cluster;Scheduler was sent the command new
07/14/2015 17:23:45;0040;PBS_Server;Svr;tyrone-cluster;Scheduler was sent the command new
07/14/2015 17:24:27;0040;PBS_Server;Svr;tyrone-cluster;Scheduler was sent the command new
07/14/2015 17:24:46;0040;PBS_Server;Svr;tyrone-cluster;Scheduler was sent the command new
07/14/2015 17:25:18;0040;PBS_Server;Svr;tyrone-cluster;Scheduler was sent the command new
07/14/2015 17:25:44;0100;PBS_Server;Job;54649.tyrone-cluster;enqueuing into batch, state 1 hop 1
07/14/2015 17:25:44;0100;PBS_Server;Job;54649.tyrone-cluster;dequeuing from batch, state QUEUED
07/14/2015 17:25:44;0100;PBS_Server;Job;54649.tyrone-cluster;enqueuing into idqueue, state 1 hop 1
07/14/2015 17:25:44;0008;PBS_Server;Job;54649.tyrone-cluster;Job Queued at request of physkgly@tyrone-cluster, owner = physkgly@tyrone-cluster, job name = ab_test, queue = idqueue
07/14/2015 17:25:44;0040;PBS_Server;Svr;tyrone-cluster;Scheduler was sent the command new
07/14/2015 17:25:44;0008;PBS_Server;Job;54649.tyrone-cluster;Job Modified at request of Scheduler@tyrone-cluster
07/14/2015 17:25:44;0008;PBS_Server;Job;54649.tyrone-cluster;Job Run at request of Scheduler@tyrone-cluster
07/14/2015 17:25:44;0040;PBS_Server;Svr;tyrone-cluster;Scheduler was sent the command recyc
07/14/2015 17:25:44;000d;PBS_Server;Job;54649.tyrone-cluster;Not sending email: User does not want mail of this type.
07/14/2015 17:25:46;0040;PBS_Server;Svr;tyrone-cluster;Scheduler was sent the command new
07/14/2015 17:26:17;0040;PBS_Server;Svr;tyrone-cluster;Scheduler was sent the command new
07/14/2015 17:26:36;0002;PBS_Server;Svr;PBS_Server;Torque Server Version = 3.0.5, loglevel = 0
07/14/2015 17:26:49;0040;PBS_Server;Svr;tyrone-cluster;Scheduler was sent the command new
07/14/2015 17:27:27;0040;PBS_Server;Svr;tyrone-cluster;Scheduler was sent the command new
07/14/2015 17:27:58;0040;PBS_Server;Svr;tyrone-cluster;Scheduler was sent the command new
07/14/2015 17:28:31;0040;PBS_Server;Svr;tyrone-cluster;Scheduler was sent the command new
07/14/2015 17:29:04;0040;PBS_Server;Svr;tyrone-cluster;Scheduler was sent the command new
07/14/2015 17:29:42;0040;PBS_Server;Svr;tyrone-cluster;Scheduler was sent the command new
07/14/2015 17:30:02;0040;PBS_Server;Svr;tyrone-cluster;Scheduler was sent the command new
07/14/2015 17:30:28;000d;PBS_Server;Job;54638.tyrone-cluster;Not sending email: User does not want mail of this type.
07/14/2015 17:30:28;0010;PBS_Server;Job;54638.tyrone-cluster;Exit_status=265 resources_used.cput=00:00:00 resources_used.mem=7564kb resources_used.vmem=1877488kb resources_used.walltime=00:10:03
07/14/2015 17:30:28;0008;PBS_Server;Job;NULL;on_job_exit valid pjob: 0x1dee940 (substate=50)
07/14/2015 17:30:28;0008;PBS_Server;Job;NULL;on_job_exit valid pjob: 0x1dee940 (substate=51)
07/14/2015 17:30:28;0008;PBS_Server;Job;NULL;on_job_exit valid pjob: 0x1dee940 (substate=51)
07/14/2015 17:30:28;0008;PBS_Server;Job;NULL;on_job_exit valid pjob: 0x1dee940 (substate=53)
07/14/2015 17:30:28;0100;PBS_Server;Job;54638.tyrone-cluster;dequeuing from qp64, state COMPLETE
07/14/2015 17:30:28;0040;PBS_Server;Svr;tyrone-cluster;Scheduler was sent the command term
07/14/2015 17:30:34;0040;PBS_Server;Svr;tyrone-cluster;Scheduler was sent the command new
07/14/2015 17:31:12;0040;PBS_Server;Svr;tyrone-cluster;Scheduler was sent the command new
07/14/2015 17:31:36;0002;PBS_Server;Svr;PBS_Server;Torque Server Version = 3.0.5, loglevel = 0
07/14/2015 17:31:43;0040;PBS_Server;Svr;tyrone-cluster;Scheduler was sent the command new
07/14/2015 17:32:16;0040;PBS_Server;Svr;tyrone-cluster;Scheduler was sent the command new
07/14/2015 17:32:48;0040;PBS_Server;Svr;tyrone-cluster;Scheduler was sent the command new
07/14/2015 17:33:27;0040;PBS_Server;Svr;tyrone-cluster;Scheduler was sent the command new
07/14/2015 17:33:47;0040;PBS_Server;Svr;tyrone-cluster;Scheduler was sent the command new
07/14/2015 17:33:51;000d;PBS_Server;Job;54649.tyrone-cluster;Not sending email: User does not want mail of this type.
07/14/2015 17:33:51;0010;PBS_Server;Job;54649.tyrone-cluster;Exit_status=0 resources_used.cput=03:15:20 resources_used.mem=279684kb resources_used.vmem=8022500kb resources_used.walltime=00:08:07
07/14/2015 17:33:51;0008;PBS_Server;Job;NULL;on_job_exit valid pjob: 0x1d13ae0 (substate=50)
07/14/2015 17:33:51;0008;PBS_Server;Job;NULL;on_job_exit valid pjob: 0x1d13ae0 (substate=51)
07/14/2015 17:33:51;0008;PBS_Server;Job;NULL;on_job_exit valid pjob: 0x1d13ae0 (substate=51)
07/14/2015 17:33:51;0008;PBS_Server;Job;NULL;on_job_exit valid pjob: 0x1d13ae0 (substate=53)
07/14/2015 17:33:51;0100;PBS_Server;Job;54649.tyrone-cluster;dequeuing from idqueue, state COMPLETE
07/14/2015 17:33:51;0040;PBS_Server;Svr;tyrone-cluster;Scheduler was sent the command term
07/14/2015 17:34:19;0040;PBS_Server;Svr;tyrone-cluster;Scheduler was sent the command new
07/14/2015 17:34:51;0040;PBS_Server;Svr;tyrone-cluster;Scheduler was sent the command new
07/14/2015 17:35:18;0040;PBS_Server;Svr;tyrone-cluster;Scheduler was sent the command new
07/14/2015 17:35:49;0040;PBS_Server;Svr;tyrone-cluster;Scheduler was sent the command new
07/14/2015 17:36:28;0040;PBS_Server;Svr;tyrone-cluster;Scheduler was sent the command new
07/14/2015 17:36:36;0002;PBS_Server;Svr;PBS_Server;Torque Server Version = 3.0.5, loglevel = 0
07/14/2015 17:36:58;0040;PBS_Server;Svr;tyrone-cluster;Scheduler was sent the command new
07/14/2015 17:37:31;0040;PBS_Server;Svr;tyrone-cluster;Scheduler was sent the command new
07/14/2015 17:38:04;0040;PBS_Server;Svr;tyrone-cluster;Scheduler was sent the command new
07/14/2015 17:38:43;0040;PBS_Server;Svr;tyrone-cluster;Scheduler was sent the command new
07/14/2015 17:39:03;0040;PBS_Server;Svr;tyrone-cluster;Scheduler was sent the command new
07/14/2015 17:39:34;0040;PBS_Server;Svr;tyrone-cluster;Scheduler was sent the command new
07/14/2015 17:40:13;0040;PBS_Server;Svr;tyrone-cluster;Scheduler was sent the command new
07/14/2015 17:40:43;0040;PBS_Server;Svr;tyrone-cluster;Scheduler was sent the command new
07/14/2015 17:41:17;0040;PBS_Server;Svr;tyrone-cluster;Scheduler was sent the command new
07/14/2015 17:41:36;0002;PBS_Server;Svr;PBS_Server;Torque Server Version = 3.0.5, loglevel = 0
07/14/2015 17:41:48;0040;PBS_Server;Svr;tyrone-cluster;Scheduler was sent the command new
07/14/2015 17:42:28;0040;PBS_Server;Svr;tyrone-cluster;Scheduler was sent the command new
07/14/2015 17:42:47;0040;PBS_Server;Svr;tyrone-cluster;Scheduler was sent the command new
07/14/2015 17:43:20;0040;PBS_Server;Svr;tyrone-cluster;Scheduler was sent the command new
07/14/2015 17:43:59;0040;PBS_Server;Svr;tyrone-cluster;Scheduler was sent the command new
07/14/2015 17:44:28;0040;PBS_Server;Svr;tyrone-cluster;Scheduler was sent the command new
07/14/2015 17:45:01;0040;PBS_Server;Svr;tyrone-cluster;Scheduler was sent the command new
07/14/2015 17:45:30;0040;PBS_Server;Svr;tyrone-cluster;Scheduler was sent the command new
07/14/2015 17:46:01;0040;PBS_Server;Svr;tyrone-cluster;Scheduler was sent the command new
07/14/2015 17:46:31;0040;PBS_Server;Svr;tyrone-cluster;Scheduler was sent the command new
07/14/2015 17:46:36;0002;PBS_Server;Svr;PBS_Server;Torque Server Version = 3.0.5, loglevel = 0
07/14/2015 17:47:00;0040;PBS_Server;Svr;tyrone-cluster;Scheduler was sent the command new
07/14/2015 17:47:31;0040;PBS_Server;Svr;tyrone-cluster;Scheduler was sent the command new
07/14/2015 17:48:02;0040;PBS_Server;Svr;tyrone-cluster;Scheduler was sent the command new
07/14/2015 17:48:30;0040;PBS_Server;Svr;tyrone-cluster;Scheduler was sent the command new
07/14/2015 17:49:13;0040;PBS_Server;Svr;tyrone-cluster;Scheduler was sent the command new
07/14/2015 17:49:32;0040;PBS_Server;Svr;tyrone-cluster;Scheduler was sent the command new
07/14/2015 17:50:04;0040;PBS_Server;Svr;tyrone-cluster;Scheduler was sent the command new
07/14/2015 17:50:43;0040;PBS_Server;Svr;tyrone-cluster;Scheduler was sent the command new
07/14/2015 17:51:13;0040;PBS_Server;Svr;tyrone-cluster;Scheduler was sent the command new
07/14/2015 17:51:36;0002;PBS_Server;Svr;PBS_Server;Torque Server Version = 3.0.5, loglevel = 0
07/14/2015 17:51:46;0040;PBS_Server;Svr;tyrone-cluster;Scheduler was sent the command new
07/14/2015 17:52:15;0040;PBS_Server;Svr;tyrone-cluster;Scheduler was sent the command new
07/14/2015 17:52:46;0040;PBS_Server;Svr;tyrone-cluster;Scheduler was sent the command new
07/14/2015 17:53:16;0040;PBS_Server;Svr;tyrone-cluster;Scheduler was sent the command new
07/14/2015 17:53:45;0040;PBS_Server;Svr;tyrone-cluster;Scheduler was sent the command new
07/14/2015 17:54:28;0040;PBS_Server;Svr;tyrone-cluster;Scheduler was sent the command new
07/14/2015 17:54:47;0040;PBS_Server;Svr;tyrone-cluster;Scheduler was sent the command new
07/14/2015 17:55:19;0040;PBS_Server;Svr;tyrone-cluster;Scheduler was sent the command new
07/14/2015 17:55:58;0040;PBS_Server;Svr;tyrone-cluster;Scheduler was sent the command new
07/14/2015 17:56:28;0040;PBS_Server;Svr;tyrone-cluster;Scheduler was sent the command new
07/14/2015 17:56:36;0002;PBS_Server;Svr;PBS_Server;Torque Server Version = 3.0.5, loglevel = 0
07/14/2015 17:57:01;0040;PBS_Server;Svr;tyrone-cluster;Scheduler was sent the command new
07/14/2015 17:57:30;0040;PBS_Server;Svr;tyrone-cluster;Scheduler was sent the command new
07/14/2015 17:58:13;0040;PBS_Server;Svr;tyrone-cluster;Scheduler was sent the command new
07/14/2015 17:58:32;0040;PBS_Server;Svr;tyrone-cluster;Scheduler was sent the command new
07/14/2015 17:59:04;0040;PBS_Server;Svr;tyrone-cluster;Scheduler was sent the command new
07/14/2015 17:59:43;0040;PBS_Server;Svr;tyrone-cluster;Scheduler was sent the command new
07/14/2015 18:00:13;0040;PBS_Server;Svr;tyrone-cluster;Scheduler was sent the command new
07/14/2015 18:00:47;0040;PBS_Server;Svr;tyrone-cluster;Scheduler was sent the command new
07/14/2015 18:01:19;0040;PBS_Server;Svr;tyrone-cluster;Scheduler was sent the command new
07/14/2015 18:01:36;0002;PBS_Server;Svr;PBS_Server;Torque Server Version = 3.0.5, loglevel = 0
07/14/2015 18:01:58;0040;PBS_Server;Svr;tyrone-cluster;Scheduler was sent the command new
07/14/2015 18:02:17;0040;PBS_Server;Svr;tyrone-cluster;Scheduler was sent the command new
07/14/2015 18:02:49;0040;PBS_Server;Svr;tyrone-cluster;Scheduler was sent the command new
07/14/2015 18:03:28;0040;PBS_Server;Svr;tyrone-cluster;Scheduler was sent the command new
07/14/2015 18:03:59;0040;PBS_Server;Svr;tyrone-cluster;Scheduler was sent the command new
07/14/2015 18:04:30;0040;PBS_Server;Svr;tyrone-cluster;Scheduler was sent the command new
07/14/2015 18:05:01;0040;PBS_Server;Svr;tyrone-cluster;Scheduler was sent the command new
07/14/2015 18:05:42;0040;PBS_Server;Svr;tyrone-cluster;Scheduler was sent the command new
07/14/2015 18:06:02;0040;PBS_Server;Svr;tyrone-cluster;Scheduler was sent the command new
07/14/2015 18:06:34;0040;PBS_Server;Svr;tyrone-cluster;Scheduler was sent the command new
07/14/2015 18:06:36;0002;PBS_Server;Svr;PBS_Server;Torque Server Version = 3.0.5, loglevel = 0
07/14/2015 18:07:13;0040;PBS_Server;Svr;tyrone-cluster;Scheduler was sent the command new
07/14/2015 18:07:44;0040;PBS_Server;Svr;tyrone-cluster;Scheduler was sent the command new
07/14/2015 18:08:16;0040;PBS_Server;Svr;tyrone-cluster;Scheduler was sent the command new
07/14/2015 18:08:46;0040;PBS_Server;Svr;tyrone-cluster;Scheduler was sent the command new
07/14/2015 18:09:16;0040;PBS_Server;Svr;tyrone-cluster;Scheduler was sent the command new
07/14/2015 18:09:46;0040;PBS_Server;Svr;tyrone-cluster;Scheduler was sent the command new
07/14/2015 18:10:16;0040;PBS_Server;Svr;tyrone-cluster;Scheduler was sent the command new
07/14/2015 18:10:58;0040;PBS_Server;Svr;tyrone-cluster;Scheduler was sent the command new
07/14/2015 18:11:17;0040;PBS_Server;Svr;tyrone-cluster;Scheduler was sent the command new
07/14/2015 18:11:36;0002;PBS_Server;Svr;PBS_Server;Torque Server Version = 3.0.5, loglevel = 0
07/14/2015 18:11:48;0040;PBS_Server;Svr;tyrone-cluster;Scheduler was sent the command new
07/14/2015 18:12:28;0040;PBS_Server;Svr;tyrone-cluster;Scheduler was sent the command new
07/14/2015 18:12:53;0100;PBS_Server;Job;54650.tyrone-cluster;enqueuing into batch, state 1 hop 1
07/14/2015 18:12:53;0008;PBS_Server;Job;54650.tyrone-cluster;Job rejected by all possible destinations (check syntax, queue resources, ...)
07/14/2015 18:12:53;0100;PBS_Server;Job;54650.tyrone-cluster;dequeuing from batch, state QUEUED
07/14/2015 18:12:53;0080;PBS_Server;Req;req_reject;Reject reply code=15041(Job rejected by all possible destinations (check syntax, queue resources, ...)), aux=0, type=Commit, from metgkch@tyrone-cluster
07/14/2015 18:12:53;0040;PBS_Server;Svr;tyrone-cluster;Scheduler was sent the command term
07/14/2015 18:12:59;0040;PBS_Server;Svr;tyrone-cluster;Scheduler was sent the command new
07/14/2015 18:13:25;0100;PBS_Server;Job;54651.tyrone-cluster;enqueuing into batch, state 1 hop 1
07/14/2015 18:13:25;0008;PBS_Server;Job;54651.tyrone-cluster;Job rejected by all possible destinations (check syntax, queue resources, ...)
07/14/2015 18:13:25;0100;PBS_Server;Job;54651.tyrone-cluster;dequeuing from batch, state QUEUED
07/14/2015 18:13:25;0080;PBS_Server;Req;req_reject;Reject reply code=15041(Job rejected by all possible destinations (check syntax, queue resources, ...)), aux=0, type=Commit, from metgkch@tyrone-cluster
07/14/2015 18:13:25;0040;PBS_Server;Svr;tyrone-cluster;Scheduler was sent the command term
07/14/2015 18:13:31;0040;PBS_Server;Svr;tyrone-cluster;Scheduler was sent the command new
07/14/2015 18:14:01;0040;PBS_Server;Svr;tyrone-cluster;Scheduler was sent the command new
07/14/2015 18:14:32;0040;PBS_Server;Svr;tyrone-cluster;Scheduler was sent the command new
07/14/2015 18:14:58;0100;PBS_Server;Job;54652.tyrone-cluster;enqueuing into batch, state 1 hop 1
07/14/2015 18:14:58;0100;PBS_Server;Job;54652.tyrone-cluster;dequeuing from batch, state QUEUED
07/14/2015 18:14:58;0100;PBS_Server;Job;54652.tyrone-cluster;enqueuing into qp64, state 1 hop 1
07/14/2015 18:14:58;0008;PBS_Server;Job;54652.tyrone-cluster;Job Queued at request of metgkch@tyrone-cluster, owner = metgkch@tyrone-cluster, job name = Opt2, queue = qp64
07/14/2015 18:14:58;0040;PBS_Server;Svr;tyrone-cluster;Scheduler was sent the command new
07/14/2015 18:14:59;0008;PBS_Server;Job;54652.tyrone-cluster;Job Modified at request of Scheduler@tyrone-cluster
07/14/2015 18:14:59;0008;PBS_Server;Job;54652.tyrone-cluster;Job Run at request of Scheduler@tyrone-cluster
07/14/2015 18:14:59;0040;PBS_Server;Svr;tyrone-cluster;Scheduler was sent the command recyc
07/14/2015 18:15:01;0040;PBS_Server;Svr;tyrone-cluster;Scheduler was sent the command new
07/14/2015 18:15:30;0040;PBS_Server;Svr;tyrone-cluster;Scheduler was sent the command new
07/14/2015 18:15:32;000d;PBS_Server;Job;54652.tyrone-cluster;Not sending email: User does not want mail of this type.
07/14/2015 18:16:13;0040;PBS_Server;Svr;tyrone-cluster;Scheduler was sent the command new
07/14/2015 18:16:32;0040;PBS_Server;Svr;tyrone-cluster;Scheduler was sent the command new
07/14/2015 18:16:36;0002;PBS_Server;Svr;PBS_Server;Torque Server Version = 3.0.5, loglevel = 0
07/14/2015 18:17:02;0040;PBS_Server;Svr;tyrone-cluster;Scheduler was sent the command new
07/14/2015 18:17:42;0040;PBS_Server;Svr;tyrone-cluster;Scheduler was sent the command new
07/14/2015 18:18:02;0040;PBS_Server;Svr;tyrone-cluster;Scheduler was sent the command new
07/14/2015 18:18:32;0040;PBS_Server;Svr;tyrone-cluster;Scheduler was sent the command new
07/14/2015 18:19:12;0040;PBS_Server;Svr;tyrone-cluster;Scheduler was sent the command new
07/14/2015 18:19:33;0040;PBS_Server;Svr;tyrone-cluster;Scheduler was sent the command new
07/14/2015 18:20:02;0040;PBS_Server;Svr;tyrone-cluster;Scheduler was sent the command new
07/14/2015 18:20:43;0040;PBS_Server;Svr;tyrone-cluster;Scheduler was sent the command new
07/14/2015 18:21:02;0040;PBS_Server;Svr;tyrone-cluster;Scheduler was sent the command new
07/14/2015 18:21:32;0040;PBS_Server;Svr;tyrone-cluster;Scheduler was sent the command new
07/14/2015 18:21:36;0002;PBS_Server;Svr;PBS_Server;Torque Server Version = 3.0.5, loglevel = 0
07/14/2015 18:22:13;0040;PBS_Server;Svr;tyrone-cluster;Scheduler was sent the command new
07/14/2015 18:22:32;0040;PBS_Server;Svr;tyrone-cluster;Scheduler was sent the command new
07/14/2015 18:23:02;0040;PBS_Server;Svr;tyrone-cluster;Scheduler was sent the command new
07/14/2015 18:23:42;0040;PBS_Server;Svr;tyrone-cluster;Scheduler was sent the command new
07/14/2015 18:24:14;0040;PBS_Server;Svr;tyrone-cluster;Scheduler was sent the command new
07/14/2015 18:24:46;0040;PBS_Server;Svr;tyrone-cluster;Scheduler was sent the command new
07/14/2015 18:25:16;0040;PBS_Server;Svr;tyrone-cluster;Scheduler was sent the command new
07/14/2015 18:25:46;0040;PBS_Server;Svr;tyrone-cluster;Scheduler was sent the command new
07/14/2015 18:26:17;0040;PBS_Server;Svr;tyrone-cluster;Scheduler was sent the command new
07/14/2015 18:26:36;0002;PBS_Server;Svr;PBS_Server;Torque Server Version = 3.0.5, loglevel = 0
07/14/2015 18:26:46;0040;PBS_Server;Svr;tyrone-cluster;Scheduler was sent the command new
07/14/2015 18:27:17;0040;PBS_Server;Svr;tyrone-cluster;Scheduler was sent the command new
07/14/2015 18:27:46;0040;PBS_Server;Svr;tyrone-cluster;Scheduler was sent the command new
07/14/2015 18:28:15;0040;PBS_Server;Svr;tyrone-cluster;Scheduler was sent the command new
07/14/2015 18:28:46;0040;PBS_Server;Svr;tyrone-cluster;Scheduler was sent the command new
07/14/2015 18:29:17;0040;PBS_Server;Svr;tyrone-cluster;Scheduler was sent the command new
07/14/2015 18:29:45;0040;PBS_Server;Svr;tyrone-cluster;Scheduler was sent the command new
07/14/2015 18:30:17;0040;PBS_Server;Svr;tyrone-cluster;Scheduler was sent the command new
07/14/2015 18:30:46;0040;PBS_Server;Svr;tyrone-cluster;Scheduler was sent the command new
07/14/2015 18:31:16;0040;PBS_Server;Svr;tyrone-cluster;Scheduler was sent the command new
07/14/2015 18:31:36;0002;PBS_Server;Svr;PBS_Server;Torque Server Version = 3.0.5, loglevel = 0
07/14/2015 18:31:47;0040;PBS_Server;Svr;tyrone-cluster;Scheduler was sent the command new
07/14/2015 18:32:17;0040;PBS_Server;Svr;tyrone-cluster;Scheduler was sent the command new
07/14/2015 18:32:46;0040;PBS_Server;Svr;tyrone-cluster;Scheduler was sent the command new
07/14/2015 18:33:17;0040;PBS_Server;Svr;tyrone-cluster;Scheduler was sent the command new
07/14/2015 18:33:47;0040;PBS_Server;Svr;tyrone-cluster;Scheduler was sent the command new
07/14/2015 18:34:16;0040;PBS_Server;Svr;tyrone-cluster;Scheduler was sent the command new
07/14/2015 18:34:51;0040;PBS_Server;Svr;tyrone-cluster;Scheduler was sent the command new
07/14/2015 18:35:17;0040;PBS_Server;Svr;tyrone-cluster;Scheduler was sent the command new
07/14/2015 18:35:47;0040;PBS_Server;Svr;tyrone-cluster;Scheduler was sent the command new
07/14/2015 18:36:28;0040;PBS_Server;Svr;tyrone-cluster;Scheduler was sent the command new
07/14/2015 18:36:36;0002;PBS_Server;Svr;PBS_Server;Torque Server Version = 3.0.5, loglevel = 0
07/14/2015 18:36:47;0040;PBS_Server;Svr;tyrone-cluster;Scheduler was sent the command new
07/14/2015 18:37:17;0040;PBS_Server;Svr;tyrone-cluster;Scheduler was sent the command new
07/14/2015 18:37:57;0040;PBS_Server;Svr;tyrone-cluster;Scheduler was sent the command new
07/14/2015 18:38:18;0040;PBS_Server;Svr;tyrone-cluster;Scheduler was sent the command new
07/14/2015 18:38:47;0040;PBS_Server;Svr;tyrone-cluster;Scheduler was sent the command new
07/14/2015 18:39:27;0040;PBS_Server;Svr;tyrone-cluster;Scheduler was sent the command new
07/14/2015 18:39:49;0040;PBS_Server;Svr;tyrone-cluster;Scheduler was sent the command new
07/14/2015 18:40:17;0040;PBS_Server;Svr;tyrone-cluster;Scheduler was sent the command new
07/14/2015 18:40:57;0040;PBS_Server;Svr;tyrone-cluster;Scheduler was sent the command new
07/14/2015 18:41:29;0040;PBS_Server;Svr;tyrone-cluster;Scheduler was sent the command new
07/14/2015 18:41:36;0002;PBS_Server;Svr;PBS_Server;Torque Server Version = 3.0.5, loglevel = 0
07/14/2015 18:42:00;0040;PBS_Server;Svr;tyrone-cluster;Scheduler was sent the command new
07/14/2015 18:42:31;0040;PBS_Server;Svr;tyrone-cluster;Scheduler was sent the command new
07/14/2015 18:43:12;0040;PBS_Server;Svr;tyrone-cluster;Scheduler was sent the command new
07/14/2015 18:43:33;0040;PBS_Server;Svr;tyrone-cluster;Scheduler was sent the command new
07/14/2015 18:44:02;0040;PBS_Server;Svr;tyrone-cluster;Scheduler was sent the command new
07/14/2015 18:44:42;0040;PBS_Server;Svr;tyrone-cluster;Scheduler was sent the command new
07/14/2015 18:45:04;0040;PBS_Server;Svr;tyrone-cluster;Scheduler was sent the command new
07/14/2015 18:45:32;0040;PBS_Server;Svr;tyrone-cluster;Scheduler was sent the command new
07/14/2015 18:46:12;0040;PBS_Server;Svr;tyrone-cluster;Scheduler was sent the command new
07/14/2015 18:46:36;0002;PBS_Server;Svr;PBS_Server;Torque Server Version = 3.0.5, loglevel = 0
07/14/2015 18:46:44;0040;PBS_Server;Svr;tyrone-cluster;Scheduler was sent the command new
07/14/2015 18:47:17;0040;PBS_Server;Svr;tyrone-cluster;Scheduler was sent the command new
07/14/2015 18:47:46;0040;PBS_Server;Svr;tyrone-cluster;Scheduler was sent the command new
07/14/2015 18:48:17;0040;PBS_Server;Svr;tyrone-cluster;Scheduler was sent the command new
07/14/2015 18:48:46;0040;PBS_Server;Svr;tyrone-cluster;Scheduler was sent the command new
07/14/2015 18:49:16;0040;PBS_Server;Svr;tyrone-cluster;Scheduler was sent the command new
07/14/2015 18:49:47;0040;PBS_Server;Svr;tyrone-cluster;Scheduler was sent the command new
07/14/2015 18:50:16;0040;PBS_Server;Svr;tyrone-cluster;Scheduler was sent the command new
07/14/2015 18:50:46;0040;PBS_Server;Svr;tyrone-cluster;Scheduler was sent the command new
07/14/2015 18:51:17;0040;PBS_Server;Svr;tyrone-cluster;Scheduler was sent the command new
07/14/2015 18:51:36;0002;PBS_Server;Svr;PBS_Server;Torque Server Version = 3.0.5, loglevel = 0
07/14/2015 18:51:47;0040;PBS_Server;Svr;tyrone-cluster;Scheduler was sent the command new
07/14/2015 18:52:16;0040;PBS_Server;Svr;tyrone-cluster;Scheduler was sent the command new
07/14/2015 18:52:47;0040;PBS_Server;Svr;tyrone-cluster;Scheduler was sent the command new
07/14/2015 18:53:16;0040;PBS_Server;Svr;tyrone-cluster;Scheduler was sent the command new
07/14/2015 18:53:46;0040;PBS_Server;Svr;tyrone-cluster;Scheduler was sent the command new
07/14/2015 18:54:28;0040;PBS_Server;Svr;tyrone-cluster;Scheduler was sent the command new
07/14/2015 18:54:48;0040;PBS_Server;Svr;tyrone-cluster;Scheduler was sent the command new
07/14/2015 18:55:17;0040;PBS_Server;Svr;tyrone-cluster;Scheduler was sent the command new
07/14/2015 18:55:57;0040;PBS_Server;Svr;tyrone-cluster;Scheduler was sent the command new
07/14/2015 18:56:18;0040;PBS_Server;Svr;tyrone-cluster;Scheduler was sent the command new
07/14/2015 18:56:36;0002;PBS_Server;Svr;PBS_Server;Torque Server Version = 3.0.5, loglevel = 0
07/14/2015 18:56:50;0040;PBS_Server;Svr;tyrone-cluster;Scheduler was sent the command new
07/14/2015 18:57:27;0040;PBS_Server;Svr;tyrone-cluster;Scheduler was sent the command new
07/14/2015 18:57:59;0040;PBS_Server;Svr;tyrone-cluster;Scheduler was sent the command new
07/14/2015 18:58:32;0040;PBS_Server;Svr;tyrone-cluster;Scheduler was sent the command new
07/14/2015 18:59:01;0040;PBS_Server;Svr;tyrone-cluster;Scheduler was sent the command new
07/14/2015 18:59:30;0040;PBS_Server;Svr;tyrone-cluster;Scheduler was sent the command new
07/14/2015 19:00:01;0040;PBS_Server;Svr;tyrone-cluster;Scheduler was sent the command new
07/14/2015 19:00:31;0040;PBS_Server;Svr;tyrone-cluster;Scheduler was sent the command new
07/14/2015 19:01:12;0040;PBS_Server;Svr;tyrone-cluster;Scheduler was sent the command new
07/14/2015 19:01:33;0040;PBS_Server;Svr;tyrone-cluster;Scheduler was sent the command new
07/14/2015 19:01:36;0002;PBS_Server;Svr;PBS_Server;Torque Server Version = 3.0.5, loglevel = 0
07/14/2015 19:02:02;0040;PBS_Server;Svr;tyrone-cluster;Scheduler was sent the command new
07/14/2015 19:02:42;0040;PBS_Server;Svr;tyrone-cluster;Scheduler was sent the command new
07/14/2015 19:03:03;0040;PBS_Server;Svr;tyrone-cluster;Scheduler was sent the command new
07/14/2015 19:03:34;0040;PBS_Server;Svr;tyrone-cluster;Scheduler was sent the command new
07/14/2015 19:04:13;0040;PBS_Server;Svr;tyrone-cluster;Scheduler was sent the command new
07/14/2015 19:04:44;0040;PBS_Server;Svr;tyrone-cluster;Scheduler was sent the command new
07/14/2015 19:05:16;0040;PBS_Server;Svr;tyrone-cluster;Scheduler was sent the command new
07/14/2015 19:05:46;0040;PBS_Server;Svr;tyrone-cluster;Scheduler was sent the command new
07/14/2015 19:06:17;0040;PBS_Server;Svr;tyrone-cluster;Scheduler was sent the command new
07/14/2015 19:06:36;0002;PBS_Server;Svr;PBS_Server;Torque Server Version = 3.0.5, loglevel = 0
07/14/2015 19:06:47;0040;PBS_Server;Svr;tyrone-cluster;Scheduler was sent the command new
07/14/2015 19:07:16;0040;PBS_Server;Svr;tyrone-cluster;Scheduler was sent the command new
07/14/2015 19:07:47;0040;PBS_Server;Svr;tyrone-cluster;Scheduler was sent the command new
07/14/2015 19:08:16;0040;PBS_Server;Svr;tyrone-cluster;Scheduler was sent the command new
07/14/2015 19:08:46;0040;PBS_Server;Svr;tyrone-cluster;Scheduler was sent the command new
07/14/2015 19:09:26;0040;PBS_Server;Svr;tyrone-cluster;Scheduler was sent the command new
07/14/2015 19:09:48;0040;PBS_Server;Svr;tyrone-cluster;Scheduler was sent the command new
07/14/2015 19:10:17;0040;PBS_Server;Svr;tyrone-cluster;Scheduler was sent the command new
07/14/2015 19:10:57;0040;PBS_Server;Svr;tyrone-cluster;Scheduler was sent the command new
07/14/2015 19:11:29;0040;PBS_Server;Svr;tyrone-cluster;Scheduler was sent the command new
07/14/2015 19:11:36;0002;PBS_Server;Svr;PBS_Server;Torque Server Version = 3.0.5, loglevel = 0
07/14/2015 19:12:00;0040;PBS_Server;Svr;tyrone-cluster;Scheduler was sent the command new
07/14/2015 19:12:31;0040;PBS_Server;Svr;tyrone-cluster;Scheduler was sent the command new
07/14/2015 19:13:12;0040;PBS_Server;Svr;tyrone-cluster;Scheduler was sent the command new
07/14/2015 19:13:33;0040;PBS_Server;Svr;tyrone-cluster;Scheduler was sent the command new
07/14/2015 19:14:02;0040;PBS_Server;Svr;tyrone-cluster;Scheduler was sent the command new
07/14/2015 19:14:42;0040;PBS_Server;Svr;tyrone-cluster;Scheduler was sent the command new
07/14/2015 19:15:04;0040;PBS_Server;Svr;tyrone-cluster;Scheduler was sent the command new
07/14/2015 19:15:32;0040;PBS_Server;Svr;tyrone-cluster;Scheduler was sent the command new
07/14/2015 19:16:12;0040;PBS_Server;Svr;tyrone-cluster;Scheduler was sent the command new
07/14/2015 19:16:34;0040;PBS_Server;Svr;tyrone-cluster;Scheduler was sent the command new
07/14/2015 19:16:36;0002;PBS_Server;Svr;PBS_Server;Torque Server Version = 3.0.5, loglevel = 0
07/14/2015 19:17:02;0040;PBS_Server;Svr;tyrone-cluster;Scheduler was sent the command new
07/14/2015 19:17:42;0040;PBS_Server;Svr;tyrone-cluster;Scheduler was sent the command new
07/14/2015 19:18:03;0040;PBS_Server;Svr;tyrone-cluster;Scheduler was sent the command new
07/14/2015 19:18:32;0040;PBS_Server;Svr;tyrone-cluster;Scheduler was sent the command new
07/14/2015 19:19:12;0040;PBS_Server;Svr;tyrone-cluster;Scheduler was sent the command new
07/14/2015 19:19:33;0040;PBS_Server;Svr;tyrone-cluster;Scheduler was sent the command new
07/14/2015 19:20:05;0040;PBS_Server;Svr;tyrone-cluster;Scheduler was sent the command new
07/14/2015 19:20:43;0040;PBS_Server;Svr;tyrone-cluster;Scheduler was sent the command new
07/14/2015 19:21:14;0040;PBS_Server;Svr;tyrone-cluster;Scheduler was sent the command new
07/14/2015 19:21:36;0002;PBS_Server;Svr;PBS_Server;Torque Server Version = 3.0.5, loglevel = 0
07/14/2015 19:21:46;0040;PBS_Server;Svr;tyrone-cluster;Scheduler was sent the command new
07/14/2015 19:22:16;0040;PBS_Server;Svr;tyrone-cluster;Scheduler was sent the command new
07/14/2015 19:22:56;0040;PBS_Server;Svr;tyrone-cluster;Scheduler was sent the command new
07/14/2015 19:23:18;0040;PBS_Server;Svr;tyrone-cluster;Scheduler was sent the command new
07/14/2015 19:23:47;0040;PBS_Server;Svr;tyrone-cluster;Scheduler was sent the command new
07/14/2015 19:24:27;0040;PBS_Server;Svr;tyrone-cluster;Scheduler was sent the command new
07/14/2015 19:24:49;0040;PBS_Server;Svr;tyrone-cluster;Scheduler was sent the command new
07/14/2015 19:25:19;0040;PBS_Server;Svr;tyrone-cluster;Scheduler was sent the command new
07/14/2015 19:25:58;0040;PBS_Server;Svr;tyrone-cluster;Scheduler was sent the command new
07/14/2015 19:26:29;0040;PBS_Server;Svr;tyrone-cluster;Scheduler was sent the command new
07/14/2015 19:26:36;0002;PBS_Server;Svr;PBS_Server;Torque Server Version = 3.0.5, loglevel = 0
07/14/2015 19:27:00;0040;PBS_Server;Svr;tyrone-cluster;Scheduler was sent the command new
07/14/2015 19:27:31;0040;PBS_Server;Svr;tyrone-cluster;Scheduler was sent the command new
07/14/2015 19:28:12;0040;PBS_Server;Svr;tyrone-cluster;Scheduler was sent the command new
07/14/2015 19:28:34;0040;PBS_Server;Svr;tyrone-cluster;Scheduler was sent the command new
07/14/2015 19:29:04;0040;PBS_Server;Svr;tyrone-cluster;Scheduler was sent the command new
07/14/2015 19:29:42;0040;PBS_Server;Svr;tyrone-cluster;Scheduler was sent the command new
07/14/2015 19:30:14;0040;PBS_Server;Svr;tyrone-cluster;Scheduler was sent the command new
07/14/2015 19:30:47;0040;PBS_Server;Svr;tyrone-cluster;Scheduler was sent the command new
07/14/2015 19:31:16;0040;PBS_Server;Svr;tyrone-cluster;Scheduler was sent the command new
07/14/2015 19:31:36;0002;PBS_Server;Svr;PBS_Server;Torque Server Version = 3.0.5, loglevel = 0
07/14/2015 19:31:47;0040;PBS_Server;Svr;tyrone-cluster;Scheduler was sent the command new
07/14/2015 19:32:17;0040;PBS_Server;Svr;tyrone-cluster;Scheduler was sent the command new
07/14/2015 19:32:46;0040;PBS_Server;Svr;tyrone-cluster;Scheduler was sent the command new
07/14/2015 19:33:26;0040;PBS_Server;Svr;tyrone-cluster;Scheduler was sent the command new
07/14/2015 19:33:48;0040;PBS_Server;Svr;tyrone-cluster;Scheduler was sent the command new
07/14/2015 19:34:17;0040;PBS_Server;Svr;tyrone-cluster;Scheduler was sent the command new
07/14/2015 19:34:51;0040;PBS_Server;Svr;tyrone-cluster;Scheduler was sent the command new
07/14/2015 19:35:19;0040;PBS_Server;Svr;tyrone-cluster;Scheduler was sent the command new
07/14/2015 19:35:47;0040;PBS_Server;Svr;tyrone-cluster;Scheduler was sent the command new
07/14/2015 19:36:27;0040;PBS_Server;Svr;tyrone-cluster;Scheduler was sent the command new
07/14/2015 19:36:36;0002;PBS_Server;Svr;PBS_Server;Torque Server Version = 3.0.5, loglevel = 0
07/14/2015 19:36:48;0040;PBS_Server;Svr;tyrone-cluster;Scheduler was sent the command new
07/14/2015 19:37:19;0040;PBS_Server;Svr;tyrone-cluster;Scheduler was sent the command new
07/14/2015 19:37:58;0040;PBS_Server;Svr;tyrone-cluster;Scheduler was sent the command new
07/14/2015 19:38:29;0040;PBS_Server;Svr;tyrone-cluster;Scheduler was sent the command new
07/14/2015 19:39:01;0040;PBS_Server;Svr;tyrone-cluster;Scheduler was sent the command new
07/14/2015 19:39:31;0040;PBS_Server;Svr;tyrone-cluster;Scheduler was sent the command new
07/14/2015 19:40:01;0040;PBS_Server;Svr;tyrone-cluster;Scheduler was sent the command new
07/14/2015 19:40:31;0040;PBS_Server;Svr;tyrone-cluster;Scheduler was sent the command new
07/14/2015 19:41:01;0040;PBS_Server;Svr;tyrone-cluster;Scheduler was sent the command new
07/14/2015 19:41:32;0040;PBS_Server;Svr;tyrone-cluster;Scheduler was sent the command new
07/14/2015 19:41:36;0002;PBS_Server;Svr;PBS_Server;Torque Server Version = 3.0.5, loglevel = 0
07/14/2015 19:42:02;0040;PBS_Server;Svr;tyrone-cluster;Scheduler was sent the command new
07/14/2015 19:42:30;0040;PBS_Server;Svr;tyrone-cluster;Scheduler was sent the command new
07/14/2015 19:43:02;0040;PBS_Server;Svr;tyrone-cluster;Scheduler was sent the command new
07/14/2015 19:43:31;0040;PBS_Server;Svr;tyrone-cluster;Scheduler was sent the command new
07/14/2015 19:44:01;0040;PBS_Server;Svr;tyrone-cluster;Scheduler was sent the command new
07/14/2015 19:44:32;0040;PBS_Server;Svr;tyrone-cluster;Scheduler was sent the command new
07/14/2015 19:45:02;0040;PBS_Server;Svr;tyrone-cluster;Scheduler was sent the command new
07/14/2015 19:45:30;0040;PBS_Server;Svr;tyrone-cluster;Scheduler was sent the command new
07/14/2015 19:46:02;0040;PBS_Server;Svr;tyrone-cluster;Scheduler was sent the command new
07/14/2015 19:46:32;0040;PBS_Server;Svr;tyrone-cluster;Scheduler was sent the command new
07/14/2015 19:46:36;0002;PBS_Server;Svr;PBS_Server;Torque Server Version = 3.0.5, loglevel = 0
07/14/2015 19:47:01;0040;PBS_Server;Svr;tyrone-cluster;Scheduler was sent the command new
07/14/2015 19:47:32;0040;PBS_Server;Svr;tyrone-cluster;Scheduler was sent the command new
07/14/2015 19:48:02;0040;PBS_Server;Svr;tyrone-cluster;Scheduler was sent the command new
07/14/2015 19:48:31;0040;PBS_Server;Svr;tyrone-cluster;Scheduler was sent the command new
07/14/2015 19:49:02;0040;PBS_Server;Svr;tyrone-cluster;Scheduler was sent the command new
07/14/2015 19:49:30;0040;PBS_Server;Svr;tyrone-cluster;Scheduler was sent the command new
07/14/2015 19:50:01;0040;PBS_Server;Svr;tyrone-cluster;Scheduler was sent the command new
07/14/2015 19:50:33;0040;PBS_Server;Svr;tyrone-cluster;Scheduler was sent the command new
07/14/2015 19:51:02;0040;PBS_Server;Svr;tyrone-cluster;Scheduler was sent the command new
07/14/2015 19:51:31;0040;PBS_Server;Svr;tyrone-cluster;Scheduler was sent the command new
07/14/2015 19:51:36;0002;PBS_Server;Svr;PBS_Server;Torque Server Version = 3.0.5, loglevel = 0
07/14/2015 19:52:02;0040;PBS_Server;Svr;tyrone-cluster;Scheduler was sent the command new
07/14/2015 19:52:32;0040;PBS_Server;Svr;tyrone-cluster;Scheduler was sent the command new
07/14/2015 19:53:01;0040;PBS_Server;Svr;tyrone-cluster;Scheduler was sent the command new
07/14/2015 19:53:42;0040;PBS_Server;Svr;tyrone-cluster;Scheduler was sent the command new
07/14/2015 19:54:03;0040;PBS_Server;Svr;tyrone-cluster;Scheduler was sent the command new
07/14/2015 19:54:32;0040;PBS_Server;Svr;tyrone-cluster;Scheduler was sent the command new
07/14/2015 19:55:12;0040;PBS_Server;Svr;tyrone-cluster;Scheduler was sent the command new
07/14/2015 19:55:34;0040;PBS_Server;Svr;tyrone-cluster;Scheduler was sent the command new
07/14/2015 19:56:02;0040;PBS_Server;Svr;tyrone-cluster;Scheduler was sent the command new
07/14/2015 19:56:36;0002;PBS_Server;Svr;PBS_Server;Torque Server Version = 3.0.5, loglevel = 0
07/14/2015 19:56:36;0040;PBS_Server;Svr;tyrone-cluster;Scheduler was sent the command new
07/14/2015 19:57:03;0040;PBS_Server;Svr;tyrone-cluster;Scheduler was sent the command new
07/14/2015 19:57:32;0040;PBS_Server;Svr;tyrone-cluster;Scheduler was sent the command new
07/14/2015 19:58:12;0040;PBS_Server;Svr;tyrone-cluster;Scheduler was sent the command new
07/14/2015 19:58:34;0040;PBS_Server;Svr;tyrone-cluster;Scheduler was sent the command new
07/14/2015 19:59:02;0040;PBS_Server;Svr;tyrone-cluster;Scheduler was sent the command new
07/14/2015 19:59:42;0040;PBS_Server;Svr;tyrone-cluster;Scheduler was sent the command new
07/14/2015 20:00:03;0040;PBS_Server;Svr;tyrone-cluster;Scheduler was sent the command new
07/14/2015 20:00:34;0040;PBS_Server;Svr;tyrone-cluster;Scheduler was sent the command new
07/14/2015 20:01:13;0040;PBS_Server;Svr;tyrone-cluster;Scheduler was sent the command new
07/14/2015 20:01:36;0002;PBS_Server;Svr;PBS_Server;Torque Server Version = 3.0.5, loglevel = 0
07/14/2015 20:01:44;0040;PBS_Server;Svr;tyrone-cluster;Scheduler was sent the command new
07/14/2015 20:02:17;0040;PBS_Server;Svr;tyrone-cluster;Scheduler was sent the command new
07/14/2015 20:02:46;0040;PBS_Server;Svr;tyrone-cluster;Scheduler was sent the command new
07/14/2015 20:03:17;0040;PBS_Server;Svr;tyrone-cluster;Scheduler was sent the command new
07/14/2015 20:03:48;0040;PBS_Server;Svr;tyrone-cluster;Scheduler was sent the command new
07/14/2015 20:04:16;0040;PBS_Server;Svr;tyrone-cluster;Scheduler was sent the command new
07/14/2015 20:04:57;0040;PBS_Server;Svr;tyrone-cluster;Scheduler was sent the command new
07/14/2015 20:05:18;0040;PBS_Server;Svr;tyrone-cluster;Scheduler was sent the command new
07/14/2015 20:05:47;0040;PBS_Server;Svr;tyrone-cluster;Scheduler was sent the command new
07/14/2015 20:06:27;0040;PBS_Server;Svr;tyrone-cluster;Scheduler was sent the command new
07/14/2015 20:06:36;0002;PBS_Server;Svr;PBS_Server;Torque Server Version = 3.0.5, loglevel = 0
07/14/2015 20:06:48;0040;PBS_Server;Svr;tyrone-cluster;Scheduler was sent the command new
07/14/2015 20:07:17;0040;PBS_Server;Svr;tyrone-cluster;Scheduler was sent the command new
07/14/2015 20:07:56;0040;PBS_Server;Svr;tyrone-cluster;Scheduler was sent the command new
07/14/2015 20:08:18;0040;PBS_Server;Svr;tyrone-cluster;Scheduler was sent the command new
07/14/2015 20:08:51;0040;PBS_Server;Svr;tyrone-cluster;Scheduler was sent the command new
07/14/2015 20:09:28;0040;PBS_Server;Svr;tyrone-cluster;Scheduler was sent the command new
07/14/2015 20:09:59;0040;PBS_Server;Svr;tyrone-cluster;Scheduler was sent the command new
07/14/2015 20:10:32;0040;PBS_Server;Svr;tyrone-cluster;Scheduler was sent the command new
07/14/2015 20:11:01;0040;PBS_Server;Svr;tyrone-cluster;Scheduler was sent the command new
07/14/2015 20:11:32;0040;PBS_Server;Svr;tyrone-cluster;Scheduler was sent the command new
07/14/2015 20:11:36;0002;PBS_Server;Svr;PBS_Server;Torque Server Version = 3.0.5, loglevel = 0
07/14/2015 20:12:02;0040;PBS_Server;Svr;tyrone-cluster;Scheduler was sent the command new
07/14/2015 20:12:31;0040;PBS_Server;Svr;tyrone-cluster;Scheduler was sent the command new
07/14/2015 20:13:02;0040;PBS_Server;Svr;tyrone-cluster;Scheduler was sent the command new
07/14/2015 20:13:32;0040;PBS_Server;Svr;tyrone-cluster;Scheduler was sent the command new
07/14/2015 20:14:01;0040;PBS_Server;Svr;tyrone-cluster;Scheduler was sent the command new
07/14/2015 20:14:32;0040;PBS_Server;Svr;tyrone-cluster;Scheduler was sent the command new
07/14/2015 20:15:02;0040;PBS_Server;Svr;tyrone-cluster;Scheduler was sent the command new
07/14/2015 20:15:31;0040;PBS_Server;Svr;tyrone-cluster;Scheduler was sent the command new
07/14/2015 20:15:44;000d;PBS_Server;Job;54652.tyrone-cluster;Not sending email: User does not want mail of this type.
07/14/2015 20:15:44;0010;PBS_Server;Job;54652.tyrone-cluster;Exit_status=143 resources_used.cput=01:31:42 resources_used.mem=288876kb resources_used.vmem=2916712kb resources_used.walltime=02:00:45
07/14/2015 20:15:44;0008;PBS_Server;Job;NULL;on_job_exit valid pjob: 0x1dee940 (substate=50)
07/14/2015 20:15:44;0008;PBS_Server;Job;NULL;on_job_exit valid pjob: 0x1dee940 (substate=51)
07/14/2015 20:15:45;0008;PBS_Server;Job;NULL;on_job_exit valid pjob: 0x1dee940 (substate=51)
07/14/2015 20:15:45;0008;PBS_Server;Job;NULL;on_job_exit valid pjob: 0x1dee940 (substate=53)
07/14/2015 20:15:45;0100;PBS_Server;Job;54652.tyrone-cluster;dequeuing from qp64, state COMPLETE
07/14/2015 20:15:45;0040;PBS_Server;Svr;tyrone-cluster;Scheduler was sent the command term
07/14/2015 20:16:03;0040;PBS_Server;Svr;tyrone-cluster;Scheduler was sent the command new
07/14/2015 20:16:32;0040;PBS_Server;Svr;tyrone-cluster;Scheduler was sent the command new
07/14/2015 20:16:36;0002;PBS_Server;Svr;PBS_Server;Torque Server Version = 3.0.5, loglevel = 0
07/14/2015 20:17:01;0040;PBS_Server;Svr;tyrone-cluster;Scheduler was sent the command new
07/14/2015 20:17:32;0040;PBS_Server;Svr;tyrone-cluster;Scheduler was sent the command new
07/14/2015 20:18:03;0040;PBS_Server;Svr;tyrone-cluster;Scheduler was sent the command new
07/14/2015 20:18:35;0040;PBS_Server;Svr;tyrone-cluster;Scheduler was sent the command new
07/14/2015 20:19:12;0040;PBS_Server;Svr;tyrone-cluster;Scheduler was sent the command new
07/14/2015 20:19:44;0040;PBS_Server;Svr;tyrone-cluster;Scheduler was sent the command new
07/14/2015 20:20:17;0040;PBS_Server;Svr;tyrone-cluster;Scheduler was sent the command new
07/14/2015 20:20:46;0040;PBS_Server;Svr;tyrone-cluster;Scheduler was sent the command new
07/14/2015 20:21:18;0040;PBS_Server;Svr;tyrone-cluster;Scheduler was sent the command new
07/14/2015 20:21:36;0002;PBS_Server;Svr;PBS_Server;Torque Server Version = 3.0.5, loglevel = 0
07/14/2015 20:21:47;0040;PBS_Server;Svr;tyrone-cluster;Scheduler was sent the command new
07/14/2015 20:22:16;0040;PBS_Server;Svr;tyrone-cluster;Scheduler was sent the command new
07/14/2015 20:22:47;0040;PBS_Server;Svr;tyrone-cluster;Scheduler was sent the command new
07/14/2015 20:23:18;0040;PBS_Server;Svr;tyrone-cluster;Scheduler was sent the command new
07/14/2015 20:23:46;0040;PBS_Server;Svr;tyrone-cluster;Scheduler was sent the command new
07/14/2015 20:24:27;0040;PBS_Server;Svr;tyrone-cluster;Scheduler was sent the command new
07/14/2015 20:24:48;0040;PBS_Server;Svr;tyrone-cluster;Scheduler was sent the command new
07/14/2015 20:25:20;0040;PBS_Server;Svr;tyrone-cluster;Scheduler was sent the command new
07/14/2015 20:25:58;0040;PBS_Server;Svr;tyrone-cluster;Scheduler was sent the command new
07/14/2015 20:26:29;0040;PBS_Server;Svr;tyrone-cluster;Scheduler was sent the command new
07/14/2015 20:26:36;0002;PBS_Server;Svr;PBS_Server;Torque Server Version = 3.0.5, loglevel = 0
07/14/2015 20:27:00;0040;PBS_Server;Svr;tyrone-cluster;Scheduler was sent the command new
07/14/2015 20:27:31;0040;PBS_Server;Svr;tyrone-cluster;Scheduler was sent the command new
07/14/2015 20:28:02;0040;PBS_Server;Svr;tyrone-cluster;Scheduler was sent the command new
07/14/2015 20:28:33;0040;PBS_Server;Svr;tyrone-cluster;Scheduler was sent the command new
07/14/2015 20:29:05;0040;PBS_Server;Svr;tyrone-cluster;Scheduler was sent the command new
07/14/2015 20:29:43;0040;PBS_Server;Svr;tyrone-cluster;Scheduler was sent the command new
07/14/2015 20:30:14;0040;PBS_Server;Svr;tyrone-cluster;Scheduler was sent the command new
07/14/2015 20:30:47;0040;PBS_Server;Svr;tyrone-cluster;Scheduler was sent the command new
07/14/2015 20:31:16;0040;PBS_Server;Svr;tyrone-cluster;Scheduler was sent the command new
07/14/2015 20:31:36;0002;PBS_Server;Svr;PBS_Server;Torque Server Version = 3.0.5, loglevel = 0
07/14/2015 20:31:47;0040;PBS_Server;Svr;tyrone-cluster;Scheduler was sent the command new
07/14/2015 20:32:17;0040;PBS_Server;Svr;tyrone-cluster;Scheduler was sent the command new
07/14/2015 20:32:46;0040;PBS_Server;Svr;tyrone-cluster;Scheduler was sent the command new
07/14/2015 20:33:17;0040;PBS_Server;Svr;tyrone-cluster;Scheduler was sent the command new
07/14/2015 20:33:47;0040;PBS_Server;Svr;tyrone-cluster;Scheduler was sent the command new
07/14/2015 20:34:16;0040;PBS_Server;Svr;tyrone-cluster;Scheduler was sent the command new
07/14/2015 20:34:48;0040;PBS_Server;Svr;tyrone-cluster;Scheduler was sent the command new
07/14/2015 20:35:17;0040;PBS_Server;Svr;tyrone-cluster;Scheduler was sent the command new
07/14/2015 20:35:46;0040;PBS_Server;Svr;tyrone-cluster;Scheduler was sent the command new
07/14/2015 20:36:17;0040;PBS_Server;Svr;tyrone-cluster;Scheduler was sent the command new
07/14/2015 20:36:36;0002;PBS_Server;Svr;PBS_Server;Torque Server Version = 3.0.5, loglevel = 0
07/14/2015 20:36:48;0040;PBS_Server;Svr;tyrone-cluster;Scheduler was sent the command new
07/14/2015 20:37:16;0040;PBS_Server;Svr;tyrone-cluster;Scheduler was sent the command new
07/14/2015 20:37:57;0040;PBS_Server;Svr;tyrone-cluster;Scheduler was sent the command new
07/14/2015 20:38:01;000d;PBS_Server;Job;54609.tyrone-cluster;Not sending email: User does not want mail of this type.
07/14/2015 20:38:01;0010;PBS_Server;Job;54609.tyrone-cluster;Exit_status=271 resources_used.cput=1535:40:54 resources_used.mem=2671848kb resources_used.vmem=36346084kb resources_used.walltime=24:00:44
07/14/2015 20:38:01;0008;PBS_Server;Job;NULL;on_job_exit valid pjob: 0x1cf8330 (substate=50)
07/14/2015 20:38:01;0008;PBS_Server;Job;NULL;on_job_exit valid pjob: 0x1cf8330 (substate=51)
07/14/2015 20:38:02;0008;PBS_Server;Job;NULL;on_job_exit valid pjob: 0x1cf8330 (substate=51)
07/14/2015 20:38:02;0008;PBS_Server;Job;NULL;on_job_exit valid pjob: 0x1cf8330 (substate=53)
07/14/2015 20:38:02;0100;PBS_Server;Job;54609.tyrone-cluster;dequeuing from qp256, state COMPLETE
07/14/2015 20:38:02;0040;PBS_Server;Svr;tyrone-cluster;Scheduler was sent the command term
07/14/2015 20:38:03;0008;PBS_Server;Job;54610.tyrone-cluster;Job Modified at request of Scheduler@tyrone-cluster
07/14/2015 20:38:03;0008;PBS_Server;Job;54610.tyrone-cluster;Job Run at request of Scheduler@tyrone-cluster
07/14/2015 20:38:03;0040;PBS_Server;Svr;tyrone-cluster;Scheduler was sent the command recyc
07/14/2015 20:38:18;0100;PBS_Server;Job;54611.tyrone-cluster;dequeuing from batch, state QUEUED
07/14/2015 20:38:18;0100;PBS_Server;Job;54611.tyrone-cluster;enqueuing into qp256, state 1 hop 1
07/14/2015 20:38:19;0040;PBS_Server;Svr;tyrone-cluster;Scheduler was sent the command new
07/14/2015 20:38:19;0008;PBS_Server;Job;54611.tyrone-cluster;Job Modified at request of Scheduler@tyrone-cluster
07/14/2015 20:38:50;0040;PBS_Server;Svr;tyrone-cluster;Scheduler was sent the command new
07/14/2015 20:39:08;000d;PBS_Server;Job;54610.tyrone-cluster;Not sending email: User does not want mail of this type.
07/14/2015 20:39:28;0040;PBS_Server;Svr;tyrone-cluster;Scheduler was sent the command new
07/14/2015 20:39:59;0040;PBS_Server;Svr;tyrone-cluster;Scheduler was sent the command new
07/14/2015 20:40:32;0040;PBS_Server;Svr;tyrone-cluster;Scheduler was sent the command new
07/14/2015 20:41:00;0040;PBS_Server;Svr;tyrone-cluster;Scheduler was sent the command new
07/14/2015 20:41:29;0040;PBS_Server;Svr;tyrone-cluster;Scheduler was sent the command new
07/14/2015 20:41:36;0002;PBS_Server;Svr;PBS_Server;Torque Server Version = 3.0.5, loglevel = 0
07/14/2015 20:42:00;0040;PBS_Server;Svr;tyrone-cluster;Scheduler was sent the command new
07/14/2015 20:42:31;0040;PBS_Server;Svr;tyrone-cluster;Scheduler was sent the command new
07/14/2015 20:43:03;0040;PBS_Server;Svr;tyrone-cluster;Scheduler was sent the command new
07/14/2015 20:43:33;0040;PBS_Server;Svr;tyrone-cluster;Scheduler was sent the command new
07/14/2015 20:44:05;0040;PBS_Server;Svr;tyrone-cluster;Scheduler was sent the command new
07/14/2015 20:44:42;0040;PBS_Server;Svr;tyrone-cluster;Scheduler was sent the command new
07/14/2015 20:45:14;0040;PBS_Server;Svr;tyrone-cluster;Scheduler was sent the command new
07/14/2015 20:45:46;0040;PBS_Server;Svr;tyrone-cluster;Scheduler was sent the command new
07/14/2015 20:46:16;0040;PBS_Server;Svr;tyrone-cluster;Scheduler was sent the command new
07/14/2015 20:46:36;0002;PBS_Server;Svr;PBS_Server;Torque Server Version = 3.0.5, loglevel = 0
07/14/2015 20:46:48;0040;PBS_Server;Svr;tyrone-cluster;Scheduler was sent the command new
07/14/2015 20:47:18;0040;PBS_Server;Svr;tyrone-cluster;Scheduler was sent the command new
07/14/2015 20:47:50;0040;PBS_Server;Svr;tyrone-cluster;Scheduler was sent the command new
07/14/2015 20:48:28;0040;PBS_Server;Svr;tyrone-cluster;Scheduler was sent the command new
07/14/2015 20:48:59;0040;PBS_Server;Svr;tyrone-cluster;Scheduler was sent the command new
07/14/2015 20:49:30;0040;PBS_Server;Svr;tyrone-cluster;Scheduler was sent the command new
07/14/2015 20:50:01;0040;PBS_Server;Svr;tyrone-cluster;Scheduler was sent the command new
07/14/2015 20:50:32;0040;PBS_Server;Svr;tyrone-cluster;Scheduler was sent the command new
07/14/2015 20:51:02;0040;PBS_Server;Svr;tyrone-cluster;Scheduler was sent the command new
07/14/2015 20:51:31;0040;PBS_Server;Svr;tyrone-cluster;Scheduler was sent the command new
07/14/2015 20:51:36;0002;PBS_Server;Svr;PBS_Server;Torque Server Version = 3.0.5, loglevel = 0
07/14/2015 20:52:01;0040;PBS_Server;Svr;tyrone-cluster;Scheduler was sent the command new
07/14/2015 20:52:32;0040;PBS_Server;Svr;tyrone-cluster;Scheduler was sent the command new
07/14/2015 20:53:01;0040;PBS_Server;Svr;tyrone-cluster;Scheduler was sent the command new
07/14/2015 20:53:32;0040;PBS_Server;Svr;tyrone-cluster;Scheduler was sent the command new
07/14/2015 20:54:03;0040;PBS_Server;Svr;tyrone-cluster;Scheduler was sent the command new
07/14/2015 20:54:31;0040;PBS_Server;Svr;tyrone-cluster;Scheduler was sent the command new
07/14/2015 20:55:12;0040;PBS_Server;Svr;tyrone-cluster;Scheduler was sent the command new
07/14/2015 20:55:33;0040;PBS_Server;Svr;tyrone-cluster;Scheduler was sent the command new
07/14/2015 20:56:05;0040;PBS_Server;Svr;tyrone-cluster;Scheduler was sent the command new
07/14/2015 20:56:36;0002;PBS_Server;Svr;PBS_Server;Torque Server Version = 3.0.5, loglevel = 0
07/14/2015 20:56:42;0040;PBS_Server;Svr;tyrone-cluster;Scheduler was sent the command new
07/14/2015 20:57:08;0040;PBS_Server;Svr;tyrone-cluster;Scheduler was sent the command new
07/14/2015 20:57:40;0040;PBS_Server;Svr;tyrone-cluster;Scheduler was sent the command new
07/14/2015 20:58:12;0040;PBS_Server;Svr;tyrone-cluster;Scheduler was sent the command new
07/14/2015 20:58:44;0040;PBS_Server;Svr;tyrone-cluster;Scheduler was sent the command new
07/14/2015 20:59:16;0040;PBS_Server;Svr;tyrone-cluster;Scheduler was sent the command new
07/14/2015 20:59:45;0040;PBS_Server;Svr;tyrone-cluster;Scheduler was sent the command new
07/14/2015 21:00:14;0040;PBS_Server;Svr;tyrone-cluster;Scheduler was sent the command new
07/14/2015 21:00:47;0040;PBS_Server;Svr;tyrone-cluster;Scheduler was sent the command new
07/14/2015 21:01:16;0040;PBS_Server;Svr;tyrone-cluster;Scheduler was sent the command new
07/14/2015 21:01:36;0002;PBS_Server;Svr;PBS_Server;Torque Server Version = 3.0.5, loglevel = 0
07/14/2015 21:01:48;0040;PBS_Server;Svr;tyrone-cluster;Scheduler was sent the command new
07/14/2015 21:02:18;0040;PBS_Server;Svr;tyrone-cluster;Scheduler was sent the command new
07/14/2015 21:02:50;0040;PBS_Server;Svr;tyrone-cluster;Scheduler was sent the command new
07/14/2015 21:03:27;0040;PBS_Server;Svr;tyrone-cluster;Scheduler was sent the command new
07/14/2015 21:03:59;0040;PBS_Server;Svr;tyrone-cluster;Scheduler was sent the command new
07/14/2015 21:04:30;0040;PBS_Server;Svr;tyrone-cluster;Scheduler was sent the command new
07/14/2015 21:05:00;0040;PBS_Server;Svr;tyrone-cluster;Scheduler was sent the command new
07/14/2015 21:05:29;0040;PBS_Server;Svr;tyrone-cluster;Scheduler was sent the command new
07/14/2015 21:06:02;0040;PBS_Server;Svr;tyrone-cluster;Scheduler was sent the command new
07/14/2015 21:06:31;0040;PBS_Server;Svr;tyrone-cluster;Scheduler was sent the command new
07/14/2015 21:06:36;0002;PBS_Server;Svr;PBS_Server;Torque Server Version = 3.0.5, loglevel = 0
07/14/2015 21:07:00;0040;PBS_Server;Svr;tyrone-cluster;Scheduler was sent the command new
07/14/2015 21:07:33;0040;PBS_Server;Svr;tyrone-cluster;Scheduler was sent the command new
07/14/2015 21:08:05;0040;PBS_Server;Svr;tyrone-cluster;Scheduler was sent the command new
07/14/2015 21:08:42;0040;PBS_Server;Svr;tyrone-cluster;Scheduler was sent the command new
07/14/2015 21:09:14;0040;PBS_Server;Svr;tyrone-cluster;Scheduler was sent the command new
07/14/2015 21:09:46;0040;PBS_Server;Svr;tyrone-cluster;Scheduler was sent the command new
07/14/2015 21:10:15;0040;PBS_Server;Svr;tyrone-cluster;Scheduler was sent the command new
07/14/2015 21:10:44;0040;PBS_Server;Svr;tyrone-cluster;Scheduler was sent the command new
07/14/2015 21:11:17;0040;PBS_Server;Svr;tyrone-cluster;Scheduler was sent the command new
07/14/2015 21:11:36;0002;PBS_Server;Svr;PBS_Server;Torque Server Version = 3.0.5, loglevel = 0
07/14/2015 21:11:46;0040;PBS_Server;Svr;tyrone-cluster;Scheduler was sent the command new
07/14/2015 21:12:18;0040;PBS_Server;Svr;tyrone-cluster;Scheduler was sent the command new
07/14/2015 21:12:48;0040;PBS_Server;Svr;tyrone-cluster;Scheduler was sent the command new
07/14/2015 21:13:20;0040;PBS_Server;Svr;tyrone-cluster;Scheduler was sent the command new
07/14/2015 21:13:57;0040;PBS_Server;Svr;tyrone-cluster;Scheduler was sent the command new
07/14/2015 21:14:29;0040;PBS_Server;Svr;tyrone-cluster;Scheduler was sent the command new
07/14/2015 21:15:02;0040;PBS_Server;Svr;tyrone-cluster;Scheduler was sent the command new
07/14/2015 21:15:30;0040;PBS_Server;Svr;tyrone-cluster;Scheduler was sent the command new
07/14/2015 21:15:59;0040;PBS_Server;Svr;tyrone-cluster;Scheduler was sent the command new
07/14/2015 21:16:33;0040;PBS_Server;Svr;tyrone-cluster;Scheduler was sent the command new
07/14/2015 21:16:36;0002;PBS_Server;Svr;PBS_Server;Torque Server Version = 3.0.5, loglevel = 0
07/14/2015 21:17:01;0040;PBS_Server;Svr;tyrone-cluster;Scheduler was sent the command new
07/14/2015 21:17:33;0040;PBS_Server;Svr;tyrone-cluster;Scheduler was sent the command new
07/14/2015 21:18:03;0040;PBS_Server;Svr;tyrone-cluster;Scheduler was sent the command new
07/14/2015 21:18:34;0040;PBS_Server;Svr;tyrone-cluster;Scheduler was sent the command new
07/14/2015 21:19:12;0040;PBS_Server;Svr;tyrone-cluster;Scheduler was sent the command new
07/14/2015 21:19:44;0040;PBS_Server;Svr;tyrone-cluster;Scheduler was sent the command new
07/14/2015 21:20:18;0040;PBS_Server;Svr;tyrone-cluster;Scheduler was sent the command new
07/14/2015 21:20:46;0040;PBS_Server;Svr;tyrone-cluster;Scheduler was sent the command new
07/14/2015 21:21:18;0040;PBS_Server;Svr;tyrone-cluster;Scheduler was sent the command new
07/14/2015 21:21:36;0002;PBS_Server;Svr;PBS_Server;Torque Server Version = 3.0.5, loglevel = 0
07/14/2015 21:21:48;0040;PBS_Server;Svr;tyrone-cluster;Scheduler was sent the command new
07/14/2015 21:22:19;0040;PBS_Server;Svr;tyrone-cluster;Scheduler was sent the command new
07/14/2015 21:22:57;0040;PBS_Server;Svr;tyrone-cluster;Scheduler was sent the command new
07/14/2015 21:23:29;0040;PBS_Server;Svr;tyrone-cluster;Scheduler was sent the command new
07/14/2015 21:24:03;0040;PBS_Server;Svr;tyrone-cluster;Scheduler was sent the command new
07/14/2015 21:24:31;0040;PBS_Server;Svr;tyrone-cluster;Scheduler was sent the command new
07/14/2015 21:25:03;0040;PBS_Server;Svr;tyrone-cluster;Scheduler was sent the command new
07/14/2015 21:25:33;0040;PBS_Server;Svr;tyrone-cluster;Scheduler was sent the command new
07/14/2015 21:26:05;0040;PBS_Server;Svr;tyrone-cluster;Scheduler was sent the command new
07/14/2015 21:26:36;0002;PBS_Server;Svr;PBS_Server;Torque Server Version = 3.0.5, loglevel = 0
07/14/2015 21:26:42;0040;PBS_Server;Svr;tyrone-cluster;Scheduler was sent the command new
07/14/2015 21:27:08;0040;PBS_Server;Svr;tyrone-cluster;Scheduler was sent the command new
07/14/2015 21:27:40;0040;PBS_Server;Svr;tyrone-cluster;Scheduler was sent the command new
07/14/2015 21:28:12;0040;PBS_Server;Svr;tyrone-cluster;Scheduler was sent the command new
07/14/2015 21:28:44;0040;PBS_Server;Svr;tyrone-cluster;Scheduler was sent the command new
07/14/2015 21:29:18;0040;PBS_Server;Svr;tyrone-cluster;Scheduler was sent the command new
07/14/2015 21:29:46;0040;PBS_Server;Svr;tyrone-cluster;Scheduler was sent the command new
07/14/2015 21:30:18;0040;PBS_Server;Svr;tyrone-cluster;Scheduler was sent the command new
07/14/2015 21:30:48;0040;PBS_Server;Svr;tyrone-cluster;Scheduler was sent the command new
07/14/2015 21:31:19;0040;PBS_Server;Svr;tyrone-cluster;Scheduler was sent the command new
07/14/2015 21:31:36;0002;PBS_Server;Svr;PBS_Server;Torque Server Version = 3.0.5, loglevel = 0
07/14/2015 21:31:57;0040;PBS_Server;Svr;tyrone-cluster;Scheduler was sent the command new
07/14/2015 21:32:29;0040;PBS_Server;Svr;tyrone-cluster;Scheduler was sent the command new
07/14/2015 21:33:03;0040;PBS_Server;Svr;tyrone-cluster;Scheduler was sent the command new
07/14/2015 21:33:31;0040;PBS_Server;Svr;tyrone-cluster;Scheduler was sent the command new
07/14/2015 21:34:03;0040;PBS_Server;Svr;tyrone-cluster;Scheduler was sent the command new
07/14/2015 21:34:33;0040;PBS_Server;Svr;tyrone-cluster;Scheduler was sent the command new
07/14/2015 21:35:05;0040;PBS_Server;Svr;tyrone-cluster;Scheduler was sent the command new
07/14/2015 21:35:42;0040;PBS_Server;Svr;tyrone-cluster;Scheduler was sent the command new
07/14/2015 21:36:14;0040;PBS_Server;Svr;tyrone-cluster;Scheduler was sent the command new
07/14/2015 21:36:36;0002;PBS_Server;Svr;PBS_Server;Torque Server Version = 3.0.5, loglevel = 0
07/14/2015 21:36:48;0040;PBS_Server;Svr;tyrone-cluster;Scheduler was sent the command new
07/14/2015 21:37:16;0040;PBS_Server;Svr;tyrone-cluster;Scheduler was sent the command new
07/14/2015 21:37:48;0040;PBS_Server;Svr;tyrone-cluster;Scheduler was sent the command new
07/14/2015 21:38:18;0040;PBS_Server;Svr;tyrone-cluster;Scheduler was sent the command new
07/14/2015 21:38:50;0040;PBS_Server;Svr;tyrone-cluster;Scheduler was sent the command new
07/14/2015 21:39:27;0040;PBS_Server;Svr;tyrone-cluster;Scheduler was sent the command new
07/14/2015 21:39:59;0040;PBS_Server;Svr;tyrone-cluster;Scheduler was sent the command new
07/14/2015 21:40:33;0040;PBS_Server;Svr;tyrone-cluster;Scheduler was sent the command new
07/14/2015 21:41:01;0040;PBS_Server;Svr;tyrone-cluster;Scheduler was sent the command new
07/14/2015 21:41:33;0040;PBS_Server;Svr;tyrone-cluster;Scheduler was sent the command new
07/14/2015 21:41:36;0002;PBS_Server;Svr;PBS_Server;Torque Server Version = 3.0.5, loglevel = 0
07/14/2015 21:42:03;0040;PBS_Server;Svr;tyrone-cluster;Scheduler was sent the command new
07/14/2015 21:42:35;0040;PBS_Server;Svr;tyrone-cluster;Scheduler was sent the command new
07/14/2015 21:43:06;0040;PBS_Server;Svr;tyrone-cluster;Scheduler was sent the command new
07/14/2015 21:43:38;0040;PBS_Server;Svr;tyrone-cluster;Scheduler was sent the command new
07/14/2015 21:44:08;0040;PBS_Server;Svr;tyrone-cluster;Scheduler was sent the command new
07/14/2015 21:44:42;0040;PBS_Server;Svr;tyrone-cluster;Scheduler was sent the command new
07/14/2015 21:45:14;0040;PBS_Server;Svr;tyrone-cluster;Scheduler was sent the command new
07/14/2015 21:45:48;0040;PBS_Server;Svr;tyrone-cluster;Scheduler was sent the command new
07/14/2015 21:46:15;0040;PBS_Server;Svr;tyrone-cluster;Scheduler was sent the command new
07/14/2015 21:46:36;0002;PBS_Server;Svr;PBS_Server;Torque Server Version = 3.0.5, loglevel = 0
07/14/2015 21:46:44;0040;PBS_Server;Svr;tyrone-cluster;Scheduler was sent the command new
07/14/2015 21:46:47;0100;PBS_Server;Job;54653.tyrone-cluster;enqueuing into batch, state 1 hop 1
07/14/2015 21:46:47;0100;PBS_Server;Job;54653.tyrone-cluster;dequeuing from batch, state QUEUED
07/14/2015 21:46:47;0100;PBS_Server;Job;54653.tyrone-cluster;enqueuing into qp64, state 1 hop 1
07/14/2015 21:46:47;0008;PBS_Server;Job;54653.tyrone-cluster;Job Queued at request of metnvv@tyrone-cluster, owner = metnvv@tyrone-cluster, job name = job256, queue = qp64
07/14/2015 21:46:47;0040;PBS_Server;Svr;tyrone-cluster;Scheduler was sent the command new
07/14/2015 21:46:47;0008;PBS_Server;Job;54653.tyrone-cluster;Job Modified at request of Scheduler@tyrone-cluster
07/14/2015 21:46:47;0008;PBS_Server;Job;54653.tyrone-cluster;Job Run at request of Scheduler@tyrone-cluster
07/14/2015 21:46:47;0040;PBS_Server;Svr;tyrone-cluster;Scheduler was sent the command recyc
