01/03/2015 00:00:29;0002;PBS_Server;Svr;Log;Log opened
01/03/2015 00:00:29;0040;PBS_Server;Svr;tyrone-cluster;Scheduler was sent the command new
01/03/2015 00:00:59;0040;PBS_Server;Svr;tyrone-cluster;Scheduler was sent the command new
01/03/2015 00:01:29;0040;PBS_Server;Svr;tyrone-cluster;Scheduler was sent the command new
01/03/2015 00:01:59;0040;PBS_Server;Svr;tyrone-cluster;Scheduler was sent the command new
01/03/2015 00:02:29;0040;PBS_Server;Svr;tyrone-cluster;Scheduler was sent the command new
01/03/2015 00:02:59;0040;PBS_Server;Svr;tyrone-cluster;Scheduler was sent the command new
01/03/2015 00:03:29;0040;PBS_Server;Svr;tyrone-cluster;Scheduler was sent the command new
01/03/2015 00:04:00;0040;PBS_Server;Svr;tyrone-cluster;Scheduler was sent the command new
01/03/2015 00:04:30;0040;PBS_Server;Svr;tyrone-cluster;Scheduler was sent the command new
01/03/2015 00:04:46;0002;PBS_Server;Svr;PBS_Server;Torque Server Version = 3.0.5, loglevel = 0
01/03/2015 00:05:00;0040;PBS_Server;Svr;tyrone-cluster;Scheduler was sent the command new
01/03/2015 00:05:30;0040;PBS_Server;Svr;tyrone-cluster;Scheduler was sent the command new
01/03/2015 00:06:00;0040;PBS_Server;Svr;tyrone-cluster;Scheduler was sent the command new
01/03/2015 00:06:30;0040;PBS_Server;Svr;tyrone-cluster;Scheduler was sent the command new
01/03/2015 00:07:00;0040;PBS_Server;Svr;tyrone-cluster;Scheduler was sent the command new
01/03/2015 00:07:30;0040;PBS_Server;Svr;tyrone-cluster;Scheduler was sent the command new
01/03/2015 00:08:01;0040;PBS_Server;Svr;tyrone-cluster;Scheduler was sent the command new
01/03/2015 00:08:31;0040;PBS_Server;Svr;tyrone-cluster;Scheduler was sent the command new
01/03/2015 00:09:01;0040;PBS_Server;Svr;tyrone-cluster;Scheduler was sent the command new
01/03/2015 00:09:17;0002;PBS_Server;Svr;Act;Account file /var/spool/torque/server_priv/accounting/20150103 opened
01/03/2015 00:09:17;0008;PBS_Server;Job;46395.tyrone-cluster;Job deleted at request of chemraja@tyrone-cluster
01/03/2015 00:09:17;0008;PBS_Server;Job;46395.tyrone-cluster;Job sent signal SIGTERM on delete
01/03/2015 00:09:19;0008;PBS_Server;Job;46395.tyrone-cluster;Job sent signal SIGKILL on delete
01/03/2015 00:09:21;000d;PBS_Server;Job;46395.tyrone-cluster;Not sending email: User does not want mail of this type.
01/03/2015 00:09:21;0010;PBS_Server;Job;46395.tyrone-cluster;Exit_status=143 resources_used.cput=00:08:31 resources_used.mem=117168kb resources_used.vmem=1960636kb resources_used.walltime=00:10:46
01/03/2015 00:09:21;0008;PBS_Server;Job;NULL;on_job_exit valid pjob: 0x1407f70 (substate=50)
01/03/2015 00:09:21;0008;PBS_Server;Job;NULL;on_job_exit valid pjob: 0x1407f70 (substate=51)
01/03/2015 00:09:21;0008;PBS_Server;Job;NULL;on_job_exit valid pjob: 0x1407f70 (substate=51)
01/03/2015 00:09:21;0008;PBS_Server;Job;NULL;on_job_exit valid pjob: 0x1407f70 (substate=53)
01/03/2015 00:09:21;0100;PBS_Server;Job;46395.tyrone-cluster;dequeuing from idqueue, state COMPLETE
01/03/2015 00:09:21;0040;PBS_Server;Svr;tyrone-cluster;Scheduler was sent the command term
01/03/2015 00:09:31;0040;PBS_Server;Svr;tyrone-cluster;Scheduler was sent the command new
01/03/2015 00:09:46;0002;PBS_Server;Svr;PBS_Server;Torque Server Version = 3.0.5, loglevel = 0
01/03/2015 00:09:46;0100;PBS_Server;Job;46396.tyrone-cluster;enqueuing into batch, state 1 hop 1
01/03/2015 00:09:46;0100;PBS_Server;Job;46396.tyrone-cluster;dequeuing from batch, state QUEUED
01/03/2015 00:09:46;0100;PBS_Server;Job;46396.tyrone-cluster;enqueuing into idqueue, state 1 hop 1
01/03/2015 00:09:46;0008;PBS_Server;Job;46396.tyrone-cluster;Job Queued at request of chemraja@tyrone-cluster, owner = chemraja@tyrone-cluster, job name = test.sh, queue = idqueue
01/03/2015 00:09:46;0040;PBS_Server;Svr;tyrone-cluster;Scheduler was sent the command new
01/03/2015 00:09:46;0008;PBS_Server;Job;46396.tyrone-cluster;Job Modified at request of Scheduler@tyrone-cluster
01/03/2015 00:09:46;0008;PBS_Server;Job;46396.tyrone-cluster;Job Run at request of Scheduler@tyrone-cluster
01/03/2015 00:09:46;0040;PBS_Server;Svr;tyrone-cluster;Scheduler was sent the command recyc
01/03/2015 00:09:46;000d;PBS_Server;Job;46396.tyrone-cluster;Not sending email: User does not want mail of this type.
01/03/2015 00:10:01;0040;PBS_Server;Svr;tyrone-cluster;Scheduler was sent the command new
01/03/2015 00:10:31;0040;PBS_Server;Svr;tyrone-cluster;Scheduler was sent the command new
01/03/2015 00:11:01;0040;PBS_Server;Svr;tyrone-cluster;Scheduler was sent the command new
01/03/2015 00:11:31;0040;PBS_Server;Svr;tyrone-cluster;Scheduler was sent the command new
01/03/2015 00:12:01;0040;PBS_Server;Svr;tyrone-cluster;Scheduler was sent the command new
01/03/2015 00:12:31;0040;PBS_Server;Svr;tyrone-cluster;Scheduler was sent the command new
01/03/2015 00:13:03;0040;PBS_Server;Svr;tyrone-cluster;Scheduler was sent the command new
01/03/2015 00:13:38;0040;PBS_Server;Svr;tyrone-cluster;Scheduler was sent the command new
01/03/2015 00:14:01;0040;PBS_Server;Svr;tyrone-cluster;Scheduler was sent the command new
01/03/2015 00:14:33;0040;PBS_Server;Svr;tyrone-cluster;Scheduler was sent the command new
01/03/2015 00:14:46;0002;PBS_Server;Svr;PBS_Server;Torque Server Version = 3.0.5, loglevel = 0
01/03/2015 00:15:09;0040;PBS_Server;Svr;tyrone-cluster;Scheduler was sent the command new
01/03/2015 00:15:38;0040;PBS_Server;Svr;tyrone-cluster;Scheduler was sent the command new
01/03/2015 00:16:11;0040;PBS_Server;Svr;tyrone-cluster;Scheduler was sent the command new
01/03/2015 00:16:40;0040;PBS_Server;Svr;tyrone-cluster;Scheduler was sent the command new
01/03/2015 00:17:13;0040;PBS_Server;Svr;tyrone-cluster;Scheduler was sent the command new
01/03/2015 00:17:46;0040;PBS_Server;Svr;tyrone-cluster;Scheduler was sent the command new
01/03/2015 00:18:18;0040;PBS_Server;Svr;tyrone-cluster;Scheduler was sent the command new
01/03/2015 00:18:23;0100;PBS_Server;Job;46397.tyrone-cluster;enqueuing into batch, state 1 hop 1
01/03/2015 00:18:23;0100;PBS_Server;Job;46397.tyrone-cluster;dequeuing from batch, state QUEUED
01/03/2015 00:18:23;0100;PBS_Server;Job;46397.tyrone-cluster;enqueuing into idqueue, state 1 hop 1
01/03/2015 00:18:23;0008;PBS_Server;Job;46397.tyrone-cluster;Job Queued at request of secparth@tyrone-cluster, owner = secparth@tyrone-cluster, job name = JOB11, queue = idqueue
01/03/2015 00:18:23;0040;PBS_Server;Svr;tyrone-cluster;Scheduler was sent the command new
01/03/2015 00:18:23;0008;PBS_Server;Job;46397.tyrone-cluster;Job Modified at request of Scheduler@tyrone-cluster
01/03/2015 00:18:48;0040;PBS_Server;Svr;tyrone-cluster;Scheduler was sent the command new
01/03/2015 00:19:18;0040;PBS_Server;Svr;tyrone-cluster;Scheduler was sent the command new
01/03/2015 00:19:46;0002;PBS_Server;Svr;PBS_Server;Torque Server Version = 3.0.5, loglevel = 0
01/03/2015 00:19:48;0040;PBS_Server;Svr;tyrone-cluster;Scheduler was sent the command new
01/03/2015 00:20:18;0040;PBS_Server;Svr;tyrone-cluster;Scheduler was sent the command new
01/03/2015 00:20:48;0040;PBS_Server;Svr;tyrone-cluster;Scheduler was sent the command new
01/03/2015 00:21:18;0040;PBS_Server;Svr;tyrone-cluster;Scheduler was sent the command new
01/03/2015 00:21:48;0040;PBS_Server;Svr;tyrone-cluster;Scheduler was sent the command new
01/03/2015 00:22:18;0040;PBS_Server;Svr;tyrone-cluster;Scheduler was sent the command new
01/03/2015 00:22:49;0040;PBS_Server;Svr;tyrone-cluster;Scheduler was sent the command new
01/03/2015 00:23:19;0040;PBS_Server;Svr;tyrone-cluster;Scheduler was sent the command new
01/03/2015 00:23:33;0008;PBS_Server;Job;46397.tyrone-cluster;Job deleted at request of secparth@tyrone-cluster
01/03/2015 00:23:33;0008;PBS_Server;Job;NULL;on_job_exit valid pjob: 0x1407f70 (substate=59)
01/03/2015 00:23:33;0100;PBS_Server;Job;46397.tyrone-cluster;dequeuing from idqueue, state COMPLETE
01/03/2015 00:23:33;0040;PBS_Server;Svr;tyrone-cluster;Scheduler was sent the command term
01/03/2015 00:23:49;0040;PBS_Server;Svr;tyrone-cluster;Scheduler was sent the command new
01/03/2015 00:24:19;0040;PBS_Server;Svr;tyrone-cluster;Scheduler was sent the command new
01/03/2015 00:24:46;0002;PBS_Server;Svr;PBS_Server;Torque Server Version = 3.0.5, loglevel = 0
01/03/2015 00:24:49;0040;PBS_Server;Svr;tyrone-cluster;Scheduler was sent the command new
01/03/2015 00:25:19;0040;PBS_Server;Svr;tyrone-cluster;Scheduler was sent the command new
01/03/2015 00:25:49;0040;PBS_Server;Svr;tyrone-cluster;Scheduler was sent the command new
01/03/2015 00:26:19;0040;PBS_Server;Svr;tyrone-cluster;Scheduler was sent the command new
01/03/2015 00:26:50;0040;PBS_Server;Svr;tyrone-cluster;Scheduler was sent the command new
01/03/2015 00:26:50;0100;PBS_Server;Job;46398.tyrone-cluster;enqueuing into batch, state 1 hop 1
01/03/2015 00:26:50;0100;PBS_Server;Job;46398.tyrone-cluster;dequeuing from batch, state QUEUED
01/03/2015 00:26:50;0100;PBS_Server;Job;46398.tyrone-cluster;enqueuing into idqueue, state 1 hop 1
01/03/2015 00:26:50;0008;PBS_Server;Job;46398.tyrone-cluster;Job Queued at request of secparth@tyrone-cluster, owner = secparth@tyrone-cluster, job name = JOB11, queue = idqueue
01/03/2015 00:26:50;0040;PBS_Server;Svr;tyrone-cluster;Scheduler was sent the command new
01/03/2015 00:26:50;0008;PBS_Server;Job;46398.tyrone-cluster;Job Modified at request of Scheduler@tyrone-cluster
01/03/2015 00:27:19;0040;PBS_Server;Svr;tyrone-cluster;Scheduler was sent the command new
01/03/2015 00:27:50;0040;PBS_Server;Svr;tyrone-cluster;Scheduler was sent the command new
01/03/2015 00:28:20;0040;PBS_Server;Svr;tyrone-cluster;Scheduler was sent the command new
01/03/2015 00:28:50;0040;PBS_Server;Svr;tyrone-cluster;Scheduler was sent the command new
01/03/2015 00:29:20;0040;PBS_Server;Svr;tyrone-cluster;Scheduler was sent the command new
01/03/2015 00:29:46;0002;PBS_Server;Svr;PBS_Server;Torque Server Version = 3.0.5, loglevel = 0
01/03/2015 00:29:50;0040;PBS_Server;Svr;tyrone-cluster;Scheduler was sent the command new
01/03/2015 00:30:20;0040;PBS_Server;Svr;tyrone-cluster;Scheduler was sent the command new
01/03/2015 00:30:24;0008;PBS_Server;Job;46398.tyrone-cluster;Job deleted at request of secparth@tyrone-cluster
01/03/2015 00:30:24;0008;PBS_Server;Job;NULL;on_job_exit valid pjob: 0x1407f70 (substate=59)
01/03/2015 00:30:24;0100;PBS_Server;Job;46398.tyrone-cluster;dequeuing from idqueue, state COMPLETE
01/03/2015 00:30:24;0040;PBS_Server;Svr;tyrone-cluster;Scheduler was sent the command term
01/03/2015 00:30:50;0040;PBS_Server;Svr;tyrone-cluster;Scheduler was sent the command new
01/03/2015 00:31:20;0040;PBS_Server;Svr;tyrone-cluster;Scheduler was sent the command new
01/03/2015 00:31:51;0040;PBS_Server;Svr;tyrone-cluster;Scheduler was sent the command new
01/03/2015 00:32:21;0040;PBS_Server;Svr;tyrone-cluster;Scheduler was sent the command new
01/03/2015 00:32:51;0040;PBS_Server;Svr;tyrone-cluster;Scheduler was sent the command new
01/03/2015 00:33:21;0040;PBS_Server;Svr;tyrone-cluster;Scheduler was sent the command new
01/03/2015 00:33:51;0040;PBS_Server;Svr;tyrone-cluster;Scheduler was sent the command new
01/03/2015 00:34:03;0100;PBS_Server;Job;46399.tyrone-cluster;enqueuing into batch, state 1 hop 1
01/03/2015 00:34:03;0100;PBS_Server;Job;46399.tyrone-cluster;dequeuing from batch, state QUEUED
01/03/2015 00:34:03;0100;PBS_Server;Job;46399.tyrone-cluster;enqueuing into idqueue, state 1 hop 1
01/03/2015 00:34:03;0008;PBS_Server;Job;46399.tyrone-cluster;Job Queued at request of secparth@tyrone-cluster, owner = secparth@tyrone-cluster, job name = JOB11, queue = idqueue
01/03/2015 00:34:03;0040;PBS_Server;Svr;tyrone-cluster;Scheduler was sent the command new
01/03/2015 00:34:03;0008;PBS_Server;Job;46399.tyrone-cluster;Job Modified at request of Scheduler@tyrone-cluster
01/03/2015 00:34:21;0040;PBS_Server;Svr;tyrone-cluster;Scheduler was sent the command new
01/03/2015 00:34:46;0002;PBS_Server;Svr;PBS_Server;Torque Server Version = 3.0.5, loglevel = 0
01/03/2015 00:34:51;0040;PBS_Server;Svr;tyrone-cluster;Scheduler was sent the command new
01/03/2015 00:35:21;0040;PBS_Server;Svr;tyrone-cluster;Scheduler was sent the command new
01/03/2015 00:35:29;0008;PBS_Server;Job;46399.tyrone-cluster;Job deleted at request of secparth@tyrone-cluster
01/03/2015 00:35:29;0008;PBS_Server;Job;NULL;on_job_exit valid pjob: 0x1407f70 (substate=59)
01/03/2015 00:35:29;0100;PBS_Server;Job;46399.tyrone-cluster;dequeuing from idqueue, state COMPLETE
01/03/2015 00:35:29;0040;PBS_Server;Svr;tyrone-cluster;Scheduler was sent the command term
01/03/2015 00:35:51;0040;PBS_Server;Svr;tyrone-cluster;Scheduler was sent the command new
01/03/2015 00:35:56;0100;PBS_Server;Job;46400.tyrone-cluster;enqueuing into batch, state 1 hop 1
01/03/2015 00:35:56;0100;PBS_Server;Job;46400.tyrone-cluster;dequeuing from batch, state QUEUED
01/03/2015 00:35:56;0100;PBS_Server;Job;46400.tyrone-cluster;enqueuing into idqueue, state 1 hop 1
01/03/2015 00:35:56;0008;PBS_Server;Job;46400.tyrone-cluster;Job Queued at request of secparth@tyrone-cluster, owner = secparth@tyrone-cluster, job name = JOB11, queue = idqueue
01/03/2015 00:35:56;0040;PBS_Server;Svr;tyrone-cluster;Scheduler was sent the command new
01/03/2015 00:35:57;0008;PBS_Server;Job;46400.tyrone-cluster;Job Modified at request of Scheduler@tyrone-cluster
01/03/2015 00:36:21;0040;PBS_Server;Svr;tyrone-cluster;Scheduler was sent the command new
01/03/2015 00:36:34;000d;PBS_Server;Job;46396.tyrone-cluster;Not sending email: User does not want mail of this type.
01/03/2015 00:36:34;0010;PBS_Server;Job;46396.tyrone-cluster;Exit_status=0 resources_used.cput=00:25:27 resources_used.mem=128648kb resources_used.vmem=1960644kb resources_used.walltime=00:26:48
01/03/2015 00:36:34;0008;PBS_Server;Job;NULL;on_job_exit valid pjob: 0x12fe400 (substate=50)
01/03/2015 00:36:34;0008;PBS_Server;Job;NULL;on_job_exit valid pjob: 0x12fe400 (substate=51)
01/03/2015 00:36:34;0008;PBS_Server;Job;NULL;on_job_exit valid pjob: 0x12fe400 (substate=51)
01/03/2015 00:36:34;0008;PBS_Server;Job;NULL;on_job_exit valid pjob: 0x12fe400 (substate=53)
01/03/2015 00:36:34;0100;PBS_Server;Job;46396.tyrone-cluster;dequeuing from idqueue, state COMPLETE
01/03/2015 00:36:34;0040;PBS_Server;Svr;tyrone-cluster;Scheduler was sent the command term
01/03/2015 00:36:34;0008;PBS_Server;Job;46400.tyrone-cluster;Job Modified at request of Scheduler@tyrone-cluster
01/03/2015 00:36:34;0008;PBS_Server;Job;46400.tyrone-cluster;Job Run at request of Scheduler@tyrone-cluster
01/03/2015 00:36:34;0040;PBS_Server;Svr;tyrone-cluster;Scheduler was sent the command recyc
01/03/2015 00:36:34;000d;PBS_Server;Job;46400.tyrone-cluster;Not sending email: User does not want mail of this type.
01/03/2015 00:36:35;000d;PBS_Server;Job;46400.tyrone-cluster;Not sending email: User does not want mail of this type.
01/03/2015 00:36:35;0010;PBS_Server;Job;46400.tyrone-cluster;Exit_status=0 resources_used.cput=00:00:00 resources_used.mem=0kb resources_used.vmem=0kb resources_used.walltime=00:00:01
01/03/2015 00:36:35;0008;PBS_Server;Job;NULL;on_job_exit valid pjob: 0x1407f70 (substate=50)
01/03/2015 00:36:35;0008;PBS_Server;Job;NULL;on_job_exit valid pjob: 0x1407f70 (substate=51)
01/03/2015 00:36:35;0008;PBS_Server;Job;NULL;on_job_exit valid pjob: 0x1407f70 (substate=51)
01/03/2015 00:36:35;0008;PBS_Server;Job;NULL;on_job_exit valid pjob: 0x1407f70 (substate=53)
01/03/2015 00:36:35;0100;PBS_Server;Job;46400.tyrone-cluster;dequeuing from idqueue, state COMPLETE
01/03/2015 00:36:35;0040;PBS_Server;Svr;tyrone-cluster;Scheduler was sent the command term
01/03/2015 00:36:52;0040;PBS_Server;Svr;tyrone-cluster;Scheduler was sent the command new
01/03/2015 00:37:22;0040;PBS_Server;Svr;tyrone-cluster;Scheduler was sent the command new
01/03/2015 00:37:52;0040;PBS_Server;Svr;tyrone-cluster;Scheduler was sent the command new
01/03/2015 00:38:22;0040;PBS_Server;Svr;tyrone-cluster;Scheduler was sent the command new
01/03/2015 00:38:52;0040;PBS_Server;Svr;tyrone-cluster;Scheduler was sent the command new
01/03/2015 00:39:22;0040;PBS_Server;Svr;tyrone-cluster;Scheduler was sent the command new
01/03/2015 00:39:46;0002;PBS_Server;Svr;PBS_Server;Torque Server Version = 3.0.5, loglevel = 0
01/03/2015 00:39:52;0040;PBS_Server;Svr;tyrone-cluster;Scheduler was sent the command new
01/03/2015 00:40:22;0040;PBS_Server;Svr;tyrone-cluster;Scheduler was sent the command new
01/03/2015 00:40:54;0040;PBS_Server;Svr;tyrone-cluster;Scheduler was sent the command new
01/03/2015 00:41:24;0040;PBS_Server;Svr;tyrone-cluster;Scheduler was sent the command new
01/03/2015 00:41:53;0040;PBS_Server;Svr;tyrone-cluster;Scheduler was sent the command new
01/03/2015 00:42:26;0040;PBS_Server;Svr;tyrone-cluster;Scheduler was sent the command new
01/03/2015 00:42:55;0040;PBS_Server;Svr;tyrone-cluster;Scheduler was sent the command new
01/03/2015 00:43:28;0040;PBS_Server;Svr;tyrone-cluster;Scheduler was sent the command new
01/03/2015 00:44:01;0040;PBS_Server;Svr;tyrone-cluster;Scheduler was sent the command new
01/03/2015 00:44:33;0040;PBS_Server;Svr;tyrone-cluster;Scheduler was sent the command new
01/03/2015 00:44:46;0002;PBS_Server;Svr;PBS_Server;Torque Server Version = 3.0.5, loglevel = 0
01/03/2015 00:45:03;0040;PBS_Server;Svr;tyrone-cluster;Scheduler was sent the command new
01/03/2015 00:45:31;0040;PBS_Server;Svr;tyrone-cluster;Scheduler was sent the command new
01/03/2015 00:46:03;0040;PBS_Server;Svr;tyrone-cluster;Scheduler was sent the command new
01/03/2015 00:46:34;0040;PBS_Server;Svr;tyrone-cluster;Scheduler was sent the command new
01/03/2015 00:46:48;0100;PBS_Server;Job;46401.tyrone-cluster;enqueuing into batch, state 1 hop 1
01/03/2015 00:46:48;0100;PBS_Server;Job;46401.tyrone-cluster;dequeuing from batch, state QUEUED
01/03/2015 00:46:48;0100;PBS_Server;Job;46401.tyrone-cluster;enqueuing into idqueue, state 1 hop 1
01/03/2015 00:46:48;0008;PBS_Server;Job;46401.tyrone-cluster;Job Queued at request of secparth@tyrone-cluster, owner = secparth@tyrone-cluster, job name = JOB11, queue = idqueue
01/03/2015 00:46:48;0040;PBS_Server;Svr;tyrone-cluster;Scheduler was sent the command new
01/03/2015 00:46:48;0008;PBS_Server;Job;46401.tyrone-cluster;Job Modified at request of Scheduler@tyrone-cluster
01/03/2015 00:46:48;0008;PBS_Server;Job;46401.tyrone-cluster;Job Run at request of Scheduler@tyrone-cluster
01/03/2015 00:46:48;0040;PBS_Server;Svr;tyrone-cluster;Scheduler was sent the command recyc
01/03/2015 00:46:48;000d;PBS_Server;Job;46401.tyrone-cluster;Not sending email: User does not want mail of this type.
01/03/2015 00:46:49;000d;PBS_Server;Job;46401.tyrone-cluster;Not sending email: User does not want mail of this type.
01/03/2015 00:46:49;0010;PBS_Server;Job;46401.tyrone-cluster;Exit_status=2 resources_used.cput=00:00:00 resources_used.mem=0kb resources_used.vmem=0kb resources_used.walltime=00:00:01
01/03/2015 00:46:49;0008;PBS_Server;Job;NULL;on_job_exit valid pjob: 0x12fe400 (substate=50)
01/03/2015 00:46:49;0008;PBS_Server;Job;NULL;on_job_exit valid pjob: 0x12fe400 (substate=51)
01/03/2015 00:46:49;0008;PBS_Server;Job;NULL;on_job_exit valid pjob: 0x12fe400 (substate=51)
01/03/2015 00:46:49;0008;PBS_Server;Job;NULL;on_job_exit valid pjob: 0x12fe400 (substate=53)
01/03/2015 00:46:49;0100;PBS_Server;Job;46401.tyrone-cluster;dequeuing from idqueue, state COMPLETE
01/03/2015 00:46:49;0040;PBS_Server;Svr;tyrone-cluster;Scheduler was sent the command term
01/03/2015 00:47:03;0040;PBS_Server;Svr;tyrone-cluster;Scheduler was sent the command new
01/03/2015 00:47:34;0040;PBS_Server;Svr;tyrone-cluster;Scheduler was sent the command new
01/03/2015 00:48:04;0040;PBS_Server;Svr;tyrone-cluster;Scheduler was sent the command new
01/03/2015 00:48:34;0040;PBS_Server;Svr;tyrone-cluster;Scheduler was sent the command new
01/03/2015 00:49:04;0040;PBS_Server;Svr;tyrone-cluster;Scheduler was sent the command new
01/03/2015 00:49:34;0040;PBS_Server;Svr;tyrone-cluster;Scheduler was sent the command new
01/03/2015 00:49:46;0002;PBS_Server;Svr;PBS_Server;Torque Server Version = 3.0.5, loglevel = 0
01/03/2015 00:49:57;0100;PBS_Server;Job;46402.tyrone-cluster;enqueuing into batch, state 1 hop 1
01/03/2015 00:49:57;0100;PBS_Server;Job;46402.tyrone-cluster;dequeuing from batch, state QUEUED
01/03/2015 00:49:57;0100;PBS_Server;Job;46402.tyrone-cluster;enqueuing into idqueue, state 1 hop 1
01/03/2015 00:49:57;0008;PBS_Server;Job;46402.tyrone-cluster;Job Queued at request of secparth@tyrone-cluster, owner = secparth@tyrone-cluster, job name = JOB11, queue = idqueue
01/03/2015 00:49:57;0040;PBS_Server;Svr;tyrone-cluster;Scheduler was sent the command new
01/03/2015 00:49:57;0008;PBS_Server;Job;46402.tyrone-cluster;Job Modified at request of Scheduler@tyrone-cluster
01/03/2015 00:49:57;0008;PBS_Server;Job;46402.tyrone-cluster;Job Run at request of Scheduler@tyrone-cluster
01/03/2015 00:49:58;0040;PBS_Server;Svr;tyrone-cluster;Scheduler was sent the command recyc
01/03/2015 00:49:58;000d;PBS_Server;Job;46402.tyrone-cluster;Not sending email: User does not want mail of this type.
01/03/2015 00:49:58;000d;PBS_Server;Job;46402.tyrone-cluster;Not sending email: User does not want mail of this type.
01/03/2015 00:49:58;0010;PBS_Server;Job;46402.tyrone-cluster;Exit_status=1 resources_used.cput=00:00:00 resources_used.mem=0kb resources_used.vmem=0kb resources_used.walltime=00:00:01
01/03/2015 00:49:58;0008;PBS_Server;Job;NULL;on_job_exit valid pjob: 0x12fe400 (substate=50)
01/03/2015 00:49:58;0008;PBS_Server;Job;NULL;on_job_exit valid pjob: 0x12fe400 (substate=51)
01/03/2015 00:49:58;0008;PBS_Server;Job;NULL;on_job_exit valid pjob: 0x12fe400 (substate=51)
01/03/2015 00:49:58;0008;PBS_Server;Job;NULL;on_job_exit valid pjob: 0x12fe400 (substate=53)
01/03/2015 00:49:58;0100;PBS_Server;Job;46402.tyrone-cluster;dequeuing from idqueue, state COMPLETE
01/03/2015 00:49:58;0040;PBS_Server;Svr;tyrone-cluster;Scheduler was sent the command term
01/03/2015 00:50:04;0040;PBS_Server;Svr;tyrone-cluster;Scheduler was sent the command new
01/03/2015 00:50:14;0100;PBS_Server;Job;46403.tyrone-cluster;enqueuing into batch, state 1 hop 1
01/03/2015 00:50:14;0100;PBS_Server;Job;46403.tyrone-cluster;dequeuing from batch, state QUEUED
01/03/2015 00:50:14;0100;PBS_Server;Job;46403.tyrone-cluster;enqueuing into idqueue, state 1 hop 1
01/03/2015 00:50:14;0008;PBS_Server;Job;46403.tyrone-cluster;Job Queued at request of secparth@tyrone-cluster, owner = secparth@tyrone-cluster, job name = JOB11, queue = idqueue
01/03/2015 00:50:14;0040;PBS_Server;Svr;tyrone-cluster;Scheduler was sent the command new
01/03/2015 00:50:15;0008;PBS_Server;Job;46403.tyrone-cluster;Job Modified at request of Scheduler@tyrone-cluster
01/03/2015 00:50:15;0008;PBS_Server;Job;46403.tyrone-cluster;Job Run at request of Scheduler@tyrone-cluster
01/03/2015 00:50:15;0040;PBS_Server;Svr;tyrone-cluster;Scheduler was sent the command recyc
01/03/2015 00:50:15;000d;PBS_Server;Job;46403.tyrone-cluster;Not sending email: User does not want mail of this type.
01/03/2015 00:50:15;000d;PBS_Server;Job;46403.tyrone-cluster;Not sending email: User does not want mail of this type.
01/03/2015 00:50:15;0010;PBS_Server;Job;46403.tyrone-cluster;Exit_status=1 resources_used.cput=00:00:00 resources_used.mem=0kb resources_used.vmem=0kb resources_used.walltime=00:00:00
01/03/2015 00:50:15;0008;PBS_Server;Job;NULL;on_job_exit valid pjob: 0x12fe400 (substate=50)
01/03/2015 00:50:15;0008;PBS_Server;Job;NULL;on_job_exit valid pjob: 0x12fe400 (substate=51)
01/03/2015 00:50:15;0008;PBS_Server;Job;NULL;on_job_exit valid pjob: 0x12fe400 (substate=51)
01/03/2015 00:50:15;0008;PBS_Server;Job;NULL;on_job_exit valid pjob: 0x12fe400 (substate=53)
01/03/2015 00:50:15;0100;PBS_Server;Job;46403.tyrone-cluster;dequeuing from idqueue, state COMPLETE
01/03/2015 00:50:15;0040;PBS_Server;Svr;tyrone-cluster;Scheduler was sent the command term
01/03/2015 00:50:34;0040;PBS_Server;Svr;tyrone-cluster;Scheduler was sent the command new
01/03/2015 00:51:05;0040;PBS_Server;Svr;tyrone-cluster;Scheduler was sent the command new
01/03/2015 00:51:35;0040;PBS_Server;Svr;tyrone-cluster;Scheduler was sent the command new
01/03/2015 00:52:05;0040;PBS_Server;Svr;tyrone-cluster;Scheduler was sent the command new
01/03/2015 00:52:35;0040;PBS_Server;Svr;tyrone-cluster;Scheduler was sent the command new
01/03/2015 00:53:05;0040;PBS_Server;Svr;tyrone-cluster;Scheduler was sent the command new
01/03/2015 00:53:35;0040;PBS_Server;Svr;tyrone-cluster;Scheduler was sent the command new
01/03/2015 00:54:05;0040;PBS_Server;Svr;tyrone-cluster;Scheduler was sent the command new
01/03/2015 00:54:35;0040;PBS_Server;Svr;tyrone-cluster;Scheduler was sent the command new
01/03/2015 00:54:46;0002;PBS_Server;Svr;PBS_Server;Torque Server Version = 3.0.5, loglevel = 0
01/03/2015 00:55:05;0040;PBS_Server;Svr;tyrone-cluster;Scheduler was sent the command new
01/03/2015 00:55:36;0040;PBS_Server;Svr;tyrone-cluster;Scheduler was sent the command new
01/03/2015 00:55:39;0100;PBS_Server;Job;46404.tyrone-cluster;enqueuing into batch, state 1 hop 1
01/03/2015 00:55:39;0100;PBS_Server;Job;46404.tyrone-cluster;dequeuing from batch, state QUEUED
01/03/2015 00:55:39;0100;PBS_Server;Job;46404.tyrone-cluster;enqueuing into idqueue, state 1 hop 1
01/03/2015 00:55:39;0008;PBS_Server;Job;46404.tyrone-cluster;Job Queued at request of secparth@tyrone-cluster, owner = secparth@tyrone-cluster, job name = JOB11, queue = idqueue
01/03/2015 00:55:39;0040;PBS_Server;Svr;tyrone-cluster;Scheduler was sent the command new
01/03/2015 00:55:39;0008;PBS_Server;Job;46404.tyrone-cluster;Job Modified at request of Scheduler@tyrone-cluster
01/03/2015 00:55:39;0008;PBS_Server;Job;46404.tyrone-cluster;Job Run at request of Scheduler@tyrone-cluster
01/03/2015 00:55:39;0040;PBS_Server;Svr;tyrone-cluster;Scheduler was sent the command recyc
01/03/2015 00:55:39;000d;PBS_Server;Job;46404.tyrone-cluster;Not sending email: User does not want mail of this type.
01/03/2015 00:55:40;000d;PBS_Server;Job;46404.tyrone-cluster;Not sending email: User does not want mail of this type.
01/03/2015 00:55:40;0010;PBS_Server;Job;46404.tyrone-cluster;Exit_status=0 resources_used.cput=00:00:00 resources_used.mem=0kb resources_used.vmem=0kb resources_used.walltime=00:00:01
01/03/2015 00:55:40;0008;PBS_Server;Job;NULL;on_job_exit valid pjob: 0x12fe400 (substate=50)
01/03/2015 00:55:40;0008;PBS_Server;Job;NULL;on_job_exit valid pjob: 0x12fe400 (substate=51)
01/03/2015 00:55:40;0008;PBS_Server;Job;NULL;on_job_exit valid pjob: 0x12fe400 (substate=51)
01/03/2015 00:55:40;0008;PBS_Server;Job;NULL;on_job_exit valid pjob: 0x12fe400 (substate=53)
01/03/2015 00:55:40;0100;PBS_Server;Job;46404.tyrone-cluster;dequeuing from idqueue, state COMPLETE
01/03/2015 00:55:40;0040;PBS_Server;Svr;tyrone-cluster;Scheduler was sent the command term
01/03/2015 00:56:06;0040;PBS_Server;Svr;tyrone-cluster;Scheduler was sent the command new
01/03/2015 00:56:36;0040;PBS_Server;Svr;tyrone-cluster;Scheduler was sent the command new
01/03/2015 00:57:06;0040;PBS_Server;Svr;tyrone-cluster;Scheduler was sent the command new
01/03/2015 00:57:36;0040;PBS_Server;Svr;tyrone-cluster;Scheduler was sent the command new
01/03/2015 00:58:06;0040;PBS_Server;Svr;tyrone-cluster;Scheduler was sent the command new
01/03/2015 00:58:36;0040;PBS_Server;Svr;tyrone-cluster;Scheduler was sent the command new
01/03/2015 00:59:06;0040;PBS_Server;Svr;tyrone-cluster;Scheduler was sent the command new
01/03/2015 00:59:36;0040;PBS_Server;Svr;tyrone-cluster;Scheduler was sent the command new
01/03/2015 00:59:46;0002;PBS_Server;Svr;PBS_Server;Torque Server Version = 3.0.5, loglevel = 0
01/03/2015 01:00:07;0040;PBS_Server;Svr;tyrone-cluster;Scheduler was sent the command new
01/03/2015 01:00:37;0040;PBS_Server;Svr;tyrone-cluster;Scheduler was sent the command new
01/03/2015 01:01:07;0040;PBS_Server;Svr;tyrone-cluster;Scheduler was sent the command new
01/03/2015 01:01:37;0040;PBS_Server;Svr;tyrone-cluster;Scheduler was sent the command new
01/03/2015 01:02:07;0040;PBS_Server;Svr;tyrone-cluster;Scheduler was sent the command new
01/03/2015 01:02:37;0040;PBS_Server;Svr;tyrone-cluster;Scheduler was sent the command new
01/03/2015 01:03:07;0040;PBS_Server;Svr;tyrone-cluster;Scheduler was sent the command new
01/03/2015 01:03:37;0040;PBS_Server;Svr;tyrone-cluster;Scheduler was sent the command new
01/03/2015 01:03:49;0100;PBS_Server;Job;46405.tyrone-cluster;enqueuing into batch, state 1 hop 1
01/03/2015 01:03:49;0100;PBS_Server;Job;46405.tyrone-cluster;dequeuing from batch, state QUEUED
01/03/2015 01:03:49;0100;PBS_Server;Job;46405.tyrone-cluster;enqueuing into idqueue, state 1 hop 1
01/03/2015 01:03:49;0008;PBS_Server;Job;46405.tyrone-cluster;Job Queued at request of secparth@tyrone-cluster, owner = secparth@tyrone-cluster, job name = JOB11, queue = idqueue
01/03/2015 01:03:49;0040;PBS_Server;Svr;tyrone-cluster;Scheduler was sent the command new
01/03/2015 01:03:49;0008;PBS_Server;Job;46405.tyrone-cluster;Job Modified at request of Scheduler@tyrone-cluster
01/03/2015 01:03:49;0008;PBS_Server;Job;46405.tyrone-cluster;Job Run at request of Scheduler@tyrone-cluster
01/03/2015 01:03:49;0040;PBS_Server;Svr;tyrone-cluster;Scheduler was sent the command recyc
01/03/2015 01:03:49;000d;PBS_Server;Job;46405.tyrone-cluster;Not sending email: User does not want mail of this type.
01/03/2015 01:03:52;000d;PBS_Server;Job;46405.tyrone-cluster;Not sending email: User does not want mail of this type.
01/03/2015 01:03:52;0010;PBS_Server;Job;46405.tyrone-cluster;Exit_status=0 resources_used.cput=00:00:00 resources_used.mem=0kb resources_used.vmem=0kb resources_used.walltime=00:00:02
01/03/2015 01:03:52;0008;PBS_Server;Job;NULL;on_job_exit valid pjob: 0x12fe400 (substate=50)
01/03/2015 01:03:52;0008;PBS_Server;Job;NULL;on_job_exit valid pjob: 0x12fe400 (substate=51)
01/03/2015 01:03:52;0008;PBS_Server;Job;NULL;on_job_exit valid pjob: 0x12fe400 (substate=51)
01/03/2015 01:03:52;0008;PBS_Server;Job;NULL;on_job_exit valid pjob: 0x12fe400 (substate=53)
01/03/2015 01:03:52;0100;PBS_Server;Job;46405.tyrone-cluster;dequeuing from idqueue, state COMPLETE
01/03/2015 01:03:52;0040;PBS_Server;Svr;tyrone-cluster;Scheduler was sent the command term
01/03/2015 01:04:07;0040;PBS_Server;Svr;tyrone-cluster;Scheduler was sent the command new
01/03/2015 01:04:38;0040;PBS_Server;Svr;tyrone-cluster;Scheduler was sent the command new
01/03/2015 01:04:46;0002;PBS_Server;Svr;PBS_Server;Torque Server Version = 3.0.5, loglevel = 0
01/03/2015 01:05:08;0040;PBS_Server;Svr;tyrone-cluster;Scheduler was sent the command new
01/03/2015 01:05:38;0040;PBS_Server;Svr;tyrone-cluster;Scheduler was sent the command new
01/03/2015 01:06:08;0040;PBS_Server;Svr;tyrone-cluster;Scheduler was sent the command new
01/03/2015 01:06:38;0040;PBS_Server;Svr;tyrone-cluster;Scheduler was sent the command new
01/03/2015 01:07:08;0040;PBS_Server;Svr;tyrone-cluster;Scheduler was sent the command new
01/03/2015 01:07:38;0040;PBS_Server;Svr;tyrone-cluster;Scheduler was sent the command new
01/03/2015 01:08:08;0040;PBS_Server;Svr;tyrone-cluster;Scheduler was sent the command new
01/03/2015 01:08:38;0040;PBS_Server;Svr;tyrone-cluster;Scheduler was sent the command new
01/03/2015 01:09:09;0040;PBS_Server;Svr;tyrone-cluster;Scheduler was sent the command new
01/03/2015 01:09:38;0040;PBS_Server;Svr;tyrone-cluster;Scheduler was sent the command new
01/03/2015 01:09:46;0002;PBS_Server;Svr;PBS_Server;Torque Server Version = 3.0.5, loglevel = 0
01/03/2015 01:10:09;0040;PBS_Server;Svr;tyrone-cluster;Scheduler was sent the command new
01/03/2015 01:10:39;0040;PBS_Server;Svr;tyrone-cluster;Scheduler was sent the command new
01/03/2015 01:11:08;0040;PBS_Server;Svr;tyrone-cluster;Scheduler was sent the command new
01/03/2015 01:11:39;0040;PBS_Server;Svr;tyrone-cluster;Scheduler was sent the command new
01/03/2015 01:12:09;0040;PBS_Server;Svr;tyrone-cluster;Scheduler was sent the command new
01/03/2015 01:12:39;0040;PBS_Server;Svr;tyrone-cluster;Scheduler was sent the command new
01/03/2015 01:13:09;0040;PBS_Server;Svr;tyrone-cluster;Scheduler was sent the command new
01/03/2015 01:13:40;0040;PBS_Server;Svr;tyrone-cluster;Scheduler was sent the command new
01/03/2015 01:14:10;0040;PBS_Server;Svr;tyrone-cluster;Scheduler was sent the command new
01/03/2015 01:14:40;0040;PBS_Server;Svr;tyrone-cluster;Scheduler was sent the command new
01/03/2015 01:14:46;0002;PBS_Server;Svr;PBS_Server;Torque Server Version = 3.0.5, loglevel = 0
01/03/2015 01:15:10;0040;PBS_Server;Svr;tyrone-cluster;Scheduler was sent the command new
01/03/2015 01:15:40;0040;PBS_Server;Svr;tyrone-cluster;Scheduler was sent the command new
01/03/2015 01:16:10;0040;PBS_Server;Svr;tyrone-cluster;Scheduler was sent the command new
01/03/2015 01:16:40;0040;PBS_Server;Svr;tyrone-cluster;Scheduler was sent the command new
01/03/2015 01:17:10;0040;PBS_Server;Svr;tyrone-cluster;Scheduler was sent the command new
01/03/2015 01:17:40;0040;PBS_Server;Svr;tyrone-cluster;Scheduler was sent the command new
01/03/2015 01:18:10;0040;PBS_Server;Svr;tyrone-cluster;Scheduler was sent the command new
01/03/2015 01:18:41;0040;PBS_Server;Svr;tyrone-cluster;Scheduler was sent the command new
01/03/2015 01:19:11;0040;PBS_Server;Svr;tyrone-cluster;Scheduler was sent the command new
01/03/2015 01:19:41;0040;PBS_Server;Svr;tyrone-cluster;Scheduler was sent the command new
01/03/2015 01:19:46;0002;PBS_Server;Svr;PBS_Server;Torque Server Version = 3.0.5, loglevel = 0
01/03/2015 01:20:11;0040;PBS_Server;Svr;tyrone-cluster;Scheduler was sent the command new
01/03/2015 01:20:41;0040;PBS_Server;Svr;tyrone-cluster;Scheduler was sent the command new
01/03/2015 01:21:11;0040;PBS_Server;Svr;tyrone-cluster;Scheduler was sent the command new
01/03/2015 01:21:42;0040;PBS_Server;Svr;tyrone-cluster;Scheduler was sent the command new
01/03/2015 01:22:12;0040;PBS_Server;Svr;tyrone-cluster;Scheduler was sent the command new
01/03/2015 01:22:42;0040;PBS_Server;Svr;tyrone-cluster;Scheduler was sent the command new
01/03/2015 01:23:12;0040;PBS_Server;Svr;tyrone-cluster;Scheduler was sent the command new
01/03/2015 01:23:42;0040;PBS_Server;Svr;tyrone-cluster;Scheduler was sent the command new
01/03/2015 01:24:12;0040;PBS_Server;Svr;tyrone-cluster;Scheduler was sent the command new
01/03/2015 01:24:42;0040;PBS_Server;Svr;tyrone-cluster;Scheduler was sent the command new
01/03/2015 01:24:46;0002;PBS_Server;Svr;PBS_Server;Torque Server Version = 3.0.5, loglevel = 0
01/03/2015 01:25:12;0040;PBS_Server;Svr;tyrone-cluster;Scheduler was sent the command new
01/03/2015 01:25:42;0040;PBS_Server;Svr;tyrone-cluster;Scheduler was sent the command new
01/03/2015 01:26:12;0040;PBS_Server;Svr;tyrone-cluster;Scheduler was sent the command new
01/03/2015 01:26:43;0040;PBS_Server;Svr;tyrone-cluster;Scheduler was sent the command new
01/03/2015 01:27:12;0040;PBS_Server;Svr;tyrone-cluster;Scheduler was sent the command new
01/03/2015 01:27:43;0040;PBS_Server;Svr;tyrone-cluster;Scheduler was sent the command new
01/03/2015 01:28:13;0040;PBS_Server;Svr;tyrone-cluster;Scheduler was sent the command new
01/03/2015 01:28:43;0040;PBS_Server;Svr;tyrone-cluster;Scheduler was sent the command new
01/03/2015 01:29:13;0040;PBS_Server;Svr;tyrone-cluster;Scheduler was sent the command new
01/03/2015 01:29:43;0040;PBS_Server;Svr;tyrone-cluster;Scheduler was sent the command new
01/03/2015 01:29:46;0002;PBS_Server;Svr;PBS_Server;Torque Server Version = 3.0.5, loglevel = 0
01/03/2015 01:30:13;0040;PBS_Server;Svr;tyrone-cluster;Scheduler was sent the command new
01/03/2015 01:30:43;0040;PBS_Server;Svr;tyrone-cluster;Scheduler was sent the command new
01/03/2015 01:31:14;0040;PBS_Server;Svr;tyrone-cluster;Scheduler was sent the command new
01/03/2015 01:31:44;0040;PBS_Server;Svr;tyrone-cluster;Scheduler was sent the command new
01/03/2015 01:32:14;0040;PBS_Server;Svr;tyrone-cluster;Scheduler was sent the command new
01/03/2015 01:32:44;0040;PBS_Server;Svr;tyrone-cluster;Scheduler was sent the command new
01/03/2015 01:33:14;0040;PBS_Server;Svr;tyrone-cluster;Scheduler was sent the command new
01/03/2015 01:33:44;0040;PBS_Server;Svr;tyrone-cluster;Scheduler was sent the command new
01/03/2015 01:34:14;0040;PBS_Server;Svr;tyrone-cluster;Scheduler was sent the command new
01/03/2015 01:34:44;0040;PBS_Server;Svr;tyrone-cluster;Scheduler was sent the command new
01/03/2015 01:34:46;0002;PBS_Server;Svr;PBS_Server;Torque Server Version = 3.0.5, loglevel = 0
01/03/2015 01:35:14;0040;PBS_Server;Svr;tyrone-cluster;Scheduler was sent the command new
01/03/2015 01:35:44;0040;PBS_Server;Svr;tyrone-cluster;Scheduler was sent the command new
01/03/2015 01:36:15;0040;PBS_Server;Svr;tyrone-cluster;Scheduler was sent the command new
01/03/2015 01:36:45;0040;PBS_Server;Svr;tyrone-cluster;Scheduler was sent the command new
01/03/2015 01:37:15;0040;PBS_Server;Svr;tyrone-cluster;Scheduler was sent the command new
01/03/2015 01:37:45;0040;PBS_Server;Svr;tyrone-cluster;Scheduler was sent the command new
01/03/2015 01:38:15;0040;PBS_Server;Svr;tyrone-cluster;Scheduler was sent the command new
01/03/2015 01:38:45;0040;PBS_Server;Svr;tyrone-cluster;Scheduler was sent the command new
01/03/2015 01:39:15;0040;PBS_Server;Svr;tyrone-cluster;Scheduler was sent the command new
01/03/2015 01:39:45;0040;PBS_Server;Svr;tyrone-cluster;Scheduler was sent the command new
01/03/2015 01:39:47;0002;PBS_Server;Svr;PBS_Server;Torque Server Version = 3.0.5, loglevel = 0
01/03/2015 01:40:15;0040;PBS_Server;Svr;tyrone-cluster;Scheduler was sent the command new
01/03/2015 01:40:46;0040;PBS_Server;Svr;tyrone-cluster;Scheduler was sent the command new
01/03/2015 01:41:16;0040;PBS_Server;Svr;tyrone-cluster;Scheduler was sent the command new
01/03/2015 01:41:46;0040;PBS_Server;Svr;tyrone-cluster;Scheduler was sent the command new
01/03/2015 01:42:16;0040;PBS_Server;Svr;tyrone-cluster;Scheduler was sent the command new
01/03/2015 01:42:46;0040;PBS_Server;Svr;tyrone-cluster;Scheduler was sent the command new
01/03/2015 01:43:16;0040;PBS_Server;Svr;tyrone-cluster;Scheduler was sent the command new
01/03/2015 01:43:46;0040;PBS_Server;Svr;tyrone-cluster;Scheduler was sent the command new
01/03/2015 01:44:16;0040;PBS_Server;Svr;tyrone-cluster;Scheduler was sent the command new
01/03/2015 01:44:46;0040;PBS_Server;Svr;tyrone-cluster;Scheduler was sent the command new
01/03/2015 01:44:47;0002;PBS_Server;Svr;PBS_Server;Torque Server Version = 3.0.5, loglevel = 0
01/03/2015 01:45:16;0040;PBS_Server;Svr;tyrone-cluster;Scheduler was sent the command new
01/03/2015 01:45:46;0040;PBS_Server;Svr;tyrone-cluster;Scheduler was sent the command new
01/03/2015 01:46:16;0040;PBS_Server;Svr;tyrone-cluster;Scheduler was sent the command new
01/03/2015 01:46:47;0040;PBS_Server;Svr;tyrone-cluster;Scheduler was sent the command new
01/03/2015 01:47:17;0040;PBS_Server;Svr;tyrone-cluster;Scheduler was sent the command new
01/03/2015 01:47:47;0040;PBS_Server;Svr;tyrone-cluster;Scheduler was sent the command new
01/03/2015 01:48:17;0040;PBS_Server;Svr;tyrone-cluster;Scheduler was sent the command new
01/03/2015 01:48:47;0040;PBS_Server;Svr;tyrone-cluster;Scheduler was sent the command new
01/03/2015 01:49:17;0040;PBS_Server;Svr;tyrone-cluster;Scheduler was sent the command new
01/03/2015 01:49:47;0002;PBS_Server;Svr;PBS_Server;Torque Server Version = 3.0.5, loglevel = 0
01/03/2015 01:49:47;0040;PBS_Server;Svr;tyrone-cluster;Scheduler was sent the command new
01/03/2015 01:50:18;0040;PBS_Server;Svr;tyrone-cluster;Scheduler was sent the command new
01/03/2015 01:50:48;0040;PBS_Server;Svr;tyrone-cluster;Scheduler was sent the command new
01/03/2015 01:51:18;0040;PBS_Server;Svr;tyrone-cluster;Scheduler was sent the command new
01/03/2015 01:51:48;0040;PBS_Server;Svr;tyrone-cluster;Scheduler was sent the command new
01/03/2015 01:52:18;0040;PBS_Server;Svr;tyrone-cluster;Scheduler was sent the command new
01/03/2015 01:52:48;0040;PBS_Server;Svr;tyrone-cluster;Scheduler was sent the command new
01/03/2015 01:53:18;0040;PBS_Server;Svr;tyrone-cluster;Scheduler was sent the command new
01/03/2015 01:53:48;0040;PBS_Server;Svr;tyrone-cluster;Scheduler was sent the command new
01/03/2015 01:54:18;0040;PBS_Server;Svr;tyrone-cluster;Scheduler was sent the command new
01/03/2015 01:54:47;0002;PBS_Server;Svr;PBS_Server;Torque Server Version = 3.0.5, loglevel = 0
01/03/2015 01:54:48;0040;PBS_Server;Svr;tyrone-cluster;Scheduler was sent the command new
01/03/2015 01:55:18;0040;PBS_Server;Svr;tyrone-cluster;Scheduler was sent the command new
01/03/2015 01:55:49;0040;PBS_Server;Svr;tyrone-cluster;Scheduler was sent the command new
01/03/2015 01:56:19;0040;PBS_Server;Svr;tyrone-cluster;Scheduler was sent the command new
01/03/2015 01:56:49;0040;PBS_Server;Svr;tyrone-cluster;Scheduler was sent the command new
01/03/2015 01:57:19;0040;PBS_Server;Svr;tyrone-cluster;Scheduler was sent the command new
01/03/2015 01:57:49;0040;PBS_Server;Svr;tyrone-cluster;Scheduler was sent the command new
01/03/2015 01:58:19;0040;PBS_Server;Svr;tyrone-cluster;Scheduler was sent the command new
01/03/2015 01:58:49;0040;PBS_Server;Svr;tyrone-cluster;Scheduler was sent the command new
01/03/2015 01:59:19;0040;PBS_Server;Svr;tyrone-cluster;Scheduler was sent the command new
01/03/2015 01:59:47;0002;PBS_Server;Svr;PBS_Server;Torque Server Version = 3.0.5, loglevel = 0
01/03/2015 01:59:49;0040;PBS_Server;Svr;tyrone-cluster;Scheduler was sent the command new
01/03/2015 02:00:20;0040;PBS_Server;Svr;tyrone-cluster;Scheduler was sent the command new
01/03/2015 02:00:50;0040;PBS_Server;Svr;tyrone-cluster;Scheduler was sent the command new
01/03/2015 02:01:20;0040;PBS_Server;Svr;tyrone-cluster;Scheduler was sent the command new
01/03/2015 02:01:50;0040;PBS_Server;Svr;tyrone-cluster;Scheduler was sent the command new
01/03/2015 02:02:20;0040;PBS_Server;Svr;tyrone-cluster;Scheduler was sent the command new
01/03/2015 02:02:50;0040;PBS_Server;Svr;tyrone-cluster;Scheduler was sent the command new
01/03/2015 02:03:20;0040;PBS_Server;Svr;tyrone-cluster;Scheduler was sent the command new
01/03/2015 02:03:50;0040;PBS_Server;Svr;tyrone-cluster;Scheduler was sent the command new
01/03/2015 02:04:20;0040;PBS_Server;Svr;tyrone-cluster;Scheduler was sent the command new
01/03/2015 02:04:47;0002;PBS_Server;Svr;PBS_Server;Torque Server Version = 3.0.5, loglevel = 0
01/03/2015 02:04:50;0040;PBS_Server;Svr;tyrone-cluster;Scheduler was sent the command new
01/03/2015 02:05:21;0040;PBS_Server;Svr;tyrone-cluster;Scheduler was sent the command new
01/03/2015 02:05:51;0040;PBS_Server;Svr;tyrone-cluster;Scheduler was sent the command new
01/03/2015 02:06:21;0040;PBS_Server;Svr;tyrone-cluster;Scheduler was sent the command new
01/03/2015 02:06:51;0040;PBS_Server;Svr;tyrone-cluster;Scheduler was sent the command new
01/03/2015 02:07:21;0040;PBS_Server;Svr;tyrone-cluster;Scheduler was sent the command new
01/03/2015 02:07:51;0040;PBS_Server;Svr;tyrone-cluster;Scheduler was sent the command new
01/03/2015 02:08:21;0040;PBS_Server;Svr;tyrone-cluster;Scheduler was sent the command new
01/03/2015 02:08:51;0040;PBS_Server;Svr;tyrone-cluster;Scheduler was sent the command new
01/03/2015 02:09:21;0040;PBS_Server;Svr;tyrone-cluster;Scheduler was sent the command new
01/03/2015 02:09:47;0002;PBS_Server;Svr;PBS_Server;Torque Server Version = 3.0.5, loglevel = 0
01/03/2015 02:09:52;0040;PBS_Server;Svr;tyrone-cluster;Scheduler was sent the command new
01/03/2015 02:10:22;0040;PBS_Server;Svr;tyrone-cluster;Scheduler was sent the command new
01/03/2015 02:10:52;0040;PBS_Server;Svr;tyrone-cluster;Scheduler was sent the command new
01/03/2015 02:11:22;0040;PBS_Server;Svr;tyrone-cluster;Scheduler was sent the command new
01/03/2015 02:11:52;0040;PBS_Server;Svr;tyrone-cluster;Scheduler was sent the command new
01/03/2015 02:12:22;0040;PBS_Server;Svr;tyrone-cluster;Scheduler was sent the command new
01/03/2015 02:12:52;0040;PBS_Server;Svr;tyrone-cluster;Scheduler was sent the command new
01/03/2015 02:13:22;0040;PBS_Server;Svr;tyrone-cluster;Scheduler was sent the command new
01/03/2015 02:13:52;0040;PBS_Server;Svr;tyrone-cluster;Scheduler was sent the command new
01/03/2015 02:14:22;0040;PBS_Server;Svr;tyrone-cluster;Scheduler was sent the command new
01/03/2015 02:14:47;0002;PBS_Server;Svr;PBS_Server;Torque Server Version = 3.0.5, loglevel = 0
01/03/2015 02:14:53;0040;PBS_Server;Svr;tyrone-cluster;Scheduler was sent the command new
01/03/2015 02:15:23;0040;PBS_Server;Svr;tyrone-cluster;Scheduler was sent the command new
01/03/2015 02:15:53;0040;PBS_Server;Svr;tyrone-cluster;Scheduler was sent the command new
01/03/2015 02:16:23;0040;PBS_Server;Svr;tyrone-cluster;Scheduler was sent the command new
01/03/2015 02:16:53;0040;PBS_Server;Svr;tyrone-cluster;Scheduler was sent the command new
01/03/2015 02:17:23;0040;PBS_Server;Svr;tyrone-cluster;Scheduler was sent the command new
01/03/2015 02:17:53;0040;PBS_Server;Svr;tyrone-cluster;Scheduler was sent the command new
01/03/2015 02:18:23;0040;PBS_Server;Svr;tyrone-cluster;Scheduler was sent the command new
01/03/2015 02:18:53;0040;PBS_Server;Svr;tyrone-cluster;Scheduler was sent the command new
01/03/2015 02:19:23;0040;PBS_Server;Svr;tyrone-cluster;Scheduler was sent the command new
01/03/2015 02:19:47;0002;PBS_Server;Svr;PBS_Server;Torque Server Version = 3.0.5, loglevel = 0
01/03/2015 02:19:54;0040;PBS_Server;Svr;tyrone-cluster;Scheduler was sent the command new
01/03/2015 02:20:24;0040;PBS_Server;Svr;tyrone-cluster;Scheduler was sent the command new
01/03/2015 02:20:54;0040;PBS_Server;Svr;tyrone-cluster;Scheduler was sent the command new
01/03/2015 02:21:24;0040;PBS_Server;Svr;tyrone-cluster;Scheduler was sent the command new
01/03/2015 02:21:54;0040;PBS_Server;Svr;tyrone-cluster;Scheduler was sent the command new
01/03/2015 02:22:24;0040;PBS_Server;Svr;tyrone-cluster;Scheduler was sent the command new
01/03/2015 02:22:54;0040;PBS_Server;Svr;tyrone-cluster;Scheduler was sent the command new
01/03/2015 02:23:24;0040;PBS_Server;Svr;tyrone-cluster;Scheduler was sent the command new
01/03/2015 02:23:54;0040;PBS_Server;Svr;tyrone-cluster;Scheduler was sent the command new
01/03/2015 02:24:25;0040;PBS_Server;Svr;tyrone-cluster;Scheduler was sent the command new
01/03/2015 02:24:47;0002;PBS_Server;Svr;PBS_Server;Torque Server Version = 3.0.5, loglevel = 0
01/03/2015 02:24:55;0040;PBS_Server;Svr;tyrone-cluster;Scheduler was sent the command new
01/03/2015 02:25:20;000d;PBS_Server;Job;46197.tyrone-cluster;Not sending email: User does not want mail of this type.
01/03/2015 02:25:20;0010;PBS_Server;Job;46197.tyrone-cluster;Exit_status=271 resources_used.cput=1534:45:12 resources_used.mem=2630344kb resources_used.vmem=36290072kb resources_used.walltime=24:00:37
01/03/2015 02:25:20;0008;PBS_Server;Job;NULL;on_job_exit valid pjob: 0x12f5730 (substate=50)
01/03/2015 02:25:20;0008;PBS_Server;Job;NULL;on_job_exit valid pjob: 0x12f5730 (substate=51)
01/03/2015 02:25:24;0100;PBS_Server;Job;46199.tyrone-cluster;dequeuing from batch, state QUEUED
01/03/2015 02:25:24;0100;PBS_Server;Job;46199.tyrone-cluster;enqueuing into qp256, state 1 hop 1
01/03/2015 02:25:24;0040;PBS_Server;Svr;tyrone-cluster;Scheduler was sent the command new
01/03/2015 02:25:24;0008;PBS_Server;Job;46290.tyrone-cluster;Job Modified at request of Scheduler@tyrone-cluster
01/03/2015 02:25:24;0008;PBS_Server;Job;46192.tyrone-cluster;Job Modified at request of Scheduler@tyrone-cluster
01/03/2015 02:25:24;0008;PBS_Server;Job;46190.tyrone-cluster;Job Modified at request of Scheduler@tyrone-cluster
01/03/2015 02:25:24;0008;PBS_Server;Job;46198.tyrone-cluster;Job Modified at request of Scheduler@tyrone-cluster
01/03/2015 02:25:24;0008;PBS_Server;Job;46193.tyrone-cluster;Job Modified at request of Scheduler@tyrone-cluster
01/03/2015 02:25:24;0008;PBS_Server;Job;46199.tyrone-cluster;Job Modified at request of Scheduler@tyrone-cluster
01/03/2015 02:25:28;0008;PBS_Server;Job;NULL;on_job_exit valid pjob: 0x12f5730 (substate=51)
01/03/2015 02:25:28;0008;PBS_Server;Job;NULL;on_job_exit valid pjob: 0x12f5730 (substate=53)
01/03/2015 02:25:28;0100;PBS_Server;Job;46197.tyrone-cluster;dequeuing from qp256, state COMPLETE
01/03/2015 02:25:28;0040;PBS_Server;Svr;tyrone-cluster;Scheduler was sent the command term
01/03/2015 02:25:28;0008;PBS_Server;Job;46290.tyrone-cluster;Job Modified at request of Scheduler@tyrone-cluster
01/03/2015 02:25:28;0008;PBS_Server;Job;46290.tyrone-cluster;Job Run at request of Scheduler@tyrone-cluster
01/03/2015 02:25:28;0008;PBS_Server;Job;46192.tyrone-cluster;Job Modified at request of Scheduler@tyrone-cluster
01/03/2015 02:25:28;0008;PBS_Server;Job;46190.tyrone-cluster;Job Modified at request of Scheduler@tyrone-cluster
01/03/2015 02:25:28;0008;PBS_Server;Job;46198.tyrone-cluster;Job Modified at request of Scheduler@tyrone-cluster
01/03/2015 02:25:28;0008;PBS_Server;Job;46193.tyrone-cluster;Job Modified at request of Scheduler@tyrone-cluster
01/03/2015 02:25:28;0008;PBS_Server;Job;46199.tyrone-cluster;Job Modified at request of Scheduler@tyrone-cluster
01/03/2015 02:25:28;0040;PBS_Server;Svr;tyrone-cluster;Scheduler was sent the command recyc
01/03/2015 02:25:37;000d;PBS_Server;Job;46290.tyrone-cluster;Not sending email: User does not want mail of this type.
01/03/2015 02:25:55;0040;PBS_Server;Svr;tyrone-cluster;Scheduler was sent the command new
01/03/2015 02:26:25;0040;PBS_Server;Svr;tyrone-cluster;Scheduler was sent the command new
01/03/2015 02:26:54;0040;PBS_Server;Svr;tyrone-cluster;Scheduler was sent the command new
01/03/2015 02:27:25;0040;PBS_Server;Svr;tyrone-cluster;Scheduler was sent the command new
01/03/2015 02:27:55;0040;PBS_Server;Svr;tyrone-cluster;Scheduler was sent the command new
01/03/2015 02:28:24;0040;PBS_Server;Svr;tyrone-cluster;Scheduler was sent the command new
01/03/2015 02:28:56;0040;PBS_Server;Svr;tyrone-cluster;Scheduler was sent the command new
01/03/2015 02:29:26;0040;PBS_Server;Svr;tyrone-cluster;Scheduler was sent the command new
01/03/2015 02:29:47;0002;PBS_Server;Svr;PBS_Server;Torque Server Version = 3.0.5, loglevel = 0
01/03/2015 02:29:54;0040;PBS_Server;Svr;tyrone-cluster;Scheduler was sent the command new
01/03/2015 02:30:26;0040;PBS_Server;Svr;tyrone-cluster;Scheduler was sent the command new
01/03/2015 02:30:56;0040;PBS_Server;Svr;tyrone-cluster;Scheduler was sent the command new
01/03/2015 02:31:24;0040;PBS_Server;Svr;tyrone-cluster;Scheduler was sent the command new
01/03/2015 02:31:56;0040;PBS_Server;Svr;tyrone-cluster;Scheduler was sent the command new
01/03/2015 02:32:26;0040;PBS_Server;Svr;tyrone-cluster;Scheduler was sent the command new
01/03/2015 02:32:54;0040;PBS_Server;Svr;tyrone-cluster;Scheduler was sent the command new
01/03/2015 02:33:27;0040;PBS_Server;Svr;tyrone-cluster;Scheduler was sent the command new
01/03/2015 02:33:56;0040;PBS_Server;Svr;tyrone-cluster;Scheduler was sent the command new
01/03/2015 02:34:24;0040;PBS_Server;Svr;tyrone-cluster;Scheduler was sent the command new
01/03/2015 02:34:47;0002;PBS_Server;Svr;PBS_Server;Torque Server Version = 3.0.5, loglevel = 0
01/03/2015 02:34:57;0040;PBS_Server;Svr;tyrone-cluster;Scheduler was sent the command new
01/03/2015 02:35:26;0040;PBS_Server;Svr;tyrone-cluster;Scheduler was sent the command new
01/03/2015 02:35:54;0040;PBS_Server;Svr;tyrone-cluster;Scheduler was sent the command new
01/03/2015 02:36:27;0040;PBS_Server;Svr;tyrone-cluster;Scheduler was sent the command new
01/03/2015 02:36:56;0040;PBS_Server;Svr;tyrone-cluster;Scheduler was sent the command new
01/03/2015 02:37:24;0040;PBS_Server;Svr;tyrone-cluster;Scheduler was sent the command new
01/03/2015 02:37:57;0040;PBS_Server;Svr;tyrone-cluster;Scheduler was sent the command new
01/03/2015 02:38:26;0040;PBS_Server;Svr;tyrone-cluster;Scheduler was sent the command new
01/03/2015 02:38:58;0040;PBS_Server;Svr;tyrone-cluster;Scheduler was sent the command new
01/03/2015 02:39:28;0040;PBS_Server;Svr;tyrone-cluster;Scheduler was sent the command new
01/03/2015 02:39:47;0002;PBS_Server;Svr;PBS_Server;Torque Server Version = 3.0.5, loglevel = 0
01/03/2015 02:39:58;0040;PBS_Server;Svr;tyrone-cluster;Scheduler was sent the command new
01/03/2015 02:40:28;0040;PBS_Server;Svr;tyrone-cluster;Scheduler was sent the command new
01/03/2015 02:40:58;0040;PBS_Server;Svr;tyrone-cluster;Scheduler was sent the command new
01/03/2015 02:41:28;0040;PBS_Server;Svr;tyrone-cluster;Scheduler was sent the command new
01/03/2015 02:41:58;0040;PBS_Server;Svr;tyrone-cluster;Scheduler was sent the command new
01/03/2015 02:42:28;0040;PBS_Server;Svr;tyrone-cluster;Scheduler was sent the command new
01/03/2015 02:42:58;0040;PBS_Server;Svr;tyrone-cluster;Scheduler was sent the command new
01/03/2015 02:43:29;0040;PBS_Server;Svr;tyrone-cluster;Scheduler was sent the command new
01/03/2015 02:43:59;0040;PBS_Server;Svr;tyrone-cluster;Scheduler was sent the command new
01/03/2015 02:44:28;0040;PBS_Server;Svr;tyrone-cluster;Scheduler was sent the command new
01/03/2015 02:44:47;0002;PBS_Server;Svr;PBS_Server;Torque Server Version = 3.0.5, loglevel = 0
01/03/2015 02:44:59;0040;PBS_Server;Svr;tyrone-cluster;Scheduler was sent the command new
01/03/2015 02:45:29;0040;PBS_Server;Svr;tyrone-cluster;Scheduler was sent the command new
01/03/2015 02:45:58;0040;PBS_Server;Svr;tyrone-cluster;Scheduler was sent the command new
01/03/2015 02:46:29;0040;PBS_Server;Svr;tyrone-cluster;Scheduler was sent the command new
01/03/2015 02:46:59;0040;PBS_Server;Svr;tyrone-cluster;Scheduler was sent the command new
01/03/2015 02:47:28;0040;PBS_Server;Svr;tyrone-cluster;Scheduler was sent the command new
01/03/2015 02:47:59;0040;PBS_Server;Svr;tyrone-cluster;Scheduler was sent the command new
01/03/2015 02:48:30;0040;PBS_Server;Svr;tyrone-cluster;Scheduler was sent the command new
01/03/2015 02:49:00;0040;PBS_Server;Svr;tyrone-cluster;Scheduler was sent the command new
01/03/2015 02:49:30;0040;PBS_Server;Svr;tyrone-cluster;Scheduler was sent the command new
01/03/2015 02:49:47;0002;PBS_Server;Svr;PBS_Server;Torque Server Version = 3.0.5, loglevel = 0
01/03/2015 02:50:00;0040;PBS_Server;Svr;tyrone-cluster;Scheduler was sent the command new
01/03/2015 02:50:30;0040;PBS_Server;Svr;tyrone-cluster;Scheduler was sent the command new
01/03/2015 02:51:00;0040;PBS_Server;Svr;tyrone-cluster;Scheduler was sent the command new
01/03/2015 02:51:30;0040;PBS_Server;Svr;tyrone-cluster;Scheduler was sent the command new
01/03/2015 02:52:00;0040;PBS_Server;Svr;tyrone-cluster;Scheduler was sent the command new
01/03/2015 02:52:31;0040;PBS_Server;Svr;tyrone-cluster;Scheduler was sent the command new
01/03/2015 02:53:01;0040;PBS_Server;Svr;tyrone-cluster;Scheduler was sent the command new
01/03/2015 02:53:31;0040;PBS_Server;Svr;tyrone-cluster;Scheduler was sent the command new
01/03/2015 02:54:01;0040;PBS_Server;Svr;tyrone-cluster;Scheduler was sent the command new
01/03/2015 02:54:31;0040;PBS_Server;Svr;tyrone-cluster;Scheduler was sent the command new
01/03/2015 02:54:47;0002;PBS_Server;Svr;PBS_Server;Torque Server Version = 3.0.5, loglevel = 0
01/03/2015 02:55:01;0040;PBS_Server;Svr;tyrone-cluster;Scheduler was sent the command new
01/03/2015 02:55:31;0040;PBS_Server;Svr;tyrone-cluster;Scheduler was sent the command new
01/03/2015 02:56:01;0040;PBS_Server;Svr;tyrone-cluster;Scheduler was sent the command new
01/03/2015 02:56:31;0040;PBS_Server;Svr;tyrone-cluster;Scheduler was sent the command new
01/03/2015 02:57:02;0040;PBS_Server;Svr;tyrone-cluster;Scheduler was sent the command new
01/03/2015 02:57:32;0040;PBS_Server;Svr;tyrone-cluster;Scheduler was sent the command new
01/03/2015 02:58:02;0040;PBS_Server;Svr;tyrone-cluster;Scheduler was sent the command new
01/03/2015 02:58:32;0040;PBS_Server;Svr;tyrone-cluster;Scheduler was sent the command new
01/03/2015 02:59:02;0040;PBS_Server;Svr;tyrone-cluster;Scheduler was sent the command new
01/03/2015 02:59:32;0040;PBS_Server;Svr;tyrone-cluster;Scheduler was sent the command new
01/03/2015 02:59:47;0002;PBS_Server;Svr;PBS_Server;Torque Server Version = 3.0.5, loglevel = 0
01/03/2015 03:00:02;0040;PBS_Server;Svr;tyrone-cluster;Scheduler was sent the command new
01/03/2015 03:00:32;0040;PBS_Server;Svr;tyrone-cluster;Scheduler was sent the command new
01/03/2015 03:01:03;0040;PBS_Server;Svr;tyrone-cluster;Scheduler was sent the command new
01/03/2015 03:01:33;0040;PBS_Server;Svr;tyrone-cluster;Scheduler was sent the command new
01/03/2015 03:02:02;0040;PBS_Server;Svr;tyrone-cluster;Scheduler was sent the command new
01/03/2015 03:02:33;0040;PBS_Server;Svr;tyrone-cluster;Scheduler was sent the command new
01/03/2015 03:03:03;0040;PBS_Server;Svr;tyrone-cluster;Scheduler was sent the command new
01/03/2015 03:03:33;0040;PBS_Server;Svr;tyrone-cluster;Scheduler was sent the command new
01/03/2015 03:04:03;0040;PBS_Server;Svr;tyrone-cluster;Scheduler was sent the command new
01/03/2015 03:04:33;0040;PBS_Server;Svr;tyrone-cluster;Scheduler was sent the command new
01/03/2015 03:04:47;0002;PBS_Server;Svr;PBS_Server;Torque Server Version = 3.0.5, loglevel = 0
01/03/2015 03:05:03;0040;PBS_Server;Svr;tyrone-cluster;Scheduler was sent the command new
01/03/2015 03:05:33;0040;PBS_Server;Svr;tyrone-cluster;Scheduler was sent the command new
01/03/2015 03:06:04;0040;PBS_Server;Svr;tyrone-cluster;Scheduler was sent the command new
01/03/2015 03:06:34;0040;PBS_Server;Svr;tyrone-cluster;Scheduler was sent the command new
01/03/2015 03:07:04;0040;PBS_Server;Svr;tyrone-cluster;Scheduler was sent the command new
01/03/2015 03:07:34;0040;PBS_Server;Svr;tyrone-cluster;Scheduler was sent the command new
01/03/2015 03:08:04;0040;PBS_Server;Svr;tyrone-cluster;Scheduler was sent the command new
01/03/2015 03:08:34;0040;PBS_Server;Svr;tyrone-cluster;Scheduler was sent the command new
01/03/2015 03:09:04;0040;PBS_Server;Svr;tyrone-cluster;Scheduler was sent the command new
01/03/2015 03:09:34;0040;PBS_Server;Svr;tyrone-cluster;Scheduler was sent the command new
01/03/2015 03:09:47;0002;PBS_Server;Svr;PBS_Server;Torque Server Version = 3.0.5, loglevel = 0
01/03/2015 03:10:04;0040;PBS_Server;Svr;tyrone-cluster;Scheduler was sent the command new
01/03/2015 03:10:35;0040;PBS_Server;Svr;tyrone-cluster;Scheduler was sent the command new
01/03/2015 03:11:05;0040;PBS_Server;Svr;tyrone-cluster;Scheduler was sent the command new
01/03/2015 03:11:35;0040;PBS_Server;Svr;tyrone-cluster;Scheduler was sent the command new
01/03/2015 03:12:05;0040;PBS_Server;Svr;tyrone-cluster;Scheduler was sent the command new
01/03/2015 03:12:35;0040;PBS_Server;Svr;tyrone-cluster;Scheduler was sent the command new
01/03/2015 03:13:05;0040;PBS_Server;Svr;tyrone-cluster;Scheduler was sent the command new
01/03/2015 03:13:35;0040;PBS_Server;Svr;tyrone-cluster;Scheduler was sent the command new
01/03/2015 03:14:05;0040;PBS_Server;Svr;tyrone-cluster;Scheduler was sent the command new
01/03/2015 03:14:35;0040;PBS_Server;Svr;tyrone-cluster;Scheduler was sent the command new
01/03/2015 03:14:47;0002;PBS_Server;Svr;PBS_Server;Torque Server Version = 3.0.5, loglevel = 0
01/03/2015 03:15:06;0040;PBS_Server;Svr;tyrone-cluster;Scheduler was sent the command new
01/03/2015 03:15:36;0040;PBS_Server;Svr;tyrone-cluster;Scheduler was sent the command new
01/03/2015 03:16:06;0040;PBS_Server;Svr;tyrone-cluster;Scheduler was sent the command new
01/03/2015 03:16:36;0040;PBS_Server;Svr;tyrone-cluster;Scheduler was sent the command new
01/03/2015 03:17:06;0040;PBS_Server;Svr;tyrone-cluster;Scheduler was sent the command new
01/03/2015 03:17:36;0040;PBS_Server;Svr;tyrone-cluster;Scheduler was sent the command new
01/03/2015 03:18:06;0040;PBS_Server;Svr;tyrone-cluster;Scheduler was sent the command new
01/03/2015 03:18:36;0040;PBS_Server;Svr;tyrone-cluster;Scheduler was sent the command new
01/03/2015 03:19:06;0040;PBS_Server;Svr;tyrone-cluster;Scheduler was sent the command new
01/03/2015 03:19:37;0040;PBS_Server;Svr;tyrone-cluster;Scheduler was sent the command new
01/03/2015 03:19:47;0002;PBS_Server;Svr;PBS_Server;Torque Server Version = 3.0.5, loglevel = 0
01/03/2015 03:20:07;0040;PBS_Server;Svr;tyrone-cluster;Scheduler was sent the command new
01/03/2015 03:20:36;0100;PBS_Server;Job;46406.tyrone-cluster;enqueuing into batch, state 1 hop 1
01/03/2015 03:20:36;0100;PBS_Server;Job;46406.tyrone-cluster;dequeuing from batch, state QUEUED
01/03/2015 03:20:36;0100;PBS_Server;Job;46406.tyrone-cluster;enqueuing into qp32, state 1 hop 1
01/03/2015 03:20:36;0008;PBS_Server;Job;46406.tyrone-cluster;Job Queued at request of asepk@tyrone-cluster, owner = asepk@tyrone-cluster, job name = DNsFlo_32, queue = qp32
01/03/2015 03:20:36;0040;PBS_Server;Svr;tyrone-cluster;Scheduler was sent the command new
01/03/2015 03:20:36;0008;PBS_Server;Job;46406.tyrone-cluster;Job Modified at request of Scheduler@tyrone-cluster
01/03/2015 03:20:37;0040;PBS_Server;Svr;tyrone-cluster;Scheduler was sent the command new
01/03/2015 03:21:07;0040;PBS_Server;Svr;tyrone-cluster;Scheduler was sent the command new
01/03/2015 03:21:37;0040;PBS_Server;Svr;tyrone-cluster;Scheduler was sent the command new
01/03/2015 03:22:07;0040;PBS_Server;Svr;tyrone-cluster;Scheduler was sent the command new
01/03/2015 03:22:37;0040;PBS_Server;Svr;tyrone-cluster;Scheduler was sent the command new
01/03/2015 03:23:07;0040;PBS_Server;Svr;tyrone-cluster;Scheduler was sent the command new
01/03/2015 03:23:37;0040;PBS_Server;Svr;tyrone-cluster;Scheduler was sent the command new
01/03/2015 03:24:07;0040;PBS_Server;Svr;tyrone-cluster;Scheduler was sent the command new
01/03/2015 03:24:38;0040;PBS_Server;Svr;tyrone-cluster;Scheduler was sent the command new
01/03/2015 03:24:47;0002;PBS_Server;Svr;PBS_Server;Torque Server Version = 3.0.5, loglevel = 0
01/03/2015 03:25:08;0040;PBS_Server;Svr;tyrone-cluster;Scheduler was sent the command new
01/03/2015 03:25:38;0040;PBS_Server;Svr;tyrone-cluster;Scheduler was sent the command new
01/03/2015 03:26:08;0040;PBS_Server;Svr;tyrone-cluster;Scheduler was sent the command new
01/03/2015 03:26:38;0040;PBS_Server;Svr;tyrone-cluster;Scheduler was sent the command new
01/03/2015 03:27:08;0040;PBS_Server;Svr;tyrone-cluster;Scheduler was sent the command new
01/03/2015 03:27:38;0040;PBS_Server;Svr;tyrone-cluster;Scheduler was sent the command new
01/03/2015 03:28:08;0040;PBS_Server;Svr;tyrone-cluster;Scheduler was sent the command new
01/03/2015 03:28:38;0040;PBS_Server;Svr;tyrone-cluster;Scheduler was sent the command new
01/03/2015 03:29:08;0040;PBS_Server;Svr;tyrone-cluster;Scheduler was sent the command new
01/03/2015 03:29:39;0040;PBS_Server;Svr;tyrone-cluster;Scheduler was sent the command new
01/03/2015 03:29:47;0002;PBS_Server;Svr;PBS_Server;Torque Server Version = 3.0.5, loglevel = 0
01/03/2015 03:30:09;0040;PBS_Server;Svr;tyrone-cluster;Scheduler was sent the command new
01/03/2015 03:30:38;0040;PBS_Server;Svr;tyrone-cluster;Scheduler was sent the command new
01/03/2015 03:31:09;0040;PBS_Server;Svr;tyrone-cluster;Scheduler was sent the command new
01/03/2015 03:31:39;0040;PBS_Server;Svr;tyrone-cluster;Scheduler was sent the command new
01/03/2015 03:32:09;0040;PBS_Server;Svr;tyrone-cluster;Scheduler was sent the command new
01/03/2015 03:32:39;0040;PBS_Server;Svr;tyrone-cluster;Scheduler was sent the command new
01/03/2015 03:33:09;0040;PBS_Server;Svr;tyrone-cluster;Scheduler was sent the command new
01/03/2015 03:33:39;0040;PBS_Server;Svr;tyrone-cluster;Scheduler was sent the command new
01/03/2015 03:34:10;0040;PBS_Server;Svr;tyrone-cluster;Scheduler was sent the command new
01/03/2015 03:34:40;0040;PBS_Server;Svr;tyrone-cluster;Scheduler was sent the command new
01/03/2015 03:34:47;0002;PBS_Server;Svr;PBS_Server;Torque Server Version = 3.0.5, loglevel = 0
01/03/2015 03:35:10;0040;PBS_Server;Svr;tyrone-cluster;Scheduler was sent the command new
01/03/2015 03:35:40;0040;PBS_Server;Svr;tyrone-cluster;Scheduler was sent the command new
01/03/2015 03:36:10;0040;PBS_Server;Svr;tyrone-cluster;Scheduler was sent the command new
01/03/2015 03:36:40;0040;PBS_Server;Svr;tyrone-cluster;Scheduler was sent the command new
01/03/2015 03:37:10;0040;PBS_Server;Svr;tyrone-cluster;Scheduler was sent the command new
01/03/2015 03:37:40;0040;PBS_Server;Svr;tyrone-cluster;Scheduler was sent the command new
01/03/2015 03:38:10;0040;PBS_Server;Svr;tyrone-cluster;Scheduler was sent the command new
01/03/2015 03:38:41;0040;PBS_Server;Svr;tyrone-cluster;Scheduler was sent the command new
01/03/2015 03:39:11;0040;PBS_Server;Svr;tyrone-cluster;Scheduler was sent the command new
01/03/2015 03:39:40;0040;PBS_Server;Svr;tyrone-cluster;Scheduler was sent the command new
01/03/2015 03:39:47;0002;PBS_Server;Svr;PBS_Server;Torque Server Version = 3.0.5, loglevel = 0
01/03/2015 03:40:11;0040;PBS_Server;Svr;tyrone-cluster;Scheduler was sent the command new
01/03/2015 03:40:41;0040;PBS_Server;Svr;tyrone-cluster;Scheduler was sent the command new
01/03/2015 03:41:11;0040;PBS_Server;Svr;tyrone-cluster;Scheduler was sent the command new
01/03/2015 03:41:41;0040;PBS_Server;Svr;tyrone-cluster;Scheduler was sent the command new
01/03/2015 03:42:11;0040;PBS_Server;Svr;tyrone-cluster;Scheduler was sent the command new
01/03/2015 03:42:42;0040;PBS_Server;Svr;tyrone-cluster;Scheduler was sent the command new
01/03/2015 03:43:12;0040;PBS_Server;Svr;tyrone-cluster;Scheduler was sent the command new
01/03/2015 03:43:42;0040;PBS_Server;Svr;tyrone-cluster;Scheduler was sent the command new
01/03/2015 03:44:12;0040;PBS_Server;Svr;tyrone-cluster;Scheduler was sent the command new
01/03/2015 03:44:42;0040;PBS_Server;Svr;tyrone-cluster;Scheduler was sent the command new
01/03/2015 03:44:47;0002;PBS_Server;Svr;PBS_Server;Torque Server Version = 3.0.5, loglevel = 0
01/03/2015 03:45:12;0040;PBS_Server;Svr;tyrone-cluster;Scheduler was sent the command new
01/03/2015 03:45:43;0040;PBS_Server;Svr;tyrone-cluster;Scheduler was sent the command new
01/03/2015 03:46:13;0040;PBS_Server;Svr;tyrone-cluster;Scheduler was sent the command new
01/03/2015 03:46:43;0040;PBS_Server;Svr;tyrone-cluster;Scheduler was sent the command new
01/03/2015 03:47:13;0040;PBS_Server;Svr;tyrone-cluster;Scheduler was sent the command new
01/03/2015 03:47:43;0040;PBS_Server;Svr;tyrone-cluster;Scheduler was sent the command new
01/03/2015 03:48:13;0040;PBS_Server;Svr;tyrone-cluster;Scheduler was sent the command new
01/03/2015 03:48:43;0040;PBS_Server;Svr;tyrone-cluster;Scheduler was sent the command new
01/03/2015 03:49:05;000d;PBS_Server;Job;46381.tyrone-cluster;Not sending email: User does not want mail of this type.
01/03/2015 03:49:05;0010;PBS_Server;Job;46381.tyrone-cluster;Exit_status=255 resources_used.cput=142:05:35 resources_used.mem=2662052kb resources_used.vmem=10054824kb resources_used.walltime=05:06:19
01/03/2015 03:49:05;0008;PBS_Server;Job;NULL;on_job_exit valid pjob: 0x12f1ef0 (substate=50)
01/03/2015 03:49:05;0008;PBS_Server;Job;NULL;on_job_exit valid pjob: 0x12f1ef0 (substate=51)
01/03/2015 03:49:13;0040;PBS_Server;Svr;tyrone-cluster;Scheduler was sent the command new
01/03/2015 03:49:17;0008;PBS_Server;Job;NULL;on_job_exit valid pjob: 0x12f1ef0 (substate=51)
01/03/2015 03:49:17;0008;PBS_Server;Job;NULL;on_job_exit valid pjob: 0x12f1ef0 (substate=53)
01/03/2015 03:49:17;0100;PBS_Server;Job;46381.tyrone-cluster;dequeuing from qp64, state COMPLETE
01/03/2015 03:49:17;0040;PBS_Server;Svr;tyrone-cluster;Scheduler was sent the command term
01/03/2015 03:49:43;0040;PBS_Server;Svr;tyrone-cluster;Scheduler was sent the command new
01/03/2015 03:49:47;0002;PBS_Server;Svr;PBS_Server;Torque Server Version = 3.0.5, loglevel = 0
01/03/2015 03:50:14;0040;PBS_Server;Svr;tyrone-cluster;Scheduler was sent the command new
01/03/2015 03:50:44;0040;PBS_Server;Svr;tyrone-cluster;Scheduler was sent the command new
01/03/2015 03:51:14;0040;PBS_Server;Svr;tyrone-cluster;Scheduler was sent the command new
01/03/2015 03:51:44;0040;PBS_Server;Svr;tyrone-cluster;Scheduler was sent the command new
01/03/2015 03:52:14;0040;PBS_Server;Svr;tyrone-cluster;Scheduler was sent the command new
01/03/2015 03:52:44;0040;PBS_Server;Svr;tyrone-cluster;Scheduler was sent the command new
01/03/2015 03:53:14;0040;PBS_Server;Svr;tyrone-cluster;Scheduler was sent the command new
01/03/2015 03:53:44;0040;PBS_Server;Svr;tyrone-cluster;Scheduler was sent the command new
01/03/2015 03:54:14;0040;PBS_Server;Svr;tyrone-cluster;Scheduler was sent the command new
01/03/2015 03:54:44;0040;PBS_Server;Svr;tyrone-cluster;Scheduler was sent the command new
01/03/2015 03:54:47;0002;PBS_Server;Svr;PBS_Server;Torque Server Version = 3.0.5, loglevel = 0
01/03/2015 03:55:15;0040;PBS_Server;Svr;tyrone-cluster;Scheduler was sent the command new
01/03/2015 03:55:45;0040;PBS_Server;Svr;tyrone-cluster;Scheduler was sent the command new
01/03/2015 03:56:15;0040;PBS_Server;Svr;tyrone-cluster;Scheduler was sent the command new
01/03/2015 03:56:45;0040;PBS_Server;Svr;tyrone-cluster;Scheduler was sent the command new
01/03/2015 03:57:15;0040;PBS_Server;Svr;tyrone-cluster;Scheduler was sent the command new
01/03/2015 03:57:45;0040;PBS_Server;Svr;tyrone-cluster;Scheduler was sent the command new
01/03/2015 03:58:15;0040;PBS_Server;Svr;tyrone-cluster;Scheduler was sent the command new
01/03/2015 03:58:45;0040;PBS_Server;Svr;tyrone-cluster;Scheduler was sent the command new
01/03/2015 03:59:15;0040;PBS_Server;Svr;tyrone-cluster;Scheduler was sent the command new
01/03/2015 03:59:46;0040;PBS_Server;Svr;tyrone-cluster;Scheduler was sent the command new
01/03/2015 03:59:47;0002;PBS_Server;Svr;PBS_Server;Torque Server Version = 3.0.5, loglevel = 0
01/03/2015 04:00:16;0040;PBS_Server;Svr;tyrone-cluster;Scheduler was sent the command new
01/03/2015 04:00:46;0040;PBS_Server;Svr;tyrone-cluster;Scheduler was sent the command new
01/03/2015 04:01:16;0040;PBS_Server;Svr;tyrone-cluster;Scheduler was sent the command new
01/03/2015 04:01:46;0040;PBS_Server;Svr;tyrone-cluster;Scheduler was sent the command new
01/03/2015 04:02:16;0040;PBS_Server;Svr;tyrone-cluster;Scheduler was sent the command new
01/03/2015 04:02:46;0040;PBS_Server;Svr;tyrone-cluster;Scheduler was sent the command new
01/03/2015 04:03:16;0040;PBS_Server;Svr;tyrone-cluster;Scheduler was sent the command new
01/03/2015 04:03:46;0040;PBS_Server;Svr;tyrone-cluster;Scheduler was sent the command new
01/03/2015 04:04:17;0040;PBS_Server;Svr;tyrone-cluster;Scheduler was sent the command new
01/03/2015 04:04:47;0002;PBS_Server;Svr;PBS_Server;Torque Server Version = 3.0.5, loglevel = 0
01/03/2015 04:04:47;0040;PBS_Server;Svr;tyrone-cluster;Scheduler was sent the command new
01/03/2015 04:05:17;0040;PBS_Server;Svr;tyrone-cluster;Scheduler was sent the command new
01/03/2015 04:05:47;0040;PBS_Server;Svr;tyrone-cluster;Scheduler was sent the command new
01/03/2015 04:06:17;0040;PBS_Server;Svr;tyrone-cluster;Scheduler was sent the command new
01/03/2015 04:06:47;0040;PBS_Server;Svr;tyrone-cluster;Scheduler was sent the command new
01/03/2015 04:07:17;0040;PBS_Server;Svr;tyrone-cluster;Scheduler was sent the command new
01/03/2015 04:07:47;0040;PBS_Server;Svr;tyrone-cluster;Scheduler was sent the command new
01/03/2015 04:08:17;0040;PBS_Server;Svr;tyrone-cluster;Scheduler was sent the command new
01/03/2015 04:08:47;0040;PBS_Server;Svr;tyrone-cluster;Scheduler was sent the command new
01/03/2015 04:09:18;0040;PBS_Server;Svr;tyrone-cluster;Scheduler was sent the command new
01/03/2015 04:09:47;0002;PBS_Server;Svr;PBS_Server;Torque Server Version = 3.0.5, loglevel = 0
01/03/2015 04:09:48;0040;PBS_Server;Svr;tyrone-cluster;Scheduler was sent the command new
01/03/2015 04:10:18;0040;PBS_Server;Svr;tyrone-cluster;Scheduler was sent the command new
01/03/2015 04:10:48;0040;PBS_Server;Svr;tyrone-cluster;Scheduler was sent the command new
01/03/2015 04:11:18;0040;PBS_Server;Svr;tyrone-cluster;Scheduler was sent the command new
01/03/2015 04:11:48;0040;PBS_Server;Svr;tyrone-cluster;Scheduler was sent the command new
01/03/2015 04:12:18;0040;PBS_Server;Svr;tyrone-cluster;Scheduler was sent the command new
01/03/2015 04:12:48;0040;PBS_Server;Svr;tyrone-cluster;Scheduler was sent the command new
01/03/2015 04:13:18;0040;PBS_Server;Svr;tyrone-cluster;Scheduler was sent the command new
01/03/2015 04:13:49;0040;PBS_Server;Svr;tyrone-cluster;Scheduler was sent the command new
01/03/2015 04:14:19;0040;PBS_Server;Svr;tyrone-cluster;Scheduler was sent the command new
01/03/2015 04:14:47;0002;PBS_Server;Svr;PBS_Server;Torque Server Version = 3.0.5, loglevel = 0
01/03/2015 04:14:49;0040;PBS_Server;Svr;tyrone-cluster;Scheduler was sent the command new
01/03/2015 04:15:19;0040;PBS_Server;Svr;tyrone-cluster;Scheduler was sent the command new
01/03/2015 04:15:49;0040;PBS_Server;Svr;tyrone-cluster;Scheduler was sent the command new
01/03/2015 04:16:19;0040;PBS_Server;Svr;tyrone-cluster;Scheduler was sent the command new
01/03/2015 04:16:49;0040;PBS_Server;Svr;tyrone-cluster;Scheduler was sent the command new
01/03/2015 04:17:19;0040;PBS_Server;Svr;tyrone-cluster;Scheduler was sent the command new
01/03/2015 04:17:49;0040;PBS_Server;Svr;tyrone-cluster;Scheduler was sent the command new
01/03/2015 04:18:20;0040;PBS_Server;Svr;tyrone-cluster;Scheduler was sent the command new
01/03/2015 04:18:50;0040;PBS_Server;Svr;tyrone-cluster;Scheduler was sent the command new
01/03/2015 04:19:20;0040;PBS_Server;Svr;tyrone-cluster;Scheduler was sent the command new
01/03/2015 04:19:47;0002;PBS_Server;Svr;PBS_Server;Torque Server Version = 3.0.5, loglevel = 0
01/03/2015 04:19:50;0040;PBS_Server;Svr;tyrone-cluster;Scheduler was sent the command new
01/03/2015 04:20:20;0040;PBS_Server;Svr;tyrone-cluster;Scheduler was sent the command new
01/03/2015 04:20:50;0040;PBS_Server;Svr;tyrone-cluster;Scheduler was sent the command new
01/03/2015 04:21:20;0040;PBS_Server;Svr;tyrone-cluster;Scheduler was sent the command new
01/03/2015 04:21:50;0040;PBS_Server;Svr;tyrone-cluster;Scheduler was sent the command new
01/03/2015 04:22:20;0040;PBS_Server;Svr;tyrone-cluster;Scheduler was sent the command new
01/03/2015 04:22:50;0040;PBS_Server;Svr;tyrone-cluster;Scheduler was sent the command new
01/03/2015 04:23:21;0040;PBS_Server;Svr;tyrone-cluster;Scheduler was sent the command new
01/03/2015 04:23:51;0040;PBS_Server;Svr;tyrone-cluster;Scheduler was sent the command new
01/03/2015 04:24:21;0040;PBS_Server;Svr;tyrone-cluster;Scheduler was sent the command new
01/03/2015 04:24:47;0002;PBS_Server;Svr;PBS_Server;Torque Server Version = 3.0.5, loglevel = 0
01/03/2015 04:24:51;0040;PBS_Server;Svr;tyrone-cluster;Scheduler was sent the command new
01/03/2015 04:25:21;0040;PBS_Server;Svr;tyrone-cluster;Scheduler was sent the command new
01/03/2015 04:25:51;0040;PBS_Server;Svr;tyrone-cluster;Scheduler was sent the command new
01/03/2015 04:26:21;0040;PBS_Server;Svr;tyrone-cluster;Scheduler was sent the command new
01/03/2015 04:26:51;0040;PBS_Server;Svr;tyrone-cluster;Scheduler was sent the command new
01/03/2015 04:27:21;0040;PBS_Server;Svr;tyrone-cluster;Scheduler was sent the command new
01/03/2015 04:27:52;0040;PBS_Server;Svr;tyrone-cluster;Scheduler was sent the command new
01/03/2015 04:28:22;0040;PBS_Server;Svr;tyrone-cluster;Scheduler was sent the command new
01/03/2015 04:28:52;0040;PBS_Server;Svr;tyrone-cluster;Scheduler was sent the command new
01/03/2015 04:29:22;0040;PBS_Server;Svr;tyrone-cluster;Scheduler was sent the command new
01/03/2015 04:29:47;0002;PBS_Server;Svr;PBS_Server;Torque Server Version = 3.0.5, loglevel = 0
01/03/2015 04:29:52;0040;PBS_Server;Svr;tyrone-cluster;Scheduler was sent the command new
01/03/2015 04:30:22;0040;PBS_Server;Svr;tyrone-cluster;Scheduler was sent the command new
01/03/2015 04:30:52;0040;PBS_Server;Svr;tyrone-cluster;Scheduler was sent the command new
01/03/2015 04:31:23;0040;PBS_Server;Svr;tyrone-cluster;Scheduler was sent the command new
01/03/2015 04:31:53;0040;PBS_Server;Svr;tyrone-cluster;Scheduler was sent the command new
01/03/2015 04:32:22;0040;PBS_Server;Svr;tyrone-cluster;Scheduler was sent the command new
01/03/2015 04:32:53;0040;PBS_Server;Svr;tyrone-cluster;Scheduler was sent the command new
01/03/2015 04:33:23;0040;PBS_Server;Svr;tyrone-cluster;Scheduler was sent the command new
01/03/2015 04:33:53;0040;PBS_Server;Svr;tyrone-cluster;Scheduler was sent the command new
01/03/2015 04:34:23;0040;PBS_Server;Svr;tyrone-cluster;Scheduler was sent the command new
01/03/2015 04:34:47;0002;PBS_Server;Svr;PBS_Server;Torque Server Version = 3.0.5, loglevel = 0
01/03/2015 04:34:53;0040;PBS_Server;Svr;tyrone-cluster;Scheduler was sent the command new
01/03/2015 04:35:23;0040;PBS_Server;Svr;tyrone-cluster;Scheduler was sent the command new
01/03/2015 04:35:53;0040;PBS_Server;Svr;tyrone-cluster;Scheduler was sent the command new
01/03/2015 04:36:24;0040;PBS_Server;Svr;tyrone-cluster;Scheduler was sent the command new
01/03/2015 04:36:54;0040;PBS_Server;Svr;tyrone-cluster;Scheduler was sent the command new
01/03/2015 04:37:24;0040;PBS_Server;Svr;tyrone-cluster;Scheduler was sent the command new
01/03/2015 04:37:54;0040;PBS_Server;Svr;tyrone-cluster;Scheduler was sent the command new
01/03/2015 04:38:24;0040;PBS_Server;Svr;tyrone-cluster;Scheduler was sent the command new
01/03/2015 04:38:54;0040;PBS_Server;Svr;tyrone-cluster;Scheduler was sent the command new
01/03/2015 04:39:24;0040;PBS_Server;Svr;tyrone-cluster;Scheduler was sent the command new
01/03/2015 04:39:47;0002;PBS_Server;Svr;PBS_Server;Torque Server Version = 3.0.5, loglevel = 0
01/03/2015 04:39:54;0040;PBS_Server;Svr;tyrone-cluster;Scheduler was sent the command new
01/03/2015 04:40:24;0040;PBS_Server;Svr;tyrone-cluster;Scheduler was sent the command new
01/03/2015 04:40:55;0040;PBS_Server;Svr;tyrone-cluster;Scheduler was sent the command new
01/03/2015 04:41:25;0040;PBS_Server;Svr;tyrone-cluster;Scheduler was sent the command new
01/03/2015 04:41:54;0040;PBS_Server;Svr;tyrone-cluster;Scheduler was sent the command new
01/03/2015 04:42:24;0040;PBS_Server;Svr;tyrone-cluster;Scheduler was sent the command new
01/03/2015 04:42:55;0040;PBS_Server;Svr;tyrone-cluster;Scheduler was sent the command new
01/03/2015 04:43:24;0040;PBS_Server;Svr;tyrone-cluster;Scheduler was sent the command new
01/03/2015 04:43:55;0040;PBS_Server;Svr;tyrone-cluster;Scheduler was sent the command new
01/03/2015 04:44:25;0040;PBS_Server;Svr;tyrone-cluster;Scheduler was sent the command new
01/03/2015 04:44:47;0002;PBS_Server;Svr;PBS_Server;Torque Server Version = 3.0.5, loglevel = 0
01/03/2015 04:44:54;0040;PBS_Server;Svr;tyrone-cluster;Scheduler was sent the command new
01/03/2015 04:45:25;0040;PBS_Server;Svr;tyrone-cluster;Scheduler was sent the command new
01/03/2015 04:45:56;0040;PBS_Server;Svr;tyrone-cluster;Scheduler was sent the command new
01/03/2015 04:46:24;0040;PBS_Server;Svr;tyrone-cluster;Scheduler was sent the command new
01/03/2015 04:46:54;0040;PBS_Server;Svr;tyrone-cluster;Scheduler was sent the command new
01/03/2015 04:47:26;0040;PBS_Server;Svr;tyrone-cluster;Scheduler was sent the command new
01/03/2015 04:47:54;0040;PBS_Server;Svr;tyrone-cluster;Scheduler was sent the command new
01/03/2015 04:48:26;0040;PBS_Server;Svr;tyrone-cluster;Scheduler was sent the command new
01/03/2015 04:48:56;0040;PBS_Server;Svr;tyrone-cluster;Scheduler was sent the command new
01/03/2015 04:49:24;0040;PBS_Server;Svr;tyrone-cluster;Scheduler was sent the command new
01/03/2015 04:49:47;0002;PBS_Server;Svr;PBS_Server;Torque Server Version = 3.0.5, loglevel = 0
01/03/2015 04:49:55;0040;PBS_Server;Svr;tyrone-cluster;Scheduler was sent the command new
01/03/2015 04:50:26;0040;PBS_Server;Svr;tyrone-cluster;Scheduler was sent the command new
01/03/2015 04:50:56;0040;PBS_Server;Svr;tyrone-cluster;Scheduler was sent the command new
01/03/2015 04:51:27;0040;PBS_Server;Svr;tyrone-cluster;Scheduler was sent the command new
01/03/2015 04:51:57;0040;PBS_Server;Svr;tyrone-cluster;Scheduler was sent the command new
01/03/2015 04:52:27;0040;PBS_Server;Svr;tyrone-cluster;Scheduler was sent the command new
01/03/2015 04:52:57;0040;PBS_Server;Svr;tyrone-cluster;Scheduler was sent the command new
01/03/2015 04:53:27;0040;PBS_Server;Svr;tyrone-cluster;Scheduler was sent the command new
01/03/2015 04:53:57;0040;PBS_Server;Svr;tyrone-cluster;Scheduler was sent the command new
01/03/2015 04:54:28;0040;PBS_Server;Svr;tyrone-cluster;Scheduler was sent the command new
01/03/2015 04:54:47;0002;PBS_Server;Svr;PBS_Server;Torque Server Version = 3.0.5, loglevel = 0
01/03/2015 04:54:58;0040;PBS_Server;Svr;tyrone-cluster;Scheduler was sent the command new
01/03/2015 04:55:28;0040;PBS_Server;Svr;tyrone-cluster;Scheduler was sent the command new
01/03/2015 04:55:58;0040;PBS_Server;Svr;tyrone-cluster;Scheduler was sent the command new
01/03/2015 04:56:28;0040;PBS_Server;Svr;tyrone-cluster;Scheduler was sent the command new
01/03/2015 04:56:58;0040;PBS_Server;Svr;tyrone-cluster;Scheduler was sent the command new
01/03/2015 04:57:28;0040;PBS_Server;Svr;tyrone-cluster;Scheduler was sent the command new
01/03/2015 04:57:58;0040;PBS_Server;Svr;tyrone-cluster;Scheduler was sent the command new
01/03/2015 04:58:28;0040;PBS_Server;Svr;tyrone-cluster;Scheduler was sent the command new
01/03/2015 04:58:59;0040;PBS_Server;Svr;tyrone-cluster;Scheduler was sent the command new
01/03/2015 04:59:29;0040;PBS_Server;Svr;tyrone-cluster;Scheduler was sent the command new
01/03/2015 04:59:47;0002;PBS_Server;Svr;PBS_Server;Torque Server Version = 3.0.5, loglevel = 0
01/03/2015 04:59:59;0040;PBS_Server;Svr;tyrone-cluster;Scheduler was sent the command new
01/03/2015 05:00:29;0040;PBS_Server;Svr;tyrone-cluster;Scheduler was sent the command new
01/03/2015 05:00:59;0040;PBS_Server;Svr;tyrone-cluster;Scheduler was sent the command new
01/03/2015 05:01:29;0040;PBS_Server;Svr;tyrone-cluster;Scheduler was sent the command new
01/03/2015 05:01:59;0040;PBS_Server;Svr;tyrone-cluster;Scheduler was sent the command new
01/03/2015 05:02:30;0040;PBS_Server;Svr;tyrone-cluster;Scheduler was sent the command new
01/03/2015 05:03:00;0040;PBS_Server;Svr;tyrone-cluster;Scheduler was sent the command new
01/03/2015 05:03:30;0040;PBS_Server;Svr;tyrone-cluster;Scheduler was sent the command new
01/03/2015 05:04:00;0040;PBS_Server;Svr;tyrone-cluster;Scheduler was sent the command new
01/03/2015 05:04:30;0040;PBS_Server;Svr;tyrone-cluster;Scheduler was sent the command new
01/03/2015 05:04:47;0002;PBS_Server;Svr;PBS_Server;Torque Server Version = 3.0.5, loglevel = 0
01/03/2015 05:05:00;0040;PBS_Server;Svr;tyrone-cluster;Scheduler was sent the command new
01/03/2015 05:05:30;0040;PBS_Server;Svr;tyrone-cluster;Scheduler was sent the command new
01/03/2015 05:06:00;0040;PBS_Server;Svr;tyrone-cluster;Scheduler was sent the command new
01/03/2015 05:06:30;0040;PBS_Server;Svr;tyrone-cluster;Scheduler was sent the command new
01/03/2015 05:07:00;0040;PBS_Server;Svr;tyrone-cluster;Scheduler was sent the command new
01/03/2015 05:07:31;0040;PBS_Server;Svr;tyrone-cluster;Scheduler was sent the command new
01/03/2015 05:08:01;0040;PBS_Server;Svr;tyrone-cluster;Scheduler was sent the command new
01/03/2015 05:08:31;0040;PBS_Server;Svr;tyrone-cluster;Scheduler was sent the command new
01/03/2015 05:09:01;0040;PBS_Server;Svr;tyrone-cluster;Scheduler was sent the command new
01/03/2015 05:09:31;0040;PBS_Server;Svr;tyrone-cluster;Scheduler was sent the command new
01/03/2015 05:09:47;0002;PBS_Server;Svr;PBS_Server;Torque Server Version = 3.0.5, loglevel = 0
01/03/2015 05:10:01;0040;PBS_Server;Svr;tyrone-cluster;Scheduler was sent the command new
01/03/2015 05:10:31;0040;PBS_Server;Svr;tyrone-cluster;Scheduler was sent the command new
01/03/2015 05:11:01;0040;PBS_Server;Svr;tyrone-cluster;Scheduler was sent the command new
01/03/2015 05:11:31;0040;PBS_Server;Svr;tyrone-cluster;Scheduler was sent the command new
01/03/2015 05:12:02;0040;PBS_Server;Svr;tyrone-cluster;Scheduler was sent the command new
01/03/2015 05:12:32;0040;PBS_Server;Svr;tyrone-cluster;Scheduler was sent the command new
01/03/2015 05:13:02;0040;PBS_Server;Svr;tyrone-cluster;Scheduler was sent the command new
01/03/2015 05:13:32;0040;PBS_Server;Svr;tyrone-cluster;Scheduler was sent the command new
01/03/2015 05:14:02;0040;PBS_Server;Svr;tyrone-cluster;Scheduler was sent the command new
01/03/2015 05:14:32;0040;PBS_Server;Svr;tyrone-cluster;Scheduler was sent the command new
01/03/2015 05:14:47;0002;PBS_Server;Svr;PBS_Server;Torque Server Version = 3.0.5, loglevel = 0
01/03/2015 05:15:02;0040;PBS_Server;Svr;tyrone-cluster;Scheduler was sent the command new
01/03/2015 05:15:32;0040;PBS_Server;Svr;tyrone-cluster;Scheduler was sent the command new
01/03/2015 05:16:02;0040;PBS_Server;Svr;tyrone-cluster;Scheduler was sent the command new
01/03/2015 05:16:32;0040;PBS_Server;Svr;tyrone-cluster;Scheduler was sent the command new
01/03/2015 05:17:02;0040;PBS_Server;Svr;tyrone-cluster;Scheduler was sent the command new
01/03/2015 05:17:33;0040;PBS_Server;Svr;tyrone-cluster;Scheduler was sent the command new
01/03/2015 05:18:03;0040;PBS_Server;Svr;tyrone-cluster;Scheduler was sent the command new
01/03/2015 05:18:33;0040;PBS_Server;Svr;tyrone-cluster;Scheduler was sent the command new
01/03/2015 05:19:03;0040;PBS_Server;Svr;tyrone-cluster;Scheduler was sent the command new
01/03/2015 05:19:33;0040;PBS_Server;Svr;tyrone-cluster;Scheduler was sent the command new
01/03/2015 05:19:47;0002;PBS_Server;Svr;PBS_Server;Torque Server Version = 3.0.5, loglevel = 0
01/03/2015 05:20:03;0040;PBS_Server;Svr;tyrone-cluster;Scheduler was sent the command new
01/03/2015 05:20:33;0040;PBS_Server;Svr;tyrone-cluster;Scheduler was sent the command new
01/03/2015 05:21:03;0040;PBS_Server;Svr;tyrone-cluster;Scheduler was sent the command new
01/03/2015 05:21:33;0040;PBS_Server;Svr;tyrone-cluster;Scheduler was sent the command new
01/03/2015 05:22:04;0040;PBS_Server;Svr;tyrone-cluster;Scheduler was sent the command new
01/03/2015 05:22:34;0040;PBS_Server;Svr;tyrone-cluster;Scheduler was sent the command new
01/03/2015 05:23:04;0040;PBS_Server;Svr;tyrone-cluster;Scheduler was sent the command new
01/03/2015 05:23:34;0040;PBS_Server;Svr;tyrone-cluster;Scheduler was sent the command new
01/03/2015 05:24:04;0040;PBS_Server;Svr;tyrone-cluster;Scheduler was sent the command new
01/03/2015 05:24:34;0040;PBS_Server;Svr;tyrone-cluster;Scheduler was sent the command new
01/03/2015 05:24:47;0002;PBS_Server;Svr;PBS_Server;Torque Server Version = 3.0.5, loglevel = 0
01/03/2015 05:25:04;0040;PBS_Server;Svr;tyrone-cluster;Scheduler was sent the command new
01/03/2015 05:25:34;0040;PBS_Server;Svr;tyrone-cluster;Scheduler was sent the command new
01/03/2015 05:26:04;0040;PBS_Server;Svr;tyrone-cluster;Scheduler was sent the command new
01/03/2015 05:26:34;0040;PBS_Server;Svr;tyrone-cluster;Scheduler was sent the command new
01/03/2015 05:27:05;0040;PBS_Server;Svr;tyrone-cluster;Scheduler was sent the command new
01/03/2015 05:27:34;0040;PBS_Server;Svr;tyrone-cluster;Scheduler was sent the command new
01/03/2015 05:28:05;0040;PBS_Server;Svr;tyrone-cluster;Scheduler was sent the command new
01/03/2015 05:28:35;0040;PBS_Server;Svr;tyrone-cluster;Scheduler was sent the command new
01/03/2015 05:29:04;0040;PBS_Server;Svr;tyrone-cluster;Scheduler was sent the command new
01/03/2015 05:29:35;0040;PBS_Server;Svr;tyrone-cluster;Scheduler was sent the command new
01/03/2015 05:29:47;0002;PBS_Server;Svr;PBS_Server;Torque Server Version = 3.0.5, loglevel = 0
01/03/2015 05:30:05;0040;PBS_Server;Svr;tyrone-cluster;Scheduler was sent the command new
01/03/2015 05:30:34;0040;PBS_Server;Svr;tyrone-cluster;Scheduler was sent the command new
01/03/2015 05:31:05;0040;PBS_Server;Svr;tyrone-cluster;Scheduler was sent the command new
01/03/2015 05:31:35;0040;PBS_Server;Svr;tyrone-cluster;Scheduler was sent the command new
01/03/2015 05:32:06;0040;PBS_Server;Svr;tyrone-cluster;Scheduler was sent the command new
01/03/2015 05:32:36;0040;PBS_Server;Svr;tyrone-cluster;Scheduler was sent the command new
01/03/2015 05:33:06;0040;PBS_Server;Svr;tyrone-cluster;Scheduler was sent the command new
01/03/2015 05:33:36;0040;PBS_Server;Svr;tyrone-cluster;Scheduler was sent the command new
01/03/2015 05:34:06;0040;PBS_Server;Svr;tyrone-cluster;Scheduler was sent the command new
01/03/2015 05:34:36;0040;PBS_Server;Svr;tyrone-cluster;Scheduler was sent the command new
01/03/2015 05:34:47;0002;PBS_Server;Svr;PBS_Server;Torque Server Version = 3.0.5, loglevel = 0
01/03/2015 05:35:06;0040;PBS_Server;Svr;tyrone-cluster;Scheduler was sent the command new
01/03/2015 05:35:36;0040;PBS_Server;Svr;tyrone-cluster;Scheduler was sent the command new
01/03/2015 05:36:06;0040;PBS_Server;Svr;tyrone-cluster;Scheduler was sent the command new
01/03/2015 05:36:36;0040;PBS_Server;Svr;tyrone-cluster;Scheduler was sent the command new
01/03/2015 05:37:07;0040;PBS_Server;Svr;tyrone-cluster;Scheduler was sent the command new
01/03/2015 05:37:37;0040;PBS_Server;Svr;tyrone-cluster;Scheduler was sent the command new
01/03/2015 05:38:07;0040;PBS_Server;Svr;tyrone-cluster;Scheduler was sent the command new
01/03/2015 05:38:37;0040;PBS_Server;Svr;tyrone-cluster;Scheduler was sent the command new
01/03/2015 05:39:07;0040;PBS_Server;Svr;tyrone-cluster;Scheduler was sent the command new
01/03/2015 05:39:37;0040;PBS_Server;Svr;tyrone-cluster;Scheduler was sent the command new
01/03/2015 05:39:47;0002;PBS_Server;Svr;PBS_Server;Torque Server Version = 3.0.5, loglevel = 0
01/03/2015 05:40:07;0040;PBS_Server;Svr;tyrone-cluster;Scheduler was sent the command new
01/03/2015 05:40:37;0040;PBS_Server;Svr;tyrone-cluster;Scheduler was sent the command new
01/03/2015 05:41:07;0040;PBS_Server;Svr;tyrone-cluster;Scheduler was sent the command new
01/03/2015 05:41:38;0040;PBS_Server;Svr;tyrone-cluster;Scheduler was sent the command new
01/03/2015 05:42:08;0040;PBS_Server;Svr;tyrone-cluster;Scheduler was sent the command new
01/03/2015 05:42:38;0040;PBS_Server;Svr;tyrone-cluster;Scheduler was sent the command new
01/03/2015 05:43:08;0040;PBS_Server;Svr;tyrone-cluster;Scheduler was sent the command new
01/03/2015 05:43:38;0040;PBS_Server;Svr;tyrone-cluster;Scheduler was sent the command new
01/03/2015 05:44:08;0040;PBS_Server;Svr;tyrone-cluster;Scheduler was sent the command new
01/03/2015 05:44:38;0040;PBS_Server;Svr;tyrone-cluster;Scheduler was sent the command new
01/03/2015 05:44:47;0002;PBS_Server;Svr;PBS_Server;Torque Server Version = 3.0.5, loglevel = 0
01/03/2015 05:45:08;0040;PBS_Server;Svr;tyrone-cluster;Scheduler was sent the command new
01/03/2015 05:45:38;0040;PBS_Server;Svr;tyrone-cluster;Scheduler was sent the command new
01/03/2015 05:46:09;0040;PBS_Server;Svr;tyrone-cluster;Scheduler was sent the command new
01/03/2015 05:46:39;0040;PBS_Server;Svr;tyrone-cluster;Scheduler was sent the command new
01/03/2015 05:47:09;0040;PBS_Server;Svr;tyrone-cluster;Scheduler was sent the command new
01/03/2015 05:47:39;0040;PBS_Server;Svr;tyrone-cluster;Scheduler was sent the command new
01/03/2015 05:48:09;0040;PBS_Server;Svr;tyrone-cluster;Scheduler was sent the command new
01/03/2015 05:48:39;0040;PBS_Server;Svr;tyrone-cluster;Scheduler was sent the command new
01/03/2015 05:49:09;0040;PBS_Server;Svr;tyrone-cluster;Scheduler was sent the command new
01/03/2015 05:49:39;0040;PBS_Server;Svr;tyrone-cluster;Scheduler was sent the command new
01/03/2015 05:49:47;0002;PBS_Server;Svr;PBS_Server;Torque Server Version = 3.0.5, loglevel = 0
01/03/2015 05:50:09;0040;PBS_Server;Svr;tyrone-cluster;Scheduler was sent the command new
01/03/2015 05:50:40;0040;PBS_Server;Svr;tyrone-cluster;Scheduler was sent the command new
01/03/2015 05:51:10;0040;PBS_Server;Svr;tyrone-cluster;Scheduler was sent the command new
01/03/2015 05:51:40;0040;PBS_Server;Svr;tyrone-cluster;Scheduler was sent the command new
01/03/2015 05:52:10;0040;PBS_Server;Svr;tyrone-cluster;Scheduler was sent the command new
01/03/2015 05:52:40;0040;PBS_Server;Svr;tyrone-cluster;Scheduler was sent the command new
01/03/2015 05:53:10;0040;PBS_Server;Svr;tyrone-cluster;Scheduler was sent the command new
01/03/2015 05:53:40;0040;PBS_Server;Svr;tyrone-cluster;Scheduler was sent the command new
01/03/2015 05:54:10;0040;PBS_Server;Svr;tyrone-cluster;Scheduler was sent the command new
01/03/2015 05:54:41;0040;PBS_Server;Svr;tyrone-cluster;Scheduler was sent the command new
01/03/2015 05:54:47;0002;PBS_Server;Svr;PBS_Server;Torque Server Version = 3.0.5, loglevel = 0
01/03/2015 05:55:11;0040;PBS_Server;Svr;tyrone-cluster;Scheduler was sent the command new
01/03/2015 05:55:41;0040;PBS_Server;Svr;tyrone-cluster;Scheduler was sent the command new
01/03/2015 05:56:11;0040;PBS_Server;Svr;tyrone-cluster;Scheduler was sent the command new
01/03/2015 05:56:41;0040;PBS_Server;Svr;tyrone-cluster;Scheduler was sent the command new
01/03/2015 05:57:11;0040;PBS_Server;Svr;tyrone-cluster;Scheduler was sent the command new
01/03/2015 05:57:41;0040;PBS_Server;Svr;tyrone-cluster;Scheduler was sent the command new
01/03/2015 05:58:11;0040;PBS_Server;Svr;tyrone-cluster;Scheduler was sent the command new
01/03/2015 05:58:41;0040;PBS_Server;Svr;tyrone-cluster;Scheduler was sent the command new
01/03/2015 05:59:11;0040;PBS_Server;Svr;tyrone-cluster;Scheduler was sent the command new
01/03/2015 05:59:42;0040;PBS_Server;Svr;tyrone-cluster;Scheduler was sent the command new
01/03/2015 05:59:47;0002;PBS_Server;Svr;PBS_Server;Torque Server Version = 3.0.5, loglevel = 0
01/03/2015 06:00:12;0040;PBS_Server;Svr;tyrone-cluster;Scheduler was sent the command new
01/03/2015 06:00:42;0040;PBS_Server;Svr;tyrone-cluster;Scheduler was sent the command new
01/03/2015 06:01:12;0040;PBS_Server;Svr;tyrone-cluster;Scheduler was sent the command new
01/03/2015 06:01:42;0040;PBS_Server;Svr;tyrone-cluster;Scheduler was sent the command new
01/03/2015 06:02:12;0040;PBS_Server;Svr;tyrone-cluster;Scheduler was sent the command new
01/03/2015 06:02:43;0040;PBS_Server;Svr;tyrone-cluster;Scheduler was sent the command new
01/03/2015 06:03:13;0040;PBS_Server;Svr;tyrone-cluster;Scheduler was sent the command new
01/03/2015 06:03:43;0040;PBS_Server;Svr;tyrone-cluster;Scheduler was sent the command new
01/03/2015 06:04:13;0040;PBS_Server;Svr;tyrone-cluster;Scheduler was sent the command new
01/03/2015 06:04:43;0040;PBS_Server;Svr;tyrone-cluster;Scheduler was sent the command new
01/03/2015 06:04:47;0002;PBS_Server;Svr;PBS_Server;Torque Server Version = 3.0.5, loglevel = 0
01/03/2015 06:05:13;0040;PBS_Server;Svr;tyrone-cluster;Scheduler was sent the command new
01/03/2015 06:05:43;0040;PBS_Server;Svr;tyrone-cluster;Scheduler was sent the command new
01/03/2015 06:06:13;0040;PBS_Server;Svr;tyrone-cluster;Scheduler was sent the command new
01/03/2015 06:06:44;0040;PBS_Server;Svr;tyrone-cluster;Scheduler was sent the command new
01/03/2015 06:07:14;0040;PBS_Server;Svr;tyrone-cluster;Scheduler was sent the command new
01/03/2015 06:07:44;0040;PBS_Server;Svr;tyrone-cluster;Scheduler was sent the command new
01/03/2015 06:08:14;0040;PBS_Server;Svr;tyrone-cluster;Scheduler was sent the command new
01/03/2015 06:08:44;0040;PBS_Server;Svr;tyrone-cluster;Scheduler was sent the command new
01/03/2015 06:09:14;0040;PBS_Server;Svr;tyrone-cluster;Scheduler was sent the command new
01/03/2015 06:09:44;0040;PBS_Server;Svr;tyrone-cluster;Scheduler was sent the command new
01/03/2015 06:09:47;0002;PBS_Server;Svr;PBS_Server;Torque Server Version = 3.0.5, loglevel = 0
01/03/2015 06:10:14;0040;PBS_Server;Svr;tyrone-cluster;Scheduler was sent the command new
01/03/2015 06:10:44;0040;PBS_Server;Svr;tyrone-cluster;Scheduler was sent the command new
01/03/2015 06:11:14;0040;PBS_Server;Svr;tyrone-cluster;Scheduler was sent the command new
01/03/2015 06:11:45;0040;PBS_Server;Svr;tyrone-cluster;Scheduler was sent the command new
01/03/2015 06:12:15;0040;PBS_Server;Svr;tyrone-cluster;Scheduler was sent the command new
01/03/2015 06:12:45;0040;PBS_Server;Svr;tyrone-cluster;Scheduler was sent the command new
01/03/2015 06:13:15;0040;PBS_Server;Svr;tyrone-cluster;Scheduler was sent the command new
01/03/2015 06:13:45;0040;PBS_Server;Svr;tyrone-cluster;Scheduler was sent the command new
01/03/2015 06:14:15;0040;PBS_Server;Svr;tyrone-cluster;Scheduler was sent the command new
01/03/2015 06:14:45;0040;PBS_Server;Svr;tyrone-cluster;Scheduler was sent the command new
01/03/2015 06:14:47;0002;PBS_Server;Svr;PBS_Server;Torque Server Version = 3.0.5, loglevel = 0
01/03/2015 06:15:15;0040;PBS_Server;Svr;tyrone-cluster;Scheduler was sent the command new
01/03/2015 06:15:45;0040;PBS_Server;Svr;tyrone-cluster;Scheduler was sent the command new
01/03/2015 06:16:15;0040;PBS_Server;Svr;tyrone-cluster;Scheduler was sent the command new
01/03/2015 06:16:46;0040;PBS_Server;Svr;tyrone-cluster;Scheduler was sent the command new
01/03/2015 06:17:16;0040;PBS_Server;Svr;tyrone-cluster;Scheduler was sent the command new
01/03/2015 06:17:46;0040;PBS_Server;Svr;tyrone-cluster;Scheduler was sent the command new
01/03/2015 06:18:16;0040;PBS_Server;Svr;tyrone-cluster;Scheduler was sent the command new
01/03/2015 06:18:46;0040;PBS_Server;Svr;tyrone-cluster;Scheduler was sent the command new
01/03/2015 06:19:16;0040;PBS_Server;Svr;tyrone-cluster;Scheduler was sent the command new
01/03/2015 06:19:46;0040;PBS_Server;Svr;tyrone-cluster;Scheduler was sent the command new
01/03/2015 06:19:47;0002;PBS_Server;Svr;PBS_Server;Torque Server Version = 3.0.5, loglevel = 0
01/03/2015 06:20:16;0040;PBS_Server;Svr;tyrone-cluster;Scheduler was sent the command new
01/03/2015 06:20:46;0040;PBS_Server;Svr;tyrone-cluster;Scheduler was sent the command new
01/03/2015 06:21:16;0040;PBS_Server;Svr;tyrone-cluster;Scheduler was sent the command new
01/03/2015 06:21:47;0040;PBS_Server;Svr;tyrone-cluster;Scheduler was sent the command new
01/03/2015 06:22:17;0040;PBS_Server;Svr;tyrone-cluster;Scheduler was sent the command new
01/03/2015 06:22:47;0040;PBS_Server;Svr;tyrone-cluster;Scheduler was sent the command new
01/03/2015 06:23:17;0040;PBS_Server;Svr;tyrone-cluster;Scheduler was sent the command new
01/03/2015 06:23:47;0040;PBS_Server;Svr;tyrone-cluster;Scheduler was sent the command new
01/03/2015 06:24:17;0040;PBS_Server;Svr;tyrone-cluster;Scheduler was sent the command new
01/03/2015 06:24:47;0002;PBS_Server;Svr;PBS_Server;Torque Server Version = 3.0.5, loglevel = 0
01/03/2015 06:24:47;0040;PBS_Server;Svr;tyrone-cluster;Scheduler was sent the command new
01/03/2015 06:25:17;0040;PBS_Server;Svr;tyrone-cluster;Scheduler was sent the command new
01/03/2015 06:25:47;0040;PBS_Server;Svr;tyrone-cluster;Scheduler was sent the command new
01/03/2015 06:26:18;0040;PBS_Server;Svr;tyrone-cluster;Scheduler was sent the command new
01/03/2015 06:26:47;0040;PBS_Server;Svr;tyrone-cluster;Scheduler was sent the command new
01/03/2015 06:27:18;0040;PBS_Server;Svr;tyrone-cluster;Scheduler was sent the command new
01/03/2015 06:27:48;0040;PBS_Server;Svr;tyrone-cluster;Scheduler was sent the command new
01/03/2015 06:28:18;0040;PBS_Server;Svr;tyrone-cluster;Scheduler was sent the command new
01/03/2015 06:28:48;0040;PBS_Server;Svr;tyrone-cluster;Scheduler was sent the command new
01/03/2015 06:29:18;0040;PBS_Server;Svr;tyrone-cluster;Scheduler was sent the command new
01/03/2015 06:29:47;0002;PBS_Server;Svr;PBS_Server;Torque Server Version = 3.0.5, loglevel = 0
01/03/2015 06:29:48;0040;PBS_Server;Svr;tyrone-cluster;Scheduler was sent the command new
01/03/2015 06:30:18;0040;PBS_Server;Svr;tyrone-cluster;Scheduler was sent the command new
01/03/2015 06:30:48;0040;PBS_Server;Svr;tyrone-cluster;Scheduler was sent the command new
01/03/2015 06:31:19;0040;PBS_Server;Svr;tyrone-cluster;Scheduler was sent the command new
01/03/2015 06:31:49;0040;PBS_Server;Svr;tyrone-cluster;Scheduler was sent the command new
01/03/2015 06:32:19;0040;PBS_Server;Svr;tyrone-cluster;Scheduler was sent the command new
01/03/2015 06:32:49;0040;PBS_Server;Svr;tyrone-cluster;Scheduler was sent the command new
01/03/2015 06:33:19;0040;PBS_Server;Svr;tyrone-cluster;Scheduler was sent the command new
01/03/2015 06:33:49;0040;PBS_Server;Svr;tyrone-cluster;Scheduler was sent the command new
01/03/2015 06:34:19;0040;PBS_Server;Svr;tyrone-cluster;Scheduler was sent the command new
01/03/2015 06:34:47;0002;PBS_Server;Svr;PBS_Server;Torque Server Version = 3.0.5, loglevel = 0
01/03/2015 06:34:49;0040;PBS_Server;Svr;tyrone-cluster;Scheduler was sent the command new
01/03/2015 06:35:19;0040;PBS_Server;Svr;tyrone-cluster;Scheduler was sent the command new
01/03/2015 06:35:49;0040;PBS_Server;Svr;tyrone-cluster;Scheduler was sent the command new
01/03/2015 06:36:20;0040;PBS_Server;Svr;tyrone-cluster;Scheduler was sent the command new
01/03/2015 06:36:50;0040;PBS_Server;Svr;tyrone-cluster;Scheduler was sent the command new
01/03/2015 06:37:20;0040;PBS_Server;Svr;tyrone-cluster;Scheduler was sent the command new
01/03/2015 06:37:50;0040;PBS_Server;Svr;tyrone-cluster;Scheduler was sent the command new
01/03/2015 06:38:20;0040;PBS_Server;Svr;tyrone-cluster;Scheduler was sent the command new
01/03/2015 06:38:50;0040;PBS_Server;Svr;tyrone-cluster;Scheduler was sent the command new
01/03/2015 06:39:20;0040;PBS_Server;Svr;tyrone-cluster;Scheduler was sent the command new
01/03/2015 06:39:47;0002;PBS_Server;Svr;PBS_Server;Torque Server Version = 3.0.5, loglevel = 0
01/03/2015 06:39:50;0040;PBS_Server;Svr;tyrone-cluster;Scheduler was sent the command new
01/03/2015 06:40:20;0040;PBS_Server;Svr;tyrone-cluster;Scheduler was sent the command new
01/03/2015 06:40:50;0040;PBS_Server;Svr;tyrone-cluster;Scheduler was sent the command new
01/03/2015 06:41:21;0040;PBS_Server;Svr;tyrone-cluster;Scheduler was sent the command new
01/03/2015 06:41:51;0040;PBS_Server;Svr;tyrone-cluster;Scheduler was sent the command new
01/03/2015 06:42:21;0040;PBS_Server;Svr;tyrone-cluster;Scheduler was sent the command new
01/03/2015 06:42:51;0040;PBS_Server;Svr;tyrone-cluster;Scheduler was sent the command new
01/03/2015 06:43:21;0040;PBS_Server;Svr;tyrone-cluster;Scheduler was sent the command new
01/03/2015 06:43:51;0040;PBS_Server;Svr;tyrone-cluster;Scheduler was sent the command new
01/03/2015 06:44:21;0040;PBS_Server;Svr;tyrone-cluster;Scheduler was sent the command new
01/03/2015 06:44:47;0002;PBS_Server;Svr;PBS_Server;Torque Server Version = 3.0.5, loglevel = 0
01/03/2015 06:44:51;0040;PBS_Server;Svr;tyrone-cluster;Scheduler was sent the command new
01/03/2015 06:45:22;0040;PBS_Server;Svr;tyrone-cluster;Scheduler was sent the command new
01/03/2015 06:45:52;0040;PBS_Server;Svr;tyrone-cluster;Scheduler was sent the command new
01/03/2015 06:46:22;0040;PBS_Server;Svr;tyrone-cluster;Scheduler was sent the command new
01/03/2015 06:46:52;0040;PBS_Server;Svr;tyrone-cluster;Scheduler was sent the command new
01/03/2015 06:47:22;0040;PBS_Server;Svr;tyrone-cluster;Scheduler was sent the command new
01/03/2015 06:47:52;0040;PBS_Server;Svr;tyrone-cluster;Scheduler was sent the command new
01/03/2015 06:48:22;0040;PBS_Server;Svr;tyrone-cluster;Scheduler was sent the command new
01/03/2015 06:48:52;0040;PBS_Server;Svr;tyrone-cluster;Scheduler was sent the command new
01/03/2015 06:49:22;0040;PBS_Server;Svr;tyrone-cluster;Scheduler was sent the command new
01/03/2015 06:49:47;0002;PBS_Server;Svr;PBS_Server;Torque Server Version = 3.0.5, loglevel = 0
01/03/2015 06:49:52;0040;PBS_Server;Svr;tyrone-cluster;Scheduler was sent the command new
01/03/2015 06:50:22;0040;PBS_Server;Svr;tyrone-cluster;Scheduler was sent the command new
01/03/2015 06:50:53;0040;PBS_Server;Svr;tyrone-cluster;Scheduler was sent the command new
01/03/2015 06:51:23;0040;PBS_Server;Svr;tyrone-cluster;Scheduler was sent the command new
01/03/2015 06:51:53;0040;PBS_Server;Svr;tyrone-cluster;Scheduler was sent the command new
01/03/2015 06:52:23;0040;PBS_Server;Svr;tyrone-cluster;Scheduler was sent the command new
01/03/2015 06:52:53;0040;PBS_Server;Svr;tyrone-cluster;Scheduler was sent the command new
01/03/2015 06:53:23;0040;PBS_Server;Svr;tyrone-cluster;Scheduler was sent the command new
01/03/2015 06:53:53;0040;PBS_Server;Svr;tyrone-cluster;Scheduler was sent the command new
01/03/2015 06:54:23;0040;PBS_Server;Svr;tyrone-cluster;Scheduler was sent the command new
01/03/2015 06:54:47;0002;PBS_Server;Svr;PBS_Server;Torque Server Version = 3.0.5, loglevel = 0
01/03/2015 06:54:54;0040;PBS_Server;Svr;tyrone-cluster;Scheduler was sent the command new
01/03/2015 06:55:24;0040;PBS_Server;Svr;tyrone-cluster;Scheduler was sent the command new
01/03/2015 06:55:54;0040;PBS_Server;Svr;tyrone-cluster;Scheduler was sent the command new
01/03/2015 06:56:24;0040;PBS_Server;Svr;tyrone-cluster;Scheduler was sent the command new
01/03/2015 06:56:54;0040;PBS_Server;Svr;tyrone-cluster;Scheduler was sent the command new
01/03/2015 06:57:24;0040;PBS_Server;Svr;tyrone-cluster;Scheduler was sent the command new
01/03/2015 06:57:54;0040;PBS_Server;Svr;tyrone-cluster;Scheduler was sent the command new
01/03/2015 06:58:24;0040;PBS_Server;Svr;tyrone-cluster;Scheduler was sent the command new
01/03/2015 06:58:54;0040;PBS_Server;Svr;tyrone-cluster;Scheduler was sent the command new
01/03/2015 06:59:24;0040;PBS_Server;Svr;tyrone-cluster;Scheduler was sent the command new
01/03/2015 06:59:47;0002;PBS_Server;Svr;PBS_Server;Torque Server Version = 3.0.5, loglevel = 0
01/03/2015 06:59:54;0040;PBS_Server;Svr;tyrone-cluster;Scheduler was sent the command new
01/03/2015 07:00:25;0040;PBS_Server;Svr;tyrone-cluster;Scheduler was sent the command new
01/03/2015 07:00:55;0040;PBS_Server;Svr;tyrone-cluster;Scheduler was sent the command new
01/03/2015 07:01:25;0040;PBS_Server;Svr;tyrone-cluster;Scheduler was sent the command new
01/03/2015 07:01:55;0040;PBS_Server;Svr;tyrone-cluster;Scheduler was sent the command new
01/03/2015 07:02:25;0040;PBS_Server;Svr;tyrone-cluster;Scheduler was sent the command new
01/03/2015 07:02:55;0040;PBS_Server;Svr;tyrone-cluster;Scheduler was sent the command new
01/03/2015 07:03:25;0040;PBS_Server;Svr;tyrone-cluster;Scheduler was sent the command new
01/03/2015 07:03:55;0040;PBS_Server;Svr;tyrone-cluster;Scheduler was sent the command new
01/03/2015 07:04:26;0040;PBS_Server;Svr;tyrone-cluster;Scheduler was sent the command new
01/03/2015 07:04:47;0002;PBS_Server;Svr;PBS_Server;Torque Server Version = 3.0.5, loglevel = 0
01/03/2015 07:04:56;0040;PBS_Server;Svr;tyrone-cluster;Scheduler was sent the command new
01/03/2015 07:05:26;0040;PBS_Server;Svr;tyrone-cluster;Scheduler was sent the command new
01/03/2015 07:05:56;0040;PBS_Server;Svr;tyrone-cluster;Scheduler was sent the command new
01/03/2015 07:06:26;0040;PBS_Server;Svr;tyrone-cluster;Scheduler was sent the command new
01/03/2015 07:06:56;0040;PBS_Server;Svr;tyrone-cluster;Scheduler was sent the command new
01/03/2015 07:07:26;0040;PBS_Server;Svr;tyrone-cluster;Scheduler was sent the command new
01/03/2015 07:07:56;0040;PBS_Server;Svr;tyrone-cluster;Scheduler was sent the command new
01/03/2015 07:08:26;0040;PBS_Server;Svr;tyrone-cluster;Scheduler was sent the command new
01/03/2015 07:08:29;000d;PBS_Server;Job;46290.tyrone-cluster;Not sending email: User does not want mail of this type.
01/03/2015 07:08:29;0010;PBS_Server;Job;46290.tyrone-cluster;Exit_status=1 resources_used.cput=03:37:36 resources_used.mem=480244kb resources_used.vmem=3216132kb resources_used.walltime=04:43:00
01/03/2015 07:08:29;0008;PBS_Server;Job;NULL;on_job_exit valid pjob: 0x13fee50 (substate=50)
01/03/2015 07:08:29;0008;PBS_Server;Job;NULL;on_job_exit valid pjob: 0x13fee50 (substate=51)
01/03/2015 07:08:29;0008;PBS_Server;Job;NULL;on_job_exit valid pjob: 0x13fee50 (substate=51)
01/03/2015 07:08:29;0008;PBS_Server;Job;NULL;on_job_exit valid pjob: 0x13fee50 (substate=53)
01/03/2015 07:08:29;0100;PBS_Server;Job;46290.tyrone-cluster;dequeuing from qp256, state COMPLETE
01/03/2015 07:08:29;0040;PBS_Server;Svr;tyrone-cluster;Scheduler was sent the command term
01/03/2015 07:08:29;0008;PBS_Server;Job;46192.tyrone-cluster;Job Modified at request of Scheduler@tyrone-cluster
01/03/2015 07:08:29;0008;PBS_Server;Job;46192.tyrone-cluster;Job Run at request of Scheduler@tyrone-cluster
01/03/2015 07:08:29;0040;PBS_Server;Svr;tyrone-cluster;Scheduler was sent the command recyc
01/03/2015 07:08:41;000d;PBS_Server;Job;46192.tyrone-cluster;Not sending email: User does not want mail of this type.
01/03/2015 07:08:41;0010;PBS_Server;Job;46192.tyrone-cluster;Exit_status=255 resources_used.cput=00:06:48 resources_used.mem=804kb resources_used.vmem=13628kb resources_used.walltime=00:00:12
01/03/2015 07:08:41;0008;PBS_Server;Job;NULL;on_job_exit valid pjob: 0x13fadd0 (substate=50)
01/03/2015 07:08:41;0008;PBS_Server;Job;NULL;on_job_exit valid pjob: 0x13fadd0 (substate=51)
01/03/2015 07:08:41;0008;PBS_Server;Job;NULL;on_job_exit valid pjob: 0x13fadd0 (substate=51)
01/03/2015 07:08:41;0008;PBS_Server;Job;NULL;on_job_exit valid pjob: 0x13fadd0 (substate=53)
01/03/2015 07:08:41;0100;PBS_Server;Job;46192.tyrone-cluster;dequeuing from qp256, state COMPLETE
01/03/2015 07:08:41;0040;PBS_Server;Svr;tyrone-cluster;Scheduler was sent the command term
01/03/2015 07:08:41;0008;PBS_Server;Job;46190.tyrone-cluster;Job Modified at request of Scheduler@tyrone-cluster
01/03/2015 07:08:41;0008;PBS_Server;Job;46190.tyrone-cluster;Job Run at request of Scheduler@tyrone-cluster
01/03/2015 07:08:41;0040;PBS_Server;Svr;tyrone-cluster;Scheduler was sent the command recyc
01/03/2015 07:08:56;0100;PBS_Server;Job;46194.tyrone-cluster;dequeuing from batch, state QUEUED
01/03/2015 07:08:56;0100;PBS_Server;Job;46194.tyrone-cluster;enqueuing into qp256, state 1 hop 1
01/03/2015 07:08:56;0040;PBS_Server;Svr;tyrone-cluster;Scheduler was sent the command new
01/03/2015 07:08:57;0008;PBS_Server;Job;46194.tyrone-cluster;Job Modified at request of Scheduler@tyrone-cluster
01/03/2015 07:09:27;0040;PBS_Server;Svr;tyrone-cluster;Scheduler was sent the command new
01/03/2015 07:09:43;000d;PBS_Server;Job;46190.tyrone-cluster;Not sending email: User does not want mail of this type.
01/03/2015 07:09:47;0002;PBS_Server;Svr;PBS_Server;Torque Server Version = 3.0.5, loglevel = 0
01/03/2015 07:09:57;0040;PBS_Server;Svr;tyrone-cluster;Scheduler was sent the command new
01/03/2015 07:10:27;0040;PBS_Server;Svr;tyrone-cluster;Scheduler was sent the command new
01/03/2015 07:10:57;0040;PBS_Server;Svr;tyrone-cluster;Scheduler was sent the command new
01/03/2015 07:11:27;0040;PBS_Server;Svr;tyrone-cluster;Scheduler was sent the command new
01/03/2015 07:11:57;0040;PBS_Server;Svr;tyrone-cluster;Scheduler was sent the command new
01/03/2015 07:12:27;0040;PBS_Server;Svr;tyrone-cluster;Scheduler was sent the command new
01/03/2015 07:12:57;0040;PBS_Server;Svr;tyrone-cluster;Scheduler was sent the command new
01/03/2015 07:13:27;0040;PBS_Server;Svr;tyrone-cluster;Scheduler was sent the command new
01/03/2015 07:13:58;0040;PBS_Server;Svr;tyrone-cluster;Scheduler was sent the command new
01/03/2015 07:14:28;0040;PBS_Server;Svr;tyrone-cluster;Scheduler was sent the command new
01/03/2015 07:14:47;0002;PBS_Server;Svr;PBS_Server;Torque Server Version = 3.0.5, loglevel = 0
01/03/2015 07:14:58;0040;PBS_Server;Svr;tyrone-cluster;Scheduler was sent the command new
01/03/2015 07:15:28;0040;PBS_Server;Svr;tyrone-cluster;Scheduler was sent the command new
01/03/2015 07:15:58;0040;PBS_Server;Svr;tyrone-cluster;Scheduler was sent the command new
01/03/2015 07:16:28;0040;PBS_Server;Svr;tyrone-cluster;Scheduler was sent the command new
01/03/2015 07:16:58;0040;PBS_Server;Svr;tyrone-cluster;Scheduler was sent the command new
01/03/2015 07:17:28;0040;PBS_Server;Svr;tyrone-cluster;Scheduler was sent the command new
01/03/2015 07:17:58;0040;PBS_Server;Svr;tyrone-cluster;Scheduler was sent the command new
01/03/2015 07:18:28;0040;PBS_Server;Svr;tyrone-cluster;Scheduler was sent the command new
01/03/2015 07:18:58;0040;PBS_Server;Svr;tyrone-cluster;Scheduler was sent the command new
01/03/2015 07:19:28;0040;PBS_Server;Svr;tyrone-cluster;Scheduler was sent the command new
01/03/2015 07:19:47;0002;PBS_Server;Svr;PBS_Server;Torque Server Version = 3.0.5, loglevel = 0
01/03/2015 07:19:59;0040;PBS_Server;Svr;tyrone-cluster;Scheduler was sent the command new
01/03/2015 07:20:29;0040;PBS_Server;Svr;tyrone-cluster;Scheduler was sent the command new
01/03/2015 07:20:59;0040;PBS_Server;Svr;tyrone-cluster;Scheduler was sent the command new
01/03/2015 07:21:29;0040;PBS_Server;Svr;tyrone-cluster;Scheduler was sent the command new
01/03/2015 07:21:59;0040;PBS_Server;Svr;tyrone-cluster;Scheduler was sent the command new
01/03/2015 07:22:29;0040;PBS_Server;Svr;tyrone-cluster;Scheduler was sent the command new
01/03/2015 07:22:59;0040;PBS_Server;Svr;tyrone-cluster;Scheduler was sent the command new
01/03/2015 07:23:30;0040;PBS_Server;Svr;tyrone-cluster;Scheduler was sent the command new
01/03/2015 07:24:00;0040;PBS_Server;Svr;tyrone-cluster;Scheduler was sent the command new
01/03/2015 07:24:30;0040;PBS_Server;Svr;tyrone-cluster;Scheduler was sent the command new
01/03/2015 07:24:47;0002;PBS_Server;Svr;PBS_Server;Torque Server Version = 3.0.5, loglevel = 0
01/03/2015 07:25:00;0040;PBS_Server;Svr;tyrone-cluster;Scheduler was sent the command new
01/03/2015 07:25:27;0100;PBS_Server;Job;46407.tyrone-cluster;enqueuing into batch, state 1 hop 1
01/03/2015 07:25:27;0100;PBS_Server;Job;46407.tyrone-cluster;dequeuing from batch, state QUEUED
01/03/2015 07:25:27;0100;PBS_Server;Job;46407.tyrone-cluster;enqueuing into qp32, state 1 hop 1
01/03/2015 07:25:27;0008;PBS_Server;Job;46407.tyrone-cluster;Job Queued at request of chejasj@tyrone-cluster, owner = chejasj@tyrone-cluster, job name = qp32, queue = qp32
01/03/2015 07:25:27;0040;PBS_Server;Svr;tyrone-cluster;Scheduler was sent the command new
01/03/2015 07:25:27;0008;PBS_Server;Job;46407.tyrone-cluster;Job Modified at request of Scheduler@tyrone-cluster
01/03/2015 07:25:30;0040;PBS_Server;Svr;tyrone-cluster;Scheduler was sent the command new
01/03/2015 07:26:00;0040;PBS_Server;Svr;tyrone-cluster;Scheduler was sent the command new
01/03/2015 07:26:30;0040;PBS_Server;Svr;tyrone-cluster;Scheduler was sent the command new
01/03/2015 07:27:00;0040;PBS_Server;Svr;tyrone-cluster;Scheduler was sent the command new
01/03/2015 07:27:30;0040;PBS_Server;Svr;tyrone-cluster;Scheduler was sent the command new
01/03/2015 07:28:00;0040;PBS_Server;Svr;tyrone-cluster;Scheduler was sent the command new
01/03/2015 07:28:31;0040;PBS_Server;Svr;tyrone-cluster;Scheduler was sent the command new
01/03/2015 07:29:01;0040;PBS_Server;Svr;tyrone-cluster;Scheduler was sent the command new
01/03/2015 07:29:31;0040;PBS_Server;Svr;tyrone-cluster;Scheduler was sent the command new
01/03/2015 07:29:47;0002;PBS_Server;Svr;PBS_Server;Torque Server Version = 3.0.5, loglevel = 0
01/03/2015 07:30:01;0040;PBS_Server;Svr;tyrone-cluster;Scheduler was sent the command new
01/03/2015 07:30:31;0040;PBS_Server;Svr;tyrone-cluster;Scheduler was sent the command new
01/03/2015 07:31:01;0040;PBS_Server;Svr;tyrone-cluster;Scheduler was sent the command new
01/03/2015 07:31:31;0040;PBS_Server;Svr;tyrone-cluster;Scheduler was sent the command new
01/03/2015 07:32:01;0040;PBS_Server;Svr;tyrone-cluster;Scheduler was sent the command new
01/03/2015 07:32:31;0040;PBS_Server;Svr;tyrone-cluster;Scheduler was sent the command new
01/03/2015 07:33:02;0040;PBS_Server;Svr;tyrone-cluster;Scheduler was sent the command new
01/03/2015 07:33:32;0040;PBS_Server;Svr;tyrone-cluster;Scheduler was sent the command new
01/03/2015 07:34:02;0040;PBS_Server;Svr;tyrone-cluster;Scheduler was sent the command new
01/03/2015 07:34:32;0040;PBS_Server;Svr;tyrone-cluster;Scheduler was sent the command new
01/03/2015 07:34:47;0002;PBS_Server;Svr;PBS_Server;Torque Server Version = 3.0.5, loglevel = 0
01/03/2015 07:35:02;0040;PBS_Server;Svr;tyrone-cluster;Scheduler was sent the command new
01/03/2015 07:35:32;0040;PBS_Server;Svr;tyrone-cluster;Scheduler was sent the command new
01/03/2015 07:36:02;0040;PBS_Server;Svr;tyrone-cluster;Scheduler was sent the command new
01/03/2015 07:36:32;0040;PBS_Server;Svr;tyrone-cluster;Scheduler was sent the command new
01/03/2015 07:37:02;0040;PBS_Server;Svr;tyrone-cluster;Scheduler was sent the command new
01/03/2015 07:37:32;0040;PBS_Server;Svr;tyrone-cluster;Scheduler was sent the command new
01/03/2015 07:38:02;0040;PBS_Server;Svr;tyrone-cluster;Scheduler was sent the command new
01/03/2015 07:38:33;0040;PBS_Server;Svr;tyrone-cluster;Scheduler was sent the command new
01/03/2015 07:39:03;0040;PBS_Server;Svr;tyrone-cluster;Scheduler was sent the command new
01/03/2015 07:39:33;0040;PBS_Server;Svr;tyrone-cluster;Scheduler was sent the command new
01/03/2015 07:39:47;0002;PBS_Server;Svr;PBS_Server;Torque Server Version = 3.0.5, loglevel = 0
01/03/2015 07:40:03;0040;PBS_Server;Svr;tyrone-cluster;Scheduler was sent the command new
01/03/2015 07:40:33;0040;PBS_Server;Svr;tyrone-cluster;Scheduler was sent the command new
01/03/2015 07:41:03;0040;PBS_Server;Svr;tyrone-cluster;Scheduler was sent the command new
01/03/2015 07:41:33;0040;PBS_Server;Svr;tyrone-cluster;Scheduler was sent the command new
01/03/2015 07:42:04;0040;PBS_Server;Svr;tyrone-cluster;Scheduler was sent the command new
01/03/2015 07:42:34;0040;PBS_Server;Svr;tyrone-cluster;Scheduler was sent the command new
01/03/2015 07:43:04;0040;PBS_Server;Svr;tyrone-cluster;Scheduler was sent the command new
01/03/2015 07:43:34;0040;PBS_Server;Svr;tyrone-cluster;Scheduler was sent the command new
01/03/2015 07:44:04;0040;PBS_Server;Svr;tyrone-cluster;Scheduler was sent the command new
01/03/2015 07:44:34;0040;PBS_Server;Svr;tyrone-cluster;Scheduler was sent the command new
01/03/2015 07:44:47;0002;PBS_Server;Svr;PBS_Server;Torque Server Version = 3.0.5, loglevel = 0
01/03/2015 07:45:04;0040;PBS_Server;Svr;tyrone-cluster;Scheduler was sent the command new
01/03/2015 07:45:34;0040;PBS_Server;Svr;tyrone-cluster;Scheduler was sent the command new
01/03/2015 07:46:04;0040;PBS_Server;Svr;tyrone-cluster;Scheduler was sent the command new
01/03/2015 07:46:34;0040;PBS_Server;Svr;tyrone-cluster;Scheduler was sent the command new
01/03/2015 07:47:05;0040;PBS_Server;Svr;tyrone-cluster;Scheduler was sent the command new
01/03/2015 07:47:35;0040;PBS_Server;Svr;tyrone-cluster;Scheduler was sent the command new
01/03/2015 07:48:05;0040;PBS_Server;Svr;tyrone-cluster;Scheduler was sent the command new
01/03/2015 07:48:35;0040;PBS_Server;Svr;tyrone-cluster;Scheduler was sent the command new
01/03/2015 07:49:05;0040;PBS_Server;Svr;tyrone-cluster;Scheduler was sent the command new
01/03/2015 07:49:35;0040;PBS_Server;Svr;tyrone-cluster;Scheduler was sent the command new
01/03/2015 07:49:47;0002;PBS_Server;Svr;PBS_Server;Torque Server Version = 3.0.5, loglevel = 0
01/03/2015 07:50:05;0040;PBS_Server;Svr;tyrone-cluster;Scheduler was sent the command new
01/03/2015 07:50:35;0040;PBS_Server;Svr;tyrone-cluster;Scheduler was sent the command new
01/03/2015 07:51:05;0040;PBS_Server;Svr;tyrone-cluster;Scheduler was sent the command new
01/03/2015 07:51:35;0040;PBS_Server;Svr;tyrone-cluster;Scheduler was sent the command new
01/03/2015 07:52:06;0040;PBS_Server;Svr;tyrone-cluster;Scheduler was sent the command new
01/03/2015 07:52:36;0040;PBS_Server;Svr;tyrone-cluster;Scheduler was sent the command new
01/03/2015 07:53:06;0040;PBS_Server;Svr;tyrone-cluster;Scheduler was sent the command new
01/03/2015 07:53:36;0040;PBS_Server;Svr;tyrone-cluster;Scheduler was sent the command new
01/03/2015 07:54:06;0040;PBS_Server;Svr;tyrone-cluster;Scheduler was sent the command new
01/03/2015 07:54:36;0040;PBS_Server;Svr;tyrone-cluster;Scheduler was sent the command new
01/03/2015 07:54:47;0002;PBS_Server;Svr;PBS_Server;Torque Server Version = 3.0.5, loglevel = 0
01/03/2015 07:55:06;0040;PBS_Server;Svr;tyrone-cluster;Scheduler was sent the command new
01/03/2015 07:55:36;0040;PBS_Server;Svr;tyrone-cluster;Scheduler was sent the command new
01/03/2015 07:56:06;0040;PBS_Server;Svr;tyrone-cluster;Scheduler was sent the command new
01/03/2015 07:56:36;0040;PBS_Server;Svr;tyrone-cluster;Scheduler was sent the command new
01/03/2015 07:57:06;0040;PBS_Server;Svr;tyrone-cluster;Scheduler was sent the command new
01/03/2015 07:57:37;0040;PBS_Server;Svr;tyrone-cluster;Scheduler was sent the command new
01/03/2015 07:58:07;0040;PBS_Server;Svr;tyrone-cluster;Scheduler was sent the command new
01/03/2015 07:58:37;0040;PBS_Server;Svr;tyrone-cluster;Scheduler was sent the command new
01/03/2015 07:59:07;0040;PBS_Server;Svr;tyrone-cluster;Scheduler was sent the command new
01/03/2015 07:59:37;0040;PBS_Server;Svr;tyrone-cluster;Scheduler was sent the command new
01/03/2015 07:59:47;0002;PBS_Server;Svr;PBS_Server;Torque Server Version = 3.0.5, loglevel = 0
01/03/2015 08:00:07;0040;PBS_Server;Svr;tyrone-cluster;Scheduler was sent the command new
01/03/2015 08:00:37;0040;PBS_Server;Svr;tyrone-cluster;Scheduler was sent the command new
01/03/2015 08:01:07;0040;PBS_Server;Svr;tyrone-cluster;Scheduler was sent the command new
01/03/2015 08:01:37;0040;PBS_Server;Svr;tyrone-cluster;Scheduler was sent the command new
01/03/2015 08:02:07;0040;PBS_Server;Svr;tyrone-cluster;Scheduler was sent the command new
01/03/2015 08:02:38;0040;PBS_Server;Svr;tyrone-cluster;Scheduler was sent the command new
01/03/2015 08:03:08;0040;PBS_Server;Svr;tyrone-cluster;Scheduler was sent the command new
01/03/2015 08:03:38;0040;PBS_Server;Svr;tyrone-cluster;Scheduler was sent the command new
01/03/2015 08:04:08;0040;PBS_Server;Svr;tyrone-cluster;Scheduler was sent the command new
01/03/2015 08:04:38;0040;PBS_Server;Svr;tyrone-cluster;Scheduler was sent the command new
01/03/2015 08:04:47;0002;PBS_Server;Svr;PBS_Server;Torque Server Version = 3.0.5, loglevel = 0
01/03/2015 08:05:08;0040;PBS_Server;Svr;tyrone-cluster;Scheduler was sent the command new
01/03/2015 08:05:38;0040;PBS_Server;Svr;tyrone-cluster;Scheduler was sent the command new
01/03/2015 08:06:08;0040;PBS_Server;Svr;tyrone-cluster;Scheduler was sent the command new
01/03/2015 08:06:38;0040;PBS_Server;Svr;tyrone-cluster;Scheduler was sent the command new
01/03/2015 08:07:09;0040;PBS_Server;Svr;tyrone-cluster;Scheduler was sent the command new
01/03/2015 08:07:38;0040;PBS_Server;Svr;tyrone-cluster;Scheduler was sent the command new
01/03/2015 08:08:08;0040;PBS_Server;Svr;tyrone-cluster;Scheduler was sent the command new
01/03/2015 08:08:39;0040;PBS_Server;Svr;tyrone-cluster;Scheduler was sent the command new
01/03/2015 08:09:09;0040;PBS_Server;Svr;tyrone-cluster;Scheduler was sent the command new
01/03/2015 08:09:38;0040;PBS_Server;Svr;tyrone-cluster;Scheduler was sent the command new
01/03/2015 08:09:47;0002;PBS_Server;Svr;PBS_Server;Torque Server Version = 3.0.5, loglevel = 0
01/03/2015 08:10:08;0040;PBS_Server;Svr;tyrone-cluster;Scheduler was sent the command new
01/03/2015 08:10:39;0040;PBS_Server;Svr;tyrone-cluster;Scheduler was sent the command new
01/03/2015 08:11:08;0040;PBS_Server;Svr;tyrone-cluster;Scheduler was sent the command new
01/03/2015 08:11:39;0040;PBS_Server;Svr;tyrone-cluster;Scheduler was sent the command new
01/03/2015 08:12:10;0040;PBS_Server;Svr;tyrone-cluster;Scheduler was sent the command new
01/03/2015 08:12:39;0040;PBS_Server;Svr;tyrone-cluster;Scheduler was sent the command new
01/03/2015 08:13:10;0040;PBS_Server;Svr;tyrone-cluster;Scheduler was sent the command new
01/03/2015 08:13:40;0040;PBS_Server;Svr;tyrone-cluster;Scheduler was sent the command new
01/03/2015 08:14:10;0040;PBS_Server;Svr;tyrone-cluster;Scheduler was sent the command new
01/03/2015 08:14:40;0040;PBS_Server;Svr;tyrone-cluster;Scheduler was sent the command new
01/03/2015 08:14:47;0002;PBS_Server;Svr;PBS_Server;Torque Server Version = 3.0.5, loglevel = 0
01/03/2015 08:15:10;0040;PBS_Server;Svr;tyrone-cluster;Scheduler was sent the command new
01/03/2015 08:15:40;0040;PBS_Server;Svr;tyrone-cluster;Scheduler was sent the command new
01/03/2015 08:16:10;0040;PBS_Server;Svr;tyrone-cluster;Scheduler was sent the command new
01/03/2015 08:16:40;0040;PBS_Server;Svr;tyrone-cluster;Scheduler was sent the command new
01/03/2015 08:17:11;0040;PBS_Server;Svr;tyrone-cluster;Scheduler was sent the command new
01/03/2015 08:17:41;0040;PBS_Server;Svr;tyrone-cluster;Scheduler was sent the command new
01/03/2015 08:18:11;0040;PBS_Server;Svr;tyrone-cluster;Scheduler was sent the command new
01/03/2015 08:18:41;0040;PBS_Server;Svr;tyrone-cluster;Scheduler was sent the command new
01/03/2015 08:19:11;0040;PBS_Server;Svr;tyrone-cluster;Scheduler was sent the command new
01/03/2015 08:19:41;0040;PBS_Server;Svr;tyrone-cluster;Scheduler was sent the command new
01/03/2015 08:19:47;0002;PBS_Server;Svr;PBS_Server;Torque Server Version = 3.0.5, loglevel = 0
01/03/2015 08:20:11;0040;PBS_Server;Svr;tyrone-cluster;Scheduler was sent the command new
01/03/2015 08:20:41;0040;PBS_Server;Svr;tyrone-cluster;Scheduler was sent the command new
01/03/2015 08:21:11;0040;PBS_Server;Svr;tyrone-cluster;Scheduler was sent the command new
01/03/2015 08:21:41;0040;PBS_Server;Svr;tyrone-cluster;Scheduler was sent the command new
01/03/2015 08:22:11;0040;PBS_Server;Svr;tyrone-cluster;Scheduler was sent the command new
01/03/2015 08:22:42;0040;PBS_Server;Svr;tyrone-cluster;Scheduler was sent the command new
01/03/2015 08:23:12;0040;PBS_Server;Svr;tyrone-cluster;Scheduler was sent the command new
01/03/2015 08:23:42;0040;PBS_Server;Svr;tyrone-cluster;Scheduler was sent the command new
01/03/2015 08:24:12;0040;PBS_Server;Svr;tyrone-cluster;Scheduler was sent the command new
01/03/2015 08:24:42;0040;PBS_Server;Svr;tyrone-cluster;Scheduler was sent the command new
01/03/2015 08:24:47;0002;PBS_Server;Svr;PBS_Server;Torque Server Version = 3.0.5, loglevel = 0
01/03/2015 08:25:12;0040;PBS_Server;Svr;tyrone-cluster;Scheduler was sent the command new
01/03/2015 08:25:42;0040;PBS_Server;Svr;tyrone-cluster;Scheduler was sent the command new
01/03/2015 08:26:12;0040;PBS_Server;Svr;tyrone-cluster;Scheduler was sent the command new
01/03/2015 08:26:42;0040;PBS_Server;Svr;tyrone-cluster;Scheduler was sent the command new
01/03/2015 08:27:13;0040;PBS_Server;Svr;tyrone-cluster;Scheduler was sent the command new
01/03/2015 08:27:43;0040;PBS_Server;Svr;tyrone-cluster;Scheduler was sent the command new
01/03/2015 08:28:13;0040;PBS_Server;Svr;tyrone-cluster;Scheduler was sent the command new
01/03/2015 08:28:43;0040;PBS_Server;Svr;tyrone-cluster;Scheduler was sent the command new
01/03/2015 08:29:13;0040;PBS_Server;Svr;tyrone-cluster;Scheduler was sent the command new
01/03/2015 08:29:43;0040;PBS_Server;Svr;tyrone-cluster;Scheduler was sent the command new
01/03/2015 08:29:47;0002;PBS_Server;Svr;PBS_Server;Torque Server Version = 3.0.5, loglevel = 0
01/03/2015 08:30:13;0040;PBS_Server;Svr;tyrone-cluster;Scheduler was sent the command new
01/03/2015 08:30:43;0040;PBS_Server;Svr;tyrone-cluster;Scheduler was sent the command new
01/03/2015 08:31:13;0040;PBS_Server;Svr;tyrone-cluster;Scheduler was sent the command new
01/03/2015 08:31:43;0040;PBS_Server;Svr;tyrone-cluster;Scheduler was sent the command new
01/03/2015 08:32:13;0040;PBS_Server;Svr;tyrone-cluster;Scheduler was sent the command new
01/03/2015 08:32:44;0040;PBS_Server;Svr;tyrone-cluster;Scheduler was sent the command new
01/03/2015 08:33:14;0040;PBS_Server;Svr;tyrone-cluster;Scheduler was sent the command new
01/03/2015 08:33:44;0040;PBS_Server;Svr;tyrone-cluster;Scheduler was sent the command new
01/03/2015 08:34:14;0040;PBS_Server;Svr;tyrone-cluster;Scheduler was sent the command new
01/03/2015 08:34:44;0040;PBS_Server;Svr;tyrone-cluster;Scheduler was sent the command new
01/03/2015 08:34:47;0002;PBS_Server;Svr;PBS_Server;Torque Server Version = 3.0.5, loglevel = 0
01/03/2015 08:35:14;0040;PBS_Server;Svr;tyrone-cluster;Scheduler was sent the command new
01/03/2015 08:35:44;0040;PBS_Server;Svr;tyrone-cluster;Scheduler was sent the command new
01/03/2015 08:36:14;0040;PBS_Server;Svr;tyrone-cluster;Scheduler was sent the command new
01/03/2015 08:36:44;0040;PBS_Server;Svr;tyrone-cluster;Scheduler was sent the command new
01/03/2015 08:37:15;0040;PBS_Server;Svr;tyrone-cluster;Scheduler was sent the command new
01/03/2015 08:37:45;0040;PBS_Server;Svr;tyrone-cluster;Scheduler was sent the command new
01/03/2015 08:38:15;0040;PBS_Server;Svr;tyrone-cluster;Scheduler was sent the command new
01/03/2015 08:38:45;0040;PBS_Server;Svr;tyrone-cluster;Scheduler was sent the command new
01/03/2015 08:39:15;0040;PBS_Server;Svr;tyrone-cluster;Scheduler was sent the command new
01/03/2015 08:39:45;0040;PBS_Server;Svr;tyrone-cluster;Scheduler was sent the command new
01/03/2015 08:39:47;0002;PBS_Server;Svr;PBS_Server;Torque Server Version = 3.0.5, loglevel = 0
01/03/2015 08:40:15;0040;PBS_Server;Svr;tyrone-cluster;Scheduler was sent the command new
01/03/2015 08:40:45;0040;PBS_Server;Svr;tyrone-cluster;Scheduler was sent the command new
01/03/2015 08:41:15;0040;PBS_Server;Svr;tyrone-cluster;Scheduler was sent the command new
01/03/2015 08:41:46;0040;PBS_Server;Svr;tyrone-cluster;Scheduler was sent the command new
01/03/2015 08:42:16;0040;PBS_Server;Svr;tyrone-cluster;Scheduler was sent the command new
01/03/2015 08:42:46;0040;PBS_Server;Svr;tyrone-cluster;Scheduler was sent the command new
01/03/2015 08:43:16;0040;PBS_Server;Svr;tyrone-cluster;Scheduler was sent the command new
01/03/2015 08:43:46;0040;PBS_Server;Svr;tyrone-cluster;Scheduler was sent the command new
01/03/2015 08:44:16;0040;PBS_Server;Svr;tyrone-cluster;Scheduler was sent the command new
01/03/2015 08:44:46;0040;PBS_Server;Svr;tyrone-cluster;Scheduler was sent the command new
01/03/2015 08:44:47;0002;PBS_Server;Svr;PBS_Server;Torque Server Version = 3.0.5, loglevel = 0
01/03/2015 08:45:16;0040;PBS_Server;Svr;tyrone-cluster;Scheduler was sent the command new
01/03/2015 08:45:46;0040;PBS_Server;Svr;tyrone-cluster;Scheduler was sent the command new
01/03/2015 08:46:16;0040;PBS_Server;Svr;tyrone-cluster;Scheduler was sent the command new
01/03/2015 08:46:47;0040;PBS_Server;Svr;tyrone-cluster;Scheduler was sent the command new
01/03/2015 08:47:17;0040;PBS_Server;Svr;tyrone-cluster;Scheduler was sent the command new
01/03/2015 08:47:47;0040;PBS_Server;Svr;tyrone-cluster;Scheduler was sent the command new
01/03/2015 08:48:17;0040;PBS_Server;Svr;tyrone-cluster;Scheduler was sent the command new
01/03/2015 08:48:47;0040;PBS_Server;Svr;tyrone-cluster;Scheduler was sent the command new
01/03/2015 08:49:17;0040;PBS_Server;Svr;tyrone-cluster;Scheduler was sent the command new
01/03/2015 08:49:47;0002;PBS_Server;Svr;PBS_Server;Torque Server Version = 3.0.5, loglevel = 0
01/03/2015 08:49:47;0040;PBS_Server;Svr;tyrone-cluster;Scheduler was sent the command new
01/03/2015 08:50:17;0040;PBS_Server;Svr;tyrone-cluster;Scheduler was sent the command new
01/03/2015 08:50:47;0040;PBS_Server;Svr;tyrone-cluster;Scheduler was sent the command new
01/03/2015 08:51:17;0040;PBS_Server;Svr;tyrone-cluster;Scheduler was sent the command new
01/03/2015 08:51:48;0040;PBS_Server;Svr;tyrone-cluster;Scheduler was sent the command new
01/03/2015 08:52:17;0040;PBS_Server;Svr;tyrone-cluster;Scheduler was sent the command new
01/03/2015 08:52:48;0040;PBS_Server;Svr;tyrone-cluster;Scheduler was sent the command new
01/03/2015 08:53:18;0040;PBS_Server;Svr;tyrone-cluster;Scheduler was sent the command new
01/03/2015 08:53:48;0040;PBS_Server;Svr;tyrone-cluster;Scheduler was sent the command new
01/03/2015 08:54:18;0040;PBS_Server;Svr;tyrone-cluster;Scheduler was sent the command new
01/03/2015 08:54:47;0002;PBS_Server;Svr;PBS_Server;Torque Server Version = 3.0.5, loglevel = 0
01/03/2015 08:54:48;0040;PBS_Server;Svr;tyrone-cluster;Scheduler was sent the command new
01/03/2015 08:55:18;0040;PBS_Server;Svr;tyrone-cluster;Scheduler was sent the command new
01/03/2015 08:55:48;0040;PBS_Server;Svr;tyrone-cluster;Scheduler was sent the command new
01/03/2015 08:56:19;0040;PBS_Server;Svr;tyrone-cluster;Scheduler was sent the command new
01/03/2015 08:56:49;0040;PBS_Server;Svr;tyrone-cluster;Scheduler was sent the command new
01/03/2015 08:57:19;0040;PBS_Server;Svr;tyrone-cluster;Scheduler was sent the command new
01/03/2015 08:57:49;0040;PBS_Server;Svr;tyrone-cluster;Scheduler was sent the command new
01/03/2015 08:58:19;0040;PBS_Server;Svr;tyrone-cluster;Scheduler was sent the command new
01/03/2015 08:58:49;0040;PBS_Server;Svr;tyrone-cluster;Scheduler was sent the command new
01/03/2015 08:59:19;0040;PBS_Server;Svr;tyrone-cluster;Scheduler was sent the command new
01/03/2015 08:59:47;0002;PBS_Server;Svr;PBS_Server;Torque Server Version = 3.0.5, loglevel = 0
01/03/2015 08:59:49;0040;PBS_Server;Svr;tyrone-cluster;Scheduler was sent the command new
01/03/2015 09:00:19;0040;PBS_Server;Svr;tyrone-cluster;Scheduler was sent the command new
01/03/2015 09:00:49;0040;PBS_Server;Svr;tyrone-cluster;Scheduler was sent the command new
01/03/2015 09:01:20;0040;PBS_Server;Svr;tyrone-cluster;Scheduler was sent the command new
01/03/2015 09:01:50;0040;PBS_Server;Svr;tyrone-cluster;Scheduler was sent the command new
01/03/2015 09:02:20;0040;PBS_Server;Svr;tyrone-cluster;Scheduler was sent the command new
01/03/2015 09:02:50;0040;PBS_Server;Svr;tyrone-cluster;Scheduler was sent the command new
01/03/2015 09:03:20;0040;PBS_Server;Svr;tyrone-cluster;Scheduler was sent the command new
01/03/2015 09:03:50;0040;PBS_Server;Svr;tyrone-cluster;Scheduler was sent the command new
01/03/2015 09:04:20;0040;PBS_Server;Svr;tyrone-cluster;Scheduler was sent the command new
01/03/2015 09:04:47;0002;PBS_Server;Svr;PBS_Server;Torque Server Version = 3.0.5, loglevel = 0
01/03/2015 09:04:50;0040;PBS_Server;Svr;tyrone-cluster;Scheduler was sent the command new
01/03/2015 09:05:20;0040;PBS_Server;Svr;tyrone-cluster;Scheduler was sent the command new
01/03/2015 09:05:50;0040;PBS_Server;Svr;tyrone-cluster;Scheduler was sent the command new
01/03/2015 09:06:21;0040;PBS_Server;Svr;tyrone-cluster;Scheduler was sent the command new
01/03/2015 09:06:51;0040;PBS_Server;Svr;tyrone-cluster;Scheduler was sent the command new
01/03/2015 09:07:21;0040;PBS_Server;Svr;tyrone-cluster;Scheduler was sent the command new
01/03/2015 09:07:51;0040;PBS_Server;Svr;tyrone-cluster;Scheduler was sent the command new
01/03/2015 09:08:21;0040;PBS_Server;Svr;tyrone-cluster;Scheduler was sent the command new
01/03/2015 09:08:51;0040;PBS_Server;Svr;tyrone-cluster;Scheduler was sent the command new
01/03/2015 09:09:21;0040;PBS_Server;Svr;tyrone-cluster;Scheduler was sent the command new
01/03/2015 09:09:47;0002;PBS_Server;Svr;PBS_Server;Torque Server Version = 3.0.5, loglevel = 0
01/03/2015 09:09:51;0040;PBS_Server;Svr;tyrone-cluster;Scheduler was sent the command new
01/03/2015 09:10:21;0040;PBS_Server;Svr;tyrone-cluster;Scheduler was sent the command new
01/03/2015 09:10:52;0040;PBS_Server;Svr;tyrone-cluster;Scheduler was sent the command new
01/03/2015 09:11:22;0040;PBS_Server;Svr;tyrone-cluster;Scheduler was sent the command new
01/03/2015 09:11:52;0040;PBS_Server;Svr;tyrone-cluster;Scheduler was sent the command new
01/03/2015 09:12:22;0040;PBS_Server;Svr;tyrone-cluster;Scheduler was sent the command new
01/03/2015 09:12:52;0040;PBS_Server;Svr;tyrone-cluster;Scheduler was sent the command new
01/03/2015 09:13:22;0040;PBS_Server;Svr;tyrone-cluster;Scheduler was sent the command new
01/03/2015 09:13:52;0040;PBS_Server;Svr;tyrone-cluster;Scheduler was sent the command new
01/03/2015 09:14:22;0040;PBS_Server;Svr;tyrone-cluster;Scheduler was sent the command new
01/03/2015 09:14:47;0002;PBS_Server;Svr;PBS_Server;Torque Server Version = 3.0.5, loglevel = 0
01/03/2015 09:14:52;0040;PBS_Server;Svr;tyrone-cluster;Scheduler was sent the command new
01/03/2015 09:15:22;0040;PBS_Server;Svr;tyrone-cluster;Scheduler was sent the command new
01/03/2015 09:15:53;0040;PBS_Server;Svr;tyrone-cluster;Scheduler was sent the command new
01/03/2015 09:16:23;0040;PBS_Server;Svr;tyrone-cluster;Scheduler was sent the command new
01/03/2015 09:16:53;0040;PBS_Server;Svr;tyrone-cluster;Scheduler was sent the command new
01/03/2015 09:17:23;0040;PBS_Server;Svr;tyrone-cluster;Scheduler was sent the command new
01/03/2015 09:17:53;0040;PBS_Server;Svr;tyrone-cluster;Scheduler was sent the command new
01/03/2015 09:18:23;0040;PBS_Server;Svr;tyrone-cluster;Scheduler was sent the command new
01/03/2015 09:18:53;0040;PBS_Server;Svr;tyrone-cluster;Scheduler was sent the command new
01/03/2015 09:19:23;0040;PBS_Server;Svr;tyrone-cluster;Scheduler was sent the command new
01/03/2015 09:19:47;0002;PBS_Server;Svr;PBS_Server;Torque Server Version = 3.0.5, loglevel = 0
01/03/2015 09:19:53;0040;PBS_Server;Svr;tyrone-cluster;Scheduler was sent the command new
01/03/2015 09:20:23;0040;PBS_Server;Svr;tyrone-cluster;Scheduler was sent the command new
01/03/2015 09:20:53;0040;PBS_Server;Svr;tyrone-cluster;Scheduler was sent the command new
01/03/2015 09:21:24;0040;PBS_Server;Svr;tyrone-cluster;Scheduler was sent the command new
01/03/2015 09:21:54;0040;PBS_Server;Svr;tyrone-cluster;Scheduler was sent the command new
01/03/2015 09:22:24;0040;PBS_Server;Svr;tyrone-cluster;Scheduler was sent the command new
01/03/2015 09:22:54;0040;PBS_Server;Svr;tyrone-cluster;Scheduler was sent the command new
01/03/2015 09:23:24;0040;PBS_Server;Svr;tyrone-cluster;Scheduler was sent the command new
01/03/2015 09:23:54;0040;PBS_Server;Svr;tyrone-cluster;Scheduler was sent the command new
01/03/2015 09:24:24;0040;PBS_Server;Svr;tyrone-cluster;Scheduler was sent the command new
01/03/2015 09:24:47;0002;PBS_Server;Svr;PBS_Server;Torque Server Version = 3.0.5, loglevel = 0
01/03/2015 09:24:54;0040;PBS_Server;Svr;tyrone-cluster;Scheduler was sent the command new
01/03/2015 09:25:24;0040;PBS_Server;Svr;tyrone-cluster;Scheduler was sent the command new
01/03/2015 09:25:54;0040;PBS_Server;Svr;tyrone-cluster;Scheduler was sent the command new
01/03/2015 09:26:25;0040;PBS_Server;Svr;tyrone-cluster;Scheduler was sent the command new
01/03/2015 09:26:54;0040;PBS_Server;Svr;tyrone-cluster;Scheduler was sent the command new
01/03/2015 09:27:25;0040;PBS_Server;Svr;tyrone-cluster;Scheduler was sent the command new
01/03/2015 09:27:55;0040;PBS_Server;Svr;tyrone-cluster;Scheduler was sent the command new
01/03/2015 09:28:24;0040;PBS_Server;Svr;tyrone-cluster;Scheduler was sent the command new
01/03/2015 09:28:55;0040;PBS_Server;Svr;tyrone-cluster;Scheduler was sent the command new
01/03/2015 09:29:25;0040;PBS_Server;Svr;tyrone-cluster;Scheduler was sent the command new
01/03/2015 09:29:47;0002;PBS_Server;Svr;PBS_Server;Torque Server Version = 3.0.5, loglevel = 0
01/03/2015 09:29:54;0040;PBS_Server;Svr;tyrone-cluster;Scheduler was sent the command new
01/03/2015 09:30:24;0040;PBS_Server;Svr;tyrone-cluster;Scheduler was sent the command new
01/03/2015 09:30:55;0040;PBS_Server;Svr;tyrone-cluster;Scheduler was sent the command new
01/03/2015 09:31:24;0040;PBS_Server;Svr;tyrone-cluster;Scheduler was sent the command new
01/03/2015 09:31:55;0040;PBS_Server;Svr;tyrone-cluster;Scheduler was sent the command new
01/03/2015 09:32:26;0040;PBS_Server;Svr;tyrone-cluster;Scheduler was sent the command new
01/03/2015 09:32:56;0040;PBS_Server;Svr;tyrone-cluster;Scheduler was sent the command new
01/03/2015 09:33:26;0040;PBS_Server;Svr;tyrone-cluster;Scheduler was sent the command new
01/03/2015 09:33:56;0040;PBS_Server;Svr;tyrone-cluster;Scheduler was sent the command new
01/03/2015 09:34:26;0040;PBS_Server;Svr;tyrone-cluster;Scheduler was sent the command new
01/03/2015 09:34:47;0002;PBS_Server;Svr;PBS_Server;Torque Server Version = 3.0.5, loglevel = 0
01/03/2015 09:34:56;0040;PBS_Server;Svr;tyrone-cluster;Scheduler was sent the command new
01/03/2015 09:35:26;0040;PBS_Server;Svr;tyrone-cluster;Scheduler was sent the command new
01/03/2015 09:35:56;0040;PBS_Server;Svr;tyrone-cluster;Scheduler was sent the command new
01/03/2015 09:36:27;0040;PBS_Server;Svr;tyrone-cluster;Scheduler was sent the command new
01/03/2015 09:36:57;0040;PBS_Server;Svr;tyrone-cluster;Scheduler was sent the command new
01/03/2015 09:37:27;0040;PBS_Server;Svr;tyrone-cluster;Scheduler was sent the command new
01/03/2015 09:37:57;0040;PBS_Server;Svr;tyrone-cluster;Scheduler was sent the command new
01/03/2015 09:38:27;0040;PBS_Server;Svr;tyrone-cluster;Scheduler was sent the command new
01/03/2015 09:38:57;0040;PBS_Server;Svr;tyrone-cluster;Scheduler was sent the command new
01/03/2015 09:39:27;0040;PBS_Server;Svr;tyrone-cluster;Scheduler was sent the command new
01/03/2015 09:39:47;0002;PBS_Server;Svr;PBS_Server;Torque Server Version = 3.0.5, loglevel = 0
01/03/2015 09:39:57;0040;PBS_Server;Svr;tyrone-cluster;Scheduler was sent the command new
01/03/2015 09:40:27;0040;PBS_Server;Svr;tyrone-cluster;Scheduler was sent the command new
01/03/2015 09:40:57;0040;PBS_Server;Svr;tyrone-cluster;Scheduler was sent the command new
01/03/2015 09:41:28;0040;PBS_Server;Svr;tyrone-cluster;Scheduler was sent the command new
01/03/2015 09:41:58;0040;PBS_Server;Svr;tyrone-cluster;Scheduler was sent the command new
01/03/2015 09:42:28;0040;PBS_Server;Svr;tyrone-cluster;Scheduler was sent the command new
01/03/2015 09:42:58;0040;PBS_Server;Svr;tyrone-cluster;Scheduler was sent the command new
01/03/2015 09:43:28;0040;PBS_Server;Svr;tyrone-cluster;Scheduler was sent the command new
01/03/2015 09:43:58;0040;PBS_Server;Svr;tyrone-cluster;Scheduler was sent the command new
01/03/2015 09:44:28;0040;PBS_Server;Svr;tyrone-cluster;Scheduler was sent the command new
01/03/2015 09:44:47;0002;PBS_Server;Svr;PBS_Server;Torque Server Version = 3.0.5, loglevel = 0
01/03/2015 09:44:58;0040;PBS_Server;Svr;tyrone-cluster;Scheduler was sent the command new
01/03/2015 09:45:28;0040;PBS_Server;Svr;tyrone-cluster;Scheduler was sent the command new
01/03/2015 09:45:58;0040;PBS_Server;Svr;tyrone-cluster;Scheduler was sent the command new
01/03/2015 09:46:28;0040;PBS_Server;Svr;tyrone-cluster;Scheduler was sent the command new
01/03/2015 09:46:59;0040;PBS_Server;Svr;tyrone-cluster;Scheduler was sent the command new
01/03/2015 09:47:29;0040;PBS_Server;Svr;tyrone-cluster;Scheduler was sent the command new
01/03/2015 09:47:59;0040;PBS_Server;Svr;tyrone-cluster;Scheduler was sent the command new
01/03/2015 09:48:29;0040;PBS_Server;Svr;tyrone-cluster;Scheduler was sent the command new
01/03/2015 09:48:59;0040;PBS_Server;Svr;tyrone-cluster;Scheduler was sent the command new
01/03/2015 09:49:29;0040;PBS_Server;Svr;tyrone-cluster;Scheduler was sent the command new
01/03/2015 09:49:47;0002;PBS_Server;Svr;PBS_Server;Torque Server Version = 3.0.5, loglevel = 0
01/03/2015 09:49:59;0040;PBS_Server;Svr;tyrone-cluster;Scheduler was sent the command new
01/03/2015 09:50:29;0040;PBS_Server;Svr;tyrone-cluster;Scheduler was sent the command new
01/03/2015 09:51:00;0040;PBS_Server;Svr;tyrone-cluster;Scheduler was sent the command new
01/03/2015 09:51:30;0040;PBS_Server;Svr;tyrone-cluster;Scheduler was sent the command new
01/03/2015 09:52:00;0040;PBS_Server;Svr;tyrone-cluster;Scheduler was sent the command new
01/03/2015 09:52:30;0040;PBS_Server;Svr;tyrone-cluster;Scheduler was sent the command new
01/03/2015 09:53:00;0040;PBS_Server;Svr;tyrone-cluster;Scheduler was sent the command new
01/03/2015 09:53:30;0040;PBS_Server;Svr;tyrone-cluster;Scheduler was sent the command new
01/03/2015 09:54:00;0040;PBS_Server;Svr;tyrone-cluster;Scheduler was sent the command new
01/03/2015 09:54:30;0040;PBS_Server;Svr;tyrone-cluster;Scheduler was sent the command new
01/03/2015 09:54:47;0002;PBS_Server;Svr;PBS_Server;Torque Server Version = 3.0.5, loglevel = 0
01/03/2015 09:55:00;0040;PBS_Server;Svr;tyrone-cluster;Scheduler was sent the command new
01/03/2015 09:55:30;0040;PBS_Server;Svr;tyrone-cluster;Scheduler was sent the command new
01/03/2015 09:56:01;0040;PBS_Server;Svr;tyrone-cluster;Scheduler was sent the command new
01/03/2015 09:56:31;0040;PBS_Server;Svr;tyrone-cluster;Scheduler was sent the command new
01/03/2015 09:57:01;0040;PBS_Server;Svr;tyrone-cluster;Scheduler was sent the command new
01/03/2015 09:57:31;0040;PBS_Server;Svr;tyrone-cluster;Scheduler was sent the command new
01/03/2015 09:58:01;0040;PBS_Server;Svr;tyrone-cluster;Scheduler was sent the command new
01/03/2015 09:58:31;0040;PBS_Server;Svr;tyrone-cluster;Scheduler was sent the command new
01/03/2015 09:59:01;0040;PBS_Server;Svr;tyrone-cluster;Scheduler was sent the command new
01/03/2015 09:59:31;0040;PBS_Server;Svr;tyrone-cluster;Scheduler was sent the command new
01/03/2015 09:59:47;0002;PBS_Server;Svr;PBS_Server;Torque Server Version = 3.0.5, loglevel = 0
01/03/2015 10:00:01;0040;PBS_Server;Svr;tyrone-cluster;Scheduler was sent the command new
01/03/2015 10:00:31;0040;PBS_Server;Svr;tyrone-cluster;Scheduler was sent the command new
01/03/2015 10:01:02;0040;PBS_Server;Svr;tyrone-cluster;Scheduler was sent the command new
01/03/2015 10:01:32;0040;PBS_Server;Svr;tyrone-cluster;Scheduler was sent the command new
01/03/2015 10:02:02;0040;PBS_Server;Svr;tyrone-cluster;Scheduler was sent the command new
01/03/2015 10:02:32;0040;PBS_Server;Svr;tyrone-cluster;Scheduler was sent the command new
01/03/2015 10:03:02;0040;PBS_Server;Svr;tyrone-cluster;Scheduler was sent the command new
01/03/2015 10:03:32;0040;PBS_Server;Svr;tyrone-cluster;Scheduler was sent the command new
01/03/2015 10:04:02;0040;PBS_Server;Svr;tyrone-cluster;Scheduler was sent the command new
01/03/2015 10:04:32;0040;PBS_Server;Svr;tyrone-cluster;Scheduler was sent the command new
01/03/2015 10:04:47;0002;PBS_Server;Svr;PBS_Server;Torque Server Version = 3.0.5, loglevel = 0
01/03/2015 10:05:02;0040;PBS_Server;Svr;tyrone-cluster;Scheduler was sent the command new
01/03/2015 10:05:32;0040;PBS_Server;Svr;tyrone-cluster;Scheduler was sent the command new
01/03/2015 10:06:02;0040;PBS_Server;Svr;tyrone-cluster;Scheduler was sent the command new
01/03/2015 10:06:32;0040;PBS_Server;Svr;tyrone-cluster;Scheduler was sent the command new
01/03/2015 10:07:03;0040;PBS_Server;Svr;tyrone-cluster;Scheduler was sent the command new
01/03/2015 10:07:33;0040;PBS_Server;Svr;tyrone-cluster;Scheduler was sent the command new
01/03/2015 10:08:03;0040;PBS_Server;Svr;tyrone-cluster;Scheduler was sent the command new
01/03/2015 10:08:33;0040;PBS_Server;Svr;tyrone-cluster;Scheduler was sent the command new
01/03/2015 10:09:03;0040;PBS_Server;Svr;tyrone-cluster;Scheduler was sent the command new
01/03/2015 10:09:33;0040;PBS_Server;Svr;tyrone-cluster;Scheduler was sent the command new
01/03/2015 10:09:47;0002;PBS_Server;Svr;PBS_Server;Torque Server Version = 3.0.5, loglevel = 0
01/03/2015 10:10:03;0040;PBS_Server;Svr;tyrone-cluster;Scheduler was sent the command new
01/03/2015 10:10:34;0040;PBS_Server;Svr;tyrone-cluster;Scheduler was sent the command new
01/03/2015 10:11:04;0040;PBS_Server;Svr;tyrone-cluster;Scheduler was sent the command new
01/03/2015 10:11:34;0040;PBS_Server;Svr;tyrone-cluster;Scheduler was sent the command new
01/03/2015 10:12:04;0040;PBS_Server;Svr;tyrone-cluster;Scheduler was sent the command new
01/03/2015 10:12:34;0040;PBS_Server;Svr;tyrone-cluster;Scheduler was sent the command new
01/03/2015 10:13:04;0040;PBS_Server;Svr;tyrone-cluster;Scheduler was sent the command new
01/03/2015 10:13:34;0040;PBS_Server;Svr;tyrone-cluster;Scheduler was sent the command new
01/03/2015 10:14:04;0040;PBS_Server;Svr;tyrone-cluster;Scheduler was sent the command new
01/03/2015 10:14:34;0040;PBS_Server;Svr;tyrone-cluster;Scheduler was sent the command new
01/03/2015 10:14:47;0002;PBS_Server;Svr;PBS_Server;Torque Server Version = 3.0.5, loglevel = 0
01/03/2015 10:15:04;0040;PBS_Server;Svr;tyrone-cluster;Scheduler was sent the command new
01/03/2015 10:15:35;0040;PBS_Server;Svr;tyrone-cluster;Scheduler was sent the command new
01/03/2015 10:16:05;0040;PBS_Server;Svr;tyrone-cluster;Scheduler was sent the command new
01/03/2015 10:16:35;0040;PBS_Server;Svr;tyrone-cluster;Scheduler was sent the command new
01/03/2015 10:17:05;0040;PBS_Server;Svr;tyrone-cluster;Scheduler was sent the command new
01/03/2015 10:17:35;0040;PBS_Server;Svr;tyrone-cluster;Scheduler was sent the command new
01/03/2015 10:18:05;0040;PBS_Server;Svr;tyrone-cluster;Scheduler was sent the command new
01/03/2015 10:18:35;0040;PBS_Server;Svr;tyrone-cluster;Scheduler was sent the command new
01/03/2015 10:19:05;0040;PBS_Server;Svr;tyrone-cluster;Scheduler was sent the command new
01/03/2015 10:19:35;0040;PBS_Server;Svr;tyrone-cluster;Scheduler was sent the command new
01/03/2015 10:19:47;0002;PBS_Server;Svr;PBS_Server;Torque Server Version = 3.0.5, loglevel = 0
01/03/2015 10:20:06;0040;PBS_Server;Svr;tyrone-cluster;Scheduler was sent the command new
01/03/2015 10:20:36;0040;PBS_Server;Svr;tyrone-cluster;Scheduler was sent the command new
01/03/2015 10:21:06;0040;PBS_Server;Svr;tyrone-cluster;Scheduler was sent the command new
01/03/2015 10:21:36;0040;PBS_Server;Svr;tyrone-cluster;Scheduler was sent the command new
01/03/2015 10:22:06;0040;PBS_Server;Svr;tyrone-cluster;Scheduler was sent the command new
01/03/2015 10:22:36;0040;PBS_Server;Svr;tyrone-cluster;Scheduler was sent the command new
01/03/2015 10:23:06;0040;PBS_Server;Svr;tyrone-cluster;Scheduler was sent the command new
01/03/2015 10:23:36;0040;PBS_Server;Svr;tyrone-cluster;Scheduler was sent the command new
01/03/2015 10:24:06;0040;PBS_Server;Svr;tyrone-cluster;Scheduler was sent the command new
01/03/2015 10:24:36;0040;PBS_Server;Svr;tyrone-cluster;Scheduler was sent the command new
01/03/2015 10:24:47;0002;PBS_Server;Svr;PBS_Server;Torque Server Version = 3.0.5, loglevel = 0
01/03/2015 10:25:07;0040;PBS_Server;Svr;tyrone-cluster;Scheduler was sent the command new
01/03/2015 10:25:37;0040;PBS_Server;Svr;tyrone-cluster;Scheduler was sent the command new
01/03/2015 10:26:07;0040;PBS_Server;Svr;tyrone-cluster;Scheduler was sent the command new
01/03/2015 10:26:37;0040;PBS_Server;Svr;tyrone-cluster;Scheduler was sent the command new
01/03/2015 10:27:07;0040;PBS_Server;Svr;tyrone-cluster;Scheduler was sent the command new
01/03/2015 10:27:37;0040;PBS_Server;Svr;tyrone-cluster;Scheduler was sent the command new
01/03/2015 10:28:07;0040;PBS_Server;Svr;tyrone-cluster;Scheduler was sent the command new
01/03/2015 10:28:37;0040;PBS_Server;Svr;tyrone-cluster;Scheduler was sent the command new
01/03/2015 10:29:07;0040;PBS_Server;Svr;tyrone-cluster;Scheduler was sent the command new
01/03/2015 10:29:37;0040;PBS_Server;Svr;tyrone-cluster;Scheduler was sent the command new
01/03/2015 10:29:47;0002;PBS_Server;Svr;PBS_Server;Torque Server Version = 3.0.5, loglevel = 0
01/03/2015 10:30:08;0040;PBS_Server;Svr;tyrone-cluster;Scheduler was sent the command new
01/03/2015 10:30:38;0040;PBS_Server;Svr;tyrone-cluster;Scheduler was sent the command new
01/03/2015 10:31:08;0040;PBS_Server;Svr;tyrone-cluster;Scheduler was sent the command new
01/03/2015 10:31:38;0040;PBS_Server;Svr;tyrone-cluster;Scheduler was sent the command new
01/03/2015 10:32:08;0040;PBS_Server;Svr;tyrone-cluster;Scheduler was sent the command new
01/03/2015 10:32:38;0040;PBS_Server;Svr;tyrone-cluster;Scheduler was sent the command new
01/03/2015 10:33:08;0040;PBS_Server;Svr;tyrone-cluster;Scheduler was sent the command new
01/03/2015 10:33:38;0040;PBS_Server;Svr;tyrone-cluster;Scheduler was sent the command new
01/03/2015 10:34:08;0040;PBS_Server;Svr;tyrone-cluster;Scheduler was sent the command new
01/03/2015 10:34:39;0040;PBS_Server;Svr;tyrone-cluster;Scheduler was sent the command new
01/03/2015 10:34:47;0002;PBS_Server;Svr;PBS_Server;Torque Server Version = 3.0.5, loglevel = 0
01/03/2015 10:35:09;0040;PBS_Server;Svr;tyrone-cluster;Scheduler was sent the command new
01/03/2015 10:35:39;0040;PBS_Server;Svr;tyrone-cluster;Scheduler was sent the command new
01/03/2015 10:36:09;0040;PBS_Server;Svr;tyrone-cluster;Scheduler was sent the command new
01/03/2015 10:36:39;0040;PBS_Server;Svr;tyrone-cluster;Scheduler was sent the command new
01/03/2015 10:37:09;0040;PBS_Server;Svr;tyrone-cluster;Scheduler was sent the command new
01/03/2015 10:37:39;0040;PBS_Server;Svr;tyrone-cluster;Scheduler was sent the command new
01/03/2015 10:38:09;0040;PBS_Server;Svr;tyrone-cluster;Scheduler was sent the command new
01/03/2015 10:38:39;0040;PBS_Server;Svr;tyrone-cluster;Scheduler was sent the command new
01/03/2015 10:39:10;0040;PBS_Server;Svr;tyrone-cluster;Scheduler was sent the command new
01/03/2015 10:39:40;0040;PBS_Server;Svr;tyrone-cluster;Scheduler was sent the command new
01/03/2015 10:39:47;0002;PBS_Server;Svr;PBS_Server;Torque Server Version = 3.0.5, loglevel = 0
01/03/2015 10:40:10;0040;PBS_Server;Svr;tyrone-cluster;Scheduler was sent the command new
01/03/2015 10:40:40;0040;PBS_Server;Svr;tyrone-cluster;Scheduler was sent the command new
01/03/2015 10:41:10;0040;PBS_Server;Svr;tyrone-cluster;Scheduler was sent the command new
01/03/2015 10:41:40;0040;PBS_Server;Svr;tyrone-cluster;Scheduler was sent the command new
01/03/2015 10:42:10;0040;PBS_Server;Svr;tyrone-cluster;Scheduler was sent the command new
01/03/2015 10:42:40;0040;PBS_Server;Svr;tyrone-cluster;Scheduler was sent the command new
01/03/2015 10:43:10;0040;PBS_Server;Svr;tyrone-cluster;Scheduler was sent the command new
01/03/2015 10:43:40;0040;PBS_Server;Svr;tyrone-cluster;Scheduler was sent the command new
01/03/2015 10:44:11;0040;PBS_Server;Svr;tyrone-cluster;Scheduler was sent the command new
01/03/2015 10:44:41;0040;PBS_Server;Svr;tyrone-cluster;Scheduler was sent the command new
01/03/2015 10:44:47;0002;PBS_Server;Svr;PBS_Server;Torque Server Version = 3.0.5, loglevel = 0
01/03/2015 10:45:11;0040;PBS_Server;Svr;tyrone-cluster;Scheduler was sent the command new
01/03/2015 10:45:41;0040;PBS_Server;Svr;tyrone-cluster;Scheduler was sent the command new
01/03/2015 10:46:11;0040;PBS_Server;Svr;tyrone-cluster;Scheduler was sent the command new
01/03/2015 10:46:41;0040;PBS_Server;Svr;tyrone-cluster;Scheduler was sent the command new
01/03/2015 10:47:11;0040;PBS_Server;Svr;tyrone-cluster;Scheduler was sent the command new
01/03/2015 10:47:41;0040;PBS_Server;Svr;tyrone-cluster;Scheduler was sent the command new
01/03/2015 10:48:11;0040;PBS_Server;Svr;tyrone-cluster;Scheduler was sent the command new
01/03/2015 10:48:41;0040;PBS_Server;Svr;tyrone-cluster;Scheduler was sent the command new
01/03/2015 10:49:12;0040;PBS_Server;Svr;tyrone-cluster;Scheduler was sent the command new
01/03/2015 10:49:42;0040;PBS_Server;Svr;tyrone-cluster;Scheduler was sent the command new
01/03/2015 10:49:47;0002;PBS_Server;Svr;PBS_Server;Torque Server Version = 3.0.5, loglevel = 0
01/03/2015 10:50:12;0040;PBS_Server;Svr;tyrone-cluster;Scheduler was sent the command new
01/03/2015 10:50:42;0040;PBS_Server;Svr;tyrone-cluster;Scheduler was sent the command new
01/03/2015 10:51:12;0040;PBS_Server;Svr;tyrone-cluster;Scheduler was sent the command new
01/03/2015 10:51:42;0040;PBS_Server;Svr;tyrone-cluster;Scheduler was sent the command new
01/03/2015 10:52:12;0040;PBS_Server;Svr;tyrone-cluster;Scheduler was sent the command new
01/03/2015 10:52:42;0040;PBS_Server;Svr;tyrone-cluster;Scheduler was sent the command new
01/03/2015 10:53:12;0040;PBS_Server;Svr;tyrone-cluster;Scheduler was sent the command new
01/03/2015 10:53:42;0040;PBS_Server;Svr;tyrone-cluster;Scheduler was sent the command new
01/03/2015 10:54:12;0040;PBS_Server;Svr;tyrone-cluster;Scheduler was sent the command new
01/03/2015 10:54:43;0040;PBS_Server;Svr;tyrone-cluster;Scheduler was sent the command new
01/03/2015 10:54:47;0002;PBS_Server;Svr;PBS_Server;Torque Server Version = 3.0.5, loglevel = 0
01/03/2015 10:55:13;0040;PBS_Server;Svr;tyrone-cluster;Scheduler was sent the command new
01/03/2015 10:55:24;0008;PBS_Server;Job;46365.tyrone-cluster;Job deleted at request of mecvamsi@tyrone-cluster
01/03/2015 10:55:24;0008;PBS_Server;Job;46365.tyrone-cluster;Job sent signal SIGTERM on delete
01/03/2015 10:55:25;000d;PBS_Server;Job;46365.tyrone-cluster;Not sending email: User does not want mail of this type.
01/03/2015 10:55:25;0010;PBS_Server;Job;46365.tyrone-cluster;Exit_status=143 resources_used.cput=578:57:09 resources_used.mem=8200216kb resources_used.vmem=11545084kb resources_used.walltime=18:07:31
01/03/2015 10:55:25;0008;PBS_Server;Job;NULL;on_job_exit valid pjob: 0x13deb80 (substate=50)
01/03/2015 10:55:25;0008;PBS_Server;Job;NULL;on_job_exit valid pjob: 0x13deb80 (substate=51)
01/03/2015 10:55:34;0008;PBS_Server;Job;NULL;on_job_exit valid pjob: 0x13deb80 (substate=51)
01/03/2015 10:55:34;000d;PBS_Server;Job;46365.tyrone-cluster;Post job file processing error; job 46365.tyrone-cluster on host tyrone-node1/31+tyrone-node1/30+tyrone-node1/29+tyrone-node1/28+tyrone-node1/27+tyrone-node1/26+tyrone-node1/25+tyrone-node1/24+tyrone-node1/23+tyrone-node1/22+tyrone-node1/21+tyrone-node1/20+tyrone-node1/19+tyrone-node1/18+tyrone-node1/17+tyrone-node1/16+tyrone-node1/15+tyrone-node1/14+tyrone-node1/13+tyrone-node1/12+tyrone-node1/11+tyrone-node1/10+tyrone-node1/9+tyrone-node1/8+tyrone-node1/7+tyrone-node1/6+tyrone-node1/5+tyrone-node1/4+tyrone-node1/3+tyrone-node1/2+tyrone-node1/1+tyrone-node1/0
01/03/2015 10:55:34;0008;PBS_Server;Job;NULL;on_job_exit valid pjob: 0x13deb80 (substate=53)
01/03/2015 10:55:34;0100;PBS_Server;Job;46365.tyrone-cluster;dequeuing from qp32, state COMPLETE
01/03/2015 10:55:34;0040;PBS_Server;Svr;tyrone-cluster;Scheduler was sent the command term
01/03/2015 10:55:34;0008;PBS_Server;Job;46406.tyrone-cluster;Job Modified at request of Scheduler@tyrone-cluster
01/03/2015 10:55:34;0008;PBS_Server;Job;46406.tyrone-cluster;Job Run at request of Scheduler@tyrone-cluster
01/03/2015 10:55:34;0040;PBS_Server;Svr;tyrone-cluster;Scheduler was sent the command recyc
01/03/2015 10:55:34;000d;PBS_Server;Job;46406.tyrone-cluster;Not sending email: User does not want mail of this type.
01/03/2015 10:55:43;0100;PBS_Server;Job;46386.tyrone-cluster;dequeuing from batch, state QUEUED
01/03/2015 10:55:43;0100;PBS_Server;Job;46386.tyrone-cluster;enqueuing into qp32, state 1 hop 1
01/03/2015 10:55:43;0040;PBS_Server;Svr;tyrone-cluster;Scheduler was sent the command new
01/03/2015 10:55:43;0008;PBS_Server;Job;46386.tyrone-cluster;Job Modified at request of Scheduler@tyrone-cluster
01/03/2015 10:56:47;0020;PBS_Server;Job;46373.tyrone-cluster;Unauthorized Request, request type: 6, Object: Job, Name: 46373.tyrone-cluster, request from: mecvamsi@tyrone-cluster
01/03/2015 10:56:47;0080;PBS_Server;Req;req_reject;Reject reply code=15007(Unauthorized Request  MSG=operation not permitted), aux=0, type=DeleteJob, from mecvamsi@tyrone-cluster
01/03/2015 10:56:57;0008;PBS_Server;Job;46386.tyrone-cluster;Job deleted at request of mecvamsi@tyrone-cluster
01/03/2015 10:56:57;0008;PBS_Server;Job;NULL;on_job_exit valid pjob: 0x1322570 (substate=59)
01/03/2015 10:56:57;0100;PBS_Server;Job;46386.tyrone-cluster;dequeuing from qp32, state COMPLETE
01/03/2015 10:56:57;0040;PBS_Server;Svr;tyrone-cluster;Scheduler was sent the command term
01/03/2015 10:57:20;0100;PBS_Server;Job;46408.tyrone-cluster;enqueuing into batch, state 1 hop 1
01/03/2015 10:57:20;0100;PBS_Server;Job;46408.tyrone-cluster;dequeuing from batch, state QUEUED
01/03/2015 10:57:20;0100;PBS_Server;Job;46408.tyrone-cluster;enqueuing into qp32, state 1 hop 1
01/03/2015 10:57:20;0008;PBS_Server;Job;46408.tyrone-cluster;Job Queued at request of mecvamsi@tyrone-cluster, owner = mecvamsi@tyrone-cluster, job name = case3v.1, queue = qp32
01/03/2015 10:57:20;0040;PBS_Server;Svr;tyrone-cluster;Scheduler was sent the command new
01/03/2015 10:57:20;0008;PBS_Server;Job;46408.tyrone-cluster;Job Modified at request of Scheduler@tyrone-cluster
01/03/2015 10:59:47;0002;PBS_Server;Svr;PBS_Server;Torque Server Version = 3.0.5, loglevel = 0
01/03/2015 11:04:47;0002;PBS_Server;Svr;PBS_Server;Torque Server Version = 3.0.5, loglevel = 0
01/03/2015 11:07:20;0040;PBS_Server;Svr;tyrone-cluster;Scheduler was sent the command time
01/03/2015 11:07:26;0008;PBS_Server;Job;46408.tyrone-cluster;Job deleted at request of mecvamsi@tyrone-cluster
01/03/2015 11:07:26;0008;PBS_Server;Job;NULL;on_job_exit valid pjob: 0x12f1ef0 (substate=59)
01/03/2015 11:07:26;0100;PBS_Server;Job;46408.tyrone-cluster;dequeuing from qp32, state COMPLETE
01/03/2015 11:07:26;0040;PBS_Server;Svr;tyrone-cluster;Scheduler was sent the command term
01/03/2015 11:09:47;0002;PBS_Server;Svr;PBS_Server;Torque Server Version = 3.0.5, loglevel = 0
01/03/2015 11:14:47;0002;PBS_Server;Svr;PBS_Server;Torque Server Version = 3.0.5, loglevel = 0
01/03/2015 11:17:26;0040;PBS_Server;Svr;tyrone-cluster;Scheduler was sent the command time
01/03/2015 11:18:09;0100;PBS_Server;Job;46409.tyrone-cluster;enqueuing into batch, state 1 hop 1
01/03/2015 11:18:09;0100;PBS_Server;Job;46409.tyrone-cluster;dequeuing from batch, state QUEUED
01/03/2015 11:18:09;0100;PBS_Server;Job;46409.tyrone-cluster;enqueuing into qp32, state 1 hop 1
01/03/2015 11:18:09;0008;PBS_Server;Job;46409.tyrone-cluster;Job Queued at request of mecvamsi@tyrone-cluster, owner = mecvamsi@tyrone-cluster, job name = case3v.1, queue = qp32
01/03/2015 11:18:09;0040;PBS_Server;Svr;tyrone-cluster;Scheduler was sent the command new
01/03/2015 11:18:09;0008;PBS_Server;Job;46409.tyrone-cluster;Job Modified at request of Scheduler@tyrone-cluster
01/03/2015 11:19:47;0002;PBS_Server;Svr;PBS_Server;Torque Server Version = 3.0.5, loglevel = 0
01/03/2015 11:24:47;0002;PBS_Server;Svr;PBS_Server;Torque Server Version = 3.0.5, loglevel = 0
01/03/2015 11:28:09;0040;PBS_Server;Svr;tyrone-cluster;Scheduler was sent the command time
01/03/2015 11:29:00;0100;PBS_Server;Job;46410.tyrone-cluster;enqueuing into batch, state 1 hop 1
01/03/2015 11:29:00;0008;PBS_Server;Job;46410.tyrone-cluster;Job Queued at request of mecvamsi@tyrone-cluster, owner = mecvamsi@tyrone-cluster, job name = case3v.2, queue = batch
01/03/2015 11:29:00;0040;PBS_Server;Svr;tyrone-cluster;Scheduler was sent the command new
01/03/2015 11:29:00;0008;PBS_Server;Job;46410.tyrone-cluster;Job Modified at request of Scheduler@tyrone-cluster
01/03/2015 11:29:30;0040;PBS_Server;Svr;tyrone-cluster;Scheduler was sent the command new
01/03/2015 11:29:47;0002;PBS_Server;Svr;PBS_Server;Torque Server Version = 3.0.5, loglevel = 0
01/03/2015 11:30:01;0040;PBS_Server;Svr;tyrone-cluster;Scheduler was sent the command new
01/03/2015 11:30:36;0040;PBS_Server;Svr;tyrone-cluster;Scheduler was sent the command new
01/03/2015 11:31:10;0040;PBS_Server;Svr;tyrone-cluster;Scheduler was sent the command new
01/03/2015 11:31:40;0040;PBS_Server;Svr;tyrone-cluster;Scheduler was sent the command new
01/03/2015 11:32:06;0040;PBS_Server;Svr;tyrone-cluster;Scheduler was sent the command new
01/03/2015 11:32:39;0040;PBS_Server;Svr;tyrone-cluster;Scheduler was sent the command new
01/03/2015 11:33:13;0040;PBS_Server;Svr;tyrone-cluster;Scheduler was sent the command new
01/03/2015 11:33:43;0040;PBS_Server;Svr;tyrone-cluster;Scheduler was sent the command new
01/03/2015 11:34:21;0040;PBS_Server;Svr;tyrone-cluster;Scheduler was sent the command new
01/03/2015 11:34:47;0002;PBS_Server;Svr;PBS_Server;Torque Server Version = 3.0.5, loglevel = 0
01/03/2015 11:34:51;0040;PBS_Server;Svr;tyrone-cluster;Scheduler was sent the command new
01/03/2015 11:35:21;0040;PBS_Server;Svr;tyrone-cluster;Scheduler was sent the command new
01/03/2015 11:35:51;0040;PBS_Server;Svr;tyrone-cluster;Scheduler was sent the command new
01/03/2015 11:36:21;0040;PBS_Server;Svr;tyrone-cluster;Scheduler was sent the command new
01/03/2015 11:36:52;0040;PBS_Server;Svr;tyrone-cluster;Scheduler was sent the command new
01/03/2015 11:37:22;0040;PBS_Server;Svr;tyrone-cluster;Scheduler was sent the command new
01/03/2015 11:37:52;0040;PBS_Server;Svr;tyrone-cluster;Scheduler was sent the command new
01/03/2015 11:38:22;0040;PBS_Server;Svr;tyrone-cluster;Scheduler was sent the command new
01/03/2015 11:38:52;0040;PBS_Server;Svr;tyrone-cluster;Scheduler was sent the command new
01/03/2015 11:39:22;0040;PBS_Server;Svr;tyrone-cluster;Scheduler was sent the command new
01/03/2015 11:39:47;0002;PBS_Server;Svr;PBS_Server;Torque Server Version = 3.0.5, loglevel = 0
01/03/2015 11:39:52;0040;PBS_Server;Svr;tyrone-cluster;Scheduler was sent the command new
01/03/2015 11:40:22;0040;PBS_Server;Svr;tyrone-cluster;Scheduler was sent the command new
01/03/2015 11:40:52;0040;PBS_Server;Svr;tyrone-cluster;Scheduler was sent the command new
01/03/2015 11:41:22;0040;PBS_Server;Svr;tyrone-cluster;Scheduler was sent the command new
01/03/2015 11:41:35;0100;PBS_Server;Job;46411.tyrone-cluster;enqueuing into batch, state 1 hop 1
01/03/2015 11:41:35;0008;PBS_Server;Job;46411.tyrone-cluster;Job Queued at request of mecvamsi@tyrone-cluster, owner = mecvamsi@tyrone-cluster, job name = case3v.3, queue = batch
01/03/2015 11:41:35;0040;PBS_Server;Svr;tyrone-cluster;Scheduler was sent the command new
01/03/2015 11:41:35;0008;PBS_Server;Job;46411.tyrone-cluster;Job Modified at request of Scheduler@tyrone-cluster
01/03/2015 11:41:52;0040;PBS_Server;Svr;tyrone-cluster;Scheduler was sent the command new
01/03/2015 11:42:13;0040;PBS_Server;Svr;tyrone-cluster;Scheduler was sent the command new
01/03/2015 11:42:23;0040;PBS_Server;Svr;tyrone-cluster;Scheduler was sent the command new
01/03/2015 11:42:43;0040;PBS_Server;Svr;tyrone-cluster;Scheduler was sent the command new
01/03/2015 11:42:53;0040;PBS_Server;Svr;tyrone-cluster;Scheduler was sent the command new
01/03/2015 11:43:21;0040;PBS_Server;Svr;tyrone-cluster;Scheduler was sent the command new
01/03/2015 11:43:23;0040;PBS_Server;Svr;tyrone-cluster;Scheduler was sent the command new
01/03/2015 11:43:53;0040;PBS_Server;Svr;tyrone-cluster;Scheduler was sent the command new
01/03/2015 11:44:23;0040;PBS_Server;Svr;tyrone-cluster;Scheduler was sent the command new
01/03/2015 11:44:47;0002;PBS_Server;Svr;PBS_Server;Torque Server Version = 3.0.5, loglevel = 0
01/03/2015 11:44:53;0040;PBS_Server;Svr;tyrone-cluster;Scheduler was sent the command new
01/03/2015 11:45:23;0040;PBS_Server;Svr;tyrone-cluster;Scheduler was sent the command new
01/03/2015 11:45:53;0040;PBS_Server;Svr;tyrone-cluster;Scheduler was sent the command new
01/03/2015 11:46:23;0040;PBS_Server;Svr;tyrone-cluster;Scheduler was sent the command new
01/03/2015 11:46:54;0040;PBS_Server;Svr;tyrone-cluster;Scheduler was sent the command new
01/03/2015 11:47:24;0040;PBS_Server;Svr;tyrone-cluster;Scheduler was sent the command new
01/03/2015 11:47:54;0040;PBS_Server;Svr;tyrone-cluster;Scheduler was sent the command new
01/03/2015 11:48:24;0040;PBS_Server;Svr;tyrone-cluster;Scheduler was sent the command new
01/03/2015 11:48:54;0040;PBS_Server;Svr;tyrone-cluster;Scheduler was sent the command new
01/03/2015 11:49:24;0040;PBS_Server;Svr;tyrone-cluster;Scheduler was sent the command new
01/03/2015 11:49:47;0002;PBS_Server;Svr;PBS_Server;Torque Server Version = 3.0.5, loglevel = 0
01/03/2015 11:49:54;0040;PBS_Server;Svr;tyrone-cluster;Scheduler was sent the command new
01/03/2015 11:50:24;0040;PBS_Server;Svr;tyrone-cluster;Scheduler was sent the command new
01/03/2015 11:50:54;0040;PBS_Server;Svr;tyrone-cluster;Scheduler was sent the command new
01/03/2015 11:51:24;0040;PBS_Server;Svr;tyrone-cluster;Scheduler was sent the command new
01/03/2015 11:51:55;0040;PBS_Server;Svr;tyrone-cluster;Scheduler was sent the command new
01/03/2015 11:52:25;0040;PBS_Server;Svr;tyrone-cluster;Scheduler was sent the command new
01/03/2015 11:52:55;0040;PBS_Server;Svr;tyrone-cluster;Scheduler was sent the command new
01/03/2015 11:53:25;0040;PBS_Server;Svr;tyrone-cluster;Scheduler was sent the command new
01/03/2015 11:53:55;0040;PBS_Server;Svr;tyrone-cluster;Scheduler was sent the command new
01/03/2015 11:54:25;0040;PBS_Server;Svr;tyrone-cluster;Scheduler was sent the command new
01/03/2015 11:54:47;0002;PBS_Server;Svr;PBS_Server;Torque Server Version = 3.0.5, loglevel = 0
01/03/2015 11:54:55;0040;PBS_Server;Svr;tyrone-cluster;Scheduler was sent the command new
01/03/2015 11:55:25;0040;PBS_Server;Svr;tyrone-cluster;Scheduler was sent the command new
01/03/2015 11:55:55;0040;PBS_Server;Svr;tyrone-cluster;Scheduler was sent the command new
01/03/2015 11:56:25;0040;PBS_Server;Svr;tyrone-cluster;Scheduler was sent the command new
01/03/2015 11:56:56;0040;PBS_Server;Svr;tyrone-cluster;Scheduler was sent the command new
01/03/2015 11:57:26;0040;PBS_Server;Svr;tyrone-cluster;Scheduler was sent the command new
01/03/2015 11:57:56;0040;PBS_Server;Svr;tyrone-cluster;Scheduler was sent the command new
01/03/2015 11:58:26;0040;PBS_Server;Svr;tyrone-cluster;Scheduler was sent the command new
01/03/2015 11:58:28;000d;PBS_Server;Job;46190.tyrone-cluster;Not sending email: User does not want mail of this type.
01/03/2015 11:58:28;0010;PBS_Server;Job;46190.tyrone-cluster;Exit_status=0 resources_used.cput=308:32:38 resources_used.mem=2579656kb resources_used.vmem=36253584kb resources_used.walltime=04:49:46
01/03/2015 11:58:28;0008;PBS_Server;Job;NULL;on_job_exit valid pjob: 0x13e7520 (substate=50)
01/03/2015 11:58:28;0008;PBS_Server;Job;NULL;on_job_exit valid pjob: 0x13e7520 (substate=51)
01/03/2015 11:58:29;0008;PBS_Server;Job;NULL;on_job_exit valid pjob: 0x13e7520 (substate=51)
01/03/2015 11:58:29;0008;PBS_Server;Job;NULL;on_job_exit valid pjob: 0x13e7520 (substate=53)
01/03/2015 11:58:29;0100;PBS_Server;Job;46190.tyrone-cluster;dequeuing from qp256, state COMPLETE
01/03/2015 11:58:29;0040;PBS_Server;Svr;tyrone-cluster;Scheduler was sent the command term
01/03/2015 11:58:29;0008;PBS_Server;Job;46198.tyrone-cluster;Job Modified at request of Scheduler@tyrone-cluster
01/03/2015 11:58:29;0008;PBS_Server;Job;46198.tyrone-cluster;Job Run at request of Scheduler@tyrone-cluster
01/03/2015 11:58:29;0040;PBS_Server;Svr;tyrone-cluster;Scheduler was sent the command recyc
01/03/2015 11:58:56;0040;PBS_Server;Svr;tyrone-cluster;Scheduler was sent the command new
01/03/2015 11:59:05;000d;PBS_Server;Job;46198.tyrone-cluster;Not sending email: User does not want mail of this type.
01/03/2015 11:59:26;0040;PBS_Server;Svr;tyrone-cluster;Scheduler was sent the command new
01/03/2015 11:59:47;0002;PBS_Server;Svr;PBS_Server;Torque Server Version = 3.0.5, loglevel = 0
01/03/2015 11:59:56;0040;PBS_Server;Svr;tyrone-cluster;Scheduler was sent the command new
01/03/2015 12:00:26;0040;PBS_Server;Svr;tyrone-cluster;Scheduler was sent the command new
01/03/2015 12:00:56;0040;PBS_Server;Svr;tyrone-cluster;Scheduler was sent the command new
01/03/2015 12:01:27;0040;PBS_Server;Svr;tyrone-cluster;Scheduler was sent the command new
01/03/2015 12:01:57;0040;PBS_Server;Svr;tyrone-cluster;Scheduler was sent the command new
01/03/2015 12:02:27;0040;PBS_Server;Svr;tyrone-cluster;Scheduler was sent the command new
01/03/2015 12:02:57;0040;PBS_Server;Svr;tyrone-cluster;Scheduler was sent the command new
01/03/2015 12:03:27;0040;PBS_Server;Svr;tyrone-cluster;Scheduler was sent the command new
01/03/2015 12:03:49;0100;PBS_Server;Job;46412.tyrone-cluster;enqueuing into batch, state 1 hop 1
01/03/2015 12:03:49;0008;PBS_Server;Job;46412.tyrone-cluster;Job Queued at request of seckavya@tyrone-node9, owner = seckavya@tyrone-node9, job name = Ec2-12, queue = batch
01/03/2015 12:03:49;0040;PBS_Server;Svr;tyrone-cluster;Scheduler was sent the command new
01/03/2015 12:03:49;0008;PBS_Server;Job;46412.tyrone-cluster;Job Modified at request of Scheduler@tyrone-cluster
01/03/2015 12:03:57;0040;PBS_Server;Svr;tyrone-cluster;Scheduler was sent the command new
01/03/2015 12:04:20;0040;PBS_Server;Svr;tyrone-cluster;Scheduler was sent the command new
01/03/2015 12:04:27;0040;PBS_Server;Svr;tyrone-cluster;Scheduler was sent the command new
01/03/2015 12:04:39;0100;PBS_Server;Job;46413.tyrone-cluster;enqueuing into batch, state 1 hop 1
01/03/2015 12:04:39;0008;PBS_Server;Job;46413.tyrone-cluster;Job Queued at request of seckavya@tyrone-node9, owner = seckavya@tyrone-node9, job name = Ec2-13, queue = batch
01/03/2015 12:04:39;0040;PBS_Server;Svr;tyrone-cluster;Scheduler was sent the command new
01/03/2015 12:04:39;0008;PBS_Server;Job;46413.tyrone-cluster;Job Modified at request of Scheduler@tyrone-cluster
01/03/2015 12:04:47;0002;PBS_Server;Svr;PBS_Server;Torque Server Version = 3.0.5, loglevel = 0
01/03/2015 12:04:55;0040;PBS_Server;Svr;tyrone-cluster;Scheduler was sent the command new
01/03/2015 12:04:57;0040;PBS_Server;Svr;tyrone-cluster;Scheduler was sent the command new
01/03/2015 12:05:09;0040;PBS_Server;Svr;tyrone-cluster;Scheduler was sent the command new
01/03/2015 12:05:27;0040;PBS_Server;Svr;tyrone-cluster;Scheduler was sent the command new
01/03/2015 12:05:40;0040;PBS_Server;Svr;tyrone-cluster;Scheduler was sent the command new
01/03/2015 12:05:57;0040;PBS_Server;Svr;tyrone-cluster;Scheduler was sent the command new
01/03/2015 12:06:13;0040;PBS_Server;Svr;tyrone-cluster;Scheduler was sent the command new
01/03/2015 12:06:17;0100;PBS_Server;Job;46414.tyrone-cluster;enqueuing into batch, state 1 hop 1
01/03/2015 12:06:17;0008;PBS_Server;Job;46414.tyrone-cluster;Job Queued at request of mbuanuv@tyrone-node9, owner = mbuanuv@tyrone-node9, job name = EcF1C-repE11, queue = batch
01/03/2015 12:06:17;0040;PBS_Server;Svr;tyrone-cluster;Scheduler was sent the command new
01/03/2015 12:06:17;0008;PBS_Server;Job;46414.tyrone-cluster;Job Modified at request of Scheduler@tyrone-cluster
01/03/2015 12:06:28;0040;PBS_Server;Svr;tyrone-cluster;Scheduler was sent the command new
01/03/2015 12:06:44;0040;PBS_Server;Svr;tyrone-cluster;Scheduler was sent the command new
01/03/2015 12:06:49;0040;PBS_Server;Svr;tyrone-cluster;Scheduler was sent the command new
01/03/2015 12:06:58;0040;PBS_Server;Svr;tyrone-cluster;Scheduler was sent the command new
01/03/2015 12:07:10;0100;PBS_Server;Job;46415.tyrone-cluster;enqueuing into batch, state 1 hop 1
01/03/2015 12:07:10;0008;PBS_Server;Job;46415.tyrone-cluster;Job Queued at request of mbuanuv@tyrone-node9, owner = mbuanuv@tyrone-node9, job name = EcF1C-repE12, queue = batch
01/03/2015 12:07:10;0040;PBS_Server;Svr;tyrone-cluster;Scheduler was sent the command new
01/03/2015 12:07:10;0008;PBS_Server;Job;46415.tyrone-cluster;Job Modified at request of Scheduler@tyrone-cluster
01/03/2015 12:07:20;0040;PBS_Server;Svr;tyrone-cluster;Scheduler was sent the command new
01/03/2015 12:07:28;0040;PBS_Server;Svr;tyrone-cluster;Scheduler was sent the command new
01/03/2015 12:07:43;0040;PBS_Server;Svr;tyrone-cluster;Scheduler was sent the command new
01/03/2015 12:07:55;0040;PBS_Server;Svr;tyrone-cluster;Scheduler was sent the command new
01/03/2015 12:07:58;0040;PBS_Server;Svr;tyrone-cluster;Scheduler was sent the command new
01/03/2015 12:08:14;0040;PBS_Server;Svr;tyrone-cluster;Scheduler was sent the command new
01/03/2015 12:08:27;0040;PBS_Server;Svr;tyrone-cluster;Scheduler was sent the command new
01/03/2015 12:08:28;0040;PBS_Server;Svr;tyrone-cluster;Scheduler was sent the command new
01/03/2015 12:08:50;0040;PBS_Server;Svr;tyrone-cluster;Scheduler was sent the command new
01/03/2015 12:08:58;0040;PBS_Server;Svr;tyrone-cluster;Scheduler was sent the command new
01/03/2015 12:09:25;0040;PBS_Server;Svr;tyrone-cluster;Scheduler was sent the command new
01/03/2015 12:09:28;0040;PBS_Server;Svr;tyrone-cluster;Scheduler was sent the command new
01/03/2015 12:09:47;0002;PBS_Server;Svr;PBS_Server;Torque Server Version = 3.0.5, loglevel = 0
01/03/2015 12:09:57;0040;PBS_Server;Svr;tyrone-cluster;Scheduler was sent the command new
01/03/2015 12:10:28;0040;PBS_Server;Svr;tyrone-cluster;Scheduler was sent the command new
01/03/2015 12:10:59;0040;PBS_Server;Svr;tyrone-cluster;Scheduler was sent the command new
01/03/2015 12:11:29;0040;PBS_Server;Svr;tyrone-cluster;Scheduler was sent the command new
01/03/2015 12:11:59;0040;PBS_Server;Svr;tyrone-cluster;Scheduler was sent the command new
01/03/2015 12:12:29;0040;PBS_Server;Svr;tyrone-cluster;Scheduler was sent the command new
01/03/2015 12:12:59;0040;PBS_Server;Svr;tyrone-cluster;Scheduler was sent the command new
01/03/2015 12:13:29;0040;PBS_Server;Svr;tyrone-cluster;Scheduler was sent the command new
01/03/2015 12:13:59;0040;PBS_Server;Svr;tyrone-cluster;Scheduler was sent the command new
01/03/2015 12:14:29;0040;PBS_Server;Svr;tyrone-cluster;Scheduler was sent the command new
01/03/2015 12:14:47;0002;PBS_Server;Svr;PBS_Server;Torque Server Version = 3.0.5, loglevel = 0
01/03/2015 12:14:59;0040;PBS_Server;Svr;tyrone-cluster;Scheduler was sent the command new
01/03/2015 12:15:30;0040;PBS_Server;Svr;tyrone-cluster;Scheduler was sent the command new
01/03/2015 12:16:00;0040;PBS_Server;Svr;tyrone-cluster;Scheduler was sent the command new
01/03/2015 12:16:30;0040;PBS_Server;Svr;tyrone-cluster;Scheduler was sent the command new
01/03/2015 12:17:00;0040;PBS_Server;Svr;tyrone-cluster;Scheduler was sent the command new
01/03/2015 12:17:30;0040;PBS_Server;Svr;tyrone-cluster;Scheduler was sent the command new
01/03/2015 12:18:00;0040;PBS_Server;Svr;tyrone-cluster;Scheduler was sent the command new
01/03/2015 12:18:30;0040;PBS_Server;Svr;tyrone-cluster;Scheduler was sent the command new
01/03/2015 12:19:00;0040;PBS_Server;Svr;tyrone-cluster;Scheduler was sent the command new
01/03/2015 12:19:30;0040;PBS_Server;Svr;tyrone-cluster;Scheduler was sent the command new
01/03/2015 12:19:47;0002;PBS_Server;Svr;PBS_Server;Torque Server Version = 3.0.5, loglevel = 0
01/03/2015 12:20:01;0040;PBS_Server;Svr;tyrone-cluster;Scheduler was sent the command new
01/03/2015 12:20:31;0040;PBS_Server;Svr;tyrone-cluster;Scheduler was sent the command new
01/03/2015 12:21:01;0040;PBS_Server;Svr;tyrone-cluster;Scheduler was sent the command new
01/03/2015 12:21:31;0040;PBS_Server;Svr;tyrone-cluster;Scheduler was sent the command new
01/03/2015 12:22:01;0040;PBS_Server;Svr;tyrone-cluster;Scheduler was sent the command new
01/03/2015 12:22:31;0040;PBS_Server;Svr;tyrone-cluster;Scheduler was sent the command new
01/03/2015 12:23:01;0040;PBS_Server;Svr;tyrone-cluster;Scheduler was sent the command new
01/03/2015 12:23:31;0040;PBS_Server;Svr;tyrone-cluster;Scheduler was sent the command new
01/03/2015 12:24:01;0040;PBS_Server;Svr;tyrone-cluster;Scheduler was sent the command new
01/03/2015 12:24:32;0040;PBS_Server;Svr;tyrone-cluster;Scheduler was sent the command new
01/03/2015 12:24:47;0002;PBS_Server;Svr;PBS_Server;Torque Server Version = 3.0.5, loglevel = 0
01/03/2015 12:25:02;0040;PBS_Server;Svr;tyrone-cluster;Scheduler was sent the command new
01/03/2015 12:25:32;0040;PBS_Server;Svr;tyrone-cluster;Scheduler was sent the command new
01/03/2015 12:26:02;0040;PBS_Server;Svr;tyrone-cluster;Scheduler was sent the command new
01/03/2015 12:26:32;0040;PBS_Server;Svr;tyrone-cluster;Scheduler was sent the command new
01/03/2015 12:27:02;0040;PBS_Server;Svr;tyrone-cluster;Scheduler was sent the command new
01/03/2015 12:27:32;0040;PBS_Server;Svr;tyrone-cluster;Scheduler was sent the command new
01/03/2015 12:28:02;0040;PBS_Server;Svr;tyrone-cluster;Scheduler was sent the command new
01/03/2015 12:28:32;0040;PBS_Server;Svr;tyrone-cluster;Scheduler was sent the command new
01/03/2015 12:29:03;0040;PBS_Server;Svr;tyrone-cluster;Scheduler was sent the command new
01/03/2015 12:29:33;0040;PBS_Server;Svr;tyrone-cluster;Scheduler was sent the command new
01/03/2015 12:29:47;0002;PBS_Server;Svr;PBS_Server;Torque Server Version = 3.0.5, loglevel = 0
01/03/2015 12:30:03;0040;PBS_Server;Svr;tyrone-cluster;Scheduler was sent the command new
01/03/2015 12:30:33;0040;PBS_Server;Svr;tyrone-cluster;Scheduler was sent the command new
01/03/2015 12:31:03;0040;PBS_Server;Svr;tyrone-cluster;Scheduler was sent the command new
01/03/2015 12:31:33;0040;PBS_Server;Svr;tyrone-cluster;Scheduler was sent the command new
01/03/2015 12:32:03;0040;PBS_Server;Svr;tyrone-cluster;Scheduler was sent the command new
01/03/2015 12:32:33;0040;PBS_Server;Svr;tyrone-cluster;Scheduler was sent the command new
01/03/2015 12:33:03;0040;PBS_Server;Svr;tyrone-cluster;Scheduler was sent the command new
01/03/2015 12:33:34;0040;PBS_Server;Svr;tyrone-cluster;Scheduler was sent the command new
01/03/2015 12:34:04;0040;PBS_Server;Svr;tyrone-cluster;Scheduler was sent the command new
01/03/2015 12:34:34;0040;PBS_Server;Svr;tyrone-cluster;Scheduler was sent the command new
01/03/2015 12:34:47;0002;PBS_Server;Svr;PBS_Server;Torque Server Version = 3.0.5, loglevel = 0
01/03/2015 12:35:04;0040;PBS_Server;Svr;tyrone-cluster;Scheduler was sent the command new
01/03/2015 12:35:34;0040;PBS_Server;Svr;tyrone-cluster;Scheduler was sent the command new
01/03/2015 12:36:04;0040;PBS_Server;Svr;tyrone-cluster;Scheduler was sent the command new
01/03/2015 12:36:34;0040;PBS_Server;Svr;tyrone-cluster;Scheduler was sent the command new
01/03/2015 12:37:04;0040;PBS_Server;Svr;tyrone-cluster;Scheduler was sent the command new
01/03/2015 12:37:35;0040;PBS_Server;Svr;tyrone-cluster;Scheduler was sent the command new
01/03/2015 12:38:05;0040;PBS_Server;Svr;tyrone-cluster;Scheduler was sent the command new
01/03/2015 12:38:35;0040;PBS_Server;Svr;tyrone-cluster;Scheduler was sent the command new
01/03/2015 12:39:05;0040;PBS_Server;Svr;tyrone-cluster;Scheduler was sent the command new
01/03/2015 12:39:35;0040;PBS_Server;Svr;tyrone-cluster;Scheduler was sent the command new
01/03/2015 12:39:47;0002;PBS_Server;Svr;PBS_Server;Torque Server Version = 3.0.5, loglevel = 0
01/03/2015 12:40:05;0040;PBS_Server;Svr;tyrone-cluster;Scheduler was sent the command new
01/03/2015 12:40:35;0040;PBS_Server;Svr;tyrone-cluster;Scheduler was sent the command new
01/03/2015 12:41:05;0040;PBS_Server;Svr;tyrone-cluster;Scheduler was sent the command new
01/03/2015 12:41:35;0040;PBS_Server;Svr;tyrone-cluster;Scheduler was sent the command new
01/03/2015 12:42:06;0040;PBS_Server;Svr;tyrone-cluster;Scheduler was sent the command new
01/03/2015 12:42:36;0040;PBS_Server;Svr;tyrone-cluster;Scheduler was sent the command new
01/03/2015 12:43:06;0040;PBS_Server;Svr;tyrone-cluster;Scheduler was sent the command new
01/03/2015 12:43:36;0040;PBS_Server;Svr;tyrone-cluster;Scheduler was sent the command new
01/03/2015 12:44:06;0040;PBS_Server;Svr;tyrone-cluster;Scheduler was sent the command new
01/03/2015 12:44:36;0040;PBS_Server;Svr;tyrone-cluster;Scheduler was sent the command new
01/03/2015 12:44:47;0002;PBS_Server;Svr;PBS_Server;Torque Server Version = 3.0.5, loglevel = 0
01/03/2015 12:45:06;0040;PBS_Server;Svr;tyrone-cluster;Scheduler was sent the command new
01/03/2015 12:45:36;0040;PBS_Server;Svr;tyrone-cluster;Scheduler was sent the command new
01/03/2015 12:46:06;0040;PBS_Server;Svr;tyrone-cluster;Scheduler was sent the command new
01/03/2015 12:46:37;0040;PBS_Server;Svr;tyrone-cluster;Scheduler was sent the command new
01/03/2015 12:47:07;0040;PBS_Server;Svr;tyrone-cluster;Scheduler was sent the command new
01/03/2015 12:47:37;0040;PBS_Server;Svr;tyrone-cluster;Scheduler was sent the command new
01/03/2015 12:48:07;0040;PBS_Server;Svr;tyrone-cluster;Scheduler was sent the command new
01/03/2015 12:48:37;0040;PBS_Server;Svr;tyrone-cluster;Scheduler was sent the command new
01/03/2015 12:49:07;0040;PBS_Server;Svr;tyrone-cluster;Scheduler was sent the command new
01/03/2015 12:49:37;0040;PBS_Server;Svr;tyrone-cluster;Scheduler was sent the command new
01/03/2015 12:49:47;0002;PBS_Server;Svr;PBS_Server;Torque Server Version = 3.0.5, loglevel = 0
01/03/2015 12:50:07;0040;PBS_Server;Svr;tyrone-cluster;Scheduler was sent the command new
01/03/2015 12:50:38;0040;PBS_Server;Svr;tyrone-cluster;Scheduler was sent the command new
01/03/2015 12:51:08;0040;PBS_Server;Svr;tyrone-cluster;Scheduler was sent the command new
01/03/2015 12:51:38;0040;PBS_Server;Svr;tyrone-cluster;Scheduler was sent the command new
01/03/2015 12:52:08;0040;PBS_Server;Svr;tyrone-cluster;Scheduler was sent the command new
01/03/2015 12:52:38;0040;PBS_Server;Svr;tyrone-cluster;Scheduler was sent the command new
01/03/2015 12:53:08;0040;PBS_Server;Svr;tyrone-cluster;Scheduler was sent the command new
01/03/2015 12:53:38;0040;PBS_Server;Svr;tyrone-cluster;Scheduler was sent the command new
01/03/2015 12:54:09;0040;PBS_Server;Svr;tyrone-cluster;Scheduler was sent the command new
01/03/2015 12:54:39;0040;PBS_Server;Svr;tyrone-cluster;Scheduler was sent the command new
01/03/2015 12:54:47;0002;PBS_Server;Svr;PBS_Server;Torque Server Version = 3.0.5, loglevel = 0
01/03/2015 12:55:09;0040;PBS_Server;Svr;tyrone-cluster;Scheduler was sent the command new
01/03/2015 12:55:39;0040;PBS_Server;Svr;tyrone-cluster;Scheduler was sent the command new
01/03/2015 12:56:09;0040;PBS_Server;Svr;tyrone-cluster;Scheduler was sent the command new
01/03/2015 12:56:39;0040;PBS_Server;Svr;tyrone-cluster;Scheduler was sent the command new
01/03/2015 12:57:09;0040;PBS_Server;Svr;tyrone-cluster;Scheduler was sent the command new
01/03/2015 12:57:39;0040;PBS_Server;Svr;tyrone-cluster;Scheduler was sent the command new
01/03/2015 12:58:10;0040;PBS_Server;Svr;tyrone-cluster;Scheduler was sent the command new
01/03/2015 12:58:40;0040;PBS_Server;Svr;tyrone-cluster;Scheduler was sent the command new
01/03/2015 12:59:10;0040;PBS_Server;Svr;tyrone-cluster;Scheduler was sent the command new
01/03/2015 12:59:40;0040;PBS_Server;Svr;tyrone-cluster;Scheduler was sent the command new
01/03/2015 12:59:47;0002;PBS_Server;Svr;PBS_Server;Torque Server Version = 3.0.5, loglevel = 0
01/03/2015 13:00:10;0040;PBS_Server;Svr;tyrone-cluster;Scheduler was sent the command new
01/03/2015 13:00:40;0040;PBS_Server;Svr;tyrone-cluster;Scheduler was sent the command new
01/03/2015 13:01:10;0040;PBS_Server;Svr;tyrone-cluster;Scheduler was sent the command new
01/03/2015 13:01:40;0040;PBS_Server;Svr;tyrone-cluster;Scheduler was sent the command new
01/03/2015 13:02:11;0040;PBS_Server;Svr;tyrone-cluster;Scheduler was sent the command new
01/03/2015 13:02:41;0040;PBS_Server;Svr;tyrone-cluster;Scheduler was sent the command new
01/03/2015 13:03:11;0040;PBS_Server;Svr;tyrone-cluster;Scheduler was sent the command new
01/03/2015 13:03:41;0040;PBS_Server;Svr;tyrone-cluster;Scheduler was sent the command new
01/03/2015 13:04:11;0040;PBS_Server;Svr;tyrone-cluster;Scheduler was sent the command new
01/03/2015 13:04:41;0040;PBS_Server;Svr;tyrone-cluster;Scheduler was sent the command new
01/03/2015 13:04:47;0002;PBS_Server;Svr;PBS_Server;Torque Server Version = 3.0.5, loglevel = 0
01/03/2015 13:05:11;0040;PBS_Server;Svr;tyrone-cluster;Scheduler was sent the command new
01/03/2015 13:05:41;0040;PBS_Server;Svr;tyrone-cluster;Scheduler was sent the command new
01/03/2015 13:06:11;0040;PBS_Server;Svr;tyrone-cluster;Scheduler was sent the command new
01/03/2015 13:06:42;0040;PBS_Server;Svr;tyrone-cluster;Scheduler was sent the command new
01/03/2015 13:07:12;0040;PBS_Server;Svr;tyrone-cluster;Scheduler was sent the command new
01/03/2015 13:07:42;0040;PBS_Server;Svr;tyrone-cluster;Scheduler was sent the command new
01/03/2015 13:08:12;0040;PBS_Server;Svr;tyrone-cluster;Scheduler was sent the command new
01/03/2015 13:08:42;0040;PBS_Server;Svr;tyrone-cluster;Scheduler was sent the command new
01/03/2015 13:09:12;0040;PBS_Server;Svr;tyrone-cluster;Scheduler was sent the command new
01/03/2015 13:09:42;0040;PBS_Server;Svr;tyrone-cluster;Scheduler was sent the command new
01/03/2015 13:09:47;0002;PBS_Server;Svr;PBS_Server;Torque Server Version = 3.0.5, loglevel = 0
01/03/2015 13:10:12;0040;PBS_Server;Svr;tyrone-cluster;Scheduler was sent the command new
01/03/2015 13:10:42;0040;PBS_Server;Svr;tyrone-cluster;Scheduler was sent the command new
01/03/2015 13:11:13;0040;PBS_Server;Svr;tyrone-cluster;Scheduler was sent the command new
01/03/2015 13:11:43;0040;PBS_Server;Svr;tyrone-cluster;Scheduler was sent the command new
01/03/2015 13:12:13;0040;PBS_Server;Svr;tyrone-cluster;Scheduler was sent the command new
01/03/2015 13:12:43;0040;PBS_Server;Svr;tyrone-cluster;Scheduler was sent the command new
01/03/2015 13:13:13;0040;PBS_Server;Svr;tyrone-cluster;Scheduler was sent the command new
01/03/2015 13:13:43;0040;PBS_Server;Svr;tyrone-cluster;Scheduler was sent the command new
01/03/2015 13:14:13;0040;PBS_Server;Svr;tyrone-cluster;Scheduler was sent the command new
01/03/2015 13:14:43;0040;PBS_Server;Svr;tyrone-cluster;Scheduler was sent the command new
01/03/2015 13:14:47;0002;PBS_Server;Svr;PBS_Server;Torque Server Version = 3.0.5, loglevel = 0
01/03/2015 13:15:13;0040;PBS_Server;Svr;tyrone-cluster;Scheduler was sent the command new
01/03/2015 13:15:44;0040;PBS_Server;Svr;tyrone-cluster;Scheduler was sent the command new
01/03/2015 13:16:14;0040;PBS_Server;Svr;tyrone-cluster;Scheduler was sent the command new
01/03/2015 13:16:44;0040;PBS_Server;Svr;tyrone-cluster;Scheduler was sent the command new
01/03/2015 13:17:14;0040;PBS_Server;Svr;tyrone-cluster;Scheduler was sent the command new
01/03/2015 13:17:44;0040;PBS_Server;Svr;tyrone-cluster;Scheduler was sent the command new
01/03/2015 13:18:14;0040;PBS_Server;Svr;tyrone-cluster;Scheduler was sent the command new
01/03/2015 13:18:44;0040;PBS_Server;Svr;tyrone-cluster;Scheduler was sent the command new
01/03/2015 13:19:14;0040;PBS_Server;Svr;tyrone-cluster;Scheduler was sent the command new
01/03/2015 13:19:45;0040;PBS_Server;Svr;tyrone-cluster;Scheduler was sent the command new
01/03/2015 13:19:47;0002;PBS_Server;Svr;PBS_Server;Torque Server Version = 3.0.5, loglevel = 0
01/03/2015 13:20:15;0040;PBS_Server;Svr;tyrone-cluster;Scheduler was sent the command new
01/03/2015 13:20:45;0040;PBS_Server;Svr;tyrone-cluster;Scheduler was sent the command new
01/03/2015 13:21:15;0040;PBS_Server;Svr;tyrone-cluster;Scheduler was sent the command new
01/03/2015 13:21:45;0040;PBS_Server;Svr;tyrone-cluster;Scheduler was sent the command new
01/03/2015 13:22:15;0040;PBS_Server;Svr;tyrone-cluster;Scheduler was sent the command new
01/03/2015 13:22:45;0040;PBS_Server;Svr;tyrone-cluster;Scheduler was sent the command new
01/03/2015 13:23:15;0040;PBS_Server;Svr;tyrone-cluster;Scheduler was sent the command new
01/03/2015 13:23:46;0040;PBS_Server;Svr;tyrone-cluster;Scheduler was sent the command new
01/03/2015 13:24:16;0040;PBS_Server;Svr;tyrone-cluster;Scheduler was sent the command new
01/03/2015 13:24:46;0040;PBS_Server;Svr;tyrone-cluster;Scheduler was sent the command new
01/03/2015 13:24:47;0002;PBS_Server;Svr;PBS_Server;Torque Server Version = 3.0.5, loglevel = 0
01/03/2015 13:25:16;0040;PBS_Server;Svr;tyrone-cluster;Scheduler was sent the command new
01/03/2015 13:25:46;0040;PBS_Server;Svr;tyrone-cluster;Scheduler was sent the command new
01/03/2015 13:26:16;0040;PBS_Server;Svr;tyrone-cluster;Scheduler was sent the command new
01/03/2015 13:26:46;0040;PBS_Server;Svr;tyrone-cluster;Scheduler was sent the command new
01/03/2015 13:27:16;0040;PBS_Server;Svr;tyrone-cluster;Scheduler was sent the command new
01/03/2015 13:27:46;0040;PBS_Server;Svr;tyrone-cluster;Scheduler was sent the command new
01/03/2015 13:28:17;0040;PBS_Server;Svr;tyrone-cluster;Scheduler was sent the command new
01/03/2015 13:28:47;0040;PBS_Server;Svr;tyrone-cluster;Scheduler was sent the command new
01/03/2015 13:29:17;0040;PBS_Server;Svr;tyrone-cluster;Scheduler was sent the command new
01/03/2015 13:29:47;0002;PBS_Server;Svr;PBS_Server;Torque Server Version = 3.0.5, loglevel = 0
01/03/2015 13:29:47;0040;PBS_Server;Svr;tyrone-cluster;Scheduler was sent the command new
01/03/2015 13:30:17;0040;PBS_Server;Svr;tyrone-cluster;Scheduler was sent the command new
01/03/2015 13:30:47;0040;PBS_Server;Svr;tyrone-cluster;Scheduler was sent the command new
01/03/2015 13:31:17;0040;PBS_Server;Svr;tyrone-cluster;Scheduler was sent the command new
01/03/2015 13:31:47;0040;PBS_Server;Svr;tyrone-cluster;Scheduler was sent the command new
01/03/2015 13:32:18;0040;PBS_Server;Svr;tyrone-cluster;Scheduler was sent the command new
01/03/2015 13:32:48;0040;PBS_Server;Svr;tyrone-cluster;Scheduler was sent the command new
01/03/2015 13:33:18;0040;PBS_Server;Svr;tyrone-cluster;Scheduler was sent the command new
01/03/2015 13:33:48;0040;PBS_Server;Svr;tyrone-cluster;Scheduler was sent the command new
01/03/2015 13:34:18;0040;PBS_Server;Svr;tyrone-cluster;Scheduler was sent the command new
01/03/2015 13:34:47;0002;PBS_Server;Svr;PBS_Server;Torque Server Version = 3.0.5, loglevel = 0
01/03/2015 13:34:48;0040;PBS_Server;Svr;tyrone-cluster;Scheduler was sent the command new
01/03/2015 13:35:18;0040;PBS_Server;Svr;tyrone-cluster;Scheduler was sent the command new
01/03/2015 13:35:48;0040;PBS_Server;Svr;tyrone-cluster;Scheduler was sent the command new
01/03/2015 13:36:18;0040;PBS_Server;Svr;tyrone-cluster;Scheduler was sent the command new
01/03/2015 13:36:49;0040;PBS_Server;Svr;tyrone-cluster;Scheduler was sent the command new
01/03/2015 13:37:19;0040;PBS_Server;Svr;tyrone-cluster;Scheduler was sent the command new
01/03/2015 13:37:49;0040;PBS_Server;Svr;tyrone-cluster;Scheduler was sent the command new
01/03/2015 13:38:19;0040;PBS_Server;Svr;tyrone-cluster;Scheduler was sent the command new
01/03/2015 13:38:49;0040;PBS_Server;Svr;tyrone-cluster;Scheduler was sent the command new
01/03/2015 13:39:19;0040;PBS_Server;Svr;tyrone-cluster;Scheduler was sent the command new
01/03/2015 13:39:47;0002;PBS_Server;Svr;PBS_Server;Torque Server Version = 3.0.5, loglevel = 0
01/03/2015 13:39:49;0040;PBS_Server;Svr;tyrone-cluster;Scheduler was sent the command new
01/03/2015 13:40:19;0040;PBS_Server;Svr;tyrone-cluster;Scheduler was sent the command new
01/03/2015 13:40:49;0040;PBS_Server;Svr;tyrone-cluster;Scheduler was sent the command new
01/03/2015 13:41:20;0040;PBS_Server;Svr;tyrone-cluster;Scheduler was sent the command new
01/03/2015 13:41:50;0040;PBS_Server;Svr;tyrone-cluster;Scheduler was sent the command new
01/03/2015 13:42:20;0040;PBS_Server;Svr;tyrone-cluster;Scheduler was sent the command new
01/03/2015 13:42:50;0040;PBS_Server;Svr;tyrone-cluster;Scheduler was sent the command new
01/03/2015 13:43:20;0040;PBS_Server;Svr;tyrone-cluster;Scheduler was sent the command new
01/03/2015 13:43:50;0040;PBS_Server;Svr;tyrone-cluster;Scheduler was sent the command new
01/03/2015 13:44:20;0040;PBS_Server;Svr;tyrone-cluster;Scheduler was sent the command new
01/03/2015 13:44:47;0002;PBS_Server;Svr;PBS_Server;Torque Server Version = 3.0.5, loglevel = 0
01/03/2015 13:44:50;0040;PBS_Server;Svr;tyrone-cluster;Scheduler was sent the command new
01/03/2015 13:45:20;0040;PBS_Server;Svr;tyrone-cluster;Scheduler was sent the command new
01/03/2015 13:45:51;0040;PBS_Server;Svr;tyrone-cluster;Scheduler was sent the command new
01/03/2015 13:46:20;0040;PBS_Server;Svr;tyrone-cluster;Scheduler was sent the command new
01/03/2015 13:46:51;0040;PBS_Server;Svr;tyrone-cluster;Scheduler was sent the command new
01/03/2015 13:47:21;0040;PBS_Server;Svr;tyrone-cluster;Scheduler was sent the command new
01/03/2015 13:47:51;0040;PBS_Server;Svr;tyrone-cluster;Scheduler was sent the command new
01/03/2015 13:48:21;0040;PBS_Server;Svr;tyrone-cluster;Scheduler was sent the command new
01/03/2015 13:48:51;0040;PBS_Server;Svr;tyrone-cluster;Scheduler was sent the command new
01/03/2015 13:49:21;0040;PBS_Server;Svr;tyrone-cluster;Scheduler was sent the command new
01/03/2015 13:49:47;0002;PBS_Server;Svr;PBS_Server;Torque Server Version = 3.0.5, loglevel = 0
01/03/2015 13:49:51;0040;PBS_Server;Svr;tyrone-cluster;Scheduler was sent the command new
01/03/2015 13:50:22;0040;PBS_Server;Svr;tyrone-cluster;Scheduler was sent the command new
01/03/2015 13:50:40;0100;PBS_Server;Job;46416.tyrone-cluster;enqueuing into batch, state 1 hop 1
01/03/2015 13:50:40;0100;PBS_Server;Job;46416.tyrone-cluster;dequeuing from batch, state QUEUED
01/03/2015 13:50:40;0100;PBS_Server;Job;46416.tyrone-cluster;enqueuing into qp64, state 1 hop 1
01/03/2015 13:50:40;0008;PBS_Server;Job;46416.tyrone-cluster;Job Queued at request of aseabwit@tyrone-cluster, owner = aseabwit@tyrone-cluster, job name = DNsFlo_128, queue = qp64
01/03/2015 13:50:40;0040;PBS_Server;Svr;tyrone-cluster;Scheduler was sent the command new
01/03/2015 13:50:41;0008;PBS_Server;Job;46416.tyrone-cluster;Job Modified at request of Scheduler@tyrone-cluster
01/03/2015 13:50:41;0008;PBS_Server;Job;46416.tyrone-cluster;Job Run at request of Scheduler@tyrone-cluster
01/03/2015 13:50:41;0040;PBS_Server;Svr;tyrone-cluster;Scheduler was sent the command recyc
01/03/2015 13:50:53;0040;PBS_Server;Svr;tyrone-cluster;Scheduler was sent the command new
01/03/2015 13:51:25;0040;PBS_Server;Svr;tyrone-cluster;Scheduler was sent the command new
01/03/2015 13:51:34;000d;PBS_Server;Job;46416.tyrone-cluster;Not sending email: User does not want mail of this type.
01/03/2015 13:51:57;0040;PBS_Server;Svr;tyrone-cluster;Scheduler was sent the command new
01/03/2015 13:52:27;0040;PBS_Server;Svr;tyrone-cluster;Scheduler was sent the command new
01/03/2015 13:52:57;0040;PBS_Server;Svr;tyrone-cluster;Scheduler was sent the command new
01/03/2015 13:53:28;0040;PBS_Server;Svr;tyrone-cluster;Scheduler was sent the command new
01/03/2015 13:53:58;0040;PBS_Server;Svr;tyrone-cluster;Scheduler was sent the command new
01/03/2015 13:54:28;0040;PBS_Server;Svr;tyrone-cluster;Scheduler was sent the command new
01/03/2015 13:54:47;0002;PBS_Server;Svr;PBS_Server;Torque Server Version = 3.0.5, loglevel = 0
01/03/2015 13:54:58;0040;PBS_Server;Svr;tyrone-cluster;Scheduler was sent the command new
01/03/2015 13:55:28;0040;PBS_Server;Svr;tyrone-cluster;Scheduler was sent the command new
01/03/2015 13:55:58;0040;PBS_Server;Svr;tyrone-cluster;Scheduler was sent the command new
01/03/2015 13:56:28;0040;PBS_Server;Svr;tyrone-cluster;Scheduler was sent the command new
01/03/2015 13:56:58;0040;PBS_Server;Svr;tyrone-cluster;Scheduler was sent the command new
01/03/2015 13:57:28;0040;PBS_Server;Svr;tyrone-cluster;Scheduler was sent the command new
01/03/2015 13:57:58;0040;PBS_Server;Svr;tyrone-cluster;Scheduler was sent the command new
01/03/2015 13:58:29;0040;PBS_Server;Svr;tyrone-cluster;Scheduler was sent the command new
01/03/2015 13:58:59;0040;PBS_Server;Svr;tyrone-cluster;Scheduler was sent the command new
01/03/2015 13:59:29;0040;PBS_Server;Svr;tyrone-cluster;Scheduler was sent the command new
01/03/2015 13:59:47;0002;PBS_Server;Svr;PBS_Server;Torque Server Version = 3.0.5, loglevel = 0
01/03/2015 13:59:48;0080;PBS_Server;Req;req_reject;Reject reply code=15001(Unknown Job Id), aux=0, type=StatusJob, from esdsubha@tyrone-cluster
01/03/2015 13:59:48;0080;PBS_Server;Req;req_reject;Reject reply code=15001(Unknown Job Id), aux=0, type=LocateJob, from esdsubha@tyrone-cluster
01/03/2015 13:59:59;0040;PBS_Server;Svr;tyrone-cluster;Scheduler was sent the command new
01/03/2015 14:00:29;0040;PBS_Server;Svr;tyrone-cluster;Scheduler was sent the command new
01/03/2015 14:00:43;0100;PBS_Server;Job;46417.tyrone-cluster;enqueuing into batch, state 1 hop 1
01/03/2015 14:00:43;0100;PBS_Server;Job;46417.tyrone-cluster;dequeuing from batch, state QUEUED
01/03/2015 14:00:43;0100;PBS_Server;Job;46417.tyrone-cluster;enqueuing into qp32, state 1 hop 1
01/03/2015 14:00:43;0008;PBS_Server;Job;46417.tyrone-cluster;Job Queued at request of esdsubha@tyrone-cluster, owner = esdsubha@tyrone-cluster, job name = Job4, queue = qp32
01/03/2015 14:00:43;0040;PBS_Server;Svr;tyrone-cluster;Scheduler was sent the command new
01/03/2015 14:00:43;0008;PBS_Server;Job;46417.tyrone-cluster;Job Modified at request of Scheduler@tyrone-cluster
01/03/2015 14:00:59;0040;PBS_Server;Svr;tyrone-cluster;Scheduler was sent the command new
01/03/2015 14:01:29;0040;PBS_Server;Svr;tyrone-cluster;Scheduler was sent the command new
01/03/2015 14:01:33;0020;PBS_Server;Job;46417.tyrone-cluster;Unauthorized Request, request type: 6, Object: Job, Name: 46417.tyrone-cluster, request from: cessahoo@tyrone-cluster
01/03/2015 14:01:33;0080;PBS_Server;Req;req_reject;Reject reply code=15007(Unauthorized Request  MSG=operation not permitted), aux=0, type=DeleteJob, from cessahoo@tyrone-cluster
01/03/2015 14:01:59;0040;PBS_Server;Svr;tyrone-cluster;Scheduler was sent the command new
01/03/2015 14:02:30;0040;PBS_Server;Svr;tyrone-cluster;Scheduler was sent the command new
01/03/2015 14:02:53;0020;PBS_Server;Job;46417.tyrone-cluster;Unauthorized Request, request type: 6, Object: Job, Name: 46417.tyrone-cluster, request from: cessahoo@tyrone-cluster
01/03/2015 14:02:53;0080;PBS_Server;Req;req_reject;Reject reply code=15007(Unauthorized Request  MSG=operation not permitted), aux=0, type=DeleteJob, from cessahoo@tyrone-cluster
01/03/2015 14:03:00;0040;PBS_Server;Svr;tyrone-cluster;Scheduler was sent the command new
01/03/2015 14:03:30;0040;PBS_Server;Svr;tyrone-cluster;Scheduler was sent the command new
01/03/2015 14:04:00;0040;PBS_Server;Svr;tyrone-cluster;Scheduler was sent the command new
01/03/2015 14:04:30;0040;PBS_Server;Svr;tyrone-cluster;Scheduler was sent the command new
01/03/2015 14:04:47;0002;PBS_Server;Svr;PBS_Server;Torque Server Version = 3.0.5, loglevel = 0
01/03/2015 14:05:00;0040;PBS_Server;Svr;tyrone-cluster;Scheduler was sent the command new
01/03/2015 14:05:30;0040;PBS_Server;Svr;tyrone-cluster;Scheduler was sent the command new
01/03/2015 14:06:01;0040;PBS_Server;Svr;tyrone-cluster;Scheduler was sent the command new
01/03/2015 14:06:31;0040;PBS_Server;Svr;tyrone-cluster;Scheduler was sent the command new
01/03/2015 14:07:01;0040;PBS_Server;Svr;tyrone-cluster;Scheduler was sent the command new
01/03/2015 14:07:31;0040;PBS_Server;Svr;tyrone-cluster;Scheduler was sent the command new
01/03/2015 14:08:01;0040;PBS_Server;Svr;tyrone-cluster;Scheduler was sent the command new
01/03/2015 14:08:31;0040;PBS_Server;Svr;tyrone-cluster;Scheduler was sent the command new
01/03/2015 14:09:01;0040;PBS_Server;Svr;tyrone-cluster;Scheduler was sent the command new
01/03/2015 14:09:31;0040;PBS_Server;Svr;tyrone-cluster;Scheduler was sent the command new
01/03/2015 14:09:47;0002;PBS_Server;Svr;PBS_Server;Torque Server Version = 3.0.5, loglevel = 0
01/03/2015 14:10:01;0040;PBS_Server;Svr;tyrone-cluster;Scheduler was sent the command new
01/03/2015 14:10:31;0040;PBS_Server;Svr;tyrone-cluster;Scheduler was sent the command new
01/03/2015 14:11:02;0040;PBS_Server;Svr;tyrone-cluster;Scheduler was sent the command new
01/03/2015 14:11:32;0040;PBS_Server;Svr;tyrone-cluster;Scheduler was sent the command new
01/03/2015 14:12:02;0040;PBS_Server;Svr;tyrone-cluster;Scheduler was sent the command new
01/03/2015 14:12:32;0040;PBS_Server;Svr;tyrone-cluster;Scheduler was sent the command new
01/03/2015 14:12:36;0100;PBS_Server;Job;46418.tyrone-cluster;enqueuing into batch, state 1 hop 1
01/03/2015 14:12:36;0008;PBS_Server;Job;46418.tyrone-cluster;Job Queued at request of esdsubha@tyrone-cluster, owner = esdsubha@tyrone-cluster, job name = Job1, queue = batch
01/03/2015 14:12:36;0040;PBS_Server;Svr;tyrone-cluster;Scheduler was sent the command new
01/03/2015 14:12:37;0008;PBS_Server;Job;46418.tyrone-cluster;Job Modified at request of Scheduler@tyrone-cluster
01/03/2015 14:13:02;0040;PBS_Server;Svr;tyrone-cluster;Scheduler was sent the command new
01/03/2015 14:13:11;0040;PBS_Server;Svr;tyrone-cluster;Scheduler was sent the command new
01/03/2015 14:13:32;0040;PBS_Server;Svr;tyrone-cluster;Scheduler was sent the command new
01/03/2015 14:13:42;0040;PBS_Server;Svr;tyrone-cluster;Scheduler was sent the command new
01/03/2015 14:14:02;0040;PBS_Server;Svr;tyrone-cluster;Scheduler was sent the command new
01/03/2015 14:14:13;0040;PBS_Server;Svr;tyrone-cluster;Scheduler was sent the command new
01/03/2015 14:14:32;0040;PBS_Server;Svr;tyrone-cluster;Scheduler was sent the command new
01/03/2015 14:14:47;0002;PBS_Server;Svr;PBS_Server;Torque Server Version = 3.0.5, loglevel = 0
01/03/2015 14:14:47;0040;PBS_Server;Svr;tyrone-cluster;Scheduler was sent the command new
01/03/2015 14:15:03;0040;PBS_Server;Svr;tyrone-cluster;Scheduler was sent the command new
01/03/2015 14:15:13;0040;PBS_Server;Svr;tyrone-cluster;Scheduler was sent the command new
01/03/2015 14:15:33;0040;PBS_Server;Svr;tyrone-cluster;Scheduler was sent the command new
01/03/2015 14:15:44;0040;PBS_Server;Svr;tyrone-cluster;Scheduler was sent the command new
01/03/2015 14:16:03;0040;PBS_Server;Svr;tyrone-cluster;Scheduler was sent the command new
01/03/2015 14:16:07;0100;PBS_Server;Job;46419.tyrone-cluster;enqueuing into batch, state 1 hop 1
01/03/2015 14:16:07;0100;PBS_Server;Job;46419.tyrone-cluster;dequeuing from batch, state QUEUED
01/03/2015 14:16:07;0100;PBS_Server;Job;46419.tyrone-cluster;enqueuing into idqueue, state 1 hop 1
01/03/2015 14:16:07;0008;PBS_Server;Job;46419.tyrone-cluster;Job Queued at request of secparth@tyrone-cluster, owner = secparth@tyrone-cluster, job name = JOB11, queue = idqueue
01/03/2015 14:16:07;0040;PBS_Server;Svr;tyrone-cluster;Scheduler was sent the command new
01/03/2015 14:16:07;0008;PBS_Server;Job;46419.tyrone-cluster;Job Modified at request of Scheduler@tyrone-cluster
01/03/2015 14:16:07;0008;PBS_Server;Job;46419.tyrone-cluster;Job Run at request of Scheduler@tyrone-cluster
01/03/2015 14:16:07;0040;PBS_Server;Svr;tyrone-cluster;Scheduler was sent the command recyc
01/03/2015 14:16:07;000d;PBS_Server;Job;46419.tyrone-cluster;Not sending email: User does not want mail of this type.
01/03/2015 14:16:10;000d;PBS_Server;Job;46419.tyrone-cluster;Not sending email: User does not want mail of this type.
01/03/2015 14:16:10;0010;PBS_Server;Job;46419.tyrone-cluster;Exit_status=0 resources_used.cput=00:00:01 resources_used.mem=0kb resources_used.vmem=0kb resources_used.walltime=00:00:03
01/03/2015 14:16:10;0008;PBS_Server;Job;NULL;on_job_exit valid pjob: 0x13f32e0 (substate=50)
01/03/2015 14:16:10;0008;PBS_Server;Job;NULL;on_job_exit valid pjob: 0x13f32e0 (substate=51)
01/03/2015 14:16:10;0008;PBS_Server;Job;NULL;on_job_exit valid pjob: 0x13f32e0 (substate=51)
01/03/2015 14:16:10;0008;PBS_Server;Job;NULL;on_job_exit valid pjob: 0x13f32e0 (substate=53)
01/03/2015 14:16:10;0100;PBS_Server;Job;46419.tyrone-cluster;dequeuing from idqueue, state COMPLETE
01/03/2015 14:16:10;0040;PBS_Server;Svr;tyrone-cluster;Scheduler was sent the command term
01/03/2015 14:16:17;0040;PBS_Server;Svr;tyrone-cluster;Scheduler was sent the command new
01/03/2015 14:16:33;0040;PBS_Server;Svr;tyrone-cluster;Scheduler was sent the command new
01/03/2015 14:16:51;0040;PBS_Server;Svr;tyrone-cluster;Scheduler was sent the command new
01/03/2015 14:17:03;0040;PBS_Server;Svr;tyrone-cluster;Scheduler was sent the command new
01/03/2015 14:17:20;0040;PBS_Server;Svr;tyrone-cluster;Scheduler was sent the command new
01/03/2015 14:17:33;0040;PBS_Server;Svr;tyrone-cluster;Scheduler was sent the command new
01/03/2015 14:17:50;0040;PBS_Server;Svr;tyrone-cluster;Scheduler was sent the command new
01/03/2015 14:18:03;0040;PBS_Server;Svr;tyrone-cluster;Scheduler was sent the command new
01/03/2015 14:18:26;0040;PBS_Server;Svr;tyrone-cluster;Scheduler was sent the command new
01/03/2015 14:18:33;0040;PBS_Server;Svr;tyrone-cluster;Scheduler was sent the command new
01/03/2015 14:18:57;0040;PBS_Server;Svr;tyrone-cluster;Scheduler was sent the command new
01/03/2015 14:19:03;0040;PBS_Server;Svr;tyrone-cluster;Scheduler was sent the command new
01/03/2015 14:19:29;0040;PBS_Server;Svr;tyrone-cluster;Scheduler was sent the command new
01/03/2015 14:19:34;0040;PBS_Server;Svr;tyrone-cluster;Scheduler was sent the command new
01/03/2015 14:19:47;0002;PBS_Server;Svr;PBS_Server;Torque Server Version = 3.0.5, loglevel = 0
01/03/2015 14:20:02;0040;PBS_Server;Svr;tyrone-cluster;Scheduler was sent the command new
01/03/2015 14:20:04;0040;PBS_Server;Svr;tyrone-cluster;Scheduler was sent the command new
01/03/2015 14:20:32;0040;PBS_Server;Svr;tyrone-cluster;Scheduler was sent the command new
01/03/2015 14:20:34;0040;PBS_Server;Svr;tyrone-cluster;Scheduler was sent the command new
01/03/2015 14:21:04;0040;PBS_Server;Svr;tyrone-cluster;Scheduler was sent the command new
01/03/2015 14:21:34;0040;PBS_Server;Svr;tyrone-cluster;Scheduler was sent the command new
01/03/2015 14:22:04;0040;PBS_Server;Svr;tyrone-cluster;Scheduler was sent the command new
01/03/2015 14:22:34;0040;PBS_Server;Svr;tyrone-cluster;Scheduler was sent the command new
01/03/2015 14:23:04;0040;PBS_Server;Svr;tyrone-cluster;Scheduler was sent the command new
01/03/2015 14:23:07;0100;PBS_Server;Job;46420.tyrone-cluster;enqueuing into batch, state 1 hop 1
01/03/2015 14:23:07;0008;PBS_Server;Job;46420.tyrone-cluster;Job rejected by all possible destinations (check syntax, queue resources, ...)
01/03/2015 14:23:07;0100;PBS_Server;Job;46420.tyrone-cluster;dequeuing from batch, state QUEUED
01/03/2015 14:23:07;0080;PBS_Server;Req;req_reject;Reject reply code=15041(Job rejected by all possible destinations (check syntax, queue resources, ...)), aux=0, type=Commit, from secparth@tyrone-cluster
01/03/2015 14:23:07;0040;PBS_Server;Svr;tyrone-cluster;Scheduler was sent the command term
01/03/2015 14:23:34;0040;PBS_Server;Svr;tyrone-cluster;Scheduler was sent the command new
01/03/2015 14:23:41;0100;PBS_Server;Job;46421.tyrone-cluster;enqueuing into batch, state 1 hop 1
01/03/2015 14:23:41;0008;PBS_Server;Job;46421.tyrone-cluster;Job rejected by all possible destinations (check syntax, queue resources, ...)
01/03/2015 14:23:41;0100;PBS_Server;Job;46421.tyrone-cluster;dequeuing from batch, state QUEUED
01/03/2015 14:23:41;0080;PBS_Server;Req;req_reject;Reject reply code=15041(Job rejected by all possible destinations (check syntax, queue resources, ...)), aux=0, type=Commit, from secparth@tyrone-cluster
01/03/2015 14:23:41;0040;PBS_Server;Svr;tyrone-cluster;Scheduler was sent the command term
01/03/2015 14:24:05;0040;PBS_Server;Svr;tyrone-cluster;Scheduler was sent the command new
01/03/2015 14:24:35;0040;PBS_Server;Svr;tyrone-cluster;Scheduler was sent the command new
01/03/2015 14:24:47;0002;PBS_Server;Svr;PBS_Server;Torque Server Version = 3.0.5, loglevel = 0
01/03/2015 14:25:05;0040;PBS_Server;Svr;tyrone-cluster;Scheduler was sent the command new
01/03/2015 14:25:35;0040;PBS_Server;Svr;tyrone-cluster;Scheduler was sent the command new
01/03/2015 14:26:05;0040;PBS_Server;Svr;tyrone-cluster;Scheduler was sent the command new
01/03/2015 14:26:35;0040;PBS_Server;Svr;tyrone-cluster;Scheduler was sent the command new
01/03/2015 14:27:05;0040;PBS_Server;Svr;tyrone-cluster;Scheduler was sent the command new
01/03/2015 14:27:35;0040;PBS_Server;Svr;tyrone-cluster;Scheduler was sent the command new
01/03/2015 14:28:05;0040;PBS_Server;Svr;tyrone-cluster;Scheduler was sent the command new
01/03/2015 14:28:36;0040;PBS_Server;Svr;tyrone-cluster;Scheduler was sent the command new
01/03/2015 14:29:05;0040;PBS_Server;Svr;tyrone-cluster;Scheduler was sent the command new
01/03/2015 14:29:36;0040;PBS_Server;Svr;tyrone-cluster;Scheduler was sent the command new
01/03/2015 14:29:46;0100;PBS_Server;Job;46422.tyrone-cluster;enqueuing into batch, state 1 hop 1
01/03/2015 14:29:46;0008;PBS_Server;Job;46422.tyrone-cluster;Job rejected by all possible destinations (check syntax, queue resources, ...)
01/03/2015 14:29:46;0100;PBS_Server;Job;46422.tyrone-cluster;dequeuing from batch, state QUEUED
01/03/2015 14:29:46;0080;PBS_Server;Req;req_reject;Reject reply code=15041(Job rejected by all possible destinations (check syntax, queue resources, ...)), aux=0, type=Commit, from secparth@tyrone-cluster
01/03/2015 14:29:46;0040;PBS_Server;Svr;tyrone-cluster;Scheduler was sent the command term
01/03/2015 14:29:47;0002;PBS_Server;Svr;PBS_Server;Torque Server Version = 3.0.5, loglevel = 0
01/03/2015 14:30:06;0040;PBS_Server;Svr;tyrone-cluster;Scheduler was sent the command new
01/03/2015 14:30:36;0040;PBS_Server;Svr;tyrone-cluster;Scheduler was sent the command new
01/03/2015 14:31:06;0040;PBS_Server;Svr;tyrone-cluster;Scheduler was sent the command new
01/03/2015 14:31:36;0040;PBS_Server;Svr;tyrone-cluster;Scheduler was sent the command new
01/03/2015 14:32:06;0040;PBS_Server;Svr;tyrone-cluster;Scheduler was sent the command new
01/03/2015 14:32:36;0040;PBS_Server;Svr;tyrone-cluster;Scheduler was sent the command new
01/03/2015 14:32:56;0100;PBS_Server;Job;46423.tyrone-cluster;enqueuing into batch, state 1 hop 1
01/03/2015 14:32:56;0008;PBS_Server;Job;46423.tyrone-cluster;Job rejected by all possible destinations (check syntax, queue resources, ...)
01/03/2015 14:32:56;0100;PBS_Server;Job;46423.tyrone-cluster;dequeuing from batch, state QUEUED
01/03/2015 14:32:56;0080;PBS_Server;Req;req_reject;Reject reply code=15041(Job rejected by all possible destinations (check syntax, queue resources, ...)), aux=0, type=Commit, from secparth@tyrone-cluster
01/03/2015 14:32:56;0040;PBS_Server;Svr;tyrone-cluster;Scheduler was sent the command term
01/03/2015 14:33:06;0040;PBS_Server;Svr;tyrone-cluster;Scheduler was sent the command new
01/03/2015 14:33:36;0040;PBS_Server;Svr;tyrone-cluster;Scheduler was sent the command new
01/03/2015 14:34:07;0040;PBS_Server;Svr;tyrone-cluster;Scheduler was sent the command new
01/03/2015 14:34:37;0040;PBS_Server;Svr;tyrone-cluster;Scheduler was sent the command new
01/03/2015 14:34:47;0002;PBS_Server;Svr;PBS_Server;Torque Server Version = 3.0.5, loglevel = 0
01/03/2015 14:35:07;0040;PBS_Server;Svr;tyrone-cluster;Scheduler was sent the command new
01/03/2015 14:35:37;0040;PBS_Server;Svr;tyrone-cluster;Scheduler was sent the command new
01/03/2015 14:36:07;0040;PBS_Server;Svr;tyrone-cluster;Scheduler was sent the command new
01/03/2015 14:36:37;0040;PBS_Server;Svr;tyrone-cluster;Scheduler was sent the command new
01/03/2015 14:37:07;0040;PBS_Server;Svr;tyrone-cluster;Scheduler was sent the command new
01/03/2015 14:37:32;0100;PBS_Server;Job;46424.tyrone-cluster;enqueuing into batch, state 1 hop 1
01/03/2015 14:37:32;0008;PBS_Server;Job;46424.tyrone-cluster;Job rejected by all possible destinations (check syntax, queue resources, ...)
01/03/2015 14:37:32;0100;PBS_Server;Job;46424.tyrone-cluster;dequeuing from batch, state QUEUED
01/03/2015 14:37:32;0080;PBS_Server;Req;req_reject;Reject reply code=15041(Job rejected by all possible destinations (check syntax, queue resources, ...)), aux=0, type=Commit, from secparth@tyrone-cluster
01/03/2015 14:37:32;0040;PBS_Server;Svr;tyrone-cluster;Scheduler was sent the command term
01/03/2015 14:37:37;0040;PBS_Server;Svr;tyrone-cluster;Scheduler was sent the command new
01/03/2015 14:38:08;0040;PBS_Server;Svr;tyrone-cluster;Scheduler was sent the command new
01/03/2015 14:38:38;0040;PBS_Server;Svr;tyrone-cluster;Scheduler was sent the command new
01/03/2015 14:39:08;0040;PBS_Server;Svr;tyrone-cluster;Scheduler was sent the command new
01/03/2015 14:39:38;0040;PBS_Server;Svr;tyrone-cluster;Scheduler was sent the command new
01/03/2015 14:39:47;0002;PBS_Server;Svr;PBS_Server;Torque Server Version = 3.0.5, loglevel = 0
01/03/2015 14:40:08;0040;PBS_Server;Svr;tyrone-cluster;Scheduler was sent the command new
01/03/2015 14:40:38;0040;PBS_Server;Svr;tyrone-cluster;Scheduler was sent the command new
01/03/2015 14:41:08;0040;PBS_Server;Svr;tyrone-cluster;Scheduler was sent the command new
01/03/2015 14:41:11;0100;PBS_Server;Job;46425.tyrone-cluster;enqueuing into batch, state 1 hop 1
01/03/2015 14:41:11;0100;PBS_Server;Job;46425.tyrone-cluster;dequeuing from batch, state QUEUED
01/03/2015 14:41:11;0100;PBS_Server;Job;46425.tyrone-cluster;enqueuing into idqueue, state 1 hop 1
01/03/2015 14:41:11;0008;PBS_Server;Job;46425.tyrone-cluster;Job Queued at request of secparth@tyrone-cluster, owner = secparth@tyrone-cluster, job name = JOB11, queue = idqueue
01/03/2015 14:41:11;0040;PBS_Server;Svr;tyrone-cluster;Scheduler was sent the command new
01/03/2015 14:41:11;0008;PBS_Server;Job;46425.tyrone-cluster;Job Modified at request of Scheduler@tyrone-cluster
01/03/2015 14:41:11;0008;PBS_Server;Job;46425.tyrone-cluster;Job Run at request of Scheduler@tyrone-cluster
01/03/2015 14:41:11;0040;PBS_Server;Svr;tyrone-cluster;Scheduler was sent the command recyc
01/03/2015 14:41:11;000d;PBS_Server;Job;46425.tyrone-cluster;Not sending email: User does not want mail of this type.
01/03/2015 14:41:12;000d;PBS_Server;Job;46425.tyrone-cluster;Not sending email: User does not want mail of this type.
01/03/2015 14:41:12;0010;PBS_Server;Job;46425.tyrone-cluster;Exit_status=255 resources_used.cput=00:00:00 resources_used.mem=0kb resources_used.vmem=0kb resources_used.walltime=00:00:01
01/03/2015 14:41:12;0008;PBS_Server;Job;NULL;on_job_exit valid pjob: 0x1318cd0 (substate=50)
01/03/2015 14:41:12;0008;PBS_Server;Job;NULL;on_job_exit valid pjob: 0x1318cd0 (substate=51)
01/03/2015 14:41:12;0008;PBS_Server;Job;NULL;on_job_exit valid pjob: 0x1318cd0 (substate=51)
01/03/2015 14:41:12;0008;PBS_Server;Job;NULL;on_job_exit valid pjob: 0x1318cd0 (substate=53)
01/03/2015 14:41:12;0100;PBS_Server;Job;46425.tyrone-cluster;dequeuing from idqueue, state COMPLETE
01/03/2015 14:41:12;0040;PBS_Server;Svr;tyrone-cluster;Scheduler was sent the command term
01/03/2015 14:41:38;0040;PBS_Server;Svr;tyrone-cluster;Scheduler was sent the command new
01/03/2015 14:42:08;0040;PBS_Server;Svr;tyrone-cluster;Scheduler was sent the command new
01/03/2015 14:42:38;0040;PBS_Server;Svr;tyrone-cluster;Scheduler was sent the command new
01/03/2015 14:43:00;0100;PBS_Server;Job;46426.tyrone-cluster;enqueuing into batch, state 1 hop 1
01/03/2015 14:43:00;0008;PBS_Server;Job;46426.tyrone-cluster;Job rejected by all possible destinations (check syntax, queue resources, ...)
01/03/2015 14:43:00;0100;PBS_Server;Job;46426.tyrone-cluster;dequeuing from batch, state QUEUED
01/03/2015 14:43:00;0080;PBS_Server;Req;req_reject;Reject reply code=15041(Job rejected by all possible destinations (check syntax, queue resources, ...)), aux=0, type=Commit, from secparth@tyrone-cluster
01/03/2015 14:43:00;0040;PBS_Server;Svr;tyrone-cluster;Scheduler was sent the command term
01/03/2015 14:43:08;0040;PBS_Server;Svr;tyrone-cluster;Scheduler was sent the command new
01/03/2015 14:43:16;0100;PBS_Server;Job;46427.tyrone-cluster;enqueuing into batch, state 1 hop 1
01/03/2015 14:43:16;0100;PBS_Server;Job;46427.tyrone-cluster;dequeuing from batch, state QUEUED
01/03/2015 14:43:16;0100;PBS_Server;Job;46427.tyrone-cluster;enqueuing into idqueue, state 1 hop 1
01/03/2015 14:43:16;0008;PBS_Server;Job;46427.tyrone-cluster;Job Queued at request of secparth@tyrone-cluster, owner = secparth@tyrone-cluster, job name = JOB11, queue = idqueue
01/03/2015 14:43:16;0040;PBS_Server;Svr;tyrone-cluster;Scheduler was sent the command new
01/03/2015 14:43:16;0008;PBS_Server;Job;46427.tyrone-cluster;Job Modified at request of Scheduler@tyrone-cluster
01/03/2015 14:43:16;0008;PBS_Server;Job;46427.tyrone-cluster;Job Run at request of Scheduler@tyrone-cluster
01/03/2015 14:43:16;0040;PBS_Server;Svr;tyrone-cluster;Scheduler was sent the command recyc
01/03/2015 14:43:16;000d;PBS_Server;Job;46427.tyrone-cluster;Not sending email: User does not want mail of this type.
01/03/2015 14:43:16;000d;PBS_Server;Job;46427.tyrone-cluster;Not sending email: User does not want mail of this type.
01/03/2015 14:43:16;0010;PBS_Server;Job;46427.tyrone-cluster;Exit_status=255 resources_used.cput=00:00:00 resources_used.mem=0kb resources_used.vmem=0kb resources_used.walltime=00:00:00
01/03/2015 14:43:16;0008;PBS_Server;Job;NULL;on_job_exit valid pjob: 0x13f32e0 (substate=50)
01/03/2015 14:43:16;0008;PBS_Server;Job;NULL;on_job_exit valid pjob: 0x13f32e0 (substate=51)
01/03/2015 14:43:16;0008;PBS_Server;Job;NULL;on_job_exit valid pjob: 0x13f32e0 (substate=51)
01/03/2015 14:43:16;0008;PBS_Server;Job;NULL;on_job_exit valid pjob: 0x13f32e0 (substate=53)
01/03/2015 14:43:16;0100;PBS_Server;Job;46427.tyrone-cluster;dequeuing from idqueue, state COMPLETE
01/03/2015 14:43:16;0040;PBS_Server;Svr;tyrone-cluster;Scheduler was sent the command term
01/03/2015 14:43:39;0040;PBS_Server;Svr;tyrone-cluster;Scheduler was sent the command new
01/03/2015 14:44:09;0040;PBS_Server;Svr;tyrone-cluster;Scheduler was sent the command new
01/03/2015 14:44:32;0100;PBS_Server;Job;46428.tyrone-cluster;enqueuing into batch, state 1 hop 1
01/03/2015 14:44:32;0100;PBS_Server;Job;46428.tyrone-cluster;dequeuing from batch, state QUEUED
01/03/2015 14:44:32;0100;PBS_Server;Job;46428.tyrone-cluster;enqueuing into idqueue, state 1 hop 1
01/03/2015 14:44:32;0008;PBS_Server;Job;46428.tyrone-cluster;Job Queued at request of secparth@tyrone-cluster, owner = secparth@tyrone-cluster, job name = JOB11, queue = idqueue
01/03/2015 14:44:32;0040;PBS_Server;Svr;tyrone-cluster;Scheduler was sent the command new
01/03/2015 14:44:32;0008;PBS_Server;Job;46428.tyrone-cluster;Job Modified at request of Scheduler@tyrone-cluster
01/03/2015 14:44:32;0008;PBS_Server;Job;46428.tyrone-cluster;Job Run at request of Scheduler@tyrone-cluster
01/03/2015 14:44:32;0040;PBS_Server;Svr;tyrone-cluster;Scheduler was sent the command recyc
01/03/2015 14:44:32;000d;PBS_Server;Job;46428.tyrone-cluster;Not sending email: User does not want mail of this type.
01/03/2015 14:44:32;000d;PBS_Server;Job;46428.tyrone-cluster;Not sending email: User does not want mail of this type.
01/03/2015 14:44:32;0010;PBS_Server;Job;46428.tyrone-cluster;Exit_status=255 resources_used.cput=00:00:00 resources_used.mem=0kb resources_used.vmem=0kb resources_used.walltime=00:00:00
01/03/2015 14:44:32;0008;PBS_Server;Job;NULL;on_job_exit valid pjob: 0x1318cf0 (substate=50)
01/03/2015 14:44:32;0008;PBS_Server;Job;NULL;on_job_exit valid pjob: 0x1318cf0 (substate=51)
01/03/2015 14:44:33;0008;PBS_Server;Job;NULL;on_job_exit valid pjob: 0x1318cf0 (substate=51)
01/03/2015 14:44:33;0008;PBS_Server;Job;NULL;on_job_exit valid pjob: 0x1318cf0 (substate=53)
01/03/2015 14:44:33;0100;PBS_Server;Job;46428.tyrone-cluster;dequeuing from idqueue, state COMPLETE
01/03/2015 14:44:33;0040;PBS_Server;Svr;tyrone-cluster;Scheduler was sent the command term
01/03/2015 14:44:39;0040;PBS_Server;Svr;tyrone-cluster;Scheduler was sent the command new
01/03/2015 14:44:47;0002;PBS_Server;Svr;PBS_Server;Torque Server Version = 3.0.5, loglevel = 0
01/03/2015 14:45:09;0040;PBS_Server;Svr;tyrone-cluster;Scheduler was sent the command new
01/03/2015 14:45:39;0040;PBS_Server;Svr;tyrone-cluster;Scheduler was sent the command new
01/03/2015 14:45:55;0100;PBS_Server;Job;46429.tyrone-cluster;enqueuing into batch, state 1 hop 1
01/03/2015 14:45:55;0100;PBS_Server;Job;46429.tyrone-cluster;dequeuing from batch, state QUEUED
01/03/2015 14:45:55;0100;PBS_Server;Job;46429.tyrone-cluster;enqueuing into idqueue, state 1 hop 1
01/03/2015 14:45:55;0008;PBS_Server;Job;46429.tyrone-cluster;Job Queued at request of secparth@tyrone-cluster, owner = secparth@tyrone-cluster, job name = JOB11, queue = idqueue
01/03/2015 14:45:55;0040;PBS_Server;Svr;tyrone-cluster;Scheduler was sent the command new
01/03/2015 14:45:55;0008;PBS_Server;Job;46429.tyrone-cluster;Job Modified at request of Scheduler@tyrone-cluster
01/03/2015 14:45:55;0008;PBS_Server;Job;46429.tyrone-cluster;Job Run at request of Scheduler@tyrone-cluster
01/03/2015 14:45:55;000d;PBS_Server;Job;46429.tyrone-cluster;Not sending email: User does not want mail of this type.
01/03/2015 14:45:55;0040;PBS_Server;Svr;tyrone-cluster;Scheduler was sent the command recyc
01/03/2015 14:45:56;000d;PBS_Server;Job;46429.tyrone-cluster;Not sending email: User does not want mail of this type.
01/03/2015 14:45:56;0010;PBS_Server;Job;46429.tyrone-cluster;Exit_status=255 resources_used.cput=00:00:00 resources_used.mem=0kb resources_used.vmem=0kb resources_used.walltime=00:00:01
01/03/2015 14:45:56;0008;PBS_Server;Job;NULL;on_job_exit valid pjob: 0x1318890 (substate=50)
01/03/2015 14:45:56;0008;PBS_Server;Job;NULL;on_job_exit valid pjob: 0x1318890 (substate=51)
01/03/2015 14:45:56;0008;PBS_Server;Job;NULL;on_job_exit valid pjob: 0x1318890 (substate=51)
01/03/2015 14:45:56;0008;PBS_Server;Job;NULL;on_job_exit valid pjob: 0x1318890 (substate=53)
01/03/2015 14:45:56;0100;PBS_Server;Job;46429.tyrone-cluster;dequeuing from idqueue, state COMPLETE
01/03/2015 14:45:56;0040;PBS_Server;Svr;tyrone-cluster;Scheduler was sent the command term
01/03/2015 14:46:09;0040;PBS_Server;Svr;tyrone-cluster;Scheduler was sent the command new
01/03/2015 14:46:39;0040;PBS_Server;Svr;tyrone-cluster;Scheduler was sent the command new
01/03/2015 14:47:06;0100;PBS_Server;Job;46430.tyrone-cluster;enqueuing into batch, state 1 hop 1
01/03/2015 14:47:06;0100;PBS_Server;Job;46430.tyrone-cluster;dequeuing from batch, state QUEUED
01/03/2015 14:47:06;0100;PBS_Server;Job;46430.tyrone-cluster;enqueuing into idqueue, state 1 hop 1
01/03/2015 14:47:06;0008;PBS_Server;Job;46430.tyrone-cluster;Job Queued at request of secparth@tyrone-cluster, owner = secparth@tyrone-cluster, job name = JOB11, queue = idqueue
01/03/2015 14:47:06;0040;PBS_Server;Svr;tyrone-cluster;Scheduler was sent the command new
01/03/2015 14:47:06;0008;PBS_Server;Job;46430.tyrone-cluster;Job Modified at request of Scheduler@tyrone-cluster
01/03/2015 14:47:06;0008;PBS_Server;Job;46430.tyrone-cluster;Job Run at request of Scheduler@tyrone-cluster
01/03/2015 14:47:06;0040;PBS_Server;Svr;tyrone-cluster;Scheduler was sent the command recyc
01/03/2015 14:47:06;000d;PBS_Server;Job;46430.tyrone-cluster;Not sending email: User does not want mail of this type.
01/03/2015 14:47:06;000d;PBS_Server;Job;46430.tyrone-cluster;Not sending email: User does not want mail of this type.
01/03/2015 14:47:06;0010;PBS_Server;Job;46430.tyrone-cluster;Exit_status=255 resources_used.cput=00:00:00 resources_used.mem=0kb resources_used.vmem=0kb resources_used.walltime=00:00:00
01/03/2015 14:47:06;0008;PBS_Server;Job;NULL;on_job_exit valid pjob: 0x1318890 (substate=50)
01/03/2015 14:47:06;0008;PBS_Server;Job;NULL;on_job_exit valid pjob: 0x1318890 (substate=51)
01/03/2015 14:47:06;0008;PBS_Server;Job;NULL;on_job_exit valid pjob: 0x1318890 (substate=51)
01/03/2015 14:47:06;0008;PBS_Server;Job;NULL;on_job_exit valid pjob: 0x1318890 (substate=53)
01/03/2015 14:47:06;0100;PBS_Server;Job;46430.tyrone-cluster;dequeuing from idqueue, state COMPLETE
01/03/2015 14:47:06;0040;PBS_Server;Svr;tyrone-cluster;Scheduler was sent the command term
01/03/2015 14:47:09;0040;PBS_Server;Svr;tyrone-cluster;Scheduler was sent the command new
01/03/2015 14:47:40;0040;PBS_Server;Svr;tyrone-cluster;Scheduler was sent the command new
01/03/2015 14:48:10;0040;PBS_Server;Svr;tyrone-cluster;Scheduler was sent the command new
01/03/2015 14:48:40;0040;PBS_Server;Svr;tyrone-cluster;Scheduler was sent the command new
01/03/2015 14:49:10;0040;PBS_Server;Svr;tyrone-cluster;Scheduler was sent the command new
01/03/2015 14:49:40;0040;PBS_Server;Svr;tyrone-cluster;Scheduler was sent the command new
01/03/2015 14:49:47;0002;PBS_Server;Svr;PBS_Server;Torque Server Version = 3.0.5, loglevel = 0
01/03/2015 14:50:05;0100;PBS_Server;Job;46431.tyrone-cluster;enqueuing into batch, state 1 hop 1
01/03/2015 14:50:05;0100;PBS_Server;Job;46431.tyrone-cluster;dequeuing from batch, state QUEUED
01/03/2015 14:50:05;0100;PBS_Server;Job;46431.tyrone-cluster;enqueuing into idqueue, state 1 hop 1
01/03/2015 14:50:05;0008;PBS_Server;Job;46431.tyrone-cluster;Job Queued at request of secparth@tyrone-cluster, owner = secparth@tyrone-cluster, job name = JOB11, queue = idqueue
01/03/2015 14:50:05;0040;PBS_Server;Svr;tyrone-cluster;Scheduler was sent the command new
01/03/2015 14:50:05;0008;PBS_Server;Job;46431.tyrone-cluster;Job Modified at request of Scheduler@tyrone-cluster
01/03/2015 14:50:05;0008;PBS_Server;Job;46431.tyrone-cluster;Job Run at request of Scheduler@tyrone-cluster
01/03/2015 14:50:05;0040;PBS_Server;Svr;tyrone-cluster;Scheduler was sent the command recyc
01/03/2015 14:50:05;000d;PBS_Server;Job;46431.tyrone-cluster;Not sending email: User does not want mail of this type.
01/03/2015 14:50:10;0040;PBS_Server;Svr;tyrone-cluster;Scheduler was sent the command new
01/03/2015 14:50:37;000d;PBS_Server;Job;46431.tyrone-cluster;Not sending email: User does not want mail of this type.
01/03/2015 14:50:37;0010;PBS_Server;Job;46431.tyrone-cluster;Exit_status=0 resources_used.cput=00:00:00 resources_used.mem=9384kb resources_used.vmem=405880kb resources_used.walltime=00:00:32
01/03/2015 14:50:37;0008;PBS_Server;Job;NULL;on_job_exit valid pjob: 0x130d980 (substate=50)
01/03/2015 14:50:37;0008;PBS_Server;Job;NULL;on_job_exit valid pjob: 0x130d980 (substate=51)
01/03/2015 14:50:37;0008;PBS_Server;Job;NULL;on_job_exit valid pjob: 0x130d980 (substate=51)
01/03/2015 14:50:37;0008;PBS_Server;Job;NULL;on_job_exit valid pjob: 0x130d980 (substate=53)
01/03/2015 14:50:37;0100;PBS_Server;Job;46431.tyrone-cluster;dequeuing from idqueue, state COMPLETE
01/03/2015 14:50:37;0040;PBS_Server;Svr;tyrone-cluster;Scheduler was sent the command term
01/03/2015 14:50:40;0040;PBS_Server;Svr;tyrone-cluster;Scheduler was sent the command new
01/03/2015 14:51:11;0040;PBS_Server;Svr;tyrone-cluster;Scheduler was sent the command new
01/03/2015 14:51:41;0040;PBS_Server;Svr;tyrone-cluster;Scheduler was sent the command new
01/03/2015 14:52:11;0040;PBS_Server;Svr;tyrone-cluster;Scheduler was sent the command new
01/03/2015 14:52:41;0040;PBS_Server;Svr;tyrone-cluster;Scheduler was sent the command new
01/03/2015 14:53:11;0040;PBS_Server;Svr;tyrone-cluster;Scheduler was sent the command new
01/03/2015 14:53:41;0040;PBS_Server;Svr;tyrone-cluster;Scheduler was sent the command new
01/03/2015 14:54:11;0040;PBS_Server;Svr;tyrone-cluster;Scheduler was sent the command new
01/03/2015 14:54:41;0040;PBS_Server;Svr;tyrone-cluster;Scheduler was sent the command new
01/03/2015 14:54:47;0002;PBS_Server;Svr;PBS_Server;Torque Server Version = 3.0.5, loglevel = 0
01/03/2015 14:55:11;0040;PBS_Server;Svr;tyrone-cluster;Scheduler was sent the command new
01/03/2015 14:55:42;0040;PBS_Server;Svr;tyrone-cluster;Scheduler was sent the command new
01/03/2015 14:56:12;0040;PBS_Server;Svr;tyrone-cluster;Scheduler was sent the command new
01/03/2015 14:56:42;0040;PBS_Server;Svr;tyrone-cluster;Scheduler was sent the command new
01/03/2015 14:57:12;0040;PBS_Server;Svr;tyrone-cluster;Scheduler was sent the command new
01/03/2015 14:57:42;0040;PBS_Server;Svr;tyrone-cluster;Scheduler was sent the command new
01/03/2015 14:58:12;0040;PBS_Server;Svr;tyrone-cluster;Scheduler was sent the command new
01/03/2015 14:58:42;0040;PBS_Server;Svr;tyrone-cluster;Scheduler was sent the command new
01/03/2015 14:59:12;0040;PBS_Server;Svr;tyrone-cluster;Scheduler was sent the command new
01/03/2015 14:59:42;0040;PBS_Server;Svr;tyrone-cluster;Scheduler was sent the command new
01/03/2015 14:59:47;0002;PBS_Server;Svr;PBS_Server;Torque Server Version = 3.0.5, loglevel = 0
01/03/2015 15:00:12;0040;PBS_Server;Svr;tyrone-cluster;Scheduler was sent the command new
01/03/2015 15:00:43;0040;PBS_Server;Svr;tyrone-cluster;Scheduler was sent the command new
01/03/2015 15:01:13;0040;PBS_Server;Svr;tyrone-cluster;Scheduler was sent the command new
01/03/2015 15:01:43;0040;PBS_Server;Svr;tyrone-cluster;Scheduler was sent the command new
01/03/2015 15:02:13;0040;PBS_Server;Svr;tyrone-cluster;Scheduler was sent the command new
01/03/2015 15:02:43;0040;PBS_Server;Svr;tyrone-cluster;Scheduler was sent the command new
01/03/2015 15:03:13;0040;PBS_Server;Svr;tyrone-cluster;Scheduler was sent the command new
01/03/2015 15:03:43;0040;PBS_Server;Svr;tyrone-cluster;Scheduler was sent the command new
01/03/2015 15:04:13;0040;PBS_Server;Svr;tyrone-cluster;Scheduler was sent the command new
01/03/2015 15:04:43;0040;PBS_Server;Svr;tyrone-cluster;Scheduler was sent the command new
01/03/2015 15:04:47;0002;PBS_Server;Svr;PBS_Server;Torque Server Version = 3.0.5, loglevel = 0
01/03/2015 15:05:14;0040;PBS_Server;Svr;tyrone-cluster;Scheduler was sent the command new
01/03/2015 15:05:43;0040;PBS_Server;Svr;tyrone-cluster;Scheduler was sent the command new
01/03/2015 15:06:13;0040;PBS_Server;Svr;tyrone-cluster;Scheduler was sent the command new
01/03/2015 15:06:44;0040;PBS_Server;Svr;tyrone-cluster;Scheduler was sent the command new
01/03/2015 15:07:14;0040;PBS_Server;Svr;tyrone-cluster;Scheduler was sent the command new
01/03/2015 15:07:43;0040;PBS_Server;Svr;tyrone-cluster;Scheduler was sent the command new
01/03/2015 15:08:13;0040;PBS_Server;Svr;tyrone-cluster;Scheduler was sent the command new
01/03/2015 15:08:44;0040;PBS_Server;Svr;tyrone-cluster;Scheduler was sent the command new
01/03/2015 15:09:13;0040;PBS_Server;Svr;tyrone-cluster;Scheduler was sent the command new
01/03/2015 15:09:44;0040;PBS_Server;Svr;tyrone-cluster;Scheduler was sent the command new
01/03/2015 15:09:47;0002;PBS_Server;Svr;PBS_Server;Torque Server Version = 3.0.5, loglevel = 0
01/03/2015 15:10:15;0040;PBS_Server;Svr;tyrone-cluster;Scheduler was sent the command new
01/03/2015 15:10:45;0040;PBS_Server;Svr;tyrone-cluster;Scheduler was sent the command new
01/03/2015 15:11:15;0040;PBS_Server;Svr;tyrone-cluster;Scheduler was sent the command new
01/03/2015 15:11:45;0040;PBS_Server;Svr;tyrone-cluster;Scheduler was sent the command new
01/03/2015 15:12:16;0040;PBS_Server;Svr;tyrone-cluster;Scheduler was sent the command new
01/03/2015 15:12:46;0040;PBS_Server;Svr;tyrone-cluster;Scheduler was sent the command new
01/03/2015 15:13:06;0100;PBS_Server;Job;46432.tyrone-cluster;enqueuing into batch, state 1 hop 1
01/03/2015 15:13:07;0100;PBS_Server;Job;46432.tyrone-cluster;dequeuing from batch, state QUEUED
01/03/2015 15:13:07;0100;PBS_Server;Job;46432.tyrone-cluster;enqueuing into idqueue, state 1 hop 1
01/03/2015 15:13:07;0008;PBS_Server;Job;46432.tyrone-cluster;Job Queued at request of secparth@tyrone-cluster, owner = secparth@tyrone-cluster, job name = JOB11, queue = idqueue
01/03/2015 15:13:07;0040;PBS_Server;Svr;tyrone-cluster;Scheduler was sent the command new
01/03/2015 15:13:07;0008;PBS_Server;Job;46432.tyrone-cluster;Job Modified at request of Scheduler@tyrone-cluster
01/03/2015 15:13:07;0008;PBS_Server;Job;46432.tyrone-cluster;Job Run at request of Scheduler@tyrone-cluster
01/03/2015 15:13:07;0040;PBS_Server;Svr;tyrone-cluster;Scheduler was sent the command recyc
01/03/2015 15:13:07;000d;PBS_Server;Job;46432.tyrone-cluster;Not sending email: User does not want mail of this type.
01/03/2015 15:13:08;000d;PBS_Server;Job;46432.tyrone-cluster;Not sending email: User does not want mail of this type.
01/03/2015 15:13:08;0010;PBS_Server;Job;46432.tyrone-cluster;Exit_status=0 resources_used.cput=00:00:00 resources_used.mem=0kb resources_used.vmem=0kb resources_used.walltime=00:00:01
01/03/2015 15:13:08;0008;PBS_Server;Job;NULL;on_job_exit valid pjob: 0x1318890 (substate=50)
01/03/2015 15:13:08;0008;PBS_Server;Job;NULL;on_job_exit valid pjob: 0x1318890 (substate=51)
01/03/2015 15:13:08;0008;PBS_Server;Job;NULL;on_job_exit valid pjob: 0x1318890 (substate=51)
01/03/2015 15:13:08;0008;PBS_Server;Job;NULL;on_job_exit valid pjob: 0x1318890 (substate=53)
01/03/2015 15:13:08;0100;PBS_Server;Job;46432.tyrone-cluster;dequeuing from idqueue, state COMPLETE
01/03/2015 15:13:08;0040;PBS_Server;Svr;tyrone-cluster;Scheduler was sent the command term
01/03/2015 15:13:16;0040;PBS_Server;Svr;tyrone-cluster;Scheduler was sent the command new
01/03/2015 15:13:46;0040;PBS_Server;Svr;tyrone-cluster;Scheduler was sent the command new
01/03/2015 15:14:16;0040;PBS_Server;Svr;tyrone-cluster;Scheduler was sent the command new
01/03/2015 15:14:46;0040;PBS_Server;Svr;tyrone-cluster;Scheduler was sent the command new
01/03/2015 15:14:47;0002;PBS_Server;Svr;PBS_Server;Torque Server Version = 3.0.5, loglevel = 0
01/03/2015 15:14:49;0100;PBS_Server;Job;46433.tyrone-cluster;enqueuing into batch, state 1 hop 1
01/03/2015 15:14:49;0008;PBS_Server;Job;46433.tyrone-cluster;Job rejected by all possible destinations (check syntax, queue resources, ...)
01/03/2015 15:14:49;0100;PBS_Server;Job;46433.tyrone-cluster;dequeuing from batch, state QUEUED
01/03/2015 15:14:49;0080;PBS_Server;Req;req_reject;Reject reply code=15041(Job rejected by all possible destinations (check syntax, queue resources, ...)), aux=0, type=Commit, from secparth@tyrone-cluster
01/03/2015 15:14:49;0040;PBS_Server;Svr;tyrone-cluster;Scheduler was sent the command term
01/03/2015 15:15:16;0040;PBS_Server;Svr;tyrone-cluster;Scheduler was sent the command new
01/03/2015 15:15:46;0040;PBS_Server;Svr;tyrone-cluster;Scheduler was sent the command new
01/03/2015 15:16:17;0040;PBS_Server;Svr;tyrone-cluster;Scheduler was sent the command new
01/03/2015 15:16:47;0040;PBS_Server;Svr;tyrone-cluster;Scheduler was sent the command new
01/03/2015 15:17:17;0040;PBS_Server;Svr;tyrone-cluster;Scheduler was sent the command new
01/03/2015 15:17:47;0040;PBS_Server;Svr;tyrone-cluster;Scheduler was sent the command new
01/03/2015 15:18:17;0040;PBS_Server;Svr;tyrone-cluster;Scheduler was sent the command new
01/03/2015 15:18:25;0100;PBS_Server;Job;46434.tyrone-cluster;enqueuing into batch, state 1 hop 1
01/03/2015 15:18:25;0100;PBS_Server;Job;46434.tyrone-cluster;dequeuing from batch, state QUEUED
01/03/2015 15:18:25;0100;PBS_Server;Job;46434.tyrone-cluster;enqueuing into idqueue, state 1 hop 1
01/03/2015 15:18:25;0008;PBS_Server;Job;46434.tyrone-cluster;Job Queued at request of secparth@tyrone-cluster, owner = secparth@tyrone-cluster, job name = JOB11, queue = idqueue
01/03/2015 15:18:25;0040;PBS_Server;Svr;tyrone-cluster;Scheduler was sent the command new
01/03/2015 15:18:25;0008;PBS_Server;Job;46434.tyrone-cluster;Job Modified at request of Scheduler@tyrone-cluster
01/03/2015 15:18:47;0040;PBS_Server;Svr;tyrone-cluster;Scheduler was sent the command new
01/03/2015 15:19:11;0100;PBS_Server;Job;46435.tyrone-cluster;enqueuing into batch, state 1 hop 1
01/03/2015 15:19:11;0100;PBS_Server;Job;46435.tyrone-cluster;dequeuing from batch, state QUEUED
01/03/2015 15:19:11;0100;PBS_Server;Job;46435.tyrone-cluster;enqueuing into idqueue, state 1 hop 1
01/03/2015 15:19:11;0008;PBS_Server;Job;46435.tyrone-cluster;Job Queued at request of secparth@tyrone-cluster, owner = secparth@tyrone-cluster, job name = JOB11, queue = idqueue
01/03/2015 15:19:11;0040;PBS_Server;Svr;tyrone-cluster;Scheduler was sent the command new
01/03/2015 15:19:11;0008;PBS_Server;Job;46435.tyrone-cluster;Job Modified at request of Scheduler@tyrone-cluster
01/03/2015 15:19:17;0040;PBS_Server;Svr;tyrone-cluster;Scheduler was sent the command new
01/03/2015 15:19:44;0008;PBS_Server;Job;46434.tyrone-cluster;Job deleted at request of secparth@tyrone-cluster
01/03/2015 15:19:44;0008;PBS_Server;Job;NULL;on_job_exit valid pjob: 0x1318cf0 (substate=59)
01/03/2015 15:19:44;0100;PBS_Server;Job;46434.tyrone-cluster;dequeuing from idqueue, state COMPLETE
01/03/2015 15:19:44;0040;PBS_Server;Svr;tyrone-cluster;Scheduler was sent the command term
01/03/2015 15:19:47;0002;PBS_Server;Svr;PBS_Server;Torque Server Version = 3.0.5, loglevel = 0
01/03/2015 15:19:47;0008;PBS_Server;Job;46435.tyrone-cluster;Job deleted at request of secparth@tyrone-cluster
01/03/2015 15:19:47;0008;PBS_Server;Job;NULL;on_job_exit valid pjob: 0x131d190 (substate=59)
01/03/2015 15:19:47;0100;PBS_Server;Job;46435.tyrone-cluster;dequeuing from idqueue, state COMPLETE
01/03/2015 15:19:47;0040;PBS_Server;Svr;tyrone-cluster;Scheduler was sent the command term
01/03/2015 15:20:18;0040;PBS_Server;Svr;tyrone-cluster;Scheduler was sent the command new
01/03/2015 15:20:42;0100;PBS_Server;Job;46436.tyrone-cluster;enqueuing into batch, state 1 hop 1
01/03/2015 15:20:42;0100;PBS_Server;Job;46436.tyrone-cluster;dequeuing from batch, state QUEUED
01/03/2015 15:20:42;0100;PBS_Server;Job;46436.tyrone-cluster;enqueuing into idqueue, state 1 hop 1
01/03/2015 15:20:42;0008;PBS_Server;Job;46436.tyrone-cluster;Job Queued at request of secparth@tyrone-cluster, owner = secparth@tyrone-cluster, job name = JOB11, queue = idqueue
01/03/2015 15:20:42;0040;PBS_Server;Svr;tyrone-cluster;Scheduler was sent the command new
01/03/2015 15:20:42;0008;PBS_Server;Job;46436.tyrone-cluster;Job Modified at request of Scheduler@tyrone-cluster
01/03/2015 15:20:48;0040;PBS_Server;Svr;tyrone-cluster;Scheduler was sent the command new
01/03/2015 15:21:18;0040;PBS_Server;Svr;tyrone-cluster;Scheduler was sent the command new
01/03/2015 15:21:48;0040;PBS_Server;Svr;tyrone-cluster;Scheduler was sent the command new
01/03/2015 15:21:55;0008;PBS_Server;Job;46436.tyrone-cluster;Job deleted at request of secparth@tyrone-cluster
01/03/2015 15:21:55;0008;PBS_Server;Job;NULL;on_job_exit valid pjob: 0x13f32e0 (substate=59)
01/03/2015 15:21:55;0100;PBS_Server;Job;46436.tyrone-cluster;dequeuing from idqueue, state COMPLETE
01/03/2015 15:21:55;0040;PBS_Server;Svr;tyrone-cluster;Scheduler was sent the command term
01/03/2015 15:22:01;0100;PBS_Server;Job;46437.tyrone-cluster;enqueuing into batch, state 1 hop 1
01/03/2015 15:22:01;0100;PBS_Server;Job;46437.tyrone-cluster;dequeuing from batch, state QUEUED
01/03/2015 15:22:01;0100;PBS_Server;Job;46437.tyrone-cluster;enqueuing into idqueue, state 1 hop 1
01/03/2015 15:22:01;0008;PBS_Server;Job;46437.tyrone-cluster;Job Queued at request of secparth@tyrone-cluster, owner = secparth@tyrone-cluster, job name = JOB11, queue = idqueue
01/03/2015 15:22:01;0040;PBS_Server;Svr;tyrone-cluster;Scheduler was sent the command new
01/03/2015 15:22:01;0008;PBS_Server;Job;46437.tyrone-cluster;Job Modified at request of Scheduler@tyrone-cluster
01/03/2015 15:22:01;0008;PBS_Server;Job;46437.tyrone-cluster;Job Run at request of Scheduler@tyrone-cluster
01/03/2015 15:22:01;0040;PBS_Server;Svr;tyrone-cluster;Scheduler was sent the command recyc
01/03/2015 15:22:01;000d;PBS_Server;Job;46437.tyrone-cluster;Not sending email: User does not want mail of this type.
01/03/2015 15:22:04;000d;PBS_Server;Job;46437.tyrone-cluster;Not sending email: User does not want mail of this type.
01/03/2015 15:22:04;0010;PBS_Server;Job;46437.tyrone-cluster;Exit_status=0 resources_used.cput=00:00:00 resources_used.mem=7156kb resources_used.vmem=305436kb resources_used.walltime=00:00:03
01/03/2015 15:22:04;0008;PBS_Server;Job;NULL;on_job_exit valid pjob: 0x130d980 (substate=50)
01/03/2015 15:22:04;0008;PBS_Server;Job;NULL;on_job_exit valid pjob: 0x130d980 (substate=51)
01/03/2015 15:22:04;0008;PBS_Server;Job;NULL;on_job_exit valid pjob: 0x130d980 (substate=51)
01/03/2015 15:22:04;0008;PBS_Server;Job;NULL;on_job_exit valid pjob: 0x130d980 (substate=53)
01/03/2015 15:22:04;0100;PBS_Server;Job;46437.tyrone-cluster;dequeuing from idqueue, state COMPLETE
01/03/2015 15:22:04;0040;PBS_Server;Svr;tyrone-cluster;Scheduler was sent the command term
01/03/2015 15:22:18;0040;PBS_Server;Svr;tyrone-cluster;Scheduler was sent the command new
01/03/2015 15:22:46;0100;PBS_Server;Job;46438.tyrone-cluster;enqueuing into batch, state 1 hop 1
01/03/2015 15:22:46;0100;PBS_Server;Job;46438.tyrone-cluster;dequeuing from batch, state QUEUED
01/03/2015 15:22:46;0100;PBS_Server;Job;46438.tyrone-cluster;enqueuing into idqueue, state 1 hop 1
01/03/2015 15:22:46;0008;PBS_Server;Job;46438.tyrone-cluster;Job Queued at request of secparth@tyrone-cluster, owner = secparth@tyrone-cluster, job name = JOB11, queue = idqueue
01/03/2015 15:22:46;0040;PBS_Server;Svr;tyrone-cluster;Scheduler was sent the command new
01/03/2015 15:22:46;0008;PBS_Server;Job;46438.tyrone-cluster;Job Modified at request of Scheduler@tyrone-cluster
01/03/2015 15:22:46;0008;PBS_Server;Job;46438.tyrone-cluster;Job Run at request of Scheduler@tyrone-cluster
01/03/2015 15:22:46;0040;PBS_Server;Svr;tyrone-cluster;Scheduler was sent the command recyc
01/03/2015 15:22:46;000d;PBS_Server;Job;46438.tyrone-cluster;Not sending email: User does not want mail of this type.
01/03/2015 15:22:48;0040;PBS_Server;Svr;tyrone-cluster;Scheduler was sent the command new
01/03/2015 15:22:48;000d;PBS_Server;Job;46438.tyrone-cluster;Not sending email: User does not want mail of this type.
01/03/2015 15:22:48;0010;PBS_Server;Job;46438.tyrone-cluster;Exit_status=0 resources_used.cput=00:00:00 resources_used.mem=8984kb resources_used.vmem=306524kb resources_used.walltime=00:00:02
01/03/2015 15:22:48;0008;PBS_Server;Job;NULL;on_job_exit valid pjob: 0x130d980 (substate=50)
01/03/2015 15:22:48;0008;PBS_Server;Job;NULL;on_job_exit valid pjob: 0x130d980 (substate=51)
01/03/2015 15:22:48;0008;PBS_Server;Job;NULL;on_job_exit valid pjob: 0x130d980 (substate=51)
01/03/2015 15:22:48;0008;PBS_Server;Job;NULL;on_job_exit valid pjob: 0x130d980 (substate=53)
01/03/2015 15:22:48;0100;PBS_Server;Job;46438.tyrone-cluster;dequeuing from idqueue, state COMPLETE
01/03/2015 15:22:48;0040;PBS_Server;Svr;tyrone-cluster;Scheduler was sent the command term
01/03/2015 15:23:18;0040;PBS_Server;Svr;tyrone-cluster;Scheduler was sent the command new
01/03/2015 15:23:49;0040;PBS_Server;Svr;tyrone-cluster;Scheduler was sent the command new
01/03/2015 15:24:18;0040;PBS_Server;Svr;tyrone-cluster;Scheduler was sent the command new
01/03/2015 15:24:47;0002;PBS_Server;Svr;PBS_Server;Torque Server Version = 3.0.5, loglevel = 0
01/03/2015 15:24:49;0040;PBS_Server;Svr;tyrone-cluster;Scheduler was sent the command new
01/03/2015 15:25:19;0040;PBS_Server;Svr;tyrone-cluster;Scheduler was sent the command new
01/03/2015 15:25:49;0040;PBS_Server;Svr;tyrone-cluster;Scheduler was sent the command new
01/03/2015 15:26:19;0040;PBS_Server;Svr;tyrone-cluster;Scheduler was sent the command new
01/03/2015 15:26:49;0040;PBS_Server;Svr;tyrone-cluster;Scheduler was sent the command new
01/03/2015 15:27:19;0040;PBS_Server;Svr;tyrone-cluster;Scheduler was sent the command new
01/03/2015 15:27:50;0040;PBS_Server;Svr;tyrone-cluster;Scheduler was sent the command new
01/03/2015 15:28:20;0040;PBS_Server;Svr;tyrone-cluster;Scheduler was sent the command new
01/03/2015 15:28:50;0040;PBS_Server;Svr;tyrone-cluster;Scheduler was sent the command new
01/03/2015 15:29:20;0040;PBS_Server;Svr;tyrone-cluster;Scheduler was sent the command new
01/03/2015 15:29:47;0002;PBS_Server;Svr;PBS_Server;Torque Server Version = 3.0.5, loglevel = 0
01/03/2015 15:29:50;0040;PBS_Server;Svr;tyrone-cluster;Scheduler was sent the command new
01/03/2015 15:30:20;0040;PBS_Server;Svr;tyrone-cluster;Scheduler was sent the command new
01/03/2015 15:30:50;0040;PBS_Server;Svr;tyrone-cluster;Scheduler was sent the command new
01/03/2015 15:31:20;0040;PBS_Server;Svr;tyrone-cluster;Scheduler was sent the command new
01/03/2015 15:31:51;0040;PBS_Server;Svr;tyrone-cluster;Scheduler was sent the command new
01/03/2015 15:32:21;0040;PBS_Server;Svr;tyrone-cluster;Scheduler was sent the command new
01/03/2015 15:32:51;0040;PBS_Server;Svr;tyrone-cluster;Scheduler was sent the command new
01/03/2015 15:33:21;0040;PBS_Server;Svr;tyrone-cluster;Scheduler was sent the command new
01/03/2015 15:33:51;0040;PBS_Server;Svr;tyrone-cluster;Scheduler was sent the command new
01/03/2015 15:34:21;0040;PBS_Server;Svr;tyrone-cluster;Scheduler was sent the command new
01/03/2015 15:34:47;0002;PBS_Server;Svr;PBS_Server;Torque Server Version = 3.0.5, loglevel = 0
01/03/2015 15:34:52;0040;PBS_Server;Svr;tyrone-cluster;Scheduler was sent the command new
01/03/2015 15:35:21;0040;PBS_Server;Svr;tyrone-cluster;Scheduler was sent the command new
01/03/2015 15:35:52;0040;PBS_Server;Svr;tyrone-cluster;Scheduler was sent the command new
01/03/2015 15:36:22;0040;PBS_Server;Svr;tyrone-cluster;Scheduler was sent the command new
01/03/2015 15:36:52;0040;PBS_Server;Svr;tyrone-cluster;Scheduler was sent the command new
01/03/2015 15:37:22;0040;PBS_Server;Svr;tyrone-cluster;Scheduler was sent the command new
01/03/2015 15:37:52;0040;PBS_Server;Svr;tyrone-cluster;Scheduler was sent the command new
01/03/2015 15:38:22;0040;PBS_Server;Svr;tyrone-cluster;Scheduler was sent the command new
01/03/2015 15:38:53;0040;PBS_Server;Svr;tyrone-cluster;Scheduler was sent the command new
01/03/2015 15:39:23;0040;PBS_Server;Svr;tyrone-cluster;Scheduler was sent the command new
01/03/2015 15:39:47;0002;PBS_Server;Svr;PBS_Server;Torque Server Version = 3.0.5, loglevel = 0
01/03/2015 15:39:53;0040;PBS_Server;Svr;tyrone-cluster;Scheduler was sent the command new
01/03/2015 15:40:23;0040;PBS_Server;Svr;tyrone-cluster;Scheduler was sent the command new
01/03/2015 15:40:53;0040;PBS_Server;Svr;tyrone-cluster;Scheduler was sent the command new
01/03/2015 15:41:23;0040;PBS_Server;Svr;tyrone-cluster;Scheduler was sent the command new
01/03/2015 15:41:53;0040;PBS_Server;Svr;tyrone-cluster;Scheduler was sent the command new
01/03/2015 15:42:23;0040;PBS_Server;Svr;tyrone-cluster;Scheduler was sent the command new
01/03/2015 15:42:54;0040;PBS_Server;Svr;tyrone-cluster;Scheduler was sent the command new
01/03/2015 15:43:24;0040;PBS_Server;Svr;tyrone-cluster;Scheduler was sent the command new
01/03/2015 15:43:54;0040;PBS_Server;Svr;tyrone-cluster;Scheduler was sent the command new
01/03/2015 15:44:24;0040;PBS_Server;Svr;tyrone-cluster;Scheduler was sent the command new
01/03/2015 15:44:47;0002;PBS_Server;Svr;PBS_Server;Torque Server Version = 3.0.5, loglevel = 0
01/03/2015 15:44:54;0040;PBS_Server;Svr;tyrone-cluster;Scheduler was sent the command new
01/03/2015 15:45:24;0040;PBS_Server;Svr;tyrone-cluster;Scheduler was sent the command new
01/03/2015 15:45:54;0040;PBS_Server;Svr;tyrone-cluster;Scheduler was sent the command new
01/03/2015 15:46:24;0040;PBS_Server;Svr;tyrone-cluster;Scheduler was sent the command new
01/03/2015 15:46:54;0040;PBS_Server;Svr;tyrone-cluster;Scheduler was sent the command new
01/03/2015 15:47:25;0040;PBS_Server;Svr;tyrone-cluster;Scheduler was sent the command new
01/03/2015 15:47:55;0040;PBS_Server;Svr;tyrone-cluster;Scheduler was sent the command new
01/03/2015 15:48:25;0040;PBS_Server;Svr;tyrone-cluster;Scheduler was sent the command new
01/03/2015 15:48:55;0040;PBS_Server;Svr;tyrone-cluster;Scheduler was sent the command new
01/03/2015 15:49:25;0040;PBS_Server;Svr;tyrone-cluster;Scheduler was sent the command new
01/03/2015 15:49:47;0002;PBS_Server;Svr;PBS_Server;Torque Server Version = 3.0.5, loglevel = 0
01/03/2015 15:49:55;0040;PBS_Server;Svr;tyrone-cluster;Scheduler was sent the command new
01/03/2015 15:50:25;0040;PBS_Server;Svr;tyrone-cluster;Scheduler was sent the command new
01/03/2015 15:50:55;0040;PBS_Server;Svr;tyrone-cluster;Scheduler was sent the command new
01/03/2015 15:51:26;0040;PBS_Server;Svr;tyrone-cluster;Scheduler was sent the command new
01/03/2015 15:51:56;0040;PBS_Server;Svr;tyrone-cluster;Scheduler was sent the command new
01/03/2015 15:52:26;0040;PBS_Server;Svr;tyrone-cluster;Scheduler was sent the command new
01/03/2015 15:52:56;0040;PBS_Server;Svr;tyrone-cluster;Scheduler was sent the command new
01/03/2015 15:53:26;0040;PBS_Server;Svr;tyrone-cluster;Scheduler was sent the command new
01/03/2015 15:53:56;0040;PBS_Server;Svr;tyrone-cluster;Scheduler was sent the command new
01/03/2015 15:54:26;0040;PBS_Server;Svr;tyrone-cluster;Scheduler was sent the command new
01/03/2015 15:54:47;0002;PBS_Server;Svr;PBS_Server;Torque Server Version = 3.0.5, loglevel = 0
01/03/2015 15:54:56;0040;PBS_Server;Svr;tyrone-cluster;Scheduler was sent the command new
01/03/2015 15:55:26;0040;PBS_Server;Svr;tyrone-cluster;Scheduler was sent the command new
01/03/2015 15:55:56;0040;PBS_Server;Svr;tyrone-cluster;Scheduler was sent the command new
01/03/2015 15:56:27;0040;PBS_Server;Svr;tyrone-cluster;Scheduler was sent the command new
01/03/2015 15:56:57;0040;PBS_Server;Svr;tyrone-cluster;Scheduler was sent the command new
01/03/2015 15:57:27;0040;PBS_Server;Svr;tyrone-cluster;Scheduler was sent the command new
01/03/2015 15:57:57;0040;PBS_Server;Svr;tyrone-cluster;Scheduler was sent the command new
01/03/2015 15:58:27;0040;PBS_Server;Svr;tyrone-cluster;Scheduler was sent the command new
01/03/2015 15:58:57;0040;PBS_Server;Svr;tyrone-cluster;Scheduler was sent the command new
01/03/2015 15:59:27;0040;PBS_Server;Svr;tyrone-cluster;Scheduler was sent the command new
01/03/2015 15:59:47;0002;PBS_Server;Svr;PBS_Server;Torque Server Version = 3.0.5, loglevel = 0
01/03/2015 15:59:57;0040;PBS_Server;Svr;tyrone-cluster;Scheduler was sent the command new
01/03/2015 16:00:28;0040;PBS_Server;Svr;tyrone-cluster;Scheduler was sent the command new
01/03/2015 16:00:58;0040;PBS_Server;Svr;tyrone-cluster;Scheduler was sent the command new
01/03/2015 16:01:28;0040;PBS_Server;Svr;tyrone-cluster;Scheduler was sent the command new
01/03/2015 16:01:58;0040;PBS_Server;Svr;tyrone-cluster;Scheduler was sent the command new
01/03/2015 16:02:28;0040;PBS_Server;Svr;tyrone-cluster;Scheduler was sent the command new
01/03/2015 16:02:58;0040;PBS_Server;Svr;tyrone-cluster;Scheduler was sent the command new
01/03/2015 16:03:28;0040;PBS_Server;Svr;tyrone-cluster;Scheduler was sent the command new
01/03/2015 16:03:58;0040;PBS_Server;Svr;tyrone-cluster;Scheduler was sent the command new
01/03/2015 16:04:28;0040;PBS_Server;Svr;tyrone-cluster;Scheduler was sent the command new
01/03/2015 16:04:47;0002;PBS_Server;Svr;PBS_Server;Torque Server Version = 3.0.5, loglevel = 0
01/03/2015 16:04:58;0040;PBS_Server;Svr;tyrone-cluster;Scheduler was sent the command new
01/03/2015 16:05:10;0100;PBS_Server;Job;46439.tyrone-cluster;enqueuing into batch, state 1 hop 1
01/03/2015 16:05:10;0100;PBS_Server;Job;46439.tyrone-cluster;dequeuing from batch, state QUEUED
01/03/2015 16:05:10;0100;PBS_Server;Job;46439.tyrone-cluster;enqueuing into qp128, state 1 hop 1
01/03/2015 16:05:10;0008;PBS_Server;Job;46439.tyrone-cluster;Job Queued at request of asepk@tyrone-cluster, owner = asepk@tyrone-cluster, job name = DNsFlo_32, queue = qp128
01/03/2015 16:05:10;0040;PBS_Server;Svr;tyrone-cluster;Scheduler was sent the command new
01/03/2015 16:05:10;0008;PBS_Server;Job;46439.tyrone-cluster;Job Modified at request of Scheduler@tyrone-cluster
01/03/2015 16:05:28;0040;PBS_Server;Svr;tyrone-cluster;Scheduler was sent the command new
01/03/2015 16:05:58;0040;PBS_Server;Svr;tyrone-cluster;Scheduler was sent the command new
01/03/2015 16:06:29;0040;PBS_Server;Svr;tyrone-cluster;Scheduler was sent the command new
01/03/2015 16:06:58;0040;PBS_Server;Svr;tyrone-cluster;Scheduler was sent the command new
01/03/2015 16:07:29;0040;PBS_Server;Svr;tyrone-cluster;Scheduler was sent the command new
01/03/2015 16:07:59;0040;PBS_Server;Svr;tyrone-cluster;Scheduler was sent the command new
01/03/2015 16:08:29;0040;PBS_Server;Svr;tyrone-cluster;Scheduler was sent the command new
01/03/2015 16:08:59;0040;PBS_Server;Svr;tyrone-cluster;Scheduler was sent the command new
01/03/2015 16:09:29;0040;PBS_Server;Svr;tyrone-cluster;Scheduler was sent the command new
01/03/2015 16:09:47;0002;PBS_Server;Svr;PBS_Server;Torque Server Version = 3.0.5, loglevel = 0
01/03/2015 16:10:00;0040;PBS_Server;Svr;tyrone-cluster;Scheduler was sent the command new
01/03/2015 16:10:30;0040;PBS_Server;Svr;tyrone-cluster;Scheduler was sent the command new
01/03/2015 16:11:00;0040;PBS_Server;Svr;tyrone-cluster;Scheduler was sent the command new
01/03/2015 16:11:30;0040;PBS_Server;Svr;tyrone-cluster;Scheduler was sent the command new
01/03/2015 16:12:00;0040;PBS_Server;Svr;tyrone-cluster;Scheduler was sent the command new
01/03/2015 16:12:30;0040;PBS_Server;Svr;tyrone-cluster;Scheduler was sent the command new
01/03/2015 16:13:00;0040;PBS_Server;Svr;tyrone-cluster;Scheduler was sent the command new
01/03/2015 16:13:30;0040;PBS_Server;Svr;tyrone-cluster;Scheduler was sent the command new
01/03/2015 16:14:01;0040;PBS_Server;Svr;tyrone-cluster;Scheduler was sent the command new
01/03/2015 16:14:31;0040;PBS_Server;Svr;tyrone-cluster;Scheduler was sent the command new
01/03/2015 16:14:47;0002;PBS_Server;Svr;PBS_Server;Torque Server Version = 3.0.5, loglevel = 0
01/03/2015 16:15:01;0040;PBS_Server;Svr;tyrone-cluster;Scheduler was sent the command new
01/03/2015 16:15:31;0040;PBS_Server;Svr;tyrone-cluster;Scheduler was sent the command new
01/03/2015 16:16:01;0040;PBS_Server;Svr;tyrone-cluster;Scheduler was sent the command new
01/03/2015 16:16:31;0040;PBS_Server;Svr;tyrone-cluster;Scheduler was sent the command new
01/03/2015 16:17:01;0040;PBS_Server;Svr;tyrone-cluster;Scheduler was sent the command new
01/03/2015 16:17:31;0040;PBS_Server;Svr;tyrone-cluster;Scheduler was sent the command new
01/03/2015 16:18:01;0040;PBS_Server;Svr;tyrone-cluster;Scheduler was sent the command new
01/03/2015 16:18:31;0040;PBS_Server;Svr;tyrone-cluster;Scheduler was sent the command new
01/03/2015 16:19:01;0040;PBS_Server;Svr;tyrone-cluster;Scheduler was sent the command new
01/03/2015 16:19:32;0040;PBS_Server;Svr;tyrone-cluster;Scheduler was sent the command new
01/03/2015 16:19:47;0002;PBS_Server;Svr;PBS_Server;Torque Server Version = 3.0.5, loglevel = 0
01/03/2015 16:20:02;0040;PBS_Server;Svr;tyrone-cluster;Scheduler was sent the command new
01/03/2015 16:20:32;0040;PBS_Server;Svr;tyrone-cluster;Scheduler was sent the command new
01/03/2015 16:21:02;0040;PBS_Server;Svr;tyrone-cluster;Scheduler was sent the command new
01/03/2015 16:21:32;0040;PBS_Server;Svr;tyrone-cluster;Scheduler was sent the command new
01/03/2015 16:22:02;0040;PBS_Server;Svr;tyrone-cluster;Scheduler was sent the command new
01/03/2015 16:22:32;0040;PBS_Server;Svr;tyrone-cluster;Scheduler was sent the command new
01/03/2015 16:23:02;0040;PBS_Server;Svr;tyrone-cluster;Scheduler was sent the command new
01/03/2015 16:23:32;0040;PBS_Server;Svr;tyrone-cluster;Scheduler was sent the command new
01/03/2015 16:24:03;0040;PBS_Server;Svr;tyrone-cluster;Scheduler was sent the command new
01/03/2015 16:24:32;0040;PBS_Server;Svr;tyrone-cluster;Scheduler was sent the command new
01/03/2015 16:24:47;0002;PBS_Server;Svr;PBS_Server;Torque Server Version = 3.0.5, loglevel = 0
01/03/2015 16:25:02;0040;PBS_Server;Svr;tyrone-cluster;Scheduler was sent the command new
01/03/2015 16:25:32;0040;PBS_Server;Svr;tyrone-cluster;Scheduler was sent the command new
01/03/2015 16:26:02;0040;PBS_Server;Svr;tyrone-cluster;Scheduler was sent the command new
01/03/2015 16:26:32;0040;PBS_Server;Svr;tyrone-cluster;Scheduler was sent the command new
01/03/2015 16:27:03;0040;PBS_Server;Svr;tyrone-cluster;Scheduler was sent the command new
01/03/2015 16:27:32;0040;PBS_Server;Svr;tyrone-cluster;Scheduler was sent the command new
01/03/2015 16:28:02;0040;PBS_Server;Svr;tyrone-cluster;Scheduler was sent the command new
01/03/2015 16:28:32;0040;PBS_Server;Svr;tyrone-cluster;Scheduler was sent the command new
01/03/2015 16:29:02;0040;PBS_Server;Svr;tyrone-cluster;Scheduler was sent the command new
01/03/2015 16:29:32;0040;PBS_Server;Svr;tyrone-cluster;Scheduler was sent the command new
01/03/2015 16:29:47;0002;PBS_Server;Svr;PBS_Server;Torque Server Version = 3.0.5, loglevel = 0
01/03/2015 16:30:04;0040;PBS_Server;Svr;tyrone-cluster;Scheduler was sent the command new
01/03/2015 16:30:32;0040;PBS_Server;Svr;tyrone-cluster;Scheduler was sent the command new
01/03/2015 16:31:02;0040;PBS_Server;Svr;tyrone-cluster;Scheduler was sent the command new
01/03/2015 16:31:33;0040;PBS_Server;Svr;tyrone-cluster;Scheduler was sent the command new
01/03/2015 16:32:02;0040;PBS_Server;Svr;tyrone-cluster;Scheduler was sent the command new
01/03/2015 16:32:32;0040;PBS_Server;Svr;tyrone-cluster;Scheduler was sent the command new
01/03/2015 16:33:02;0040;PBS_Server;Svr;tyrone-cluster;Scheduler was sent the command new
01/03/2015 16:33:32;0040;PBS_Server;Svr;tyrone-cluster;Scheduler was sent the command new
01/03/2015 16:34:02;0040;PBS_Server;Svr;tyrone-cluster;Scheduler was sent the command new
01/03/2015 16:34:32;0040;PBS_Server;Svr;tyrone-cluster;Scheduler was sent the command new
01/03/2015 16:34:47;0002;PBS_Server;Svr;PBS_Server;Torque Server Version = 3.0.5, loglevel = 0
01/03/2015 16:35:02;0040;PBS_Server;Svr;tyrone-cluster;Scheduler was sent the command new
01/03/2015 16:35:32;0040;PBS_Server;Svr;tyrone-cluster;Scheduler was sent the command new
01/03/2015 16:36:02;0040;PBS_Server;Svr;tyrone-cluster;Scheduler was sent the command new
01/03/2015 16:36:32;0040;PBS_Server;Svr;tyrone-cluster;Scheduler was sent the command new
01/03/2015 16:37:03;0040;PBS_Server;Svr;tyrone-cluster;Scheduler was sent the command new
01/03/2015 16:37:36;0040;PBS_Server;Svr;tyrone-cluster;Scheduler was sent the command new
01/03/2015 16:38:02;0040;PBS_Server;Svr;tyrone-cluster;Scheduler was sent the command new
01/03/2015 16:38:32;0040;PBS_Server;Svr;tyrone-cluster;Scheduler was sent the command new
01/03/2015 16:39:02;0040;PBS_Server;Svr;tyrone-cluster;Scheduler was sent the command new
01/03/2015 16:39:32;0040;PBS_Server;Svr;tyrone-cluster;Scheduler was sent the command new
01/03/2015 16:39:47;0002;PBS_Server;Svr;PBS_Server;Torque Server Version = 3.0.5, loglevel = 0
01/03/2015 16:40:02;0040;PBS_Server;Svr;tyrone-cluster;Scheduler was sent the command new
01/03/2015 16:40:32;0040;PBS_Server;Svr;tyrone-cluster;Scheduler was sent the command new
01/03/2015 16:41:02;0040;PBS_Server;Svr;tyrone-cluster;Scheduler was sent the command new
01/03/2015 16:41:32;0040;PBS_Server;Svr;tyrone-cluster;Scheduler was sent the command new
01/03/2015 16:42:02;0040;PBS_Server;Svr;tyrone-cluster;Scheduler was sent the command new
01/03/2015 16:42:32;0040;PBS_Server;Svr;tyrone-cluster;Scheduler was sent the command new
01/03/2015 16:43:02;0040;PBS_Server;Svr;tyrone-cluster;Scheduler was sent the command new
01/03/2015 16:43:35;0040;PBS_Server;Svr;tyrone-cluster;Scheduler was sent the command new
01/03/2015 16:44:03;0040;PBS_Server;Svr;tyrone-cluster;Scheduler was sent the command new
01/03/2015 16:44:35;0040;PBS_Server;Svr;tyrone-cluster;Scheduler was sent the command new
01/03/2015 16:44:47;0002;PBS_Server;Svr;PBS_Server;Torque Server Version = 3.0.5, loglevel = 0
01/03/2015 16:45:07;0040;PBS_Server;Svr;tyrone-cluster;Scheduler was sent the command new
01/03/2015 16:45:37;0040;PBS_Server;Svr;tyrone-cluster;Scheduler was sent the command new
01/03/2015 16:46:07;0040;PBS_Server;Svr;tyrone-cluster;Scheduler was sent the command new
01/03/2015 16:46:38;0040;PBS_Server;Svr;tyrone-cluster;Scheduler was sent the command new
01/03/2015 16:47:08;0040;PBS_Server;Svr;tyrone-cluster;Scheduler was sent the command new
01/03/2015 16:47:38;0040;PBS_Server;Svr;tyrone-cluster;Scheduler was sent the command new
01/03/2015 16:48:08;0040;PBS_Server;Svr;tyrone-cluster;Scheduler was sent the command new
01/03/2015 16:48:38;0040;PBS_Server;Svr;tyrone-cluster;Scheduler was sent the command new
01/03/2015 16:49:08;0040;PBS_Server;Svr;tyrone-cluster;Scheduler was sent the command new
01/03/2015 16:49:38;0040;PBS_Server;Svr;tyrone-cluster;Scheduler was sent the command new
01/03/2015 16:49:47;0002;PBS_Server;Svr;PBS_Server;Torque Server Version = 3.0.5, loglevel = 0
01/03/2015 16:50:08;0040;PBS_Server;Svr;tyrone-cluster;Scheduler was sent the command new
01/03/2015 16:50:38;0040;PBS_Server;Svr;tyrone-cluster;Scheduler was sent the command new
01/03/2015 16:51:09;0040;PBS_Server;Svr;tyrone-cluster;Scheduler was sent the command new
01/03/2015 16:51:38;0040;PBS_Server;Svr;tyrone-cluster;Scheduler was sent the command new
01/03/2015 16:52:09;0040;PBS_Server;Svr;tyrone-cluster;Scheduler was sent the command new
01/03/2015 16:52:39;0040;PBS_Server;Svr;tyrone-cluster;Scheduler was sent the command new
01/03/2015 16:53:09;0040;PBS_Server;Svr;tyrone-cluster;Scheduler was sent the command new
01/03/2015 16:53:39;0040;PBS_Server;Svr;tyrone-cluster;Scheduler was sent the command new
01/03/2015 16:54:09;0040;PBS_Server;Svr;tyrone-cluster;Scheduler was sent the command new
01/03/2015 16:54:39;0040;PBS_Server;Svr;tyrone-cluster;Scheduler was sent the command new
01/03/2015 16:54:47;0002;PBS_Server;Svr;PBS_Server;Torque Server Version = 3.0.5, loglevel = 0
01/03/2015 16:55:09;0040;PBS_Server;Svr;tyrone-cluster;Scheduler was sent the command new
01/03/2015 16:55:39;0040;PBS_Server;Svr;tyrone-cluster;Scheduler was sent the command new
01/03/2015 16:56:09;0040;PBS_Server;Svr;tyrone-cluster;Scheduler was sent the command new
01/03/2015 16:56:40;0040;PBS_Server;Svr;tyrone-cluster;Scheduler was sent the command new
01/03/2015 16:57:10;0040;PBS_Server;Svr;tyrone-cluster;Scheduler was sent the command new
01/03/2015 16:57:40;0040;PBS_Server;Svr;tyrone-cluster;Scheduler was sent the command new
01/03/2015 16:58:10;0040;PBS_Server;Svr;tyrone-cluster;Scheduler was sent the command new
01/03/2015 16:58:40;0040;PBS_Server;Svr;tyrone-cluster;Scheduler was sent the command new
01/03/2015 16:59:10;0040;PBS_Server;Svr;tyrone-cluster;Scheduler was sent the command new
01/03/2015 16:59:40;0040;PBS_Server;Svr;tyrone-cluster;Scheduler was sent the command new
01/03/2015 16:59:47;0002;PBS_Server;Svr;PBS_Server;Torque Server Version = 3.0.5, loglevel = 0
01/03/2015 17:00:11;0040;PBS_Server;Svr;tyrone-cluster;Scheduler was sent the command new
01/03/2015 17:00:41;0040;PBS_Server;Svr;tyrone-cluster;Scheduler was sent the command new
01/03/2015 17:01:11;0040;PBS_Server;Svr;tyrone-cluster;Scheduler was sent the command new
01/03/2015 17:01:41;0040;PBS_Server;Svr;tyrone-cluster;Scheduler was sent the command new
01/03/2015 17:02:11;0040;PBS_Server;Svr;tyrone-cluster;Scheduler was sent the command new
01/03/2015 17:02:41;0040;PBS_Server;Svr;tyrone-cluster;Scheduler was sent the command new
01/03/2015 17:03:11;0040;PBS_Server;Svr;tyrone-cluster;Scheduler was sent the command new
01/03/2015 17:03:41;0040;PBS_Server;Svr;tyrone-cluster;Scheduler was sent the command new
01/03/2015 17:04:11;0040;PBS_Server;Svr;tyrone-cluster;Scheduler was sent the command new
01/03/2015 17:04:42;0040;PBS_Server;Svr;tyrone-cluster;Scheduler was sent the command new
01/03/2015 17:04:47;0002;PBS_Server;Svr;PBS_Server;Torque Server Version = 3.0.5, loglevel = 0
01/03/2015 17:05:12;0040;PBS_Server;Svr;tyrone-cluster;Scheduler was sent the command new
01/03/2015 17:05:42;0040;PBS_Server;Svr;tyrone-cluster;Scheduler was sent the command new
01/03/2015 17:06:12;0040;PBS_Server;Svr;tyrone-cluster;Scheduler was sent the command new
01/03/2015 17:06:42;0040;PBS_Server;Svr;tyrone-cluster;Scheduler was sent the command new
01/03/2015 17:07:12;0040;PBS_Server;Svr;tyrone-cluster;Scheduler was sent the command new
01/03/2015 17:07:42;0040;PBS_Server;Svr;tyrone-cluster;Scheduler was sent the command new
01/03/2015 17:08:12;0040;PBS_Server;Svr;tyrone-cluster;Scheduler was sent the command new
01/03/2015 17:08:42;0040;PBS_Server;Svr;tyrone-cluster;Scheduler was sent the command new
01/03/2015 17:09:12;0040;PBS_Server;Svr;tyrone-cluster;Scheduler was sent the command new
01/03/2015 17:09:23;000d;PBS_Server;Job;46373.tyrone-cluster;Not sending email: User does not want mail of this type.
01/03/2015 17:09:23;0010;PBS_Server;Job;46373.tyrone-cluster;Exit_status=143 resources_used.cput=767:52:47 resources_used.mem=1057560kb resources_used.vmem=8568128kb resources_used.walltime=24:00:40
01/03/2015 17:09:23;0008;PBS_Server;Job;NULL;on_job_exit valid pjob: 0x1417520 (substate=50)
01/03/2015 17:09:23;0008;PBS_Server;Job;NULL;on_job_exit valid pjob: 0x1417520 (substate=51)
01/03/2015 17:09:23;0008;PBS_Server;Job;NULL;on_job_exit valid pjob: 0x1417520 (substate=51)
01/03/2015 17:09:23;0008;PBS_Server;Job;NULL;on_job_exit valid pjob: 0x1417520 (substate=53)
01/03/2015 17:09:23;0100;PBS_Server;Job;46373.tyrone-cluster;dequeuing from qp32, state COMPLETE
01/03/2015 17:09:23;0040;PBS_Server;Svr;tyrone-cluster;Scheduler was sent the command term
01/03/2015 17:09:23;0008;PBS_Server;Job;46407.tyrone-cluster;Job Modified at request of Scheduler@tyrone-cluster
01/03/2015 17:09:23;0008;PBS_Server;Job;46407.tyrone-cluster;Job Run at request of Scheduler@tyrone-cluster
01/03/2015 17:09:23;0040;PBS_Server;Svr;tyrone-cluster;Scheduler was sent the command recyc
01/03/2015 17:09:23;000d;PBS_Server;Job;46407.tyrone-cluster;Not sending email: User does not want mail of this type.
01/03/2015 17:09:42;0040;PBS_Server;Svr;tyrone-cluster;Scheduler was sent the command new
01/03/2015 17:09:47;0002;PBS_Server;Svr;PBS_Server;Torque Server Version = 3.0.5, loglevel = 0
01/03/2015 17:10:13;0040;PBS_Server;Svr;tyrone-cluster;Scheduler was sent the command new
01/03/2015 17:10:43;0040;PBS_Server;Svr;tyrone-cluster;Scheduler was sent the command new
01/03/2015 17:11:13;0040;PBS_Server;Svr;tyrone-cluster;Scheduler was sent the command new
01/03/2015 17:11:43;0040;PBS_Server;Svr;tyrone-cluster;Scheduler was sent the command new
01/03/2015 17:12:13;0040;PBS_Server;Svr;tyrone-cluster;Scheduler was sent the command new
01/03/2015 17:12:43;0040;PBS_Server;Svr;tyrone-cluster;Scheduler was sent the command new
01/03/2015 17:13:13;0040;PBS_Server;Svr;tyrone-cluster;Scheduler was sent the command new
01/03/2015 17:13:43;0040;PBS_Server;Svr;tyrone-cluster;Scheduler was sent the command new
01/03/2015 17:14:14;0040;PBS_Server;Svr;tyrone-cluster;Scheduler was sent the command new
01/03/2015 17:14:44;0040;PBS_Server;Svr;tyrone-cluster;Scheduler was sent the command new
01/03/2015 17:14:47;0002;PBS_Server;Svr;PBS_Server;Torque Server Version = 3.0.5, loglevel = 0
01/03/2015 17:15:14;0040;PBS_Server;Svr;tyrone-cluster;Scheduler was sent the command new
01/03/2015 17:15:44;0040;PBS_Server;Svr;tyrone-cluster;Scheduler was sent the command new
01/03/2015 17:16:14;0040;PBS_Server;Svr;tyrone-cluster;Scheduler was sent the command new
01/03/2015 17:16:44;0040;PBS_Server;Svr;tyrone-cluster;Scheduler was sent the command new
01/03/2015 17:17:14;0040;PBS_Server;Svr;tyrone-cluster;Scheduler was sent the command new
01/03/2015 17:17:44;0040;PBS_Server;Svr;tyrone-cluster;Scheduler was sent the command new
01/03/2015 17:18:14;0040;PBS_Server;Svr;tyrone-cluster;Scheduler was sent the command new
01/03/2015 17:18:44;0040;PBS_Server;Svr;tyrone-cluster;Scheduler was sent the command new
01/03/2015 17:19:14;0040;PBS_Server;Svr;tyrone-cluster;Scheduler was sent the command new
01/03/2015 17:19:44;0040;PBS_Server;Svr;tyrone-cluster;Scheduler was sent the command new
01/03/2015 17:19:47;0002;PBS_Server;Svr;PBS_Server;Torque Server Version = 3.0.5, loglevel = 0
01/03/2015 17:20:15;0040;PBS_Server;Svr;tyrone-cluster;Scheduler was sent the command new
01/03/2015 17:20:45;0040;PBS_Server;Svr;tyrone-cluster;Scheduler was sent the command new
01/03/2015 17:21:15;0040;PBS_Server;Svr;tyrone-cluster;Scheduler was sent the command new
01/03/2015 17:21:45;0040;PBS_Server;Svr;tyrone-cluster;Scheduler was sent the command new
01/03/2015 17:22:16;0040;PBS_Server;Svr;tyrone-cluster;Scheduler was sent the command new
01/03/2015 17:22:46;0040;PBS_Server;Svr;tyrone-cluster;Scheduler was sent the command new
01/03/2015 17:23:16;0040;PBS_Server;Svr;tyrone-cluster;Scheduler was sent the command new
01/03/2015 17:23:46;0040;PBS_Server;Svr;tyrone-cluster;Scheduler was sent the command new
01/03/2015 17:24:16;0040;PBS_Server;Svr;tyrone-cluster;Scheduler was sent the command new
01/03/2015 17:24:46;0040;PBS_Server;Svr;tyrone-cluster;Scheduler was sent the command new
01/03/2015 17:24:47;0002;PBS_Server;Svr;PBS_Server;Torque Server Version = 3.0.5, loglevel = 0
01/03/2015 17:25:16;0040;PBS_Server;Svr;tyrone-cluster;Scheduler was sent the command new
01/03/2015 17:25:46;0040;PBS_Server;Svr;tyrone-cluster;Scheduler was sent the command new
01/03/2015 17:26:16;0040;PBS_Server;Svr;tyrone-cluster;Scheduler was sent the command new
01/03/2015 17:26:46;0040;PBS_Server;Svr;tyrone-cluster;Scheduler was sent the command new
01/03/2015 17:27:17;0040;PBS_Server;Svr;tyrone-cluster;Scheduler was sent the command new
01/03/2015 17:27:47;0040;PBS_Server;Svr;tyrone-cluster;Scheduler was sent the command new
01/03/2015 17:28:17;0040;PBS_Server;Svr;tyrone-cluster;Scheduler was sent the command new
01/03/2015 17:28:47;0040;PBS_Server;Svr;tyrone-cluster;Scheduler was sent the command new
01/03/2015 17:29:17;0040;PBS_Server;Svr;tyrone-cluster;Scheduler was sent the command new
01/03/2015 17:29:47;0002;PBS_Server;Svr;PBS_Server;Torque Server Version = 3.0.5, loglevel = 0
01/03/2015 17:29:47;0040;PBS_Server;Svr;tyrone-cluster;Scheduler was sent the command new
01/03/2015 17:30:17;0040;PBS_Server;Svr;tyrone-cluster;Scheduler was sent the command new
01/03/2015 17:30:47;0040;PBS_Server;Svr;tyrone-cluster;Scheduler was sent the command new
01/03/2015 17:31:18;0040;PBS_Server;Svr;tyrone-cluster;Scheduler was sent the command new
01/03/2015 17:31:48;0040;PBS_Server;Svr;tyrone-cluster;Scheduler was sent the command new
01/03/2015 17:32:18;0040;PBS_Server;Svr;tyrone-cluster;Scheduler was sent the command new
01/03/2015 17:32:48;0040;PBS_Server;Svr;tyrone-cluster;Scheduler was sent the command new
01/03/2015 17:33:18;0040;PBS_Server;Svr;tyrone-cluster;Scheduler was sent the command new
01/03/2015 17:33:48;0040;PBS_Server;Svr;tyrone-cluster;Scheduler was sent the command new
01/03/2015 17:34:18;0040;PBS_Server;Svr;tyrone-cluster;Scheduler was sent the command new
01/03/2015 17:34:47;0002;PBS_Server;Svr;PBS_Server;Torque Server Version = 3.0.5, loglevel = 0
01/03/2015 17:34:48;0040;PBS_Server;Svr;tyrone-cluster;Scheduler was sent the command new
01/03/2015 17:35:18;0040;PBS_Server;Svr;tyrone-cluster;Scheduler was sent the command new
01/03/2015 17:35:48;0040;PBS_Server;Svr;tyrone-cluster;Scheduler was sent the command new
01/03/2015 17:36:19;0040;PBS_Server;Svr;tyrone-cluster;Scheduler was sent the command new
01/03/2015 17:36:49;0040;PBS_Server;Svr;tyrone-cluster;Scheduler was sent the command new
01/03/2015 17:37:11;0008;PBS_Server;Job;46439.tyrone-cluster;Job deleted at request of asepk@tyrone-cluster
01/03/2015 17:37:11;0008;PBS_Server;Job;NULL;on_job_exit valid pjob: 0x13f32e0 (substate=59)
01/03/2015 17:37:11;0100;PBS_Server;Job;46439.tyrone-cluster;dequeuing from qp128, state COMPLETE
01/03/2015 17:37:11;0040;PBS_Server;Svr;tyrone-cluster;Scheduler was sent the command term
01/03/2015 17:37:19;0040;PBS_Server;Svr;tyrone-cluster;Scheduler was sent the command new
01/03/2015 17:37:49;0040;PBS_Server;Svr;tyrone-cluster;Scheduler was sent the command new
01/03/2015 17:38:19;0040;PBS_Server;Svr;tyrone-cluster;Scheduler was sent the command new
01/03/2015 17:38:49;0040;PBS_Server;Svr;tyrone-cluster;Scheduler was sent the command new
01/03/2015 17:39:19;0040;PBS_Server;Svr;tyrone-cluster;Scheduler was sent the command new
01/03/2015 17:39:23;0100;PBS_Server;Job;46440.tyrone-cluster;enqueuing into batch, state 1 hop 1
01/03/2015 17:39:23;0100;PBS_Server;Job;46440.tyrone-cluster;dequeuing from batch, state QUEUED
01/03/2015 17:39:23;0100;PBS_Server;Job;46440.tyrone-cluster;enqueuing into qp128, state 1 hop 1
01/03/2015 17:39:23;0008;PBS_Server;Job;46440.tyrone-cluster;Job Queued at request of asepk@tyrone-cluster, owner = asepk@tyrone-cluster, job name = DNsFlo_128, queue = qp128
01/03/2015 17:39:23;0040;PBS_Server;Svr;tyrone-cluster;Scheduler was sent the command new
01/03/2015 17:39:23;0008;PBS_Server;Job;46440.tyrone-cluster;Job Modified at request of Scheduler@tyrone-cluster
01/03/2015 17:39:47;0002;PBS_Server;Svr;PBS_Server;Torque Server Version = 3.0.5, loglevel = 0
01/03/2015 17:39:49;0040;PBS_Server;Svr;tyrone-cluster;Scheduler was sent the command new
01/03/2015 17:40:19;0040;PBS_Server;Svr;tyrone-cluster;Scheduler was sent the command new
01/03/2015 17:40:50;0040;PBS_Server;Svr;tyrone-cluster;Scheduler was sent the command new
01/03/2015 17:41:20;0040;PBS_Server;Svr;tyrone-cluster;Scheduler was sent the command new
01/03/2015 17:41:50;0040;PBS_Server;Svr;tyrone-cluster;Scheduler was sent the command new
01/03/2015 17:42:20;0040;PBS_Server;Svr;tyrone-cluster;Scheduler was sent the command new
01/03/2015 17:42:50;0040;PBS_Server;Svr;tyrone-cluster;Scheduler was sent the command new
01/03/2015 17:43:20;0040;PBS_Server;Svr;tyrone-cluster;Scheduler was sent the command new
01/03/2015 17:43:50;0040;PBS_Server;Svr;tyrone-cluster;Scheduler was sent the command new
01/03/2015 17:44:20;0040;PBS_Server;Svr;tyrone-cluster;Scheduler was sent the command new
01/03/2015 17:44:47;0002;PBS_Server;Svr;PBS_Server;Torque Server Version = 3.0.5, loglevel = 0
01/03/2015 17:44:50;0040;PBS_Server;Svr;tyrone-cluster;Scheduler was sent the command new
01/03/2015 17:45:20;0040;PBS_Server;Svr;tyrone-cluster;Scheduler was sent the command new
01/03/2015 17:45:50;0040;PBS_Server;Svr;tyrone-cluster;Scheduler was sent the command new
01/03/2015 17:46:21;0040;PBS_Server;Svr;tyrone-cluster;Scheduler was sent the command new
01/03/2015 17:46:51;0040;PBS_Server;Svr;tyrone-cluster;Scheduler was sent the command new
01/03/2015 17:47:21;0040;PBS_Server;Svr;tyrone-cluster;Scheduler was sent the command new
01/03/2015 17:47:51;0040;PBS_Server;Svr;tyrone-cluster;Scheduler was sent the command new
01/03/2015 17:48:21;0040;PBS_Server;Svr;tyrone-cluster;Scheduler was sent the command new
01/03/2015 17:48:51;0040;PBS_Server;Svr;tyrone-cluster;Scheduler was sent the command new
01/03/2015 17:49:21;0040;PBS_Server;Svr;tyrone-cluster;Scheduler was sent the command new
01/03/2015 17:49:47;0002;PBS_Server;Svr;PBS_Server;Torque Server Version = 3.0.5, loglevel = 0
01/03/2015 17:49:52;0040;PBS_Server;Svr;tyrone-cluster;Scheduler was sent the command new
01/03/2015 17:50:22;0040;PBS_Server;Svr;tyrone-cluster;Scheduler was sent the command new
01/03/2015 17:50:52;0040;PBS_Server;Svr;tyrone-cluster;Scheduler was sent the command new
01/03/2015 17:51:22;0040;PBS_Server;Svr;tyrone-cluster;Scheduler was sent the command new
01/03/2015 17:51:52;0040;PBS_Server;Svr;tyrone-cluster;Scheduler was sent the command new
01/03/2015 17:52:22;0040;PBS_Server;Svr;tyrone-cluster;Scheduler was sent the command new
01/03/2015 17:52:52;0040;PBS_Server;Svr;tyrone-cluster;Scheduler was sent the command new
01/03/2015 17:53:23;0040;PBS_Server;Svr;tyrone-cluster;Scheduler was sent the command new
01/03/2015 17:53:53;0040;PBS_Server;Svr;tyrone-cluster;Scheduler was sent the command new
01/03/2015 17:54:23;0040;PBS_Server;Svr;tyrone-cluster;Scheduler was sent the command new
01/03/2015 17:54:47;0002;PBS_Server;Svr;PBS_Server;Torque Server Version = 3.0.5, loglevel = 0
01/03/2015 17:54:53;0040;PBS_Server;Svr;tyrone-cluster;Scheduler was sent the command new
01/03/2015 17:55:23;0040;PBS_Server;Svr;tyrone-cluster;Scheduler was sent the command new
01/03/2015 17:55:53;0040;PBS_Server;Svr;tyrone-cluster;Scheduler was sent the command new
01/03/2015 17:56:23;0040;PBS_Server;Svr;tyrone-cluster;Scheduler was sent the command new
01/03/2015 17:56:53;0040;PBS_Server;Svr;tyrone-cluster;Scheduler was sent the command new
01/03/2015 17:57:23;0040;PBS_Server;Svr;tyrone-cluster;Scheduler was sent the command new
01/03/2015 17:57:54;0040;PBS_Server;Svr;tyrone-cluster;Scheduler was sent the command new
01/03/2015 17:58:24;0040;PBS_Server;Svr;tyrone-cluster;Scheduler was sent the command new
01/03/2015 17:58:54;0040;PBS_Server;Svr;tyrone-cluster;Scheduler was sent the command new
01/03/2015 17:59:24;0040;PBS_Server;Svr;tyrone-cluster;Scheduler was sent the command new
01/03/2015 17:59:47;0002;PBS_Server;Svr;PBS_Server;Torque Server Version = 3.0.5, loglevel = 0
01/03/2015 17:59:54;0040;PBS_Server;Svr;tyrone-cluster;Scheduler was sent the command new
01/03/2015 18:00:24;0040;PBS_Server;Svr;tyrone-cluster;Scheduler was sent the command new
01/03/2015 18:00:54;0040;PBS_Server;Svr;tyrone-cluster;Scheduler was sent the command new
01/03/2015 18:01:24;0040;PBS_Server;Svr;tyrone-cluster;Scheduler was sent the command new
01/03/2015 18:01:54;0040;PBS_Server;Svr;tyrone-cluster;Scheduler was sent the command new
01/03/2015 18:02:24;0040;PBS_Server;Svr;tyrone-cluster;Scheduler was sent the command new
01/03/2015 18:02:54;0040;PBS_Server;Svr;tyrone-cluster;Scheduler was sent the command new
01/03/2015 18:03:25;0040;PBS_Server;Svr;tyrone-cluster;Scheduler was sent the command new
01/03/2015 18:03:55;0040;PBS_Server;Svr;tyrone-cluster;Scheduler was sent the command new
01/03/2015 18:04:25;0040;PBS_Server;Svr;tyrone-cluster;Scheduler was sent the command new
01/03/2015 18:04:47;0002;PBS_Server;Svr;PBS_Server;Torque Server Version = 3.0.5, loglevel = 0
01/03/2015 18:04:55;0040;PBS_Server;Svr;tyrone-cluster;Scheduler was sent the command new
01/03/2015 18:05:25;0040;PBS_Server;Svr;tyrone-cluster;Scheduler was sent the command new
01/03/2015 18:05:55;0040;PBS_Server;Svr;tyrone-cluster;Scheduler was sent the command new
01/03/2015 18:06:26;0040;PBS_Server;Svr;tyrone-cluster;Scheduler was sent the command new
01/03/2015 18:06:56;0040;PBS_Server;Svr;tyrone-cluster;Scheduler was sent the command new
01/03/2015 18:07:26;0040;PBS_Server;Svr;tyrone-cluster;Scheduler was sent the command new
01/03/2015 18:07:56;0040;PBS_Server;Svr;tyrone-cluster;Scheduler was sent the command new
01/03/2015 18:08:26;0040;PBS_Server;Svr;tyrone-cluster;Scheduler was sent the command new
01/03/2015 18:08:56;0040;PBS_Server;Svr;tyrone-cluster;Scheduler was sent the command new
01/03/2015 18:09:26;0040;PBS_Server;Svr;tyrone-cluster;Scheduler was sent the command new
01/03/2015 18:09:47;0002;PBS_Server;Svr;PBS_Server;Torque Server Version = 3.0.5, loglevel = 0
01/03/2015 18:09:56;0040;PBS_Server;Svr;tyrone-cluster;Scheduler was sent the command new
01/03/2015 18:10:26;0040;PBS_Server;Svr;tyrone-cluster;Scheduler was sent the command new
01/03/2015 18:10:57;0040;PBS_Server;Svr;tyrone-cluster;Scheduler was sent the command new
01/03/2015 18:11:27;0040;PBS_Server;Svr;tyrone-cluster;Scheduler was sent the command new
01/03/2015 18:11:57;0040;PBS_Server;Svr;tyrone-cluster;Scheduler was sent the command new
01/03/2015 18:12:02;0008;PBS_Server;Job;46416.tyrone-cluster;Job deleted at request of aseabwit@tyrone-cluster
01/03/2015 18:12:02;0008;PBS_Server;Job;46416.tyrone-cluster;Job sent signal SIGTERM on delete
01/03/2015 18:12:03;000d;PBS_Server;Job;46416.tyrone-cluster;Not sending email: User does not want mail of this type.
01/03/2015 18:12:03;0010;PBS_Server;Job;46416.tyrone-cluster;Exit_status=143 resources_used.cput=119:45:33 resources_used.mem=2595132kb resources_used.vmem=10158160kb resources_used.walltime=04:21:18
01/03/2015 18:12:03;0008;PBS_Server;Job;NULL;on_job_exit valid pjob: 0x13e7520 (substate=50)
01/03/2015 18:12:03;0008;PBS_Server;Job;NULL;on_job_exit valid pjob: 0x13e7520 (substate=51)
01/03/2015 18:12:04;0008;PBS_Server;Job;NULL;on_job_exit valid pjob: 0x13e7520 (substate=51)
01/03/2015 18:12:04;0008;PBS_Server;Job;NULL;on_job_exit valid pjob: 0x13e7520 (substate=53)
01/03/2015 18:12:04;0100;PBS_Server;Job;46416.tyrone-cluster;dequeuing from qp64, state COMPLETE
01/03/2015 18:12:04;0040;PBS_Server;Svr;tyrone-cluster;Scheduler was sent the command term
01/03/2015 18:12:27;0040;PBS_Server;Svr;tyrone-cluster;Scheduler was sent the command new
01/03/2015 18:12:28;0100;PBS_Server;Job;46441.tyrone-cluster;enqueuing into batch, state 1 hop 1
01/03/2015 18:12:28;0100;PBS_Server;Job;46441.tyrone-cluster;dequeuing from batch, state QUEUED
01/03/2015 18:12:28;0100;PBS_Server;Job;46441.tyrone-cluster;enqueuing into qp64, state 1 hop 1
01/03/2015 18:12:28;0008;PBS_Server;Job;46441.tyrone-cluster;Job Queued at request of aseabwit@tyrone-cluster, owner = aseabwit@tyrone-cluster, job name = DNsFlo_64, queue = qp64
01/03/2015 18:12:28;0040;PBS_Server;Svr;tyrone-cluster;Scheduler was sent the command new
01/03/2015 18:12:28;0008;PBS_Server;Job;46441.tyrone-cluster;Job Modified at request of Scheduler@tyrone-cluster
01/03/2015 18:12:28;0008;PBS_Server;Job;46441.tyrone-cluster;Job Run at request of Scheduler@tyrone-cluster
01/03/2015 18:12:28;0040;PBS_Server;Svr;tyrone-cluster;Scheduler was sent the command recyc
01/03/2015 18:12:57;0040;PBS_Server;Svr;tyrone-cluster;Scheduler was sent the command new
01/03/2015 18:13:16;000d;PBS_Server;Job;46441.tyrone-cluster;Not sending email: User does not want mail of this type.
01/03/2015 18:13:27;0040;PBS_Server;Svr;tyrone-cluster;Scheduler was sent the command new
01/03/2015 18:13:57;0040;PBS_Server;Svr;tyrone-cluster;Scheduler was sent the command new
01/03/2015 18:14:27;0040;PBS_Server;Svr;tyrone-cluster;Scheduler was sent the command new
01/03/2015 18:14:47;0002;PBS_Server;Svr;PBS_Server;Torque Server Version = 3.0.5, loglevel = 0
01/03/2015 18:14:57;0040;PBS_Server;Svr;tyrone-cluster;Scheduler was sent the command new
01/03/2015 18:15:27;0040;PBS_Server;Svr;tyrone-cluster;Scheduler was sent the command new
01/03/2015 18:15:58;0040;PBS_Server;Svr;tyrone-cluster;Scheduler was sent the command new
01/03/2015 18:16:28;0040;PBS_Server;Svr;tyrone-cluster;Scheduler was sent the command new
01/03/2015 18:16:58;0040;PBS_Server;Svr;tyrone-cluster;Scheduler was sent the command new
01/03/2015 18:17:28;0040;PBS_Server;Svr;tyrone-cluster;Scheduler was sent the command new
01/03/2015 18:17:58;0040;PBS_Server;Svr;tyrone-cluster;Scheduler was sent the command new
01/03/2015 18:18:28;0040;PBS_Server;Svr;tyrone-cluster;Scheduler was sent the command new
01/03/2015 18:18:58;0040;PBS_Server;Svr;tyrone-cluster;Scheduler was sent the command new
01/03/2015 18:19:28;0040;PBS_Server;Svr;tyrone-cluster;Scheduler was sent the command new
01/03/2015 18:19:47;0002;PBS_Server;Svr;PBS_Server;Torque Server Version = 3.0.5, loglevel = 0
01/03/2015 18:19:58;0040;PBS_Server;Svr;tyrone-cluster;Scheduler was sent the command new
01/03/2015 18:20:29;0040;PBS_Server;Svr;tyrone-cluster;Scheduler was sent the command new
01/03/2015 18:20:59;0040;PBS_Server;Svr;tyrone-cluster;Scheduler was sent the command new
01/03/2015 18:21:29;0040;PBS_Server;Svr;tyrone-cluster;Scheduler was sent the command new
01/03/2015 18:21:59;0040;PBS_Server;Svr;tyrone-cluster;Scheduler was sent the command new
01/03/2015 18:22:29;0040;PBS_Server;Svr;tyrone-cluster;Scheduler was sent the command new
01/03/2015 18:22:59;0040;PBS_Server;Svr;tyrone-cluster;Scheduler was sent the command new
01/03/2015 18:23:29;0040;PBS_Server;Svr;tyrone-cluster;Scheduler was sent the command new
01/03/2015 18:23:59;0040;PBS_Server;Svr;tyrone-cluster;Scheduler was sent the command new
01/03/2015 18:24:29;0040;PBS_Server;Svr;tyrone-cluster;Scheduler was sent the command new
01/03/2015 18:24:47;0002;PBS_Server;Svr;PBS_Server;Torque Server Version = 3.0.5, loglevel = 0
01/03/2015 18:24:59;0040;PBS_Server;Svr;tyrone-cluster;Scheduler was sent the command new
01/03/2015 18:25:30;0040;PBS_Server;Svr;tyrone-cluster;Scheduler was sent the command new
01/03/2015 18:25:59;0040;PBS_Server;Svr;tyrone-cluster;Scheduler was sent the command new
01/03/2015 18:26:30;0040;PBS_Server;Svr;tyrone-cluster;Scheduler was sent the command new
01/03/2015 18:27:00;0040;PBS_Server;Svr;tyrone-cluster;Scheduler was sent the command new
01/03/2015 18:27:30;0040;PBS_Server;Svr;tyrone-cluster;Scheduler was sent the command new
01/03/2015 18:28:00;0040;PBS_Server;Svr;tyrone-cluster;Scheduler was sent the command new
01/03/2015 18:28:31;0040;PBS_Server;Svr;tyrone-cluster;Scheduler was sent the command new
01/03/2015 18:29:01;0040;PBS_Server;Svr;tyrone-cluster;Scheduler was sent the command new
01/03/2015 18:29:31;0040;PBS_Server;Svr;tyrone-cluster;Scheduler was sent the command new
01/03/2015 18:29:47;0002;PBS_Server;Svr;PBS_Server;Torque Server Version = 3.0.5, loglevel = 0
01/03/2015 18:30:01;0040;PBS_Server;Svr;tyrone-cluster;Scheduler was sent the command new
01/03/2015 18:30:31;0040;PBS_Server;Svr;tyrone-cluster;Scheduler was sent the command new
01/03/2015 18:31:01;0040;PBS_Server;Svr;tyrone-cluster;Scheduler was sent the command new
01/03/2015 18:31:31;0040;PBS_Server;Svr;tyrone-cluster;Scheduler was sent the command new
01/03/2015 18:32:01;0040;PBS_Server;Svr;tyrone-cluster;Scheduler was sent the command new
01/03/2015 18:32:31;0040;PBS_Server;Svr;tyrone-cluster;Scheduler was sent the command new
01/03/2015 18:33:02;0040;PBS_Server;Svr;tyrone-cluster;Scheduler was sent the command new
01/03/2015 18:33:31;0040;PBS_Server;Svr;tyrone-cluster;Scheduler was sent the command new
01/03/2015 18:34:02;0040;PBS_Server;Svr;tyrone-cluster;Scheduler was sent the command new
01/03/2015 18:34:32;0040;PBS_Server;Svr;tyrone-cluster;Scheduler was sent the command new
01/03/2015 18:34:47;0002;PBS_Server;Svr;PBS_Server;Torque Server Version = 3.0.5, loglevel = 0
01/03/2015 18:35:02;0040;PBS_Server;Svr;tyrone-cluster;Scheduler was sent the command new
01/03/2015 18:35:32;0040;PBS_Server;Svr;tyrone-cluster;Scheduler was sent the command new
01/03/2015 18:36:02;0040;PBS_Server;Svr;tyrone-cluster;Scheduler was sent the command new
01/03/2015 18:36:32;0040;PBS_Server;Svr;tyrone-cluster;Scheduler was sent the command new
01/03/2015 18:37:02;0040;PBS_Server;Svr;tyrone-cluster;Scheduler was sent the command new
01/03/2015 18:37:32;0040;PBS_Server;Svr;tyrone-cluster;Scheduler was sent the command new
01/03/2015 18:38:03;0040;PBS_Server;Svr;tyrone-cluster;Scheduler was sent the command new
01/03/2015 18:38:33;0040;PBS_Server;Svr;tyrone-cluster;Scheduler was sent the command new
01/03/2015 18:39:03;0040;PBS_Server;Svr;tyrone-cluster;Scheduler was sent the command new
01/03/2015 18:39:33;0040;PBS_Server;Svr;tyrone-cluster;Scheduler was sent the command new
01/03/2015 18:39:47;0002;PBS_Server;Svr;PBS_Server;Torque Server Version = 3.0.5, loglevel = 0
01/03/2015 18:40:03;0040;PBS_Server;Svr;tyrone-cluster;Scheduler was sent the command new
01/03/2015 18:40:33;0040;PBS_Server;Svr;tyrone-cluster;Scheduler was sent the command new
01/03/2015 18:41:03;0040;PBS_Server;Svr;tyrone-cluster;Scheduler was sent the command new
01/03/2015 18:41:33;0040;PBS_Server;Svr;tyrone-cluster;Scheduler was sent the command new
01/03/2015 18:42:03;0040;PBS_Server;Svr;tyrone-cluster;Scheduler was sent the command new
01/03/2015 18:42:33;0040;PBS_Server;Svr;tyrone-cluster;Scheduler was sent the command new
01/03/2015 18:43:03;0040;PBS_Server;Svr;tyrone-cluster;Scheduler was sent the command new
01/03/2015 18:43:34;0040;PBS_Server;Svr;tyrone-cluster;Scheduler was sent the command new
01/03/2015 18:44:03;0040;PBS_Server;Svr;tyrone-cluster;Scheduler was sent the command new
01/03/2015 18:44:33;0040;PBS_Server;Svr;tyrone-cluster;Scheduler was sent the command new
01/03/2015 18:44:47;0002;PBS_Server;Svr;PBS_Server;Torque Server Version = 3.0.5, loglevel = 0
01/03/2015 18:45:04;0040;PBS_Server;Svr;tyrone-cluster;Scheduler was sent the command new
01/03/2015 18:45:34;0040;PBS_Server;Svr;tyrone-cluster;Scheduler was sent the command new
01/03/2015 18:46:04;0040;PBS_Server;Svr;tyrone-cluster;Scheduler was sent the command new
01/03/2015 18:46:34;0040;PBS_Server;Svr;tyrone-cluster;Scheduler was sent the command new
01/03/2015 18:47:04;0040;PBS_Server;Svr;tyrone-cluster;Scheduler was sent the command new
01/03/2015 18:47:34;0040;PBS_Server;Svr;tyrone-cluster;Scheduler was sent the command new
01/03/2015 18:48:05;0040;PBS_Server;Svr;tyrone-cluster;Scheduler was sent the command new
01/03/2015 18:48:35;0040;PBS_Server;Svr;tyrone-cluster;Scheduler was sent the command new
01/03/2015 18:49:05;0040;PBS_Server;Svr;tyrone-cluster;Scheduler was sent the command new
01/03/2015 18:49:35;0040;PBS_Server;Svr;tyrone-cluster;Scheduler was sent the command new
01/03/2015 18:49:47;0002;PBS_Server;Svr;PBS_Server;Torque Server Version = 3.0.5, loglevel = 0
01/03/2015 18:50:05;0040;PBS_Server;Svr;tyrone-cluster;Scheduler was sent the command new
01/03/2015 18:50:35;0040;PBS_Server;Svr;tyrone-cluster;Scheduler was sent the command new
01/03/2015 18:51:03;0008;PBS_Server;Job;46441.tyrone-cluster;Job deleted at request of aseabwit@tyrone-cluster
01/03/2015 18:51:03;0008;PBS_Server;Job;46441.tyrone-cluster;Job sent signal SIGTERM on delete
01/03/2015 18:51:04;000d;PBS_Server;Job;46441.tyrone-cluster;Not sending email: User does not want mail of this type.
01/03/2015 18:51:04;0010;PBS_Server;Job;46441.tyrone-cluster;Exit_status=143 resources_used.cput=15:30:17 resources_used.mem=1687180kb resources_used.vmem=8392784kb resources_used.walltime=00:38:36
01/03/2015 18:51:04;0008;PBS_Server;Job;NULL;on_job_exit valid pjob: 0x13e7520 (substate=50)
01/03/2015 18:51:04;0008;PBS_Server;Job;NULL;on_job_exit valid pjob: 0x13e7520 (substate=51)
01/03/2015 18:51:05;0008;PBS_Server;Job;NULL;on_job_exit valid pjob: 0x13e7520 (substate=51)
01/03/2015 18:51:05;0008;PBS_Server;Job;NULL;on_job_exit valid pjob: 0x13e7520 (substate=53)
01/03/2015 18:51:05;0100;PBS_Server;Job;46441.tyrone-cluster;dequeuing from qp64, state COMPLETE
01/03/2015 18:51:05;0040;PBS_Server;Svr;tyrone-cluster;Scheduler was sent the command term
01/03/2015 18:51:24;0100;PBS_Server;Job;46442.tyrone-cluster;enqueuing into batch, state 1 hop 1
01/03/2015 18:51:24;0100;PBS_Server;Job;46442.tyrone-cluster;dequeuing from batch, state QUEUED
01/03/2015 18:51:24;0100;PBS_Server;Job;46442.tyrone-cluster;enqueuing into qp64, state 1 hop 1
01/03/2015 18:51:24;0008;PBS_Server;Job;46442.tyrone-cluster;Job Queued at request of aseabwit@tyrone-cluster, owner = aseabwit@tyrone-cluster, job name = DNsFlo_64, queue = qp64
01/03/2015 18:51:24;0040;PBS_Server;Svr;tyrone-cluster;Scheduler was sent the command new
01/03/2015 18:51:24;0008;PBS_Server;Job;46442.tyrone-cluster;Job Modified at request of Scheduler@tyrone-cluster
01/03/2015 18:51:24;0008;PBS_Server;Job;46442.tyrone-cluster;Job Run at request of Scheduler@tyrone-cluster
01/03/2015 18:51:24;0040;PBS_Server;Svr;tyrone-cluster;Scheduler was sent the command recyc
01/03/2015 18:51:36;0040;PBS_Server;Svr;tyrone-cluster;Scheduler was sent the command new
01/03/2015 18:52:06;0040;PBS_Server;Svr;tyrone-cluster;Scheduler was sent the command new
01/03/2015 18:52:18;000d;PBS_Server;Job;46442.tyrone-cluster;Not sending email: User does not want mail of this type.
01/03/2015 18:52:36;0040;PBS_Server;Svr;tyrone-cluster;Scheduler was sent the command new
01/03/2015 18:53:06;0040;PBS_Server;Svr;tyrone-cluster;Scheduler was sent the command new
01/03/2015 18:53:36;0040;PBS_Server;Svr;tyrone-cluster;Scheduler was sent the command new
01/03/2015 18:54:06;0040;PBS_Server;Svr;tyrone-cluster;Scheduler was sent the command new
01/03/2015 18:54:36;0040;PBS_Server;Svr;tyrone-cluster;Scheduler was sent the command new
01/03/2015 18:54:47;0002;PBS_Server;Svr;PBS_Server;Torque Server Version = 3.0.5, loglevel = 0
01/03/2015 18:55:06;0040;PBS_Server;Svr;tyrone-cluster;Scheduler was sent the command new
01/03/2015 18:55:27;0008;PBS_Server;Job;46442.tyrone-cluster;Job deleted at request of aseabwit@tyrone-cluster
01/03/2015 18:55:27;0008;PBS_Server;Job;46442.tyrone-cluster;Job sent signal SIGTERM on delete
01/03/2015 18:55:27;000d;PBS_Server;Job;46442.tyrone-cluster;Not sending email: User does not want mail of this type.
01/03/2015 18:55:27;0010;PBS_Server;Job;46442.tyrone-cluster;Exit_status=143 resources_used.cput=00:00:11 resources_used.mem=353752kb resources_used.vmem=3228656kb resources_used.walltime=00:04:03
01/03/2015 18:55:27;0008;PBS_Server;Job;NULL;on_job_exit valid pjob: 0x13e7520 (substate=50)
01/03/2015 18:55:27;0008;PBS_Server;Job;NULL;on_job_exit valid pjob: 0x13e7520 (substate=51)
01/03/2015 18:55:28;0008;PBS_Server;Job;NULL;on_job_exit valid pjob: 0x13e7520 (substate=51)
01/03/2015 18:55:28;0008;PBS_Server;Job;NULL;on_job_exit valid pjob: 0x13e7520 (substate=53)
01/03/2015 18:55:28;0100;PBS_Server;Job;46442.tyrone-cluster;dequeuing from qp64, state COMPLETE
01/03/2015 18:55:28;0040;PBS_Server;Svr;tyrone-cluster;Scheduler was sent the command term
01/03/2015 18:55:36;0040;PBS_Server;Svr;tyrone-cluster;Scheduler was sent the command new
01/03/2015 18:56:07;0040;PBS_Server;Svr;tyrone-cluster;Scheduler was sent the command new
01/03/2015 18:56:28;0100;PBS_Server;Job;46443.tyrone-cluster;enqueuing into batch, state 1 hop 1
01/03/2015 18:56:28;0100;PBS_Server;Job;46443.tyrone-cluster;dequeuing from batch, state QUEUED
01/03/2015 18:56:28;0100;PBS_Server;Job;46443.tyrone-cluster;enqueuing into qp64, state 1 hop 1
01/03/2015 18:56:28;0008;PBS_Server;Job;46443.tyrone-cluster;Job Queued at request of aseabwit@tyrone-cluster, owner = aseabwit@tyrone-cluster, job name = DNsFlo_64, queue = qp64
01/03/2015 18:56:28;0040;PBS_Server;Svr;tyrone-cluster;Scheduler was sent the command new
01/03/2015 18:56:29;0008;PBS_Server;Job;46443.tyrone-cluster;Job Modified at request of Scheduler@tyrone-cluster
01/03/2015 18:56:29;0008;PBS_Server;Job;46443.tyrone-cluster;Job Run at request of Scheduler@tyrone-cluster
01/03/2015 18:56:29;0040;PBS_Server;Svr;tyrone-cluster;Scheduler was sent the command recyc
01/03/2015 18:56:37;0040;PBS_Server;Svr;tyrone-cluster;Scheduler was sent the command new
01/03/2015 18:57:07;0040;PBS_Server;Svr;tyrone-cluster;Scheduler was sent the command new
01/03/2015 18:57:35;000d;PBS_Server;Job;46443.tyrone-cluster;Not sending email: User does not want mail of this type.
01/03/2015 18:57:37;0040;PBS_Server;Svr;tyrone-cluster;Scheduler was sent the command new
01/03/2015 18:58:07;0040;PBS_Server;Svr;tyrone-cluster;Scheduler was sent the command new
01/03/2015 18:58:37;0040;PBS_Server;Svr;tyrone-cluster;Scheduler was sent the command new
01/03/2015 18:59:07;0040;PBS_Server;Svr;tyrone-cluster;Scheduler was sent the command new
01/03/2015 18:59:37;0040;PBS_Server;Svr;tyrone-cluster;Scheduler was sent the command new
01/03/2015 18:59:47;0002;PBS_Server;Svr;PBS_Server;Torque Server Version = 3.0.5, loglevel = 0
01/03/2015 19:00:07;0040;PBS_Server;Svr;tyrone-cluster;Scheduler was sent the command new
01/03/2015 19:00:37;0040;PBS_Server;Svr;tyrone-cluster;Scheduler was sent the command new
01/03/2015 19:01:08;0040;PBS_Server;Svr;tyrone-cluster;Scheduler was sent the command new
01/03/2015 19:01:15;0008;PBS_Server;Job;46443.tyrone-cluster;Job deleted at request of aseabwit@tyrone-cluster
01/03/2015 19:01:15;0008;PBS_Server;Job;46443.tyrone-cluster;Job sent signal SIGTERM on delete
01/03/2015 19:01:15;000d;PBS_Server;Job;46443.tyrone-cluster;Not sending email: User does not want mail of this type.
01/03/2015 19:01:15;0010;PBS_Server;Job;46443.tyrone-cluster;Exit_status=143 resources_used.cput=00:00:00 resources_used.mem=353748kb resources_used.vmem=3228656kb resources_used.walltime=00:04:46
01/03/2015 19:01:15;0008;PBS_Server;Job;NULL;on_job_exit valid pjob: 0x13e7520 (substate=50)
01/03/2015 19:01:15;0008;PBS_Server;Job;NULL;on_job_exit valid pjob: 0x13e7520 (substate=51)
01/03/2015 19:01:16;0008;PBS_Server;Job;NULL;on_job_exit valid pjob: 0x13e7520 (substate=51)
01/03/2015 19:01:16;0008;PBS_Server;Job;NULL;on_job_exit valid pjob: 0x13e7520 (substate=53)
01/03/2015 19:01:16;0100;PBS_Server;Job;46443.tyrone-cluster;dequeuing from qp64, state COMPLETE
01/03/2015 19:01:16;0040;PBS_Server;Svr;tyrone-cluster;Scheduler was sent the command term
01/03/2015 19:01:38;0040;PBS_Server;Svr;tyrone-cluster;Scheduler was sent the command new
01/03/2015 19:02:08;0040;PBS_Server;Svr;tyrone-cluster;Scheduler was sent the command new
01/03/2015 19:02:38;0040;PBS_Server;Svr;tyrone-cluster;Scheduler was sent the command new
01/03/2015 19:03:08;0040;PBS_Server;Svr;tyrone-cluster;Scheduler was sent the command new
01/03/2015 19:03:38;0040;PBS_Server;Svr;tyrone-cluster;Scheduler was sent the command new
01/03/2015 19:04:08;0040;PBS_Server;Svr;tyrone-cluster;Scheduler was sent the command new
01/03/2015 19:04:38;0040;PBS_Server;Svr;tyrone-cluster;Scheduler was sent the command new
01/03/2015 19:04:47;0002;PBS_Server;Svr;PBS_Server;Torque Server Version = 3.0.5, loglevel = 0
01/03/2015 19:05:08;0040;PBS_Server;Svr;tyrone-cluster;Scheduler was sent the command new
01/03/2015 19:05:38;0040;PBS_Server;Svr;tyrone-cluster;Scheduler was sent the command new
01/03/2015 19:05:38;0100;PBS_Server;Job;46444.tyrone-cluster;enqueuing into batch, state 1 hop 1
01/03/2015 19:05:38;0100;PBS_Server;Job;46444.tyrone-cluster;dequeuing from batch, state QUEUED
01/03/2015 19:05:38;0100;PBS_Server;Job;46444.tyrone-cluster;enqueuing into qp64, state 1 hop 1
01/03/2015 19:05:38;0008;PBS_Server;Job;46444.tyrone-cluster;Job Queued at request of aseabwit@tyrone-cluster, owner = aseabwit@tyrone-cluster, job name = DNsFlo_64, queue = qp64
01/03/2015 19:05:39;0008;PBS_Server;Job;46444.tyrone-cluster;Job Modified at request of Scheduler@tyrone-cluster
01/03/2015 19:05:39;0008;PBS_Server;Job;46444.tyrone-cluster;Job Run at request of Scheduler@tyrone-cluster
01/03/2015 19:05:39;0040;PBS_Server;Svr;tyrone-cluster;Scheduler was sent the command recyc
01/03/2015 19:06:09;0040;PBS_Server;Svr;tyrone-cluster;Scheduler was sent the command new
01/03/2015 19:06:37;000d;PBS_Server;Job;46444.tyrone-cluster;Not sending email: User does not want mail of this type.
01/03/2015 19:06:39;0040;PBS_Server;Svr;tyrone-cluster;Scheduler was sent the command new
01/03/2015 19:07:09;0040;PBS_Server;Svr;tyrone-cluster;Scheduler was sent the command new
01/03/2015 19:07:39;0040;PBS_Server;Svr;tyrone-cluster;Scheduler was sent the command new
01/03/2015 19:08:09;0040;PBS_Server;Svr;tyrone-cluster;Scheduler was sent the command new
01/03/2015 19:08:39;0040;PBS_Server;Svr;tyrone-cluster;Scheduler was sent the command new
01/03/2015 19:09:09;0040;PBS_Server;Svr;tyrone-cluster;Scheduler was sent the command new
01/03/2015 19:09:39;0040;PBS_Server;Svr;tyrone-cluster;Scheduler was sent the command new
01/03/2015 19:09:44;0100;PBS_Server;Job;46445.tyrone-cluster;enqueuing into batch, state 1 hop 1
01/03/2015 19:09:44;0100;PBS_Server;Job;46445.tyrone-cluster;dequeuing from batch, state QUEUED
01/03/2015 19:09:44;0100;PBS_Server;Job;46445.tyrone-cluster;enqueuing into idqueue, state 1 hop 1
01/03/2015 19:09:44;0008;PBS_Server;Job;46445.tyrone-cluster;Job Queued at request of chemraja@tyrone-cluster, owner = chemraja@tyrone-cluster, job name = test.sh, queue = idqueue
01/03/2015 19:09:44;0040;PBS_Server;Svr;tyrone-cluster;Scheduler was sent the command new
01/03/2015 19:09:45;0008;PBS_Server;Job;46445.tyrone-cluster;Job Modified at request of Scheduler@tyrone-cluster
01/03/2015 19:09:45;0008;PBS_Server;Job;46445.tyrone-cluster;Job Run at request of Scheduler@tyrone-cluster
01/03/2015 19:09:45;0040;PBS_Server;Svr;tyrone-cluster;Scheduler was sent the command recyc
01/03/2015 19:09:45;000d;PBS_Server;Job;46445.tyrone-cluster;Not sending email: User does not want mail of this type.
01/03/2015 19:09:47;0002;PBS_Server;Svr;PBS_Server;Torque Server Version = 3.0.5, loglevel = 0
01/03/2015 19:10:10;0040;PBS_Server;Svr;tyrone-cluster;Scheduler was sent the command new
01/03/2015 19:10:40;0040;PBS_Server;Svr;tyrone-cluster;Scheduler was sent the command new
01/03/2015 19:11:10;0040;PBS_Server;Svr;tyrone-cluster;Scheduler was sent the command new
01/03/2015 19:11:40;0040;PBS_Server;Svr;tyrone-cluster;Scheduler was sent the command new
01/03/2015 19:12:10;0040;PBS_Server;Svr;tyrone-cluster;Scheduler was sent the command new
01/03/2015 19:12:40;0040;PBS_Server;Svr;tyrone-cluster;Scheduler was sent the command new
01/03/2015 19:13:10;0040;PBS_Server;Svr;tyrone-cluster;Scheduler was sent the command new
01/03/2015 19:13:40;0040;PBS_Server;Svr;tyrone-cluster;Scheduler was sent the command new
01/03/2015 19:14:10;0040;PBS_Server;Svr;tyrone-cluster;Scheduler was sent the command new
01/03/2015 19:14:41;0040;PBS_Server;Svr;tyrone-cluster;Scheduler was sent the command new
01/03/2015 19:14:47;0002;PBS_Server;Svr;PBS_Server;Torque Server Version = 3.0.5, loglevel = 0
01/03/2015 19:15:11;0040;PBS_Server;Svr;tyrone-cluster;Scheduler was sent the command new
01/03/2015 19:15:41;0040;PBS_Server;Svr;tyrone-cluster;Scheduler was sent the command new
01/03/2015 19:16:11;0040;PBS_Server;Svr;tyrone-cluster;Scheduler was sent the command new
01/03/2015 19:16:41;0040;PBS_Server;Svr;tyrone-cluster;Scheduler was sent the command new
01/03/2015 19:17:11;0040;PBS_Server;Svr;tyrone-cluster;Scheduler was sent the command new
01/03/2015 19:17:41;0040;PBS_Server;Svr;tyrone-cluster;Scheduler was sent the command new
01/03/2015 19:18:11;0040;PBS_Server;Svr;tyrone-cluster;Scheduler was sent the command new
01/03/2015 19:18:42;0040;PBS_Server;Svr;tyrone-cluster;Scheduler was sent the command new
01/03/2015 19:19:12;0040;PBS_Server;Svr;tyrone-cluster;Scheduler was sent the command new
01/03/2015 19:19:24;000d;PBS_Server;Job;46283.tyrone-cluster;Not sending email: User does not want mail of this type.
01/03/2015 19:19:24;0010;PBS_Server;Job;46283.tyrone-cluster;Exit_status=143 resources_used.cput=00:05:11 resources_used.mem=10400kb resources_used.vmem=328828kb resources_used.walltime=24:00:27
01/03/2015 19:19:24;0008;PBS_Server;Job;NULL;on_job_exit valid pjob: 0x13e3600 (substate=50)
01/03/2015 19:19:24;0008;PBS_Server;Job;NULL;on_job_exit valid pjob: 0x13e3600 (substate=51)
01/03/2015 19:19:25;0008;PBS_Server;Job;NULL;on_job_exit valid pjob: 0x13e3600 (substate=51)
01/03/2015 19:19:25;0008;PBS_Server;Job;NULL;on_job_exit valid pjob: 0x13e3600 (substate=53)
01/03/2015 19:19:25;0100;PBS_Server;Job;46283.tyrone-cluster;dequeuing from qp256, state COMPLETE
01/03/2015 19:19:25;0040;PBS_Server;Svr;tyrone-cluster;Scheduler was sent the command term
01/03/2015 19:19:25;0008;PBS_Server;Job;46193.tyrone-cluster;Job Modified at request of Scheduler@tyrone-cluster
01/03/2015 19:19:25;0008;PBS_Server;Job;46193.tyrone-cluster;Job Run at request of Scheduler@tyrone-cluster
01/03/2015 19:19:25;0040;PBS_Server;Svr;tyrone-cluster;Scheduler was sent the command recyc
01/03/2015 19:19:35;000d;PBS_Server;Job;46193.tyrone-cluster;Not sending email: User does not want mail of this type.
01/03/2015 19:19:35;0010;PBS_Server;Job;46193.tyrone-cluster;Exit_status=255 resources_used.cput=00:06:39 resources_used.mem=804kb resources_used.vmem=13628kb resources_used.walltime=00:00:10
01/03/2015 19:19:35;0008;PBS_Server;Job;NULL;on_job_exit valid pjob: 0x13e0430 (substate=50)
01/03/2015 19:19:35;0008;PBS_Server;Job;NULL;on_job_exit valid pjob: 0x13e0430 (substate=51)
01/03/2015 19:19:36;0008;PBS_Server;Job;NULL;on_job_exit valid pjob: 0x13e0430 (substate=51)
01/03/2015 19:19:36;0008;PBS_Server;Job;NULL;on_job_exit valid pjob: 0x13e0430 (substate=53)
01/03/2015 19:19:36;0100;PBS_Server;Job;46193.tyrone-cluster;dequeuing from qp256, state COMPLETE
01/03/2015 19:19:36;0040;PBS_Server;Svr;tyrone-cluster;Scheduler was sent the command term
01/03/2015 19:19:36;0008;PBS_Server;Job;46199.tyrone-cluster;Job Modified at request of Scheduler@tyrone-cluster
01/03/2015 19:19:36;0008;PBS_Server;Job;46194.tyrone-cluster;Job Modified at request of Scheduler@tyrone-cluster
01/03/2015 19:19:36;0008;PBS_Server;Job;46194.tyrone-cluster;Job Run at request of Scheduler@tyrone-cluster
01/03/2015 19:19:36;0040;PBS_Server;Svr;tyrone-cluster;Scheduler was sent the command recyc
01/03/2015 19:19:42;0100;PBS_Server;Job;46414.tyrone-cluster;dequeuing from batch, state QUEUED
01/03/2015 19:19:42;0100;PBS_Server;Job;46414.tyrone-cluster;enqueuing into qp256, state 1 hop 1
01/03/2015 19:19:42;0040;PBS_Server;Svr;tyrone-cluster;Scheduler was sent the command new
01/03/2015 19:19:42;0008;PBS_Server;Job;46199.tyrone-cluster;Job Modified at request of Scheduler@tyrone-cluster
01/03/2015 19:19:42;0008;PBS_Server;Job;46414.tyrone-cluster;Job Modified at request of Scheduler@tyrone-cluster
01/03/2015 19:19:46;000d;PBS_Server;Job;46194.tyrone-cluster;Not sending email: User does not want mail of this type.
01/03/2015 19:19:46;0010;PBS_Server;Job;46194.tyrone-cluster;Exit_status=255 resources_used.cput=00:05:59 resources_used.mem=804kb resources_used.vmem=13628kb resources_used.walltime=00:00:10
01/03/2015 19:19:46;0008;PBS_Server;Job;NULL;on_job_exit valid pjob: 0x12ecd40 (substate=50)
01/03/2015 19:19:46;0008;PBS_Server;Job;NULL;on_job_exit valid pjob: 0x12ecd40 (substate=51)
01/03/2015 19:19:47;0008;PBS_Server;Job;NULL;on_job_exit valid pjob: 0x12ecd40 (substate=51)
01/03/2015 19:19:47;0008;PBS_Server;Job;NULL;on_job_exit valid pjob: 0x12ecd40 (substate=53)
01/03/2015 19:19:47;0100;PBS_Server;Job;46194.tyrone-cluster;dequeuing from qp256, state COMPLETE
01/03/2015 19:19:47;0002;PBS_Server;Svr;PBS_Server;Torque Server Version = 3.0.5, loglevel = 0
01/03/2015 19:19:47;0040;PBS_Server;Svr;tyrone-cluster;Scheduler was sent the command term
01/03/2015 19:19:47;0008;PBS_Server;Job;46199.tyrone-cluster;Job Modified at request of Scheduler@tyrone-cluster
01/03/2015 19:19:47;0008;PBS_Server;Job;46414.tyrone-cluster;Job Modified at request of Scheduler@tyrone-cluster
01/03/2015 19:19:47;0008;PBS_Server;Job;46414.tyrone-cluster;Job Run at request of Scheduler@tyrone-cluster
01/03/2015 19:19:47;0040;PBS_Server;Svr;tyrone-cluster;Scheduler was sent the command recyc
01/03/2015 19:19:56;000d;PBS_Server;Job;46414.tyrone-cluster;Not sending email: User does not want mail of this type.
01/03/2015 19:19:56;0010;PBS_Server;Job;46414.tyrone-cluster;Exit_status=255 resources_used.cput=00:06:50 resources_used.mem=808kb resources_used.vmem=13628kb resources_used.walltime=00:00:09
01/03/2015 19:19:56;0008;PBS_Server;Job;NULL;on_job_exit valid pjob: 0x12f32e0 (substate=50)
01/03/2015 19:19:56;0008;PBS_Server;Job;NULL;on_job_exit valid pjob: 0x12f32e0 (substate=51)
01/03/2015 19:19:57;0008;PBS_Server;Job;NULL;on_job_exit valid pjob: 0x12f32e0 (substate=51)
01/03/2015 19:19:57;0008;PBS_Server;Job;NULL;on_job_exit valid pjob: 0x12f32e0 (substate=53)
01/03/2015 19:19:57;0100;PBS_Server;Job;46414.tyrone-cluster;dequeuing from qp256, state COMPLETE
01/03/2015 19:19:57;0040;PBS_Server;Svr;tyrone-cluster;Scheduler was sent the command term
01/03/2015 19:20:12;0100;PBS_Server;Job;46415.tyrone-cluster;dequeuing from batch, state QUEUED
01/03/2015 19:20:12;0100;PBS_Server;Job;46415.tyrone-cluster;enqueuing into qp256, state 1 hop 1
01/03/2015 19:20:12;0040;PBS_Server;Svr;tyrone-cluster;Scheduler was sent the command new
01/03/2015 19:20:12;0008;PBS_Server;Job;46415.tyrone-cluster;Job Modified at request of Scheduler@tyrone-cluster
01/03/2015 19:20:12;0008;PBS_Server;Job;46415.tyrone-cluster;Job Run at request of Scheduler@tyrone-cluster
01/03/2015 19:20:12;0040;PBS_Server;Svr;tyrone-cluster;Scheduler was sent the command recyc
01/03/2015 19:20:23;000d;PBS_Server;Job;46415.tyrone-cluster;Not sending email: User does not want mail of this type.
01/03/2015 19:20:23;0010;PBS_Server;Job;46415.tyrone-cluster;Exit_status=255 resources_used.cput=00:07:06 resources_used.mem=804kb resources_used.vmem=13628kb resources_used.walltime=00:00:11
01/03/2015 19:20:23;0008;PBS_Server;Job;NULL;on_job_exit valid pjob: 0x13deb80 (substate=50)
01/03/2015 19:20:23;0008;PBS_Server;Job;NULL;on_job_exit valid pjob: 0x13deb80 (substate=51)
01/03/2015 19:20:24;0008;PBS_Server;Job;NULL;on_job_exit valid pjob: 0x13deb80 (substate=51)
01/03/2015 19:20:24;0008;PBS_Server;Job;NULL;on_job_exit valid pjob: 0x13deb80 (substate=53)
01/03/2015 19:20:24;0100;PBS_Server;Job;46415.tyrone-cluster;dequeuing from qp256, state COMPLETE
01/03/2015 19:20:24;0040;PBS_Server;Svr;tyrone-cluster;Scheduler was sent the command term
01/03/2015 19:20:42;0040;PBS_Server;Svr;tyrone-cluster;Scheduler was sent the command new
01/03/2015 19:21:12;0040;PBS_Server;Svr;tyrone-cluster;Scheduler was sent the command new
01/03/2015 19:21:42;0040;PBS_Server;Svr;tyrone-cluster;Scheduler was sent the command new
01/03/2015 19:22:12;0040;PBS_Server;Svr;tyrone-cluster;Scheduler was sent the command new
01/03/2015 19:22:42;0040;PBS_Server;Svr;tyrone-cluster;Scheduler was sent the command new
01/03/2015 19:23:13;0040;PBS_Server;Svr;tyrone-cluster;Scheduler was sent the command new
01/03/2015 19:23:43;0040;PBS_Server;Svr;tyrone-cluster;Scheduler was sent the command new
01/03/2015 19:24:13;0040;PBS_Server;Svr;tyrone-cluster;Scheduler was sent the command new
01/03/2015 19:24:43;0040;PBS_Server;Svr;tyrone-cluster;Scheduler was sent the command new
01/03/2015 19:24:47;0002;PBS_Server;Svr;PBS_Server;Torque Server Version = 3.0.5, loglevel = 0
01/03/2015 19:25:13;0040;PBS_Server;Svr;tyrone-cluster;Scheduler was sent the command new
01/03/2015 19:25:19;000d;PBS_Server;Job;46382.tyrone-cluster;Not sending email: User does not want mail of this type.
01/03/2015 19:25:19;0010;PBS_Server;Job;46382.tyrone-cluster;Exit_status=143 resources_used.cput=767:43:38 resources_used.mem=847948kb resources_used.vmem=8698428kb resources_used.walltime=24:00:30
01/03/2015 19:25:19;0008;PBS_Server;Job;NULL;on_job_exit valid pjob: 0x14010b0 (substate=50)
01/03/2015 19:25:19;0008;PBS_Server;Job;NULL;on_job_exit valid pjob: 0x14010b0 (substate=51)
01/03/2015 19:25:19;0008;PBS_Server;Job;NULL;on_job_exit valid pjob: 0x14010b0 (substate=51)
01/03/2015 19:25:19;0008;PBS_Server;Job;NULL;on_job_exit valid pjob: 0x14010b0 (substate=53)
01/03/2015 19:25:19;0100;PBS_Server;Job;46382.tyrone-cluster;dequeuing from qp128, state COMPLETE
01/03/2015 19:25:19;0040;PBS_Server;Svr;tyrone-cluster;Scheduler was sent the command term
01/03/2015 19:25:19;0008;PBS_Server;Job;46440.tyrone-cluster;Job Modified at request of Scheduler@tyrone-cluster
01/03/2015 19:25:19;0008;PBS_Server;Job;46440.tyrone-cluster;Job Run at request of Scheduler@tyrone-cluster
01/03/2015 19:25:19;0040;PBS_Server;Svr;tyrone-cluster;Scheduler was sent the command recyc
01/03/2015 19:25:43;0040;PBS_Server;Svr;tyrone-cluster;Scheduler was sent the command new
01/03/2015 19:25:59;000d;PBS_Server;Job;46440.tyrone-cluster;Not sending email: User does not want mail of this type.
01/03/2015 19:26:13;0040;PBS_Server;Svr;tyrone-cluster;Scheduler was sent the command new
01/03/2015 19:26:43;0040;PBS_Server;Svr;tyrone-cluster;Scheduler was sent the command new
01/03/2015 19:27:13;0040;PBS_Server;Svr;tyrone-cluster;Scheduler was sent the command new
01/03/2015 19:27:43;0040;PBS_Server;Svr;tyrone-cluster;Scheduler was sent the command new
01/03/2015 19:28:14;0040;PBS_Server;Svr;tyrone-cluster;Scheduler was sent the command new
01/03/2015 19:28:44;0040;PBS_Server;Svr;tyrone-cluster;Scheduler was sent the command new
01/03/2015 19:29:14;0040;PBS_Server;Svr;tyrone-cluster;Scheduler was sent the command new
01/03/2015 19:29:44;0040;PBS_Server;Svr;tyrone-cluster;Scheduler was sent the command new
01/03/2015 19:29:47;0002;PBS_Server;Svr;PBS_Server;Torque Server Version = 3.0.5, loglevel = 0
01/03/2015 19:30:14;0040;PBS_Server;Svr;tyrone-cluster;Scheduler was sent the command new
01/03/2015 19:30:44;0040;PBS_Server;Svr;tyrone-cluster;Scheduler was sent the command new
01/03/2015 19:31:14;0040;PBS_Server;Svr;tyrone-cluster;Scheduler was sent the command new
01/03/2015 19:31:44;0040;PBS_Server;Svr;tyrone-cluster;Scheduler was sent the command new
01/03/2015 19:32:14;0040;PBS_Server;Svr;tyrone-cluster;Scheduler was sent the command new
01/03/2015 19:32:44;0040;PBS_Server;Svr;tyrone-cluster;Scheduler was sent the command new
01/03/2015 19:33:15;0040;PBS_Server;Svr;tyrone-cluster;Scheduler was sent the command new
01/03/2015 19:33:25;0008;PBS_Server;Job;46440.tyrone-cluster;Job deleted at request of asepk@tyrone-cluster
01/03/2015 19:33:25;0008;PBS_Server;Job;46440.tyrone-cluster;Job sent signal SIGTERM on delete
01/03/2015 19:33:25;000d;PBS_Server;Job;46440.tyrone-cluster;Not sending email: User does not want mail of this type.
01/03/2015 19:33:25;0010;PBS_Server;Job;46440.tyrone-cluster;Exit_status=143 resources_used.cput=00:08:04 resources_used.mem=41644kb resources_used.vmem=1764840kb resources_used.walltime=00:08:05
01/03/2015 19:33:25;0008;PBS_Server;Job;NULL;on_job_exit valid pjob: 0x1318890 (substate=50)
01/03/2015 19:33:25;0008;PBS_Server;Job;NULL;on_job_exit valid pjob: 0x1318890 (substate=51)
01/03/2015 19:33:34;0008;PBS_Server;Job;NULL;on_job_exit valid pjob: 0x1318890 (substate=51)
01/03/2015 19:33:34;000d;PBS_Server;Job;46440.tyrone-cluster;Post job file processing error; job 46440.tyrone-cluster on host tyrone-node6/31+tyrone-node6/30+tyrone-node6/29+tyrone-node6/28+tyrone-node6/27+tyrone-node6/26+tyrone-node6/25+tyrone-node6/24+tyrone-node6/23+tyrone-node6/22+tyrone-node6/21+tyrone-node6/20+tyrone-node6/19+tyrone-node6/18+tyrone-node6/17+tyrone-node6/16+tyrone-node6/15+tyrone-node6/14+tyrone-node6/13+tyrone-node6/12+tyrone-node6/11+tyrone-node6/10+tyrone-node6/9+tyrone-node6/8+tyrone-node6/7+tyrone-node6/6+tyrone-node6/5+tyrone-node6/4+tyrone-node6/3+tyrone-node6/2+tyrone-node6/1+tyrone-node6/0+tyrone-node5/31+tyrone-node5/30+tyrone-node5/29+tyrone-node5/28+tyrone-node5/27+tyrone-node5/26+tyrone-node5/25+tyrone-node5/24+tyrone-node5/23+tyrone-node5/22+tyrone-node5/21+tyrone-node5/20+tyrone-node5/19+tyrone-node5/18+tyrone-node5/17+tyrone-node5/16+tyrone-node5/15+tyrone-node5/14+tyrone-node5/13+tyrone-node5/12+tyrone-node5/11+tyrone-node5/10+tyrone-node5/9+tyrone-node5/8+tyrone-node5/7+tyrone-node5/6+tyrone-node5/5+tyrone-node5/4+tyrone-node5/3+tyrone-node5/2+tyrone-node5/1+tyrone-node5/0+tyrone-node4/31+tyrone-node4/30+tyrone-node4/29+tyrone-node4/28+tyrone-node4/27+tyrone-node4/26+tyrone-node4/25+tyrone-node4/24+tyrone-node4/23+tyrone-node4/22+tyrone-node4/21+tyrone-node4/20+tyrone-node4/19+tyrone-node4/18+tyrone-node4/17+tyrone-node4/16+tyrone-node4/15+tyrone-node4/14+tyrone-node4/13+tyrone-node4/12+tyrone-node4/11+tyrone-node4/10+tyrone-node4/9+tyrone-node4/8+tyrone-node4/7+tyrone-node4/6+tyrone-node4/5+tyrone-node4/4+tyrone-node4/3+tyrone-node4/2+tyrone-node4/1+tyrone-node4/0+tyrone-node3/31+tyrone-node3/30+tyrone-node3/29+tyrone-node3/28+tyrone-node3/27+tyrone-node3/26+tyrone-node3/25+tyrone-node3/24+tyrone-node3/23+tyrone-node3/22+tyrone-node3/21+tyrone-node3/20+tyrone-node3/19+tyrone-node3/18+tyrone-node3/17+tyrone-node3/16+tyrone-node3/15+tyrone-node3/14+tyrone-node3/13+tyrone-node3/12+tyrone-node3/11+tyrone-node3/10+tyrone-node3/9+tyrone-node3/8+tyrone-node3/7+tyrone-node3/6+tyrone-node3/5+tyrone-node3/4+tyrone-node3/3+tyrone-node3/2+tyrone-node3/1+tyrone-node3/0
01/03/2015 19:33:34;0008;PBS_Server;Job;NULL;on_job_exit valid pjob: 0x1318890 (substate=53)
01/03/2015 19:33:34;0100;PBS_Server;Job;46440.tyrone-cluster;dequeuing from qp128, state COMPLETE
01/03/2015 19:33:34;0040;PBS_Server;Svr;tyrone-cluster;Scheduler was sent the command term
01/03/2015 19:33:44;0040;PBS_Server;Svr;tyrone-cluster;Scheduler was sent the command new
01/03/2015 19:33:44;0100;PBS_Server;Job;46446.tyrone-cluster;enqueuing into batch, state 1 hop 1
01/03/2015 19:33:44;0100;PBS_Server;Job;46446.tyrone-cluster;dequeuing from batch, state QUEUED
01/03/2015 19:33:44;0100;PBS_Server;Job;46446.tyrone-cluster;enqueuing into qp128, state 1 hop 1
01/03/2015 19:33:44;0008;PBS_Server;Job;46446.tyrone-cluster;Job Queued at request of asepk@tyrone-cluster, owner = asepk@tyrone-cluster, job name = DNsFlo_128, queue = qp128
01/03/2015 19:33:44;0008;PBS_Server;Job;46446.tyrone-cluster;Job Modified at request of Scheduler@tyrone-cluster
01/03/2015 19:33:44;0008;PBS_Server;Job;46446.tyrone-cluster;Job Run at request of Scheduler@tyrone-cluster
01/03/2015 19:33:44;0040;PBS_Server;Svr;tyrone-cluster;Scheduler was sent the command recyc
01/03/2015 19:34:15;0040;PBS_Server;Svr;tyrone-cluster;Scheduler was sent the command new
01/03/2015 19:34:28;000d;PBS_Server;Job;46446.tyrone-cluster;Not sending email: User does not want mail of this type.
01/03/2015 19:34:45;0040;PBS_Server;Svr;tyrone-cluster;Scheduler was sent the command new
01/03/2015 19:34:47;0002;PBS_Server;Svr;PBS_Server;Torque Server Version = 3.0.5, loglevel = 0
01/03/2015 19:35:15;0040;PBS_Server;Svr;tyrone-cluster;Scheduler was sent the command new
01/03/2015 19:35:44;0040;PBS_Server;Svr;tyrone-cluster;Scheduler was sent the command new
01/03/2015 19:36:15;0040;PBS_Server;Svr;tyrone-cluster;Scheduler was sent the command new
01/03/2015 19:36:45;0040;PBS_Server;Svr;tyrone-cluster;Scheduler was sent the command new
01/03/2015 19:37:15;0040;PBS_Server;Svr;tyrone-cluster;Scheduler was sent the command new
01/03/2015 19:37:39;0008;PBS_Server;Job;46444.tyrone-cluster;Job deleted at request of aseabwit@tyrone-cluster
01/03/2015 19:37:39;0008;PBS_Server;Job;46444.tyrone-cluster;Job sent signal SIGTERM on delete
01/03/2015 19:37:39;000d;PBS_Server;Job;46444.tyrone-cluster;Not sending email: User does not want mail of this type.
01/03/2015 19:37:39;0010;PBS_Server;Job;46444.tyrone-cluster;Exit_status=143 resources_used.cput=00:00:00 resources_used.mem=353748kb resources_used.vmem=3228656kb resources_used.walltime=00:32:00
01/03/2015 19:37:39;0008;PBS_Server;Job;NULL;on_job_exit valid pjob: 0x13e7520 (substate=50)
01/03/2015 19:37:39;0008;PBS_Server;Job;NULL;on_job_exit valid pjob: 0x13e7520 (substate=51)
01/03/2015 19:37:40;0008;PBS_Server;Job;NULL;on_job_exit valid pjob: 0x13e7520 (substate=51)
01/03/2015 19:37:40;0008;PBS_Server;Job;NULL;on_job_exit valid pjob: 0x13e7520 (substate=53)
01/03/2015 19:37:40;0100;PBS_Server;Job;46444.tyrone-cluster;dequeuing from qp64, state COMPLETE
01/03/2015 19:37:40;0040;PBS_Server;Svr;tyrone-cluster;Scheduler was sent the command term
01/03/2015 19:37:46;0040;PBS_Server;Svr;tyrone-cluster;Scheduler was sent the command new
01/03/2015 19:38:04;0008;PBS_Server;Job;46446.tyrone-cluster;Job deleted at request of asepk@tyrone-cluster
01/03/2015 19:38:04;0008;PBS_Server;Job;46446.tyrone-cluster;Job sent signal SIGTERM on delete
01/03/2015 19:38:04;000d;PBS_Server;Job;46446.tyrone-cluster;Not sending email: User does not want mail of this type.
01/03/2015 19:38:04;0010;PBS_Server;Job;46446.tyrone-cluster;Exit_status=143 resources_used.cput=00:04:18 resources_used.mem=250112kb resources_used.vmem=3169044kb resources_used.walltime=00:04:20
01/03/2015 19:38:04;0008;PBS_Server;Job;NULL;on_job_exit valid pjob: 0x13e3600 (substate=50)
01/03/2015 19:38:04;0008;PBS_Server;Job;NULL;on_job_exit valid pjob: 0x13e3600 (substate=51)
01/03/2015 19:38:13;0008;PBS_Server;Job;NULL;on_job_exit valid pjob: 0x13e3600 (substate=51)
01/03/2015 19:38:13;000d;PBS_Server;Job;46446.tyrone-cluster;Post job file processing error; job 46446.tyrone-cluster on host tyrone-node6/31+tyrone-node6/30+tyrone-node6/29+tyrone-node6/28+tyrone-node6/27+tyrone-node6/26+tyrone-node6/25+tyrone-node6/24+tyrone-node6/23+tyrone-node6/22+tyrone-node6/21+tyrone-node6/20+tyrone-node6/19+tyrone-node6/18+tyrone-node6/17+tyrone-node6/16+tyrone-node6/15+tyrone-node6/14+tyrone-node6/13+tyrone-node6/12+tyrone-node6/11+tyrone-node6/10+tyrone-node6/9+tyrone-node6/8+tyrone-node6/7+tyrone-node6/6+tyrone-node6/5+tyrone-node6/4+tyrone-node6/3+tyrone-node6/2+tyrone-node6/1+tyrone-node6/0+tyrone-node5/31+tyrone-node5/30+tyrone-node5/29+tyrone-node5/28+tyrone-node5/27+tyrone-node5/26+tyrone-node5/25+tyrone-node5/24+tyrone-node5/23+tyrone-node5/22+tyrone-node5/21+tyrone-node5/20+tyrone-node5/19+tyrone-node5/18+tyrone-node5/17+tyrone-node5/16+tyrone-node5/15+tyrone-node5/14+tyrone-node5/13+tyrone-node5/12+tyrone-node5/11+tyrone-node5/10+tyrone-node5/9+tyrone-node5/8+tyrone-node5/7+tyrone-node5/6+tyrone-node5/5+tyrone-node5/4+tyrone-node5/3+tyrone-node5/2+tyrone-node5/1+tyrone-node5/0+tyrone-node4/31+tyrone-node4/30+tyrone-node4/29+tyrone-node4/28+tyrone-node4/27+tyrone-node4/26+tyrone-node4/25+tyrone-node4/24+tyrone-node4/23+tyrone-node4/22+tyrone-node4/21+tyrone-node4/20+tyrone-node4/19+tyrone-node4/18+tyrone-node4/17+tyrone-node4/16+tyrone-node4/15+tyrone-node4/14+tyrone-node4/13+tyrone-node4/12+tyrone-node4/11+tyrone-node4/10+tyrone-node4/9+tyrone-node4/8+tyrone-node4/7+tyrone-node4/6+tyrone-node4/5+tyrone-node4/4+tyrone-node4/3+tyrone-node4/2+tyrone-node4/1+tyrone-node4/0+tyrone-node3/31+tyrone-node3/30+tyrone-node3/29+tyrone-node3/28+tyrone-node3/27+tyrone-node3/26+tyrone-node3/25+tyrone-node3/24+tyrone-node3/23+tyrone-node3/22+tyrone-node3/21+tyrone-node3/20+tyrone-node3/19+tyrone-node3/18+tyrone-node3/17+tyrone-node3/16+tyrone-node3/15+tyrone-node3/14+tyrone-node3/13+tyrone-node3/12+tyrone-node3/11+tyrone-node3/10+tyrone-node3/9+tyrone-node3/8+tyrone-node3/7+tyrone-node3/6+tyrone-node3/5+tyrone-node3/4+tyrone-node3/3+tyrone-node3/2+tyrone-node3/1+tyrone-node3/0
01/03/2015 19:38:13;0008;PBS_Server;Job;NULL;on_job_exit valid pjob: 0x13e3600 (substate=53)
01/03/2015 19:38:13;0100;PBS_Server;Job;46446.tyrone-cluster;dequeuing from qp128, state COMPLETE
01/03/2015 19:38:13;0040;PBS_Server;Svr;tyrone-cluster;Scheduler was sent the command term
01/03/2015 19:38:16;0040;PBS_Server;Svr;tyrone-cluster;Scheduler was sent the command new
01/03/2015 19:38:45;0040;PBS_Server;Svr;tyrone-cluster;Scheduler was sent the command new
01/03/2015 19:38:45;0008;PBS_Server;Job;46445.tyrone-cluster;Job deleted at request of chemraja@tyrone-cluster
01/03/2015 19:38:45;0008;PBS_Server;Job;46445.tyrone-cluster;Job sent signal SIGTERM on delete
01/03/2015 19:38:47;0008;PBS_Server;Job;46445.tyrone-cluster;Job sent signal SIGKILL on delete
01/03/2015 19:38:50;000d;PBS_Server;Job;46445.tyrone-cluster;Not sending email: User does not want mail of this type.
01/03/2015 19:38:50;0010;PBS_Server;Job;46445.tyrone-cluster;Exit_status=143 resources_used.cput=00:25:50 resources_used.mem=142732kb resources_used.vmem=1957988kb resources_used.walltime=00:29:05
01/03/2015 19:38:50;0008;PBS_Server;Job;NULL;on_job_exit valid pjob: 0x130d980 (substate=50)
01/03/2015 19:38:50;0008;PBS_Server;Job;NULL;on_job_exit valid pjob: 0x130d980 (substate=51)
01/03/2015 19:38:50;0008;PBS_Server;Job;NULL;on_job_exit valid pjob: 0x130d980 (substate=51)
01/03/2015 19:38:50;0008;PBS_Server;Job;NULL;on_job_exit valid pjob: 0x130d980 (substate=53)
01/03/2015 19:38:50;0100;PBS_Server;Job;46445.tyrone-cluster;dequeuing from idqueue, state COMPLETE
01/03/2015 19:38:50;0040;PBS_Server;Svr;tyrone-cluster;Scheduler was sent the command term
01/03/2015 19:39:15;0040;PBS_Server;Svr;tyrone-cluster;Scheduler was sent the command new
01/03/2015 19:39:46;0040;PBS_Server;Svr;tyrone-cluster;Scheduler was sent the command new
01/03/2015 19:39:47;0002;PBS_Server;Svr;PBS_Server;Torque Server Version = 3.0.5, loglevel = 0
01/03/2015 19:40:16;0040;PBS_Server;Svr;tyrone-cluster;Scheduler was sent the command new
01/03/2015 19:40:46;0040;PBS_Server;Svr;tyrone-cluster;Scheduler was sent the command new
01/03/2015 19:41:01;0100;PBS_Server;Job;46447.tyrone-cluster;enqueuing into batch, state 1 hop 1
01/03/2015 19:41:01;0100;PBS_Server;Job;46447.tyrone-cluster;dequeuing from batch, state QUEUED
01/03/2015 19:41:01;0100;PBS_Server;Job;46447.tyrone-cluster;enqueuing into qp256, state 1 hop 1
01/03/2015 19:41:01;0008;PBS_Server;Job;46447.tyrone-cluster;Job Queued at request of asepk@tyrone-cluster, owner = asepk@tyrone-cluster, job name = DNsFlo_128, queue = qp256
01/03/2015 19:41:01;0040;PBS_Server;Svr;tyrone-cluster;Scheduler was sent the command new
01/03/2015 19:41:01;0008;PBS_Server;Job;46447.tyrone-cluster;Job Modified at request of Scheduler@tyrone-cluster
01/03/2015 19:41:01;0008;PBS_Server;Job;46447.tyrone-cluster;Job Run at request of Scheduler@tyrone-cluster
01/03/2015 19:41:01;0040;PBS_Server;Svr;tyrone-cluster;Scheduler was sent the command recyc
01/03/2015 19:41:03;000d;PBS_Server;Job;46447.tyrone-cluster;Not sending email: User does not want mail of this type.
01/03/2015 19:41:03;0010;PBS_Server;Job;46447.tyrone-cluster;Exit_status=255 resources_used.cput=00:00:00 resources_used.mem=800kb resources_used.vmem=13624kb resources_used.walltime=00:00:02
01/03/2015 19:41:03;0008;PBS_Server;Job;NULL;on_job_exit valid pjob: 0x13e7520 (substate=50)
01/03/2015 19:41:03;0008;PBS_Server;Job;NULL;on_job_exit valid pjob: 0x13e7520 (substate=51)
01/03/2015 19:41:12;0008;PBS_Server;Job;NULL;on_job_exit valid pjob: 0x13e7520 (substate=51)
01/03/2015 19:41:12;000d;PBS_Server;Job;46447.tyrone-cluster;Post job file processing error; job 46447.tyrone-cluster on host tyrone-node16/63+tyrone-node16/62+tyrone-node16/61+tyrone-node16/60+tyrone-node16/59+tyrone-node16/58+tyrone-node16/57+tyrone-node16/56+tyrone-node16/55+tyrone-node16/54+tyrone-node16/53+tyrone-node16/52+tyrone-node16/51+tyrone-node16/50+tyrone-node16/49+tyrone-node16/48+tyrone-node16/47+tyrone-node16/46+tyrone-node16/45+tyrone-node16/44+tyrone-node16/43+tyrone-node16/42+tyrone-node16/41+tyrone-node16/40+tyrone-node16/39+tyrone-node16/38+tyrone-node16/37+tyrone-node16/36+tyrone-node16/35+tyrone-node16/34+tyrone-node16/33+tyrone-node16/32+tyrone-node16/31+tyrone-node16/30+tyrone-node16/29+tyrone-node16/28+tyrone-node16/27+tyrone-node16/26+tyrone-node16/25+tyrone-node16/24+tyrone-node16/23+tyrone-node16/22+tyrone-node16/21+tyrone-node16/20+tyrone-node16/19+tyrone-node16/18+tyrone-node16/17+tyrone-node16/16+tyrone-node16/15+tyrone-node16/14+tyrone-node16/13+tyrone-node16/12+tyrone-node16/11+tyrone-node16/10+tyrone-node16/9+tyrone-node16/8+tyrone-node16/7+tyrone-node16/6+tyrone-node16/5+tyrone-node16/4+tyrone-node16/3+tyrone-node16/2+tyrone-node16/1+tyrone-node16/0+tyrone-node15/63+tyrone-node15/62+tyrone-node15/61+tyrone-node15/60+tyrone-node15/59+tyrone-node15/58+tyrone-node15/57+tyrone-node15/56+tyrone-node15/55+tyrone-node15/54+tyrone-node15/53+tyrone-node15/52+tyrone-node15/51+tyrone-node15/50+tyrone-node15/49+tyrone-node15/48+tyrone-node15/47+tyrone-node15/46+tyrone-node15/45+tyrone-node15/44+tyrone-node15/43+tyrone-node15/42+tyrone-node15/41+tyrone-node15/40+tyrone-node15/39+tyrone-node15/38+tyrone-node15/37+tyrone-node15/36+tyrone-node15/35+tyrone-node15/34+tyrone-node15/33+tyrone-node15/32+tyrone-node15/31+tyrone-node15/30+tyrone-node15/29+tyrone-node15/28+tyrone-node15/27+tyrone-node15/26+tyrone-node15/25+tyrone-node15/24+tyrone-node15/23+tyrone-node15/22+tyrone-node15/21+tyrone-node15/20+tyrone-node15/19+tyrone-node15/18+tyrone-node15/17+tyrone-node15/16+tyrone-node15/15+tyrone-node15/14+tyrone-node15/13+tyrone-node15/12+tyrone-node15/11+tyrone-node15/10+tyrone-node15/9+tyrone-node15/8+tyrone-node15/7+tyrone-node15/6+tyrone-node15/5+tyrone-node15/4+tyrone-node15/3+tyrone-node15/2+tyrone-node15/1+tyrone-node15/0+tyrone-node14/63+tyrone-node14/62+tyrone-node14/61+tyrone-node14/60+tyrone-node14/59+tyrone-node14/58+tyrone-node14/57+tyrone-node14/56+tyrone-node14/55+tyrone-node14/54+tyrone-node14/53+tyrone-node14/52+tyrone-node14/51+tyrone-node14/50+tyrone-node14/49+tyrone-node14/48+tyrone-node14/47+tyrone-node14/46+tyrone-node14/45+tyrone-node14/44+tyrone-node14/43+tyrone-node14/42+tyrone-node14/41+tyrone-node14/40+tyrone-node14/39+tyrone-node14/38+tyrone-node14/37+tyrone-node14/36+tyrone-node14/35+tyrone-node14/34+tyrone-node14/33+tyrone-node14/32+tyrone-node14/31+tyrone-node14/30+tyrone-node14/29+tyrone-node14/28+tyrone-node14/27+tyrone-node14/26+tyrone-node14/25+tyrone-node14/24+tyrone-node14/23+tyrone-node14/22+tyrone-node14/21+tyrone-node14/20+tyrone-node14/19+tyrone-node14/18+tyrone-node14/17+tyrone-node14/16+tyrone-node14/15+tyrone-node14/14+tyrone-node14/13+tyrone-node14/12+tyrone-node14/11+tyrone-node14/10+tyrone-node14/9+tyrone-node14/8+tyrone-node14/7+tyrone-node14/6+tyrone-node14/5+tyrone-node14/4+tyrone-node14/3+tyrone-node14/2+tyrone-node14/1+tyrone-node14/0+tyrone-node13/63+tyrone-node13/62+tyrone-node13/61+tyrone-node13/60+tyrone-node13/59+tyrone-node13/58+tyrone-node13/57+tyrone-node13/56+tyrone-node13/55+tyrone-node13/54+tyrone-node13/53+tyrone-node13/52+tyrone-node13/51+tyrone-node13/50+tyrone-node13/49+tyrone-node13/48+tyrone-node13/47+tyrone-node13/46+tyrone-node13/45+tyrone-node13/44+tyrone-node13/43+tyrone-node13/42+tyrone-node13/41+tyrone-node13/40+tyrone-node13/39+tyrone-node13/38+tyrone-node13/37+tyrone-node13/36+tyrone-node13/35+tyrone-node13/34+tyrone-node13/33+tyrone-node13/32+tyrone-node13/31+tyrone-node13/30+tyrone-node13/29+tyrone-node13/28+tyrone-node13/27+tyrone-node13/26+tyrone-node13/25+tyrone-node13/24+tyrone-node13/23+tyrone-node13/22+tyrone-node13/21+tyrone-node13/20+tyrone-node13/19+tyrone-node13/18+tyrone-node13/17+tyrone-node13/16+tyrone-node13/15+tyrone-node13/14+tyrone-node13/13+tyrone-node13/12+tyrone-node13/11+tyrone-node13/10+tyrone-node13/9+tyrone-node13/8+tyrone-node13/7+tyrone-node13/6+tyrone-node13/5+tyrone-node13/4+tyrone-node13/3+tyrone-node13/2+tyrone-node13/1+tyrone-node13/0
01/03/2015 19:41:12;0008;PBS_Server;Job;NULL;on_job_exit valid pjob: 0x13e7520 (substate=53)
01/03/2015 19:41:12;0100;PBS_Server;Job;46447.tyrone-cluster;dequeuing from qp256, state COMPLETE
01/03/2015 19:41:12;0040;PBS_Server;Svr;tyrone-cluster;Scheduler was sent the command term
01/03/2015 19:41:16;0040;PBS_Server;Svr;tyrone-cluster;Scheduler was sent the command new
01/03/2015 19:41:46;0040;PBS_Server;Svr;tyrone-cluster;Scheduler was sent the command new
01/03/2015 19:42:17;0040;PBS_Server;Svr;tyrone-cluster;Scheduler was sent the command new
01/03/2015 19:42:47;0040;PBS_Server;Svr;tyrone-cluster;Scheduler was sent the command new
01/03/2015 19:43:17;0040;PBS_Server;Svr;tyrone-cluster;Scheduler was sent the command new
01/03/2015 19:43:47;0040;PBS_Server;Svr;tyrone-cluster;Scheduler was sent the command new
01/03/2015 19:43:49;0100;PBS_Server;Job;46448.tyrone-cluster;enqueuing into batch, state 1 hop 1
01/03/2015 19:43:49;0100;PBS_Server;Job;46448.tyrone-cluster;dequeuing from batch, state QUEUED
01/03/2015 19:43:49;0100;PBS_Server;Job;46448.tyrone-cluster;enqueuing into qp128, state 1 hop 1
01/03/2015 19:43:49;0008;PBS_Server;Job;46448.tyrone-cluster;Job Queued at request of asepk@tyrone-cluster, owner = asepk@tyrone-cluster, job name = DNsFlo_128, queue = qp128
01/03/2015 19:43:49;0040;PBS_Server;Svr;tyrone-cluster;Scheduler was sent the command new
01/03/2015 19:43:50;0008;PBS_Server;Job;46448.tyrone-cluster;Job Modified at request of Scheduler@tyrone-cluster
01/03/2015 19:43:50;0008;PBS_Server;Job;46448.tyrone-cluster;Job Run at request of Scheduler@tyrone-cluster
01/03/2015 19:43:50;0040;PBS_Server;Svr;tyrone-cluster;Scheduler was sent the command recyc
01/03/2015 19:43:55;000d;PBS_Server;Job;46448.tyrone-cluster;Not sending email: User does not want mail of this type.
01/03/2015 19:43:55;0010;PBS_Server;Job;46448.tyrone-cluster;Exit_status=255 resources_used.cput=00:00:47 resources_used.mem=796kb resources_used.vmem=13624kb resources_used.walltime=00:00:05
01/03/2015 19:43:55;0008;PBS_Server;Job;NULL;on_job_exit valid pjob: 0x13e3600 (substate=50)
01/03/2015 19:43:55;0008;PBS_Server;Job;NULL;on_job_exit valid pjob: 0x13e3600 (substate=51)
01/03/2015 19:44:04;0008;PBS_Server;Job;NULL;on_job_exit valid pjob: 0x13e3600 (substate=51)
01/03/2015 19:44:04;000d;PBS_Server;Job;46448.tyrone-cluster;Post job file processing error; job 46448.tyrone-cluster on host tyrone-node6/31+tyrone-node6/30+tyrone-node6/29+tyrone-node6/28+tyrone-node6/27+tyrone-node6/26+tyrone-node6/25+tyrone-node6/24+tyrone-node6/23+tyrone-node6/22+tyrone-node6/21+tyrone-node6/20+tyrone-node6/19+tyrone-node6/18+tyrone-node6/17+tyrone-node6/16+tyrone-node6/15+tyrone-node6/14+tyrone-node6/13+tyrone-node6/12+tyrone-node6/11+tyrone-node6/10+tyrone-node6/9+tyrone-node6/8+tyrone-node6/7+tyrone-node6/6+tyrone-node6/5+tyrone-node6/4+tyrone-node6/3+tyrone-node6/2+tyrone-node6/1+tyrone-node6/0+tyrone-node5/31+tyrone-node5/30+tyrone-node5/29+tyrone-node5/28+tyrone-node5/27+tyrone-node5/26+tyrone-node5/25+tyrone-node5/24+tyrone-node5/23+tyrone-node5/22+tyrone-node5/21+tyrone-node5/20+tyrone-node5/19+tyrone-node5/18+tyrone-node5/17+tyrone-node5/16+tyrone-node5/15+tyrone-node5/14+tyrone-node5/13+tyrone-node5/12+tyrone-node5/11+tyrone-node5/10+tyrone-node5/9+tyrone-node5/8+tyrone-node5/7+tyrone-node5/6+tyrone-node5/5+tyrone-node5/4+tyrone-node5/3+tyrone-node5/2+tyrone-node5/1+tyrone-node5/0+tyrone-node4/31+tyrone-node4/30+tyrone-node4/29+tyrone-node4/28+tyrone-node4/27+tyrone-node4/26+tyrone-node4/25+tyrone-node4/24+tyrone-node4/23+tyrone-node4/22+tyrone-node4/21+tyrone-node4/20+tyrone-node4/19+tyrone-node4/18+tyrone-node4/17+tyrone-node4/16+tyrone-node4/15+tyrone-node4/14+tyrone-node4/13+tyrone-node4/12+tyrone-node4/11+tyrone-node4/10+tyrone-node4/9+tyrone-node4/8+tyrone-node4/7+tyrone-node4/6+tyrone-node4/5+tyrone-node4/4+tyrone-node4/3+tyrone-node4/2+tyrone-node4/1+tyrone-node4/0+tyrone-node3/31+tyrone-node3/30+tyrone-node3/29+tyrone-node3/28+tyrone-node3/27+tyrone-node3/26+tyrone-node3/25+tyrone-node3/24+tyrone-node3/23+tyrone-node3/22+tyrone-node3/21+tyrone-node3/20+tyrone-node3/19+tyrone-node3/18+tyrone-node3/17+tyrone-node3/16+tyrone-node3/15+tyrone-node3/14+tyrone-node3/13+tyrone-node3/12+tyrone-node3/11+tyrone-node3/10+tyrone-node3/9+tyrone-node3/8+tyrone-node3/7+tyrone-node3/6+tyrone-node3/5+tyrone-node3/4+tyrone-node3/3+tyrone-node3/2+tyrone-node3/1+tyrone-node3/0
01/03/2015 19:44:04;0008;PBS_Server;Job;NULL;on_job_exit valid pjob: 0x13e3600 (substate=53)
01/03/2015 19:44:04;0100;PBS_Server;Job;46448.tyrone-cluster;dequeuing from qp128, state COMPLETE
01/03/2015 19:44:04;0040;PBS_Server;Svr;tyrone-cluster;Scheduler was sent the command term
01/03/2015 19:44:17;0040;PBS_Server;Svr;tyrone-cluster;Scheduler was sent the command new
01/03/2015 19:44:26;0100;PBS_Server;Job;46449.tyrone-cluster;enqueuing into batch, state 1 hop 1
01/03/2015 19:44:26;0100;PBS_Server;Job;46449.tyrone-cluster;dequeuing from batch, state QUEUED
01/03/2015 19:44:26;0100;PBS_Server;Job;46449.tyrone-cluster;enqueuing into qp128, state 1 hop 1
01/03/2015 19:44:26;0008;PBS_Server;Job;46449.tyrone-cluster;Job Queued at request of asepk@tyrone-cluster, owner = asepk@tyrone-cluster, job name = DNsFlo_128, queue = qp128
01/03/2015 19:44:26;0040;PBS_Server;Svr;tyrone-cluster;Scheduler was sent the command new
01/03/2015 19:44:26;0008;PBS_Server;Job;46449.tyrone-cluster;Job Modified at request of Scheduler@tyrone-cluster
01/03/2015 19:44:26;0008;PBS_Server;Job;46449.tyrone-cluster;Job Run at request of Scheduler@tyrone-cluster
01/03/2015 19:44:26;0040;PBS_Server;Svr;tyrone-cluster;Scheduler was sent the command recyc
01/03/2015 19:44:30;000d;PBS_Server;Job;46449.tyrone-cluster;Not sending email: User does not want mail of this type.
01/03/2015 19:44:30;0010;PBS_Server;Job;46449.tyrone-cluster;Exit_status=255 resources_used.cput=00:00:45 resources_used.mem=800kb resources_used.vmem=13624kb resources_used.walltime=00:00:04
01/03/2015 19:44:30;0008;PBS_Server;Job;NULL;on_job_exit valid pjob: 0x1417520 (substate=50)
01/03/2015 19:44:30;0008;PBS_Server;Job;NULL;on_job_exit valid pjob: 0x1417520 (substate=51)
01/03/2015 19:44:38;0008;PBS_Server;Job;NULL;on_job_exit valid pjob: 0x1417520 (substate=51)
01/03/2015 19:44:38;000d;PBS_Server;Job;46449.tyrone-cluster;Post job file processing error; job 46449.tyrone-cluster on host tyrone-node6/31+tyrone-node6/30+tyrone-node6/29+tyrone-node6/28+tyrone-node6/27+tyrone-node6/26+tyrone-node6/25+tyrone-node6/24+tyrone-node6/23+tyrone-node6/22+tyrone-node6/21+tyrone-node6/20+tyrone-node6/19+tyrone-node6/18+tyrone-node6/17+tyrone-node6/16+tyrone-node6/15+tyrone-node6/14+tyrone-node6/13+tyrone-node6/12+tyrone-node6/11+tyrone-node6/10+tyrone-node6/9+tyrone-node6/8+tyrone-node6/7+tyrone-node6/6+tyrone-node6/5+tyrone-node6/4+tyrone-node6/3+tyrone-node6/2+tyrone-node6/1+tyrone-node6/0+tyrone-node5/31+tyrone-node5/30+tyrone-node5/29+tyrone-node5/28+tyrone-node5/27+tyrone-node5/26+tyrone-node5/25+tyrone-node5/24+tyrone-node5/23+tyrone-node5/22+tyrone-node5/21+tyrone-node5/20+tyrone-node5/19+tyrone-node5/18+tyrone-node5/17+tyrone-node5/16+tyrone-node5/15+tyrone-node5/14+tyrone-node5/13+tyrone-node5/12+tyrone-node5/11+tyrone-node5/10+tyrone-node5/9+tyrone-node5/8+tyrone-node5/7+tyrone-node5/6+tyrone-node5/5+tyrone-node5/4+tyrone-node5/3+tyrone-node5/2+tyrone-node5/1+tyrone-node5/0+tyrone-node4/31+tyrone-node4/30+tyrone-node4/29+tyrone-node4/28+tyrone-node4/27+tyrone-node4/26+tyrone-node4/25+tyrone-node4/24+tyrone-node4/23+tyrone-node4/22+tyrone-node4/21+tyrone-node4/20+tyrone-node4/19+tyrone-node4/18+tyrone-node4/17+tyrone-node4/16+tyrone-node4/15+tyrone-node4/14+tyrone-node4/13+tyrone-node4/12+tyrone-node4/11+tyrone-node4/10+tyrone-node4/9+tyrone-node4/8+tyrone-node4/7+tyrone-node4/6+tyrone-node4/5+tyrone-node4/4+tyrone-node4/3+tyrone-node4/2+tyrone-node4/1+tyrone-node4/0+tyrone-node3/31+tyrone-node3/30+tyrone-node3/29+tyrone-node3/28+tyrone-node3/27+tyrone-node3/26+tyrone-node3/25+tyrone-node3/24+tyrone-node3/23+tyrone-node3/22+tyrone-node3/21+tyrone-node3/20+tyrone-node3/19+tyrone-node3/18+tyrone-node3/17+tyrone-node3/16+tyrone-node3/15+tyrone-node3/14+tyrone-node3/13+tyrone-node3/12+tyrone-node3/11+tyrone-node3/10+tyrone-node3/9+tyrone-node3/8+tyrone-node3/7+tyrone-node3/6+tyrone-node3/5+tyrone-node3/4+tyrone-node3/3+tyrone-node3/2+tyrone-node3/1+tyrone-node3/0
01/03/2015 19:44:38;0008;PBS_Server;Job;NULL;on_job_exit valid pjob: 0x1417520 (substate=53)
01/03/2015 19:44:38;0100;PBS_Server;Job;46449.tyrone-cluster;dequeuing from qp128, state COMPLETE
01/03/2015 19:44:38;0040;PBS_Server;Svr;tyrone-cluster;Scheduler was sent the command term
01/03/2015 19:44:47;0002;PBS_Server;Svr;PBS_Server;Torque Server Version = 3.0.5, loglevel = 0
01/03/2015 19:44:47;0040;PBS_Server;Svr;tyrone-cluster;Scheduler was sent the command new
01/03/2015 19:45:17;0040;PBS_Server;Svr;tyrone-cluster;Scheduler was sent the command new
01/03/2015 19:45:47;0040;PBS_Server;Svr;tyrone-cluster;Scheduler was sent the command new
01/03/2015 19:46:17;0040;PBS_Server;Svr;tyrone-cluster;Scheduler was sent the command new
01/03/2015 19:46:19;0100;PBS_Server;Job;46450.tyrone-cluster;enqueuing into batch, state 1 hop 1
01/03/2015 19:46:19;0100;PBS_Server;Job;46450.tyrone-cluster;dequeuing from batch, state QUEUED
01/03/2015 19:46:19;0100;PBS_Server;Job;46450.tyrone-cluster;enqueuing into qp128, state 1 hop 1
01/03/2015 19:46:19;0008;PBS_Server;Job;46450.tyrone-cluster;Job Queued at request of asepk@tyrone-cluster, owner = asepk@tyrone-cluster, job name = DNsFlo_128, queue = qp128
01/03/2015 19:46:19;0040;PBS_Server;Svr;tyrone-cluster;Scheduler was sent the command new
01/03/2015 19:46:19;0008;PBS_Server;Job;46450.tyrone-cluster;Job Modified at request of Scheduler@tyrone-cluster
01/03/2015 19:46:19;0008;PBS_Server;Job;46450.tyrone-cluster;Job Run at request of Scheduler@tyrone-cluster
01/03/2015 19:46:19;0040;PBS_Server;Svr;tyrone-cluster;Scheduler was sent the command recyc
01/03/2015 19:46:29;000d;PBS_Server;Job;46450.tyrone-cluster;Not sending email: User does not want mail of this type.
01/03/2015 19:46:29;0010;PBS_Server;Job;46450.tyrone-cluster;Exit_status=255 resources_used.cput=00:02:28 resources_used.mem=800kb resources_used.vmem=13624kb resources_used.walltime=00:00:10
01/03/2015 19:46:29;0008;PBS_Server;Job;NULL;on_job_exit valid pjob: 0x13e7520 (substate=50)
01/03/2015 19:46:29;0008;PBS_Server;Job;NULL;on_job_exit valid pjob: 0x13e7520 (substate=51)
01/03/2015 19:46:37;0008;PBS_Server;Job;NULL;on_job_exit valid pjob: 0x13e7520 (substate=51)
01/03/2015 19:46:37;000d;PBS_Server;Job;46450.tyrone-cluster;Post job file processing error; job 46450.tyrone-cluster on host tyrone-node6/31+tyrone-node6/30+tyrone-node6/29+tyrone-node6/28+tyrone-node6/27+tyrone-node6/26+tyrone-node6/25+tyrone-node6/24+tyrone-node6/23+tyrone-node6/22+tyrone-node6/21+tyrone-node6/20+tyrone-node6/19+tyrone-node6/18+tyrone-node6/17+tyrone-node6/16+tyrone-node6/15+tyrone-node6/14+tyrone-node6/13+tyrone-node6/12+tyrone-node6/11+tyrone-node6/10+tyrone-node6/9+tyrone-node6/8+tyrone-node6/7+tyrone-node6/6+tyrone-node6/5+tyrone-node6/4+tyrone-node6/3+tyrone-node6/2+tyrone-node6/1+tyrone-node6/0+tyrone-node5/31+tyrone-node5/30+tyrone-node5/29+tyrone-node5/28+tyrone-node5/27+tyrone-node5/26+tyrone-node5/25+tyrone-node5/24+tyrone-node5/23+tyrone-node5/22+tyrone-node5/21+tyrone-node5/20+tyrone-node5/19+tyrone-node5/18+tyrone-node5/17+tyrone-node5/16+tyrone-node5/15+tyrone-node5/14+tyrone-node5/13+tyrone-node5/12+tyrone-node5/11+tyrone-node5/10+tyrone-node5/9+tyrone-node5/8+tyrone-node5/7+tyrone-node5/6+tyrone-node5/5+tyrone-node5/4+tyrone-node5/3+tyrone-node5/2+tyrone-node5/1+tyrone-node5/0+tyrone-node4/31+tyrone-node4/30+tyrone-node4/29+tyrone-node4/28+tyrone-node4/27+tyrone-node4/26+tyrone-node4/25+tyrone-node4/24+tyrone-node4/23+tyrone-node4/22+tyrone-node4/21+tyrone-node4/20+tyrone-node4/19+tyrone-node4/18+tyrone-node4/17+tyrone-node4/16+tyrone-node4/15+tyrone-node4/14+tyrone-node4/13+tyrone-node4/12+tyrone-node4/11+tyrone-node4/10+tyrone-node4/9+tyrone-node4/8+tyrone-node4/7+tyrone-node4/6+tyrone-node4/5+tyrone-node4/4+tyrone-node4/3+tyrone-node4/2+tyrone-node4/1+tyrone-node4/0+tyrone-node3/31+tyrone-node3/30+tyrone-node3/29+tyrone-node3/28+tyrone-node3/27+tyrone-node3/26+tyrone-node3/25+tyrone-node3/24+tyrone-node3/23+tyrone-node3/22+tyrone-node3/21+tyrone-node3/20+tyrone-node3/19+tyrone-node3/18+tyrone-node3/17+tyrone-node3/16+tyrone-node3/15+tyrone-node3/14+tyrone-node3/13+tyrone-node3/12+tyrone-node3/11+tyrone-node3/10+tyrone-node3/9+tyrone-node3/8+tyrone-node3/7+tyrone-node3/6+tyrone-node3/5+tyrone-node3/4+tyrone-node3/3+tyrone-node3/2+tyrone-node3/1+tyrone-node3/0
01/03/2015 19:46:37;0008;PBS_Server;Job;NULL;on_job_exit valid pjob: 0x13e7520 (substate=53)
01/03/2015 19:46:37;0100;PBS_Server;Job;46450.tyrone-cluster;dequeuing from qp128, state COMPLETE
01/03/2015 19:46:37;0040;PBS_Server;Svr;tyrone-cluster;Scheduler was sent the command term
01/03/2015 19:46:47;0040;PBS_Server;Svr;tyrone-cluster;Scheduler was sent the command new
01/03/2015 19:47:18;0040;PBS_Server;Svr;tyrone-cluster;Scheduler was sent the command new
01/03/2015 19:47:29;0100;PBS_Server;Job;46451.tyrone-cluster;enqueuing into batch, state 1 hop 1
01/03/2015 19:47:29;0100;PBS_Server;Job;46451.tyrone-cluster;dequeuing from batch, state QUEUED
01/03/2015 19:47:29;0100;PBS_Server;Job;46451.tyrone-cluster;enqueuing into idqueue, state 1 hop 1
01/03/2015 19:47:29;0008;PBS_Server;Job;46451.tyrone-cluster;Job Queued at request of chemraja@tyrone-cluster, owner = chemraja@tyrone-cluster, job name = test.sh, queue = idqueue
01/03/2015 19:47:29;0040;PBS_Server;Svr;tyrone-cluster;Scheduler was sent the command new
01/03/2015 19:47:29;0008;PBS_Server;Job;46451.tyrone-cluster;Job Modified at request of Scheduler@tyrone-cluster
01/03/2015 19:47:29;0008;PBS_Server;Job;46451.tyrone-cluster;Job Run at request of Scheduler@tyrone-cluster
01/03/2015 19:47:29;0040;PBS_Server;Svr;tyrone-cluster;Scheduler was sent the command recyc
01/03/2015 19:47:29;000d;PBS_Server;Job;46451.tyrone-cluster;Not sending email: User does not want mail of this type.
01/03/2015 19:47:48;0040;PBS_Server;Svr;tyrone-cluster;Scheduler was sent the command new
01/03/2015 19:48:18;0040;PBS_Server;Svr;tyrone-cluster;Scheduler was sent the command new
01/03/2015 19:48:48;0040;PBS_Server;Svr;tyrone-cluster;Scheduler was sent the command new
01/03/2015 19:49:18;0040;PBS_Server;Svr;tyrone-cluster;Scheduler was sent the command new
01/03/2015 19:49:47;0002;PBS_Server;Svr;PBS_Server;Torque Server Version = 3.0.5, loglevel = 0
01/03/2015 19:49:48;0040;PBS_Server;Svr;tyrone-cluster;Scheduler was sent the command new
01/03/2015 19:50:18;0040;PBS_Server;Svr;tyrone-cluster;Scheduler was sent the command new
01/03/2015 19:50:48;0040;PBS_Server;Svr;tyrone-cluster;Scheduler was sent the command new
01/03/2015 19:51:05;000d;PBS_Server;Job;46451.tyrone-cluster;Not sending email: User does not want mail of this type.
01/03/2015 19:51:05;0010;PBS_Server;Job;46451.tyrone-cluster;Exit_status=0 resources_used.cput=00:03:15 resources_used.mem=105668kb resources_used.vmem=1957988kb resources_used.walltime=00:03:36
01/03/2015 19:51:05;0008;PBS_Server;Job;NULL;on_job_exit valid pjob: 0x13e7520 (substate=50)
01/03/2015 19:51:05;0008;PBS_Server;Job;NULL;on_job_exit valid pjob: 0x13e7520 (substate=51)
01/03/2015 19:51:05;0008;PBS_Server;Job;NULL;on_job_exit valid pjob: 0x13e7520 (substate=51)
01/03/2015 19:51:05;0008;PBS_Server;Job;NULL;on_job_exit valid pjob: 0x13e7520 (substate=53)
01/03/2015 19:51:05;0100;PBS_Server;Job;46451.tyrone-cluster;dequeuing from idqueue, state COMPLETE
01/03/2015 19:51:05;0040;PBS_Server;Svr;tyrone-cluster;Scheduler was sent the command term
01/03/2015 19:51:18;0040;PBS_Server;Svr;tyrone-cluster;Scheduler was sent the command new
01/03/2015 19:51:48;0040;PBS_Server;Svr;tyrone-cluster;Scheduler was sent the command new
01/03/2015 19:52:19;0040;PBS_Server;Svr;tyrone-cluster;Scheduler was sent the command new
01/03/2015 19:52:49;0040;PBS_Server;Svr;tyrone-cluster;Scheduler was sent the command new
01/03/2015 19:53:19;0040;PBS_Server;Svr;tyrone-cluster;Scheduler was sent the command new
01/03/2015 19:53:33;0100;PBS_Server;Job;46452.tyrone-cluster;enqueuing into batch, state 1 hop 1
01/03/2015 19:53:33;0100;PBS_Server;Job;46452.tyrone-cluster;dequeuing from batch, state QUEUED
01/03/2015 19:53:33;0100;PBS_Server;Job;46452.tyrone-cluster;enqueuing into qp128, state 1 hop 1
01/03/2015 19:53:33;0008;PBS_Server;Job;46452.tyrone-cluster;Job Queued at request of aseabwit@tyrone-cluster, owner = aseabwit@tyrone-cluster, job name = DNsFlo_128, queue = qp128
01/03/2015 19:53:33;0040;PBS_Server;Svr;tyrone-cluster;Scheduler was sent the command new
01/03/2015 19:53:33;0008;PBS_Server;Job;46452.tyrone-cluster;Job Modified at request of Scheduler@tyrone-cluster
01/03/2015 19:53:33;0008;PBS_Server;Job;46452.tyrone-cluster;Job Run at request of Scheduler@tyrone-cluster
01/03/2015 19:53:33;0040;PBS_Server;Svr;tyrone-cluster;Scheduler was sent the command recyc
01/03/2015 19:53:49;0040;PBS_Server;Svr;tyrone-cluster;Scheduler was sent the command new
01/03/2015 19:54:10;000d;PBS_Server;Job;46452.tyrone-cluster;Not sending email: User does not want mail of this type.
01/03/2015 19:54:19;0040;PBS_Server;Svr;tyrone-cluster;Scheduler was sent the command new
01/03/2015 19:54:47;0002;PBS_Server;Svr;PBS_Server;Torque Server Version = 3.0.5, loglevel = 0
01/03/2015 19:54:49;0040;PBS_Server;Svr;tyrone-cluster;Scheduler was sent the command new
01/03/2015 19:55:19;0040;PBS_Server;Svr;tyrone-cluster;Scheduler was sent the command new
01/03/2015 19:55:49;0040;PBS_Server;Svr;tyrone-cluster;Scheduler was sent the command new
01/03/2015 19:56:19;0040;PBS_Server;Svr;tyrone-cluster;Scheduler was sent the command new
01/03/2015 19:56:50;0040;PBS_Server;Svr;tyrone-cluster;Scheduler was sent the command new
01/03/2015 19:57:19;0040;PBS_Server;Svr;tyrone-cluster;Scheduler was sent the command new
01/03/2015 19:57:50;0040;PBS_Server;Svr;tyrone-cluster;Scheduler was sent the command new
01/03/2015 19:58:20;0040;PBS_Server;Svr;tyrone-cluster;Scheduler was sent the command new
01/03/2015 19:58:50;0040;PBS_Server;Svr;tyrone-cluster;Scheduler was sent the command new
01/03/2015 19:59:20;0040;PBS_Server;Svr;tyrone-cluster;Scheduler was sent the command new
01/03/2015 19:59:47;0002;PBS_Server;Svr;PBS_Server;Torque Server Version = 3.0.5, loglevel = 0
01/03/2015 19:59:50;0040;PBS_Server;Svr;tyrone-cluster;Scheduler was sent the command new
01/03/2015 20:00:20;0040;PBS_Server;Svr;tyrone-cluster;Scheduler was sent the command new
01/03/2015 20:00:50;0040;PBS_Server;Svr;tyrone-cluster;Scheduler was sent the command new
01/03/2015 20:01:20;0040;PBS_Server;Svr;tyrone-cluster;Scheduler was sent the command new
01/03/2015 20:01:51;0040;PBS_Server;Svr;tyrone-cluster;Scheduler was sent the command new
01/03/2015 20:01:59;0008;PBS_Server;Job;46452.tyrone-cluster;Job deleted at request of aseabwit@tyrone-cluster
01/03/2015 20:01:59;0008;PBS_Server;Job;46452.tyrone-cluster;Job sent signal SIGTERM on delete
01/03/2015 20:01:59;000d;PBS_Server;Job;46452.tyrone-cluster;Not sending email: User does not want mail of this type.
01/03/2015 20:01:59;0010;PBS_Server;Job;46452.tyrone-cluster;Exit_status=143 resources_used.cput=00:07:41 resources_used.mem=294560kb resources_used.vmem=3716064kb resources_used.walltime=00:08:26
01/03/2015 20:01:59;0008;PBS_Server;Job;NULL;on_job_exit valid pjob: 0x13e7520 (substate=50)
01/03/2015 20:01:59;0008;PBS_Server;Job;NULL;on_job_exit valid pjob: 0x13e7520 (substate=51)
01/03/2015 20:02:00;0008;PBS_Server;Job;NULL;on_job_exit valid pjob: 0x13e7520 (substate=51)
01/03/2015 20:02:00;0008;PBS_Server;Job;NULL;on_job_exit valid pjob: 0x13e7520 (substate=53)
01/03/2015 20:02:00;0100;PBS_Server;Job;46452.tyrone-cluster;dequeuing from qp128, state COMPLETE
01/03/2015 20:02:00;0040;PBS_Server;Svr;tyrone-cluster;Scheduler was sent the command term
01/03/2015 20:02:21;0040;PBS_Server;Svr;tyrone-cluster;Scheduler was sent the command new
01/03/2015 20:02:51;0040;PBS_Server;Svr;tyrone-cluster;Scheduler was sent the command new
01/03/2015 20:03:21;0040;PBS_Server;Svr;tyrone-cluster;Scheduler was sent the command new
01/03/2015 20:03:51;0040;PBS_Server;Svr;tyrone-cluster;Scheduler was sent the command new
01/03/2015 20:04:21;0040;PBS_Server;Svr;tyrone-cluster;Scheduler was sent the command new
01/03/2015 20:04:47;0002;PBS_Server;Svr;PBS_Server;Torque Server Version = 3.0.5, loglevel = 0
01/03/2015 20:04:51;0040;PBS_Server;Svr;tyrone-cluster;Scheduler was sent the command new
01/03/2015 20:05:21;0040;PBS_Server;Svr;tyrone-cluster;Scheduler was sent the command new
01/03/2015 20:05:45;0008;PBS_Server;Job;46406.tyrone-cluster;Job deleted at request of asepk@tyrone-cluster
01/03/2015 20:05:45;0008;PBS_Server;Job;46406.tyrone-cluster;Job sent signal SIGTERM on delete
01/03/2015 20:05:47;0008;PBS_Server;Job;46406.tyrone-cluster;Job sent signal SIGKILL on delete
01/03/2015 20:05:47;000d;PBS_Server;Job;46406.tyrone-cluster;Not sending email: User does not want mail of this type.
01/03/2015 20:05:47;0010;PBS_Server;Job;46406.tyrone-cluster;Exit_status=143 resources_used.cput=255:40:16 resources_used.mem=2232688kb resources_used.vmem=8702352kb resources_used.walltime=09:10:12
01/03/2015 20:05:47;0008;PBS_Server;Job;NULL;on_job_exit valid pjob: 0x12fe400 (substate=50)
01/03/2015 20:05:47;0008;PBS_Server;Job;NULL;on_job_exit valid pjob: 0x12fe400 (substate=51)
01/03/2015 20:05:51;0040;PBS_Server;Svr;tyrone-cluster;Scheduler was sent the command new
01/03/2015 20:05:51;0008;PBS_Server;Job;46409.tyrone-cluster;Job Modified at request of Scheduler@tyrone-cluster
01/03/2015 20:05:51;0008;PBS_Server;Job;46409.tyrone-cluster;Job Run at request of Scheduler@tyrone-cluster
01/03/2015 20:05:51;0040;PBS_Server;Svr;tyrone-cluster;Scheduler was sent the command recyc
01/03/2015 20:05:51;000d;PBS_Server;Job;46409.tyrone-cluster;Not sending email: User does not want mail of this type.
01/03/2015 20:05:56;0008;PBS_Server;Job;NULL;on_job_exit valid pjob: 0x12fe400 (substate=51)
01/03/2015 20:05:56;000d;PBS_Server;Job;46406.tyrone-cluster;Post job file processing error; job 46406.tyrone-cluster on host tyrone-node1/31+tyrone-node1/30+tyrone-node1/29+tyrone-node1/28+tyrone-node1/27+tyrone-node1/26+tyrone-node1/25+tyrone-node1/24+tyrone-node1/23+tyrone-node1/22+tyrone-node1/21+tyrone-node1/20+tyrone-node1/19+tyrone-node1/18+tyrone-node1/17+tyrone-node1/16+tyrone-node1/15+tyrone-node1/14+tyrone-node1/13+tyrone-node1/12+tyrone-node1/11+tyrone-node1/10+tyrone-node1/9+tyrone-node1/8+tyrone-node1/7+tyrone-node1/6+tyrone-node1/5+tyrone-node1/4+tyrone-node1/3+tyrone-node1/2+tyrone-node1/1+tyrone-node1/0
01/03/2015 20:05:56;0008;PBS_Server;Job;NULL;on_job_exit valid pjob: 0x12fe400 (substate=53)
01/03/2015 20:05:56;0100;PBS_Server;Job;46406.tyrone-cluster;dequeuing from qp32, state COMPLETE
01/03/2015 20:05:56;0040;PBS_Server;Svr;tyrone-cluster;Scheduler was sent the command term
01/03/2015 20:05:59;000d;PBS_Server;Job;46409.tyrone-cluster;Not sending email: User does not want mail of this type.
01/03/2015 20:05:59;0010;PBS_Server;Job;46409.tyrone-cluster;Exit_status=0 resources_used.cput=00:00:02 resources_used.mem=65664kb resources_used.vmem=256200kb resources_used.walltime=00:00:08
01/03/2015 20:05:59;0008;PBS_Server;Job;NULL;on_job_exit valid pjob: 0x12f1ef0 (substate=50)
01/03/2015 20:05:59;0008;PBS_Server;Job;NULL;on_job_exit valid pjob: 0x12f1ef0 (substate=51)
01/03/2015 20:06:08;0008;PBS_Server;Job;NULL;on_job_exit valid pjob: 0x12f1ef0 (substate=51)
01/03/2015 20:06:08;000d;PBS_Server;Job;46409.tyrone-cluster;Post job file processing error; job 46409.tyrone-cluster on host tyrone-node3/31+tyrone-node3/30+tyrone-node3/29+tyrone-node3/28+tyrone-node3/27+tyrone-node3/26+tyrone-node3/25+tyrone-node3/24+tyrone-node3/23+tyrone-node3/22+tyrone-node3/21+tyrone-node3/20+tyrone-node3/19+tyrone-node3/18+tyrone-node3/17+tyrone-node3/16+tyrone-node3/15+tyrone-node3/14+tyrone-node3/13+tyrone-node3/12+tyrone-node3/11+tyrone-node3/10+tyrone-node3/9+tyrone-node3/8+tyrone-node3/7+tyrone-node3/6+tyrone-node3/5+tyrone-node3/4+tyrone-node3/3+tyrone-node3/2+tyrone-node3/1+tyrone-node3/0
01/03/2015 20:06:08;0008;PBS_Server;Job;NULL;on_job_exit valid pjob: 0x12f1ef0 (substate=53)
01/03/2015 20:06:08;0100;PBS_Server;Job;46409.tyrone-cluster;dequeuing from qp32, state COMPLETE
01/03/2015 20:06:08;0040;PBS_Server;Svr;tyrone-cluster;Scheduler was sent the command term
01/03/2015 20:06:08;0008;PBS_Server;Job;46417.tyrone-cluster;Job Modified at request of Scheduler@tyrone-cluster
01/03/2015 20:06:08;0008;PBS_Server;Job;46417.tyrone-cluster;Job Run at request of Scheduler@tyrone-cluster
01/03/2015 20:06:08;0040;PBS_Server;Svr;tyrone-cluster;Scheduler was sent the command recyc
01/03/2015 20:06:08;000d;PBS_Server;Job;46417.tyrone-cluster;Not sending email: User does not want mail of this type.
01/03/2015 20:06:21;0100;PBS_Server;Job;46410.tyrone-cluster;dequeuing from batch, state QUEUED
01/03/2015 20:06:21;0100;PBS_Server;Job;46410.tyrone-cluster;enqueuing into qp32, state 1 hop 1
01/03/2015 20:06:21;0040;PBS_Server;Svr;tyrone-cluster;Scheduler was sent the command new
01/03/2015 20:06:21;0008;PBS_Server;Job;46410.tyrone-cluster;Job Modified at request of Scheduler@tyrone-cluster
01/03/2015 20:06:30;000d;PBS_Server;Job;46417.tyrone-cluster;Not sending email: User does not want mail of this type.
01/03/2015 20:06:30;0010;PBS_Server;Job;46417.tyrone-cluster;Exit_status=123 resources_used.cput=00:00:19 resources_used.mem=0kb resources_used.vmem=0kb resources_used.walltime=00:00:22
01/03/2015 20:06:30;0008;PBS_Server;Job;NULL;on_job_exit valid pjob: 0x132e370 (substate=50)
01/03/2015 20:06:30;0008;PBS_Server;Job;NULL;on_job_exit valid pjob: 0x132e370 (substate=51)
01/03/2015 20:06:34;0008;PBS_Server;Job;NULL;on_job_exit valid pjob: 0x132e370 (substate=51)
01/03/2015 20:06:34;000d;PBS_Server;Job;46417.tyrone-cluster;Post job file processing error; job 46417.tyrone-cluster on host tyrone-node1/31+tyrone-node1/30+tyrone-node1/29+tyrone-node1/28+tyrone-node1/27+tyrone-node1/26+tyrone-node1/25+tyrone-node1/24+tyrone-node1/23+tyrone-node1/22+tyrone-node1/21+tyrone-node1/20+tyrone-node1/19+tyrone-node1/18+tyrone-node1/17+tyrone-node1/16+tyrone-node1/15+tyrone-node1/14+tyrone-node1/13+tyrone-node1/12+tyrone-node1/11+tyrone-node1/10+tyrone-node1/9+tyrone-node1/8+tyrone-node1/7+tyrone-node1/6+tyrone-node1/5+tyrone-node1/4+tyrone-node1/3+tyrone-node1/2+tyrone-node1/1+tyrone-node1/0
01/03/2015 20:06:34;0008;PBS_Server;Job;NULL;on_job_exit valid pjob: 0x132e370 (substate=53)
01/03/2015 20:06:34;0100;PBS_Server;Job;46417.tyrone-cluster;dequeuing from qp32, state COMPLETE
01/03/2015 20:06:34;0040;PBS_Server;Svr;tyrone-cluster;Scheduler was sent the command term
01/03/2015 20:06:34;0008;PBS_Server;Job;46410.tyrone-cluster;Job Modified at request of Scheduler@tyrone-cluster
01/03/2015 20:06:34;0008;PBS_Server;Job;46410.tyrone-cluster;Job Run at request of Scheduler@tyrone-cluster
01/03/2015 20:06:34;0040;PBS_Server;Svr;tyrone-cluster;Scheduler was sent the command recyc
01/03/2015 20:06:34;000d;PBS_Server;Job;46410.tyrone-cluster;Not sending email: User does not want mail of this type.
01/03/2015 20:06:41;000d;PBS_Server;Job;46410.tyrone-cluster;Not sending email: User does not want mail of this type.
01/03/2015 20:06:41;0010;PBS_Server;Job;46410.tyrone-cluster;Exit_status=0 resources_used.cput=00:00:31 resources_used.mem=531020kb resources_used.vmem=4723600kb resources_used.walltime=00:00:08
01/03/2015 20:06:41;0008;PBS_Server;Job;NULL;on_job_exit valid pjob: 0x13fadd0 (substate=50)
01/03/2015 20:06:41;0008;PBS_Server;Job;NULL;on_job_exit valid pjob: 0x13fadd0 (substate=51)
01/03/2015 20:06:50;0008;PBS_Server;Job;NULL;on_job_exit valid pjob: 0x13fadd0 (substate=51)
01/03/2015 20:06:50;000d;PBS_Server;Job;46410.tyrone-cluster;Post job file processing error; job 46410.tyrone-cluster on host tyrone-node1/31+tyrone-node1/30+tyrone-node1/29+tyrone-node1/28+tyrone-node1/27+tyrone-node1/26+tyrone-node1/25+tyrone-node1/24+tyrone-node1/23+tyrone-node1/22+tyrone-node1/21+tyrone-node1/20+tyrone-node1/19+tyrone-node1/18+tyrone-node1/17+tyrone-node1/16+tyrone-node1/15+tyrone-node1/14+tyrone-node1/13+tyrone-node1/12+tyrone-node1/11+tyrone-node1/10+tyrone-node1/9+tyrone-node1/8+tyrone-node1/7+tyrone-node1/6+tyrone-node1/5+tyrone-node1/4+tyrone-node1/3+tyrone-node1/2+tyrone-node1/1+tyrone-node1/0
01/03/2015 20:06:50;0008;PBS_Server;Job;NULL;on_job_exit valid pjob: 0x13fadd0 (substate=53)
01/03/2015 20:06:50;0100;PBS_Server;Job;46410.tyrone-cluster;dequeuing from qp32, state COMPLETE
01/03/2015 20:06:50;0040;PBS_Server;Svr;tyrone-cluster;Scheduler was sent the command term
01/03/2015 20:06:52;0100;PBS_Server;Job;46411.tyrone-cluster;dequeuing from batch, state QUEUED
01/03/2015 20:06:52;0100;PBS_Server;Job;46411.tyrone-cluster;enqueuing into qp32, state 1 hop 1
01/03/2015 20:06:52;0100;PBS_Server;Job;46418.tyrone-cluster;dequeuing from batch, state QUEUED
01/03/2015 20:06:52;0100;PBS_Server;Job;46418.tyrone-cluster;enqueuing into qp32, state 1 hop 1
01/03/2015 20:06:52;0040;PBS_Server;Svr;tyrone-cluster;Scheduler was sent the command new
01/03/2015 20:06:52;0008;PBS_Server;Job;46411.tyrone-cluster;Job Modified at request of Scheduler@tyrone-cluster
01/03/2015 20:06:52;0008;PBS_Server;Job;46411.tyrone-cluster;Job Run at request of Scheduler@tyrone-cluster
01/03/2015 20:06:52;0008;PBS_Server;Job;46418.tyrone-cluster;Job Modified at request of Scheduler@tyrone-cluster
01/03/2015 20:06:52;0040;PBS_Server;Svr;tyrone-cluster;Scheduler was sent the command recyc
01/03/2015 20:06:52;000d;PBS_Server;Job;46411.tyrone-cluster;Not sending email: User does not want mail of this type.
01/03/2015 20:06:57;0100;PBS_Server;Job;46453.tyrone-cluster;enqueuing into batch, state 1 hop 1
01/03/2015 20:06:57;0100;PBS_Server;Job;46453.tyrone-cluster;dequeuing from batch, state QUEUED
01/03/2015 20:06:57;0100;PBS_Server;Job;46453.tyrone-cluster;enqueuing into qp32, state 1 hop 1
01/03/2015 20:06:57;0008;PBS_Server;Job;46453.tyrone-cluster;Job Queued at request of asepk@tyrone-cluster, owner = asepk@tyrone-cluster, job name = DNsFlo_32, queue = qp32
01/03/2015 20:06:57;0040;PBS_Server;Svr;tyrone-cluster;Scheduler was sent the command new
01/03/2015 20:06:57;0008;PBS_Server;Job;46453.tyrone-cluster;Job Modified at request of Scheduler@tyrone-cluster
01/03/2015 20:06:58;000d;PBS_Server;Job;46411.tyrone-cluster;Not sending email: User does not want mail of this type.
01/03/2015 20:06:58;0010;PBS_Server;Job;46411.tyrone-cluster;Exit_status=0 resources_used.cput=00:00:02 resources_used.mem=0kb resources_used.vmem=0kb resources_used.walltime=00:00:07
01/03/2015 20:06:58;0008;PBS_Server;Job;NULL;on_job_exit valid pjob: 0x1322570 (substate=50)
01/03/2015 20:06:58;0008;PBS_Server;Job;NULL;on_job_exit valid pjob: 0x1322570 (substate=51)
01/03/2015 20:07:07;0008;PBS_Server;Job;NULL;on_job_exit valid pjob: 0x1322570 (substate=51)
01/03/2015 20:07:07;000d;PBS_Server;Job;46411.tyrone-cluster;Post job file processing error; job 46411.tyrone-cluster on host tyrone-node1/31+tyrone-node1/30+tyrone-node1/29+tyrone-node1/28+tyrone-node1/27+tyrone-node1/26+tyrone-node1/25+tyrone-node1/24+tyrone-node1/23+tyrone-node1/22+tyrone-node1/21+tyrone-node1/20+tyrone-node1/19+tyrone-node1/18+tyrone-node1/17+tyrone-node1/16+tyrone-node1/15+tyrone-node1/14+tyrone-node1/13+tyrone-node1/12+tyrone-node1/11+tyrone-node1/10+tyrone-node1/9+tyrone-node1/8+tyrone-node1/7+tyrone-node1/6+tyrone-node1/5+tyrone-node1/4+tyrone-node1/3+tyrone-node1/2+tyrone-node1/1+tyrone-node1/0
01/03/2015 20:07:07;0008;PBS_Server;Job;NULL;on_job_exit valid pjob: 0x1322570 (substate=53)
01/03/2015 20:07:07;0100;PBS_Server;Job;46411.tyrone-cluster;dequeuing from qp32, state COMPLETE
01/03/2015 20:07:07;0040;PBS_Server;Svr;tyrone-cluster;Scheduler was sent the command term
01/03/2015 20:07:07;0008;PBS_Server;Job;46418.tyrone-cluster;Job Modified at request of Scheduler@tyrone-cluster
01/03/2015 20:07:07;0008;PBS_Server;Job;46418.tyrone-cluster;Job Run at request of Scheduler@tyrone-cluster
01/03/2015 20:07:07;0040;PBS_Server;Svr;tyrone-cluster;Scheduler was sent the command recyc
01/03/2015 20:07:07;000d;PBS_Server;Job;46418.tyrone-cluster;Not sending email: User does not want mail of this type.
01/03/2015 20:07:22;0040;PBS_Server;Svr;tyrone-cluster;Scheduler was sent the command new
01/03/2015 20:07:52;0040;PBS_Server;Svr;tyrone-cluster;Scheduler was sent the command new
01/03/2015 20:08:22;0040;PBS_Server;Svr;tyrone-cluster;Scheduler was sent the command new
01/03/2015 20:08:52;0040;PBS_Server;Svr;tyrone-cluster;Scheduler was sent the command new
01/03/2015 20:09:22;0040;PBS_Server;Svr;tyrone-cluster;Scheduler was sent the command new
01/03/2015 20:09:47;0002;PBS_Server;Svr;PBS_Server;Torque Server Version = 3.0.5, loglevel = 0
01/03/2015 20:09:52;0040;PBS_Server;Svr;tyrone-cluster;Scheduler was sent the command new
01/03/2015 20:10:05;0100;PBS_Server;Job;46454.tyrone-cluster;enqueuing into batch, state 1 hop 1
01/03/2015 20:10:05;0100;PBS_Server;Job;46454.tyrone-cluster;dequeuing from batch, state QUEUED
01/03/2015 20:10:05;0100;PBS_Server;Job;46454.tyrone-cluster;enqueuing into idqueue, state 1 hop 1
01/03/2015 20:10:05;0008;PBS_Server;Job;46454.tyrone-cluster;Job Queued at request of chemraja@tyrone-cluster, owner = chemraja@tyrone-cluster, job name = test.sh, queue = idqueue
01/03/2015 20:10:05;0040;PBS_Server;Svr;tyrone-cluster;Scheduler was sent the command new
01/03/2015 20:10:05;0008;PBS_Server;Job;46454.tyrone-cluster;Job Modified at request of Scheduler@tyrone-cluster
01/03/2015 20:10:05;0008;PBS_Server;Job;46454.tyrone-cluster;Job Run at request of Scheduler@tyrone-cluster
01/03/2015 20:10:05;0040;PBS_Server;Svr;tyrone-cluster;Scheduler was sent the command recyc
01/03/2015 20:10:05;000d;PBS_Server;Job;46454.tyrone-cluster;Not sending email: User does not want mail of this type.
01/03/2015 20:10:22;0040;PBS_Server;Svr;tyrone-cluster;Scheduler was sent the command new
01/03/2015 20:10:52;0040;PBS_Server;Svr;tyrone-cluster;Scheduler was sent the command new
01/03/2015 20:11:23;0040;PBS_Server;Svr;tyrone-cluster;Scheduler was sent the command new
01/03/2015 20:11:52;0040;PBS_Server;Svr;tyrone-cluster;Scheduler was sent the command new
01/03/2015 20:12:16;0100;PBS_Server;Job;46455.tyrone-cluster;enqueuing into batch, state 1 hop 1
01/03/2015 20:12:16;0100;PBS_Server;Job;46455.tyrone-cluster;dequeuing from batch, state QUEUED
01/03/2015 20:12:16;0100;PBS_Server;Job;46455.tyrone-cluster;enqueuing into qp128, state 1 hop 1
01/03/2015 20:12:16;0008;PBS_Server;Job;46455.tyrone-cluster;Job Queued at request of nisabish@tyrone-cluster, owner = nisabish@tyrone-cluster, job name = fe36nscf, queue = qp128
01/03/2015 20:12:16;0040;PBS_Server;Svr;tyrone-cluster;Scheduler was sent the command new
01/03/2015 20:12:17;0008;PBS_Server;Job;46455.tyrone-cluster;Job Modified at request of Scheduler@tyrone-cluster
01/03/2015 20:12:17;0008;PBS_Server;Job;46455.tyrone-cluster;Job Run at request of Scheduler@tyrone-cluster
01/03/2015 20:12:17;0040;PBS_Server;Svr;tyrone-cluster;Scheduler was sent the command recyc
01/03/2015 20:12:23;0040;PBS_Server;Svr;tyrone-cluster;Scheduler was sent the command new
01/03/2015 20:12:53;0040;PBS_Server;Svr;tyrone-cluster;Scheduler was sent the command new
01/03/2015 20:13:04;000d;PBS_Server;Job;46455.tyrone-cluster;Not sending email: User does not want mail of this type.
01/03/2015 20:13:23;0040;PBS_Server;Svr;tyrone-cluster;Scheduler was sent the command new
01/03/2015 20:13:42;000d;PBS_Server;Job;46454.tyrone-cluster;Not sending email: User does not want mail of this type.
01/03/2015 20:13:42;0010;PBS_Server;Job;46454.tyrone-cluster;Exit_status=0 resources_used.cput=00:03:24 resources_used.mem=104696kb resources_used.vmem=1957984kb resources_used.walltime=00:03:37
01/03/2015 20:13:42;0008;PBS_Server;Job;NULL;on_job_exit valid pjob: 0x13e3600 (substate=50)
01/03/2015 20:13:42;0008;PBS_Server;Job;NULL;on_job_exit valid pjob: 0x13e3600 (substate=51)
01/03/2015 20:13:42;0008;PBS_Server;Job;NULL;on_job_exit valid pjob: 0x13e3600 (substate=51)
01/03/2015 20:13:42;0008;PBS_Server;Job;NULL;on_job_exit valid pjob: 0x13e3600 (substate=53)
01/03/2015 20:13:42;0100;PBS_Server;Job;46454.tyrone-cluster;dequeuing from idqueue, state COMPLETE
01/03/2015 20:13:42;0040;PBS_Server;Svr;tyrone-cluster;Scheduler was sent the command term
01/03/2015 20:13:53;0040;PBS_Server;Svr;tyrone-cluster;Scheduler was sent the command new
01/03/2015 20:14:23;0040;PBS_Server;Svr;tyrone-cluster;Scheduler was sent the command new
01/03/2015 20:14:47;0002;PBS_Server;Svr;PBS_Server;Torque Server Version = 3.0.5, loglevel = 0
01/03/2015 20:14:53;0040;PBS_Server;Svr;tyrone-cluster;Scheduler was sent the command new
01/03/2015 20:15:23;0040;PBS_Server;Svr;tyrone-cluster;Scheduler was sent the command new
01/03/2015 20:15:53;0040;PBS_Server;Svr;tyrone-cluster;Scheduler was sent the command new
01/03/2015 20:16:09;0100;PBS_Server;Job;46456.tyrone-cluster;enqueuing into batch, state 1 hop 1
01/03/2015 20:16:09;0100;PBS_Server;Job;46456.tyrone-cluster;dequeuing from batch, state QUEUED
01/03/2015 20:16:09;0100;PBS_Server;Job;46456.tyrone-cluster;enqueuing into qp256, state 1 hop 1
01/03/2015 20:16:09;0008;PBS_Server;Job;46456.tyrone-cluster;Job Queued at request of aseabwit@tyrone-cluster, owner = aseabwit@tyrone-cluster, job name = DNsFlo_256, queue = qp256
01/03/2015 20:16:09;0040;PBS_Server;Svr;tyrone-cluster;Scheduler was sent the command new
01/03/2015 20:16:09;0008;PBS_Server;Job;46456.tyrone-cluster;Job Modified at request of Scheduler@tyrone-cluster
01/03/2015 20:16:09;0008;PBS_Server;Job;46456.tyrone-cluster;Job Run at request of Scheduler@tyrone-cluster
01/03/2015 20:16:09;0040;PBS_Server;Svr;tyrone-cluster;Scheduler was sent the command recyc
01/03/2015 20:16:11;000d;PBS_Server;Job;46456.tyrone-cluster;Not sending email: User does not want mail of this type.
01/03/2015 20:16:11;0010;PBS_Server;Job;46456.tyrone-cluster;Exit_status=255 resources_used.cput=00:00:00 resources_used.mem=796kb resources_used.vmem=13624kb resources_used.walltime=00:00:02
01/03/2015 20:16:11;0008;PBS_Server;Job;NULL;on_job_exit valid pjob: 0x13e7520 (substate=50)
01/03/2015 20:16:11;0008;PBS_Server;Job;NULL;on_job_exit valid pjob: 0x13e7520 (substate=51)
01/03/2015 20:16:12;0008;PBS_Server;Job;NULL;on_job_exit valid pjob: 0x13e7520 (substate=51)
01/03/2015 20:16:12;0008;PBS_Server;Job;NULL;on_job_exit valid pjob: 0x13e7520 (substate=53)
01/03/2015 20:16:12;0100;PBS_Server;Job;46456.tyrone-cluster;dequeuing from qp256, state COMPLETE
01/03/2015 20:16:12;0040;PBS_Server;Svr;tyrone-cluster;Scheduler was sent the command term
01/03/2015 20:16:24;0040;PBS_Server;Svr;tyrone-cluster;Scheduler was sent the command new
01/03/2015 20:16:53;0100;PBS_Server;Job;46457.tyrone-cluster;enqueuing into batch, state 1 hop 1
01/03/2015 20:16:53;0100;PBS_Server;Job;46457.tyrone-cluster;dequeuing from batch, state QUEUED
01/03/2015 20:16:53;0100;PBS_Server;Job;46457.tyrone-cluster;enqueuing into qp256, state 1 hop 1
01/03/2015 20:16:53;0008;PBS_Server;Job;46457.tyrone-cluster;Job Queued at request of aseabwit@tyrone-cluster, owner = aseabwit@tyrone-cluster, job name = DNsFlo_256, queue = qp256
01/03/2015 20:16:53;0040;PBS_Server;Svr;tyrone-cluster;Scheduler was sent the command new
01/03/2015 20:16:53;0008;PBS_Server;Job;46457.tyrone-cluster;Job Modified at request of Scheduler@tyrone-cluster
01/03/2015 20:16:53;0008;PBS_Server;Job;46457.tyrone-cluster;Job Run at request of Scheduler@tyrone-cluster
01/03/2015 20:16:53;0040;PBS_Server;Svr;tyrone-cluster;Scheduler was sent the command recyc
01/03/2015 20:16:54;0040;PBS_Server;Svr;tyrone-cluster;Scheduler was sent the command new
01/03/2015 20:16:54;0008;PBS_Server;Job;46199.tyrone-cluster;Job Modified at request of Scheduler@tyrone-cluster
01/03/2015 20:16:54;000d;PBS_Server;Job;46457.tyrone-cluster;Not sending email: User does not want mail of this type.
01/03/2015 20:16:54;0010;PBS_Server;Job;46457.tyrone-cluster;Exit_status=255 resources_used.cput=00:00:00 resources_used.mem=796kb resources_used.vmem=13624kb resources_used.walltime=00:00:02
01/03/2015 20:16:54;0008;PBS_Server;Job;NULL;on_job_exit valid pjob: 0x13e7520 (substate=50)
01/03/2015 20:16:54;0008;PBS_Server;Job;NULL;on_job_exit valid pjob: 0x13e7520 (substate=51)
01/03/2015 20:16:55;0008;PBS_Server;Job;NULL;on_job_exit valid pjob: 0x13e7520 (substate=51)
01/03/2015 20:16:55;0008;PBS_Server;Job;NULL;on_job_exit valid pjob: 0x13e7520 (substate=53)
01/03/2015 20:16:55;0100;PBS_Server;Job;46457.tyrone-cluster;dequeuing from qp256, state COMPLETE
01/03/2015 20:16:55;0040;PBS_Server;Svr;tyrone-cluster;Scheduler was sent the command term
01/03/2015 20:16:55;0008;PBS_Server;Job;46199.tyrone-cluster;Job Modified at request of Scheduler@tyrone-cluster
01/03/2015 20:17:24;0040;PBS_Server;Svr;tyrone-cluster;Scheduler was sent the command new
01/03/2015 20:17:54;0040;PBS_Server;Svr;tyrone-cluster;Scheduler was sent the command new
01/03/2015 20:18:24;0040;PBS_Server;Svr;tyrone-cluster;Scheduler was sent the command new
01/03/2015 20:18:54;0040;PBS_Server;Svr;tyrone-cluster;Scheduler was sent the command new
01/03/2015 20:19:24;0040;PBS_Server;Svr;tyrone-cluster;Scheduler was sent the command new
01/03/2015 20:19:47;0002;PBS_Server;Svr;PBS_Server;Torque Server Version = 3.0.5, loglevel = 0
01/03/2015 20:19:54;0040;PBS_Server;Svr;tyrone-cluster;Scheduler was sent the command new
01/03/2015 20:20:24;0040;PBS_Server;Svr;tyrone-cluster;Scheduler was sent the command new
01/03/2015 20:20:54;0040;PBS_Server;Svr;tyrone-cluster;Scheduler was sent the command new
01/03/2015 20:21:25;0040;PBS_Server;Svr;tyrone-cluster;Scheduler was sent the command new
01/03/2015 20:21:55;0040;PBS_Server;Svr;tyrone-cluster;Scheduler was sent the command new
01/03/2015 20:22:25;0040;PBS_Server;Svr;tyrone-cluster;Scheduler was sent the command new
01/03/2015 20:22:55;0040;PBS_Server;Svr;tyrone-cluster;Scheduler was sent the command new
01/03/2015 20:23:25;0040;PBS_Server;Svr;tyrone-cluster;Scheduler was sent the command new
01/03/2015 20:23:55;0040;PBS_Server;Svr;tyrone-cluster;Scheduler was sent the command new
01/03/2015 20:24:25;0040;PBS_Server;Svr;tyrone-cluster;Scheduler was sent the command new
01/03/2015 20:24:47;0002;PBS_Server;Svr;PBS_Server;Torque Server Version = 3.0.5, loglevel = 0
01/03/2015 20:24:55;0040;PBS_Server;Svr;tyrone-cluster;Scheduler was sent the command new
01/03/2015 20:25:14;0100;PBS_Server;Job;46458.tyrone-cluster;enqueuing into batch, state 1 hop 1
01/03/2015 20:25:14;0100;PBS_Server;Job;46458.tyrone-cluster;dequeuing from batch, state QUEUED
01/03/2015 20:25:14;0100;PBS_Server;Job;46458.tyrone-cluster;enqueuing into idqueue, state 1 hop 1
01/03/2015 20:25:14;0008;PBS_Server;Job;46458.tyrone-cluster;Job Queued at request of aseabwit@tyrone-cluster, owner = aseabwit@tyrone-cluster, job name = DNsFlo_32, queue = idqueue
01/03/2015 20:25:14;0040;PBS_Server;Svr;tyrone-cluster;Scheduler was sent the command new
01/03/2015 20:25:14;0008;PBS_Server;Job;46458.tyrone-cluster;Job Modified at request of Scheduler@tyrone-cluster
01/03/2015 20:25:14;0008;PBS_Server;Job;46458.tyrone-cluster;Job Run at request of Scheduler@tyrone-cluster
01/03/2015 20:25:14;0040;PBS_Server;Svr;tyrone-cluster;Scheduler was sent the command recyc
01/03/2015 20:25:14;000d;PBS_Server;Job;46458.tyrone-cluster;Not sending email: User does not want mail of this type.
01/03/2015 20:25:25;0040;PBS_Server;Svr;tyrone-cluster;Scheduler was sent the command new
01/03/2015 20:25:55;0040;PBS_Server;Svr;tyrone-cluster;Scheduler was sent the command new
01/03/2015 20:26:26;0040;PBS_Server;Svr;tyrone-cluster;Scheduler was sent the command new
01/03/2015 20:26:55;0040;PBS_Server;Svr;tyrone-cluster;Scheduler was sent the command new
01/03/2015 20:27:25;0040;PBS_Server;Svr;tyrone-cluster;Scheduler was sent the command new
01/03/2015 20:27:56;0040;PBS_Server;Svr;tyrone-cluster;Scheduler was sent the command new
01/03/2015 20:28:26;0040;PBS_Server;Svr;tyrone-cluster;Scheduler was sent the command new
01/03/2015 20:28:56;0040;PBS_Server;Svr;tyrone-cluster;Scheduler was sent the command new
01/03/2015 20:29:26;0040;PBS_Server;Svr;tyrone-cluster;Scheduler was sent the command new
01/03/2015 20:29:47;0002;PBS_Server;Svr;PBS_Server;Torque Server Version = 3.0.5, loglevel = 0
01/03/2015 20:29:56;0040;PBS_Server;Svr;tyrone-cluster;Scheduler was sent the command new
01/03/2015 20:30:26;0040;PBS_Server;Svr;tyrone-cluster;Scheduler was sent the command new
01/03/2015 20:30:57;0040;PBS_Server;Svr;tyrone-cluster;Scheduler was sent the command new
01/03/2015 20:31:27;0040;PBS_Server;Svr;tyrone-cluster;Scheduler was sent the command new
01/03/2015 20:31:57;0040;PBS_Server;Svr;tyrone-cluster;Scheduler was sent the command new
01/03/2015 20:32:27;0040;PBS_Server;Svr;tyrone-cluster;Scheduler was sent the command new
01/03/2015 20:32:57;0040;PBS_Server;Svr;tyrone-cluster;Scheduler was sent the command new
01/03/2015 20:33:27;0040;PBS_Server;Svr;tyrone-cluster;Scheduler was sent the command new
01/03/2015 20:33:57;0040;PBS_Server;Svr;tyrone-cluster;Scheduler was sent the command new
01/03/2015 20:34:27;0040;PBS_Server;Svr;tyrone-cluster;Scheduler was sent the command new
01/03/2015 20:34:47;0002;PBS_Server;Svr;PBS_Server;Torque Server Version = 3.0.5, loglevel = 0
01/03/2015 20:34:57;0040;PBS_Server;Svr;tyrone-cluster;Scheduler was sent the command new
01/03/2015 20:35:28;0040;PBS_Server;Svr;tyrone-cluster;Scheduler was sent the command new
01/03/2015 20:35:58;0040;PBS_Server;Svr;tyrone-cluster;Scheduler was sent the command new
01/03/2015 20:36:28;0040;PBS_Server;Svr;tyrone-cluster;Scheduler was sent the command new
01/03/2015 20:36:58;0040;PBS_Server;Svr;tyrone-cluster;Scheduler was sent the command new
01/03/2015 20:37:28;0040;PBS_Server;Svr;tyrone-cluster;Scheduler was sent the command new
01/03/2015 20:37:58;0040;PBS_Server;Svr;tyrone-cluster;Scheduler was sent the command new
01/03/2015 20:38:28;0040;PBS_Server;Svr;tyrone-cluster;Scheduler was sent the command new
01/03/2015 20:38:58;0040;PBS_Server;Svr;tyrone-cluster;Scheduler was sent the command new
01/03/2015 20:39:29;0040;PBS_Server;Svr;tyrone-cluster;Scheduler was sent the command new
01/03/2015 20:39:47;0002;PBS_Server;Svr;PBS_Server;Torque Server Version = 3.0.5, loglevel = 0
01/03/2015 20:39:59;0040;PBS_Server;Svr;tyrone-cluster;Scheduler was sent the command new
01/03/2015 20:40:29;0040;PBS_Server;Svr;tyrone-cluster;Scheduler was sent the command new
01/03/2015 20:40:59;0040;PBS_Server;Svr;tyrone-cluster;Scheduler was sent the command new
01/03/2015 20:41:29;0040;PBS_Server;Svr;tyrone-cluster;Scheduler was sent the command new
01/03/2015 20:41:59;0040;PBS_Server;Svr;tyrone-cluster;Scheduler was sent the command new
01/03/2015 20:42:30;0040;PBS_Server;Svr;tyrone-cluster;Scheduler was sent the command new
01/03/2015 20:42:59;0040;PBS_Server;Svr;tyrone-cluster;Scheduler was sent the command new
01/03/2015 20:42:59;0100;PBS_Server;Job;46459.tyrone-cluster;enqueuing into batch, state 1 hop 1
01/03/2015 20:42:59;0100;PBS_Server;Job;46459.tyrone-cluster;dequeuing from batch, state QUEUED
01/03/2015 20:42:59;0100;PBS_Server;Job;46459.tyrone-cluster;enqueuing into qp64, state 1 hop 1
01/03/2015 20:42:59;0008;PBS_Server;Job;46459.tyrone-cluster;Job Queued at request of asepk@tyrone-cluster, owner = asepk@tyrone-cluster, job name = DNsFlo_64, queue = qp64
01/03/2015 20:42:59;0008;PBS_Server;Job;46459.tyrone-cluster;Job Modified at request of Scheduler@tyrone-cluster
01/03/2015 20:42:59;0008;PBS_Server;Job;46459.tyrone-cluster;Job Run at request of Scheduler@tyrone-cluster
01/03/2015 20:42:59;0040;PBS_Server;Svr;tyrone-cluster;Scheduler was sent the command recyc
01/03/2015 20:43:30;0040;PBS_Server;Svr;tyrone-cluster;Scheduler was sent the command new
01/03/2015 20:43:57;000d;PBS_Server;Job;46459.tyrone-cluster;Not sending email: User does not want mail of this type.
01/03/2015 20:44:00;0040;PBS_Server;Svr;tyrone-cluster;Scheduler was sent the command new
01/03/2015 20:44:30;0040;PBS_Server;Svr;tyrone-cluster;Scheduler was sent the command new
01/03/2015 20:44:47;0002;PBS_Server;Svr;PBS_Server;Torque Server Version = 3.0.5, loglevel = 0
01/03/2015 20:45:00;0040;PBS_Server;Svr;tyrone-cluster;Scheduler was sent the command new
01/03/2015 20:45:30;0040;PBS_Server;Svr;tyrone-cluster;Scheduler was sent the command new
01/03/2015 20:46:00;0040;PBS_Server;Svr;tyrone-cluster;Scheduler was sent the command new
01/03/2015 20:46:30;0040;PBS_Server;Svr;tyrone-cluster;Scheduler was sent the command new
01/03/2015 20:47:00;0040;PBS_Server;Svr;tyrone-cluster;Scheduler was sent the command new
01/03/2015 20:47:31;0040;PBS_Server;Svr;tyrone-cluster;Scheduler was sent the command new
01/03/2015 20:48:01;0040;PBS_Server;Svr;tyrone-cluster;Scheduler was sent the command new
01/03/2015 20:48:30;0040;PBS_Server;Svr;tyrone-cluster;Scheduler was sent the command new
01/03/2015 20:49:01;0040;PBS_Server;Svr;tyrone-cluster;Scheduler was sent the command new
01/03/2015 20:49:31;0040;PBS_Server;Svr;tyrone-cluster;Scheduler was sent the command new
01/03/2015 20:49:37;0100;PBS_Server;Job;46460.tyrone-cluster;enqueuing into batch, state 1 hop 1
01/03/2015 20:49:37;0100;PBS_Server;Job;46460.tyrone-cluster;dequeuing from batch, state QUEUED
01/03/2015 20:49:37;0100;PBS_Server;Job;46460.tyrone-cluster;enqueuing into qp128, state 1 hop 1
01/03/2015 20:49:37;0008;PBS_Server;Job;46460.tyrone-cluster;Job Queued at request of uggupta@tyrone-cluster, owner = uggupta@tyrone-cluster, job name = MPIfor100new, queue = qp128
01/03/2015 20:49:37;0040;PBS_Server;Svr;tyrone-cluster;Scheduler was sent the command new
01/03/2015 20:49:37;0008;PBS_Server;Job;46460.tyrone-cluster;Job Modified at request of Scheduler@tyrone-cluster
01/03/2015 20:49:47;0002;PBS_Server;Svr;PBS_Server;Torque Server Version = 3.0.5, loglevel = 0
01/03/2015 20:50:00;0040;PBS_Server;Svr;tyrone-cluster;Scheduler was sent the command new
01/03/2015 20:50:13;0008;PBS_Server;Job;46460.tyrone-cluster;Job deleted at request of uggupta@tyrone-cluster
01/03/2015 20:50:13;0008;PBS_Server;Job;NULL;on_job_exit valid pjob: 0x12f1ef0 (substate=59)
01/03/2015 20:50:13;0100;PBS_Server;Job;46460.tyrone-cluster;dequeuing from qp128, state COMPLETE
01/03/2015 20:50:13;0040;PBS_Server;Svr;tyrone-cluster;Scheduler was sent the command term
01/03/2015 20:50:32;0040;PBS_Server;Svr;tyrone-cluster;Scheduler was sent the command new
01/03/2015 20:51:02;0040;PBS_Server;Svr;tyrone-cluster;Scheduler was sent the command new
01/03/2015 20:51:03;0100;PBS_Server;Job;46461.tyrone-cluster;enqueuing into batch, state 1 hop 1
01/03/2015 20:51:03;0100;PBS_Server;Job;46461.tyrone-cluster;dequeuing from batch, state QUEUED
01/03/2015 20:51:03;0100;PBS_Server;Job;46461.tyrone-cluster;enqueuing into qp128, state 1 hop 1
01/03/2015 20:51:03;0008;PBS_Server;Job;46461.tyrone-cluster;Job Queued at request of uggupta@tyrone-cluster, owner = uggupta@tyrone-cluster, job name = 256Data, queue = qp128
01/03/2015 20:51:03;0040;PBS_Server;Svr;tyrone-cluster;Scheduler was sent the command new
01/03/2015 20:51:03;0008;PBS_Server;Job;46461.tyrone-cluster;Job Modified at request of Scheduler@tyrone-cluster
01/03/2015 20:51:30;0040;PBS_Server;Svr;tyrone-cluster;Scheduler was sent the command new
01/03/2015 20:52:02;0040;PBS_Server;Svr;tyrone-cluster;Scheduler was sent the command new
01/03/2015 20:52:32;0040;PBS_Server;Svr;tyrone-cluster;Scheduler was sent the command new
01/03/2015 20:53:00;0040;PBS_Server;Svr;tyrone-cluster;Scheduler was sent the command new
01/03/2015 20:53:14;0100;PBS_Server;Job;46462.tyrone-cluster;enqueuing into batch, state 1 hop 1
01/03/2015 20:53:14;0100;PBS_Server;Job;46462.tyrone-cluster;dequeuing from batch, state QUEUED
01/03/2015 20:53:14;0100;PBS_Server;Job;46462.tyrone-cluster;enqueuing into idqueue, state 1 hop 1
01/03/2015 20:53:14;0008;PBS_Server;Job;46462.tyrone-cluster;Job Queued at request of chemraja@tyrone-cluster, owner = chemraja@tyrone-cluster, job name = test.sh, queue = idqueue
01/03/2015 20:53:14;0040;PBS_Server;Svr;tyrone-cluster;Scheduler was sent the command new
01/03/2015 20:53:14;0008;PBS_Server;Job;46462.tyrone-cluster;Job Modified at request of Scheduler@tyrone-cluster
01/03/2015 20:53:32;0040;PBS_Server;Svr;tyrone-cluster;Scheduler was sent the command new
01/03/2015 20:54:02;0040;PBS_Server;Svr;tyrone-cluster;Scheduler was sent the command new
01/03/2015 20:54:32;0040;PBS_Server;Svr;tyrone-cluster;Scheduler was sent the command new
01/03/2015 20:54:47;0002;PBS_Server;Svr;PBS_Server;Torque Server Version = 3.0.5, loglevel = 0
01/03/2015 20:55:02;0040;PBS_Server;Svr;tyrone-cluster;Scheduler was sent the command new
01/03/2015 20:55:33;0040;PBS_Server;Svr;tyrone-cluster;Scheduler was sent the command new
01/03/2015 20:55:39;0100;PBS_Server;Job;46463.tyrone-cluster;enqueuing into batch, state 1 hop 1
01/03/2015 20:55:39;0100;PBS_Server;Job;46463.tyrone-cluster;dequeuing from batch, state QUEUED
01/03/2015 20:55:39;0100;PBS_Server;Job;46463.tyrone-cluster;enqueuing into idqueue, state 1 hop 1
01/03/2015 20:55:39;0008;PBS_Server;Job;46463.tyrone-cluster;Job Queued at request of chemraja@tyrone-cluster, owner = chemraja@tyrone-cluster, job name = siraj.sh, queue = idqueue
01/03/2015 20:55:39;0040;PBS_Server;Svr;tyrone-cluster;Scheduler was sent the command new
01/03/2015 20:55:39;0008;PBS_Server;Job;46463.tyrone-cluster;Job Modified at request of Scheduler@tyrone-cluster
01/03/2015 20:56:03;0040;PBS_Server;Svr;tyrone-cluster;Scheduler was sent the command new
01/03/2015 20:56:33;0040;PBS_Server;Svr;tyrone-cluster;Scheduler was sent the command new
01/03/2015 20:57:03;0040;PBS_Server;Svr;tyrone-cluster;Scheduler was sent the command new
01/03/2015 20:57:33;0040;PBS_Server;Svr;tyrone-cluster;Scheduler was sent the command new
01/03/2015 20:58:03;0040;PBS_Server;Svr;tyrone-cluster;Scheduler was sent the command new
01/03/2015 20:58:33;0040;PBS_Server;Svr;tyrone-cluster;Scheduler was sent the command new
01/03/2015 20:59:03;0040;PBS_Server;Svr;tyrone-cluster;Scheduler was sent the command new
01/03/2015 20:59:34;0040;PBS_Server;Svr;tyrone-cluster;Scheduler was sent the command new
01/03/2015 20:59:47;0002;PBS_Server;Svr;PBS_Server;Torque Server Version = 3.0.5, loglevel = 0
01/03/2015 21:00:04;0040;PBS_Server;Svr;tyrone-cluster;Scheduler was sent the command new
01/03/2015 21:00:34;0040;PBS_Server;Svr;tyrone-cluster;Scheduler was sent the command new
01/03/2015 21:01:04;0040;PBS_Server;Svr;tyrone-cluster;Scheduler was sent the command new
01/03/2015 21:01:34;0040;PBS_Server;Svr;tyrone-cluster;Scheduler was sent the command new
01/03/2015 21:02:04;0040;PBS_Server;Svr;tyrone-cluster;Scheduler was sent the command new
01/03/2015 21:02:34;0040;PBS_Server;Svr;tyrone-cluster;Scheduler was sent the command new
01/03/2015 21:03:04;0040;PBS_Server;Svr;tyrone-cluster;Scheduler was sent the command new
01/03/2015 21:03:35;0040;PBS_Server;Svr;tyrone-cluster;Scheduler was sent the command new
01/03/2015 21:04:05;0040;PBS_Server;Svr;tyrone-cluster;Scheduler was sent the command new
01/03/2015 21:04:35;0040;PBS_Server;Svr;tyrone-cluster;Scheduler was sent the command new
01/03/2015 21:04:47;0002;PBS_Server;Svr;PBS_Server;Torque Server Version = 3.0.5, loglevel = 0
01/03/2015 21:05:05;0040;PBS_Server;Svr;tyrone-cluster;Scheduler was sent the command new
01/03/2015 21:05:35;0040;PBS_Server;Svr;tyrone-cluster;Scheduler was sent the command new
01/03/2015 21:06:05;0040;PBS_Server;Svr;tyrone-cluster;Scheduler was sent the command new
01/03/2015 21:06:35;0040;PBS_Server;Svr;tyrone-cluster;Scheduler was sent the command new
01/03/2015 21:07:05;0040;PBS_Server;Svr;tyrone-cluster;Scheduler was sent the command new
01/03/2015 21:07:35;0040;PBS_Server;Svr;tyrone-cluster;Scheduler was sent the command new
01/03/2015 21:08:06;0040;PBS_Server;Svr;tyrone-cluster;Scheduler was sent the command new
01/03/2015 21:08:36;0040;PBS_Server;Svr;tyrone-cluster;Scheduler was sent the command new
01/03/2015 21:09:06;0040;PBS_Server;Svr;tyrone-cluster;Scheduler was sent the command new
01/03/2015 21:09:36;0040;PBS_Server;Svr;tyrone-cluster;Scheduler was sent the command new
01/03/2015 21:09:47;0002;PBS_Server;Svr;PBS_Server;Torque Server Version = 3.0.5, loglevel = 0
01/03/2015 21:10:06;0040;PBS_Server;Svr;tyrone-cluster;Scheduler was sent the command new
01/03/2015 21:10:36;0040;PBS_Server;Svr;tyrone-cluster;Scheduler was sent the command new
01/03/2015 21:11:06;0040;PBS_Server;Svr;tyrone-cluster;Scheduler was sent the command new
01/03/2015 21:11:36;0040;PBS_Server;Svr;tyrone-cluster;Scheduler was sent the command new
01/03/2015 21:12:07;0040;PBS_Server;Svr;tyrone-cluster;Scheduler was sent the command new
01/03/2015 21:12:37;0040;PBS_Server;Svr;tyrone-cluster;Scheduler was sent the command new
01/03/2015 21:13:07;0040;PBS_Server;Svr;tyrone-cluster;Scheduler was sent the command new
01/03/2015 21:13:37;0040;PBS_Server;Svr;tyrone-cluster;Scheduler was sent the command new
01/03/2015 21:14:07;0040;PBS_Server;Svr;tyrone-cluster;Scheduler was sent the command new
01/03/2015 21:14:37;0040;PBS_Server;Svr;tyrone-cluster;Scheduler was sent the command new
01/03/2015 21:14:47;0002;PBS_Server;Svr;PBS_Server;Torque Server Version = 3.0.5, loglevel = 0
01/03/2015 21:15:07;0040;PBS_Server;Svr;tyrone-cluster;Scheduler was sent the command new
01/03/2015 21:15:37;0040;PBS_Server;Svr;tyrone-cluster;Scheduler was sent the command new
01/03/2015 21:16:08;0040;PBS_Server;Svr;tyrone-cluster;Scheduler was sent the command new
01/03/2015 21:16:38;0040;PBS_Server;Svr;tyrone-cluster;Scheduler was sent the command new
01/03/2015 21:17:08;0040;PBS_Server;Svr;tyrone-cluster;Scheduler was sent the command new
01/03/2015 21:17:38;0040;PBS_Server;Svr;tyrone-cluster;Scheduler was sent the command new
01/03/2015 21:18:08;0040;PBS_Server;Svr;tyrone-cluster;Scheduler was sent the command new
01/03/2015 21:18:38;0040;PBS_Server;Svr;tyrone-cluster;Scheduler was sent the command new
01/03/2015 21:19:08;0040;PBS_Server;Svr;tyrone-cluster;Scheduler was sent the command new
01/03/2015 21:19:38;0040;PBS_Server;Svr;tyrone-cluster;Scheduler was sent the command new
01/03/2015 21:19:47;0002;PBS_Server;Svr;PBS_Server;Torque Server Version = 3.0.5, loglevel = 0
01/03/2015 21:20:09;0040;PBS_Server;Svr;tyrone-cluster;Scheduler was sent the command new
01/03/2015 21:20:39;0040;PBS_Server;Svr;tyrone-cluster;Scheduler was sent the command new
01/03/2015 21:21:09;0040;PBS_Server;Svr;tyrone-cluster;Scheduler was sent the command new
01/03/2015 21:21:39;0040;PBS_Server;Svr;tyrone-cluster;Scheduler was sent the command new
01/03/2015 21:22:09;0040;PBS_Server;Svr;tyrone-cluster;Scheduler was sent the command new
01/03/2015 21:22:39;0040;PBS_Server;Svr;tyrone-cluster;Scheduler was sent the command new
01/03/2015 21:23:09;0040;PBS_Server;Svr;tyrone-cluster;Scheduler was sent the command new
01/03/2015 21:23:39;0040;PBS_Server;Svr;tyrone-cluster;Scheduler was sent the command new
01/03/2015 21:24:09;0040;PBS_Server;Svr;tyrone-cluster;Scheduler was sent the command new
01/03/2015 21:24:40;0040;PBS_Server;Svr;tyrone-cluster;Scheduler was sent the command new
01/03/2015 21:24:47;0002;PBS_Server;Svr;PBS_Server;Torque Server Version = 3.0.5, loglevel = 0
01/03/2015 21:25:10;0040;PBS_Server;Svr;tyrone-cluster;Scheduler was sent the command new
01/03/2015 21:25:40;0040;PBS_Server;Svr;tyrone-cluster;Scheduler was sent the command new
01/03/2015 21:26:10;0040;PBS_Server;Svr;tyrone-cluster;Scheduler was sent the command new
01/03/2015 21:26:40;0040;PBS_Server;Svr;tyrone-cluster;Scheduler was sent the command new
01/03/2015 21:27:10;0040;PBS_Server;Svr;tyrone-cluster;Scheduler was sent the command new
01/03/2015 21:27:40;0040;PBS_Server;Svr;tyrone-cluster;Scheduler was sent the command new
01/03/2015 21:28:10;0040;PBS_Server;Svr;tyrone-cluster;Scheduler was sent the command new
01/03/2015 21:28:41;0040;PBS_Server;Svr;tyrone-cluster;Scheduler was sent the command new
01/03/2015 21:29:11;0040;PBS_Server;Svr;tyrone-cluster;Scheduler was sent the command new
01/03/2015 21:29:40;0040;PBS_Server;Svr;tyrone-cluster;Scheduler was sent the command new
01/03/2015 21:29:47;0002;PBS_Server;Svr;PBS_Server;Torque Server Version = 3.0.5, loglevel = 0
01/03/2015 21:30:11;0040;PBS_Server;Svr;tyrone-cluster;Scheduler was sent the command new
01/03/2015 21:30:41;0040;PBS_Server;Svr;tyrone-cluster;Scheduler was sent the command new
01/03/2015 21:31:11;0040;PBS_Server;Svr;tyrone-cluster;Scheduler was sent the command new
01/03/2015 21:31:41;0040;PBS_Server;Svr;tyrone-cluster;Scheduler was sent the command new
01/03/2015 21:32:11;0040;PBS_Server;Svr;tyrone-cluster;Scheduler was sent the command new
01/03/2015 21:32:41;0040;PBS_Server;Svr;tyrone-cluster;Scheduler was sent the command new
01/03/2015 21:33:12;0040;PBS_Server;Svr;tyrone-cluster;Scheduler was sent the command new
01/03/2015 21:33:42;0040;PBS_Server;Svr;tyrone-cluster;Scheduler was sent the command new
01/03/2015 21:34:12;0040;PBS_Server;Svr;tyrone-cluster;Scheduler was sent the command new
01/03/2015 21:34:42;0040;PBS_Server;Svr;tyrone-cluster;Scheduler was sent the command new
01/03/2015 21:34:47;0002;PBS_Server;Svr;PBS_Server;Torque Server Version = 3.0.5, loglevel = 0
01/03/2015 21:35:12;0040;PBS_Server;Svr;tyrone-cluster;Scheduler was sent the command new
01/03/2015 21:35:42;0040;PBS_Server;Svr;tyrone-cluster;Scheduler was sent the command new
01/03/2015 21:36:12;0040;PBS_Server;Svr;tyrone-cluster;Scheduler was sent the command new
01/03/2015 21:36:42;0040;PBS_Server;Svr;tyrone-cluster;Scheduler was sent the command new
01/03/2015 21:37:12;0040;PBS_Server;Svr;tyrone-cluster;Scheduler was sent the command new
01/03/2015 21:37:43;0040;PBS_Server;Svr;tyrone-cluster;Scheduler was sent the command new
01/03/2015 21:38:13;0040;PBS_Server;Svr;tyrone-cluster;Scheduler was sent the command new
01/03/2015 21:38:42;0040;PBS_Server;Svr;tyrone-cluster;Scheduler was sent the command new
01/03/2015 21:39:13;0040;PBS_Server;Svr;tyrone-cluster;Scheduler was sent the command new
01/03/2015 21:39:43;0040;PBS_Server;Svr;tyrone-cluster;Scheduler was sent the command new
01/03/2015 21:39:47;0002;PBS_Server;Svr;PBS_Server;Torque Server Version = 3.0.5, loglevel = 0
01/03/2015 21:40:12;0040;PBS_Server;Svr;tyrone-cluster;Scheduler was sent the command new
01/03/2015 21:40:43;0040;PBS_Server;Svr;tyrone-cluster;Scheduler was sent the command new
01/03/2015 21:41:14;0040;PBS_Server;Svr;tyrone-cluster;Scheduler was sent the command new
01/03/2015 21:41:44;0040;PBS_Server;Svr;tyrone-cluster;Scheduler was sent the command new
01/03/2015 21:42:14;0040;PBS_Server;Svr;tyrone-cluster;Scheduler was sent the command new
01/03/2015 21:42:44;0040;PBS_Server;Svr;tyrone-cluster;Scheduler was sent the command new
01/03/2015 21:43:14;0040;PBS_Server;Svr;tyrone-cluster;Scheduler was sent the command new
01/03/2015 21:43:44;0040;PBS_Server;Svr;tyrone-cluster;Scheduler was sent the command new
01/03/2015 21:44:14;0040;PBS_Server;Svr;tyrone-cluster;Scheduler was sent the command new
01/03/2015 21:44:44;0040;PBS_Server;Svr;tyrone-cluster;Scheduler was sent the command new
01/03/2015 21:44:47;0002;PBS_Server;Svr;PBS_Server;Torque Server Version = 3.0.5, loglevel = 0
01/03/2015 21:45:15;0040;PBS_Server;Svr;tyrone-cluster;Scheduler was sent the command new
01/03/2015 21:45:45;0040;PBS_Server;Svr;tyrone-cluster;Scheduler was sent the command new
01/03/2015 21:46:15;0040;PBS_Server;Svr;tyrone-cluster;Scheduler was sent the command new
01/03/2015 21:46:45;0040;PBS_Server;Svr;tyrone-cluster;Scheduler was sent the command new
01/03/2015 21:47:15;0040;PBS_Server;Svr;tyrone-cluster;Scheduler was sent the command new
01/03/2015 21:47:45;0040;PBS_Server;Svr;tyrone-cluster;Scheduler was sent the command new
01/03/2015 21:48:15;0040;PBS_Server;Svr;tyrone-cluster;Scheduler was sent the command new
01/03/2015 21:48:45;0040;PBS_Server;Svr;tyrone-cluster;Scheduler was sent the command new
01/03/2015 21:49:15;0040;PBS_Server;Svr;tyrone-cluster;Scheduler was sent the command new
01/03/2015 21:49:46;0040;PBS_Server;Svr;tyrone-cluster;Scheduler was sent the command new
01/03/2015 21:49:47;0002;PBS_Server;Svr;PBS_Server;Torque Server Version = 3.0.5, loglevel = 0
01/03/2015 21:50:15;0040;PBS_Server;Svr;tyrone-cluster;Scheduler was sent the command new
01/03/2015 21:50:46;0040;PBS_Server;Svr;tyrone-cluster;Scheduler was sent the command new
01/03/2015 21:51:15;0040;PBS_Server;Svr;tyrone-cluster;Scheduler was sent the command new
01/03/2015 21:51:15;000d;PBS_Server;Job;46418.tyrone-cluster;Not sending email: User does not want mail of this type.
01/03/2015 21:51:15;0010;PBS_Server;Job;46418.tyrone-cluster;Exit_status=0 resources_used.cput=01:43:50 resources_used.mem=7884kb resources_used.vmem=56712kb resources_used.walltime=01:44:08
01/03/2015 21:51:15;0008;PBS_Server;Job;NULL;on_job_exit valid pjob: 0x1403230 (substate=50)
01/03/2015 21:51:15;0008;PBS_Server;Job;NULL;on_job_exit valid pjob: 0x1403230 (substate=51)
01/03/2015 21:51:15;0008;PBS_Server;Job;46453.tyrone-cluster;Job Modified at request of Scheduler@tyrone-cluster
01/03/2015 21:51:15;0008;PBS_Server;Job;NULL;on_job_exit valid pjob: 0x1403230 (substate=51)
01/03/2015 21:51:15;0008;PBS_Server;Job;NULL;on_job_exit valid pjob: 0x1403230 (substate=53)
01/03/2015 21:51:15;0100;PBS_Server;Job;46418.tyrone-cluster;dequeuing from qp32, state COMPLETE
01/03/2015 21:51:15;0040;PBS_Server;Svr;tyrone-cluster;Scheduler was sent the command term
01/03/2015 21:51:15;0008;PBS_Server;Job;46453.tyrone-cluster;Job Modified at request of Scheduler@tyrone-cluster
01/03/2015 21:51:15;0008;PBS_Server;Job;46453.tyrone-cluster;Job Run at request of Scheduler@tyrone-cluster
01/03/2015 21:51:15;0040;PBS_Server;Svr;tyrone-cluster;Scheduler was sent the command recyc
01/03/2015 21:51:15;000d;PBS_Server;Job;46453.tyrone-cluster;Not sending email: User does not want mail of this type.
01/03/2015 21:51:45;0040;PBS_Server;Svr;tyrone-cluster;Scheduler was sent the command new
01/03/2015 21:52:16;0040;PBS_Server;Svr;tyrone-cluster;Scheduler was sent the command new
01/03/2015 21:52:45;0040;PBS_Server;Svr;tyrone-cluster;Scheduler was sent the command new
01/03/2015 21:53:16;0040;PBS_Server;Svr;tyrone-cluster;Scheduler was sent the command new
01/03/2015 21:53:45;0040;PBS_Server;Svr;tyrone-cluster;Scheduler was sent the command new
01/03/2015 21:54:15;0040;PBS_Server;Svr;tyrone-cluster;Scheduler was sent the command new
01/03/2015 21:54:47;0002;PBS_Server;Svr;PBS_Server;Torque Server Version = 3.0.5, loglevel = 0
01/03/2015 21:54:47;0040;PBS_Server;Svr;tyrone-cluster;Scheduler was sent the command new
01/03/2015 21:55:17;0040;PBS_Server;Svr;tyrone-cluster;Scheduler was sent the command new
01/03/2015 21:55:47;0040;PBS_Server;Svr;tyrone-cluster;Scheduler was sent the command new
01/03/2015 21:56:17;0040;PBS_Server;Svr;tyrone-cluster;Scheduler was sent the command new
01/03/2015 21:56:47;0040;PBS_Server;Svr;tyrone-cluster;Scheduler was sent the command new
01/03/2015 21:57:17;0040;PBS_Server;Svr;tyrone-cluster;Scheduler was sent the command new
01/03/2015 21:57:48;0040;PBS_Server;Svr;tyrone-cluster;Scheduler was sent the command new
01/03/2015 21:58:18;0040;PBS_Server;Svr;tyrone-cluster;Scheduler was sent the command new
01/03/2015 21:58:48;0040;PBS_Server;Svr;tyrone-cluster;Scheduler was sent the command new
01/03/2015 21:59:18;0040;PBS_Server;Svr;tyrone-cluster;Scheduler was sent the command new
01/03/2015 21:59:47;0002;PBS_Server;Svr;PBS_Server;Torque Server Version = 3.0.5, loglevel = 0
01/03/2015 21:59:48;0040;PBS_Server;Svr;tyrone-cluster;Scheduler was sent the command new
01/03/2015 22:00:18;0040;PBS_Server;Svr;tyrone-cluster;Scheduler was sent the command new
01/03/2015 22:00:48;0040;PBS_Server;Svr;tyrone-cluster;Scheduler was sent the command new
01/03/2015 22:01:18;0040;PBS_Server;Svr;tyrone-cluster;Scheduler was sent the command new
01/03/2015 22:01:49;0040;PBS_Server;Svr;tyrone-cluster;Scheduler was sent the command new
01/03/2015 22:02:19;0040;PBS_Server;Svr;tyrone-cluster;Scheduler was sent the command new
01/03/2015 22:02:49;0040;PBS_Server;Svr;tyrone-cluster;Scheduler was sent the command new
01/03/2015 22:03:19;0040;PBS_Server;Svr;tyrone-cluster;Scheduler was sent the command new
01/03/2015 22:03:49;0040;PBS_Server;Svr;tyrone-cluster;Scheduler was sent the command new
01/03/2015 22:04:19;0040;PBS_Server;Svr;tyrone-cluster;Scheduler was sent the command new
01/03/2015 22:04:47;0002;PBS_Server;Svr;PBS_Server;Torque Server Version = 3.0.5, loglevel = 0
01/03/2015 22:04:49;0040;PBS_Server;Svr;tyrone-cluster;Scheduler was sent the command new
01/03/2015 22:05:19;0040;PBS_Server;Svr;tyrone-cluster;Scheduler was sent the command new
01/03/2015 22:05:50;0040;PBS_Server;Svr;tyrone-cluster;Scheduler was sent the command new
01/03/2015 22:06:20;0040;PBS_Server;Svr;tyrone-cluster;Scheduler was sent the command new
01/03/2015 22:06:50;0040;PBS_Server;Svr;tyrone-cluster;Scheduler was sent the command new
01/03/2015 22:07:20;0040;PBS_Server;Svr;tyrone-cluster;Scheduler was sent the command new
01/03/2015 22:07:50;0040;PBS_Server;Svr;tyrone-cluster;Scheduler was sent the command new
01/03/2015 22:08:20;0040;PBS_Server;Svr;tyrone-cluster;Scheduler was sent the command new
01/03/2015 22:08:50;0040;PBS_Server;Svr;tyrone-cluster;Scheduler was sent the command new
01/03/2015 22:09:21;0040;PBS_Server;Svr;tyrone-cluster;Scheduler was sent the command new
