01/01/2016 00:01:50;0002;PBS_Server;Svr;Log;Log opened
01/01/2016 00:01:50;0002;PBS_Server;Svr;PBS_Server;Torque Server Version = 3.0.5, loglevel = 0
01/01/2016 00:02:38;0040;PBS_Server;Svr;tyrone-cluster;Scheduler was sent the command time
01/01/2016 00:06:50;0002;PBS_Server;Svr;PBS_Server;Torque Server Version = 3.0.5, loglevel = 0
01/01/2016 00:11:50;0002;PBS_Server;Svr;PBS_Server;Torque Server Version = 3.0.5, loglevel = 0
01/01/2016 00:12:38;0040;PBS_Server;Svr;tyrone-cluster;Scheduler was sent the command time
01/01/2016 00:16:50;0002;PBS_Server;Svr;PBS_Server;Torque Server Version = 3.0.5, loglevel = 0
01/01/2016 00:21:50;0002;PBS_Server;Svr;PBS_Server;Torque Server Version = 3.0.5, loglevel = 0
01/01/2016 00:22:38;0040;PBS_Server;Svr;tyrone-cluster;Scheduler was sent the command time
01/01/2016 00:26:50;0002;PBS_Server;Svr;PBS_Server;Torque Server Version = 3.0.5, loglevel = 0
01/01/2016 00:31:50;0002;PBS_Server;Svr;PBS_Server;Torque Server Version = 3.0.5, loglevel = 0
01/01/2016 00:32:38;0040;PBS_Server;Svr;tyrone-cluster;Scheduler was sent the command time
01/01/2016 00:36:50;0002;PBS_Server;Svr;PBS_Server;Torque Server Version = 3.0.5, loglevel = 0
01/01/2016 00:41:50;0002;PBS_Server;Svr;PBS_Server;Torque Server Version = 3.0.5, loglevel = 0
01/01/2016 00:42:38;0040;PBS_Server;Svr;tyrone-cluster;Scheduler was sent the command time
01/01/2016 00:46:50;0002;PBS_Server;Svr;PBS_Server;Torque Server Version = 3.0.5, loglevel = 0
01/01/2016 00:51:50;0002;PBS_Server;Svr;PBS_Server;Torque Server Version = 3.0.5, loglevel = 0
01/01/2016 00:52:38;0040;PBS_Server;Svr;tyrone-cluster;Scheduler was sent the command time
01/01/2016 00:56:50;0002;PBS_Server;Svr;PBS_Server;Torque Server Version = 3.0.5, loglevel = 0
01/01/2016 01:01:50;0002;PBS_Server;Svr;PBS_Server;Torque Server Version = 3.0.5, loglevel = 0
01/01/2016 01:02:38;0040;PBS_Server;Svr;tyrone-cluster;Scheduler was sent the command time
01/01/2016 01:06:50;0002;PBS_Server;Svr;PBS_Server;Torque Server Version = 3.0.5, loglevel = 0
01/01/2016 01:11:50;0002;PBS_Server;Svr;PBS_Server;Torque Server Version = 3.0.5, loglevel = 0
01/01/2016 01:12:38;0040;PBS_Server;Svr;tyrone-cluster;Scheduler was sent the command time
01/01/2016 01:16:50;0002;PBS_Server;Svr;PBS_Server;Torque Server Version = 3.0.5, loglevel = 0
01/01/2016 01:21:50;0002;PBS_Server;Svr;PBS_Server;Torque Server Version = 3.0.5, loglevel = 0
01/01/2016 01:22:38;0040;PBS_Server;Svr;tyrone-cluster;Scheduler was sent the command time
01/01/2016 01:26:50;0002;PBS_Server;Svr;PBS_Server;Torque Server Version = 3.0.5, loglevel = 0
01/01/2016 01:31:50;0002;PBS_Server;Svr;PBS_Server;Torque Server Version = 3.0.5, loglevel = 0
01/01/2016 01:32:38;0040;PBS_Server;Svr;tyrone-cluster;Scheduler was sent the command time
01/01/2016 01:36:50;0002;PBS_Server;Svr;PBS_Server;Torque Server Version = 3.0.5, loglevel = 0
01/01/2016 01:41:50;0002;PBS_Server;Svr;PBS_Server;Torque Server Version = 3.0.5, loglevel = 0
01/01/2016 01:42:38;0040;PBS_Server;Svr;tyrone-cluster;Scheduler was sent the command time
01/01/2016 01:46:50;0002;PBS_Server;Svr;PBS_Server;Torque Server Version = 3.0.5, loglevel = 0
01/01/2016 01:51:50;0002;PBS_Server;Svr;PBS_Server;Torque Server Version = 3.0.5, loglevel = 0
01/01/2016 01:52:38;0040;PBS_Server;Svr;tyrone-cluster;Scheduler was sent the command time
01/01/2016 01:56:50;0002;PBS_Server;Svr;PBS_Server;Torque Server Version = 3.0.5, loglevel = 0
01/01/2016 02:01:50;0002;PBS_Server;Svr;PBS_Server;Torque Server Version = 3.0.5, loglevel = 0
01/01/2016 02:02:38;0040;PBS_Server;Svr;tyrone-cluster;Scheduler was sent the command time
01/01/2016 02:06:50;0002;PBS_Server;Svr;PBS_Server;Torque Server Version = 3.0.5, loglevel = 0
01/01/2016 02:11:50;0002;PBS_Server;Svr;PBS_Server;Torque Server Version = 3.0.5, loglevel = 0
01/01/2016 02:12:38;0040;PBS_Server;Svr;tyrone-cluster;Scheduler was sent the command time
01/01/2016 02:16:50;0002;PBS_Server;Svr;PBS_Server;Torque Server Version = 3.0.5, loglevel = 0
01/01/2016 02:21:50;0002;PBS_Server;Svr;PBS_Server;Torque Server Version = 3.0.5, loglevel = 0
01/01/2016 02:22:38;0040;PBS_Server;Svr;tyrone-cluster;Scheduler was sent the command time
01/01/2016 02:26:50;0002;PBS_Server;Svr;PBS_Server;Torque Server Version = 3.0.5, loglevel = 0
01/01/2016 02:31:50;0002;PBS_Server;Svr;PBS_Server;Torque Server Version = 3.0.5, loglevel = 0
01/01/2016 02:32:38;0040;PBS_Server;Svr;tyrone-cluster;Scheduler was sent the command time
01/01/2016 02:36:50;0002;PBS_Server;Svr;PBS_Server;Torque Server Version = 3.0.5, loglevel = 0
01/01/2016 02:41:50;0002;PBS_Server;Svr;PBS_Server;Torque Server Version = 3.0.5, loglevel = 0
01/01/2016 02:42:38;0040;PBS_Server;Svr;tyrone-cluster;Scheduler was sent the command time
01/01/2016 02:46:50;0002;PBS_Server;Svr;PBS_Server;Torque Server Version = 3.0.5, loglevel = 0
01/01/2016 02:51:50;0002;PBS_Server;Svr;PBS_Server;Torque Server Version = 3.0.5, loglevel = 0
01/01/2016 02:52:38;0040;PBS_Server;Svr;tyrone-cluster;Scheduler was sent the command time
01/01/2016 02:56:50;0002;PBS_Server;Svr;PBS_Server;Torque Server Version = 3.0.5, loglevel = 0
01/01/2016 03:01:50;0002;PBS_Server;Svr;PBS_Server;Torque Server Version = 3.0.5, loglevel = 0
01/01/2016 03:02:38;0040;PBS_Server;Svr;tyrone-cluster;Scheduler was sent the command time
01/01/2016 03:06:50;0002;PBS_Server;Svr;PBS_Server;Torque Server Version = 3.0.5, loglevel = 0
01/01/2016 03:11:50;0002;PBS_Server;Svr;PBS_Server;Torque Server Version = 3.0.5, loglevel = 0
01/01/2016 03:12:38;0040;PBS_Server;Svr;tyrone-cluster;Scheduler was sent the command time
01/01/2016 03:16:50;0002;PBS_Server;Svr;PBS_Server;Torque Server Version = 3.0.5, loglevel = 0
01/01/2016 03:21:50;0002;PBS_Server;Svr;PBS_Server;Torque Server Version = 3.0.5, loglevel = 0
01/01/2016 03:22:38;0040;PBS_Server;Svr;tyrone-cluster;Scheduler was sent the command time
01/01/2016 03:26:50;0002;PBS_Server;Svr;PBS_Server;Torque Server Version = 3.0.5, loglevel = 0
01/01/2016 03:31:50;0002;PBS_Server;Svr;PBS_Server;Torque Server Version = 3.0.5, loglevel = 0
01/01/2016 03:32:38;0040;PBS_Server;Svr;tyrone-cluster;Scheduler was sent the command time
01/01/2016 03:36:50;0002;PBS_Server;Svr;PBS_Server;Torque Server Version = 3.0.5, loglevel = 0
01/01/2016 03:41:50;0002;PBS_Server;Svr;PBS_Server;Torque Server Version = 3.0.5, loglevel = 0
01/01/2016 03:42:38;0040;PBS_Server;Svr;tyrone-cluster;Scheduler was sent the command time
01/01/2016 03:46:50;0002;PBS_Server;Svr;PBS_Server;Torque Server Version = 3.0.5, loglevel = 0
01/01/2016 03:51:50;0002;PBS_Server;Svr;PBS_Server;Torque Server Version = 3.0.5, loglevel = 0
01/01/2016 03:52:38;0040;PBS_Server;Svr;tyrone-cluster;Scheduler was sent the command time
01/01/2016 03:56:50;0002;PBS_Server;Svr;PBS_Server;Torque Server Version = 3.0.5, loglevel = 0
01/01/2016 04:01:50;0002;PBS_Server;Svr;PBS_Server;Torque Server Version = 3.0.5, loglevel = 0
01/01/2016 04:02:38;0040;PBS_Server;Svr;tyrone-cluster;Scheduler was sent the command time
01/01/2016 04:06:50;0002;PBS_Server;Svr;PBS_Server;Torque Server Version = 3.0.5, loglevel = 0
01/01/2016 04:11:50;0002;PBS_Server;Svr;PBS_Server;Torque Server Version = 3.0.5, loglevel = 0
01/01/2016 04:12:38;0040;PBS_Server;Svr;tyrone-cluster;Scheduler was sent the command time
01/01/2016 04:16:50;0002;PBS_Server;Svr;PBS_Server;Torque Server Version = 3.0.5, loglevel = 0
01/01/2016 04:21:50;0002;PBS_Server;Svr;PBS_Server;Torque Server Version = 3.0.5, loglevel = 0
01/01/2016 04:22:38;0040;PBS_Server;Svr;tyrone-cluster;Scheduler was sent the command time
01/01/2016 04:26:50;0002;PBS_Server;Svr;PBS_Server;Torque Server Version = 3.0.5, loglevel = 0
01/01/2016 04:31:50;0002;PBS_Server;Svr;PBS_Server;Torque Server Version = 3.0.5, loglevel = 0
01/01/2016 04:32:38;0040;PBS_Server;Svr;tyrone-cluster;Scheduler was sent the command time
01/01/2016 04:36:50;0002;PBS_Server;Svr;PBS_Server;Torque Server Version = 3.0.5, loglevel = 0
01/01/2016 04:41:50;0002;PBS_Server;Svr;PBS_Server;Torque Server Version = 3.0.5, loglevel = 0
01/01/2016 04:42:38;0040;PBS_Server;Svr;tyrone-cluster;Scheduler was sent the command time
01/01/2016 04:46:50;0002;PBS_Server;Svr;PBS_Server;Torque Server Version = 3.0.5, loglevel = 0
01/01/2016 04:51:50;0002;PBS_Server;Svr;PBS_Server;Torque Server Version = 3.0.5, loglevel = 0
01/01/2016 04:52:38;0040;PBS_Server;Svr;tyrone-cluster;Scheduler was sent the command time
01/01/2016 04:56:50;0002;PBS_Server;Svr;PBS_Server;Torque Server Version = 3.0.5, loglevel = 0
01/01/2016 05:01:50;0002;PBS_Server;Svr;PBS_Server;Torque Server Version = 3.0.5, loglevel = 0
01/01/2016 05:02:38;0040;PBS_Server;Svr;tyrone-cluster;Scheduler was sent the command time
01/01/2016 05:06:50;0002;PBS_Server;Svr;PBS_Server;Torque Server Version = 3.0.5, loglevel = 0
01/01/2016 05:11:50;0002;PBS_Server;Svr;PBS_Server;Torque Server Version = 3.0.5, loglevel = 0
01/01/2016 05:12:38;0040;PBS_Server;Svr;tyrone-cluster;Scheduler was sent the command time
01/01/2016 05:16:50;0002;PBS_Server;Svr;PBS_Server;Torque Server Version = 3.0.5, loglevel = 0
01/01/2016 05:21:50;0002;PBS_Server;Svr;PBS_Server;Torque Server Version = 3.0.5, loglevel = 0
01/01/2016 05:22:38;0040;PBS_Server;Svr;tyrone-cluster;Scheduler was sent the command time
01/01/2016 05:26:50;0002;PBS_Server;Svr;PBS_Server;Torque Server Version = 3.0.5, loglevel = 0
01/01/2016 05:31:50;0002;PBS_Server;Svr;PBS_Server;Torque Server Version = 3.0.5, loglevel = 0
01/01/2016 05:32:38;0040;PBS_Server;Svr;tyrone-cluster;Scheduler was sent the command time
01/01/2016 05:36:50;0002;PBS_Server;Svr;PBS_Server;Torque Server Version = 3.0.5, loglevel = 0
01/01/2016 05:41:50;0002;PBS_Server;Svr;PBS_Server;Torque Server Version = 3.0.5, loglevel = 0
01/01/2016 05:42:38;0040;PBS_Server;Svr;tyrone-cluster;Scheduler was sent the command time
01/01/2016 05:46:50;0002;PBS_Server;Svr;PBS_Server;Torque Server Version = 3.0.5, loglevel = 0
01/01/2016 05:51:50;0002;PBS_Server;Svr;PBS_Server;Torque Server Version = 3.0.5, loglevel = 0
01/01/2016 05:52:38;0040;PBS_Server;Svr;tyrone-cluster;Scheduler was sent the command time
01/01/2016 05:56:50;0002;PBS_Server;Svr;PBS_Server;Torque Server Version = 3.0.5, loglevel = 0
01/01/2016 06:01:50;0002;PBS_Server;Svr;PBS_Server;Torque Server Version = 3.0.5, loglevel = 0
01/01/2016 06:02:38;0040;PBS_Server;Svr;tyrone-cluster;Scheduler was sent the command time
01/01/2016 06:06:50;0002;PBS_Server;Svr;PBS_Server;Torque Server Version = 3.0.5, loglevel = 0
01/01/2016 06:11:50;0002;PBS_Server;Svr;PBS_Server;Torque Server Version = 3.0.5, loglevel = 0
01/01/2016 06:12:38;0040;PBS_Server;Svr;tyrone-cluster;Scheduler was sent the command time
01/01/2016 06:16:50;0002;PBS_Server;Svr;PBS_Server;Torque Server Version = 3.0.5, loglevel = 0
01/01/2016 06:21:50;0002;PBS_Server;Svr;PBS_Server;Torque Server Version = 3.0.5, loglevel = 0
01/01/2016 06:22:38;0040;PBS_Server;Svr;tyrone-cluster;Scheduler was sent the command time
01/01/2016 06:26:50;0002;PBS_Server;Svr;PBS_Server;Torque Server Version = 3.0.5, loglevel = 0
01/01/2016 06:31:50;0002;PBS_Server;Svr;PBS_Server;Torque Server Version = 3.0.5, loglevel = 0
01/01/2016 06:32:38;0040;PBS_Server;Svr;tyrone-cluster;Scheduler was sent the command time
01/01/2016 06:36:50;0002;PBS_Server;Svr;PBS_Server;Torque Server Version = 3.0.5, loglevel = 0
01/01/2016 06:41:50;0002;PBS_Server;Svr;PBS_Server;Torque Server Version = 3.0.5, loglevel = 0
01/01/2016 06:42:38;0040;PBS_Server;Svr;tyrone-cluster;Scheduler was sent the command time
01/01/2016 06:46:50;0002;PBS_Server;Svr;PBS_Server;Torque Server Version = 3.0.5, loglevel = 0
01/01/2016 06:51:50;0002;PBS_Server;Svr;PBS_Server;Torque Server Version = 3.0.5, loglevel = 0
01/01/2016 06:52:38;0040;PBS_Server;Svr;tyrone-cluster;Scheduler was sent the command time
01/01/2016 06:56:50;0002;PBS_Server;Svr;PBS_Server;Torque Server Version = 3.0.5, loglevel = 0
01/01/2016 07:01:50;0002;PBS_Server;Svr;PBS_Server;Torque Server Version = 3.0.5, loglevel = 0
01/01/2016 07:02:38;0040;PBS_Server;Svr;tyrone-cluster;Scheduler was sent the command time
01/01/2016 07:06:50;0002;PBS_Server;Svr;PBS_Server;Torque Server Version = 3.0.5, loglevel = 0
01/01/2016 07:11:50;0002;PBS_Server;Svr;PBS_Server;Torque Server Version = 3.0.5, loglevel = 0
01/01/2016 07:12:38;0040;PBS_Server;Svr;tyrone-cluster;Scheduler was sent the command time
01/01/2016 07:16:50;0002;PBS_Server;Svr;PBS_Server;Torque Server Version = 3.0.5, loglevel = 0
01/01/2016 07:21:50;0002;PBS_Server;Svr;PBS_Server;Torque Server Version = 3.0.5, loglevel = 0
01/01/2016 07:22:38;0040;PBS_Server;Svr;tyrone-cluster;Scheduler was sent the command time
01/01/2016 07:26:50;0002;PBS_Server;Svr;PBS_Server;Torque Server Version = 3.0.5, loglevel = 0
01/01/2016 07:31:50;0002;PBS_Server;Svr;PBS_Server;Torque Server Version = 3.0.5, loglevel = 0
01/01/2016 07:32:38;0040;PBS_Server;Svr;tyrone-cluster;Scheduler was sent the command time
01/01/2016 07:36:50;0002;PBS_Server;Svr;PBS_Server;Torque Server Version = 3.0.5, loglevel = 0
01/01/2016 07:41:50;0002;PBS_Server;Svr;PBS_Server;Torque Server Version = 3.0.5, loglevel = 0
01/01/2016 07:42:38;0040;PBS_Server;Svr;tyrone-cluster;Scheduler was sent the command time
01/01/2016 07:46:50;0002;PBS_Server;Svr;PBS_Server;Torque Server Version = 3.0.5, loglevel = 0
01/01/2016 07:51:50;0002;PBS_Server;Svr;PBS_Server;Torque Server Version = 3.0.5, loglevel = 0
01/01/2016 07:52:38;0040;PBS_Server;Svr;tyrone-cluster;Scheduler was sent the command time
01/01/2016 07:56:50;0002;PBS_Server;Svr;PBS_Server;Torque Server Version = 3.0.5, loglevel = 0
01/01/2016 08:01:50;0002;PBS_Server;Svr;PBS_Server;Torque Server Version = 3.0.5, loglevel = 0
01/01/2016 08:02:38;0040;PBS_Server;Svr;tyrone-cluster;Scheduler was sent the command time
01/01/2016 08:03:07;000d;PBS_Server;Job;58855.tyrone-cluster;Not sending email: User does not want mail of this type.
01/01/2016 08:03:07;0002;PBS_Server;Svr;Act;Account file /var/spool/torque/server_priv/accounting/20160101 opened
01/01/2016 08:03:07;0010;PBS_Server;Job;58855.tyrone-cluster;Exit_status=11 resources_used.cput=459:01:22 resources_used.mem=30855852kb resources_used.vmem=36954344kb resources_used.walltime=14:29:18
01/01/2016 08:03:07;0008;PBS_Server;Job;NULL;on_job_exit valid pjob: 0x2aa9a00 (substate=50)
01/01/2016 08:03:07;0008;PBS_Server;Job;NULL;on_job_exit valid pjob: 0x2aa9a00 (substate=51)
01/01/2016 08:03:07;0008;PBS_Server;Job;NULL;on_job_exit valid pjob: 0x2aa9a00 (substate=51)
01/01/2016 08:03:07;0008;PBS_Server;Job;NULL;on_job_exit valid pjob: 0x2aa9a00 (substate=53)
01/01/2016 08:03:07;0100;PBS_Server;Job;58855.tyrone-cluster;dequeuing from qp32, state COMPLETE
01/01/2016 08:03:07;0040;PBS_Server;Svr;tyrone-cluster;Scheduler was sent the command term
01/01/2016 08:06:50;0002;PBS_Server;Svr;PBS_Server;Torque Server Version = 3.0.5, loglevel = 0
01/01/2016 08:11:50;0002;PBS_Server;Svr;PBS_Server;Torque Server Version = 3.0.5, loglevel = 0
01/01/2016 08:13:07;0040;PBS_Server;Svr;tyrone-cluster;Scheduler was sent the command time
01/01/2016 08:16:50;0002;PBS_Server;Svr;PBS_Server;Torque Server Version = 3.0.5, loglevel = 0
01/01/2016 08:21:50;0002;PBS_Server;Svr;PBS_Server;Torque Server Version = 3.0.5, loglevel = 0
01/01/2016 08:23:07;0040;PBS_Server;Svr;tyrone-cluster;Scheduler was sent the command time
01/01/2016 08:26:51;0002;PBS_Server;Svr;PBS_Server;Torque Server Version = 3.0.5, loglevel = 0
01/01/2016 08:31:51;0002;PBS_Server;Svr;PBS_Server;Torque Server Version = 3.0.5, loglevel = 0
01/01/2016 08:33:07;0040;PBS_Server;Svr;tyrone-cluster;Scheduler was sent the command time
01/01/2016 08:36:51;0002;PBS_Server;Svr;PBS_Server;Torque Server Version = 3.0.5, loglevel = 0
01/01/2016 08:41:51;0002;PBS_Server;Svr;PBS_Server;Torque Server Version = 3.0.5, loglevel = 0
01/01/2016 08:43:07;0040;PBS_Server;Svr;tyrone-cluster;Scheduler was sent the command time
01/01/2016 08:46:51;0002;PBS_Server;Svr;PBS_Server;Torque Server Version = 3.0.5, loglevel = 0
01/01/2016 08:51:51;0002;PBS_Server;Svr;PBS_Server;Torque Server Version = 3.0.5, loglevel = 0
01/01/2016 08:53:07;0040;PBS_Server;Svr;tyrone-cluster;Scheduler was sent the command time
01/01/2016 08:56:51;0002;PBS_Server;Svr;PBS_Server;Torque Server Version = 3.0.5, loglevel = 0
01/01/2016 09:01:51;0002;PBS_Server;Svr;PBS_Server;Torque Server Version = 3.0.5, loglevel = 0
01/01/2016 09:03:07;0040;PBS_Server;Svr;tyrone-cluster;Scheduler was sent the command time
01/01/2016 09:06:51;0002;PBS_Server;Svr;PBS_Server;Torque Server Version = 3.0.5, loglevel = 0
01/01/2016 09:11:51;0002;PBS_Server;Svr;PBS_Server;Torque Server Version = 3.0.5, loglevel = 0
01/01/2016 09:13:07;0040;PBS_Server;Svr;tyrone-cluster;Scheduler was sent the command time
01/01/2016 09:16:51;0002;PBS_Server;Svr;PBS_Server;Torque Server Version = 3.0.5, loglevel = 0
01/01/2016 09:21:51;0002;PBS_Server;Svr;PBS_Server;Torque Server Version = 3.0.5, loglevel = 0
01/01/2016 09:23:07;0040;PBS_Server;Svr;tyrone-cluster;Scheduler was sent the command time
01/01/2016 09:26:51;0002;PBS_Server;Svr;PBS_Server;Torque Server Version = 3.0.5, loglevel = 0
01/01/2016 09:31:51;0002;PBS_Server;Svr;PBS_Server;Torque Server Version = 3.0.5, loglevel = 0
01/01/2016 09:33:07;0040;PBS_Server;Svr;tyrone-cluster;Scheduler was sent the command time
01/01/2016 09:36:51;0002;PBS_Server;Svr;PBS_Server;Torque Server Version = 3.0.5, loglevel = 0
01/01/2016 09:41:51;0002;PBS_Server;Svr;PBS_Server;Torque Server Version = 3.0.5, loglevel = 0
01/01/2016 09:43:07;0040;PBS_Server;Svr;tyrone-cluster;Scheduler was sent the command time
01/01/2016 09:46:51;0002;PBS_Server;Svr;PBS_Server;Torque Server Version = 3.0.5, loglevel = 0
01/01/2016 09:51:51;0002;PBS_Server;Svr;PBS_Server;Torque Server Version = 3.0.5, loglevel = 0
01/01/2016 09:53:07;0040;PBS_Server;Svr;tyrone-cluster;Scheduler was sent the command time
01/01/2016 09:56:51;0002;PBS_Server;Svr;PBS_Server;Torque Server Version = 3.0.5, loglevel = 0
01/01/2016 10:01:51;0002;PBS_Server;Svr;PBS_Server;Torque Server Version = 3.0.5, loglevel = 0
01/01/2016 10:03:07;0040;PBS_Server;Svr;tyrone-cluster;Scheduler was sent the command time
01/01/2016 10:06:51;0002;PBS_Server;Svr;PBS_Server;Torque Server Version = 3.0.5, loglevel = 0
01/01/2016 10:11:51;0002;PBS_Server;Svr;PBS_Server;Torque Server Version = 3.0.5, loglevel = 0
01/01/2016 10:13:07;0040;PBS_Server;Svr;tyrone-cluster;Scheduler was sent the command time
01/01/2016 10:16:51;0002;PBS_Server;Svr;PBS_Server;Torque Server Version = 3.0.5, loglevel = 0
01/01/2016 10:21:51;0002;PBS_Server;Svr;PBS_Server;Torque Server Version = 3.0.5, loglevel = 0
01/01/2016 10:23:07;0040;PBS_Server;Svr;tyrone-cluster;Scheduler was sent the command time
01/01/2016 10:26:51;0002;PBS_Server;Svr;PBS_Server;Torque Server Version = 3.0.5, loglevel = 0
01/01/2016 10:31:51;0002;PBS_Server;Svr;PBS_Server;Torque Server Version = 3.0.5, loglevel = 0
01/01/2016 10:33:07;0040;PBS_Server;Svr;tyrone-cluster;Scheduler was sent the command time
01/01/2016 10:36:51;0002;PBS_Server;Svr;PBS_Server;Torque Server Version = 3.0.5, loglevel = 0
01/01/2016 10:41:51;0002;PBS_Server;Svr;PBS_Server;Torque Server Version = 3.0.5, loglevel = 0
01/01/2016 10:43:07;0040;PBS_Server;Svr;tyrone-cluster;Scheduler was sent the command time
01/01/2016 10:46:51;0002;PBS_Server;Svr;PBS_Server;Torque Server Version = 3.0.5, loglevel = 0
01/01/2016 10:51:51;0002;PBS_Server;Svr;PBS_Server;Torque Server Version = 3.0.5, loglevel = 0
01/01/2016 10:53:07;0040;PBS_Server;Svr;tyrone-cluster;Scheduler was sent the command time
01/01/2016 10:56:51;0002;PBS_Server;Svr;PBS_Server;Torque Server Version = 3.0.5, loglevel = 0
01/01/2016 11:01:51;0002;PBS_Server;Svr;PBS_Server;Torque Server Version = 3.0.5, loglevel = 0
01/01/2016 11:03:07;0040;PBS_Server;Svr;tyrone-cluster;Scheduler was sent the command time
01/01/2016 11:06:51;0002;PBS_Server;Svr;PBS_Server;Torque Server Version = 3.0.5, loglevel = 0
01/01/2016 11:11:51;0002;PBS_Server;Svr;PBS_Server;Torque Server Version = 3.0.5, loglevel = 0
01/01/2016 11:13:07;0040;PBS_Server;Svr;tyrone-cluster;Scheduler was sent the command time
01/01/2016 11:16:51;0002;PBS_Server;Svr;PBS_Server;Torque Server Version = 3.0.5, loglevel = 0
01/01/2016 11:21:51;0002;PBS_Server;Svr;PBS_Server;Torque Server Version = 3.0.5, loglevel = 0
01/01/2016 11:23:07;0040;PBS_Server;Svr;tyrone-cluster;Scheduler was sent the command time
01/01/2016 11:26:51;0002;PBS_Server;Svr;PBS_Server;Torque Server Version = 3.0.5, loglevel = 0
01/01/2016 11:31:51;0002;PBS_Server;Svr;PBS_Server;Torque Server Version = 3.0.5, loglevel = 0
01/01/2016 11:33:07;0040;PBS_Server;Svr;tyrone-cluster;Scheduler was sent the command time
01/01/2016 11:36:51;0002;PBS_Server;Svr;PBS_Server;Torque Server Version = 3.0.5, loglevel = 0
01/01/2016 11:41:51;0002;PBS_Server;Svr;PBS_Server;Torque Server Version = 3.0.5, loglevel = 0
01/01/2016 11:43:07;0040;PBS_Server;Svr;tyrone-cluster;Scheduler was sent the command time
01/01/2016 11:46:51;0002;PBS_Server;Svr;PBS_Server;Torque Server Version = 3.0.5, loglevel = 0
01/01/2016 11:51:51;0002;PBS_Server;Svr;PBS_Server;Torque Server Version = 3.0.5, loglevel = 0
01/01/2016 11:53:07;0040;PBS_Server;Svr;tyrone-cluster;Scheduler was sent the command time
01/01/2016 11:56:51;0002;PBS_Server;Svr;PBS_Server;Torque Server Version = 3.0.5, loglevel = 0
01/01/2016 12:01:51;0002;PBS_Server;Svr;PBS_Server;Torque Server Version = 3.0.5, loglevel = 0
01/01/2016 12:03:07;0040;PBS_Server;Svr;tyrone-cluster;Scheduler was sent the command time
01/01/2016 12:06:51;0002;PBS_Server;Svr;PBS_Server;Torque Server Version = 3.0.5, loglevel = 0
01/01/2016 12:11:51;0002;PBS_Server;Svr;PBS_Server;Torque Server Version = 3.0.5, loglevel = 0
01/01/2016 12:13:07;0040;PBS_Server;Svr;tyrone-cluster;Scheduler was sent the command time
01/01/2016 12:14:19;0100;PBS_Server;Job;58857.tyrone-cluster;enqueuing into batch, state 1 hop 1
01/01/2016 12:14:19;0100;PBS_Server;Job;58857.tyrone-cluster;dequeuing from batch, state QUEUED
01/01/2016 12:14:19;0100;PBS_Server;Job;58857.tyrone-cluster;enqueuing into qp32, state 1 hop 1
01/01/2016 12:14:19;0008;PBS_Server;Job;58857.tyrone-cluster;Job Queued at request of chearit@tyrone-cluster, owner = chearit@tyrone-cluster, job name = jobname, queue = qp32
01/01/2016 12:14:19;0040;PBS_Server;Svr;tyrone-cluster;Scheduler was sent the command new
01/01/2016 12:14:19;0008;PBS_Server;Job;58857.tyrone-cluster;Job Modified at request of Scheduler@tyrone-cluster
01/01/2016 12:14:19;0008;PBS_Server;Job;58857.tyrone-cluster;Job Run at request of Scheduler@tyrone-cluster
01/01/2016 12:14:19;0040;PBS_Server;Svr;tyrone-cluster;Scheduler was sent the command recyc
01/01/2016 12:14:19;000d;PBS_Server;Job;58857.tyrone-cluster;Not sending email: User does not want mail of this type.
01/01/2016 12:16:51;0002;PBS_Server;Svr;PBS_Server;Torque Server Version = 3.0.5, loglevel = 0
01/01/2016 12:21:51;0002;PBS_Server;Svr;PBS_Server;Torque Server Version = 3.0.5, loglevel = 0
01/01/2016 12:24:19;0040;PBS_Server;Svr;tyrone-cluster;Scheduler was sent the command time
01/01/2016 12:26:51;0002;PBS_Server;Svr;PBS_Server;Torque Server Version = 3.0.5, loglevel = 0
01/01/2016 12:31:43;0100;PBS_Server;Job;58858.tyrone-cluster;enqueuing into batch, state 1 hop 1
01/01/2016 12:31:43;0100;PBS_Server;Job;58858.tyrone-cluster;dequeuing from batch, state QUEUED
01/01/2016 12:31:43;0100;PBS_Server;Job;58858.tyrone-cluster;enqueuing into qp128, state 1 hop 1
01/01/2016 12:31:43;0008;PBS_Server;Job;58858.tyrone-cluster;Job Queued at request of cesthyag@tyrone-cluster, owner = cesthyag@tyrone-cluster, job name = cig_test, queue = qp128
01/01/2016 12:31:43;0040;PBS_Server;Svr;tyrone-cluster;Scheduler was sent the command new
01/01/2016 12:31:44;0008;PBS_Server;Job;58858.tyrone-cluster;Job Modified at request of Scheduler@tyrone-cluster
01/01/2016 12:31:44;0008;PBS_Server;Job;58858.tyrone-cluster;Job Run at request of Scheduler@tyrone-cluster
01/01/2016 12:31:44;0040;PBS_Server;Svr;tyrone-cluster;Scheduler was sent the command recyc
01/01/2016 12:31:51;0002;PBS_Server;Svr;PBS_Server;Torque Server Version = 3.0.5, loglevel = 0
01/01/2016 12:32:35;000d;PBS_Server;Job;58858.tyrone-cluster;Not sending email: User does not want mail of this type.
01/01/2016 12:34:44;000d;PBS_Server;Job;58858.tyrone-cluster;Not sending email: User does not want mail of this type.
01/01/2016 12:34:44;0010;PBS_Server;Job;58858.tyrone-cluster;Exit_status=0 resources_used.cput=04:24:53 resources_used.mem=15642276kb resources_used.vmem=54995348kb resources_used.walltime=00:03:01
01/01/2016 12:34:44;0008;PBS_Server;Job;NULL;on_job_exit valid pjob: 0x2aa80e0 (substate=50)
01/01/2016 12:34:44;0008;PBS_Server;Job;NULL;on_job_exit valid pjob: 0x2aa80e0 (substate=51)
01/01/2016 12:34:44;0008;PBS_Server;Job;NULL;on_job_exit valid pjob: 0x2aa80e0 (substate=51)
01/01/2016 12:34:44;0008;PBS_Server;Job;NULL;on_job_exit valid pjob: 0x2aa80e0 (substate=53)
01/01/2016 12:34:44;0100;PBS_Server;Job;58858.tyrone-cluster;dequeuing from qp128, state COMPLETE
01/01/2016 12:34:44;0040;PBS_Server;Svr;tyrone-cluster;Scheduler was sent the command term
01/01/2016 12:35:52;0100;PBS_Server;Job;58859.tyrone-cluster;enqueuing into batch, state 1 hop 1
01/01/2016 12:35:52;0100;PBS_Server;Job;58859.tyrone-cluster;dequeuing from batch, state QUEUED
01/01/2016 12:35:52;0100;PBS_Server;Job;58859.tyrone-cluster;enqueuing into qp128, state 1 hop 1
01/01/2016 12:35:52;0008;PBS_Server;Job;58859.tyrone-cluster;Job Queued at request of cesthyag@tyrone-cluster, owner = cesthyag@tyrone-cluster, job name = cig_test, queue = qp128
01/01/2016 12:35:52;0040;PBS_Server;Svr;tyrone-cluster;Scheduler was sent the command new
01/01/2016 12:35:52;0008;PBS_Server;Job;58859.tyrone-cluster;Job Modified at request of Scheduler@tyrone-cluster
01/01/2016 12:35:52;0008;PBS_Server;Job;58859.tyrone-cluster;Job Run at request of Scheduler@tyrone-cluster
01/01/2016 12:35:52;0040;PBS_Server;Svr;tyrone-cluster;Scheduler was sent the command recyc
01/01/2016 12:36:22;000d;PBS_Server;Job;58859.tyrone-cluster;Not sending email: User does not want mail of this type.
01/01/2016 12:36:26;0100;PBS_Server;Job;58860.tyrone-cluster;enqueuing into batch, state 1 hop 1
01/01/2016 12:36:26;0100;PBS_Server;Job;58860.tyrone-cluster;dequeuing from batch, state QUEUED
01/01/2016 12:36:26;0100;PBS_Server;Job;58860.tyrone-cluster;enqueuing into qp128, state 1 hop 1
01/01/2016 12:36:26;0008;PBS_Server;Job;58860.tyrone-cluster;Job Queued at request of cesthyag@tyrone-cluster, owner = cesthyag@tyrone-cluster, job name = cig_test, queue = qp128
01/01/2016 12:36:26;0040;PBS_Server;Svr;tyrone-cluster;Scheduler was sent the command new
01/01/2016 12:36:26;0008;PBS_Server;Job;58860.tyrone-cluster;Job Modified at request of Scheduler@tyrone-cluster
01/01/2016 12:36:51;0002;PBS_Server;Svr;PBS_Server;Torque Server Version = 3.0.5, loglevel = 0
01/01/2016 12:38:36;000d;PBS_Server;Job;58859.tyrone-cluster;Not sending email: User does not want mail of this type.
01/01/2016 12:38:36;0010;PBS_Server;Job;58859.tyrone-cluster;Exit_status=0 resources_used.cput=03:27:58 resources_used.mem=15650188kb resources_used.vmem=54984936kb resources_used.walltime=00:02:44
01/01/2016 12:38:36;0008;PBS_Server;Job;NULL;on_job_exit valid pjob: 0x2aa80e0 (substate=50)
01/01/2016 12:38:36;0008;PBS_Server;Job;NULL;on_job_exit valid pjob: 0x2aa80e0 (substate=51)
01/01/2016 12:38:36;0008;PBS_Server;Job;NULL;on_job_exit valid pjob: 0x2aa80e0 (substate=51)
01/01/2016 12:38:36;0008;PBS_Server;Job;NULL;on_job_exit valid pjob: 0x2aa80e0 (substate=53)
01/01/2016 12:38:36;0100;PBS_Server;Job;58859.tyrone-cluster;dequeuing from qp128, state COMPLETE
01/01/2016 12:38:36;0040;PBS_Server;Svr;tyrone-cluster;Scheduler was sent the command term
01/01/2016 12:38:36;0008;PBS_Server;Job;58860.tyrone-cluster;Job Modified at request of Scheduler@tyrone-cluster
01/01/2016 12:38:36;0008;PBS_Server;Job;58860.tyrone-cluster;Job Run at request of Scheduler@tyrone-cluster
01/01/2016 12:38:36;0040;PBS_Server;Svr;tyrone-cluster;Scheduler was sent the command recyc
01/01/2016 12:39:24;000d;PBS_Server;Job;58860.tyrone-cluster;Not sending email: User does not want mail of this type.
01/01/2016 12:41:51;0002;PBS_Server;Svr;PBS_Server;Torque Server Version = 3.0.5, loglevel = 0
01/01/2016 12:46:51;0002;PBS_Server;Svr;PBS_Server;Torque Server Version = 3.0.5, loglevel = 0
01/01/2016 12:48:36;0040;PBS_Server;Svr;tyrone-cluster;Scheduler was sent the command time
01/01/2016 12:51:51;0002;PBS_Server;Svr;PBS_Server;Torque Server Version = 3.0.5, loglevel = 0
01/01/2016 12:56:51;0002;PBS_Server;Svr;PBS_Server;Torque Server Version = 3.0.5, loglevel = 0
01/01/2016 12:58:36;0040;PBS_Server;Svr;tyrone-cluster;Scheduler was sent the command time
01/01/2016 12:59:38;0100;PBS_Server;Job;58861.tyrone-cluster;enqueuing into batch, state 1 hop 1
01/01/2016 12:59:38;0100;PBS_Server;Job;58861.tyrone-cluster;dequeuing from batch, state QUEUED
01/01/2016 12:59:38;0100;PBS_Server;Job;58861.tyrone-cluster;enqueuing into qp64, state 1 hop 1
01/01/2016 12:59:38;0008;PBS_Server;Job;58861.tyrone-cluster;Job Queued at request of chearit@tyrone-cluster, owner = chearit@tyrone-cluster, job name = testpara, queue = qp64
01/01/2016 12:59:38;0040;PBS_Server;Svr;tyrone-cluster;Scheduler was sent the command new
01/01/2016 12:59:38;0008;PBS_Server;Job;58861.tyrone-cluster;Job Modified at request of Scheduler@tyrone-cluster
01/01/2016 12:59:38;0008;PBS_Server;Job;58861.tyrone-cluster;Job Run at request of Scheduler@tyrone-cluster
01/01/2016 12:59:38;0040;PBS_Server;Svr;tyrone-cluster;Scheduler was sent the command recyc
01/01/2016 13:00:26;000d;PBS_Server;Job;58861.tyrone-cluster;Not sending email: User does not want mail of this type.
01/01/2016 13:01:51;0002;PBS_Server;Svr;PBS_Server;Torque Server Version = 3.0.5, loglevel = 0
01/01/2016 13:06:51;0002;PBS_Server;Svr;PBS_Server;Torque Server Version = 3.0.5, loglevel = 0
01/01/2016 13:09:38;0040;PBS_Server;Svr;tyrone-cluster;Scheduler was sent the command time
01/01/2016 13:11:51;0002;PBS_Server;Svr;PBS_Server;Torque Server Version = 3.0.5, loglevel = 0
01/01/2016 13:16:51;0002;PBS_Server;Svr;PBS_Server;Torque Server Version = 3.0.5, loglevel = 0
01/01/2016 13:19:38;0040;PBS_Server;Svr;tyrone-cluster;Scheduler was sent the command time
01/01/2016 13:21:51;0002;PBS_Server;Svr;PBS_Server;Torque Server Version = 3.0.5, loglevel = 0
01/01/2016 13:26:51;0002;PBS_Server;Svr;PBS_Server;Torque Server Version = 3.0.5, loglevel = 0
01/01/2016 13:29:38;0040;PBS_Server;Svr;tyrone-cluster;Scheduler was sent the command time
01/01/2016 13:31:51;0002;PBS_Server;Svr;PBS_Server;Torque Server Version = 3.0.5, loglevel = 0
01/01/2016 13:36:51;0002;PBS_Server;Svr;PBS_Server;Torque Server Version = 3.0.5, loglevel = 0
01/01/2016 13:39:38;0040;PBS_Server;Svr;tyrone-cluster;Scheduler was sent the command time
01/01/2016 13:41:51;0002;PBS_Server;Svr;PBS_Server;Torque Server Version = 3.0.5, loglevel = 0
01/01/2016 13:46:51;0002;PBS_Server;Svr;PBS_Server;Torque Server Version = 3.0.5, loglevel = 0
01/01/2016 13:49:38;0040;PBS_Server;Svr;tyrone-cluster;Scheduler was sent the command time
01/01/2016 13:51:51;0002;PBS_Server;Svr;PBS_Server;Torque Server Version = 3.0.5, loglevel = 0
01/01/2016 13:56:28;0100;PBS_Server;Job;58862.tyrone-cluster;enqueuing into batch, state 1 hop 1
01/01/2016 13:56:28;0100;PBS_Server;Job;58862.tyrone-cluster;dequeuing from batch, state QUEUED
01/01/2016 13:56:28;0100;PBS_Server;Job;58862.tyrone-cluster;enqueuing into qp32, state 1 hop 1
01/01/2016 13:56:28;0008;PBS_Server;Job;58862.tyrone-cluster;Job Queued at request of secvarma@tyrone-cluster, owner = secvarma@tyrone-cluster, job name = simple_8c_s20, queue = qp32
01/01/2016 13:56:28;0040;PBS_Server;Svr;tyrone-cluster;Scheduler was sent the command new
01/01/2016 13:56:28;0008;PBS_Server;Job;58862.tyrone-cluster;Job Modified at request of Scheduler@tyrone-cluster
01/01/2016 13:56:28;0008;PBS_Server;Job;58862.tyrone-cluster;Job Run at request of Scheduler@tyrone-cluster
01/01/2016 13:56:28;0040;PBS_Server;Svr;tyrone-cluster;Scheduler was sent the command recyc
01/01/2016 13:56:28;000d;PBS_Server;Job;58862.tyrone-cluster;Not sending email: User does not want mail of this type.
01/01/2016 13:56:51;0002;PBS_Server;Svr;PBS_Server;Torque Server Version = 3.0.5, loglevel = 0
01/01/2016 13:57:01;000d;PBS_Server;Job;58862.tyrone-cluster;Not sending email: User does not want mail of this type.
01/01/2016 13:57:01;0010;PBS_Server;Job;58862.tyrone-cluster;Exit_status=0 resources_used.cput=00:04:12 resources_used.mem=311068kb resources_used.vmem=1124564kb resources_used.walltime=00:00:33
01/01/2016 13:57:01;0008;PBS_Server;Job;NULL;on_job_exit valid pjob: 0x2aaed40 (substate=50)
01/01/2016 13:57:01;0008;PBS_Server;Job;NULL;on_job_exit valid pjob: 0x2aaed40 (substate=51)
01/01/2016 13:57:01;0008;PBS_Server;Job;NULL;on_job_exit valid pjob: 0x2aaed40 (substate=51)
01/01/2016 13:57:01;0008;PBS_Server;Job;NULL;on_job_exit valid pjob: 0x2aaed40 (substate=53)
01/01/2016 13:57:01;0100;PBS_Server;Job;58862.tyrone-cluster;dequeuing from qp32, state COMPLETE
01/01/2016 13:57:01;0040;PBS_Server;Svr;tyrone-cluster;Scheduler was sent the command term
01/01/2016 13:57:05;0100;PBS_Server;Job;58863.tyrone-cluster;enqueuing into batch, state 1 hop 1
01/01/2016 13:57:05;0100;PBS_Server;Job;58863.tyrone-cluster;dequeuing from batch, state QUEUED
01/01/2016 13:57:05;0100;PBS_Server;Job;58863.tyrone-cluster;enqueuing into qp32, state 1 hop 1
01/01/2016 13:57:05;0008;PBS_Server;Job;58863.tyrone-cluster;Job Queued at request of secvarma@tyrone-cluster, owner = secvarma@tyrone-cluster, job name = simple_16c_s20, queue = qp32
01/01/2016 13:57:05;0040;PBS_Server;Svr;tyrone-cluster;Scheduler was sent the command new
01/01/2016 13:57:05;0008;PBS_Server;Job;58863.tyrone-cluster;Job Modified at request of Scheduler@tyrone-cluster
01/01/2016 13:57:05;0008;PBS_Server;Job;58863.tyrone-cluster;Job Run at request of Scheduler@tyrone-cluster
01/01/2016 13:57:05;0040;PBS_Server;Svr;tyrone-cluster;Scheduler was sent the command recyc
01/01/2016 13:57:05;000d;PBS_Server;Job;58863.tyrone-cluster;Not sending email: User does not want mail of this type.
01/01/2016 13:57:28;000d;PBS_Server;Job;58863.tyrone-cluster;Not sending email: User does not want mail of this type.
01/01/2016 13:57:28;0010;PBS_Server;Job;58863.tyrone-cluster;Exit_status=0 resources_used.cput=00:05:56 resources_used.mem=686620kb resources_used.vmem=2173160kb resources_used.walltime=00:00:23
01/01/2016 13:57:28;0008;PBS_Server;Job;NULL;on_job_exit valid pjob: 0x2aaed40 (substate=50)
01/01/2016 13:57:28;0008;PBS_Server;Job;NULL;on_job_exit valid pjob: 0x2aaed40 (substate=51)
01/01/2016 13:57:28;0008;PBS_Server;Job;NULL;on_job_exit valid pjob: 0x2aaed40 (substate=51)
01/01/2016 13:57:28;0008;PBS_Server;Job;NULL;on_job_exit valid pjob: 0x2aaed40 (substate=53)
01/01/2016 13:57:28;0100;PBS_Server;Job;58863.tyrone-cluster;dequeuing from qp32, state COMPLETE
01/01/2016 13:57:28;0040;PBS_Server;Svr;tyrone-cluster;Scheduler was sent the command term
01/01/2016 14:01:22;0100;PBS_Server;Job;58864.tyrone-cluster;enqueuing into batch, state 1 hop 1
01/01/2016 14:01:22;0100;PBS_Server;Job;58864.tyrone-cluster;dequeuing from batch, state QUEUED
01/01/2016 14:01:22;0100;PBS_Server;Job;58864.tyrone-cluster;enqueuing into qp32, state 1 hop 1
01/01/2016 14:01:22;0008;PBS_Server;Job;58864.tyrone-cluster;Job Queued at request of secvarma@tyrone-cluster, owner = secvarma@tyrone-cluster, job name = simple_32c_s20, queue = qp32
01/01/2016 14:01:22;0040;PBS_Server;Svr;tyrone-cluster;Scheduler was sent the command new
01/01/2016 14:01:22;0008;PBS_Server;Job;58864.tyrone-cluster;Job Modified at request of Scheduler@tyrone-cluster
01/01/2016 14:01:22;0008;PBS_Server;Job;58864.tyrone-cluster;Job Run at request of Scheduler@tyrone-cluster
01/01/2016 14:01:22;0040;PBS_Server;Svr;tyrone-cluster;Scheduler was sent the command recyc
01/01/2016 14:01:22;000d;PBS_Server;Job;58864.tyrone-cluster;Not sending email: User does not want mail of this type.
01/01/2016 14:01:51;0002;PBS_Server;Svr;PBS_Server;Torque Server Version = 3.0.5, loglevel = 0
01/01/2016 14:01:52;0100;PBS_Server;Job;58865.tyrone-cluster;enqueuing into batch, state 1 hop 1
01/01/2016 14:01:52;0100;PBS_Server;Job;58865.tyrone-cluster;dequeuing from batch, state QUEUED
01/01/2016 14:01:52;0100;PBS_Server;Job;58865.tyrone-cluster;enqueuing into qp64, state 1 hop 1
01/01/2016 14:01:52;0008;PBS_Server;Job;58865.tyrone-cluster;Job Queued at request of secvarma@tyrone-cluster, owner = secvarma@tyrone-cluster, job name = simple_64c_s20, queue = qp64
01/01/2016 14:01:52;0040;PBS_Server;Svr;tyrone-cluster;Scheduler was sent the command new
01/01/2016 14:01:52;0008;PBS_Server;Job;58865.tyrone-cluster;Job Modified at request of Scheduler@tyrone-cluster
01/01/2016 14:01:58;000d;PBS_Server;Job;58864.tyrone-cluster;Not sending email: User does not want mail of this type.
01/01/2016 14:01:58;0010;PBS_Server;Job;58864.tyrone-cluster;Exit_status=0 resources_used.cput=00:18:11 resources_used.mem=901096kb resources_used.vmem=6520896kb resources_used.walltime=00:00:35
01/01/2016 14:01:58;0008;PBS_Server;Job;NULL;on_job_exit valid pjob: 0x2aaed40 (substate=50)
01/01/2016 14:01:58;0008;PBS_Server;Job;NULL;on_job_exit valid pjob: 0x2aaed40 (substate=51)
01/01/2016 14:01:58;0008;PBS_Server;Job;NULL;on_job_exit valid pjob: 0x2aaed40 (substate=51)
01/01/2016 14:01:58;0008;PBS_Server;Job;NULL;on_job_exit valid pjob: 0x2aaed40 (substate=53)
01/01/2016 14:01:58;0100;PBS_Server;Job;58864.tyrone-cluster;dequeuing from qp32, state COMPLETE
01/01/2016 14:01:58;0040;PBS_Server;Svr;tyrone-cluster;Scheduler was sent the command term
01/01/2016 14:02:22;0100;PBS_Server;Job;58866.tyrone-cluster;enqueuing into batch, state 1 hop 1
01/01/2016 14:02:22;0100;PBS_Server;Job;58866.tyrone-cluster;dequeuing from batch, state QUEUED
01/01/2016 14:02:22;0100;PBS_Server;Job;58866.tyrone-cluster;enqueuing into qp128, state 1 hop 1
01/01/2016 14:02:22;0008;PBS_Server;Job;58866.tyrone-cluster;Job Queued at request of secvarma@tyrone-cluster, owner = secvarma@tyrone-cluster, job name = simple_128c_s20, queue = qp128
01/01/2016 14:02:22;0040;PBS_Server;Svr;tyrone-cluster;Scheduler was sent the command new
01/01/2016 14:02:22;0008;PBS_Server;Job;58866.tyrone-cluster;Job Modified at request of Scheduler@tyrone-cluster
01/01/2016 14:02:47;0100;PBS_Server;Job;58867.tyrone-cluster;enqueuing into batch, state 1 hop 1
01/01/2016 14:02:47;0100;PBS_Server;Job;58867.tyrone-cluster;dequeuing from batch, state QUEUED
01/01/2016 14:02:47;0100;PBS_Server;Job;58867.tyrone-cluster;enqueuing into qp256, state 1 hop 1
01/01/2016 14:02:47;0008;PBS_Server;Job;58867.tyrone-cluster;Job Queued at request of secvarma@tyrone-cluster, owner = secvarma@tyrone-cluster, job name = simple_256_s20, queue = qp256
01/01/2016 14:02:47;0040;PBS_Server;Svr;tyrone-cluster;Scheduler was sent the command new
01/01/2016 14:02:47;0008;PBS_Server;Job;58867.tyrone-cluster;Job Modified at request of Scheduler@tyrone-cluster
01/01/2016 14:02:47;0008;PBS_Server;Job;58867.tyrone-cluster;Job Run at request of Scheduler@tyrone-cluster
01/01/2016 14:02:47;0040;PBS_Server;Svr;tyrone-cluster;Scheduler was sent the command recyc
01/01/2016 14:02:49;000d;PBS_Server;Job;58867.tyrone-cluster;Not sending email: User does not want mail of this type.
01/01/2016 14:02:49;0010;PBS_Server;Job;58867.tyrone-cluster;Exit_status=255 resources_used.cput=00:00:09 resources_used.mem=800kb resources_used.vmem=13624kb resources_used.walltime=00:00:03
01/01/2016 14:02:49;0008;PBS_Server;Job;NULL;on_job_exit valid pjob: 0x2ab74b0 (substate=50)
01/01/2016 14:02:49;0008;PBS_Server;Job;NULL;on_job_exit valid pjob: 0x2ab74b0 (substate=51)
01/01/2016 14:02:49;0008;PBS_Server;Job;NULL;on_job_exit valid pjob: 0x2ab74b0 (substate=51)
01/01/2016 14:02:49;0008;PBS_Server;Job;NULL;on_job_exit valid pjob: 0x2ab74b0 (substate=53)
01/01/2016 14:02:49;0100;PBS_Server;Job;58867.tyrone-cluster;dequeuing from qp256, state COMPLETE
01/01/2016 14:02:49;0040;PBS_Server;Svr;tyrone-cluster;Scheduler was sent the command term
01/01/2016 14:06:51;0002;PBS_Server;Svr;PBS_Server;Torque Server Version = 3.0.5, loglevel = 0
01/01/2016 14:11:51;0002;PBS_Server;Svr;PBS_Server;Torque Server Version = 3.0.5, loglevel = 0
01/01/2016 14:12:49;0040;PBS_Server;Svr;tyrone-cluster;Scheduler was sent the command time
01/01/2016 14:16:51;0002;PBS_Server;Svr;PBS_Server;Torque Server Version = 3.0.5, loglevel = 0
01/01/2016 14:21:51;0002;PBS_Server;Svr;PBS_Server;Torque Server Version = 3.0.5, loglevel = 0
01/01/2016 14:21:58;0100;PBS_Server;Job;58868.tyrone-cluster;enqueuing into batch, state 1 hop 1
01/01/2016 14:21:58;0100;PBS_Server;Job;58868.tyrone-cluster;dequeuing from batch, state QUEUED
01/01/2016 14:21:58;0100;PBS_Server;Job;58868.tyrone-cluster;enqueuing into idqueue, state 1 hop 1
01/01/2016 14:21:58;0008;PBS_Server;Job;58868.tyrone-cluster;Job Queued at request of metgkch@tyrone-cluster, owner = metgkch@tyrone-cluster, job name = Opt2, queue = idqueue
01/01/2016 14:21:58;0040;PBS_Server;Svr;tyrone-cluster;Scheduler was sent the command new
01/01/2016 14:21:58;0008;PBS_Server;Job;58868.tyrone-cluster;Job Modified at request of Scheduler@tyrone-cluster
01/01/2016 14:21:58;0008;PBS_Server;Job;58868.tyrone-cluster;Job Run at request of Scheduler@tyrone-cluster
01/01/2016 14:21:58;0040;PBS_Server;Svr;tyrone-cluster;Scheduler was sent the command recyc
01/01/2016 14:21:58;000d;PBS_Server;Job;58868.tyrone-cluster;Not sending email: User does not want mail of this type.
01/01/2016 14:23:21;000d;PBS_Server;Job;58860.tyrone-cluster;Not sending email: User does not want mail of this type.
01/01/2016 14:23:21;0010;PBS_Server;Job;58860.tyrone-cluster;Exit_status=0 resources_used.cput=167:12:06 resources_used.mem=16218132kb resources_used.vmem=55006288kb resources_used.walltime=01:44:44
01/01/2016 14:23:21;0008;PBS_Server;Job;NULL;on_job_exit valid pjob: 0x2ab1150 (substate=50)
01/01/2016 14:23:21;0008;PBS_Server;Job;NULL;on_job_exit valid pjob: 0x2ab1150 (substate=51)
01/01/2016 14:23:22;0008;PBS_Server;Job;NULL;on_job_exit valid pjob: 0x2ab1150 (substate=51)
01/01/2016 14:23:22;0008;PBS_Server;Job;NULL;on_job_exit valid pjob: 0x2ab1150 (substate=53)
01/01/2016 14:23:22;0100;PBS_Server;Job;58860.tyrone-cluster;dequeuing from qp128, state COMPLETE
01/01/2016 14:23:22;0040;PBS_Server;Svr;tyrone-cluster;Scheduler was sent the command term
01/01/2016 14:23:22;0008;PBS_Server;Job;58866.tyrone-cluster;Job Modified at request of Scheduler@tyrone-cluster
01/01/2016 14:23:22;0008;PBS_Server;Job;58866.tyrone-cluster;Job Run at request of Scheduler@tyrone-cluster
01/01/2016 14:23:22;0040;PBS_Server;Svr;tyrone-cluster;Scheduler was sent the command recyc
01/01/2016 14:24:36;000d;PBS_Server;Job;58866.tyrone-cluster;Not sending email: User does not want mail of this type.
01/01/2016 14:26:51;0002;PBS_Server;Svr;PBS_Server;Torque Server Version = 3.0.5, loglevel = 0
01/01/2016 14:31:51;0002;PBS_Server;Svr;PBS_Server;Torque Server Version = 3.0.5, loglevel = 0
01/01/2016 14:33:22;0040;PBS_Server;Svr;tyrone-cluster;Scheduler was sent the command time
01/01/2016 14:36:51;0002;PBS_Server;Svr;PBS_Server;Torque Server Version = 3.0.5, loglevel = 0
01/01/2016 14:41:51;0002;PBS_Server;Svr;PBS_Server;Torque Server Version = 3.0.5, loglevel = 0
01/01/2016 14:43:22;0040;PBS_Server;Svr;tyrone-cluster;Scheduler was sent the command time
01/01/2016 14:46:51;0002;PBS_Server;Svr;PBS_Server;Torque Server Version = 3.0.5, loglevel = 0
01/01/2016 14:51:51;0002;PBS_Server;Svr;PBS_Server;Torque Server Version = 3.0.5, loglevel = 0
01/01/2016 14:53:22;0040;PBS_Server;Svr;tyrone-cluster;Scheduler was sent the command time
01/01/2016 14:56:51;0002;PBS_Server;Svr;PBS_Server;Torque Server Version = 3.0.5, loglevel = 0
01/01/2016 15:01:51;0002;PBS_Server;Svr;PBS_Server;Torque Server Version = 3.0.5, loglevel = 0
01/01/2016 15:03:22;0040;PBS_Server;Svr;tyrone-cluster;Scheduler was sent the command time
01/01/2016 15:06:51;0002;PBS_Server;Svr;PBS_Server;Torque Server Version = 3.0.5, loglevel = 0
01/01/2016 15:11:51;0002;PBS_Server;Svr;PBS_Server;Torque Server Version = 3.0.5, loglevel = 0
01/01/2016 15:13:22;0040;PBS_Server;Svr;tyrone-cluster;Scheduler was sent the command time
01/01/2016 15:16:51;0002;PBS_Server;Svr;PBS_Server;Torque Server Version = 3.0.5, loglevel = 0
01/01/2016 15:21:51;0002;PBS_Server;Svr;PBS_Server;Torque Server Version = 3.0.5, loglevel = 0
01/01/2016 15:23:22;0040;PBS_Server;Svr;tyrone-cluster;Scheduler was sent the command time
01/01/2016 15:26:51;0002;PBS_Server;Svr;PBS_Server;Torque Server Version = 3.0.5, loglevel = 0
01/01/2016 15:31:51;0002;PBS_Server;Svr;PBS_Server;Torque Server Version = 3.0.5, loglevel = 0
01/01/2016 15:33:22;0040;PBS_Server;Svr;tyrone-cluster;Scheduler was sent the command time
01/01/2016 15:36:51;0002;PBS_Server;Svr;PBS_Server;Torque Server Version = 3.0.5, loglevel = 0
01/01/2016 15:41:51;0002;PBS_Server;Svr;PBS_Server;Torque Server Version = 3.0.5, loglevel = 0
01/01/2016 15:43:22;0040;PBS_Server;Svr;tyrone-cluster;Scheduler was sent the command time
01/01/2016 15:44:27;0008;PBS_Server;Job;58861.tyrone-cluster;Job deleted at request of chearit@tyrone-cluster
01/01/2016 15:44:27;0008;PBS_Server;Job;58861.tyrone-cluster;Job sent signal SIGTERM on delete
01/01/2016 15:44:29;0008;PBS_Server;Job;58861.tyrone-cluster;Job sent signal SIGKILL on delete
01/01/2016 15:44:37;0008;PBS_Server;Job;58861.tyrone-cluster;Job deleted at request of chearit@tyrone-cluster
01/01/2016 15:44:37;0008;PBS_Server;Job;58861.tyrone-cluster;Job sent signal SIGTERM on delete
01/01/2016 15:45:42;000d;PBS_Server;Job;58861.tyrone-cluster;Not sending email: User does not want mail of this type.
01/01/2016 15:45:42;0010;PBS_Server;Job;58861.tyrone-cluster;Exit_status=143 resources_used.cput=42:34:58 resources_used.mem=64166028kb resources_used.vmem=129947300kb resources_used.walltime=02:46:06
01/01/2016 15:45:42;0008;PBS_Server;Job;NULL;on_job_exit valid pjob: 0x2aa80e0 (substate=50)
01/01/2016 15:45:42;0008;PBS_Server;Job;NULL;on_job_exit valid pjob: 0x2aa80e0 (substate=51)
01/01/2016 15:45:43;0008;PBS_Server;Job;NULL;on_job_exit valid pjob: 0x2aa80e0 (substate=51)
01/01/2016 15:45:43;0008;PBS_Server;Job;NULL;on_job_exit valid pjob: 0x2aa80e0 (substate=53)
01/01/2016 15:45:43;0100;PBS_Server;Job;58861.tyrone-cluster;dequeuing from qp64, state COMPLETE
01/01/2016 15:45:43;0040;PBS_Server;Svr;tyrone-cluster;Scheduler was sent the command term
01/01/2016 15:45:43;0008;PBS_Server;Job;58865.tyrone-cluster;Job Modified at request of Scheduler@tyrone-cluster
01/01/2016 15:45:43;0008;PBS_Server;Job;58865.tyrone-cluster;Job Run at request of Scheduler@tyrone-cluster
01/01/2016 15:45:43;0040;PBS_Server;Svr;tyrone-cluster;Scheduler was sent the command recyc
01/01/2016 15:46:19;000d;PBS_Server;Job;58865.tyrone-cluster;Not sending email: User does not want mail of this type.
01/01/2016 15:46:51;0002;PBS_Server;Svr;PBS_Server;Torque Server Version = 3.0.5, loglevel = 0
01/01/2016 15:46:59;0100;PBS_Server;Job;58869.tyrone-cluster;enqueuing into batch, state 1 hop 1
01/01/2016 15:46:59;0100;PBS_Server;Job;58869.tyrone-cluster;dequeuing from batch, state QUEUED
01/01/2016 15:46:59;0100;PBS_Server;Job;58869.tyrone-cluster;enqueuing into qp128, state 1 hop 1
01/01/2016 15:46:59;0008;PBS_Server;Job;58869.tyrone-cluster;Job Queued at request of chearit@tyrone-cluster, owner = chearit@tyrone-cluster, job name = testpara, queue = qp128
01/01/2016 15:46:59;0040;PBS_Server;Svr;tyrone-cluster;Scheduler was sent the command new
01/01/2016 15:46:59;0008;PBS_Server;Job;58869.tyrone-cluster;Job Modified at request of Scheduler@tyrone-cluster
01/01/2016 15:47:06;000d;PBS_Server;Job;58865.tyrone-cluster;Not sending email: User does not want mail of this type.
01/01/2016 15:47:06;0010;PBS_Server;Job;58865.tyrone-cluster;Exit_status=0 resources_used.cput=00:38:12 resources_used.mem=1349656kb resources_used.vmem=7136496kb resources_used.walltime=00:01:23
01/01/2016 15:47:06;0008;PBS_Server;Job;NULL;on_job_exit valid pjob: 0x2ab61f0 (substate=50)
01/01/2016 15:47:06;0008;PBS_Server;Job;NULL;on_job_exit valid pjob: 0x2ab61f0 (substate=51)
01/01/2016 15:47:06;0008;PBS_Server;Job;NULL;on_job_exit valid pjob: 0x2ab61f0 (substate=51)
01/01/2016 15:47:06;0008;PBS_Server;Job;NULL;on_job_exit valid pjob: 0x2ab61f0 (substate=53)
01/01/2016 15:47:06;0100;PBS_Server;Job;58865.tyrone-cluster;dequeuing from qp64, state COMPLETE
01/01/2016 15:47:06;0040;PBS_Server;Svr;tyrone-cluster;Scheduler was sent the command term
01/01/2016 15:51:51;0002;PBS_Server;Svr;PBS_Server;Torque Server Version = 3.0.5, loglevel = 0
01/01/2016 15:53:41;0100;PBS_Server;Job;58870.tyrone-cluster;enqueuing into batch, state 1 hop 1
01/01/2016 15:53:41;0100;PBS_Server;Job;58870.tyrone-cluster;dequeuing from batch, state QUEUED
01/01/2016 15:53:41;0100;PBS_Server;Job;58870.tyrone-cluster;enqueuing into qp32, state 1 hop 1
01/01/2016 15:53:41;0008;PBS_Server;Job;58870.tyrone-cluster;Job Queued at request of secvarma@tyrone-cluster, owner = secvarma@tyrone-cluster, job name = simple_32c_s20, queue = qp32
01/01/2016 15:53:41;0040;PBS_Server;Svr;tyrone-cluster;Scheduler was sent the command new
01/01/2016 15:53:41;0008;PBS_Server;Job;58870.tyrone-cluster;Job Modified at request of Scheduler@tyrone-cluster
01/01/2016 15:53:41;0008;PBS_Server;Job;58870.tyrone-cluster;Job Run at request of Scheduler@tyrone-cluster
01/01/2016 15:53:41;0040;PBS_Server;Svr;tyrone-cluster;Scheduler was sent the command recyc
01/01/2016 15:53:41;000d;PBS_Server;Job;58870.tyrone-cluster;Not sending email: User does not want mail of this type.
01/01/2016 15:53:56;0008;PBS_Server;Job;58870.tyrone-cluster;Job deleted at request of secvarma@tyrone-cluster
01/01/2016 15:53:56;0008;PBS_Server;Job;58870.tyrone-cluster;Job sent signal SIGTERM on delete
01/01/2016 15:53:57;000d;PBS_Server;Job;58870.tyrone-cluster;Not sending email: User does not want mail of this type.
01/01/2016 15:53:57;0010;PBS_Server;Job;58870.tyrone-cluster;Exit_status=143 resources_used.cput=00:07:24 resources_used.mem=623576kb resources_used.vmem=8044228kb resources_used.walltime=00:00:15
01/01/2016 15:53:57;0008;PBS_Server;Job;NULL;on_job_exit valid pjob: 0x2aba090 (substate=50)
01/01/2016 15:53:57;0008;PBS_Server;Job;NULL;on_job_exit valid pjob: 0x2aba090 (substate=51)
01/01/2016 15:53:57;0008;PBS_Server;Job;NULL;on_job_exit valid pjob: 0x2aba090 (substate=51)
01/01/2016 15:53:57;0008;PBS_Server;Job;NULL;on_job_exit valid pjob: 0x2aba090 (substate=53)
01/01/2016 15:53:57;0100;PBS_Server;Job;58870.tyrone-cluster;dequeuing from qp32, state COMPLETE
01/01/2016 15:53:57;0040;PBS_Server;Svr;tyrone-cluster;Scheduler was sent the command term
01/01/2016 15:54:12;0100;PBS_Server;Job;58871.tyrone-cluster;enqueuing into batch, state 1 hop 1
01/01/2016 15:54:12;0100;PBS_Server;Job;58871.tyrone-cluster;dequeuing from batch, state QUEUED
01/01/2016 15:54:12;0100;PBS_Server;Job;58871.tyrone-cluster;enqueuing into qp32, state 1 hop 1
01/01/2016 15:54:12;0008;PBS_Server;Job;58871.tyrone-cluster;Job Queued at request of secvarma@tyrone-cluster, owner = secvarma@tyrone-cluster, job name = simple_32c_s22, queue = qp32
01/01/2016 15:54:12;0040;PBS_Server;Svr;tyrone-cluster;Scheduler was sent the command new
01/01/2016 15:54:12;0008;PBS_Server;Job;58871.tyrone-cluster;Job Modified at request of Scheduler@tyrone-cluster
01/01/2016 15:54:12;0008;PBS_Server;Job;58871.tyrone-cluster;Job Run at request of Scheduler@tyrone-cluster
01/01/2016 15:54:12;0040;PBS_Server;Svr;tyrone-cluster;Scheduler was sent the command recyc
01/01/2016 15:54:12;000d;PBS_Server;Job;58871.tyrone-cluster;Not sending email: User does not want mail of this type.
01/01/2016 15:54:59;000d;PBS_Server;Job;58871.tyrone-cluster;Not sending email: User does not want mail of this type.
01/01/2016 15:54:59;0010;PBS_Server;Job;58871.tyrone-cluster;Exit_status=0 resources_used.cput=00:24:37 resources_used.mem=2601736kb resources_used.vmem=8192456kb resources_used.walltime=00:00:47
01/01/2016 15:54:59;0008;PBS_Server;Job;NULL;on_job_exit valid pjob: 0x2aba090 (substate=50)
01/01/2016 15:54:59;0008;PBS_Server;Job;NULL;on_job_exit valid pjob: 0x2aba090 (substate=51)
01/01/2016 15:54:59;0008;PBS_Server;Job;NULL;on_job_exit valid pjob: 0x2aba090 (substate=51)
01/01/2016 15:54:59;0008;PBS_Server;Job;NULL;on_job_exit valid pjob: 0x2aba090 (substate=53)
01/01/2016 15:54:59;0100;PBS_Server;Job;58871.tyrone-cluster;dequeuing from qp32, state COMPLETE
01/01/2016 15:54:59;0040;PBS_Server;Svr;tyrone-cluster;Scheduler was sent the command term
01/01/2016 15:56:51;0002;PBS_Server;Svr;PBS_Server;Torque Server Version = 3.0.5, loglevel = 0
01/01/2016 16:01:43;0100;PBS_Server;Job;58872.tyrone-cluster;enqueuing into batch, state 1 hop 1
01/01/2016 16:01:43;0100;PBS_Server;Job;58872.tyrone-cluster;dequeuing from batch, state QUEUED
01/01/2016 16:01:43;0100;PBS_Server;Job;58872.tyrone-cluster;enqueuing into idqueue, state 1 hop 1
01/01/2016 16:01:43;0008;PBS_Server;Job;58872.tyrone-cluster;Job Queued at request of nsesidd@tyrone-cluster, owner = nsesidd@tyrone-cluster, job name = jobname, queue = idqueue
01/01/2016 16:01:43;0040;PBS_Server;Svr;tyrone-cluster;Scheduler was sent the command new
01/01/2016 16:01:43;0008;PBS_Server;Job;58872.tyrone-cluster;Job Modified at request of Scheduler@tyrone-cluster
01/01/2016 16:01:51;0002;PBS_Server;Svr;PBS_Server;Torque Server Version = 3.0.5, loglevel = 0
01/01/2016 16:06:51;0002;PBS_Server;Svr;PBS_Server;Torque Server Version = 3.0.5, loglevel = 0
01/01/2016 16:11:43;0040;PBS_Server;Svr;tyrone-cluster;Scheduler was sent the command time
01/01/2016 16:11:51;0002;PBS_Server;Svr;PBS_Server;Torque Server Version = 3.0.5, loglevel = 0
01/01/2016 16:16:51;0002;PBS_Server;Svr;PBS_Server;Torque Server Version = 3.0.5, loglevel = 0
01/01/2016 16:21:43;0040;PBS_Server;Svr;tyrone-cluster;Scheduler was sent the command time
01/01/2016 16:21:51;0002;PBS_Server;Svr;PBS_Server;Torque Server Version = 3.0.5, loglevel = 0
01/01/2016 16:22:43;000d;PBS_Server;Job;58868.tyrone-cluster;Not sending email: User does not want mail of this type.
01/01/2016 16:22:43;0010;PBS_Server;Job;58868.tyrone-cluster;Exit_status=143 resources_used.cput=55:38:58 resources_used.mem=2069684kb resources_used.vmem=8088716kb resources_used.walltime=02:00:45
01/01/2016 16:22:43;0008;PBS_Server;Job;NULL;on_job_exit valid pjob: 0x2ab8dd0 (substate=50)
01/01/2016 16:22:43;0008;PBS_Server;Job;NULL;on_job_exit valid pjob: 0x2ab8dd0 (substate=51)
01/01/2016 16:22:43;0008;PBS_Server;Job;NULL;on_job_exit valid pjob: 0x2ab8dd0 (substate=51)
01/01/2016 16:22:43;0008;PBS_Server;Job;NULL;on_job_exit valid pjob: 0x2ab8dd0 (substate=53)
01/01/2016 16:22:43;0100;PBS_Server;Job;58868.tyrone-cluster;dequeuing from idqueue, state COMPLETE
01/01/2016 16:22:43;0040;PBS_Server;Svr;tyrone-cluster;Scheduler was sent the command term
01/01/2016 16:22:43;0008;PBS_Server;Job;58872.tyrone-cluster;Job Modified at request of Scheduler@tyrone-cluster
01/01/2016 16:22:43;0008;PBS_Server;Job;58872.tyrone-cluster;Job Run at request of Scheduler@tyrone-cluster
01/01/2016 16:22:43;0040;PBS_Server;Svr;tyrone-cluster;Scheduler was sent the command recyc
01/01/2016 16:22:43;000d;PBS_Server;Job;58872.tyrone-cluster;Not sending email: User does not want mail of this type.
01/01/2016 16:22:54;000d;PBS_Server;Job;58872.tyrone-cluster;Not sending email: User does not want mail of this type.
01/01/2016 16:22:54;0010;PBS_Server;Job;58872.tyrone-cluster;Exit_status=3 resources_used.cput=00:00:52 resources_used.mem=0kb resources_used.vmem=0kb resources_used.walltime=00:00:11
01/01/2016 16:22:54;0008;PBS_Server;Job;NULL;on_job_exit valid pjob: 0x2aba090 (substate=50)
01/01/2016 16:22:54;0008;PBS_Server;Job;NULL;on_job_exit valid pjob: 0x2aba090 (substate=51)
01/01/2016 16:22:54;0008;PBS_Server;Job;NULL;on_job_exit valid pjob: 0x2aba090 (substate=51)
01/01/2016 16:22:54;0008;PBS_Server;Job;NULL;on_job_exit valid pjob: 0x2aba090 (substate=53)
01/01/2016 16:22:54;0100;PBS_Server;Job;58872.tyrone-cluster;dequeuing from idqueue, state COMPLETE
01/01/2016 16:22:54;0040;PBS_Server;Svr;tyrone-cluster;Scheduler was sent the command term
01/01/2016 16:26:51;0002;PBS_Server;Svr;PBS_Server;Torque Server Version = 3.0.5, loglevel = 0
01/01/2016 16:31:51;0002;PBS_Server;Svr;PBS_Server;Torque Server Version = 3.0.5, loglevel = 0
01/01/2016 16:32:54;0040;PBS_Server;Svr;tyrone-cluster;Scheduler was sent the command time
01/01/2016 16:36:51;0002;PBS_Server;Svr;PBS_Server;Torque Server Version = 3.0.5, loglevel = 0
01/01/2016 16:41:51;0002;PBS_Server;Svr;PBS_Server;Torque Server Version = 3.0.5, loglevel = 0
01/01/2016 16:42:54;0040;PBS_Server;Svr;tyrone-cluster;Scheduler was sent the command time
01/01/2016 16:46:51;0002;PBS_Server;Svr;PBS_Server;Torque Server Version = 3.0.5, loglevel = 0
01/01/2016 16:51:51;0002;PBS_Server;Svr;PBS_Server;Torque Server Version = 3.0.5, loglevel = 0
01/01/2016 16:52:54;0040;PBS_Server;Svr;tyrone-cluster;Scheduler was sent the command time
01/01/2016 16:56:51;0002;PBS_Server;Svr;PBS_Server;Torque Server Version = 3.0.5, loglevel = 0
01/01/2016 17:01:51;0002;PBS_Server;Svr;PBS_Server;Torque Server Version = 3.0.5, loglevel = 0
01/01/2016 17:02:54;0040;PBS_Server;Svr;tyrone-cluster;Scheduler was sent the command time
01/01/2016 17:06:51;0002;PBS_Server;Svr;PBS_Server;Torque Server Version = 3.0.5, loglevel = 0
01/01/2016 17:11:51;0002;PBS_Server;Svr;PBS_Server;Torque Server Version = 3.0.5, loglevel = 0
01/01/2016 17:12:54;0040;PBS_Server;Svr;tyrone-cluster;Scheduler was sent the command time
01/01/2016 17:16:51;0002;PBS_Server;Svr;PBS_Server;Torque Server Version = 3.0.5, loglevel = 0
01/01/2016 17:21:51;0002;PBS_Server;Svr;PBS_Server;Torque Server Version = 3.0.5, loglevel = 0
01/01/2016 17:22:54;0040;PBS_Server;Svr;tyrone-cluster;Scheduler was sent the command time
01/01/2016 17:26:51;0002;PBS_Server;Svr;PBS_Server;Torque Server Version = 3.0.5, loglevel = 0
01/01/2016 17:31:51;0002;PBS_Server;Svr;PBS_Server;Torque Server Version = 3.0.5, loglevel = 0
01/01/2016 17:32:54;0040;PBS_Server;Svr;tyrone-cluster;Scheduler was sent the command time
01/01/2016 17:36:51;0002;PBS_Server;Svr;PBS_Server;Torque Server Version = 3.0.5, loglevel = 0
01/01/2016 17:41:51;0002;PBS_Server;Svr;PBS_Server;Torque Server Version = 3.0.5, loglevel = 0
01/01/2016 17:42:54;0040;PBS_Server;Svr;tyrone-cluster;Scheduler was sent the command time
01/01/2016 17:46:51;0002;PBS_Server;Svr;PBS_Server;Torque Server Version = 3.0.5, loglevel = 0
01/01/2016 17:49:02;000d;PBS_Server;Job;58857.tyrone-cluster;Not sending email: User does not want mail of this type.
01/01/2016 17:49:02;0010;PBS_Server;Job;58857.tyrone-cluster;Exit_status=139 resources_used.cput=178:22:05 resources_used.mem=30857128kb resources_used.vmem=36932032kb resources_used.walltime=05:34:45
01/01/2016 17:49:02;0008;PBS_Server;Job;NULL;on_job_exit valid pjob: 0x2aa9a00 (substate=50)
01/01/2016 17:49:02;0008;PBS_Server;Job;NULL;on_job_exit valid pjob: 0x2aa9a00 (substate=51)
01/01/2016 17:49:02;0008;PBS_Server;Job;NULL;on_job_exit valid pjob: 0x2aa9a00 (substate=51)
01/01/2016 17:49:02;0008;PBS_Server;Job;NULL;on_job_exit valid pjob: 0x2aa9a00 (substate=53)
01/01/2016 17:49:02;0100;PBS_Server;Job;58857.tyrone-cluster;dequeuing from qp32, state COMPLETE
01/01/2016 17:49:02;0040;PBS_Server;Svr;tyrone-cluster;Scheduler was sent the command term
01/01/2016 17:51:51;0002;PBS_Server;Svr;PBS_Server;Torque Server Version = 3.0.5, loglevel = 0
01/01/2016 17:56:51;0002;PBS_Server;Svr;PBS_Server;Torque Server Version = 3.0.5, loglevel = 0
01/01/2016 17:59:02;0040;PBS_Server;Svr;tyrone-cluster;Scheduler was sent the command time
01/01/2016 18:01:51;0002;PBS_Server;Svr;PBS_Server;Torque Server Version = 3.0.5, loglevel = 0
01/01/2016 18:06:51;0002;PBS_Server;Svr;PBS_Server;Torque Server Version = 3.0.5, loglevel = 0
01/01/2016 18:09:02;0040;PBS_Server;Svr;tyrone-cluster;Scheduler was sent the command time
01/01/2016 18:11:51;0002;PBS_Server;Svr;PBS_Server;Torque Server Version = 3.0.5, loglevel = 0
01/01/2016 18:16:51;0002;PBS_Server;Svr;PBS_Server;Torque Server Version = 3.0.5, loglevel = 0
01/01/2016 18:17:28;0100;PBS_Server;Job;58873.tyrone-cluster;enqueuing into batch, state 1 hop 1
01/01/2016 18:17:28;0100;PBS_Server;Job;58873.tyrone-cluster;dequeuing from batch, state QUEUED
01/01/2016 18:17:28;0100;PBS_Server;Job;58873.tyrone-cluster;enqueuing into qp32, state 1 hop 1
01/01/2016 18:17:28;0008;PBS_Server;Job;58873.tyrone-cluster;Job Queued at request of chearit@tyrone-cluster, owner = chearit@tyrone-cluster, job name = jobname, queue = qp32
01/01/2016 18:17:28;0040;PBS_Server;Svr;tyrone-cluster;Scheduler was sent the command new
01/01/2016 18:17:28;0008;PBS_Server;Job;58873.tyrone-cluster;Job Modified at request of Scheduler@tyrone-cluster
01/01/2016 18:17:28;0008;PBS_Server;Job;58873.tyrone-cluster;Job Run at request of Scheduler@tyrone-cluster
01/01/2016 18:17:28;0040;PBS_Server;Svr;tyrone-cluster;Scheduler was sent the command recyc
01/01/2016 18:17:28;000d;PBS_Server;Job;58873.tyrone-cluster;Not sending email: User does not want mail of this type.
01/01/2016 18:21:11;000d;PBS_Server;Job;58873.tyrone-cluster;Not sending email: User does not want mail of this type.
01/01/2016 18:21:11;0010;PBS_Server;Job;58873.tyrone-cluster;Exit_status=139 resources_used.cput=01:52:01 resources_used.mem=30846448kb resources_used.vmem=36963572kb resources_used.walltime=00:03:43
01/01/2016 18:21:11;0008;PBS_Server;Job;NULL;on_job_exit valid pjob: 0x2aa9990 (substate=50)
01/01/2016 18:21:11;0008;PBS_Server;Job;NULL;on_job_exit valid pjob: 0x2aa9990 (substate=51)
01/01/2016 18:21:11;0008;PBS_Server;Job;NULL;on_job_exit valid pjob: 0x2aa9990 (substate=51)
01/01/2016 18:21:11;0008;PBS_Server;Job;NULL;on_job_exit valid pjob: 0x2aa9990 (substate=53)
01/01/2016 18:21:11;0100;PBS_Server;Job;58873.tyrone-cluster;dequeuing from qp32, state COMPLETE
01/01/2016 18:21:11;0040;PBS_Server;Svr;tyrone-cluster;Scheduler was sent the command term
01/01/2016 18:21:51;0002;PBS_Server;Svr;PBS_Server;Torque Server Version = 3.0.5, loglevel = 0
01/01/2016 18:26:51;0002;PBS_Server;Svr;PBS_Server;Torque Server Version = 3.0.5, loglevel = 0
01/01/2016 18:27:27;0100;PBS_Server;Job;58874.tyrone-cluster;enqueuing into batch, state 1 hop 1
01/01/2016 18:27:27;0100;PBS_Server;Job;58874.tyrone-cluster;dequeuing from batch, state QUEUED
01/01/2016 18:27:27;0100;PBS_Server;Job;58874.tyrone-cluster;enqueuing into qp32, state 1 hop 1
01/01/2016 18:27:27;0008;PBS_Server;Job;58874.tyrone-cluster;Job Queued at request of chearit@tyrone-cluster, owner = chearit@tyrone-cluster, job name = testpara, queue = qp32
01/01/2016 18:27:27;0040;PBS_Server;Svr;tyrone-cluster;Scheduler was sent the command new
01/01/2016 18:27:27;0008;PBS_Server;Job;58874.tyrone-cluster;Job Modified at request of Scheduler@tyrone-cluster
01/01/2016 18:27:27;0008;PBS_Server;Job;58874.tyrone-cluster;Job Run at request of Scheduler@tyrone-cluster
01/01/2016 18:27:27;0040;PBS_Server;Svr;tyrone-cluster;Scheduler was sent the command recyc
01/01/2016 18:27:27;000d;PBS_Server;Job;58874.tyrone-cluster;Not sending email: User does not want mail of this type.
01/01/2016 18:31:51;0002;PBS_Server;Svr;PBS_Server;Torque Server Version = 3.0.5, loglevel = 0
01/01/2016 18:36:51;0002;PBS_Server;Svr;PBS_Server;Torque Server Version = 3.0.5, loglevel = 0
01/01/2016 18:37:27;0040;PBS_Server;Svr;tyrone-cluster;Scheduler was sent the command time
01/01/2016 18:38:05;000d;PBS_Server;Job;58874.tyrone-cluster;Not sending email: User does not want mail of this type.
01/01/2016 18:38:05;0010;PBS_Server;Job;58874.tyrone-cluster;Exit_status=0 resources_used.cput=00:37:57 resources_used.mem=15343356kb resources_used.vmem=16061296kb resources_used.walltime=00:10:39
01/01/2016 18:38:05;0008;PBS_Server;Job;NULL;on_job_exit valid pjob: 0x2aa9990 (substate=50)
01/01/2016 18:38:05;0008;PBS_Server;Job;NULL;on_job_exit valid pjob: 0x2aa9990 (substate=51)
01/01/2016 18:38:05;0008;PBS_Server;Job;NULL;on_job_exit valid pjob: 0x2aa9990 (substate=51)
01/01/2016 18:38:05;0008;PBS_Server;Job;NULL;on_job_exit valid pjob: 0x2aa9990 (substate=53)
01/01/2016 18:38:05;0100;PBS_Server;Job;58874.tyrone-cluster;dequeuing from qp32, state COMPLETE
01/01/2016 18:38:05;0040;PBS_Server;Svr;tyrone-cluster;Scheduler was sent the command term
01/01/2016 18:40:26;0100;PBS_Server;Job;58875.tyrone-cluster;enqueuing into batch, state 1 hop 1
01/01/2016 18:40:26;0100;PBS_Server;Job;58875.tyrone-cluster;dequeuing from batch, state QUEUED
01/01/2016 18:40:26;0100;PBS_Server;Job;58875.tyrone-cluster;enqueuing into qp32, state 1 hop 1
01/01/2016 18:40:26;0008;PBS_Server;Job;58875.tyrone-cluster;Job Queued at request of chearit@tyrone-cluster, owner = chearit@tyrone-cluster, job name = testpara, queue = qp32
01/01/2016 18:40:26;0040;PBS_Server;Svr;tyrone-cluster;Scheduler was sent the command new
01/01/2016 18:40:26;0008;PBS_Server;Job;58875.tyrone-cluster;Job Modified at request of Scheduler@tyrone-cluster
01/01/2016 18:40:26;0008;PBS_Server;Job;58875.tyrone-cluster;Job Run at request of Scheduler@tyrone-cluster
01/01/2016 18:40:26;0040;PBS_Server;Svr;tyrone-cluster;Scheduler was sent the command recyc
01/01/2016 18:40:26;000d;PBS_Server;Job;58875.tyrone-cluster;Not sending email: User does not want mail of this type.
01/01/2016 18:41:13;000d;PBS_Server;Job;58875.tyrone-cluster;Not sending email: User does not want mail of this type.
01/01/2016 18:41:13;0010;PBS_Server;Job;58875.tyrone-cluster;Exit_status=139 resources_used.cput=00:03:44 resources_used.mem=4608888kb resources_used.vmem=16061296kb resources_used.walltime=00:00:47
01/01/2016 18:41:13;0008;PBS_Server;Job;NULL;on_job_exit valid pjob: 0x2aa9990 (substate=50)
01/01/2016 18:41:13;0008;PBS_Server;Job;NULL;on_job_exit valid pjob: 0x2aa9990 (substate=51)
01/01/2016 18:41:13;0008;PBS_Server;Job;NULL;on_job_exit valid pjob: 0x2aa9990 (substate=51)
01/01/2016 18:41:13;0008;PBS_Server;Job;NULL;on_job_exit valid pjob: 0x2aa9990 (substate=53)
01/01/2016 18:41:13;0100;PBS_Server;Job;58875.tyrone-cluster;dequeuing from qp32, state COMPLETE
01/01/2016 18:41:13;0040;PBS_Server;Svr;tyrone-cluster;Scheduler was sent the command term
01/01/2016 18:41:51;0002;PBS_Server;Svr;PBS_Server;Torque Server Version = 3.0.5, loglevel = 0
01/01/2016 18:46:51;0002;PBS_Server;Svr;PBS_Server;Torque Server Version = 3.0.5, loglevel = 0
01/01/2016 18:48:38;0100;PBS_Server;Job;58876.tyrone-cluster;enqueuing into batch, state 1 hop 1
01/01/2016 18:48:38;0100;PBS_Server;Job;58876.tyrone-cluster;dequeuing from batch, state QUEUED
01/01/2016 18:48:38;0100;PBS_Server;Job;58876.tyrone-cluster;enqueuing into qp32, state 1 hop 1
01/01/2016 18:48:38;0008;PBS_Server;Job;58876.tyrone-cluster;Job Queued at request of chearit@tyrone-cluster, owner = chearit@tyrone-cluster, job name = jobname, queue = qp32
01/01/2016 18:48:38;0040;PBS_Server;Svr;tyrone-cluster;Scheduler was sent the command new
01/01/2016 18:48:38;0008;PBS_Server;Job;58876.tyrone-cluster;Job Modified at request of Scheduler@tyrone-cluster
01/01/2016 18:48:38;0008;PBS_Server;Job;58876.tyrone-cluster;Job Run at request of Scheduler@tyrone-cluster
01/01/2016 18:48:38;0040;PBS_Server;Svr;tyrone-cluster;Scheduler was sent the command recyc
01/01/2016 18:48:38;000d;PBS_Server;Job;58876.tyrone-cluster;Not sending email: User does not want mail of this type.
01/01/2016 18:51:51;0002;PBS_Server;Svr;PBS_Server;Torque Server Version = 3.0.5, loglevel = 0
01/01/2016 18:52:18;000d;PBS_Server;Job;58876.tyrone-cluster;Not sending email: User does not want mail of this type.
01/01/2016 18:52:18;0010;PBS_Server;Job;58876.tyrone-cluster;Exit_status=11 resources_used.cput=01:50:10 resources_used.mem=30844196kb resources_used.vmem=36930804kb resources_used.walltime=00:03:40
01/01/2016 18:52:18;0008;PBS_Server;Job;NULL;on_job_exit valid pjob: 0x2aa9990 (substate=50)
01/01/2016 18:52:18;0008;PBS_Server;Job;NULL;on_job_exit valid pjob: 0x2aa9990 (substate=51)
01/01/2016 18:52:19;0008;PBS_Server;Job;NULL;on_job_exit valid pjob: 0x2aa9990 (substate=51)
01/01/2016 18:52:19;0008;PBS_Server;Job;NULL;on_job_exit valid pjob: 0x2aa9990 (substate=53)
01/01/2016 18:52:19;0100;PBS_Server;Job;58876.tyrone-cluster;dequeuing from qp32, state COMPLETE
01/01/2016 18:52:19;0040;PBS_Server;Svr;tyrone-cluster;Scheduler was sent the command term
01/01/2016 18:54:55;0100;PBS_Server;Job;58877.tyrone-cluster;enqueuing into batch, state 1 hop 1
01/01/2016 18:54:55;0100;PBS_Server;Job;58877.tyrone-cluster;dequeuing from batch, state QUEUED
01/01/2016 18:54:55;0100;PBS_Server;Job;58877.tyrone-cluster;enqueuing into qp32, state 1 hop 1
01/01/2016 18:54:55;0008;PBS_Server;Job;58877.tyrone-cluster;Job Queued at request of chearit@tyrone-cluster, owner = chearit@tyrone-cluster, job name = jobname, queue = qp32
01/01/2016 18:54:55;0040;PBS_Server;Svr;tyrone-cluster;Scheduler was sent the command new
01/01/2016 18:54:55;0008;PBS_Server;Job;58877.tyrone-cluster;Job Modified at request of Scheduler@tyrone-cluster
01/01/2016 18:54:55;0008;PBS_Server;Job;58877.tyrone-cluster;Job Run at request of Scheduler@tyrone-cluster
01/01/2016 18:54:55;0040;PBS_Server;Svr;tyrone-cluster;Scheduler was sent the command recyc
01/01/2016 18:54:55;000d;PBS_Server;Job;58877.tyrone-cluster;Not sending email: User does not want mail of this type.
01/01/2016 18:56:51;0002;PBS_Server;Svr;PBS_Server;Torque Server Version = 3.0.5, loglevel = 0
01/01/2016 18:58:29;000d;PBS_Server;Job;58877.tyrone-cluster;Not sending email: User does not want mail of this type.
01/01/2016 18:58:29;0010;PBS_Server;Job;58877.tyrone-cluster;Exit_status=139 resources_used.cput=01:47:30 resources_used.mem=30847496kb resources_used.vmem=36963572kb resources_used.walltime=00:03:34
01/01/2016 18:58:29;0008;PBS_Server;Job;NULL;on_job_exit valid pjob: 0x2aa9990 (substate=50)
01/01/2016 18:58:29;0008;PBS_Server;Job;NULL;on_job_exit valid pjob: 0x2aa9990 (substate=51)
01/01/2016 18:58:29;0008;PBS_Server;Job;NULL;on_job_exit valid pjob: 0x2aa9990 (substate=51)
01/01/2016 18:58:29;0008;PBS_Server;Job;NULL;on_job_exit valid pjob: 0x2aa9990 (substate=53)
01/01/2016 18:58:29;0100;PBS_Server;Job;58877.tyrone-cluster;dequeuing from qp32, state COMPLETE
01/01/2016 18:58:29;0040;PBS_Server;Svr;tyrone-cluster;Scheduler was sent the command term
01/01/2016 19:01:51;0002;PBS_Server;Svr;PBS_Server;Torque Server Version = 3.0.5, loglevel = 0
01/01/2016 19:03:31;0100;PBS_Server;Job;58878.tyrone-cluster;enqueuing into batch, state 1 hop 1
01/01/2016 19:03:31;0100;PBS_Server;Job;58878.tyrone-cluster;dequeuing from batch, state QUEUED
01/01/2016 19:03:31;0100;PBS_Server;Job;58878.tyrone-cluster;enqueuing into qp32, state 1 hop 1
01/01/2016 19:03:31;0008;PBS_Server;Job;58878.tyrone-cluster;Job Queued at request of chearit@tyrone-cluster, owner = chearit@tyrone-cluster, job name = jobname, queue = qp32
01/01/2016 19:03:31;0040;PBS_Server;Svr;tyrone-cluster;Scheduler was sent the command new
01/01/2016 19:03:31;0008;PBS_Server;Job;58878.tyrone-cluster;Job Modified at request of Scheduler@tyrone-cluster
01/01/2016 19:03:31;0008;PBS_Server;Job;58878.tyrone-cluster;Job Run at request of Scheduler@tyrone-cluster
01/01/2016 19:03:31;0040;PBS_Server;Svr;tyrone-cluster;Scheduler was sent the command recyc
01/01/2016 19:03:31;000d;PBS_Server;Job;58878.tyrone-cluster;Not sending email: User does not want mail of this type.
01/01/2016 19:06:51;0002;PBS_Server;Svr;PBS_Server;Torque Server Version = 3.0.5, loglevel = 0
01/01/2016 19:06:57;0100;PBS_Server;Job;58879.tyrone-cluster;enqueuing into batch, state 1 hop 1
01/01/2016 19:06:57;0008;PBS_Server;Job;58879.tyrone-cluster;Job Queued at request of chearit@tyrone-cluster, owner = chearit@tyrone-cluster, job name = testpara, queue = batch
01/01/2016 19:06:57;0040;PBS_Server;Svr;tyrone-cluster;Scheduler was sent the command new
01/01/2016 19:06:57;0008;PBS_Server;Job;58879.tyrone-cluster;Job Modified at request of Scheduler@tyrone-cluster
01/01/2016 19:07:11;0008;PBS_Server;Job;58879.tyrone-cluster;Job deleted at request of chearit@tyrone-cluster
01/01/2016 19:07:11;0008;PBS_Server;Job;NULL;on_job_exit valid pjob: 0x2ab6170 (substate=59)
01/01/2016 19:07:11;0100;PBS_Server;Job;58879.tyrone-cluster;dequeuing from batch, state COMPLETE
01/01/2016 19:07:11;0040;PBS_Server;Svr;tyrone-cluster;Scheduler was sent the command term
01/01/2016 19:11:51;0002;PBS_Server;Svr;PBS_Server;Torque Server Version = 3.0.5, loglevel = 0
01/01/2016 19:16:51;0002;PBS_Server;Svr;PBS_Server;Torque Server Version = 3.0.5, loglevel = 0
01/01/2016 19:17:11;0040;PBS_Server;Svr;tyrone-cluster;Scheduler was sent the command time
01/01/2016 19:21:51;0002;PBS_Server;Svr;PBS_Server;Torque Server Version = 3.0.5, loglevel = 0
01/01/2016 19:26:51;0002;PBS_Server;Svr;PBS_Server;Torque Server Version = 3.0.5, loglevel = 0
01/01/2016 19:27:11;0040;PBS_Server;Svr;tyrone-cluster;Scheduler was sent the command time
01/01/2016 19:31:51;0002;PBS_Server;Svr;PBS_Server;Torque Server Version = 3.0.5, loglevel = 0
01/01/2016 19:36:51;0002;PBS_Server;Svr;PBS_Server;Torque Server Version = 3.0.5, loglevel = 0
01/01/2016 19:37:11;0040;PBS_Server;Svr;tyrone-cluster;Scheduler was sent the command time
01/01/2016 19:41:51;0002;PBS_Server;Svr;PBS_Server;Torque Server Version = 3.0.5, loglevel = 0
01/01/2016 19:46:51;0002;PBS_Server;Svr;PBS_Server;Torque Server Version = 3.0.5, loglevel = 0
01/01/2016 19:47:11;0040;PBS_Server;Svr;tyrone-cluster;Scheduler was sent the command time
01/01/2016 19:51:51;0002;PBS_Server;Svr;PBS_Server;Torque Server Version = 3.0.5, loglevel = 0
01/01/2016 19:56:51;0002;PBS_Server;Svr;PBS_Server;Torque Server Version = 3.0.5, loglevel = 0
01/01/2016 19:57:11;0040;PBS_Server;Svr;tyrone-cluster;Scheduler was sent the command time
01/01/2016 20:01:51;0002;PBS_Server;Svr;PBS_Server;Torque Server Version = 3.0.5, loglevel = 0
01/01/2016 20:06:51;0002;PBS_Server;Svr;PBS_Server;Torque Server Version = 3.0.5, loglevel = 0
01/01/2016 20:07:11;0040;PBS_Server;Svr;tyrone-cluster;Scheduler was sent the command time
01/01/2016 20:11:51;0002;PBS_Server;Svr;PBS_Server;Torque Server Version = 3.0.5, loglevel = 0
01/01/2016 20:16:51;0002;PBS_Server;Svr;PBS_Server;Torque Server Version = 3.0.5, loglevel = 0
01/01/2016 20:17:11;0040;PBS_Server;Svr;tyrone-cluster;Scheduler was sent the command time
01/01/2016 20:21:51;0002;PBS_Server;Svr;PBS_Server;Torque Server Version = 3.0.5, loglevel = 0
01/01/2016 20:26:51;0002;PBS_Server;Svr;PBS_Server;Torque Server Version = 3.0.5, loglevel = 0
01/01/2016 20:27:11;0040;PBS_Server;Svr;tyrone-cluster;Scheduler was sent the command time
01/01/2016 20:31:51;0002;PBS_Server;Svr;PBS_Server;Torque Server Version = 3.0.5, loglevel = 0
01/01/2016 20:36:51;0002;PBS_Server;Svr;PBS_Server;Torque Server Version = 3.0.5, loglevel = 0
01/01/2016 20:37:11;0040;PBS_Server;Svr;tyrone-cluster;Scheduler was sent the command time
01/01/2016 20:41:51;0002;PBS_Server;Svr;PBS_Server;Torque Server Version = 3.0.5, loglevel = 0
01/01/2016 20:46:51;0002;PBS_Server;Svr;PBS_Server;Torque Server Version = 3.0.5, loglevel = 0
01/01/2016 20:47:11;0040;PBS_Server;Svr;tyrone-cluster;Scheduler was sent the command time
01/01/2016 20:51:51;0002;PBS_Server;Svr;PBS_Server;Torque Server Version = 3.0.5, loglevel = 0
01/01/2016 20:56:51;0002;PBS_Server;Svr;PBS_Server;Torque Server Version = 3.0.5, loglevel = 0
01/01/2016 20:57:11;0040;PBS_Server;Svr;tyrone-cluster;Scheduler was sent the command time
01/01/2016 21:01:51;0002;PBS_Server;Svr;PBS_Server;Torque Server Version = 3.0.5, loglevel = 0
01/01/2016 21:06:51;0002;PBS_Server;Svr;PBS_Server;Torque Server Version = 3.0.5, loglevel = 0
01/01/2016 21:07:11;0040;PBS_Server;Svr;tyrone-cluster;Scheduler was sent the command time
01/01/2016 21:11:51;0002;PBS_Server;Svr;PBS_Server;Torque Server Version = 3.0.5, loglevel = 0
01/01/2016 21:16:51;0002;PBS_Server;Svr;PBS_Server;Torque Server Version = 3.0.5, loglevel = 0
01/01/2016 21:17:11;0040;PBS_Server;Svr;tyrone-cluster;Scheduler was sent the command time
01/01/2016 21:21:51;0002;PBS_Server;Svr;PBS_Server;Torque Server Version = 3.0.5, loglevel = 0
01/01/2016 21:26:51;0002;PBS_Server;Svr;PBS_Server;Torque Server Version = 3.0.5, loglevel = 0
01/01/2016 21:27:11;0040;PBS_Server;Svr;tyrone-cluster;Scheduler was sent the command time
01/01/2016 21:31:51;0002;PBS_Server;Svr;PBS_Server;Torque Server Version = 3.0.5, loglevel = 0
01/01/2016 21:36:51;0002;PBS_Server;Svr;PBS_Server;Torque Server Version = 3.0.5, loglevel = 0
01/01/2016 21:37:11;0040;PBS_Server;Svr;tyrone-cluster;Scheduler was sent the command time
01/01/2016 21:41:51;0002;PBS_Server;Svr;PBS_Server;Torque Server Version = 3.0.5, loglevel = 0
01/01/2016 21:46:51;0002;PBS_Server;Svr;PBS_Server;Torque Server Version = 3.0.5, loglevel = 0
01/01/2016 21:47:11;0040;PBS_Server;Svr;tyrone-cluster;Scheduler was sent the command time
01/01/2016 21:51:51;0002;PBS_Server;Svr;PBS_Server;Torque Server Version = 3.0.5, loglevel = 0
01/01/2016 21:56:51;0002;PBS_Server;Svr;PBS_Server;Torque Server Version = 3.0.5, loglevel = 0
01/01/2016 21:57:11;0040;PBS_Server;Svr;tyrone-cluster;Scheduler was sent the command time
01/01/2016 22:01:51;0002;PBS_Server;Svr;PBS_Server;Torque Server Version = 3.0.5, loglevel = 0
01/01/2016 22:06:51;0002;PBS_Server;Svr;PBS_Server;Torque Server Version = 3.0.5, loglevel = 0
01/01/2016 22:07:11;0040;PBS_Server;Svr;tyrone-cluster;Scheduler was sent the command time
01/01/2016 22:10:34;0100;PBS_Server;Job;58880.tyrone-cluster;enqueuing into batch, state 1 hop 1
01/01/2016 22:10:34;0100;PBS_Server;Job;58880.tyrone-cluster;dequeuing from batch, state QUEUED
01/01/2016 22:10:34;0100;PBS_Server;Job;58880.tyrone-cluster;enqueuing into qp128, state 1 hop 1
01/01/2016 22:10:34;0008;PBS_Server;Job;58880.tyrone-cluster;Job Queued at request of mbunisha@tyrone-cluster, owner = mbunisha@tyrone-cluster, job name = Vmg-r-1, queue = qp128
01/01/2016 22:10:34;0040;PBS_Server;Svr;tyrone-cluster;Scheduler was sent the command new
01/01/2016 22:10:34;0008;PBS_Server;Job;58880.tyrone-cluster;Job Modified at request of Scheduler@tyrone-cluster
01/01/2016 22:10:38;0100;PBS_Server;Job;58881.tyrone-cluster;enqueuing into batch, state 1 hop 1
01/01/2016 22:10:38;0100;PBS_Server;Job;58881.tyrone-cluster;dequeuing from batch, state QUEUED
01/01/2016 22:10:38;0100;PBS_Server;Job;58881.tyrone-cluster;enqueuing into qp128, state 1 hop 1
01/01/2016 22:10:38;0008;PBS_Server;Job;58881.tyrone-cluster;Job Queued at request of mbunisha@tyrone-cluster, owner = mbunisha@tyrone-cluster, job name = Vmg-r-1, queue = qp128
01/01/2016 22:10:38;0040;PBS_Server;Svr;tyrone-cluster;Scheduler was sent the command new
01/01/2016 22:10:38;0008;PBS_Server;Job;58881.tyrone-cluster;Job Modified at request of Scheduler@tyrone-cluster
01/01/2016 22:10:39;0100;PBS_Server;Job;58882.tyrone-cluster;enqueuing into batch, state 1 hop 1
01/01/2016 22:10:39;0008;PBS_Server;Job;58882.tyrone-cluster;Job Queued at request of mbunisha@tyrone-cluster, owner = mbunisha@tyrone-cluster, job name = Vmg-r-1, queue = batch
01/01/2016 22:10:39;0040;PBS_Server;Svr;tyrone-cluster;Scheduler was sent the command new
01/01/2016 22:10:39;0008;PBS_Server;Job;58882.tyrone-cluster;Job Modified at request of Scheduler@tyrone-cluster
01/01/2016 22:10:40;0100;PBS_Server;Job;58883.tyrone-cluster;enqueuing into batch, state 1 hop 1
01/01/2016 22:10:40;0008;PBS_Server;Job;58883.tyrone-cluster;Job Queued at request of mbunisha@tyrone-cluster, owner = mbunisha@tyrone-cluster, job name = Vmg-r-1, queue = batch
01/01/2016 22:10:40;0040;PBS_Server;Svr;tyrone-cluster;Scheduler was sent the command new
01/01/2016 22:10:40;0008;PBS_Server;Job;58883.tyrone-cluster;Job Modified at request of Scheduler@tyrone-cluster
01/01/2016 22:11:11;0040;PBS_Server;Svr;tyrone-cluster;Scheduler was sent the command new
01/01/2016 22:11:42;0040;PBS_Server;Svr;tyrone-cluster;Scheduler was sent the command new
01/01/2016 22:11:51;0002;PBS_Server;Svr;PBS_Server;Torque Server Version = 3.0.5, loglevel = 0
01/01/2016 22:12:15;0040;PBS_Server;Svr;tyrone-cluster;Scheduler was sent the command new
01/01/2016 22:12:41;0040;PBS_Server;Svr;tyrone-cluster;Scheduler was sent the command new
01/01/2016 22:12:50;0040;PBS_Server;Svr;tyrone-cluster;Scheduler was sent the command new
01/01/2016 22:13:13;0040;PBS_Server;Svr;tyrone-cluster;Scheduler was sent the command new
01/01/2016 22:13:21;0040;PBS_Server;Svr;tyrone-cluster;Scheduler was sent the command new
01/01/2016 22:13:45;0040;PBS_Server;Svr;tyrone-cluster;Scheduler was sent the command new
01/01/2016 22:13:54;0040;PBS_Server;Svr;tyrone-cluster;Scheduler was sent the command new
01/01/2016 22:14:17;0040;PBS_Server;Svr;tyrone-cluster;Scheduler was sent the command new
01/01/2016 22:14:22;0040;PBS_Server;Svr;tyrone-cluster;Scheduler was sent the command new
01/01/2016 22:14:51;0040;PBS_Server;Svr;tyrone-cluster;Scheduler was sent the command new
01/01/2016 22:15:24;0040;PBS_Server;Svr;tyrone-cluster;Scheduler was sent the command new
01/01/2016 22:15:50;0100;PBS_Server;Job;58884.tyrone-cluster;enqueuing into batch, state 1 hop 1
01/01/2016 22:15:50;0100;PBS_Server;Job;58884.tyrone-cluster;dequeuing from batch, state QUEUED
01/01/2016 22:15:50;0100;PBS_Server;Job;58884.tyrone-cluster;enqueuing into qp64, state 1 hop 1
01/01/2016 22:15:50;0008;PBS_Server;Job;58884.tyrone-cluster;Job Queued at request of mbuteja@tyrone-cluster, owner = mbuteja@tyrone-cluster, job name = Emg-r-1, queue = qp64
01/01/2016 22:15:50;0040;PBS_Server;Svr;tyrone-cluster;Scheduler was sent the command new
01/01/2016 22:15:50;0008;PBS_Server;Job;58884.tyrone-cluster;Job Modified at request of Scheduler@tyrone-cluster
01/01/2016 22:15:50;0008;PBS_Server;Job;58884.tyrone-cluster;Job Run at request of Scheduler@tyrone-cluster
01/01/2016 22:15:51;0040;PBS_Server;Svr;tyrone-cluster;Scheduler was sent the command recyc
01/01/2016 22:15:53;0040;PBS_Server;Svr;tyrone-cluster;Scheduler was sent the command new
01/01/2016 22:16:09;000d;PBS_Server;Job;58884.tyrone-cluster;Not sending email: User does not want mail of this type.
01/01/2016 22:16:26;0040;PBS_Server;Svr;tyrone-cluster;Scheduler was sent the command new
01/01/2016 22:16:51;0002;PBS_Server;Svr;PBS_Server;Torque Server Version = 3.0.5, loglevel = 0
01/01/2016 22:16:54;0040;PBS_Server;Svr;tyrone-cluster;Scheduler was sent the command new
01/01/2016 22:17:29;0040;PBS_Server;Svr;tyrone-cluster;Scheduler was sent the command new
01/01/2016 22:17:56;0040;PBS_Server;Svr;tyrone-cluster;Scheduler was sent the command new
01/01/2016 22:18:28;0040;PBS_Server;Svr;tyrone-cluster;Scheduler was sent the command new
01/01/2016 22:19:00;0040;PBS_Server;Svr;tyrone-cluster;Scheduler was sent the command new
01/01/2016 22:19:35;0040;PBS_Server;Svr;tyrone-cluster;Scheduler was sent the command new
01/01/2016 22:20:06;0040;PBS_Server;Svr;tyrone-cluster;Scheduler was sent the command new
01/01/2016 22:20:39;0040;PBS_Server;Svr;tyrone-cluster;Scheduler was sent the command new
01/01/2016 22:21:08;0040;PBS_Server;Svr;tyrone-cluster;Scheduler was sent the command new
01/01/2016 22:21:41;0040;PBS_Server;Svr;tyrone-cluster;Scheduler was sent the command new
01/01/2016 22:21:51;0002;PBS_Server;Svr;PBS_Server;Torque Server Version = 3.0.5, loglevel = 0
01/01/2016 22:22:09;0040;PBS_Server;Svr;tyrone-cluster;Scheduler was sent the command new
01/01/2016 22:22:45;0040;PBS_Server;Svr;tyrone-cluster;Scheduler was sent the command new
01/01/2016 22:23:11;0040;PBS_Server;Svr;tyrone-cluster;Scheduler was sent the command new
01/01/2016 22:23:43;0040;PBS_Server;Svr;tyrone-cluster;Scheduler was sent the command new
01/01/2016 22:24:15;0040;PBS_Server;Svr;tyrone-cluster;Scheduler was sent the command new
01/01/2016 22:24:50;0040;PBS_Server;Svr;tyrone-cluster;Scheduler was sent the command new
01/01/2016 22:25:21;0040;PBS_Server;Svr;tyrone-cluster;Scheduler was sent the command new
01/01/2016 22:25:53;0040;PBS_Server;Svr;tyrone-cluster;Scheduler was sent the command new
01/01/2016 22:26:22;0040;PBS_Server;Svr;tyrone-cluster;Scheduler was sent the command new
01/01/2016 22:26:51;0002;PBS_Server;Svr;PBS_Server;Torque Server Version = 3.0.5, loglevel = 0
01/01/2016 22:26:56;0040;PBS_Server;Svr;tyrone-cluster;Scheduler was sent the command new
01/01/2016 22:27:24;0040;PBS_Server;Svr;tyrone-cluster;Scheduler was sent the command new
01/01/2016 22:27:53;0040;PBS_Server;Svr;tyrone-cluster;Scheduler was sent the command new
01/01/2016 22:28:26;0040;PBS_Server;Svr;tyrone-cluster;Scheduler was sent the command new
01/01/2016 22:28:54;0040;PBS_Server;Svr;tyrone-cluster;Scheduler was sent the command new
01/01/2016 22:29:29;0040;PBS_Server;Svr;tyrone-cluster;Scheduler was sent the command new
01/01/2016 22:29:56;0040;PBS_Server;Svr;tyrone-cluster;Scheduler was sent the command new
01/01/2016 22:30:28;0040;PBS_Server;Svr;tyrone-cluster;Scheduler was sent the command new
01/01/2016 22:31:00;0040;PBS_Server;Svr;tyrone-cluster;Scheduler was sent the command new
01/01/2016 22:31:34;0040;PBS_Server;Svr;tyrone-cluster;Scheduler was sent the command new
01/01/2016 22:31:51;0002;PBS_Server;Svr;PBS_Server;Torque Server Version = 3.0.5, loglevel = 0
01/01/2016 22:32:06;0040;PBS_Server;Svr;tyrone-cluster;Scheduler was sent the command new
01/01/2016 22:32:39;0040;PBS_Server;Svr;tyrone-cluster;Scheduler was sent the command new
01/01/2016 22:33:08;0040;PBS_Server;Svr;tyrone-cluster;Scheduler was sent the command new
01/01/2016 22:33:41;0040;PBS_Server;Svr;tyrone-cluster;Scheduler was sent the command new
01/01/2016 22:34:09;0040;PBS_Server;Svr;tyrone-cluster;Scheduler was sent the command new
01/01/2016 22:34:44;0040;PBS_Server;Svr;tyrone-cluster;Scheduler was sent the command new
01/01/2016 22:35:11;0040;PBS_Server;Svr;tyrone-cluster;Scheduler was sent the command new
01/01/2016 22:35:43;0040;PBS_Server;Svr;tyrone-cluster;Scheduler was sent the command new
01/01/2016 22:36:15;0040;PBS_Server;Svr;tyrone-cluster;Scheduler was sent the command new
01/01/2016 22:36:46;0040;PBS_Server;Svr;tyrone-cluster;Scheduler was sent the command new
01/01/2016 22:36:51;0002;PBS_Server;Svr;PBS_Server;Torque Server Version = 3.0.5, loglevel = 0
01/01/2016 22:37:21;0040;PBS_Server;Svr;tyrone-cluster;Scheduler was sent the command new
01/01/2016 22:37:53;0040;PBS_Server;Svr;tyrone-cluster;Scheduler was sent the command new
01/01/2016 22:38:22;0040;PBS_Server;Svr;tyrone-cluster;Scheduler was sent the command new
01/01/2016 22:38:56;0040;PBS_Server;Svr;tyrone-cluster;Scheduler was sent the command new
01/01/2016 22:39:24;0040;PBS_Server;Svr;tyrone-cluster;Scheduler was sent the command new
01/01/2016 22:39:53;0040;PBS_Server;Svr;tyrone-cluster;Scheduler was sent the command new
01/01/2016 22:40:26;0040;PBS_Server;Svr;tyrone-cluster;Scheduler was sent the command new
01/01/2016 22:40:54;0040;PBS_Server;Svr;tyrone-cluster;Scheduler was sent the command new
01/01/2016 22:41:29;0040;PBS_Server;Svr;tyrone-cluster;Scheduler was sent the command new
01/01/2016 22:41:51;0002;PBS_Server;Svr;PBS_Server;Torque Server Version = 3.0.5, loglevel = 0
01/01/2016 22:41:56;0040;PBS_Server;Svr;tyrone-cluster;Scheduler was sent the command new
01/01/2016 22:42:28;0040;PBS_Server;Svr;tyrone-cluster;Scheduler was sent the command new
01/01/2016 22:43:00;0040;PBS_Server;Svr;tyrone-cluster;Scheduler was sent the command new
01/01/2016 22:43:34;0040;PBS_Server;Svr;tyrone-cluster;Scheduler was sent the command new
01/01/2016 22:44:06;0040;PBS_Server;Svr;tyrone-cluster;Scheduler was sent the command new
01/01/2016 22:44:39;0040;PBS_Server;Svr;tyrone-cluster;Scheduler was sent the command new
01/01/2016 22:45:08;0040;PBS_Server;Svr;tyrone-cluster;Scheduler was sent the command new
01/01/2016 22:45:41;0040;PBS_Server;Svr;tyrone-cluster;Scheduler was sent the command new
01/01/2016 22:46:09;0040;PBS_Server;Svr;tyrone-cluster;Scheduler was sent the command new
01/01/2016 22:46:44;0040;PBS_Server;Svr;tyrone-cluster;Scheduler was sent the command new
01/01/2016 22:46:51;0002;PBS_Server;Svr;PBS_Server;Torque Server Version = 3.0.5, loglevel = 0
01/01/2016 22:47:11;0040;PBS_Server;Svr;tyrone-cluster;Scheduler was sent the command new
01/01/2016 22:47:43;0040;PBS_Server;Svr;tyrone-cluster;Scheduler was sent the command new
01/01/2016 22:48:15;0040;PBS_Server;Svr;tyrone-cluster;Scheduler was sent the command new
01/01/2016 22:48:49;0040;PBS_Server;Svr;tyrone-cluster;Scheduler was sent the command new
01/01/2016 22:49:21;0040;PBS_Server;Svr;tyrone-cluster;Scheduler was sent the command new
01/01/2016 22:49:54;0040;PBS_Server;Svr;tyrone-cluster;Scheduler was sent the command new
01/01/2016 22:50:23;0040;PBS_Server;Svr;tyrone-cluster;Scheduler was sent the command new
01/01/2016 22:50:56;0040;PBS_Server;Svr;tyrone-cluster;Scheduler was sent the command new
01/01/2016 22:51:24;0040;PBS_Server;Svr;tyrone-cluster;Scheduler was sent the command new
01/01/2016 22:51:51;0002;PBS_Server;Svr;PBS_Server;Torque Server Version = 3.0.5, loglevel = 0
01/01/2016 22:51:59;0040;PBS_Server;Svr;tyrone-cluster;Scheduler was sent the command new
01/01/2016 22:52:28;0040;PBS_Server;Svr;tyrone-cluster;Scheduler was sent the command new
01/01/2016 22:52:58;0040;PBS_Server;Svr;tyrone-cluster;Scheduler was sent the command new
01/01/2016 22:53:30;0040;PBS_Server;Svr;tyrone-cluster;Scheduler was sent the command new
01/01/2016 22:54:04;0040;PBS_Server;Svr;tyrone-cluster;Scheduler was sent the command new
01/01/2016 22:54:36;0040;PBS_Server;Svr;tyrone-cluster;Scheduler was sent the command new
01/01/2016 22:55:09;0040;PBS_Server;Svr;tyrone-cluster;Scheduler was sent the command new
01/01/2016 22:55:38;0040;PBS_Server;Svr;tyrone-cluster;Scheduler was sent the command new
01/01/2016 22:56:11;0040;PBS_Server;Svr;tyrone-cluster;Scheduler was sent the command new
01/01/2016 22:56:39;0040;PBS_Server;Svr;tyrone-cluster;Scheduler was sent the command new
01/01/2016 22:56:51;0002;PBS_Server;Svr;PBS_Server;Torque Server Version = 3.0.5, loglevel = 0
01/01/2016 22:57:14;0040;PBS_Server;Svr;tyrone-cluster;Scheduler was sent the command new
01/01/2016 22:57:43;0040;PBS_Server;Svr;tyrone-cluster;Scheduler was sent the command new
01/01/2016 22:58:13;0040;PBS_Server;Svr;tyrone-cluster;Scheduler was sent the command new
01/01/2016 22:58:45;0040;PBS_Server;Svr;tyrone-cluster;Scheduler was sent the command new
01/01/2016 22:59:17;0040;PBS_Server;Svr;tyrone-cluster;Scheduler was sent the command new
01/01/2016 22:59:51;0040;PBS_Server;Svr;tyrone-cluster;Scheduler was sent the command new
01/01/2016 23:00:23;0040;PBS_Server;Svr;tyrone-cluster;Scheduler was sent the command new
01/01/2016 23:00:52;0040;PBS_Server;Svr;tyrone-cluster;Scheduler was sent the command new
01/01/2016 23:01:26;0040;PBS_Server;Svr;tyrone-cluster;Scheduler was sent the command new
01/01/2016 23:01:51;0002;PBS_Server;Svr;PBS_Server;Torque Server Version = 3.0.5, loglevel = 0
01/01/2016 23:01:54;0040;PBS_Server;Svr;tyrone-cluster;Scheduler was sent the command new
01/01/2016 23:02:29;0040;PBS_Server;Svr;tyrone-cluster;Scheduler was sent the command new
01/01/2016 23:02:58;0040;PBS_Server;Svr;tyrone-cluster;Scheduler was sent the command new
01/01/2016 23:03:28;0040;PBS_Server;Svr;tyrone-cluster;Scheduler was sent the command new
01/01/2016 23:04:00;0040;PBS_Server;Svr;tyrone-cluster;Scheduler was sent the command new
01/01/2016 23:04:34;0040;PBS_Server;Svr;tyrone-cluster;Scheduler was sent the command new
01/01/2016 23:05:06;0040;PBS_Server;Svr;tyrone-cluster;Scheduler was sent the command new
01/01/2016 23:05:38;0040;PBS_Server;Svr;tyrone-cluster;Scheduler was sent the command new
01/01/2016 23:06:07;0040;PBS_Server;Svr;tyrone-cluster;Scheduler was sent the command new
01/01/2016 23:06:41;0040;PBS_Server;Svr;tyrone-cluster;Scheduler was sent the command new
01/01/2016 23:06:51;0002;PBS_Server;Svr;PBS_Server;Torque Server Version = 3.0.5, loglevel = 0
01/01/2016 23:07:09;0040;PBS_Server;Svr;tyrone-cluster;Scheduler was sent the command new
01/01/2016 23:07:44;0040;PBS_Server;Svr;tyrone-cluster;Scheduler was sent the command new
01/01/2016 23:08:13;0040;PBS_Server;Svr;tyrone-cluster;Scheduler was sent the command new
01/01/2016 23:08:43;0040;PBS_Server;Svr;tyrone-cluster;Scheduler was sent the command new
01/01/2016 23:09:15;0040;PBS_Server;Svr;tyrone-cluster;Scheduler was sent the command new
01/01/2016 23:09:50;0040;PBS_Server;Svr;tyrone-cluster;Scheduler was sent the command new
01/01/2016 23:10:21;0040;PBS_Server;Svr;tyrone-cluster;Scheduler was sent the command new
01/01/2016 23:10:53;0040;PBS_Server;Svr;tyrone-cluster;Scheduler was sent the command new
01/01/2016 23:11:22;0040;PBS_Server;Svr;tyrone-cluster;Scheduler was sent the command new
01/01/2016 23:11:51;0002;PBS_Server;Svr;PBS_Server;Torque Server Version = 3.0.5, loglevel = 0
01/01/2016 23:11:56;0040;PBS_Server;Svr;tyrone-cluster;Scheduler was sent the command new
01/01/2016 23:12:24;0040;PBS_Server;Svr;tyrone-cluster;Scheduler was sent the command new
01/01/2016 23:12:53;0040;PBS_Server;Svr;tyrone-cluster;Scheduler was sent the command new
01/01/2016 23:13:26;0040;PBS_Server;Svr;tyrone-cluster;Scheduler was sent the command new
01/01/2016 23:13:54;0040;PBS_Server;Svr;tyrone-cluster;Scheduler was sent the command new
01/01/2016 23:14:29;0040;PBS_Server;Svr;tyrone-cluster;Scheduler was sent the command new
01/01/2016 23:14:58;0040;PBS_Server;Svr;tyrone-cluster;Scheduler was sent the command new
01/01/2016 23:15:28;0040;PBS_Server;Svr;tyrone-cluster;Scheduler was sent the command new
01/01/2016 23:16:00;0040;PBS_Server;Svr;tyrone-cluster;Scheduler was sent the command new
01/01/2016 23:16:34;0040;PBS_Server;Svr;tyrone-cluster;Scheduler was sent the command new
01/01/2016 23:16:51;0002;PBS_Server;Svr;PBS_Server;Torque Server Version = 3.0.5, loglevel = 0
01/01/2016 23:17:06;0040;PBS_Server;Svr;tyrone-cluster;Scheduler was sent the command new
01/01/2016 23:17:39;0040;PBS_Server;Svr;tyrone-cluster;Scheduler was sent the command new
01/01/2016 23:18:07;0040;PBS_Server;Svr;tyrone-cluster;Scheduler was sent the command new
01/01/2016 23:18:41;0040;PBS_Server;Svr;tyrone-cluster;Scheduler was sent the command new
01/01/2016 23:19:09;0040;PBS_Server;Svr;tyrone-cluster;Scheduler was sent the command new
01/01/2016 23:19:44;0040;PBS_Server;Svr;tyrone-cluster;Scheduler was sent the command new
01/01/2016 23:20:13;0040;PBS_Server;Svr;tyrone-cluster;Scheduler was sent the command new
01/01/2016 23:20:43;0040;PBS_Server;Svr;tyrone-cluster;Scheduler was sent the command new
01/01/2016 23:21:15;0040;PBS_Server;Svr;tyrone-cluster;Scheduler was sent the command new
01/01/2016 23:21:46;0040;PBS_Server;Svr;tyrone-cluster;Scheduler was sent the command new
01/01/2016 23:21:51;0002;PBS_Server;Svr;PBS_Server;Torque Server Version = 3.0.5, loglevel = 0
01/01/2016 23:22:21;0040;PBS_Server;Svr;tyrone-cluster;Scheduler was sent the command new
01/01/2016 23:22:54;0040;PBS_Server;Svr;tyrone-cluster;Scheduler was sent the command new
01/01/2016 23:23:22;0040;PBS_Server;Svr;tyrone-cluster;Scheduler was sent the command new
01/01/2016 23:23:56;0040;PBS_Server;Svr;tyrone-cluster;Scheduler was sent the command new
01/01/2016 23:24:24;0040;PBS_Server;Svr;tyrone-cluster;Scheduler was sent the command new
01/01/2016 23:24:59;0040;PBS_Server;Svr;tyrone-cluster;Scheduler was sent the command new
01/01/2016 23:25:28;0040;PBS_Server;Svr;tyrone-cluster;Scheduler was sent the command new
01/01/2016 23:25:59;0040;PBS_Server;Svr;tyrone-cluster;Scheduler was sent the command new
01/01/2016 23:26:30;0040;PBS_Server;Svr;tyrone-cluster;Scheduler was sent the command new
01/01/2016 23:26:51;0002;PBS_Server;Svr;PBS_Server;Torque Server Version = 3.0.5, loglevel = 0
01/01/2016 23:27:04;0040;PBS_Server;Svr;tyrone-cluster;Scheduler was sent the command new
01/01/2016 23:27:36;0040;PBS_Server;Svr;tyrone-cluster;Scheduler was sent the command new
01/01/2016 23:28:08;0040;PBS_Server;Svr;tyrone-cluster;Scheduler was sent the command new
01/01/2016 23:28:37;0040;PBS_Server;Svr;tyrone-cluster;Scheduler was sent the command new
01/01/2016 23:29:11;0040;PBS_Server;Svr;tyrone-cluster;Scheduler was sent the command new
01/01/2016 23:29:39;0040;PBS_Server;Svr;tyrone-cluster;Scheduler was sent the command new
01/01/2016 23:30:14;0040;PBS_Server;Svr;tyrone-cluster;Scheduler was sent the command new
01/01/2016 23:30:43;0040;PBS_Server;Svr;tyrone-cluster;Scheduler was sent the command new
01/01/2016 23:31:14;0040;PBS_Server;Svr;tyrone-cluster;Scheduler was sent the command new
01/01/2016 23:31:45;0040;PBS_Server;Svr;tyrone-cluster;Scheduler was sent the command new
01/01/2016 23:31:51;0002;PBS_Server;Svr;PBS_Server;Torque Server Version = 3.0.5, loglevel = 0
01/01/2016 23:32:19;0040;PBS_Server;Svr;tyrone-cluster;Scheduler was sent the command new
01/01/2016 23:32:51;0040;PBS_Server;Svr;tyrone-cluster;Scheduler was sent the command new
01/01/2016 23:33:23;0040;PBS_Server;Svr;tyrone-cluster;Scheduler was sent the command new
01/01/2016 23:33:52;0040;PBS_Server;Svr;tyrone-cluster;Scheduler was sent the command new
01/01/2016 23:34:26;0040;PBS_Server;Svr;tyrone-cluster;Scheduler was sent the command new
01/01/2016 23:34:54;0040;PBS_Server;Svr;tyrone-cluster;Scheduler was sent the command new
01/01/2016 23:35:29;0040;PBS_Server;Svr;tyrone-cluster;Scheduler was sent the command new
01/01/2016 23:35:58;0040;PBS_Server;Svr;tyrone-cluster;Scheduler was sent the command new
01/01/2016 23:36:29;0040;PBS_Server;Svr;tyrone-cluster;Scheduler was sent the command new
01/01/2016 23:36:51;0002;PBS_Server;Svr;PBS_Server;Torque Server Version = 3.0.5, loglevel = 0
01/01/2016 23:37:00;0040;PBS_Server;Svr;tyrone-cluster;Scheduler was sent the command new
01/01/2016 23:37:34;0040;PBS_Server;Svr;tyrone-cluster;Scheduler was sent the command new
01/01/2016 23:38:06;0040;PBS_Server;Svr;tyrone-cluster;Scheduler was sent the command new
01/01/2016 23:38:38;0040;PBS_Server;Svr;tyrone-cluster;Scheduler was sent the command new
01/01/2016 23:39:07;0040;PBS_Server;Svr;tyrone-cluster;Scheduler was sent the command new
01/01/2016 23:39:41;0040;PBS_Server;Svr;tyrone-cluster;Scheduler was sent the command new
01/01/2016 23:40:09;0040;PBS_Server;Svr;tyrone-cluster;Scheduler was sent the command new
01/01/2016 23:40:44;0040;PBS_Server;Svr;tyrone-cluster;Scheduler was sent the command new
01/01/2016 23:41:13;0040;PBS_Server;Svr;tyrone-cluster;Scheduler was sent the command new
01/01/2016 23:41:44;0040;PBS_Server;Svr;tyrone-cluster;Scheduler was sent the command new
01/01/2016 23:41:51;0002;PBS_Server;Svr;PBS_Server;Torque Server Version = 3.0.5, loglevel = 0
01/01/2016 23:42:15;0040;PBS_Server;Svr;tyrone-cluster;Scheduler was sent the command new
01/01/2016 23:42:49;0040;PBS_Server;Svr;tyrone-cluster;Scheduler was sent the command new
01/01/2016 23:43:21;0040;PBS_Server;Svr;tyrone-cluster;Scheduler was sent the command new
01/01/2016 23:43:53;0040;PBS_Server;Svr;tyrone-cluster;Scheduler was sent the command new
01/01/2016 23:44:22;0040;PBS_Server;Svr;tyrone-cluster;Scheduler was sent the command new
01/01/2016 23:44:56;0040;PBS_Server;Svr;tyrone-cluster;Scheduler was sent the command new
01/01/2016 23:45:24;0040;PBS_Server;Svr;tyrone-cluster;Scheduler was sent the command new
01/01/2016 23:45:59;0040;PBS_Server;Svr;tyrone-cluster;Scheduler was sent the command new
01/01/2016 23:46:28;0040;PBS_Server;Svr;tyrone-cluster;Scheduler was sent the command new
01/01/2016 23:46:51;0002;PBS_Server;Svr;PBS_Server;Torque Server Version = 3.0.5, loglevel = 0
01/01/2016 23:46:59;0040;PBS_Server;Svr;tyrone-cluster;Scheduler was sent the command new
01/01/2016 23:47:30;0040;PBS_Server;Svr;tyrone-cluster;Scheduler was sent the command new
01/01/2016 23:48:04;0040;PBS_Server;Svr;tyrone-cluster;Scheduler was sent the command new
01/01/2016 23:48:36;0040;PBS_Server;Svr;tyrone-cluster;Scheduler was sent the command new
01/01/2016 23:49:08;0040;PBS_Server;Svr;tyrone-cluster;Scheduler was sent the command new
01/01/2016 23:49:37;0040;PBS_Server;Svr;tyrone-cluster;Scheduler was sent the command new
01/01/2016 23:50:10;0040;PBS_Server;Svr;tyrone-cluster;Scheduler was sent the command new
01/01/2016 23:50:39;0040;PBS_Server;Svr;tyrone-cluster;Scheduler was sent the command new
01/01/2016 23:51:07;0040;PBS_Server;Svr;tyrone-cluster;Scheduler was sent the command new
01/01/2016 23:51:41;0040;PBS_Server;Svr;tyrone-cluster;Scheduler was sent the command new
01/01/2016 23:51:51;0002;PBS_Server;Svr;PBS_Server;Torque Server Version = 3.0.5, loglevel = 0
01/01/2016 23:52:08;0040;PBS_Server;Svr;tyrone-cluster;Scheduler was sent the command new
01/01/2016 23:52:37;0040;PBS_Server;Svr;tyrone-cluster;Scheduler was sent the command new
01/01/2016 23:53:11;0040;PBS_Server;Svr;tyrone-cluster;Scheduler was sent the command new
01/01/2016 23:53:38;0040;PBS_Server;Svr;tyrone-cluster;Scheduler was sent the command new
01/01/2016 23:54:07;0040;PBS_Server;Svr;tyrone-cluster;Scheduler was sent the command new
01/01/2016 23:54:40;0040;PBS_Server;Svr;tyrone-cluster;Scheduler was sent the command new
01/01/2016 23:55:08;0040;PBS_Server;Svr;tyrone-cluster;Scheduler was sent the command new
01/01/2016 23:55:37;0040;PBS_Server;Svr;tyrone-cluster;Scheduler was sent the command new
01/01/2016 23:56:11;0040;PBS_Server;Svr;tyrone-cluster;Scheduler was sent the command new
01/01/2016 23:56:39;0040;PBS_Server;Svr;tyrone-cluster;Scheduler was sent the command new
01/01/2016 23:56:51;0002;PBS_Server;Svr;PBS_Server;Torque Server Version = 3.0.5, loglevel = 0
01/01/2016 23:57:14;0040;PBS_Server;Svr;tyrone-cluster;Scheduler was sent the command new
01/01/2016 23:57:43;0040;PBS_Server;Svr;tyrone-cluster;Scheduler was sent the command new
01/01/2016 23:58:13;0040;PBS_Server;Svr;tyrone-cluster;Scheduler was sent the command new
01/01/2016 23:58:45;0040;PBS_Server;Svr;tyrone-cluster;Scheduler was sent the command new
01/01/2016 23:59:17;0040;PBS_Server;Svr;tyrone-cluster;Scheduler was sent the command new
01/01/2016 23:59:51;0040;PBS_Server;Svr;tyrone-cluster;Scheduler was sent the command new
01/02/2016 00:00:23;0002;PBS_Server;Svr;Log;Log closed
